Workbook

Sheet Instrucciones
A1: Carta de Apertura y Escandallo del Churro
A2: AI Chef Pro · aichef.pro — Cómo Montar una Churrería-Chocolatería
A3: Para qué sirve: decidir a cuánto vendes la ración, la docena, el kilo y la taza, con el coste real de la masa frita y del aceite que se lleva, y saber qué margen te queda de verdad.
A5: Instrucciones de Uso
A6: Celdas verdes = campos editables
A7: Las celdas en crema son resultados que el libro calcula; las blancas con fórmula, también. No escribas encima.
A9: 1. Hoja «Parámetros». Arriba, el IVA de cada canal: la sala al 10 % y, para llevar, una celda por categoría. Chocolate y bebidas para llevar van al 10 % en celda verde con un aviso (consulta a tu asesor: con agua y un preparado azucarado podría ser el 21 %); granizado y horchata para llevar llevan el 21 % por prudencia, también en celda verde y con el mismo aviso (es zona gris: lo decide tu asesor). Abajo, los supuestos de la masa y del aceite, y la tabla de insumos: es la ÚNICA tabla donde se tocan los precios. El del aceite es la celda única de todo el paquete.
A10: 2. Hoja «Escandallo por kg de Masa». Cuánto cuesta un kilo de masa con el preparado comercial y con un mix propio, cuánto cuesta un churro y una porra, y de la masa a cada una de las 24 referencias de la carta. Al pie, la receta y el envase de cada referencia: el envase sólo cuenta cuando se vende para llevar.
A11: 3. Hoja «Absorción de Aceite y Merma». Los euros de aceite que se lleva cada kilo de masa frita y lo que cuesta la masa que se fríe y no se vende. Aquí sólo está el aceite ABSORBIDO; la renovación del aceite de la cuba la calcula el libro 4.
A12: 4. Hoja «Chocolate a la Taza». Lo que cuesta una taza y qué dice la etiqueta de tu preparado. La carta usa la denominación que figura en esa etiqueta; si el cacao seco total baja del 35 % o lleva grasa vegetal, la hoja te pide consultar a tu servicio de consumo antes de imprimir la carta.
A13: 5. Hoja «Coste Hora». El coste de empresa de una hora de tu plantilla y los minutos de mano de obra que lleva cada ración. Nace con el de El Molinete; cuando rellenes el libro 8, su fila de CUADRE te dirá si este número se ha quedado viejo.
A14: 6. Hoja «Ración, Docena o Kilo». Los siete formatos de churro y porra, comparados por los euros que deja cada kilo de masa que fríes.
... A63: Versión 1.0 · octubre 2026 · aichef.pro/guia-churreria-chocolateria · info@aichef.pro

Sheet Parámetros
A1: Parámetros
A2: AI Chef Pro · aichef.pro — Cómo Montar una Churrería-Chocolatería
A3: Todo lo que el resto de hojas da por sabido vive aquí. Ninguna fórmula de este libro lleva un número de IVA, de margen o de umbral dentro.
A4: IVA por Canal (El Capítulo 03 de la Guía lo Explica) | K4: Lo que Copian Otros Libros (No Muevas Estas Celdas)
A5: IVA en sala, barra y terraza (servicio de hostelería) | B5: 0.1 | C5: tipo | D5: CHN-71c + FC-IVA-01 | E5: Servicio de hostelería: lo que se consume en barra, sala o terraza, bebidas incluidas, va al tipo reducido. | K5: Precio del aceite (base imponible), EUR/L | L5: =G34 -> 1.996 | M5: Lo copia: libro 2 (calculadora-capex-churreria.xlsx, hoja Parámetros, X17); libro 4 (aceite-de-fritura-coste-y-cambio.xlsx, hoja Parámetros, X2)
A6: IVA de churros y porras para llevar | B6: 0.1 | C6: tipo | D6: FC-IVA-02 | E6: Churros y porras para llevar: entrega de un alimento. | K6: Absorción de aceite, en % del peso frito | L6: =B18 -> 0.1 | M6: Lo copia: libro 4 (aceite-de-fritura-coste-y-cambio.xlsx, hoja Parámetros, X2)
A7: IVA del chocolate a la taza para llevar | B7: 0.1 | C7: tipo | D7: CUN-18 | E7: Consulta a tu asesor: con agua y un preparado azucarado podría ser el 21 %. El Molinete aplica el 10 % y lo deja en celda verde: es una zona gris y el tipo lo decide tu asesor, no este libro. | K7: Densidad del aceite, kg/L | L7: =B19 -> 0.92 | M7: Lo copia: libro 4 (aceite-de-fritura-coste-y-cambio.xlsx, hoja Parámetros, X2)
A8: IVA de las demás bebidas para llevar (café, leche con cacao, zumo, agua, batido) | B8: 0.1 | C8: tipo | D8: CUN-18 + CHN-71c | E8: Consulta a tu asesor: con agua y un preparado azucarado podría ser el 21 %. El mismo aviso vale para todas las bebidas para llevar, leche con cacao incluida. El refresco con azúcar añadido para llevar va al tipo general: tiene su propia fila. | K8: Precio del preparado para masa (base imponible), EUR/kg | L8: =G33 -> 1.45 | M8: Lo copia: libro 2 (calculadora-capex-churreria.xlsx, hoja Parámetros, X17)
A9: IVA del granizado y la horchata para llevar | B9: 0.21 | C9: tipo | D9: FC-IVA-04 + CUN-17 | E9: Aviso, no regla: El Molinete pone el 21 % por prudencia. Desde el 1-1-2021 las bebidas refrescantes con azúcares añadidos para llevar quedan fuera del tipo reducido y no hay una consulta que diga si tu granizado o tu horchata lo son. Es zona gris: consúltalo con tu asesor y, si te confirma el 10 %, cámbialo aquí. En sala siguen al 10 % (servicio de hostelería). | K9: Kilos fritos que salen de un kilo de masa, kg/kg | L9: =B17 -> 0.9 | M9: Lo copia: libro 1 (produccion-hora-punta-y-local.xlsx, hoja Parámetros, X1 bis)
A10: IVA general (envases, equipamiento, servicios) | B10: 0.21 | C10: tipo | D10: CHN-71c | E10: Tipo general: equipamiento, obra, envases y servicios. | K10: Precio del insumo «Chocolate a la taza en polvo (bolsa de 800 g, rinde 4,3 L)» (base imponible), EUR/unidad | L10: =G35 -> 7.1875 | M10: Lo copia: libro 2 (calculadora-capex-churreria.xlsx, hoja Parámetros, X17)
A11: IVA soportado de los alimentos que compras | B11: 0.1 | C11: tipo | D11: supuesto declarado | E11: IVA soportado del mix, el aceite y el preparado: compruébalo en cada factura, el aceite ha tenido tipos rebajados temporales. | K11: Precio del insumo «Cobertura de chocolate negro (1 kg)» (base imponible), EUR/unidad | L11: =G36 -> 6.5 | M11: Lo copia: libro 2 (calculadora-capex-churreria.xlsx, hoja Parámetros, X17)
K12: Precio del insumo «Cucurucho de cartón para churros (caja de 100)» (base imponible), EUR/unidad | L12: =G37 -> 0.15 | M12: Lo copia: libro 2 (calculadora-capex-churreria.xlsx, hoja Parámetros, X17)
A13: Masa, Fritura y Aceite (Supuestos Declarados de El Molinete) | K13: Precio del insumo «Vaso de papel plastificado con tapa» (base imponible), EUR/unidad | L13: =G51 -> 0.08 | M13: Lo copia: libro 2 (calculadora-capex-churreria.xlsx, hoja Parámetros, X17)
A14: Gramos de masa por churro (lo que se vende) | B14: 20 | C14: g/pieza | D14: supuesto declarado | E14: Supuesto de El Molinete: pesa diez churros de tu masa y divide. | K14: Precio del insumo «Papel antigrasa para sueltos» (base imponible), EUR/unidad | L14: =G52 -> 0.02 | M14: Lo copia: libro 2 (calculadora-capex-churreria.xlsx, hoja Parámetros, X17)
A15: Gramos de masa por porra (lo que se vende) | B15: 60 | C15: g/pieza | D15: supuesto declarado | E15: Supuesto de El Molinete: pesa diez porras de tu masa y divide. | K15: Precio del insumo «Caja de cartón para el kilo» (base imponible), EUR/unidad | L15: =G53 -> 0.25 | M15: Lo copia: libro 2 (calculadora-capex-churreria.xlsx, hoja Parámetros, X17)
A16: Merma: masa que se fríe y no se vende | B16: 0.05 | C16: sobre lo frito | D16: supuesto declarado | E16: Masa que se fríe y no se vende: restos, piezas rotas y el sobrante del cierre. Se produce y se fríe igual. | K16: Precio del insumo «Café en grano» (base imponible), EUR/unidad | L16: =G42 -> 18 | M16: Lo copia: libro 2 (calculadora-capex-churreria.xlsx, hoja Parámetros, X17)
A17: Kilos fritos que salen de un kilo de masa | B17: 0.9 | C17: kg/kg | D17: supuesto declarado | E17: La masa pierde agua al freírse y gana aceite: lo que pesa la pieza frita frente a la masa cruda. Sin fuente pública. | K17: Precio del insumo «Leche» (base imponible), EUR/unidad | L17: =G41 -> 0.85 | M17: Lo copia: libro 2 (calculadora-capex-churreria.xlsx, hoja Parámetros, X17)
A18: Absorción de aceite, en % del peso frito | B18: 0.1 | C18: del peso frito | D18: supuesto declarado | E18: Supuesto, sin fuente pública; pon el tuyo. Aceite que se queda en la pieza, en % de lo que pesa ya frita: pesa una tanda de masa antes y después de freír. | K18: Precio del insumo «Azúcar para espolvorear y sobres» (base imponible), EUR/unidad | L18: =G40 -> 1 | M18: Lo copia: libro 2 (calculadora-capex-churreria.xlsx, hoja Parámetros, X17)
A19: Densidad del aceite | B19: 0.92 | C19: kg/L | D19: supuesto declarado | E19: Supuesto, sin fuente pública; pon el tuyo (lo trae la ficha técnica del aceite). Hace falta porque la absorción va en peso y el aceite se compra por litros. | K19: Precio del insumo «Cacao soluble» (base imponible), EUR/unidad | L19: =G44 -> 6 | M19: Lo copia: libro 2 (calculadora-capex-churreria.xlsx, hoja Parámetros, X17)
A20: Azúcar para espolvorear por cada 100 g de masa vendida | B20: 5 | C20: g/100 g | D20: supuesto declarado | E20: Azúcar para espolvorear, por cada 100 g de masa vendida. | K20: Precio del insumo «Infusión (sobre)» (base imponible), EUR/unidad | L20: =G43 -> 0.06 | M20: Lo copia: libro 2 (calculadora-capex-churreria.xlsx, hoja Parámetros, X17)
A21: Kilos de preparado comercial por kilo de masa | B21: 0.34782609 | C21: kg/kg | D21: CUS-21 | E21: El vendedor declara que cada saco de 4 kg prepara unos 11,5 kg de masa; el resto hasta el kilo es agua, sin coste. | K21: Precio del insumo «Agua (botella de 50 cl)» (base imponible), EUR/unidad | L21: =G46 -> 0.22 | M21: Lo copia: libro 2 (calculadora-capex-churreria.xlsx, hoja Parámetros, X17)
A22: Masa con la que costeas la carta | B22: Preparado comercial | C22: lista | D22: decisión 5 | E22: El Molinete compra el preparado comercial. Cambia a «Mix propio» para ver el escandallo con tu mezcla (hoja «Escandallo por kg de Masa»).
A24: El Vaso para Llevar, Cobrado Aparte
A25: Vaso para llevar (plástico o papel plastificado), cobrado aparte: importe con IVA | B25: 0.1 | C25: EUR/vaso | D25: supuesto declarado | E25: El importe es un supuesto: la ley obliga a cobrarlo aparte, no fija cuánto. Su IVA, el de la bebida, en celda verde. Su IVA es el de «las demás bebidas para llevar» (fila 8).
A27: Umbrales de la Decisión de Surtido (Criterio de la Casa)
A28: Margen mínimo por unidad para no revisar el precio | B28: 0.5 | C28: EUR/unidad | D28: supuesto declarado | E28: Criterio de la casa, no del sector: es el margen en EUROS de la unidad de venta. Un margen alto en porcentaje sobre un churro de 0,30 EUR no paga la renta.
A29: Rotación mínima para no vigilar una referencia | B29: 2 | C29: % del mix | D29: supuesto declarado | E29: Por debajo de este peso en el mix de invierno Y en el de verano, la referencia ocupa carta, stock y cabeza sin vender.
A31: Insumos: La Única Tabla Donde se Tocan los Precios
A32: Insumo | B32: Precio del formato (EUR) | C32: ¿El precio lleva IVA? | D32: Tipo de IVA | E32: Cantidad del formato | F32: Unidad | G32: Precio SIN IVA por unidad (EUR) | H32: Fuente | I32: Base de IVA declarada y nota
A33: Preparado para masa de churro (caja de 6 sacos de 4 kg) | B33: 34.8 | C33: No | D33: ='Parámetros'!$B$11 -> 0.1 | E33: 24 | F33: kg | G33: =IFERROR(IF(C33="Sí",B33/(1+D33),B33)/E33,"") -> 1.45 | H33: CUS-21 | I33: Base de la fuente: sin IVA, declarada en la ficha («Impuestos excluidos»). Precio de una caja de 6 sacos de 4 kg, impuestos excluidos (tienda del proveedor, leída el 03-10-2026). Cada saco prepara unos 11,5 kg de masa.
A34: Aceite especial de fritura (garrafa de 25 L) | B34: 49.9 | C34: No | D34: ='Parámetros'!$B$11 -> 0.1 | E34: 25 | F34: L | G34: =IFERROR(IF(C34="Sí",B34/(1+D34),B34)/E34,"") -> 1.996 | H34: CUS-23 | I34: Base de la fuente: sin IVA, declarada en la ficha («Impuestos excluidos»). El techo de las dos garrafas de la ficha. Es la CELDA ÚNICA del precio del aceite de todo el paquete: vive en el libro 3 y la copian el 4 y el 2.
A35: Chocolate a la taza en polvo (bolsa de 800 g, rinde 4,3 L) | B35: 5.75 | C35: No | D35: ='Parámetros'!$B$11 -> 0.1 | E35: 0.8 | F35: kg | G35: =IFERROR(IF(C35="Sí",B35/(1+D35),B35)/E35,"") -> 7.1875 | H35: CUS-24 | I35: Base de la fuente: sin IVA, declarada en la ficha («Impuestos excluidos»). El techo por kilo de la ficha. La ficha no dice a qué denominación del RD 1055/2003 corresponde: la carta usa la de la etiqueta.
A36: Cobertura de chocolate negro (1 kg) | B36: 6.5 | C36: No | D36: ='Parámetros'!$B$11 -> 0.1 | E36: 1 | F36: kg | G36: =IFERROR(IF(C36="Sí",B36/(1+D36),B36)/E36,"") -> 6.5 | H36: CUS-24 | I36: Base de la fuente: sin IVA, declarada en la ficha («Impuestos excluidos»). Para rellenar y bañar churros.
A37: Cucurucho de cartón para churros (caja de 100) | B37: 15 | C37: No | D37: ='Parámetros'!$B$10 -> 0.21 | E37: 100 | F37: ud | G37: =IFERROR(IF(C37="Sí",B37/(1+D37),B37)/E37,"") -> 0.15 | H37: CUS-25 | I37: Base de la fuente: sin IVA, inferida (celda «¿lleva IVA?» en verde, «no» por defecto). Su composición está por confirmar: no se presenta como conforme a la ley de plásticos.
A38: Harina especial para churros (mix propio) | B38: 0.8 | C38: No | D38: ='Parámetros'!$B$11 -> 0.1 | E38: 1 | F38: kg | G38: =IFERROR(IF(C38="Sí",B38/(1+D38),B38)/E38,"") -> 0.8 | H38: supuesto declarado | I38: Base de la fuente: supuesto, sin IVA. Sólo para la decisión 5: el proveedor verificado no publica precio.
A39: Sal | B39: 0.4 | C39: No | D39: ='Parámetros'!$B$11 -> 0.1 | E39: 1 | F39: kg | G39: =IFERROR(IF(C39="Sí",B39/(1+D39),B39)/E39,"") -> 0.4 | H39: supuesto declarado | I39: Base de la fuente: supuesto, sin IVA. Mix propio.
A40: Azúcar para espolvorear y sobres | B40: 1 | C40: No | D40: ='Parámetros'!$B$11 -> 0.1 | E40: 1 | F40: kg | G40: =IFERROR(IF(C40="Sí",B40/(1+D40),B40)/E40,"") -> 1 | H40: supuesto declarado | I40: Base de la fuente: supuesto, sin IVA. El azúcar glas que publica CUS-25 es otro producto.
A41: Leche | B41: 0.85 | C41: No | D41: ='Parámetros'!$B$11 -> 0.1 | E41: 1 | F41: L | G41: =IFERROR(IF(C41="Sí",B41/(1+D41),B41)/E41,"") -> 0.85 | H41: supuesto declarado | I41: Base de la fuente: supuesto, sin IVA.
A42: Café en grano | B42: 18 | C42: No | D42: ='Parámetros'!$B$11 -> 0.1 | E42: 1 | F42: kg | G42: =IFERROR(IF(C42="Sí",B42/(1+D42),B42)/E42,"") -> 18 | H42: supuesto declarado | I42: Base de la fuente: supuesto, sin IVA. Sin fuente de precio de café en el research.
A43: Infusión (sobre) | B43: 0.06 | C43: No | D43: ='Parámetros'!$B$11 -> 0.1 | E43: 1 | F43: ud | G43: =IFERROR(IF(C43="Sí",B43/(1+D43),B43)/E43,"") -> 0.06 | H43: supuesto declarado | I43: Base de la fuente: supuesto, sin IVA.
...

Sheet Escandallo por kg de Masa
A1: Escandallo por kg de Masa
A2: AI Chef Pro · aichef.pro — Cómo Montar una Churrería-Chocolatería
A3: Datos de ejemplo para que las fórmulas calculen: las cantidades no son una receta. Todos los precios, SIN IVA, de la tabla de insumos de «Parámetros».
A5: 1. Un Kilo de Masa con el Preparado Comercial
A6: Concepto | B6: Cantidad por kg de masa | C6: Unidad | D6: Precio SIN IVA por unidad (EUR) | E6: Importe (EUR) | F6: Fuente
A7: Preparado para masa de churro (caja de 6 sacos de 4 kg) | B7: ='Parámetros'!$B$21 -> 0.34782609 | C7: kg | D7: ='Parámetros'!$G$33 -> 1.45 | E7: =IFERROR(B7*D7,"") -> 0.50434783 | F7: CUS-21
A8: Agua (sin coste) | B8: =1-B7 -> 0.65217391 | C8: L | D8: sin coste | F8: calculado
A9: COSTE DE 1 KG DE MASA CON EL PREPARADO (EUR) | E9: =SUM(E7:E8) -> 0.50434783
A11: 2. Un Kilo de Masa con Mix Propio (Decisión 5)
A12: Concepto | B12: Cantidad por kg de masa | C12: Unidad | D12: Precio SIN IVA por unidad (EUR) | E12: Importe (EUR) | F12: Fuente
A13: Harina especial para churros (mix propio) | B13: 0.45 | C13: kg | D13: ='Parámetros'!$G$38 -> 0.8 | E13: =IFERROR(B13*D13,"") -> 0.36 | F13: supuesto declarado | G13: Proporciones de EJEMPLO para que la comparación calcule, no una receta. El ahorro del mix propio se paga con pesar, tamizar y con la regularidad de la masa.
A14: Sal | B14: 0.008 | C14: kg | D14: ='Parámetros'!$G$39 -> 0.4 | E14: =IFERROR(B14*D14,"") -> 0.0032 | F14: supuesto declarado
A15: Agua (sin coste) | B15: =1-SUM(B13:B14) -> 0.542 | C15: L | D15: sin coste | F15: calculado
A16: COSTE DE 1 KG DE MASA CON MIX PROPIO (EUR) | E16: =SUM(E13:E15) -> 0.3632
A18: Ahorro del mix propio por kg de masa (EUR) | B18: =E9-E16 -> 0.14114783
A19: COSTE DEL KG DE MASA CON EL QUE COSTEAS (EUR) | B19: =IF('Parámetros'!$B$22="Mix propio",E16,E9) -> 0.50434783
A20: Masa elegida en «Parámetros» | B20: ='Parámetros'!$B$22 -> Preparado comercial
A22: 3. La Pieza: Churro y Porra
A23: Concepto | B23: Churro | C23: Porra
A24: Gramos de masa por pieza (lo que se vende) | B24: ='Parámetros'!$B$14 -> 20 | C24: ='Parámetros'!$B$15 -> 60
A25: Gramos de masa que hay que freír por pieza (con la merma) | B25: =IFERROR(B24/(1-'Parámetros'!$B$16),"") -> 21.052632 | C25: =IFERROR(C24/(1-'Parámetros'!$B$16),"") -> 63.157895
A26: Piezas por kilo de masa vendida | B26: =IFERROR(1000/B24,"") -> 50 | C26: =IFERROR(1000/C24,"") -> 16.666667
A27: Coste de la masa por pieza (EUR) | B27: =IFERROR(B25/1000*$B$19,"") -> 0.010617849 | C27: =IFERROR(C25/1000*$B$19,"") -> 0.031853547
A28: Aceite absorbido por pieza (EUR) | B28: =IFERROR(B25/1000*'Absorción de Aceite y Merma'!$B$11,"") -> 0.0041107551 | C28: =IFERROR(C25/1000*'Absorción de Aceite y Merma'!$B$11,"") -> 0.012332265
A29: Azúcar de espolvorear por pieza (EUR) | B29: =IFERROR(B24/1000*'Parámetros'!$B$20/100*'Parámetros'!$G$40,"") -> 0.001 | C29: =IFERROR(C24/1000*'Parámetros'!$B$20/100*'Parámetros'!$G$40,"") -> 0.003
A30: COSTE DE MATERIA DE LA PIEZA (EUR) | B30: =SUM(B27:B29) -> 0.015728604 | C30: =SUM(C27:C29) -> 0.047185812
A31: Coste de materia de una docena (EUR) | B31: =IFERROR(B30*12,"") -> 0.18874325 | C31: =IFERROR(C30*12,"") -> 0.56622975
A33: 4. De la Masa a Cada Referencia de la Carta
A34: Id y referencia | B34: Familia | C34: Piezas de la unidad | D34: Tipo de pieza | E34: Kilos fritos (sólo si se vende al peso) | F34: Masa vendida (kg) | G34: Masa que se fríe, con merma (kg) | H34: Coste de la masa (EUR) | I34: Azúcar (EUR) | J34: Receta, sin envase (EUR) | K34: Envase para llevar (EUR) | L34: Aceite absorbido (EUR) | M34: MATERIA EN SALA, aceite incluido (EUR) | N34: MATERIA PARA LLEVAR, aceite y envase incluidos (EUR)
A35: CH1 · Ración de churros (6 uds) | B35: Churros y porras | C35: 6 | D35: churro | E35: 0 | F35: =IF(E35>0,IFERROR(E35/'Parámetros'!$B$17,""),IFERROR(C35*IF(D35="porra",'Parámetros'!$B$15,IF(D35="churro",'Parámetros'!$B$14,0))/1000,"")) -> 0.12 | G35: =IFERROR(F35/(1-'Parámetros'!$B$16),"") -> 0.12631579 | H35: =IFERROR(G35*$B$19,"") -> 0.063707094 | I35: =IFERROR(F35*'Parámetros'!$B$20/100*'Parámetros'!$G$40,"") -> 0.006 | J35: =SUMIF($A$63:$A$100,"CH1",$I$63:$I$100) -> 0 | K35: =SUMIF($A$63:$A$100,"CH1",$J$63:$J$100) -> 0.15 | L35: =IFERROR(G35*'Absorción de Aceite y Merma'!$B$11,"") -> 0.024664531 | M35: =IFERROR(H35+I35+J35+L35,"") -> 0.094371625 | N35: =IFERROR(M35+K35,"") -> 0.24437162
A36: CH2 · Media ración de churros (3 uds) | B36: Churros y porras | C36: 3 | D36: churro | E36: 0 | F36: =IF(E36>0,IFERROR(E36/'Parámetros'!$B$17,""),IFERROR(C36*IF(D36="porra",'Parámetros'!$B$15,IF(D36="churro",'Parámetros'!$B$14,0))/1000,"")) -> 0.06 | G36: =IFERROR(F36/(1-'Parámetros'!$B$16),"") -> 0.063157895 | H36: =IFERROR(G36*$B$19,"") -> 0.031853547 | I36: =IFERROR(F36*'Parámetros'!$B$20/100*'Parámetros'!$G$40,"") -> 0.003 | J36: =SUMIF($A$63:$A$100,"CH2",$I$63:$I$100) -> 0 | K36: =SUMIF($A$63:$A$100,"CH2",$J$63:$J$100) -> 0 | L36: =IFERROR(G36*'Absorción de Aceite y Merma'!$B$11,"") -> 0.012332265 | M36: =IFERROR(H36+I36+J36+L36,"") -> 0.047185812 | N36: =IFERROR(M36+K36,"") -> 0.047185812
A37: CH3 · Ración de porras (3 uds) | B37: Churros y porras | C37: 3 | D37: porra | E37: 0 | F37: =IF(E37>0,IFERROR(E37/'Parámetros'!$B$17,""),IFERROR(C37*IF(D37="porra",'Parámetros'!$B$15,IF(D37="churro",'Parámetros'!$B$14,0))/1000,"")) -> 0.18 | G37: =IFERROR(F37/(1-'Parámetros'!$B$16),"") -> 0.18947368 | H37: =IFERROR(G37*$B$19,"") -> 0.095560641 | I37: =IFERROR(F37*'Parámetros'!$B$20/100*'Parámetros'!$G$40,"") -> 0.009 | J37: =SUMIF($A$63:$A$100,"CH3",$I$63:$I$100) -> 0 | K37: =SUMIF($A$63:$A$100,"CH3",$J$63:$J$100) -> 0.15 | L37: =IFERROR(G37*'Absorción de Aceite y Merma'!$B$11,"") -> 0.036996796 | M37: =IFERROR(H37+I37+J37+L37,"") -> 0.14155744 | N37: =IFERROR(M37+K37,"") -> 0.29155744
A38: CH4 · Churro suelto | B38: Churros y porras | C38: 1 | D38: churro | E38: 0 | F38: =IF(E38>0,IFERROR(E38/'Parámetros'!$B$17,""),IFERROR(C38*IF(D38="porra",'Parámetros'!$B$15,IF(D38="churro",'Parámetros'!$B$14,0))/1000,"")) -> 0.02 | G38: =IFERROR(F38/(1-'Parámetros'!$B$16),"") -> 0.021052632 | H38: =IFERROR(G38*$B$19,"") -> 0.010617849 | I38: =IFERROR(F38*'Parámetros'!$B$20/100*'Parámetros'!$G$40,"") -> 0.001 | J38: =SUMIF($A$63:$A$100,"CH4",$I$63:$I$100) -> 0 | K38: =SUMIF($A$63:$A$100,"CH4",$J$63:$J$100) -> 0.02 | L38: =IFERROR(G38*'Absorción de Aceite y Merma'!$B$11,"") -> 0.0041107551 | M38: =IFERROR(H38+I38+J38+L38,"") -> 0.015728604 | N38: =IFERROR(M38+K38,"") -> 0.035728604
A39: CH5 · Porra suelta | B39: Churros y porras | C39: 1 | D39: porra | E39: 0 | F39: =IF(E39>0,IFERROR(E39/'Parámetros'!$B$17,""),IFERROR(C39*IF(D39="porra",'Parámetros'!$B$15,IF(D39="churro",'Parámetros'!$B$14,0))/1000,"")) -> 0.06 | G39: =IFERROR(F39/(1-'Parámetros'!$B$16),"") -> 0.063157895 | H39: =IFERROR(G39*$B$19,"") -> 0.031853547 | I39: =IFERROR(F39*'Parámetros'!$B$20/100*'Parámetros'!$G$40,"") -> 0.003 | J39: =SUMIF($A$63:$A$100,"CH5",$I$63:$I$100) -> 0 | K39: =SUMIF($A$63:$A$100,"CH5",$J$63:$J$100) -> 0.02 | L39: =IFERROR(G39*'Absorción de Aceite y Merma'!$B$11,"") -> 0.012332265 | M39: =IFERROR(H39+I39+J39+L39,"") -> 0.047185812 | N39: =IFERROR(M39+K39,"") -> 0.067185812
A40: CH6 · Docena de churros para llevar | B40: Churros y porras | C40: 12 | D40: churro | E40: 0 | F40: =IF(E40>0,IFERROR(E40/'Parámetros'!$B$17,""),IFERROR(C40*IF(D40="porra",'Parámetros'!$B$15,IF(D40="churro",'Parámetros'!$B$14,0))/1000,"")) -> 0.24 | G40: =IFERROR(F40/(1-'Parámetros'!$B$16),"") -> 0.25263158 | H40: =IFERROR(G40*$B$19,"") -> 0.12741419 | I40: =IFERROR(F40*'Parámetros'!$B$20/100*'Parámetros'!$G$40,"") -> 0.012 | J40: =SUMIF($A$63:$A$100,"CH6",$I$63:$I$100) -> 0 | K40: =SUMIF($A$63:$A$100,"CH6",$J$63:$J$100) -> 0.15 | L40: =IFERROR(G40*'Absorción de Aceite y Merma'!$B$11,"") -> 0.049329062 | M40: =IFERROR(H40+I40+J40+L40,"") -> 0.18874325 | N40: =IFERROR(M40+K40,"") -> 0.33874325
A41: CH7 · Kilo de churros para llevar | B41: Churros y porras | C41: 0 | D41: churro | E41: 1 | F41: =IF(E41>0,IFERROR(E41/'Parámetros'!$B$17,""),IFERROR(C41*IF(D41="porra",'Parámetros'!$B$15,IF(D41="churro",'Parámetros'!$B$14,0))/1000,"")) -> 1.1111111 | G41: =IFERROR(F41/(1-'Parámetros'!$B$16),"") -> 1.1695906 | H41: =IFERROR(G41*$B$19,"") -> 0.5898805 | I41: =IFERROR(F41*'Parámetros'!$B$20/100*'Parámetros'!$G$40,"") -> 0.055555556 | J41: =SUMIF($A$63:$A$100,"CH7",$I$63:$I$100) -> 0 | K41: =SUMIF($A$63:$A$100,"CH7",$J$63:$J$100) -> 0.25 | L41: =IFERROR(G41*'Absorción de Aceite y Merma'!$B$11,"") -> 0.22837529 | M41: =IFERROR(H41+I41+J41+L41,"") -> 0.87381134 | N41: =IFERROR(M41+K41,"") -> 1.1238113
A42: RE1 · Churro relleno de chocolate (ud) | B42: Rellenos y especiales | C42: 1 | D42: porra | E42: 0 | F42: =IF(E42>0,IFERROR(E42/'Parámetros'!$B$17,""),IFERROR(C42*IF(D42="porra",'Parámetros'!$B$15,IF(D42="churro",'Parámetros'!$B$14,0))/1000,"")) -> 0.06 | G42: =IFERROR(F42/(1-'Parámetros'!$B$16),"") -> 0.063157895 | H42: =IFERROR(G42*$B$19,"") -> 0.031853547 | I42: =IFERROR(F42*'Parámetros'!$B$20/100*'Parámetros'!$G$40,"") -> 0.003 | J42: =SUMIF($A$63:$A$100,"RE1",$I$63:$I$100) -> 0.13 | K42: =SUMIF($A$63:$A$100,"RE1",$J$63:$J$100) -> 0 | L42: =IFERROR(G42*'Absorción de Aceite y Merma'!$B$11,"") -> 0.012332265 | M42: =IFERROR(H42+I42+J42+L42,"") -> 0.17718581 | N42: =IFERROR(M42+K42,"") -> 0.17718581
A43: RE2 · Ración de churros con cobertura de chocolate (6 uds) | B43: Rellenos y especiales | C43: 6 | D43: churro | E43: 0 | F43: =IF(E43>0,IFERROR(E43/'Parámetros'!$B$17,""),IFERROR(C43*IF(D43="porra",'Parámetros'!$B$15,IF(D43="churro",'Parámetros'!$B$14,0))/1000,"")) -> 0.12 | G43: =IFERROR(F43/(1-'Parámetros'!$B$16),"") -> 0.12631579 | H43: =IFERROR(G43*$B$19,"") -> 0.063707094 | I43: =IFERROR(F43*'Parámetros'!$B$20/100*'Parámetros'!$G$40,"") -> 0.006 | J43: =SUMIF($A$63:$A$100,"RE2",$I$63:$I$100) -> 0.195 | K43: =SUMIF($A$63:$A$100,"RE2",$J$63:$J$100) -> 0 | L43: =IFERROR(G43*'Absorción de Aceite y Merma'!$B$11,"") -> 0.024664531 | M43: =IFERROR(H43+I43+J43+L43,"") -> 0.28937162 | N43: =IFERROR(M43+K43,"") -> 0.28937162
A44: CT1 · Chocolate a la taza en barra | B44: Chocolate a la taza | C44: 0 | D44: sin masa | E44: 0 | F44: =IF(E44>0,IFERROR(E44/'Parámetros'!$B$17,""),IFERROR(C44*IF(D44="porra",'Parámetros'!$B$15,IF(D44="churro",'Parámetros'!$B$14,0))/1000,"")) -> 0 | G44: =IFERROR(F44/(1-'Parámetros'!$B$16),"") -> 0 | H44: =IFERROR(G44*$B$19,"") -> 0 | I44: =IFERROR(F44*'Parámetros'!$B$20/100*'Parámetros'!$G$40,"") -> 0 | J44: =SUMIF($A$63:$A$100,"CT1",$I$63:$I$100) -> 0.43744186 | K44: =SUMIF($A$63:$A$100,"CT1",$J$63:$J$100) -> 0 | L44: =IFERROR(G44*'Absorción de Aceite y Merma'!$B$11,"") -> 0 | M44: =IFERROR(H44+I44+J44+L44,"") -> 0.43744186 | N44: =IFERROR(M44+K44,"") -> 0.43744186
A45: CT2 · Chocolate a la taza en terraza | B45: Chocolate a la taza | C45: 0 | D45: sin masa | E45: 0 | F45: =IF(E45>0,IFERROR(E45/'Parámetros'!$B$17,""),IFERROR(C45*IF(D45="porra",'Parámetros'!$B$15,IF(D45="churro",'Parámetros'!$B$14,0))/1000,"")) -> 0 | G45: =IFERROR(F45/(1-'Parámetros'!$B$16),"") -> 0 | H45: =IFERROR(G45*$B$19,"") -> 0 | I45: =IFERROR(F45*'Parámetros'!$B$20/100*'Parámetros'!$G$40,"") -> 0 | J45: =SUMIF($A$63:$A$100,"CT2",$I$63:$I$100) -> 0.43744186 | K45: =SUMIF($A$63:$A$100,"CT2",$J$63:$J$100) -> 0 | L45: =IFERROR(G45*'Absorción de Aceite y Merma'!$B$11,"") -> 0 | M45: =IFERROR(H45+I45+J45+L45,"") -> 0.43744186 | N45: =IFERROR(M45+K45,"") -> 0.43744186
...

Sheet Absorción de Aceite y Merma
A1: Absorción de Aceite y Merma
A2: AI Chef Pro · aichef.pro — Cómo Montar una Churrería-Chocolatería
A3: El aceite que se lleva la masa frita, en euros. La renovación del aceite de la cuba (el descarte) la calcula el libro 4.
A4: Del Aceite al Euro por Kilo de Masa | K4: Lo que Copian Otros Libros (No Muevas Estas Celdas)
A5: Kilos fritos que salen de un kilo de masa | B5: ='Parámetros'!$B$17 -> 0.9 | C5: kg/kg | K5: Aceite absorbido por ración media (mix de invierno), EUR | L5: =B20 -> 0.019119579 | M5: Lo copia: libro 4 (aceite-de-fritura-coste-y-cambio.xlsx, hoja Parámetros, X2 bis)
A6: Absorción de aceite, en % del peso frito | B6: ='Parámetros'!$B$18 -> 0.1
A7: Kilos de aceite que se lleva un kilo de masa | B7: =IFERROR(B5*B6,"") -> 0.09 | C7: kg
A8: Densidad del aceite | B8: ='Parámetros'!$B$19 -> 0.92 | C8: kg/L
A9: Litros de aceite que se lleva un kilo de masa | B9: =IFERROR(B7/B8,"") -> 0.097826087 | C9: L
A10: Precio del aceite (base imponible) | B10: ='Parámetros'!$L$5 -> 1.996 | C10: EUR/L
A11: EUROS DE ACEITE ABSORBIDO POR KILO DE MASA | B11: =IFERROR(B9*B10,"") -> 0.19526087 | C11: EUR/kg
A13: La Merma
A14: Merma: masa que se fríe y no se vende | B14: ='Parámetros'!$B$16 -> 0.05
A15: Kilos de masa que hay que freír por kilo vendido | B15: =IFERROR(1/(1-B14),"") -> 1.0526316 | C15: kg/kg
A16: Coste de la merma por kilo vendido (masa y aceite) | B16: =IFERROR((B15-1)*('Escandallo por kg de Masa'!$B$19+B11),"") -> 0.03682151 | C16: EUR/kg
A18: Por Ración Media
A19: Kilos de masa que se fríen por ración media (mix de invierno) | B19: ='Mix y Ticket Canal y Temporada'!$L$5 -> 0.097918129 | C19: kg/ración | D19: La ración media es la unidad de venta media de la carta, ponderada por el mix de invierno (hoja «Mix y Ticket Canal y Temporada»).
A20: ACEITE ABSORBIDO POR RACIÓN MEDIA | B20: =IFERROR(B19*B11,"") -> 0.019119579 | C20: EUR/ración | D20: El libro 4 recibe esta cifra para la fila de contraste «aceite absorbido (3) más renovación (4) = aceite total por ración». El 6 suma las dos, cada una con su fuente.
A21: Litros de aceite absorbido cada 100 raciones | B21: =IFERROR(B19*B9*100,"") -> 0.95789474 | C21: L
A22: Peso del aceite absorbido en la materia de la ración media | B22: =IFERROR(B20/'Mix y Ticket Canal y Temporada'!$D$7,"") -> 0.067597868
A25: Si la Absorción Fuera Otra (Pon las Tuyas)
A26: Absorción de aceite, en % del peso frito | B26: EUR de aceite por kilo de masa | C26: EUR de aceite por ración media | D26: Diferencia por ración frente a tu absorción (EUR) | E26: Diferencia cada 1.000 raciones (EUR)
A27: 0.06 | B27: =IFERROR($B$5*A27/$B$8*$B$10,"") -> 0.11715652 | C27: =IFERROR(B27*$B$19,"") -> 0.011471747 | D27: =IFERROR(C27-$B$20,"") -> -0.0076478316 | E27: =IFERROR(D27*1000,"") -> -7.6478316
A28: 0.08 | B28: =IFERROR($B$5*A28/$B$8*$B$10,"") -> 0.1562087 | C28: =IFERROR(B28*$B$19,"") -> 0.015295663 | D28: =IFERROR(C28-$B$20,"") -> -0.0038239158 | E28: =IFERROR(D28*1000,"") -> -3.8239158
A29: 0.1 | B29: =IFERROR($B$5*A29/$B$8*$B$10,"") -> 0.19526087 | C29: =IFERROR(B29*$B$19,"") -> 0.019119579 | D29: =IFERROR(C29-$B$20,"") -> 0 | E29: =IFERROR(D29*1000,"") -> 0
A30: 0.12 | B30: =IFERROR($B$5*A30/$B$8*$B$10,"") -> 0.23431304 | C30: =IFERROR(B30*$B$19,"") -> 0.022943495 | D30: =IFERROR(C30-$B$20,"") -> 0.0038239158 | E30: =IFERROR(D30*1000,"") -> 3.8239158
A31: 0.14 | B31: =IFERROR($B$5*A31/$B$8*$B$10,"") -> 0.27336522 | C31: =IFERROR(B31*$B$19,"") -> 0.026767411 | D31: =IFERROR(C31-$B$20,"") -> 0.0076478316 | E31: =IFERROR(D31*1000,"") -> 7.6478316
A33: La absorción es un supuesto declarado, sin fuente pública: mídela pesando una tanda de masa antes y después de freír. Cambiar de aceite o de freidora la mueve.
A35: Versión 1.0 · octubre 2026 · aichef.pro/guia-churreria-chocolateria · info@aichef.pro

Sheet Chocolate a la Taza
A1: Chocolate a la Taza
A2: AI Chef Pro · aichef.pro — Cómo Montar una Churrería-Chocolatería
A3: Lo que cuesta una taza y qué dice la etiqueta de tu preparado. La carta usa la denominación que figura en esa etiqueta.
A5: 1. Lo que Cuesta el Chocolate
A6: Precio del preparado SIN IVA (EUR/kg) | B6: ='Parámetros'!$G$35 -> 7.1875
A7: Kilos de preparado del formato que compras | B7: ='Parámetros'!$E$35 -> 0.8
A8: Litros de chocolate que rinde ese formato (lo dice el envase) | B8: 4.3
A9: Kilos de preparado por litro de chocolate | B9: =IFERROR(B7/B8,"") -> 0.18604651
A10: Coste del preparado por litro de chocolate (EUR) | B10: =IFERROR(B9*B6,"") -> 1.3372093
A11: Leche, litro por litro de chocolate (EUR/L) | B11: ='Parámetros'!$G$41 -> 0.85
A12: COSTE DEL CHOCOLATE POR LITRO (EUR) | B12: =B10+B11 -> 2.1872093
A13: Mililitros de una taza | B13: 200 | C13: supuesto declarado
A14: Mililitros de media taza | B14: 120 | C14: supuesto declarado
A15: COSTE DE UNA TAZA (EUR) | B15: =IFERROR(B13/1000*B12,"") -> 0.43744186
A16: Coste de media taza (EUR) | B16: =IFERROR(B14/1000*B12,"") -> 0.26246512
A19: 2. Qué Dice la Etiqueta de Tu Preparado
A20: Denominación que figura en la etiqueta del preparado (cópiala tal cual) | B20: Chocolate a la taza | C20: Supuesto del ejemplo: un preparado comercial cuya etiqueta dice «chocolate a la taza». Pon la de TU preparado.
A21: Cacao seco total que declara la etiqueta | B21: 0.35 | C21: Lo que dice la etiqueta del preparado del ejemplo. Copia el de la etiqueta de TU preparado.
A22: ¿La etiqueta declara grasa vegetal distinta de la manteca de cacao? | B22: No
A23: Cacao seco total mínimo del producto «chocolate a la taza» | B23: 0.35
A24: AVISO ANTES DE IMPRIMIR LA CARTA | B24: =IF(NOT(ISNUMBER(B21)),"",IF(OR(B21<B23,B22="Sí"),"Consulta a tu servicio de consumo antes de imprimir la carta","Sin aviso: la carta usa la denominación de la etiqueta")) -> Sin aviso: la carta usa la denominación de la etiqueta
A25: Nombre con el que la taza va en tu carta | B25: =B20 -> Chocolate a la taza | C25: Es una interpretación, no una regla del Real Decreto: la carta repite la denominación de la etiqueta y, si hay aviso, lo consultas antes de imprimir. La decisión 6 es qué preparado compras y qué dice su etiqueta.
A27: 3. El IVA de la Taza para Llevar
A28: IVA que aplicas a la taza para llevar (de «Parámetros») | B28: ='Parámetros'!$B$7 -> 0.1
A29: Zona gris: El Molinete aplica el 10 % en celda verde. Consulta a tu asesor: con agua y un preparado azucarado podría ser el 21 %. Se cambia en «Parámetros», en una sola celda.
A31: 4. Las Tazas de la Carta
A32: Referencia | B32: PVP con IVA (EUR) | C32: Ingreso medio SIN IVA (EUR) | D32: Materia media (EUR) | E32: Margen por unidad (EUR) | F32: Margen sobre materia | G32: Nota
A33: CT1 · Chocolate a la taza en barra | B33: ='Mix y Ticket Canal y Temporada'!$D$26 -> 2 | C33: ='Mix y Ticket Canal y Temporada'!$O$26 -> 1.8181818 | D33: ='Mix y Ticket Canal y Temporada'!$R$26 -> 0.43744186 | E33: =IFERROR(C33-D33,"") -> 1.38074 | F33: =IFERROR(1-D33/C33,"") -> 0.75940698 | G33: Precio de La Churrería de Granada (2026). La denominación de la carta es la de la etiqueta del preparado.
A34: CT2 · Chocolate a la taza en terraza | B34: ='Mix y Ticket Canal y Temporada'!$D$27 -> 2.5 | C34: ='Mix y Ticket Canal y Temporada'!$O$27 -> 2.2727273 | D34: ='Mix y Ticket Canal y Temporada'!$R$27 -> 0.43744186 | E34: =IFERROR(C34-D34,"") -> 1.8352854 | F34: =IFERROR(1-D34/C34,"") -> 0.80752558 | G34: Precio de La Churrería de Granada (2026).
A35: CT3 · Chocolate con churros (taza y ración de 6) | B35: ='Mix y Ticket Canal y Temporada'!$D$28 -> 3.8 | C35: ='Mix y Ticket Canal y Temporada'!$O$28 -> 3.4545455 | D35: ='Mix y Ticket Canal y Temporada'!$R$28 -> 0.53181349 | E35: =IFERROR(C35-D35,"") -> 2.922732 | F35: =IFERROR(1-D35/C35,"") -> 0.84605399 | G35: Supuesto dentro del rango de 3,50-4 € con chocolate que publica CHS-32 (genérico de un proveedor de TPV).
A36: CT4 · Chocolate a la taza para llevar | B36: ='Mix y Ticket Canal y Temporada'!$D$29 -> 2.2 | C36: ='Mix y Ticket Canal y Temporada'!$O$29 -> 2.0909091 | D36: ='Mix y Ticket Canal y Temporada'!$R$29 -> 0.51744186 | E36: =IFERROR(C36-D36,"") -> 1.5734672 | F36: =IFERROR(1-D36/C36,"") -> 0.75252781 | G36: Su IVA es la celda verde del 10 % con aviso; el vaso se cobra aparte.
A37: CT5 · Media taza de chocolate | B37: ='Mix y Ticket Canal y Temporada'!$D$30 -> 1.3 | C37: ='Mix y Ticket Canal y Temporada'!$O$30 -> 1.1818182 | D37: ='Mix y Ticket Canal y Temporada'!$R$30 -> 0.26246512 | E37: =IFERROR(C37-D37,"") -> 0.91935307 | F37: =IFERROR(1-D37/C37,"") -> 0.77791413
A41: Listas de validación (no las borres: las usan los desplegables)
A42: Sí o no
A43: Sí
A44: No
A46: Versión 1.0 · octubre 2026 · aichef.pro/guia-churreria-chocolateria · info@aichef.pro

Sheet Coste Hora
A1: Coste Hora
A2: AI Chef Pro · aichef.pro — Cómo Montar una Churrería-Chocolatería
A3: El coste de empresa de una hora de tu plantilla y la mano de obra que lleva cada ración. La plantilla y el convenio viven en el libro 8.
A4: La Hora y la Ración | K4: Lo que Copian Otros Libros (No Muevas Estas Celdas)
A5: COSTE HORA DE MANO DE OBRA (coste de empresa por hora contratada) | B5: 13.243843 | C5: EUR/h | D5: Supuesto calculado con la plantilla de El Molinete (titular, dos churreros, un camarero y el medio refuerzo; convenio de ejemplo con tablas de 2025, suelo del SMI 2026 y Seguridad Social de empresa). Este libro va antes que el 8 y lo SUPONE: cuando rellenes el 8, su fila de CUADRE compara este número con el de tu plantilla. | K5: Coste hora de mano de obra, EUR/h | L5: =B5 -> 13.243843 | M5: Lo copia: libro 5 (temporada-franjas-y-ferias.xlsx, hoja Parámetros, X5); libro 8 (turnos-plantilla-y-madrugada.xlsx, hoja Parámetros, X8)
A6: Minutos de mano de obra por ración | B6: 4.4748603 | C6: min/ración | D6: Supuesto calculado: las horas contratadas de la plantilla al año, por 60, entre las raciones del año de El Molinete. Con tus números: horas de tu plantilla (libro 8) por 60 entre tus raciones del año (libro 5).
A7: Raciones por hora de mano de obra | B7: =IFERROR(60/B6,"") -> 13.40824 | C7: raciones/h
A8: COSTE DE MANO DE OBRA POR RACIÓN | B8: =IFERROR(B5*B6/60,"") -> 0.98773912 | C8: EUR/ración
A9: Ticket SIN IVA por ración (mix de invierno) | B9: ='Mix y Ticket Canal y Temporada'!$D$6 -> 2.1613636 | C9: EUR/ración
A10: Peso de la mano de obra sobre el ticket | B10: =IFERROR(B8/B9,"") -> 0.45699812
A11: Lo que Vale un Minuto
A12: Coste de un minuto de mano de obra (EUR) | B12: =IFERROR(B5/60,"") -> 0.22073071
A13: Mano de obra cada 100 raciones (EUR) | B13: =IFERROR(B8*100,"") -> 98.773912
A15: Por qué está aquí: el margen de la carta no paga sólo la materia. «Los Dos Márgenes» resta este coste para que veas el margen que te queda tras aceite y mano de obra. El libro 5 lo usa para valorar las horas de refuerzo, y el 8 lo cuadra con tu plantilla.
A17: Versión 1.0 · octubre 2026 · aichef.pro/guia-churreria-chocolateria · info@aichef.pro

Sheet Ración, Docena o Kilo
A1: Ración, Docena o Kilo
A2: AI Chef Pro · aichef.pro — Cómo Montar una Churrería-Chocolatería
A3: Los formatos de churro y porra, comparados por los euros SIN IVA que deja cada kilo de masa que fríes (decisión 7).
A6: Formato | B6: Piezas | C6: PVP con IVA (EUR) | D6: Precio por pieza con IVA (EUR) | E6: Canal que manda | F6: Ingreso SIN IVA (EUR) | G6: Materia, aceite incluido (EUR) | H6: Margen por unidad (EUR) | I6: Masa que se fríe (kg) | J6: EUR QUE DEJA CADA KG DE MASA | K6: Año y fuente del precio
A7: CH1 · Ración de churros (6 uds) | B7: ='Escandallo por kg de Masa'!$C$35 -> 6 | C7: ='Mix y Ticket Canal y Temporada'!$D$17 -> 2.6 | D7: =IF(B7>0,IFERROR(C7/B7,""),"") -> 0.43333333 | E7: =IF('Mix y Ticket Canal y Temporada'!$F$17>=1-'Mix y Ticket Canal y Temporada'!$F$17,"Para llevar","Sala") -> Sala | F7: =IF(E7="Para llevar",'Mix y Ticket Canal y Temporada'!$N$17,'Mix y Ticket Canal y Temporada'!$K$17) -> 2.3636364 | G7: =IF(E7="Para llevar",'Escandallo por kg de Masa'!$N$35,'Escandallo por kg de Masa'!$M$35) -> 0.094371625 | H7: =IFERROR(F7-G7,"") -> 2.2692647 | I7: ='Escandallo por kg de Masa'!$G$35 -> 0.12631579 | J7: =IFERROR(H7/I7,"") -> 17.965013 | K7: ='Mix y Ticket Canal y Temporada'!$C$17&" · "&'Mix y Ticket Canal y Temporada'!$E$17 -> 2025 · CUS-17
A8: CH2 · Media ración de churros (3 uds) | B8: ='Escandallo por kg de Masa'!$C$36 -> 3 | C8: ='Mix y Ticket Canal y Temporada'!$D$18 -> 1.4 | D8: =IF(B8>0,IFERROR(C8/B8,""),"") -> 0.46666667 | E8: =IF('Mix y Ticket Canal y Temporada'!$F$18>=1-'Mix y Ticket Canal y Temporada'!$F$18,"Para llevar","Sala") -> Sala | F8: =IF(E8="Para llevar",'Mix y Ticket Canal y Temporada'!$N$18,'Mix y Ticket Canal y Temporada'!$K$18) -> 1.2727273 | G8: =IF(E8="Para llevar",'Escandallo por kg de Masa'!$N$36,'Escandallo por kg de Masa'!$M$36) -> 0.047185812 | H8: =IFERROR(F8-G8,"") -> 1.2255415 | I8: ='Escandallo por kg de Masa'!$G$36 -> 0.063157895 | J8: =IFERROR(H8/I8,"") -> 19.404406 | K8: ='Mix y Ticket Canal y Temporada'!$C$18&" · "&'Mix y Ticket Canal y Temporada'!$E$18 -> 2025 · CUS-17
A9: CH3 · Ración de porras (3 uds) | B9: ='Escandallo por kg de Masa'!$C$37 -> 3 | C9: ='Mix y Ticket Canal y Temporada'!$D$19 -> 2.7 | D9: =IF(B9>0,IFERROR(C9/B9,""),"") -> 0.9 | E9: =IF('Mix y Ticket Canal y Temporada'!$F$19>=1-'Mix y Ticket Canal y Temporada'!$F$19,"Para llevar","Sala") -> Sala | F9: =IF(E9="Para llevar",'Mix y Ticket Canal y Temporada'!$N$19,'Mix y Ticket Canal y Temporada'!$K$19) -> 2.4545455 | G9: =IF(E9="Para llevar",'Escandallo por kg de Masa'!$N$37,'Escandallo por kg de Masa'!$M$37) -> 0.14155744 | H9: =IFERROR(F9-G9,"") -> 2.312988 | I9: ='Escandallo por kg de Masa'!$G$37 -> 0.18947368 | J9: =IFERROR(H9/I9,"") -> 12.207437 | K9: ='Mix y Ticket Canal y Temporada'!$C$19&" · "&'Mix y Ticket Canal y Temporada'!$E$19 -> 2026 · supuesto declarado
A10: CH4 · Churro suelto | B10: ='Escandallo por kg de Masa'!$C$38 -> 1 | C10: ='Mix y Ticket Canal y Temporada'!$D$20 -> 0.3 | D10: =IF(B10>0,IFERROR(C10/B10,""),"") -> 0.3 | E10: =IF('Mix y Ticket Canal y Temporada'!$F$20>=1-'Mix y Ticket Canal y Temporada'!$F$20,"Para llevar","Sala") -> Para llevar | F10: =IF(E10="Para llevar",'Mix y Ticket Canal y Temporada'!$N$20,'Mix y Ticket Canal y Temporada'!$K$20) -> 0.27272727 | G10: =IF(E10="Para llevar",'Escandallo por kg de Masa'!$N$38,'Escandallo por kg de Masa'!$M$38) -> 0.035728604 | H10: =IFERROR(F10-G10,"") -> 0.23699867 | I10: ='Escandallo por kg de Masa'!$G$38 -> 0.021052632 | J10: =IFERROR(H10/I10,"") -> 11.257437 | K10: ='Mix y Ticket Canal y Temporada'!$C$20&" · "&'Mix y Ticket Canal y Temporada'!$E$20 -> 2026 · CUS-16
A11: CH5 · Porra suelta | B11: ='Escandallo por kg de Masa'!$C$39 -> 1 | C11: ='Mix y Ticket Canal y Temporada'!$D$21 -> 0.6 | D11: =IF(B11>0,IFERROR(C11/B11,""),"") -> 0.6 | E11: =IF('Mix y Ticket Canal y Temporada'!$F$21>=1-'Mix y Ticket Canal y Temporada'!$F$21,"Para llevar","Sala") -> Para llevar | F11: =IF(E11="Para llevar",'Mix y Ticket Canal y Temporada'!$N$21,'Mix y Ticket Canal y Temporada'!$K$21) -> 0.54545455 | G11: =IF(E11="Para llevar",'Escandallo por kg de Masa'!$N$39,'Escandallo por kg de Masa'!$M$39) -> 0.067185812 | H11: =IFERROR(F11-G11,"") -> 0.47826873 | I11: ='Escandallo por kg de Masa'!$G$39 -> 0.063157895 | J11: =IFERROR(H11/I11,"") -> 7.5725883 | K11: ='Mix y Ticket Canal y Temporada'!$C$21&" · "&'Mix y Ticket Canal y Temporada'!$E$21 -> 2026 · CUS-16
A12: CH6 · Docena de churros para llevar | B12: ='Escandallo por kg de Masa'!$C$40 -> 12 | C12: ='Mix y Ticket Canal y Temporada'!$D$22 -> 3.5 | D12: =IF(B12>0,IFERROR(C12/B12,""),"") -> 0.29166667 | E12: =IF('Mix y Ticket Canal y Temporada'!$F$22>=1-'Mix y Ticket Canal y Temporada'!$F$22,"Para llevar","Sala") -> Para llevar | F12: =IF(E12="Para llevar",'Mix y Ticket Canal y Temporada'!$N$22,'Mix y Ticket Canal y Temporada'!$K$22) -> 3.1818182 | G12: =IF(E12="Para llevar",'Escandallo por kg de Masa'!$N$40,'Escandallo por kg de Masa'!$M$40) -> 0.33874325 | H12: =IFERROR(F12-G12,"") -> 2.8430749 | I12: ='Escandallo por kg de Masa'!$G$40 -> 0.25263158 | J12: =IFERROR(H12/I12,"") -> 11.253838 | K12: ='Mix y Ticket Canal y Temporada'!$C$22&" · "&'Mix y Ticket Canal y Temporada'!$E$22 -> 2026 · supuesto declarado
A13: CH7 · Kilo de churros para llevar | B13: ='Escandallo por kg de Masa'!$C$41 -> 0 | C13: ='Mix y Ticket Canal y Temporada'!$D$23 -> 10 | D13: =IF(B13>0,IFERROR(C13/B13,""),"") | E13: =IF('Mix y Ticket Canal y Temporada'!$F$23>=1-'Mix y Ticket Canal y Temporada'!$F$23,"Para llevar","Sala") -> Para llevar | F13: =IF(E13="Para llevar",'Mix y Ticket Canal y Temporada'!$N$23,'Mix y Ticket Canal y Temporada'!$K$23) -> 9.0909091 | G13: =IF(E13="Para llevar",'Escandallo por kg de Masa'!$N$41,'Escandallo por kg de Masa'!$M$41) -> 1.1238113 | H13: =IFERROR(F13-G13,"") -> 7.9670978 | I13: ='Escandallo por kg de Masa'!$G$41 -> 1.1695906 | J13: =IFERROR(H13/I13,"") -> 6.8118686 | K13: ='Mix y Ticket Canal y Temporada'!$C$23&" · "&'Mix y Ticket Canal y Temporada'!$E$23 -> 2026 · supuesto declarado
A15: Lo que Dice la Comparación
A16: El formato que más deja por kilo de masa | B16: =IFERROR(INDEX(A7:A13,MATCH(MAX(J7:J13),J7:J13,0)),"") -> CH2 · Media ración de churros (3 uds)
A17: Lo que deja ese formato por kilo de masa (EUR) | B17: =MAX(J7:J13) -> 19.404406
A18: El formato que menos deja por kilo de masa | B18: =IFERROR(INDEX(A7:A13,MATCH(MIN(J7:J13),J7:J13,0)),"") -> CH7 · Kilo de churros para llevar
A19: Lo que deja ese formato por kilo de masa (EUR) | B19: =MIN(J7:J13) -> 6.8118686
A20: Ración de churros frente al kilo: EUR más por kilo de masa | B20: =IFERROR(J7-J13,"") -> 11.153144
A22: El kilo es el formato con menos euros por kilo de masa porque se vende por peso frito, al precio más bajo por pieza. No es un error que lo tengas: es el que trae el pedido grande del domingo. Lo que esta hoja te dice es cuánto cuesta cada formato en masa, en aceite y en freidora, para que el precio de cada uno sea una decisión. El canal que manda es el de la mayor parte de sus ventas (hoja «Mix y Ticket Canal y Temporada»).
A24: Versión 1.0 · octubre 2026 · aichef.pro/guia-churreria-chocolateria · info@aichef.pro

Sheet Mix y Ticket Canal y Temporada
A1: Mix y Ticket Canal y Temporada
A2: AI Chef Pro · aichef.pro — Cómo Montar una Churrería-Chocolatería
A3: El PVP con IVA de cada referencia, la parte que se vende para llevar y dos mixes: invierno (septiembre a junio) y verano (julio y agosto). Cada mix suma 100.
A4: Ticket y Materia por Canal y Temporada | K4: Lo que Copian Otros Libros (No Muevas Estas Celdas)
A5: Por ración | B5: Invierno · sala | C5: Invierno · para llevar | D5: Invierno · total | E5: Verano · sala | F5: Verano · para llevar | G5: Verano · total | K5: Kilos de masa por ración media (mix de invierno, merma incluida) | L5: =D11 -> 0.097918129 | M5: Lo copia: libro 1 (produccion-hora-punta-y-local.xlsx, hoja Parámetros, X1); libro 4 (aceite-de-fritura-coste-y-cambio.xlsx, hoja Parámetros, X2 bis)
A6: Ticket SIN IVA por ración (EUR) | B6: =IFERROR(SUMPRODUCT(U17:U40,K17:K40)/U$41,"") -> 2.1480519 | C6: =IFERROR(SUMPRODUCT(V17:V40,N17:N40)/V$41,"") -> 2.1924242 | D6: =IFERROR(SUMPRODUCT(S17:S40,O17:O40)/S$41,"") -> 2.1613636 | E6: =IFERROR(SUMPRODUCT(W17:W40,K17:K40)/W$41,"") -> 2.2277629 | F6: =IFERROR(SUMPRODUCT(X17:X40,N17:N40)/X$41,"") -> 2.1586804 | G6: =IFERROR(SUMPRODUCT(T17:T40,O17:O40)/T$41,"") -> 2.2067273 | K6: Ticket SIN IVA por ración en verano (carta de verano), EUR | L6: =G6 -> 2.2067273 | M6: Lo copia: libro 5 (temporada-franjas-y-ferias.xlsx, hoja Parámetros, X5)
A7: Coste de materia por ración, aceite absorbido incluido (EUR) | B7: =IFERROR(SUMPRODUCT(U17:U40,P17:P40)/U$41,"") -> 0.27314864 | C7: =IFERROR(SUMPRODUCT(V17:V40,Q17:Q40)/V$41,"") -> 0.30546293 | D7: =IFERROR(SUMPRODUCT(S17:S40,R17:R40)/S$41,"") -> 0.28284293 | E7: =IFERROR(SUMPRODUCT(W17:W40,P17:P40)/W$41,"") -> 0.3475811 | F7: =IFERROR(SUMPRODUCT(X17:X40,Q17:Q40)/X$41,"") -> 0.3834419 | G7: =IFERROR(SUMPRODUCT(T17:T40,R17:R40)/T$41,"") -> 0.35850072 | K7: Coste de materia por ración en verano, aceite absorbido incluido, EUR | L7: =G7 -> 0.35850072 | M7: Lo copia: libro 5 (temporada-franjas-y-ferias.xlsx, hoja Parámetros, X5)
A8: Margen sobre materia por ración (EUR) | B8: =IFERROR(B6-B7,"") -> 1.8749033 | C8: =IFERROR(C6-C7,"") -> 1.8869613 | D8: =IFERROR(D6-D7,"") -> 1.8785207 | E8: =IFERROR(E6-E7,"") -> 1.8801818 | F8: =IFERROR(F6-F7,"") -> 1.7752385 | G8: =IFERROR(G6-G7,"") -> 1.8482266 | K8: Coste de materia por ración para llevar (invierno), aceite absorbido incluido, EUR | L8: =C7 -> 0.30546293 | M8: Lo copia: libro 5 (temporada-franjas-y-ferias.xlsx, hoja Parámetros, X5); libro 6 (plan-financiero-3-anos-churreria.xlsx, hoja 0. Supuestos, X11)
A9: Margen sobre materia (%) | B9: =IFERROR(1-B7/B6,"") -> 0.8728389 | C9: =IFERROR(1-C7/C6,"") -> 0.86067344 | D9: =IFERROR(1-D7/D6,"") -> 0.86913682 | E9: =IFERROR(1-E7/E6,"") -> 0.84397751 | F9: =IFERROR(1-F7/F6,"") -> 0.82237208 | G9: =IFERROR(1-G7/G6,"") -> 0.8375419 | K9: Coste de materia por ración en sala (invierno), aceite absorbido incluido, EUR | L9: =B7 -> 0.27314864 | M9: Lo copia: libro 6 (plan-financiero-3-anos-churreria.xlsx, hoja 0. Supuestos, X11)
A10: Parte de las raciones del canal | B10: =IFERROR(U$41/S$41,"") -> 0.7 | C10: =IFERROR(V$41/S$41,"") -> 0.3 | D10: =IFERROR(S$41/S$41,"") -> 1 | E10: =IFERROR(W$41/T$41,"") -> 0.6955 | F10: =IFERROR(X$41/T$41,"") -> 0.3045 | G10: =IFERROR(T$41/T$41,"") -> 1 | K10: Ticket SIN IVA por ración en sala (invierno), EUR | L10: =B6 -> 2.1480519 | M10: Lo copia: libro 6 (plan-financiero-3-anos-churreria.xlsx, hoja 0. Supuestos, X11)
A11: Kilos de masa que se fríen por ración media | B11: =IFERROR(SUMPRODUCT(U17:U40,Y17:Y40)/U$41,"") -> 0.070827068 | C11: =IFERROR(SUMPRODUCT(V17:V40,Y17:Y40)/V$41,"") -> 0.1611306 | D11: =IFERROR(SUMPRODUCT(S17:S40,Y17:Y40)/S$41,"") -> 0.097918129 | E11: =IFERROR(SUMPRODUCT(W17:W40,Y17:Y40)/W$41,"") -> 0.038276136 | F11: =IFERROR(SUMPRODUCT(X17:X40,Y17:Y40)/X$41,"") -> 0.082347632 | G11: =IFERROR(SUMPRODUCT(T17:T40,Y17:Y40)/T$41,"") -> 0.051695906 | K11: Ticket SIN IVA por ración para llevar (invierno), EUR | L11: =C6 -> 2.1924242 | M11: Lo copia: libro 6 (plan-financiero-3-anos-churreria.xlsx, hoja 0. Supuestos, X11)
A12: Comprobación: cada mix suma 100 | B12: =IF(OR(NOT(ISNUMBER(S41)),NOT(ISNUMBER(T41))),"",IF(AND(ROUND(S41,6)=100,ROUND(T41,6)=100),"CUADRAN los dos mixes","REVISA: algún mix no suma 100")) -> CUADRAN los dos mixes | K12: Raciones en sala, en fracción (0,70 = 70 %; el resto, para llevar) | L12: =B10 -> 0.7 | M12: Lo copia: libro 6 (plan-financiero-3-anos-churreria.xlsx, hoja 0. Supuestos, X11)
A13: El ticket incluye, al llevar, el vaso cobrado aparte. La materia incluye el aceite absorbido y, al llevar, el envase. Las franjas del día no están aquí: viven en el libro 5.
A16: Id y referencia | B16: Familia | C16: Año del precio | D16: PVP con IVA (EUR) | E16: Fuente del precio | F16: Parte que se vende para llevar | G16: ¿Vaso cobrado aparte al llevar? | H16: IVA para llevar: categoría | I16: IVA en sala | J16: IVA para llevar | K16: PVP SIN IVA en sala (EUR) | L16: PVP SIN IVA para llevar (EUR) | M16: Vaso SIN IVA (EUR) | N16: Ingreso SIN IVA para llevar (EUR) | O16: Ingreso medio SIN IVA (EUR) | P16: Materia en sala (EUR) | Q16: Materia para llevar (EUR) | R16: Materia media (EUR) | S16: Mix de invierno (%) | T16: Mix de julio y agosto (%) | U16: Peso sala invierno | V16: Peso llevar invierno | W16: Peso sala verano | X16: Peso llevar verano | Y16: Masa que se fríe (kg) | Z16: Alérgenos de la receta del ejemplo
A17: CH1 · Ración de churros (6 uds) | B17: Churros y porras | C17: 2025 | D17: 2.6 | E17: CUS-17 | F17: 0.15 | G17: No | H17: Comida para llevar | I17: ='Parámetros'!$B$5 -> 0.1 | J17: ='Parámetros'!$B$6 -> 0.1 | K17: =IFERROR(D17/(1+I17),"") -> 2.3636364 | L17: =IFERROR(D17/(1+J17),"") -> 2.3636364 | M17: =IF(G17="Sí",IFERROR('Parámetros'!$B$25/(1+'Parámetros'!$B$8),""),0) -> 0 | N17: =IFERROR(L17+M17,"") -> 2.3636364 | O17: =IFERROR((1-F17)*K17+F17*N17,"") -> 2.3636364 | P17: ='Escandallo por kg de Masa'!$M$35 -> 0.094371625 | Q17: ='Escandallo por kg de Masa'!$N$35 -> 0.24437162 | R17: =IFERROR((1-F17)*P17+F17*Q17,"") -> 0.11687162 | S17: 20 | T17: 12 | U17: =IFERROR(S17*(1-F17),"") -> 17 | V17: =IFERROR(S17*F17,"") -> 3 | W17: =IFERROR(T17*(1-F17),"") -> 10.2 | X17: =IFERROR(T17*F17,"") -> 1.8 | Y17: ='Escandallo por kg de Masa'!$G$35 -> 0.12631579 | Z17: gluten
A18: CH2 · Media ración de churros (3 uds) | B18: Churros y porras | C18: 2025 | D18: 1.4 | E18: CUS-17 | F18: 0 | G18: No | H18: Comida para llevar | I18: ='Parámetros'!$B$5 -> 0.1 | J18: ='Parámetros'!$B$6 -> 0.1 | K18: =IFERROR(D18/(1+I18),"") -> 1.2727273 | L18: =IFERROR(D18/(1+J18),"") -> 1.2727273 | M18: =IF(G18="Sí",IFERROR('Parámetros'!$B$25/(1+'Parámetros'!$B$8),""),0) -> 0 | N18: =IFERROR(L18+M18,"") -> 1.2727273 | O18: =IFERROR((1-F18)*K18+F18*N18,"") -> 1.2727273 | P18: ='Escandallo por kg de Masa'!$M$36 -> 0.047185812 | Q18: ='Escandallo por kg de Masa'!$N$36 -> 0.047185812 | R18: =IFERROR((1-F18)*P18+F18*Q18,"") -> 0.047185812 | S18: 4 | T18: 3 | U18: =IFERROR(S18*(1-F18),"") -> 4 | V18: =IFERROR(S18*F18,"") -> 0 | W18: =IFERROR(T18*(1-F18),"") -> 3 | X18: =IFERROR(T18*F18,"") -> 0 | Y18: ='Escandallo por kg de Masa'!$G$36 -> 0.063157895 | Z18: gluten
A19: CH3 · Ración de porras (3 uds) | B19: Churros y porras | C19: 2026 | D19: 2.7 | E19: supuesto declarado | F19: 0.25 | G19: No | H19: Comida para llevar | I19: ='Parámetros'!$B$5 -> 0.1 | J19: ='Parámetros'!$B$6 -> 0.1 | K19: =IFERROR(D19/(1+I19),"") -> 2.4545455 | L19: =IFERROR(D19/(1+J19),"") -> 2.4545455 | M19: =IF(G19="Sí",IFERROR('Parámetros'!$B$25/(1+'Parámetros'!$B$8),""),0) -> 0 | N19: =IFERROR(L19+M19,"") -> 2.4545455 | O19: =IFERROR((1-F19)*K19+F19*N19,"") -> 2.4545455 | P19: ='Escandallo por kg de Masa'!$M$37 -> 0.14155744 | Q19: ='Escandallo por kg de Masa'!$N$37 -> 0.29155744 | R19: =IFERROR((1-F19)*P19+F19*Q19,"") -> 0.17905744 | S19: 6 | T19: 3 | U19: =IFERROR(S19*(1-F19),"") -> 4.5 | V19: =IFERROR(S19*F19,"") -> 1.5 | W19: =IFERROR(T19*(1-F19),"") -> 2.25 | X19: =IFERROR(T19*F19,"") -> 0.75 | Y19: ='Escandallo por kg de Masa'!$G$37 -> 0.18947368 | Z19: gluten
A20: CH4 · Churro suelto | B20: Churros y porras | C20: 2026 | D20: 0.3 | E20: CUS-16 | F20: 1 | G20: No | H20: Comida para llevar | I20: ='Parámetros'!$B$5 -> 0.1 | J20: ='Parámetros'!$B$6 -> 0.1 | K20: =IFERROR(D20/(1+I20),"") -> 0.27272727 | L20: =IFERROR(D20/(1+J20),"") -> 0.27272727 | M20: =IF(G20="Sí",IFERROR('Parámetros'!$B$25/(1+'Parámetros'!$B$8),""),0) -> 0 | N20: =IFERROR(L20+M20,"") -> 0.27272727 | O20: =IFERROR((1-F20)*K20+F20*N20,"") -> 0.27272727 | P20: ='Escandallo por kg de Masa'!$M$38 -> 0.015728604 | Q20: ='Escandallo por kg de Masa'!$N$38 -> 0.035728604 | R20: =IFERROR((1-F20)*P20+F20*Q20,"") -> 0.035728604 | S20: 6 | T20: 4 | U20: =IFERROR(S20*(1-F20),"") -> 0 | V20: =IFERROR(S20*F20,"") -> 6 | W20: =IFERROR(T20*(1-F20),"") -> 0 | X20: =IFERROR(T20*F20,"") -> 4 | Y20: ='Escandallo por kg de Masa'!$G$38 -> 0.021052632 | Z20: gluten
A21: CH5 · Porra suelta | B21: Churros y porras | C21: 2026 | D21: 0.6 | E21: CUS-16 | F21: 1 | G21: No | H21: Comida para llevar | I21: ='Parámetros'!$B$5 -> 0.1 | J21: ='Parámetros'!$B$6 -> 0.1 | K21: =IFERROR(D21/(1+I21),"") -> 0.54545455 | L21: =IFERROR(D21/(1+J21),"") -> 0.54545455 | M21: =IF(G21="Sí",IFERROR('Parámetros'!$B$25/(1+'Parámetros'!$B$8),""),0) -> 0 | N21: =IFERROR(L21+M21,"") -> 0.54545455 | O21: =IFERROR((1-F21)*K21+F21*N21,"") -> 0.54545455 | P21: ='Escandallo por kg de Masa'!$M$39 -> 0.047185812 | Q21: ='Escandallo por kg de Masa'!$N$39 -> 0.067185812 | R21: =IFERROR((1-F21)*P21+F21*Q21,"") -> 0.067185812 | S21: 3 | T21: 2 | U21: =IFERROR(S21*(1-F21),"") -> 0 | V21: =IFERROR(S21*F21,"") -> 3 | W21: =IFERROR(T21*(1-F21),"") -> 0 | X21: =IFERROR(T21*F21,"") -> 2 | Y21: ='Escandallo por kg de Masa'!$G$39 -> 0.063157895 | Z21: gluten
A22: CH6 · Docena de churros para llevar | B22: Churros y porras | C22: 2026 | D22: 3.5 | E22: supuesto declarado | F22: 1 | G22: No | H22: Comida para llevar | I22: ='Parámetros'!$B$5 -> 0.1 | J22: ='Parámetros'!$B$6 -> 0.1 | K22: =IFERROR(D22/(1+I22),"") -> 3.1818182 | L22: =IFERROR(D22/(1+J22),"") -> 3.1818182 | M22: =IF(G22="Sí",IFERROR('Parámetros'!$B$25/(1+'Parámetros'!$B$8),""),0) -> 0 | N22: =IFERROR(L22+M22,"") -> 3.1818182 | O22: =IFERROR((1-F22)*K22+F22*N22,"") -> 3.1818182 | P22: ='Escandallo por kg de Masa'!$M$40 -> 0.18874325 | Q22: ='Escandallo por kg de Masa'!$N$40 -> 0.33874325 | R22: =IFERROR((1-F22)*P22+F22*Q22,"") -> 0.33874325 | S22: 6 | T22: 3 | U22: =IFERROR(S22*(1-F22),"") -> 0 | V22: =IFERROR(S22*F22,"") -> 6 | W22: =IFERROR(T22*(1-F22),"") -> 0 | X22: =IFERROR(T22*F22,"") -> 3 | Y22: ='Escandallo por kg de Masa'!$G$40 -> 0.25263158 | Z22: gluten
A23: CH7 · Kilo de churros para llevar | B23: Churros y porras | C23: 2026 | D23: 10 | E23: supuesto declarado | F23: 1 | G23: No | H23: Comida para llevar | I23: ='Parámetros'!$B$5 -> 0.1 | J23: ='Parámetros'!$B$6 -> 0.1 | K23: =IFERROR(D23/(1+I23),"") -> 9.0909091 | L23: =IFERROR(D23/(1+J23),"") -> 9.0909091 | M23: =IF(G23="Sí",IFERROR('Parámetros'!$B$25/(1+'Parámetros'!$B$8),""),0) -> 0 | N23: =IFERROR(L23+M23,"") -> 9.0909091 | O23: =IFERROR((1-F23)*K23+F23*N23,"") -> 9.0909091 | P23: ='Escandallo por kg de Masa'!$M$41 -> 0.87381134 | Q23: ='Escandallo por kg de Masa'!$N$41 -> 1.1238113 | R23: =IFERROR((1-F23)*P23+F23*Q23,"") -> 1.1238113 | S23: 2 | T23: 1 | U23: =IFERROR(S23*(1-F23),"") -> 0 | V23: =IFERROR(S23*F23,"") -> 2 | W23: =IFERROR(T23*(1-F23),"") -> 0 | X23: =IFERROR(T23*F23,"") -> 1 | Y23: ='Escandallo por kg de Masa'!$G$41 -> 1.1695906 | Z23: gluten
A24: RE1 · Churro relleno de chocolate (ud) | B24: Rellenos y especiales | C24: 2026 | D24: 1.2 | E24: supuesto declarado | F24: 0 | G24: No | H24: Comida para llevar | I24: ='Parámetros'!$B$5 -> 0.1 | J24: ='Parámetros'!$B$6 -> 0.1 | K24: =IFERROR(D24/(1+I24),"") -> 1.0909091 | L24: =IFERROR(D24/(1+J24),"") -> 1.0909091 | M24: =IF(G24="Sí",IFERROR('Parámetros'!$B$25/(1+'Parámetros'!$B$8),""),0) -> 0 | N24: =IFERROR(L24+M24,"") -> 1.0909091 | O24: =IFERROR((1-F24)*K24+F24*N24,"") -> 1.0909091 | P24: ='Escandallo por kg de Masa'!$M$42 -> 0.17718581 | Q24: ='Escandallo por kg de Masa'!$N$42 -> 0.17718581 | R24: =IFERROR((1-F24)*P24+F24*Q24,"") -> 0.17718581 | S24: 3 | T24: 2 | U24: =IFERROR(S24*(1-F24),"") -> 3 | V24: =IFERROR(S24*F24,"") -> 0 | W24: =IFERROR(T24*(1-F24),"") -> 2 | X24: =IFERROR(T24*F24,"") -> 0 | Y24: ='Escandallo por kg de Masa'!$G$42 -> 0.063157895 | Z24: gluten, leche, soja
A25: RE2 · Ración de churros con cobertura de chocolate (6 uds) | B25: Rellenos y especiales | C25: 2026 | D25: 3.5 | E25: supuesto declarado | F25: 0 | G25: No | H25: Comida para llevar | I25: ='Parámetros'!$B$5 -> 0.1 | J25: ='Parámetros'!$B$6 -> 0.1 | K25: =IFERROR(D25/(1+I25),"") -> 3.1818182 | L25: =IFERROR(D25/(1+J25),"") -> 3.1818182 | M25: =IF(G25="Sí",IFERROR('Parámetros'!$B$25/(1+'Parámetros'!$B$8),""),0) -> 0 | N25: =IFERROR(L25+M25,"") -> 3.1818182 | O25: =IFERROR((1-F25)*K25+F25*N25,"") -> 3.1818182 | P25: ='Escandallo por kg de Masa'!$M$43 -> 0.28937162 | Q25: ='Escandallo por kg de Masa'!$N$43 -> 0.28937162 | R25: =IFERROR((1-F25)*P25+F25*Q25,"") -> 0.28937162 | S25: 2 | T25: 1 | U25: =IFERROR(S25*(1-F25),"") -> 2 | V25: =IFERROR(S25*F25,"") -> 0 | W25: =IFERROR(T25*(1-F25),"") -> 1 | X25: =IFERROR(T25*F25,"") -> 0 | Y25: ='Escandallo por kg de Masa'!$G$43 -> 0.12631579 | Z25: gluten, leche, soja
A26: CT1 · Chocolate a la taza en barra | B26: Chocolate a la taza | C26: 2026 | D26: 2 | E26: CUS-15 | F26: 0 | G26: No | H26: Chocolate para llevar (zona gris) | I26: ='Parámetros'!$B$5 -> 0.1 | J26: ='Parámetros'!$B$7 -> 0.1 | K26: =IFERROR(D26/(1+I26),"") -> 1.8181818 | L26: =IFERROR(D26/(1+J26),"") -> 1.8181818 | M26: =IF(G26="Sí",IFERROR('Parámetros'!$B$25/(1+'Parámetros'!$B$8),""),0) -> 0 | N26: =IFERROR(L26+M26,"") -> 1.8181818 | O26: =IFERROR((1-F26)*K26+F26*N26,"") -> 1.8181818 | P26: ='Escandallo por kg de Masa'!$M$44 -> 0.43744186 | Q26: ='Escandallo por kg de Masa'!$N$44 -> 0.43744186 | R26: =IFERROR((1-F26)*P26+F26*Q26,"") -> 0.43744186 | S26: 12 | T26: 4 | U26: =IFERROR(S26*(1-F26),"") -> 12 | V26: =IFERROR(S26*F26,"") -> 0 | W26: =IFERROR(T26*(1-F26),"") -> 4 | X26: =IFERROR(T26*F26,"") -> 0 | Y26: ='Escandallo por kg de Masa'!$G$44 -> 0 | Z26: leche
A27: CT2 · Chocolate a la taza en terraza | B27: Chocolate a la taza | C27: 2026 | D27: 2.5 | E27: CUS-15 | F27: 0 | G27: No | H27: Chocolate para llevar (zona gris) | I27: ='Parámetros'!$B$5 -> 0.1 | J27: ='Parámetros'!$B$7 -> 0.1 | K27: =IFERROR(D27/(1+I27),"") -> 2.2727273 | L27: =IFERROR(D27/(1+J27),"") -> 2.2727273 | M27: =IF(G27="Sí",IFERROR('Parámetros'!$B$25/(1+'Parámetros'!$B$8),""),0) -> 0 | N27: =IFERROR(L27+M27,"") -> 2.2727273 | O27: =IFERROR((1-F27)*K27+F27*N27,"") -> 2.2727273 | P27: ='Escandallo por kg de Masa'!$M$45 -> 0.43744186 | Q27: ='Escandallo por kg de Masa'!$N$45 -> 0.43744186 | R27: =IFERROR((1-F27)*P27+F27*Q27,"") -> 0.43744186 | S27: 4 | T27: 2 | U27: =IFERROR(S27*(1-F27),"") -> 4 | V27: =IFERROR(S27*F27,"") -> 0 | W27: =IFERROR(T27*(1-F27),"") -> 2 | X27: =IFERROR(T27*F27,"") -> 0 | Y27: ='Escandallo por kg de Masa'!$G$45 -> 0 | Z27: leche
