Workbook

Sheet Instrucciones
A1: Turnos, Plantilla y Madrugada
A2: AI Chef Pro · aichef.pro — Cómo Montar una Churrería-Chocolatería
A3: Para qué sirve: saber cuánta gente necesitas, si alguien es trabajador nocturno, cuánto cuesta el plus de la madrugada, cuánto cuesta tu plantilla al año y cuántas horas haces tú.
A5: Instrucciones de Uso
A6: Celdas verdes = campos editables
A7: Las celdas en crema son resultados que el libro calcula; las blancas con fórmula, también. No escribas encima.
A9: 1. Hoja «Parámetros». Arriba, tres celdas verdes que copias a mano de los libros 1, 5 y 3 (cada una dice de qué celda exacta). Debajo, tu convenio (provincia, tablas, pagas, plus de convenio y salario base por nivel), las dos figuras de nocturnidad con sus franjas, el SMI y la Seguridad Social. Al pie, primero el CONTRASTE de tus copias con tu plantilla y después el CUADRE: anota lo que publica hoy la celda de origen de cada cifra y, si lo que usas se separa, su fila se pone en rojo.
A10: 2. Hoja «Cuadrante por Franja». Los mínimos de cobertura (cuántas personas hacen falta en cada tramo y cuántas en la línea de fritura) y los turnos de la SEMANA TIPO, persona a persona. La rejilla de medias horas cuenta quién está y marca cada hueco: tiene que dar cero.
A11: 3. Hoja «Nocturnidad ET y Convenio». Para cada persona, las dos figuras por separado: si es trabajador nocturno según el Estatuto (sí, no o revísalo con tu asesor) y cuántas horas cobra con el plus del convenio y cuánto cuesta ese plus al año.
A12: 4. Hoja «Coste de Plantilla». Jornada, nivel y si cotiza la Seguridad Social de empresa de cada puesto; su salario, el plus, el suelo del SMI y el coste anual. Abajo, el coste hora, las sustituciones de vacaciones, el refuerzo de Navidad y el COSTE ANUAL DE PLANTILLA que copia el libro 6.
A13: 5. Hoja «Identifica tu Convenio». El método para encontrar el tuyo, con Madrid como ejemplo. Rellena tu respuesta en cada paso.
A14: 6. Hoja «Horas del Titular». Las horas que haces tú, las que van por encima de una jornada completa, la madrugada que asumes y lo que valen al coste hora.
... A37: Versión 1.0 · octubre 2026 · aichef.pro/guia-churreria-chocolateria · info@aichef.pro

Sheet Parámetros
A1: Parámetros
A2: AI Chef Pro · aichef.pro — Cómo Montar una Churrería-Chocolatería
A3: Todo lo que el resto de hojas da por sabido vive aquí. Ninguna fórmula de este libro lleva dentro un salario, un porcentaje, una hora ni un umbral.
A5: Parámetro | B5: Valor | C5: Unidad | D5: De dónde sale | E5: Nota
A6: Lo que Copias de los Libros 1, 5 y 3
A7: Personas en la línea en el pico del fin de semana | B7: 2 | C7: personas | D7: cópialo del libro 1: produccion-hora-punta-y-local.xlsx!Equipos y Capacidad!L5 | E7: Sale de la capacidad de la línea del libro 1. Aquí manda el mínimo de personas en la línea del pico en «Cuadrante por Franja»: si tu cuadrante no las pone, aparecen huecos.
A8: Horas de refuerzo de Navidad y Reyes al año | B8: 56 | C8: h/año | D8: cópialo del libro 5: temporada-franjas-y-ferias.xlsx!Refuerzo por Pico!L5 | E8: Días punta de Navidad y Reyes con una persona más por la mañana. Se pagan al coste hora de la plantilla en «Coste de Plantilla».
A9: Coste hora de mano de obra que usaste en el escandallo | B9: 13.243843 | C9: EUR/h | D9: cópialo del libro 3: carta-de-apertura-y-escandallo-churro.xlsx!Coste Hora!L5 | E9: El libro 3 va antes y lo supone para valorar la mano de obra de cada ración. Aquí se cuadra con el que sale de tu plantilla.
A11: Tu Convenio (Ejemplo: Madrid, Clase C, Tablas 2025)
A12: Provincia de tu local | B12: Madrid | D12: supuesto declarado de El Molinete | E12: Pon la tuya: de ella depende el convenio que te toca.
A13: Código REGCON de tu convenio | B13: 28002085011981 | D13: CUN-39 | E13: El del ejemplo es el de hostelería de la Comunidad de Madrid. Busca el tuyo con la hoja «Identifica tu Convenio».
A14: Nombre de tu convenio | B14: Hostelería y Actividades Turísticas de la Comunidad de Madrid | D14: CUN-39
A15: Clase o grupo en el que entra tu local | B15: C | D15: CUN-39 | E15: La clase C agrupa cafeterías de una taza, chocolaterías, cafés-bares y bares; el convenio nombra freidurías, quioscos y chocolaterías.
A16: Tablas salariales que usas | B16: 2025 · convenio vencido el 31-12-2025, en negociación; se aplican sus tablas mientras no se publique el nuevo | D16: CUN-39 + CUN-V01 | E16: Etiqueta obligatoria de toda celda que use estas cuantías. Antes de cada versión 2.x, mirar el BOCM.
A17: Pagas al año | B17: 14 | C17: pagas | D17: supuesto declarado de El Molinete | E17: Dos gratificaciones del art. 26 de una mensualidad cada una: compruébalo en tu convenio. Es aritmética del ejemplo, no una cifra de la ficha.
A18: Plus de convenio | B18: 191.22 | C18: EUR/mes | D18: CUN-39 | E18: Plus de convenio de la clase C en 2025.
A19: Meses que se cobra el plus de convenio | B19: 11 | C19: meses | D19: CUN-39 | E19: El plus se cobra durante once meses.
A20: SMI anual (suelo de cada puesto a jornada completa) | B20: 17094 | C20: EUR/año | D20: CHN-67 | E20: Cuantía anual de referencia, en celda verde. El real decreto no dice «14 pagas». Coste por puesto = MAX(salario; SMI anual a su jornada).
A21: SMI mensual | B21: 1221 | C21: EUR/mes | D21: CHN-67 | E21: Caduca el 31-12-2026. Sirve para leer una oferta de mercado mes a mes.
A22: Seguridad Social a cargo de la empresa | B22: 0.33 | C22: del bruto | D22: heredado de la hermana o del motor (motor.PARAMETROS[ss_empresa]) | E22: Cotización empresarial aproximada sobre el bruto, la misma de toda la familia. Ajústala a tus contratos.
A23: Jornada anual de un contrato a jornada completa | B23: 1780 | C23: h/año | D23: heredado de la Guía de la Chocolatería (supuesto declarado) | E23: Horas efectivas de un contrato a jornada completa en el ejemplo. La del convenio de Madrid no está verificada: celda verde.
A24: Horas a la semana de una jornada completa (1,0) | B24: 40 | C24: h/semana | D24: heredado de la Guía de la Chocolatería (supuesto declarado) | E24: Jornada completa de 40 horas a la semana (1,0).
A26: Salario Base Mensual por Nivel (Tabla de Ejemplo)
A27: En la columna A, el nombre del nivel tal como lo eliges en «Coste de Plantilla»; en la B, su salario base de 2025. Si tu convenio tiene otros niveles, cambia el nombre y el importe.
A28: III | B28: 1160.37 | C28: EUR/mes | D28: CUN-39 · 2025 · convenio vencido el 31-12-2025, en negociación; se aplican sus tablas mientras no se publique el nuevo | E28: Nivel III de la clase C del ejemplo. El puesto que encajas aquí es una asimilación propuesta: compruébala con tu asesor.
A29: IV | B29: 1127.42 | C29: EUR/mes | D29: CUN-39 · 2025 · convenio vencido el 31-12-2025, en negociación; se aplican sus tablas mientras no se publique el nuevo | E29: Nivel IV de la clase C del ejemplo. El puesto que encajas aquí es una asimilación propuesta: compruébala con tu asesor.
A30: V | B30: 1086.31 | C30: EUR/mes | D30: CUN-39 · 2025 · convenio vencido el 31-12-2025, en negociación; se aplican sus tablas mientras no se publique el nuevo | E30: Nivel V de la clase C del ejemplo. El puesto que encajas aquí es una asimilación propuesta: compruébala con tu asesor.
A32: Figura 1: Trabajador Nocturno del Estatuto (Art. 36.1)
A33: Empieza el periodo nocturno del Estatuto a las | B33: 22 | C33: h | D33: CUN-29 | E33: Trabajo nocturno: el realizado entre las 22:00 y las 6:00.
A34: Termina el periodo nocturno del Estatuto a las (hora del día siguiente) | B34: 6 | C34: h | D34: CUN-29 | E34: Las 6:00 de la mañana siguiente. Escribe la hora del reloj: 6.
A35: Horas diarias en ese periodo para ser trabajador nocturno | B35: 3 | C35: h/día | D35: CUN-29 | E35: Trabajador nocturno: quien realiza NORMALMENTE en ese periodo al menos tres horas de su jornada diaria.
A36: O parte de la jornada anual en ese periodo | B36: 0.33333333 | C36: de la jornada | D36: CUN-29 | E36: O quien se prevé que realice en él un tercio de su jornada anual.
A38: Figura 2: Plus de Nocturnidad del Convenio (Franjas en Verde)
A39: Franja 1 del plus: desde las | B39: 22 | C39: h | D39: CUN-40 | E39: Primera franja del convenio de ejemplo: de 22:00 a 0:00.
A40: Franja 1 del plus: hasta las (24 = medianoche) | B40: 24 | C40: h | D40: CUN-40 | E40: Medianoche se escribe 24.
A41: Franja 1 del plus: recargo sobre el salario base por hora | B41: 0.01 | C41: por hora | D41: CUN-40 | E41: De 22:00 a 0:00, cada hora lleva un 1 % más sobre el salario base.
A42: Franja 2 del plus: desde las (0 = medianoche) | B42: 0 | C42: h | D42: CUN-40 | E42: Segunda franja: de 0:00 a 8:00.
A43: Franja 2 del plus: hasta las | B43: 8 | C43: h | D43: CUN-40 | E43: Las horas de esta franja son también las de la madrugada del titular.
A44: Franja 2 del plus: recargo sobre el salario base por hora | B44: 0.25 | C44: por hora | D44: CUN-40 | E44: De 0:00 a 8:00, cada hora lleva un 25 % más sobre el salario base.
A45: Horas entre el inicio de la franja 1 y el final de la 2 para que la jornada cuente entera como nocturna | B45: 5 | C45: h/día | D45: CUN-40 | E45: Con cinco o más horas entre las 22:00 y las 8:00, toda la jornada cuenta como nocturna a efectos del plus.
...

Sheet Cuadrante por Franja
A1: Cuadrante por Franja
A2: AI Chef Pro · aichef.pro — Cómo Montar una Churrería-Chocolatería
A3: La semana tipo del plan: mínimos de cobertura, turnos persona a persona y una rejilla de medias horas que cuenta quién está y marca los huecos. No es el cuadrante de cada semana.
A4: Resumen del Cuadrante
A5: Horas de apertura con mínimo de cobertura (a la semana) | B5: =COUNTIF(S64:Y105,">0")*'Parámetros'!$B$57 -> 83.5
A6: Horas de trabajo que piden los mínimos (personas por horas) | B6: =SUM(S64:Y105)*'Parámetros'!$B$57 -> 163.5
A7: Horas de trabajo que pone tu cuadrante | B7: =SUM(F23:F58) -> 189 | C7: Más que lo que piden los mínimos: preparación de la masa antes de abrir, solapes de relevo y el cierre.
A8: Medias horas sin cubrir (huecos de cobertura) | B8: =SUM(AA64:AG105) -> 0
A9: Veredicto de cobertura | B9: =IF(ISNUMBER(B8),IF(B8>0,"HAY HUECOS: mira la rejilla de huecos, abajo","Sin huecos: el cuadrante cubre todos los mínimos"),"") -> Sin huecos: el cuadrante cubre todos los mínimos
A10: Máximo de personas en la línea a la vez | B10: =MAX(K64:Q105) -> 2
A12: Mínimos de Cobertura (1 = Ese Día se Exige)
A13: Tramo | B13: Desde (h) | C13: Hasta (h) | D13: Personas | E13: De ellas en la línea | F13: L | G13: M | H13: X | I13: J | J13: V | K13: S | L13: D
A14: Mañana entre semana: una persona fríe y otra atiende. | B14: 7 | C14: 13 | D14: 2 | E14: 1 | F14: 1 | G14: 1 | H14: 1 | I14: 1 | J14: 1 | K14: 0 | L14: 0
A15: Pico del fin de semana: dos en la línea y una en la barra. | B15: 6 | C15: 10 | D15: 3 | E15: ='Parámetros'!$B$7 -> 2 | F15: 0 | G15: 0 | H15: 0 | I15: 0 | J15: 0 | K15: 1 | L15: 1 | M15: Personas en la línea del pico: las copia «Parámetros» del libro 1 (X6).
A16: Media mañana del fin de semana. | B16: 10 | C16: 13 | D16: 2 | E16: 1 | F16: 0 | G16: 0 | H16: 0 | I16: 0 | J16: 0 | K16: 1 | L16: 1
A17: Apertura de tarde: pone la freidora a punto y atiende. | B17: 16.5 | C17: 17 | D17: 1 | E17: 1 | F17: 1 | G17: 1 | H17: 1 | I17: 1 | J17: 1 | K17: 1 | L17: 1
A18: Merienda: una persona fríe y otra atiende. | B18: 17 | C18: 21 | D18: 2 | E18: 1 | F18: 1 | G18: 1 | H18: 1 | I18: 1 | J18: 1 | K18: 1 | L18: 1
A19: Noche: quien cierra fríe y cobra. | B19: 21 | C19: 25 | D19: 1 | E19: 1 | F19: 0 | G19: 0 | H19: 0 | I19: 0 | J19: 1 | K19: 1 | L19: 0
A21: Turnos de la Semana Tipo (Persona, Día, Desde, Hasta, Puesto)
A22: Persona | B22: Día | C22: Desde (h) | D22: Hasta (h; la 1:00 es 25) | E22: Puesto (L línea, B barra) | F22: Horas | G22: Horas de 22:00 a 6:00 (ET) | H22: Horas en la franja 1 del plus | I22: Horas en la franja 2 del plus | J22: Horas en la ventana nocturna del convenio
A23: P2 | B23: L | C23: 6 | D23: 14 | E23: L | F23: =MAX(0,D23-C23) -> 8 | G23: =MAX(0,MIN(D23,'Parámetros'!$B$34+'Parámetros'!$B$48)-MAX(C23,'Parámetros'!$B$33))+MAX(0,MIN(D23,'Parámetros'!$B$34)-MAX(C23,0)) -> 0 | H23: =MAX(0,MIN(D23,'Parámetros'!$B$40)-MAX(C23,'Parámetros'!$B$39)) -> 0 | I23: =MAX(0,MIN(D23,'Parámetros'!$B$43)-MAX(C23,'Parámetros'!$B$42))+MAX(0,MIN(D23,'Parámetros'!$B$43+'Parámetros'!$B$48)-MAX(C23,'Parámetros'!$B$42+'Parámetros'!$B$48)) -> 2 | J23: =MAX(0,MIN(D23,'Parámetros'!$B$43+'Parámetros'!$B$48)-MAX(C23,'Parámetros'!$B$39))+MAX(0,MIN(D23,'Parámetros'!$B$43)-MAX(C23,'Parámetros'!$B$42)) -> 2
A24: P2 | B24: M | C24: 6 | D24: 14 | E24: L | F24: =MAX(0,D24-C24) -> 8 | G24: =MAX(0,MIN(D24,'Parámetros'!$B$34+'Parámetros'!$B$48)-MAX(C24,'Parámetros'!$B$33))+MAX(0,MIN(D24,'Parámetros'!$B$34)-MAX(C24,0)) -> 0 | H24: =MAX(0,MIN(D24,'Parámetros'!$B$40)-MAX(C24,'Parámetros'!$B$39)) -> 0 | I24: =MAX(0,MIN(D24,'Parámetros'!$B$43)-MAX(C24,'Parámetros'!$B$42))+MAX(0,MIN(D24,'Parámetros'!$B$43+'Parámetros'!$B$48)-MAX(C24,'Parámetros'!$B$42+'Parámetros'!$B$48)) -> 2 | J24: =MAX(0,MIN(D24,'Parámetros'!$B$43+'Parámetros'!$B$48)-MAX(C24,'Parámetros'!$B$39))+MAX(0,MIN(D24,'Parámetros'!$B$43)-MAX(C24,'Parámetros'!$B$42)) -> 2
A25: P2 | B25: X | C25: 6 | D25: 14 | E25: L | F25: =MAX(0,D25-C25) -> 8 | G25: =MAX(0,MIN(D25,'Parámetros'!$B$34+'Parámetros'!$B$48)-MAX(C25,'Parámetros'!$B$33))+MAX(0,MIN(D25,'Parámetros'!$B$34)-MAX(C25,0)) -> 0 | H25: =MAX(0,MIN(D25,'Parámetros'!$B$40)-MAX(C25,'Parámetros'!$B$39)) -> 0 | I25: =MAX(0,MIN(D25,'Parámetros'!$B$43)-MAX(C25,'Parámetros'!$B$42))+MAX(0,MIN(D25,'Parámetros'!$B$43+'Parámetros'!$B$48)-MAX(C25,'Parámetros'!$B$42+'Parámetros'!$B$48)) -> 2 | J25: =MAX(0,MIN(D25,'Parámetros'!$B$43+'Parámetros'!$B$48)-MAX(C25,'Parámetros'!$B$39))+MAX(0,MIN(D25,'Parámetros'!$B$43)-MAX(C25,'Parámetros'!$B$42)) -> 2
A26: P2 | B26: J | C26: 6 | D26: 14 | E26: L | F26: =MAX(0,D26-C26) -> 8 | G26: =MAX(0,MIN(D26,'Parámetros'!$B$34+'Parámetros'!$B$48)-MAX(C26,'Parámetros'!$B$33))+MAX(0,MIN(D26,'Parámetros'!$B$34)-MAX(C26,0)) -> 0 | H26: =MAX(0,MIN(D26,'Parámetros'!$B$40)-MAX(C26,'Parámetros'!$B$39)) -> 0 | I26: =MAX(0,MIN(D26,'Parámetros'!$B$43)-MAX(C26,'Parámetros'!$B$42))+MAX(0,MIN(D26,'Parámetros'!$B$43+'Parámetros'!$B$48)-MAX(C26,'Parámetros'!$B$42+'Parámetros'!$B$48)) -> 2 | J26: =MAX(0,MIN(D26,'Parámetros'!$B$43+'Parámetros'!$B$48)-MAX(C26,'Parámetros'!$B$39))+MAX(0,MIN(D26,'Parámetros'!$B$43)-MAX(C26,'Parámetros'!$B$42)) -> 2
A27: P2 | B27: V | C27: 6 | D27: 14 | E27: L | F27: =MAX(0,D27-C27) -> 8 | G27: =MAX(0,MIN(D27,'Parámetros'!$B$34+'Parámetros'!$B$48)-MAX(C27,'Parámetros'!$B$33))+MAX(0,MIN(D27,'Parámetros'!$B$34)-MAX(C27,0)) -> 0 | H27: =MAX(0,MIN(D27,'Parámetros'!$B$40)-MAX(C27,'Parámetros'!$B$39)) -> 0 | I27: =MAX(0,MIN(D27,'Parámetros'!$B$43)-MAX(C27,'Parámetros'!$B$42))+MAX(0,MIN(D27,'Parámetros'!$B$43+'Parámetros'!$B$48)-MAX(C27,'Parámetros'!$B$42+'Parámetros'!$B$48)) -> 2 | J27: =MAX(0,MIN(D27,'Parámetros'!$B$43+'Parámetros'!$B$48)-MAX(C27,'Parámetros'!$B$39))+MAX(0,MIN(D27,'Parámetros'!$B$43)-MAX(C27,'Parámetros'!$B$42)) -> 2
A28: P3 | B28: S | C28: 4.5 | D28: 12.5 | E28: L | F28: =MAX(0,D28-C28) -> 8 | G28: =MAX(0,MIN(D28,'Parámetros'!$B$34+'Parámetros'!$B$48)-MAX(C28,'Parámetros'!$B$33))+MAX(0,MIN(D28,'Parámetros'!$B$34)-MAX(C28,0)) -> 1.5 | H28: =MAX(0,MIN(D28,'Parámetros'!$B$40)-MAX(C28,'Parámetros'!$B$39)) -> 0 | I28: =MAX(0,MIN(D28,'Parámetros'!$B$43)-MAX(C28,'Parámetros'!$B$42))+MAX(0,MIN(D28,'Parámetros'!$B$43+'Parámetros'!$B$48)-MAX(C28,'Parámetros'!$B$42+'Parámetros'!$B$48)) -> 3.5 | J28: =MAX(0,MIN(D28,'Parámetros'!$B$43+'Parámetros'!$B$48)-MAX(C28,'Parámetros'!$B$39))+MAX(0,MIN(D28,'Parámetros'!$B$43)-MAX(C28,'Parámetros'!$B$42)) -> 3.5
A29: P3 | B29: D | C29: 4.5 | D29: 12.5 | E29: L | F29: =MAX(0,D29-C29) -> 8 | G29: =MAX(0,MIN(D29,'Parámetros'!$B$34+'Parámetros'!$B$48)-MAX(C29,'Parámetros'!$B$33))+MAX(0,MIN(D29,'Parámetros'!$B$34)-MAX(C29,0)) -> 1.5 | H29: =MAX(0,MIN(D29,'Parámetros'!$B$40)-MAX(C29,'Parámetros'!$B$39)) -> 0 | I29: =MAX(0,MIN(D29,'Parámetros'!$B$43)-MAX(C29,'Parámetros'!$B$42))+MAX(0,MIN(D29,'Parámetros'!$B$43+'Parámetros'!$B$48)-MAX(C29,'Parámetros'!$B$42+'Parámetros'!$B$48)) -> 3.5 | J29: =MAX(0,MIN(D29,'Parámetros'!$B$43+'Parámetros'!$B$48)-MAX(C29,'Parámetros'!$B$39))+MAX(0,MIN(D29,'Parámetros'!$B$43)-MAX(C29,'Parámetros'!$B$42)) -> 3.5
A30: P4 | B30: V | C30: 17 | D30: 21 | E30: B | F30: =MAX(0,D30-C30) -> 4 | G30: =MAX(0,MIN(D30,'Parámetros'!$B$34+'Parámetros'!$B$48)-MAX(C30,'Parámetros'!$B$33))+MAX(0,MIN(D30,'Parámetros'!$B$34)-MAX(C30,0)) -> 0 | H30: =MAX(0,MIN(D30,'Parámetros'!$B$40)-MAX(C30,'Parámetros'!$B$39)) -> 0 | I30: =MAX(0,MIN(D30,'Parámetros'!$B$43)-MAX(C30,'Parámetros'!$B$42))+MAX(0,MIN(D30,'Parámetros'!$B$43+'Parámetros'!$B$48)-MAX(C30,'Parámetros'!$B$42+'Parámetros'!$B$48)) -> 0 | J30: =MAX(0,MIN(D30,'Parámetros'!$B$43+'Parámetros'!$B$48)-MAX(C30,'Parámetros'!$B$39))+MAX(0,MIN(D30,'Parámetros'!$B$43)-MAX(C30,'Parámetros'!$B$42)) -> 0
A31: P4 | B31: V | C31: 21 | D31: 25 | E31: L | F31: =MAX(0,D31-C31) -> 4 | G31: =MAX(0,MIN(D31,'Parámetros'!$B$34+'Parámetros'!$B$48)-MAX(C31,'Parámetros'!$B$33))+MAX(0,MIN(D31,'Parámetros'!$B$34)-MAX(C31,0)) -> 3 | H31: =MAX(0,MIN(D31,'Parámetros'!$B$40)-MAX(C31,'Parámetros'!$B$39)) -> 2 | I31: =MAX(0,MIN(D31,'Parámetros'!$B$43)-MAX(C31,'Parámetros'!$B$42))+MAX(0,MIN(D31,'Parámetros'!$B$43+'Parámetros'!$B$48)-MAX(C31,'Parámetros'!$B$42+'Parámetros'!$B$48)) -> 1 | J31: =MAX(0,MIN(D31,'Parámetros'!$B$43+'Parámetros'!$B$48)-MAX(C31,'Parámetros'!$B$39))+MAX(0,MIN(D31,'Parámetros'!$B$43)-MAX(C31,'Parámetros'!$B$42)) -> 3
A32: P4 | B32: S | C32: 17 | D32: 21 | E32: B | F32: =MAX(0,D32-C32) -> 4 | G32: =MAX(0,MIN(D32,'Parámetros'!$B$34+'Parámetros'!$B$48)-MAX(C32,'Parámetros'!$B$33))+MAX(0,MIN(D32,'Parámetros'!$B$34)-MAX(C32,0)) -> 0 | H32: =MAX(0,MIN(D32,'Parámetros'!$B$40)-MAX(C32,'Parámetros'!$B$39)) -> 0 | I32: =MAX(0,MIN(D32,'Parámetros'!$B$43)-MAX(C32,'Parámetros'!$B$42))+MAX(0,MIN(D32,'Parámetros'!$B$43+'Parámetros'!$B$48)-MAX(C32,'Parámetros'!$B$42+'Parámetros'!$B$48)) -> 0 | J32: =MAX(0,MIN(D32,'Parámetros'!$B$43+'Parámetros'!$B$48)-MAX(C32,'Parámetros'!$B$39))+MAX(0,MIN(D32,'Parámetros'!$B$43)-MAX(C32,'Parámetros'!$B$42)) -> 0
A33: P4 | B33: S | C33: 21 | D33: 25 | E33: L | F33: =MAX(0,D33-C33) -> 4 | G33: =MAX(0,MIN(D33,'Parámetros'!$B$34+'Parámetros'!$B$48)-MAX(C33,'Parámetros'!$B$33))+MAX(0,MIN(D33,'Parámetros'!$B$34)-MAX(C33,0)) -> 3 | H33: =MAX(0,MIN(D33,'Parámetros'!$B$40)-MAX(C33,'Parámetros'!$B$39)) -> 2 | I33: =MAX(0,MIN(D33,'Parámetros'!$B$43)-MAX(C33,'Parámetros'!$B$42))+MAX(0,MIN(D33,'Parámetros'!$B$43+'Parámetros'!$B$48)-MAX(C33,'Parámetros'!$B$42+'Parámetros'!$B$48)) -> 1 | J33: =MAX(0,MIN(D33,'Parámetros'!$B$43+'Parámetros'!$B$48)-MAX(C33,'Parámetros'!$B$39))+MAX(0,MIN(D33,'Parámetros'!$B$43)-MAX(C33,'Parámetros'!$B$42)) -> 3
A34: P3 | B34: M | C34: 7 | D34: 13 | E34: B | F34: =MAX(0,D34-C34) -> 6 | G34: =MAX(0,MIN(D34,'Parámetros'!$B$34+'Parámetros'!$B$48)-MAX(C34,'Parámetros'!$B$33))+MAX(0,MIN(D34,'Parámetros'!$B$34)-MAX(C34,0)) -> 0 | H34: =MAX(0,MIN(D34,'Parámetros'!$B$40)-MAX(C34,'Parámetros'!$B$39)) -> 0 | I34: =MAX(0,MIN(D34,'Parámetros'!$B$43)-MAX(C34,'Parámetros'!$B$42))+MAX(0,MIN(D34,'Parámetros'!$B$43+'Parámetros'!$B$48)-MAX(C34,'Parámetros'!$B$42+'Parámetros'!$B$48)) -> 1 | J34: =MAX(0,MIN(D34,'Parámetros'!$B$43+'Parámetros'!$B$48)-MAX(C34,'Parámetros'!$B$39))+MAX(0,MIN(D34,'Parámetros'!$B$43)-MAX(C34,'Parámetros'!$B$42)) -> 1
... A58: P1 | B58: D | C58: 16 | D58: 21.5 | E58: L | F58: =MAX(0,D58-C58) -> 5.5 | G58: =MAX(0,MIN(D58,'Parámetros'!$B$34+'Parámetros'!$B$48)-MAX(C58,'Parámetros'!$B$33))+MAX(0,MIN(D58,'Parámetros'!$B$34)-MAX(C58,0)) -> 0 | H58: =MAX(0,MIN(D58,'Parámetros'!$B$40)-MAX(C58,'Parámetros'!$B$39)) -> 0 | I58: =MAX(0,MIN(D58,'Parámetros'!$B$43)-MAX(C58,'Parámetros'!$B$42))+MAX(0,MIN(D58,'Parámetros'!$B$43+'Parámetros'!$B$48)-MAX(C58,'Parámetros'!$B$42+'Parámetros'!$B$48)) -> 0 | J58: =MAX(0,MIN(D58,'Parámetros'!$B$43+'Parámetros'!$B$48)-MAX(C58,'Parámetros'!$B$39))+MAX(0,MIN(D58,'Parámetros'!$B$43)-MAX(C58,'Parámetros'!$B$42)) -> 0
A61: Quién Está en Cada Media Hora (y Dónde Falta Gente)
C62: Personas presentes | K62: De ellas en la línea | S62: Mínimo exigido (personas) | AA62: Hueco (1 = falta gente)
A63: Desde (h) | B63: Hora | C63: L | D63: M | E63: X | F63: J | G63: V | H63: S | I63: D | K63: L | L63: M | M63: X | N63: J | O63: V | P63: S | Q63: D | S63: L | T63: M | U63: X | V63: J | W63: V | X63: S | Y63: D | AA63: L | AB63: M | AC63: X | AD63: J | AE63: V | AF63: S | AG63: D
A64: ='Parámetros'!$B$56 -> 4 | B64: =IFERROR(A64/'Parámetros'!$B$48,"") -> 0.16666667 | C64: =SUMPRODUCT(--($B$23:$B$58=C$63),--($C$23:$C$58<=$A64),--($D$23:$D$58>$A64))+0 -> 0 | D64: =SUMPRODUCT(--($B$23:$B$58=D$63),--($C$23:$C$58<=$A64),--($D$23:$D$58>$A64))+0 -> 0 | E64: =SUMPRODUCT(--($B$23:$B$58=E$63),--($C$23:$C$58<=$A64),--($D$23:$D$58>$A64))+0 -> 0 | F64: =SUMPRODUCT(--($B$23:$B$58=F$63),--($C$23:$C$58<=$A64),--($D$23:$D$58>$A64))+0 -> 0 | G64: =SUMPRODUCT(--($B$23:$B$58=G$63),--($C$23:$C$58<=$A64),--($D$23:$D$58>$A64))+0 -> 0 | H64: =SUMPRODUCT(--($B$23:$B$58=H$63),--($C$23:$C$58<=$A64),--($D$23:$D$58>$A64))+0 -> 0 | I64: =SUMPRODUCT(--($B$23:$B$58=I$63),--($C$23:$C$58<=$A64),--($D$23:$D$58>$A64))+0 -> 0 | K64: =SUMPRODUCT(--($B$23:$B$58=C$63),--($C$23:$C$58<=$A64),--($D$23:$D$58>$A64),--($E$23:$E$58="L"))+0 -> 0 | L64: =SUMPRODUCT(--($B$23:$B$58=D$63),--($C$23:$C$58<=$A64),--($D$23:$D$58>$A64),--($E$23:$E$58="L"))+0 -> 0 | M64: =SUMPRODUCT(--($B$23:$B$58=E$63),--($C$23:$C$58<=$A64),--($D$23:$D$58>$A64),--($E$23:$E$58="L"))+0 -> 0 | N64: =SUMPRODUCT(--($B$23:$B$58=F$63),--($C$23:$C$58<=$A64),--($D$23:$D$58>$A64),--($E$23:$E$58="L"))+0 -> 0 | O64: =SUMPRODUCT(--($B$23:$B$58=G$63),--($C$23:$C$58<=$A64),--($D$23:$D$58>$A64),--($E$23:$E$58="L"))+0 -> 0 | P64: =SUMPRODUCT(--($B$23:$B$58=H$63),--($C$23:$C$58<=$A64),--($D$23:$D$58>$A64),--($E$23:$E$58="L"))+0 -> 0 | Q64: =SUMPRODUCT(--($B$23:$B$58=I$63),--($C$23:$C$58<=$A64),--($D$23:$D$58>$A64),--($E$23:$E$58="L"))+0 -> 0 | S64: =SUMPRODUCT($F$14:$F$19,--($B$14:$B$19<=$A64),--($C$14:$C$19>$A64),$D$14:$D$19)+0 -> 0 | T64: =SUMPRODUCT($G$14:$G$19,--($B$14:$B$19<=$A64),--($C$14:$C$19>$A64),$D$14:$D$19)+0 -> 0 | U64: =SUMPRODUCT($H$14:$H$19,--($B$14:$B$19<=$A64),--($C$14:$C$19>$A64),$D$14:$D$19)+0 -> 0 | V64: =SUMPRODUCT($I$14:$I$19,--($B$14:$B$19<=$A64),--($C$14:$C$19>$A64),$D$14:$D$19)+0 -> 0 | W64: =SUMPRODUCT($J$14:$J$19,--($B$14:$B$19<=$A64),--($C$14:$C$19>$A64),$D$14:$D$19)+0 -> 0 | X64: =SUMPRODUCT($K$14:$K$19,--($B$14:$B$19<=$A64),--($C$14:$C$19>$A64),$D$14:$D$19)+0 -> 0 | Y64: =SUMPRODUCT($L$14:$L$19,--($B$14:$B$19<=$A64),--($C$14:$C$19>$A64),$D$14:$D$19)+0 -> 0 | AA64: =IF(OR(K64<SUMPRODUCT($F$14:$F$19,--($B$14:$B$19<=$A64),--($C$14:$C$19>$A64),$E$14:$E$19),C64<S64),1,0) -> 0 | AB64: =IF(OR(L64<SUMPRODUCT($G$14:$G$19,--($B$14:$B$19<=$A64),--($C$14:$C$19>$A64),$E$14:$E$19),D64<T64),1,0) -> 0 | AC64: =IF(OR(M64<SUMPRODUCT($H$14:$H$19,--($B$14:$B$19<=$A64),--($C$14:$C$19>$A64),$E$14:$E$19),E64<U64),1,0) -> 0 | AD64: =IF(OR(N64<SUMPRODUCT($I$14:$I$19,--($B$14:$B$19<=$A64),--($C$14:$C$19>$A64),$E$14:$E$19),F64<V64),1,0) -> 0 | AE64: =IF(OR(O64<SUMPRODUCT($J$14:$J$19,--($B$14:$B$19<=$A64),--($C$14:$C$19>$A64),$E$14:$E$19),G64<W64),1,0) -> 0 | AF64: =IF(OR(P64<SUMPRODUCT($K$14:$K$19,--($B$14:$B$19<=$A64),--($C$14:$C$19>$A64),$E$14:$E$19),H64<X64),1,0) -> 0 | AG64: =IF(OR(Q64<SUMPRODUCT($L$14:$L$19,--($B$14:$B$19<=$A64),--($C$14:$C$19>$A64),$E$14:$E$19),I64<Y64),1,0) -> 0
A65: =A64+'Parámetros'!$B$57 -> 4.5 | B65: =IFERROR(A65/'Parámetros'!$B$48,"") -> 0.1875 | C65: =SUMPRODUCT(--($B$23:$B$58=C$63),--($C$23:$C$58<=$A65),--($D$23:$D$58>$A65))+0 -> 0 | D65: =SUMPRODUCT(--($B$23:$B$58=D$63),--($C$23:$C$58<=$A65),--($D$23:$D$58>$A65))+0 -> 0 | E65: =SUMPRODUCT(--($B$23:$B$58=E$63),--($C$23:$C$58<=$A65),--($D$23:$D$58>$A65))+0 -> 0 | F65: =SUMPRODUCT(--($B$23:$B$58=F$63),--($C$23:$C$58<=$A65),--($D$23:$D$58>$A65))+0 -> 0 | G65: =SUMPRODUCT(--($B$23:$B$58=G$63),--($C$23:$C$58<=$A65),--($D$23:$D$58>$A65))+0 -> 0 | H65: =SUMPRODUCT(--($B$23:$B$58=H$63),--($C$23:$C$58<=$A65),--($D$23:$D$58>$A65))+0 -> 1 | I65: =SUMPRODUCT(--($B$23:$B$58=I$63),--($C$23:$C$58<=$A65),--($D$23:$D$58>$A65))+0 -> 1 | K65: =SUMPRODUCT(--($B$23:$B$58=C$63),--($C$23:$C$58<=$A65),--($D$23:$D$58>$A65),--($E$23:$E$58="L"))+0 -> 0 | L65: =SUMPRODUCT(--($B$23:$B$58=D$63),--($C$23:$C$58<=$A65),--($D$23:$D$58>$A65),--($E$23:$E$58="L"))+0 -> 0 | M65: =SUMPRODUCT(--($B$23:$B$58=E$63),--($C$23:$C$58<=$A65),--($D$23:$D$58>$A65),--($E$23:$E$58="L"))+0 -> 0 | N65: =SUMPRODUCT(--($B$23:$B$58=F$63),--($C$23:$C$58<=$A65),--($D$23:$D$58>$A65),--($E$23:$E$58="L"))+0 -> 0 | O65: =SUMPRODUCT(--($B$23:$B$58=G$63),--($C$23:$C$58<=$A65),--($D$23:$D$58>$A65),--($E$23:$E$58="L"))+0 -> 0 | P65: =SUMPRODUCT(--($B$23:$B$58=H$63),--($C$23:$C$58<=$A65),--($D$23:$D$58>$A65),--($E$23:$E$58="L"))+0 -> 1 | Q65: =SUMPRODUCT(--($B$23:$B$58=I$63),--($C$23:$C$58<=$A65),--($D$23:$D$58>$A65),--($E$23:$E$58="L"))+0 -> 1 | S65: =SUMPRODUCT($F$14:$F$19,--($B$14:$B$19<=$A65),--($C$14:$C$19>$A65),$D$14:$D$19)+0 -> 0 | T65: =SUMPRODUCT($G$14:$G$19,--($B$14:$B$19<=$A65),--($C$14:$C$19>$A65),$D$14:$D$19)+0 -> 0 | U65: =SUMPRODUCT($H$14:$H$19,--($B$14:$B$19<=$A65),--($C$14:$C$19>$A65),$D$14:$D$19)+0 -> 0 | V65: =SUMPRODUCT($I$14:$I$19,--($B$14:$B$19<=$A65),--($C$14:$C$19>$A65),$D$14:$D$19)+0 -> 0 | W65: =SUMPRODUCT($J$14:$J$19,--($B$14:$B$19<=$A65),--($C$14:$C$19>$A65),$D$14:$D$19)+0 -> 0 | X65: =SUMPRODUCT($K$14:$K$19,--($B$14:$B$19<=$A65),--($C$14:$C$19>$A65),$D$14:$D$19)+0 -> 0 | Y65: =SUMPRODUCT($L$14:$L$19,--($B$14:$B$19<=$A65),--($C$14:$C$19>$A65),$D$14:$D$19)+0 -> 0 | AA65: =IF(OR(K65<SUMPRODUCT($F$14:$F$19,--($B$14:$B$19<=$A65),--($C$14:$C$19>$A65),$E$14:$E$19),C65<S65),1,0) -> 0 | AB65: =IF(OR(L65<SUMPRODUCT($G$14:$G$19,--($B$14:$B$19<=$A65),--($C$14:$C$19>$A65),$E$14:$E$19),D65<T65),1,0) -> 0 | AC65: =IF(OR(M65<SUMPRODUCT($H$14:$H$19,--($B$14:$B$19<=$A65),--($C$14:$C$19>$A65),$E$14:$E$19),E65<U65),1,0) -> 0 | AD65: =IF(OR(N65<SUMPRODUCT($I$14:$I$19,--($B$14:$B$19<=$A65),--($C$14:$C$19>$A65),$E$14:$E$19),F65<V65),1,0) -> 0 | AE65: =IF(OR(O65<SUMPRODUCT($J$14:$J$19,--($B$14:$B$19<=$A65),--($C$14:$C$19>$A65),$E$14:$E$19),G65<W65),1,0) -> 0 | AF65: =IF(OR(P65<SUMPRODUCT($K$14:$K$19,--($B$14:$B$19<=$A65),--($C$14:$C$19>$A65),$E$14:$E$19),H65<X65),1,0) -> 0 | AG65: =IF(OR(Q65<SUMPRODUCT($L$14:$L$19,--($B$14:$B$19<=$A65),--($C$14:$C$19>$A65),$E$14:$E$19),I65<Y65),1,0) -> 0
A66: =A65+'Parámetros'!$B$57 -> 5 | B66: =IFERROR(A66/'Parámetros'!$B$48,"") -> 0.20833333 | C66: =SUMPRODUCT(--($B$23:$B$58=C$63),--($C$23:$C$58<=$A66),--($D$23:$D$58>$A66))+0 -> 0 | D66: =SUMPRODUCT(--($B$23:$B$58=D$63),--($C$23:$C$58<=$A66),--($D$23:$D$58>$A66))+0 -> 0 | E66: =SUMPRODUCT(--($B$23:$B$58=E$63),--($C$23:$C$58<=$A66),--($D$23:$D$58>$A66))+0 -> 0 | F66: =SUMPRODUCT(--($B$23:$B$58=F$63),--($C$23:$C$58<=$A66),--($D$23:$D$58>$A66))+0 -> 0 | G66: =SUMPRODUCT(--($B$23:$B$58=G$63),--($C$23:$C$58<=$A66),--($D$23:$D$58>$A66))+0 -> 0 | H66: =SUMPRODUCT(--($B$23:$B$58=H$63),--($C$23:$C$58<=$A66),--($D$23:$D$58>$A66))+0 -> 1 | I66: =SUMPRODUCT(--($B$23:$B$58=I$63),--($C$23:$C$58<=$A66),--($D$23:$D$58>$A66))+0 -> 1 | K66: =SUMPRODUCT(--($B$23:$B$58=C$63),--($C$23:$C$58<=$A66),--($D$23:$D$58>$A66),--($E$23:$E$58="L"))+0 -> 0 | L66: =SUMPRODUCT(--($B$23:$B$58=D$63),--($C$23:$C$58<=$A66),--($D$23:$D$58>$A66),--($E$23:$E$58="L"))+0 -> 0 | M66: =SUMPRODUCT(--($B$23:$B$58=E$63),--($C$23:$C$58<=$A66),--($D$23:$D$58>$A66),--($E$23:$E$58="L"))+0 -> 0 | N66: =SUMPRODUCT(--($B$23:$B$58=F$63),--($C$23:$C$58<=$A66),--($D$23:$D$58>$A66),--($E$23:$E$58="L"))+0 -> 0 | O66: =SUMPRODUCT(--($B$23:$B$58=G$63),--($C$23:$C$58<=$A66),--($D$23:$D$58>$A66),--($E$23:$E$58="L"))+0 -> 0 | P66: =SUMPRODUCT(--($B$23:$B$58=H$63),--($C$23:$C$58<=$A66),--($D$23:$D$58>$A66),--($E$23:$E$58="L"))+0 -> 1 | Q66: =SUMPRODUCT(--($B$23:$B$58=I$63),--($C$23:$C$58<=$A66),--($D$23:$D$58>$A66),--($E$23:$E$58="L"))+0 -> 1 | S66: =SUMPRODUCT($F$14:$F$19,--($B$14:$B$19<=$A66),--($C$14:$C$19>$A66),$D$14:$D$19)+0 -> 0 | T66: =SUMPRODUCT($G$14:$G$19,--($B$14:$B$19<=$A66),--($C$14:$C$19>$A66),$D$14:$D$19)+0 -> 0 | U66: =SUMPRODUCT($H$14:$H$19,--($B$14:$B$19<=$A66),--($C$14:$C$19>$A66),$D$14:$D$19)+0 -> 0 | V66: =SUMPRODUCT($I$14:$I$19,--($B$14:$B$19<=$A66),--($C$14:$C$19>$A66),$D$14:$D$19)+0 -> 0 | W66: =SUMPRODUCT($J$14:$J$19,--($B$14:$B$19<=$A66),--($C$14:$C$19>$A66),$D$14:$D$19)+0 -> 0 | X66: =SUMPRODUCT($K$14:$K$19,--($B$14:$B$19<=$A66),--($C$14:$C$19>$A66),$D$14:$D$19)+0 -> 0 | Y66: =SUMPRODUCT($L$14:$L$19,--($B$14:$B$19<=$A66),--($C$14:$C$19>$A66),$D$14:$D$19)+0 -> 0 | AA66: =IF(OR(K66<SUMPRODUCT($F$14:$F$19,--($B$14:$B$19<=$A66),--($C$14:$C$19>$A66),$E$14:$E$19),C66<S66),1,0) -> 0 | AB66: =IF(OR(L66<SUMPRODUCT($G$14:$G$19,--($B$14:$B$19<=$A66),--($C$14:$C$19>$A66),$E$14:$E$19),D66<T66),1,0) -> 0 | AC66: =IF(OR(M66<SUMPRODUCT($H$14:$H$19,--($B$14:$B$19<=$A66),--($C$14:$C$19>$A66),$E$14:$E$19),E66<U66),1,0) -> 0 | AD66: =IF(OR(N66<SUMPRODUCT($I$14:$I$19,--($B$14:$B$19<=$A66),--($C$14:$C$19>$A66),$E$14:$E$19),F66<V66),1,0) -> 0 | AE66: =IF(OR(O66<SUMPRODUCT($J$14:$J$19,--($B$14:$B$19<=$A66),--($C$14:$C$19>$A66),$E$14:$E$19),G66<W66),1,0) -> 0 | AF66: =IF(OR(P66<SUMPRODUCT($K$14:$K$19,--($B$14:$B$19<=$A66),--($C$14:$C$19>$A66),$E$14:$E$19),H66<X66),1,0) -> 0 | AG66: =IF(OR(Q66<SUMPRODUCT($L$14:$L$19,--($B$14:$B$19<=$A66),--($C$14:$C$19>$A66),$E$14:$E$19),I66<Y66),1,0) -> 0
A67: =A66+'Parámetros'!$B$57 -> 5.5 | B67: =IFERROR(A67/'Parámetros'!$B$48,"") -> 0.22916667 | C67: =SUMPRODUCT(--($B$23:$B$58=C$63),--($C$23:$C$58<=$A67),--($D$23:$D$58>$A67))+0 -> 0 | D67: =SUMPRODUCT(--($B$23:$B$58=D$63),--($C$23:$C$58<=$A67),--($D$23:$D$58>$A67))+0 -> 0 | E67: =SUMPRODUCT(--($B$23:$B$58=E$63),--($C$23:$C$58<=$A67),--($D$23:$D$58>$A67))+0 -> 0 | F67: =SUMPRODUCT(--($B$23:$B$58=F$63),--($C$23:$C$58<=$A67),--($D$23:$D$58>$A67))+0 -> 0 | G67: =SUMPRODUCT(--($B$23:$B$58=G$63),--($C$23:$C$58<=$A67),--($D$23:$D$58>$A67))+0 -> 0 | H67: =SUMPRODUCT(--($B$23:$B$58=H$63),--($C$23:$C$58<=$A67),--($D$23:$D$58>$A67))+0 -> 1 | I67: =SUMPRODUCT(--($B$23:$B$58=I$63),--($C$23:$C$58<=$A67),--($D$23:$D$58>$A67))+0 -> 1 | K67: =SUMPRODUCT(--($B$23:$B$58=C$63),--($C$23:$C$58<=$A67),--($D$23:$D$58>$A67),--($E$23:$E$58="L"))+0 -> 0 | L67: =SUMPRODUCT(--($B$23:$B$58=D$63),--($C$23:$C$58<=$A67),--($D$23:$D$58>$A67),--($E$23:$E$58="L"))+0 -> 0 | M67: =SUMPRODUCT(--($B$23:$B$58=E$63),--($C$23:$C$58<=$A67),--($D$23:$D$58>$A67),--($E$23:$E$58="L"))+0 -> 0 | N67: =SUMPRODUCT(--($B$23:$B$58=F$63),--($C$23:$C$58<=$A67),--($D$23:$D$58>$A67),--($E$23:$E$58="L"))+0 -> 0 | O67: =SUMPRODUCT(--($B$23:$B$58=G$63),--($C$23:$C$58<=$A67),--($D$23:$D$58>$A67),--($E$23:$E$58="L"))+0 -> 0 | P67: =SUMPRODUCT(--($B$23:$B$58=H$63),--($C$23:$C$58<=$A67),--($D$23:$D$58>$A67),--($E$23:$E$58="L"))+0 -> 1 | Q67: =SUMPRODUCT(--($B$23:$B$58=I$63),--($C$23:$C$58<=$A67),--($D$23:$D$58>$A67),--($E$23:$E$58="L"))+0 -> 1 | S67: =SUMPRODUCT($F$14:$F$19,--($B$14:$B$19<=$A67),--($C$14:$C$19>$A67),$D$14:$D$19)+0 -> 0 | T67: =SUMPRODUCT($G$14:$G$19,--($B$14:$B$19<=$A67),--($C$14:$C$19>$A67),$D$14:$D$19)+0 -> 0 | U67: =SUMPRODUCT($H$14:$H$19,--($B$14:$B$19<=$A67),--($C$14:$C$19>$A67),$D$14:$D$19)+0 -> 0 | V67: =SUMPRODUCT($I$14:$I$19,--($B$14:$B$19<=$A67),--($C$14:$C$19>$A67),$D$14:$D$19)+0 -> 0 | W67: =SUMPRODUCT($J$14:$J$19,--($B$14:$B$19<=$A67),--($C$14:$C$19>$A67),$D$14:$D$19)+0 -> 0 | X67: =SUMPRODUCT($K$14:$K$19,--($B$14:$B$19<=$A67),--($C$14:$C$19>$A67),$D$14:$D$19)+0 -> 0 | Y67: =SUMPRODUCT($L$14:$L$19,--($B$14:$B$19<=$A67),--($C$14:$C$19>$A67),$D$14:$D$19)+0 -> 0 | AA67: =IF(OR(K67<SUMPRODUCT($F$14:$F$19,--($B$14:$B$19<=$A67),--($C$14:$C$19>$A67),$E$14:$E$19),C67<S67),1,0) -> 0 | AB67: =IF(OR(L67<SUMPRODUCT($G$14:$G$19,--($B$14:$B$19<=$A67),--($C$14:$C$19>$A67),$E$14:$E$19),D67<T67),1,0) -> 0 | AC67: =IF(OR(M67<SUMPRODUCT($H$14:$H$19,--($B$14:$B$19<=$A67),--($C$14:$C$19>$A67),$E$14:$E$19),E67<U67),1,0) -> 0 | AD67: =IF(OR(N67<SUMPRODUCT($I$14:$I$19,--($B$14:$B$19<=$A67),--($C$14:$C$19>$A67),$E$14:$E$19),F67<V67),1,0) -> 0 | AE67: =IF(OR(O67<SUMPRODUCT($J$14:$J$19,--($B$14:$B$19<=$A67),--($C$14:$C$19>$A67),$E$14:$E$19),G67<W67),1,0) -> 0 | AF67: =IF(OR(P67<SUMPRODUCT($K$14:$K$19,--($B$14:$B$19<=$A67),--($C$14:$C$19>$A67),$E$14:$E$19),H67<X67),1,0) -> 0 | AG67: =IF(OR(Q67<SUMPRODUCT($L$14:$L$19,--($B$14:$B$19<=$A67),--($C$14:$C$19>$A67),$E$14:$E$19),I67<Y67),1,0) -> 0
...

Sheet Nocturnidad ET y Convenio
A1: Nocturnidad ET y Convenio
A2: AI Chef Pro · aichef.pro — Cómo Montar una Churrería-Chocolatería
A3: Dos columnas por persona: la del Estatuto (¿es trabajador nocturno?) y la del convenio (¿cuánto plus cobra?). Son dos figuras distintas y aquí no se mezclan.
C6: FIGURA 1 · Trabajador nocturno del Estatuto (art. 36.1): de 22:00 a 6:00 | H6: FIGURA 2 · Plus de nocturnidad del convenio de ejemplo
A7: Persona | B7: Puesto | C7: Horas de 22:00 a 6:00 a la semana | D7: Días que trabaja | E7: Días con 3 h o más en ese periodo | F7: Parte de su jornada en ese periodo | G7: ¿Trabajador nocturno? (ET) | H7: Horas en la franja 1 a la semana | I7: Horas en la franja 2 a la semana | J7: Días con jornada entera nocturna | K7: Plus a la semana | L7: Plus al año | M7: Qué le toca por la figura 1 | N7: Aviso de la figura 2
A8: ='Coste de Plantilla'!$A$9 -> P1 | B8: ='Coste de Plantilla'!$B$9 -> Titular (encargado/a) | C8: =SUM(C28:I28) -> 0 | D8: =COUNTIF(C21:I21,">0") -> 7 | E8: =COUNTIF(C28:I28,">="&'Parámetros'!$B$35) -> 0 | F8: =IFERROR(C8/'Coste de Plantilla'!$G$9,"") -> 0 | G8: =IF('Coste de Plantilla'!$E$9="sí","No aplica (autónomo)",IF(AND(ISNUMBER(D8),ISNUMBER(E8),ISNUMBER(F8)),IF(AND(E8=0,F8<'Parámetros'!$B$36),"no",IF(OR(AND(D8>0,E8=D8),F8>='Parámetros'!$B$36),"sí","revísalo con tu asesor")),"")) -> No aplica (autónomo) | H8: =SUMPRODUCT(--('Cuadrante por Franja'!$A$23:$A$58=$A8),'Cuadrante por Franja'!$H$23:$H$58)+0 -> 0 | I8: =SUMPRODUCT(--('Cuadrante por Franja'!$A$23:$A$58=$A8),'Cuadrante por Franja'!$I$23:$I$58)+0 -> 5 | J8: =COUNTIF(C35:I35,">="&'Parámetros'!$B$45) -> 0 | K8: =IF('Coste de Plantilla'!$E$9="sí",0,(H8*'Parámetros'!$B$41+I8*'Parámetros'!$B$44)*'Coste de Plantilla'!$L$9) -> 0 | L8: =K8*'Parámetros'!$B$53 -> 0 | M8: =IF('Coste de Plantilla'!$E$9="sí","Titular autónomo: ni las dos figuras ni el plus le alcanzan; sus horas, en «Horas del Titular»",IF(G8="sí","Trabajador nocturno: no puede hacer horas extra y su jornada no pasa de ocho horas diarias de media",IF(G8="no","No es trabajador nocturno: el Estatuto no le pone esos límites; el plus del convenio se paga igual",IF(G8="revísalo con tu asesor","Revísalo con tu asesor: no llega a tres horas todos los días, pero hay días en que sí; el «normalmente» del artículo no está interpretado","")))) -> Titular autónomo: ni las dos figuras ni el plus le alcanzan; sus horas, en «Horas del Titular» | N8: =IF(AND(ISNUMBER(J8),J8>0),"Hay días con la jornada entera nocturna según el convenio: este libro paga el plus hora a hora; revísalo con tu asesor","")
A9: ='Coste de Plantilla'!$A$10 -> P2 | B9: ='Coste de Plantilla'!$B$10 -> Churrero/a 1 | C9: =SUM(C29:I29) -> 0 | D9: =COUNTIF(C22:I22,">0") -> 5 | E9: =COUNTIF(C29:I29,">="&'Parámetros'!$B$35) -> 0 | F9: =IFERROR(C9/'Coste de Plantilla'!$G$10,"") -> 0 | G9: =IF('Coste de Plantilla'!$E$10="sí","No aplica (autónomo)",IF(AND(ISNUMBER(D9),ISNUMBER(E9),ISNUMBER(F9)),IF(AND(E9=0,F9<'Parámetros'!$B$36),"no",IF(OR(AND(D9>0,E9=D9),F9>='Parámetros'!$B$36),"sí","revísalo con tu asesor")),"")) -> no | H9: =SUMPRODUCT(--('Cuadrante por Franja'!$A$23:$A$58=$A9),'Cuadrante por Franja'!$H$23:$H$58)+0 -> 0 | I9: =SUMPRODUCT(--('Cuadrante por Franja'!$A$23:$A$58=$A9),'Cuadrante por Franja'!$I$23:$I$58)+0 -> 10 | J9: =COUNTIF(C36:I36,">="&'Parámetros'!$B$45) -> 0 | K9: =IF('Coste de Plantilla'!$E$10="sí",0,(H9*'Parámetros'!$B$41+I9*'Parámetros'!$B$44)*'Coste de Plantilla'!$L$10) -> 22.816264 | L9: =K9*'Parámetros'!$B$53 -> 1015.3237 | M9: =IF('Coste de Plantilla'!$E$10="sí","Titular autónomo: ni las dos figuras ni el plus le alcanzan; sus horas, en «Horas del Titular»",IF(G9="sí","Trabajador nocturno: no puede hacer horas extra y su jornada no pasa de ocho horas diarias de media",IF(G9="no","No es trabajador nocturno: el Estatuto no le pone esos límites; el plus del convenio se paga igual",IF(G9="revísalo con tu asesor","Revísalo con tu asesor: no llega a tres horas todos los días, pero hay días en que sí; el «normalmente» del artículo no está interpretado","")))) -> No es trabajador nocturno: el Estatuto no le pone esos límites; el plus del convenio se paga igual | N9: =IF(AND(ISNUMBER(J9),J9>0),"Hay días con la jornada entera nocturna según el convenio: este libro paga el plus hora a hora; revísalo con tu asesor","")
A10: ='Coste de Plantilla'!$A$11 -> P3 | B10: ='Coste de Plantilla'!$B$11 -> Churrero/a 2 | C10: =SUM(C30:I30) -> 3 | D10: =COUNTIF(C23:I23,">0") -> 6 | E10: =COUNTIF(C30:I30,">="&'Parámetros'!$B$35) -> 0 | F10: =IFERROR(C10/'Coste de Plantilla'!$G$11,"") -> 0.075 | G10: =IF('Coste de Plantilla'!$E$11="sí","No aplica (autónomo)",IF(AND(ISNUMBER(D10),ISNUMBER(E10),ISNUMBER(F10)),IF(AND(E10=0,F10<'Parámetros'!$B$36),"no",IF(OR(AND(D10>0,E10=D10),F10>='Parámetros'!$B$36),"sí","revísalo con tu asesor")),"")) -> no | H10: =SUMPRODUCT(--('Cuadrante por Franja'!$A$23:$A$58=$A10),'Cuadrante por Franja'!$H$23:$H$58)+0 -> 0 | I10: =SUMPRODUCT(--('Cuadrante por Franja'!$A$23:$A$58=$A10),'Cuadrante por Franja'!$I$23:$I$58)+0 -> 11 | J10: =COUNTIF(C37:I37,">="&'Parámetros'!$B$45) -> 0 | K10: =IF('Coste de Plantilla'!$E$11="sí",0,(H10*'Parámetros'!$B$41+I10*'Parámetros'!$B$44)*'Coste de Plantilla'!$L$11) -> 25.09789 | L10: =K10*'Parámetros'!$B$53 -> 1116.8561 | M10: =IF('Coste de Plantilla'!$E$11="sí","Titular autónomo: ni las dos figuras ni el plus le alcanzan; sus horas, en «Horas del Titular»",IF(G10="sí","Trabajador nocturno: no puede hacer horas extra y su jornada no pasa de ocho horas diarias de media",IF(G10="no","No es trabajador nocturno: el Estatuto no le pone esos límites; el plus del convenio se paga igual",IF(G10="revísalo con tu asesor","Revísalo con tu asesor: no llega a tres horas todos los días, pero hay días en que sí; el «normalmente» del artículo no está interpretado","")))) -> No es trabajador nocturno: el Estatuto no le pone esos límites; el plus del convenio se paga igual | N10: =IF(AND(ISNUMBER(J10),J10>0),"Hay días con la jornada entera nocturna según el convenio: este libro paga el plus hora a hora; revísalo con tu asesor","")
A11: ='Coste de Plantilla'!$A$12 -> P4 | B11: ='Coste de Plantilla'!$B$12 -> Camarero/a de sala | C11: =SUM(C31:I31) -> 6 | D11: =COUNTIF(C24:I24,">0") -> 6 | E11: =COUNTIF(C31:I31,">="&'Parámetros'!$B$35) -> 2 | F11: =IFERROR(C11/'Coste de Plantilla'!$G$12,"") -> 0.16216216 | G11: =IF('Coste de Plantilla'!$E$12="sí","No aplica (autónomo)",IF(AND(ISNUMBER(D11),ISNUMBER(E11),ISNUMBER(F11)),IF(AND(E11=0,F11<'Parámetros'!$B$36),"no",IF(OR(AND(D11>0,E11=D11),F11>='Parámetros'!$B$36),"sí","revísalo con tu asesor")),"")) -> revísalo con tu asesor | H11: =SUMPRODUCT(--('Cuadrante por Franja'!$A$23:$A$58=$A11),'Cuadrante por Franja'!$H$23:$H$58)+0 -> 4 | I11: =SUMPRODUCT(--('Cuadrante por Franja'!$A$23:$A$58=$A11),'Cuadrante por Franja'!$I$23:$I$58)+0 -> 2 | J11: =COUNTIF(C38:I38,">="&'Parámetros'!$B$45) -> 0 | K11: =IF('Coste de Plantilla'!$E$12="sí",0,(H11*'Parámetros'!$B$41+I11*'Parámetros'!$B$44)*'Coste de Plantilla'!$L$12) -> 4.7883681 | L11: =K11*'Parámetros'!$B$53 -> 213.08238 | M11: =IF('Coste de Plantilla'!$E$12="sí","Titular autónomo: ni las dos figuras ni el plus le alcanzan; sus horas, en «Horas del Titular»",IF(G11="sí","Trabajador nocturno: no puede hacer horas extra y su jornada no pasa de ocho horas diarias de media",IF(G11="no","No es trabajador nocturno: el Estatuto no le pone esos límites; el plus del convenio se paga igual",IF(G11="revísalo con tu asesor","Revísalo con tu asesor: no llega a tres horas todos los días, pero hay días en que sí; el «normalmente» del artículo no está interpretado","")))) -> Revísalo con tu asesor: no llega a tres horas todos los días, pero hay días en que sí; el «normalmente» del artículo no está interpretado | N11: =IF(AND(ISNUMBER(J11),J11>0),"Hay días con la jornada entera nocturna según el convenio: este libro paga el plus hora a hora; revísalo con tu asesor","")
A12: ='Coste de Plantilla'!$A$13 -> P5 | B12: ='Coste de Plantilla'!$B$13 -> Refuerzo de fin de semana | C12: =SUM(C32:I32) -> 0 | D12: =COUNTIF(C25:I25,">0") -> 3 | E12: =COUNTIF(C32:I32,">="&'Parámetros'!$B$35) -> 0 | F12: =IFERROR(C12/'Coste de Plantilla'!$G$13,"") -> 0 | G12: =IF('Coste de Plantilla'!$E$13="sí","No aplica (autónomo)",IF(AND(ISNUMBER(D12),ISNUMBER(E12),ISNUMBER(F12)),IF(AND(E12=0,F12<'Parámetros'!$B$36),"no",IF(OR(AND(D12>0,E12=D12),F12>='Parámetros'!$B$36),"sí","revísalo con tu asesor")),"")) -> no | H12: =SUMPRODUCT(--('Cuadrante por Franja'!$A$23:$A$58=$A12),'Cuadrante por Franja'!$H$23:$H$58)+0 -> 0 | I12: =SUMPRODUCT(--('Cuadrante por Franja'!$A$23:$A$58=$A12),'Cuadrante por Franja'!$I$23:$I$58)+0 -> 4 | J12: =COUNTIF(C39:I39,">="&'Parámetros'!$B$45) -> 0 | K12: =IF('Coste de Plantilla'!$E$13="sí",0,(H12*'Parámetros'!$B$41+I12*'Parámetros'!$B$44)*'Coste de Plantilla'!$L$13) -> 8.5440112 | L12: =K12*'Parámetros'!$B$53 -> 380.2085 | M12: =IF('Coste de Plantilla'!$E$13="sí","Titular autónomo: ni las dos figuras ni el plus le alcanzan; sus horas, en «Horas del Titular»",IF(G12="sí","Trabajador nocturno: no puede hacer horas extra y su jornada no pasa de ocho horas diarias de media",IF(G12="no","No es trabajador nocturno: el Estatuto no le pone esos límites; el plus del convenio se paga igual",IF(G12="revísalo con tu asesor","Revísalo con tu asesor: no llega a tres horas todos los días, pero hay días en que sí; el «normalmente» del artículo no está interpretado","")))) -> No es trabajador nocturno: el Estatuto no le pone esos límites; el plus del convenio se paga igual | N12: =IF(AND(ISNUMBER(J12),J12>0),"Hay días con la jornada entera nocturna según el convenio: este libro paga el plus hora a hora; revísalo con tu asesor","")
A14: Figura 1. Las horas del periodo nocturno del Estatuto se cuentan día a día en la tabla de abajo. «Sí» si todos los días que trabaja hace tres horas o más en ese periodo, o si ese periodo es un tercio de su jornada o más; «no» si ningún día llega a tres y no llega al tercio; «revísalo con tu asesor» en medio.
A15: Figura 2. El plus se paga por hora sobre el salario base por hora del puesto («Coste de Plantilla», columna L), con el recargo de cada franja. El titular no lo cobra: es autónomo. Si tu convenio paga la jornada entera cuando pasa de su umbral, el aviso de la columna N te lo dice.
A16: Ejemplo de El Molinete: el turno de las 4:30 del fin de semana tiene hora y media en el periodo del Estatuto (no es trabajador nocturno) y tres horas y media con plus. Quien cierra el viernes y el sábado hasta la 1:00 tiene tres horas dos días por semana: «revísalo con tu asesor».
A19: Horas por Día (Lo que Usan las Columnas de Arriba)
A20: Persona | B20: Horas trabajadas por día | C20: L | D20: M | E20: X | F20: J | G20: V | H20: S | I20: D
A21: ='Coste de Plantilla'!$A$9 -> P1 | C21: =SUMPRODUCT(--('Cuadrante por Franja'!$A$23:$A$58=$A21),--('Cuadrante por Franja'!$B$23:$B$58=C$20),'Cuadrante por Franja'!$F$23:$F$58)+0 -> 11.5 | D21: =SUMPRODUCT(--('Cuadrante por Franja'!$A$23:$A$58=$A21),--('Cuadrante por Franja'!$B$23:$B$58=D$20),'Cuadrante por Franja'!$F$23:$F$58)+0 -> 5.5 | E21: =SUMPRODUCT(--('Cuadrante por Franja'!$A$23:$A$58=$A21),--('Cuadrante por Franja'!$B$23:$B$58=E$20),'Cuadrante por Franja'!$F$23:$F$58)+0 -> 5.5 | F21: =SUMPRODUCT(--('Cuadrante por Franja'!$A$23:$A$58=$A21),--('Cuadrante por Franja'!$B$23:$B$58=F$20),'Cuadrante por Franja'!$F$23:$F$58)+0 -> 5.5 | G21: =SUMPRODUCT(--('Cuadrante por Franja'!$A$23:$A$58=$A21),--('Cuadrante por Franja'!$B$23:$B$58=G$20),'Cuadrante por Franja'!$F$23:$F$58)+0 -> 5 | H21: =SUMPRODUCT(--('Cuadrante por Franja'!$A$23:$A$58=$A21),--('Cuadrante por Franja'!$B$23:$B$58=H$20),'Cuadrante por Franja'!$F$23:$F$58)+0 -> 9.5 | I21: =SUMPRODUCT(--('Cuadrante por Franja'!$A$23:$A$58=$A21),--('Cuadrante por Franja'!$B$23:$B$58=I$20),'Cuadrante por Franja'!$F$23:$F$58)+0 -> 10
A22: ='Coste de Plantilla'!$A$10 -> P2 | C22: =SUMPRODUCT(--('Cuadrante por Franja'!$A$23:$A$58=$A22),--('Cuadrante por Franja'!$B$23:$B$58=C$20),'Cuadrante por Franja'!$F$23:$F$58)+0 -> 8 | D22: =SUMPRODUCT(--('Cuadrante por Franja'!$A$23:$A$58=$A22),--('Cuadrante por Franja'!$B$23:$B$58=D$20),'Cuadrante por Franja'!$F$23:$F$58)+0 -> 8 | E22: =SUMPRODUCT(--('Cuadrante por Franja'!$A$23:$A$58=$A22),--('Cuadrante por Franja'!$B$23:$B$58=E$20),'Cuadrante por Franja'!$F$23:$F$58)+0 -> 8 | F22: =SUMPRODUCT(--('Cuadrante por Franja'!$A$23:$A$58=$A22),--('Cuadrante por Franja'!$B$23:$B$58=F$20),'Cuadrante por Franja'!$F$23:$F$58)+0 -> 8 | G22: =SUMPRODUCT(--('Cuadrante por Franja'!$A$23:$A$58=$A22),--('Cuadrante por Franja'!$B$23:$B$58=G$20),'Cuadrante por Franja'!$F$23:$F$58)+0 -> 8 | H22: =SUMPRODUCT(--('Cuadrante por Franja'!$A$23:$A$58=$A22),--('Cuadrante por Franja'!$B$23:$B$58=H$20),'Cuadrante por Franja'!$F$23:$F$58)+0 -> 0 | I22: =SUMPRODUCT(--('Cuadrante por Franja'!$A$23:$A$58=$A22),--('Cuadrante por Franja'!$B$23:$B$58=I$20),'Cuadrante por Franja'!$F$23:$F$58)+0 -> 0
A23: ='Coste de Plantilla'!$A$11 -> P3 | C23: =SUMPRODUCT(--('Cuadrante por Franja'!$A$23:$A$58=$A23),--('Cuadrante por Franja'!$B$23:$B$58=C$20),'Cuadrante por Franja'!$F$23:$F$58)+0 -> 0 | D23: =SUMPRODUCT(--('Cuadrante por Franja'!$A$23:$A$58=$A23),--('Cuadrante por Franja'!$B$23:$B$58=D$20),'Cuadrante por Franja'!$F$23:$F$58)+0 -> 6 | E23: =SUMPRODUCT(--('Cuadrante por Franja'!$A$23:$A$58=$A23),--('Cuadrante por Franja'!$B$23:$B$58=E$20),'Cuadrante por Franja'!$F$23:$F$58)+0 -> 6 | F23: =SUMPRODUCT(--('Cuadrante por Franja'!$A$23:$A$58=$A23),--('Cuadrante por Franja'!$B$23:$B$58=F$20),'Cuadrante por Franja'!$F$23:$F$58)+0 -> 6 | G23: =SUMPRODUCT(--('Cuadrante por Franja'!$A$23:$A$58=$A23),--('Cuadrante por Franja'!$B$23:$B$58=G$20),'Cuadrante por Franja'!$F$23:$F$58)+0 -> 6 | H23: =SUMPRODUCT(--('Cuadrante por Franja'!$A$23:$A$58=$A23),--('Cuadrante por Franja'!$B$23:$B$58=H$20),'Cuadrante por Franja'!$F$23:$F$58)+0 -> 8 | I23: =SUMPRODUCT(--('Cuadrante por Franja'!$A$23:$A$58=$A23),--('Cuadrante por Franja'!$B$23:$B$58=I$20),'Cuadrante por Franja'!$F$23:$F$58)+0 -> 8
A24: ='Coste de Plantilla'!$A$12 -> P4 | C24: =SUMPRODUCT(--('Cuadrante por Franja'!$A$23:$A$58=$A24),--('Cuadrante por Franja'!$B$23:$B$58=C$20),'Cuadrante por Franja'!$F$23:$F$58)+0 -> 0 | D24: =SUMPRODUCT(--('Cuadrante por Franja'!$A$23:$A$58=$A24),--('Cuadrante por Franja'!$B$23:$B$58=D$20),'Cuadrante por Franja'!$F$23:$F$58)+0 -> 5.5 | E24: =SUMPRODUCT(--('Cuadrante por Franja'!$A$23:$A$58=$A24),--('Cuadrante por Franja'!$B$23:$B$58=E$20),'Cuadrante por Franja'!$F$23:$F$58)+0 -> 5.5 | F24: =SUMPRODUCT(--('Cuadrante por Franja'!$A$23:$A$58=$A24),--('Cuadrante por Franja'!$B$23:$B$58=F$20),'Cuadrante por Franja'!$F$23:$F$58)+0 -> 5.5 | G24: =SUMPRODUCT(--('Cuadrante por Franja'!$A$23:$A$58=$A24),--('Cuadrante por Franja'!$B$23:$B$58=G$20),'Cuadrante por Franja'!$F$23:$F$58)+0 -> 8 | H24: =SUMPRODUCT(--('Cuadrante por Franja'!$A$23:$A$58=$A24),--('Cuadrante por Franja'!$B$23:$B$58=H$20),'Cuadrante por Franja'!$F$23:$F$58)+0 -> 8 | I24: =SUMPRODUCT(--('Cuadrante por Franja'!$A$23:$A$58=$A24),--('Cuadrante por Franja'!$B$23:$B$58=I$20),'Cuadrante por Franja'!$F$23:$F$58)+0 -> 4.5
A25: ='Coste de Plantilla'!$A$13 -> P5 | C25: =SUMPRODUCT(--('Cuadrante por Franja'!$A$23:$A$58=$A25),--('Cuadrante por Franja'!$B$23:$B$58=C$20),'Cuadrante por Franja'!$F$23:$F$58)+0 -> 5.5 | D25: =SUMPRODUCT(--('Cuadrante por Franja'!$A$23:$A$58=$A25),--('Cuadrante por Franja'!$B$23:$B$58=D$20),'Cuadrante por Franja'!$F$23:$F$58)+0 -> 0 | E25: =SUMPRODUCT(--('Cuadrante por Franja'!$A$23:$A$58=$A25),--('Cuadrante por Franja'!$B$23:$B$58=E$20),'Cuadrante por Franja'!$F$23:$F$58)+0 -> 0 | F25: =SUMPRODUCT(--('Cuadrante por Franja'!$A$23:$A$58=$A25),--('Cuadrante por Franja'!$B$23:$B$58=F$20),'Cuadrante por Franja'!$F$23:$F$58)+0 -> 0 | G25: =SUMPRODUCT(--('Cuadrante por Franja'!$A$23:$A$58=$A25),--('Cuadrante por Franja'!$B$23:$B$58=G$20),'Cuadrante por Franja'!$F$23:$F$58)+0 -> 0 | H25: =SUMPRODUCT(--('Cuadrante por Franja'!$A$23:$A$58=$A25),--('Cuadrante por Franja'!$B$23:$B$58=H$20),'Cuadrante por Franja'!$F$23:$F$58)+0 -> 7 | I25: =SUMPRODUCT(--('Cuadrante por Franja'!$A$23:$A$58=$A25),--('Cuadrante por Franja'!$B$23:$B$58=I$20),'Cuadrante por Franja'!$F$23:$F$58)+0 -> 7
A27: Persona | B27: Horas de 22:00 a 6:00 por día (Estatuto) | C27: L | D27: M | E27: X | F27: J | G27: V | H27: S | I27: D
A28: ='Coste de Plantilla'!$A$9 -> P1 | C28: =SUMPRODUCT(--('Cuadrante por Franja'!$A$23:$A$58=$A28),--('Cuadrante por Franja'!$B$23:$B$58=C$27),'Cuadrante por Franja'!$G$23:$G$58)+0 -> 0 | D28: =SUMPRODUCT(--('Cuadrante por Franja'!$A$23:$A$58=$A28),--('Cuadrante por Franja'!$B$23:$B$58=D$27),'Cuadrante por Franja'!$G$23:$G$58)+0 -> 0 | E28: =SUMPRODUCT(--('Cuadrante por Franja'!$A$23:$A$58=$A28),--('Cuadrante por Franja'!$B$23:$B$58=E$27),'Cuadrante por Franja'!$G$23:$G$58)+0 -> 0 | F28: =SUMPRODUCT(--('Cuadrante por Franja'!$A$23:$A$58=$A28),--('Cuadrante por Franja'!$B$23:$B$58=F$27),'Cuadrante por Franja'!$G$23:$G$58)+0 -> 0 | G28: =SUMPRODUCT(--('Cuadrante por Franja'!$A$23:$A$58=$A28),--('Cuadrante por Franja'!$B$23:$B$58=G$27),'Cuadrante por Franja'!$G$23:$G$58)+0 -> 0 | H28: =SUMPRODUCT(--('Cuadrante por Franja'!$A$23:$A$58=$A28),--('Cuadrante por Franja'!$B$23:$B$58=H$27),'Cuadrante por Franja'!$G$23:$G$58)+0 -> 0 | I28: =SUMPRODUCT(--('Cuadrante por Franja'!$A$23:$A$58=$A28),--('Cuadrante por Franja'!$B$23:$B$58=I$27),'Cuadrante por Franja'!$G$23:$G$58)+0 -> 0
A29: ='Coste de Plantilla'!$A$10 -> P2 | C29: =SUMPRODUCT(--('Cuadrante por Franja'!$A$23:$A$58=$A29),--('Cuadrante por Franja'!$B$23:$B$58=C$27),'Cuadrante por Franja'!$G$23:$G$58)+0 -> 0 | D29: =SUMPRODUCT(--('Cuadrante por Franja'!$A$23:$A$58=$A29),--('Cuadrante por Franja'!$B$23:$B$58=D$27),'Cuadrante por Franja'!$G$23:$G$58)+0 -> 0 | E29: =SUMPRODUCT(--('Cuadrante por Franja'!$A$23:$A$58=$A29),--('Cuadrante por Franja'!$B$23:$B$58=E$27),'Cuadrante por Franja'!$G$23:$G$58)+0 -> 0 | F29: =SUMPRODUCT(--('Cuadrante por Franja'!$A$23:$A$58=$A29),--('Cuadrante por Franja'!$B$23:$B$58=F$27),'Cuadrante por Franja'!$G$23:$G$58)+0 -> 0 | G29: =SUMPRODUCT(--('Cuadrante por Franja'!$A$23:$A$58=$A29),--('Cuadrante por Franja'!$B$23:$B$58=G$27),'Cuadrante por Franja'!$G$23:$G$58)+0 -> 0 | H29: =SUMPRODUCT(--('Cuadrante por Franja'!$A$23:$A$58=$A29),--('Cuadrante por Franja'!$B$23:$B$58=H$27),'Cuadrante por Franja'!$G$23:$G$58)+0 -> 0 | I29: =SUMPRODUCT(--('Cuadrante por Franja'!$A$23:$A$58=$A29),--('Cuadrante por Franja'!$B$23:$B$58=I$27),'Cuadrante por Franja'!$G$23:$G$58)+0 -> 0
A30: ='Coste de Plantilla'!$A$11 -> P3 | C30: =SUMPRODUCT(--('Cuadrante por Franja'!$A$23:$A$58=$A30),--('Cuadrante por Franja'!$B$23:$B$58=C$27),'Cuadrante por Franja'!$G$23:$G$58)+0 -> 0 | D30: =SUMPRODUCT(--('Cuadrante por Franja'!$A$23:$A$58=$A30),--('Cuadrante por Franja'!$B$23:$B$58=D$27),'Cuadrante por Franja'!$G$23:$G$58)+0 -> 0 | E30: =SUMPRODUCT(--('Cuadrante por Franja'!$A$23:$A$58=$A30),--('Cuadrante por Franja'!$B$23:$B$58=E$27),'Cuadrante por Franja'!$G$23:$G$58)+0 -> 0 | F30: =SUMPRODUCT(--('Cuadrante por Franja'!$A$23:$A$58=$A30),--('Cuadrante por Franja'!$B$23:$B$58=F$27),'Cuadrante por Franja'!$G$23:$G$58)+0 -> 0 | G30: =SUMPRODUCT(--('Cuadrante por Franja'!$A$23:$A$58=$A30),--('Cuadrante por Franja'!$B$23:$B$58=G$27),'Cuadrante por Franja'!$G$23:$G$58)+0 -> 0 | H30: =SUMPRODUCT(--('Cuadrante por Franja'!$A$23:$A$58=$A30),--('Cuadrante por Franja'!$B$23:$B$58=H$27),'Cuadrante por Franja'!$G$23:$G$58)+0 -> 1.5 | I30: =SUMPRODUCT(--('Cuadrante por Franja'!$A$23:$A$58=$A30),--('Cuadrante por Franja'!$B$23:$B$58=I$27),'Cuadrante por Franja'!$G$23:$G$58)+0 -> 1.5
A31: ='Coste de Plantilla'!$A$12 -> P4 | C31: =SUMPRODUCT(--('Cuadrante por Franja'!$A$23:$A$58=$A31),--('Cuadrante por Franja'!$B$23:$B$58=C$27),'Cuadrante por Franja'!$G$23:$G$58)+0 -> 0 | D31: =SUMPRODUCT(--('Cuadrante por Franja'!$A$23:$A$58=$A31),--('Cuadrante por Franja'!$B$23:$B$58=D$27),'Cuadrante por Franja'!$G$23:$G$58)+0 -> 0 | E31: =SUMPRODUCT(--('Cuadrante por Franja'!$A$23:$A$58=$A31),--('Cuadrante por Franja'!$B$23:$B$58=E$27),'Cuadrante por Franja'!$G$23:$G$58)+0 -> 0 | F31: =SUMPRODUCT(--('Cuadrante por Franja'!$A$23:$A$58=$A31),--('Cuadrante por Franja'!$B$23:$B$58=F$27),'Cuadrante por Franja'!$G$23:$G$58)+0 -> 0 | G31: =SUMPRODUCT(--('Cuadrante por Franja'!$A$23:$A$58=$A31),--('Cuadrante por Franja'!$B$23:$B$58=G$27),'Cuadrante por Franja'!$G$23:$G$58)+0 -> 3 | H31: =SUMPRODUCT(--('Cuadrante por Franja'!$A$23:$A$58=$A31),--('Cuadrante por Franja'!$B$23:$B$58=H$27),'Cuadrante por Franja'!$G$23:$G$58)+0 -> 3 | I31: =SUMPRODUCT(--('Cuadrante por Franja'!$A$23:$A$58=$A31),--('Cuadrante por Franja'!$B$23:$B$58=I$27),'Cuadrante por Franja'!$G$23:$G$58)+0 -> 0
A32: ='Coste de Plantilla'!$A$13 -> P5 | C32: =SUMPRODUCT(--('Cuadrante por Franja'!$A$23:$A$58=$A32),--('Cuadrante por Franja'!$B$23:$B$58=C$27),'Cuadrante por Franja'!$G$23:$G$58)+0 -> 0 | D32: =SUMPRODUCT(--('Cuadrante por Franja'!$A$23:$A$58=$A32),--('Cuadrante por Franja'!$B$23:$B$58=D$27),'Cuadrante por Franja'!$G$23:$G$58)+0 -> 0 | E32: =SUMPRODUCT(--('Cuadrante por Franja'!$A$23:$A$58=$A32),--('Cuadrante por Franja'!$B$23:$B$58=E$27),'Cuadrante por Franja'!$G$23:$G$58)+0 -> 0 | F32: =SUMPRODUCT(--('Cuadrante por Franja'!$A$23:$A$58=$A32),--('Cuadrante por Franja'!$B$23:$B$58=F$27),'Cuadrante por Franja'!$G$23:$G$58)+0 -> 0 | G32: =SUMPRODUCT(--('Cuadrante por Franja'!$A$23:$A$58=$A32),--('Cuadrante por Franja'!$B$23:$B$58=G$27),'Cuadrante por Franja'!$G$23:$G$58)+0 -> 0 | H32: =SUMPRODUCT(--('Cuadrante por Franja'!$A$23:$A$58=$A32),--('Cuadrante por Franja'!$B$23:$B$58=H$27),'Cuadrante por Franja'!$G$23:$G$58)+0 -> 0 | I32: =SUMPRODUCT(--('Cuadrante por Franja'!$A$23:$A$58=$A32),--('Cuadrante por Franja'!$B$23:$B$58=I$27),'Cuadrante por Franja'!$G$23:$G$58)+0 -> 0
A34: Persona | B34: Horas en la ventana nocturna del convenio por día | C34: L | D34: M | E34: X | F34: J | G34: V | H34: S | I34: D
A35: ='Coste de Plantilla'!$A$9 -> P1 | C35: =SUMPRODUCT(--('Cuadrante por Franja'!$A$23:$A$58=$A35),--('Cuadrante por Franja'!$B$23:$B$58=C$34),'Cuadrante por Franja'!$J$23:$J$58)+0 -> 1 | D35: =SUMPRODUCT(--('Cuadrante por Franja'!$A$23:$A$58=$A35),--('Cuadrante por Franja'!$B$23:$B$58=D$34),'Cuadrante por Franja'!$J$23:$J$58)+0 -> 0 | E35: =SUMPRODUCT(--('Cuadrante por Franja'!$A$23:$A$58=$A35),--('Cuadrante por Franja'!$B$23:$B$58=E$34),'Cuadrante por Franja'!$J$23:$J$58)+0 -> 0 | F35: =SUMPRODUCT(--('Cuadrante por Franja'!$A$23:$A$58=$A35),--('Cuadrante por Franja'!$B$23:$B$58=F$34),'Cuadrante por Franja'!$J$23:$J$58)+0 -> 0 | G35: =SUMPRODUCT(--('Cuadrante por Franja'!$A$23:$A$58=$A35),--('Cuadrante por Franja'!$B$23:$B$58=G$34),'Cuadrante por Franja'!$J$23:$J$58)+0 -> 0 | H35: =SUMPRODUCT(--('Cuadrante por Franja'!$A$23:$A$58=$A35),--('Cuadrante por Franja'!$B$23:$B$58=H$34),'Cuadrante por Franja'!$J$23:$J$58)+0 -> 2 | I35: =SUMPRODUCT(--('Cuadrante por Franja'!$A$23:$A$58=$A35),--('Cuadrante por Franja'!$B$23:$B$58=I$34),'Cuadrante por Franja'!$J$23:$J$58)+0 -> 2
A36: ='Coste de Plantilla'!$A$10 -> P2 | C36: =SUMPRODUCT(--('Cuadrante por Franja'!$A$23:$A$58=$A36),--('Cuadrante por Franja'!$B$23:$B$58=C$34),'Cuadrante por Franja'!$J$23:$J$58)+0 -> 2 | D36: =SUMPRODUCT(--('Cuadrante por Franja'!$A$23:$A$58=$A36),--('Cuadrante por Franja'!$B$23:$B$58=D$34),'Cuadrante por Franja'!$J$23:$J$58)+0 -> 2 | E36: =SUMPRODUCT(--('Cuadrante por Franja'!$A$23:$A$58=$A36),--('Cuadrante por Franja'!$B$23:$B$58=E$34),'Cuadrante por Franja'!$J$23:$J$58)+0 -> 2 | F36: =SUMPRODUCT(--('Cuadrante por Franja'!$A$23:$A$58=$A36),--('Cuadrante por Franja'!$B$23:$B$58=F$34),'Cuadrante por Franja'!$J$23:$J$58)+0 -> 2 | G36: =SUMPRODUCT(--('Cuadrante por Franja'!$A$23:$A$58=$A36),--('Cuadrante por Franja'!$B$23:$B$58=G$34),'Cuadrante por Franja'!$J$23:$J$58)+0 -> 2 | H36: =SUMPRODUCT(--('Cuadrante por Franja'!$A$23:$A$58=$A36),--('Cuadrante por Franja'!$B$23:$B$58=H$34),'Cuadrante por Franja'!$J$23:$J$58)+0 -> 0 | I36: =SUMPRODUCT(--('Cuadrante por Franja'!$A$23:$A$58=$A36),--('Cuadrante por Franja'!$B$23:$B$58=I$34),'Cuadrante por Franja'!$J$23:$J$58)+0 -> 0
A37: ='Coste de Plantilla'!$A$11 -> P3 | C37: =SUMPRODUCT(--('Cuadrante por Franja'!$A$23:$A$58=$A37),--('Cuadrante por Franja'!$B$23:$B$58=C$34),'Cuadrante por Franja'!$J$23:$J$58)+0 -> 0 | D37: =SUMPRODUCT(--('Cuadrante por Franja'!$A$23:$A$58=$A37),--('Cuadrante por Franja'!$B$23:$B$58=D$34),'Cuadrante por Franja'!$J$23:$J$58)+0 -> 1 | E37: =SUMPRODUCT(--('Cuadrante por Franja'!$A$23:$A$58=$A37),--('Cuadrante por Franja'!$B$23:$B$58=E$34),'Cuadrante por Franja'!$J$23:$J$58)+0 -> 1 | F37: =SUMPRODUCT(--('Cuadrante por Franja'!$A$23:$A$58=$A37),--('Cuadrante por Franja'!$B$23:$B$58=F$34),'Cuadrante por Franja'!$J$23:$J$58)+0 -> 1 | G37: =SUMPRODUCT(--('Cuadrante por Franja'!$A$23:$A$58=$A37),--('Cuadrante por Franja'!$B$23:$B$58=G$34),'Cuadrante por Franja'!$J$23:$J$58)+0 -> 1 | H37: =SUMPRODUCT(--('Cuadrante por Franja'!$A$23:$A$58=$A37),--('Cuadrante por Franja'!$B$23:$B$58=H$34),'Cuadrante por Franja'!$J$23:$J$58)+0 -> 3.5 | I37: =SUMPRODUCT(--('Cuadrante por Franja'!$A$23:$A$58=$A37),--('Cuadrante por Franja'!$B$23:$B$58=I$34),'Cuadrante por Franja'!$J$23:$J$58)+0 -> 3.5
A38: ='Coste de Plantilla'!$A$12 -> P4 | C38: =SUMPRODUCT(--('Cuadrante por Franja'!$A$23:$A$58=$A38),--('Cuadrante por Franja'!$B$23:$B$58=C$34),'Cuadrante por Franja'!$J$23:$J$58)+0 -> 0 | D38: =SUMPRODUCT(--('Cuadrante por Franja'!$A$23:$A$58=$A38),--('Cuadrante por Franja'!$B$23:$B$58=D$34),'Cuadrante por Franja'!$J$23:$J$58)+0 -> 0 | E38: =SUMPRODUCT(--('Cuadrante por Franja'!$A$23:$A$58=$A38),--('Cuadrante por Franja'!$B$23:$B$58=E$34),'Cuadrante por Franja'!$J$23:$J$58)+0 -> 0 | F38: =SUMPRODUCT(--('Cuadrante por Franja'!$A$23:$A$58=$A38),--('Cuadrante por Franja'!$B$23:$B$58=F$34),'Cuadrante por Franja'!$J$23:$J$58)+0 -> 0 | G38: =SUMPRODUCT(--('Cuadrante por Franja'!$A$23:$A$58=$A38),--('Cuadrante por Franja'!$B$23:$B$58=G$34),'Cuadrante por Franja'!$J$23:$J$58)+0 -> 3 | H38: =SUMPRODUCT(--('Cuadrante por Franja'!$A$23:$A$58=$A38),--('Cuadrante por Franja'!$B$23:$B$58=H$34),'Cuadrante por Franja'!$J$23:$J$58)+0 -> 3 | I38: =SUMPRODUCT(--('Cuadrante por Franja'!$A$23:$A$58=$A38),--('Cuadrante por Franja'!$B$23:$B$58=I$34),'Cuadrante por Franja'!$J$23:$J$58)+0 -> 0
A39: ='Coste de Plantilla'!$A$13 -> P5 | C39: =SUMPRODUCT(--('Cuadrante por Franja'!$A$23:$A$58=$A39),--('Cuadrante por Franja'!$B$23:$B$58=C$34),'Cuadrante por Franja'!$J$23:$J$58)+0 -> 0 | D39: =SUMPRODUCT(--('Cuadrante por Franja'!$A$23:$A$58=$A39),--('Cuadrante por Franja'!$B$23:$B$58=D$34),'Cuadrante por Franja'!$J$23:$J$58)+0 -> 0 | E39: =SUMPRODUCT(--('Cuadrante por Franja'!$A$23:$A$58=$A39),--('Cuadrante por Franja'!$B$23:$B$58=E$34),'Cuadrante por Franja'!$J$23:$J$58)+0 -> 0 | F39: =SUMPRODUCT(--('Cuadrante por Franja'!$A$23:$A$58=$A39),--('Cuadrante por Franja'!$B$23:$B$58=F$34),'Cuadrante por Franja'!$J$23:$J$58)+0 -> 0 | G39: =SUMPRODUCT(--('Cuadrante por Franja'!$A$23:$A$58=$A39),--('Cuadrante por Franja'!$B$23:$B$58=G$34),'Cuadrante por Franja'!$J$23:$J$58)+0 -> 0 | H39: =SUMPRODUCT(--('Cuadrante por Franja'!$A$23:$A$58=$A39),--('Cuadrante por Franja'!$B$23:$B$58=H$34),'Cuadrante por Franja'!$J$23:$J$58)+0 -> 2 | I39: =SUMPRODUCT(--('Cuadrante por Franja'!$A$23:$A$58=$A39),--('Cuadrante por Franja'!$B$23:$B$58=I$34),'Cuadrante por Franja'!$J$23:$J$58)+0 -> 2
A42: Versión 1.0 · octubre 2026 · aichef.pro/guia-churreria-chocolateria · info@aichef.pro

Sheet Coste de Plantilla
A1: Coste de Plantilla
A2: AI Chef Pro · aichef.pro — Cómo Montar una Churrería-Chocolatería
