Workbook

Sheet Instrucciones
A1: Auditoría interna de cocina
A2: AI Chef Pro · aichef.pro — Manual del Chef Ejecutivo
A3: Para qué sirve: puntuar la disciplina de tu cocina siempre igual, ver si mejora y comparar unas cocinas con otras.
A5: Instrucciones de uso
A6: 1. Hoja «Auditoría»: escribe la fecha, quién audita y qué cocina se audita. La escala viene a 5 y los dos umbrales del semáforo (ámbar y crítico) son celdas verdes: son tuyos, no de ningún estándar.
A7: 2. Recorre los 50 puntos y puntúa cada uno de 0 a la escala. El peso ya viene puesto de 1 a 3 y también es editable: si en tu casa la trazabilidad de las fichas pesa más que el orden del office, súbelo.
A8: 3. La nota de la visita es una MEDIA PONDERADA, no la media de los 50 números: cada punto pesa lo que dice su columna. Está arriba, junto al cumplimiento sobre la escala y los puntos que llevas puntuados.
A9: 4. Hoja «Resumen por Área»: los mismos 50 puntos repartidos en cinco áreas, cada una con su nota, su peso y su comparación contra la visita que elijas en la celda verde de arriba. La columna «Lectura» dice con palabras si el área empeora.
A10: 5. Esa comparación por área es LO IMPORTANTE de este libro. En el ejemplo la nota global sube de 3,09 a 3,54 y aun así el área de mermas cae de 3,67 a 2,58: una media global se traga eso y una comparación por área no.
A11: 6. Hoja «Histórico»: una fila por visita. La primera es la visita ya cerrada, con sus notas por área escritas a mano; la segunda es la VISITA EN CURSO y se lee sola de las otras dos hojas. Cuando la cierres, copia esa fila y pégala como valores en la primera fila libre de abajo.
A12: 7. Hoja «Histórico por Unidad»: la misma auditoría puntuada en varias cocinas. La unidad de referencia se calcula sola; las demás las rellenas tú cuando las audites. Debajo tienes la media del grupo y tu estándar, para ver quién se aparta y por dónde.
A13: 8. Hoja «Estado Normativo»: qué dice hoy cada norma que toca esta auditoría, qué tiene que hacer el chef, la fecha en que se comprobó y el enlace para comprobarlo tú. La fecha de corte es editable y el libro te avisa cuando ha pasado demasiado tiempo desde ella.
... A32: Versión 1.0 · septiembre 2026 · aichef.pro/manual-chef-ejecutivo · info@aichef.pro

Sheet Auditoría
A1: Auditoría interna de cocina: 50 puntos en cinco áreas
A2: AI Chef Pro · aichef.pro — Manual del Chef Ejecutivo
A3: La nota es una media PONDERADA por el peso de cada punto. No mira limpieza, plagas ni temperaturas de cámara: eso es el Pack APPCC.
A5: ESTA VISITA
B6: Campo | D6: Valor
B7: Fecha de la visita | D7: 46269
B8: Quién audita | D8: Dirección, con el chef delante
B9: Unidad o cocina auditada | D9: La Encina (unidad de referencia)
B10: Escala máxima de puntuación | D10: 5
B11: Aviso ÁMBAR: puntuación por debajo de | D11: 3
B12: Aviso CRÍTICO: puntuación por debajo de | D12: 2
B13: Puntuación media PONDERADA de la visita | D13: =IFERROR(SUMPRODUCT($D$19:$D$68,$E$19:$E$68)/SUM($D$19:$D$68),"") -> 3.5447154
B14: Cumplimiento sobre la escala | D14: =IFERROR(IF(OR(NOT(ISNUMBER($D$13)),NOT(ISNUMBER($D$10)),$D$10=0),"",$D$13/$D$10),"") -> 0.70894309
B15: Puntos puntuados (de los 50) | D15: =COUNT($E$19:$E$68) -> 50
B16: La media ponderada divide la suma de peso x puntuación entre la suma de los pesos. Un punto sin puntuar cuenta como cero: puntúa los 50.
A18: Nº | B18: Área | C18: Punto de control | D18: Peso (1 a 3) | E18: Puntuación (0 a la escala) | F18: Ponderado | G18: Norma aplicable | H18: Verificación | I18: Observación
A19: 1 | B19: Orden y mise en place | C19: Cada partida tiene su mise en place montada antes de la hora de apertura | D19: 3 | E19: 5 | F19: =IFERROR(IF(OR(NOT(ISNUMBER($D19)),NOT(ISNUMBER($E19))),"",$D19*$E19),"") -> 15
A20: 2 | B20: Orden y mise en place | C20: Los cubetos están etiquetados con producto y fecha de elaboración | D20: 2 | E20: 4 | F20: =IFERROR(IF(OR(NOT(ISNUMBER($D20)),NOT(ISNUMBER($E20))),"",$D20*$E20),"") -> 8
A21: 3 | B21: Orden y mise en place | C21: La cámara está ordenada por orden de caducidad y sin producto sin tapar | D21: 3 | E21: 4 | F21: =IFERROR(IF(OR(NOT(ISNUMBER($D21)),NOT(ISNUMBER($E21))),"",$D21*$E21),"") -> 12
A22: 4 | B22: Orden y mise en place | C22: El pase está despejado y con el material de emplatado a mano | D22: 2 | E22: 4 | F22: =IFERROR(IF(OR(NOT(ISNUMBER($D22)),NOT(ISNUMBER($E22))),"",$D22*$E22),"") -> 8
A23: 5 | B23: Orden y mise en place | C23: Los cuchillos están afilados y guardados en su soporte, no en el cajon | D23: 2 | E23: 4 | F23: =IFERROR(IF(OR(NOT(ISNUMBER($D23)),NOT(ISNUMBER($E23))),"",$D23*$E23),"") -> 8
A24: 6 | B24: Orden y mise en place | C24: No hay producto elaborado sin identificar en ninguna partida | D24: 3 | E24: 4 | F24: =IFERROR(IF(OR(NOT(ISNUMBER($D24)),NOT(ISNUMBER($E24))),"",$D24*$E24),"") -> 12
A25: 7 | B25: Orden y mise en place | C25: El office está al día al empezar el servicio | D25: 2 | E25: 4 | F25: =IFERROR(IF(OR(NOT(ISNUMBER($D25)),NOT(ISNUMBER($E25))),"",$D25*$E25),"") -> 8
A26: 8 | B26: Orden y mise en place | C26: Las estanterías de seco están rotuladas y sin cajas en el suelo | D26: 1 | E26: 4 | F26: =IFERROR(IF(OR(NOT(ISNUMBER($D26)),NOT(ISNUMBER($E26))),"",$D26*$E26),"") -> 4
A27: 9 | B27: Orden y mise en place | C27: Cada partida deja su puesto montado para el turno siguiente | D27: 2 | E27: 4 | F27: =IFERROR(IF(OR(NOT(ISNUMBER($D27)),NOT(ISNUMBER($E27))),"",$D27*$E27),"") -> 8
A28: 10 | B28: Orden y mise en place | C28: El parte de incidencias del servicio anterior está escrito y leído | D28: 2 | E28: 3 | F28: =IFERROR(IF(OR(NOT(ISNUMBER($D28)),NOT(ISNUMBER($E28))),"",$D28*$E28),"") -> 6
A29: 11 | B29: Aplicación de fichas técnicas | C29: Todos los platos de la carta tienen ficha técnica cerrada y firmada | D29: 3 | E29: 4 | F29: =IFERROR(IF(OR(NOT(ISNUMBER($D29)),NOT(ISNUMBER($E29))),"",$D29*$E29),"") -> 12
A30: 12 | B30: Aplicación de fichas técnicas | C30: La ficha está accesible en la partida que produce el plato | D30: 3 | E30: 4 | F30: =IFERROR(IF(OR(NOT(ISNUMBER($D30)),NOT(ISNUMBER($E30))),"",$D30*$E30),"") -> 12
... A46: 28 | B46: Mermas por partida | C46: Las tres semanas de peor merma del trimestre tienen causa escrita | D46: 2 | E46: 3 | F46: =IFERROR(IF(OR(NOT(ISNUMBER($D46)),NOT(ISNUMBER($E46))),"",$D46*$E46),"") -> 6
A47: 29 | B47: Mermas por partida | C47: El excedente apto se gestiona según la jerarquía de la Ley 1/2025 | D47: 2 | E47: 3 | F47: =IFERROR(IF(OR(NOT(ISNUMBER($D47)),NOT(ISNUMBER($E47))),"",$D47*$E47),"") -> 6 | G47: Ley 1/2025, art. 5.1 y 5.2 | H47: Verificado el 06-09-2026 · Ley 1/2025, art. 5.1-5.2 · https://www.boe.es/buscar/act.php?id=BOE-A-2025-6597
A48: 30 | B48: Mermas por partida | C48: El plato que sale por la puerta se envasa y se registra como marca el protocolo | D48: 2 | E48: 2 | F48: =IFERROR(IF(OR(NOT(ISNUMBER($D48)),NOT(ISNUMBER($E48))),"",$D48*$E48),"") -> 4
A49: 31 | B49: Prevención de riesgos laborales | C49: La temperatura del local está dentro del rango que fija la evaluación de riesgos para la categoría de trabajo de la cocina | D49: 3 | E49: 4 | F49: =IFERROR(IF(OR(NOT(ISNUMBER($D49)),NOT(ISNUMBER($E49))),"",$D49*$E49),"") -> 12 | G49: RD 486/1997, Anexo III, punto 3 | H49: Verificado el 06-09-2026 · RD 486/1997, Anexo III, punto 3 · https://www.boe.es/buscar/act.php?id=BOE-A-1997-8669
A50: 32 | B50: Prevención de riesgos laborales | C50: Los suelos son fijos, estables y no resbaladizos, sin irregularidades ni pendientes peligrosas | D50: 3 | E50: 4 | F50: =IFERROR(IF(OR(NOT(ISNUMBER($D50)),NOT(ISNUMBER($E50))),"",$D50*$E50),"") -> 12 | G50: RD 486/1997, Anexo I, punto 3, apartado 1.º | H50: Verificado el 06-09-2026 · RD 486/1997, Anexo I, punto 3.1 · https://www.boe.es/buscar/act.php?id=BOE-A-1997-8669
A51: 33 | B51: Prevención de riesgos laborales | C51: Hay guante de protección mecánica y calzado antideslizante para todo el que los necesita, entregados gratuitamente y repuestos | D51: 3 | E51: 3 | F51: =IFERROR(IF(OR(NOT(ISNUMBER($D51)),NOT(ISNUMBER($E51))),"",$D51*$E51),"") -> 9 | G51: RD 773/1997, art. 3.c) y Anexo III | H51: Verificado el 06-09-2026 · RD 773/1997, art. 3.c) y Anexo III · https://www.boe.es/buscar/act.php?id=BOE-A-1997-12735
A52: 34 | B52: Prevención de riesgos laborales | C52: Cortadora, picadora y batidora tienen sus resguardos puestos y en uso | D52: 3 | E52: 4 | F52: =IFERROR(IF(OR(NOT(ISNUMBER($D52)),NOT(ISNUMBER($E52))),"",$D52*$E52),"") -> 12 | G52: RD 1215/1997, Anexo I, punto 1.8 | H52: Verificado el 06-09-2026 · RD 1215/1997, Anexo I, punto 1.8 · https://www.boe.es/buscar/doc.php?id=BOE-A-1997-17824
A53: 35 | B53: Prevención de riesgos laborales | C53: Las comprobaciones periódicas de los equipos están documentadas y conservadas | D53: 3 | E53: 5 | F53: =IFERROR(IF(OR(NOT(ISNUMBER($D53)),NOT(ISNUMBER($E53))),"",$D53*$E53),"") -> 15 | G53: RD 1215/1997, art. 4 | H53: Verificado el 06-09-2026 · RD 1215/1997, art. 4 · https://www.boe.es/buscar/doc.php?id=BOE-A-1997-17824
A54: 36 | B54: Prevención de riesgos laborales | C54: Las freidoras se vacían y se filtran en frío, con el procedimiento escrito | D54: 2 | E54: 4 | F54: =IFERROR(IF(OR(NOT(ISNUMBER($D54)),NOT(ISNUMBER($E54))),"",$D54*$E54),"") -> 8
A55: 37 | B55: Prevención de riesgos laborales | C55: El botiquín está completo y hay quien sepa usarlo en cada turno | D55: 2 | E55: 3 | F55: =IFERROR(IF(OR(NOT(ISNUMBER($D55)),NOT(ISNUMBER($E55))),"",$D55*$E55),"") -> 6
A56: 38 | B56: Prevención de riesgos laborales | C56: Las cargas pesadas se mueven con ayuda o con carro; nadie levanta solo lo que no debe | D56: 3 | E56: 4 | F56: =IFERROR(IF(OR(NOT(ISNUMBER($D56)),NOT(ISNUMBER($E56))),"",$D56*$E56),"") -> 12 | G56: RD 487/1997, Anexo, puntos 1 a 5 (la norma no fija ninguna cifra en kilos) | H56: Verificado el 06-09-2026 · RD 487/1997, Anexo, puntos 1-5 · https://www.boe.es/buscar/act.php?id=BOE-A-1997-8670
A57: 39 | B57: Prevención de riesgos laborales | C57: Los pasillos de cocina están libres y las zonas mojadas señalizadas | D57: 2 | E57: 4 | F57: =IFERROR(IF(OR(NOT(ISNUMBER($D57)),NOT(ISNUMBER($E57))),"",$D57*$E57),"") -> 8
...

Sheet Resumen por Área
A1: Resumen por área
A2: AI Chef Pro · aichef.pro — Manual del Chef Ejecutivo
A3: Una media global esconde el área que empeora. Aquí se ve por separado, y comparada con la visita que elijas.
A4: Visita del histórico con la que comparar (nº) | B4: 1 | C4: Escribe aquí el número de una visita de la hoja «Histórico» y las columnas de comparación se recalculan.
A5: Área | B5: Puntos puntuados | C5: Peso total del área | D5: Nota de esta visita | E5: Cumplimiento sobre la escala | F5: Tu objetivo (0 a la escala) | G5: Nota de la visita comparada | H5: Variación | I5: Lectura
A6: Orden y mise en place | B6: =COUNT('Auditoría'!$E$19:$E$28) -> 10 | C6: =SUM('Auditoría'!$D$19:$D$28) -> 22 | D6: =IFERROR(SUMPRODUCT('Auditoría'!$D$19:$D$28,'Auditoría'!$E$19:$E$28)/SUM('Auditoría'!$D$19:$D$28),"") -> 4.0454545 | E6: =IFERROR(IF(OR(NOT(ISNUMBER($D6)),NOT(ISNUMBER('Auditoría'!$D$10)),'Auditoría'!$D$10=0),"",$D6/'Auditoría'!$D$10),"") -> 0.80909091 | G6: =IFERROR(INDEX('Histórico'!$D$6:$H$13,MATCH($B$4,'Histórico'!$A$6:$A$13,0),MATCH($A6,'Histórico'!$D$5:$H$5,0)),"") -> 3.454545 | H6: =IFERROR(IF(OR(NOT(ISNUMBER($D6)),NOT(ISNUMBER($G6))),"",$D6-$G6),"") -> 0.59090955 | I6: =IF(NOT(ISNUMBER($H6)),"",IF($H6<0,"EMPEORA respecto a la visita comparada","Mejora o se mantiene")) -> Mejora o se mantiene
A7: Aplicación de fichas técnicas | B7: =COUNT('Auditoría'!$E$29:$E$38) -> 10 | C7: =SUM('Auditoría'!$D$29:$D$38) -> 25 | D7: =IFERROR(SUMPRODUCT('Auditoría'!$D$29:$D$38,'Auditoría'!$E$29:$E$38)/SUM('Auditoría'!$D$29:$D$38),"") -> 3.6 | E7: =IFERROR(IF(OR(NOT(ISNUMBER($D7)),NOT(ISNUMBER('Auditoría'!$D$10)),'Auditoría'!$D$10=0),"",$D7/'Auditoría'!$D$10),"") -> 0.72 | G7: =IFERROR(INDEX('Histórico'!$D$6:$H$13,MATCH($B$4,'Histórico'!$A$6:$A$13,0),MATCH($A7,'Histórico'!$D$5:$H$5,0)),"") -> 2.68 | H7: =IFERROR(IF(OR(NOT(ISNUMBER($D7)),NOT(ISNUMBER($G7))),"",$D7-$G7),"") -> 0.92 | I7: =IF(NOT(ISNUMBER($H7)),"",IF($H7<0,"EMPEORA respecto a la visita comparada","Mejora o se mantiene")) -> Mejora o se mantiene
A8: Mermas por partida | B8: =COUNT('Auditoría'!$E$39:$E$48) -> 10 | C8: =SUM('Auditoría'!$D$39:$D$48) -> 24 | D8: =IFERROR(SUMPRODUCT('Auditoría'!$D$39:$D$48,'Auditoría'!$E$39:$E$48)/SUM('Auditoría'!$D$39:$D$48),"") -> 2.5833333 | E8: =IFERROR(IF(OR(NOT(ISNUMBER($D8)),NOT(ISNUMBER('Auditoría'!$D$10)),'Auditoría'!$D$10=0),"",$D8/'Auditoría'!$D$10),"") -> 0.51666667 | G8: =IFERROR(INDEX('Histórico'!$D$6:$H$13,MATCH($B$4,'Histórico'!$A$6:$A$13,0),MATCH($A8,'Histórico'!$D$5:$H$5,0)),"") -> 3.666667 | H8: =IFERROR(IF(OR(NOT(ISNUMBER($D8)),NOT(ISNUMBER($G8))),"",$D8-$G8),"") -> -1.0833337 | I8: =IF(NOT(ISNUMBER($H8)),"",IF($H8<0,"EMPEORA respecto a la visita comparada","Mejora o se mantiene")) -> EMPEORA respecto a la visita comparada
A9: Prevención de riesgos laborales | B9: =COUNT('Auditoría'!$E$49:$E$58) -> 10 | C9: =SUM('Auditoría'!$D$49:$D$58) -> 26 | D9: =IFERROR(SUMPRODUCT('Auditoría'!$D$49:$D$58,'Auditoría'!$E$49:$E$58)/SUM('Auditoría'!$D$49:$D$58),"") -> 3.8461538 | E9: =IFERROR(IF(OR(NOT(ISNUMBER($D9)),NOT(ISNUMBER('Auditoría'!$D$10)),'Auditoría'!$D$10=0),"",$D9/'Auditoría'!$D$10),"") -> 0.76923077 | G9: =IFERROR(INDEX('Histórico'!$D$6:$H$13,MATCH($B$4,'Histórico'!$A$6:$A$13,0),MATCH($A9,'Histórico'!$D$5:$H$5,0)),"") -> 3 | H9: =IFERROR(IF(OR(NOT(ISNUMBER($D9)),NOT(ISNUMBER($G9))),"",$D9-$G9),"") -> 0.84615385 | I9: =IF(NOT(ISNUMBER($H9)),"",IF($H9<0,"EMPEORA respecto a la visita comparada","Mejora o se mantiene")) -> Mejora o se mantiene
A10: Alérgenos en el pase | B10: =COUNT('Auditoría'!$E$59:$E$68) -> 10 | C10: =SUM('Auditoría'!$D$59:$D$68) -> 26 | D10: =IFERROR(SUMPRODUCT('Auditoría'!$D$59:$D$68,'Auditoría'!$E$59:$E$68)/SUM('Auditoría'!$D$59:$D$68),"") -> 3.6538462 | E10: =IFERROR(IF(OR(NOT(ISNUMBER($D10)),NOT(ISNUMBER('Auditoría'!$D$10)),'Auditoría'!$D$10=0),"",$D10/'Auditoría'!$D$10),"") -> 0.73076923 | G10: =IFERROR(INDEX('Histórico'!$D$6:$H$13,MATCH($B$4,'Histórico'!$A$6:$A$13,0),MATCH($A10,'Histórico'!$D$5:$H$5,0)),"") -> 2.730769 | H10: =IFERROR(IF(OR(NOT(ISNUMBER($D10)),NOT(ISNUMBER($G10))),"",$D10-$G10),"") -> 0.92307715 | I10: =IF(NOT(ISNUMBER($H10)),"",IF($H10<0,"EMPEORA respecto a la visita comparada","Mejora o se mantiene")) -> Mejora o se mantiene
A12: TOTAL PONDERADO DE LA VISITA | B12: =COUNT('Auditoría'!$E$19:$E$68) -> 50 | C12: =SUM('Auditoría'!$D$19:$D$68) -> 123 | D12: =IF('Auditoría'!$D$13="","",'Auditoría'!$D$13) -> 3.5447154 | E12: =IF('Auditoría'!$D$14="","",'Auditoría'!$D$14) -> 0.70894309 | G12: =IFERROR(INDEX('Histórico'!$I$6:$I$13,MATCH($B$4,'Histórico'!$A$6:$A$13,0)),"") -> 3.0894308 | H12: =IFERROR(IF(OR(NOT(ISNUMBER($D$12)),NOT(ISNUMBER($G$12))),"",$D$12-$G$12),"") -> 0.45528462 | I12: =IF(NOT(ISNUMBER($H$12)),"",IF($H$12<0,"EMPEORA respecto a la visita comparada","Mejora o se mantiene")) -> Mejora o se mantiene
A14: La columna «Tu objetivo» viene VACÍA a propósito. Mientras la dejes vacía su semáforo no se enciende: no existe ninguna nota de auditoría de cocina publicada en español con la que compararte, y aquí no se inventa una.
A15: La comparación que sí vale es contra tu visita anterior, y por ÁREA. En el juego de ejemplo la nota global sube y el área de mermas por partida cae más de un punto: eso es exactamente lo que una media global esconde.
A16: El peso de cada punto se lee de la hoja «Auditoría»: si lo cambias allí, estas notas se recalculan solas.

Sheet Histórico
A1: Histórico de auditorías de esta cocina
A2: AI Chef Pro · aichef.pro — Manual del Chef Ejecutivo
A3: Una fila por visita. La visita en curso se lee sola de las otras hojas; las cerradas se pegan como valores.
A4: Peso total de cada área (se lee del resumen) | D4: =IF('Resumen por Área'!$C$6="","",'Resumen por Área'!$C$6) -> 22 | E4: =IF('Resumen por Área'!$C$7="","",'Resumen por Área'!$C$7) -> 25 | F4: =IF('Resumen por Área'!$C$8="","",'Resumen por Área'!$C$8) -> 24 | G4: =IF('Resumen por Área'!$C$9="","",'Resumen por Área'!$C$9) -> 26 | H4: =IF('Resumen por Área'!$C$10="","",'Resumen por Área'!$C$10) -> 26
A5: Nº de visita | B5: Fecha | C5: Quién audita | D5: Orden y mise en place | E5: Aplicación de fichas técnicas | F5: Mermas por partida | G5: Prevención de riesgos laborales | H5: Alérgenos en el pase | I5: Nota ponderada global | J5: Cumplimiento sobre la escala | K5: Unidad o cocina | L5: Variación respecto a la fila anterior
A6: 1 | B6: 46192 | C6: P02 (autoauditoría) | D6: 3.454545 | E6: 2.68 | F6: 3.666667 | G6: 3 | H6: 2.730769 | I6: =IFERROR(IF(OR(COUNT($D6:$H6)=0,SUM($D$4:$H$4)=0),"",SUMPRODUCT($D6:$H6,$D$4:$H$4)/SUM($D$4:$H$4)),"") -> 3.0894308 | J6: =IFERROR(IF(OR(NOT(ISNUMBER($I6)),NOT(ISNUMBER('Auditoría'!$D$10)),'Auditoría'!$D$10=0),"",$I6/'Auditoría'!$D$10),"") -> 0.61788617 | K6: La Encina (unidad de referencia)
A7: 2 | B7: =IF('Auditoría'!$D$7="","",'Auditoría'!$D$7) -> 46269 | C7: =IF('Auditoría'!$D$8="","",'Auditoría'!$D$8) -> Dirección, con el chef delante | D7: =IF('Resumen por Área'!$D$6="","",'Resumen por Área'!$D$6) -> 4.0454545 | E7: =IF('Resumen por Área'!$D$7="","",'Resumen por Área'!$D$7) -> 3.6 | F7: =IF('Resumen por Área'!$D$8="","",'Resumen por Área'!$D$8) -> 2.5833333 | G7: =IF('Resumen por Área'!$D$9="","",'Resumen por Área'!$D$9) -> 3.8461538 | H7: =IF('Resumen por Área'!$D$10="","",'Resumen por Área'!$D$10) -> 3.6538462 | I7: =IFERROR(IF(OR(COUNT($D7:$H7)=0,SUM($D$4:$H$4)=0),"",SUMPRODUCT($D7:$H7,$D$4:$H$4)/SUM($D$4:$H$4)),"") -> 3.5447154 | J7: =IFERROR(IF(OR(NOT(ISNUMBER($I7)),NOT(ISNUMBER('Auditoría'!$D$10)),'Auditoría'!$D$10=0),"",$I7/'Auditoría'!$D$10),"") -> 0.70894309 | K7: =IF('Auditoría'!$D$9="","",'Auditoría'!$D$9) -> La Encina (unidad de referencia) | L7: =IFERROR(IF(OR(NOT(ISNUMBER($I7)),NOT(ISNUMBER($I6))),"",$I7-$I6),"") -> 0.45528462 | M7: VISITA EN CURSO: esta fila se lee sola de las hojas «Auditoría» y «Resumen por Área».
I8: =IFERROR(IF(OR(COUNT($D8:$H8)=0,SUM($D$4:$H$4)=0),"",SUMPRODUCT($D8:$H8,$D$4:$H$4)/SUM($D$4:$H$4)),"") | J8: =IFERROR(IF(OR(NOT(ISNUMBER($I8)),NOT(ISNUMBER('Auditoría'!$D$10)),'Auditoría'!$D$10=0),"",$I8/'Auditoría'!$D$10),"") | L8: =IFERROR(IF(OR(NOT(ISNUMBER($I8)),NOT(ISNUMBER($I7))),"",$I8-$I7),"")
I9: =IFERROR(IF(OR(COUNT($D9:$H9)=0,SUM($D$4:$H$4)=0),"",SUMPRODUCT($D9:$H9,$D$4:$H$4)/SUM($D$4:$H$4)),"") | J9: =IFERROR(IF(OR(NOT(ISNUMBER($I9)),NOT(ISNUMBER('Auditoría'!$D$10)),'Auditoría'!$D$10=0),"",$I9/'Auditoría'!$D$10),"") | L9: =IFERROR(IF(OR(NOT(ISNUMBER($I9)),NOT(ISNUMBER($I8))),"",$I9-$I8),"")
I10: =IFERROR(IF(OR(COUNT($D10:$H10)=0,SUM($D$4:$H$4)=0),"",SUMPRODUCT($D10:$H10,$D$4:$H$4)/SUM($D$4:$H$4)),"") | J10: =IFERROR(IF(OR(NOT(ISNUMBER($I10)),NOT(ISNUMBER('Auditoría'!$D$10)),'Auditoría'!$D$10=0),"",$I10/'Auditoría'!$D$10),"") | L10: =IFERROR(IF(OR(NOT(ISNUMBER($I10)),NOT(ISNUMBER($I9))),"",$I10-$I9),"")
I11: =IFERROR(IF(OR(COUNT($D11:$H11)=0,SUM($D$4:$H$4)=0),"",SUMPRODUCT($D11:$H11,$D$4:$H$4)/SUM($D$4:$H$4)),"") | J11: =IFERROR(IF(OR(NOT(ISNUMBER($I11)),NOT(ISNUMBER('Auditoría'!$D$10)),'Auditoría'!$D$10=0),"",$I11/'Auditoría'!$D$10),"") | L11: =IFERROR(IF(OR(NOT(ISNUMBER($I11)),NOT(ISNUMBER($I10))),"",$I11-$I10),"")
I12: =IFERROR(IF(OR(COUNT($D12:$H12)=0,SUM($D$4:$H$4)=0),"",SUMPRODUCT($D12:$H12,$D$4:$H$4)/SUM($D$4:$H$4)),"") | J12: =IFERROR(IF(OR(NOT(ISNUMBER($I12)),NOT(ISNUMBER('Auditoría'!$D$10)),'Auditoría'!$D$10=0),"",$I12/'Auditoría'!$D$10),"") | L12: =IFERROR(IF(OR(NOT(ISNUMBER($I12)),NOT(ISNUMBER($I11))),"",$I12-$I11),"")
I13: =IFERROR(IF(OR(COUNT($D13:$H13)=0,SUM($D$4:$H$4)=0),"",SUMPRODUCT($D13:$H13,$D$4:$H$4)/SUM($D$4:$H$4)),"") | J13: =IFERROR(IF(OR(NOT(ISNUMBER($I13)),NOT(ISNUMBER('Auditoría'!$D$10)),'Auditoría'!$D$10=0),"",$I13/'Auditoría'!$D$10),"") | L13: =IFERROR(IF(OR(NOT(ISNUMBER($I13)),NOT(ISNUMBER($I12))),"",$I13-$I12),"")
A15: Cómo se cierra una visita: cuando termines la auditoría, copia la fila de la visita en curso y pégala como VALORES en la primera fila libre de abajo. A partir de ahí la fila enlazada vuelve a quedar libre para la siguiente.
A16: La nota global de cada fila NO es la media de las cinco áreas: es la media ponderada por el peso de cada área, que está en la fila de arriba. Por eso un área con mucho peso mueve más la nota.
A17: Guarda también quién audita. Una autoauditoría del jefe de cocina y una visita de dirección con el chef delante no puntúan igual, y saber cuál fue cada una evita conclusiones falsas.

Sheet Histórico por Unidad
A1: La misma auditoría, cocina por cocina
A2: AI Chef Pro · aichef.pro — Manual del Chef Ejecutivo
A3: «Una cocina, con las herramientas para comparar varias». La unidad de referencia se calcula sola; las demás las rellenas cuando las audites.
A4: Peso total de cada área (se lee del resumen) | C4: =IF('Resumen por Área'!$C$6="","",'Resumen por Área'!$C$6) -> 22 | D4: =IF('Resumen por Área'!$C$7="","",'Resumen por Área'!$C$7) -> 25 | E4: =IF('Resumen por Área'!$C$8="","",'Resumen por Área'!$C$8) -> 24 | F4: =IF('Resumen por Área'!$C$9="","",'Resumen por Área'!$C$9) -> 26 | G4: =IF('Resumen por Área'!$C$10="","",'Resumen por Área'!$C$10) -> 26
A5: Unidad o cocina | B5: Fecha de la auditoría | C5: Orden y mise en place | D5: Aplicación de fichas técnicas | E5: Mermas por partida | F5: Prevención de riesgos laborales | G5: Alérgenos en el pase | H5: Nota ponderada | I5: Cumplimiento sobre la escala | J5: Desviación contra la media del grupo | K5: Desviación contra tu estándar | L5: Lectura
A6: =IF('Auditoría'!$D$9="","",'Auditoría'!$D$9) -> La Encina (unidad de referencia) | B6: =IF('Auditoría'!$D$7="","",'Auditoría'!$D$7) -> 46269 | C6: =IF('Resumen por Área'!$D$6="","",'Resumen por Área'!$D$6) -> 4.0454545 | D6: =IF('Resumen por Área'!$D$7="","",'Resumen por Área'!$D$7) -> 3.6 | E6: =IF('Resumen por Área'!$D$8="","",'Resumen por Área'!$D$8) -> 2.5833333 | F6: =IF('Resumen por Área'!$D$9="","",'Resumen por Área'!$D$9) -> 3.8461538 | G6: =IF('Resumen por Área'!$D$10="","",'Resumen por Área'!$D$10) -> 3.6538462 | H6: =IFERROR(IF(OR(COUNT($C6:$G6)=0,SUM($C$4:$G$4)=0),"",SUMPRODUCT($C6:$G6,$C$4:$G$4)/SUM($C$4:$G$4)),"") -> 3.5447154 | I6: =IFERROR(IF(OR(NOT(ISNUMBER($H6)),NOT(ISNUMBER('Auditoría'!$D$10)),'Auditoría'!$D$10=0),"",$H6/'Auditoría'!$D$10),"") -> 0.70894309 | J6: =IFERROR(IF(OR(NOT(ISNUMBER($H6)),NOT(ISNUMBER($C$13))),"",$H6-$C$13),"") -> 0 | K6: =IFERROR(IF(OR(NOT(ISNUMBER($H6)),NOT(ISNUMBER($C$14))),"",$H6-$C$14),"") -> 0.0047154472 | L6: =IF(NOT(ISNUMBER($K6)),"",IF($K6<0,"Por debajo de tu objetivo","En tu objetivo")) -> En tu objetivo
A7: La Encina Norte | H7: =IFERROR(IF(OR(COUNT($C7:$G7)=0,SUM($C$4:$G$4)=0),"",SUMPRODUCT($C7:$G7,$C$4:$G$4)/SUM($C$4:$G$4)),"") | I7: =IFERROR(IF(OR(NOT(ISNUMBER($H7)),NOT(ISNUMBER('Auditoría'!$D$10)),'Auditoría'!$D$10=0),"",$H7/'Auditoría'!$D$10),"") | J7: =IFERROR(IF(OR(NOT(ISNUMBER($H7)),NOT(ISNUMBER($C$13))),"",$H7-$C$13),"") | K7: =IFERROR(IF(OR(NOT(ISNUMBER($H7)),NOT(ISNUMBER($C$14))),"",$H7-$C$14),"") | L7: =IF(NOT(ISNUMBER($K7)),"",IF($K7<0,"Por debajo de tu objetivo","En tu objetivo"))
A8: La Encina Playa | H8: =IFERROR(IF(OR(COUNT($C8:$G8)=0,SUM($C$4:$G$4)=0),"",SUMPRODUCT($C8:$G8,$C$4:$G$4)/SUM($C$4:$G$4)),"") | I8: =IFERROR(IF(OR(NOT(ISNUMBER($H8)),NOT(ISNUMBER('Auditoría'!$D$10)),'Auditoría'!$D$10=0),"",$H8/'Auditoría'!$D$10),"") | J8: =IFERROR(IF(OR(NOT(ISNUMBER($H8)),NOT(ISNUMBER($C$13))),"",$H8-$C$13),"") | K8: =IFERROR(IF(OR(NOT(ISNUMBER($H8)),NOT(ISNUMBER($C$14))),"",$H8-$C$14),"") | L8: =IF(NOT(ISNUMBER($K8)),"",IF($K8<0,"Por debajo de tu objetivo","En tu objetivo"))
H9: =IFERROR(IF(OR(COUNT($C9:$G9)=0,SUM($C$4:$G$4)=0),"",SUMPRODUCT($C9:$G9,$C$4:$G$4)/SUM($C$4:$G$4)),"") | I9: =IFERROR(IF(OR(NOT(ISNUMBER($H9)),NOT(ISNUMBER('Auditoría'!$D$10)),'Auditoría'!$D$10=0),"",$H9/'Auditoría'!$D$10),"") | J9: =IFERROR(IF(OR(NOT(ISNUMBER($H9)),NOT(ISNUMBER($C$13))),"",$H9-$C$13),"") | K9: =IFERROR(IF(OR(NOT(ISNUMBER($H9)),NOT(ISNUMBER($C$14))),"",$H9-$C$14),"") | L9: =IF(NOT(ISNUMBER($K9)),"",IF($K9<0,"Por debajo de tu objetivo","En tu objetivo"))
H10: =IFERROR(IF(OR(COUNT($C10:$G10)=0,SUM($C$4:$G$4)=0),"",SUMPRODUCT($C10:$G10,$C$4:$G$4)/SUM($C$4:$G$4)),"") | I10: =IFERROR(IF(OR(NOT(ISNUMBER($H10)),NOT(ISNUMBER('Auditoría'!$D$10)),'Auditoría'!$D$10=0),"",$H10/'Auditoría'!$D$10),"") | J10: =IFERROR(IF(OR(NOT(ISNUMBER($H10)),NOT(ISNUMBER($C$13))),"",$H10-$C$13),"") | K10: =IFERROR(IF(OR(NOT(ISNUMBER($H10)),NOT(ISNUMBER($C$14))),"",$H10-$C$14),"") | L10: =IF(NOT(ISNUMBER($K10)),"",IF($K10<0,"Por debajo de tu objetivo","En tu objetivo"))
H11: =IFERROR(IF(OR(COUNT($C11:$G11)=0,SUM($C$4:$G$4)=0),"",SUMPRODUCT($C11:$G11,$C$4:$G$4)/SUM($C$4:$G$4)),"") | I11: =IFERROR(IF(OR(NOT(ISNUMBER($H11)),NOT(ISNUMBER('Auditoría'!$D$10)),'Auditoría'!$D$10=0),"",$H11/'Auditoría'!$D$10),"") | J11: =IFERROR(IF(OR(NOT(ISNUMBER($H11)),NOT(ISNUMBER($C$13))),"",$H11-$C$13),"") | K11: =IFERROR(IF(OR(NOT(ISNUMBER($H11)),NOT(ISNUMBER($C$14))),"",$H11-$C$14),"") | L11: =IF(NOT(ISNUMBER($K11)),"",IF($K11<0,"Por debajo de tu objetivo","En tu objetivo"))
A13: Media del grupo (unidades auditadas) | C13: =IFERROR(IF(COUNT($H$6:$H$11)=0,"",SUM($H$6:$H$11)/COUNT($H$6:$H$11)),"") -> 3.5447154
A14: Tu estándar de grupo (objetivo propio, 0 a la escala) | C14: 3.54
A16: Las unidades del grupo vienen con NOMBRE y sin puntuación: sus notas son las que saques tú cuando las audites. Aquí no se inventa la puntuación de una cocina que nadie ha visitado.
A17: Para que la comparación valga, las tres cosas tienen que ser iguales: los mismos 50 puntos, los mismos pesos y la misma escala. Si en una unidad cambias un peso, cámbialo en todas o deja de comparar.
A18: Comparar cocinas de formatos distintos sin decirlo es la forma más rápida de tomar una decisión mala con un número bueno. Una cocina de banquetes y una de carta no se auditan igual aunque el checklist sea el mismo.
A19: El ejemplo trae el estándar sembrado con la nota ponderada de tu última visita (3.54): empezar exigiéndote no bajar de donde ya estás es un criterio razonable. Cámbialo por el tuyo cuando quieras.

Sheet Estado Normativo
A1: Estado normativo a la fecha de corte
A2: AI Chef Pro · aichef.pro — Manual del Chef Ejecutivo
A3: Qué dice hoy cada norma que toca esta auditoría, con el enlace para que lo compruebes tú. La fecha de corte es editable.
A5: Fecha de corte de esta revisión | B5: 46271 | C5: Es el día en que se comprobó cada norma contra el texto consolidado del BOE o de EUR-Lex.
A6: Fecha para simular (déjala vacía y se usa la de hoy)
A7: Hoy (fecha de referencia) | B7: =IFERROR(IF($B$6="",TODAY(),$B$6),"") -> 46271
A8: Días naturales desde la fecha de corte | B8: =IFERROR(IF(OR(NOT(ISNUMBER($B$7)),NOT(ISNUMBER($B$5))),"",$B$7-$B$5),"") -> 0
A9: Avisar cuando hayan pasado más de (días) | B9: 180 | C9: Criterio de la casa, no una obligación de ninguna norma: media año es un plazo razonable para volver a mirar los enlaces.
A10: Aviso | B10: =IF(OR(NOT(ISNUMBER($B$8)),NOT(ISNUMBER($B$9))),"",IF($B$8>$B$9,"REVISAR: ha pasado mucho desde la fecha de corte","Revisión reciente")) -> Revisión reciente
A12: Norma | B12: Estado a la fecha de corte | C12: Qué tiene que hacer el chef | D12: Fecha de corte | E12: Id | F12: Verificación y enlace | G12: Comprobado por ti el | H12: Estado tras tu comprobación
A13: Reglamento (CE) 852/2004, con la modificación 2021/382 | B13: Vigente; la modificación se aplica desde el 24-03-2021 | C13: La cultura de seguridad alimentaria es obligación de la dirección, no del último que entró: hay que poder demostrarla (Cap. XI bis) | D13: =IF($B$5="","",$B$5) -> 46271 | E13: CE-02 | F13: Verificado el 06-09-2026 · Reglamento (CE) 852/2004, Anexo II, Capítulo XI bis, puntos 1-3 · https://eur-lex.europa.eu/legal-content/ES/TXT/HTML/?uri=CELEX:02004R0852-20210324 | H13: Sin comprobar
A14: Reglamento (UE) 1169/2011 y RD 126/2015 | B14: Vigentes | C14: Los 14 alérgenos, por escrito y accesibles. El cartel de «consulte al personal» no basta sin soporte escrito | D14: =IF($B$5="","",$B$5) -> 46271 | E14: CE-06 | F14: Verificado el 06-09-2026 · Reglamento (UE) 1169/2011, Anexo II y art. 44.1; RD 126/2015 art. 6.5 · https://www.boe.es/buscar/act.php?id=BOE-A-2015-2293 | H14: Sin comprobar
A15: Reglamento (UE) 828/2014 (gluten) | B15: Vigente desde el 20-07-2016 | C15: Si anuncias un plato «sin gluten» te obligas a 20 mg/kg; «muy bajo en gluten», 100 mg/kg | D15: =IF($B$5="","",$B$5) -> 46271 | E15: CE-07 | F15: Verificado el 06-09-2026 · Reglamento (UE) 828/2014, arts. 1-3 y 5 · https://eur-lex.europa.eu/legal-content/ES/TXT/HTML/?uri=CELEX:32014R0828 | H15: Sin comprobar
A16: Reglamento (CE) 2073/2005 (criterios microbiológicos) | B16: Vigente, consolidado a 08-03-2020 | C16: Si el plato favorece el crecimiento de Listeria, el estudio de vida útil se documenta: no hay un número de días fijado por ley | D16: =IF($B$5="","",$B$5) -> 46271 | E16: CE-08 | F16: Verificado el 06-09-2026 · Reglamento (CE) 2073/2005, art. 1 y Anexo II · https://eur-lex.europa.eu/legal-content/ES/TXT/HTML/?uri=CELEX:02005R2073-20200308 | H16: Sin comprobar
A17: RD 1086/2020 (redacción del RD 1021/2022), art. 30 | B17: Vigente; última actualización 22-12-2022 | C17: Las cinco temperaturas y el binomio de enfriamiento van en la ficha de cada plato que se mantenga o se regenere | D17: =IF($B$5="","",$B$5) -> 46271 | E17: CE-10 | F17: Verificado el 06-09-2026 · RD 1086/2020, art. 30.1, 30.2, 30.5 y 30.7 (redacción del RD 1021/2022) · https://www.boe.es/buscar/act.php?id=BOE-A-2020-15872 | H17: Sin comprobar
A18: RD 1086/2020, art. 30, apartados 8, 9 y 10 (comidas testigo) | B18: Vigente | C18: Más de 40 comensales en un encargo: 100 g por elaboración, 7 días, a 4 °C o a -18 °C, identificada y fechada | D18: =IF($B$5="","",$B$5) -> 46271 | E18: CE-11 | F18: Verificado el 06-09-2026 · RD 1086/2020, art. 30, apartados 8, 9 y 10 · https://www.boe.es/buscar/act.php?id=BOE-A-2020-15872 | H18: Sin comprobar
A19: RD 1021/2022, art. 11 (elaboración propia) | B19: Vigente desde el 22-12-2022 | C19: La mención es voluntaria; fraccionar, envasar, deshuesar carne fresca o limpiar pescado NO es elaboración | D19: =IF($B$5="","",$B$5) -> 46271 | E19: CE-12 | F19: Verificado el 06-09-2026 · RD 1021/2022, art. 11 · https://www.boe.es/buscar/act.php?id=BOE-A-2022-21681 | H19: Sin comprobar
A20: RD 1021/2022, art. 8 (anisakis) | B20: Vigente. El RD 1420/2006 está DEROGADO con efectos del 22-12-2022 | C20: Congelación a -20 °C durante 24 horas, o a -35 °C durante 15 horas, salvo el pescado de aguas continentales (excluido) y salvo la acuicultura marina con declaración del operador de origen por lote; hay que informar al consumidor por cartel o carta-menú. El plazo de siete días que circula por el sector viene de una norma derogada | D20: =IF($B$5="","",$B$5) -> 46271 | E20: CE-14 | F20: Verificado el 06-09-2026 · RD 1021/2022, art. 8.1-8.3 · https://www.boe.es/buscar/act.php?id=BOE-A-2022-21681 | H20: Sin comprobar
A21: Orden de 26-01-1989 sobre aceites de fritura, art. 6.3 | B21: Vigente (otros artículos derogados por el RD 176/2013) | C21: Por debajo del 25 % de compuestos polares. Se mide, no se mira el color | D21: =IF($B$5="","",$B$5) -> 46271 | E21: CE-17 | F21: Verificado el 06-09-2026 · Orden de 26-01-1989, art. 6.3 · https://www.boe.es/buscar/act.php?id=BOE-A-1989-2265 | H21: Sin comprobar
A22: Reglamento (UE) 2023/915 (contaminantes) | B22: Vigente desde mayo de 2023; derogó el Reglamento 1881/2006 | C22: Vincula al COMPRAR: es la garantía que se le pide al proveedor, no un análisis de cocina | D22: =IF($B$5="","",$B$5) -> 46271 | E22: CE-18 | F22: Verificado el 06-09-2026 · Reglamento (UE) 2023/915, arts. 9 y 11 · https://eur-lex.europa.eu/legal-content/ES/TXT/HTML/?uri=CELEX:32023R0915 | H22: Sin comprobar
A23: Reglamento (UE) 2017/2158 (acrilamida) | B23: Vigente desde el 11-04-2018; no nombra a los restaurantes como sujeto obligado | C23: Los niveles de referencia no son un límite sancionable: freír la patata por debajo de 175 °C es la medida práctica | D23: =IF($B$5="","",$B$5) -> 46271 | E23: CE-19 | F23: Verificado el 06-09-2026 · Reglamento (UE) 2017/2158, art. 1.2 y Anexo II · https://eur-lex.europa.eu/legal-content/ES/TXT/HTML/?uri=CELEX:32017R2158 | H23: Sin comprobar
A24: RD 486/1997, Anexo III (temperatura del local) | B24: Vigente, actualizado en 2025 | C24: La categoría de trabajo la fija TU evaluación de riesgos, y el Anexo III admite condicionantes del local: 17-27 °C sedentario, 14-25 °C ligero y sin rango para el trabajo pesado. La cocina no tiene un rango propio en la norma: el suyo sale de la evaluación de riesgos del local | D24: =IF($B$5="","",$B$5) -> 46271 | E24: CE-21 | F24: Verificado el 06-09-2026 · RD 486/1997, Anexo III, punto 3 · https://www.boe.es/buscar/act.php?id=BOE-A-1997-8669 | H24: Sin comprobar
... A26: Ley 1/2025 de prevención de pérdidas y desperdicio alimentario | B26: Publicada en el BOE el 02-04-2025; las obligaciones del art. 6 son exigibles desde el 02-04-2026 (DF vigésima) | C26: Las microempresas quedan excluidas de las obligaciones del art. 6, pero el doggy bag del art. 8 les sigue obligando | D26: =IF($B$5="","",$B$5) -> 46271 | E26: CE-33 | F26: Verificado el 06-09-2026 · Ley 1/2025, art. 6.4.c) y 6.6 · https://www.boe.es/buscar/act.php?id=BOE-A-2025-6597 | H26: Sin comprobar
A28: Esta hoja existe para que no tengas que creerte nada. Cada fila trae el enlace al texto consolidado: si algo ha cambiado desde el día de corte, lo ves tú en dos clics y lo anotas en las dos últimas columnas.
A29: Las normas de esta hoja son las que toca la auditoría de cocina: seguridad alimentaria, alérgenos, comidas testigo, temperaturas, anisakis, aceites de fritura, prevención de riesgos y desperdicio. Las de convenio y las laborales viven en el «Manual del Manager de Restaurante».
A30: Que una norma esté vigente no quiere decir que te aplique entera. La columna «Qué tiene que hacer el chef» es la que traduce el artículo a la cocina; el resto es contexto.
A32: LISTA DEL DESPLEGABLE (no la borres)
A33: Estado tras tu comprobación
A34: Sin comprobar
A35: Sigue igual
A36: Ha cambiado
