Workbook

Sheet Instrucciones
A1: Brigada, puestos y evaluación técnica
A2: AI Chef Pro · aichef.pro — Manual del Chef Ejecutivo
A3: Para qué sirve: decidir a quién promocionar, a quién formar en qué y quién decide qué.
A5: Instrucciones de uso
A6: 1. Hoja «Organigrama»: declara cuántas partidas (estaciones, en el vocabulario de la matriz de polivalencia del Manual del Manager) tiene tu cocina, ponles nombre y di quién es el titular de cada una. Debajo va la brigada: una fila por persona, con su puesto del convenio y su partida principal. Es la hoja que alimenta a todas las demás.
A7: 2. Hoja «Fichas de Puesto»: los diez puestos de cocina del convenio con sus funciones LITERALES. Esa columna no se toca: es lo que pone el ALEH VI, y es lo que un inspector o un abogado va a leer. Lo que sí escribes es la columna verde de al lado, con lo que en TU casa hace ese puesto y el convenio no dice: cerrar la cámara, pasar el pedido del pescado, llevar el registro de temperaturas.
A8: 3. Hoja «Matriz RACI»: quince decisiones que cruzan cocina, sala y dirección. Para cada una, marca quién hace (R), quién responde (A), a quién se consulta antes (C) y a quién se informa después (I). La hoja te avisa si una decisión se ha quedado sin A o con dos: es el fallo que hace que un plato se retire de la carta dos veces y ninguna.
A9: 4. Hoja «Rúbrica de Competencias»: siete competencias técnicas con los cinco niveles descritos, los pesos de cada una POR PUESTO y la evaluación de tu gente. Puntúa de 1 a 5 y deja en blanco lo que no aplique. La media ponderada ignora los blancos: un ayudante que no hace fondos no baja nota por no hacerlos.
A10: 5. Hoja «Prueba Práctica»: el guion de la prueba, una por competencia, con lo que es un 5 y lo que es un 1. Sin esto, la rúbrica es una opinión; con esto, es una nota que se puede defender delante de quien la recibe.
A11: 6. Hoja «Plan de Desarrollo Individual»: qué va a trabajar cada persona, con quién, para cuándo y en qué estado está. La columna «próxima partida a aprender» es la que enlaza con el plan de cross-training del Manual del Manager: no se repite aquí, se cita.
A12: 7. Hoja «Histórico»: una línea por evaluación y por persona. La primera ronda no dice nada; la segunda es la que enseña quién ha crecido y quién lleva año y medio en el mismo sitio.
A14: Celdas verdes = campos editables
A16: QUÉ SE COPIA DE DÓNDE Y QUÉ NO HAY QUE VOLVER A TECLEAR
A17: Producto | B17: Qué aporta | C17: Qué NO hay que volver a teclear
A18: Manual del Manager de Restaurante | B18: Las 12 personas de la plantilla, las 6 unidades (aquí «partidas»), la matriz de polivalencia y las 52 semanas ISO con sus cubiertos | C18: No vuelvas a teclear la plantilla ni los cubiertos: si ya tienes el Manager, copia y pega de su cuadro semanal
A19: Guía Food Cost + Ingeniería de Menú | B19: La carta de 20 platos, el mix de venta de los 12 de ejemplo y el coste por ración de la ficha de escandallo | C19: El coste por ración de la ficha técnica de proceso se COPIA del escandallo (celda verde); este pack no lo recalcula
A20: Este manual | B20: Producción y merma por partida, tiempos de pase, incidencias de alérgenos, horas de cocina, evaluación técnica, banquetes y auditoría de cocina | C20: Es la capa que no cubre ninguno de los dos anteriores
A21: Es COPIA declarada, no vínculo: en todo este pack no hay ni una fórmula que apunte a otro fichero. Un enlace entre libros se rompe en cuanto alguien mueve una carpeta o renombra un fichero, y entonces el libro miente sin avisar de nada.
A23: Lo que conviene saber antes de empezar
A24: COBERTURA NO ES COMPETENCIA, y es la confusión que más caro sale. La matriz de polivalencia del «Manual del Manager de Restaurante» responde a «¿puede sostener esta partida en un servicio?». Esta rúbrica responde a «¿con qué nivel técnico?». La columna «nivel en cocina» de la hoja «Rúbrica de Competencias» es una COPIA de aquella matriz, puesta ahí para poder contrastarlas: quien cubre el pase un viernes no necesariamente lo domina.
A25: N/A NO ES CERO. Una competencia que no aplica a un puesto se deja en blanco y sale de la media; un cero dice que se hizo la prueba y salió mal. Las cuatro personas de sala pura del ejemplo tienen las siete casillas en blanco: su evaluación genérica vive en el Kit de Gestión de Personal, no aquí.
A26: Las funciones de los diez puestos son las del convenio, palabra por palabra. «Chef ejecutivo», «chef corporativo» y «sous chef» NO son categorías del ALEH VI: son denominaciones de uso, y quien las lleva se clasifica por las funciones que hace. La tabla de equivalencias está en la hoja «Fichas de Puesto».
A27: La evaluación se puntúa POR PRUEBA PRÁCTICA, nunca por impresión ni por autoevaluación. Si no ha habido prueba, la casilla se queda en blanco: una nota sin prueba detrás no se sostiene el día que hay que explicar por qué asciende uno y no otro.
A28: Este libro no calcula nóminas, ni cuadrantes, ni coste laboral: eso es el Kit de Gestión de Personal y el cuadro de mando del Manual del Manager. Aquí se decide quién hace qué, con qué nivel y qué le falta.
A30: Cada cuánto se usa este libro
A31: Cadencia: el organigrama y las fichas de puesto, AL ABRIR TEMPORADA o cuando entra o sale alguien. La rúbrica y la prueba práctica, DOS VECES AL AÑO. El plan de desarrollo individual se repasa cada mes. La matriz RACI se escribe UNA VEZ y se toca cuando cambia la estructura.
A33: Para editar la estructura o una celda que no este en verde, desprotege la hoja (sin contraseña).
A34: Ruta en Excel: Revisar > Desproteger hoja. La protección no tiene contraseña; sirve para no pisar una fórmula sin querer.
A36: Diseñado por John Guerrero — chef y consultor gastronómico desde 2010 · johnguerrero.es
A37: Versión 1.0 · septiembre 2026 · aichef.pro/manual-chef-ejecutivo · info@aichef.pro

Sheet Organigrama
A1: Organigrama de cocina
A2: AI Chef Pro · aichef.pro — Manual del Chef Ejecutivo
A3: Las partidas de arriba y la brigada de abajo son la misma cocina vista de dos maneras. Todo lo demás en este libro se lee de aquí.
A5: Partidas activas (de 3 a 8) | C5: 6 | D5: La tabla trae ocho filas fijas. Las que pases de este número se marcan «Fuera del alcance» y dejan de avisarte: una cocina de tres partidas usa este libro igual que una de ocho.
A6: Área funcional de la brigada de cocina | C6: Área 2ª | D6: El ALEH VI tipifica seis áreas funcionales y tres grupos profesionales; cocina y economato son la segunda. Verificado el 06-09-2026 · Arts. 11.2, 15 y 16 del ALEH VI (BOE-A-2023-6344), con la modificación de BOE-A-2026-18630 · https://www.boe.es/buscar/act.php?id=BOE-A-2023-6344
A8: LAS PARTIDAS DE TU COCINA
A9: Nº | B9: Partida | C9: ¿Produce raciones? | D9: Qué produce | E9: Responsable (titular) | F9: Quién la cubre si falta | G9: Personas asignadas | H9: Alcance | I9: Aviso
A10: 1 | B10: Pase y caliente | C10: Sí | D10: Principales calientes: plancha, brasa, horno, arroces y salsas del pase | E10: Iván R. (P02) | G10: =IFERROR(IF($B10="","",COUNTIF($H$23:$H$38,$B10&"")),"") -> 4 | H10: =IF($B10="","",IF(OR(NOT(ISNUMBER($C$5)),$A10<=$C$5),"Activa","Fuera del alcance")) -> Activa | I10: =IF(OR($B10="",$H10<>"Activa"),"",IF($E10="","FALTA RESPONSABLE",IF(AND(ISNUMBER($G10),$G10=0),"SIN PERSONAL ASIGNADO","Correcto"))) -> Correcto
A11: 2 | B11: Fríos y entrantes | C11: Sí | D11: Entrantes fríos y calientes de entrada: ensaladas, cazuelas, fritos y raciones | E11: Laura S. (P05) | G11: =IFERROR(IF($B11="","",COUNTIF($H$23:$H$38,$B11&"")),"") -> 1 | H11: =IF($B11="","",IF(OR(NOT(ISNUMBER($C$5)),$A11<=$C$5),"Activa","Fuera del alcance")) -> Activa | I11: =IF(OR($B11="",$H11<>"Activa"),"",IF($E11="","FALTA RESPONSABLE",IF(AND(ISNUMBER($G11),$G11=0),"SIN PERSONAL ASIGNADO","Correcto"))) -> Correcto
A12: 3 | B12: Postres y panadería | C12: Sí | D12: Postres de plato, masas y pan de la casa | E12: Rocío F. (P07) | G12: =IFERROR(IF($B12="","",COUNTIF($H$23:$H$38,$B12&"")),"") -> 1 | H12: =IF($B12="","",IF(OR(NOT(ISNUMBER($C$5)),$A12<=$C$5),"Activa","Fuera del alcance")) -> Activa | I12: =IF(OR($B12="",$H12<>"Activa"),"",IF($E12="","FALTA RESPONSABLE",IF(AND(ISNUMBER($G12),$G12=0),"SIN PERSONAL ASIGNADO","Correcto"))) -> Correcto
A13: 4 | B13: Barra y bebidas | C13: Sí | D13: Elaboraciones de barra: zumos naturales, vermut, coctelería y aperitivo | E13: Elena T. (P09) | G13: =IFERROR(IF($B13="","",COUNTIF($H$23:$H$38,$B13&"")),"") -> 2 | H13: =IF($B13="","",IF(OR(NOT(ISNUMBER($C$5)),$A13<=$C$5),"Activa","Fuera del alcance")) -> Activa | I13: =IF(OR($B13="",$H13<>"Activa"),"",IF($E13="","FALTA RESPONSABLE",IF(AND(ISNUMBER($G13),$G13=0),"SIN PERSONAL ASIGNADO","Correcto"))) -> Correcto
A14: 5 | B14: Sala y servicio | C14: No | D14: Servicio de sala: no produce raciones, por eso su columna va vacía | E14: Nuria C. (P03) | G14: =IFERROR(IF($B14="","",COUNTIF($H$23:$H$38,$B14&"")),"") -> 3 | H14: =IF($B14="","",IF(OR(NOT(ISNUMBER($C$5)),$A14<=$C$5),"Activa","Fuera del alcance")) -> Activa | I14: =IF(OR($B14="",$H14<>"Activa"),"",IF($E14="","FALTA RESPONSABLE",IF(AND(ISNUMBER($G14),$G14=0),"SIN PERSONAL ASIGNADO","Correcto"))) -> Correcto
A15: 6 | B15: Caja y cierre | C15: No | D15: Caja y cierre: no produce raciones, por eso su columna va vacía | E15: Marta L. (P01) | G15: =IFERROR(IF($B15="","",COUNTIF($H$23:$H$38,$B15&"")),"") -> 1 | H15: =IF($B15="","",IF(OR(NOT(ISNUMBER($C$5)),$A15<=$C$5),"Activa","Fuera del alcance")) -> Activa | I15: =IF(OR($B15="",$H15<>"Activa"),"",IF($E15="","FALTA RESPONSABLE",IF(AND(ISNUMBER($G15),$G15=0),"SIN PERSONAL ASIGNADO","Correcto"))) -> Correcto
A16: 7 | G16: =IFERROR(IF($B16="","",COUNTIF($H$23:$H$38,$B16&"")),"") | H16: =IF($B16="","",IF(OR(NOT(ISNUMBER($C$5)),$A16<=$C$5),"Activa","Fuera del alcance")) | I16: =IF(OR($B16="",$H16<>"Activa"),"",IF($E16="","FALTA RESPONSABLE",IF(AND(ISNUMBER($G16),$G16=0),"SIN PERSONAL ASIGNADO","Correcto")))
A17: 8 | G17: =IFERROR(IF($B17="","",COUNTIF($H$23:$H$38,$B17&"")),"") | H17: =IF($B17="","",IF(OR(NOT(ISNUMBER($C$5)),$A17<=$C$5),"Activa","Fuera del alcance")) | I17: =IF(OR($B17="",$H17<>"Activa"),"",IF($E17="","FALTA RESPONSABLE",IF(AND(ISNUMBER($G17),$G17=0),"SIN PERSONAL ASIGNADO","Correcto")))
A18: La columna «quién la cubre si falta» se deja en blanco a propósito: quién puede sostener una partida en un servicio no se decide aquí, se mide en la matriz de polivalencia del «Manual del Manager de Restaurante». Escribe aquí el nombre que salga de allí.
A19: Dos partidas del ejemplo no producen raciones (sala y caja): existen en el negocio y en la matriz del Manager, pero no entran en la producción ni en la merma del cuadro de mando de cocina.
A21: LA BRIGADA: QUIÉN ESTÁ HOY EN CADA PARTIDA
A22: Id | B22: Nombre | C22: Grupo | D22: Puesto en tu organigrama | E22: Puesto del convenio (ALEH VI) | F22: Área funcional | G22: Nivel de delegación | H22: Partida principal | I22: Contrato y jornada | J22: Nivel en cocina
A23: P01 | B23: Marta L. | C23: Grupo I | D23: Gerente / encargada general (manager; administrador, en el uso de otros países) | F23: Área 1ª | H23: Caja y cierre | I23: Indefinido · 40 h/semana | J23: 1
A24: P02 | B24: Iván R. | C24: Grupo I | D24: Jefe de cocina | E24: Jefe/a de cocina | F24: Área 2ª | G24: Cualificado, autónomo y responsable | H24: Pase y caliente | I24: Indefinido · 40 h/semana | J24: 3
A25: P03 | B25: Nuria C. | C25: Grupo I | D25: Jefa de sala (salón, en el uso de otros países) | F25: Área 3ª | H25: Sala y servicio | I25: Indefinido · 40 h/semana | J25: 1
A26: P04 | B26: Diego M. | C26: Grupo II | D26: Cocinero (partida caliente) | E26: Cocinero/a | F26: Área 2ª | G26: Cualificado, autónomo y responsable | H26: Pase y caliente | I26: Indefinido · 40 h/semana | J26: 3
A27: P05 | B27: Laura S. | C27: Grupo II | D27: Cocinera (partida fría) | E27: Cocinero/a | F27: Área 2ª | G27: Cualificado, autónomo y responsable | H27: Fríos y entrantes | I27: Indefinido · 40 h/semana | J27: 3
A28: P06 | B28: Omar B. | C28: Grupo III | D28: Ayudante de cocina | E28: Ayudante/a de cocina | F28: Área 2ª | G28: Con alguna autonomía, bajo supervisión | H28: Pase y caliente | I28: Indefinido · 40 h/semana | J28: 2
A29: P07 | B29: Rocío F. | C29: Grupo III | D29: Ayudante de cocina y postres | E29: Ayudante/a de cocina | F29: Área 2ª | G29: Con alguna autonomía, bajo supervisión | H29: Postres y panadería | I29: Fijo-discontinuo (campaña de marzo a noviembre) · 40 h/semana | J29: 3
A30: P08 | B30: Carlos V. | C30: Grupo II | D30: Camarero, jefe de rango | F30: Área 3ª | H30: Sala y servicio | I30: Indefinido · 40 h/semana | J30: 0
A31: P09 | B31: Elena T. | C31: Grupo II | D31: Camarera | F31: Área 3ª | H31: Barra y bebidas | I31: Indefinido · 40 h/semana | J31: 0
A32: P10 | B32: Youssef A. | C32: Grupo II | D32: Camarero | F32: Área 3ª | H32: Sala y servicio | I32: Indefinido · 40 h/semana | J32: 0
A33: P11 | B33: Paula G. | C33: Grupo III | D33: Ayudante de camarera | F33: Área 3ª | H33: Barra y bebidas | I33: Formativo en alternancia · 25 h/semana | J33: 0
A34: P12 | B34: Andrés P. | C34: Grupo III | D34: Friegaplatos y office | E34: Auxiliar de cocina y economato | F34: Área 2ª | G34: Sin cualificación, bajo supervisión | H34: Pase y caliente | I34: Indefinido a tiempo parcial · 30 h/semana | J34: 1
A39: Personas de la brigada de cocina | F39: =IFERROR(COUNTIF($F$23:$F$38,$C$6),"") -> 6
A40: Personas de la casa dadas de alta en esta hoja | F40: =IF(COUNT($J$23:$J$38)=0,"",COUNT($J$23:$J$38)) -> 12
A42: La columna «nivel en cocina» es el nivel MÁXIMO de polivalencia de esa persona en las tres partidas de cocina, copiado de la matriz del «Manual del Manager de Restaurante». Está aquí para poder contrastarlo con la nota técnica de la hoja «Rúbrica de Competencias»: son dos preguntas distintas y a menudo dan respuestas distintas.
A43: El puesto del convenio sólo se rellena para el área funcional de cocina y economato: quien está en sala o en administración se clasifica en otra área del mismo convenio, y sus funciones no son las del artículo 17.B.
A44: Ojo con los fijos-discontinuos: en el ejemplo, una de las seis personas de cocina sólo está de campaña, así que las horas contratadas de la brigada no son las mismas en febrero que en agosto.
A46: LISTAS DE REFERENCIA DE LOS DESPLEGABLES (fuera del área de impresión)
A47: Sí / No | B47: Partidas | C47: Puestos del convenio
A48: Sí | B48: Pase y caliente | C48: Jefe/a de cocina
A49: No | B49: Fríos y entrantes | C49: Segundo/a jefe/a de cocina
...

Sheet Fichas de Puesto
A1: Fichas de puesto de cocina
A2: AI Chef Pro · aichef.pro — Manual del Chef Ejecutivo
A3: La columna de funciones del convenio es LITERAL: es lo que pone el ALEH VI. Lo que escribes tú es la columna verde de al lado.
A5: Puesto (denominación del art. 17.B) | B5: Grupo | C5: Funciones del convenio (literal, art. 17.B) | D5: Funciones propias de tu casa | E5: Nivel de delegación | F5: Quién lo ocupa hoy | G5: Personas
A6: Jefe/a de cocina | B6: Grupo I | C6: Realizar de manera cualificada, funciones de planificación, organización y control de todas las tareas propias del departamento de cocina y repostería. Organizar, dirigir y coordinar el trabajo del personal a su cargo. Dirigir y planificar el conjunto de actividades de su área. Realizar inventarios y controles de materiales, mercancías, etc. Diseñar platos y participar en su elaboración. Realizar propuestas de pedidos de mercancías y materias primas y gestionar su conservación, almacenamiento y rendimiento. Supervisar y controlar el mantenimiento y uso de maquinaria, materiales, utillaje, etc. Colaborar en la instrucción del personal a su cargo | E6: Cualificado, autónomo y responsable | F6: P02 | G6: =IFERROR(COUNTIF('Organigrama'!$E$23:$E$38,$A6),"") -> 1
A7: Segundo/a jefe/a de cocina | B7: Grupo I | C7: Realizar de manera cualificada las funciones de planificación, organización y control de todas las tareas propias del departamento de cocina y repostería. Colaborar y sustituir al jefe/a de cocina en las tareas propias del mismo | E7: Cualificado, autónomo y responsable | G7: =IFERROR(COUNTIF('Organigrama'!$E$23:$E$38,$A7),"") -> 0
A8: Jefe/a de catering | B8: Grupo I | C8: Realizar de manera cualificada y responsable de la dirección, control y seguimiento del proceso de elaboración y distribución de comidas. Organizar, controlar y coordinar todo el proceso de preparación y distribución de la producción a su cargo. Cuidar de que la producción reuna las condiciones exigidas, tanto higiénicas como de montaje. Organizar, instruir y evaluar al personal a su cargo | E8: Cualificado, autónomo y responsable | G8: =IFERROR(COUNTIF('Organigrama'!$E$23:$E$38,$A8),"") -> 0
A9: Jefe/a de partida | B9: Grupo II | C9: Realizar de manera cualificada las funciones de control y supervisión de la partida y/o servicio que le sea asignado bajo la dirección del jefe/a de cocina. Las mismas del cocinero/a, y además: participar en el control de aprovisionamientos, conservación y almacenamiento de mercancías. Elaborar informes sobre la gestión de los recursos y procesos de su partida y/o servicio. Colaborar en la instrucción del personal a su cargo | E9: Cualificado, autónomo y responsable | G9: =IFERROR(COUNTIF('Organigrama'!$E$23:$E$38,$A9),"") -> 0
A10: Cocinero/a | B10: Grupo II | C10: Realizar de manera cualificada, autónoma y responsable, la preparación, aderezo y presentación de platos utilizando las técnicas más idóneas. Colaborar en los pedidos y conservación de materias primas. Colaborar en la planificación de menús y cartas. Colaborar en la gestión de costes e inventarios, así como en las compras | E10: Cualificado, autónomo y responsable | F10: P04, P05 | G10: =IFERROR(COUNTIF('Organigrama'!$E$23:$E$38,$A10),"") -> 2
A11: Repostero/a | B11: Grupo II | C11: Realizar de manera cualificada y autónoma, la preparación y presentación de postres y dulces en general, así como bollería y masas. Realizar el cálculo de costes, relacionados con sus cometidos. Organizar y controlar el personal a su cargo | E11: Cualificado, autónomo y responsable | G11: =IFERROR(COUNTIF('Organigrama'!$E$23:$E$38,$A11),"") -> 0
A12: Encargado/a de economato | B12: Grupo II | C12: Realizar de forma cualificada la dirección, control y supervisión del conjunto de tareas que se desarrollan en su departamento. Establecer las necesidades de mercancías y material. Elaborar las peticiones de ofertas, evaluación y recomendación de las adjudicaciones. Controlar y planificar las existencias, en coordinación con otras secciones del establecimiento | E12: Cualificado, autónomo y responsable | G12: =IFERROR(COUNTIF('Organigrama'!$E$23:$E$38,$A12),"") -> 0
A13: Ayudante/a de cocina | B13: Grupo II | C13: Participar con alguna autonomía y responsabilidad en las elaboraciones de cocina bajo supervisión. Realizar las preparaciones básicas, así como cualquier otra relacionada con las elaboraciones culinarias que le sean encomendadas | E13: Con alguna autonomía, bajo supervisión | F13: P06, P07 | G13: =IFERROR(COUNTIF('Organigrama'!$E$23:$E$38,$A13),"") -> 2
A14: Ayudante/a de economato | B14: Grupo II | C14: Realizar de manera cualificada, autónoma y responsable, la compra y gestión de mercancías y materiales. Recibir las mercancías y material pedidos y controlar las fechas de caducidad. Vigilar y controlar las existencias | E14: Con alguna autonomía, bajo supervisión | G14: =IFERROR(COUNTIF('Organigrama'!$E$23:$E$38,$A14),"") -> 0
A15: Auxiliar de cocina y economato | B15: Grupo III | C15: Realizar sin cualificación las tareas de limpieza de útiles, maquinaria y menaje del restaurante y cocina, para lo cual no requiere una formación específica y que trabaja bajo supervisión. Preparar e higienizar los alimentos. Transportar pedidos | E15: Sin cualificación, bajo supervisión | F15: P12 | G15: =IFERROR(COUNTIF('Organigrama'!$E$23:$E$38,$A15),"") -> 1
A16: TOTAL de personas encuadradas | G16: =IF(COUNT($G$6:$G$15)=0,"",SUM($G$6:$G$15)) -> 6
A18: ALEH VI, art. 17.B (BOE-A-2023-6344) - las FUNCIONES de esta columna no las toca la Resolución de 25-08-2026 (BOE-A-2026-18630, BOE de 04-09-2026), que solo normaliza el lenguaje de género en los NOMBRES de los puestos de los arts. 15 a 17. Verificado el 06-09-2026 - consolidado (art. 17.B): https://www.boe.es/buscar/act.php?id=BOE-A-2023-6344 - resolución de 2026: https://www.boe.es/diario_boe/txt.php?id=BOE-A-2026-18630
A19: La columna «Personas» cuenta cuántas filas de la hoja «Organigrama» tienen ese puesto del convenio. Si el total no cuadra con tu plantilla de cocina, es que alguien está sin encuadrar: el grupo profesional y la ocupación tienen que constar en el contrato y en el recibo de salario. Verificado el 06-09-2026 · Arts. 11.2, 15 y 16 del ALEH VI (BOE-A-2023-6344), con la modificación de BOE-A-2026-18630 · https://www.boe.es/buscar/act.php?id=BOE-A-2023-6344
A20: La columna A es una denominación de TRABAJO, no la lista literal del art. 15: la Resolución de 25-08-2026 solo cambió el nombre de 5 de los 10 puestos (invirtiendo el orden de género) y dejó los otros cuatro como en 2023, y el propio BOE es incoherente con «Ayudante/a economato» (sin cambiar en el art. 15, «Ayudanta/e economato» en los arts. 16 y 17). Lo literal es la columna C.
A21: LOS TRES NIVELES DE DELEGACIÓN QUE YA ESTÁN EN EL CONVENIO
A22: Nivel | C22: Puestos | E22: Cómo se manda en ese nivel
A23: Cualificado, autónomo y responsable | C23: Jefe/a de cocina, segundo/a, jefe/a de catering, jefe/a de partida, cocinero/a, repostero/a y encargado/a de economato | E23: Se le encarga el RESULTADO. No se supervisa el cómo
A24: Con alguna autonomía, bajo supervisión | C24: Ayudante/a de cocina y ayudante/a de economato | E24: Se le encarga la TAREA con el estándar escrito delante, y se comprueba
A25: Sin cualificación, bajo supervisión | C25: Auxiliar de cocina y economato | E25: Se le enseña la tarea, se hace con el la primera vez y se comprueba siempre
A27: DENOMINACIONES DE USO Y SU EQUIVALENCIA EN EL CONVENIO
A28: Denominación de uso | B28: ¿Está en el ALEH VI? | C28: Puesto equivalente por las funciones que hace
A29: Chef ejecutivo | B29: No | C29: Jefe/a de cocina (Grupo I, área 2.ª)
A30: Chef corporativo | B30: No | C30: No existe en el ALEH VI. Quien dirige varias cocinas se encuadra por las funciones que hace: normalmente jefe/a de cocina del Grupo I, y su relación con cada unidad se define en el contrato, no en el convenio
A31: Sous chef | B31: No | C31: Segundo/a jefe/a de cocina (Grupo I, área 2.ª)
A32: Chef de partie | B32: No | C32: Jefe/a de partida (Grupo II, área 2.ª)
A33: Commis | B33: No | C33: Ayudante/a de cocina (Grupo II, área 2.ª)
A34: Marmitón o pinche | B34: No | C34: Auxiliar de cocina y economato (Grupo III, área 2.ª)
A35: Esto no es una discusión de nombres: el grupo profesional decide el salario del convenio, el periodo de prueba y la clasificación que consta en el contrato. Llamarse «chef ejecutivo» no cambia ninguna de las tres.
A37: FORMACIÓN: LO QUE OBLIGA, POR PUESTO
A38: La formación en higiene se da de acuerdo con la actividad laboral de CADA PUESTO, no de forma genérica para toda la casa. Verificado el 06-09-2026 · Reglamento (CE) 852/2004, Anexo II, Cap. XII, punto 1 · https://eur-lex.europa.eu/legal-content/ES/TXT/HTML/?uri=CELEX:02004R0852-20210324
A39: Y la formación en prevención es teórica y práctica, suficiente y adecuada al puesto, dentro de la jornada, y su coste no puede recaer nunca sobre el trabajador. Verificado el 06-09-2026 · Ley 31/1995 de Prevención de Riesgos Laborales, art. 19 · https://www.boe.es/buscar/act.php?id=BOE-A-1995-24292
A41: Versión 1.0 · septiembre 2026 · aichef.pro/manual-chef-ejecutivo · info@aichef.pro

Sheet Matriz RACI
A1: Matriz RACI: cocina, sala y dirección
A2: AI Chef Pro · aichef.pro — Manual del Chef Ejecutivo
A3: Quince decisiones que cruzan los tres. La hoja no opina sobre quién debe decidir: comprueba que alguien lo haga, y sólo uno.
A5: Letra | B5: Qué quiere decir
A6: R | B6: Hace el trabajo. Puede haber varios.
A7: A | B7: Responde del resultado. Uno y sólo uno por decisión.
A8: C | B8: Se le consulta ANTES de decidir.
A9: I | B9: Se le informa DESPUÉS de decidir.
A12: Decisión | B12: Chef ejecutivo | C12: Segundo/a de cocina | D12: Jefe/a de partida | E12: Jefe/a de sala | F12: Gerencia | G12: Propiedad | H12: Nº de A | I12: Nº de R | J12: Comprobación
A13: Autorizar un 86: retirar un plato de la carta en mitad del servicio | B13: A | C13: R | D13: C | E13: I | F13: I | H13: =IFERROR(IF($A13="","",COUNTIF($B13:$G13,$A$7)),"") -> 1 | I13: =IFERROR(IF($A13="","",COUNTIF($B13:$G13,$A$6)),"") -> 1 | J13: =IF($A13="","",IF($H13=0,"Falta la A",IF($H13>1,"Más de una A",IF($I13=0,"Falta la R","Correcta")))) -> Correcta
A14: Aprobar una ficha técnica nueva antes de subir el plato a la carta | B14: A | C14: R | D14: C | E14: I | F14: I | H14: =IFERROR(IF($A14="","",COUNTIF($B14:$G14,$A$7)),"") -> 1 | I14: =IFERROR(IF($A14="","",COUNTIF($B14:$G14,$A$6)),"") -> 1 | J14: =IF($A14="","",IF($H14=0,"Falta la A",IF($H14>1,"Más de una A",IF($I14=0,"Falta la R","Correcta")))) -> Correcta
A15: Fijar el PVP de un plato nuevo | B15: C | E15: I | F15: R | G15: A | H15: =IFERROR(IF($A15="","",COUNTIF($B15:$G15,$A$7)),"") -> 1 | I15: =IFERROR(IF($A15="","",COUNTIF($B15:$G15,$A$6)),"") -> 1 | J15: =IF($A15="","",IF($H15=0,"Falta la A",IF($H15>1,"Más de una A",IF($I15=0,"Falta la R","Correcta")))) -> Correcta
A16: Aceptar un encargo de grupo de más de 40 comensales | B16: C | C16: I | E16: R | F16: A | G16: I | H16: =IFERROR(IF($A16="","",COUNTIF($B16:$G16,$A$7)),"") -> 1 | I16: =IFERROR(IF($A16="","",COUNTIF($B16:$G16,$A$6)),"") -> 1 | J16: =IF($A16="","",IF($H16=0,"Falta la A",IF($H16>1,"Más de una A",IF($I16=0,"Falta la R","Correcta")))) -> Correcta
A17: Gestionar una incidencia de alérgeno detectada en el pase | B17: A | C17: R | D17: R | E17: R | F17: I | H17: =IFERROR(IF($A17="","",COUNTIF($B17:$G17,$A$7)),"") -> 1 | I17: =IFERROR(IF($A17="","",COUNTIF($B17:$G17,$A$6)),"") -> 3 | J17: =IF($A17="","",IF($H17=0,"Falta la A",IF($H17>1,"Más de una A",IF($I17=0,"Falta la R","Correcta")))) -> Correcta
A18: Comprar fuera de escandallo un producto de temporada sin precio cerrado | B18: R | C18: I | D18: C | F18: A | G18: I | H18: =IFERROR(IF($A18="","",COUNTIF($B18:$G18,$A$7)),"") -> 1 | I18: =IFERROR(IF($A18="","",COUNTIF($B18:$G18,$A$6)),"") -> 1 | J18: =IF($A18="","",IF($H18=0,"Falta la A",IF($H18>1,"Más de una A",IF($I18=0,"Falta la R","Correcta")))) -> Correcta
A19: Cambiar de proveedor en una familia de producto | B19: R | C19: C | D19: C | F19: A | G19: I | H19: =IFERROR(IF($A19="","",COUNTIF($B19:$G19,$A$7)),"") -> 1 | I19: =IFERROR(IF($A19="","",COUNTIF($B19:$G19,$A$6)),"") -> 1 | J19: =IF($A19="","",IF($H19=0,"Falta la A",IF($H19>1,"Más de una A",IF($I19=0,"Falta la R","Correcta")))) -> Correcta
A20: Retirar de la carta un plato con margen bajo pero muy vendido | B20: R | C20: C | D20: I | E20: C | F20: A | G20: I | H20: =IFERROR(IF($A20="","",COUNTIF($B20:$G20,$A$7)),"") -> 1 | I20: =IFERROR(IF($A20="","",COUNTIF($B20:$G20,$A$6)),"") -> 1 | J20: =IF($A20="","",IF($H20=0,"Falta la A",IF($H20>1,"Más de una A",IF($I20=0,"Falta la R","Correcta")))) -> Correcta
A21: Parar el pase por una avería de frío | B21: A | C21: R | D21: C | E21: I | F21: I | H21: =IFERROR(IF($A21="","",COUNTIF($B21:$G21,$A$7)),"") -> 1 | I21: =IFERROR(IF($A21="","",COUNTIF($B21:$G21,$A$6)),"") -> 1 | J21: =IF($A21="","",IF($H21=0,"Falta la A",IF($H21>1,"Más de una A",IF($I21=0,"Falta la R","Correcta")))) -> Correcta
A22: Autorizar horas extraordinarias en cocina un fin de semana | B22: R | C22: C | D22: I | F22: A | G22: I | H22: =IFERROR(IF($A22="","",COUNTIF($B22:$G22,$A$7)),"") -> 1 | I22: =IFERROR(IF($A22="","",COUNTIF($B22:$G22,$A$6)),"") -> 1 | J22: =IF($A22="","",IF($H22=0,"Falta la A",IF($H22>1,"Más de una A",IF($I22=0,"Falta la R","Correcta")))) -> Correcta
A23: Contratar a un cocinero o cocinera | B23: R | C23: C | D23: C | F23: A | G23: I | H23: =IFERROR(IF($A23="","",COUNTIF($B23:$G23,$A$7)),"") -> 1 | I23: =IFERROR(IF($A23="","",COUNTIF($B23:$G23,$A$6)),"") -> 1 | J23: =IF($A23="","",IF($H23=0,"Falta la A",IF($H23>1,"Más de una A",IF($I23=0,"Falta la R","Correcta")))) -> Correcta
A24: Aprobar el menú de un banquete y su producción | B24: A | C24: R | D24: C | E24: C | F24: C | G24: I | H24: =IFERROR(IF($A24="","",COUNTIF($B24:$G24,$A$7)),"") -> 1 | I24: =IFERROR(IF($A24="","",COUNTIF($B24:$G24,$A$6)),"") -> 1 | J24: =IF($A24="","",IF($H24=0,"Falta la A",IF($H24>1,"Más de una A",IF($I24=0,"Falta la R","Correcta")))) -> Correcta
A25: Responder a una reseña que critica un plato | B25: C | E25: R | F25: A | G25: I | H25: =IFERROR(IF($A25="","",COUNTIF($B25:$G25,$A$7)),"") -> 1 | I25: =IFERROR(IF($A25="","",COUNTIF($B25:$G25,$A$6)),"") -> 1 | J25: =IF($A25="","",IF($H25=0,"Falta la A",IF($H25>1,"Más de una A",IF($I25=0,"Falta la R","Correcta")))) -> Correcta
A26: Decidir el destino del excedente de un servicio (donación o doggy bag) | B26: A | C26: R | D26: C | E26: I | F26: C | G26: I | H26: =IFERROR(IF($A26="","",COUNTIF($B26:$G26,$A$7)),"") -> 1 | I26: =IFERROR(IF($A26="","",COUNTIF($B26:$G26,$A$6)),"") -> 1 | J26: =IF($A26="","",IF($H26=0,"Falta la A",IF($H26>1,"Más de una A",IF($I26=0,"Falta la R","Correcta")))) -> Correcta
A27: Modificar el gramaje de un plato que ya está en carta | B27: A | C27: R | D27: C | E27: I | F27: C | H27: =IFERROR(IF($A27="","",COUNTIF($B27:$G27,$A$7)),"") -> 1 | I27: =IFERROR(IF($A27="","",COUNTIF($B27:$G27,$A$6)),"") -> 1 | J27: =IF($A27="","",IF($H27=0,"Falta la A",IF($H27>1,"Más de una A",IF($I27=0,"Falta la R","Correcta")))) -> Correcta
H28: =IFERROR(IF($A28="","",COUNTIF($B28:$G28,$A$7)),"") | I28: =IFERROR(IF($A28="","",COUNTIF($B28:$G28,$A$6)),"") | J28: =IF($A28="","",IF($H28=0,"Falta la A",IF($H28>1,"Más de una A",IF($I28=0,"Falta la R","Correcta"))))
H29: =IFERROR(IF($A29="","",COUNTIF($B29:$G29,$A$7)),"") | I29: =IFERROR(IF($A29="","",COUNTIF($B29:$G29,$A$6)),"") | J29: =IF($A29="","",IF($H29=0,"Falta la A",IF($H29>1,"Más de una A",IF($I29=0,"Falta la R","Correcta"))))
H30: =IFERROR(IF($A30="","",COUNTIF($B30:$G30,$A$7)),"") | I30: =IFERROR(IF($A30="","",COUNTIF($B30:$G30,$A$6)),"") | J30: =IF($A30="","",IF($H30=0,"Falta la A",IF($H30>1,"Más de una A",IF($I30=0,"Falta la R","Correcta"))))
H31: =IFERROR(IF($A31="","",COUNTIF($B31:$G31,$A$7)),"") | I31: =IFERROR(IF($A31="","",COUNTIF($B31:$G31,$A$6)),"") | J31: =IF($A31="","",IF($H31=0,"Falta la A",IF($H31>1,"Más de una A",IF($I31=0,"Falta la R","Correcta"))))
H32: =IFERROR(IF($A32="","",COUNTIF($B32:$G32,$A$7)),"") | I32: =IFERROR(IF($A32="","",COUNTIF($B32:$G32,$A$6)),"") | J32: =IF($A32="","",IF($H32=0,"Falta la A",IF($H32>1,"Más de una A",IF($I32=0,"Falta la R","Correcta"))))
A34: Una sola A por decisión. Dos personas que responden de lo mismo es la forma más fiable de que un plato se retire de la carta dos veces y ninguna, y de que la incidencia de un alérgeno se quede esperando a que la coja alguien.
A35: Esta matriz dice QUIÉN decide. Cómo se lleva una discusión entre cocina y sala sin que acabe en el pase está en el capítulo 18 del «Manual del Manager de Restaurante»; y cómo se lleva una propuesta al gerente con la cifra de la semana delante, en el capítulo 19 de este manual.
A36: Las filas son un punto de partida, no un dogma: en una casa con propiedad presente, el PVP puede ser A de propiedad; en un grupo con dirección de operaciones, no. Cámbialas. Lo que no se cambia es la regla de la A única.
A38: Versión 1.0 · septiembre 2026 · aichef.pro/manual-chef-ejecutivo · info@aichef.pro

Sheet Rúbrica de Competencias
A1: Rúbrica de competencias técnicas
A2: AI Chef Pro · aichef.pro — Manual del Chef Ejecutivo
A3: Siete competencias, cinco niveles descritos y pesos por puesto. Se puntúa por prueba práctica; lo que no aplica se deja en blanco y sale de la media.
A5: Competencia | B5: Nivel 1 | C5: Nivel 2 | D5: Nivel 3 | E5: Nivel 4 | F5: Nivel 5
A6: Cortes y manejo de cuchillo | B6: Corta con inseguridad, tamaño irregular y merma alta; no afila | C6: Corta los formatos básicos con lentitud y regularidad justa | D6: Corta con regularidad y a ritmo de servicio los formatos de su partida | E6: Corta todos los formatos de la carta con merma baja y mantiene el filo | F6: Enseña a cortar, corrige la postura de otros y fija el estándar de corte
A7: Cocciones y puntos | B7: Necesita que le digan el punto y el tiempo en cada pieza | C7: Acierta el punto en las piezas fáciles; falla con las gruesas | D7: Acierta el punto de las piezas de su partida de forma repetible | E7: Acierta el punto de toda la carta y corrige sobre la marcha | F7: Define puntos y tiempos de un plato nuevo y los deja escritos en la ficha
A8: Fondos, salsas y bases | B8: No los elabora | C8: Elabora fondos siguiendo la ficha, con supervisión | D8: Elabora y conserva los fondos y salsas de su partida sin supervisión | E8: Ajusta ligazón, sazón y acidez sin receta y aprovecha recortes | F8: Diseña bases nuevas, las escandalla con el jefe de cocina y las documenta
A9: Emplatado y montaje | B9: El plato no se parece a la foto de la ficha | C9: Reproduce el montaje con la foto delante y despacio | D9: Reproduce el montaje de memoria y a ritmo de pase | E9: Mantiene el montaje idéntico en un servicio de 120 cubiertos | F9: Diseña el montaje de un plato nuevo y hace la foto de la ficha
A10: Higiene de manipulación y APPCC en el puesto | B10: Hay que recordarle los básicos de higiene y de registro | C10: Cumple cuando se le supervisa; olvida registros | D10: Cumple y registra sin que se lo recuerden | E10: Detecta y corrige desviaciones de otros en su partida | F10: Forma a los nuevos en higiene del puesto y prepara la visita de Sanidad
A11: Conocimiento y aplicación de la ficha técnica | B11: No consulta la ficha | C11: Consulta la ficha pero se aparta de gramajes y tiempos | D11: Aplica la ficha de los platos de su partida sin desviaciones | E11: Aplica la ficha de toda la carta y avisa cuando la ficha está mal | F11: Escribe y revisa fichas y forma al equipo en el cambio de carta
A12: Gestión de la merma de su partida | B12: No mide la merma de su partida | C12: Anota la merma cuando se le pide | D12: Anota la merma a diario y conoce el objetivo de su partida | E12: Ajusta la producción para bajar la merma y propone aprovechamientos | F12: Analiza la serie de merma de su partida y presenta el plan de corrección
A14: PESO DE CADA COMPETENCIA POR PUESTO (0 a 3)
A15: Puesto | B15: Cortes y manejo de cuchillo | C15: Cocciones y puntos | D15: Fondos, salsas y bases | E15: Emplatado y montaje | F15: Higiene de manipulación y APPCC en el puesto | G15: Conocimiento y aplicación de la ficha técnica | H15: Gestión de la merma de su partida
A16: Jefe/a de cocina | B16: 2 | C16: 3 | D16: 3 | E16: 3 | F16: 3 | G16: 3 | H16: 3
A17: Segundo/a jefe/a de cocina | B17: 2 | C17: 3 | D17: 3 | E17: 3 | F17: 3 | G17: 3 | H17: 3
A18: Jefe/a de partida | B18: 3 | C18: 3 | D18: 3 | E18: 3 | F18: 3 | G18: 3 | H18: 3
A19: Cocinero/a | B19: 3 | C19: 3 | D19: 3 | E19: 2 | F19: 3 | G19: 3 | H19: 2
A20: Repostero/a | B20: 2 | C20: 3 | D20: 3 | E20: 3 | F20: 3 | G20: 3 | H20: 2
A21: Ayudante/a de cocina | B21: 3 | C21: 2 | D21: 2 | E21: 2 | F21: 3 | G21: 2 | H21: 2
A22: Auxiliar de cocina y economato | B22: 2 | C22: 1 | D22: 1 | E22: 1 | F22: 3 | G22: 1 | H22: 1
A23: No evaluado en la rúbrica de cocina
A24: Un peso 0 quiere decir que esa competencia no cuenta para ese puesto y sale de la media. La última fila no tiene pesos a propósito: es la que se elige para quien no pisa cocina, y deja toda su evaluación en blanco.
A26: BANDAS: DE LA MEDIA PONDERADA AL NIVEL TÉCNICO
A27: Nivel técnico | B27: Media desde | C27: Media hasta
A28: 3 | B28: 3.8 | C28: 5
A29: 2 | B29: 3 | C29: 3.79
A30: 1 | B30: 1.8 | C30: 2.99
A32: EVALUACIÓN TÉCNICA DE LA BRIGADA
A33: Id | B33: Nombre | C33: Puesto de la rúbrica | D33: Fecha | E33: Evaluador | F33: Cortes y manejo de cuchillo | G33: Cocciones y puntos | H33: Fondos, salsas y bases | I33: Emplatado y montaje | J33: Higiene de manipulación y APPCC en el puesto | K33: Conocimiento y aplicación de la ficha técnica | L33: Gestión de la merma de su partida | M33: Media ponderada | N33: Nivel técnico | O33: Nivel en cocina | P33: Lectura | R33: Peso aplicado 1 | S33: Peso aplicado 2 | T33: Peso aplicado 3 | U33: Peso aplicado 4 | V33: Peso aplicado 5 | W33: Peso aplicado 6 | X33: Peso aplicado 7 | Y33: Puntos 1 | Z33: Puntos 2 | AA33: Puntos 3 | AB33: Puntos 4 | AC33: Puntos 5 | AD33: Puntos 6 | AE33: Puntos 7
A34: P01 | B34: Marta L. | C34: Ayudante/a de cocina | D34: 46267 | E34: P02 | F34: 2 | G34: 2 | I34: 2 | J34: 4 | K34: 3 | M34: =IFERROR(IF(SUM($R34:$X34)=0,"",SUM($Y34:$AE34)/SUM($R34:$X34)),"") -> 2.6666667 | N34: =IF(NOT(ISNUMBER($M34)),"",IF($M34>=$B$28,$A$28,IF($M34>=$B$29,$A$29,IF($M34>=$B$30,$A$30,"")))) -> 1 | O34: 1 | P34: =IF(OR(NOT(ISNUMBER($N34)),NOT(ISNUMBER($O34))),"",IF($N34>$O34,$A$56,IF($N34=$O34,$A$54,$A$55))) -> Coherente | R34: =IFERROR(IF(NOT(ISNUMBER($F34)),"",INDEX($B$16:$H$23,MATCH($C34,$A$16:$A$23,0),1)),"") -> 3 | S34: =IFERROR(IF(NOT(ISNUMBER($G34)),"",INDEX($B$16:$H$23,MATCH($C34,$A$16:$A$23,0),2)),"") -> 2 | T34: =IFERROR(IF(NOT(ISNUMBER($H34)),"",INDEX($B$16:$H$23,MATCH($C34,$A$16:$A$23,0),3)),"") | U34: =IFERROR(IF(NOT(ISNUMBER($I34)),"",INDEX($B$16:$H$23,MATCH($C34,$A$16:$A$23,0),4)),"") -> 2 | V34: =IFERROR(IF(NOT(ISNUMBER($J34)),"",INDEX($B$16:$H$23,MATCH($C34,$A$16:$A$23,0),5)),"") -> 3 | W34: =IFERROR(IF(NOT(ISNUMBER($K34)),"",INDEX($B$16:$H$23,MATCH($C34,$A$16:$A$23,0),6)),"") -> 2 | X34: =IFERROR(IF(NOT(ISNUMBER($L34)),"",INDEX($B$16:$H$23,MATCH($C34,$A$16:$A$23,0),7)),"") | Y34: =IFERROR(IF(NOT(ISNUMBER($R34)),"",$F34*$R34),"") -> 6 | Z34: =IFERROR(IF(NOT(ISNUMBER($S34)),"",$G34*$S34),"") -> 4 | AA34: =IFERROR(IF(NOT(ISNUMBER($T34)),"",$H34*$T34),"") | AB34: =IFERROR(IF(NOT(ISNUMBER($U34)),"",$I34*$U34),"") -> 4 | AC34: =IFERROR(IF(NOT(ISNUMBER($V34)),"",$J34*$V34),"") -> 12 | AD34: =IFERROR(IF(NOT(ISNUMBER($W34)),"",$K34*$W34),"") -> 6 | AE34: =IFERROR(IF(NOT(ISNUMBER($X34)),"",$L34*$X34),"")
A35: P02 | B35: Iván R. | C35: Jefe/a de cocina | D35: 46266 | E35: Dirección | F35: 4 | G35: 5 | H35: 5 | I35: 4 | J35: 5 | K35: 5 | L35: 4 | M35: =IFERROR(IF(SUM($R35:$X35)=0,"",SUM($Y35:$AE35)/SUM($R35:$X35)),"") -> 4.6 | N35: =IF(NOT(ISNUMBER($M35)),"",IF($M35>=$B$28,$A$28,IF($M35>=$B$29,$A$29,IF($M35>=$B$30,$A$30,"")))) -> 3 | O35: 3 | P35: =IF(OR(NOT(ISNUMBER($N35)),NOT(ISNUMBER($O35))),"",IF($N35>$O35,$A$56,IF($N35=$O35,$A$54,$A$55))) -> Coherente | R35: =IFERROR(IF(NOT(ISNUMBER($F35)),"",INDEX($B$16:$H$23,MATCH($C35,$A$16:$A$23,0),1)),"") -> 2 | S35: =IFERROR(IF(NOT(ISNUMBER($G35)),"",INDEX($B$16:$H$23,MATCH($C35,$A$16:$A$23,0),2)),"") -> 3 | T35: =IFERROR(IF(NOT(ISNUMBER($H35)),"",INDEX($B$16:$H$23,MATCH($C35,$A$16:$A$23,0),3)),"") -> 3 | U35: =IFERROR(IF(NOT(ISNUMBER($I35)),"",INDEX($B$16:$H$23,MATCH($C35,$A$16:$A$23,0),4)),"") -> 3 | V35: =IFERROR(IF(NOT(ISNUMBER($J35)),"",INDEX($B$16:$H$23,MATCH($C35,$A$16:$A$23,0),5)),"") -> 3 | W35: =IFERROR(IF(NOT(ISNUMBER($K35)),"",INDEX($B$16:$H$23,MATCH($C35,$A$16:$A$23,0),6)),"") -> 3 | X35: =IFERROR(IF(NOT(ISNUMBER($L35)),"",INDEX($B$16:$H$23,MATCH($C35,$A$16:$A$23,0),7)),"") -> 3 | Y35: =IFERROR(IF(NOT(ISNUMBER($R35)),"",$F35*$R35),"") -> 8 | Z35: =IFERROR(IF(NOT(ISNUMBER($S35)),"",$G35*$S35),"") -> 15 | AA35: =IFERROR(IF(NOT(ISNUMBER($T35)),"",$H35*$T35),"") -> 15 | AB35: =IFERROR(IF(NOT(ISNUMBER($U35)),"",$I35*$U35),"") -> 12 | AC35: =IFERROR(IF(NOT(ISNUMBER($V35)),"",$J35*$V35),"") -> 15 | AD35: =IFERROR(IF(NOT(ISNUMBER($W35)),"",$K35*$W35),"") -> 15 | AE35: =IFERROR(IF(NOT(ISNUMBER($X35)),"",$L35*$X35),"") -> 12
A36: P03 | B36: Nuria C. | C36: Ayudante/a de cocina | D36: 46267 | E36: P02 | F36: 2 | G36: 2 | I36: 3 | J36: 4 | K36: 2 | M36: =IFERROR(IF(SUM($R36:$X36)=0,"",SUM($Y36:$AE36)/SUM($R36:$X36)),"") -> 2.6666667 | N36: =IF(NOT(ISNUMBER($M36)),"",IF($M36>=$B$28,$A$28,IF($M36>=$B$29,$A$29,IF($M36>=$B$30,$A$30,"")))) -> 1 | O36: 1 | P36: =IF(OR(NOT(ISNUMBER($N36)),NOT(ISNUMBER($O36))),"",IF($N36>$O36,$A$56,IF($N36=$O36,$A$54,$A$55))) -> Coherente | R36: =IFERROR(IF(NOT(ISNUMBER($F36)),"",INDEX($B$16:$H$23,MATCH($C36,$A$16:$A$23,0),1)),"") -> 3 | S36: =IFERROR(IF(NOT(ISNUMBER($G36)),"",INDEX($B$16:$H$23,MATCH($C36,$A$16:$A$23,0),2)),"") -> 2 | T36: =IFERROR(IF(NOT(ISNUMBER($H36)),"",INDEX($B$16:$H$23,MATCH($C36,$A$16:$A$23,0),3)),"") | U36: =IFERROR(IF(NOT(ISNUMBER($I36)),"",INDEX($B$16:$H$23,MATCH($C36,$A$16:$A$23,0),4)),"") -> 2 | V36: =IFERROR(IF(NOT(ISNUMBER($J36)),"",INDEX($B$16:$H$23,MATCH($C36,$A$16:$A$23,0),5)),"") -> 3 | W36: =IFERROR(IF(NOT(ISNUMBER($K36)),"",INDEX($B$16:$H$23,MATCH($C36,$A$16:$A$23,0),6)),"") -> 2 | X36: =IFERROR(IF(NOT(ISNUMBER($L36)),"",INDEX($B$16:$H$23,MATCH($C36,$A$16:$A$23,0),7)),"") | Y36: =IFERROR(IF(NOT(ISNUMBER($R36)),"",$F36*$R36),"") -> 6 | Z36: =IFERROR(IF(NOT(ISNUMBER($S36)),"",$G36*$S36),"") -> 4 | AA36: =IFERROR(IF(NOT(ISNUMBER($T36)),"",$H36*$T36),"") | AB36: =IFERROR(IF(NOT(ISNUMBER($U36)),"",$I36*$U36),"") -> 6 | AC36: =IFERROR(IF(NOT(ISNUMBER($V36)),"",$J36*$V36),"") -> 12 | AD36: =IFERROR(IF(NOT(ISNUMBER($W36)),"",$K36*$W36),"") -> 4 | AE36: =IFERROR(IF(NOT(ISNUMBER($X36)),"",$L36*$X36),"")
A37: P04 | B37: Diego M. | C37: Cocinero/a | D37: 46266 | E37: P02 | F37: 4 | G37: 4 | H37: 4 | I37: 4 | J37: 4 | K37: 4 | L37: 3 | M37: =IFERROR(IF(SUM($R37:$X37)=0,"",SUM($Y37:$AE37)/SUM($R37:$X37)),"") -> 3.8947368 | N37: =IF(NOT(ISNUMBER($M37)),"",IF($M37>=$B$28,$A$28,IF($M37>=$B$29,$A$29,IF($M37>=$B$30,$A$30,"")))) -> 3 | O37: 3 | P37: =IF(OR(NOT(ISNUMBER($N37)),NOT(ISNUMBER($O37))),"",IF($N37>$O37,$A$56,IF($N37=$O37,$A$54,$A$55))) -> Coherente | R37: =IFERROR(IF(NOT(ISNUMBER($F37)),"",INDEX($B$16:$H$23,MATCH($C37,$A$16:$A$23,0),1)),"") -> 3 | S37: =IFERROR(IF(NOT(ISNUMBER($G37)),"",INDEX($B$16:$H$23,MATCH($C37,$A$16:$A$23,0),2)),"") -> 3 | T37: =IFERROR(IF(NOT(ISNUMBER($H37)),"",INDEX($B$16:$H$23,MATCH($C37,$A$16:$A$23,0),3)),"") -> 3 | U37: =IFERROR(IF(NOT(ISNUMBER($I37)),"",INDEX($B$16:$H$23,MATCH($C37,$A$16:$A$23,0),4)),"") -> 2 | V37: =IFERROR(IF(NOT(ISNUMBER($J37)),"",INDEX($B$16:$H$23,MATCH($C37,$A$16:$A$23,0),5)),"") -> 3 | W37: =IFERROR(IF(NOT(ISNUMBER($K37)),"",INDEX($B$16:$H$23,MATCH($C37,$A$16:$A$23,0),6)),"") -> 3 | X37: =IFERROR(IF(NOT(ISNUMBER($L37)),"",INDEX($B$16:$H$23,MATCH($C37,$A$16:$A$23,0),7)),"") -> 2 | Y37: =IFERROR(IF(NOT(ISNUMBER($R37)),"",$F37*$R37),"") -> 12 | Z37: =IFERROR(IF(NOT(ISNUMBER($S37)),"",$G37*$S37),"") -> 12 | AA37: =IFERROR(IF(NOT(ISNUMBER($T37)),"",$H37*$T37),"") -> 12 | AB37: =IFERROR(IF(NOT(ISNUMBER($U37)),"",$I37*$U37),"") -> 8 | AC37: =IFERROR(IF(NOT(ISNUMBER($V37)),"",$J37*$V37),"") -> 12 | AD37: =IFERROR(IF(NOT(ISNUMBER($W37)),"",$K37*$W37),"") -> 12 | AE37: =IFERROR(IF(NOT(ISNUMBER($X37)),"",$L37*$X37),"") -> 6
A38: P05 | B38: Laura S. | C38: Cocinero/a | D38: 46266 | E38: P02 | F38: 5 | G38: 4 | H38: 4 | I38: 5 | J38: 4 | K38: 5 | L38: 3 | M38: =IFERROR(IF(SUM($R38:$X38)=0,"",SUM($Y38:$AE38)/SUM($R38:$X38)),"") -> 4.3157895 | N38: =IF(NOT(ISNUMBER($M38)),"",IF($M38>=$B$28,$A$28,IF($M38>=$B$29,$A$29,IF($M38>=$B$30,$A$30,"")))) -> 3 | O38: 3 | P38: =IF(OR(NOT(ISNUMBER($N38)),NOT(ISNUMBER($O38))),"",IF($N38>$O38,$A$56,IF($N38=$O38,$A$54,$A$55))) -> Coherente | R38: =IFERROR(IF(NOT(ISNUMBER($F38)),"",INDEX($B$16:$H$23,MATCH($C38,$A$16:$A$23,0),1)),"") -> 3 | S38: =IFERROR(IF(NOT(ISNUMBER($G38)),"",INDEX($B$16:$H$23,MATCH($C38,$A$16:$A$23,0),2)),"") -> 3 | T38: =IFERROR(IF(NOT(ISNUMBER($H38)),"",INDEX($B$16:$H$23,MATCH($C38,$A$16:$A$23,0),3)),"") -> 3 | U38: =IFERROR(IF(NOT(ISNUMBER($I38)),"",INDEX($B$16:$H$23,MATCH($C38,$A$16:$A$23,0),4)),"") -> 2 | V38: =IFERROR(IF(NOT(ISNUMBER($J38)),"",INDEX($B$16:$H$23,MATCH($C38,$A$16:$A$23,0),5)),"") -> 3 | W38: =IFERROR(IF(NOT(ISNUMBER($K38)),"",INDEX($B$16:$H$23,MATCH($C38,$A$16:$A$23,0),6)),"") -> 3 | X38: =IFERROR(IF(NOT(ISNUMBER($L38)),"",INDEX($B$16:$H$23,MATCH($C38,$A$16:$A$23,0),7)),"") -> 2 | Y38: =IFERROR(IF(NOT(ISNUMBER($R38)),"",$F38*$R38),"") -> 15 | Z38: =IFERROR(IF(NOT(ISNUMBER($S38)),"",$G38*$S38),"") -> 12 | AA38: =IFERROR(IF(NOT(ISNUMBER($T38)),"",$H38*$T38),"") -> 12 | AB38: =IFERROR(IF(NOT(ISNUMBER($U38)),"",$I38*$U38),"") -> 10 | AC38: =IFERROR(IF(NOT(ISNUMBER($V38)),"",$J38*$V38),"") -> 12 | AD38: =IFERROR(IF(NOT(ISNUMBER($W38)),"",$K38*$W38),"") -> 15 | AE38: =IFERROR(IF(NOT(ISNUMBER($X38)),"",$L38*$X38),"") -> 6
A39: P06 | B39: Omar B. | C39: Ayudante/a de cocina | D39: 46267 | E39: P02 | F39: 3 | G39: 3 | H39: 3 | I39: 4 | J39: 4 | K39: 3 | L39: 3 | M39: =IFERROR(IF(SUM($R39:$X39)=0,"",SUM($Y39:$AE39)/SUM($R39:$X39)),"") -> 3.3125 | N39: =IF(NOT(ISNUMBER($M39)),"",IF($M39>=$B$28,$A$28,IF($M39>=$B$29,$A$29,IF($M39>=$B$30,$A$30,"")))) -> 2 | O39: 2 | P39: =IF(OR(NOT(ISNUMBER($N39)),NOT(ISNUMBER($O39))),"",IF($N39>$O39,$A$56,IF($N39=$O39,$A$54,$A$55))) -> Coherente | R39: =IFERROR(IF(NOT(ISNUMBER($F39)),"",INDEX($B$16:$H$23,MATCH($C39,$A$16:$A$23,0),1)),"") -> 3 | S39: =IFERROR(IF(NOT(ISNUMBER($G39)),"",INDEX($B$16:$H$23,MATCH($C39,$A$16:$A$23,0),2)),"") -> 2 | T39: =IFERROR(IF(NOT(ISNUMBER($H39)),"",INDEX($B$16:$H$23,MATCH($C39,$A$16:$A$23,0),3)),"") -> 2 | U39: =IFERROR(IF(NOT(ISNUMBER($I39)),"",INDEX($B$16:$H$23,MATCH($C39,$A$16:$A$23,0),4)),"") -> 2 | V39: =IFERROR(IF(NOT(ISNUMBER($J39)),"",INDEX($B$16:$H$23,MATCH($C39,$A$16:$A$23,0),5)),"") -> 3 | W39: =IFERROR(IF(NOT(ISNUMBER($K39)),"",INDEX($B$16:$H$23,MATCH($C39,$A$16:$A$23,0),6)),"") -> 2 | X39: =IFERROR(IF(NOT(ISNUMBER($L39)),"",INDEX($B$16:$H$23,MATCH($C39,$A$16:$A$23,0),7)),"") -> 2 | Y39: =IFERROR(IF(NOT(ISNUMBER($R39)),"",$F39*$R39),"") -> 9 | Z39: =IFERROR(IF(NOT(ISNUMBER($S39)),"",$G39*$S39),"") -> 6 | AA39: =IFERROR(IF(NOT(ISNUMBER($T39)),"",$H39*$T39),"") -> 6 | AB39: =IFERROR(IF(NOT(ISNUMBER($U39)),"",$I39*$U39),"") -> 8 | AC39: =IFERROR(IF(NOT(ISNUMBER($V39)),"",$J39*$V39),"") -> 12 | AD39: =IFERROR(IF(NOT(ISNUMBER($W39)),"",$K39*$W39),"") -> 6 | AE39: =IFERROR(IF(NOT(ISNUMBER($X39)),"",$L39*$X39),"") -> 6
A40: P07 | B40: Rocío F. | C40: Ayudante/a de cocina | D40: 46267 | E40: P02 | F40: 4 | G40: 4 | H40: 4 | I40: 5 | J40: 4 | K40: 4 | L40: 3 | M40: =IFERROR(IF(SUM($R40:$X40)=0,"",SUM($Y40:$AE40)/SUM($R40:$X40)),"") -> 4 | N40: =IF(NOT(ISNUMBER($M40)),"",IF($M40>=$B$28,$A$28,IF($M40>=$B$29,$A$29,IF($M40>=$B$30,$A$30,"")))) -> 3 | O40: 3 | P40: =IF(OR(NOT(ISNUMBER($N40)),NOT(ISNUMBER($O40))),"",IF($N40>$O40,$A$56,IF($N40=$O40,$A$54,$A$55))) -> Coherente | R40: =IFERROR(IF(NOT(ISNUMBER($F40)),"",INDEX($B$16:$H$23,MATCH($C40,$A$16:$A$23,0),1)),"") -> 3 | S40: =IFERROR(IF(NOT(ISNUMBER($G40)),"",INDEX($B$16:$H$23,MATCH($C40,$A$16:$A$23,0),2)),"") -> 2 | T40: =IFERROR(IF(NOT(ISNUMBER($H40)),"",INDEX($B$16:$H$23,MATCH($C40,$A$16:$A$23,0),3)),"") -> 2 | U40: =IFERROR(IF(NOT(ISNUMBER($I40)),"",INDEX($B$16:$H$23,MATCH($C40,$A$16:$A$23,0),4)),"") -> 2 | V40: =IFERROR(IF(NOT(ISNUMBER($J40)),"",INDEX($B$16:$H$23,MATCH($C40,$A$16:$A$23,0),5)),"") -> 3 | W40: =IFERROR(IF(NOT(ISNUMBER($K40)),"",INDEX($B$16:$H$23,MATCH($C40,$A$16:$A$23,0),6)),"") -> 2 | X40: =IFERROR(IF(NOT(ISNUMBER($L40)),"",INDEX($B$16:$H$23,MATCH($C40,$A$16:$A$23,0),7)),"") -> 2 | Y40: =IFERROR(IF(NOT(ISNUMBER($R40)),"",$F40*$R40),"") -> 12 | Z40: =IFERROR(IF(NOT(ISNUMBER($S40)),"",$G40*$S40),"") -> 8 | AA40: =IFERROR(IF(NOT(ISNUMBER($T40)),"",$H40*$T40),"") -> 8 | AB40: =IFERROR(IF(NOT(ISNUMBER($U40)),"",$I40*$U40),"") -> 10 | AC40: =IFERROR(IF(NOT(ISNUMBER($V40)),"",$J40*$V40),"") -> 12 | AD40: =IFERROR(IF(NOT(ISNUMBER($W40)),"",$K40*$W40),"") -> 8 | AE40: =IFERROR(IF(NOT(ISNUMBER($X40)),"",$L40*$X40),"") -> 6
A41: P08 | B41: Carlos V. | C41: No evaluado en la rúbrica de cocina | M41: =IFERROR(IF(SUM($R41:$X41)=0,"",SUM($Y41:$AE41)/SUM($R41:$X41)),"") | N41: =IF(NOT(ISNUMBER($M41)),"",IF($M41>=$B$28,$A$28,IF($M41>=$B$29,$A$29,IF($M41>=$B$30,$A$30,"")))) | O41: 0 | P41: =IF(OR(NOT(ISNUMBER($N41)),NOT(ISNUMBER($O41))),"",IF($N41>$O41,$A$56,IF($N41=$O41,$A$54,$A$55))) | R41: =IFERROR(IF(NOT(ISNUMBER($F41)),"",INDEX($B$16:$H$23,MATCH($C41,$A$16:$A$23,0),1)),"") | S41: =IFERROR(IF(NOT(ISNUMBER($G41)),"",INDEX($B$16:$H$23,MATCH($C41,$A$16:$A$23,0),2)),"") | T41: =IFERROR(IF(NOT(ISNUMBER($H41)),"",INDEX($B$16:$H$23,MATCH($C41,$A$16:$A$23,0),3)),"") | U41: =IFERROR(IF(NOT(ISNUMBER($I41)),"",INDEX($B$16:$H$23,MATCH($C41,$A$16:$A$23,0),4)),"") | V41: =IFERROR(IF(NOT(ISNUMBER($J41)),"",INDEX($B$16:$H$23,MATCH($C41,$A$16:$A$23,0),5)),"") | W41: =IFERROR(IF(NOT(ISNUMBER($K41)),"",INDEX($B$16:$H$23,MATCH($C41,$A$16:$A$23,0),6)),"") | X41: =IFERROR(IF(NOT(ISNUMBER($L41)),"",INDEX($B$16:$H$23,MATCH($C41,$A$16:$A$23,0),7)),"") | Y41: =IFERROR(IF(NOT(ISNUMBER($R41)),"",$F41*$R41),"") | Z41: =IFERROR(IF(NOT(ISNUMBER($S41)),"",$G41*$S41),"") | AA41: =IFERROR(IF(NOT(ISNUMBER($T41)),"",$H41*$T41),"") | AB41: =IFERROR(IF(NOT(ISNUMBER($U41)),"",$I41*$U41),"") | AC41: =IFERROR(IF(NOT(ISNUMBER($V41)),"",$J41*$V41),"") | AD41: =IFERROR(IF(NOT(ISNUMBER($W41)),"",$K41*$W41),"") | AE41: =IFERROR(IF(NOT(ISNUMBER($X41)),"",$L41*$X41),"")
A42: P09 | B42: Elena T. | C42: No evaluado en la rúbrica de cocina | M42: =IFERROR(IF(SUM($R42:$X42)=0,"",SUM($Y42:$AE42)/SUM($R42:$X42)),"") | N42: =IF(NOT(ISNUMBER($M42)),"",IF($M42>=$B$28,$A$28,IF($M42>=$B$29,$A$29,IF($M42>=$B$30,$A$30,"")))) | O42: 0 | P42: =IF(OR(NOT(ISNUMBER($N42)),NOT(ISNUMBER($O42))),"",IF($N42>$O42,$A$56,IF($N42=$O42,$A$54,$A$55))) | R42: =IFERROR(IF(NOT(ISNUMBER($F42)),"",INDEX($B$16:$H$23,MATCH($C42,$A$16:$A$23,0),1)),"") | S42: =IFERROR(IF(NOT(ISNUMBER($G42)),"",INDEX($B$16:$H$23,MATCH($C42,$A$16:$A$23,0),2)),"") | T42: =IFERROR(IF(NOT(ISNUMBER($H42)),"",INDEX($B$16:$H$23,MATCH($C42,$A$16:$A$23,0),3)),"") | U42: =IFERROR(IF(NOT(ISNUMBER($I42)),"",INDEX($B$16:$H$23,MATCH($C42,$A$16:$A$23,0),4)),"") | V42: =IFERROR(IF(NOT(ISNUMBER($J42)),"",INDEX($B$16:$H$23,MATCH($C42,$A$16:$A$23,0),5)),"") | W42: =IFERROR(IF(NOT(ISNUMBER($K42)),"",INDEX($B$16:$H$23,MATCH($C42,$A$16:$A$23,0),6)),"") | X42: =IFERROR(IF(NOT(ISNUMBER($L42)),"",INDEX($B$16:$H$23,MATCH($C42,$A$16:$A$23,0),7)),"") | Y42: =IFERROR(IF(NOT(ISNUMBER($R42)),"",$F42*$R42),"") | Z42: =IFERROR(IF(NOT(ISNUMBER($S42)),"",$G42*$S42),"") | AA42: =IFERROR(IF(NOT(ISNUMBER($T42)),"",$H42*$T42),"") | AB42: =IFERROR(IF(NOT(ISNUMBER($U42)),"",$I42*$U42),"") | AC42: =IFERROR(IF(NOT(ISNUMBER($V42)),"",$J42*$V42),"") | AD42: =IFERROR(IF(NOT(ISNUMBER($W42)),"",$K42*$W42),"") | AE42: =IFERROR(IF(NOT(ISNUMBER($X42)),"",$L42*$X42),"")
A43: P10 | B43: Youssef A. | C43: No evaluado en la rúbrica de cocina | M43: =IFERROR(IF(SUM($R43:$X43)=0,"",SUM($Y43:$AE43)/SUM($R43:$X43)),"") | N43: =IF(NOT(ISNUMBER($M43)),"",IF($M43>=$B$28,$A$28,IF($M43>=$B$29,$A$29,IF($M43>=$B$30,$A$30,"")))) | O43: 0 | P43: =IF(OR(NOT(ISNUMBER($N43)),NOT(ISNUMBER($O43))),"",IF($N43>$O43,$A$56,IF($N43=$O43,$A$54,$A$55))) | R43: =IFERROR(IF(NOT(ISNUMBER($F43)),"",INDEX($B$16:$H$23,MATCH($C43,$A$16:$A$23,0),1)),"") | S43: =IFERROR(IF(NOT(ISNUMBER($G43)),"",INDEX($B$16:$H$23,MATCH($C43,$A$16:$A$23,0),2)),"") | T43: =IFERROR(IF(NOT(ISNUMBER($H43)),"",INDEX($B$16:$H$23,MATCH($C43,$A$16:$A$23,0),3)),"") | U43: =IFERROR(IF(NOT(ISNUMBER($I43)),"",INDEX($B$16:$H$23,MATCH($C43,$A$16:$A$23,0),4)),"") | V43: =IFERROR(IF(NOT(ISNUMBER($J43)),"",INDEX($B$16:$H$23,MATCH($C43,$A$16:$A$23,0),5)),"") | W43: =IFERROR(IF(NOT(ISNUMBER($K43)),"",INDEX($B$16:$H$23,MATCH($C43,$A$16:$A$23,0),6)),"") | X43: =IFERROR(IF(NOT(ISNUMBER($L43)),"",INDEX($B$16:$H$23,MATCH($C43,$A$16:$A$23,0),7)),"") | Y43: =IFERROR(IF(NOT(ISNUMBER($R43)),"",$F43*$R43),"") | Z43: =IFERROR(IF(NOT(ISNUMBER($S43)),"",$G43*$S43),"") | AA43: =IFERROR(IF(NOT(ISNUMBER($T43)),"",$H43*$T43),"") | AB43: =IFERROR(IF(NOT(ISNUMBER($U43)),"",$I43*$U43),"") | AC43: =IFERROR(IF(NOT(ISNUMBER($V43)),"",$J43*$V43),"") | AD43: =IFERROR(IF(NOT(ISNUMBER($W43)),"",$K43*$W43),"") | AE43: =IFERROR(IF(NOT(ISNUMBER($X43)),"",$L43*$X43),"")
A44: P11 | B44: Paula G. | C44: No evaluado en la rúbrica de cocina | M44: =IFERROR(IF(SUM($R44:$X44)=0,"",SUM($Y44:$AE44)/SUM($R44:$X44)),"") | N44: =IF(NOT(ISNUMBER($M44)),"",IF($M44>=$B$28,$A$28,IF($M44>=$B$29,$A$29,IF($M44>=$B$30,$A$30,"")))) | O44: 0 | P44: =IF(OR(NOT(ISNUMBER($N44)),NOT(ISNUMBER($O44))),"",IF($N44>$O44,$A$56,IF($N44=$O44,$A$54,$A$55))) | R44: =IFERROR(IF(NOT(ISNUMBER($F44)),"",INDEX($B$16:$H$23,MATCH($C44,$A$16:$A$23,0),1)),"") | S44: =IFERROR(IF(NOT(ISNUMBER($G44)),"",INDEX($B$16:$H$23,MATCH($C44,$A$16:$A$23,0),2)),"") | T44: =IFERROR(IF(NOT(ISNUMBER($H44)),"",INDEX($B$16:$H$23,MATCH($C44,$A$16:$A$23,0),3)),"") | U44: =IFERROR(IF(NOT(ISNUMBER($I44)),"",INDEX($B$16:$H$23,MATCH($C44,$A$16:$A$23,0),4)),"") | V44: =IFERROR(IF(NOT(ISNUMBER($J44)),"",INDEX($B$16:$H$23,MATCH($C44,$A$16:$A$23,0),5)),"") | W44: =IFERROR(IF(NOT(ISNUMBER($K44)),"",INDEX($B$16:$H$23,MATCH($C44,$A$16:$A$23,0),6)),"") | X44: =IFERROR(IF(NOT(ISNUMBER($L44)),"",INDEX($B$16:$H$23,MATCH($C44,$A$16:$A$23,0),7)),"") | Y44: =IFERROR(IF(NOT(ISNUMBER($R44)),"",$F44*$R44),"") | Z44: =IFERROR(IF(NOT(ISNUMBER($S44)),"",$G44*$S44),"") | AA44: =IFERROR(IF(NOT(ISNUMBER($T44)),"",$H44*$T44),"") | AB44: =IFERROR(IF(NOT(ISNUMBER($U44)),"",$I44*$U44),"") | AC44: =IFERROR(IF(NOT(ISNUMBER($V44)),"",$J44*$V44),"") | AD44: =IFERROR(IF(NOT(ISNUMBER($W44)),"",$K44*$W44),"") | AE44: =IFERROR(IF(NOT(ISNUMBER($X44)),"",$L44*$X44),"")
...

Sheet Prueba Práctica
A1: Prueba práctica de competencias
A2: AI Chef Pro · aichef.pro — Manual del Chef Ejecutivo
A3: El guion de la prueba: una por competencia, con lo que es un 5 y lo que es un 1. Sin esto, la rúbrica es una opinión.
A5: Persona evaluada | D5: Imprime una copia por persona: la prueba se apunta mientras se hace, no después.
A6: Fecha de la prueba
A7: Evaluador
A10: Competencia | B10: Prueba | C10: Minutos | D10: Material | E10: Qué es un 5 | F10: Qué es un 1 | G10: Puntuación | H10: Observaciones
A11: Cortes y manejo de cuchillo | B11: Brunoise de 200 g de cebolla, juliana de 200 g de puerro y racionado de un solomillo de cerdo en medallones de 110 g | C11: 20 | D11: Tabla, cuchillo cebollero, puntilla, báscula | E11: Corte regular, dentro de peso en los seis medallones y merma por debajo del objetivo de la partida, a ritmo | F11: Corte irregular, medallones fuera de peso y merma por encima del doble del objetivo
A12: Cocciones y puntos | B12: Marcar y terminar dos solomillos: uno al punto y otro poco hecho, con sonda a la vista del evaluador | C12: 25 | D12: Plancha, horno, sonda calibrada | E12: Los dos puntos clavados con menos de 2 °C de desviación y reposo respetado | F12: Los dos puntos fuera y sin usar la sonda
A13: Fondos, salsas y bases | B13: Elaborar la salsa de Pedro Ximénez de la ficha de P1 a partir del fondo del día | C13: 30 | D13: Rondon, chino, ficha técnica del plato | E13: Ligazón, sazón y acidez de la ficha, colada y enfriada según conservación | F13: Salsa desligada o quemada, o sin enfriar según el procedimiento
A14: Emplatado y montaje | B14: Montar tres raciones seguidas del plato P1 con la foto de la ficha tapada | C14: 15 | D14: Vajilla de servicio, ficha con la foto tapada | E14: Los tres platos idénticos entre si y a la foto, en menos de 3 minutos cada uno | F14: Los tres platos distintos entre si o fuera del montaje de la ficha
A15: Higiene de manipulación y APPCC en el puesto | B15: Recepción simulada de un pedido de pescado y carne: comprobación, etiquetado y registro hasta cámara | C15: 20 | D15: Termómetro, etiquetas, hojas de registro del plan APPCC | E15: Comprueba temperatura y etiquetado, rechaza lo que procede, registra y coloca por orden de caducidad | F15: No mide temperatura, no registra o rompe el orden de caducidad
A16: Conocimiento y aplicación de la ficha técnica | B16: Ejecutar un plato de otra partida solo con la ficha delante | C16: 30 | D16: Ficha técnica del plato, mise en place estándar | E16: Sale igual que el de la partida titular, con gramajes y tiempos de la ficha | F16: Se aparta de gramajes o tiempos sin darse cuenta
A17: Gestión de la merma de su partida | B17: Analizar la serie de cuatro semanas de merma de su partida y proponer dos acciones con su ahorro estimado | C17: 20 | D17: Cuadro de mando de cocina, hoja de la partida | E17: Identifica la causa real, propone dos acciones concretas y estima el ahorro con la herramienta | F17: No sabe cuál es el objetivo de su partida ni de dónde sale su merma
A18: Duración total de la prueba (minutos) | C18: =IF(COUNT($C$11:$C$17)=0,"",SUM($C$11:$C$17)) -> 160
A19: Media SIMPLE de la prueba (sin pesos) | G19: =IFERROR(IF(COUNT($G$11:$G$17)=0,"",AVERAGE($G$11:$G$17)),"")
A21: Esta media es SIMPLE y sólo sirve para verla de un vistazo al terminar. La nota que cuenta es la ponderada de la hoja «Rúbrica de Competencias», que pesa cada competencia según el puesto: para un ayudante, los cortes pesan más que las salsas.
A22: Las puntuaciones de esta hoja se pasan A MANO a la hoja de evaluación. Es a propósito: la prueba se hace con una persona delante y la evaluación se cierra después, revisando lo que se apuntó.
A24: Versión 1.0 · septiembre 2026 · aichef.pro/manual-chef-ejecutivo · info@aichef.pro

Sheet Plan de Desarrollo Individual
A1: Plan de desarrollo individual
A2: AI Chef Pro · aichef.pro — Manual del Chef Ejecutivo
A3: Qué va a trabajar cada persona, con quién y para cuándo. Sale de la evaluación técnica, no de una conversación de pasillo.
A5: Fecha de control | C5: 46271 | D5: Cámbiala y se recalculan los días que quedan para cada fecha objetivo.
A8: Id | B8: Persona | C8: Objetivo | D8: Competencias a trabajar | E8: Acciones | F8: Responsable | G8: Fecha objetivo | H8: Estado | I8: Días restantes | J8: Próxima partida a aprender | K8: Remite a
A9: P06 | B9: Omar B. | C9: Sostener la partida de fríos en un servicio de 75 cubiertos (nivel 2) | D9: Cortes y manejo de cuchillo; Conocimiento y aplicación de la ficha técnica; Gestión de la merma de su partida | E9: Dos servicios por semana en fríos con P05 al lado; ejecutar los cuatro entrantes con la ficha delante; anotar merma a diario durante seis semanas | F9: P05 | G9: 46310 | H9: En curso | I9: =IFERROR(IF(OR($G9="",$C$5=""),"",$G9-$C$5),"") -> 39 | J9: Fríos y entrantes | K9: Plan de Cross-Training del Manual del Manager, fila 1
A10: P12 | B10: Andrés P. | C10: Cubrir el pase en caliente a nivel 2 antes de la temporada alta | D10: Cortes y manejo de cuchillo; Cocciones y puntos; Higiene de manipulación y APPCC en el puesto | E10: Rotación de dos servicios por semana en pase; prueba práctica de cortes y de puntos en enero | F10: P04 | G10: 46418 | H10: Planificado | I10: =IFERROR(IF(OR($G10="",$C$5=""),"",$G10-$C$5),"") -> 147 | J10: Pase y caliente | K10: Plan de Cross-Training del Manual del Manager, fila 7
A11: P05 | B11: Laura S. | C11: Subir de 3 a 4 en gestión de la merma de su partida tras el verano | D11: Gestión de la merma de su partida | E11: Analizar las semanas 33, 34 y 35 con el cuadro de mando; fijar producción diaria de fríos con la lista de producción; revisión quincenal con el jefe de cocina | F11: P02 | G11: 46356 | H11: En curso | I11: =IFERROR(IF(OR($G11="",$C$5=""),"",$G11-$C$5),"") -> 85 | K11: Cuadro de mando de cocina, hoja Semana
A12: P04 | B12: Diego M. | C12: Preparar el paso a jefe de partida de caliente | D12: Emplatado y montaje; Gestión de la merma de su partida | E12: Llevar el pase de los viernes y sábados; escribir dos fichas técnicas nuevas de la carta de otoño; presentar el informe de merma de su partida en la reunión mensual | F12: P02 | G12: 46477 | H12: Planificado | I12: =IFERROR(IF(OR($G12="",$C$5=""),"",$G12-$C$5),"") -> 206 | J12: Fríos y entrantes | K12: Fichas de puesto del libro de brigada, «Jefe/a de partida»
I13: =IFERROR(IF(OR($G13="",$C$5=""),"",$G13-$C$5),"")
I14: =IFERROR(IF(OR($G14="",$C$5=""),"",$G14-$C$5),"")
I15: =IFERROR(IF(OR($G15="",$C$5=""),"",$G15-$C$5),"")
I16: =IFERROR(IF(OR($G16="",$C$5=""),"",$G16-$C$5),"")
I17: =IFERROR(IF(OR($G17="",$C$5=""),"",$G17-$C$5),"")
I18: =IFERROR(IF(OR($G18="",$C$5=""),"",$G18-$C$5),"")
