Workbook

Sheet Instrucciones
A1: Planificación de producción semanal
A2: AI Chef Pro · aichef.pro — Manual del Chef Ejecutivo
A3: Para qué sirve: producir lo que se va a vender, ni una ración más.
A5: Instrucciones de uso
A6: 1. Hoja «Previsión de Cubiertos»: pon la semana ISO, el lunes que la abre y cuántos días abres. Después, por cada día y servicio, las reservas confirmadas y el histórico de ese mismo servicio (la media de las cuatro semanas anteriores). El libro te sugiere una previsión; la que manda es la que escribas tú en la columna verde.
A7: 2. Hoja «Producción por Partida»: escribe tus partidas (estaciones, en el vocabulario de la matriz de polivalencia del Manual del Manager) y cuántas tienes activas. Después, plato a plato: la partida que lo produce, la unidad de ración, el mix de venta y lo que ya tienes elaborado en cámara.
A8: 3. Esa hoja hace la única cuenta que importa: cantidad a producir = cubiertos previstos x mix de venta - stock ya elaborado. Si te sale cero, no produces; si el stock supera la demanda de toda la semana, la columna «Alerta» te lo dice con todas las letras.
A9: 4. El bloque «Resumen por partida» del final te dice cuántas raciones le tocan esta semana a cada partida. Es lo que se lee en la reunión de los lunes y lo que decide si hace falta una mano más en fríos.
A10: 5. Hoja «Lista de Producción Diaria»: elige el día y IMPRÍMELA. Sale en A4 vertical con las cantidades del día ya calculadas, y con las columnas en blanco para que el equipo anote lo producido, la hora, la conservación y quién lo hizo. Es el checklist de este manual.
A11: 6. Hoja «Ajuste por Desviación»: se rellena al CERRAR la semana, no antes. Se apuntan los cubiertos reales y lo que de verdad se produjo y se vendió, y la hoja te dice de cuánto te has desviado y qué histórico llevarte a la semana siguiente. Viene vacía a propósito.
A12: 7. Cadencia de uso: la previsión y la producción, UNA VEZ POR SEMANA (el viernes o el sábado, para la semana siguiente). La lista diaria, todos los días. El ajuste, al cerrar la semana.
A14: Celdas verdes = campos editables
A16: De dónde sale cada dato
A17: Dato | B17: De dónde sale | C17: Qué no hay que volver a teclear
A18: Cubiertos previstos por día y servicio | B18: Del histórico de tu TPV y de las reservas confirmadas. Si tienes el Manual del Manager, la columna de cubiertos de su cuadro de mando semanal ya lleva el histórico de las 52 semanas | C18: El histórico: cópialo de una semana a otra con la última columna de la hoja «Ajuste por Desviación»
A19: Mix de venta de cada plato | B19: Del TPV o de la ingeniería de menú de la «Guía Food Cost + Ingeniería de Menú» | C19: El mix se teclea una vez por temporada, no cada semana
A20: Partidas de la cocina | B20: Las mismas del cuadro de mando de cocina (libro 1 de este pack) | C20: Cópialas del libro 1: son copia declarada, no vínculo
A21: Ninguna hoja de este libro lee una celda de otro fichero: es copia declarada. Si mueves un fichero de carpeta, nada se rompe.
A23: Lo que conviene saber antes de empezar
A24: ESTE LIBRO NO ES UN CHECKLIST DE TAREAS. Los «Kit de Tareas» preguntan «¿se hizo la tarea de apertura?»; éste responde «cuántas raciones hay que producir hoy en cada partida». La «Lista de Producción Diaria» es la única hoja que se imprime y se firma, y lo que registra son cantidades, no tareas.
A25: La merma NO se mide aquí. Lo que esta hoja mide al cerrar la semana es el SOBRANTE: raciones producidas menos raciones vendidas. La merma por partida (kilos que se van a la basura sobre kilos producidos) se registra en el cuadro de mando de cocina, que es el libro 1 de este pack. No son lo mismo y no se suman.
A26: El coste de una ración no se calcula aquí: se copia del escandallo. Este pack no recalcula ningún coste, y por eso ninguna hoja lleva una columna de euros. El escandallo vive en el «Kit de Escandallos» y en la «Guía Food Cost + Ingeniería de Menú».
A27: El mix de venta es el porcentaje de cubiertos que pide cada plato: si de cada 100 comensales 11 piden croquetas, el mix de las croquetas es el 11 %. Sale del TPV, del histórico de la carta o de la ingeniería de menú, y se revisa cuando cambia la carta.
A28: La previsión sugerida es el MAYOR entre las reservas confirmadas y el histórico, redondeado hacia arriba. Es una sugerencia mecánica: el que sabe que el sábado hay partido, o que llueve toda la semana, eres tú.
A29: Un dato que falta se deja EN BLANCO, nunca a cero. Un cero es una medida («no hay stock de este plato») y un blanco es la ausencia de medida: el libro los trata distinto.
A31: Para editar la estructura o una celda que no este en verde, desprotege la hoja (sin contraseña).
A32: Ruta en Excel: Revisar > Desproteger hoja. La protección no tiene contraseña; sirve para no pisar una fórmula sin querer.
A34: Diseñado por John Guerrero — chef y consultor gastronómico desde 2010 · johnguerrero.es
A35: Versión 1.0 · septiembre 2026 · aichef.pro/manual-chef-ejecutivo · info@aichef.pro

Sheet Previsión de Cubiertos
A1: Previsión de cubiertos de la semana
A2: AI Chef Pro · aichef.pro — Manual del Chef Ejecutivo
A3: La previsión que manda es la tuya. La sugerida es una cuenta mecánica sobre reservas e histórico.
A5: LA SEMANA QUE SE PLANIFICA
A6: Semana ISO | B6: 37
A7: Lunes de la semana | B7: 46272
A8: Días que cubre la planificación | B8: 7
A9: Último día de la semana | B9: =IF(OR($B$7="",$B$8=""),"",$B$7+$B$8-1) -> 46278
A10: La semana ISO empieza en lunes y la semana 1 del año es la que contiene el primer jueves de enero. Los días que cubre la planificación son SIETE aunque cierres uno o dos: los días de cierre se dejan en blanco y no suman.
A11: El último día de la semana lo calcula el libro y es el que usa la hoja «Producción por Partida» para avisar de un stock que caduca antes de consumirse.
A13: PREVISIÓN POR DÍA Y SERVICIO
A14: Día | B14: Servicio | C14: Reservas confirmadas | D14: Histórico del mismo servicio (media de 4 semanas) | E14: Previsión sugerida | F14: Previsión de cubiertos (la tuya) | G14: Diferencia con la sugerida
A15: Lunes | B15: Comida | E15: =IFERROR(IF(AND($C15="",$D15=""),"",ROUNDUP(MAX(IF($C15="",0,$C15),IF($D15="",0,$D15)),0)),"") | G15: =IFERROR(IF(OR(NOT(ISNUMBER($F15)),NOT(ISNUMBER($E15)),$E15=0),"",($F15-$E15)/$E15),"")
A16: Lunes | B16: Cena | E16: =IFERROR(IF(AND($C16="",$D16=""),"",ROUNDUP(MAX(IF($C16="",0,$C16),IF($D16="",0,$D16)),0)),"") | G16: =IFERROR(IF(OR(NOT(ISNUMBER($F16)),NOT(ISNUMBER($E16)),$E16=0),"",($F16-$E16)/$E16),"")
A17: Martes | B17: Comida | C17: 34 | D17: 58 | E17: =IFERROR(IF(AND($C17="",$D17=""),"",ROUNDUP(MAX(IF($C17="",0,$C17),IF($D17="",0,$D17)),0)),"") -> 58 | F17: 60 | G17: =IFERROR(IF(OR(NOT(ISNUMBER($F17)),NOT(ISNUMBER($E17)),$E17=0),"",($F17-$E17)/$E17),"") -> 0.034482759
A18: Martes | B18: Cena | C18: 22 | D18: 41 | E18: =IFERROR(IF(AND($C18="",$D18=""),"",ROUNDUP(MAX(IF($C18="",0,$C18),IF($D18="",0,$D18)),0)),"") -> 41 | F18: 40 | G18: =IFERROR(IF(OR(NOT(ISNUMBER($F18)),NOT(ISNUMBER($E18)),$E18=0),"",($F18-$E18)/$E18),"") -> -0.024390244
A19: Miércoles | B19: Comida | C19: 38 | D19: 62 | E19: =IFERROR(IF(AND($C19="",$D19=""),"",ROUNDUP(MAX(IF($C19="",0,$C19),IF($D19="",0,$D19)),0)),"") -> 62 | F19: 64 | G19: =IFERROR(IF(OR(NOT(ISNUMBER($F19)),NOT(ISNUMBER($E19)),$E19=0),"",($F19-$E19)/$E19),"") -> 0.032258065
A20: Miércoles | B20: Cena | C20: 26 | D20: 45 | E20: =IFERROR(IF(AND($C20="",$D20=""),"",ROUNDUP(MAX(IF($C20="",0,$C20),IF($D20="",0,$D20)),0)),"") -> 45 | F20: 46 | G20: =IFERROR(IF(OR(NOT(ISNUMBER($F20)),NOT(ISNUMBER($E20)),$E20=0),"",($F20-$E20)/$E20),"") -> 0.022222222
A21: Jueves | B21: Comida | C21: 41 | D21: 68 | E21: =IFERROR(IF(AND($C21="",$D21=""),"",ROUNDUP(MAX(IF($C21="",0,$C21),IF($D21="",0,$D21)),0)),"") -> 68 | F21: 70 | G21: =IFERROR(IF(OR(NOT(ISNUMBER($F21)),NOT(ISNUMBER($E21)),$E21=0),"",($F21-$E21)/$E21),"") -> 0.029411765
A22: Jueves | B22: Cena | C22: 34 | D22: 56 | E22: =IFERROR(IF(AND($C22="",$D22=""),"",ROUNDUP(MAX(IF($C22="",0,$C22),IF($D22="",0,$D22)),0)),"") -> 56 | F22: 58 | G22: =IFERROR(IF(OR(NOT(ISNUMBER($F22)),NOT(ISNUMBER($E22)),$E22=0),"",($F22-$E22)/$E22),"") -> 0.035714286
A23: Viernes | B23: Comida | C23: 46 | D23: 76 | E23: =IFERROR(IF(AND($C23="",$D23=""),"",ROUNDUP(MAX(IF($C23="",0,$C23),IF($D23="",0,$D23)),0)),"") -> 76 | F23: 78 | G23: =IFERROR(IF(OR(NOT(ISNUMBER($F23)),NOT(ISNUMBER($E23)),$E23=0),"",($F23-$E23)/$E23),"") -> 0.026315789
A24: Viernes | B24: Cena | C24: 68 | D24: 102 | E24: =IFERROR(IF(AND($C24="",$D24=""),"",ROUNDUP(MAX(IF($C24="",0,$C24),IF($D24="",0,$D24)),0)),"") -> 102 | F24: 105 | G24: =IFERROR(IF(OR(NOT(ISNUMBER($F24)),NOT(ISNUMBER($E24)),$E24=0),"",($F24-$E24)/$E24),"") -> 0.029411765
A25: Sábado | B25: Comida | C25: 55 | D25: 89 | E25: =IFERROR(IF(AND($C25="",$D25=""),"",ROUNDUP(MAX(IF($C25="",0,$C25),IF($D25="",0,$D25)),0)),"") -> 89 | F25: 92 | G25: =IFERROR(IF(OR(NOT(ISNUMBER($F25)),NOT(ISNUMBER($E25)),$E25=0),"",($F25-$E25)/$E25),"") -> 0.033707865
A26: Sábado | B26: Cena | C26: 79 | D26: 115 | E26: =IFERROR(IF(AND($C26="",$D26=""),"",ROUNDUP(MAX(IF($C26="",0,$C26),IF($D26="",0,$D26)),0)),"") -> 115 | F26: 118 | G26: =IFERROR(IF(OR(NOT(ISNUMBER($F26)),NOT(ISNUMBER($E26)),$E26=0),"",($F26-$E26)/$E26),"") -> 0.026086957
A27: Domingo | B27: Comida | C27: 88 | D27: 128 | E27: =IFERROR(IF(AND($C27="",$D27=""),"",ROUNDUP(MAX(IF($C27="",0,$C27),IF($D27="",0,$D27)),0)),"") -> 128 | F27: 132 | G27: =IFERROR(IF(OR(NOT(ISNUMBER($F27)),NOT(ISNUMBER($E27)),$E27=0),"",($F27-$E27)/$E27),"") -> 0.03125
A28: Domingo | B28: Cena | C28: 56 | D28: 93 | E28: =IFERROR(IF(AND($C28="",$D28=""),"",ROUNDUP(MAX(IF($C28="",0,$C28),IF($D28="",0,$D28)),0)),"") -> 93 | F28: 95 | G28: =IFERROR(IF(OR(NOT(ISNUMBER($F28)),NOT(ISNUMBER($E28)),$E28=0),"",($F28-$E28)/$E28),"") -> 0.021505376
A29: TOTAL DE LA SEMANA | C29: =IF(COUNT(C15:C28)=0,"",SUM(C15:C28)) -> 587 | D29: =IF(COUNT(D15:D28)=0,"",SUM(D15:D28)) -> 933 | E29: =IF(COUNT(E15:E28)=0,"",SUM(E15:E28)) -> 933 | F29: =IF(COUNT(F15:F28)=0,"",SUM(F15:F28)) -> 958 | G29: =IFERROR(IF(OR(NOT(ISNUMBER($F$29)),NOT(ISNUMBER($E$29)),$E$29=0),"",($F$29-$E$29)/$E$29),"") -> 0.026795284
A31: El total de la columna «Previsión de cubiertos (la tuya)» es el que alimenta la hoja «Producción por Partida». Si cambias un solo día, la producción de toda la semana se recalcula sola.
A32: En el restaurante de ejemplo el lunes está cerrado: sus dos filas van en blanco y no suman. Si tú abres los lunes, rellénalas.
A33: La diferencia con la sugerida no es un error: es tu criterio. Lo que sí conviene mirar es si SIEMPRE vas por encima o SIEMPRE por debajo, porque entonces el que está mal calibrado es el histórico.

Sheet Producción por Partida
A1: Producción de la semana, partida por partida
A2: AI Chef Pro · aichef.pro — Manual del Chef Ejecutivo
A3: Cantidad a producir = cubiertos previstos x mix de venta - stock ya elaborado.
A5: PARÁMETROS DE LA SEMANA
A6: Cubiertos previstos de la semana | B6: =IF('Previsión de Cubiertos'!$F$29="","",'Previsión de Cubiertos'!$F$29) -> 958
A7: Partidas activas (de 3 a 8) | B7: 6
A8: Los cubiertos de la semana los trae la hoja «Previsión de Cubiertos»: no se teclean aquí.
A9: Las partidas activas gobiernan el «Resumen por partida» del final de la hoja: si pones 4, las ranuras 5 a 8 se quedan en blanco.
A11: Partidas de tu cocina
A12: Pase y caliente
A13: Fríos y entrantes
A14: Postres y panadería
A15: Barra y bebidas
A16: Sala y servicio
A17: Caja y cierre
A20: Son las mismas partidas del cuadro de mando de cocina (libro 1). Cópialas de allí: este libro no lee ningún fichero ajeno. Las dos últimas ranuras están libres para cocinas con más partidas.
A22: PLATOS DE LA CARTA
A23: Id | B23: Plato | C23: Elaboración previa (mise en place) | D23: Partida | E23: Unidad de ración | F23: Mix de venta (% de los cubiertos) | G23: Raciones previstas en la semana | H23: Stock ya elaborado (raciones) | I23: Conservación del stock | J23: Fecha de elaboración del stock | K23: Vida útil (días) | L23: Consumir antes del | M23: Cantidad a producir (raciones) | N23: Alerta
A24: E1 | B24: Croquetas de jamón ibérico (6 ud) | C24: Masa de croqueta ya formada y empanada | D24: Fríos y entrantes | E24: 6 croquetas | F24: 0.10769231 | G24: =IFERROR(IF(OR(NOT(ISNUMBER($F24)),NOT(ISNUMBER($B$6))),"",ROUNDUP($F24*$B$6,0)),"") -> 104 | H24: 140 | I24: Refrigeración a 4 °C | J24: 46270 | K24: 3 | L24: =IF(OR(NOT(ISNUMBER($J24)),NOT(ISNUMBER($K24))),"",$J24+$K24) -> 46273 | M24: =IFERROR(IF($G24="","",MAX(0,$G24-IF($H24="",0,$H24))),"") -> 0 | N24: =IFERROR(IF($G24="","",TRIM(IF(AND(ISNUMBER($H24),$H24>$G24),"Sobreproducción: el stock ya cubre toda la semana, no produzcas","")&IF(AND(AND(ISNUMBER($H24),$H24>$G24),AND(ISNUMBER($L24),ISNUMBER($H24),$H24>0,ISNUMBER('Previsión de Cubiertos'!$B$7),ISNUMBER('Previsión de Cubiertos'!$B$8),$G24>0,$L24<'Previsión de Cubiertos'!$B$7+$H24*'Previsión de Cubiertos'!$B$8/$G24)),". ","")&IF(AND(ISNUMBER($L24),ISNUMBER($H24),$H24>0,ISNUMBER('Previsión de Cubiertos'!$B$7),ISNUMBER('Previsión de Cubiertos'!$B$8),$G24>0,$L24<'Previsión de Cubiertos'!$B$7+$H24*'Previsión de Cubiertos'!$B$8/$G24),"El stock caduca antes de consumirse al ritmo previsto: prográmalo en los primeros días",""))),"") -> Sobreproducción: el stock ya cubre toda la semana, no produzcas. El stock caduca antes de consumirse al ritmo previsto: prográmalo en los primeros días
A25: E2 | B25: Ensalada de tomate rosa, ventresca y cebolleta | D25: Fríos y entrantes | E25: 1 ración de ensalada | F25: 0.079487179 | G25: =IFERROR(IF(OR(NOT(ISNUMBER($F25)),NOT(ISNUMBER($B$6))),"",ROUNDUP($F25*$B$6,0)),"") -> 77 | H25: 0 | I25: No aplica | L25: =IF(OR(NOT(ISNUMBER($J25)),NOT(ISNUMBER($K25))),"",$J25+$K25) | M25: =IFERROR(IF($G25="","",MAX(0,$G25-IF($H25="",0,$H25))),"") -> 77 | N25: =IFERROR(IF($G25="","",TRIM(IF(AND(ISNUMBER($H25),$H25>$G25),"Sobreproducción: el stock ya cubre toda la semana, no produzcas","")&IF(AND(AND(ISNUMBER($H25),$H25>$G25),AND(ISNUMBER($L25),ISNUMBER($H25),$H25>0,ISNUMBER('Previsión de Cubiertos'!$B$7),ISNUMBER('Previsión de Cubiertos'!$B$8),$G25>0,$L25<'Previsión de Cubiertos'!$B$7+$H25*'Previsión de Cubiertos'!$B$8/$G25)),". ","")&IF(AND(ISNUMBER($L25),ISNUMBER($H25),$H25>0,ISNUMBER('Previsión de Cubiertos'!$B$7),ISNUMBER('Previsión de Cubiertos'!$B$8),$G25>0,$L25<'Previsión de Cubiertos'!$B$7+$H25*'Previsión de Cubiertos'!$B$8/$G25),"El stock caduca antes de consumirse al ritmo previsto: prográmalo en los primeros días",""))),"")
A26: E3 | B26: Gambas al ajillo | C26: Gamba pelada y racionada | D26: Fríos y entrantes | E26: 1 cazuela | F26: 0.066666667 | G26: =IFERROR(IF(OR(NOT(ISNUMBER($F26)),NOT(ISNUMBER($B$6))),"",ROUNDUP($F26*$B$6,0)),"") -> 64 | H26: 32 | I26: Refrigeración a 4 °C | J26: 46271 | K26: 1 | L26: =IF(OR(NOT(ISNUMBER($J26)),NOT(ISNUMBER($K26))),"",$J26+$K26) -> 46272 | M26: =IFERROR(IF($G26="","",MAX(0,$G26-IF($H26="",0,$H26))),"") -> 32 | N26: =IFERROR(IF($G26="","",TRIM(IF(AND(ISNUMBER($H26),$H26>$G26),"Sobreproducción: el stock ya cubre toda la semana, no produzcas","")&IF(AND(AND(ISNUMBER($H26),$H26>$G26),AND(ISNUMBER($L26),ISNUMBER($H26),$H26>0,ISNUMBER('Previsión de Cubiertos'!$B$7),ISNUMBER('Previsión de Cubiertos'!$B$8),$G26>0,$L26<'Previsión de Cubiertos'!$B$7+$H26*'Previsión de Cubiertos'!$B$8/$G26)),". ","")&IF(AND(ISNUMBER($L26),ISNUMBER($H26),$H26>0,ISNUMBER('Previsión de Cubiertos'!$B$7),ISNUMBER('Previsión de Cubiertos'!$B$8),$G26>0,$L26<'Previsión de Cubiertos'!$B$7+$H26*'Previsión de Cubiertos'!$B$8/$G26),"El stock caduca antes de consumirse al ritmo previsto: prográmalo en los primeros días",""))),"") -> El stock caduca antes de consumirse al ritmo previsto: prográmalo en los primeros días
A27: E4 | B27: Huevos rotos con patatas y chistorra | C27: Patata confitada | D27: Fríos y entrantes | E27: 1 ración para compartir | F27: 0.097435897 | G27: =IFERROR(IF(OR(NOT(ISNUMBER($F27)),NOT(ISNUMBER($B$6))),"",ROUNDUP($F27*$B$6,0)),"") -> 94 | H27: 90 | I27: Refrigeración a 4 °C | J27: 46270 | K27: 4 | L27: =IF(OR(NOT(ISNUMBER($J27)),NOT(ISNUMBER($K27))),"",$J27+$K27) -> 46274 | M27: =IFERROR(IF($G27="","",MAX(0,$G27-IF($H27="",0,$H27))),"") -> 4 | N27: =IFERROR(IF($G27="","",TRIM(IF(AND(ISNUMBER($H27),$H27>$G27),"Sobreproducción: el stock ya cubre toda la semana, no produzcas","")&IF(AND(AND(ISNUMBER($H27),$H27>$G27),AND(ISNUMBER($L27),ISNUMBER($H27),$H27>0,ISNUMBER('Previsión de Cubiertos'!$B$7),ISNUMBER('Previsión de Cubiertos'!$B$8),$G27>0,$L27<'Previsión de Cubiertos'!$B$7+$H27*'Previsión de Cubiertos'!$B$8/$G27)),". ","")&IF(AND(ISNUMBER($L27),ISNUMBER($H27),$H27>0,ISNUMBER('Previsión de Cubiertos'!$B$7),ISNUMBER('Previsión de Cubiertos'!$B$8),$G27>0,$L27<'Previsión de Cubiertos'!$B$7+$H27*'Previsión de Cubiertos'!$B$8/$G27),"El stock caduca antes de consumirse al ritmo previsto: prográmalo en los primeros días",""))),"") -> El stock caduca antes de consumirse al ritmo previsto: prográmalo en los primeros días
A28: P1 | B28: Solomillo de cerdo ibérico con puré de boniato | C28: Puré de boniato | D28: Pase y caliente | E28: 1 ración (solomillo y puré) | F28: 0.087179487 | G28: =IFERROR(IF(OR(NOT(ISNUMBER($F28)),NOT(ISNUMBER($B$6))),"",ROUNDUP($F28*$B$6,0)),"") -> 84 | H28: 60 | I28: Refrigeración a 4 °C | J28: 46271 | K28: 3 | L28: =IF(OR(NOT(ISNUMBER($J28)),NOT(ISNUMBER($K28))),"",$J28+$K28) -> 46274 | M28: =IFERROR(IF($G28="","",MAX(0,$G28-IF($H28="",0,$H28))),"") -> 24 | N28: =IFERROR(IF($G28="","",TRIM(IF(AND(ISNUMBER($H28),$H28>$G28),"Sobreproducción: el stock ya cubre toda la semana, no produzcas","")&IF(AND(AND(ISNUMBER($H28),$H28>$G28),AND(ISNUMBER($L28),ISNUMBER($H28),$H28>0,ISNUMBER('Previsión de Cubiertos'!$B$7),ISNUMBER('Previsión de Cubiertos'!$B$8),$G28>0,$L28<'Previsión de Cubiertos'!$B$7+$H28*'Previsión de Cubiertos'!$B$8/$G28)),". ","")&IF(AND(ISNUMBER($L28),ISNUMBER($H28),$H28>0,ISNUMBER('Previsión de Cubiertos'!$B$7),ISNUMBER('Previsión de Cubiertos'!$B$8),$G28>0,$L28<'Previsión de Cubiertos'!$B$7+$H28*'Previsión de Cubiertos'!$B$8/$G28),"El stock caduca antes de consumirse al ritmo previsto: prográmalo en los primeros días",""))),"") -> El stock caduca antes de consumirse al ritmo previsto: prográmalo en los primeros días
A29: P2 | B29: Bacalao confitado al pil-pil | C29: Bacalao desalado y porcionado | D29: Pase y caliente | E29: 1 lomo confitado | F29: 0.048717949 | G29: =IFERROR(IF(OR(NOT(ISNUMBER($F29)),NOT(ISNUMBER($B$6))),"",ROUNDUP($F29*$B$6,0)),"") -> 47 | H29: 24 | I29: Refrigeración a 4 °C | J29: 46270 | K29: 2 | L29: =IF(OR(NOT(ISNUMBER($J29)),NOT(ISNUMBER($K29))),"",$J29+$K29) -> 46272 | M29: =IFERROR(IF($G29="","",MAX(0,$G29-IF($H29="",0,$H29))),"") -> 23 | N29: =IFERROR(IF($G29="","",TRIM(IF(AND(ISNUMBER($H29),$H29>$G29),"Sobreproducción: el stock ya cubre toda la semana, no produzcas","")&IF(AND(AND(ISNUMBER($H29),$H29>$G29),AND(ISNUMBER($L29),ISNUMBER($H29),$H29>0,ISNUMBER('Previsión de Cubiertos'!$B$7),ISNUMBER('Previsión de Cubiertos'!$B$8),$G29>0,$L29<'Previsión de Cubiertos'!$B$7+$H29*'Previsión de Cubiertos'!$B$8/$G29)),". ","")&IF(AND(ISNUMBER($L29),ISNUMBER($H29),$H29>0,ISNUMBER('Previsión de Cubiertos'!$B$7),ISNUMBER('Previsión de Cubiertos'!$B$8),$G29>0,$L29<'Previsión de Cubiertos'!$B$7+$H29*'Previsión de Cubiertos'!$B$8/$G29),"El stock caduca antes de consumirse al ritmo previsto: prográmalo en los primeros días",""))),"") -> El stock caduca antes de consumirse al ritmo previsto: prográmalo en los primeros días
A30: P3 | B30: Hamburguesa de vaca madurada con patatas | C30: Hamburguesa formada | D30: Pase y caliente | E30: 1 hamburguesa con guarnición | F30: 0.11794872 | G30: =IFERROR(IF(OR(NOT(ISNUMBER($F30)),NOT(ISNUMBER($B$6))),"",ROUNDUP($F30*$B$6,0)),"") -> 113 | H30: 80 | I30: Refrigeración a 4 °C | J30: 46271 | K30: 2 | L30: =IF(OR(NOT(ISNUMBER($J30)),NOT(ISNUMBER($K30))),"",$J30+$K30) -> 46273 | M30: =IFERROR(IF($G30="","",MAX(0,$G30-IF($H30="",0,$H30))),"") -> 33 | N30: =IFERROR(IF($G30="","",TRIM(IF(AND(ISNUMBER($H30),$H30>$G30),"Sobreproducción: el stock ya cubre toda la semana, no produzcas","")&IF(AND(AND(ISNUMBER($H30),$H30>$G30),AND(ISNUMBER($L30),ISNUMBER($H30),$H30>0,ISNUMBER('Previsión de Cubiertos'!$B$7),ISNUMBER('Previsión de Cubiertos'!$B$8),$G30>0,$L30<'Previsión de Cubiertos'!$B$7+$H30*'Previsión de Cubiertos'!$B$8/$G30)),". ","")&IF(AND(ISNUMBER($L30),ISNUMBER($H30),$H30>0,ISNUMBER('Previsión de Cubiertos'!$B$7),ISNUMBER('Previsión de Cubiertos'!$B$8),$G30>0,$L30<'Previsión de Cubiertos'!$B$7+$H30*'Previsión de Cubiertos'!$B$8/$G30),"El stock caduca antes de consumirse al ritmo previsto: prográmalo en los primeros días",""))),"") -> El stock caduca antes de consumirse al ritmo previsto: prográmalo en los primeros días
A31: P4 | B31: Arroz meloso de secreto ibérico y setas | C31: Fondo de arroz y sofrito | D31: Pase y caliente | E31: 1 ración de arroz (mínimo 2 pax) | F31: 0.069230769 | G31: =IFERROR(IF(OR(NOT(ISNUMBER($F31)),NOT(ISNUMBER($B$6))),"",ROUNDUP($F31*$B$6,0)),"") -> 67 | H31: 110 | I31: Refrigeración a 4 °C | J31: 46269 | K31: 5 | L31: =IF(OR(NOT(ISNUMBER($J31)),NOT(ISNUMBER($K31))),"",$J31+$K31) -> 46274 | M31: =IFERROR(IF($G31="","",MAX(0,$G31-IF($H31="",0,$H31))),"") -> 0 | N31: =IFERROR(IF($G31="","",TRIM(IF(AND(ISNUMBER($H31),$H31>$G31),"Sobreproducción: el stock ya cubre toda la semana, no produzcas","")&IF(AND(AND(ISNUMBER($H31),$H31>$G31),AND(ISNUMBER($L31),ISNUMBER($H31),$H31>0,ISNUMBER('Previsión de Cubiertos'!$B$7),ISNUMBER('Previsión de Cubiertos'!$B$8),$G31>0,$L31<'Previsión de Cubiertos'!$B$7+$H31*'Previsión de Cubiertos'!$B$8/$G31)),". ","")&IF(AND(ISNUMBER($L31),ISNUMBER($H31),$H31>0,ISNUMBER('Previsión de Cubiertos'!$B$7),ISNUMBER('Previsión de Cubiertos'!$B$8),$G31>0,$L31<'Previsión de Cubiertos'!$B$7+$H31*'Previsión de Cubiertos'!$B$8/$G31),"El stock caduca antes de consumirse al ritmo previsto: prográmalo en los primeros días",""))),"") -> Sobreproducción: el stock ya cubre toda la semana, no produzcas. El stock caduca antes de consumirse al ritmo previsto: prográmalo en los primeros días
A32: P5 | B32: Chuletón de vaca madurada (500 g) | D32: Pase y caliente | E32: 1 chuletón de 500 g | F32: 0.028205128 | G32: =IFERROR(IF(OR(NOT(ISNUMBER($F32)),NOT(ISNUMBER($B$6))),"",ROUNDUP($F32*$B$6,0)),"") -> 28 | H32: 0 | I32: No aplica | L32: =IF(OR(NOT(ISNUMBER($J32)),NOT(ISNUMBER($K32))),"",$J32+$K32) | M32: =IFERROR(IF($G32="","",MAX(0,$G32-IF($H32="",0,$H32))),"") -> 28 | N32: =IFERROR(IF($G32="","",TRIM(IF(AND(ISNUMBER($H32),$H32>$G32),"Sobreproducción: el stock ya cubre toda la semana, no produzcas","")&IF(AND(AND(ISNUMBER($H32),$H32>$G32),AND(ISNUMBER($L32),ISNUMBER($H32),$H32>0,ISNUMBER('Previsión de Cubiertos'!$B$7),ISNUMBER('Previsión de Cubiertos'!$B$8),$G32>0,$L32<'Previsión de Cubiertos'!$B$7+$H32*'Previsión de Cubiertos'!$B$8/$G32)),". ","")&IF(AND(ISNUMBER($L32),ISNUMBER($H32),$H32>0,ISNUMBER('Previsión de Cubiertos'!$B$7),ISNUMBER('Previsión de Cubiertos'!$B$8),$G32>0,$L32<'Previsión de Cubiertos'!$B$7+$H32*'Previsión de Cubiertos'!$B$8/$G32),"El stock caduca antes de consumirse al ritmo previsto: prográmalo en los primeros días",""))),"")
A33: D1 | B33: Tarta de queso cremosa | C33: Tarta de queso cuajada | D33: Postres y panadería | E33: 1 porción | F33: 0.13333333 | G33: =IFERROR(IF(OR(NOT(ISNUMBER($F33)),NOT(ISNUMBER($B$6))),"",ROUNDUP($F33*$B$6,0)),"") -> 128 | H33: 46 | I33: Refrigeración a 4 °C | J33: 46271 | K33: 4 | L33: =IF(OR(NOT(ISNUMBER($J33)),NOT(ISNUMBER($K33))),"",$J33+$K33) -> 46275 | M33: =IFERROR(IF($G33="","",MAX(0,$G33-IF($H33="",0,$H33))),"") -> 82 | N33: =IFERROR(IF($G33="","",TRIM(IF(AND(ISNUMBER($H33),$H33>$G33),"Sobreproducción: el stock ya cubre toda la semana, no produzcas","")&IF(AND(AND(ISNUMBER($H33),$H33>$G33),AND(ISNUMBER($L33),ISNUMBER($H33),$H33>0,ISNUMBER('Previsión de Cubiertos'!$B$7),ISNUMBER('Previsión de Cubiertos'!$B$8),$G33>0,$L33<'Previsión de Cubiertos'!$B$7+$H33*'Previsión de Cubiertos'!$B$8/$G33)),". ","")&IF(AND(ISNUMBER($L33),ISNUMBER($H33),$H33>0,ISNUMBER('Previsión de Cubiertos'!$B$7),ISNUMBER('Previsión de Cubiertos'!$B$8),$G33>0,$L33<'Previsión de Cubiertos'!$B$7+$H33*'Previsión de Cubiertos'!$B$8/$G33),"El stock caduca antes de consumirse al ritmo previsto: prográmalo en los primeros días",""))),"")
A34: D2 | B34: Torrija caramelizada con helado | C34: Torrija empapada, sin caramelizar | D34: Postres y panadería | E34: 1 torrija con helado | F34: 0.053846154 | G34: =IFERROR(IF(OR(NOT(ISNUMBER($F34)),NOT(ISNUMBER($B$6))),"",ROUNDUP($F34*$B$6,0)),"") -> 52 | H34: 32 | I34: Refrigeración a 4 °C | J34: 46270 | K34: 3 | L34: =IF(OR(NOT(ISNUMBER($J34)),NOT(ISNUMBER($K34))),"",$J34+$K34) -> 46273 | M34: =IFERROR(IF($G34="","",MAX(0,$G34-IF($H34="",0,$H34))),"") -> 20 | N34: =IFERROR(IF($G34="","",TRIM(IF(AND(ISNUMBER($H34),$H34>$G34),"Sobreproducción: el stock ya cubre toda la semana, no produzcas","")&IF(AND(AND(ISNUMBER($H34),$H34>$G34),AND(ISNUMBER($L34),ISNUMBER($H34),$H34>0,ISNUMBER('Previsión de Cubiertos'!$B$7),ISNUMBER('Previsión de Cubiertos'!$B$8),$G34>0,$L34<'Previsión de Cubiertos'!$B$7+$H34*'Previsión de Cubiertos'!$B$8/$G34)),". ","")&IF(AND(ISNUMBER($L34),ISNUMBER($H34),$H34>0,ISNUMBER('Previsión de Cubiertos'!$B$7),ISNUMBER('Previsión de Cubiertos'!$B$8),$G34>0,$L34<'Previsión de Cubiertos'!$B$7+$H34*'Previsión de Cubiertos'!$B$8/$G34),"El stock caduca antes de consumirse al ritmo previsto: prográmalo en los primeros días",""))),"") -> El stock caduca antes de consumirse al ritmo previsto: prográmalo en los primeros días
A35: D3 | B35: Coulant de chocolate | C35: Coulant crudo congelado | D35: Postres y panadería | E35: 1 coulant | F35: 0.084615385 | G35: =IFERROR(IF(OR(NOT(ISNUMBER($F35)),NOT(ISNUMBER($B$6))),"",ROUNDUP($F35*$B$6,0)),"") -> 82 | H35: 120 | I35: Congelación a -18 °C | J35: 46262 | K35: 60 | L35: =IF(OR(NOT(ISNUMBER($J35)),NOT(ISNUMBER($K35))),"",$J35+$K35) -> 46322 | M35: =IFERROR(IF($G35="","",MAX(0,$G35-IF($H35="",0,$H35))),"") -> 0 | N35: =IFERROR(IF($G35="","",TRIM(IF(AND(ISNUMBER($H35),$H35>$G35),"Sobreproducción: el stock ya cubre toda la semana, no produzcas","")&IF(AND(AND(ISNUMBER($H35),$H35>$G35),AND(ISNUMBER($L35),ISNUMBER($H35),$H35>0,ISNUMBER('Previsión de Cubiertos'!$B$7),ISNUMBER('Previsión de Cubiertos'!$B$8),$G35>0,$L35<'Previsión de Cubiertos'!$B$7+$H35*'Previsión de Cubiertos'!$B$8/$G35)),". ","")&IF(AND(ISNUMBER($L35),ISNUMBER($H35),$H35>0,ISNUMBER('Previsión de Cubiertos'!$B$7),ISNUMBER('Previsión de Cubiertos'!$B$8),$G35>0,$L35<'Previsión de Cubiertos'!$B$7+$H35*'Previsión de Cubiertos'!$B$8/$G35),"El stock caduca antes de consumirse al ritmo previsto: prográmalo en los primeros días",""))),"") -> Sobreproducción: el stock ya cubre toda la semana, no produzcas
G36: =IFERROR(IF(OR(NOT(ISNUMBER($F36)),NOT(ISNUMBER($B$6))),"",ROUNDUP($F36*$B$6,0)),"") | L36: =IF(OR(NOT(ISNUMBER($J36)),NOT(ISNUMBER($K36))),"",$J36+$K36) | M36: =IFERROR(IF($G36="","",MAX(0,$G36-IF($H36="",0,$H36))),"") | N36: =IFERROR(IF($G36="","",TRIM(IF(AND(ISNUMBER($H36),$H36>$G36),"Sobreproducción: el stock ya cubre toda la semana, no produzcas","")&IF(AND(AND(ISNUMBER($H36),$H36>$G36),AND(ISNUMBER($L36),ISNUMBER($H36),$H36>0,ISNUMBER('Previsión de Cubiertos'!$B$7),ISNUMBER('Previsión de Cubiertos'!$B$8),$G36>0,$L36<'Previsión de Cubiertos'!$B$7+$H36*'Previsión de Cubiertos'!$B$8/$G36)),". ","")&IF(AND(ISNUMBER($L36),ISNUMBER($H36),$H36>0,ISNUMBER('Previsión de Cubiertos'!$B$7),ISNUMBER('Previsión de Cubiertos'!$B$8),$G36>0,$L36<'Previsión de Cubiertos'!$B$7+$H36*'Previsión de Cubiertos'!$B$8/$G36),"El stock caduca antes de consumirse al ritmo previsto: prográmalo en los primeros días",""))),"")
G37: =IFERROR(IF(OR(NOT(ISNUMBER($F37)),NOT(ISNUMBER($B$6))),"",ROUNDUP($F37*$B$6,0)),"") | L37: =IF(OR(NOT(ISNUMBER($J37)),NOT(ISNUMBER($K37))),"",$J37+$K37) | M37: =IFERROR(IF($G37="","",MAX(0,$G37-IF($H37="",0,$H37))),"") | N37: =IFERROR(IF($G37="","",TRIM(IF(AND(ISNUMBER($H37),$H37>$G37),"Sobreproducción: el stock ya cubre toda la semana, no produzcas","")&IF(AND(AND(ISNUMBER($H37),$H37>$G37),AND(ISNUMBER($L37),ISNUMBER($H37),$H37>0,ISNUMBER('Previsión de Cubiertos'!$B$7),ISNUMBER('Previsión de Cubiertos'!$B$8),$G37>0,$L37<'Previsión de Cubiertos'!$B$7+$H37*'Previsión de Cubiertos'!$B$8/$G37)),". ","")&IF(AND(ISNUMBER($L37),ISNUMBER($H37),$H37>0,ISNUMBER('Previsión de Cubiertos'!$B$7),ISNUMBER('Previsión de Cubiertos'!$B$8),$G37>0,$L37<'Previsión de Cubiertos'!$B$7+$H37*'Previsión de Cubiertos'!$B$8/$G37),"El stock caduca antes de consumirse al ritmo previsto: prográmalo en los primeros días",""))),"")
G38: =IFERROR(IF(OR(NOT(ISNUMBER($F38)),NOT(ISNUMBER($B$6))),"",ROUNDUP($F38*$B$6,0)),"") | L38: =IF(OR(NOT(ISNUMBER($J38)),NOT(ISNUMBER($K38))),"",$J38+$K38) | M38: =IFERROR(IF($G38="","",MAX(0,$G38-IF($H38="",0,$H38))),"") | N38: =IFERROR(IF($G38="","",TRIM(IF(AND(ISNUMBER($H38),$H38>$G38),"Sobreproducción: el stock ya cubre toda la semana, no produzcas","")&IF(AND(AND(ISNUMBER($H38),$H38>$G38),AND(ISNUMBER($L38),ISNUMBER($H38),$H38>0,ISNUMBER('Previsión de Cubiertos'!$B$7),ISNUMBER('Previsión de Cubiertos'!$B$8),$G38>0,$L38<'Previsión de Cubiertos'!$B$7+$H38*'Previsión de Cubiertos'!$B$8/$G38)),". ","")&IF(AND(ISNUMBER($L38),ISNUMBER($H38),$H38>0,ISNUMBER('Previsión de Cubiertos'!$B$7),ISNUMBER('Previsión de Cubiertos'!$B$8),$G38>0,$L38<'Previsión de Cubiertos'!$B$7+$H38*'Previsión de Cubiertos'!$B$8/$G38),"El stock caduca antes de consumirse al ritmo previsto: prográmalo en los primeros días",""))),"")
G39: =IFERROR(IF(OR(NOT(ISNUMBER($F39)),NOT(ISNUMBER($B$6))),"",ROUNDUP($F39*$B$6,0)),"") | L39: =IF(OR(NOT(ISNUMBER($J39)),NOT(ISNUMBER($K39))),"",$J39+$K39) | M39: =IFERROR(IF($G39="","",MAX(0,$G39-IF($H39="",0,$H39))),"") | N39: =IFERROR(IF($G39="","",TRIM(IF(AND(ISNUMBER($H39),$H39>$G39),"Sobreproducción: el stock ya cubre toda la semana, no produzcas","")&IF(AND(AND(ISNUMBER($H39),$H39>$G39),AND(ISNUMBER($L39),ISNUMBER($H39),$H39>0,ISNUMBER('Previsión de Cubiertos'!$B$7),ISNUMBER('Previsión de Cubiertos'!$B$8),$G39>0,$L39<'Previsión de Cubiertos'!$B$7+$H39*'Previsión de Cubiertos'!$B$8/$G39)),". ","")&IF(AND(ISNUMBER($L39),ISNUMBER($H39),$H39>0,ISNUMBER('Previsión de Cubiertos'!$B$7),ISNUMBER('Previsión de Cubiertos'!$B$8),$G39>0,$L39<'Previsión de Cubiertos'!$B$7+$H39*'Previsión de Cubiertos'!$B$8/$G39),"El stock caduca antes de consumirse al ritmo previsto: prográmalo en los primeros días",""))),"")
G40: =IFERROR(IF(OR(NOT(ISNUMBER($F40)),NOT(ISNUMBER($B$6))),"",ROUNDUP($F40*$B$6,0)),"") | L40: =IF(OR(NOT(ISNUMBER($J40)),NOT(ISNUMBER($K40))),"",$J40+$K40) | M40: =IFERROR(IF($G40="","",MAX(0,$G40-IF($H40="",0,$H40))),"") | N40: =IFERROR(IF($G40="","",TRIM(IF(AND(ISNUMBER($H40),$H40>$G40),"Sobreproducción: el stock ya cubre toda la semana, no produzcas","")&IF(AND(AND(ISNUMBER($H40),$H40>$G40),AND(ISNUMBER($L40),ISNUMBER($H40),$H40>0,ISNUMBER('Previsión de Cubiertos'!$B$7),ISNUMBER('Previsión de Cubiertos'!$B$8),$G40>0,$L40<'Previsión de Cubiertos'!$B$7+$H40*'Previsión de Cubiertos'!$B$8/$G40)),". ","")&IF(AND(ISNUMBER($L40),ISNUMBER($H40),$H40>0,ISNUMBER('Previsión de Cubiertos'!$B$7),ISNUMBER('Previsión de Cubiertos'!$B$8),$G40>0,$L40<'Previsión de Cubiertos'!$B$7+$H40*'Previsión de Cubiertos'!$B$8/$G40),"El stock caduca antes de consumirse al ritmo previsto: prográmalo en los primeros días",""))),"")
G41: =IFERROR(IF(OR(NOT(ISNUMBER($F41)),NOT(ISNUMBER($B$6))),"",ROUNDUP($F41*$B$6,0)),"") | L41: =IF(OR(NOT(ISNUMBER($J41)),NOT(ISNUMBER($K41))),"",$J41+$K41) | M41: =IFERROR(IF($G41="","",MAX(0,$G41-IF($H41="",0,$H41))),"") | N41: =IFERROR(IF($G41="","",TRIM(IF(AND(ISNUMBER($H41),$H41>$G41),"Sobreproducción: el stock ya cubre toda la semana, no produzcas","")&IF(AND(AND(ISNUMBER($H41),$H41>$G41),AND(ISNUMBER($L41),ISNUMBER($H41),$H41>0,ISNUMBER('Previsión de Cubiertos'!$B$7),ISNUMBER('Previsión de Cubiertos'!$B$8),$G41>0,$L41<'Previsión de Cubiertos'!$B$7+$H41*'Previsión de Cubiertos'!$B$8/$G41)),". ","")&IF(AND(ISNUMBER($L41),ISNUMBER($H41),$H41>0,ISNUMBER('Previsión de Cubiertos'!$B$7),ISNUMBER('Previsión de Cubiertos'!$B$8),$G41>0,$L41<'Previsión de Cubiertos'!$B$7+$H41*'Previsión de Cubiertos'!$B$8/$G41),"El stock caduca antes de consumirse al ritmo previsto: prográmalo en los primeros días",""))),"")
G42: =IFERROR(IF(OR(NOT(ISNUMBER($F42)),NOT(ISNUMBER($B$6))),"",ROUNDUP($F42*$B$6,0)),"") | L42: =IF(OR(NOT(ISNUMBER($J42)),NOT(ISNUMBER($K42))),"",$J42+$K42) | M42: =IFERROR(IF($G42="","",MAX(0,$G42-IF($H42="",0,$H42))),"") | N42: =IFERROR(IF($G42="","",TRIM(IF(AND(ISNUMBER($H42),$H42>$G42),"Sobreproducción: el stock ya cubre toda la semana, no produzcas","")&IF(AND(AND(ISNUMBER($H42),$H42>$G42),AND(ISNUMBER($L42),ISNUMBER($H42),$H42>0,ISNUMBER('Previsión de Cubiertos'!$B$7),ISNUMBER('Previsión de Cubiertos'!$B$8),$G42>0,$L42<'Previsión de Cubiertos'!$B$7+$H42*'Previsión de Cubiertos'!$B$8/$G42)),". ","")&IF(AND(ISNUMBER($L42),ISNUMBER($H42),$H42>0,ISNUMBER('Previsión de Cubiertos'!$B$7),ISNUMBER('Previsión de Cubiertos'!$B$8),$G42>0,$L42<'Previsión de Cubiertos'!$B$7+$H42*'Previsión de Cubiertos'!$B$8/$G42),"El stock caduca antes de consumirse al ritmo previsto: prográmalo en los primeros días",""))),"")
G43: =IFERROR(IF(OR(NOT(ISNUMBER($F43)),NOT(ISNUMBER($B$6))),"",ROUNDUP($F43*$B$6,0)),"") | L43: =IF(OR(NOT(ISNUMBER($J43)),NOT(ISNUMBER($K43))),"",$J43+$K43) | M43: =IFERROR(IF($G43="","",MAX(0,$G43-IF($H43="",0,$H43))),"") | N43: =IFERROR(IF($G43="","",TRIM(IF(AND(ISNUMBER($H43),$H43>$G43),"Sobreproducción: el stock ya cubre toda la semana, no produzcas","")&IF(AND(AND(ISNUMBER($H43),$H43>$G43),AND(ISNUMBER($L43),ISNUMBER($H43),$H43>0,ISNUMBER('Previsión de Cubiertos'!$B$7),ISNUMBER('Previsión de Cubiertos'!$B$8),$G43>0,$L43<'Previsión de Cubiertos'!$B$7+$H43*'Previsión de Cubiertos'!$B$8/$G43)),". ","")&IF(AND(ISNUMBER($L43),ISNUMBER($H43),$H43>0,ISNUMBER('Previsión de Cubiertos'!$B$7),ISNUMBER('Previsión de Cubiertos'!$B$8),$G43>0,$L43<'Previsión de Cubiertos'!$B$7+$H43*'Previsión de Cubiertos'!$B$8/$G43),"El stock caduca antes de consumirse al ritmo previsto: prográmalo en los primeros días",""))),"")
A44: TOTAL | F44: =IF(COUNT($F24:$F43)=0,"",SUM($F24:$F43)) -> 0.97435897 | G44: =IF(COUNT(G24:G43)=0,"",SUM(G24:G43)) -> 940 | H44: =IF(COUNT(H24:H43)=0,"",SUM(H24:H43)) -> 734 | M44: =IF(COUNT(M24:M43)=0,"",SUM(M24:M43)) -> 323
A45: El total del mix no tiene por qué sumar 100 %: mide cuántas raciones de estos platos se venden por cada 100 cubiertos, y un comensal puede pedir entrante y principal, o sólo un plato del menú.
...

Sheet Lista de Producción Diaria
A1: Lista de producción diaria
A2: AI Chef Pro · aichef.pro — Manual del Chef Ejecutivo
A3: Elige el día, imprime y cuélgala en la cocina. Las cuatro columnas de la derecha se rellenan a mano.
A5: Semana ISO | B5: =IF('Previsión de Cubiertos'!$B$6="","",'Previsión de Cubiertos'!$B$6) -> 37
A6: Día de la lista | B6: Viernes
A7: Fecha | B7: =IFERROR(IF(OR($B$6="",'Previsión de Cubiertos'!$B$7=""),"",'Previsión de Cubiertos'!$B$7+MATCH($B$6,$A$45:$A$51,0)-1),"") -> 46276
A8: Cubiertos previstos del día | B8: =IFERROR(IF($B$6="","",SUMIF('Previsión de Cubiertos'!$A$15:$A$28,$B$6,'Previsión de Cubiertos'!$F$15:$F$28)),"") -> 183
A9: Cubiertos previstos de la semana | B9: =IF('Previsión de Cubiertos'!$F$29="","",'Previsión de Cubiertos'!$F$29) -> 958
A10: Las raciones de hoy salen de la producción de la semana repartida por el peso de los cubiertos de este día: cantidad semanal x cubiertos del día / cubiertos de la semana, redondeada hacia arriba.
A11: Si un día concreto pide otra cosa (un menú de grupo, una fiesta local), corrige la cantidad a mano sobre el papel: esta hoja es un punto de partida, no una orden.
A13: Partida | B13: Elaboración | C13: Unidad de ración | D13: Raciones para hoy | E13: Producido (raciones) | F13: Hora de fin | G13: Conservación | H13: Responsable | I13: Estado
A14: =IF('Producción por Partida'!$D$24="","",'Producción por Partida'!$D$24) -> Fríos y entrantes | B14: =IF('Producción por Partida'!$B$24="","",IF('Producción por Partida'!$C$24="",'Producción por Partida'!$B$24,'Producción por Partida'!$C$24)) -> Masa de croqueta ya formada y empanada | C14: =IF('Producción por Partida'!$E$24="","",'Producción por Partida'!$E$24) -> 6 croquetas | D14: =IFERROR(IF(OR('Producción por Partida'!$M$24="",NOT(ISNUMBER($B$8)),NOT(ISNUMBER($B$9)),$B$9=0),"",ROUNDUP('Producción por Partida'!$M$24*$B$8/$B$9,0)),"") -> 0
A15: =IF('Producción por Partida'!$D$25="","",'Producción por Partida'!$D$25) -> Fríos y entrantes | B15: =IF('Producción por Partida'!$B$25="","",IF('Producción por Partida'!$C$25="",'Producción por Partida'!$B$25,'Producción por Partida'!$C$25)) -> Ensalada de tomate rosa, ventresca y cebolleta | C15: =IF('Producción por Partida'!$E$25="","",'Producción por Partida'!$E$25) -> 1 ración de ensalada | D15: =IFERROR(IF(OR('Producción por Partida'!$M$25="",NOT(ISNUMBER($B$8)),NOT(ISNUMBER($B$9)),$B$9=0),"",ROUNDUP('Producción por Partida'!$M$25*$B$8/$B$9,0)),"") -> 15
A16: =IF('Producción por Partida'!$D$26="","",'Producción por Partida'!$D$26) -> Fríos y entrantes | B16: =IF('Producción por Partida'!$B$26="","",IF('Producción por Partida'!$C$26="",'Producción por Partida'!$B$26,'Producción por Partida'!$C$26)) -> Gamba pelada y racionada | C16: =IF('Producción por Partida'!$E$26="","",'Producción por Partida'!$E$26) -> 1 cazuela | D16: =IFERROR(IF(OR('Producción por Partida'!$M$26="",NOT(ISNUMBER($B$8)),NOT(ISNUMBER($B$9)),$B$9=0),"",ROUNDUP('Producción por Partida'!$M$26*$B$8/$B$9,0)),"") -> 7
A17: =IF('Producción por Partida'!$D$27="","",'Producción por Partida'!$D$27) -> Fríos y entrantes | B17: =IF('Producción por Partida'!$B$27="","",IF('Producción por Partida'!$C$27="",'Producción por Partida'!$B$27,'Producción por Partida'!$C$27)) -> Patata confitada | C17: =IF('Producción por Partida'!$E$27="","",'Producción por Partida'!$E$27) -> 1 ración para compartir | D17: =IFERROR(IF(OR('Producción por Partida'!$M$27="",NOT(ISNUMBER($B$8)),NOT(ISNUMBER($B$9)),$B$9=0),"",ROUNDUP('Producción por Partida'!$M$27*$B$8/$B$9,0)),"") -> 1
A18: =IF('Producción por Partida'!$D$28="","",'Producción por Partida'!$D$28) -> Pase y caliente | B18: =IF('Producción por Partida'!$B$28="","",IF('Producción por Partida'!$C$28="",'Producción por Partida'!$B$28,'Producción por Partida'!$C$28)) -> Puré de boniato | C18: =IF('Producción por Partida'!$E$28="","",'Producción por Partida'!$E$28) -> 1 ración (solomillo y puré) | D18: =IFERROR(IF(OR('Producción por Partida'!$M$28="",NOT(ISNUMBER($B$8)),NOT(ISNUMBER($B$9)),$B$9=0),"",ROUNDUP('Producción por Partida'!$M$28*$B$8/$B$9,0)),"") -> 5
A19: =IF('Producción por Partida'!$D$29="","",'Producción por Partida'!$D$29) -> Pase y caliente | B19: =IF('Producción por Partida'!$B$29="","",IF('Producción por Partida'!$C$29="",'Producción por Partida'!$B$29,'Producción por Partida'!$C$29)) -> Bacalao desalado y porcionado | C19: =IF('Producción por Partida'!$E$29="","",'Producción por Partida'!$E$29) -> 1 lomo confitado | D19: =IFERROR(IF(OR('Producción por Partida'!$M$29="",NOT(ISNUMBER($B$8)),NOT(ISNUMBER($B$9)),$B$9=0),"",ROUNDUP('Producción por Partida'!$M$29*$B$8/$B$9,0)),"") -> 5
A20: =IF('Producción por Partida'!$D$30="","",'Producción por Partida'!$D$30) -> Pase y caliente | B20: =IF('Producción por Partida'!$B$30="","",IF('Producción por Partida'!$C$30="",'Producción por Partida'!$B$30,'Producción por Partida'!$C$30)) -> Hamburguesa formada | C20: =IF('Producción por Partida'!$E$30="","",'Producción por Partida'!$E$30) -> 1 hamburguesa con guarnición | D20: =IFERROR(IF(OR('Producción por Partida'!$M$30="",NOT(ISNUMBER($B$8)),NOT(ISNUMBER($B$9)),$B$9=0),"",ROUNDUP('Producción por Partida'!$M$30*$B$8/$B$9,0)),"") -> 7
A21: =IF('Producción por Partida'!$D$31="","",'Producción por Partida'!$D$31) -> Pase y caliente | B21: =IF('Producción por Partida'!$B$31="","",IF('Producción por Partida'!$C$31="",'Producción por Partida'!$B$31,'Producción por Partida'!$C$31)) -> Fondo de arroz y sofrito | C21: =IF('Producción por Partida'!$E$31="","",'Producción por Partida'!$E$31) -> 1 ración de arroz (mínimo 2 pax) | D21: =IFERROR(IF(OR('Producción por Partida'!$M$31="",NOT(ISNUMBER($B$8)),NOT(ISNUMBER($B$9)),$B$9=0),"",ROUNDUP('Producción por Partida'!$M$31*$B$8/$B$9,0)),"") -> 0
A22: =IF('Producción por Partida'!$D$32="","",'Producción por Partida'!$D$32) -> Pase y caliente | B22: =IF('Producción por Partida'!$B$32="","",IF('Producción por Partida'!$C$32="",'Producción por Partida'!$B$32,'Producción por Partida'!$C$32)) -> Chuletón de vaca madurada (500 g) | C22: =IF('Producción por Partida'!$E$32="","",'Producción por Partida'!$E$32) -> 1 chuletón de 500 g | D22: =IFERROR(IF(OR('Producción por Partida'!$M$32="",NOT(ISNUMBER($B$8)),NOT(ISNUMBER($B$9)),$B$9=0),"",ROUNDUP('Producción por Partida'!$M$32*$B$8/$B$9,0)),"") -> 6
A23: =IF('Producción por Partida'!$D$33="","",'Producción por Partida'!$D$33) -> Postres y panadería | B23: =IF('Producción por Partida'!$B$33="","",IF('Producción por Partida'!$C$33="",'Producción por Partida'!$B$33,'Producción por Partida'!$C$33)) -> Tarta de queso cuajada | C23: =IF('Producción por Partida'!$E$33="","",'Producción por Partida'!$E$33) -> 1 porción | D23: =IFERROR(IF(OR('Producción por Partida'!$M$33="",NOT(ISNUMBER($B$8)),NOT(ISNUMBER($B$9)),$B$9=0),"",ROUNDUP('Producción por Partida'!$M$33*$B$8/$B$9,0)),"") -> 16
A24: =IF('Producción por Partida'!$D$34="","",'Producción por Partida'!$D$34) -> Postres y panadería | B24: =IF('Producción por Partida'!$B$34="","",IF('Producción por Partida'!$C$34="",'Producción por Partida'!$B$34,'Producción por Partida'!$C$34)) -> Torrija empapada, sin caramelizar | C24: =IF('Producción por Partida'!$E$34="","",'Producción por Partida'!$E$34) -> 1 torrija con helado | D24: =IFERROR(IF(OR('Producción por Partida'!$M$34="",NOT(ISNUMBER($B$8)),NOT(ISNUMBER($B$9)),$B$9=0),"",ROUNDUP('Producción por Partida'!$M$34*$B$8/$B$9,0)),"") -> 4
A25: =IF('Producción por Partida'!$D$35="","",'Producción por Partida'!$D$35) -> Postres y panadería | B25: =IF('Producción por Partida'!$B$35="","",IF('Producción por Partida'!$C$35="",'Producción por Partida'!$B$35,'Producción por Partida'!$C$35)) -> Coulant crudo congelado | C25: =IF('Producción por Partida'!$E$35="","",'Producción por Partida'!$E$35) -> 1 coulant | D25: =IFERROR(IF(OR('Producción por Partida'!$M$35="",NOT(ISNUMBER($B$8)),NOT(ISNUMBER($B$9)),$B$9=0),"",ROUNDUP('Producción por Partida'!$M$35*$B$8/$B$9,0)),"") -> 0
A26: =IF('Producción por Partida'!$D$36="","",'Producción por Partida'!$D$36) | B26: =IF('Producción por Partida'!$B$36="","",IF('Producción por Partida'!$C$36="",'Producción por Partida'!$B$36,'Producción por Partida'!$C$36)) | C26: =IF('Producción por Partida'!$E$36="","",'Producción por Partida'!$E$36) | D26: =IFERROR(IF(OR('Producción por Partida'!$M$36="",NOT(ISNUMBER($B$8)),NOT(ISNUMBER($B$9)),$B$9=0),"",ROUNDUP('Producción por Partida'!$M$36*$B$8/$B$9,0)),"")
A27: =IF('Producción por Partida'!$D$37="","",'Producción por Partida'!$D$37) | B27: =IF('Producción por Partida'!$B$37="","",IF('Producción por Partida'!$C$37="",'Producción por Partida'!$B$37,'Producción por Partida'!$C$37)) | C27: =IF('Producción por Partida'!$E$37="","",'Producción por Partida'!$E$37) | D27: =IFERROR(IF(OR('Producción por Partida'!$M$37="",NOT(ISNUMBER($B$8)),NOT(ISNUMBER($B$9)),$B$9=0),"",ROUNDUP('Producción por Partida'!$M$37*$B$8/$B$9,0)),"")
A28: =IF('Producción por Partida'!$D$38="","",'Producción por Partida'!$D$38) | B28: =IF('Producción por Partida'!$B$38="","",IF('Producción por Partida'!$C$38="",'Producción por Partida'!$B$38,'Producción por Partida'!$C$38)) | C28: =IF('Producción por Partida'!$E$38="","",'Producción por Partida'!$E$38) | D28: =IFERROR(IF(OR('Producción por Partida'!$M$38="",NOT(ISNUMBER($B$8)),NOT(ISNUMBER($B$9)),$B$9=0),"",ROUNDUP('Producción por Partida'!$M$38*$B$8/$B$9,0)),"")
A29: =IF('Producción por Partida'!$D$39="","",'Producción por Partida'!$D$39) | B29: =IF('Producción por Partida'!$B$39="","",IF('Producción por Partida'!$C$39="",'Producción por Partida'!$B$39,'Producción por Partida'!$C$39)) | C29: =IF('Producción por Partida'!$E$39="","",'Producción por Partida'!$E$39) | D29: =IFERROR(IF(OR('Producción por Partida'!$M$39="",NOT(ISNUMBER($B$8)),NOT(ISNUMBER($B$9)),$B$9=0),"",ROUNDUP('Producción por Partida'!$M$39*$B$8/$B$9,0)),"")
A30: =IF('Producción por Partida'!$D$40="","",'Producción por Partida'!$D$40) | B30: =IF('Producción por Partida'!$B$40="","",IF('Producción por Partida'!$C$40="",'Producción por Partida'!$B$40,'Producción por Partida'!$C$40)) | C30: =IF('Producción por Partida'!$E$40="","",'Producción por Partida'!$E$40) | D30: =IFERROR(IF(OR('Producción por Partida'!$M$40="",NOT(ISNUMBER($B$8)),NOT(ISNUMBER($B$9)),$B$9=0),"",ROUNDUP('Producción por Partida'!$M$40*$B$8/$B$9,0)),"")
A31: =IF('Producción por Partida'!$D$41="","",'Producción por Partida'!$D$41) | B31: =IF('Producción por Partida'!$B$41="","",IF('Producción por Partida'!$C$41="",'Producción por Partida'!$B$41,'Producción por Partida'!$C$41)) | C31: =IF('Producción por Partida'!$E$41="","",'Producción por Partida'!$E$41) | D31: =IFERROR(IF(OR('Producción por Partida'!$M$41="",NOT(ISNUMBER($B$8)),NOT(ISNUMBER($B$9)),$B$9=0),"",ROUNDUP('Producción por Partida'!$M$41*$B$8/$B$9,0)),"")
A32: =IF('Producción por Partida'!$D$42="","",'Producción por Partida'!$D$42) | B32: =IF('Producción por Partida'!$B$42="","",IF('Producción por Partida'!$C$42="",'Producción por Partida'!$B$42,'Producción por Partida'!$C$42)) | C32: =IF('Producción por Partida'!$E$42="","",'Producción por Partida'!$E$42) | D32: =IFERROR(IF(OR('Producción por Partida'!$M$42="",NOT(ISNUMBER($B$8)),NOT(ISNUMBER($B$9)),$B$9=0),"",ROUNDUP('Producción por Partida'!$M$42*$B$8/$B$9,0)),"")
A33: =IF('Producción por Partida'!$D$43="","",'Producción por Partida'!$D$43) | B33: =IF('Producción por Partida'!$B$43="","",IF('Producción por Partida'!$C$43="",'Producción por Partida'!$B$43,'Producción por Partida'!$C$43)) | C33: =IF('Producción por Partida'!$E$43="","",'Producción por Partida'!$E$43) | D33: =IFERROR(IF(OR('Producción por Partida'!$M$43="",NOT(ISNUMBER($B$8)),NOT(ISNUMBER($B$9)),$B$9=0),"",ROUNDUP('Producción por Partida'!$M$43*$B$8/$B$9,0)),"")
A34: TOTAL DEL DÍA | D34: =IF(COUNT(D14:D33)=0,"",SUM(D14:D33)) -> 66 | E34: =IF(COUNT(E14:E33)=0,"",SUM(E14:E33))
A36: Responsable de cocina del día (nombre y firma):
A37: Incidencias del día:
A38: Temperaturas de la columna «Conservación»: mantener en caliente a 63 °C o más; refrigerar a 4 °C o menos si la vida útil pasa de 24 horas y a 8 °C o menos si no llega; congelar a -18 °C o menos; y al enfriar, bajar de 60 °C a 10 °C en menos de dos horas. La norma admite otras temperaturas si el operador demuestra ante la autoridad competente que son seguras. Verificado el 06-09-2026 · RD 1086/2020, art. 30.1, 30.2, 30.5 y 30.7 (redacción del RD 1021/2022) · https://www.boe.es/buscar/act.php?id=BOE-A-2020-15872
A39: Esta hoja NO sustituye a los registros del APPCC ni a la matriz de alérgenos por plato: ésos van en el «Pack APPCC». Aquí se registra cuánto se produjo y cómo se conservó.
A40: Se imprime en A4 vertical. Las listas de los desplegables están debajo, fuera de la zona de impresión: no las borres.
A44: Días de la semana
A45: Lunes
A46: Martes
...

Sheet Ajuste por Desviación
A1: Ajuste por desviación
A2: AI Chef Pro · aichef.pro — Manual del Chef Ejecutivo
A3: Se rellena al CERRAR la semana, con lo que pasó de verdad. Por eso viene vacía.
A5: DESVIACIÓN DE CUBIERTOS
A6: Tolerancia de desviación (%)
A7: La tolerancia viene VACÍA y es obligatoria: mientras no escribas la tuya, la columna de desviación se queda gris. No existe ningún estándar publicado de cuánto puede desviarse una previsión de cubiertos, y este producto no se inventa ninguno: empieza mirando tus cuatro últimas semanas y ponte el número que puedas sostener.
A9: Día | B9: Servicio | C9: Previsión | D9: Cubiertos reales | E9: Desviación (cubiertos) | F9: Desviación (%) | G9: Lectura | H9: Histórico para la semana que viene
A10: =IF('Previsión de Cubiertos'!$A$15="","",'Previsión de Cubiertos'!$A$15) -> Lunes | B10: =IF('Previsión de Cubiertos'!$B$15="","",'Previsión de Cubiertos'!$B$15) -> Comida | C10: =IF('Previsión de Cubiertos'!$F$15="","",'Previsión de Cubiertos'!$F$15) | E10: =IF(OR(NOT(ISNUMBER($C10)),NOT(ISNUMBER($D10))),"",$D10-$C10) | F10: =IFERROR(IF(OR(NOT(ISNUMBER($E10)),NOT(ISNUMBER($C10)),$C10=0),"",$E10/$C10),"") | G10: =IF(NOT(ISNUMBER($E10)),"",IF($E10>0,"Por encima de lo previsto",IF($E10<0,"Por debajo de lo previsto","Justo en la previsión"))) | H10: =IF($D10="","",$D10)
A11: =IF('Previsión de Cubiertos'!$A$16="","",'Previsión de Cubiertos'!$A$16) -> Lunes | B11: =IF('Previsión de Cubiertos'!$B$16="","",'Previsión de Cubiertos'!$B$16) -> Cena | C11: =IF('Previsión de Cubiertos'!$F$16="","",'Previsión de Cubiertos'!$F$16) | E11: =IF(OR(NOT(ISNUMBER($C11)),NOT(ISNUMBER($D11))),"",$D11-$C11) | F11: =IFERROR(IF(OR(NOT(ISNUMBER($E11)),NOT(ISNUMBER($C11)),$C11=0),"",$E11/$C11),"") | G11: =IF(NOT(ISNUMBER($E11)),"",IF($E11>0,"Por encima de lo previsto",IF($E11<0,"Por debajo de lo previsto","Justo en la previsión"))) | H11: =IF($D11="","",$D11)
A12: =IF('Previsión de Cubiertos'!$A$17="","",'Previsión de Cubiertos'!$A$17) -> Martes | B12: =IF('Previsión de Cubiertos'!$B$17="","",'Previsión de Cubiertos'!$B$17) -> Comida | C12: =IF('Previsión de Cubiertos'!$F$17="","",'Previsión de Cubiertos'!$F$17) -> 60 | E12: =IF(OR(NOT(ISNUMBER($C12)),NOT(ISNUMBER($D12))),"",$D12-$C12) | F12: =IFERROR(IF(OR(NOT(ISNUMBER($E12)),NOT(ISNUMBER($C12)),$C12=0),"",$E12/$C12),"") | G12: =IF(NOT(ISNUMBER($E12)),"",IF($E12>0,"Por encima de lo previsto",IF($E12<0,"Por debajo de lo previsto","Justo en la previsión"))) | H12: =IF($D12="","",$D12)
A13: =IF('Previsión de Cubiertos'!$A$18="","",'Previsión de Cubiertos'!$A$18) -> Martes | B13: =IF('Previsión de Cubiertos'!$B$18="","",'Previsión de Cubiertos'!$B$18) -> Cena | C13: =IF('Previsión de Cubiertos'!$F$18="","",'Previsión de Cubiertos'!$F$18) -> 40 | E13: =IF(OR(NOT(ISNUMBER($C13)),NOT(ISNUMBER($D13))),"",$D13-$C13) | F13: =IFERROR(IF(OR(NOT(ISNUMBER($E13)),NOT(ISNUMBER($C13)),$C13=0),"",$E13/$C13),"") | G13: =IF(NOT(ISNUMBER($E13)),"",IF($E13>0,"Por encima de lo previsto",IF($E13<0,"Por debajo de lo previsto","Justo en la previsión"))) | H13: =IF($D13="","",$D13)
A14: =IF('Previsión de Cubiertos'!$A$19="","",'Previsión de Cubiertos'!$A$19) -> Miércoles | B14: =IF('Previsión de Cubiertos'!$B$19="","",'Previsión de Cubiertos'!$B$19) -> Comida | C14: =IF('Previsión de Cubiertos'!$F$19="","",'Previsión de Cubiertos'!$F$19) -> 64 | E14: =IF(OR(NOT(ISNUMBER($C14)),NOT(ISNUMBER($D14))),"",$D14-$C14) | F14: =IFERROR(IF(OR(NOT(ISNUMBER($E14)),NOT(ISNUMBER($C14)),$C14=0),"",$E14/$C14),"") | G14: =IF(NOT(ISNUMBER($E14)),"",IF($E14>0,"Por encima de lo previsto",IF($E14<0,"Por debajo de lo previsto","Justo en la previsión"))) | H14: =IF($D14="","",$D14)
A15: =IF('Previsión de Cubiertos'!$A$20="","",'Previsión de Cubiertos'!$A$20) -> Miércoles | B15: =IF('Previsión de Cubiertos'!$B$20="","",'Previsión de Cubiertos'!$B$20) -> Cena | C15: =IF('Previsión de Cubiertos'!$F$20="","",'Previsión de Cubiertos'!$F$20) -> 46 | E15: =IF(OR(NOT(ISNUMBER($C15)),NOT(ISNUMBER($D15))),"",$D15-$C15) | F15: =IFERROR(IF(OR(NOT(ISNUMBER($E15)),NOT(ISNUMBER($C15)),$C15=0),"",$E15/$C15),"") | G15: =IF(NOT(ISNUMBER($E15)),"",IF($E15>0,"Por encima de lo previsto",IF($E15<0,"Por debajo de lo previsto","Justo en la previsión"))) | H15: =IF($D15="","",$D15)
A16: =IF('Previsión de Cubiertos'!$A$21="","",'Previsión de Cubiertos'!$A$21) -> Jueves | B16: =IF('Previsión de Cubiertos'!$B$21="","",'Previsión de Cubiertos'!$B$21) -> Comida | C16: =IF('Previsión de Cubiertos'!$F$21="","",'Previsión de Cubiertos'!$F$21) -> 70 | E16: =IF(OR(NOT(ISNUMBER($C16)),NOT(ISNUMBER($D16))),"",$D16-$C16) | F16: =IFERROR(IF(OR(NOT(ISNUMBER($E16)),NOT(ISNUMBER($C16)),$C16=0),"",$E16/$C16),"") | G16: =IF(NOT(ISNUMBER($E16)),"",IF($E16>0,"Por encima de lo previsto",IF($E16<0,"Por debajo de lo previsto","Justo en la previsión"))) | H16: =IF($D16="","",$D16)
A17: =IF('Previsión de Cubiertos'!$A$22="","",'Previsión de Cubiertos'!$A$22) -> Jueves | B17: =IF('Previsión de Cubiertos'!$B$22="","",'Previsión de Cubiertos'!$B$22) -> Cena | C17: =IF('Previsión de Cubiertos'!$F$22="","",'Previsión de Cubiertos'!$F$22) -> 58 | E17: =IF(OR(NOT(ISNUMBER($C17)),NOT(ISNUMBER($D17))),"",$D17-$C17) | F17: =IFERROR(IF(OR(NOT(ISNUMBER($E17)),NOT(ISNUMBER($C17)),$C17=0),"",$E17/$C17),"") | G17: =IF(NOT(ISNUMBER($E17)),"",IF($E17>0,"Por encima de lo previsto",IF($E17<0,"Por debajo de lo previsto","Justo en la previsión"))) | H17: =IF($D17="","",$D17)
A18: =IF('Previsión de Cubiertos'!$A$23="","",'Previsión de Cubiertos'!$A$23) -> Viernes | B18: =IF('Previsión de Cubiertos'!$B$23="","",'Previsión de Cubiertos'!$B$23) -> Comida | C18: =IF('Previsión de Cubiertos'!$F$23="","",'Previsión de Cubiertos'!$F$23) -> 78 | E18: =IF(OR(NOT(ISNUMBER($C18)),NOT(ISNUMBER($D18))),"",$D18-$C18) | F18: =IFERROR(IF(OR(NOT(ISNUMBER($E18)),NOT(ISNUMBER($C18)),$C18=0),"",$E18/$C18),"") | G18: =IF(NOT(ISNUMBER($E18)),"",IF($E18>0,"Por encima de lo previsto",IF($E18<0,"Por debajo de lo previsto","Justo en la previsión"))) | H18: =IF($D18="","",$D18)
A19: =IF('Previsión de Cubiertos'!$A$24="","",'Previsión de Cubiertos'!$A$24) -> Viernes | B19: =IF('Previsión de Cubiertos'!$B$24="","",'Previsión de Cubiertos'!$B$24) -> Cena | C19: =IF('Previsión de Cubiertos'!$F$24="","",'Previsión de Cubiertos'!$F$24) -> 105 | E19: =IF(OR(NOT(ISNUMBER($C19)),NOT(ISNUMBER($D19))),"",$D19-$C19) | F19: =IFERROR(IF(OR(NOT(ISNUMBER($E19)),NOT(ISNUMBER($C19)),$C19=0),"",$E19/$C19),"") | G19: =IF(NOT(ISNUMBER($E19)),"",IF($E19>0,"Por encima de lo previsto",IF($E19<0,"Por debajo de lo previsto","Justo en la previsión"))) | H19: =IF($D19="","",$D19)
A20: =IF('Previsión de Cubiertos'!$A$25="","",'Previsión de Cubiertos'!$A$25) -> Sábado | B20: =IF('Previsión de Cubiertos'!$B$25="","",'Previsión de Cubiertos'!$B$25) -> Comida | C20: =IF('Previsión de Cubiertos'!$F$25="","",'Previsión de Cubiertos'!$F$25) -> 92 | E20: =IF(OR(NOT(ISNUMBER($C20)),NOT(ISNUMBER($D20))),"",$D20-$C20) | F20: =IFERROR(IF(OR(NOT(ISNUMBER($E20)),NOT(ISNUMBER($C20)),$C20=0),"",$E20/$C20),"") | G20: =IF(NOT(ISNUMBER($E20)),"",IF($E20>0,"Por encima de lo previsto",IF($E20<0,"Por debajo de lo previsto","Justo en la previsión"))) | H20: =IF($D20="","",$D20)
A21: =IF('Previsión de Cubiertos'!$A$26="","",'Previsión de Cubiertos'!$A$26) -> Sábado | B21: =IF('Previsión de Cubiertos'!$B$26="","",'Previsión de Cubiertos'!$B$26) -> Cena | C21: =IF('Previsión de Cubiertos'!$F$26="","",'Previsión de Cubiertos'!$F$26) -> 118 | E21: =IF(OR(NOT(ISNUMBER($C21)),NOT(ISNUMBER($D21))),"",$D21-$C21) | F21: =IFERROR(IF(OR(NOT(ISNUMBER($E21)),NOT(ISNUMBER($C21)),$C21=0),"",$E21/$C21),"") | G21: =IF(NOT(ISNUMBER($E21)),"",IF($E21>0,"Por encima de lo previsto",IF($E21<0,"Por debajo de lo previsto","Justo en la previsión"))) | H21: =IF($D21="","",$D21)
A22: =IF('Previsión de Cubiertos'!$A$27="","",'Previsión de Cubiertos'!$A$27) -> Domingo | B22: =IF('Previsión de Cubiertos'!$B$27="","",'Previsión de Cubiertos'!$B$27) -> Comida | C22: =IF('Previsión de Cubiertos'!$F$27="","",'Previsión de Cubiertos'!$F$27) -> 132 | E22: =IF(OR(NOT(ISNUMBER($C22)),NOT(ISNUMBER($D22))),"",$D22-$C22) | F22: =IFERROR(IF(OR(NOT(ISNUMBER($E22)),NOT(ISNUMBER($C22)),$C22=0),"",$E22/$C22),"") | G22: =IF(NOT(ISNUMBER($E22)),"",IF($E22>0,"Por encima de lo previsto",IF($E22<0,"Por debajo de lo previsto","Justo en la previsión"))) | H22: =IF($D22="","",$D22)
A23: =IF('Previsión de Cubiertos'!$A$28="","",'Previsión de Cubiertos'!$A$28) -> Domingo | B23: =IF('Previsión de Cubiertos'!$B$28="","",'Previsión de Cubiertos'!$B$28) -> Cena | C23: =IF('Previsión de Cubiertos'!$F$28="","",'Previsión de Cubiertos'!$F$28) -> 95 | E23: =IF(OR(NOT(ISNUMBER($C23)),NOT(ISNUMBER($D23))),"",$D23-$C23) | F23: =IFERROR(IF(OR(NOT(ISNUMBER($E23)),NOT(ISNUMBER($C23)),$C23=0),"",$E23/$C23),"") | G23: =IF(NOT(ISNUMBER($E23)),"",IF($E23>0,"Por encima de lo previsto",IF($E23<0,"Por debajo de lo previsto","Justo en la previsión"))) | H23: =IF($D23="","",$D23)
A24: TOTAL DE LA SEMANA | C24: =IF(COUNT(C10:C23)=0,"",SUM(C10:C23)) -> 958 | D24: =IF(COUNT(D10:D23)=0,"",SUM(D10:D23)) | E24: =IF(COUNT(E10:E23)=0,"",SUM(E10:E23)) | F24: =IFERROR(IF(OR(NOT(ISNUMBER($E$24)),NOT(ISNUMBER($C$24)),$C$24=0),"",$E$24/$C$24),"") | G24: =IF(NOT(ISNUMBER($E$24)),"",IF($E$24>0,"Por encima de lo previsto",IF($E$24<0,"Por debajo de lo previsto","Justo en la previsión")))
A26: La última columna es la que cierra el círculo: esos cubiertos reales son el histórico de la semana que viene. Cópialos a la columna «Histórico del mismo servicio» de la hoja «Previsión de Cubiertos» antes de planificar.
A27: Una desviación aislada no dice nada. Lo que hay que mirar es el signo repetido: cuatro semanas seguidas por debajo significan que estás produciendo de más todas las semanas.
A29: SOBRANTE DE PRODUCCIÓN
A30: Id | B30: Plato | C30: Partida | D30: Raciones a producir previstas | E30: Raciones producidas | F30: Raciones vendidas | G30: Sobrante (raciones) | H30: Sobrante sobre lo producido | I30: Lectura
A31: =IF('Producción por Partida'!$A$24="","",'Producción por Partida'!$A$24) -> E1 | B31: =IF('Producción por Partida'!$B$24="","",'Producción por Partida'!$B$24) -> Croquetas de jamón ibérico (6 ud) | C31: =IF('Producción por Partida'!$D$24="","",'Producción por Partida'!$D$24) -> Fríos y entrantes | D31: =IF('Producción por Partida'!$M$24="","",'Producción por Partida'!$M$24) -> 0 | G31: =IF(OR(NOT(ISNUMBER($E31)),NOT(ISNUMBER($F31))),"",$E31-$F31) | H31: =IFERROR(IF(OR(NOT(ISNUMBER($G31)),NOT(ISNUMBER($E31)),$E31=0),"",$G31/$E31),"") | I31: =IF(NOT(ISNUMBER($G31)),"",IF($G31>0,"Sobra: baja la producción de este plato",IF($G31<0,"Faltó: sube la producción de este plato","Ajustado")))
A32: =IF('Producción por Partida'!$A$25="","",'Producción por Partida'!$A$25) -> E2 | B32: =IF('Producción por Partida'!$B$25="","",'Producción por Partida'!$B$25) -> Ensalada de tomate rosa, ventresca y cebolleta | C32: =IF('Producción por Partida'!$D$25="","",'Producción por Partida'!$D$25) -> Fríos y entrantes | D32: =IF('Producción por Partida'!$M$25="","",'Producción por Partida'!$M$25) -> 77 | G32: =IF(OR(NOT(ISNUMBER($E32)),NOT(ISNUMBER($F32))),"",$E32-$F32) | H32: =IFERROR(IF(OR(NOT(ISNUMBER($G32)),NOT(ISNUMBER($E32)),$E32=0),"",$G32/$E32),"") | I32: =IF(NOT(ISNUMBER($G32)),"",IF($G32>0,"Sobra: baja la producción de este plato",IF($G32<0,"Faltó: sube la producción de este plato","Ajustado")))
A33: =IF('Producción por Partida'!$A$26="","",'Producción por Partida'!$A$26) -> E3 | B33: =IF('Producción por Partida'!$B$26="","",'Producción por Partida'!$B$26) -> Gambas al ajillo | C33: =IF('Producción por Partida'!$D$26="","",'Producción por Partida'!$D$26) -> Fríos y entrantes | D33: =IF('Producción por Partida'!$M$26="","",'Producción por Partida'!$M$26) -> 32 | G33: =IF(OR(NOT(ISNUMBER($E33)),NOT(ISNUMBER($F33))),"",$E33-$F33) | H33: =IFERROR(IF(OR(NOT(ISNUMBER($G33)),NOT(ISNUMBER($E33)),$E33=0),"",$G33/$E33),"") | I33: =IF(NOT(ISNUMBER($G33)),"",IF($G33>0,"Sobra: baja la producción de este plato",IF($G33<0,"Faltó: sube la producción de este plato","Ajustado")))
