Workbook

Sheet Instrucciones
B2: 10 — Plan de Producción Semanal y Control de Mermas
B4: Qué resuelve esta plantilla:
B5: ▸ Cuánto produces de cada referencia, cuánto vendes y cuánto tiras — con el coste en euros.
B6: ▸ La merma es el margen que se te va sin que lo veas: medirla una semana ya cambia el plan.
B8: Cómo usar esta plantilla:
B9: ▸ Hoja Plan Semanal: escribe las unidades previstas por día. Es el plan que baja al obrador.
B10: ▸ Hoja Producido vs Vendido: al cerrar la tienda anota producido y vendido de cada referencia.
B11: ▸ El sobrante, el porcentaje de merma y su coste se calculan solos. Rellena el coste por unidad con el escandallo real (si no lo tienes, empieza por el coste de materia prima).
B12: ▸ Hoja Resumen por Partida: mira dónde se concentra la merma antes de tocar el plan.
B14: Columna Acción: qué hacer con el sobrante
B15: ▸ Cada opción lleva su condición dentro. Léela antes de elegir: no todo el sobrante se puede congelar.
B16: ▸ Registra siempre lo que decides: es lo que te permite defender tu criterio ante una inspección.
... B26: Versión 2.0 · agosto 2026 · aichef.pro/kit-tareas-pasteleria · info@aichef.pro

Sheet Plan Semanal
A1: Plan de Producción Semanal
A2: Semana del ____/____ al ____/____ Responsable: _________________________ Anota las unidades previstas por día
A4: Producto | B4: Partida | C4: Lun | D4: Mar | E4: Mié | F4: Jue | G4: Vie | H4: Sáb | I4: Dom | J4: Total semana | K4: Notas
A5: Bollería
A6: Croissant de mantequilla | B6: Bollería | J6: =SUM(C6:I6) -> 0
A7: Pain au chocolat | B7: Bollería | J7: =SUM(C7:I7) -> 0
A8: Napolitana de crema | B8: Bollería | J8: =SUM(C8:I8) -> 0
A9: Ensaimada | B9: Bollería | J9: =SUM(C9:I9) -> 0
A10: Brioche | B10: Bollería | J10: =SUM(C10:I10) -> 0
A11: Caracola de pasas | B11: Bollería | J11: =SUM(C11:I11) -> 0
A12: Palmera de hojaldre | B12: Bollería | J12: =SUM(C12:I12) -> 0
A13: Croissant relleno de crema | B13: Bollería | J13: =SUM(C13:I13) -> 0
J14: =SUM(C14:I14) -> 0
J15: =SUM(C15:I15) -> 0
A16: Pastelería
A17: Tarta de queso | B17: Pastelería | J17: =SUM(C17:I17) -> 0
A18: Tarta de manzana | B18: Pastelería | J18: =SUM(C18:I18) -> 0
A19: Milhojas | B19: Pastelería | J19: =SUM(C19:I19) -> 0
A20: Éclair | B20: Pastelería | J20: =SUM(C20:I20) -> 0
A21: Tarta de zanahoria | B21: Pastelería | J21: =SUM(C21:I21) -> 0
A22: Tarta Sacher | B22: Pastelería | J22: =SUM(C22:I22) -> 0
A23: Entremet individual | B23: Pastelería | J23: =SUM(C23:I23) -> 0
A24: Macarons (caja de 6) | B24: Pastelería | J24: =SUM(C24:I24) -> 0
A25: Tartaleta de frutas | B25: Pastelería | J25: =SUM(C25:I25) -> 0
A26: Lionesa o profiterol | B26: Pastelería | J26: =SUM(C26:I26) -> 0
J27: =SUM(C27:I27) -> 0
J28: =SUM(C28:I28) -> 0
A29: Pan
A30: Barra | B30: Pan | J30: =SUM(C30:I30) -> 0
A31: Hogaza de masa madre | B31: Pan | J31: =SUM(C31:I31) -> 0
A32: Chapata | B32: Pan | J32: =SUM(C32:I32) -> 0
A33: Pan de molde | B33: Pan | J33: =SUM(C33:I33) -> 0
A34: Focaccia | B34: Pan | J34: =SUM(C34:I34) -> 0
J35: =SUM(C35:I35) -> 0
J36: =SUM(C36:I36) -> 0
A37: Salado
A38: Quiche | B38: Salado | J38: =SUM(C38:I38) -> 0
A39: Empanada | B39: Salado | J39: =SUM(C39:I39) -> 0
A40: Croissant de jamón y queso | B40: Salado | J40: =SUM(C40:I40) -> 0
J41: =SUM(C41:I41) -> 0
...

Sheet Producido vs Vendido
A1: Producido vs Vendido — Control Diario de Mermas
A2: Anota cada día lo que has producido y lo que has vendido: el sobrante y su coste se calculan solos
A4: Fecha | B4: Producto | C4: Partida | D4: Previsto | E4: Producido | F4: Vendido | G4: Sobrante | H4: Merma % | I4: Coste ud (€) | J4: Coste merma (€) | K4: Acción | L4: Notas
B5: Croissant de mantequilla | C5: Bollería | G5: =IFERROR(E5-F5,0) -> 0 | H5: =IFERROR(G5/E5,0) -> 0 | J5: =IFERROR(G5*I5,0) -> 0
B6: Pain au chocolat | C6: Bollería | G6: =IFERROR(E6-F6,0) -> 0 | H6: =IFERROR(G6/E6,0) -> 0 | J6: =IFERROR(G6*I6,0) -> 0
B7: Napolitana de crema | C7: Bollería | G7: =IFERROR(E7-F7,0) -> 0 | H7: =IFERROR(G7/E7,0) -> 0 | J7: =IFERROR(G7*I7,0) -> 0
B8: Palmera de hojaldre | C8: Bollería | G8: =IFERROR(E8-F8,0) -> 0 | H8: =IFERROR(G8/E8,0) -> 0 | J8: =IFERROR(G8*I8,0) -> 0
B9: Tarta de queso | C9: Pastelería | G9: =IFERROR(E9-F9,0) -> 0 | H9: =IFERROR(G9/E9,0) -> 0 | J9: =IFERROR(G9*I9,0) -> 0
B10: Milhojas | C10: Pastelería | G10: =IFERROR(E10-F10,0) -> 0 | H10: =IFERROR(G10/E10,0) -> 0 | J10: =IFERROR(G10*I10,0) -> 0
B11: Tartaleta de frutas | C11: Pastelería | G11: =IFERROR(E11-F11,0) -> 0 | H11: =IFERROR(G11/E11,0) -> 0 | J11: =IFERROR(G11*I11,0) -> 0
B12: Barra | C12: Pan | G12: =IFERROR(E12-F12,0) -> 0 | H12: =IFERROR(G12/E12,0) -> 0 | J12: =IFERROR(G12*I12,0) -> 0
B13: Hogaza de masa madre | C13: Pan | G13: =IFERROR(E13-F13,0) -> 0 | H13: =IFERROR(G13/E13,0) -> 0 | J13: =IFERROR(G13*I13,0) -> 0
B14: Quiche | C14: Salado | G14: =IFERROR(E14-F14,0) -> 0 | H14: =IFERROR(G14/E14,0) -> 0 | J14: =IFERROR(G14*I14,0) -> 0
B15: Magdalena | C15: Bizcochería | G15: =IFERROR(E15-F15,0) -> 0 | H15: =IFERROR(G15/E15,0) -> 0 | J15: =IFERROR(G15*I15,0) -> 0
B16: Cookie de chocolate | C16: Bizcochería | G16: =IFERROR(E16-F16,0) -> 0 | H16: =IFERROR(G16/E16,0) -> 0 | J16: =IFERROR(G16*I16,0) -> 0
G17: =IFERROR(E17-F17,0) -> 0 | H17: =IFERROR(G17/E17,0) -> 0 | J17: =IFERROR(G17*I17,0) -> 0
G18: =IFERROR(E18-F18,0) -> 0 | H18: =IFERROR(G18/E18,0) -> 0 | J18: =IFERROR(G18*I18,0) -> 0
G19: =IFERROR(E19-F19,0) -> 0 | H19: =IFERROR(G19/E19,0) -> 0 | J19: =IFERROR(G19*I19,0) -> 0
G20: =IFERROR(E20-F20,0) -> 0 | H20: =IFERROR(G20/E20,0) -> 0 | J20: =IFERROR(G20*I20,0) -> 0
G21: =IFERROR(E21-F21,0) -> 0 | H21: =IFERROR(G21/E21,0) -> 0 | J21: =IFERROR(G21*I21,0) -> 0
G22: =IFERROR(E22-F22,0) -> 0 | H22: =IFERROR(G22/E22,0) -> 0 | J22: =IFERROR(G22*I22,0) -> 0
G23: =IFERROR(E23-F23,0) -> 0 | H23: =IFERROR(G23/E23,0) -> 0 | J23: =IFERROR(G23*I23,0) -> 0
G24: =IFERROR(E24-F24,0) -> 0 | H24: =IFERROR(G24/E24,0) -> 0 | J24: =IFERROR(G24*I24,0) -> 0
G25: =IFERROR(E25-F25,0) -> 0 | H25: =IFERROR(G25/E25,0) -> 0 | J25: =IFERROR(G25*I25,0) -> 0
G26: =IFERROR(E26-F26,0) -> 0 | H26: =IFERROR(G26/E26,0) -> 0 | J26: =IFERROR(G26*I26,0) -> 0
G27: =IFERROR(E27-F27,0) -> 0 | H27: =IFERROR(G27/E27,0) -> 0 | J27: =IFERROR(G27*I27,0) -> 0
G28: =IFERROR(E28-F28,0) -> 0 | H28: =IFERROR(G28/E28,0) -> 0 | J28: =IFERROR(G28*I28,0) -> 0
... G254: =IFERROR(E254-F254,0) -> 0 | H254: =IFERROR(G254/E254,0) -> 0 | J254: =IFERROR(G254*I254,0) -> 0
A255: TOTALES | D255: =SUM(D5:D254) -> 0 | E255: =SUM(E5:E254) -> 0 | F255: =SUM(F5:F254) -> 0 | G255: =SUM(G5:G254) -> 0 | H255: =IFERROR(G255/E255,0) -> 0 | J255: =SUM(J5:J254) -> 0
A257: Criterio APPCC: el producto que ha estado expuesto en vitrina NO se congela para venderlo después. Solo se congela producto del día que no ha salido a la venta y que se abate antes de bajar de −18 °C. Si vendes un producto que ha sido congelado, tienes que informar de que está descongelado. Prioriza la donación sobre el desecho: revisa el plan de prevención de pérdidas y desperdicio alimentario que te aplique antes de dar salida al sobrante.
A261: — Kit de Tareas Recurrentes · Pastelería / Obrador · AI Chef Pro · aichef.pro

Sheet Resumen por Partida
A1: Resumen Semanal por Partida
A2: Se calcula solo a partir de la hoja Producido vs Vendido
A4: Partida | B4: Producido | C4: Vendido | D4: Sobrante | E4: Merma % | F4: Coste merma (€) | G4: Lectura
A5: Bollería | B5: =SUMIF('Producido vs Vendido'!$C$5:$C$254,$A5,'Producido vs Vendido'!$E$5:$E$254) -> 0 | C5: =SUMIF('Producido vs Vendido'!$C$5:$C$254,$A5,'Producido vs Vendido'!$F$5:$F$254) -> 0 | D5: =SUMIF('Producido vs Vendido'!$C$5:$C$254,$A5,'Producido vs Vendido'!$G$5:$G$254) -> 0 | E5: =IFERROR(D5/B5,0) -> 0 | F5: =SUMIF('Producido vs Vendido'!$C$5:$C$254,$A5,'Producido vs Vendido'!$J$5:$J$254) -> 0 | G5: =IF(E5<=$B$13,"OK","Revisar") -> OK
A6: Pastelería | B6: =SUMIF('Producido vs Vendido'!$C$5:$C$254,$A6,'Producido vs Vendido'!$E$5:$E$254) -> 0 | C6: =SUMIF('Producido vs Vendido'!$C$5:$C$254,$A6,'Producido vs Vendido'!$F$5:$F$254) -> 0 | D6: =SUMIF('Producido vs Vendido'!$C$5:$C$254,$A6,'Producido vs Vendido'!$G$5:$G$254) -> 0 | E6: =IFERROR(D6/B6,0) -> 0 | F6: =SUMIF('Producido vs Vendido'!$C$5:$C$254,$A6,'Producido vs Vendido'!$J$5:$J$254) -> 0 | G6: =IF(E6<=$B$13,"OK","Revisar") -> OK
A7: Pan | B7: =SUMIF('Producido vs Vendido'!$C$5:$C$254,$A7,'Producido vs Vendido'!$E$5:$E$254) -> 0 | C7: =SUMIF('Producido vs Vendido'!$C$5:$C$254,$A7,'Producido vs Vendido'!$F$5:$F$254) -> 0 | D7: =SUMIF('Producido vs Vendido'!$C$5:$C$254,$A7,'Producido vs Vendido'!$G$5:$G$254) -> 0 | E7: =IFERROR(D7/B7,0) -> 0 | F7: =SUMIF('Producido vs Vendido'!$C$5:$C$254,$A7,'Producido vs Vendido'!$J$5:$J$254) -> 0 | G7: =IF(E7<=$B$13,"OK","Revisar") -> OK
A8: Salado | B8: =SUMIF('Producido vs Vendido'!$C$5:$C$254,$A8,'Producido vs Vendido'!$E$5:$E$254) -> 0 | C8: =SUMIF('Producido vs Vendido'!$C$5:$C$254,$A8,'Producido vs Vendido'!$F$5:$F$254) -> 0 | D8: =SUMIF('Producido vs Vendido'!$C$5:$C$254,$A8,'Producido vs Vendido'!$G$5:$G$254) -> 0 | E8: =IFERROR(D8/B8,0) -> 0 | F8: =SUMIF('Producido vs Vendido'!$C$5:$C$254,$A8,'Producido vs Vendido'!$J$5:$J$254) -> 0 | G8: =IF(E8<=$B$13,"OK","Revisar") -> OK
A9: Bizcochería | B9: =SUMIF('Producido vs Vendido'!$C$5:$C$254,$A9,'Producido vs Vendido'!$E$5:$E$254) -> 0 | C9: =SUMIF('Producido vs Vendido'!$C$5:$C$254,$A9,'Producido vs Vendido'!$F$5:$F$254) -> 0 | D9: =SUMIF('Producido vs Vendido'!$C$5:$C$254,$A9,'Producido vs Vendido'!$G$5:$G$254) -> 0 | E9: =IFERROR(D9/B9,0) -> 0 | F9: =SUMIF('Producido vs Vendido'!$C$5:$C$254,$A9,'Producido vs Vendido'!$J$5:$J$254) -> 0 | G9: =IF(E9<=$B$13,"OK","Revisar") -> OK
A10: TOTAL | B10: =SUM(B5:B9) -> 0 | C10: =SUM(C5:C9) -> 0 | D10: =SUM(D5:D9) -> 0 | E10: =IFERROR(D10/B10,0) -> 0 | F10: =SUM(F5:F9) -> 0 | G10: =IF(E10<=$B$13,"OK","Revisar") -> OK
A12: Objetivo de Merma
A13: Objetivo de merma (editable) | B13: 0.05 | C13: Escribe aquí tu objetivo: la columna Lectura compara cada partida contra él.
A14: Merma global de la semana | B14: =E10 -> 0 | C14: =IF(B14<=B13,"Dentro del objetivo","Por encima del objetivo: revisa el plan") -> Dentro del objetivo
A16: Criterio: la merma de una pastelería artesana suele moverse entre el 3 % y el 8 % de la producción. Por encima del 10 % hay que revisar el plan de producción: casi siempre es exceso de unidades en dos o tres referencias, no un problema general.
A19: — Kit de Tareas Recurrentes · Pastelería / Obrador · AI Chef Pro · aichef.pro
