Workbook

Sheet Instrucciones
B2: 12 — Control de Alérgenos de Vitrina · 14 Alérgenos de Declaración Obligatoria
B4: Esta plantilla se entrega como BORRADOR. Los símbolos vienen pre-marcados en gris como propuesta de partida. No publiques ni enseñes nada sin contrastar cada referencia con tu receta real y con las fichas técnicas de tus proveedores. La responsabilidad de la información es del establecimiento.
B6: Qué exige la ley:
B7: ▸ El Reglamento (UE) 1169/2011 y el Real Decreto 126/2015 obligan a informar de los 14 alérgenos también en los alimentos que se venden sin envasar: vitrina, granel, obrador y cafetería.
B8: ▸ En producto sin envasar la información tiene que estar disponible POR ESCRITO y ser accesible antes de la compra. La vía oral solo vale si hay un cartel visible que indique que la información escrita se puede solicitar.
B9: ▸ Un «puede contener» genérico no sustituye a declarar los alérgenos que llevas de forma intencionada.
B11: Cómo usar esta plantilla:
B12: ▸ Hoja Matriz Alérgenos: repasa referencia por referencia. Marca ● si el producto lo contiene y ○ si puede contener trazas por contaminación cruzada en tu obrador.
B13: ▸ Anota el proveedor y el número de ficha técnica que respalda cada decisión, pon la fecha de verificación y firma. Hasta que no pongas la fecha, la columna Estado dice NO PUBLICAR.
B14: ▸ La columna Notas de verificación te dice qué mirar en las referencias donde el símbolo depende de la marca o de la receta: pasas y fruta escarchada (sulfitos), turrón (clara de huevo), coberturas de chocolate (lecitina de soja), polvorones (ajonjolí).
B15: ▸ La frase de contaminación cruzada del cartel y de la carta está en celda verde: sustituye la lista por los alérgenos que se manipulan de verdad en tu obrador. Declarar «los 14» cuando no trabajas con crustáceos ni con moluscos es el «puede contener» genérico que la ley desaconseja.
B16: ▸ Hoja Carta de Alérgenos: se rellena sola desde la matriz. Es el documento que se enseña al cliente y el que pide el inspector. Imprímela cuando no quede ninguna referencia sin verificar.
... B32: Versión 2.0 · agosto 2026 · aichef.pro/kit-tareas-pasteleria · info@aichef.pro

Sheet Matriz Alérgenos
A1: Matriz de Alérgenos de Vitrina — Borrador de Trabajo
A2: PLANTILLA DE PARTIDA — NO LA PUBLIQUES SIN VERIFICARLA. Los símbolos vienen pre-marcados en gris como propuesta: contrasta cada referencia con TU receta real y con las fichas técnicas de tus proveedores antes de enseñar nada a un cliente.
A3: ● contiene ○ puede contener trazas celda vacía no contiene Los símbolos en gris son la propuesta de partida; al verificarlos, reescríbelos.
A4: Producto | B4: Categoría | C4: Gluten | D4: Crustáceos | E4: Huevos | F4: Pescado | G4: Cacahuetes | H4: Soja | I4: Lácteos | J4: Frutos de cáscara | K4: Apio | L4: Mostaza | M4: Sésamo | N4: Sulfitos | O4: Altramuces | P4: Moluscos | Q4: Total ● | R4: Proveedor / Nº de ficha técnica | S4: Verificado con ficha técnica (fecha) | T4: Firma | U4: Estado | V4: Notas de verificación
A5: Croissant de mantequilla | B5: Bollería | C5: ● | E5: ● | H5: ○ | I5: ● | J5: ○ | M5: ○ | Q5: =COUNTIF(C5:P5,"●") -> 3 | U5: =IF($S5="","NO PUBLICAR","Verificado") -> NO PUBLICAR
A6: Pain au chocolat | B6: Bollería | C6: ● | E6: ● | H6: ● | I6: ● | J6: ○ | Q6: =COUNTIF(C6:P6,"●") -> 4 | U6: =IF($S6="","NO PUBLICAR","Verificado") -> NO PUBLICAR
A7: Napolitana de crema | B7: Bollería | C7: ● | E7: ● | H7: ○ | I7: ● | J7: ○ | Q7: =COUNTIF(C7:P7,"●") -> 3 | U7: =IF($S7="","NO PUBLICAR","Verificado") -> NO PUBLICAR
A8: Ensaimada | B8: Bollería | C8: ● | E8: ● | H8: ○ | I8: ○ | J8: ○ | Q8: =COUNTIF(C8:P8,"●") -> 2 | U8: =IF($S8="","NO PUBLICAR","Verificado") -> NO PUBLICAR
A9: Brioche | B9: Bollería | C9: ● | E9: ● | H9: ○ | I9: ● | J9: ○ | Q9: =COUNTIF(C9:P9,"●") -> 3 | U9: =IF($S9="","NO PUBLICAR","Verificado") -> NO PUBLICAR
A10: Caracola de pasas | B10: Bollería | C10: ● | E10: ● | H10: ○ | I10: ● | J10: ○ | N10: ● | Q10: =COUNTIF(C10:P10,"●") -> 4 | U10: =IF($S10="","NO PUBLICAR","Verificado") -> NO PUBLICAR | V10: Sulfitos: las pasas suelen ir sulfitadas — comprobar mg/kg en la ficha técnica.
A11: Palmera de hojaldre | B11: Bollería | C11: ● | E11: ○ | H11: ○ | I11: ● | J11: ○ | Q11: =COUNTIF(C11:P11,"●") -> 2 | U11: =IF($S11="","NO PUBLICAR","Verificado") -> NO PUBLICAR
A12: Croissant relleno de crema | B12: Bollería | C12: ● | E12: ● | H12: ○ | I12: ● | J12: ○ | Q12: =COUNTIF(C12:P12,"●") -> 3 | U12: =IF($S12="","NO PUBLICAR","Verificado") -> NO PUBLICAR
A13: Tarta de queso | B13: Pastelería | C13: ● | E13: ● | H13: ○ | I13: ● | J13: ○ | Q13: =COUNTIF(C13:P13,"●") -> 3 | U13: =IF($S13="","NO PUBLICAR","Verificado") -> NO PUBLICAR
A14: Tarta de manzana | B14: Pastelería | C14: ● | E14: ● | I14: ● | J14: ○ | N14: ○ | Q14: =COUNTIF(C14:P14,"●") -> 3 | U14: =IF($S14="","NO PUBLICAR","Verificado") -> NO PUBLICAR
A15: Milhojas | B15: Pastelería | C15: ● | E15: ● | H15: ○ | I15: ● | J15: ○ | Q15: =COUNTIF(C15:P15,"●") -> 3 | U15: =IF($S15="","NO PUBLICAR","Verificado") -> NO PUBLICAR
A16: Éclair | B16: Pastelería | C16: ● | E16: ● | H16: ○ | I16: ● | J16: ○ | Q16: =COUNTIF(C16:P16,"●") -> 3 | U16: =IF($S16="","NO PUBLICAR","Verificado") -> NO PUBLICAR
A17: Tarta de zanahoria | B17: Pastelería | C17: ● | E17: ● | H17: ○ | I17: ● | J17: ● | Q17: =COUNTIF(C17:P17,"●") -> 4 | U17: =IF($S17="","NO PUBLICAR","Verificado") -> NO PUBLICAR
A18: Tarta Sacher | B18: Pastelería | C18: ● | E18: ● | H18: ● | I18: ● | J18: ○ | Q18: =COUNTIF(C18:P18,"●") -> 4 | U18: =IF($S18="","NO PUBLICAR","Verificado") -> NO PUBLICAR
A19: Entremet individual | B19: Pastelería | C19: ● | E19: ● | H19: ● | I19: ● | J19: ○ | Q19: =COUNTIF(C19:P19,"●") -> 4 | U19: =IF($S19="","NO PUBLICAR","Verificado") -> NO PUBLICAR
A20: Macarons (caja de 6) | B20: Pastelería | C20: ○ | E20: ● | H20: ○ | I20: ● | J20: ● | Q20: =COUNTIF(C20:P20,"●") -> 3 | U20: =IF($S20="","NO PUBLICAR","Verificado") -> NO PUBLICAR | V20: Frutos de cáscara: almendra como ingrediente principal, nunca es una traza.
A21: Tartaleta de frutas | B21: Pastelería | C21: ● | E21: ● | I21: ● | J21: ○ | N21: ○ | Q21: =COUNTIF(C21:P21,"●") -> 3 | U21: =IF($S21="","NO PUBLICAR","Verificado") -> NO PUBLICAR
A22: Lionesa o profiterol | B22: Pastelería | C22: ● | E22: ● | H22: ○ | I22: ● | J22: ○ | Q22: =COUNTIF(C22:P22,"●") -> 3 | U22: =IF($S22="","NO PUBLICAR","Verificado") -> NO PUBLICAR
A23: Roscón de Reyes | B23: Temporada | C23: ● | E23: ● | H23: ○ | I23: ● | J23: ● | N23: ● | Q23: =COUNTIF(C23:P23,"●") -> 5 | U23: =IF($S23="","NO PUBLICAR","Verificado") -> NO PUBLICAR | V23: Sulfitos: comprobar mg/kg en la ficha técnica de la fruta escarchada.
A24: Torrijas | B24: Temporada | C24: ● | E24: ● | I24: ● | J24: ○ | N24: ○ | Q24: =COUNTIF(C24:P24,"●") -> 3 | U24: =IF($S24="","NO PUBLICAR","Verificado") -> NO PUBLICAR | V24: Sulfitos: si las elaboras con vino, declara el sulfito como ingrediente, no como traza.
A25: Buñuelos de viento | B25: Temporada | C25: ● | E25: ● | H25: ○ | I25: ● | J25: ○ | Q25: =COUNTIF(C25:P25,"●") -> 3 | U25: =IF($S25="","NO PUBLICAR","Verificado") -> NO PUBLICAR
A26: Huesos de santo | B26: Temporada | C26: ○ | E26: ● | I26: ○ | J26: ● | Q26: =COUNTIF(C26:P26,"●") -> 2 | U26: =IF($S26="","NO PUBLICAR","Verificado") -> NO PUBLICAR
A27: Panellets | B27: Temporada | C27: ○ | E27: ● | I27: ○ | J27: ● | Q27: =COUNTIF(C27:P27,"●") -> 2 | U27: =IF($S27="","NO PUBLICAR","Verificado") -> NO PUBLICAR
A28: Polvorón o mantecado | B28: Temporada | C28: ● | E28: ○ | I28: ○ | J28: ● | M28: ○ | Q28: =COUNTIF(C28:P28,"●") -> 2 | U28: =IF($S28="","NO PUBLICAR","Verificado") -> NO PUBLICAR | V28: Sésamo: muchos polvorones llevan ajonjolí como ingrediente — revisa el tuyo.
A29: Turrón de almendra | B29: Temporada | E29: ● | H29: ○ | I29: ○ | J29: ● | M29: ○ | Q29: =COUNTIF(C29:P29,"●") -> 2 | U29: =IF($S29="","NO PUBLICAR","Verificado") -> NO PUBLICAR | V29: Clara de huevo: verificar receta o variedad (Alicante lleva, Jijona puede no llevar).
A30: Mona de Pascua | B30: Temporada | C30: ● | E30: ● | H30: ● | I30: ● | J30: ○ | Q30: =COUNTIF(C30:P30,"●") -> 4 | U30: =IF($S30="","NO PUBLICAR","Verificado") -> NO PUBLICAR
A31: Brownie | B31: Bizcochería | C31: ● | E31: ● | H31: ● | I31: ● | J31: ● | Q31: =COUNTIF(C31:P31,"●") -> 5 | U31: =IF($S31="","NO PUBLICAR","Verificado") -> NO PUBLICAR | V31: Soja: lecitina de la cobertura de chocolate — comprobar la ficha técnica de tu cobertura.
A32: Cookie de chocolate | B32: Bizcochería | C32: ● | E32: ● | H32: ● | I32: ● | J32: ○ | Q32: =COUNTIF(C32:P32,"●") -> 4 | U32: =IF($S32="","NO PUBLICAR","Verificado") -> NO PUBLICAR | V32: Soja: lecitina de las pepitas de chocolate — comprobar la ficha técnica.
A33: Magdalena | B33: Bizcochería | C33: ● | E33: ● | H33: ○ | I33: ● | J33: ○ | Q33: =COUNTIF(C33:P33,"●") -> 3 | U33: =IF($S33="","NO PUBLICAR","Verificado") -> NO PUBLICAR
A34: Bizcocho de yogur | B34: Bizcochería | C34: ● | E34: ● | H34: ○ | I34: ● | J34: ○ | Q34: =COUNTIF(C34:P34,"●") -> 3 | U34: =IF($S34="","NO PUBLICAR","Verificado") -> NO PUBLICAR
A35: Galleta de mantequilla | B35: Bizcochería | C35: ● | E35: ● | H35: ○ | I35: ● | J35: ○ | Q35: =COUNTIF(C35:P35,"●") -> 3 | U35: =IF($S35="","NO PUBLICAR","Verificado") -> NO PUBLICAR
A36: Financier de almendra | B36: Bizcochería | C36: ● | E36: ● | H36: ○ | I36: ● | J36: ● | Q36: =COUNTIF(C36:P36,"●") -> 4 | U36: =IF($S36="","NO PUBLICAR","Verificado") -> NO PUBLICAR
A37: Quiche | B37: Salado | C37: ● | E37: ● | H37: ○ | I37: ● | K37: ○ | L37: ○ | Q37: =COUNTIF(C37:P37,"●") -> 3 | U37: =IF($S37="","NO PUBLICAR","Verificado") -> NO PUBLICAR
A38: Empanada de atún | B38: Salado | C38: ● | E38: ○ | F38: ● | K38: ○ | N38: ○ | Q38: =COUNTIF(C38:P38,"●") -> 2 | U38: =IF($S38="","NO PUBLICAR","Verificado") -> NO PUBLICAR | V38: Pescado: solo si es de atún o de bonito. Cambia la referencia si la tuya es de carne.
A39: Croissant de jamón y queso | B39: Salado | C39: ● | E39: ● | H39: ○ | I39: ● | L39: ○ | Q39: =COUNTIF(C39:P39,"●") -> 3 | U39: =IF($S39="","NO PUBLICAR","Verificado") -> NO PUBLICAR | V39: Huevo: sale de la misma masa laminada pincelada que el croissant de mantequilla.
A40: Pan de molde | B40: Pan | C40: ● | H40: ○ | I40: ○ | M40: ○ | Q40: =COUNTIF(C40:P40,"●") -> 1 | U40: =IF($S40="","NO PUBLICAR","Verificado") -> NO PUBLICAR
...

Sheet Carta de Alérgenos
A1: Carta de Alérgenos
A2: Establecimiento: ______________________________ Fecha de revisión: ____/____/________
A3: Documento para enseñar al cliente. Se rellena solo desde la hoja Matriz Alérgenos: verifica allí cada referencia antes de imprimir esta carta. ● contiene ○ puede contener trazas
A5: Producto | B5: Gluten | C5: Crustáceos | D5: Huevos | E5: Pescado | F5: Cacahuetes | G5: Soja | H5: Lácteos | I5: Frutos de cáscara | J5: Apio | K5: Mostaza | L5: Sésamo | M5: Sulfitos | N5: Altramuces | O5: Moluscos
A6: =IF('Matriz Alérgenos'!A5="","",'Matriz Alérgenos'!A5) -> Croissant de mantequilla | B6: =IF('Matriz Alérgenos'!C5="","",'Matriz Alérgenos'!C5) -> ● | C6: =IF('Matriz Alérgenos'!D5="","",'Matriz Alérgenos'!D5) | D6: =IF('Matriz Alérgenos'!E5="","",'Matriz Alérgenos'!E5) -> ● | E6: =IF('Matriz Alérgenos'!F5="","",'Matriz Alérgenos'!F5) | F6: =IF('Matriz Alérgenos'!G5="","",'Matriz Alérgenos'!G5) | G6: =IF('Matriz Alérgenos'!H5="","",'Matriz Alérgenos'!H5) -> ○ | H6: =IF('Matriz Alérgenos'!I5="","",'Matriz Alérgenos'!I5) -> ● | I6: =IF('Matriz Alérgenos'!J5="","",'Matriz Alérgenos'!J5) -> ○ | ... O6: =IF('Matriz Alérgenos'!P5="","",'Matriz Alérgenos'!P5)
A7: =IF('Matriz Alérgenos'!A6="","",'Matriz Alérgenos'!A6) -> Pain au chocolat | B7: =IF('Matriz Alérgenos'!C6="","",'Matriz Alérgenos'!C6) -> ● | C7: =IF('Matriz Alérgenos'!D6="","",'Matriz Alérgenos'!D6) | D7: =IF('Matriz Alérgenos'!E6="","",'Matriz Alérgenos'!E6) -> ● | E7: =IF('Matriz Alérgenos'!F6="","",'Matriz Alérgenos'!F6) | F7: =IF('Matriz Alérgenos'!G6="","",'Matriz Alérgenos'!G6) | G7: =IF('Matriz Alérgenos'!H6="","",'Matriz Alérgenos'!H6) -> ● | H7: =IF('Matriz Alérgenos'!I6="","",'Matriz Alérgenos'!I6) -> ● | I7: =IF('Matriz Alérgenos'!J6="","",'Matriz Alérgenos'!J6) -> ○ | ... O7: =IF('Matriz Alérgenos'!P6="","",'Matriz Alérgenos'!P6)
A8: =IF('Matriz Alérgenos'!A7="","",'Matriz Alérgenos'!A7) -> Napolitana de crema | B8: =IF('Matriz Alérgenos'!C7="","",'Matriz Alérgenos'!C7) -> ● | C8: =IF('Matriz Alérgenos'!D7="","",'Matriz Alérgenos'!D7) | D8: =IF('Matriz Alérgenos'!E7="","",'Matriz Alérgenos'!E7) -> ● | E8: =IF('Matriz Alérgenos'!F7="","",'Matriz Alérgenos'!F7) | F8: =IF('Matriz Alérgenos'!G7="","",'Matriz Alérgenos'!G7) | G8: =IF('Matriz Alérgenos'!H7="","",'Matriz Alérgenos'!H7) -> ○ | H8: =IF('Matriz Alérgenos'!I7="","",'Matriz Alérgenos'!I7) -> ● | I8: =IF('Matriz Alérgenos'!J7="","",'Matriz Alérgenos'!J7) -> ○ | ... O8: =IF('Matriz Alérgenos'!P7="","",'Matriz Alérgenos'!P7)
A9: =IF('Matriz Alérgenos'!A8="","",'Matriz Alérgenos'!A8) -> Ensaimada | B9: =IF('Matriz Alérgenos'!C8="","",'Matriz Alérgenos'!C8) -> ● | C9: =IF('Matriz Alérgenos'!D8="","",'Matriz Alérgenos'!D8) | D9: =IF('Matriz Alérgenos'!E8="","",'Matriz Alérgenos'!E8) -> ● | E9: =IF('Matriz Alérgenos'!F8="","",'Matriz Alérgenos'!F8) | F9: =IF('Matriz Alérgenos'!G8="","",'Matriz Alérgenos'!G8) | G9: =IF('Matriz Alérgenos'!H8="","",'Matriz Alérgenos'!H8) -> ○ | H9: =IF('Matriz Alérgenos'!I8="","",'Matriz Alérgenos'!I8) -> ○ | I9: =IF('Matriz Alérgenos'!J8="","",'Matriz Alérgenos'!J8) -> ○ | ... O9: =IF('Matriz Alérgenos'!P8="","",'Matriz Alérgenos'!P8)
A10: =IF('Matriz Alérgenos'!A9="","",'Matriz Alérgenos'!A9) -> Brioche | B10: =IF('Matriz Alérgenos'!C9="","",'Matriz Alérgenos'!C9) -> ● | C10: =IF('Matriz Alérgenos'!D9="","",'Matriz Alérgenos'!D9) | D10: =IF('Matriz Alérgenos'!E9="","",'Matriz Alérgenos'!E9) -> ● | E10: =IF('Matriz Alérgenos'!F9="","",'Matriz Alérgenos'!F9) | F10: =IF('Matriz Alérgenos'!G9="","",'Matriz Alérgenos'!G9) | G10: =IF('Matriz Alérgenos'!H9="","",'Matriz Alérgenos'!H9) -> ○ | H10: =IF('Matriz Alérgenos'!I9="","",'Matriz Alérgenos'!I9) -> ● | I10: =IF('Matriz Alérgenos'!J9="","",'Matriz Alérgenos'!J9) -> ○ | ... O10: =IF('Matriz Alérgenos'!P9="","",'Matriz Alérgenos'!P9)
A11: =IF('Matriz Alérgenos'!A10="","",'Matriz Alérgenos'!A10) -> Caracola de pasas | B11: =IF('Matriz Alérgenos'!C10="","",'Matriz Alérgenos'!C10) -> ● | C11: =IF('Matriz Alérgenos'!D10="","",'Matriz Alérgenos'!D10) | D11: =IF('Matriz Alérgenos'!E10="","",'Matriz Alérgenos'!E10) -> ● | E11: =IF('Matriz Alérgenos'!F10="","",'Matriz Alérgenos'!F10) | F11: =IF('Matriz Alérgenos'!G10="","",'Matriz Alérgenos'!G10) | G11: =IF('Matriz Alérgenos'!H10="","",'Matriz Alérgenos'!H10) -> ○ | H11: =IF('Matriz Alérgenos'!I10="","",'Matriz Alérgenos'!I10) -> ● | I11: =IF('Matriz Alérgenos'!J10="","",'Matriz Alérgenos'!J10) -> ○ | ... O11: =IF('Matriz Alérgenos'!P10="","",'Matriz Alérgenos'!P10)
A12: =IF('Matriz Alérgenos'!A11="","",'Matriz Alérgenos'!A11) -> Palmera de hojaldre | B12: =IF('Matriz Alérgenos'!C11="","",'Matriz Alérgenos'!C11) -> ● | C12: =IF('Matriz Alérgenos'!D11="","",'Matriz Alérgenos'!D11) | D12: =IF('Matriz Alérgenos'!E11="","",'Matriz Alérgenos'!E11) -> ○ | E12: =IF('Matriz Alérgenos'!F11="","",'Matriz Alérgenos'!F11) | F12: =IF('Matriz Alérgenos'!G11="","",'Matriz Alérgenos'!G11) | G12: =IF('Matriz Alérgenos'!H11="","",'Matriz Alérgenos'!H11) -> ○ | H12: =IF('Matriz Alérgenos'!I11="","",'Matriz Alérgenos'!I11) -> ● | I12: =IF('Matriz Alérgenos'!J11="","",'Matriz Alérgenos'!J11) -> ○ | ... O12: =IF('Matriz Alérgenos'!P11="","",'Matriz Alérgenos'!P11)
A13: =IF('Matriz Alérgenos'!A12="","",'Matriz Alérgenos'!A12) -> Croissant relleno de crema | B13: =IF('Matriz Alérgenos'!C12="","",'Matriz Alérgenos'!C12) -> ● | C13: =IF('Matriz Alérgenos'!D12="","",'Matriz Alérgenos'!D12) | D13: =IF('Matriz Alérgenos'!E12="","",'Matriz Alérgenos'!E12) -> ● | E13: =IF('Matriz Alérgenos'!F12="","",'Matriz Alérgenos'!F12) | F13: =IF('Matriz Alérgenos'!G12="","",'Matriz Alérgenos'!G12) | G13: =IF('Matriz Alérgenos'!H12="","",'Matriz Alérgenos'!H12) -> ○ | H13: =IF('Matriz Alérgenos'!I12="","",'Matriz Alérgenos'!I12) -> ● | I13: =IF('Matriz Alérgenos'!J12="","",'Matriz Alérgenos'!J12) -> ○ | ... O13: =IF('Matriz Alérgenos'!P12="","",'Matriz Alérgenos'!P12)
A14: =IF('Matriz Alérgenos'!A13="","",'Matriz Alérgenos'!A13) -> Tarta de queso | B14: =IF('Matriz Alérgenos'!C13="","",'Matriz Alérgenos'!C13) -> ● | C14: =IF('Matriz Alérgenos'!D13="","",'Matriz Alérgenos'!D13) | D14: =IF('Matriz Alérgenos'!E13="","",'Matriz Alérgenos'!E13) -> ● | E14: =IF('Matriz Alérgenos'!F13="","",'Matriz Alérgenos'!F13) | F14: =IF('Matriz Alérgenos'!G13="","",'Matriz Alérgenos'!G13) | G14: =IF('Matriz Alérgenos'!H13="","",'Matriz Alérgenos'!H13) -> ○ | H14: =IF('Matriz Alérgenos'!I13="","",'Matriz Alérgenos'!I13) -> ● | I14: =IF('Matriz Alérgenos'!J13="","",'Matriz Alérgenos'!J13) -> ○ | ... O14: =IF('Matriz Alérgenos'!P13="","",'Matriz Alérgenos'!P13)
A15: =IF('Matriz Alérgenos'!A14="","",'Matriz Alérgenos'!A14) -> Tarta de manzana | B15: =IF('Matriz Alérgenos'!C14="","",'Matriz Alérgenos'!C14) -> ● | C15: =IF('Matriz Alérgenos'!D14="","",'Matriz Alérgenos'!D14) | D15: =IF('Matriz Alérgenos'!E14="","",'Matriz Alérgenos'!E14) -> ● | E15: =IF('Matriz Alérgenos'!F14="","",'Matriz Alérgenos'!F14) | F15: =IF('Matriz Alérgenos'!G14="","",'Matriz Alérgenos'!G14) | G15: =IF('Matriz Alérgenos'!H14="","",'Matriz Alérgenos'!H14) | H15: =IF('Matriz Alérgenos'!I14="","",'Matriz Alérgenos'!I14) -> ● | I15: =IF('Matriz Alérgenos'!J14="","",'Matriz Alérgenos'!J14) -> ○ | ... O15: =IF('Matriz Alérgenos'!P14="","",'Matriz Alérgenos'!P14)
A16: =IF('Matriz Alérgenos'!A15="","",'Matriz Alérgenos'!A15) -> Milhojas | B16: =IF('Matriz Alérgenos'!C15="","",'Matriz Alérgenos'!C15) -> ● | C16: =IF('Matriz Alérgenos'!D15="","",'Matriz Alérgenos'!D15) | D16: =IF('Matriz Alérgenos'!E15="","",'Matriz Alérgenos'!E15) -> ● | E16: =IF('Matriz Alérgenos'!F15="","",'Matriz Alérgenos'!F15) | F16: =IF('Matriz Alérgenos'!G15="","",'Matriz Alérgenos'!G15) | G16: =IF('Matriz Alérgenos'!H15="","",'Matriz Alérgenos'!H15) -> ○ | H16: =IF('Matriz Alérgenos'!I15="","",'Matriz Alérgenos'!I15) -> ● | I16: =IF('Matriz Alérgenos'!J15="","",'Matriz Alérgenos'!J15) -> ○ | ... O16: =IF('Matriz Alérgenos'!P15="","",'Matriz Alérgenos'!P15)
A17: =IF('Matriz Alérgenos'!A16="","",'Matriz Alérgenos'!A16) -> Éclair | B17: =IF('Matriz Alérgenos'!C16="","",'Matriz Alérgenos'!C16) -> ● | C17: =IF('Matriz Alérgenos'!D16="","",'Matriz Alérgenos'!D16) | D17: =IF('Matriz Alérgenos'!E16="","",'Matriz Alérgenos'!E16) -> ● | E17: =IF('Matriz Alérgenos'!F16="","",'Matriz Alérgenos'!F16) | F17: =IF('Matriz Alérgenos'!G16="","",'Matriz Alérgenos'!G16) | G17: =IF('Matriz Alérgenos'!H16="","",'Matriz Alérgenos'!H16) -> ○ | H17: =IF('Matriz Alérgenos'!I16="","",'Matriz Alérgenos'!I16) -> ● | I17: =IF('Matriz Alérgenos'!J16="","",'Matriz Alérgenos'!J16) -> ○ | ... O17: =IF('Matriz Alérgenos'!P16="","",'Matriz Alérgenos'!P16)
... A52: =IF('Matriz Alérgenos'!A51="","",'Matriz Alérgenos'!A51) | B52: =IF('Matriz Alérgenos'!C51="","",'Matriz Alérgenos'!C51) | C52: =IF('Matriz Alérgenos'!D51="","",'Matriz Alérgenos'!D51) | D52: =IF('Matriz Alérgenos'!E51="","",'Matriz Alérgenos'!E51) | E52: =IF('Matriz Alérgenos'!F51="","",'Matriz Alérgenos'!F51) | F52: =IF('Matriz Alérgenos'!G51="","",'Matriz Alérgenos'!G51) | G52: =IF('Matriz Alérgenos'!H51="","",'Matriz Alérgenos'!H51) | H52: =IF('Matriz Alérgenos'!I51="","",'Matriz Alérgenos'!I51) | I52: =IF('Matriz Alérgenos'!J51="","",'Matriz Alérgenos'!J51) | ... O52: =IF('Matriz Alérgenos'!P51="","",'Matriz Alérgenos'!P51)
A54: En nuestro obrador se manipulan, entre otros, cereales con gluten, huevo, leche, frutos de cáscara, soja y sésamo, por lo que puede haber contaminación cruzada. Esta advertencia complementa la información por escrito: no la sustituye.
A57: Revisado por: _________________________ Firma: _________________________
A59: — Kit de Tareas Recurrentes · Pastelería / Obrador · AI Chef Pro · aichef.pro

Sheet Cartel Vitrina
B2: Información sobre Alérgenos
B4: INFORMACIÓN DE ALÉRGENOS DISPONIBLE POR ESCRITO — SOLICÍTELA A NUESTRO PERSONAL
B7: En nuestro obrador se manipulan, entre otros, cereales con gluten, huevo, leche, frutos de cáscara, soja y sésamo, por lo que puede haber contaminación cruzada. Esta advertencia complementa la información por escrito: no la sustituye.
B10: Los 14 alérgenos de declaración obligatoria
B11: Alérgeno | C11: Qué incluye | D11: Nuestros productos que lo contienen
B12: Gluten | C12: Cereales con gluten: trigo, centeno, cebada, avena, espelta, kamut y sus derivados
B13: Crustáceos | C13: Crustáceos y productos a base de crustáceos
B14: Huevos | C14: Huevos y productos a base de huevo
B15: Pescado | C15: Pescado y productos a base de pescado
B16: Cacahuetes | C16: Cacahuetes y productos a base de cacahuete
B17: Soja | C17: Soja y productos a base de soja, incluida la lecitina de soja
B18: Lácteos | C18: Leche y sus derivados, incluida la lactosa
B19: Frutos de cáscara | C19: Almendra, avellana, nuez, anacardo, pistacho, pacana, nuez de Brasil y macadamia
B20: Apio | C20: Apio y productos derivados
B21: Mostaza | C21: Mostaza y productos derivados
B22: Sésamo | C22: Granos de sésamo y productos a base de sésamo
B23: Sulfitos | C23: Dióxido de azufre y sulfitos en concentración superior a 10 mg/kg o 10 mg/l
... B25: Moluscos | C25: Moluscos y productos a base de moluscos
B27: Establecimiento: ______________________________ Última revisión: ____/____/________
B28: Reglamento (UE) 1169/2011 y Real Decreto 126/2015, sobre la información alimentaria de los alimentos que se presentan sin envasar.
B30: — Kit de Tareas Recurrentes · Pastelería / Obrador · AI Chef Pro · aichef.pro

Sheet Etiquetas Vitrina
B1: Etiquetas de Vitrina
B2: Rellena, imprime en cartulina y recorta por el borde. Abrevia los alérgenos: GLU gluten · HUE huevos · LAC lácteos · FCA frutos de cáscara · SOJ soja · SES sésamo · SUL sulfitos.
B29: Cada etiqueta: primera línea el producto, segunda el precio por unidad, tercera los alérgenos (→ hoja Carta de Alérgenos).
B31: — Kit de Tareas Recurrentes · Pastelería / Obrador · AI Chef Pro · aichef.pro
