Workbook

Sheet Instrucciones
B2: 05 · P&L Mensual — Real vs Presupuesto
B4: AI Chef Pro · aichef.pro — Kit Plan Financiero para Restaurantes
B6: Cómo usar esta plantilla:
B7: ▸ Cada mes tiene su pestaña con columnas: Presupuesto, Real, Desviación €, Desviación %.
B8: ▸ El semáforo va CON SIGNO: en ingresos y EBITDA avisa cuando te quedas corto; en gastos, cuando te pasas. Los umbrales son editables en «Resumen Anual» (B22:B25).
B9: ▸ Food Cost % se mide sobre las ventas de comida (total menos barra) y Beverage Cost % sobre las de barra.
B10: ▸ La pestaña Resumen consolida los 12 meses.
B11: ▸ El estado «—» significa que ese mes todavía no tiene presupuesto: el semáforo no opina hasta que lo pongas.
B13: Todas las cifras van SIN IVA; en el 03 (tesorería) van CON IVA porque es caja.
B14: Para editar una celda que no esté en verde: Revisar → Desproteger hoja (no tiene contraseña).
B15: Diseñado por John Guerrero — chef y consultor gastronómico desde 2010, en cocina desde los 17 años · johnguerrero.es
B16: Versión 2.0 · agosto 2026 · aichef.pro/kit-plan-financiero · info@aichef.pro

Sheet Ene
A1: P&L Ene — Real vs Presupuesto
A2: AI Chef Pro · aichef.pro — Kit Plan Financiero para Restaurantes
A4: Concepto | B4: Presupuesto (€) | C4: Real (€) | D4: Desviación (€) | E4: Desviación % | F4: Semáforo
A5: INGRESOS
A6: Ventas Comedor (sin IVA) | B6: 0 | C6: 0 | D6: =C6-B6 -> 0 | E6: =IF($B6=0,"",IFERROR(($C6-$B6)/$B6,"")) | F6: =IFERROR(IF(ISNUMBER($E6),IF($E6>=-'Resumen Anual'!$B$22,"✅ OK",IF($E6>=-'Resumen Anual'!$B$23,"⚠️ Atención","🔴 Alerta")),"—"),"—") -> —
A7: Ventas Barra (sin IVA) | B7: 0 | C7: 0 | D7: =C7-B7 -> 0 | E7: =IF($B7=0,"",IFERROR(($C7-$B7)/$B7,"")) | F7: =IFERROR(IF(ISNUMBER($E7),IF($E7>=-'Resumen Anual'!$B$22,"✅ OK",IF($E7>=-'Resumen Anual'!$B$23,"⚠️ Atención","🔴 Alerta")),"—"),"—") -> —
A8: Ventas Delivery (sin IVA) | B8: 0 | C8: 0 | D8: =C8-B8 -> 0 | E8: =IF($B8=0,"",IFERROR(($C8-$B8)/$B8,"")) | F8: =IFERROR(IF(ISNUMBER($E8),IF($E8>=-'Resumen Anual'!$B$22,"✅ OK",IF($E8>=-'Resumen Anual'!$B$23,"⚠️ Atención","🔴 Alerta")),"—"),"—") -> —
A9: Eventos / Catering (sin IVA) | B9: 0 | C9: 0 | D9: =C9-B9 -> 0 | E9: =IF($B9=0,"",IFERROR(($C9-$B9)/$B9,"")) | F9: =IFERROR(IF(ISNUMBER($E9),IF($E9>=-'Resumen Anual'!$B$22,"✅ OK",IF($E9>=-'Resumen Anual'!$B$23,"⚠️ Atención","🔴 Alerta")),"—"),"—") -> —
A10: TOTAL INGRESOS (sin IVA) | B10: =B6+B7+B8+B9 -> 0 | C10: =C6+C7+C8+C9 -> 0 | D10: =C10-B10 -> 0 | E10: =IF($B10=0,"",IFERROR(($C10-$B10)/$B10,"")) | F10: =IFERROR(IF(ISNUMBER($E10),IF($E10>=-'Resumen Anual'!$B$22,"✅ OK",IF($E10>=-'Resumen Anual'!$B$23,"⚠️ Atención","🔴 Alerta")),"—"),"—") -> —
A12: GASTOS
A13: Coste de comida (materia prima) | B13: 0 | C13: 0 | D13: =C13-B13 -> 0 | E13: =IF($B13=0,"",IFERROR(($C13-$B13)/$B13,"")) | F13: =IFERROR(IF(ISNUMBER($E13),IF($E13<='Resumen Anual'!$B$22,"✅ OK",IF($E13<='Resumen Anual'!$B$23,"⚠️ Atención","🔴 Alerta")),"—"),"—") -> —
A14: Coste de bebida (barra) | B14: 0 | C14: 0 | D14: =C14-B14 -> 0 | E14: =IF($B14=0,"",IFERROR(($C14-$B14)/$B14,"")) | F14: =IFERROR(IF(ISNUMBER($E14),IF($E14<='Resumen Anual'!$B$22,"✅ OK",IF($E14<='Resumen Anual'!$B$23,"⚠️ Atención","🔴 Alerta")),"—"),"—") -> —
A15: Personal (Labor) | B15: 0 | C15: 0 | D15: =C15-B15 -> 0 | E15: =IF($B15=0,"",IFERROR(($C15-$B15)/$B15,"")) | F15: =IFERROR(IF(ISNUMBER($E15),IF($E15<='Resumen Anual'!$B$22,"✅ OK",IF($E15<='Resumen Anual'!$B$23,"⚠️ Atención","🔴 Alerta")),"—"),"—") -> —
A16: Comisiones de plataformas (delivery) | B16: 0 | C16: 0 | D16: =C16-B16 -> 0 | E16: =IF($B16=0,"",IFERROR(($C16-$B16)/$B16,"")) | F16: =IFERROR(IF(ISNUMBER($E16),IF($E16<='Resumen Anual'!$B$22,"✅ OK",IF($E16<='Resumen Anual'!$B$23,"⚠️ Atención","🔴 Alerta")),"—"),"—") -> —
A17: Alquiler | B17: 0 | C17: 0 | D17: =C17-B17 -> 0 | E17: =IF($B17=0,"",IFERROR(($C17-$B17)/$B17,"")) | F17: =IFERROR(IF(ISNUMBER($E17),IF($E17<='Resumen Anual'!$B$22,"✅ OK",IF($E17<='Resumen Anual'!$B$23,"⚠️ Atención","🔴 Alerta")),"—"),"—") -> —
A18: Suministros | B18: 0 | C18: 0 | D18: =C18-B18 -> 0 | E18: =IF($B18=0,"",IFERROR(($C18-$B18)/$B18,"")) | F18: =IFERROR(IF(ISNUMBER($E18),IF($E18<='Resumen Anual'!$B$22,"✅ OK",IF($E18<='Resumen Anual'!$B$23,"⚠️ Atención","🔴 Alerta")),"—"),"—") -> —
A19: Marketing | B19: 0 | C19: 0 | D19: =C19-B19 -> 0 | E19: =IF($B19=0,"",IFERROR(($C19-$B19)/$B19,"")) | F19: =IFERROR(IF(ISNUMBER($E19),IF($E19<='Resumen Anual'!$B$22,"✅ OK",IF($E19<='Resumen Anual'!$B$23,"⚠️ Atención","🔴 Alerta")),"—"),"—") -> —
A20: Administración / Otros | B20: 0 | C20: 0 | D20: =C20-B20 -> 0 | E20: =IF($B20=0,"",IFERROR(($C20-$B20)/$B20,"")) | F20: =IFERROR(IF(ISNUMBER($E20),IF($E20<='Resumen Anual'!$B$22,"✅ OK",IF($E20<='Resumen Anual'!$B$23,"⚠️ Atención","🔴 Alerta")),"—"),"—") -> —
A21: TOTAL GASTOS | B21: =SUM(B13:B20) -> 0 | C21: =SUM(C13:C20) -> 0 | D21: =C21-B21 -> 0 | E21: =IF($B21=0,"",IFERROR(($C21-$B21)/$B21,"")) | F21: =IFERROR(IF(ISNUMBER($E21),IF($E21<='Resumen Anual'!$B$22,"✅ OK",IF($E21<='Resumen Anual'!$B$23,"⚠️ Atención","🔴 Alerta")),"—"),"—") -> —
A23: EBITDA | B23: =B10-B21 -> 0 | C23: =C10-C21 -> 0 | D23: =C23-B23 -> 0 | E23: =IF($B23=0,"",IFERROR(($C23-$B23)/ABS($B23),"")) | F23: =IFERROR(IF(ISNUMBER($E23),IF($E23>=-'Resumen Anual'!$B$22,"✅ OK",IF($E23>=-'Resumen Anual'!$B$23,"⚠️ Atención","🔴 Alerta")),"—"),"—") -> —
A24: Margen EBITDA % | B24: =IF(B10=0,"",B23/B10) | C24: =IF(C10=0,"",C23/C10) | D24: =IFERROR($C24-$B24,"") | E24: p.p. | F24: =IFERROR(IF(ISNUMBER($D24),IF($D24>=-'Resumen Anual'!$B$24,"✅ OK",IF($D24>=-'Resumen Anual'!$B$25,"⚠️ Atención","🔴 Alerta")),"—"),"—") -> —
A26: RATIOS AUTOMÁTICOS
A27: Food Cost % (sobre ventas de comida) | B27: =IF((B10-B7)<=0,"",B13/(B10-B7)) | C27: =IF((C10-C7)<=0,"",C13/(C10-C7)) | D27: =IFERROR($C27-$B27,"") | E27: p.p. | F27: =IFERROR(IF(ISNUMBER($D27),IF($D27<='Resumen Anual'!$B$24,"✅ OK",IF($D27<='Resumen Anual'!$B$25,"⚠️ Atención","🔴 Alerta")),"—"),"—") -> —
A28: Beverage Cost % (sobre ventas de barra) | B28: =IF(B7=0,"",B14/B7) | C28: =IF(C7=0,"",C14/C7) | D28: =IFERROR($C28-$B28,"") | E28: p.p. | F28: =IFERROR(IF(ISNUMBER($D28),IF($D28<='Resumen Anual'!$B$24,"✅ OK",IF($D28<='Resumen Anual'!$B$25,"⚠️ Atención","🔴 Alerta")),"—"),"—") -> —
A29: Labor Cost % | B29: =IF(B10=0,"",B15/B10) | C29: =IF(C10=0,"",C15/C10) | D29: =IFERROR($C29-$B29,"") | E29: p.p. | F29: =IFERROR(IF(ISNUMBER($D29),IF($D29<='Resumen Anual'!$B$24,"✅ OK",IF($D29<='Resumen Anual'!$B$25,"⚠️ Atención","🔴 Alerta")),"—"),"—") -> —
A30: Prime Cost % (comida + bebida + personal) | B30: =IF(B10=0,"",(B13+B14+B15)/B10) | C30: =IF(C10=0,"",(C13+C14+C15)/C10) | D30: =IFERROR($C30-$B30,"") | E30: p.p. | F30: =IFERROR(IF(ISNUMBER($D30),IF($D30<='Resumen Anual'!$B$24,"✅ OK",IF($D30<='Resumen Anual'!$B$25,"⚠️ Atención","🔴 Alerta")),"—"),"—") -> —
A32: © 2026 AI Chef Pro · aichef.pro

Sheet Feb
A1: P&L Feb — Real vs Presupuesto
A2: AI Chef Pro · aichef.pro — Kit Plan Financiero para Restaurantes
A4: Concepto | B4: Presupuesto (€) | C4: Real (€) | D4: Desviación (€) | E4: Desviación % | F4: Semáforo
A5: INGRESOS
A6: Ventas Comedor (sin IVA) | B6: 0 | C6: 0 | D6: =C6-B6 -> 0 | E6: =IF($B6=0,"",IFERROR(($C6-$B6)/$B6,"")) | F6: =IFERROR(IF(ISNUMBER($E6),IF($E6>=-'Resumen Anual'!$B$22,"✅ OK",IF($E6>=-'Resumen Anual'!$B$23,"⚠️ Atención","🔴 Alerta")),"—"),"—") -> —
A7: Ventas Barra (sin IVA) | B7: 0 | C7: 0 | D7: =C7-B7 -> 0 | E7: =IF($B7=0,"",IFERROR(($C7-$B7)/$B7,"")) | F7: =IFERROR(IF(ISNUMBER($E7),IF($E7>=-'Resumen Anual'!$B$22,"✅ OK",IF($E7>=-'Resumen Anual'!$B$23,"⚠️ Atención","🔴 Alerta")),"—"),"—") -> —
A8: Ventas Delivery (sin IVA) | B8: 0 | C8: 0 | D8: =C8-B8 -> 0 | E8: =IF($B8=0,"",IFERROR(($C8-$B8)/$B8,"")) | F8: =IFERROR(IF(ISNUMBER($E8),IF($E8>=-'Resumen Anual'!$B$22,"✅ OK",IF($E8>=-'Resumen Anual'!$B$23,"⚠️ Atención","🔴 Alerta")),"—"),"—") -> —
A9: Eventos / Catering (sin IVA) | B9: 0 | C9: 0 | D9: =C9-B9 -> 0 | E9: =IF($B9=0,"",IFERROR(($C9-$B9)/$B9,"")) | F9: =IFERROR(IF(ISNUMBER($E9),IF($E9>=-'Resumen Anual'!$B$22,"✅ OK",IF($E9>=-'Resumen Anual'!$B$23,"⚠️ Atención","🔴 Alerta")),"—"),"—") -> —
A10: TOTAL INGRESOS (sin IVA) | B10: =B6+B7+B8+B9 -> 0 | C10: =C6+C7+C8+C9 -> 0 | D10: =C10-B10 -> 0 | E10: =IF($B10=0,"",IFERROR(($C10-$B10)/$B10,"")) | F10: =IFERROR(IF(ISNUMBER($E10),IF($E10>=-'Resumen Anual'!$B$22,"✅ OK",IF($E10>=-'Resumen Anual'!$B$23,"⚠️ Atención","🔴 Alerta")),"—"),"—") -> —
A12: GASTOS
A13: Coste de comida (materia prima) | B13: 0 | C13: 0 | D13: =C13-B13 -> 0 | E13: =IF($B13=0,"",IFERROR(($C13-$B13)/$B13,"")) | F13: =IFERROR(IF(ISNUMBER($E13),IF($E13<='Resumen Anual'!$B$22,"✅ OK",IF($E13<='Resumen Anual'!$B$23,"⚠️ Atención","🔴 Alerta")),"—"),"—") -> —
A14: Coste de bebida (barra) | B14: 0 | C14: 0 | D14: =C14-B14 -> 0 | E14: =IF($B14=0,"",IFERROR(($C14-$B14)/$B14,"")) | F14: =IFERROR(IF(ISNUMBER($E14),IF($E14<='Resumen Anual'!$B$22,"✅ OK",IF($E14<='Resumen Anual'!$B$23,"⚠️ Atención","🔴 Alerta")),"—"),"—") -> —
A15: Personal (Labor) | B15: 0 | C15: 0 | D15: =C15-B15 -> 0 | E15: =IF($B15=0,"",IFERROR(($C15-$B15)/$B15,"")) | F15: =IFERROR(IF(ISNUMBER($E15),IF($E15<='Resumen Anual'!$B$22,"✅ OK",IF($E15<='Resumen Anual'!$B$23,"⚠️ Atención","🔴 Alerta")),"—"),"—") -> —
A16: Comisiones de plataformas (delivery) | B16: 0 | C16: 0 | D16: =C16-B16 -> 0 | E16: =IF($B16=0,"",IFERROR(($C16-$B16)/$B16,"")) | F16: =IFERROR(IF(ISNUMBER($E16),IF($E16<='Resumen Anual'!$B$22,"✅ OK",IF($E16<='Resumen Anual'!$B$23,"⚠️ Atención","🔴 Alerta")),"—"),"—") -> —
A17: Alquiler | B17: 0 | C17: 0 | D17: =C17-B17 -> 0 | E17: =IF($B17=0,"",IFERROR(($C17-$B17)/$B17,"")) | F17: =IFERROR(IF(ISNUMBER($E17),IF($E17<='Resumen Anual'!$B$22,"✅ OK",IF($E17<='Resumen Anual'!$B$23,"⚠️ Atención","🔴 Alerta")),"—"),"—") -> —
A18: Suministros | B18: 0 | C18: 0 | D18: =C18-B18 -> 0 | E18: =IF($B18=0,"",IFERROR(($C18-$B18)/$B18,"")) | F18: =IFERROR(IF(ISNUMBER($E18),IF($E18<='Resumen Anual'!$B$22,"✅ OK",IF($E18<='Resumen Anual'!$B$23,"⚠️ Atención","🔴 Alerta")),"—"),"—") -> —
A19: Marketing | B19: 0 | C19: 0 | D19: =C19-B19 -> 0 | E19: =IF($B19=0,"",IFERROR(($C19-$B19)/$B19,"")) | F19: =IFERROR(IF(ISNUMBER($E19),IF($E19<='Resumen Anual'!$B$22,"✅ OK",IF($E19<='Resumen Anual'!$B$23,"⚠️ Atención","🔴 Alerta")),"—"),"—") -> —
A20: Administración / Otros | B20: 0 | C20: 0 | D20: =C20-B20 -> 0 | E20: =IF($B20=0,"",IFERROR(($C20-$B20)/$B20,"")) | F20: =IFERROR(IF(ISNUMBER($E20),IF($E20<='Resumen Anual'!$B$22,"✅ OK",IF($E20<='Resumen Anual'!$B$23,"⚠️ Atención","🔴 Alerta")),"—"),"—") -> —
A21: TOTAL GASTOS | B21: =SUM(B13:B20) -> 0 | C21: =SUM(C13:C20) -> 0 | D21: =C21-B21 -> 0 | E21: =IF($B21=0,"",IFERROR(($C21-$B21)/$B21,"")) | F21: =IFERROR(IF(ISNUMBER($E21),IF($E21<='Resumen Anual'!$B$22,"✅ OK",IF($E21<='Resumen Anual'!$B$23,"⚠️ Atención","🔴 Alerta")),"—"),"—") -> —
A23: EBITDA | B23: =B10-B21 -> 0 | C23: =C10-C21 -> 0 | D23: =C23-B23 -> 0 | E23: =IF($B23=0,"",IFERROR(($C23-$B23)/ABS($B23),"")) | F23: =IFERROR(IF(ISNUMBER($E23),IF($E23>=-'Resumen Anual'!$B$22,"✅ OK",IF($E23>=-'Resumen Anual'!$B$23,"⚠️ Atención","🔴 Alerta")),"—"),"—") -> —
A24: Margen EBITDA % | B24: =IF(B10=0,"",B23/B10) | C24: =IF(C10=0,"",C23/C10) | D24: =IFERROR($C24-$B24,"") | E24: p.p. | F24: =IFERROR(IF(ISNUMBER($D24),IF($D24>=-'Resumen Anual'!$B$24,"✅ OK",IF($D24>=-'Resumen Anual'!$B$25,"⚠️ Atención","🔴 Alerta")),"—"),"—") -> —
A26: RATIOS AUTOMÁTICOS
A27: Food Cost % (sobre ventas de comida) | B27: =IF((B10-B7)<=0,"",B13/(B10-B7)) | C27: =IF((C10-C7)<=0,"",C13/(C10-C7)) | D27: =IFERROR($C27-$B27,"") | E27: p.p. | F27: =IFERROR(IF(ISNUMBER($D27),IF($D27<='Resumen Anual'!$B$24,"✅ OK",IF($D27<='Resumen Anual'!$B$25,"⚠️ Atención","🔴 Alerta")),"—"),"—") -> —
A28: Beverage Cost % (sobre ventas de barra) | B28: =IF(B7=0,"",B14/B7) | C28: =IF(C7=0,"",C14/C7) | D28: =IFERROR($C28-$B28,"") | E28: p.p. | F28: =IFERROR(IF(ISNUMBER($D28),IF($D28<='Resumen Anual'!$B$24,"✅ OK",IF($D28<='Resumen Anual'!$B$25,"⚠️ Atención","🔴 Alerta")),"—"),"—") -> —
A29: Labor Cost % | B29: =IF(B10=0,"",B15/B10) | C29: =IF(C10=0,"",C15/C10) | D29: =IFERROR($C29-$B29,"") | E29: p.p. | F29: =IFERROR(IF(ISNUMBER($D29),IF($D29<='Resumen Anual'!$B$24,"✅ OK",IF($D29<='Resumen Anual'!$B$25,"⚠️ Atención","🔴 Alerta")),"—"),"—") -> —
A30: Prime Cost % (comida + bebida + personal) | B30: =IF(B10=0,"",(B13+B14+B15)/B10) | C30: =IF(C10=0,"",(C13+C14+C15)/C10) | D30: =IFERROR($C30-$B30,"") | E30: p.p. | F30: =IFERROR(IF(ISNUMBER($D30),IF($D30<='Resumen Anual'!$B$24,"✅ OK",IF($D30<='Resumen Anual'!$B$25,"⚠️ Atención","🔴 Alerta")),"—"),"—") -> —
A32: © 2026 AI Chef Pro · aichef.pro

Sheet Mar
A1: P&L Mar — Real vs Presupuesto
A2: AI Chef Pro · aichef.pro — Kit Plan Financiero para Restaurantes
A4: Concepto | B4: Presupuesto (€) | C4: Real (€) | D4: Desviación (€) | E4: Desviación % | F4: Semáforo
A5: INGRESOS
A6: Ventas Comedor (sin IVA) | B6: 0 | C6: 0 | D6: =C6-B6 -> 0 | E6: =IF($B6=0,"",IFERROR(($C6-$B6)/$B6,"")) | F6: =IFERROR(IF(ISNUMBER($E6),IF($E6>=-'Resumen Anual'!$B$22,"✅ OK",IF($E6>=-'Resumen Anual'!$B$23,"⚠️ Atención","🔴 Alerta")),"—"),"—") -> —
A7: Ventas Barra (sin IVA) | B7: 0 | C7: 0 | D7: =C7-B7 -> 0 | E7: =IF($B7=0,"",IFERROR(($C7-$B7)/$B7,"")) | F7: =IFERROR(IF(ISNUMBER($E7),IF($E7>=-'Resumen Anual'!$B$22,"✅ OK",IF($E7>=-'Resumen Anual'!$B$23,"⚠️ Atención","🔴 Alerta")),"—"),"—") -> —
A8: Ventas Delivery (sin IVA) | B8: 0 | C8: 0 | D8: =C8-B8 -> 0 | E8: =IF($B8=0,"",IFERROR(($C8-$B8)/$B8,"")) | F8: =IFERROR(IF(ISNUMBER($E8),IF($E8>=-'Resumen Anual'!$B$22,"✅ OK",IF($E8>=-'Resumen Anual'!$B$23,"⚠️ Atención","🔴 Alerta")),"—"),"—") -> —
A9: Eventos / Catering (sin IVA) | B9: 0 | C9: 0 | D9: =C9-B9 -> 0 | E9: =IF($B9=0,"",IFERROR(($C9-$B9)/$B9,"")) | F9: =IFERROR(IF(ISNUMBER($E9),IF($E9>=-'Resumen Anual'!$B$22,"✅ OK",IF($E9>=-'Resumen Anual'!$B$23,"⚠️ Atención","🔴 Alerta")),"—"),"—") -> —
A10: TOTAL INGRESOS (sin IVA) | B10: =B6+B7+B8+B9 -> 0 | C10: =C6+C7+C8+C9 -> 0 | D10: =C10-B10 -> 0 | E10: =IF($B10=0,"",IFERROR(($C10-$B10)/$B10,"")) | F10: =IFERROR(IF(ISNUMBER($E10),IF($E10>=-'Resumen Anual'!$B$22,"✅ OK",IF($E10>=-'Resumen Anual'!$B$23,"⚠️ Atención","🔴 Alerta")),"—"),"—") -> —
A12: GASTOS
A13: Coste de comida (materia prima) | B13: 0 | C13: 0 | D13: =C13-B13 -> 0 | E13: =IF($B13=0,"",IFERROR(($C13-$B13)/$B13,"")) | F13: =IFERROR(IF(ISNUMBER($E13),IF($E13<='Resumen Anual'!$B$22,"✅ OK",IF($E13<='Resumen Anual'!$B$23,"⚠️ Atención","🔴 Alerta")),"—"),"—") -> —
A14: Coste de bebida (barra) | B14: 0 | C14: 0 | D14: =C14-B14 -> 0 | E14: =IF($B14=0,"",IFERROR(($C14-$B14)/$B14,"")) | F14: =IFERROR(IF(ISNUMBER($E14),IF($E14<='Resumen Anual'!$B$22,"✅ OK",IF($E14<='Resumen Anual'!$B$23,"⚠️ Atención","🔴 Alerta")),"—"),"—") -> —
A15: Personal (Labor) | B15: 0 | C15: 0 | D15: =C15-B15 -> 0 | E15: =IF($B15=0,"",IFERROR(($C15-$B15)/$B15,"")) | F15: =IFERROR(IF(ISNUMBER($E15),IF($E15<='Resumen Anual'!$B$22,"✅ OK",IF($E15<='Resumen Anual'!$B$23,"⚠️ Atención","🔴 Alerta")),"—"),"—") -> —
A16: Comisiones de plataformas (delivery) | B16: 0 | C16: 0 | D16: =C16-B16 -> 0 | E16: =IF($B16=0,"",IFERROR(($C16-$B16)/$B16,"")) | F16: =IFERROR(IF(ISNUMBER($E16),IF($E16<='Resumen Anual'!$B$22,"✅ OK",IF($E16<='Resumen Anual'!$B$23,"⚠️ Atención","🔴 Alerta")),"—"),"—") -> —
A17: Alquiler | B17: 0 | C17: 0 | D17: =C17-B17 -> 0 | E17: =IF($B17=0,"",IFERROR(($C17-$B17)/$B17,"")) | F17: =IFERROR(IF(ISNUMBER($E17),IF($E17<='Resumen Anual'!$B$22,"✅ OK",IF($E17<='Resumen Anual'!$B$23,"⚠️ Atención","🔴 Alerta")),"—"),"—") -> —
A18: Suministros | B18: 0 | C18: 0 | D18: =C18-B18 -> 0 | E18: =IF($B18=0,"",IFERROR(($C18-$B18)/$B18,"")) | F18: =IFERROR(IF(ISNUMBER($E18),IF($E18<='Resumen Anual'!$B$22,"✅ OK",IF($E18<='Resumen Anual'!$B$23,"⚠️ Atención","🔴 Alerta")),"—"),"—") -> —
A19: Marketing | B19: 0 | C19: 0 | D19: =C19-B19 -> 0 | E19: =IF($B19=0,"",IFERROR(($C19-$B19)/$B19,"")) | F19: =IFERROR(IF(ISNUMBER($E19),IF($E19<='Resumen Anual'!$B$22,"✅ OK",IF($E19<='Resumen Anual'!$B$23,"⚠️ Atención","🔴 Alerta")),"—"),"—") -> —
A20: Administración / Otros | B20: 0 | C20: 0 | D20: =C20-B20 -> 0 | E20: =IF($B20=0,"",IFERROR(($C20-$B20)/$B20,"")) | F20: =IFERROR(IF(ISNUMBER($E20),IF($E20<='Resumen Anual'!$B$22,"✅ OK",IF($E20<='Resumen Anual'!$B$23,"⚠️ Atención","🔴 Alerta")),"—"),"—") -> —
A21: TOTAL GASTOS | B21: =SUM(B13:B20) -> 0 | C21: =SUM(C13:C20) -> 0 | D21: =C21-B21 -> 0 | E21: =IF($B21=0,"",IFERROR(($C21-$B21)/$B21,"")) | F21: =IFERROR(IF(ISNUMBER($E21),IF($E21<='Resumen Anual'!$B$22,"✅ OK",IF($E21<='Resumen Anual'!$B$23,"⚠️ Atención","🔴 Alerta")),"—"),"—") -> —
A23: EBITDA | B23: =B10-B21 -> 0 | C23: =C10-C21 -> 0 | D23: =C23-B23 -> 0 | E23: =IF($B23=0,"",IFERROR(($C23-$B23)/ABS($B23),"")) | F23: =IFERROR(IF(ISNUMBER($E23),IF($E23>=-'Resumen Anual'!$B$22,"✅ OK",IF($E23>=-'Resumen Anual'!$B$23,"⚠️ Atención","🔴 Alerta")),"—"),"—") -> —
A24: Margen EBITDA % | B24: =IF(B10=0,"",B23/B10) | C24: =IF(C10=0,"",C23/C10) | D24: =IFERROR($C24-$B24,"") | E24: p.p. | F24: =IFERROR(IF(ISNUMBER($D24),IF($D24>=-'Resumen Anual'!$B$24,"✅ OK",IF($D24>=-'Resumen Anual'!$B$25,"⚠️ Atención","🔴 Alerta")),"—"),"—") -> —
A26: RATIOS AUTOMÁTICOS
A27: Food Cost % (sobre ventas de comida) | B27: =IF((B10-B7)<=0,"",B13/(B10-B7)) | C27: =IF((C10-C7)<=0,"",C13/(C10-C7)) | D27: =IFERROR($C27-$B27,"") | E27: p.p. | F27: =IFERROR(IF(ISNUMBER($D27),IF($D27<='Resumen Anual'!$B$24,"✅ OK",IF($D27<='Resumen Anual'!$B$25,"⚠️ Atención","🔴 Alerta")),"—"),"—") -> —
A28: Beverage Cost % (sobre ventas de barra) | B28: =IF(B7=0,"",B14/B7) | C28: =IF(C7=0,"",C14/C7) | D28: =IFERROR($C28-$B28,"") | E28: p.p. | F28: =IFERROR(IF(ISNUMBER($D28),IF($D28<='Resumen Anual'!$B$24,"✅ OK",IF($D28<='Resumen Anual'!$B$25,"⚠️ Atención","🔴 Alerta")),"—"),"—") -> —
A29: Labor Cost % | B29: =IF(B10=0,"",B15/B10) | C29: =IF(C10=0,"",C15/C10) | D29: =IFERROR($C29-$B29,"") | E29: p.p. | F29: =IFERROR(IF(ISNUMBER($D29),IF($D29<='Resumen Anual'!$B$24,"✅ OK",IF($D29<='Resumen Anual'!$B$25,"⚠️ Atención","🔴 Alerta")),"—"),"—") -> —
A30: Prime Cost % (comida + bebida + personal) | B30: =IF(B10=0,"",(B13+B14+B15)/B10) | C30: =IF(C10=0,"",(C13+C14+C15)/C10) | D30: =IFERROR($C30-$B30,"") | E30: p.p. | F30: =IFERROR(IF(ISNUMBER($D30),IF($D30<='Resumen Anual'!$B$24,"✅ OK",IF($D30<='Resumen Anual'!$B$25,"⚠️ Atención","🔴 Alerta")),"—"),"—") -> —
A32: © 2026 AI Chef Pro · aichef.pro

Sheet Abr
A1: P&L Abr — Real vs Presupuesto
A2: AI Chef Pro · aichef.pro — Kit Plan Financiero para Restaurantes
A4: Concepto | B4: Presupuesto (€) | C4: Real (€) | D4: Desviación (€) | E4: Desviación % | F4: Semáforo
A5: INGRESOS
A6: Ventas Comedor (sin IVA) | B6: 0 | C6: 0 | D6: =C6-B6 -> 0 | E6: =IF($B6=0,"",IFERROR(($C6-$B6)/$B6,"")) | F6: =IFERROR(IF(ISNUMBER($E6),IF($E6>=-'Resumen Anual'!$B$22,"✅ OK",IF($E6>=-'Resumen Anual'!$B$23,"⚠️ Atención","🔴 Alerta")),"—"),"—") -> —
A7: Ventas Barra (sin IVA) | B7: 0 | C7: 0 | D7: =C7-B7 -> 0 | E7: =IF($B7=0,"",IFERROR(($C7-$B7)/$B7,"")) | F7: =IFERROR(IF(ISNUMBER($E7),IF($E7>=-'Resumen Anual'!$B$22,"✅ OK",IF($E7>=-'Resumen Anual'!$B$23,"⚠️ Atención","🔴 Alerta")),"—"),"—") -> —
A8: Ventas Delivery (sin IVA) | B8: 0 | C8: 0 | D8: =C8-B8 -> 0 | E8: =IF($B8=0,"",IFERROR(($C8-$B8)/$B8,"")) | F8: =IFERROR(IF(ISNUMBER($E8),IF($E8>=-'Resumen Anual'!$B$22,"✅ OK",IF($E8>=-'Resumen Anual'!$B$23,"⚠️ Atención","🔴 Alerta")),"—"),"—") -> —
A9: Eventos / Catering (sin IVA) | B9: 0 | C9: 0 | D9: =C9-B9 -> 0 | E9: =IF($B9=0,"",IFERROR(($C9-$B9)/$B9,"")) | F9: =IFERROR(IF(ISNUMBER($E9),IF($E9>=-'Resumen Anual'!$B$22,"✅ OK",IF($E9>=-'Resumen Anual'!$B$23,"⚠️ Atención","🔴 Alerta")),"—"),"—") -> —
A10: TOTAL INGRESOS (sin IVA) | B10: =B6+B7+B8+B9 -> 0 | C10: =C6+C7+C8+C9 -> 0 | D10: =C10-B10 -> 0 | E10: =IF($B10=0,"",IFERROR(($C10-$B10)/$B10,"")) | F10: =IFERROR(IF(ISNUMBER($E10),IF($E10>=-'Resumen Anual'!$B$22,"✅ OK",IF($E10>=-'Resumen Anual'!$B$23,"⚠️ Atención","🔴 Alerta")),"—"),"—") -> —
A12: GASTOS
A13: Coste de comida (materia prima) | B13: 0 | C13: 0 | D13: =C13-B13 -> 0 | E13: =IF($B13=0,"",IFERROR(($C13-$B13)/$B13,"")) | F13: =IFERROR(IF(ISNUMBER($E13),IF($E13<='Resumen Anual'!$B$22,"✅ OK",IF($E13<='Resumen Anual'!$B$23,"⚠️ Atención","🔴 Alerta")),"—"),"—") -> —
A14: Coste de bebida (barra) | B14: 0 | C14: 0 | D14: =C14-B14 -> 0 | E14: =IF($B14=0,"",IFERROR(($C14-$B14)/$B14,"")) | F14: =IFERROR(IF(ISNUMBER($E14),IF($E14<='Resumen Anual'!$B$22,"✅ OK",IF($E14<='Resumen Anual'!$B$23,"⚠️ Atención","🔴 Alerta")),"—"),"—") -> —
A15: Personal (Labor) | B15: 0 | C15: 0 | D15: =C15-B15 -> 0 | E15: =IF($B15=0,"",IFERROR(($C15-$B15)/$B15,"")) | F15: =IFERROR(IF(ISNUMBER($E15),IF($E15<='Resumen Anual'!$B$22,"✅ OK",IF($E15<='Resumen Anual'!$B$23,"⚠️ Atención","🔴 Alerta")),"—"),"—") -> —
A16: Comisiones de plataformas (delivery) | B16: 0 | C16: 0 | D16: =C16-B16 -> 0 | E16: =IF($B16=0,"",IFERROR(($C16-$B16)/$B16,"")) | F16: =IFERROR(IF(ISNUMBER($E16),IF($E16<='Resumen Anual'!$B$22,"✅ OK",IF($E16<='Resumen Anual'!$B$23,"⚠️ Atención","🔴 Alerta")),"—"),"—") -> —
A17: Alquiler | B17: 0 | C17: 0 | D17: =C17-B17 -> 0 | E17: =IF($B17=0,"",IFERROR(($C17-$B17)/$B17,"")) | F17: =IFERROR(IF(ISNUMBER($E17),IF($E17<='Resumen Anual'!$B$22,"✅ OK",IF($E17<='Resumen Anual'!$B$23,"⚠️ Atención","🔴 Alerta")),"—"),"—") -> —
A18: Suministros | B18: 0 | C18: 0 | D18: =C18-B18 -> 0 | E18: =IF($B18=0,"",IFERROR(($C18-$B18)/$B18,"")) | F18: =IFERROR(IF(ISNUMBER($E18),IF($E18<='Resumen Anual'!$B$22,"✅ OK",IF($E18<='Resumen Anual'!$B$23,"⚠️ Atención","🔴 Alerta")),"—"),"—") -> —
A19: Marketing | B19: 0 | C19: 0 | D19: =C19-B19 -> 0 | E19: =IF($B19=0,"",IFERROR(($C19-$B19)/$B19,"")) | F19: =IFERROR(IF(ISNUMBER($E19),IF($E19<='Resumen Anual'!$B$22,"✅ OK",IF($E19<='Resumen Anual'!$B$23,"⚠️ Atención","🔴 Alerta")),"—"),"—") -> —
A20: Administración / Otros | B20: 0 | C20: 0 | D20: =C20-B20 -> 0 | E20: =IF($B20=0,"",IFERROR(($C20-$B20)/$B20,"")) | F20: =IFERROR(IF(ISNUMBER($E20),IF($E20<='Resumen Anual'!$B$22,"✅ OK",IF($E20<='Resumen Anual'!$B$23,"⚠️ Atención","🔴 Alerta")),"—"),"—") -> —
A21: TOTAL GASTOS | B21: =SUM(B13:B20) -> 0 | C21: =SUM(C13:C20) -> 0 | D21: =C21-B21 -> 0 | E21: =IF($B21=0,"",IFERROR(($C21-$B21)/$B21,"")) | F21: =IFERROR(IF(ISNUMBER($E21),IF($E21<='Resumen Anual'!$B$22,"✅ OK",IF($E21<='Resumen Anual'!$B$23,"⚠️ Atención","🔴 Alerta")),"—"),"—") -> —
A23: EBITDA | B23: =B10-B21 -> 0 | C23: =C10-C21 -> 0 | D23: =C23-B23 -> 0 | E23: =IF($B23=0,"",IFERROR(($C23-$B23)/ABS($B23),"")) | F23: =IFERROR(IF(ISNUMBER($E23),IF($E23>=-'Resumen Anual'!$B$22,"✅ OK",IF($E23>=-'Resumen Anual'!$B$23,"⚠️ Atención","🔴 Alerta")),"—"),"—") -> —
A24: Margen EBITDA % | B24: =IF(B10=0,"",B23/B10) | C24: =IF(C10=0,"",C23/C10) | D24: =IFERROR($C24-$B24,"") | E24: p.p. | F24: =IFERROR(IF(ISNUMBER($D24),IF($D24>=-'Resumen Anual'!$B$24,"✅ OK",IF($D24>=-'Resumen Anual'!$B$25,"⚠️ Atención","🔴 Alerta")),"—"),"—") -> —
A26: RATIOS AUTOMÁTICOS
A27: Food Cost % (sobre ventas de comida) | B27: =IF((B10-B7)<=0,"",B13/(B10-B7)) | C27: =IF((C10-C7)<=0,"",C13/(C10-C7)) | D27: =IFERROR($C27-$B27,"") | E27: p.p. | F27: =IFERROR(IF(ISNUMBER($D27),IF($D27<='Resumen Anual'!$B$24,"✅ OK",IF($D27<='Resumen Anual'!$B$25,"⚠️ Atención","🔴 Alerta")),"—"),"—") -> —
A28: Beverage Cost % (sobre ventas de barra) | B28: =IF(B7=0,"",B14/B7) | C28: =IF(C7=0,"",C14/C7) | D28: =IFERROR($C28-$B28,"") | E28: p.p. | F28: =IFERROR(IF(ISNUMBER($D28),IF($D28<='Resumen Anual'!$B$24,"✅ OK",IF($D28<='Resumen Anual'!$B$25,"⚠️ Atención","🔴 Alerta")),"—"),"—") -> —
A29: Labor Cost % | B29: =IF(B10=0,"",B15/B10) | C29: =IF(C10=0,"",C15/C10) | D29: =IFERROR($C29-$B29,"") | E29: p.p. | F29: =IFERROR(IF(ISNUMBER($D29),IF($D29<='Resumen Anual'!$B$24,"✅ OK",IF($D29<='Resumen Anual'!$B$25,"⚠️ Atención","🔴 Alerta")),"—"),"—") -> —
A30: Prime Cost % (comida + bebida + personal) | B30: =IF(B10=0,"",(B13+B14+B15)/B10) | C30: =IF(C10=0,"",(C13+C14+C15)/C10) | D30: =IFERROR($C30-$B30,"") | E30: p.p. | F30: =IFERROR(IF(ISNUMBER($D30),IF($D30<='Resumen Anual'!$B$24,"✅ OK",IF($D30<='Resumen Anual'!$B$25,"⚠️ Atención","🔴 Alerta")),"—"),"—") -> —
A32: © 2026 AI Chef Pro · aichef.pro

Sheet May
A1: P&L May — Real vs Presupuesto
A2: AI Chef Pro · aichef.pro — Kit Plan Financiero para Restaurantes
A4: Concepto | B4: Presupuesto (€) | C4: Real (€) | D4: Desviación (€) | E4: Desviación % | F4: Semáforo
A5: INGRESOS
A6: Ventas Comedor (sin IVA) | B6: 0 | C6: 0 | D6: =C6-B6 -> 0 | E6: =IF($B6=0,"",IFERROR(($C6-$B6)/$B6,"")) | F6: =IFERROR(IF(ISNUMBER($E6),IF($E6>=-'Resumen Anual'!$B$22,"✅ OK",IF($E6>=-'Resumen Anual'!$B$23,"⚠️ Atención","🔴 Alerta")),"—"),"—") -> —
A7: Ventas Barra (sin IVA) | B7: 0 | C7: 0 | D7: =C7-B7 -> 0 | E7: =IF($B7=0,"",IFERROR(($C7-$B7)/$B7,"")) | F7: =IFERROR(IF(ISNUMBER($E7),IF($E7>=-'Resumen Anual'!$B$22,"✅ OK",IF($E7>=-'Resumen Anual'!$B$23,"⚠️ Atención","🔴 Alerta")),"—"),"—") -> —
A8: Ventas Delivery (sin IVA) | B8: 0 | C8: 0 | D8: =C8-B8 -> 0 | E8: =IF($B8=0,"",IFERROR(($C8-$B8)/$B8,"")) | F8: =IFERROR(IF(ISNUMBER($E8),IF($E8>=-'Resumen Anual'!$B$22,"✅ OK",IF($E8>=-'Resumen Anual'!$B$23,"⚠️ Atención","🔴 Alerta")),"—"),"—") -> —
A9: Eventos / Catering (sin IVA) | B9: 0 | C9: 0 | D9: =C9-B9 -> 0 | E9: =IF($B9=0,"",IFERROR(($C9-$B9)/$B9,"")) | F9: =IFERROR(IF(ISNUMBER($E9),IF($E9>=-'Resumen Anual'!$B$22,"✅ OK",IF($E9>=-'Resumen Anual'!$B$23,"⚠️ Atención","🔴 Alerta")),"—"),"—") -> —
A10: TOTAL INGRESOS (sin IVA) | B10: =B6+B7+B8+B9 -> 0 | C10: =C6+C7+C8+C9 -> 0 | D10: =C10-B10 -> 0 | E10: =IF($B10=0,"",IFERROR(($C10-$B10)/$B10,"")) | F10: =IFERROR(IF(ISNUMBER($E10),IF($E10>=-'Resumen Anual'!$B$22,"✅ OK",IF($E10>=-'Resumen Anual'!$B$23,"⚠️ Atención","🔴 Alerta")),"—"),"—") -> —
A12: GASTOS
A13: Coste de comida (materia prima) | B13: 0 | C13: 0 | D13: =C13-B13 -> 0 | E13: =IF($B13=0,"",IFERROR(($C13-$B13)/$B13,"")) | F13: =IFERROR(IF(ISNUMBER($E13),IF($E13<='Resumen Anual'!$B$22,"✅ OK",IF($E13<='Resumen Anual'!$B$23,"⚠️ Atención","🔴 Alerta")),"—"),"—") -> —
A14: Coste de bebida (barra) | B14: 0 | C14: 0 | D14: =C14-B14 -> 0 | E14: =IF($B14=0,"",IFERROR(($C14-$B14)/$B14,"")) | F14: =IFERROR(IF(ISNUMBER($E14),IF($E14<='Resumen Anual'!$B$22,"✅ OK",IF($E14<='Resumen Anual'!$B$23,"⚠️ Atención","🔴 Alerta")),"—"),"—") -> —
A15: Personal (Labor) | B15: 0 | C15: 0 | D15: =C15-B15 -> 0 | E15: =IF($B15=0,"",IFERROR(($C15-$B15)/$B15,"")) | F15: =IFERROR(IF(ISNUMBER($E15),IF($E15<='Resumen Anual'!$B$22,"✅ OK",IF($E15<='Resumen Anual'!$B$23,"⚠️ Atención","🔴 Alerta")),"—"),"—") -> —
A16: Comisiones de plataformas (delivery) | B16: 0 | C16: 0 | D16: =C16-B16 -> 0 | E16: =IF($B16=0,"",IFERROR(($C16-$B16)/$B16,"")) | F16: =IFERROR(IF(ISNUMBER($E16),IF($E16<='Resumen Anual'!$B$22,"✅ OK",IF($E16<='Resumen Anual'!$B$23,"⚠️ Atención","🔴 Alerta")),"—"),"—") -> —
A17: Alquiler | B17: 0 | C17: 0 | D17: =C17-B17 -> 0 | E17: =IF($B17=0,"",IFERROR(($C17-$B17)/$B17,"")) | F17: =IFERROR(IF(ISNUMBER($E17),IF($E17<='Resumen Anual'!$B$22,"✅ OK",IF($E17<='Resumen Anual'!$B$23,"⚠️ Atención","🔴 Alerta")),"—"),"—") -> —
A18: Suministros | B18: 0 | C18: 0 | D18: =C18-B18 -> 0 | E18: =IF($B18=0,"",IFERROR(($C18-$B18)/$B18,"")) | F18: =IFERROR(IF(ISNUMBER($E18),IF($E18<='Resumen Anual'!$B$22,"✅ OK",IF($E18<='Resumen Anual'!$B$23,"⚠️ Atención","🔴 Alerta")),"—"),"—") -> —
A19: Marketing | B19: 0 | C19: 0 | D19: =C19-B19 -> 0 | E19: =IF($B19=0,"",IFERROR(($C19-$B19)/$B19,"")) | F19: =IFERROR(IF(ISNUMBER($E19),IF($E19<='Resumen Anual'!$B$22,"✅ OK",IF($E19<='Resumen Anual'!$B$23,"⚠️ Atención","🔴 Alerta")),"—"),"—") -> —
A20: Administración / Otros | B20: 0 | C20: 0 | D20: =C20-B20 -> 0 | E20: =IF($B20=0,"",IFERROR(($C20-$B20)/$B20,"")) | F20: =IFERROR(IF(ISNUMBER($E20),IF($E20<='Resumen Anual'!$B$22,"✅ OK",IF($E20<='Resumen Anual'!$B$23,"⚠️ Atención","🔴 Alerta")),"—"),"—") -> —
A21: TOTAL GASTOS | B21: =SUM(B13:B20) -> 0 | C21: =SUM(C13:C20) -> 0 | D21: =C21-B21 -> 0 | E21: =IF($B21=0,"",IFERROR(($C21-$B21)/$B21,"")) | F21: =IFERROR(IF(ISNUMBER($E21),IF($E21<='Resumen Anual'!$B$22,"✅ OK",IF($E21<='Resumen Anual'!$B$23,"⚠️ Atención","🔴 Alerta")),"—"),"—") -> —
A23: EBITDA | B23: =B10-B21 -> 0 | C23: =C10-C21 -> 0 | D23: =C23-B23 -> 0 | E23: =IF($B23=0,"",IFERROR(($C23-$B23)/ABS($B23),"")) | F23: =IFERROR(IF(ISNUMBER($E23),IF($E23>=-'Resumen Anual'!$B$22,"✅ OK",IF($E23>=-'Resumen Anual'!$B$23,"⚠️ Atención","🔴 Alerta")),"—"),"—") -> —
A24: Margen EBITDA % | B24: =IF(B10=0,"",B23/B10) | C24: =IF(C10=0,"",C23/C10) | D24: =IFERROR($C24-$B24,"") | E24: p.p. | F24: =IFERROR(IF(ISNUMBER($D24),IF($D24>=-'Resumen Anual'!$B$24,"✅ OK",IF($D24>=-'Resumen Anual'!$B$25,"⚠️ Atención","🔴 Alerta")),"—"),"—") -> —
A26: RATIOS AUTOMÁTICOS
A27: Food Cost % (sobre ventas de comida) | B27: =IF((B10-B7)<=0,"",B13/(B10-B7)) | C27: =IF((C10-C7)<=0,"",C13/(C10-C7)) | D27: =IFERROR($C27-$B27,"") | E27: p.p. | F27: =IFERROR(IF(ISNUMBER($D27),IF($D27<='Resumen Anual'!$B$24,"✅ OK",IF($D27<='Resumen Anual'!$B$25,"⚠️ Atención","🔴 Alerta")),"—"),"—") -> —
A28: Beverage Cost % (sobre ventas de barra) | B28: =IF(B7=0,"",B14/B7) | C28: =IF(C7=0,"",C14/C7) | D28: =IFERROR($C28-$B28,"") | E28: p.p. | F28: =IFERROR(IF(ISNUMBER($D28),IF($D28<='Resumen Anual'!$B$24,"✅ OK",IF($D28<='Resumen Anual'!$B$25,"⚠️ Atención","🔴 Alerta")),"—"),"—") -> —
A29: Labor Cost % | B29: =IF(B10=0,"",B15/B10) | C29: =IF(C10=0,"",C15/C10) | D29: =IFERROR($C29-$B29,"") | E29: p.p. | F29: =IFERROR(IF(ISNUMBER($D29),IF($D29<='Resumen Anual'!$B$24,"✅ OK",IF($D29<='Resumen Anual'!$B$25,"⚠️ Atención","🔴 Alerta")),"—"),"—") -> —
A30: Prime Cost % (comida + bebida + personal) | B30: =IF(B10=0,"",(B13+B14+B15)/B10) | C30: =IF(C10=0,"",(C13+C14+C15)/C10) | D30: =IFERROR($C30-$B30,"") | E30: p.p. | F30: =IFERROR(IF(ISNUMBER($D30),IF($D30<='Resumen Anual'!$B$24,"✅ OK",IF($D30<='Resumen Anual'!$B$25,"⚠️ Atención","🔴 Alerta")),"—"),"—") -> —
A32: © 2026 AI Chef Pro · aichef.pro

Sheet Jun
A1: P&L Jun — Real vs Presupuesto
A2: AI Chef Pro · aichef.pro — Kit Plan Financiero para Restaurantes
A4: Concepto | B4: Presupuesto (€) | C4: Real (€) | D4: Desviación (€) | E4: Desviación % | F4: Semáforo
A5: INGRESOS
A6: Ventas Comedor (sin IVA) | B6: 0 | C6: 0 | D6: =C6-B6 -> 0 | E6: =IF($B6=0,"",IFERROR(($C6-$B6)/$B6,"")) | F6: =IFERROR(IF(ISNUMBER($E6),IF($E6>=-'Resumen Anual'!$B$22,"✅ OK",IF($E6>=-'Resumen Anual'!$B$23,"⚠️ Atención","🔴 Alerta")),"—"),"—") -> —
A7: Ventas Barra (sin IVA) | B7: 0 | C7: 0 | D7: =C7-B7 -> 0 | E7: =IF($B7=0,"",IFERROR(($C7-$B7)/$B7,"")) | F7: =IFERROR(IF(ISNUMBER($E7),IF($E7>=-'Resumen Anual'!$B$22,"✅ OK",IF($E7>=-'Resumen Anual'!$B$23,"⚠️ Atención","🔴 Alerta")),"—"),"—") -> —
A8: Ventas Delivery (sin IVA) | B8: 0 | C8: 0 | D8: =C8-B8 -> 0 | E8: =IF($B8=0,"",IFERROR(($C8-$B8)/$B8,"")) | F8: =IFERROR(IF(ISNUMBER($E8),IF($E8>=-'Resumen Anual'!$B$22,"✅ OK",IF($E8>=-'Resumen Anual'!$B$23,"⚠️ Atención","🔴 Alerta")),"—"),"—") -> —
A9: Eventos / Catering (sin IVA) | B9: 0 | C9: 0 | D9: =C9-B9 -> 0 | E9: =IF($B9=0,"",IFERROR(($C9-$B9)/$B9,"")) | F9: =IFERROR(IF(ISNUMBER($E9),IF($E9>=-'Resumen Anual'!$B$22,"✅ OK",IF($E9>=-'Resumen Anual'!$B$23,"⚠️ Atención","🔴 Alerta")),"—"),"—") -> —
A10: TOTAL INGRESOS (sin IVA) | B10: =B6+B7+B8+B9 -> 0 | C10: =C6+C7+C8+C9 -> 0 | D10: =C10-B10 -> 0 | E10: =IF($B10=0,"",IFERROR(($C10-$B10)/$B10,"")) | F10: =IFERROR(IF(ISNUMBER($E10),IF($E10>=-'Resumen Anual'!$B$22,"✅ OK",IF($E10>=-'Resumen Anual'!$B$23,"⚠️ Atención","🔴 Alerta")),"—"),"—") -> —
A12: GASTOS
A13: Coste de comida (materia prima) | B13: 0 | C13: 0 | D13: =C13-B13 -> 0 | E13: =IF($B13=0,"",IFERROR(($C13-$B13)/$B13,"")) | F13: =IFERROR(IF(ISNUMBER($E13),IF($E13<='Resumen Anual'!$B$22,"✅ OK",IF($E13<='Resumen Anual'!$B$23,"⚠️ Atención","🔴 Alerta")),"—"),"—") -> —
A14: Coste de bebida (barra) | B14: 0 | C14: 0 | D14: =C14-B14 -> 0 | E14: =IF($B14=0,"",IFERROR(($C14-$B14)/$B14,"")) | F14: =IFERROR(IF(ISNUMBER($E14),IF($E14<='Resumen Anual'!$B$22,"✅ OK",IF($E14<='Resumen Anual'!$B$23,"⚠️ Atención","🔴 Alerta")),"—"),"—") -> —
A15: Personal (Labor) | B15: 0 | C15: 0 | D15: =C15-B15 -> 0 | E15: =IF($B15=0,"",IFERROR(($C15-$B15)/$B15,"")) | F15: =IFERROR(IF(ISNUMBER($E15),IF($E15<='Resumen Anual'!$B$22,"✅ OK",IF($E15<='Resumen Anual'!$B$23,"⚠️ Atención","🔴 Alerta")),"—"),"—") -> —
A16: Comisiones de plataformas (delivery) | B16: 0 | C16: 0 | D16: =C16-B16 -> 0 | E16: =IF($B16=0,"",IFERROR(($C16-$B16)/$B16,"")) | F16: =IFERROR(IF(ISNUMBER($E16),IF($E16<='Resumen Anual'!$B$22,"✅ OK",IF($E16<='Resumen Anual'!$B$23,"⚠️ Atención","🔴 Alerta")),"—"),"—") -> —
A17: Alquiler | B17: 0 | C17: 0 | D17: =C17-B17 -> 0 | E17: =IF($B17=0,"",IFERROR(($C17-$B17)/$B17,"")) | F17: =IFERROR(IF(ISNUMBER($E17),IF($E17<='Resumen Anual'!$B$22,"✅ OK",IF($E17<='Resumen Anual'!$B$23,"⚠️ Atención","🔴 Alerta")),"—"),"—") -> —
A18: Suministros | B18: 0 | C18: 0 | D18: =C18-B18 -> 0 | E18: =IF($B18=0,"",IFERROR(($C18-$B18)/$B18,"")) | F18: =IFERROR(IF(ISNUMBER($E18),IF($E18<='Resumen Anual'!$B$22,"✅ OK",IF($E18<='Resumen Anual'!$B$23,"⚠️ Atención","🔴 Alerta")),"—"),"—") -> —
A19: Marketing | B19: 0 | C19: 0 | D19: =C19-B19 -> 0 | E19: =IF($B19=0,"",IFERROR(($C19-$B19)/$B19,"")) | F19: =IFERROR(IF(ISNUMBER($E19),IF($E19<='Resumen Anual'!$B$22,"✅ OK",IF($E19<='Resumen Anual'!$B$23,"⚠️ Atención","🔴 Alerta")),"—"),"—") -> —
A20: Administración / Otros | B20: 0 | C20: 0 | D20: =C20-B20 -> 0 | E20: =IF($B20=0,"",IFERROR(($C20-$B20)/$B20,"")) | F20: =IFERROR(IF(ISNUMBER($E20),IF($E20<='Resumen Anual'!$B$22,"✅ OK",IF($E20<='Resumen Anual'!$B$23,"⚠️ Atención","🔴 Alerta")),"—"),"—") -> —
A21: TOTAL GASTOS | B21: =SUM(B13:B20) -> 0 | C21: =SUM(C13:C20) -> 0 | D21: =C21-B21 -> 0 | E21: =IF($B21=0,"",IFERROR(($C21-$B21)/$B21,"")) | F21: =IFERROR(IF(ISNUMBER($E21),IF($E21<='Resumen Anual'!$B$22,"✅ OK",IF($E21<='Resumen Anual'!$B$23,"⚠️ Atención","🔴 Alerta")),"—"),"—") -> —
A23: EBITDA | B23: =B10-B21 -> 0 | C23: =C10-C21 -> 0 | D23: =C23-B23 -> 0 | E23: =IF($B23=0,"",IFERROR(($C23-$B23)/ABS($B23),"")) | F23: =IFERROR(IF(ISNUMBER($E23),IF($E23>=-'Resumen Anual'!$B$22,"✅ OK",IF($E23>=-'Resumen Anual'!$B$23,"⚠️ Atención","🔴 Alerta")),"—"),"—") -> —
A24: Margen EBITDA % | B24: =IF(B10=0,"",B23/B10) | C24: =IF(C10=0,"",C23/C10) | D24: =IFERROR($C24-$B24,"") | E24: p.p. | F24: =IFERROR(IF(ISNUMBER($D24),IF($D24>=-'Resumen Anual'!$B$24,"✅ OK",IF($D24>=-'Resumen Anual'!$B$25,"⚠️ Atención","🔴 Alerta")),"—"),"—") -> —
A26: RATIOS AUTOMÁTICOS
A27: Food Cost % (sobre ventas de comida) | B27: =IF((B10-B7)<=0,"",B13/(B10-B7)) | C27: =IF((C10-C7)<=0,"",C13/(C10-C7)) | D27: =IFERROR($C27-$B27,"") | E27: p.p. | F27: =IFERROR(IF(ISNUMBER($D27),IF($D27<='Resumen Anual'!$B$24,"✅ OK",IF($D27<='Resumen Anual'!$B$25,"⚠️ Atención","🔴 Alerta")),"—"),"—") -> —
A28: Beverage Cost % (sobre ventas de barra) | B28: =IF(B7=0,"",B14/B7) | C28: =IF(C7=0,"",C14/C7) | D28: =IFERROR($C28-$B28,"") | E28: p.p. | F28: =IFERROR(IF(ISNUMBER($D28),IF($D28<='Resumen Anual'!$B$24,"✅ OK",IF($D28<='Resumen Anual'!$B$25,"⚠️ Atención","🔴 Alerta")),"—"),"—") -> —
A29: Labor Cost % | B29: =IF(B10=0,"",B15/B10) | C29: =IF(C10=0,"",C15/C10) | D29: =IFERROR($C29-$B29,"") | E29: p.p. | F29: =IFERROR(IF(ISNUMBER($D29),IF($D29<='Resumen Anual'!$B$24,"✅ OK",IF($D29<='Resumen Anual'!$B$25,"⚠️ Atención","🔴 Alerta")),"—"),"—") -> —
A30: Prime Cost % (comida + bebida + personal) | B30: =IF(B10=0,"",(B13+B14+B15)/B10) | C30: =IF(C10=0,"",(C13+C14+C15)/C10) | D30: =IFERROR($C30-$B30,"") | E30: p.p. | F30: =IFERROR(IF(ISNUMBER($D30),IF($D30<='Resumen Anual'!$B$24,"✅ OK",IF($D30<='Resumen Anual'!$B$25,"⚠️ Atención","🔴 Alerta")),"—"),"—") -> —
A32: © 2026 AI Chef Pro · aichef.pro

Sheet Jul
A1: P&L Jul — Real vs Presupuesto
A2: AI Chef Pro · aichef.pro — Kit Plan Financiero para Restaurantes
A4: Concepto | B4: Presupuesto (€) | C4: Real (€) | D4: Desviación (€) | E4: Desviación % | F4: Semáforo
A5: INGRESOS
A6: Ventas Comedor (sin IVA) | B6: 0 | C6: 0 | D6: =C6-B6 -> 0 | E6: =IF($B6=0,"",IFERROR(($C6-$B6)/$B6,"")) | F6: =IFERROR(IF(ISNUMBER($E6),IF($E6>=-'Resumen Anual'!$B$22,"✅ OK",IF($E6>=-'Resumen Anual'!$B$23,"⚠️ Atención","🔴 Alerta")),"—"),"—") -> —
A7: Ventas Barra (sin IVA) | B7: 0 | C7: 0 | D7: =C7-B7 -> 0 | E7: =IF($B7=0,"",IFERROR(($C7-$B7)/$B7,"")) | F7: =IFERROR(IF(ISNUMBER($E7),IF($E7>=-'Resumen Anual'!$B$22,"✅ OK",IF($E7>=-'Resumen Anual'!$B$23,"⚠️ Atención","🔴 Alerta")),"—"),"—") -> —
A8: Ventas Delivery (sin IVA) | B8: 0 | C8: 0 | D8: =C8-B8 -> 0 | E8: =IF($B8=0,"",IFERROR(($C8-$B8)/$B8,"")) | F8: =IFERROR(IF(ISNUMBER($E8),IF($E8>=-'Resumen Anual'!$B$22,"✅ OK",IF($E8>=-'Resumen Anual'!$B$23,"⚠️ Atención","🔴 Alerta")),"—"),"—") -> —
A9: Eventos / Catering (sin IVA) | B9: 0 | C9: 0 | D9: =C9-B9 -> 0 | E9: =IF($B9=0,"",IFERROR(($C9-$B9)/$B9,"")) | F9: =IFERROR(IF(ISNUMBER($E9),IF($E9>=-'Resumen Anual'!$B$22,"✅ OK",IF($E9>=-'Resumen Anual'!$B$23,"⚠️ Atención","🔴 Alerta")),"—"),"—") -> —
A10: TOTAL INGRESOS (sin IVA) | B10: =B6+B7+B8+B9 -> 0 | C10: =C6+C7+C8+C9 -> 0 | D10: =C10-B10 -> 0 | E10: =IF($B10=0,"",IFERROR(($C10-$B10)/$B10,"")) | F10: =IFERROR(IF(ISNUMBER($E10),IF($E10>=-'Resumen Anual'!$B$22,"✅ OK",IF($E10>=-'Resumen Anual'!$B$23,"⚠️ Atención","🔴 Alerta")),"—"),"—") -> —
A12: GASTOS
A13: Coste de comida (materia prima) | B13: 0 | C13: 0 | D13: =C13-B13 -> 0 | E13: =IF($B13=0,"",IFERROR(($C13-$B13)/$B13,"")) | F13: =IFERROR(IF(ISNUMBER($E13),IF($E13<='Resumen Anual'!$B$22,"✅ OK",IF($E13<='Resumen Anual'!$B$23,"⚠️ Atención","🔴 Alerta")),"—"),"—") -> —
A14: Coste de bebida (barra) | B14: 0 | C14: 0 | D14: =C14-B14 -> 0 | E14: =IF($B14=0,"",IFERROR(($C14-$B14)/$B14,"")) | F14: =IFERROR(IF(ISNUMBER($E14),IF($E14<='Resumen Anual'!$B$22,"✅ OK",IF($E14<='Resumen Anual'!$B$23,"⚠️ Atención","🔴 Alerta")),"—"),"—") -> —
A15: Personal (Labor) | B15: 0 | C15: 0 | D15: =C15-B15 -> 0 | E15: =IF($B15=0,"",IFERROR(($C15-$B15)/$B15,"")) | F15: =IFERROR(IF(ISNUMBER($E15),IF($E15<='Resumen Anual'!$B$22,"✅ OK",IF($E15<='Resumen Anual'!$B$23,"⚠️ Atención","🔴 Alerta")),"—"),"—") -> —
A16: Comisiones de plataformas (delivery) | B16: 0 | C16: 0 | D16: =C16-B16 -> 0 | E16: =IF($B16=0,"",IFERROR(($C16-$B16)/$B16,"")) | F16: =IFERROR(IF(ISNUMBER($E16),IF($E16<='Resumen Anual'!$B$22,"✅ OK",IF($E16<='Resumen Anual'!$B$23,"⚠️ Atención","🔴 Alerta")),"—"),"—") -> —
A17: Alquiler | B17: 0 | C17: 0 | D17: =C17-B17 -> 0 | E17: =IF($B17=0,"",IFERROR(($C17-$B17)/$B17,"")) | F17: =IFERROR(IF(ISNUMBER($E17),IF($E17<='Resumen Anual'!$B$22,"✅ OK",IF($E17<='Resumen Anual'!$B$23,"⚠️ Atención","🔴 Alerta")),"—"),"—") -> —
A18: Suministros | B18: 0 | C18: 0 | D18: =C18-B18 -> 0 | E18: =IF($B18=0,"",IFERROR(($C18-$B18)/$B18,"")) | F18: =IFERROR(IF(ISNUMBER($E18),IF($E18<='Resumen Anual'!$B$22,"✅ OK",IF($E18<='Resumen Anual'!$B$23,"⚠️ Atención","🔴 Alerta")),"—"),"—") -> —
A19: Marketing | B19: 0 | C19: 0 | D19: =C19-B19 -> 0 | E19: =IF($B19=0,"",IFERROR(($C19-$B19)/$B19,"")) | F19: =IFERROR(IF(ISNUMBER($E19),IF($E19<='Resumen Anual'!$B$22,"✅ OK",IF($E19<='Resumen Anual'!$B$23,"⚠️ Atención","🔴 Alerta")),"—"),"—") -> —
A20: Administración / Otros | B20: 0 | C20: 0 | D20: =C20-B20 -> 0 | E20: =IF($B20=0,"",IFERROR(($C20-$B20)/$B20,"")) | F20: =IFERROR(IF(ISNUMBER($E20),IF($E20<='Resumen Anual'!$B$22,"✅ OK",IF($E20<='Resumen Anual'!$B$23,"⚠️ Atención","🔴 Alerta")),"—"),"—") -> —
A21: TOTAL GASTOS | B21: =SUM(B13:B20) -> 0 | C21: =SUM(C13:C20) -> 0 | D21: =C21-B21 -> 0 | E21: =IF($B21=0,"",IFERROR(($C21-$B21)/$B21,"")) | F21: =IFERROR(IF(ISNUMBER($E21),IF($E21<='Resumen Anual'!$B$22,"✅ OK",IF($E21<='Resumen Anual'!$B$23,"⚠️ Atención","🔴 Alerta")),"—"),"—") -> —
A23: EBITDA | B23: =B10-B21 -> 0 | C23: =C10-C21 -> 0 | D23: =C23-B23 -> 0 | E23: =IF($B23=0,"",IFERROR(($C23-$B23)/ABS($B23),"")) | F23: =IFERROR(IF(ISNUMBER($E23),IF($E23>=-'Resumen Anual'!$B$22,"✅ OK",IF($E23>=-'Resumen Anual'!$B$23,"⚠️ Atención","🔴 Alerta")),"—"),"—") -> —
A24: Margen EBITDA % | B24: =IF(B10=0,"",B23/B10) | C24: =IF(C10=0,"",C23/C10) | D24: =IFERROR($C24-$B24,"") | E24: p.p. | F24: =IFERROR(IF(ISNUMBER($D24),IF($D24>=-'Resumen Anual'!$B$24,"✅ OK",IF($D24>=-'Resumen Anual'!$B$25,"⚠️ Atención","🔴 Alerta")),"—"),"—") -> —
A26: RATIOS AUTOMÁTICOS
A27: Food Cost % (sobre ventas de comida) | B27: =IF((B10-B7)<=0,"",B13/(B10-B7)) | C27: =IF((C10-C7)<=0,"",C13/(C10-C7)) | D27: =IFERROR($C27-$B27,"") | E27: p.p. | F27: =IFERROR(IF(ISNUMBER($D27),IF($D27<='Resumen Anual'!$B$24,"✅ OK",IF($D27<='Resumen Anual'!$B$25,"⚠️ Atención","🔴 Alerta")),"—"),"—") -> —
A28: Beverage Cost % (sobre ventas de barra) | B28: =IF(B7=0,"",B14/B7) | C28: =IF(C7=0,"",C14/C7) | D28: =IFERROR($C28-$B28,"") | E28: p.p. | F28: =IFERROR(IF(ISNUMBER($D28),IF($D28<='Resumen Anual'!$B$24,"✅ OK",IF($D28<='Resumen Anual'!$B$25,"⚠️ Atención","🔴 Alerta")),"—"),"—") -> —
A29: Labor Cost % | B29: =IF(B10=0,"",B15/B10) | C29: =IF(C10=0,"",C15/C10) | D29: =IFERROR($C29-$B29,"") | E29: p.p. | F29: =IFERROR(IF(ISNUMBER($D29),IF($D29<='Resumen Anual'!$B$24,"✅ OK",IF($D29<='Resumen Anual'!$B$25,"⚠️ Atención","🔴 Alerta")),"—"),"—") -> —
A30: Prime Cost % (comida + bebida + personal) | B30: =IF(B10=0,"",(B13+B14+B15)/B10) | C30: =IF(C10=0,"",(C13+C14+C15)/C10) | D30: =IFERROR($C30-$B30,"") | E30: p.p. | F30: =IFERROR(IF(ISNUMBER($D30),IF($D30<='Resumen Anual'!$B$24,"✅ OK",IF($D30<='Resumen Anual'!$B$25,"⚠️ Atención","🔴 Alerta")),"—"),"—") -> —
A32: © 2026 AI Chef Pro · aichef.pro

Sheet Ago
A1: P&L Ago — Real vs Presupuesto
A2: AI Chef Pro · aichef.pro — Kit Plan Financiero para Restaurantes
A4: Concepto | B4: Presupuesto (€) | C4: Real (€) | D4: Desviación (€) | E4: Desviación % | F4: Semáforo
A5: INGRESOS
A6: Ventas Comedor (sin IVA) | B6: 0 | C6: 0 | D6: =C6-B6 -> 0 | E6: =IF($B6=0,"",IFERROR(($C6-$B6)/$B6,"")) | F6: =IFERROR(IF(ISNUMBER($E6),IF($E6>=-'Resumen Anual'!$B$22,"✅ OK",IF($E6>=-'Resumen Anual'!$B$23,"⚠️ Atención","🔴 Alerta")),"—"),"—") -> —
A7: Ventas Barra (sin IVA) | B7: 0 | C7: 0 | D7: =C7-B7 -> 0 | E7: =IF($B7=0,"",IFERROR(($C7-$B7)/$B7,"")) | F7: =IFERROR(IF(ISNUMBER($E7),IF($E7>=-'Resumen Anual'!$B$22,"✅ OK",IF($E7>=-'Resumen Anual'!$B$23,"⚠️ Atención","🔴 Alerta")),"—"),"—") -> —
A8: Ventas Delivery (sin IVA) | B8: 0 | C8: 0 | D8: =C8-B8 -> 0 | E8: =IF($B8=0,"",IFERROR(($C8-$B8)/$B8,"")) | F8: =IFERROR(IF(ISNUMBER($E8),IF($E8>=-'Resumen Anual'!$B$22,"✅ OK",IF($E8>=-'Resumen Anual'!$B$23,"⚠️ Atención","🔴 Alerta")),"—"),"—") -> —
A9: Eventos / Catering (sin IVA) | B9: 0 | C9: 0 | D9: =C9-B9 -> 0 | E9: =IF($B9=0,"",IFERROR(($C9-$B9)/$B9,"")) | F9: =IFERROR(IF(ISNUMBER($E9),IF($E9>=-'Resumen Anual'!$B$22,"✅ OK",IF($E9>=-'Resumen Anual'!$B$23,"⚠️ Atención","🔴 Alerta")),"—"),"—") -> —
A10: TOTAL INGRESOS (sin IVA) | B10: =B6+B7+B8+B9 -> 0 | C10: =C6+C7+C8+C9 -> 0 | D10: =C10-B10 -> 0 | E10: =IF($B10=0,"",IFERROR(($C10-$B10)/$B10,"")) | F10: =IFERROR(IF(ISNUMBER($E10),IF($E10>=-'Resumen Anual'!$B$22,"✅ OK",IF($E10>=-'Resumen Anual'!$B$23,"⚠️ Atención","🔴 Alerta")),"—"),"—") -> —
A12: GASTOS
A13: Coste de comida (materia prima) | B13: 0 | C13: 0 | D13: =C13-B13 -> 0 | E13: =IF($B13=0,"",IFERROR(($C13-$B13)/$B13,"")) | F13: =IFERROR(IF(ISNUMBER($E13),IF($E13<='Resumen Anual'!$B$22,"✅ OK",IF($E13<='Resumen Anual'!$B$23,"⚠️ Atención","🔴 Alerta")),"—"),"—") -> —
A14: Coste de bebida (barra) | B14: 0 | C14: 0 | D14: =C14-B14 -> 0 | E14: =IF($B14=0,"",IFERROR(($C14-$B14)/$B14,"")) | F14: =IFERROR(IF(ISNUMBER($E14),IF($E14<='Resumen Anual'!$B$22,"✅ OK",IF($E14<='Resumen Anual'!$B$23,"⚠️ Atención","🔴 Alerta")),"—"),"—") -> —
A15: Personal (Labor) | B15: 0 | C15: 0 | D15: =C15-B15 -> 0 | E15: =IF($B15=0,"",IFERROR(($C15-$B15)/$B15,"")) | F15: =IFERROR(IF(ISNUMBER($E15),IF($E15<='Resumen Anual'!$B$22,"✅ OK",IF($E15<='Resumen Anual'!$B$23,"⚠️ Atención","🔴 Alerta")),"—"),"—") -> —
A16: Comisiones de plataformas (delivery) | B16: 0 | C16: 0 | D16: =C16-B16 -> 0 | E16: =IF($B16=0,"",IFERROR(($C16-$B16)/$B16,"")) | F16: =IFERROR(IF(ISNUMBER($E16),IF($E16<='Resumen Anual'!$B$22,"✅ OK",IF($E16<='Resumen Anual'!$B$23,"⚠️ Atención","🔴 Alerta")),"—"),"—") -> —
A17: Alquiler | B17: 0 | C17: 0 | D17: =C17-B17 -> 0 | E17: =IF($B17=0,"",IFERROR(($C17-$B17)/$B17,"")) | F17: =IFERROR(IF(ISNUMBER($E17),IF($E17<='Resumen Anual'!$B$22,"✅ OK",IF($E17<='Resumen Anual'!$B$23,"⚠️ Atención","🔴 Alerta")),"—"),"—") -> —
A18: Suministros | B18: 0 | C18: 0 | D18: =C18-B18 -> 0 | E18: =IF($B18=0,"",IFERROR(($C18-$B18)/$B18,"")) | F18: =IFERROR(IF(ISNUMBER($E18),IF($E18<='Resumen Anual'!$B$22,"✅ OK",IF($E18<='Resumen Anual'!$B$23,"⚠️ Atención","🔴 Alerta")),"—"),"—") -> —
A19: Marketing | B19: 0 | C19: 0 | D19: =C19-B19 -> 0 | E19: =IF($B19=0,"",IFERROR(($C19-$B19)/$B19,"")) | F19: =IFERROR(IF(ISNUMBER($E19),IF($E19<='Resumen Anual'!$B$22,"✅ OK",IF($E19<='Resumen Anual'!$B$23,"⚠️ Atención","🔴 Alerta")),"—"),"—") -> —
A20: Administración / Otros | B20: 0 | C20: 0 | D20: =C20-B20 -> 0 | E20: =IF($B20=0,"",IFERROR(($C20-$B20)/$B20,"")) | F20: =IFERROR(IF(ISNUMBER($E20),IF($E20<='Resumen Anual'!$B$22,"✅ OK",IF($E20<='Resumen Anual'!$B$23,"⚠️ Atención","🔴 Alerta")),"—"),"—") -> —
A21: TOTAL GASTOS | B21: =SUM(B13:B20) -> 0 | C21: =SUM(C13:C20) -> 0 | D21: =C21-B21 -> 0 | E21: =IF($B21=0,"",IFERROR(($C21-$B21)/$B21,"")) | F21: =IFERROR(IF(ISNUMBER($E21),IF($E21<='Resumen Anual'!$B$22,"✅ OK",IF($E21<='Resumen Anual'!$B$23,"⚠️ Atención","🔴 Alerta")),"—"),"—") -> —
A23: EBITDA | B23: =B10-B21 -> 0 | C23: =C10-C21 -> 0 | D23: =C23-B23 -> 0 | E23: =IF($B23=0,"",IFERROR(($C23-$B23)/ABS($B23),"")) | F23: =IFERROR(IF(ISNUMBER($E23),IF($E23>=-'Resumen Anual'!$B$22,"✅ OK",IF($E23>=-'Resumen Anual'!$B$23,"⚠️ Atención","🔴 Alerta")),"—"),"—") -> —
A24: Margen EBITDA % | B24: =IF(B10=0,"",B23/B10) | C24: =IF(C10=0,"",C23/C10) | D24: =IFERROR($C24-$B24,"") | E24: p.p. | F24: =IFERROR(IF(ISNUMBER($D24),IF($D24>=-'Resumen Anual'!$B$24,"✅ OK",IF($D24>=-'Resumen Anual'!$B$25,"⚠️ Atención","🔴 Alerta")),"—"),"—") -> —
A26: RATIOS AUTOMÁTICOS
A27: Food Cost % (sobre ventas de comida) | B27: =IF((B10-B7)<=0,"",B13/(B10-B7)) | C27: =IF((C10-C7)<=0,"",C13/(C10-C7)) | D27: =IFERROR($C27-$B27,"") | E27: p.p. | F27: =IFERROR(IF(ISNUMBER($D27),IF($D27<='Resumen Anual'!$B$24,"✅ OK",IF($D27<='Resumen Anual'!$B$25,"⚠️ Atención","🔴 Alerta")),"—"),"—") -> —
A28: Beverage Cost % (sobre ventas de barra) | B28: =IF(B7=0,"",B14/B7) | C28: =IF(C7=0,"",C14/C7) | D28: =IFERROR($C28-$B28,"") | E28: p.p. | F28: =IFERROR(IF(ISNUMBER($D28),IF($D28<='Resumen Anual'!$B$24,"✅ OK",IF($D28<='Resumen Anual'!$B$25,"⚠️ Atención","🔴 Alerta")),"—"),"—") -> —
A29: Labor Cost % | B29: =IF(B10=0,"",B15/B10) | C29: =IF(C10=0,"",C15/C10) | D29: =IFERROR($C29-$B29,"") | E29: p.p. | F29: =IFERROR(IF(ISNUMBER($D29),IF($D29<='Resumen Anual'!$B$24,"✅ OK",IF($D29<='Resumen Anual'!$B$25,"⚠️ Atención","🔴 Alerta")),"—"),"—") -> —
A30: Prime Cost % (comida + bebida + personal) | B30: =IF(B10=0,"",(B13+B14+B15)/B10) | C30: =IF(C10=0,"",(C13+C14+C15)/C10) | D30: =IFERROR($C30-$B30,"") | E30: p.p. | F30: =IFERROR(IF(ISNUMBER($D30),IF($D30<='Resumen Anual'!$B$24,"✅ OK",IF($D30<='Resumen Anual'!$B$25,"⚠️ Atención","🔴 Alerta")),"—"),"—") -> —
A32: © 2026 AI Chef Pro · aichef.pro

Sheet Sep
A1: P&L Sep — Real vs Presupuesto
A2: AI Chef Pro · aichef.pro — Kit Plan Financiero para Restaurantes
A4: Concepto | B4: Presupuesto (€) | C4: Real (€) | D4: Desviación (€) | E4: Desviación % | F4: Semáforo
A5: INGRESOS
A6: Ventas Comedor (sin IVA) | B6: 0 | C6: 0 | D6: =C6-B6 -> 0 | E6: =IF($B6=0,"",IFERROR(($C6-$B6)/$B6,"")) | F6: =IFERROR(IF(ISNUMBER($E6),IF($E6>=-'Resumen Anual'!$B$22,"✅ OK",IF($E6>=-'Resumen Anual'!$B$23,"⚠️ Atención","🔴 Alerta")),"—"),"—") -> —
A7: Ventas Barra (sin IVA) | B7: 0 | C7: 0 | D7: =C7-B7 -> 0 | E7: =IF($B7=0,"",IFERROR(($C7-$B7)/$B7,"")) | F7: =IFERROR(IF(ISNUMBER($E7),IF($E7>=-'Resumen Anual'!$B$22,"✅ OK",IF($E7>=-'Resumen Anual'!$B$23,"⚠️ Atención","🔴 Alerta")),"—"),"—") -> —
A8: Ventas Delivery (sin IVA) | B8: 0 | C8: 0 | D8: =C8-B8 -> 0 | E8: =IF($B8=0,"",IFERROR(($C8-$B8)/$B8,"")) | F8: =IFERROR(IF(ISNUMBER($E8),IF($E8>=-'Resumen Anual'!$B$22,"✅ OK",IF($E8>=-'Resumen Anual'!$B$23,"⚠️ Atención","🔴 Alerta")),"—"),"—") -> —
A9: Eventos / Catering (sin IVA) | B9: 0 | C9: 0 | D9: =C9-B9 -> 0 | E9: =IF($B9=0,"",IFERROR(($C9-$B9)/$B9,"")) | F9: =IFERROR(IF(ISNUMBER($E9),IF($E9>=-'Resumen Anual'!$B$22,"✅ OK",IF($E9>=-'Resumen Anual'!$B$23,"⚠️ Atención","🔴 Alerta")),"—"),"—") -> —
A10: TOTAL INGRESOS (sin IVA) | B10: =B6+B7+B8+B9 -> 0 | C10: =C6+C7+C8+C9 -> 0 | D10: =C10-B10 -> 0 | E10: =IF($B10=0,"",IFERROR(($C10-$B10)/$B10,"")) | F10: =IFERROR(IF(ISNUMBER($E10),IF($E10>=-'Resumen Anual'!$B$22,"✅ OK",IF($E10>=-'Resumen Anual'!$B$23,"⚠️ Atención","🔴 Alerta")),"—"),"—") -> —
A12: GASTOS
A13: Coste de comida (materia prima) | B13: 0 | C13: 0 | D13: =C13-B13 -> 0 | E13: =IF($B13=0,"",IFERROR(($C13-$B13)/$B13,"")) | F13: =IFERROR(IF(ISNUMBER($E13),IF($E13<='Resumen Anual'!$B$22,"✅ OK",IF($E13<='Resumen Anual'!$B$23,"⚠️ Atención","🔴 Alerta")),"—"),"—") -> —
A14: Coste de bebida (barra) | B14: 0 | C14: 0 | D14: =C14-B14 -> 0 | E14: =IF($B14=0,"",IFERROR(($C14-$B14)/$B14,"")) | F14: =IFERROR(IF(ISNUMBER($E14),IF($E14<='Resumen Anual'!$B$22,"✅ OK",IF($E14<='Resumen Anual'!$B$23,"⚠️ Atención","🔴 Alerta")),"—"),"—") -> —
A15: Personal (Labor) | B15: 0 | C15: 0 | D15: =C15-B15 -> 0 | E15: =IF($B15=0,"",IFERROR(($C15-$B15)/$B15,"")) | F15: =IFERROR(IF(ISNUMBER($E15),IF($E15<='Resumen Anual'!$B$22,"✅ OK",IF($E15<='Resumen Anual'!$B$23,"⚠️ Atención","🔴 Alerta")),"—"),"—") -> —
A16: Comisiones de plataformas (delivery) | B16: 0 | C16: 0 | D16: =C16-B16 -> 0 | E16: =IF($B16=0,"",IFERROR(($C16-$B16)/$B16,"")) | F16: =IFERROR(IF(ISNUMBER($E16),IF($E16<='Resumen Anual'!$B$22,"✅ OK",IF($E16<='Resumen Anual'!$B$23,"⚠️ Atención","🔴 Alerta")),"—"),"—") -> —
A17: Alquiler | B17: 0 | C17: 0 | D17: =C17-B17 -> 0 | E17: =IF($B17=0,"",IFERROR(($C17-$B17)/$B17,"")) | F17: =IFERROR(IF(ISNUMBER($E17),IF($E17<='Resumen Anual'!$B$22,"✅ OK",IF($E17<='Resumen Anual'!$B$23,"⚠️ Atención","🔴 Alerta")),"—"),"—") -> —
A18: Suministros | B18: 0 | C18: 0 | D18: =C18-B18 -> 0 | E18: =IF($B18=0,"",IFERROR(($C18-$B18)/$B18,"")) | F18: =IFERROR(IF(ISNUMBER($E18),IF($E18<='Resumen Anual'!$B$22,"✅ OK",IF($E18<='Resumen Anual'!$B$23,"⚠️ Atención","🔴 Alerta")),"—"),"—") -> —
A19: Marketing | B19: 0 | C19: 0 | D19: =C19-B19 -> 0 | E19: =IF($B19=0,"",IFERROR(($C19-$B19)/$B19,"")) | F19: =IFERROR(IF(ISNUMBER($E19),IF($E19<='Resumen Anual'!$B$22,"✅ OK",IF($E19<='Resumen Anual'!$B$23,"⚠️ Atención","🔴 Alerta")),"—"),"—") -> —
A20: Administración / Otros | B20: 0 | C20: 0 | D20: =C20-B20 -> 0 | E20: =IF($B20=0,"",IFERROR(($C20-$B20)/$B20,"")) | F20: =IFERROR(IF(ISNUMBER($E20),IF($E20<='Resumen Anual'!$B$22,"✅ OK",IF($E20<='Resumen Anual'!$B$23,"⚠️ Atención","🔴 Alerta")),"—"),"—") -> —
A21: TOTAL GASTOS | B21: =SUM(B13:B20) -> 0 | C21: =SUM(C13:C20) -> 0 | D21: =C21-B21 -> 0 | E21: =IF($B21=0,"",IFERROR(($C21-$B21)/$B21,"")) | F21: =IFERROR(IF(ISNUMBER($E21),IF($E21<='Resumen Anual'!$B$22,"✅ OK",IF($E21<='Resumen Anual'!$B$23,"⚠️ Atención","🔴 Alerta")),"—"),"—") -> —
A23: EBITDA | B23: =B10-B21 -> 0 | C23: =C10-C21 -> 0 | D23: =C23-B23 -> 0 | E23: =IF($B23=0,"",IFERROR(($C23-$B23)/ABS($B23),"")) | F23: =IFERROR(IF(ISNUMBER($E23),IF($E23>=-'Resumen Anual'!$B$22,"✅ OK",IF($E23>=-'Resumen Anual'!$B$23,"⚠️ Atención","🔴 Alerta")),"—"),"—") -> —
A24: Margen EBITDA % | B24: =IF(B10=0,"",B23/B10) | C24: =IF(C10=0,"",C23/C10) | D24: =IFERROR($C24-$B24,"") | E24: p.p. | F24: =IFERROR(IF(ISNUMBER($D24),IF($D24>=-'Resumen Anual'!$B$24,"✅ OK",IF($D24>=-'Resumen Anual'!$B$25,"⚠️ Atención","🔴 Alerta")),"—"),"—") -> —
A26: RATIOS AUTOMÁTICOS
A27: Food Cost % (sobre ventas de comida) | B27: =IF((B10-B7)<=0,"",B13/(B10-B7)) | C27: =IF((C10-C7)<=0,"",C13/(C10-C7)) | D27: =IFERROR($C27-$B27,"") | E27: p.p. | F27: =IFERROR(IF(ISNUMBER($D27),IF($D27<='Resumen Anual'!$B$24,"✅ OK",IF($D27<='Resumen Anual'!$B$25,"⚠️ Atención","🔴 Alerta")),"—"),"—") -> —
A28: Beverage Cost % (sobre ventas de barra) | B28: =IF(B7=0,"",B14/B7) | C28: =IF(C7=0,"",C14/C7) | D28: =IFERROR($C28-$B28,"") | E28: p.p. | F28: =IFERROR(IF(ISNUMBER($D28),IF($D28<='Resumen Anual'!$B$24,"✅ OK",IF($D28<='Resumen Anual'!$B$25,"⚠️ Atención","🔴 Alerta")),"—"),"—") -> —
A29: Labor Cost % | B29: =IF(B10=0,"",B15/B10) | C29: =IF(C10=0,"",C15/C10) | D29: =IFERROR($C29-$B29,"") | E29: p.p. | F29: =IFERROR(IF(ISNUMBER($D29),IF($D29<='Resumen Anual'!$B$24,"✅ OK",IF($D29<='Resumen Anual'!$B$25,"⚠️ Atención","🔴 Alerta")),"—"),"—") -> —
A30: Prime Cost % (comida + bebida + personal) | B30: =IF(B10=0,"",(B13+B14+B15)/B10) | C30: =IF(C10=0,"",(C13+C14+C15)/C10) | D30: =IFERROR($C30-$B30,"") | E30: p.p. | F30: =IFERROR(IF(ISNUMBER($D30),IF($D30<='Resumen Anual'!$B$24,"✅ OK",IF($D30<='Resumen Anual'!$B$25,"⚠️ Atención","🔴 Alerta")),"—"),"—") -> —
A32: © 2026 AI Chef Pro · aichef.pro

Sheet Oct
A1: P&L Oct — Real vs Presupuesto
A2: AI Chef Pro · aichef.pro — Kit Plan Financiero para Restaurantes
A4: Concepto | B4: Presupuesto (€) | C4: Real (€) | D4: Desviación (€) | E4: Desviación % | F4: Semáforo
A5: INGRESOS
A6: Ventas Comedor (sin IVA) | B6: 0 | C6: 0 | D6: =C6-B6 -> 0 | E6: =IF($B6=0,"",IFERROR(($C6-$B6)/$B6,"")) | F6: =IFERROR(IF(ISNUMBER($E6),IF($E6>=-'Resumen Anual'!$B$22,"✅ OK",IF($E6>=-'Resumen Anual'!$B$23,"⚠️ Atención","🔴 Alerta")),"—"),"—") -> —
A7: Ventas Barra (sin IVA) | B7: 0 | C7: 0 | D7: =C7-B7 -> 0 | E7: =IF($B7=0,"",IFERROR(($C7-$B7)/$B7,"")) | F7: =IFERROR(IF(ISNUMBER($E7),IF($E7>=-'Resumen Anual'!$B$22,"✅ OK",IF($E7>=-'Resumen Anual'!$B$23,"⚠️ Atención","🔴 Alerta")),"—"),"—") -> —
A8: Ventas Delivery (sin IVA) | B8: 0 | C8: 0 | D8: =C8-B8 -> 0 | E8: =IF($B8=0,"",IFERROR(($C8-$B8)/$B8,"")) | F8: =IFERROR(IF(ISNUMBER($E8),IF($E8>=-'Resumen Anual'!$B$22,"✅ OK",IF($E8>=-'Resumen Anual'!$B$23,"⚠️ Atención","🔴 Alerta")),"—"),"—") -> —
A9: Eventos / Catering (sin IVA) | B9: 0 | C9: 0 | D9: =C9-B9 -> 0 | E9: =IF($B9=0,"",IFERROR(($C9-$B9)/$B9,"")) | F9: =IFERROR(IF(ISNUMBER($E9),IF($E9>=-'Resumen Anual'!$B$22,"✅ OK",IF($E9>=-'Resumen Anual'!$B$23,"⚠️ Atención","🔴 Alerta")),"—"),"—") -> —
A10: TOTAL INGRESOS (sin IVA) | B10: =B6+B7+B8+B9 -> 0 | C10: =C6+C7+C8+C9 -> 0 | D10: =C10-B10 -> 0 | E10: =IF($B10=0,"",IFERROR(($C10-$B10)/$B10,"")) | F10: =IFERROR(IF(ISNUMBER($E10),IF($E10>=-'Resumen Anual'!$B$22,"✅ OK",IF($E10>=-'Resumen Anual'!$B$23,"⚠️ Atención","🔴 Alerta")),"—"),"—") -> —
A12: GASTOS
A13: Coste de comida (materia prima) | B13: 0 | C13: 0 | D13: =C13-B13 -> 0 | E13: =IF($B13=0,"",IFERROR(($C13-$B13)/$B13,"")) | F13: =IFERROR(IF(ISNUMBER($E13),IF($E13<='Resumen Anual'!$B$22,"✅ OK",IF($E13<='Resumen Anual'!$B$23,"⚠️ Atención","🔴 Alerta")),"—"),"—") -> —
A14: Coste de bebida (barra) | B14: 0 | C14: 0 | D14: =C14-B14 -> 0 | E14: =IF($B14=0,"",IFERROR(($C14-$B14)/$B14,"")) | F14: =IFERROR(IF(ISNUMBER($E14),IF($E14<='Resumen Anual'!$B$22,"✅ OK",IF($E14<='Resumen Anual'!$B$23,"⚠️ Atención","🔴 Alerta")),"—"),"—") -> —
A15: Personal (Labor) | B15: 0 | C15: 0 | D15: =C15-B15 -> 0 | E15: =IF($B15=0,"",IFERROR(($C15-$B15)/$B15,"")) | F15: =IFERROR(IF(ISNUMBER($E15),IF($E15<='Resumen Anual'!$B$22,"✅ OK",IF($E15<='Resumen Anual'!$B$23,"⚠️ Atención","🔴 Alerta")),"—"),"—") -> —
A16: Comisiones de plataformas (delivery) | B16: 0 | C16: 0 | D16: =C16-B16 -> 0 | E16: =IF($B16=0,"",IFERROR(($C16-$B16)/$B16,"")) | F16: =IFERROR(IF(ISNUMBER($E16),IF($E16<='Resumen Anual'!$B$22,"✅ OK",IF($E16<='Resumen Anual'!$B$23,"⚠️ Atención","🔴 Alerta")),"—"),"—") -> —
A17: Alquiler | B17: 0 | C17: 0 | D17: =C17-B17 -> 0 | E17: =IF($B17=0,"",IFERROR(($C17-$B17)/$B17,"")) | F17: =IFERROR(IF(ISNUMBER($E17),IF($E17<='Resumen Anual'!$B$22,"✅ OK",IF($E17<='Resumen Anual'!$B$23,"⚠️ Atención","🔴 Alerta")),"—"),"—") -> —
A18: Suministros | B18: 0 | C18: 0 | D18: =C18-B18 -> 0 | E18: =IF($B18=0,"",IFERROR(($C18-$B18)/$B18,"")) | F18: =IFERROR(IF(ISNUMBER($E18),IF($E18<='Resumen Anual'!$B$22,"✅ OK",IF($E18<='Resumen Anual'!$B$23,"⚠️ Atención","🔴 Alerta")),"—"),"—") -> —
A19: Marketing | B19: 0 | C19: 0 | D19: =C19-B19 -> 0 | E19: =IF($B19=0,"",IFERROR(($C19-$B19)/$B19,"")) | F19: =IFERROR(IF(ISNUMBER($E19),IF($E19<='Resumen Anual'!$B$22,"✅ OK",IF($E19<='Resumen Anual'!$B$23,"⚠️ Atención","🔴 Alerta")),"—"),"—") -> —
A20: Administración / Otros | B20: 0 | C20: 0 | D20: =C20-B20 -> 0 | E20: =IF($B20=0,"",IFERROR(($C20-$B20)/$B20,"")) | F20: =IFERROR(IF(ISNUMBER($E20),IF($E20<='Resumen Anual'!$B$22,"✅ OK",IF($E20<='Resumen Anual'!$B$23,"⚠️ Atención","🔴 Alerta")),"—"),"—") -> —
A21: TOTAL GASTOS | B21: =SUM(B13:B20) -> 0 | C21: =SUM(C13:C20) -> 0 | D21: =C21-B21 -> 0 | E21: =IF($B21=0,"",IFERROR(($C21-$B21)/$B21,"")) | F21: =IFERROR(IF(ISNUMBER($E21),IF($E21<='Resumen Anual'!$B$22,"✅ OK",IF($E21<='Resumen Anual'!$B$23,"⚠️ Atención","🔴 Alerta")),"—"),"—") -> —
A23: EBITDA | B23: =B10-B21 -> 0 | C23: =C10-C21 -> 0 | D23: =C23-B23 -> 0 | E23: =IF($B23=0,"",IFERROR(($C23-$B23)/ABS($B23),"")) | F23: =IFERROR(IF(ISNUMBER($E23),IF($E23>=-'Resumen Anual'!$B$22,"✅ OK",IF($E23>=-'Resumen Anual'!$B$23,"⚠️ Atención","🔴 Alerta")),"—"),"—") -> —
A24: Margen EBITDA % | B24: =IF(B10=0,"",B23/B10) | C24: =IF(C10=0,"",C23/C10) | D24: =IFERROR($C24-$B24,"") | E24: p.p. | F24: =IFERROR(IF(ISNUMBER($D24),IF($D24>=-'Resumen Anual'!$B$24,"✅ OK",IF($D24>=-'Resumen Anual'!$B$25,"⚠️ Atención","🔴 Alerta")),"—"),"—") -> —
A26: RATIOS AUTOMÁTICOS
A27: Food Cost % (sobre ventas de comida) | B27: =IF((B10-B7)<=0,"",B13/(B10-B7)) | C27: =IF((C10-C7)<=0,"",C13/(C10-C7)) | D27: =IFERROR($C27-$B27,"") | E27: p.p. | F27: =IFERROR(IF(ISNUMBER($D27),IF($D27<='Resumen Anual'!$B$24,"✅ OK",IF($D27<='Resumen Anual'!$B$25,"⚠️ Atención","🔴 Alerta")),"—"),"—") -> —
A28: Beverage Cost % (sobre ventas de barra) | B28: =IF(B7=0,"",B14/B7) | C28: =IF(C7=0,"",C14/C7) | D28: =IFERROR($C28-$B28,"") | E28: p.p. | F28: =IFERROR(IF(ISNUMBER($D28),IF($D28<='Resumen Anual'!$B$24,"✅ OK",IF($D28<='Resumen Anual'!$B$25,"⚠️ Atención","🔴 Alerta")),"—"),"—") -> —
A29: Labor Cost % | B29: =IF(B10=0,"",B15/B10) | C29: =IF(C10=0,"",C15/C10) | D29: =IFERROR($C29-$B29,"") | E29: p.p. | F29: =IFERROR(IF(ISNUMBER($D29),IF($D29<='Resumen Anual'!$B$24,"✅ OK",IF($D29<='Resumen Anual'!$B$25,"⚠️ Atención","🔴 Alerta")),"—"),"—") -> —
A30: Prime Cost % (comida + bebida + personal) | B30: =IF(B10=0,"",(B13+B14+B15)/B10) | C30: =IF(C10=0,"",(C13+C14+C15)/C10) | D30: =IFERROR($C30-$B30,"") | E30: p.p. | F30: =IFERROR(IF(ISNUMBER($D30),IF($D30<='Resumen Anual'!$B$24,"✅ OK",IF($D30<='Resumen Anual'!$B$25,"⚠️ Atención","🔴 Alerta")),"—"),"—") -> —
A32: © 2026 AI Chef Pro · aichef.pro

Sheet Nov
A1: P&L Nov — Real vs Presupuesto
A2: AI Chef Pro · aichef.pro — Kit Plan Financiero para Restaurantes
A4: Concepto | B4: Presupuesto (€) | C4: Real (€) | D4: Desviación (€) | E4: Desviación % | F4: Semáforo
A5: INGRESOS
A6: Ventas Comedor (sin IVA) | B6: 0 | C6: 0 | D6: =C6-B6 -> 0 | E6: =IF($B6=0,"",IFERROR(($C6-$B6)/$B6,"")) | F6: =IFERROR(IF(ISNUMBER($E6),IF($E6>=-'Resumen Anual'!$B$22,"✅ OK",IF($E6>=-'Resumen Anual'!$B$23,"⚠️ Atención","🔴 Alerta")),"—"),"—") -> —
A7: Ventas Barra (sin IVA) | B7: 0 | C7: 0 | D7: =C7-B7 -> 0 | E7: =IF($B7=0,"",IFERROR(($C7-$B7)/$B7,"")) | F7: =IFERROR(IF(ISNUMBER($E7),IF($E7>=-'Resumen Anual'!$B$22,"✅ OK",IF($E7>=-'Resumen Anual'!$B$23,"⚠️ Atención","🔴 Alerta")),"—"),"—") -> —
A8: Ventas Delivery (sin IVA) | B8: 0 | C8: 0 | D8: =C8-B8 -> 0 | E8: =IF($B8=0,"",IFERROR(($C8-$B8)/$B8,"")) | F8: =IFERROR(IF(ISNUMBER($E8),IF($E8>=-'Resumen Anual'!$B$22,"✅ OK",IF($E8>=-'Resumen Anual'!$B$23,"⚠️ Atención","🔴 Alerta")),"—"),"—") -> —
A9: Eventos / Catering (sin IVA) | B9: 0 | C9: 0 | D9: =C9-B9 -> 0 | E9: =IF($B9=0,"",IFERROR(($C9-$B9)/$B9,"")) | F9: =IFERROR(IF(ISNUMBER($E9),IF($E9>=-'Resumen Anual'!$B$22,"✅ OK",IF($E9>=-'Resumen Anual'!$B$23,"⚠️ Atención","🔴 Alerta")),"—"),"—") -> —
A10: TOTAL INGRESOS (sin IVA) | B10: =B6+B7+B8+B9 -> 0 | C10: =C6+C7+C8+C9 -> 0 | D10: =C10-B10 -> 0 | E10: =IF($B10=0,"",IFERROR(($C10-$B10)/$B10,"")) | F10: =IFERROR(IF(ISNUMBER($E10),IF($E10>=-'Resumen Anual'!$B$22,"✅ OK",IF($E10>=-'Resumen Anual'!$B$23,"⚠️ Atención","🔴 Alerta")),"—"),"—") -> —
A12: GASTOS
A13: Coste de comida (materia prima) | B13: 0 | C13: 0 | D13: =C13-B13 -> 0 | E13: =IF($B13=0,"",IFERROR(($C13-$B13)/$B13,"")) | F13: =IFERROR(IF(ISNUMBER($E13),IF($E13<='Resumen Anual'!$B$22,"✅ OK",IF($E13<='Resumen Anual'!$B$23,"⚠️ Atención","🔴 Alerta")),"—"),"—") -> —
