Workbook

Sheet 0. Assumptions
A1: ASSUMPTIONS — the RATES and DRIVERS of the model are typed here
A2: Change the GREEN cells: the rest of the workbook recalculates on its own. Expense items are typed on their own tab (also in green) and are not repeated here. Amounts are in your currency.
A3: BUSINESS ACTIVITY
A4: Covers per day (year-1 average) | B4: 130 | C4: Equivalent covers per day, year-1 average: about 55 dine-in (40 seats, no patio), about 55 from take-out, pickup and pre-orders, and about 20 from delivery marketplaces. A family meal counts as 3.5 covers, and a Sunday runs about 1.6 to 1.8 times a weekday (roughly 65-70 birds on the rotisseries) (Kit estimate). Compare it with the foot traffic on your street on a Sunday at noon and a Tuesday at lunch, and with your own test pre-orders
A5: Average check (excl. sales tax) | B5: 17.5 | C5: Per cover, EXCL. sales tax and tip: plates average $12.79 (a quarter chicken with 2 sides at $13.00 for 35% of covers, a half with 2 sides at $17.50 for 15%, a family meal at $34.00 counted as 3.5 covers for 30%, and a chicken sandwich or bowl at $13.50 for 20%), plus about $1.50 of extra sides, $0.36 of dessert, $0.30 of sauces and 0.65 drinks at $3.84 (Kit estimate). Family meals with a whole chicken run $31-34 in mid-size cities (menus read in October 2026). The "Menu price incl. sales tax (calculated)" row below shows the price with your local rate applied
A6: Operating days per year | B6: 360 | C6: 365 days minus Thanksgiving, Christmas Day, New Year's Day and 2 deep-clean days for the hood and the rotisseries, rounded to 360: the restaurant is open 7 days a week and holidays open like a Sunday. It is the SAME figure for the P&L, break-even, scenarios and staffing hours
A7: Volume growth in year 2 | B7: 0.06 | C7: Repeat neighborhood regulars, Sunday family meals and pre-orders that become a habit in year 2. It applies to covers at the same average check; staffing does NOT rise with this percentage: it comes from the "Staffing" tab
A8: Volume growth in year 3 | B8: 0.04 | C8: On top of year 2. Conservative: the ceiling is set by the two rotisseries (48 birds per load each) before the Sunday lunch peak and by the counter at that peak
A9: Menu price incl. sales tax (calculated) | B9: =IFERROR(IF($B$5="","",$B$5*(1+SUMPRODUCT('3-Year P&L'!$E$10:$E$11,'3-Year P&L'!$G$10:$G$11))),"") -> 18.9 | C9: =IFERROR("Average check excl. sales tax plus the weighted sales tax of your sales lines ("&TEXT(SUMPRODUCT('3-Year P&L'!$E$10:$E$11,'3-Year P&L'!$G$10:$G$11)*100,"0")&"%), rounded. In the US, menu prices usually exclude sales tax and it is added at the register; the beverage share in column H of the beverage line of the P&L only moves this average if your state taxes alcohol at another rate. "&"In the UK, menu prices include VAT.","") -> Average check excl. sales tax plus the weighted sales tax of your sales lines (8%), rounded. In the US, menu prices usually exclude sales tax and it is added at the register; the beverage share in column H of the beverage line of the P&L only moves this average if your state taxes alcohol at another rate. In the UK, menu prices include VAT.
A10: SALES MIX AND COST OF GOODS SOLD
A11: FOOD share of total sales | B11: 0.86 | C11: Share of FOOD in total sales. It is an INPUT: change it here and the P&L, the cash flow and the sales tax collected recalculate on their own
A12: BEVERAGE share of total sales | B12: =IFERROR(IF(COUNT(B11)=0,"",1-B11),"") -> 0.14 | C12: Calculated as the remainder: food + beverage = 100%
A13: Cost of goods sold on FOOD sales | B13: 0.29 | C13: Cost of goods sold on food sales: the menu averages about 29% of menu price (family meal about 29.6%, quarter with 2 sides about 28.8%, half with 2 sides about 30.0%, chicken sandwich or bowl about 22%). A marinated bird costs about $5.99 (3.0 lb (1.4 kg) at $1.75 a lb plus marinade and 5% display shrink). Chicken prices are Kit estimates: enter your distributor's and cost every plate with the Rotisserie Chicken Yield & Costing Calculator
A14: Cost of goods sold on BEVERAGE sales | B14: 0.22 | C14: Weighted average of sodas (Peruvian golden soda among them), house-made chicha morada, beer and wine against their menu prices: about 22%. Soft drinks cost a small share of their price, while beer and wine run higher and pull the average up. If your beer distributor lends you the cooler, get the terms in writing
A15: Disposables and packaging as % of sales | B15: 0.04 | C15: Family-meal boxes, vented clamshells, foil bags, sauce cups, heated-display bags, napkins and gloves for everything that leaves the restaurant, plus take-out containers for leftovers: about 4% of sales (no supplier posts a rate: Kit estimate). Some cities and states restrict foam and single-use plastics or require utensils only on request: check your local packaging ordinances
A16: Delivery share of total sales | B16: 0.15 | C16: Sales through third-party delivery marketplaces (DoorDash, Uber Eats, Grubhub) as a share of total sales. Counter orders, direct pickup, pre-orders by phone or web and party trays pay no commission and do not go here. A whole rotisserie chicken travels well, but fries and yuca fries arrive soft: do not go above this share without testing it
A17: Delivery platform fee | B17: 0.25 | C17: The example uses 25%, a Plus plan on DoorDash or Uber Eats (the Basic plan is about 15% with little visibility, Premier is 30%, and app pickup orders add 6-10%). Check your contract. If you deliver yourself, enter 0 and add the driver to the "Staffing" tab as a W-2 employee, with hired and non-owned auto insurance (check your state)
A18: Card processing fee | B18: 0.03 | C18: Card and mobile wallet (contactless) processing fees on total sales. Ask your POS provider for its rate
A19: LABOR
A20: Employer payroll taxes | B20: 0.1 | C20: FICA (Social Security 6.2% + Medicare 1.45%) + federal and state unemployment taxes (FUTA / SUTA) + workers' comp. About 10% in total: adjust it to your state and your insurance carrier
A21: Monthly pay periods per year (keep 12) | B21: 12 | C21: Annual gross pay = monthly gross pay × this number. Keep 12 in the US: it counts the monthly salaries the model pays in a year, not how often you run payroll (weekly or biweekly payroll pays the same annual amount)
A22: Federal minimum wage, annual full-time | B22: 15080 | C22: US federal minimum wage: 7.25 per hour × 2,080 hours = 15,080 per year for a full-time job. Your state or city may set a higher floor: enter it in the state / local minimum wage cell below. Check the current rates at dol.gov
A23: RENT AND FIXED COSTS
A24: Monthly rent | B24: 3733 | C24: About 1,600 sq ft (149 sq m) with a Type I hood and exhaust route to the roof possible (that is the filter for the space): a kitchen with the two rotisseries in view of the street, a counter with a heated display, a dining room with 40 seats, restrooms (one ADA-accessible) and storage, in a residential or retail area of a mid-size city with easy parking for pickup, second-generation space with no key money: about $28 per sq ft a year (Kit estimate, editable). The weight of rent on sales is calculated by the workbook itself in the rent row of the "3-Year P&L"
A25: Security deposit (months of rent) | B25: 2 | C25: Security deposit, in months of rent. The example uses two; commercial leases commonly ask for one to three, and some landlords also want a personal guarantee: check it with your attorney
A26: Monthly utilities (electricity, water, gas) | B26: 1800 | C26: Gas for the two rotisseries and the fryers, electricity for the walk-in, the hood and makeup air and HVAC, and water. Commercial gas rates are a Kit estimate: ask the landlord for the space's utility history and ask your utility for the rate
A27: Insurance (per year) | B27: 6500 | C27: General liability, liquor liability (beer & wine), property coverage with equipment breakdown for the refrigeration, and workers' comp. Tell the carrier you cook with gas rotisseries and fryers: it changes the premium and the terms. Rates vary by state, so get at least two quotes
A28: Miscellaneous and contingency as % of sales | B28: 0.01 | C28: Cushion for operating costs you did not budget (small repairs, spare spits or smallwares that break, menu tests)
A29: FINANCING
A30: Owner's equity contributed | B30: 120000 | C30: Owner's cash. Lenders usually expect an owner equity injection (often around 10% for SBA start-ups; many want 20-30%) toward the cash need
A31: Loan requested | B31: 216000 | C31: Principal requested. The "Financing" tab compares what you put in with the cash need on "Startup Costs" and tells you whether you have a surplus or a shortfall: adjust the loan with that figure. The example is an SBA 7(a) loan, which you apply for through your lender (SBA Microloans go up to $50,000)
A32: Nominal annual interest rate (not APR) | B32: 0.1 | C32: Nominal annual rate, not APR. The example uses 10%. Ask two lenders for a quote before you set it; the rotisseries, the walk-in and the fryers can also be financed through equipment financing or a lease: compare
A33: Loan term (years) | B33: 10 | C33: Total years, interest-only period included
A34: Interest-only period (years) | B34: 0 | C34: Years you pay interest only before principal repayment starts. The example uses 0, because SBA 7(a) loans amortize from the start. A year of interest only can ease the build-out, the hood, the gas lines and the first months of trading: ask your lender, and check the cash slack of the first repayment year on the "Break-Even" tab
A35: Working capital (months of fixed costs) | B35: 3 | C35: Three months of fixed costs: the cushion for the ramp-up, which with Month 1 in January falls on the slowest months of the year (January and February)
A36: TAXES
A37: Effective income tax rate (years 1-2) | B37: 0.25 | C37: Example: 21% federal rate for a C corporation plus state tax, rounded to 25%. If you operate as a sole proprietorship, LLC taxed as a pass-through or S corporation, the business itself pays 0% here and you pay tax on the profit personally: set this to 0 and budget for your personal tax separately. The model applies this rate to the first two years with positive taxable income
A38: Effective income tax rate (from year 3) | B38: 0.25 | C38: From the third year with positive taxable income. Same example rate (21% federal C corporation + state). Confirm the rate that applies to you with your accountant and change it here
A39: Sales tax rate on sales | B39: 0.08 | C39: Example rate: state + local sales tax combined. It varies widely by state and city: look up yours. UK: 20% VAT on hot food and dine-in
A40: Sales tax rate on alcohol to go | B40: 0.08 | C40: One sales tax rate for the whole example (8%: state plus local, so look up yours). In this workbook it also applies to alcohol sold to go, and it equals the on-site rate, so the two rows give the same result. There is no input credit: the workbook does not recover sales tax on purchases, so that row is 0. Some states tax food to go differently, so check yours. Utilities, equipment and services use the rate in the cell below
...

Sheet Startup Costs
A1: ROTISSERIE CHICKEN RESTAURANT BUSINESS PLAN: PERUVIAN-STYLE COUNTER SERVICE
A2: Estimated Startup Costs — counter-service rotisserie chicken restaurant with two gas rotisseries and 40 seats
A3: US kit example (2026) — replace with your own quotes.
A5: Item | B5: Amount | C5: % of startup costs | D5: Notes | E5: Taxable / recoverable tax?
A6: STARTUP COSTS | B6: =IFERROR(IF(COUNT(B7:B27)=0,"",SUM(B7:B27)),"") -> 237832 | C6: =IFERROR(B6/$B$30,"") -> 0.70844838
A7: Architect, MEP & hood drawings, plan review & permit fees | B7: 13000 | C7: =IFERROR(B7/$B$30,"") -> 0.038724095 | D7: Architect, MEP and hood drawings, plan review and permit fees for the build-out, the hood and the gas lines. The beer & wine license varies widely by state in cost and timing: ask your state agency early and add your own quote; this line does not assume one | E7: Yes
A8: Build-out (second-generation space, 1,600 sq ft), signage & facade | B8: 53000 | C8: =IFERROR(B8/$B$30,"") -> 0.15787516 | D8: Kitchen with washable wall finish and slip-resistant floor (also around the rotisseries), restrooms (one ADA-accessible), the service counter, ceilings and acoustic treatment, plus signage and facade ($5,000), so the rotisseries can be seen from the street. Second-generation space of 1,600 sq ft (149 sq m). Kit estimate: get two bids | E8: Yes
A9: Type I hood (about 14 ft), UL 300 fire suppression & makeup air | B9: 26000 | C9: =IFERROR(B9/$B$30,"") -> 0.077448189 | D9: A Type I hood of about 14 ft (4.3 m) with UL 300 fire suppression and makeup air over the two rotisseries, the two fryers and the range. Hood packages run $5,000-$28,000 and the example budgets $26,000. A charcoal rotisserie is a solid-fuel appliance (NFPA 96: its own exhaust, a spark arrester and daily ash removal), so it is a variant, not the example. No manufacturer posts a price per foot: ask your mechanical contractor for a quote with your drawings, and ask the fire marshal in writing | E9: Yes
A10: Electrical service, panel & gas lines | B10: 11000 | C10: =IFERROR(B10/$B$30,"") -> 0.032766542 | D10: Electrical service and panel for the refrigeration, hood, makeup air, HVAC, dish machine and rotisserie motors, plus the gas lines. Two gas rotisseries of about 177,500 BTU together need a gas service and regulator sized for them, with a gas permit. Ask for the available electrical and gas capacity BEFORE you sign the lease: a new service from the utility can take weeks or months. | E10: Yes
A11: Plumbing, grease interceptor & HVAC | B11: 13000 | C11: =IFERROR(B11/$B$30,"") -> 0.038724095 | D11: Hot and cold water in the kitchen, drains with a grease interceptor ($3,500-$7,500) and HVAC for the dining room and kitchen, installed by licensed contractors with their permits and inspections | E11: Yes
A12: Commercial gas rotisseries × 2 (8 spits, 48 birds per load each) | B12: 13000 | C12: =IFERROR(B12/$B$30,"") -> 0.038724095 | D12: Two gas commercial rotisseries with 8 spits and 48 birds per load each. WebstaurantStore lists the Pegasus CR-8G at $6,011 retail (Oct 2026); the example budgets $13,000 for the pair with freight and installation. An electric rotisserie (Alto-Shaam AR-7E at $11,912) and a listed charcoal rotisserie ($27,500 to $35,950) are variants. Size the rotisseries with your Sunday count | E12: Yes
A13: Heated display merchandiser, steam table & holding cabinet | B13: 5500 | C13: =IFERROR(B13/$B$30,"") -> 0.016383271 | D13: Heated display merchandiser that holds whole chickens at 135 °F (57 °C) or above (models run from an Avantco HDC-48 at $599 to an Alto-Shaam ED3-72 at $11,207), plus a steam table and a holding cabinet for the sides | E13: Yes
A14: Fryers × 2 (50 lb) & range with stock-pot burners | B14: 7000 | C14: =IFERROR(B14/$B$30,"") -> 0.020851436 | D14: Two 50 lb (23 kg) fryers for the yuca fries and fries (an Avantco FF50 lists at $799 and a Pitco 65C+S at $1,848) and a range with stock-pot burners for the rice & beans, the sauces and the chicha morada. Kit estimate for the range: get a quote | E14: Yes
A15: Walk-in cooler (6×8) | B15: 12800 | C15: =IFERROR(B15/$B$30,"") -> 0.038128339 | D15: A 6×8 ft (1.8×2.4 m) walk-in cooler for the raw chicken and the marinade: birds marinate 24-48 hours. A Norlake Kold Locker lists at $12,808 (WebstaurantStore, Oct 2026) | E15: Yes
A16: Refrigerated prep table & reach-in freezer | B16: 6500 | C16: =IFERROR(B16/$B$30,"") -> 0.019362047 | D16: Refrigerated prep table and a reach-in freezer for the frozen yuca. Raw and marinated chicken stays at 41 °F (5 °C) or below, on the bottom shelf and date-marked; the example buys birds WOG (without giblets). Kit estimate: get two quotes | E16: Yes
A17: 3-comp sink, dish machine, hand & poultry prep sinks, shelving & stainless | B17: 11500 | C17: =IFERROR(B17/$B$30,"") -> 0.03425593 | D17: 3-compartment sink, dish machine, hand sinks and a separate prep sink and stainless table for the raw chicken, kept apart from where food is served, plus shelving. Check that your spits fit the dish machine. Kit estimate | E17: Yes
A18: Smallwares & sauce station (spare spits, hotel pans, probes, blender, marinating tubs) | B18: 7500 | C18: =IFERROR(B18/$B$30,"") -> 0.022340824 | D18: Spare spits, hotel pans, probes, scales, color-coded boards, a packing station, a sauce station (blender, squeeze bottles, portion cups), marinating tubs, the required public notices (health permit, beer & wine license, labor law posters) and allergen signs (the 9 major allergens, including sesame). Food handler cards and the CFPM exam are budgeted in the P&L | E18: Yes
... A24: Opening inventory | B24: 5000 | C24: =IFERROR(B24/$B$30,"") -> 0.014893883 | D24: Chicken, frozen yuca and fries, oil, marinade ingredients (soy sauce, aji panca, huacatay, cumin), packaging, sodas, beer and wine | E24: Yes
A25: Security deposit | B25: =IFERROR(IF('0. Assumptions'!$B$24="","",'0. Assumptions'!$B$24*'0. Assumptions'!$B$25),"") -> 7466 | C25: =IFERROR(B25/$B$30,"") -> 0.022239545 | D25: =IFERROR(""&TEXT('0. Assumptions'!$B$25,"0")&IF('0. Assumptions'!$B$25=1," month"," months")&" of rent, from ""0. Assumptions"". Refundable when the lease ends: it is not depreciated and carries no tax","") -> 2 months of rent, from "0. Assumptions". Refundable when the lease ends: it is not depreciated and carries no tax | E25: No
A26: Rent paid before opening | B26: =IFERROR(IF('0. Assumptions'!$B$24="","",'0. Assumptions'!$B$24*'0. Assumptions'!$B$54),"") -> 7466 | C26: =IFERROR(B26/$B$30,"") -> 0.022239545 | D26: =IFERROR("Rent "&IF('0. Assumptions'!$B$54=1,"for the month","for the "&TEXT('0. Assumptions'!$B$54,"0")&" months")&" of build-out and permits before opening. It does not overlap the P&L, which starts on opening day: its twelve months are twelve trading months","") -> Rent for the 2 months of build-out and permits before opening. It does not overlap the P&L, which starts on opening day: its twelve months are twelve trading months | E26: Yes
A27: Build-out and setup contingency | B27: =IFERROR(IF(COUNT(B7,B8,B9,B10,B11)=0,"",ROUND((B7+B8+B9+B10+B11)*'0. Assumptions'!$B$55,0)),"") -> 11600 | C27: =IFERROR(B27/$B$30,"") -> 0.034553808 | D27: =IFERROR("At "&TEXT('0. Assumptions'!$B$55,"0%")&" of the BUILD-OUT items of this block (architect, MEP & hood drawings and permit fees; build-out, signage & facade; Type I hood (about 14 ft), UL 300 fire suppression & makeup air; "&"electrical service, panel & gas lines; plumbing, grease interceptor & HVAC), not of the whole block: the rotisseries, the equipment and the other items are left out. No lender funds a build-out without a cushion: the percentage is in ""0. Assumptions""","") -> At 10% of the BUILD-OUT items of this block (architect, MEP & hood drawings and permit fees; build-out, signage & facade; Type I hood (about 14 ft), UL 300 fire suppression & makeup air; electrical service, panel & gas lines; plumbing, grease interceptor & HVAC), not of the whole block: the rotisseries, the equipment and the other items are left out. No lender funds a build-out without a cushion: the percentage is in "0. Assumptions" | E27: Yes
A28: WORKING CAPITAL | B28: =IFERROR(IF(B29="","",B29),"") -> 97876.3 | C28: =IFERROR(B28/$B$30,"") -> 0.29155162
A29: Operating cushion until break-even | B29: =IFERROR(IF('0. Assumptions'!$B$35*('3-Year P&L'!$B$37-'3-Year P&L'!$B$35)=0,"",'0. Assumptions'!$B$35*('3-Year P&L'!$B$37-'3-Year P&L'!$B$35)/12),"") -> 97876.3 | C29: =IFERROR(B29/$B$30,"") -> 0.29155162 | D29: =IFERROR("Covers "&TEXT('0. Assumptions'!$B$35,"0")&IF('0. Assumptions'!$B$35=1," month"," months")&" of year-1 CASH fixed costs (the P&L fixed costs minus depreciation, which is not paid out), the minimum the Instructions of this workbook ask for","") -> Covers 3 months of year-1 CASH fixed costs (the P&L fixed costs minus depreciation, which is not paid out), the minimum the Instructions of this workbook ask for | E29: No
A30: TOTAL STARTUP COSTS (sum of the blocks) | B30: =IFERROR(B6+B28,"") -> 335708.3 | D30: =IFERROR("The percentages in column C are read on this figure, which includes the working capital ("&TEXT(C28,"0%")&" of the total). To compare the breakdown with another plan, use the CAPEX row below.","") -> The percentages in column C are read on this figure, which includes the working capital (29% of the total). To compare the breakdown with another plan, use the CAPEX row below.
A31: CAPEX (startup costs excluding working capital) | B31: =IFERROR(B30-B28,"") -> 237832 | D31: What you buy: build-out, equipment, launch and formation costs. The cash cushion is not an investment: it is working capital
A32: Recoverable input tax on capex | B32: =IFERROR(IF(B30="","",SUMIF($E$7:$E$27,"Yes",$B$7:$B$27)*'0. Assumptions'!$B$41),"") -> 0 | D32: =IFERROR("At "&TEXT('0. Assumptions'!$B$41,"0%")&" on the items marked ""Yes"" in the tax column. US: the sales tax you pay on equipment is part of its cost and is not recovered, so this rate is 0. UK (VAT-registered): 20%, reclaimed on your VAT return, but you pay it first, so the loan has to cover it","") -> At 0% on the items marked "Yes" in the tax column. US: the sales tax you pay on equipment is part of its cost and is not recovered, so this rate is 0. UK (VAT-registered): 20%, reclaimed on your VAT return, but you pay it first, so the loan has to cover it
A33: TOTAL CASH NEEDED AT LAUNCH | B33: =IFERROR(B30+B32,"") -> 335708.3 | D33: This is the figure the Financing tab has to cover
A34: DEPRECIATION BASES (not added to startup costs)
A35: Build-out, fixtures and setup | B35: =IFERROR(IF(B7="","",B7+B8+B9+B10+B11+B27),"") -> 127600 | D35: =IFERROR("Depreciated over "&TEXT('0. Assumptions'!$B$44,"0")&" years","") -> Depreciated over 10 years
A36: Machinery, furniture and equipment | B36: =IFERROR(IF(B12="","",B12+B13+B14+B15+B16+B17+B18+B19+B20+B21),"") -> 82300 | D36: =IFERROR("Depreciated over "&TEXT('0. Assumptions'!$B$45,"0")&" years","") -> Depreciated over 7 years
A37: Annual depreciation of fixed assets | B37: =IFERROR(B35/MAX(1,'0. Assumptions'!$B$44)+B36/MAX(1,'0. Assumptions'!$B$45),"") -> 24517.143 | D37: =IFERROR("Not depreciated, because they are not fixed assets: LLC, legal and food safety plan; branding, website, photos and launch; opening inventory; security deposit; pre-opening rent and the working capital reserve. They add up to "&TEXT(B30-B35-B36,"#,##0")&" of the "&TEXT(B30,"#,##0")&" total investment.","") -> Not depreciated, because they are not fixed assets: LLC, legal and food safety plan; branding, website, photos and launch; opening inventory; security deposit; pre-opening rent and the working capital reserve. They add up to 125808 of the 335708 total investment.

Sheet 3-Year P&L
A1: PRO FORMA P&L — 3 YEARS
A2: Base case — rotisserie chicken restaurant: counter, pickup & pre-orders, delivery and dine-in
A4: Item | B4: Year 1 | C4: Year 2 | D4: Year 3 | E4: % of sales (year 1) | F4: Notes | G4: Sales tax rate on the line (%) | H4: Beverage share taxed at the alcohol rate in B40 (%)
A5: REVENUE
A6: Covers per day (average) | B6: =IFERROR(IF('0. Assumptions'!$B$4="","",'0. Assumptions'!$B$4),"") -> 130 | C6: =IFERROR(B6*(1+'0. Assumptions'!$B$7),"") -> 137.8 | D6: =IFERROR(C6*(1+'0. Assumptions'!$B$8),"") -> 143.312 | F6: Growth for years 2 and 3 is set in "0. Assumptions"
A7: Average check (excl. sales tax) | B7: =IFERROR(IF('0. Assumptions'!$B$5="","",'0. Assumptions'!$B$5),"") -> 17.5 | C7: =IFERROR(IF(B7="","",B7),"") -> 17.5 | D7: =IFERROR(IF(C7="","",C7),"") -> 17.5 | F7: Held constant at year-1 prices: a price increase is a separate decision
A8: Operating days per year | B8: =IFERROR(IF('0. Assumptions'!$B$6="","",'0. Assumptions'!$B$6),"") -> 360 | C8: =IFERROR(IF(B8="","",B8),"") -> 360 | D8: =IFERROR(IF(C8="","",C8),"") -> 360
A9: TOTAL REVENUE (excl. sales tax) | B9: =IFERROR(IF(B6*B7*B8=0,"",B6*B7*B8),"") -> 819000 | C9: =IFERROR(IF(C6*C7*C8=0,"",C6*C7*C8),"") -> 868140 | D9: =IFERROR(IF(D6*D7*D8=0,"",D6*D7*D8),"") -> 902865.6 | E9: =IFERROR(IF(B9="","",1),"") -> 1
A10: Food sales (rotisserie chicken plates, family meals & sides: counter, pickup, pre-orders, delivery & dine-in) | B10: =IFERROR(IF(B9="","",B9*$E$10),"") -> 704340 | C10: =IFERROR(IF(C9="","",C9*$E$10),"") -> 746600.4 | D10: =IFERROR(IF(D9="","",D9*$E$10),"") -> 776464.42 | E10: =IFERROR(IF('0. Assumptions'!$B$11="","",'0. Assumptions'!$B$11),"") -> 0.86 | F10: Rotisserie chicken (quarter, half and whole), family meals, sandwiches and bowls, and sides: about 42.5% dine-in, about 42.5% pickup and pre-orders, and 15% through delivery marketplaces. One sales tax rate in the example, whether guests eat in or take it to go; some states tax food to go differently, so check yours | G10: =IFERROR(IF(B9="","",'0. Assumptions'!$B$39),"") -> 0.08
A11: Beverage sales (sodas, chicha morada, beer & wine) | B11: =IFERROR(IF(B9="","",B9*$E$11),"") -> 114660 | C11: =IFERROR(IF(C9="","",C9*$E$11),"") -> 121539.6 | D11: =IFERROR(IF(D9="","",D9*$E$11),"") -> 126401.18 | E11: =IFERROR(IF('0. Assumptions'!$B$12="","",'0. Assumptions'!$B$12),"") -> 0.14 | F11: Dine-in beverages and the drinks that go out with orders (sodas, chicha morada, beer & wine) · Column H is the share of beverage sales taxed at the alcohol rate in "0. Assumptions" B40. With the example rates (B39 = B40 = 8%: state + local) it changes nothing. Some states tax alcohol differently: type your alcohol rate in B40 and the alcohol share of beverage sales here | G11: =IFERROR(IF(B9="","",H11*'0. Assumptions'!$B$40+(1-H11)*'0. Assumptions'!$B$39),"") -> 0.08 | H11: 0.17
A12: VARIABLE COSTS
A13: Cost of goods sold — food | B13: =IFERROR(IF(B9="","",B9*'0. Assumptions'!$B$11*'0. Assumptions'!$B$13),"") -> 204258.6 | C13: =IFERROR(IF(C9="","",C9*'0. Assumptions'!$B$11*'0. Assumptions'!$B$13),"") -> 216514.12 | D13: =IFERROR(IF(D9="","",D9*'0. Assumptions'!$B$11*'0. Assumptions'!$B$13),"") -> 225174.68 | E13: =IFERROR(B13/$B$9,"") -> 0.2494 | F13: =IFERROR("At "&TEXT('0. Assumptions'!$B$13,"0%")&" of FOOD sales, not of total sales: beverages have their own line · "&"whole chickens, marinade, cooking oil, frozen yuca and fries, rice, beans, produce and sauce ingredients: check it against your distributor invoices and the Rotisserie Chicken Yield & Costing Calculator","") -> At 29% of FOOD sales, not of total sales: beverages have their own line · whole chickens, marinade, cooking oil, frozen yuca and fries, rice, beans, produce and sauce ingredients: check it against your distributor invoices and the Rotisserie Chicken Yield & Costing Calculator | G13: 0
A14: Cost of goods sold — beverage | B14: =IFERROR(IF(B9="","",B9*'0. Assumptions'!$B$12*'0. Assumptions'!$B$14),"") -> 25225.2 | C14: =IFERROR(IF(C9="","",C9*'0. Assumptions'!$B$12*'0. Assumptions'!$B$14),"") -> 26738.712 | D14: =IFERROR(IF(D9="","",D9*'0. Assumptions'!$B$12*'0. Assumptions'!$B$14),"") -> 27808.26 | E14: =IFERROR(B14/$B$9,"") -> 0.0308 | F14: =IFERROR("At "&TEXT('0. Assumptions'!$B$14,"0%")&" of BEVERAGE sales","") -> At 22% of BEVERAGE sales | G14: =IFERROR(IF(B9="","",'0. Assumptions'!$B$41),"") -> 0
A15: Disposables and packaging | B15: =IFERROR(IF(B9="","",B9*'0. Assumptions'!$B$15),"") -> 32760 | C15: =IFERROR(IF(C9="","",C9*'0. Assumptions'!$B$15),"") -> 34725.6 | D15: =IFERROR(IF(D9="","",D9*'0. Assumptions'!$B$15),"") -> 36114.624 | E15: =IFERROR(B15/$B$9,"") -> 0.04 | G15: =IFERROR(IF(B9="","",'0. Assumptions'!$B$41),"") -> 0
A16: Delivery platform fees | B16: =IFERROR(IF(B9="","",B9*'0. Assumptions'!$B$16*'0. Assumptions'!$B$17),"") -> 30712.5 | C16: =IFERROR(IF(C9="","",C9*'0. Assumptions'!$B$16*'0. Assumptions'!$B$17),"") -> 32555.25 | D16: =IFERROR(IF(D9="","",D9*'0. Assumptions'!$B$16*'0. Assumptions'!$B$17),"") -> 33857.46 | E16: =IFERROR(B16/$B$9,"") -> 0.0375 | F16: Applied to the sales of THAT CHANNEL. With 0% delivery in Assumptions, this line is zero | G16: =IFERROR(IF(B9="","",'0. Assumptions'!$B$41),"") -> 0
A17: Card processing fees | B17: =IFERROR(IF(B9="","",B9*'0. Assumptions'!$B$18),"") -> 24570 | C17: =IFERROR(IF(C9="","",C9*'0. Assumptions'!$B$18),"") -> 26044.2 | D17: =IFERROR(IF(D9="","",D9*'0. Assumptions'!$B$18),"") -> 27085.968 | E17: =IFERROR(B17/$B$9,"") -> 0.03 | F17: Card processing fees are not subject to sales tax: no tax is recovered or deducted for them | G17: 0
A18: Miscellaneous and contingency | B18: =IFERROR(IF(B9="","",B9*'0. Assumptions'!$B$28),"") -> 8190 | C18: =IFERROR(IF(C9="","",C9*'0. Assumptions'!$B$28),"") -> 8681.4 | D18: =IFERROR(IF(D9="","",D9*'0. Assumptions'!$B$28),"") -> 9028.656 | E18: =IFERROR(B18/$B$9,"") -> 0.01 | F18: =IFERROR("At "&TEXT('0. Assumptions'!$B$28,"0%")&" of sales. It is a VARIABLE cost: it moves with revenue, so it cannot sit in fixed costs","") -> At 1% of sales. It is a VARIABLE cost: it moves with revenue, so it cannot sit in fixed costs | G18: =IFERROR(IF(B9="","",'0. Assumptions'!$B$41),"") -> 0
A19: TOTAL VARIABLE COSTS | B19: =IFERROR(IF(B9="","",SUM(B13:B18)),"") -> 325716.3 | C19: =IFERROR(IF(C9="","",SUM(C13:C18)),"") -> 345259.28 | D19: =IFERROR(IF(D9="","",SUM(D13:D18)),"") -> 359069.65 | E19: =IFERROR(B19/$B$9,"") -> 0.3977
A20: GROSS MARGIN | B20: =IFERROR(IF(B9="","",B9-B19),"") -> 493283.7 | C20: =IFERROR(IF(C9="","",C9-C19),"") -> 522880.72 | D20: =IFERROR(IF(D9="","",D9-D19),"") -> 543795.95 | E20: =IFERROR(B20/$B$9,"") -> 0.6023
A21: FIXED COSTS
A22: Rent | B22: =IFERROR(IF(B9="","",'0. Assumptions'!$B$24*12),"") -> 44796 | C22: =IFERROR(IF(C9="","",B22*(1+'0. Assumptions'!$B$48)),"") -> 44796 | D22: =IFERROR(IF(D9="","",C22*(1+'0. Assumptions'!$B$48)),"") -> 44796 | E22: =IFERROR(B22/$B$9,"") -> 0.054695971 | F22: The monthly amount is on the "0. Assumptions" tab; here it is multiplied by twelve. The two months of rent before opening are on "Startup Costs" and are NOT counted twice | G22: =IFERROR(IF(B9="","",'0. Assumptions'!$B$41),"") -> 0
A23: Labor (wages + employer payroll taxes) | B23: =IFERROR(IF(B9="","",Staffing!$G$12),"") -> 271009.2 | C23: =IFERROR(IF(C9="","",Staffing!$B$16),"") -> 276009.2 | D23: =IFERROR(IF(D9="","",Staffing!$B$17),"") -> 281009.2 | E23: =IFERROR(B23/$B$9,"") -> 0.33090256 | F23: Comes from the Staffing tab: it is the SAME number, not a separate estimate. Years 2 and 3 add the new hires declared on that tab, not a percentage of volume | G23: 0
A24: Utilities (electricity, water, gas) | B24: =IFERROR(IF(B9="","",'0. Assumptions'!$B$26*12),"") -> 21600 | C24: =IFERROR(IF(C9="","",B24*(1+'0. Assumptions'!$B$48)),"") -> 21600 | D24: =IFERROR(IF(D9="","",C24*(1+'0. Assumptions'!$B$48)),"") -> 21600 | E24: =IFERROR(B24/$B$9,"") -> 0.026373626 | F24: Enter the monthly bills excl. sales tax. The workbook applies a single tax treatment to this whole line, the one in the column next to it; if one utility is taxed differently in your area, give it its own line | G24: =IFERROR(IF(B9="","",'0. Assumptions'!$B$41),"") -> 0
A25: Insurance (general + liquor liability + property + workers' comp) | B25: =IFERROR(IF(B9="","",'0. Assumptions'!$B$27),"") -> 6500 | C25: =IFERROR(IF(C9="","",B25*(1+'0. Assumptions'!$B$48)),"") -> 6500 | D25: =IFERROR(IF(D9="","",C25*(1+'0. Assumptions'!$B$48)),"") -> 6500 | E25: =IFERROR(B25/$B$9,"") -> 0.0079365079 | F25: Insurance premiums are not subject to sales tax: there is no recoverable tax on them | G25: 0
A26: Accounting & bookkeeping | B26: 4200 | C26: =IFERROR(IF(C9="","",B26*(1+'0. Assumptions'!$B$48)),"") -> 4200 | D26: =IFERROR(IF(D9="","",C26*(1+'0. Assumptions'!$B$48)),"") -> 4200 | E26: =IFERROR(B26/$B$9,"") -> 0.0051282051 | F26: Bookkeeping, income tax and payroll filings for the LLC, payroll processing and the staff paperwork (offer letters, I-9, W-4) | G26: =IFERROR(IF(B9="","",'0. Assumptions'!$B$41),"") -> 0
A27: Maintenance (quarterly hood cleaning, rotisserie service, refrigeration) | B27: 3600 | C27: =IFERROR(IF(C9="","",B27*(1+'0. Assumptions'!$B$48)),"") -> 3600 | D27: =IFERROR(IF(D9="","",C27*(1+'0. Assumptions'!$B$48)),"") -> 3600 | E27: =IFERROR(B27/$B$9,"") -> 0.0043956044 | F27: Hood and duct cleaning every quarter (NFPA 96, Table 11.4), annual service for the rotisseries and gas lines (burners, motors and spits), and the refrigeration technician. Ask your fire marshal what your jurisdiction requires | G27: =IFERROR(IF(B9="","",'0. Assumptions'!$B$41),"") -> 0
A28: Marketing and advertising | B28: 6400 | C28: =IFERROR(IF(C9="","",B28*(1+'0. Assumptions'!$B$48)),"") -> 6400 | D28: =IFERROR(IF(D9="","",C28*(1+'0. Assumptions'!$B$48)),"") -> 6400 | E28: =IFERROR(B28/$B$9,"") -> 0.0078144078 | F28: Google Business Profile, Yelp, Instagram, photos, flyers and cards with the pre-order phone and website, and the big dates: Mother's Day, Super Bowl Sunday, Christmas Eve and New Year's Eve and, if you make Peruvian pollo a la brasa, Pollo a la Brasa Day (the third Sunday of July). The opening campaign is in "Startup Costs" | G28: =IFERROR(IF(B9="","",'0. Assumptions'!$B$41),"") -> 0
A29: Software, POS & online ordering | B29: 3600 | C29: =IFERROR(IF(C9="","",B29*(1+'0. Assumptions'!$B$48)),"") -> 3600 | D29: =IFERROR(IF(D9="","",C29*(1+'0. Assumptions'!$B$48)),"") -> 3600 | E29: =IFERROR(B29/$B$9,"") -> 0.0043956044 | F29: POS subscription, online ordering for pre-orders, the delivery marketplace tablets, phone and internet | G29: =IFERROR(IF(B9="","",'0. Assumptions'!$B$41),"") -> 0
A30: Cleaning, linens & uniforms | B30: 2000 | C30: =IFERROR(IF(C9="","",B30*(1+'0. Assumptions'!$B$48)),"") -> 2000 | D30: =IFERROR(IF(D9="","",C30*(1+'0. Assumptions'!$B$48)),"") -> 2000 | E30: =IFERROR(B30/$B$9,"") -> 0.0024420024 | F30: Cleaning supplies and degreasers, uniform and towel laundry, gloves and any lab tests or records your written food safety plan calls for | G30: =IFERROR(IF(B9="","",'0. Assumptions'!$B$41),"") -> 0
A31: Waste, grease & used-oil hauling + permit renewals | B31: 3500 | C31: =IFERROR(IF(C9="","",B31*(1+'0. Assumptions'!$B$48)),"") -> 3500 | D31: =IFERROR(IF(D9="","",C31*(1+'0. Assumptions'!$B$48)),"") -> 3500 | E31: =IFERROR(B31/$B$9,"") -> 0.0042735043 | F31: Licensed hauler for trash, cardboard, used cooking oil and the rotisserie drip-tray grease (check the pickup fee), plus annual permit renewals. Ask your city for its waste fees: this plan has not read any city fee schedule, so enter your own | G31: =IFERROR(IF(B9="","",'0. Assumptions'!$B$41),"") -> 0
A32: Pest control | B32: 900 | C32: =IFERROR(IF(C9="","",B32*(1+'0. Assumptions'!$B$48)),"") -> 900 | D32: =IFERROR(IF(D9="","",C32*(1+'0. Assumptions'!$B$48)),"") -> 900 | E32: =IFERROR(B32/$B$9,"") -> 0.0010989011 | F32: Contract with a licensed pest control operator: it is part of the prerequisites of your written food safety plan. | G32: =IFERROR(IF(B9="","",'0. Assumptions'!$B$41),"") -> 0
A33: Music licensing (ASCAP/BMI/SESAC) | B33: 1000 | C33: =IFERROR(IF(C9="","",B33*(1+'0. Assumptions'!$B$48)),"") -> 1000 | D33: =IFERROR(IF(D9="","",C33*(1+'0. Assumptions'!$B$48)),"") -> 1000 | E33: =IFERROR(B33/$B$9,"") -> 0.0012210012 | F33: ASCAP, BMI and SESAC are separate licenses; the fee depends on the square footage and the seating of your restaurant | G33: =IFERROR(IF(B9="","",'0. Assumptions'!$B$41),"") -> 0
A34: Food safety & staff training (CFPM, allergens, OSHA) | B34: 800 | C34: =IFERROR(IF(C9="","",B34*(1+'0. Assumptions'!$B$48)),"") -> 800 | D34: =IFERROR(IF(D9="","",C34*(1+'0. Assumptions'!$B$48)),"") -> 800 | E34: =IFERROR(B34/$B$9,"") -> 0.00097680098 | F34: CFPM certification and food handler cards, allergen training and OSHA basics for every employee: burns from the rotisseries and the fryers, cuts when carving and spitting, gas and heat | G34: =IFERROR(IF(B9="","",'0. Assumptions'!$B$41),"") -> 0
A35: Depreciation of fixed assets | B35: =IFERROR(IF(B9="","",'Startup Costs'!$B$37),"") -> 24517.143 | C35: =IFERROR(IF(C9="","",B35),"") -> 24517.143 | D35: =IFERROR(IF(D9="","",B35),"") -> 24517.143 | E35: =IFERROR(B35/$B$9,"") -> 0.029935461 | F35: Comes from the depreciation bases on the Startup Costs tab: real fixed assets only. It does NOT rise with inflation: it is a charge on the HISTORICAL cost of the assets | G35: 0
A36: Interest expense (loan interest) | B36: =IFERROR(IF(B9="","",Financing!$B$44),"") -> 21600 | C36: =IFERROR(IF(C9="","",Financing!$B$46),"") -> 20244.699 | D36: =IFERROR(IF(D9="","",Financing!$B$48),"") -> 18753.869 | E36: =IFERROR(B36/$B$9,"") -> 0.026373626 | F36: Only INTEREST is an expense. Principal repaid appears on the cash flow tab | G36: 0
A37: TOTAL FIXED COSTS | B37: =IFERROR(IF(B9="","",SUM(B22:B36)),"") -> 416022.34 | C37: =IFERROR(IF(C9="","",SUM(C22:C36)),"") -> 419667.04 | D37: =IFERROR(IF(D9="","",SUM(D22:D36)),"") -> 423176.21 | E37: =IFERROR(B37/$B$9,"") -> 0.50796379
A38: Recoverable input tax on variable costs | B38: =IFERROR(IF(B9="","",SUMPRODUCT(B13:B18,G13:G18)),"") -> 0 | C38: =IFERROR(IF(C9="","",SUMPRODUCT(C13:C18,G13:G18)),"") -> 0 | D38: =IFERROR(IF(D9="","",SUMPRODUCT(D13:D18,G13:G18)),"") -> 0 | F38: Each line at ITS OWN rate, read from the column next to it. It is what the cash flow tab overpays to suppliers and later deducts (zero wherever no tax is recoverable)
A39: Recoverable input tax on fixed costs | B39: =IFERROR(IF(B9="","",SUMPRODUCT(B22:B36,G22:G36)),"") -> 0 | C39: =IFERROR(IF(C9="","",SUMPRODUCT(C22:C36,G22:G36)),"") -> 0 | D39: =IFERROR(IF(D9="","",SUMPRODUCT(D22:D36,G22:G36)),"") -> 0
A40: PRE-TAX INCOME (EBT) | B40: =IFERROR(IF(B9="","",B20-B37),"") -> 77261.357 | C40: =IFERROR(IF(C9="","",C20-C37),"") -> 103213.68 | D40: =IFERROR(IF(D9="","",D20-D37),"") -> 120619.74 | E40: =IFERROR(B40/$B$9,"") -> 0.094336211
A41: Net operating losses carried forward (opening) | B41: =IFERROR(IF(B9="","",'0. Assumptions'!$B$42),"") -> 0 | C41: =IFERROR(IF(C9="","",B46),"") -> 0 | D41: =IFERROR(IF(D9="","",C46),"") -> 0 | F41: Federal rules let a year's losses offset the profits of later years (the federal limit is 80% of taxable income; this model offsets 100% as a simplification)
...

Sheet Break-Even
A1: BREAK-EVEN ANALYSIS
A2: Monthly and daily break-even — neighborhood rotisserie chicken restaurant
A4: Variable | B4: Year 1 | C4: Year 2 | D4: Year 3 | E4: Notes
A5: BASE DATA BY YEAR
A6: Annual fixed costs | B6: =IFERROR(IF('3-Year P&L'!$B$9="","",'3-Year P&L'!$B$37),"") -> 416022.34 | C6: =IFERROR(IF('3-Year P&L'!$C$9="","",'3-Year P&L'!$C$37),"") -> 419667.04 | D6: =IFERROR(IF('3-Year P&L'!$D$9="","",'3-Year P&L'!$D$37),"") -> 423176.21 | E6: The SAME fixed costs as the P&L. Each year has its own, which is why the threshold cannot be a single one for all three years
A7: Monthly fixed costs | B7: =IFERROR(IF('3-Year P&L'!$B$9="","",B6/12),"") -> 34668.529 | C7: =IFERROR(IF('3-Year P&L'!$C$9="","",C6/12),"") -> 34972.254 | D7: =IFERROR(IF('3-Year P&L'!$D$9="","",D6/12),"") -> 35264.684
A8: Average check (excl. sales tax) | B8: =IFERROR(IF('3-Year P&L'!$B$9="","",'3-Year P&L'!$B$7),"") -> 17.5 | C8: =IFERROR(IF('3-Year P&L'!$C$9="","",'3-Year P&L'!$C$7),"") -> 17.5 | D8: =IFERROR(IF('3-Year P&L'!$D$9="","",'3-Year P&L'!$D$7),"") -> 17.5
A9: Variable cost per cover | B9: =IFERROR(IF('3-Year P&L'!$B$9="","",'3-Year P&L'!$B$19/('3-Year P&L'!$B$6*'3-Year P&L'!$B$8)),"") -> 6.95975 | C9: =IFERROR(IF('3-Year P&L'!$C$9="","",'3-Year P&L'!$C$19/('3-Year P&L'!$C$6*'3-Year P&L'!$C$8)),"") -> 6.95975 | D9: =IFERROR(IF('3-Year P&L'!$D$9="","",'3-Year P&L'!$D$19/('3-Year P&L'!$D$6*'3-Year P&L'!$D$8)),"") -> 6.95975 | E9: Comes from the P&L total variable costs, not from a separate estimate. It includes miscellaneous and contingency, which is a percentage of sales
A10: Contribution margin per cover | B10: =IFERROR(IF('3-Year P&L'!$B$9="","",B8-B9),"") -> 10.54025 | C10: =IFERROR(IF('3-Year P&L'!$C$9="","",C8-C9),"") -> 10.54025 | D10: =IFERROR(IF('3-Year P&L'!$D$9="","",D8-D9),"") -> 10.54025 | E10: Average check minus unit variable cost
A11: Operating days per year | B11: =IFERROR(IF('3-Year P&L'!$B$9="","",'3-Year P&L'!$B$8),"") -> 360 | C11: =IFERROR(IF('3-Year P&L'!$C$9="","",'3-Year P&L'!$C$8),"") -> 360 | D11: =IFERROR(IF('3-Year P&L'!$D$9="","",'3-Year P&L'!$D$8),"") -> 360 | E11: The same calendar as the P&L and the scenarios
A12: Principal repaid in the year | B12: =IFERROR(IF('3-Year P&L'!$B$9="","",Financing!$B$45),"") -> 13553.005 | C12: =IFERROR(IF('3-Year P&L'!$C$9="","",Financing!$B$47),"") -> 14908.306 | D12: =IFERROR(IF('3-Year P&L'!$D$9="","",Financing!$B$49),"") -> 16399.136 | E12: Principal is NOT a P&L expense, but it leaves the cash account. Without it, the published break-even threshold would sit below the real one
A13: ACCOUNTING BREAK-EVEN (includes depreciation)
A14: Covers needed per year | B14: =IFERROR(IF('3-Year P&L'!$B$9="","",IF(B10<=0,"",B6/B10)),"") -> 39469.874 | C14: =IFERROR(IF('3-Year P&L'!$C$9="","",IF(C10<=0,"",C6/C10)),"") -> 39815.663 | D14: =IFERROR(IF('3-Year P&L'!$D$9="","",IF(D10<=0,"",D6/D10)),"") -> 40148.593
A15: Covers needed per day | B15: =IFERROR(IF('3-Year P&L'!$B$9="","",B14/B11),"") -> 109.63854 | C15: =IFERROR(IF('3-Year P&L'!$C$9="","",C14/C11),"") -> 110.59906 | D15: =IFERROR(IF('3-Year P&L'!$D$9="","",D14/D11),"") -> 111.52387
A16: Revenue needed per year | B16: =IFERROR(IF('3-Year P&L'!$B$9="","",B14*B8),"") -> 690722.8 | C16: =IFERROR(IF('3-Year P&L'!$C$9="","",C14*C8),"") -> 696774.1 | D16: =IFERROR(IF('3-Year P&L'!$D$9="","",D14*D8),"") -> 702600.38
A17: CASH BREAK-EVEN (loan payments in, depreciation out)
A18: Cash fixed costs + principal repaid for the year | B18: =IFERROR(IF('3-Year P&L'!$B$9="","",B6-'3-Year P&L'!$B$35+B12),"") -> 405058.21 | C18: =IFERROR(IF('3-Year P&L'!$C$9="","",C6-'3-Year P&L'!$C$35+C12),"") -> 410058.21 | D18: =IFERROR(IF('3-Year P&L'!$D$9="","",D6-'3-Year P&L'!$D$35+D12),"") -> 415058.21 | E18: The P&L fixed costs without depreciation (which is not paid in cash) and WITH principal repaid (which is). This is the threshold that decides whether cash holds up
A19: Covers needed per year (cash) | B19: =IFERROR(IF('3-Year P&L'!$B$9="","",IF(B10<=0,"",B18/B10)),"") -> 38429.658 | C19: =IFERROR(IF('3-Year P&L'!$C$9="","",IF(C10<=0,"",C18/C10)),"") -> 38904.03 | D19: =IFERROR(IF('3-Year P&L'!$D$9="","",IF(D10<=0,"",D18/D10)),"") -> 39378.402
A20: Covers needed per day (cash) | B20: =IFERROR(IF('3-Year P&L'!$B$9="","",B19/B11),"") -> 106.74905 | C20: =IFERROR(IF('3-Year P&L'!$C$9="","",C19/C11),"") -> 108.06675 | D20: =IFERROR(IF('3-Year P&L'!$D$9="","",D19/D11),"") -> 109.38445
A21: Revenue needed per year (cash) | B21: =IFERROR(IF('3-Year P&L'!$B$9="","",B19*B8),"") -> 672519.02 | C21: =IFERROR(IF('3-Year P&L'!$C$9="","",C19*C8),"") -> 680820.53 | D21: =IFERROR(IF('3-Year P&L'!$D$9="","",D19*D8),"") -> 689122.04
A22: COMPARISON WITH THE PLAN
A23: Covers per day forecast in the plan | B23: =IFERROR(IF('3-Year P&L'!$B$9="","",'3-Year P&L'!$B$6),"") -> 130 | C23: =IFERROR(IF('3-Year P&L'!$C$9="","",'3-Year P&L'!$C$6),"") -> 137.8 | D23: =IFERROR(IF('3-Year P&L'!$D$9="","",'3-Year P&L'!$D$6),"") -> 143.312
A24: Cushion above CASH break-even (%) | B24: =IFERROR(IF('3-Year P&L'!$B$9="","",B23/B20-1),"") -> 0.21780942 | C24: =IFERROR(IF('3-Year P&L'!$C$9="","",C23/C20-1),"") -> 0.27513781 | D24: =IFERROR(IF('3-Year P&L'!$D$9="","",D23/D20-1),"") -> 0.31016793 | E24: How far planned sales sit above cash break-even. The drop you can absorb before you cannot pay the fixed costs and the loan payment is somewhat smaller: with a 25% cushion, 20%. The required minimum is set in the "0. Assumptions" tab
A25: INTERPRETATION
A26: =IFERROR("With the average check excl. sales tax above, you need "&TEXT(ROUNDUP(B15,0),"0")&" covers a day over your "&TEXT(B11,"0")&" opening days to avoid losing money (accounting break-even, depreciation included), and "&TEXT(ROUNDUP(B20,0),"0")&" for cash to hold (cash break-even: depreciation out, because it is not paid, and the year's loan payment in"&IF(B12=0,"; no principal is repaid this year (interest-only period or no loan)","")&"). The ""Revenue needed per year"" rows show the same figures in your currency.","") -> With the average check excl. sales tax above, you need 110 covers a day over your 360 opening days to avoid losing money (accounting break-even, depreciation included), and 107 for cash to hold (cash break-even: depreciation out, because it is not paid, and the year's loan payment in). The "Revenue needed per year" rows show the same figures in your currency.
A28: BREAK-EVEN SENSITIVITY
A29: Covers per day needed to cover costs for each average check (columns) and each variable cost per cover (rows). Green cells are below the covers per day the plan forecasts.
A31: Covers per day needed: average check excl. sales tax (columns) × variable cost per cover (rows) | B31: =IFERROR($B$8-2,"") -> 15.5 | C31: =IFERROR(IF($B$8="","",$B$8),"") -> 17.5 | D31: =IFERROR($B$8+2,"") -> 19.5 | E31: =IFERROR($B$8+4,"") -> 21.5
A32: =IFERROR($B$9*0.85,"") -> 5.9157875 | B32: =IFERROR(IF($B$31-$A32<=0,"",$B$6/($B$31-$A32)/$B$11),"") -> 120.57512 | C32: =IFERROR(IF($C$31-$A32<=0,"",$B$6/($C$31-$A32)/$B$11),"") -> 99.757978 | D32: =IFERROR(IF($D$31-$A32<=0,"",$B$6/($D$31-$A32)/$B$11),"") -> 85.070638 | E32: =IFERROR(IF($E$31-$A32<=0,"",$B$6/($E$31-$A32)/$B$11),"") -> 74.153097
A33: =IFERROR($B$9*0.925,"") -> 6.4377688 | B33: =IFERROR(IF($B$31-$A33<=0,"",$B$6/($B$31-$A33)/$B$11),"") -> 127.52021 | C33: =IFERROR(IF($C$31-$A33<=0,"",$B$6/($C$31-$A33)/$B$11),"") -> 104.46515 | D33: =IFERROR(IF($D$31-$A33<=0,"",$B$6/($D$31-$A33)/$B$11),"") -> 88.470155 | E33: =IFERROR(IF($E$31-$A33<=0,"",$B$6/($E$31-$A33)/$B$11),"") -> 76.722871
A34: =IFERROR($B$9*1.0,"") -> 6.95975 | B34: =IFERROR(IF($B$31-$A34<=0,"",$B$6/($B$31-$A34)/$B$11),"") -> 135.31426 | C34: =IFERROR(IF($C$31-$A34<=0,"",$B$6/($C$31-$A34)/$B$11),"") -> 109.63854 | D34: =IFERROR(IF($D$31-$A34<=0,"",$B$6/($D$31-$A34)/$B$11),"") -> 92.152678 | E34: =IFERROR(IF($E$31-$A34<=0,"",$B$6/($E$31-$A34)/$B$11),"") -> 79.477149
A35: =IFERROR($B$9*1.075,"") -> 7.4817312 | B35: =IFERROR(IF($B$31-$A35<=0,"",$B$6/($B$31-$A35)/$B$11),"") -> 144.12308 | C35: =IFERROR(IF($C$31-$A35<=0,"",$B$6/($C$31-$A35)/$B$11),"") -> 115.35103 | D35: =IFERROR(IF($D$31-$A35<=0,"",$B$6/($D$31-$A35)/$B$11),"") -> 96.155082 | E35: =IFERROR(IF($E$31-$A35<=0,"",$B$6/($E$31-$A35)/$B$11),"") -> 82.436543
A36: =IFERROR($B$9*1.15,"") -> 8.0037125 | B36: =IFERROR(IF($B$31-$A36<=0,"",$B$6/($B$31-$A36)/$B$11),"") -> 154.15866 | C36: =IFERROR(IF($C$31-$A36<=0,"",$B$6/($C$31-$A36)/$B$11),"") -> 121.69152 | D36: =IFERROR(IF($D$31-$A36<=0,"",$B$6/($D$31-$A36)/$B$11),"") -> 100.52094 | E36: =IFERROR(IF($E$31-$A36<=0,"",$B$6/($E$31-$A36)/$B$11),"") -> 85.624852

Sheet Scenarios
A1: SCENARIO ANALYSIS
A2: Pessimistic / Base / Optimistic — Year 1
A4: Metric | B4: Pessimistic | C4: Base | D4: Optimistic | E4: Notes
A5: Covers per day | B5: 110 | C5: =IFERROR(IF('3-Year P&L'!$B$6="","",'3-Year P&L'!$B$6),"") -> 130 | D5: 150
A6: Average check (excl. sales tax) | B6: 16.5 | C6: =IFERROR(IF('3-Year P&L'!$B$7="","",'3-Year P&L'!$B$7),"") -> 17.5 | D6: 18.5
A7: Operating days per year | B7: 355 | C7: =IFERROR(IF('3-Year P&L'!$B$8="","",'3-Year P&L'!$B$8),"") -> 360 | D7: 362
A8: ANNUAL REVENUE (excl. sales tax) | B8: =IFERROR(IF(B5*B6*B7=0,"",B5*B6*B7),"") -> 644325 | C8: =IFERROR(IF(C5*C6*C7=0,"",C5*C6*C7),"") -> 819000 | D8: =IFERROR(IF(D5*D6*D7=0,"",D5*D6*D7),"") -> 1004550
A9: Cost of goods sold — food | B9: =IFERROR(IF(B8="","",B8*'0. Assumptions'!$B$11*'0. Assumptions'!$B$13),"") -> 160694.65 | C9: =IFERROR(IF(C8="","",C8*'0. Assumptions'!$B$11*'0. Assumptions'!$B$13),"") -> 204258.6 | D9: =IFERROR(IF(D8="","",D8*'0. Assumptions'!$B$11*'0. Assumptions'!$B$13),"") -> 250534.77
A10: Cost of goods sold — beverage | B10: =IFERROR(IF(B8="","",B8*'0. Assumptions'!$B$12*'0. Assumptions'!$B$14),"") -> 19845.21 | C10: =IFERROR(IF(C8="","",C8*'0. Assumptions'!$B$12*'0. Assumptions'!$B$14),"") -> 25225.2 | D10: =IFERROR(IF(D8="","",D8*'0. Assumptions'!$B$12*'0. Assumptions'!$B$14),"") -> 30940.14
A11: Disposables and packaging | B11: =IFERROR(IF(B8="","",B8*'0. Assumptions'!$B$15),"") -> 25773 | C11: =IFERROR(IF(C8="","",C8*'0. Assumptions'!$B$15),"") -> 32760 | D11: =IFERROR(IF(D8="","",D8*'0. Assumptions'!$B$15),"") -> 40182
A12: Delivery platform fees | B12: =IFERROR(IF(B8="","",B8*'0. Assumptions'!$B$16*'0. Assumptions'!$B$17),"") -> 24162.188 | C12: =IFERROR(IF(C8="","",C8*'0. Assumptions'!$B$16*'0. Assumptions'!$B$17),"") -> 30712.5 | D12: =IFERROR(IF(D8="","",D8*'0. Assumptions'!$B$16*'0. Assumptions'!$B$17),"") -> 37670.625
A13: Card processing fees | B13: =IFERROR(IF(B8="","",B8*'0. Assumptions'!$B$18),"") -> 19329.75 | C13: =IFERROR(IF(C8="","",C8*'0. Assumptions'!$B$18),"") -> 24570 | D13: =IFERROR(IF(D8="","",D8*'0. Assumptions'!$B$18),"") -> 30136.5
A14: Miscellaneous and contingency | B14: =IFERROR(IF(B8="","",B8*'0. Assumptions'!$B$28),"") -> 6443.25 | C14: =IFERROR(IF(C8="","",C8*'0. Assumptions'!$B$28),"") -> 8190 | D14: =IFERROR(IF(D8="","",D8*'0. Assumptions'!$B$28),"") -> 10045.5
A15: TOTAL VARIABLE COSTS | B15: =IFERROR(IF(B8="","",SUM(B9:B14)),"") -> 256248.05 | C15: =IFERROR(IF(C8="","",SUM(C9:C14)),"") -> 325716.3 | D15: =IFERROR(IF(D8="","",SUM(D9:D14)),"") -> 399509.53
A16: GROSS MARGIN | B16: =IFERROR(IF(B8="","",B8-B15),"") -> 388076.95 | C16: =IFERROR(IF(C8="","",C8-C15),"") -> 493283.7 | D16: =IFERROR(IF(D8="","",D8-D15),"") -> 605040.47
A17: FIXED COSTS (the P&L's) | B17: =IFERROR(IF(B8="","",'3-Year P&L'!$B$37),"") -> 416022.34 | C17: =IFERROR(IF(C8="","",'3-Year P&L'!$B$37),"") -> 416022.34 | D17: =IFERROR(IF(D8="","",'3-Year P&L'!$B$37),"") -> 416022.34 | E17: Fixed costs do not change with the scenario: that is why they are fixed
A18: PRE-TAX INCOME (EBT) | B18: =IFERROR(IF(B8="","",B16-B17),"") -> -27945.395 | C18: =IFERROR(IF(C8="","",C16-C17),"") -> 77261.357 | D18: =IFERROR(IF(D8="","",D16-D17),"") -> 189018.12
A19: Income tax | B19: =IFERROR(IF(B8="","",MAX(0,B18-'0. Assumptions'!$B$42)*'0. Assumptions'!$B$37),"") -> 0 | C19: =IFERROR(IF(C8="","",MAX(0,C18-'0. Assumptions'!$B$42)*'0. Assumptions'!$B$37),"") -> 19315.339 | D19: =IFERROR(IF(D8="","",MAX(0,D18-'0. Assumptions'!$B$42)*'0. Assumptions'!$B$37),"") -> 47254.531 | E19: At the "years 1-2" effective income tax rate, offsetting prior net operating losses
A20: NET INCOME | B20: =IFERROR(IF(B8="","",B18-B19),"") -> -27945.395 | C20: =IFERROR(IF(C8="","",C18-C19),"") -> 57946.018 | D20: =IFERROR(IF(D8="","",D18-D19),"") -> 141763.59
A21: Covers per day to break even | B21: =IFERROR(IF(B8="","",IF(B6-B15/(B5*B7)<=0,"",B17/(B6-B15/(B5*B7))/B7)),"") -> 117.92109 | C21: =IFERROR(IF(C8="","",IF(C6-C15/(C5*C7)<=0,"",C17/(C6-C15/(C5*C7))/C7)),"") -> 109.63854 | D21: =IFERROR(IF(D8="","",IF(D6-D15/(D5*D7)<=0,"",D17/(D6-D15/(D5*D7))/D7)),"") -> 103.13914
A22: WHAT EACH SCENARIO DEMANDS
A23: Labor cost / Sales | B23: =IFERROR(IF(B8="","",'3-Year P&L'!$B$23/B8),"") -> 0.42060948 | C23: =IFERROR(IF(C8="","",'3-Year P&L'!$B$23/C8),"") -> 0.33090256 | D23: =IFERROR(IF(D8="","",'3-Year P&L'!$B$23/D8),"") -> 0.26978169 | E23: The SAME staffing in all three scenarios. If labor cost blows up in the pessimistic case, adjust it in the Staffing tab, not here
A24: Covers per year per full-time equivalent | B24: =IFERROR(IF(B8="","",B5*B7/Staffing!$C$12),"") -> 5916.6667 | C24: =IFERROR(IF(C8="","",C5*C7/Staffing!$C$12),"") -> 7090.9091 | D24: =IFERROR(IF(D8="","",D5*D7/Staffing!$C$12),"") -> 8227.2727 | E24: Covers each full-time employee in the "Staffing" tab would have to serve. In the optimistic scenario it tells you whether you need to hire
A25: Year-1 closing cash balance (estimate, same method in all three scenarios) | B25: =IFERROR(IF(B8="","",'Startup Costs'!$B$29+B20+'3-Year P&L'!$B$35-Financing!$B$45),"") -> 80895.042 | C25: =IFERROR(IF(C8="","",'Startup Costs'!$B$29+C20+'3-Year P&L'!$B$35-Financing!$B$45),"") -> 166786.46 | D25: =IFERROR(IF(D8="","",'Startup Costs'!$B$29+D20+'3-Year P&L'!$B$35-Financing!$B$45),"") -> 250604.03 | E25: ESTIMATED balance: working capital plus the year's result, adding back depreciation (which is not paid) and subtracting loan principal. It does not include the timing gap between receipts and payments or the sales tax settlement, so the three columns can be compared with each other. In red, the scenario runs out of cash
A26: Actual month-12 balance from the 12-Month Cash Flow tab (Base case only) | C26: =IFERROR(IF(C8="","",'12-Month Cash Flow'!$M$22),"") -> 212282 | E26: The ACTUAL base-case balance, with its timing of receipts and payments and its sales tax settlement. It exists only for the Base scenario, the only one with its own monthly cash flow: that is why it is not in the row above, where it would be compared against two estimates
A28: The "Base" column reads its three inputs from the "0. Assumptions" tab, so it reproduces EXACTLY year 1 of the P&L. The other two scenarios use the same cost rates: the only things that change are covers, average check and days. FIXED COSTS are the same in all three: miscellaneous and contingency, which is a percentage of sales, sits at the top with the variable costs and each scenario carries its own.

Sheet Staffing
A1: STAFFING STRUCTURE AND COSTS
A2: =IFERROR("Payroll — "&TEXT('0. Assumptions'!$B$21,"0")&" pay periods + employer taxes "&TEXT('0. Assumptions'!$B$20*100,"0")&"%","") -> Payroll — 12 pay periods + employer taxes 10%
A4: Position | B4: People | C4: FTE | D4: Gross pay per month (total for the position) | E4: Employer payroll taxes (total for the position) | F4: Cost per month (total for the position) | G4: Cost per year | H4: Hours per week per person | I4: Hours per year for the position | J4: Notes
A5: Owner / GM & head of rotisserie | B5: 1 | C5: 1 | D5: 4500 | E5: =IFERROR(IF(D5="","",D5*'0. Assumptions'!$B$20),"") -> 450 | F5: =IFERROR(IF(D5="","",D5+E5),"") -> 4950 | G5: =IFERROR(IF(D5="","",F5*MAX(12,'0. Assumptions'!$B$21)),"") -> 59400 | H5: =IFERROR(IF(D5="","",C5*$B$19),"") -> 40 | I5: =IFERROR(IF(D5="","",H5*B5*$B$20),"") -> 1840 | J5: Buys the chicken and sets the bird size, makes the marinades, runs the rotisseries and the Sunday loads, handles pre-orders and manages. The workbook imputes a monthly salary as if on payroll, which is the prudent side; confirm with your CPA how you will pay yourself (owner's draw or W-2 under an S corp). The example pays the owner below a manager: owner's draw in addition from net profit
A6: Rotisserie cook (spitting, loads, carving) | B6: 1 | C6: 1 | D6: 3293 | E6: =IFERROR(IF(D6="","",D6*'0. Assumptions'!$B$20),"") -> 329.3 | F6: =IFERROR(IF(D6="","",D6+E6),"") -> 3622.3 | G6: =IFERROR(IF(D6="","",F6*MAX(12,'0. Assumptions'!$B$21)),"") -> 43467.6 | H6: =IFERROR(IF(D6="","",C6*$B$19),"") -> 40 | I6: =IFERROR(IF(D6="","",H6*B6*$B$20),"") -> 1840 | J6: Spits and loads the rotisseries, runs the fryers and the sides, and can probe and carve. It is an investment, not an expense: if only the owner can run the rotisseries, a sick day closes your biggest day
A7: Counter lead / cashier | B7: 1 | C7: 1 | D7: 2773 | E7: =IFERROR(IF(D7="","",D7*'0. Assumptions'!$B$20),"") -> 277.3 | F7: =IFERROR(IF(D7="","",D7+E7),"") -> 3050.3 | G7: =IFERROR(IF(D7="","",F7*MAX(12,'0. Assumptions'!$B$21)),"") -> 36603.6 | H7: =IFERROR(IF(D7="","",C7*$B$19),"") -> 40 | I7: =IFERROR(IF(D7="","",H7*B7*$B$20),"") -> 1840 | J7: Counter, register, phone and pre-orders, the delivery marketplace tablets and allergen information, all year round
A8: Counter, packing & expo (part-time W-2) | B8: 4 | C8: 0.4 | D8: 4159 | E8: =IFERROR(IF(D8="","",D8*'0. Assumptions'!$B$20),"") -> 415.9 | F8: =IFERROR(IF(D8="","",D8+E8),"") -> 4574.9 | G8: =IFERROR(IF(D8="","",F8*MAX(12,'0. Assumptions'!$B$21)),"") -> 54898.8 | H8: =IFERROR(IF(D8="","",C8*$B$19),"") -> 16 | I8: =IFERROR(IF(D8="","",H8*B8*$B$20),"") -> 2944 | J8: About 16 hours a week each: the lunch and dinner rushes at the counter, packing family meals and expo. Part-time W-2 employees; tips are not modeled
A9: Dish & prep (part-time W-2) | B9: 1 | C9: 0.5 | D9: 1300 | E9: =IFERROR(IF(D9="","",D9*'0. Assumptions'!$B$20),"") -> 130 | F9: =IFERROR(IF(D9="","",D9+E9),"") -> 1430 | G9: =IFERROR(IF(D9="","",F9*MAX(12,'0. Assumptions'!$B$21)),"") -> 17160 | H9: =IFERROR(IF(D9="","",C9*$B$19),"") -> 20 | I9: =IFERROR(IF(D9="","",H9*B9*$B$20),"") -> 920 | J9: Weekend help: dish, prep of the sides and sauces, and the spits through the dish machine, plus the dining room cleanup. Part-time W-2 employees
A10: Fry & line cook (part-time W-2, weekends & peak days) | B10: 1 | C10: 0.5 | D10: 1473 | E10: =IFERROR(IF(D10="","",D10*'0. Assumptions'!$B$20),"") -> 147.3 | F10: =IFERROR(IF(D10="","",D10+E10),"") -> 1620.3 | G10: =IFERROR(IF(D10="","",F10*MAX(12,'0. Assumptions'!$B$21)),"") -> 19443.6 | H10: =IFERROR(IF(D10="","",C10*$B$19),"") -> 20 | I10: =IFERROR(IF(D10="","",H10*B10*$B$20),"") -> 920 | J10: Weekend and peak-day help (Sunday, holidays and pre-order pickups): fries the yuca fries and fries and runs the line. This plan has NO delivery drivers of its own: if you add them, they are W-2 employees in most states, never independent contractors by default (check yours), and you need hired and non-owned auto insurance
A11: Prep & relief rotisserie cook (marinades, sides, sauces; days off) | B11: 1 | C11: 1 | D11: 3033 | E11: =IFERROR(IF(D11="","",D11*'0. Assumptions'!$B$20),"") -> 303.3 | F11: =IFERROR(IF(D11="","",D11+E11),"") -> 3336.3 | G11: =IFERROR(IF(D11="","",F11*MAX(12,'0. Assumptions'!$B$21)),"") -> 40035.6 | H11: =IFERROR(IF(D11="","",C11*$B$19),"") -> 40 | I11: =IFERROR(IF(D11="","",H11*B11*$B$20),"") -> 1840 | J11: Coverage for vacations and the team's days off through the year. Paid sick leave is required by some states and cities: check yours
A12: TOTAL STAFF | B12: =IFERROR(IF(COUNT(D5:D11)=0,"",SUM(B5:B11)),"") -> 10 | C12: =IFERROR(IF(COUNT(D5:D11)=0,"",SUMPRODUCT(B5:B11,C5:C11)),"") -> 6.6 | D12: =IFERROR(IF(COUNT(D5:D11)=0,"",SUM(D5:D11)),"") -> 20531 | E12: =IFERROR(IF(COUNT(D5:D11)=0,"",SUM(E5:E11)),"") -> 2053.1 | F12: =IFERROR(IF(COUNT(D5:D11)=0,"",SUM(F5:F11)),"") -> 22584.1 | G12: =IFERROR(IF(COUNT(D5:D11)=0,"",SUM(G5:G11)),"") -> 271009.2 | I12: =IFERROR(IF(COUNT(D5:D11)=0,"",SUM(I5:I11)),"") -> 12144
A13: STAFF GROWTH (stepped cost)
A14: Annual cost of year-2 hires | B14: 5000 | J14: FULL ANNUAL cost (gross pay + employer payroll taxes, over all pay periods) of whoever you hire that year. The P&L adds it to the previous year's cost: staffing grows by people, not by a percentage
A15: Annual cost of year-3 hires | B15: 5000 | J15: FULL ANNUAL cost (gross pay + employer payroll taxes, over all pay periods) of whoever you hire that year. The P&L adds it to the previous year's cost: staffing grows by people, not by a percentage
A16: Labor cost, year 2 | B16: =IFERROR(IF(G12="","",G12*(1+'0. Assumptions'!$B$48)+B14),"") -> 276009.2
A17: Labor cost, year 3 | B17: =IFERROR(IF(B16="","",B16*(1+'0. Assumptions'!$B$48)+B15),"") -> 281009.2
A18: COVERAGE OF SERVICE HOURS
A19: Full-time week (hours per week) | B19: 40 | J19: 40 hours a week is the FLSA overtime threshold for non-exempt employees; some states add daily overtime rules. Change it if your own full-time week is different
A20: Weeks worked per year per person | B20: 46 | J20: 46 weeks: 52 minus about six weeks for vacation, holidays and average absences. There is no federal vacation requirement in the US: adjust it to your own policy
A21: Service hours per day to cover | B21: 10.5 | J21: Hours the restaurant is open to the public each day, 7 days a week, on average, adding the preparation for each service. Any slow stretch between services is not counted
