Workbook

Sheet Chicken Yield
A1: CHICKEN YIELD: HOW MUCH A COOKED BIRD WEIGHS, WHAT IT COSTS AND HOW MANY BIRDS YOU NEED
A2: Type only in the GREEN cells: everything else is calculated. Amounts before sales tax. Every default value is a kit estimate, editable: replace it with your supplier's numbers and, above all, with what you measure on your own birds.
A3: FIXED NOTICE. The cooked yield (72 %) is a kit estimate; the kit works with a range of 70 to 75 % and no manufacturer figure is published. Weigh 5 raw and cooked birds from the same load, and adjust the yield until it matches what you measure.
A5: A. THE BIRD | B5: Value | C5: Notes
A6: Average whole chicken weight (lb, WOG) | B6: 3 | C6: Broiler/fryer of 2.5 to 4.5 lb WOG (without giblets). Weigh your birds at receiving. Kit estimate, editable.
A7: Whole chicken price ($/lb, before tax) | B7: 1.75 | C7: Delivered price of fresh whole chickens. The USDA wholesale composite ran about $1.17/lb in August 2026 and a distributor adds freight and margin. Type your supplier's price. Kit estimate, editable.
A8: Marinade per bird ($, before tax) | B8: 0.45 | C8: Soy sauce, beer, garlic, cumin, aji panca, huacatay and vinegar, marinated 24 to 48 hours. Kit estimate, editable.
A9: Display and holding waste (% of the bird cost) | B9: 0.05 | C9: Birds that pass their hot-holding window. Kit target: 5 % or less of the birds you load. Kit estimate, editable.
A10: Cooked yield (cooked weight ÷ raw weight) | B10: 0.72 | C10: What is left of the bird after roasting, bone-in. No manufacturer figure is published. Measure it with 5 birds from the same load (see the "Instructions" sheet). Kit estimate, editable.
A11: Benchmark: kit range for a rotisserie bird (midpoint of 70 to 75 %) | B11: 0.725 | C11: Fixed benchmark: the kit works with a cooked yield of 70 to 75 %. Not editable.
A12: Guests who share one bird | B12: 3 | C12: Whole number greater than 0. For a main plate with two sides it is usually 3. Kit estimate, editable.
A13: Guests you want to serve (pre-order or party) | B13: 40 | C13: Whole number greater than 0. It tells you how many birds to order.
A14: Birds left unsold at close | B14: 2 | C14: Whole birds that stay unsold when you close. Count them; default 2. Kit estimate, editable.
A15: Share of the leftover you reuse (%) | B15: 0.5 | C15: Next-day sandwich or bowl meat, after correct cooling (135 to 70 °F within 2 hours and to 41 °F within 6 hours in total). The part you throw away costs money. Kit estimate, editable.
A16: Ounces per lb (constant: 16 oz per lb) | B16: 16 | C16: Constant: 1 lb = 16 oz. Not editable. It converts the cooked pounds to ounces.
A17: Halves per bird (constant) | B17: 2 | C17: Constant: a bird is cut into 2 halves. Not editable.
A18: Quarters per bird (constant) | B18: 4 | C18: Constant: a bird is cut into 4 quarters. Not editable.
A20: RESULTS | B20: Value | C20: Notes
A21: COOKED WEIGHT OF ONE BIRD (lb) | B21: =$B$6*$B$10 -> 2.16 | C21: Raw weight × cooked yield.
A22: Cooking loss (lb) | B22: =$B$6-$B$21 -> 0.84 | C22: Water, fat and skin that leave the rotisserie.
A23: Cooking loss (%) | B23: =$B$22/$B$6 -> 0.28 | C23: Loss ÷ raw weight.
A24: COOKED YIELD (%) | B24: =$B$21/$B$6 -> 0.72 | C24: Cooked weight ÷ raw weight.
A25: Your cooked yield against the kit benchmark (%) | B25: =$B$24/$B$11 -> 0.99310345 | C25: Below 100 %: you lose more than the kit midpoint; weigh again.
A26: COST PER WHOLE BIRD ($) | B26: =($B$6*$B$7+$B$8)*(1+$B$9) -> 5.985 | C26: Weight × price per lb + marinade, plus the holding waste. It feeds the costing.
A27: COST PER COOKED LB ($) | B27: =$B$26/$B$21 -> 2.7708333 | C27: Bird cost ÷ cooked pounds.
A28: Cooked ounces of a whole bird (oz) | B28: =$B$21*$B$16 -> 34.56 | C28: Cooked weight × 16.
A29: Cooked ounces of a half chicken (oz) | B29: =$B$28/$B$17 -> 17.28 | C29: Whole cooked bird ÷ 2.
A30: Cooked ounces of a quarter chicken (oz) | B30: =$B$28/$B$18 -> 8.64 | C30: Whole cooked bird ÷ 4.
A31: Cost of a half chicken ($) | B31: =$B$26/$B$17 -> 2.9925 | C31: Bird cost ÷ 2.
A32: Cost of a quarter chicken ($) | B32: =$B$26/$B$18 -> 1.49625 | C32: Bird cost ÷ 4.
A33: BIRDS FOR THE GUESTS (birds) | B33: =ROUNDUP($B$13/$B$12,0) -> 14 | C33: Guests ÷ guests per bird, rounded up.
A34: Raw pounds you have to buy (lb) | B34: =$B$33*$B$6 -> 42 | C34: Birds × raw weight.
A35: Cost of the leftover you throw away ($) | B35: =$B$14*(1-$B$15)*$B$26 -> 5.985 | C35: Leftover birds × share you do not reuse × bird cost.

Sheet Rotisserie
A1: ROTISSERIE LOADS: DO YOUR SPITS REACH THE SUNDAY PEAK?
A2: Type only in the GREEN cells: everything else is calculated. Every default value is a kit estimate, editable. The capacity counts the full loads that fit between the first load and the deadline.
A3: FIXED NOTICE. The cook time (80 minutes) has no published figure: no spec sheet gives the time of a 3 lb bird. Time your own unit and your own bird size before you trust the capacity.
A5: A. THE ROTISSERIES AND THE SUNDAY | B5: Value | C5: Notes
A6: Rotisseries | B6: 2 | C6: Whole number greater than 0. The kit case runs two gas rotisseries of 8 spits each.
A7: Spits per rotisserie | B7: 8 | C7: Whole number greater than 0. Type your model (8-spit units are common).
A8: Birds per spit | B8: 6 | C8: Spec sheets give about 6 chickens per spit on an 8-spit gas unit (48 birds). Whole number greater than 0.
A9: Cook minutes of one load | B9: 80 | C9: NO PUBLISHED FIGURE: no spec sheet gives the time of a 3 lb bird. The kit works with 75 to 90 minutes. Time your own unit (see the "Instructions" sheet). Kit estimate, editable.
A10: Load, unload and clean minutes between loads | B10: 15 | C10: Skewering the next load while the last one comes out. Kit estimate, editable.
A11: First load: hour (24-hour clock) | B11: 9 | C11: Whole hour from 0 to 23. With 9 and 0 minutes, the first load goes on at 9:00 AM. Kit estimate, editable.
A12: First load: minutes | B12: 0 | C12: Minutes from 0 to 59.
A13: Deadline to have the birds cooked: hour (24-hour clock) | B13: 13 | C13: The Sunday lunch peak runs until about 1:30 PM. Whole hour from 0 to 23. Kit estimate, editable.
A14: Deadline to have the birds cooked: minutes | B14: 30 | C14: Minutes from 0 to 59.
A15: Birds you sell on a normal Sunday | B15: 68 | C15: About 1.6 to 1.8 times a weekday in the kit case (65 to 70 birds). Replace it with yours. Kit estimate, editable.
A16: Share of the Sunday sold in the peak window (%) | B16: 0.7 | C16: Between about 11:30 AM and 1:30 PM. Kit estimate, editable.
A17: Increase on a holiday or peak day (%) | B17: 1 | C17: Over a normal Sunday: Mother's Day or a Super Bowl Sunday reach 120 to 150 birds in the kit case. Kit estimate, editable.
... A21: BTU per therm (constant) | B21: 100000 | C21: Constant: 1 therm = 100,000 BTU. Not editable.
A23: RESULTS | B23: Value | C23: Notes
A24: BIRDS PER LOAD | B24: =$B$6*$B$7*$B$8 -> 96 | C24: Rotisseries × spits × birds per spit.
A25: Birds per load, each rotisserie | B25: =$B$7*$B$8 -> 48 | C25: Spits × birds per spit.
A26: Minutes of a full cycle | B26: =$B$9+$B$10 -> 95 | C26: Cook + load and unload.
A27: Loads per hour | B27: =$B$20/$B$26 -> 0.63157895 | C27: 60 minutes ÷ minutes of the cycle.
A28: Capacity per hour (birds) | B28: =$B$24*$B$27 -> 60.631579 | C28: Birds per load × loads per hour.
A29: Minutes between the first load and the deadline | B29: =($B$13-$B$11)*$B$20+($B$14-$B$12) -> 270 | C29: If it is negative, the deadline is before the first load.
A30: LOADS BEFORE THE DEADLINE | B30: =INT(MAX(0,$B$29)/$B$26) -> 2 | C30: Full cycles that fit in that time.
A31: SUNDAY CAPACITY BEFORE THE DEADLINE (birds) | B31: =$B$24*$B$30 -> 192 | C31: Birds per load × loads.
A32: Birds sold in the peak window of a normal Sunday | B32: =$B$15*$B$16 -> 47.6 | C32: Sunday birds × share sold in the peak window.
A33: Loads a normal Sunday needs (all day) | B33: =ROUNDUP($B$15/$B$24,0) -> 1 | C33: Sunday birds ÷ birds per load, rounded up.
A34: Loads the peak window of a normal Sunday needs | B34: =ROUNDUP($B$32/$B$24,0) -> 1 | C34: Peak birds ÷ birds per load, rounded up.
A35: Surplus (+) or shortfall (−) at the peak (birds) | B35: =$B$31-$B$32 -> 144.4 | C35: Capacity before the deadline minus the peak birds.
A36: Peak traffic light (normal Sunday) | B36: =IF($B$35>=0,"Covered","Short at the peak") -> Covered | C36: Covered if the capacity reaches the peak birds.
A37: Birds on a holiday or peak day | B37: =ROUNDUP($B$15*(1+$B$17),0) -> 136 | C37: Normal Sunday plus the increase, rounded up.
A38: Loads a holiday or peak day needs | B38: =ROUNDUP($B$37/$B$24,0) -> 2 | C38: Peak-day birds ÷ birds per load, rounded up.
A39: Surplus (+) or shortfall (−) at the peak of a peak day (birds) | B39: =$B$31-$B$37*$B$16 -> 96.8 | C39: Capacity minus the peak-day peak.
A40: Peak traffic light (holiday or peak day) | B40: =IF($B$39>=0,"Covered","Short at the peak") -> Covered | C40: Covered if the capacity reaches the peak of a peak day.
A41: Latest first load (minutes since 00:00) | B41: =$B$13*$B$20+$B$14-$B$34*$B$26 -> 715 | C41: Deadline minus the peak loads times the cycle.
A42: Latest first load: hour | B42: =INT($B$41/$B$20) -> 11 | C42: If you load later, you miss the peak.
A43: Latest first load: minutes | B43: =MOD($B$41,$B$20) -> 55
A44: Hours of rotisserie burning on a normal Sunday | B44: =$B$33*$B$26/$B$20 -> 1.5833333 | C44: Loads × cycle ÷ 60.
A45: Gas of a normal Sunday ($) | B45: =$B$18*$B$6*$B$44/$B$21*$B$19 -> 7.3070833 | C45: BTU/h × rotisseries × hours ÷ BTU per therm × price per therm.
...

Sheet Costing
A1: PLATE COSTING: WHOLE, HALF, QUARTER, FAMILY MEAL, SANDWICH OR BOWL, SIDES AND A DRINK, IN OUNCES
A2: Type only in the GREEN cells (prices, ounces, names, bird fractions and menu prices). Amounts before sales tax except the menu price. Prices are a kit estimate, editable: type your distributor's. The cost of the chicken comes from the "Chicken Yield" sheet.
A4: GENERAL DATA | B4: Value | D4: Notes
A5: Sales tax included in your menu prices (%) | B5: 0 | D5: Typically 0 %: a US menu is quoted before tax and the tax is added at the register. Rates vary by state and city; ask your accountant.
A6: Target food cost (% of the price before tax) | B6: 0.3 | D6: Rotisserie chicken reference: food and beverage at 30 % or less. Kit estimate, editable.
A7: Watch margin over the target (points) | B7: 0.05 | D7: Up to this margin above the target, the traffic light says "Watch the cost". The whole bird tends to land here.
A8: Production waste on the sides (%) | B8: 0 | D8: Default 0: the bird already carries its holding waste on the "Chicken Yield" sheet. Type a percentage if you throw away fries, salad or rice. Kit estimate, editable.
A9: Packaging per takeout order ($, before tax) | B9: 0.6 | D9: Thermal bag, tray and sauce cups of one order. Kit estimate, editable.
A10: Delivery marketplace commission (%) | B10: 0.25 | D10: Over the price before tax. Check your contract with each marketplace. Kit estimate, editable.
A11: Menu markup on the marketplace (%) | B11: 0.15 | D11: How much you raise the price on the marketplace to offset the commission. Kit estimate, editable.
A13: INGREDIENT (in ounces) | B13: $/lb before tax | C13: Unit | D13: Whole chicken | E13: Half chicken + 2 sides | F13: Quarter chicken + 2 sides | G13: Family meal (whole chicken + 2 large sides) | H13: Chicken sandwich or bowl | I13: Salchipapas | J13: Large yuca fries (side) | K13: Maduros (side) | L13: Inca Kola or soda | M13: WHERE THE PRICE COMES FROM
A14: Menu price ($) | D14: 19 | E14: 17.5 | F14: 13 | G14: 34 | H14: 13.5 | I14: 10.5 | J14: 8 | K14: 4.5 | L14: 3.25
A15: Yuca fries (frozen, with fry oil) | B15: 2.97 | C15: oz | D15: 0 | E15: 7.5 | F15: 7.5 | G15: 14.4 | H15: 0 | I15: 0 | J15: 12 | K15: 0 | L15: 0 | M15: Kit estimate (Oct 2026): frozen yuca about $2.75/lb plus fry oil. Replace with your distributor's price
A16: French fries (frozen, with fry oil) | B16: 2.2 | C16: oz | D16: 0 | E16: 0 | F16: 0 | G16: 0 | H16: 0 | I16: 10 | J16: 0 | K16: 0 | L16: 0 | M16: Kit estimate (Oct 2026): replace with your distributor's price
A17: Rice & beans (cooked) | B17: 1.2 | C17: oz | D17: 0 | E17: 0 | F17: 0 | G17: 12 | H17: 6 | I17: 0 | J17: 0 | K17: 0 | L17: 0 | M17: Kit estimate (Oct 2026): replace with your distributor's price
A18: House salad | B18: 2.4 | C18: oz | D18: 0 | E18: 4 | F18: 4 | G18: 0 | H18: 3 | I18: 0 | J18: 0 | K18: 0 | L18: 0 | M18: Kit estimate (Oct 2026): replace with your distributor's price
A19: Maduros (fried sweet plantains) | B19: 3 | C19: oz | D19: 0 | E19: 0 | F19: 0 | G19: 0 | H19: 0 | I19: 0 | J19: 0 | K19: 5 | L19: 0 | M19: Kit estimate (Oct 2026): replace with your distributor's price
A20: Aji verde (Peruvian green sauce) | B20: 2 | C20: oz | D20: 0 | E20: 2 | F20: 2 | G20: 4 | H20: 1 | I20: 2 | J20: 2 | K20: 0 | L20: 0 | M20: Kit estimate (Oct 2026): replace with your distributor's price
A21: Sliced sausage (for salchipapas) | B21: 4.5 | C21: oz | D21: 0 | E21: 0 | F21: 0 | G21: 0 | H21: 0 | I21: 4 | J21: 0 | K21: 0 | L21: 0 | M21: Kit estimate (Oct 2026): replace with your distributor's price
A22: INGREDIENT (in units) | B22: $/ea before tax | C22: Unit
A23: Rotisserie chicken (fraction of a whole bird) | B23: ='Chicken Yield'!$B$26 -> 5.985 | C23: bird | D23: 1 | E23: 0.5 | F23: 0.25 | G23: 1 | H23: 0.25 | I23: 0 | J23: 0 | K23: 0 | L23: 0 | M23: linked from the Chicken Yield sheet (cost per whole bird)
A24: Bread roll (ea) | B24: 0.4 | C24: ea | D24: 0 | E24: 0 | F24: 0 | G24: 0 | H24: 1 | I24: 0 | J24: 0 | K24: 0 | L24: 0 | M24: Kit estimate (Oct 2026): replace with your distributor's price
A25: Inca Kola or soda, can or bottle (ea) | B25: 0.7 | C25: ea | D25: 0 | E25: 0 | F25: 0 | G25: 0 | H25: 0 | I25: 0 | J25: 0 | K25: 0 | L25: 1 | M25: Kit estimate (Oct 2026): replace with your distributor's price
A27: RESULT PER ITEM (ounces and units in the columns above) | D27: =D13 -> Whole chicken | E27: =E13 -> Half chicken + 2 sides | F27: =F13 -> Quarter chicken + 2 sides | G27: =G13 -> Family meal (whole chicken + 2 large sides) | H27: =H13 -> Chicken sandwich or bowl | I27: =I13 -> Salchipapas | J27: =J13 -> Large yuca fries (side) | K27: =K13 -> Maduros (side) | L27: =L13 -> Inca Kola or soda
A28: Weight served on the plate (oz) | D28: =SUM(D$15:D$21)+D$23*'Chicken Yield'!$B$28 -> 34.56 | E28: =SUM(E$15:E$21)+E$23*'Chicken Yield'!$B$28 -> 30.78 | F28: =SUM(F$15:F$21)+F$23*'Chicken Yield'!$B$28 -> 22.14 | G28: =SUM(G$15:G$21)+G$23*'Chicken Yield'!$B$28 -> 64.96 | H28: =SUM(H$15:H$21)+H$23*'Chicken Yield'!$B$28 -> 18.64 | I28: =SUM(I$15:I$21)+I$23*'Chicken Yield'!$B$28 -> 16 | J28: =SUM(J$15:J$21)+J$23*'Chicken Yield'!$B$28 -> 14 | K28: =SUM(K$15:K$21)+K$23*'Chicken Yield'!$B$28 -> 5 | L28: =SUM(L$15:L$21)+L$23*'Chicken Yield'!$B$28 -> 0
A29: Cost of the chicken ($) | D29: =D$23*$B$23 -> 5.985 | E29: =E$23*$B$23 -> 2.9925 | F29: =F$23*$B$23 -> 1.49625 | G29: =G$23*$B$23 -> 5.985 | H29: =H$23*$B$23 -> 1.49625 | I29: =I$23*$B$23 -> 0 | J29: =J$23*$B$23 -> 0 | K29: =K$23*$B$23 -> 0 | L29: =L$23*$B$23 -> 0
A30: Cost of sides, sauces, bread and drinks, before waste ($) | D30: =SUMPRODUCT(D$15:D$21,$B$15:$B$21)/'Chicken Yield'!$B$16+SUMPRODUCT(D$24:D$25,$B$24:$B$25) -> 0 | E30: =SUMPRODUCT(E$15:E$21,$B$15:$B$21)/'Chicken Yield'!$B$16+SUMPRODUCT(E$24:E$25,$B$24:$B$25) -> 2.2421875 | F30: =SUMPRODUCT(F$15:F$21,$B$15:$B$21)/'Chicken Yield'!$B$16+SUMPRODUCT(F$24:F$25,$B$24:$B$25) -> 2.2421875 | G30: =SUMPRODUCT(G$15:G$21,$B$15:$B$21)/'Chicken Yield'!$B$16+SUMPRODUCT(G$24:G$25,$B$24:$B$25) -> 4.073 | H30: =SUMPRODUCT(H$15:H$21,$B$15:$B$21)/'Chicken Yield'!$B$16+SUMPRODUCT(H$24:H$25,$B$24:$B$25) -> 1.425 | I30: =SUMPRODUCT(I$15:I$21,$B$15:$B$21)/'Chicken Yield'!$B$16+SUMPRODUCT(I$24:I$25,$B$24:$B$25) -> 2.75 | J30: =SUMPRODUCT(J$15:J$21,$B$15:$B$21)/'Chicken Yield'!$B$16+SUMPRODUCT(J$24:J$25,$B$24:$B$25) -> 2.4775 | K30: =SUMPRODUCT(K$15:K$21,$B$15:$B$21)/'Chicken Yield'!$B$16+SUMPRODUCT(K$24:K$25,$B$24:$B$25) -> 0.9375 | L30: =SUMPRODUCT(L$15:L$21,$B$15:$B$21)/'Chicken Yield'!$B$16+SUMPRODUCT(L$24:L$25,$B$24:$B$25) -> 0.7
A31: COST WITH WASTE ON THE SIDES ($) | D31: =D29+D30*(1+$B$8) -> 5.985 | E31: =E29+E30*(1+$B$8) -> 5.2346875 | F31: =F29+F30*(1+$B$8) -> 3.7384375 | G31: =G29+G30*(1+$B$8) -> 10.058 | H31: =H29+H30*(1+$B$8) -> 2.92125 | I31: =I29+I30*(1+$B$8) -> 2.75 | J31: =J29+J30*(1+$B$8) -> 2.4775 | K31: =K29+K30*(1+$B$8) -> 0.9375 | L31: =L29+L30*(1+$B$8) -> 0.7
A32: Menu price before tax ($) | D32: =D14/(1+$B$5) -> 19 | E32: =E14/(1+$B$5) -> 17.5 | F32: =F14/(1+$B$5) -> 13 | G32: =G14/(1+$B$5) -> 34 | H32: =H14/(1+$B$5) -> 13.5 | I32: =I14/(1+$B$5) -> 10.5 | J32: =J14/(1+$B$5) -> 8 | K32: =K14/(1+$B$5) -> 4.5 | L32: =L14/(1+$B$5) -> 3.25
A33: FOOD COST (%) | D33: =D31/D32 -> 0.315 | E33: =E31/E32 -> 0.299125 | F33: =F31/F32 -> 0.28757212 | G33: =G31/G32 -> 0.29582353 | H33: =H31/H32 -> 0.21638889 | I33: =I31/I32 -> 0.26190476 | J33: =J31/J32 -> 0.3096875 | K33: =K31/K32 -> 0.20833333 | L33: =L31/L32 -> 0.21538462
A34: Traffic light against the target | D34: =IF(D33<=$B$6,"On target",IF(D33<=$B$6+$B$7,"Watch the cost","Above target")) -> Watch the cost | E34: =IF(E33<=$B$6,"On target",IF(E33<=$B$6+$B$7,"Watch the cost","Above target")) -> On target | F34: =IF(F33<=$B$6,"On target",IF(F33<=$B$6+$B$7,"Watch the cost","Above target")) -> On target | G34: =IF(G33<=$B$6,"On target",IF(G33<=$B$6+$B$7,"Watch the cost","Above target")) -> On target | H34: =IF(H33<=$B$6,"On target",IF(H33<=$B$6+$B$7,"Watch the cost","Above target")) -> On target | I34: =IF(I33<=$B$6,"On target",IF(I33<=$B$6+$B$7,"Watch the cost","Above target")) -> On target | J34: =IF(J33<=$B$6,"On target",IF(J33<=$B$6+$B$7,"Watch the cost","Above target")) -> Watch the cost | K34: =IF(K33<=$B$6,"On target",IF(K33<=$B$6+$B$7,"Watch the cost","Above target")) -> On target | L34: =IF(L33<=$B$6,"On target",IF(L33<=$B$6+$B$7,"Watch the cost","Above target")) -> On target
A35: Gross margin ($, price before tax − cost) | D35: =D32-D31 -> 13.015 | E35: =E32-E31 -> 12.265313 | F35: =F32-F31 -> 9.2615625 | G35: =G32-G31 -> 23.942 | H35: =H32-H31 -> 10.57875 | I35: =I32-I31 -> 7.75 | J35: =J32-J31 -> 5.5225 | K35: =K32-K31 -> 3.5625 | L35: =L32-L31 -> 2.55
A36: Menu price with tax needed to hit the target ($) | D36: =D31/$B$6*(1+$B$5) -> 19.95 | E36: =E31/$B$6*(1+$B$5) -> 17.448958 | F36: =F31/$B$6*(1+$B$5) -> 12.461458 | G36: =G31/$B$6*(1+$B$5) -> 33.526667 | H36: =H31/$B$6*(1+$B$5) -> 9.7375 | I36: =I31/$B$6*(1+$B$5) -> 9.1666667 | J36: =J31/$B$6*(1+$B$5) -> 8.2583333 | K36: =K31/$B$6*(1+$B$5) -> 3.125 | L36: =L31/$B$6*(1+$B$5) -> 2.3333333
A38: MARGIN BY CHANNEL (every item) | D38: =D13 -> Whole chicken | E38: =E13 -> Half chicken + 2 sides | F38: =F13 -> Quarter chicken + 2 sides | G38: =G13 -> Family meal (whole chicken + 2 large sides) | H38: =H13 -> Chicken sandwich or bowl | I38: =I13 -> Salchipapas | J38: =J13 -> Large yuca fries (side) | K38: =K13 -> Maduros (side) | L38: =L13 -> Inca Kola or soda
A39: Dine-in: margin ($) | D39: =D35 -> 13.015 | E39: =E35 -> 12.265313 | F39: =F35 -> 9.2615625 | G39: =G35 -> 23.942 | H39: =H35 -> 10.57875 | I39: =I35 -> 7.75 | J39: =J35 -> 5.5225 | K39: =K35 -> 3.5625 | L39: =L35 -> 2.55
A40: Dine-in: margin (%) | D40: =D39/D32 -> 0.685 | E40: =E39/E32 -> 0.700875 | F40: =F39/F32 -> 0.71242788 | G40: =G39/G32 -> 0.70417647 | H40: =H39/H32 -> 0.78361111 | I40: =I39/I32 -> 0.73809524 | J40: =J39/J32 -> 0.6903125 | K40: =K39/K32 -> 0.79166667 | L40: =L39/L32 -> 0.78461538
A41: Pickup & pre-orders: margin ($, after packaging) | D41: =D39-$B$9 -> 12.415 | E41: =E39-$B$9 -> 11.665313 | F41: =F39-$B$9 -> 8.6615625 | G41: =G39-$B$9 -> 23.342 | H41: =H39-$B$9 -> 9.97875 | I41: =I39-$B$9 -> 7.15 | J41: =J39-$B$9 -> 4.9225 | K41: =K39-$B$9 -> 2.9625 | L41: =L39-$B$9 -> 1.95
A42: Pickup & pre-orders: margin (%) | D42: =D41/D32 -> 0.65342105 | E42: =E41/E32 -> 0.66658929 | F42: =F41/F32 -> 0.66627404 | G42: =G41/G32 -> 0.68652941 | H42: =H41/H32 -> 0.73916667 | I42: =I41/I32 -> 0.68095238 | J42: =J41/J32 -> 0.6153125 | K42: =K41/K32 -> 0.65833333 | L42: =L41/L32 -> 0.6
A43: Marketplace: price before tax with markup ($) | D43: =D32*(1+$B$11) -> 21.85 | E43: =E32*(1+$B$11) -> 20.125 | F43: =F32*(1+$B$11) -> 14.95 | G43: =G32*(1+$B$11) -> 39.1 | H43: =H32*(1+$B$11) -> 15.525 | I43: =I32*(1+$B$11) -> 12.075 | J43: =J32*(1+$B$11) -> 9.2 | K43: =K32*(1+$B$11) -> 5.175 | L43: =L32*(1+$B$11) -> 3.7375
A44: Marketplace: margin ($, after packaging and commission) | D44: =D43*(1-$B$10)-D31-$B$9 -> 9.8025 | E44: =E43*(1-$B$10)-E31-$B$9 -> 9.2590625 | F44: =F43*(1-$B$10)-F31-$B$9 -> 6.8740625 | G44: =G43*(1-$B$10)-G31-$B$9 -> 18.667 | H44: =H43*(1-$B$10)-H31-$B$9 -> 8.1225 | I44: =I43*(1-$B$10)-I31-$B$9 -> 5.70625 | J44: =J43*(1-$B$10)-J31-$B$9 -> 3.8225 | K44: =K43*(1-$B$10)-K31-$B$9 -> 2.34375 | L44: =L43*(1-$B$10)-L31-$B$9 -> 1.503125
...

Sheet Instructions
A1: INSTRUCTIONS: Rotisserie Chicken Yield & Costing Calculator
A2: Three tools in one workbook: the "Chicken Yield" sheet tells you how much a cooked bird weighs, what each cooked pound and each portion costs, and how many birds you need for a number of guests; the "Rotisserie" sheet compares the capacity of your rotisseries with the Sunday peak and with a holiday or peak day; the "Costing" sheet calculates the cost, food cost, margin and menu price of the whole chicken, the half, the quarter, the family meal, a sandwich or bowl, three sides and a drink, with the margin dine-in, on pickup and pre-orders and on a delivery marketplace. Type only in the GREEN cells; everything else is calculated. Chicken prices are in $/lb and portions in ounces (16 oz per lb, the gray constant).
A3: Every default value is a kit estimate, editable: they are examples consistent with the kit's business plan case, not anyone's prices. Replace them with your supplier's numbers and with what you measure in your own kitchen before you set prices.
A4: SHEET "Chicken Yield"
A6: 1. How to measure your cooked yield. Weigh 5 raw birds from the same load, cook the 5 together and weigh them again when they come out, drained. Divide the cooked weight by the raw weight and use the average: that is your real cooked yield. The kit works with a range of 70 to 75 %; no manufacturer figure is published.
A7: 2. The most useful results are the cost per whole bird and per cooked pound, which feed the costing, and the birds you have to order for a pre-order or a party. Look at the cost of the leftover you throw away too: the birds that stay unsold at close and are not reused are money lost.
A8: 3. Food safety. Probe the thickest part of the thigh: 165 °F is the Food Code cook temperature for poultry. In the heated display, hold at 135 °F or above, and check your county's rules for hot holding and for time as a public health control, which usually need a written procedure and a time mark on every load. Leftover you want to reuse is cooled from 135 to 70 °F within 2 hours and to 41 °F within 6 hours in total, and reheated to 165 °F for hot holding. Local rules vary: ask your health department.
A9: SHEET "Rotisserie"
A11: 1. Type your rotisseries, the spits of each one and the birds per spit, and the cook minutes. The cook time has no published figure: time a load from the moment you light the unit until the thigh reaches 165 °F, with the bird size you buy. Add the minutes to load, unload and clean.
A12: 2. Type the time of the first load and the deadline by which you want the birds cooked (the Sunday lunch peak runs until about 1:30 PM). The sheet counts the full loads that fit, the capacity and whether you cover the peak of a normal Sunday and the one of a holiday or peak day.
A13: 3. The latest first load is the time you must load the first birds so you do not fall short at the peak. The gas per bird uses the BTU/h rating of your units, the hours they burn and the price per therm from your gas bill: it is an estimate, so check it against your bill.
A14: SHEET "Costing"
... A28: Planning tool, not financial, tax or legal advice. Requirements vary by state, county and city — check with your accountant and local authorities.
