Workbook

Sheet Instructions
A1: 3-Year Financial Plan
A2: AI Chef Pro · aichef.pro — How to Open a Pastry Shop
A3: What it's for: knowing whether the business holds up, when it reaches break-even and which channel carries it.
A5: How to use it
A6: 1. "0. Assumptions" sheet: it's the control panel. This is where you type the RATES and DRIVERS (tickets a day, average ticket, days open, VAT/GST rates, target food cost, loan terms, control thresholds) and the rest of the workbook recalculates on its own. Expense lines are typed on their own sheet, not here.
A7: 2. "Startup Investment" sheet: what it costs to open, line by line, with its "Carries VAT/GST?" column and its rate per line. In the US leave the rates at 0% and put any sales tax you pay inside each line's amount: it's a cost, not something you get back. At the bottom, the VAT/GST you have to FRONT (UK, Canada and Australia only) and the total startup cash need.
A8: 3. "3-Year P&L" sheet: the profit and loss statement. YEAR 2 is the steady-state year; year 1 carries the ramp-up and year 3 grows on top of steady state. The owner's pay, depreciation and interest go INSIDE fixed costs: otherwise the profitability a business plan publishes means nothing.
A9: 4. "Break-Even" sheet: how many tickets a day you need so you don't lose money, in two versions. The ACCOUNTING one includes depreciation; the CASH one takes out depreciation (which you don't pay out) and adds the loan principal you repay (which you do). The second is the one that decides whether you make it to the end of the month.
A10: 5. "Scenarios" sheet: the same model with three sets of tickets, average ticket and days open. The "Realistic" column reads the P&L's steady-state year, so it can't drift away from it.
A11: 6. "Staff" sheet: five people and 3.5 FTEs, with base pay from the case's wage table in a green cell and payroll taxes, workers' comp and benefits INSIDE. From gross pay to employer cost there's a third more: it's the jump that surprises people most.
A12: 7. "12-Month Cash Flow" sheet: the P&L says whether the business makes money; this sheet says whether it has the cash to reach the end of the month. It carries month-by-month seasonality, the ramp-up, the lag between collections and payments and, only where VAT or GST applies (UK, Canada, Australia), the quarterly return.
A13: 8. "Financing" sheet: where the money comes from and what it costs to pay it back. The amortization schedule is MONTHLY, with 84 rows, because this case has six interest-only months and a yearly schedule can't express half a year. At the bottom, the DSCR year by year: it's the number that decides the loan.
... A26: WHAT THIS WORKBOOK DOES AND WHAT ANOTHER ONE DOES (so you don't type things twice)
A27: Product or workbook | B27: What it brings | C27: What this workbook does NOT do
A28: Your daily task checklists (outside this pack) | B28: Running the kitchen once you're open: weekly production plan, custom orders, display-case allergens, temperatures. | C28: This workbook does NOT plan production or track orders. It takes their result in dollars and projects it over three years.
A29: Food Cost Kit Pro and opening-menu-and-recipe-costing.xlsx | B29: The real cost of each piece, with its labor and its margin. | C29: Here cost of sales comes in as ONE percentage of sales: the 32% rule. When you measure yours, change it in "0. Assumptions".
A30: Bakery Business Plan Kit | B30: The complete package you hand the lender, with the written plan. | C30: This workbook is the numbers engine of an opening GUIDE. If you're going to apply for real financing, the lender's package is that product.
A31: startup-cost-calculator.xlsx, in this same guide | B31: Startup costs line by line, the format variant and the takeover vs. new build comparison. | C31: Only the TOTALS by block come in here. The two equipment cells on the "Startup Investment" sheet come seeded and are green: replace them with that workbook's totals once you've closed it.
A32: In this whole pack there isn't a single formula pointing to another file. Whatever comes from another workbook is COPIED and declared: a link between files breaks as soon as someone moves a folder, and then the workbook lies without warning.
A34: How often to use this workbook
A35: How often: "0. Assumptions" and "Startup Investment", WHILE YOU'RE LOOKING FOR A SPACE and getting quotes, as often as needed. The P&L, break-even and scenarios, ONCE BEFORE YOU SIGN and again before you sit down with the lender. "12-Month Cash Flow", EVERY MONTH during the first year, replacing the forecast with what actually happened. "Channels and Break-Even", each time you consider opening or closing a channel.
A37: To edit the structure or a cell that isn't green: Review > Unprotect Sheet (no password).
A39: Designed by John Guerrero — chef and restaurant consultant since 2010, in the kitchen since age 17.
A40: Version 1.0 · October 2026 · aichef.pro/en/digital-products/how-to-open-a-pastry-shop · info@aichef.pro

Sheet 0. Assumptions
A1: Assumptions: the Model's Rates and Drivers
A2: AI Chef Pro · aichef.pro — How to Open a Pastry Shop
A3: Change the GREEN cells and the rest of the workbook recalculates on its own. Expense lines are typed on their own sheet, not here. Each assumption has next to it where it comes from and what happens if you move it.
A5: ACTIVITY
A6: Tickets a day at steady state | B6: 183 | C6: ASSUMPTION. We found no public data on bakery foot traffic, so this number isn't a benchmark: it's what gives the model something to calculate. Count them yourself at the door of three shops like the one you want to open, on a Saturday and on a Tuesday.
A7: Items per ticket | B7: 2.6 | C7: ASSUMPTION. The average ticket comes from here and is NOT typed: it's calculated. Publishing a "bakery average ticket" would mean making up a figure that doesn't exist.
A8: Weighted average menu price ($/item; VAT/GST included where it applies) | B8: 2.257236 | C8: In the US it's the pre-tax price ($2.26 in the case): sales tax goes on top at the register and isn't revenue. It comes from the 30 items in opening-menu-and-recipe-costing.xlsx, weighted by their sales mix. If you change the menu there, bring the new average price here: it's a declared COPY, not a link between files.
A9: Average ticket, VAT/GST included where it applies ($) | B9: =IFERROR($B$7*$B$8,"") -> 5.8688137 | C9: Items per ticket × weighted average price. In the US it equals the pre-tax ticket: sales tax is added at the register.
A10: Average ticket before sales tax ($) | B10: =IFERROR($B$9/(1+$B$20),"") -> 5.8688137 | C10: It's the one that goes into the P&L: the P&L is always before sales tax or VAT/GST. It's divided by the menu's AVERAGE VAT/GST rate (row 20), not by a single rate; in the US that rate is 0%.
A11: Days open per year | B11: 300 | C11: ASSUMPTION: 6 days a week × 52 weeks = 312, minus 12 days closed in August. Holidays are NOT taken off: the case opens on them. Your hours depend on your lease, the center's rules and your city, so check them in writing. The SAME figure is used by the P&L, break-even and scenarios.
A12: Year-1 activity vs. steady state (%) | B12: =IFERROR(SUMPRODUCT('12-Month Cash Flow'!B6:M6,'12-Month Cash Flow'!B7:M7),"") -> 0.87639985 | C12: NOT typed: it comes from the seasonality and ramp-up on the "12-Month Cash Flow" sheet. A new shop doesn't sell on day one what it sells six months in, and projecting year 1 at steady-state speed is the mistake that sinks more business plans than any other.
A13: Year-3 volume growth (%) | B13: 0.04 | C13: ASSUMPTION. Year 2 is already steady state: year 3 only grows by what your regulars bring, not by a jump in business. 4% is cautious; if you put more, you'll have to say where it comes from.
A14: SALES TAX AND VAT/GST RATES
A15: VAT/GST rate on pastries, viennoiserie and cakes (UK, Canada, Australia; 0% in the US) | B15: 0 | C15: In the US, leave it at 0%: sales tax isn't part of the price in the P&L, and pastries sold to go are generally exempt in the four example states (it follows how you sell, not what you sell: chapter 19 of the guide). Type a rate here only if you charge VAT or GST (UK, Canada, Australia).
A16: VAT/GST rate on bread (UK, Canada, Australia; 0% in the US) | B16: 0 | C16: In the US bread carries no rate of its own: to go, it's generally exempt like the rest of the case (chapter 19 of the guide). What the bread you bag yourself does bring is the full label (Food Code 3-602.11). Leave it at 0%.
A17: Standard VAT/GST rate (UK, Canada, Australia; 0% in the US) | B17: 0 | C17: The rate you pay on build-out, equipment, packaging and services if you charge and recover VAT or GST. In the US, sales tax on those purchases is a cost: put it inside the amounts on "Startup Investment" and leave this at 0%.
A18: Average VAT/GST rate on ingredient purchases (UK, Canada, Australia; 0% in the US) | B18: 0 | C18: Working ASSUMPTION for VAT/GST countries. It only affects CASH FLOW (what you front to the supplier), never the result. Ask your supplier for a sample invoice to fine-tune it. In the US leave it at 0%, and ask your CPA how your state treats the ingredients you buy.
A19: Bread's share of sales before tax (%) | B19: 0.201276 | C19: It comes from the Breads family of the menu in opening-menu-and-recipe-costing.xlsx, weighted by its mix. It splits revenue into its two P&L lines; it only touches tax where bread and pastries carry different VAT/GST rates.
A20: Weighted average VAT/GST rate of the menu (%) | B20: =IFERROR($B$19*$B$16+(1-$B$19)*$B$15,"") -> 0 | C20: It isn't a legal rate: it's what's needed to go from cash to net sales when you sell at two different rates. 0% in the US.
A21: COST OF SALES
A22: Cost of sales as a share of sales (food cost, %) | B22: 0.32 | C22: The house's SINGLE RULE: a gross margin of 65-70% is a food cost of 30-35%, the same rule said twice. 32% is the midpoint. It includes what a piece's recipe costing leaves out: third-party products the counter resells, real waste, packaging and ingredient price increases. That's why it's HIGHER than your recipe costing, and why it's the conservative assumption.
A23: Target gross margin (%) | B23: =IFERROR(1-$B$22,"") -> 0.68 | C23: DERIVED from food cost, not stored separately: if both were stored, sooner or later they'd say different things.
A24: STAFF
A25: Payroll taxes, workers' comp and benefits (% of gross pay) | B25: 0.33 | C25: The case's 33%: about 10% is mandatory (FICA 7.65%, FUTA, your state's unemployment tax and workers' comp, which is optional for private employers in Texas); the rest depends on whether you offer health insurance and paid time off. Adjust it to your state and your benefits.
A26: Monthly pay installments per year | B26: 12 | C26: 12 in the US case: the annual pay is split into 12 equal monthly amounts, with no extra-pay months (the annual total doesn't change). If you pay weekly or every two weeks, the annual total is still the same.
A27: Minimum wage, full-time (annual: $7.25 × 2,080 h) | B27: 15080 | C27: $7.25 an hour × 2,080 hours = $15,080 a year ($1,256.67 a month): the federal minimum, which is also Texas's. Your state or city may set a higher one (California $16.90; New York $17.00 or $16.00 depending on the region; Florida $14.00 until September 29, 2026, so check FloridaCommerce for the current rate): put yours here.
A28: Full-time hours (hours/week) | B28: 40 | C28: ASSUMPTION: 40 hours, the federal overtime threshold (overtime at 1.5× above 40 hours a week). Check your state's rules before you size the shifts.
A29: SPACE AND FIXED COSTS
A30: Monthly rent ($) | B30: 1200 | C30: ASSUMPTION for a mid-size city: $1,200 a month on 969 sq ft is about $15 per sq ft a year, below the national average asking rent for retail space (CBRE: $24.79 per sq ft a year, Q2 2026). Put in your own, plus NNN charges if your lease has them.
A31: Security deposit (months of rent) | B31: 2 | C31: ASSUMPTION. The security deposit isn't an expense: it's money you get back. It goes into the investment because you need it the day you sign.
A32: Monthly utilities: electricity, gas and water ($) | B32: 1450 | C32: ASSUMPTION. With 62 kW installed and refrigeration running 24 hours, it's the business's second-biggest line. Don't estimate it: ask the utility for a quote based on the connected load in your electrical plans.
A33: Owner's monthly pay ($) | B33: 2400 | C33: ASSUMPTION, and a line of its own among fixed costs, before your own self-employment and income tax. If the owner works in the kitchen, that work has a cost even if you don't pay it to yourself at the end of the month.
A34: Annual increase in fixed costs (%) | B34: 0 | C34: Set to ZERO: the three P&L columns are in year-1 dollars (real terms). Raise it if you want to project in current dollars, but then raise the average ticket too, or you'll be projecting a margin loss you haven't decided on.
A35: FINANCING
A36: Owner's equity contributed ($) | B36: 167915.61 | C36: ASSUMPTION seeded so the plan is financed: it's the total startup cash need minus the loan. Look at it twice, because it's a lot of money: if you don't have it, either lower the investment (see the "Takeover vs New Build" sheet in startup-cost-calculator.xlsx) or raise the loan, and then watch the DSCR on the "Financing" sheet.
A37: Bank loan requested ($) | B37: 60000 | C37: ASSUMPTION. Your lender sets the terms, and they depend on your credit and collateral. Get offers from two lenders, including an SBA-backed 7(a) loan, before you fix it.
A38: Annual nominal interest rate (%) | B38: 0.062 | C38: ASSUMPTION.
A39: Total loan term (months) | B39: 84 | C39: ASSUMPTION: 7 years, interest-only months included. The schedule on the "Financing" sheet has 84 rows; if you stretch the term past 84 months, you'll have to add them.
A40: Interest-only period (months) | B40: 6 | C40: ASSUMPTION, and the FIRST thing to negotiate: the interest-only period keeps the loan from eating your cash during the ramp-up. During it you only pay interest.
A41: Working capital (months of fixed costs) | B41: 4 | C41: ASSUMPTION. Months of fixed costs you need in the bank the day you open. It's a startup cost line, not a tip.
...

Sheet Startup Investment
A1: Startup Investment: What It Costs to Open
A2: AI Chef Pro · aichef.pro — How to Open a Pastry Shop
A3: Each line has its "Carries VAT/GST?" column and its rate. VAT/GST you recover (UK, Canada, Australia) goes in the rate column; in the US, add your sales tax to each line's amount instead and leave the rate at 0%: it's a cost, not something you get back. Whatever you haven't had quoted, leave at its seeded value and flag it to ask for.
A5: Line | B5: Amount ($, before VAT/GST) | C5: Share of the investment | D5: Carries VAT/GST? | E5: VAT/GST rate (UK, Canada, Australia; 0% in the US) | F5: Notes
A6: Build-out and building systems · Build-out, middle scenario ($83.61 per sq ft × 969 sq ft) | B6: 81000 | C6: =IFERROR(B6/$B$19,"") -> 0.35539471 | D6: No | E6: 0 | F6: Reference scenario. The other two ($55.74 and $111.48 per sq ft) are in startup-cost-calculator.xlsx. [Source: case assumption]
A7: Production kitchen equipment · Production kitchen equipment (the modeled case's package) | B7: 54296.24 | C7: =IFERROR(B7/$B$19,"") -> 0.23822959 | D7: No | E7: 0 | F7: Block total, seeded from the modeled case's package in equipment-and-suppliers-checklist.xlsx, ALL on a pre-tax basis. Replace it with your real quotes when you have them: it's a declared COPY, not a link between files. [Source: example prices + assumptions]
A8: Storefront and display · Storefront and display (the modeled case's package) | B8: 12684.1 | C8: =IFERROR(B8/$B$19,"") -> 0.055652618 | D8: No | E8: 0 | F8: Block total, seeded from the modeled case's package in equipment-and-suppliers-checklist.xlsx, ALL on a pre-tax basis. Replace it with your real quotes when you have them: it's a declared COPY, not a link between files. [Source: example prices + assumption]
A9: Permits, plans and fees · Plans and specifications for plan review | B9: 5000 | C9: =IFERROR(B9/$B$19,"") -> 0.021937945 | D9: No | E9: 0 | F9: [Source: example price]
A10: Permits, plans and fees · Professional advice (CPA, attorney) | B10: 1000 | C10: =IFERROR(B10/$B$19,"") -> 0.0043875891 | D10: No | E10: 0 | F10: [Source: example amount]
A11: Permits, plans and fees · City and county permit fees (building permit, certificate of occupancy) | B11: 1800 | C11: =IFERROR(B11/$B$19,"") -> 0.0078976603 | D11: No | E11: 0 | F11: Government permit fees carry no sales tax, and the amount changes from one city or county to the next: it's a number to go and find, not copy. [Source: assumption]
A12: Permits, plans and fees · Health department plan review and food permit application | B12: 120 | C12: =IFERROR(B12/$B$19,"") -> 0.00052651069 | D12: No | E12: 0 | F12: The health department reviews your plans and inspects before it issues the food permit; you can't open without it. The amount is an assumption (Austin, for example, charges $312 for plan review and $178 for the pre-opening inspection, FY 2025-26). [Source: Food Code + assumption]
A13: Security deposit · Lease security deposit (2 months) | B13: 2400 | C13: =IFERROR(B13/$B$19,"") -> 0.010530214 | D13: No | E13: 0 | F13: The security deposit isn't an expense: it's money you get back. It goes into startup costs because you need it the day you sign. [Source: assumption]
A14: Opening packaging · First packaging order: bags, boxes and labels | B14: 2500 | C14: =IFERROR(B14/$B$19,"") -> 0.010968973 | D14: No | E14: 0 | F14: Start with the supplier's minimum: custom-printed packaging means big orders and money sitting in the storeroom. [Source: assumption]
A15: Opening marketing · Opening marketing | B15: 5000 | C15: =IFERROR(B15/$B$19,"") -> 0.021937945 | D15: No | E15: 0 | F15: [Source: example amount]
A16: Working capital · Cash cushion (months of fixed costs) | B16: =IFERROR('0. Assumptions'!$B$41*'3-Year P&L'!C33/12,"") -> 62115.262 | C16: =IFERROR(B16/$B$19,"") -> 0.27253624 | D16: No | E16: 0 | F16: Calculated: months of cushion × the steady-state year's monthly fixed costs. It isn't an investment you buy, it's cash: that's why it comes out of CAPEX in the row below. [Source: assumption]
A17: INVESTMENT SUBTOTAL (before working capital) | B17: =IFERROR(IF(COUNT(B6:B15)=0,"",SUM(B6:B15)),"") -> 165800.34 | C17: =IFERROR(B17/$B$19,"") -> 0.72746376
A18: WORKING CAPITAL | B18: =IFERROR(B16,"") -> 62115.262 | C18: =IFERROR(B18/$B$19,"") -> 0.27253624
A19: TOTAL INVESTMENT (what you buy plus the startup cash) | B19: =IFERROR(B17+B18,"") -> 227915.6
A20: CAPEX (investment before working capital) | B20: =IFERROR(B19-B18,"") -> 165800.34 | F20: It's what you BUY: build-out, equipment, permits, packaging and launch. The cash cushion isn't an investment, it's liquidity.
A21: VAT/GST fronted on the investment (UK, Canada and Australia only; $0 in the US) | B21: =IFERROR(SUMPRODUCT(B6:B16,E6:E16),"") -> 0 | F21: Each line at ITS rate, read from the column next to it. Outside the US it comes back on your VAT/GST returns, but it takes time: the "12-Month Cash Flow" sheet carries it forward. $0 in the US, where sales tax on purchases is a cost already inside each amount.
A22: TOTAL STARTUP CASH NEED | B22: =IFERROR(B19+B21,"") -> 227915.6 | F22: It's the figure the "Financing" sheet has to cover.
A23: Check: lines with "Yes" and a zero rate, or the other way around | B23: =IFERROR(SUMPRODUCT((D6:D16="Yes")*(E6:E16=0))+SUMPRODUCT((D6:D16="No")*(E6:E16>0)),"") -> 0 | F23: It has to read zero. If it turns red, a line says "Yes" with its rate at zero (or the other way around) and the VAT/GST on the investment is miscalculated.
A25: DEPRECIATION BASES (not added to the investment)
A26: Depreciable fixed assets | B26: =IFERROR(B17-B13-B14,"") -> 160900.34 | F26: The whole subtotal minus the security deposit (money you get back) and the first packaging order (inventory, not fixed assets).
A27: Annual depreciation of fixed assets | B27: =IFERROR(B26/MAX(1,'0. Assumptions'!$B$47),"") -> 16090.034 | F27: It's the line that goes into the P&L's fixed costs. Without it the published profit is a lie: ovens wear out.
A29: Every figure in the "Amount" column is BEFORE VAT/GST (in the US, include any sales tax you pay: it's part of the cost). VAT/GST is calculated separately below, so you can see how much you have to front and get back. Rent you pay BEFORE opening isn't here: if you'll pay it, add it to the security deposit line and say so in its note, so startup-cost-calculator.xlsx and this workbook keep saying the same thing.
A31: Validation lists (don't delete them: the dropdowns come from here)
A32: Carries VAT/GST?
A33: Yes
A34: No

Sheet 3-Year P&L
A1: 3-Year Profit and Loss
A2: AI Chef Pro · aichef.pro — How to Open a Pastry Shop
A3: YEAR 2 is the steady-state year: it's the one the guide and the business plan quote. Year 1 carries the ramp-up and year 3 grows on top of steady state. Owner's pay, depreciation and interest go INSIDE fixed costs.
A5: Line | B5: Year 1 (ramp-up) | C5: Year 2 (steady state) | D5: Year 3 | E5: Share of year-2 sales (%) | F5: VAT/GST rate (UK, Canada, Australia; 0% in the US) | G5: Notes
A6: REVENUE
A7: Tickets a day | B7: =IFERROR('0. Assumptions'!$B$6,"") -> 183 | C7: =IFERROR('0. Assumptions'!$B$6,"") -> 183 | D7: =IFERROR(C7*(1+'0. Assumptions'!$B$13),"") -> 190.32 | G7: Years 1 and 2 share steady-state traffic; what sets year 1 apart is the ramp-up in the row below, not fewer customers a day by month 12.
A8: Average ticket before sales tax ($) | B8: =IFERROR('0. Assumptions'!$B$10,"") -> 5.8688137 | C8: =IFERROR('0. Assumptions'!$B$10,"") -> 5.8688137 | D8: =IFERROR('0. Assumptions'!$B$10,"") -> 5.8688137 | G8: Constant in year-1 dollars: a price increase is a separate decision, and you make it on the menu, not here.
A9: Days open per year | B9: =IFERROR('0. Assumptions'!$B$11,"") -> 300 | C9: =IFERROR('0. Assumptions'!$B$11,"") -> 300 | D9: =IFERROR('0. Assumptions'!$B$11,"") -> 300
A10: Activity vs. steady-state speed (%) | B10: =IFERROR('0. Assumptions'!$B$12,"") -> 0.87639985 | C10: 1 | D10: 1 | G10: "0. Assumptions" calculates year 1 from the ramp-up and seasonality on the "12-Month Cash Flow" sheet. Years 2 and 3 are at 100% because year 2 is, by definition, steady state: if you think you'll take longer to get there, lower them.
A11: TOTAL REVENUE (before sales tax) | B11: =IFERROR(IF(B7*B8*B9*B10=0,"",B7*B8*B9*B10),"") -> 282374.17 | C11: =IFERROR(IF(C7*C8*C9*C10=0,"",C7*C8*C9*C10),"") -> 322197.87 | D11: =IFERROR(IF(D7*D8*D9*D10=0,"",D7*D8*D9*D10),"") -> 335085.79 | E11: =IFERROR(C11/$C$11,"") -> 1
A12: Pastry, viennoiserie and cake sales | B12: =IFERROR(IF(B11="","",B11*(1-'0. Assumptions'!$B$19)),"") -> 225539.02 | C12: =IFERROR(IF(C11="","",C11*(1-'0. Assumptions'!$B$19)),"") -> 257347.17 | D12: =IFERROR(IF(D11="","",D11*(1-'0. Assumptions'!$B$19)),"") -> 267641.06 | E12: =IFERROR(C12/$C$11,"") -> 0.798724 | F12: =IFERROR('0. Assumptions'!$B$15,"") -> 0
A13: Bread sales | B13: =IFERROR(IF(B11="","",B11*'0. Assumptions'!$B$19),"") -> 56835.143 | C13: =IFERROR(IF(C11="","",C11*'0. Assumptions'!$B$19),"") -> 64850.699 | D13: =IFERROR(IF(D11="","",D11*'0. Assumptions'!$B$19),"") -> 67444.727 | E13: =IFERROR(C13/$C$11,"") -> 0.201276 | F13: =IFERROR('0. Assumptions'!$B$16,"") -> 0 | G13: Two lines so you can see bread's weight in your sales. Where bread and pastries carry different VAT/GST rates (outside the US), the split is also what makes cash and the tax return reconcile.
A14: VARIABLE COSTS
A15: Cost of sales (ingredients, packaging and waste) | B15: =IFERROR(IF(B11="","",B11*'0. Assumptions'!$B$22),"") -> 90359.734 | C15: =IFERROR(IF(C11="","",C11*'0. Assumptions'!$B$22),"") -> 103103.32 | D15: =IFERROR(IF(D11="","",D11*'0. Assumptions'!$B$22),"") -> 107227.45 | E15: =IFERROR(C15/$C$11,"") -> 0.32 | F15: =IFERROR('0. Assumptions'!$B$18,"") -> 0 | G15: At the SINGLE RULE of 32%, not at the menu's recipe-costing food cost: the rule includes third-party products the counter resells, real waste, packaging and ingredient price increases. It's the conservative assumption, and the gap with your recipe costing is your cushion.
A16: TOTAL VARIABLE COSTS | B16: =IFERROR(IF(B11="","",SUM(B15:B15)),"") -> 90359.734 | C16: =IFERROR(IF(C11="","",SUM(C15:C15)),"") -> 103103.32 | D16: =IFERROR(IF(D11="","",SUM(D15:D15)),"") -> 107227.45 | E16: =IFERROR(C16/$C$11,"") -> 0.32
A17: GROSS MARGIN | B17: =IFERROR(IF(B11="","",B11-B16),"") -> 192014.43 | C17: =IFERROR(IF(C11="","",C11-C16),"") -> 219094.55 | D17: =IFERROR(IF(D11="","",D11-D16),"") -> 227858.34 | E17: =IFERROR(C17/$C$11,"") -> 0.68
A18: FIXED COSTS
A19: Staff (wages plus payroll taxes, workers' comp and benefits) | B19: =IFERROR(IF(B11="","",'Staff'!$I$11),"") -> 92776.079 | C19: =IFERROR(IF(C11="","",'Staff'!$I$11),"") -> 92776.079 | D19: =IFERROR(IF(D11="","",'Staff'!$I$11),"") -> 92776.079 | E19: =IFERROR(C19/$C$11,"") -> 0.28794752 | F19: 0 | G19: It comes from the "Staff" sheet: it's the SAME number, not a separate estimate. Payroll carries no sales tax or VAT/GST. If you hire someone in year 2 or 3, add them there and you'll see it here.
A20: Owner's pay (before your own self-employment and income tax) | B20: =IFERROR(IF(B11="","",'0. Assumptions'!$B$33*12),"") -> 28800 | C20: =IFERROR(IF(C11="","",B20*(1+'0. Assumptions'!$B$34)),"") -> 28800 | D20: =IFERROR(IF(D11="","",C20*(1+'0. Assumptions'!$B$34)),"") -> 28800 | E20: =IFERROR(C20/$C$11,"") -> 0.089386065 | F20: 0 | G20: A line of its own, and not part of the five-person team. A business that's only profitable because its owner doesn't get paid isn't profitable.
A21: Rent | B21: =IFERROR(IF(B11="","",'0. Assumptions'!$B$30*12),"") -> 14400 | C21: =IFERROR(IF(C11="","",B21*(1+'0. Assumptions'!$B$34)),"") -> 14400 | D21: =IFERROR(IF(D11="","",C21*(1+'0. Assumptions'!$B$34)),"") -> 14400 | E21: =IFERROR(C21/$C$11,"") -> 0.044693033 | F21: =IFERROR('0. Assumptions'!$B$17,"") -> 0 | G21: The monthly amount is in "0. Assumptions"; here it's multiplied by twelve. If your lease is triple net (NNN), add the property taxes, insurance and CAM charges.
A22: Utilities (electricity, gas and water) | B22: =IFERROR(IF(B11="","",'0. Assumptions'!$B$32*12),"") -> 17400 | C22: =IFERROR(IF(C11="","",B22*(1+'0. Assumptions'!$B$34)),"") -> 17400 | D22: =IFERROR(IF(D11="","",C22*(1+'0. Assumptions'!$B$34)),"") -> 17400 | E22: =IFERROR(C22/$C$11,"") -> 0.054004081 | F22: =IFERROR('0. Assumptions'!$B$17,"") -> 0 | G22: Assumption. Ask the utilities for an estimate based on your connected load. Outside the US, the workbook applies the VAT/GST rate in the next column to the whole line; in the US it stays at 0%.
A23: Insurance (general liability and property) | B23: 1440 | C23: =IFERROR(IF(C11="","",B23*(1+'0. Assumptions'!$B$34)),"") -> 1440 | D23: =IFERROR(IF(D11="","",C23*(1+'0. Assumptions'!$B$34)),"") -> 1440 | E23: =IFERROR(C23/$C$11,"") -> 0.0044693033 | F23: 0 | G23: Assumption. Ask your insurance agent what your landlord and lender require.
A24: Accounting and bookkeeping | B24: 2640 | C24: =IFERROR(IF(C11="","",B24*(1+'0. Assumptions'!$B$34)),"") -> 2640 | D24: =IFERROR(IF(D11="","",C24*(1+'0. Assumptions'!$B$34)),"") -> 2640 | E24: =IFERROR(C24/$C$11,"") -> 0.0081937226 | F24: 0 | G24: Assumption.
A25: Software, POS and payment processing | B25: 720 | C25: =IFERROR(IF(C11="","",B25*(1+'0. Assumptions'!$B$34)),"") -> 720 | D25: =IFERROR(IF(D11="","",C25*(1+'0. Assumptions'!$B$34)),"") -> 720 | E25: =IFERROR(C25/$C$11,"") -> 0.0022346516 | F25: 0 | G25: Assumption. Your POS has to tag to-go and for-here sales separately from day one (chapter 19 of the guide).
A26: Phone and internet | B26: 660 | C26: =IFERROR(IF(C11="","",B26*(1+'0. Assumptions'!$B$34)),"") -> 660 | D26: =IFERROR(IF(D11="","",C26*(1+'0. Assumptions'!$B$34)),"") -> 660 | E26: =IFERROR(C26/$C$11,"") -> 0.0020484307 | F26: 0 | G26: Assumption.
A27: Cleaning and supplies | B27: 2160 | C27: =IFERROR(IF(C11="","",B27*(1+'0. Assumptions'!$B$34)),"") -> 2160 | D27: =IFERROR(IF(D11="","",C27*(1+'0. Assumptions'!$B$34)),"") -> 2160 | E27: =IFERROR(C27/$C$11,"") -> 0.0067039549 | F27: 0 | G27: Assumption.
A28: Equipment maintenance | B28: 1800 | C28: =IFERROR(IF(C11="","",B28*(1+'0. Assumptions'!$B$34)),"") -> 1800 | D28: =IFERROR(IF(D11="","",C28*(1+'0. Assumptions'!$B$34)),"") -> 1800 | E28: =IFERROR(C28/$C$11,"") -> 0.0055866291 | F28: 0 | G28: Assumption.
A29: Advertising and social media | B29: 2400 | C29: =IFERROR(IF(C11="","",B29*(1+'0. Assumptions'!$B$34)),"") -> 2400 | D29: =IFERROR(IF(D11="","",C29*(1+'0. Assumptions'!$B$34)),"") -> 2400 | E29: =IFERROR(C29/$C$11,"") -> 0.0074488388 | F29: 0 | G29: Assumption.
A30: Other overhead | B30: 1800 | C30: =IFERROR(IF(C11="","",B30*(1+'0. Assumptions'!$B$34)),"") -> 1800 | D30: =IFERROR(IF(D11="","",C30*(1+'0. Assumptions'!$B$34)),"") -> 1800 | E30: =IFERROR(C30/$C$11,"") -> 0.0055866291 | F30: 0 | G30: Assumption.
A31: Depreciation | B31: =IFERROR(IF(B11="","",'Startup Investment'!$B$27),"") -> 16090.034 | C31: =IFERROR(IF(C11="","",'Startup Investment'!$B$27),"") -> 16090.034 | D31: =IFERROR(IF(D11="","",'Startup Investment'!$B$27),"") -> 16090.034 | E31: =IFERROR(C31/$C$11,"") -> 0.049938362 | F31: 0 | G31: It comes from the depreciation base on the "Startup Investment" sheet. It doesn't rise with inflation: it's an accounting spread of an investment already made.
A32: Loan interest | B32: =IFERROR(IF(B11="","",'Financing'!$B$116),"") -> 3671.1048 | C32: =IFERROR(IF(C11="","",'Financing'!$B$117),"") -> 3259.673 | D32: =IFERROR(IF(D11="","",'Financing'!$B$118),"") -> 2750.6598 | E32: =IFERROR(C32/$C$11,"") -> 0.010116991 | F32: 0 | G32: Only the INTEREST is an expense. The principal repaid leaves your cash but not your profit: it's on the "12-Month Cash Flow" sheet.
A33: TOTAL FIXED COSTS | B33: =IFERROR(IF(B11="","",SUM(B19:B32)),"") -> 186757.22 | C33: =IFERROR(IF(C11="","",SUM(C19:C32)),"") -> 186345.79 | D33: =IFERROR(IF(D11="","",SUM(D19:D32)),"") -> 185836.77 | E33: =IFERROR(C33/$C$11,"") -> 0.57835821
A34: Input VAT/GST on variable costs (UK, Canada, Australia; $0 in the US) | B34: =IFERROR(IF(B11="","",B15*$F$15),"") -> 0 | C34: =IFERROR(IF(C11="","",C15*$F$15),"") -> 0 | D34: =IFERROR(IF(D11="","",D15*$F$15),"") -> 0
A35: Input VAT/GST on fixed costs (UK, Canada, Australia; $0 in the US) | B35: =IFERROR(IF(B11="","",SUMPRODUCT(B19:B32,$F$19:$F$32)),"") -> 0 | C35: =IFERROR(IF(C11="","",SUMPRODUCT(C19:C32,$F$19:$F$32)),"") -> 0 | D35: =IFERROR(IF(D11="","",SUMPRODUCT(D19:D32,$F$19:$F$32)),"") -> 0 | G35: Each line at ITS rate, read from the column next to it. It's what the "12-Month Cash Flow" sheet pays suppliers on top and then recovers on the VAT/GST return. $0 in the US.
A36: PRE-TAX PROFIT | B36: =IFERROR(IF(B11="","",B17-B33),"") -> 5257.2164 | C36: =IFERROR(IF(C11="","",C17-C33),"") -> 32748.768 | D36: =IFERROR(IF(D11="","",D17-D33),"") -> 42021.563 | E36: =IFERROR(C36/$C$11,"") -> 0.10164179
A37: Net operating losses at the start of the year | B37: =IFERROR(IF(B11="","",'0. Assumptions'!$B$45),"") -> 0 | C37: =IFERROR(IF(C11="","",B42),"") -> 0 | D37: =IFERROR(IF(D11="","",C42),"") -> 0 | G37: A loss in one year can be carried forward against later profits (a net operating loss); how much and for how long depends on your business structure: ask your CPA.
A38: Taxable income (after losses) | B38: =IFERROR(IF(B11="","",MAX(0,B36-B37)),"") -> 5257.2164 | C38: =IFERROR(IF(C11="","",MAX(0,C36-C37)),"") -> 32748.768 | D38: =IFERROR(IF(D11="","",MAX(0,D36-D37)),"") -> 42021.563
A39: Years with a profit (running count) | B39: =IFERROR(IF(B11="","",IF(B38>0,1,0)),"") -> 1 | C39: =IFERROR(IF(C11="","",B39+IF(C38>0,1,0)),"") -> 2 | D39: =IFERROR(IF(D11="","",C39+IF(D38>0,1,0)),"") -> 3
A40: Income tax rate (illustrative) | B40: =IFERROR(IF(B11="","",IF(B38<=0,"",IF(B39<=2,'0. Assumptions'!$B$43,'0. Assumptions'!$B$44))),"") -> 0.15 | C40: =IFERROR(IF(C11="","",IF(C38<=0,"",IF(C39<=2,'0. Assumptions'!$B$43,'0. Assumptions'!$B$44))),"") -> 0.15 | D40: =IFERROR(IF(D11="","",IF(D38<=0,"",IF(D39<=2,'0. Assumptions'!$B$43,'0. Assumptions'!$B$44))),"") -> 0.25 | G40: Illustrative: 15% for the first two years with a profit, 25% after. By default a single-member LLC is reported on its owner's return and a multi-member LLC is classified as a partnership (IRS): ask your CPA.
A41: Income tax (the workbook's illustrative rate) | B41: =IFERROR(IF(B11="","",IF(B40="",0,B38*B40)),"") -> 788.58246 | C41: =IFERROR(IF(C11="","",IF(C40="",0,C38*C40)),"") -> 4912.3152 | D41: =IFERROR(IF(D11="","",IF(D40="",0,D38*D40)),"") -> 10505.391
...

Sheet Break-Even
A1: Break-Even: How Many Tickets a Day
A2: AI Chef Pro · aichef.pro — How to Open a Pastry Shop
A3: Two thresholds, and they don't say the same thing. The ACCOUNTING one includes depreciation; the CASH one takes out depreciation (which you don't pay out) and adds the loan principal you repay (which you do). The second is the one that decides whether you make it to the end of the month.
A5: Variable | B5: Year 1 | C5: Year 2 | D5: Year 3 | E5: Notes
A6: BASE DATA BY YEAR
A7: Annual fixed costs | B7: =IFERROR(IF('3-Year P&L'!B11="","",'3-Year P&L'!B33),"") -> 186757.22 | C7: =IFERROR(IF('3-Year P&L'!C11="","",'3-Year P&L'!C33),"") -> 186345.79 | D7: =IFERROR(IF('3-Year P&L'!D11="","",'3-Year P&L'!D33),"") -> 185836.77 | E7: The SAME fixed costs as the P&L. Each year has its own: that's why the threshold can't be a single one for all three.
A8: Monthly fixed costs | B8: =IFERROR(IF('3-Year P&L'!B11="","",B7/12),"") -> 15563.101 | C8: =IFERROR(IF('3-Year P&L'!C11="","",C7/12),"") -> 15528.815 | D8: =IFERROR(IF('3-Year P&L'!D11="","",D7/12),"") -> 15486.398
A9: Average ticket before sales tax ($) | B9: =IFERROR(IF('3-Year P&L'!B11="","",'3-Year P&L'!B8),"") -> 5.8688137 | C9: =IFERROR(IF('3-Year P&L'!C11="","",'3-Year P&L'!C8),"") -> 5.8688137 | D9: =IFERROR(IF('3-Year P&L'!D11="","",'3-Year P&L'!D8),"") -> 5.8688137
A10: Variable cost per ticket ($) | B10: =IFERROR(IF('3-Year P&L'!B11="","",'3-Year P&L'!B16/('3-Year P&L'!B7*'3-Year P&L'!B9*'3-Year P&L'!B10)),"") -> 1.8780204 | C10: =IFERROR(IF('3-Year P&L'!C11="","",'3-Year P&L'!C16/('3-Year P&L'!C7*'3-Year P&L'!C9*'3-Year P&L'!C10)),"") -> 1.8780204 | D10: =IFERROR(IF('3-Year P&L'!D11="","",'3-Year P&L'!D16/('3-Year P&L'!D7*'3-Year P&L'!D9*'3-Year P&L'!D10)),"") -> 1.8780204 | E10: It comes from the P&L's total variable costs divided by that year's tickets, not from a separate estimate.
A11: Contribution margin per ticket ($) | B11: =IFERROR(IF('3-Year P&L'!B11="","",B9-B10),"") -> 3.9907933 | C11: =IFERROR(IF('3-Year P&L'!C11="","",C9-C10),"") -> 3.9907933 | D11: =IFERROR(IF('3-Year P&L'!D11="","",D9-D10),"") -> 3.9907933 | E11: Ticket minus unit variable cost. It's what each customer leaves behind to pay the fixed costs.
A12: Days open per year | B12: =IFERROR(IF('3-Year P&L'!B11="","",'3-Year P&L'!B9),"") -> 300 | C12: =IFERROR(IF('3-Year P&L'!C11="","",'3-Year P&L'!C9),"") -> 300 | D12: =IFERROR(IF('3-Year P&L'!D11="","",'3-Year P&L'!D9),"") -> 300
A13: Loan principal repaid this year (cash out) | B13: =IFERROR(IF('3-Year P&L'!B11="","",'Financing'!$C$116),"") -> 3808.3297 | C13: =IFERROR(IF('3-Year P&L'!C11="","",'Financing'!$C$117),"") -> 7979.196 | D13: =IFERROR(IF('3-Year P&L'!D11="","",'Financing'!$C$118),"") -> 8488.2092 | E13: Principal is NOT a P&L expense, but it leaves your cash. Without it, the break-even threshold gets published below what you really need to sell.
A14: ACCOUNTING BREAK-EVEN (includes depreciation)
A15: Tickets needed per year | B15: =IFERROR(IF('3-Year P&L'!B11="","",IF(B11<=0,"",B7/B11)),"") -> 46797.016 | C15: =IFERROR(IF('3-Year P&L'!C11="","",IF(C11<=0,"",C7/C11)),"") -> 46693.92 | D15: =IFERROR(IF('3-Year P&L'!D11="","",IF(D11<=0,"",D7/D11)),"") -> 46566.373
A16: Tickets needed per day | B16: =IFERROR(IF('3-Year P&L'!B11="","",B15/B12),"") -> 155.99005 | C16: =IFERROR(IF('3-Year P&L'!C11="","",C15/C12),"") -> 155.6464 | D16: =IFERROR(IF('3-Year P&L'!D11="","",D15/D12),"") -> 155.22124
A17: Revenue needed per year (before sales tax) | B17: =IFERROR(IF('3-Year P&L'!B11="","",B15*B9),"") -> 274642.97 | C17: =IFERROR(IF('3-Year P&L'!C11="","",C15*C9),"") -> 274037.92 | D17: =IFERROR(IF('3-Year P&L'!D11="","",D15*D9),"") -> 273289.37
A18: Revenue needed per month (before sales tax) | B18: =IFERROR(IF('3-Year P&L'!B11="","",B17/12),"") -> 22886.914 | C18: =IFERROR(IF('3-Year P&L'!C11="","",C17/12),"") -> 22836.493 | D18: =IFERROR(IF('3-Year P&L'!D11="","",D17/12),"") -> 22774.114
A19: CASH BREAK-EVEN (includes the loan payment)
A20: Cash fixed costs plus the year's principal | B20: =IFERROR(IF('3-Year P&L'!B11="","",B7-'3-Year P&L'!B31+B13),"") -> 174475.51 | C20: =IFERROR(IF('3-Year P&L'!C11="","",C7-'3-Year P&L'!C31+C13),"") -> 178234.95 | D20: =IFERROR(IF('3-Year P&L'!D11="","",D7-'3-Year P&L'!D31+D13),"") -> 178234.95 | E20: The P&L's fixed costs without depreciation (which you don't pay out) and WITH the principal repaid (which you do). It's the threshold that decides whether you survive, not the accounting one.
A21: Tickets needed per year (cash) | B21: =IFERROR(IF('3-Year P&L'!B11="","",IF(B11<=0,"",B20/B11)),"") -> 43719.506 | C21: =IFERROR(IF('3-Year P&L'!C11="","",IF(C11<=0,"",C20/C11)),"") -> 44661.533 | D21: =IFERROR(IF('3-Year P&L'!D11="","",IF(D11<=0,"",D20/D11)),"") -> 44661.533
A22: Tickets needed per day (cash) | B22: =IFERROR(IF('3-Year P&L'!B11="","",B21/B12),"") -> 145.73169 | C22: =IFERROR(IF('3-Year P&L'!C11="","",C21/C12),"") -> 148.87178 | D22: =IFERROR(IF('3-Year P&L'!D11="","",D21/D12),"") -> 148.87178
A23: Revenue needed per year (cash, before sales tax) | B23: =IFERROR(IF('3-Year P&L'!B11="","",B21*B9),"") -> 256581.64 | C23: =IFERROR(IF('3-Year P&L'!C11="","",C21*C9),"") -> 262110.22 | D23: =IFERROR(IF('3-Year P&L'!D11="","",D21*D9),"") -> 262110.22
A24: CHECK AGAINST THE PLAN
A25: Tickets a day forecast in the plan | B25: =IFERROR(IF('3-Year P&L'!B11="","",'3-Year P&L'!B7*'3-Year P&L'!B10),"") -> 160.38117 | C25: =IFERROR(IF('3-Year P&L'!C11="","",'3-Year P&L'!C7*'3-Year P&L'!C10),"") -> 183 | D25: =IFERROR(IF('3-Year P&L'!D11="","",'3-Year P&L'!D7*'3-Year P&L'!D10),"") -> 190.32
A26: Cushion above CASH break-even (%) | B26: =IFERROR(IF('3-Year P&L'!B11="","",IF(B22<=0,"",B25/B22-1)),"") -> 0.10052368 | C26: =IFERROR(IF('3-Year P&L'!C11="","",IF(C22<=0,"",C25/C22-1)),"") -> 0.22924576 | D26: =IFERROR(IF('3-Year P&L'!D11="","",IF(D22<=0,"",D25/D22-1)),"") -> 0.27841559 | E26: How far the plan sits above CASH break-even. The drop in sales it can absorb is smaller: 1 − 1/(1 + this %), about 18.6% in the case. The minimum required is in "0. Assumptions".
A27: Reading the cushion | B27: =IFERROR(IF('3-Year P&L'!B11="","",IF(B26<0,"Below break-even",IF(B26<'0. Assumptions'!$B$60,"Tight","Enough"))),"") -> Tight | C27: =IFERROR(IF('3-Year P&L'!C11="","",IF(C26<0,"Below break-even",IF(C26<'0. Assumptions'!$B$60,"Tight","Enough"))),"") -> Enough | D27: =IFERROR(IF('3-Year P&L'!D11="","",IF(D26<0,"Below break-even",IF(D26<'0. Assumptions'!$B$60,"Tight","Enough"))),"") -> Enough
A28: Quick read: if the tickets a day you forecast are below the CASH tickets a day, the business doesn't generate enough to pay the fixed costs and the loan payment, whatever the accounting result says. If they're just above, you have no room for a bad month: negotiate interest-only months, lower the investment or review the average ticket before you sign anything.
A30: BREAK-EVEN SENSITIVITY (steady-state year)
A31: Tickets a day needed: average ticket (columns) × variable cost per ticket (rows) | B31: =IFERROR($C$9-1,"") -> 4.8688137 | C31: =IFERROR($C$9,"") -> 5.8688137 | D31: =IFERROR($C$9+1,"") -> 6.8688137 | E31: =IFERROR($C$9+2,"") -> 7.8688137
A32: =IFERROR($C$10-2*'0. Assumptions'!$B$65,"") -> 1.4780204 | B32: =IFERROR(IF(B$31-$A32<=0,"",$C$7/(B$31-$A32)/$C$12),"") -> 183.18799 | C32: =IFERROR(IF(C$31-$A32<=0,"",$C$7/(C$31-$A32)/$C$12),"") -> 141.46706 | D32: =IFERROR(IF(D$31-$A32<=0,"",$C$7/(D$31-$A32)/$C$12),"") -> 115.22471 | E32: =IFERROR(IF(E$31-$A32<=0,"",$C$7/(E$31-$A32)/$C$12),"") -> 97.194916
A33: =IFERROR($C$10-1*'0. Assumptions'!$B$65,"") -> 1.6780204 | B33: =IFERROR(IF(B$31-$A33<=0,"",$C$7/(B$31-$A33)/$C$12),"") -> 194.67028 | C33: =IFERROR(IF(C$31-$A33<=0,"",$C$7/(C$31-$A33)/$C$12),"") -> 148.21839 | D33: =IFERROR(IF(D$31-$A33<=0,"",$C$7/(D$31-$A33)/$C$12),"") -> 119.66429 | E33: =IFERROR(IF(E$31-$A33<=0,"",$C$7/(E$31-$A33)/$C$12),"") -> 100.3349
A34: =IFERROR($C$10,"") -> 1.8780204 | B34: =IFERROR(IF(B$31-$A34<=0,"",$C$7/(B$31-$A34)/$C$12),"") -> 207.68825 | C34: =IFERROR(IF(C$31-$A34<=0,"",$C$7/(C$31-$A34)/$C$12),"") -> 155.6464 | D34: =IFERROR(IF(D$31-$A34<=0,"",$C$7/(D$31-$A34)/$C$12),"") -> 124.4597 | E34: =IFERROR(IF(E$31-$A34<=0,"",$C$7/(E$31-$A34)/$C$12),"") -> 103.68453
A35: =IFERROR($C$10+1*'0. Assumptions'!$B$65,"") -> 2.0780204 | B35: =IFERROR(IF(B$31-$A35<=0,"",$C$7/(B$31-$A35)/$C$12),"") -> 222.57206 | C35: =IFERROR(IF(C$31-$A35<=0,"",$C$7/(C$31-$A35)/$C$12),"") -> 163.85821 | D35: =IFERROR(IF(D$31-$A35<=0,"",$C$7/(D$31-$A35)/$C$12),"") -> 129.65548 | E35: =IFERROR(IF(E$31-$A35<=0,"",$C$7/(E$31-$A35)/$C$12),"") -> 107.26555
A36: =IFERROR($C$10+2*'0. Assumptions'!$B$65,"") -> 2.2780204 | B36: =IFERROR(IF(B$31-$A36<=0,"",$C$7/(B$31-$A36)/$C$12),"") -> 239.75383 | C36: =IFERROR(IF(C$31-$A36<=0,"",$C$7/(C$31-$A36)/$C$12),"") -> 172.98479 | D36: =IFERROR(IF(D$31-$A36<=0,"",$C$7/(D$31-$A36)/$C$12),"") -> 135.30398 | E36: =IFERROR(IF(E$31-$A36<=0,"",$C$7/(E$31-$A36)/$C$12),"") -> 111.10277
A38: The center cell is your scenario. Move one column to the left and you're seeing what happens if you have to cut the average ticket by a dollar; one row down, what happens if butter and cocoa push up your variable cost. Both can happen in a single year.

Sheet Scenarios
A1: Scenarios: Pessimistic, Realistic and Optimistic
A2: AI Chef Pro · aichef.pro — How to Open a Pastry Shop
A3: The "Realistic" column READS the P&L's steady-state year, so it can't drift away from it. The other two are green: they're your bets, and the one on the left is the one you have to be able to survive.
A5: Metric | B5: Pessimistic | C5: Realistic | D5: Optimistic | E5: Notes
A6: Tickets a day | B6: 140 | C6: =IFERROR('3-Year P&L'!C7,"") -> 183 | D6: 220 | E6: Both extremes are ASSUMPTIONS. The pessimistic one isn't "a bad day": it's the whole year going badly.
A7: Average ticket before sales tax ($) | B7: 5.2 | C7: =IFERROR('3-Year P&L'!C8,"") -> 5.8688137 | D7: 6.6 | E7: ASSUMPTIONS. Cutting the average ticket by a dollar weighs more than losing twenty customers a day: see it in the break-even sensitivity table.
A8: Days open per year | B8: 290 | C8: =IFERROR('3-Year P&L'!C9,"") -> 300 | D8: 305 | E8: ASSUMPTIONS.
A9: ANNUAL REVENUE (before sales tax) | B9: =IFERROR(IF(B6*B7*B8=0,"",B6*B7*B8),"") -> 211120 | C9: =IFERROR(IF(C6*C7*C8=0,"",C6*C7*C8),"") -> 322197.87 | D9: =IFERROR(IF(D6*D7*D8=0,"",D6*D7*D8),"") -> 442860
A10: Cost of sales (single food cost rule) | B10: =IFERROR(IF(B9="","",B9*'0. Assumptions'!$B$22),"") -> 67558.4 | C10: =IFERROR(IF(C9="","",C9*'0. Assumptions'!$B$22),"") -> 103103.32 | D10: =IFERROR(IF(D9="","",D9*'0. Assumptions'!$B$22),"") -> 141715.2
A11: TOTAL VARIABLE COSTS | B11: =IFERROR(IF(B9="","",SUM(B10:B10)),"") -> 67558.4 | C11: =IFERROR(IF(C9="","",SUM(C10:C10)),"") -> 103103.32 | D11: =IFERROR(IF(D9="","",SUM(D10:D10)),"") -> 141715.2
A12: GROSS MARGIN | B12: =IFERROR(IF(B9="","",B9-B11),"") -> 143561.6 | C12: =IFERROR(IF(C9="","",C9-C11),"") -> 219094.55 | D12: =IFERROR(IF(D9="","",D9-D11),"") -> 301144.8
A13: FIXED COSTS (the P&L's steady-state year) | B13: =IFERROR(IF(B9="","",'3-Year P&L'!$C$33),"") -> 186345.79 | C13: =IFERROR(IF(C9="","",'3-Year P&L'!$C$33),"") -> 186345.79 | D13: =IFERROR(IF(D9="","",'3-Year P&L'!$C$33),"") -> 186345.79 | E13: Fixed costs don't change with the scenario: that's why they're fixed. If they soar against sales in the pessimistic one, the adjustment is made on the "Staff" sheet, not here.
A14: PRE-TAX PROFIT | B14: =IFERROR(IF(B9="","",B12-B13),"") -> -42784.185 | C14: =IFERROR(IF(C9="","",C12-C13),"") -> 32748.768 | D14: =IFERROR(IF(D9="","",D12-D13),"") -> 114799.01
A15: Income tax (the workbook's illustrative rate) | B15: =IFERROR(IF(B9="","",MAX(0,B14-'0. Assumptions'!$B$45)*'0. Assumptions'!$B$43),"") -> 0 | C15: =IFERROR(IF(C9="","",MAX(0,C14-'0. Assumptions'!$B$45)*'0. Assumptions'!$B$43),"") -> 4912.3152 | D15: =IFERROR(IF(D9="","",MAX(0,D14-'0. Assumptions'!$B$45)*'0. Assumptions'!$B$43),"") -> 17219.852 | E15: At the workbook's illustrative income tax rate for the first years with a profit (15%), after any net operating losses carried forward. With a loss there's no tax.
A16: NET PROFIT | B16: =IFERROR(IF(B9="","",B14-B15),"") -> -42784.185 | C16: =IFERROR(IF(C9="","",C14-C15),"") -> 27836.453 | D16: =IFERROR(IF(D9="","",D14-D15),"") -> 97579.162
A17: Net margin (%) | B17: =IFERROR(IF(B9="","",B16/B9),"") -> -0.2026534 | C17: =IFERROR(IF(C9="","",C16/C9),"") -> 0.08639552 | D17: =IFERROR(IF(D9="","",D16/D9),"") -> 0.22033862 | E17: Compare it with the 8-12% reference band in "0. Assumptions". An optimistic scenario far above it is usually forgetting a cost, not discovering a better business.
A18: Tickets a day to break even | B18: =IFERROR(IF(B9="","",IF(B7-B11/(B6*B8)<=0,"",B13/(B7-B11/(B6*B8))/B8)),"") -> 181.72276 | C18: =IFERROR(IF(C9="","",IF(C7-C11/(C6*C8)<=0,"",C13/(C7-C11/(C6*C8))/C8)),"") -> 155.6464 | D18: =IFERROR(IF(D9="","",IF(D7-D11/(D6*D8)<=0,"",D13/(D7-D11/(D6*D8))/D8)),"") -> 136.13409
A19: WHAT EACH SCENARIO DEMANDS
A20: Staff cost / sales | B20: =IFERROR(IF(B9="","",'3-Year P&L'!$C$19/B9),"") -> 0.43944713 | C20: =IFERROR(IF(C9="","",'3-Year P&L'!$C$19/C9),"") -> 0.28794752 | D20: =IFERROR(IF(D9="","",'3-Year P&L'!$C$19/D9),"") -> 0.20949302 | E20: The SAME team in all three scenarios: five people and 3.5 FTEs. The pessimistic one is where you see whether that team holds up.
A21: Sales per year per FTE ($) | B21: =IFERROR(IF(B9="","",B9/'Staff'!$C$11),"") -> 60320 | C21: =IFERROR(IF(C9="","",C9/'Staff'!$C$11),"") -> 92056.535 | D21: =IFERROR(IF(D9="","",D9/'Staff'!$C$11),"") -> 126531.43 | E21: How much each full-time equivalent on the "Staff" sheet would have to sell. In the optimistic one it tells you whether you'd need to hire before getting there.
A22: Estimated cash balance at the end of year 1 (same method in all three) | B22: =IFERROR(IF(B9="","",'Startup Investment'!$B$18+B16+'3-Year P&L'!$C$31-'Financing'!$C$116),"") -> 31612.781 | C22: =IFERROR(IF(C9="","",'Startup Investment'!$B$18+C16+'3-Year P&L'!$C$31-'Financing'!$C$116),"") -> 102233.42 | D22: =IFERROR(IF(D9="","",'Startup Investment'!$B$18+D16+'3-Year P&L'!$C$31-'Financing'!$C$116),"") -> 171976.13 | E22: Working capital plus the year's result, adding back depreciation (which you don't pay out) and subtracting principal (which you do). It's an ESTIMATE: the real balance, with the lag in collections and, where it applies, VAT/GST, is on the "12-Month Cash Flow" sheet.
A23: Actual month-12 balance from the "12-Month Cash Flow" sheet (realistic only) | C23: =IFERROR(IF(C9="","",'12-Month Cash Flow'!M23),"") -> 87811.132 | E23: It only exists for the base case: the month-by-month cash flow is built on the P&L's year 1, not on the scenarios.
A25: The "Realistic" column reads its three inputs from the P&L's steady-state year, so it reproduces that year EXACTLY. If you want to move the base case, move it in "0. Assumptions" and this column follows.

Sheet Staff
A1: Staff: Five People and 3.5 FTEs
A2: AI Chef Pro · aichef.pro — How to Open a Pastry Shop
A3: The four roles are the case's (Head Pastry Chef, Pastry Cook, Bakery Assistant and Counter Associate), with TWO people as Counter Associate. Base pay comes from the case's wage table, in a green cell, and payroll taxes, workers' comp and benefits go INSIDE: from gross pay to employer cost there's a third more.
A5: Person and role | B5: People | C5: FTE | D5: Pay grade | E5: Monthly pay for the grade ($) | F5: Monthly pay for the role ($) | G5: Payroll taxes, workers' comp and benefits ($) | H5: Monthly employer cost ($) | I5: Annual employer cost ($) | J5: Hours/week | K5: Notes
A6: P1 · Head Pastry Chef | B6: 1 | C6: 1 | D6: Group 2 | E6: =IFERROR(INDEX($E$15:$E$20,MATCH(D6,$A$15:$A$20,0)),"") -> 1784.8625 | F6: =IFERROR(E6*C6*B6,"") -> 1784.8625 | G6: =IFERROR(F6*'0. Assumptions'!$B$25,"") -> 589.00463 | H6: =IFERROR(F6+G6,"") -> 2373.8671 | I6: =IFERROR(H6*MAX(12,'0. Assumptions'!$B$26),"") -> 28486.406 | J6: 40 | K6: PRODUCTION KITCHEN area · Early bake shift (04:30-12:30)
A7: P2 · Pastry Cook | B7: 1 | C7: 1 | D7: Group 3 | E7: =IFERROR(INDEX($E$15:$E$20,MATCH(D7,$A$15:$A$20,0)),"") -> 1721.1375 | F7: =IFERROR(E7*C7*B7,"") -> 1721.1375 | G7: =IFERROR(F7*'0. Assumptions'!$B$25,"") -> 567.97537 | H7: =IFERROR(F7+G7,"") -> 2289.1129 | I7: =IFERROR(H7*MAX(12,'0. Assumptions'!$B$26),"") -> 27469.354 | J7: 40 | K7: PRODUCTION KITCHEN area · Early bake shift (05:00-13:00)
A8: P3 · Bakery Assistant | B8: 1 | C8: 0.5 | D8: Group 5 | E8: =IFERROR(INDEX($E$15:$E$20,MATCH(D8,$A$15:$A$20,0)),"") -> 1490.525 | F8: =IFERROR(E8*C8*B8,"") -> 745.2625 | G8: =IFERROR(F8*'0. Assumptions'!$B$25,"") -> 245.93663 | H8: =IFERROR(F8+G8,"") -> 991.19913 | I8: =IFERROR(H8*MAX(12,'0. Assumptions'!$B$26),"") -> 11894.39 | J8: 20 | K8: PRODUCTION KITCHEN area · Morning shift (07:00-11:00)
A9: P4 · Counter Associate A | B9: 1 | C9: 0.5 | D9: Group 4 | E9: =IFERROR(INDEX($E$15:$E$20,MATCH(D9,$A$15:$A$20,0)),"") -> 1561.775 | F9: =IFERROR(E9*C9*B9,"") -> 780.8875 | G9: =IFERROR(F9*'0. Assumptions'!$B$25,"") -> 257.69288 | H9: =IFERROR(F9+G9,"") -> 1038.5804 | I9: =IFERROR(H9*MAX(12,'0. Assumptions'!$B$26),"") -> 12462.965 | J9: 20 | K9: FRONT COUNTER area · Morning shift (08:00-12:00)
A10: P5 · Counter Associate B | B10: 1 | C10: 0.5 | D10: Group 4 | E10: =IFERROR(INDEX($E$15:$E$20,MATCH(D10,$A$15:$A$20,0)),"") -> 1561.775 | F10: =IFERROR(E10*C10*B10,"") -> 780.8875 | G10: =IFERROR(F10*'0. Assumptions'!$B$25,"") -> 257.69288 | H10: =IFERROR(F10+G10,"") -> 1038.5804 | I10: =IFERROR(H10*MAX(12,'0. Assumptions'!$B$26),"") -> 12462.965 | J10: 20 | K10: FRONT COUNTER area · Afternoon shift (16:30-20:30)
A11: TOTAL for the team | B11: =IFERROR(IF(COUNT(E6:E10)=0,"",SUM(B6:B10)),"") -> 5 | C11: =IFERROR(IF(COUNT(E6:E10)=0,"",SUM(C6:C10)),"") -> 3.5 | F11: =IFERROR(IF(COUNT(E6:E10)=0,"",SUM(F6:F10)),"") -> 5813.0375 | G11: =IFERROR(IF(COUNT(E6:E10)=0,"",SUM(G6:G10)),"") -> 1918.3024 | H11: =IFERROR(IF(COUNT(E6:E10)=0,"",SUM(H6:H10)),"") -> 7731.3399 | I11: =IFERROR(IF(COUNT(E6:E10)=0,"",SUM(I6:I10)),"") -> 92776.079 | J11: =IFERROR(IF(COUNT(E6:E10)=0,"",SUM(J6:J10)),"") -> 140 | K11: This "Annual employer cost" is the one the P&L reads. There's no second staffing estimate anywhere in the workbook.
A13: THE CASE'S WAGE TABLE (replace it with yours)
A14: Group | B14: Name | E14: Monthly pay ($) | F14: Annual pay ($) | G14: Functional areas | I14: Roles the table lists
A15: Group 1 | B15: Office and administration (degree-level) | E15: 2167.35 | F15: =IFERROR(E15*MAX(12,'0. Assumptions'!$B$26),"") -> 26008.2 | G15: ADMINISTRATION | I15: -
A16: Group 2 | B16: Management and supervisors | E16: 1784.8625 | F16: =IFERROR(E16*MAX(12,'0. Assumptions'!$B$26),"") -> 21418.35 | G16: PRODUCTION KITCHEN / FRONT COUNTER / ADMINISTRATION | I16: head of the production kitchen
A17: Group 3 | B17: Skilled specialists | E17: 1721.1375 | F17: =IFERROR(E17*MAX(12,'0. Assumptions'!$B$26),"") -> 20653.65 | G17: PRODUCTION KITCHEN / FRONT COUNTER | I17: lead production baker, section lead, head counter associate
A18: Group 4 | B18: Qualified staff | E18: 1561.775 | F18: =IFERROR(E18*MAX(12,'0. Assumptions'!$B$26),"") -> 18741.3 | G18: PRODUCTION KITCHEN / FRONT COUNTER | I18: production baker, lead packer, counter associate, delivery driver
A19: Group 5 | B19: Support staff | E19: 1490.525 | F19: =IFERROR(E19*MAX(12,'0. Assumptions'!$B$26),"") -> 17886.3 | G19: PRODUCTION KITCHEN / FRONT COUNTER | I19: production assistant, finisher, counter assistant
A20: Group 6 | B20: Auxiliary services | E20: 1490.525 | F20: =IFERROR(E20*MAX(12,'0. Assumptions'!$B$26),"") -> 17886.3 | G20: PRODUCTION KITCHEN / FRONT COUNTER | I20: general laborer, cleaner, stock clerk
A22: MINIMUM WAGE CHECK
A23: Annual pay of the lowest grade ($) | B23: =IFERROR(IF(COUNT(F15:F20)=0,"",MIN(F15:F20)),"") -> 17886.3
A24: Annual minimum wage for reference ($) | B24: =IFERROR('0. Assumptions'!$B$27,"") -> 15080
A25: Is any grade below the minimum wage? | B25: =IFERROR(IF(B23="","",IF(B23<B24,"Yes: below the annual minimum wage","No: every grade is above the minimum you entered")),"") -> No: every grade is above the minimum you entered | K25: The minimum here is the federal one ($7.25 an hour × 2,080 hours = $15,080 a year), which is also Texas's. Many states and cities set a higher one (California $16.90; New York $17.00 or $16.00 depending on the region; Florida $14.00 until September 29, 2026, so check FloridaCommerce for the current rate): at those rates, the case's wage table would be illegal. Put yours in "0. Assumptions".
A27: HOURS AND STAFFING
A28: Hours scheduled per week | B28: =IFERROR(J11,"") -> 140
A29: Full-time equivalents (FTEs) | B29: =IFERROR(C11,"") -> 3.5
A30: People scheduled for more hours than their FTE | B30: =IFERROR(SUMPRODUCT((J6:J10>C6:C10*'0. Assumptions'!$B$28)*1),"") -> 0 | K30: It has to read zero. If it turns red, someone hired part-time is working more hours than they're paid for: that isn't a saving, it's a wage claim waiting to happen.
A32: Seasonal extra staff is NOT in this table: the peaks call for three more people at Three Kings Day and one or two at the other peaks, and that's sized and costed in seasonal-peaks-planner.xlsx and staff-schedule-and-labor-cost.xlsx. This is the STEADY team, the one that goes into the P&L's fixed costs.

Sheet 12-Month Cash Flow
A1: Cash Flow for the First 12 Months
A2: AI Chef Pro · aichef.pro — How to Open a Pastry Shop
A3: The P&L says whether the business makes money; this sheet says whether it has the cash to reach the end of the month. It's the first one a lender looks at, and the one that has saved the most openings.
A5: Line | B5: Month 1 | C5: Month 2 | D5: Month 3 | E5: Month 4 | F5: Month 5 | G5: Month 6 | H5: Month 7 | I5: Month 8 | J5: Month 9 | K5: Month 10 | L5: Month 11 | M5: Month 12 | N5: Year ($) | O5: Notes
A6: Monthly seasonality (has to add up to 100%) | B6: 0.111667 | C6: 0.0775 | D6: 0.080833 | E6: 0.086667 | F6: 0.089167 | G6: 0.080833 | H6: 0.070833 | I6: 0.054167 | J6: 0.075833 | K6: 0.079167 | L6: 0.09 | M6: 0.103333 | N6: =IFERROR(SUM(B6:M6),"") -> 1 | O6: January leads with Three Kings Day and December with the holidays; August is the low point. It's a mid-size city's profile: in a beach town, summer goes up. It has to add up to 100%, and the year cell tells you.
A7: Ramp-up (% of steady-state activity) | B7: =IFERROR(MIN(1,'0. Assumptions'!$B$49+(1-'0. Assumptions'!$B$49)*0/MAX(1,'0. Assumptions'!$B$50-1)),"") -> 0.55 | C7: =IFERROR(MIN(1,'0. Assumptions'!$B$49+(1-'0. Assumptions'!$B$49)*1/MAX(1,'0. Assumptions'!$B$50-1)),"") -> 0.64 | D7: =IFERROR(MIN(1,'0. Assumptions'!$B$49+(1-'0. Assumptions'!$B$49)*2/MAX(1,'0. Assumptions'!$B$50-1)),"") -> 0.73 | E7: =IFERROR(MIN(1,'0. Assumptions'!$B$49+(1-'0. Assumptions'!$B$49)*3/MAX(1,'0. Assumptions'!$B$50-1)),"") -> 0.82 | F7: =IFERROR(MIN(1,'0. Assumptions'!$B$49+(1-'0. Assumptions'!$B$49)*4/MAX(1,'0. Assumptions'!$B$50-1)),"") -> 0.91 | G7: =IFERROR(MIN(1,'0. Assumptions'!$B$49+(1-'0. Assumptions'!$B$49)*5/MAX(1,'0. Assumptions'!$B$50-1)),"") -> 1 | H7: =IFERROR(MIN(1,'0. Assumptions'!$B$49+(1-'0. Assumptions'!$B$49)*6/MAX(1,'0. Assumptions'!$B$50-1)),"") -> 1 | I7: =IFERROR(MIN(1,'0. Assumptions'!$B$49+(1-'0. Assumptions'!$B$49)*7/MAX(1,'0. Assumptions'!$B$50-1)),"") -> 1 | J7: =IFERROR(MIN(1,'0. Assumptions'!$B$49+(1-'0. Assumptions'!$B$49)*8/MAX(1,'0. Assumptions'!$B$50-1)),"") -> 1 | K7: =IFERROR(MIN(1,'0. Assumptions'!$B$49+(1-'0. Assumptions'!$B$49)*9/MAX(1,'0. Assumptions'!$B$50-1)),"") -> 1 | L7: =IFERROR(MIN(1,'0. Assumptions'!$B$49+(1-'0. Assumptions'!$B$49)*10/MAX(1,'0. Assumptions'!$B$50-1)),"") -> 1 | M7: =IFERROR(MIN(1,'0. Assumptions'!$B$49+(1-'0. Assumptions'!$B$49)*11/MAX(1,'0. Assumptions'!$B$50-1)),"") -> 1 | O7: It climbs in a straight line from the month-1 percentage to 100% over the months you set in "0. Assumptions". With 100% in month 1 the ramp-up disappears, and then you're projecting an opening that doesn't exist.
A8: Share of activity by month (calculated) | B8: =IFERROR(B6*B7/SUMPRODUCT($B$6:$M$6,$B$7:$M$7),"") -> 0.070078572 | C8: =IFERROR(C6*C7/SUMPRODUCT($B$6:$M$6,$B$7:$M$7),"") -> 0.056595172 | D8: =IFERROR(D6*D7/SUMPRODUCT($B$6:$M$6,$B$7:$M$7),"") -> 0.067330101 | E8: =IFERROR(E6*E7/SUMPRODUCT($B$6:$M$6,$B$7:$M$7),"") -> 0.08108963 | F8: =IFERROR(F6*F7/SUMPRODUCT($B$6:$M$6,$B$7:$M$7),"") -> 0.092585559 | G8: =IFERROR(G6*G7/SUMPRODUCT($B$6:$M$6,$B$7:$M$7),"") -> 0.092233014 | H8: =IFERROR(H6*H7/SUMPRODUCT($B$6:$M$6,$B$7:$M$7),"") -> 0.080822698 | I8: =IFERROR(I6*I7/SUMPRODUCT($B$6:$M$6,$B$7:$M$7),"") -> 0.061806263 | ... M8: =IFERROR(M6*M7/SUMPRODUCT($B$6:$M$6,$B$7:$M$7),"") -> 0.11790623 | N8: =IFERROR(SUM(B8:M8),"") -> 1 | O8: Seasonality × ramp-up, normalized to 100%: the YEAR sells what the P&L says, but spread the way reality spreads it.
A9: COLLECTIONS
A10: Sales collected (VAT/GST included where it applies; $0 of tax in the US) | B10: =IFERROR(IF('3-Year P&L'!$B$11="","",'3-Year P&L'!$B$11*(1+'0. Assumptions'!$B$20)*(B8*(1-'0. Assumptions'!$B$52/30))),"") -> 18304.25 | C10: =IFERROR(IF('3-Year P&L'!$B$11="","",'3-Year P&L'!$B$11*(1+'0. Assumptions'!$B$20)*(C8*(1-'0. Assumptions'!$B$52/30)+B8*('0. Assumptions'!$B$52/30))),"") -> 16266.567 | D10: =IFERROR(IF('3-Year P&L'!$B$11="","",'3-Year P&L'!$B$11*(1+'0. Assumptions'!$B$20)*(D8*(1-'0. Assumptions'!$B$52/30)+C8*('0. Assumptions'!$B$52/30))),"") -> 18784.936 | E10: =IFERROR(IF('3-Year P&L'!$B$11="","",'3-Year P&L'!$B$11*(1+'0. Assumptions'!$B$20)*(E8*(1-'0. Assumptions'!$B$52/30)+D8*('0. Assumptions'!$B$52/30))),"") -> 22606.217 | F10: =IFERROR(IF('3-Year P&L'!$B$11="","",'3-Year P&L'!$B$11*(1+'0. Assumptions'!$B$20)*(F8*(1-'0. Assumptions'!$B$52/30)+E8*('0. Assumptions'!$B$52/30))),"") -> 25900.309 | G10: =IFERROR(IF('3-Year P&L'!$B$11="","",'3-Year P&L'!$B$11*(1+'0. Assumptions'!$B$20)*(G8*(1-'0. Assumptions'!$B$52/30)+F8*('0. Assumptions'!$B$52/30))),"") -> 26051.687 | H10: =IFERROR(IF('3-Year P&L'!$B$11="","",'3-Year P&L'!$B$11*(1+'0. Assumptions'!$B$20)*(H8*(1-'0. Assumptions'!$B$52/30)+G8*('0. Assumptions'!$B$52/30))),"") -> 23063.89 | I10: =IFERROR(IF('3-Year P&L'!$B$11="","",'3-Year P&L'!$B$11*(1+'0. Assumptions'!$B$20)*(I8*(1-'0. Assumptions'!$B$52/30)+H8*('0. Assumptions'!$B$52/30))),"") -> 17855.223 | J10: =IFERROR(IF('3-Year P&L'!$B$11="","",'3-Year P&L'!$B$11*(1+'0. Assumptions'!$B$20)*(J8*(1-'0. Assumptions'!$B$52/30)+I8*('0. Assumptions'!$B$52/30))),"") -> 23909.676 | ... M10: =IFERROR(IF('3-Year P&L'!$B$11="","",'3-Year P&L'!$B$11*(1+'0. Assumptions'!$B$20)*(M8*(1-'0. Assumptions'!$B$52/30)+L8*('0. Assumptions'!$B$52/30))),"") -> 32971.483 | N10: =IFERROR(IF('3-Year P&L'!$B$11="","",SUM(B10:M10)),"") -> 279877.14 | O10: The month's sales, with VAT/GST where it applies (none in the US case: its counter sales are exempt and the tax layer reads zero), adjusted for the average days to collect from the channels sheet. The counter collects on the spot; wholesale at 45 days.
A11: PAYMENTS
