Workbook

Sheet Instructions
A1: Equipment and Suppliers Checklist
A2: AI Chef Pro · aichef.pro — How to Open a Pastry Shop
A3: What it's for: deciding what equipment you buy, from whom, at what real price and with what delivery lead time.
A5: How to use it
A6: 1. "Equipment" sheet: the full equipment package of a pastry shop with its own production kitchen, line by line. Start with the green block at the top: the sales tax rate, the range you want to see around the reference price, the equipment startup cost from startup-cost-calculator.xlsx, the deviation you'll allow and the weeks left until the opening date you have in mind. Everything else on the sheet recalculates from that.
A7: 2. On each line, enter three things: the real price you've been quoted (BEFORE sales tax), who sells it to you and in how many weeks they deliver. All three come filled with a default value so you can see the sheet working; all three are assumptions and have to be replaced.
A8: 3. Mark the status of each line (Pending, Quoted, Ordered, Received, Installed or N/A). "N/A" is what your format doesn't need, and it counts neither for nor against your progress.
A9: 4. "Format Variant" sheet: choose at the top what you're going to open, and the sheet tells you which lines of the package you don't need, which ones you're missing and what that variant costs against the base case. It's the sheet that keeps you from buying another business's equipment.
A10: 5. "Suppliers" sheet: nine suppliers whose official websites were checked in October 2026, with green columns for your contact, your minimum order, your lead time and your payment terms. Anyone we couldn't verify stays out: a directory with a broken link is worth less than a short one.
A11: 6. "Counter" sheet: your checklist progress, progress on what's CRITICAL (the part that decides whether you can open), the split by startup cost block and by category, and what you negotiated against the reference.
A13: Green cells = fields you can edit
A15: What to know before you start
... A31: Version 1.0 · October 2026 · aichef.pro/en/digital-products/how-to-open-a-pastry-shop · info@aichef.pro

Sheet Equipment
A1: Equipment, Line by Line
A2: AI Chef Pro · aichef.pro — How to Open a Pastry Shop
A3: Reference prices are example prices from a European dealer's listing (eight lines) or declared assumptions (fourteen), all before sales tax. What a US list price leaves out (freight, installation, voltage and phase) goes in your quotes.
A5: Settings for this sheet
A6: Parameter | C6: Value | D6: Note
A7: Sales tax rate on equipment (%) | C7: 0 | D7: 0% by default: the case is priced before sales tax. Type your combined state and local rate (e.g. 8.25%, the Texas maximum) and the sheet adds the tax to the cash-out line. In the US, sales tax on equipment is a cost: it doesn't come back the way VAT does. Ask your CPA whether your state exempts any of it.
A8: Range around the reference price (±%) | C8: 0.25 | D8: ASSUMPTION. How wide you want to see the low and high estimates around the reference price. 25% is the band between what a web listing asks and what you close with three quotes; widen it if you buy from a single dealer.
A9: Equipment startup cost from startup-cost-calculator.xlsx ($, pre-tax) | C9: 66980.34 | D9: COPY IT FROM startup-cost-calculator.xlsx, blocks "Production kitchen equipment" and "Storefront and display". It comes filled with the modeled case's value as an ASSUMPTION, so the sheet works before you open that workbook. There's no formula between workbooks: this is a declared copy, not a link.
A10: Allowed deviation threshold (%) | C10: 0.1 | D10: ASSUMPTION. Above this deviation from startup-cost-calculator.xlsx, the sheet flags it in red: either you've bought too much, or the financial plan in 3-year-financial-plan.xlsx is built on an investment that's no longer yours.
A11: Weeks left until your planned opening | C11: 20 | D11: ASSUMPTION. Count from today to the date you have in mind. The full timeline, with the critical path of permits and build-out, is on the "Timeline and Critical Path" sheet of permits-and-licenses-checklist.xlsx.
A12: Safety margin between delivery and opening (weeks) | C12: 2 | D12: ASSUMPTION. What you need between the machine arriving and opening: setup, hookup, start-up and production tests. With less than two weeks, the first breakdown catches you with the doors open.
A14: The full package, line by line
A15: Status | B15: No. | C15: Line item | D15: Brand | E15: Model | F15: Category | G15: Startup cost block | H15: Priority | I15: Reference price ($) | J15: Price basis | K15: Sales tax rate (%) | L15: Pre-tax price ($) | M15: Low estimate ($) | N15: High estimate ($) | O15: Negotiated price ($, pre-tax) | P15: Deviation from reference (%) | Q15: Supplier | R15: Lead time (weeks) | S15: Margin to opening (weeks) | T15: Aux · lead time of critical lines | U15: Aux · lead time too long? (1 = yes) | V15: Source | W15: Note
A16: Pending | B16: 1 | C16: Convection oven, 6 trays | D16: Not named | E16: Electric, with humidity, 6 trays (600 × 400 mm) | F16: Heat | G16: Production kitchen equipment | H16: Critical | I16: 2772 | J16: pre-tax | K16: =$C$7 -> 0 | L16: =IFERROR(IF($I16="","",IF($J16=$E$62,$I16/(1+$K16),$I16)),"") -> 2772 | M16: =IF($L16="","",$L16*(1-$C$8)) -> 2079 | N16: =IF($L16="","",$L16*(1+$C$8)) -> 3465 | O16: 2772 | P16: =IFERROR(IF(OR($O16="",$L16=""),"",$O16/$L16-1),"") -> 0 | Q16: Not named | R16: 5 | S16: =IFERROR(IF(OR($R16="",$C$11="",$C$12=""),"",$C$11-$R16-$C$12),"") -> 13 | T16: =IF($H16=$C$61,$R16,"") -> 5 | U16: =IF($S16="","",IF($S16<0,1,0)) -> 0 | V16: Example price | W16: Example price from a European dealer's listing, before tax. Check that the model you buy matches your voltage and phase.
A17: Pending | B17: 2 | C17: Convection oven, 4 trays | D17: Not named | E17: Electric, with humidity, 4 trays (600 × 400 mm) | F17: Heat | G17: Production kitchen equipment | H17: Critical | I17: 2077.1983 | J17: pre-tax | K17: =$C$7 -> 0 | L17: =IFERROR(IF($I17="","",IF($J17=$E$62,$I17/(1+$K17),$I17)),"") -> 2077.1983 | M17: =IF($L17="","",$L17*(1-$C$8)) -> 1557.8988 | N17: =IF($L17="","",$L17*(1+$C$8)) -> 2596.4979 | O17: 2077.2 | P17: =IFERROR(IF(OR($O17="",$L17=""),"",$O17/$L17-1),"") -> 7.9573169e-07 | Q17: Not named | R17: 5 | S17: =IFERROR(IF(OR($R17="",$C$11="",$C$12=""),"",$C$11-$R17-$C$12),"") -> 13 | T17: =IF($H17=$C$61,$R17,"") -> 5 | U17: =IF($S17="","",IF($S17<0,1,0)) -> 0 | V17: Example price | W17: Second oven: without it you can't bake at two different temperatures at once.
A18: Pending | B18: 3 | C18: Refrigerated bakery display case, curved glass, about 5 ft | D18: Not named | E18: 452 L (about 16 cu ft) | F18: Storefront and display | G18: Storefront and display | H18: Critical | I18: 2284.1 | J18: pre-tax | K18: =$C$7 -> 0 | L18: =IFERROR(IF($I18="","",IF($J18=$E$62,$I18/(1+$K18),$I18)),"") -> 2284.1 | M18: =IF($L18="","",$L18*(1-$C$8)) -> 1713.075 | N18: =IF($L18="","",$L18*(1+$C$8)) -> 2855.125 | O18: 2284.1 | P18: =IFERROR(IF(OR($O18="",$L18=""),"",$O18/$L18-1),"") -> 0 | Q18: Not named | R18: 6 | S18: =IFERROR(IF(OR($R18="",$C$11="",$C$12=""),"",$C$11-$R18-$C$12),"") -> 12 | T18: =IF($H18=$C$61,$R18,"") -> 6 | U18: =IF($S18="","",IF($S18<0,1,0)) -> 0 | V18: Example price | W18: 59 × 35 × 51 in, 452 L (about 16 cu ft), about 10 sq ft of display, R-290 refrigerant. The price carries a 30% promotional discount off list: a DATED price that can expire, so check it again before you budget. One case, counted once.
A19: Pending | B19: 4 | C19: Rear sliding doors for the display case (accessory) | D19: Not named | E19: Accessory for the case above | F19: Storefront and display | G19: Storefront and display | H19: Optional | I19: 120.4 | J19: pre-tax | K19: =$C$7 -> 0 | L19: =IFERROR(IF($I19="","",IF($J19=$E$62,$I19/(1+$K19),$I19)),"") -> 120.4 | M19: =IF($L19="","",$L19*(1-$C$8)) -> 90.3 | N19: =IF($L19="","",$L19*(1+$C$8)) -> 150.5 | O19: 120.4 | P19: =IFERROR(IF(OR($O19="",$L19=""),"",$O19/$L19-1),"") -> 0 | Q19: Not named | R19: 6 | S19: =IFERROR(IF(OR($R19="",$C$11="",$C$12=""),"",$C$11-$R19-$C$12),"") -> 12 | T19: =IF($H19=$C$61,$R19,"") | U19: =IF($S19="","",IF($S19<0,1,0)) -> 0 | V19: Example price | W19: Accessory: it stays out of the comparable subtotal of the standard package.
A20: Pending | B20: 5 | C20: Blast chiller, 4 trays | D20: Irinox | E20: MultiFresh line | F20: Freezing | G20: Production kitchen equipment | H20: Critical | I20: 10037 | J20: pre-tax | K20: =$C$7 -> 0 | L20: =IFERROR(IF($I20="","",IF($J20=$E$62,$I20/(1+$K20),$I20)),"") -> 10037 | M20: =IF($L20="","",$L20*(1-$C$8)) -> 7527.75 | N20: =IF($L20="","",$L20*(1+$C$8)) -> 12546.25 | O20: 10037 | P20: =IFERROR(IF(OR($O20="",$L20=""),"",$O20/$L20-1),"") -> 0 | Q20: Irinox | R20: 8 | S20: =IFERROR(IF(OR($R20="",$C$11="",$C$12=""),"",$C$11-$R20-$C$12),"") -> 10 | T20: =IF($H20=$C$61,$R20,"") -> 8 | U20: =IF($S20="","",IF($S20<0,1,0)) -> 0 | V20: Example price | W20: The most expensive purchase and the most argued about. Cycles from above 185 °F down to -40 °F. A chest freezer is NOT a blast chiller: cooling cooked TCS food on time (135 °F to 70 °F in 2 hours, to 41 °F within 6 hours in total, Food Code 3-501.14) takes real blast capacity. For reference, a US dealer listed the Irinox MultiFresh Next S at $21,729 in October 2026.
A21: Pending | B21: 6 | C21: Dough sheeter, up to 16 in wide | D21: Not named | E21: Automatic, up to 16 in (40 cm) | F21: Sheeting | G21: Production kitchen equipment | H21: Critical | I21: 1215 | J21: pre-tax | K21: =$C$7 -> 0 | L21: =IFERROR(IF($I21="","",IF($J21=$E$62,$I21/(1+$K21),$I21)),"") -> 1215 | M21: =IF($L21="","",$L21*(1-$C$8)) -> 911.25 | N21: =IF($L21="","",$L21*(1+$C$8)) -> 1518.75 | O21: 1215 | P21: =IFERROR(IF(OR($O21="",$L21=""),"",$O21/$L21-1),"") -> 0 | Q21: Not named | R21: 4 | S21: =IFERROR(IF(OR($R21="",$C$11="",$C$12=""),"",$C$11-$R21-$C$12),"") -> 14 | T21: =IF($H21=$C$61,$R21,"") -> 4 | U21: =IF($S21="","",IF($S21<0,1,0)) -> 0 | V21: Example price | W21: Example price, before tax: $1,215.00. We found no comparable US listing for dough sheeters in October 2026: this line goes straight to quotes.
A22: Pending | B22: 7 | C22: Planetary mixer, 20 L (about 21 qt) | D22: Not named | E22: 20 L (about 21 qt) bowl | F22: Mixing | G22: Production kitchen equipment | H22: Critical | I22: 595.04 | J22: pre-tax | K22: =$C$7 -> 0 | L22: =IFERROR(IF($I22="","",IF($J22=$E$62,$I22/(1+$K22),$I22)),"") -> 595.04 | M22: =IF($L22="","",$L22*(1-$C$8)) -> 446.28 | N22: =IF($L22="","",$L22*(1+$C$8)) -> 743.8 | O22: 595.04 | P22: =IFERROR(IF(OR($O22="",$L22=""),"",$O22/$L22-1),"") -> 0 | Q22: Not named | R22: 3 | S22: =IFERROR(IF(OR($R22="",$C$11="",$C$12=""),"",$C$11-$R22-$C$12),"") -> 15 | T22: =IF($H22=$C$61,$R22,"") -> 3 | U22: =IF($S22="","",IF($S22<0,1,0)) -> 0 | V22: Example price | W22: 900 W, 95-392 rpm, 0-99 min timer. The listing behind it didn't say whether the price included tax; it's treated as pre-tax. At $595.04 it's below the cheapest 20-qt mixer a US dealer listed in October 2026 ($849): treat it as optimistic.
A23: Pending | B23: 8 | C23: Chocolate tempering machine, 12 kg (26 lb) | D23: Not named | E23: 12-kg (26-lb) tank | F23: Chocolate | G23: Production kitchen equipment | H23: Optional | I23: 7400 | J23: pre-tax | K23: =$C$7 -> 0 | L23: =IFERROR(IF($I23="","",IF($J23=$E$62,$I23/(1+$K23),$I23)),"") -> 7400 | M23: =IF($L23="","",$L23*(1-$C$8)) -> 5550 | N23: =IF($L23="","",$L23*(1+$C$8)) -> 9250 | O23: 7400 | P23: =IFERROR(IF(OR($O23="",$L23=""),"",$O23/$L23-1),"") -> 0 | Q23: Not named | R23: 7 | S23: =IFERROR(IF(OR($R23="",$C$11="",$C$12=""),"",$C$11-$R23-$C$12),"") -> 11 | T23: =IF($H23=$C$61,$R23,"") | U23: =IF($S23="","",IF($S23<0,1,0)) -> 0 | V23: Example price | W23: OPTIONAL depending on the concept: only if you open a bonbon or chocolate line. That's why it stays OUT of the comparable subtotal of the standard package: with it inside, a single machine was 25% of the subtotal.
A24: Pending | B24: 9 | C24: Modular deck oven, 1 to 5 decks | F24: Heat | G24: Production kitchen equipment | H24: Optional | I24: 12000 | J24: pre-tax | K24: =$C$7 -> 0 | L24: =IFERROR(IF($I24="","",IF($J24=$E$62,$I24/(1+$K24),$I24)),"") -> 12000 | M24: =IF($L24="","",$L24*(1-$C$8)) -> 9000 | N24: =IF($L24="","",$L24*(1+$C$8)) -> 15000 | O24: 12000 | P24: =IFERROR(IF(OR($O24="",$L24=""),"",$O24/$L24-1),"") -> 0 | Q24: Not named | R24: 12 | S24: =IFERROR(IF(OR($R24="",$C$11="",$C$12=""),"",$C$11-$R24-$C$12),"") -> 6 | T24: =IF($H24=$C$61,$R24,"") | U24: =IF($S24="","",IF($S24<0,1,0)) -> 0 | V24: Assumption | W24: Deck ovens are sold through dealers and by quote: no pastry deck oven came up with a published price. For reference, electric pizza-style deck ovens listed from $6,749 for one deck to $32,376.50 for three (WebstaurantStore, October 2026). The default value is an ASSUMPTION so the cell isn't empty: get three quotes. A deck oven usually goes under a Type I hood.
A25: Pending | B25: 10 | C25: Retarder-proofer (roll-in) | F25: Refrigeration | G25: Production kitchen equipment | H25: Critical | I25: 8500 | J25: pre-tax | K25: =$C$7 -> 0 | L25: =IFERROR(IF($I25="","",IF($J25=$E$62,$I25/(1+$K25),$I25)),"") -> 8500 | M25: =IF($L25="","",$L25*(1-$C$8)) -> 6375 | N25: =IF($L25="","",$L25*(1+$C$8)) -> 10625 | O25: 8500 | P25: =IFERROR(IF(OR($O25="",$L25=""),"",$O25/$L25-1),"") -> 0 | Q25: Pending: get three quotes | R25: 9 | S25: =IFERROR(IF(OR($R25="",$C$11="",$C$12=""),"",$C$11-$R25-$C$12),"") -> 9 | T25: =IF($H25=$C$61,$R25,"") -> 9 | U25: =IF($S25="","",IF($S25<0,1,0)) -> 0 | V25: Assumption | W25: The case's value is an assumption well below what a US dealer listed in October 2026: $27,937.80 for a one-section roll-in Doyon KDPR11 (usually ships in 6 weeks). It's what lets the viennoiserie be baked by 7:00 without starting at 3:00.
A26: Pending | B26: 11 | C26: Stainless steel exhaust duct | F26: Building systems | G26: Production kitchen equipment | H26: Critical | I26: 6500 | J26: pre-tax | K26: =$C$7 -> 0 | L26: =IFERROR(IF($I26="","",IF($J26=$E$62,$I26/(1+$K26),$I26)),"") -> 6500 | M26: =IF($L26="","",$L26*(1-$C$8)) -> 4875 | N26: =IF($L26="","",$L26*(1+$C$8)) -> 8125 | O26: 6500 | P26: =IFERROR(IF(OR($O26="",$L26=""),"",$O26/$L26-1),"") -> 0 | Q26: Pending: get three quotes | R26: 6 | S26: =IFERROR(IF(OR($R26="",$C$11="",$C$12=""),"",$C$11-$R26-$C$12),"") -> 12 | T26: =IF($H26=$C$61,$R26,"") -> 6 | U26: =IF($S26="","",IF($S26<0,1,0)) -> 0 | V26: Assumption | W26: The line that kills the most spaces, and the one you have to settle BEFORE you sign (chapter 6). The hood type follows your ovens: Type I with fire suppression for deck ovens, Type II for enclosed electric convection (IMC 507). One published estimate puts a complete hood at $5,000 to $28,000 installed, plus $3,000 to $12,000 for suppression; the case's value is an assumption.
A27: Pending | B27: 12 | C27: Spiral mixer, 25 kg (55 lb) of dough | F27: Mixing | G27: Production kitchen equipment | H27: Critical | I27: 5200 | J27: pre-tax | K27: =$C$7 -> 0 | L27: =IFERROR(IF($I27="","",IF($J27=$E$62,$I27/(1+$K27),$I27)),"") -> 5200 | M27: =IF($L27="","",$L27*(1-$C$8)) -> 3900 | N27: =IF($L27="","",$L27*(1+$C$8)) -> 6500 | O27: 5200 | P27: =IFERROR(IF(OR($O27="",$L27=""),"",$O27/$L27-1),"") -> 0 | Q27: Pending: get three quotes | R27: 6 | S27: =IFERROR(IF(OR($R27="",$C$11="",$C$12=""),"",$C$11-$R27-$C$12),"") -> 12 | T27: =IF($H27=$C$61,$R27,"") -> 6 | U27: =IF($S27="","",IF($S27<0,1,0)) -> 0 | V27: Assumption | W27: Assumption. For reference, a US dealer listed a 60-qt spiral mixer (88 lb of dough) at $2,249 in October 2026: a figure without your spec, used as an order of magnitude, not as a price.
A28: Pending | B28: 13 | C28: Modular walk-in cooler (8 m³, about 283 cu ft) | F28: Refrigeration | G28: Production kitchen equipment | H28: Critical | I28: 4800 | J28: pre-tax | K28: =$C$7 -> 0 | L28: =IFERROR(IF($I28="","",IF($J28=$E$62,$I28/(1+$K28),$I28)),"") -> 4800 | M28: =IF($L28="","",$L28*(1-$C$8)) -> 3600 | N28: =IF($L28="","",$L28*(1+$C$8)) -> 6000 | O28: 4800 | P28: =IFERROR(IF(OR($O28="",$L28=""),"",$O28/$L28-1),"") -> 0 | Q28: Pending: get three quotes | R28: 7 | S28: =IFERROR(IF(OR($R28="",$C$11="",$C$12=""),"",$C$11-$R28-$C$12),"") -> 11 | T28: =IF($H28=$C$61,$R28,"") -> 7 | U28: =IF($S28="","",IF($S28<0,1,0)) -> 0 | V28: Assumption | W28: It holds TCS items at 41 °F or below (Food Code 3-501.16). A US dealer listed 8 × 10 ft walk-ins at about $10,000 to $17,000 (October 2026).
A29: Pending | B29: 14 | C29: Reach-in freezer, 0 °F | F29: Freezing | G29: Production kitchen equipment | H29: Critical | I29: 1900 | J29: pre-tax | K29: =$C$7 -> 0 | L29: =IFERROR(IF($I29="","",IF($J29=$E$62,$I29/(1+$K29),$I29)),"") -> 1900 | M29: =IF($L29="","",$L29*(1-$C$8)) -> 1425 | N29: =IF($L29="","",$L29*(1+$C$8)) -> 2375 | O29: 1900 | P29: =IFERROR(IF(OR($O29="",$L29=""),"",$O29/$L29-1),"") -> 0 | Q29: Pending: get three quotes | R29: 4 | S29: =IFERROR(IF(OR($R29="",$C$11="",$C$12=""),"",$C$11-$R29-$C$12),"") -> 14 | T29: =IF($H29=$C$61,$R29,"") -> 4 | U29: =IF($S29="","",IF($S29<0,1,0)) -> 0 | V29: Assumption | W29: It KEEPS frozen product frozen; it doesn't freeze it. It doesn't replace the blast chiller.
A30: Pending | B30: 15 | C30: Refrigerated worktable with drawers (6.5 ft) | F30: Refrigeration | G30: Production kitchen equipment | H30: Critical | I30: 2400 | J30: pre-tax | K30: =$C$7 -> 0 | L30: =IFERROR(IF($I30="","",IF($J30=$E$62,$I30/(1+$K30),$I30)),"") -> 2400 | M30: =IF($L30="","",$L30*(1-$C$8)) -> 1800 | N30: =IF($L30="","",$L30*(1+$C$8)) -> 3000 | O30: 2400 | P30: =IFERROR(IF(OR($O30="",$L30=""),"",$O30/$L30-1),"") -> 0 | Q30: Pending: get three quotes | R30: 5 | S30: =IFERROR(IF(OR($R30="",$C$11="",$C$12=""),"",$C$11-$R30-$C$12),"") -> 13 | T30: =IF($H30=$C$61,$R30,"") -> 5 | U30: =IF($S30="","",IF($S30<0,1,0)) -> 0 | V30: Assumption
A31: Pending | B31: 16 | C31: Stainless steel worktables and shelving (lot) | F31: Kitchen fixtures | G31: Production kitchen equipment | H31: Critical | I31: 2800 | J31: pre-tax | K31: =$C$7 -> 0 | L31: =IFERROR(IF($I31="","",IF($J31=$E$62,$I31/(1+$K31),$I31)),"") -> 2800 | M31: =IF($L31="","",$L31*(1-$C$8)) -> 2100 | N31: =IF($L31="","",$L31*(1+$C$8)) -> 3500 | O31: 2800 | P31: =IFERROR(IF(OR($O31="",$L31=""),"",$O31/$L31-1),"") -> 0 | Q31: Pending: get three quotes | R31: 4 | S31: =IFERROR(IF(OR($R31="",$C$11="",$C$12=""),"",$C$11-$R31-$C$12),"") -> 14 | T31: =IF($H31=$C$61,$R31,"") -> 4 | U31: =IF($S31="","",IF($S31<0,1,0)) -> 0 | V31: Assumption
A32: Pending | B32: 17 | C32: Three-compartment sink, hand sink and mop sink | F32: Building systems | G32: Production kitchen equipment | H32: Critical | I32: 1400 | J32: pre-tax | K32: =$C$7 -> 0 | L32: =IFERROR(IF($I32="","",IF($J32=$E$62,$I32/(1+$K32),$I32)),"") -> 1400 | M32: =IF($L32="","",$L32*(1-$C$8)) -> 1050 | N32: =IF($L32="","",$L32*(1+$C$8)) -> 1750 | O32: 1400 | P32: =IFERROR(IF(OR($O32="",$L32=""),"",$O32/$L32-1),"") -> 0 | Q32: Pending: get three quotes | R32: 3 | S32: =IFERROR(IF(OR($R32="",$C$11="",$C$12=""),"",$C$11-$R32-$C$12),"") -> 15 | T32: =IF($H32=$C$61,$R32,"") -> 3 | U32: =IF($S32="","",IF($S32<0,1,0)) -> 0 | V32: Food Code + assumption | W32: A requirement, not an extra: a 3-compartment sink (Food Code 4-301.12), handwashing sinks (5-203.11) and a mop sink (5-203.13).
A33: Pending | B33: 18 | C33: Front-counter fixtures (counter, shelving, interior sign) | F33: Storefront and display | G33: Storefront and display | H33: Critical | I33: 7500 | J33: pre-tax | K33: =$C$7 -> 0 | L33: =IFERROR(IF($I33="","",IF($J33=$E$62,$I33/(1+$K33),$I33)),"") -> 7500 | M33: =IF($L33="","",$L33*(1-$C$8)) -> 5625 | N33: =IF($L33="","",$L33*(1+$C$8)) -> 9375 | O33: 7500 | P33: =IFERROR(IF(OR($O33="",$L33=""),"",$O33/$L33-1),"") -> 0 | Q33: Pending: get three quotes | R33: 8 | S33: =IFERROR(IF(OR($R33="",$C$11="",$C$12=""),"",$C$11-$R33-$C$12),"") -> 10 | T33: =IF($H33=$C$61,$R33,"") -> 8 | U33: =IF($S33="","",IF($S33<0,1,0)) -> 0 | V33: Assumption
A34: Pending | B34: 19 | C34: POS terminal and software | F34: Storefront and display | G34: Storefront and display | H34: Critical | I34: 1300 | J34: pre-tax | K34: =$C$7 -> 0 | L34: =IFERROR(IF($I34="","",IF($J34=$E$62,$I34/(1+$K34),$I34)),"") -> 1300 | M34: =IF($L34="","",$L34*(1-$C$8)) -> 975 | N34: =IF($L34="","",$L34*(1+$C$8)) -> 1625 | O34: 1300 | P34: =IFERROR(IF(OR($O34="",$L34=""),"",$O34/$L34-1),"") -> 0 | Q34: Pending: get three quotes | R34: 3 | S34: =IFERROR(IF(OR($R34="",$C$11="",$C$12=""),"",$C$11-$R34-$C$12),"") -> 15 | T34: =IF($H34=$C$61,$R34,"") -> 3 | U34: =IF($S34="","",IF($S34<0,1,0)) -> 0 | V34: Assumption | W34: The POS is what rings up to-go and for-here sales separately: if you ever add seating, what's eaten at your tables is generally taxable and pastries to go generally aren't (chapter 19 of the guide). Set the keys up from day one.
A35: Pending | B35: 20 | C35: Ambient display case | F35: Storefront and display | G35: Storefront and display | H35: Critical | I35: 1600 | J35: pre-tax | K35: =$C$7 -> 0 | L35: =IFERROR(IF($I35="","",IF($J35=$E$62,$I35/(1+$K35),$I35)),"") -> 1600 | M35: =IF($L35="","",$L35*(1-$C$8)) -> 1200 | N35: =IF($L35="","",$L35*(1+$C$8)) -> 2000 | O35: 1600 | P35: =IFERROR(IF(OR($O35="",$L35=""),"",$O35/$L35-1),"") -> 0 | Q35: Pending: get three quotes | R35: 6 | S35: =IFERROR(IF(OR($R35="",$C$11="",$C$12=""),"",$C$11-$R35-$C$12),"") -> 12 | T35: =IF($H35=$C$61,$R35,"") -> 6 | U35: =IF($S35="","",IF($S35<0,1,0)) -> 0 | V35: Assumption | W35: For what's shelf-stable at room temperature: palmiers, Sachertorte, huesos de santo, turrón and the breads. How many feet of this case you need, and how many of the refrigerated one, is decided by the "Egg & TCS Decision" sheet in opening-menu-and-recipe-costing.xlsx, not by taste.
A36: Pending | B36: 21 | C36: Vacuum packer, sealer and smallwares (lot) | F36: Kitchen fixtures | G36: Production kitchen equipment | H36: Critical | I36: 3200 | J36: pre-tax | K36: =$C$7 -> 0 | L36: =IFERROR(IF($I36="","",IF($J36=$E$62,$I36/(1+$K36),$I36)),"") -> 3200 | M36: =IF($L36="","",$L36*(1-$C$8)) -> 2400 | N36: =IF($L36="","",$L36*(1+$C$8)) -> 4000 | O36: 3200 | P36: =IFERROR(IF(OR($O36="",$L36=""),"",$O36/$L36-1),"") -> 0 | Q36: Pending: get three quotes | R36: 4 | S36: =IFERROR(IF(OR($R36="",$C$11="",$C$12=""),"",$C$11-$R36-$C$12),"") -> 14 | T36: =IF($H36=$C$61,$R36,"") -> 4 | U36: =IF($S36="","",IF($S36<0,1,0)) -> 0 | V36: Assumption
A37: Pending | B37: 22 | C37: Probe thermometers, scales and temperature data loggers | F37: Monitoring | G37: Production kitchen equipment | H37: Critical | I37: 900 | J37: pre-tax | K37: =$C$7 -> 0 | L37: =IFERROR(IF($I37="","",IF($J37=$E$62,$I37/(1+$K37),$I37)),"") -> 900 | M37: =IF($L37="","",$L37*(1-$C$8)) -> 675 | N37: =IF($L37="","",$L37*(1+$C$8)) -> 1125 | O37: 900 | P37: =IFERROR(IF(OR($O37="",$L37=""),"",$O37/$L37-1),"") -> 0 | Q37: Pending: get three quotes | R37: 2 | S37: =IFERROR(IF(OR($R37="",$C$11="",$C$12=""),"",$C$11-$R37-$C$12),"") -> 16 | T37: =IF($H37=$C$61,$R37,"") -> 2 | U37: =IF($S37="","",IF($S37<0,1,0)) -> 0 | V37: Assumption | W37: Without a probe you can't prove your cold holding and cooling temperatures (41 °F, Food Code 3-501.16 and 3-501.14). It's the cheapest purchase with the most consequences.
A39: Summary of this sheet
A40: Checklist lines | I40: =COUNTIF($C$16:$C$37,"<>") -> 22 | K40: The 22 lines of the standard package for a pastry shop with its own production kitchen.
A41: Pre-tax reference total, critical lines only ($) | I41: =SUMPRODUCT(--($H$16:$H$37=$C$61),$L$16:$L$37) -> 66980.338 | K41: What it costs to buy what you can't open without, at reference price and before sales tax.
A42: Pre-tax reference total, all lines ($) | I42: =SUM($L$16:$L$37) -> 86500.738 | K42: With the chocolate tempering machine and the deck oven included, which are optional depending on the concept.
A43: Pre-tax negotiated total, critical lines only ($) | I43: =SUMPRODUCT(--($H$16:$H$37=$C$61),$O$16:$O$37) -> 66980.34 | K43: The same with YOUR prices: it's the number you take to startup-cost-calculator.xlsx.
...

Sheet Format Variant
A1: What Equipment Each Format Variant Needs
A2: AI Chef Pro · aichef.pro — How to Open a Pastry Shop
A3: The full package is the mid-size pastry shop with its own production kitchen and a counter (the case). The other six variants read as deviations from it: which lines you don't need and which ones you're missing.
A5: Choose the variant you're opening
A6: Variant you're opening | C6: Mid-size pastry shop (the case) | E6: Dropdown from the list further down. It comes set to the base case because that's the modeled case; change it to yours.
A7: Equipment lines you need | C7: =IFERROR(INDEX($E$38:$K$38,MATCH($C$6,$E$15:$K$15,0)),"") -> 19 | E7: Only the ones marked "Yes". The "Depends" lines aren't counted: those are the ones you have to decide.
A8: Reference investment for that variant ($, pre-tax) | C8: =IFERROR(INDEX($E$39:$K$39,MATCH($C$6,$E$15:$K$15,0)),"") -> 66980.338 | E8: Sum of the pre-tax reference prices of the lines marked "Yes". It doesn't include build-out, permits or working capital: that's startup-cost-calculator.xlsx.
A9: Reference investment for the base case ($, pre-tax) | C9: =$G$39 -> 66980.338 | E9: The mid-size pastry shop with a counter: the modeled case.
A10: Difference from the base case ($) | C10: =IFERROR(IF($C$8="","",$C$8-$C$9),"") -> 0 | E10: Negative = your variant needs less equipment than the base case.
A11: Base-case lines you don't need | C11: =SUMPRODUCT(--($L$16:$L$37<>$C$43),--($G$16:$G$37=$C$43)) -> 0 | E11: They're in the full package and your format doesn't call for them.
A12: Lines you're missing compared with the base case | C12: =SUMPRODUCT(--($L$16:$L$37=$C$43),--($G$16:$G$37<>$C$43)) -> 0 | E12: Your format calls for them and they're not in the base case.
A14: What each variant needs, line by line
A15: No. | B15: Line item | C15: Pre-tax reference price ($) | D15: Priority | E15: Home-based bakery under cottage food | F15: Closed-door production kitchen | G15: Mid-size pastry shop (the case) | H15: Bakery-café | I15: Small bake-off shop | J15: Wholesale production kitchen for restaurants and cafés | K15: Ventless pastry shop (no Type I hood) | L15: Do you need it? | M15: Why
A16: 1 | B16: Convection oven, 6 trays | C16: ='Equipment'!$L$16 -> 2772 | D16: ='Equipment'!$H$16 -> Critical | E16: No | F16: Yes | G16: Yes | H16: Yes | I16: Yes | J16: Yes | K16: Yes | L16: =IFERROR(INDEX($E16:$K16,MATCH($C$6,$E$15:$K$15,0)),"") -> Yes | M16: Example price from a European dealer's listing, before tax. Check that the model you buy matches your voltage and phase.
A17: 2 | B17: Convection oven, 4 trays | C17: ='Equipment'!$L$17 -> 2077.1983 | D17: ='Equipment'!$H$17 -> Critical | E17: No | F17: Depends | G17: Yes | H17: Yes | I17: Depends | J17: Yes | K17: Yes | L17: =IFERROR(INDEX($E17:$K17,MATCH($C$6,$E$15:$K$15,0)),"") -> Yes | M17: Second oven: without it you can't bake at two different temperatures at once.
A18: 3 | B18: Refrigerated bakery display case, curved glass, about 5 ft | C18: ='Equipment'!$L$18 -> 2284.1 | D18: ='Equipment'!$H$18 -> Critical | E18: No | F18: No | G18: Yes | H18: Yes | I18: Yes | J18: No | K18: Yes | L18: =IFERROR(INDEX($E18:$K18,MATCH($C$6,$E$15:$K$15,0)),"") -> Yes | M18: 59 × 35 × 51 in, 452 L (about 16 cu ft), about 10 sq ft of display, R-290 refrigerant. The price carries a 30% promotional discount off list: a DATED price that can expire, so check it again before you budget. One case, counted once.
A19: 4 | B19: Rear sliding doors for the display case (accessory) | C19: ='Equipment'!$L$19 -> 120.4 | D19: ='Equipment'!$H$19 -> Optional | E19: No | F19: No | G19: Depends | H19: Depends | I19: Depends | J19: No | K19: Depends | L19: =IFERROR(INDEX($E19:$K19,MATCH($C$6,$E$15:$K$15,0)),"") -> Depends | M19: Accessory: it stays out of the comparable subtotal of the standard package.
A20: 5 | B20: Blast chiller, 4 trays | C20: ='Equipment'!$L$20 -> 10037 | D20: ='Equipment'!$H$20 -> Critical | E20: No | F20: Yes | G20: Yes | H20: Yes | I20: No | J20: Yes | K20: Yes | L20: =IFERROR(INDEX($E20:$K20,MATCH($C$6,$E$15:$K$15,0)),"") -> Yes | M20: The most expensive purchase and the most argued about. Cycles from above 185 °F down to -40 °F. A chest freezer is NOT a blast chiller: cooling cooked TCS food on time (135 °F to 70 °F in 2 hours, to 41 °F within 6 hours in total, Food Code 3-501.14) takes real blast capacity. For reference, a US dealer listed the Irinox MultiFresh Next S at $21,729 in October 2026.
A21: 6 | B21: Dough sheeter, up to 16 in wide | C21: ='Equipment'!$L$21 -> 1215 | D21: ='Equipment'!$H$21 -> Critical | E21: No | F21: Yes | G21: Yes | H21: Yes | I21: No | J21: Yes | K21: Yes | L21: =IFERROR(INDEX($E21:$K21,MATCH($C$6,$E$15:$K$15,0)),"") -> Yes | M21: Example price, before tax: $1,215.00. We found no comparable US listing for dough sheeters in October 2026: this line goes straight to quotes.
A22: 7 | B22: Planetary mixer, 20 L (about 21 qt) | C22: ='Equipment'!$L$22 -> 595.04 | D22: ='Equipment'!$H$22 -> Critical | E22: Depends | F22: Yes | G22: Yes | H22: Yes | I22: No | J22: Yes | K22: Yes | L22: =IFERROR(INDEX($E22:$K22,MATCH($C$6,$E$15:$K$15,0)),"") -> Yes | M22: 900 W, 95-392 rpm, 0-99 min timer. The listing behind it didn't say whether the price included tax; it's treated as pre-tax. At $595.04 it's below the cheapest 20-qt mixer a US dealer listed in October 2026 ($849): treat it as optimistic.
A23: 8 | B23: Chocolate tempering machine, 12 kg (26 lb) | C23: ='Equipment'!$L$23 -> 7400 | D23: ='Equipment'!$H$23 -> Optional | E23: No | F23: Depends | G23: Depends | H23: Depends | I23: No | J23: Depends | K23: Depends | L23: =IFERROR(INDEX($E23:$K23,MATCH($C$6,$E$15:$K$15,0)),"") -> Depends | M23: OPTIONAL depending on the concept: only if you open a bonbon or chocolate line. That's why it stays OUT of the comparable subtotal of the standard package: with it inside, a single machine was 25% of the subtotal.
A24: 9 | B24: Modular deck oven, 1 to 5 decks | C24: ='Equipment'!$L$24 -> 12000 | D24: ='Equipment'!$H$24 -> Optional | E24: No | F24: Depends | G24: Depends | H24: Depends | I24: No | J24: Yes | K24: Depends | L24: =IFERROR(INDEX($E24:$K24,MATCH($C$6,$E$15:$K$15,0)),"") -> Depends | M24: Deck ovens are sold through dealers and by quote: no pastry deck oven came up with a published price. For reference, electric pizza-style deck ovens listed from $6,749 for one deck to $32,376.50 for three (WebstaurantStore, October 2026). The default value is an ASSUMPTION so the cell isn't empty: get three quotes. A deck oven usually goes under a Type I hood.
A25: 10 | B25: Retarder-proofer (roll-in) | C25: ='Equipment'!$L$25 -> 8500 | D25: ='Equipment'!$H$25 -> Critical | E25: No | F25: Yes | G25: Yes | H25: Yes | I25: No | J25: Yes | K25: Yes | L25: =IFERROR(INDEX($E25:$K25,MATCH($C$6,$E$15:$K$15,0)),"") -> Yes | M25: The case's value is an assumption well below what a US dealer listed in October 2026: $27,937.80 for a one-section roll-in Doyon KDPR11 (usually ships in 6 weeks). It's what lets the viennoiserie be baked by 7:00 without starting at 3:00.
A26: 11 | B26: Stainless steel exhaust duct | C26: ='Equipment'!$L$26 -> 6500 | D26: ='Equipment'!$H$26 -> Critical | E26: No | F26: Yes | G26: Yes | H26: Yes | I26: Depends | J26: Yes | K26: No | L26: =IFERROR(INDEX($E26:$K26,MATCH($C$6,$E$15:$K$15,0)),"") -> Yes | M26: The line that kills the most spaces, and the one you have to settle BEFORE you sign (chapter 6). The hood type follows your ovens: Type I with fire suppression for deck ovens, Type II for enclosed electric convection (IMC 507). One published estimate puts a complete hood at $5,000 to $28,000 installed, plus $3,000 to $12,000 for suppression; the case's value is an assumption.
A27: 12 | B27: Spiral mixer, 25 kg (55 lb) of dough | C27: ='Equipment'!$L$27 -> 5200 | D27: ='Equipment'!$H$27 -> Critical | E27: No | F27: Yes | G27: Yes | H27: Yes | I27: No | J27: Yes | K27: Yes | L27: =IFERROR(INDEX($E27:$K27,MATCH($C$6,$E$15:$K$15,0)),"") -> Yes | M27: Assumption. For reference, a US dealer listed a 60-qt spiral mixer (88 lb of dough) at $2,249 in October 2026: a figure without your spec, used as an order of magnitude, not as a price.
A28: 13 | B28: Modular walk-in cooler (8 m³, about 283 cu ft) | C28: ='Equipment'!$L$28 -> 4800 | D28: ='Equipment'!$H$28 -> Critical | E28: No | F28: Yes | G28: Yes | H28: Yes | I28: Depends | J28: Yes | K28: Yes | L28: =IFERROR(INDEX($E28:$K28,MATCH($C$6,$E$15:$K$15,0)),"") -> Yes | M28: It holds TCS items at 41 °F or below (Food Code 3-501.16). A US dealer listed 8 × 10 ft walk-ins at about $10,000 to $17,000 (October 2026).
A29: 14 | B29: Reach-in freezer, 0 °F | C29: ='Equipment'!$L$29 -> 1900 | D29: ='Equipment'!$H$29 -> Critical | E29: Depends | F29: Yes | G29: Yes | H29: Yes | I29: Yes | J29: Yes | K29: Yes | L29: =IFERROR(INDEX($E29:$K29,MATCH($C$6,$E$15:$K$15,0)),"") -> Yes | M29: It KEEPS frozen product frozen; it doesn't freeze it. It doesn't replace the blast chiller.
A30: 15 | B30: Refrigerated worktable with drawers (6.5 ft) | C30: ='Equipment'!$L$30 -> 2400 | D30: ='Equipment'!$H$30 -> Critical | E30: No | F30: Yes | G30: Yes | H30: Yes | I30: No | J30: Yes | K30: Yes | L30: =IFERROR(INDEX($E30:$K30,MATCH($C$6,$E$15:$K$15,0)),"") -> Yes
A31: 16 | B31: Stainless steel worktables and shelving (lot) | C31: ='Equipment'!$L$31 -> 2800 | D31: ='Equipment'!$H$31 -> Critical | E31: Depends | F31: Yes | G31: Yes | H31: Yes | I31: Yes | J31: Yes | K31: Yes | L31: =IFERROR(INDEX($E31:$K31,MATCH($C$6,$E$15:$K$15,0)),"") -> Yes
A32: 17 | B32: Three-compartment sink, hand sink and mop sink | C32: ='Equipment'!$L$32 -> 1400 | D32: ='Equipment'!$H$32 -> Critical | E32: Depends | F32: Yes | G32: Yes | H32: Yes | I32: Yes | J32: Yes | K32: Yes | L32: =IFERROR(INDEX($E32:$K32,MATCH($C$6,$E$15:$K$15,0)),"") -> Yes | M32: A requirement, not an extra: a 3-compartment sink (Food Code 4-301.12), handwashing sinks (5-203.11) and a mop sink (5-203.13).
A33: 18 | B33: Front-counter fixtures (counter, shelving, interior sign) | C33: ='Equipment'!$L$33 -> 7500 | D33: ='Equipment'!$H$33 -> Critical | E33: No | F33: No | G33: Yes | H33: Yes | I33: Yes | J33: No | K33: Yes | L33: =IFERROR(INDEX($E33:$K33,MATCH($C$6,$E$15:$K$15,0)),"") -> Yes
A34: 19 | B34: POS terminal and software | C34: ='Equipment'!$L$34 -> 1300 | D34: ='Equipment'!$H$34 -> Critical | E34: Yes | F34: Yes | G34: Yes | H34: Yes | I34: Yes | J34: Yes | K34: Yes | L34: =IFERROR(INDEX($E34:$K34,MATCH($C$6,$E$15:$K$15,0)),"") -> Yes | M34: The POS is what rings up to-go and for-here sales separately: if you ever add seating, what's eaten at your tables is generally taxable and pastries to go generally aren't (chapter 19 of the guide). Set the keys up from day one.
A35: 20 | B35: Ambient display case | C35: ='Equipment'!$L$35 -> 1600 | D35: ='Equipment'!$H$35 -> Critical | E35: No | F35: No | G35: Yes | H35: Yes | I35: Yes | J35: No | K35: Yes | L35: =IFERROR(INDEX($E35:$K35,MATCH($C$6,$E$15:$K$15,0)),"") -> Yes | M35: For what's shelf-stable at room temperature: palmiers, Sachertorte, huesos de santo, turrón and the breads. How many feet of this case you need, and how many of the refrigerated one, is decided by the "Egg & TCS Decision" sheet in opening-menu-and-recipe-costing.xlsx, not by taste.
A36: 21 | B36: Vacuum packer, sealer and smallwares (lot) | C36: ='Equipment'!$L$36 -> 3200 | D36: ='Equipment'!$H$36 -> Critical | E36: Depends | F36: Yes | G36: Yes | H36: Yes | I36: Depends | J36: Yes | K36: Yes | L36: =IFERROR(INDEX($E36:$K36,MATCH($C$6,$E$15:$K$15,0)),"") -> Yes
A37: 22 | B37: Probe thermometers, scales and temperature data loggers | C37: ='Equipment'!$L$37 -> 900 | D37: ='Equipment'!$H$37 -> Critical | E37: Yes | F37: Yes | G37: Yes | H37: Yes | I37: Yes | J37: Yes | K37: Yes | L37: =IFERROR(INDEX($E37:$K37,MATCH($C$6,$E$15:$K$15,0)),"") -> Yes | M37: Without a probe you can't prove your cold holding and cooling temperatures (41 °F, Food Code 3-501.16 and 3-501.14). It's the cheapest purchase with the most consequences.
A38: Lines marked "Yes" | E38: =SUMPRODUCT(--($E$16:$E$37=$C$43)) -> 2 | F38: =SUMPRODUCT(--($F$16:$F$37=$C$43)) -> 15 | G38: =SUMPRODUCT(--($G$16:$G$37=$C$43)) -> 19 | H38: =SUMPRODUCT(--($H$16:$H$37=$C$43)) -> 19 | I38: =SUMPRODUCT(--($I$16:$I$37=$C$43)) -> 9 | J38: =SUMPRODUCT(--($J$16:$J$37=$C$43)) -> 17 | K38: =SUMPRODUCT(--($K$16:$K$37=$C$43)) -> 18
A39: Pre-tax reference investment ($) | E39: =SUMPRODUCT(--($E$16:$E$37=$C$43),$C$16:$C$37) -> 2200 | F39: =SUMPRODUCT(--($F$16:$F$37=$C$43),$C$16:$C$37) -> 53519.04 | G39: =SUMPRODUCT(--($G$16:$G$37=$C$43),$C$16:$C$37) -> 66980.338 | H39: =SUMPRODUCT(--($H$16:$H$37=$C$43),$C$16:$C$37) -> 66980.338 | I39: =SUMPRODUCT(--($I$16:$I$37=$C$43),$C$16:$C$37) -> 22456.1 | J39: =SUMPRODUCT(--($J$16:$J$37=$C$43),$C$16:$C$37) -> 67596.238 | K39: =SUMPRODUCT(--($K$16:$K$37=$C$43),$C$16:$C$37) -> 60480.338
A41: The seven variants (dropdown list)
A42: No. | B42: Variant | C42: Vocabulary | D42: Source | E42: What changes from the base case
A43: 1 | B43: Home-based bakery under cottage food | C43: Yes | D43: Zenind, 2026 | E43: Selling direct to consumers from your home under your state's cottage food law. Published range for a home bakery: $15,000 to $25,000 (third-party estimate).
...

Sheet Suppliers
A1: Ingredient and Packaging Suppliers
A2: AI Chef Pro · aichef.pro — How to Open a Pastry Shop
A3: The nine whose official websites we checked in October 2026. Anyone we couldn't verify stays out: a directory with a broken link is worth less than a short one.
A5: The nine verified suppliers
A6: No. | B6: Supplier | C6: What it sells you | D6: Link | E6: Source | F6: Do you buy from it? | G6: Sales rep | H6: Minimum order ($) | I6: Lead time (days) | J6: Payment terms | K6: Negotiation notes | L6: Why it's on the list
A7: 1 | B7: AUI Fine Foods | C7: Specialty pastry ingredients, decorations and frozen desserts | D7: https://www.auifinefoods.com/ | E7: Official website, Oct 2026 | F7: No | G7: Pending: ask to open an account | H7: 300 | I7: 7 | J7: To be negotiated | K7: Pending the first sales visit | L7: Headquartered in Gaithersburg, Maryland; prices shown once you log in, plus a distributors page.
A8: 2 | B8: Puratos | C8: Sourdough, improvers, mixes, fillings and chocolate | D8: https://www.puratos.us/ | E8: Official website, Oct 2026 | F8: No | G8: Pending: ask to open an account | H8: 300 | I8: 7 | J8: To be negotiated | K8: Pending the first sales visit | L8: Official website checked October 2026; it sells to bakeries and pastry shops.
A9: 3 | B9: BakeMark | C9: Bakery mixes, fillings, icings and glazes | D9: https://bakemark.com/ | E9: Official website, Oct 2026 | F9: No | G9: Pending: ask to open an account | H9: 300 | I9: 7 | J9: To be negotiated | K9: Pending the first sales visit | L9: Bakery manufacturer and distributor based in Pico Rivera, California.
A10: 4 | B10: Barry Callebaut (Callebaut) | C10: Chocolate and couverture | D10: https://www.callebaut.com/en-US | E10: Official website, Oct 2026 | F10: No | G10: Pending: ask to open an account | H10: 300 | I10: 7 | J10: To be negotiated | K10: Pending the first sales visit | L10: Chocolate Academy courses in Chicago; where-to-buy map on its US site.
A11: 5 | B11: Valrhona | C11: Premium chocolate and training | D11: https://valrhona.us/ | E11: Official website, Oct 2026 | F11: No | G11: Pending: ask to open an account | H11: 300 | I11: 7 | J11: To be negotiated | K11: Pending the first sales visit | L11: Its own US website; expert-led classes at L'Ecole Valrhona Brooklyn.
A12: 6 | B12: Plugrà (Dairy Farmers of America) | C12: European-style butter, 82% butterfat | D12: https://www.plugra.com/ | E12: Official website, Oct 2026 | F12: No | G12: Pending: ask to open an account | H12: 300 | I12: 7 | J12: To be negotiated | K12: Pending the first sales visit | L12: 82% butterfat; find-a-distributor link.
A13: 7 | B13: King Arthur Baking | C13: Bakery flour | D13: https://www.kingarthurbaking.com/pro | E13: Official website, Oct 2026 | F13: No | G13: Pending: ask to open an account | H13: 300 | I13: 7 | J13: To be negotiated | K13: Pending the first sales visit | L13: Professional sales team for bakery and pastry shops; distributor network.
A14: 8 | B14: Sysco | C14: Broadline foodservice distribution | D14: https://www.sysco.com/ | E14: Official website, Oct 2026 | F14: No | G14: Pending: ask to open an account | H14: 300 | I14: 7 | J14: To be negotiated | K14: Pending the first sales visit | L14: Tax ID or EIN to open an account; several product families on one truck.
A15: 9 | B15: WebstaurantStore | C15: Packaging: cake and bakery boxes | D15: https://www.webstaurantstore.com/ | E15: Official website, Oct 2026 | F15: No | G15: Pending: ask to open an account | H15: 300 | I15: 7 | J15: To be negotiated | K15: Pending the first sales visit | L15: Official website checked October 2026; it sells to bakeries and pastry shops.
A16: Suppliers listed on this sheet | F16: =COUNTIF($B$7:$B$15,"<>") -> 9 | G16: Nine verified, official websites checked October 2026.
A17: Suppliers you already buy from | F17: =SUMPRODUCT(--($F$7:$F$15=$B$23)) -> 0 | G17: Start with two or three: opening accounts with nine suppliers at once is a week of paperwork and no discount.
A18: Combined minimum order if you order from all at once ($) | F18: =SUM($H$7:$H$15) -> 2700 | G18: It's money sitting on your shelves on the day you have the least cash. The minimum orders are ASSUMPTIONS: each sales rep confirms them.
A19: Average committed lead time (days) | F19: =IFERROR(AVERAGE($I$7:$I$15),"") -> 7 | G19: How far ahead you have to order ingredients for each peak. The purchasing lead time for each season is worked out in seasonal-peaks-planner.xlsx.
A21: Lists (source of the dropdowns)
A22: No. | B22: Do you buy from it?
A23: 1 | B23: Yes
A24: 2 | B24: No
A26: Nine suppliers whose official websites were checked in October 2026. Anyone we couldn't verify stays out: a directory with a broken link is worth less than a short one.
A27: Need more names? Start with each brand's distributor locator (Plugrà, Callebaut, AUI Fine Foods) and ask your broadline sales rep.
A28: The minimum orders, lead times and payment terms filled in here are ASSUMPTIONS so the sheet works from the first minute: they aren't these companies' terms. Each one will give you its own, and they change with your volume and your area.
A30: Designed by John Guerrero — chef and restaurant consultant since 2010, in the kitchen since age 17.
A31: Version 1.0 · October 2026 · aichef.pro/en/digital-products/how-to-open-a-pastry-shop · info@aichef.pro

Sheet Counter
A1: Checklist Counter
A2: AI Chef Pro · aichef.pro — How to Open a Pastry Shop
A3: Everything on this sheet is read from "Equipment" and "Suppliers": you don't type anything here.
A5: Equipment checklist progress
A6: Item | B6: Value | C6: Note
A7: Checklist lines | B7: =COUNTIF('Equipment'!$C$16:$C$37,"<>") -> 22 | C7: The full package of a pastry shop with its own production kitchen.
A8: Lines marked "N/A" (outside your scope) | B8: =SUMPRODUCT(--('Equipment'!$A$16:$A$37='Equipment'!$A$66)) -> 0 | C8: What your format doesn't need. It counts neither for nor against you.
A9: Lines within your scope | B9: =$B$7-$B$8 -> 22 | C9: It's the denominator of your progress.
A10: Lines installed | B10: =SUMPRODUCT(--('Equipment'!$A$16:$A$37='Equipment'!$A$65)) -> 0 | C10: Installed means set up, hooked up and tested; received isn't installed, and that difference is days.
A11: Lines received | B11: =COUNTIF('Equipment'!$A$16:$A$37,"Received") -> 0 | C11: They're on site, in their crates.
A12: Lines ordered | B12: =COUNTIF('Equipment'!$A$16:$A$37,"Ordered") -> 0 | C12: Ordered and paid, or with a deposit: the lead time is already running.
A13: Lines quoted | B13: =COUNTIF('Equipment'!$A$16:$A$37,"Quoted") -> 0 | C13: You have the price; you haven't ordered.
A14: Lines pending | B14: =COUNTIF('Equipment'!$A$16:$A$37,"Pending") -> 22 | C14: You haven't even asked for a quote.
A15: Checklist progress (% installed) | B15: =IFERROR(IF($B$9=0,"",$B$10/$B$9),"") -> 0 | C15: Measured against what's within your scope, not against the 22 lines.
A17: What's critical, which is what decides whether you open
A18: Critical lines | B18: =SUMPRODUCT(--('Equipment'!$H$16:$H$37='Equipment'!$C$61)) -> 19 | C18: You don't open without them. Optional lines aren't counted here.
A19: Critical lines installed | B19: =SUMPRODUCT(--('Equipment'!$H$16:$H$37='Equipment'!$C$61),--('Equipment'!$A$16:$A$37='Equipment'!$A$65)) -> 0
A20: Critical progress (%) | B20: =IFERROR(IF($B$18=0,"",$B$19/$B$18),"") -> 0 | C20: This is the percentage to watch the week before you open.
A21: Can you open with what's installed? | B21: =IF($B$18=0,"",IF($B$19=$B$18,"Yes: everything critical is installed",CONCATENATE("No: missing ",$B$18-$B$19," critical lines"))) -> No: missing 19 critical lines | C21: The permits run on their own track: permits-and-licenses-checklist.xlsx answers that.
A23: By startup cost block
A24: Block | B24: Lines | C24: Pre-tax reference ($) | D24: Negotiated ($) | E24: Deviation (%) | F24: Note
A25: Production kitchen equipment | B25: =SUMPRODUCT(--('Equipment'!$G$16:$G$37=$A25)) -> 17 | C25: =SUMPRODUCT(--('Equipment'!$G$16:$G$37=$A25),'Equipment'!$L$16:$L$37) -> 73696.238 | D25: =SUMPRODUCT(--('Equipment'!$G$16:$G$37=$A25),'Equipment'!$O$16:$O$37) -> 73696.24 | E25: =IFERROR(IF($C25=0,"",$D25/$C25-1),"") -> 2.2428452e-08 | F25: It's the block startup-cost-calculator.xlsx carries to its "Startup Costs by Block" sheet under this same name.
A26: Storefront and display | B26: =SUMPRODUCT(--('Equipment'!$G$16:$G$37=$A26)) -> 5 | C26: =SUMPRODUCT(--('Equipment'!$G$16:$G$37=$A26),'Equipment'!$L$16:$L$37) -> 12804.5 | D26: =SUMPRODUCT(--('Equipment'!$G$16:$G$37=$A26),'Equipment'!$O$16:$O$37) -> 12804.5 | E26: =IFERROR(IF($C26=0,"",$D26/$C26-1),"") -> 0 | F26: It's the block startup-cost-calculator.xlsx carries to its "Startup Costs by Block" sheet under this same name.
A27: TOTAL | B27: =SUMPRODUCT(--('Equipment'!$G$16:$G$37<>"")) -> 22 | C27: =SUMPRODUCT('Equipment'!$L$16:$L$37) -> 86500.738 | D27: =SUMPRODUCT('Equipment'!$O$16:$O$37) -> 86500.74 | E27: =IFERROR(IF($C$27=0,"",$D$27/$C$27-1),"") -> 1.9108422e-08
A29: By equipment category
A30: Category | B30: Lines | C30: Pre-tax reference ($) | D30: Negotiated ($) | E30: Installed | F30: Note
A31: Heat | B31: =SUMPRODUCT(--('Equipment'!$F$16:$F$37=$A31)) -> 3 | C31: =SUMPRODUCT(--('Equipment'!$F$16:$F$37=$A31),'Equipment'!$L$16:$L$37) -> 16849.198 | D31: =SUMPRODUCT(--('Equipment'!$F$16:$F$37=$A31),'Equipment'!$O$16:$O$37) -> 16849.2 | E31: =SUMPRODUCT(--('Equipment'!$F$16:$F$37=$A31),--('Equipment'!$A$16:$A$37='Equipment'!$A$65)) -> 0
A32: Storefront and display | B32: =SUMPRODUCT(--('Equipment'!$F$16:$F$37=$A32)) -> 5 | C32: =SUMPRODUCT(--('Equipment'!$F$16:$F$37=$A32),'Equipment'!$L$16:$L$37) -> 12804.5 | D32: =SUMPRODUCT(--('Equipment'!$F$16:$F$37=$A32),'Equipment'!$O$16:$O$37) -> 12804.5 | E32: =SUMPRODUCT(--('Equipment'!$F$16:$F$37=$A32),--('Equipment'!$A$16:$A$37='Equipment'!$A$65)) -> 0
A33: Freezing | B33: =SUMPRODUCT(--('Equipment'!$F$16:$F$37=$A33)) -> 2 | C33: =SUMPRODUCT(--('Equipment'!$F$16:$F$37=$A33),'Equipment'!$L$16:$L$37) -> 11937 | D33: =SUMPRODUCT(--('Equipment'!$F$16:$F$37=$A33),'Equipment'!$O$16:$O$37) -> 11937 | E33: =SUMPRODUCT(--('Equipment'!$F$16:$F$37=$A33),--('Equipment'!$A$16:$A$37='Equipment'!$A$65)) -> 0
A34: Sheeting | B34: =SUMPRODUCT(--('Equipment'!$F$16:$F$37=$A34)) -> 1 | C34: =SUMPRODUCT(--('Equipment'!$F$16:$F$37=$A34),'Equipment'!$L$16:$L$37) -> 1215 | D34: =SUMPRODUCT(--('Equipment'!$F$16:$F$37=$A34),'Equipment'!$O$16:$O$37) -> 1215 | E34: =SUMPRODUCT(--('Equipment'!$F$16:$F$37=$A34),--('Equipment'!$A$16:$A$37='Equipment'!$A$65)) -> 0
A35: Mixing | B35: =SUMPRODUCT(--('Equipment'!$F$16:$F$37=$A35)) -> 2 | C35: =SUMPRODUCT(--('Equipment'!$F$16:$F$37=$A35),'Equipment'!$L$16:$L$37) -> 5795.04 | D35: =SUMPRODUCT(--('Equipment'!$F$16:$F$37=$A35),'Equipment'!$O$16:$O$37) -> 5795.04 | E35: =SUMPRODUCT(--('Equipment'!$F$16:$F$37=$A35),--('Equipment'!$A$16:$A$37='Equipment'!$A$65)) -> 0
A36: Chocolate | B36: =SUMPRODUCT(--('Equipment'!$F$16:$F$37=$A36)) -> 1 | C36: =SUMPRODUCT(--('Equipment'!$F$16:$F$37=$A36),'Equipment'!$L$16:$L$37) -> 7400 | D36: =SUMPRODUCT(--('Equipment'!$F$16:$F$37=$A36),'Equipment'!$O$16:$O$37) -> 7400 | E36: =SUMPRODUCT(--('Equipment'!$F$16:$F$37=$A36),--('Equipment'!$A$16:$A$37='Equipment'!$A$65)) -> 0
A37: Refrigeration | B37: =SUMPRODUCT(--('Equipment'!$F$16:$F$37=$A37)) -> 3 | C37: =SUMPRODUCT(--('Equipment'!$F$16:$F$37=$A37),'Equipment'!$L$16:$L$37) -> 15700 | D37: =SUMPRODUCT(--('Equipment'!$F$16:$F$37=$A37),'Equipment'!$O$16:$O$37) -> 15700 | E37: =SUMPRODUCT(--('Equipment'!$F$16:$F$37=$A37),--('Equipment'!$A$16:$A$37='Equipment'!$A$65)) -> 0
A38: Building systems | B38: =SUMPRODUCT(--('Equipment'!$F$16:$F$37=$A38)) -> 2 | C38: =SUMPRODUCT(--('Equipment'!$F$16:$F$37=$A38),'Equipment'!$L$16:$L$37) -> 7900 | D38: =SUMPRODUCT(--('Equipment'!$F$16:$F$37=$A38),'Equipment'!$O$16:$O$37) -> 7900 | E38: =SUMPRODUCT(--('Equipment'!$F$16:$F$37=$A38),--('Equipment'!$A$16:$A$37='Equipment'!$A$65)) -> 0
A39: Kitchen fixtures | B39: =SUMPRODUCT(--('Equipment'!$F$16:$F$37=$A39)) -> 2 | C39: =SUMPRODUCT(--('Equipment'!$F$16:$F$37=$A39),'Equipment'!$L$16:$L$37) -> 6000 | D39: =SUMPRODUCT(--('Equipment'!$F$16:$F$37=$A39),'Equipment'!$O$16:$O$37) -> 6000 | E39: =SUMPRODUCT(--('Equipment'!$F$16:$F$37=$A39),--('Equipment'!$A$16:$A$37='Equipment'!$A$65)) -> 0
A40: Monitoring | B40: =SUMPRODUCT(--('Equipment'!$F$16:$F$37=$A40)) -> 1 | C40: =SUMPRODUCT(--('Equipment'!$F$16:$F$37=$A40),'Equipment'!$L$16:$L$37) -> 900 | D40: =SUMPRODUCT(--('Equipment'!$F$16:$F$37=$A40),'Equipment'!$O$16:$O$37) -> 900 | E40: =SUMPRODUCT(--('Equipment'!$F$16:$F$37=$A40),--('Equipment'!$A$16:$A$37='Equipment'!$A$65)) -> 0
A42: Suppliers
A43: Verified suppliers listed | B43: ='Suppliers'!$F$16 -> 9 | C43: The nine with official websites checked October 2026.
A44: Suppliers you already buy from | B44: ='Suppliers'!$F$17 -> 0
A45: Equipment lines with no supplier assigned | B45: =SUMPRODUCT(--('Equipment'!$Q$16:$Q$37='Equipment'!$G$61)) -> 13 | C45: The ones still reading "Pending: get three quotes". Production kitchen equipment is sold by quote: until there's a name, there's no price.
...
