Workbook

Sheet Instructions
A1: Permits, Licenses and Opening Timeline Checklist
A2: AI Chef Pro · aichef.pro — How to Open a Pastry Shop
A3: What it's for: knowing which permits apply to you, in what order, which agency issues your food permit and when you can open.
A5: How to use it
A6: 1. "Permits Checklist (P1-P6)" sheet: the thirty steps in the order you do them, in six phases. Mark the status, enter the cost you're quoted and what you end up paying, and add both dates. Each phase has its own counter and % complete; at the bottom you get the summary of everything and the variance between budget and actual.
A7: 2. "Which Permit Do I Need" sheet: three questions and a verdict. It clears up a common mix-up: a bakery that sells directly to consumers is a retail food establishment, does NOT register with FDA, and gets its food permit from the local health department (or, in New York and Florida, from the state agriculture department if it bakes and sells to go).
A8: 3. "Selling Wholesale" sheet: the FDA 50% line, with its gateway question first. If you don't sell to other businesses, it doesn't apply and the sheet says so on the first line. If it does, there are three checks (the 50% line, cold chain and labels), and the 50% line can be measured TWO alternative ways.
A9: 4. "Cottage Food Route" sheet: if you're thinking of starting from home. Three checks (a weekly volume ceiling, volume for your space and records that prove you're under your state's sales cap), what each of the four example states lets you sell, the channel rules and the label statement. Watch Texas: since September 1, 2025 it allows cream cakes and cheesecake from home with DSHS registration.
A10: 5. "Training Log" sheet: one line per person with the date, the certificate or card and the renewal date. The person in charge must be a certified food protection manager (CFPM); food handler card rules depend on your state.
A11: 6. "Timeline and Critical Path" sheet: twelve milestones with their durations and dependencies. The sheet works out when each one starts and ends, how much slack it has, which ones are on the critical path (the ones where a day late means opening a day late) and which month you end up opening. And it warns you if that date falls inside a peak season.
A13: Green cells = fields you can edit
A15: What to know before you start
... A23: WHAT THIS WORKBOOK DOES AND WHAT ANOTHER ONE DOES (so you don't type things twice)
A24: Product or workbook | B24: What it gives you | C24: What this workbook does NOT do
A25: HACCP Food Safety Kit Pro | B25: Your food safety logs, temperature logs and display-case allergen matrix, already built and ready to fill in. | C25: Here there's only one checklist ROW for the plan and one reminding you to post the allergen notice before you open. The plan and the matrix themselves are in that product.
A26: Bakery Business Plan Kit | B26: The business plan for your bank or SBA lender, ready to fill in. | C26: This workbook tracks permits and dates, not the pitch to your lender: that's what the kit is for.
A27: The "equipment-and-suppliers-checklist" workbook in this guide | B27: Each piece of equipment's lead time, which is what really moves your opening date. | C27: This workbook's timeline works in MONTHS, with one duration per milestone. When you have lead times in writing, bring them into the "Order and delivery of equipment" milestone.
A28: The "3-year-financial-plan" workbook in this guide | B28: The dollars: what each block of the startup investment costs and when the cash goes out. | C28: The costs in this checklist are those of the STEPS. The build-out, equipment and working capital are there, and that's where they add up.
A30: How often to use this workbook
A31: How often: the checklist and the timeline, ONCE A WEEK from the day you decide to open until you open. The three decision sheets (which permit, selling wholesale and cottage food), ONCE AT THE START and again every time you change channels: the day you agree to supply the café next door, you start selling wholesale without noticing. The training log, every time someone joins and whenever someone's card or certificate is due.
A33: To edit the structure or a cell that isn't green: Review > Unprotect Sheet (no password).
A35: Designed by John Guerrero — chef and restaurant consultant since 2010, in the kitchen since age 17.
A36: Version 1.0 · October 2026 · aichef.pro/en/digital-products/how-to-open-a-pastry-shop · info@aichef.pro

Sheet Permits Checklist (P1-P6)
A1: Permits and Licenses Checklist, in Six Phases
A2: AI Chef Pro · aichef.pro — How to Open a Pastry Shop
A3: Thirty steps in the order you do them. Mark the status, enter what you're quoted and what you end up paying, and add both dates. What changes by state is flagged in its own column.
B5: Phase | C5: Step | D5: Who does it | E5: Lead time (days) | F5: Budgeted cost ($) | G5: Actual cost ($) | H5: Target date | I5: Date done | J5: Varies by state? | K5: Notes
A6: P1 · Before you sign anything: can this space work?
A7: Pending | B7: P1 | C7: Ask the city's zoning office whether this space allows a bakery with on-site production, not just retail | D7: Owner | E7: 10 | F7: Get a quote | G7: Not paid yet | H7: 46275 | I7: 46275 | J7: No | K7: Zoning is set by your city or county, and there's no national rule. Ask it as a QUESTION, in writing: which use a bakery with a production kitchen falls under, and what a change of use triggers (building permit, new certificate of occupancy). Never assume it. [Source: local zoning code]
A8: Pending | B8: P1 | C8: Find out which hood your ovens need (Type I or Type II) and where the duct can run | D8: Owner | E8: 15 | F8: Get a quote | G8: Not paid yet | H8: 46275 | I8: 46275 | J8: No | K8: Hood type follows the appliance, its listing and your local mechanical code. An enclosed electric convection or rack oven may need only a Type II hood, or none if it's a single light-duty unit (3.7 kW or less) or listed to UL 710B; deck and pizza-style ovens usually go under a Type I hood with fire suppression. Get the answer in writing BEFORE you sign. [Source: International Mechanical Code §507]
A9: Pending | B9: P1 | C9: Get the landlord's written OK for the hood, the duct route and any roof work | D9: Owner | E9: 30 | F9: Get a quote | G9: Not paid yet | H9: 46275 | I9: 46275 | J9: No | K9: Timing depends on the landlord and, in a shopping center, on the center's rules (CC&Rs). It's the variable you control least. [Source: guide estimate]
A10: Pending | B10: P1 | C10: Check the electrical service (amps and voltage) and what an upgrade would cost | D10: Owner | E10: 15 | F10: Get a quote | G10: Not paid yet | H10: 46275 | I10: 46275 | J10: No | K10: Ovens alone can draw 20-80 kW: have an electrician check the panel before you sign. [Source: guide estimate]
A11: Pending | B11: P1 | C11: Check the 7 kitchen zones and the required sinks fit with a one-way flow | D11: Owner | E11: 5 | F11: Get a quote | G11: Not paid yet | H11: 46275 | I11: 46275 | J11: No | K11: Food Code 2022: handwashing sinks where needed (5-203.11), a sink with at least 3 compartments for manual dishwashing (4-301.12) and a service (mop) sink (5-203.13). Zone sizes: "kitchen-capacity-and-site" workbook. [Source: FDA Food Code 2022]
C12: PHASE P1 PROGRESS | D12: =IFERROR(COUNTIF(A7:A11,"Done"),"") -> 0 | E12: =IFERROR(COUNTIF(B7:B11,"P1"),"") -> 5 | F12: =IFERROR(SUMIF(F7:F11,">=0"),"") -> 0 | G12: =IFERROR(SUMIF(G7:G11,">=0"),"") -> 0 | J12: =IFERROR(IF(E12=0,"",(D12+COUNTIF(A7:A11,"N/A"))/E12),"") -> 0 | K12: Done · steps in the phase · budgeted cost · actual cost · % complete ("N/A" counts as resolved).
A14: P2 · Business setup, tax IDs and plans
A15: Pending | B15: P2 | C15: Form your LLC with the state (or start as a sole proprietor) and file a DBA if you need one | D15: Owner | E15: 20 | F15: 600 | G15: Not paid yet | H15: 46275 | I15: 46275 | J15: No | K15: A sole proprietorship exists automatically; an LLC is registered with your state. Decide before you sign: the lease, bank account and permits go in that name. The $600 is the guide's placeholder for filing fees and help. [Source: SBA, 2026]
A16: Pending | B16: P2 | C16: Get your EIN from the IRS and open the business bank account | D16: Attorney or CPA | E16: 3 | F16: Get a quote | G16: Not paid yet | H16: 46275 | I16: 46275 | J16: No | K16: The EIN is free from the IRS, and you need it once you have employees or a multi-member LLC. Your bank, payroll provider and state tax registration will all ask for it. [Source: IRS, 2026]
A17: Pending | B17: P2 | C17: Register for your state sales tax permit and as an employer with your state workforce agency | D17: Attorney or CPA | E17: 3 | F17: Get a quote | G17: Not paid yet | H17: 46275 | I17: 46275 | J17: No | K17: [Source: guide estimate; confirm locally]
A18: Pending | B18: P2 | C18: Hire the architect or engineer for the stamped plans and specifications | D18: Architect or engineer | E18: 30 | F18: 5000 | G18: Not paid yet | H18: 46275 | I18: 46275 | J18: No | K18: It's the document everything else hangs on: the health department's plan review asks for the layout, equipment by make and model, finishes and mechanical plans (Food Code 8-201.12), and the building permit needs it too. [Source: FDA Food Code 2022]
A19: Pending | B19: P2 | C19: Sign the lease with a permit contingency and pay the security deposit | D19: Owner | E19: 5 | F19: 2400 | G19: Not paid yet | H19: 46275 | I19: 46275 | J19: Yes | K19: Before you sign: a use clause that says "bakery with on-site production and retail sales", a permit and zoning contingency, who pays for HVAC and the roof, and a cap on the personal guarantee. Lease law is state law: have a local attorney read it. [Source: guide's lease checklist]
C20: PHASE P2 PROGRESS | D20: =IFERROR(COUNTIF(A15:A19,"Done"),"") -> 0 | E20: =IFERROR(COUNTIF(B15:B19,"P2"),"") -> 5 | F20: =IFERROR(SUMIF(F15:F19,">=0"),"") -> 8000 | G20: =IFERROR(SUMIF(G15:G19,">=0"),"") -> 0 | J20: =IFERROR(IF(E20=0,"",(D20+COUNTIF(A15:A19,"N/A"))/E20),"") -> 0 | K20: Done · steps in the phase · budgeted cost · actual cost · % complete ("N/A" counts as resolved).
A22: P3 · Plan review and local permits
A23: Pending | B23: P3 | C23: Submit plans and specifications for the health department's plan review | D23: Architect or engineer | E23: 45 | F23: 1800 | G23: Not paid yet | H23: 46275 | I23: 46275 | J23: Yes | K23: Food Code 8-201.11: plans go in BEFORE you build or remodel. California requires it by law (20 working days, H&S Code §114380); Austin, TX charges $312 for a new build; Florida's FDACS review is voluntary ($55.10). In New York and Florida, a bakery that bakes and sells to go answers to the state agriculture department. The $1,800 is the guide's placeholder: use your county's fee. [Source: FDA Food Code 2022 + state and city rules]
A24: Pending | B24: P3 | C24: Pull the building permit (and the change of use if the space wasn't a food business) | D24: Architect or engineer | E24: 30 | F24: Get a quote | G24: Not paid yet | H24: 46275 | I24: 46275 | J24: Yes | K24: [Source: guide estimate; confirm locally]
A25: Pending | B25: P3 | C25: Get the city or county business license and the sign permit | D25: Owner | E25: 20 | F25: Get a quote | G25: Not paid yet | H25: 46275 | I25: 46275 | J25: Yes | K25: [Source: guide estimate; confirm locally]
C26: PHASE P3 PROGRESS | D26: =IFERROR(COUNTIF(A23:A25,"Done"),"") -> 0 | E26: =IFERROR(COUNTIF(B23:B25,"P3"),"") -> 3 | F26: =IFERROR(SUMIF(F23:F25,">=0"),"") -> 1800 | G26: =IFERROR(SUMIF(G23:G25,">=0"),"") -> 0 | J26: =IFERROR(IF(E26=0,"",(D26+COUNTIF(A23:A25,"N/A"))/E26),"") -> 0 | K26: Done · steps in the phase · budgeted cost · actual cost · % complete ("N/A" counts as resolved).
A28: P4 · Build-out, equipment and inspections
A29: Pending | B29: P4 | C29: Build out the space: construction, plumbing, electrical and HVAC | D29: Contractor | E29: 60 | F29: 81000 | G29: Not paid yet | H29: 46275 | I29: 46275 | J29: No | K29: Mid scenario: $83.61 per sq ft × 969 sq ft. [Source: the guide's build-out estimate]
A30: Pending | B30: P4 | C30: Order the equipment with the delivery lead time in writing | D30: Owner | E30: 5 | F30: Get a quote | G30: Not paid yet | H30: 46275 | I30: 46275 | J30: No | K30: Lead time, not price, moves your opening date: a roll-in retarder-proofer can take about 6 weeks to ship from the manufacturer. Get it in writing and enter it in the "equipment-and-suppliers-checklist" workbook. [Source: WebstaurantStore listing, October 2026]
A31: Pending | B31: P4 | C31: Fire marshal inspection: hood fire suppression (Type I hoods) and Class K extinguisher | D31: Licensed installer | E31: 15 | F31: Get a quote | G31: Not paid yet | H31: 46275 | I31: 46275 | J31: No | K31: A Type I hood needs a fire-suppression system (NFPA 96), and the fire marshal inspects it along with the extinguishers. If you use gas ovens, ask the building department about the gas line permit too. [Source: NFPA 96, city fire code example]
A32: Pending | B32: P4 | C32: Electrical permit and final electrical inspection | D32: Licensed installer | E32: 10 | F32: Get a quote | G32: Not paid yet | H32: 46275 | I32: 46275 | J32: No | K32: [Source: guide estimate; confirm locally]
A33: Pending | B33: P4 | C33: Check ADA accessibility, starting with the sales counter | D33: Architect or engineer | E33: 10 | F33: Get a quote | G33: Not paid yet | H33: 46275 | I33: 46275 | J33: No | K33: ADA 904.4.1: at least one section of the sales counter 36 inches long and no higher than 36 inches, with room for a parallel approach (if the counter is shorter than 36 inches, all of it). Check it on the drawings, not after the counter is built. [Source: U.S. Access Board]
C34: PHASE P4 PROGRESS | D34: =IFERROR(COUNTIF(A29:A33,"Done"),"") -> 0 | E34: =IFERROR(COUNTIF(B29:B33,"P4"),"") -> 5 | F34: =IFERROR(SUMIF(F29:F33,">=0"),"") -> 81000 | G34: =IFERROR(SUMIF(G29:G33,">=0"),"") -> 0 | J34: =IFERROR(IF(E34=0,"",(D34+COUNTIF(A29:A33,"N/A"))/E34),"") -> 0 | K34: Done · steps in the phase · budgeted cost · actual cost · % complete ("N/A" counts as resolved).
A36: P5 · Food permit, food safety and training
A37: Pending | B37: P5 | C37: Apply for the food establishment permit and pass the pre-opening inspection | D37: Owner | E37: 5 | F37: 120 | G37: Not paid yet | H37: 46275 | I37: 46275 | J37: Yes | K37: It's NOT an FDA registration: a bakery that sells to consumers is exempt from that. The permit is local: county or city environmental health in California and Texas (Texas DSHS where there's no local department); for a bakery that bakes and sells to go, Agriculture and Markets (Article 20-C) in New York and FDACS in Florida; with seating, the health department (NY) or DBPR (FL). Florida asks you to apply 21 days before opening. The $120 is the guide's placeholder. [Source: state agencies, 2026]
A38: Pending | B38: P5 | C38: Check whether your wholesale accounts make you register with FDA | D38: Owner | E38: 5 | F38: Get a quote | G38: Not paid yet | H38: 46275 | I38: 46275 | J38: No | K38: Only matters if you sell to cafés, restaurants or stores. You stay a retail food establishment, with no FDA registration, while more than half of your food sales by value go directly to consumers; businesses never count as consumers. Cross that line and check FDA food facility registration. The "Selling Wholesale" sheet does the math. [Source: 21 CFR 1.226(c) and 1.227]
A39: Pending | B39: P5 | C39: Write the food safety plan and name a certified food protection manager as person in charge | D39: Owner | E39: 20 | F39: 800 | G39: Not paid yet | H39: 46275 | I39: 46275 | J39: No | K39: Food Code 2022 (2-102.12): the person in charge must be a certified food protection manager. Inspectors enforce your state's adopted edition (Texas and Florida 2017, New York 2001, California its own code), but building to the 2022 rules is the safe choice. The HACCP Food Safety Kit Pro has the logs ready. [Source: FDA Food Code 2022 + FDA, 2024]
A40: Pending | B40: P5 | C40: Train the team in food safety and allergens, and log it person by person | D40: Owner | E40: 10 | F40: 240 | G40: Not paid yet | H40: 46275 | I40: 46275 | J40: No | K40: Food Code 2022 (2-103.11(O)): staff trained in food safety, allergen awareness included. Cards are state rules: California, a food handler card within 30 days of hire; Texas, an accredited food handler course; New York State, no card (New York City requires a Food Protection Certificate). The "Training Log" sheet tracks them. [Source: FDA Food Code 2022 + state rules]
A41: Pending | B41: P5 | C41: Post the written allergen notice for the display case before you open | D41: Owner | E41: 5 | F41: Get a quote | G41: Not paid yet | H41: 46275 | I41: 46275 | J41: No | K41: Food Code 2022 (3-602.12(C)): written notice of the 9 major allergens in the unpackaged food you sell. The display-case matrix comes ready in the HACCP Food Safety Kit Pro; this guide builds the KITCHEN one (ingredients by allergen and production order), a different thing. New York also signed a law on allergen notices for food packaged in the store (November 12, 2025). [Source: FDA Food Code 2022]
A42: Pending | B42: P5 | C42: Set up timekeeping: records of hours worked for everyone on payroll | D42: Attorney or CPA | E42: 5 | F42: Get a quote | G42: Not paid yet | H42: 46275 | I42: 46275 | J42: No | K42: FLSA: keep records of hours worked; overtime over 40 hours in a workweek at 1.5× or more, with no federal premium for nights, weekends or holidays. California adds meal and rest breaks, with one hour of pay as the penalty for each day one is missed. [Source: U.S. DOL + California DIR, 2026]
C43: PHASE P5 PROGRESS | D43: =IFERROR(COUNTIF(A37:A42,"Done"),"") -> 0 | E43: =IFERROR(COUNTIF(B37:B42,"P5"),"") -> 6 | F43: =IFERROR(SUMIF(F37:F42,">=0"),"") -> 1160 | G43: =IFERROR(SUMIF(G37:G42,">=0"),"") -> 0 | J43: =IFERROR(IF(E43=0,"",(D43+COUNTIF(A37:A42,"N/A"))/E43),"") -> 0 | K43: Done · steps in the phase · budgeted cost · actual cost · % complete ("N/A" counts as resolved).
A45: P6 · Opening: payroll, sales tax and the shop
A46: Pending | B46: P6 | C46: Hire the team at or above your state's minimum wage, with Form I-9 and workers' comp | D46: Attorney or CPA | E46: 15 | F46: Get a quote | G46: Not paid yet | H46: 46275 | I46: 46275 | J46: Yes | K46: 2026 minimums: Texas $7.25 (the federal rate), California $16.90, New York $17.00 (NYC, Long Island, Westchester) or $16.00 elsewhere, Florida $14.00 until September 29, 2026 (check FloridaCommerce for the current rate). Many cities set higher ones. The guide's wage table clears Texas but not California, New York or Florida: use your own figures. Workers' comp is required in most states. [Source: U.S. DOL, July 2026]
...

Sheet Which Permit Do I Need
A1: Which Permit Do I Need: Local Food Permit or FDA Registration?
A2: AI Chef Pro · aichef.pro — How to Open a Pastry Shop
A3: Three questions and a verdict. It clears up a common mix-up: a bakery that sells to consumers needs a food permit, not an FDA food facility registration.
A5: THE THREE QUESTIONS
A6: Do you sell directly to consumers (counter, custom orders or your own website)? | B6: Yes | C6: If "Yes", you're a retail food establishment, and retail food establishments don't register with FDA as long as more than half of their food sales, by value, go directly to consumers. Your permit comes from your local or state food agency.
A7: Do you also sell to other BUSINESSES (cafés, restaurants, stores)? | B7: No | C7: Businesses never count as consumers, however small they are. If "Yes", go to the "Selling Wholesale" sheet before you read the verdict.
A8: Do you have, or plan, a second location? | B8: No | C8: Ask your agency before you open it: whether the second site needs its own permit, and how it treats food you bake at one site and sell at the other.
A9: Your state | B9: Texas | C9: Four EXAMPLE states, chosen because they permit the same bakery in very different ways. If yours isn't listed, choose "Other" and search "[your county] environmental health food facility plan check".
A11: THE VERDICT
A12: What you are | B12: =IFERROR(IF(B6<>"Yes","Not a retail bakery: with no sales directly to consumers you're not exempt, so check FDA food facility registration and get advice",IF(B7="No","Retail food establishment: a local or state food permit is what you need, with no FDA registration",'Selling Wholesale'!$B$41)),"") -> Retail food establishment: a local or state food permit is what you need, with no FDA registration
A13: The permit to get | B13: =IFERROR(IF(B7="No","Retail food permit from your county or city health department (in NY and FL, the state agriculture department if you bake and sell to go)","The same retail food permit PLUS whatever the ""Selling Wholesale"" sheet says"),"") -> Retail food permit from your county or city health department (in NY and FL, the state agriculture department if you bake and sell to go)
A14: Can you open once you've applied? | B14: No. The food permit is issued after plan review and the pre-opening inspection, and you need it in hand to open. It doesn't replace your building permit, certificate of occupancy or business license.
A15: Who issues it in your state | B15: =IFERROR(IF(B9="Texas","Texas: city or county health department, or DSHS where there's none (Austin: plan review $312, pre-opening inspection $178)","CA: county environmental health · NY: Agriculture and Markets (20-C) · FL: FDACS (DBPR with seating) · Other: look up your state"),"") -> Texas: city or county health department, or DSHS where there's none (Austin: plan review $312, pre-opening inspection $178)
A16: If you have a second location | B16: =IFERROR(IF(B8="Yes","Ask your agency whether each location needs its own permit and how it treats food you bake at one and sell at the other","Not applicable"),"") -> Not applicable
A18: THE THREE CASES, SO YOU SEE WHY
A19: Your situation | B19: What you need | C19: Why
A20: You sell only to consumers, at your counter and on your website | B20: A retail food permit from your local (or state) food agency | C20: You're a retail food establishment, exempt from FDA registration. Selling online to consumers, shipped to their door, generally keeps you retail while consumers take more than half of your food sales by value.
A21: You also sell to cafés or stores, consumers still take more than half of your sales, and you pass the three wholesale checks | B21: The same retail food permit, PLUS full labels or allergen sheets for every account and a cold chain you can show | C21: Still outside FDA registration, with more paperwork. The "Selling Wholesale" sheet runs the three checks one by one.
A22: You sell to businesses and fail one of the three checks | B22: FDA registration if businesses take half or more; otherwise fix what fails | C22: Failing the 50% line is what triggers FDA registration; failing cold chain or labels is a fix before your next delivery. Watch the line when one account grows: a single hotel or chain can tip it.
A24: A bakery that sells to consumers is a retail food establishment: while more than half of its annual food sales, by value, go directly to consumers, it doesn't register with FDA (21 CFR 1.226(c) and 1.227). What it does need is a food permit from the local health department or, in New York and Florida, from the state agriculture department if it bakes and sells to go, usually issued after plan review and a pre-opening inspection. All of this was checked against the official texts in October 2026, and each cell's comment has the link.
A26: Validation lists (don't delete them: the dropdowns come from here)
A27: Yes or No
A28: Yes
A29: No
A31: State
A32: Texas
A33: California
A34: New York
A35: Florida
A36: Other (check your state)

Sheet Selling Wholesale
A1: Selling Wholesale: the FDA 50% Line and Two More Checks
A2: AI Chef Pro · aichef.pro — How to Open a Pastry Shop
A3: First the gateway: this applies ONLY if you sell to other businesses. Then three checks: the FDA line (with two ALTERNATIVE ways to measure it), cold chain and labels.
A5: GATEWAY: DOES THIS APPLY TO YOU AT ALL?
A6: Do you sell food you make to other BUSINESSES (cafés, restaurants, stores, caterers)? | B6: No | F6: If "No", skip the rest of the sheet. Selling to consumers, even online and shipped to their door, isn't wholesale.
A7: Gateway answer | B7: =IFERROR(IF(B6="No","This sheet doesn't apply: nothing below binds you","It applies: go through the three checks"),"") -> This sheet doesn't apply: nothing below binds you
A9: YOUR WHOLESALE ACCOUNTS
A10: Account | B10: kg a week | C10: % of annual food sales | D10: Miles | E10: Missing label or allergen info? | F10: Notes
A11: Corner coffee shop | B11: 22 | C11: 0.018 | D11: 1.2 | E11: No
A12: Neighborhood restaurant | B12: 14 | C12: 0.011 | D12: 2.4 | E12: No
A13: Downtown specialty food store | B13: 9 | C13: 0.007 | D13: 3.1 | E13: No
A14: Boutique hotel on the avenue | B14: 6 | C14: 0.005 | D14: 4 | E14: No
A15: (open: type your fifth account here) | B15: 0 | C15: 0 | D15: 0 | E15: No
A16: (open: type your sixth account here) | B16: 0 | C16: 0 | D16: 0 | E16: No
A17: TOTAL | B17: =IFERROR(SUM(B11:B16),"") -> 51 | C17: =IFERROR(SUM(C11:C16),"") -> 0.041 | D17: =IFERROR(MAX(D11:D16),"") -> 4 | E17: =IFERROR(COUNTIF(E11:E16,"Yes"),"") -> 0 | F17: Kilos and percentages add up; miles take the MAXIMUM (your farthest account decides), and the last column counts the accounts missing labels or allergen info.
A19: CHECK 1 · THE FDA LINE (two ALTERNATIVE ways to measure it: one is enough)
A20: Way a) · Your working line: share of food sales going to businesses (%) | B20: 0.25 | F20: FDA's legal line is 50%: you stay a retail food establishment while consumers take MORE than half of your food sales by value. The line seeded here is deliberately cautious, so you see it coming.
A21: Your share to businesses (from the table) | B21: =IFERROR(C17,"") -> 0.041
A22: Way a) passes? | B22: =IFERROR(IF(B21<=B20,"Yes","No"),"") -> Yes
A23: Way b) · Your direct-to-consumer food sales, a typical week ($) | B23: 500 | F23: The legal test, by value: what consumers buy at your counter, by custom order or online. Use your POS figures, and check the whole year, not one good week.
A24: Your food sales to businesses, the same week ($) | B24: 380 | F24: SEEDED ASSUMPTION. Use your invoices. Way b) passes while this stays below the consumer figure, that is, while businesses take less than half.
A25: Way b) passes? | B25: =IFERROR(IF(B24<=B23,"Yes","No"),"") -> Yes
A26: UNDER THE FDA LINE? | B26: =IFERROR(IF(OR(B22="Yes",B25="Yes"),"Yes","No"),"") -> Yes | F26: One way is enough: both measure the same line. Businesses never count as consumers (21 CFR 1.227).
A28: CHECK 2 · COLD CHAIN AND DELIVERY
A29: Can you deliver every wholesale order yourself (or with your staff), keeping TCS items at 41 °F or below? | B29: Yes | F29: Cream fillings, custards and cheesecake are TCS foods: the Food Code holds them at 41 °F or below, and on the road that's on you until the account receives them.
A30: Your maximum delivery radius for TCS items (miles) | B30: 50 | F30: Your own figure, not a legal one: how far you can drive and still arrive at 41 °F or below.
A31: Distance to your farthest account (miles) | B31: =IFERROR(D17,"") -> 4
A32: Do you deliver TCS items (cream, custard, cheesecake) to any account? | B32: No
A33: COLD CHAIN OK? | B33: =IFERROR(IF(AND(B29="Yes",OR(B32="No",B31<=B30)),"Yes","No"),"") -> Yes
A35: CHECK 3 · LABELS AND ALLERGEN INFO
A36: Accounts missing labels or allergen info | B36: =IFERROR(E17,"") -> 0 | F36: Packaged items need the full label: common name, ingredients by weight, net quantity, your name and address, and the source of each major allergen. Unpackaged items need an allergen sheet so the café can give its customers the written notice. One account without it is enough to fail.
A37: LABELS OK? | B37: =IFERROR(IF(B36=0,"Yes","No"),"") -> Yes
A39: THE VERDICT
A40: Checks passed (out of three) | B40: =IFERROR(COUNTIF(B26:B26,"Yes")+COUNTIF(B33:B33,"Yes")+COUNTIF(B37:B37,"Yes"),"") -> 3
A41: VERDICT | B41: =IFERROR(IF(B6="No","This sheet doesn't apply: you don't sell to other businesses",IF(B40=3,"All three pass: you stay a retail food establishment (no FDA registration), with labels and records in order","Not yet: fix the check that fails (FDA line: check FDA food facility registration; cold chain or labels: fix them before you deliver)")),"") -> This sheet doesn't apply: you don't sell to other businesses
A42: What else you need if you sell wholesale | B42: =IFERROR(IF(B6="No","None of this applies to you","Keep a record of each account (what, how much and when), send labels or allergen sheets with every product and ask your CPA about resale certificates"),"") -> None of this applies to you
A44: Only the first check decides FDA registration: if businesses take half or more of your food sales by value, you're no longer a retail food establishment and you check FDA food facility registration (21 CFR 1.227). The other two don't change your permit, but they're what accounts and inspectors expect: a cold chain at 41 °F or below and full labels with allergens. And don't read it as "I can wholesale anything while I stay under half": in New York the Article 20-C license already covers wholesale bakery operations, and in Florida ask FDACS whether your volume needs its Wholesale/Manufactured Food Establishment Permit.
A46: Validation lists (don't delete them: the dropdowns come from here)
A47: Yes or No
A48: Yes
...

Sheet Cottage Food Route
A1: Cottage Food Route: Baking Legally from Home
A2: AI Chef Pro · aichef.pro — How to Open a Pastry Shop
A3: The four example states cap cottage food by annual SALES in dollars, not by weight, and each lists what you may sell. This sheet runs three checks: a weekly volume ceiling for a home kitchen (our criterion), volume for your space (our criterion) and records that prove you're under your state's sales cap (the law). The one people miss is the last.
A5: YOUR NUMBERS
A6: USABLE square feet dedicated to production | B6: 129.16693 | C6: Truly usable: the work surface and storage you dedicate, not the whole kitchen if you also eat in it.
A7: Kilos of product you make a week | B7: 60 | C7: SEEDED ASSUMPTION. Weigh it for two weeks: it drives both volume checks on this sheet.
A8: Do you keep sales records that show you're under your state's cap? | B8: No | C8: Without them you can't show you're within the cap (California 2026: $88,878 Class A / $177,756 Class B; Texas $150,000; Florida $250,000, all sales count; New York's page lists none).
A9: Does your state allow TCS items (cream fillings, cheesecake) from home? | B9: No | C9: Of the four example states, only Texas does (since September 1, 2025, with DSHS registration). In California, New York and Florida, cottage food has to be food that doesn't need refrigeration.
A10: Your state | B10: Texas
A12: THE THREE CHECKS
A13: Weekly volume ceiling for a home kitchen (kg) | B13: 100 | C13: Our ceiling, not the law's: about 14 kg a day. The four example states cap SALES in dollars (see the sales-records question above), not weight. A home kitchen rarely gets here, so this light is usually green. Don't rely on that.
A14: Volume ceiling check | B14: =IFERROR(IF(B7<=B13,"Under the ceiling","OVER: above the weekly ceiling for a home kitchen"),"") -> Under the ceiling
A15: House criterion: kg per usable sq ft a week | B15: 0.74322432 | C15: Not a legal figure. It's ours: use it to show your math, never quote it as the law.
A16: Your kg per usable sq ft a week | B16: =IFERROR(IF(B6=0,"",B7/B6),"") -> 0.4645152
A17: Volume-for-space check | B17: =IFERROR(IF(B16="","",IF(B16<=B15,"In proportion","Check it: a lot of volume for that space")),"") -> In proportion
A18: Can you prove you're under the sales cap? | B18: =IFERROR(IF(B8="Yes","Yes","NO: without sales records you can't show you're under your state's cap, whatever your volume"),"") -> NO: without sales records you can't show you're under your state's cap, whatever your volume
A20: WHAT YOU CAN SELL FROM HOME: FOUR STATES AND THE REST
A21: State and what you can sell | C21: What's out
A22: California (CFO): only foods on the Approved Cottage Food List (non-potentially hazardous foods) | C22: Anything off the list: cream fillings, custards, cheesecake. Class A sells direct only; Class B also through shops and restaurants.
A23: Texas (CFPO): any food not excluded; cream cakes and cheesecake (TCS) with DSHS registration since Sept. 1, 2025 | C23: Meat and poultry, fish and shellfish, ice, ice cream and frozen custard or gelato, low-acid canned foods, CBD or THC products, raw milk.
A24: New York (home processor): a closed list: breads, muffins, cookies, brownies, scones, double-crust fruit pies, simple cakes | C24: Cheesecake, cream-filled pastries, cream and meringue pies, custard, single-crust pies, homemade buttercream or cream cheese frosting.
A25: Florida (§500.80): cottage food products that don't need time and temperature control (non-TCS) | C25: Foods that need refrigeration (TCS); check the FDACS guidance item by item.
A26: Other states: cottage food is legal in all 50 states, each with its own list | C26: Nothing by default: look up your state's cottage food page before you bake to sell.
A27: That's why you can't say "cream cakes from home are illegal in the US". The right answer is: in most states only foods that don't need refrigeration qualify, but Texas has allowed TCS items such as cream cakes and cheesecake since September 1, 2025, if you register with DSHS and deliver them at 41 °F or below. Check your state's page.
A29: WHERE YOU CAN SELL: THREE CHANNEL RULES
A30: Channel | B30: What it covers | C30: The four states
A31: Wholesale | B31: Selling to cafés, shops and restaurants | C31: Florida: no. Texas: non-TCS only, to a registered cottage food vendor. California: Class B only. New York: yes, within New York.
A32: Shipping | B32: Online orders sent by mail or courier | C32: California and Florida: yes. Texas: only if you, an employee or a household member delivers. New York: within the state only.
A33: Out of state | B33: Selling or shipping across state lines | C33: New York: not allowed. Elsewhere, check your state's page before you ship.
A35: REQUIRED LABEL
A36: Statement your label must carry | B36: Texas (the case's state) | C36: Word for word: "THIS PRODUCT WAS PRODUCED IN A PRIVATE RESIDENCE THAT IS NOT SUBJECT TO GOVERNMENTAL LICENSING OR INSPECTION." Plus allergens; TCS items also need the production date and safe-handling instructions. New York: "Made in a Home Kitchen". Florida: "Made in a cottage food operation that is not subject to Florida's food safety regulations."
A38: IF YOUR STATE IS TEXAS
A39: Texas Senate Bill 541 widened cottage food (in force since September 1, 2025): any food except an excluded list (meat, poultry, seafood, ice and ice cream, low-acid canned foods, CBD or THC, raw milk), up to $150,000 a year. TCS items such as cream cakes and cheesecake are allowed if you register with DSHS, label them with the production date and safe-handling instructions, and deliver them at 41 °F or below. Local authorities can't require a permit, license or fee.
A40: What Texas doesn't open: wholesale of TCS items, and online sales you don't deliver yourself. It's proof that your state's rules can change: check its page every year.
A42: THE VERDICT
A43: The three checks together | B43: =IFERROR(IF(B7>B13,"NO: over the weekly ceiling for a home kitchen",IF(B8<>"Yes","NOT YET: you need sales records",IF(AND(ISNUMBER(B16),B16>B15),"Careful: under the ceiling, but a lot of volume for that space","Within the three checks: now confirm every item is on your state's allowed list"))),"") -> NOT YET: you need sales records
A45: Passing the three checks isn't enough on its own: every item has to be on your state's allowed list, sold through the channels it allows and labeled the way it says. This sheet helps you decide whether starting from home works for you; it doesn't replace your state's cottage food page or your local health department.
A47: Validation lists (don't delete them: the dropdowns come from here)
A48: Yes or No
A49: Yes
...

Sheet Training Log
A1: Training Log: Food Safety Certificates and Cards
A2: AI Chef Pro · aichef.pro — How to Open a Pastry Shop
A3: Who needs what: under the 2022 Food Code, the person in charge must be a certified food protection manager (CFPM), and food handler card rules depend on your state. Log every certificate and card here: making sure staff are trained is the person in charge's job (Food Code 2-103.11).
A5: Person | B5: Area | C5: Certificate or course | D5: Hours | E5: Training date | F5: Renew by | G5: Days left | H5: Notes
A6: P1 · Head Pastry Chef | B6: PRODUCTION KITCHEN | C6: Certified food protection manager (CFPM) exam | D6: 6 | E6: 46275 | F6: =IFERROR(IF(E6="","",E6+$B$13),"") -> 47005 | G6: =IFERROR(IF(F6="","",F6-$B$14),"") -> 730 | H6: Course content and hours are ASSUMPTIONS: the accredited provider sets them. What you do need is each certificate or card on file, under each person's full name.
A7: P2 · Pastry Cook | B7: PRODUCTION KITCHEN | C7: Food handler card + allergen awareness | D7: 6 | E7: 46275 | F7: =IFERROR(IF(E7="","",E7+$B$13),"") -> 47005 | G7: =IFERROR(IF(F7="","",F7-$B$14),"") -> 730
A8: P3 · Bakery Assistant | B8: PRODUCTION KITCHEN | C8: Food handler card | D8: 6 | E8: 46275 | F8: =IFERROR(IF(E8="","",E8+$B$13),"") -> 47005 | G8: =IFERROR(IF(F8="","",F8-$B$14),"") -> 730
A9: P4 · Counter Associate A | B9: FRONT COUNTER | C9: Food handler card + allergens at the counter | D9: 6 | E9: 46275 | F9: =IFERROR(IF(E9="","",E9+$B$13),"") -> 47005 | G9: =IFERROR(IF(F9="","",F9-$B$14),"") -> 730
A10: P5 · Counter Associate B | B10: FRONT COUNTER | C10: Food handler card + allergens at the counter | D10: 6 | E10: 46275 | F10: =IFERROR(IF(E10="","",E10+$B$13),"") -> 47005 | G10: =IFERROR(IF(F10="","",F10-$B$14),"") -> 730
A12: HOUSE SETTINGS
A13: House renewal interval (days) | B13: 730 | H13: Not a legal deadline: it's your own policy, and writing it down is what makes it defensible.
A14: Check date | B14: 46275 | H14: Change it to today's date every time you review the sheet.
A16: SUMMARY
A17: People with training on file | B17: =IFERROR(COUNTIF(E6:E10,">0"),"") -> 5
A18: Overdue | B18: =IFERROR(COUNTIF(G6:G10,"<0"),"") -> 0
A19: Due for renewal in under 90 days | B19: =IFERROR(COUNTIF(G6:G10,"<90")-B18,"") -> 0 | H19: The 90 days are our own alert, so you can book the course without stopping production.
A21: Food Code 2022: the person in charge must be a certified food protection manager (2-102.12), and employees must be trained in food safety, allergen awareness included, for their duties (2-103.11(O)). Cards are state rules: California requires a food handler card within 30 days of hire, valid 3 years; Texas requires a DSHS-accredited food handler course and a certified food manager; New York has no state card, but New York City requires a supervisor with a Food Protection Certificate; in Florida, check FDACS (retail) or DBPR (food service). Keep each certificate and card on file: that's what you show at inspection.

Sheet Timeline and Critical Path
A1: Opening Timeline and Critical Path
A2: AI Chef Pro · aichef.pro — How to Open a Pastry Shop
A3: Twelve milestones with their durations and dependencies. The sheet works out when each one starts and ends, how much slack it has, which ones are on the critical path and which month you end up opening. Everything is in MONTHS with index arithmetic: not a single date function.
A5: Month the project starts (1-12) | C5: 1 | O5: The calendar month you take the first step. Your estimated opening date comes from here, so try two or three: moving the start two months can take you out of a peak or put you right in one.
A6: Sentinel value for the dependency matrix (months) | C6: 999 | O6: A calculation trick, not data: in the dependency matrix, cells that don't apply hold this number instead of staying blank, so MIN can work with numbers only. The matrix format hides it. Don't change it unless your project runs longer than 999 months.
A8: ID | B8: Milestone | C8: Duration (months) | D8: Depends on (1) | E8: Depends on (2) | F8: Depends on (3) | G8: Starts (project month) | H8: Ends (project month) | I8: Slack (months) | J8: Critical path? | K8: Calendar month it ends | O8: Notes
A9: M1 | B9: Site search and screening | C9: 2 | D9: - | E9: - | F9: - | G9: =IFERROR(MAX(IFERROR(INDEX($H$8:H8,MATCH(D9,$A$8:A8,0)),0),IFERROR(INDEX($H$8:H8,MATCH(E9,$A$8:A8,0)),0),IFERROR(INDEX($H$8:H8,MATCH(F9,$A$8:A8,0)),0)),"") -> 0 | H9: =IFERROR(G9+C9,"") -> 2 | I9: =IFERROR(MIN(MIN(C24:C35),MAX($H$9:$H$20))-H9,"") -> 0 | J9: =IFERROR(IF(ROUND(I9,3)<=0,"Yes","No"),"") -> Yes | K9: =IFERROR(INDEX('Timeline and Critical Path'!$A$73:$A$84,ROUNDDOWN(MOD($C$5-1+H9,12),0)+1),"") -> March | O9: Searching is the only thing you can speed up on your own, and it's where the hood and the electrical service get decided: use the site visit checklist in the "kitchen-capacity-and-site" workbook BEFORE you fall for a space.
A10: M2 | B10: Lease signing and security deposit | C10: 0.5 | D10: M1 | E10: - | F10: - | G10: =IFERROR(MAX(IFERROR(INDEX($H$8:H9,MATCH(D10,$A$8:A9,0)),0),IFERROR(INDEX($H$8:H9,MATCH(E10,$A$8:A9,0)),0),IFERROR(INDEX($H$8:H9,MATCH(F10,$A$8:A9,0)),0)),"") -> 2 | H10: =IFERROR(G10+C10,"") -> 2.5 | I10: =IFERROR(MIN(MIN(D24:D35),MAX($H$9:$H$20))-H10,"") -> 0 | J10: =IFERROR(IF(ROUND(I10,3)<=0,"Yes","No"),"") -> Yes | K10: =IFERROR(INDEX('Timeline and Critical Path'!$A$73:$A$84,ROUNDDOWN(MOD($C$5-1+H10,12),0)+1),"") -> March
A11: M3 | B11: Stamped plans and specifications | C11: 1 | D11: M2 | E11: - | F11: - | G11: =IFERROR(MAX(IFERROR(INDEX($H$8:H10,MATCH(D11,$A$8:A10,0)),0),IFERROR(INDEX($H$8:H10,MATCH(E11,$A$8:A10,0)),0),IFERROR(INDEX($H$8:H10,MATCH(F11,$A$8:A10,0)),0)),"") -> 2.5 | H11: =IFERROR(G11+C11,"") -> 3.5 | I11: =IFERROR(MIN(MIN(E24:E35),MAX($H$9:$H$20))-H11,"") -> 0 | J11: =IFERROR(IF(ROUND(I11,3)<=0,"Yes","No"),"") -> Yes | K11: =IFERROR(INDEX('Timeline and Critical Path'!$A$73:$A$84,ROUNDDOWN(MOD($C$5-1+H11,12),0)+1),"") -> April
A12: M4 | B12: Plan review and building permit | C12: 1.5 | D12: M3 | E12: - | F12: - | G12: =IFERROR(MAX(IFERROR(INDEX($H$8:H11,MATCH(D12,$A$8:A11,0)),0),IFERROR(INDEX($H$8:H11,MATCH(E12,$A$8:A11,0)),0),IFERROR(INDEX($H$8:H11,MATCH(F12,$A$8:A11,0)),0)),"") -> 3.5 | H12: =IFERROR(G12+C12,"") -> 5 | I12: =IFERROR(MIN(MIN(F24:F35),MAX($H$9:$H$20))-H12,"") -> 0 | J12: =IFERROR(IF(ROUND(I12,3)<=0,"Yes","No"),"") -> Yes | K12: =IFERROR(INDEX('Timeline and Critical Path'!$A$73:$A$84,ROUNDDOWN(MOD($C$5-1+H12,12),0)+1),"") -> June | O12: Depends on your county and city (California gives the health department 20 working days for plan review). It's the milestone with the most variance in the whole chart, which is why the move is to start ordering equipment in parallel.
A13: M5 | B13: Build-out and installations | C13: 2 | D13: M4 | E13: - | F13: - | G13: =IFERROR(MAX(IFERROR(INDEX($H$8:H12,MATCH(D13,$A$8:A12,0)),0),IFERROR(INDEX($H$8:H12,MATCH(E13,$A$8:A12,0)),0),IFERROR(INDEX($H$8:H12,MATCH(F13,$A$8:A12,0)),0)),"") -> 5 | H13: =IFERROR(G13+C13,"") -> 7 | I13: =IFERROR(MIN(MIN(G24:G35),MAX($H$9:$H$20))-H13,"") -> 0 | J13: =IFERROR(IF(ROUND(I13,3)<=0,"Yes","No"),"") -> Yes | K13: =IFERROR(INDEX('Timeline and Critical Path'!$A$73:$A$84,ROUNDDOWN(MOD($C$5-1+H13,12),0)+1),"") -> August
A14: M6 | B14: Order and delivery of equipment | C14: 2.5 | D14: M3 | E14: - | F14: - | G14: =IFERROR(MAX(IFERROR(INDEX($H$8:H13,MATCH(D14,$A$8:A13,0)),0),IFERROR(INDEX($H$8:H13,MATCH(E14,$A$8:A13,0)),0),IFERROR(INDEX($H$8:H13,MATCH(F14,$A$8:A13,0)),0)),"") -> 3.5 | H14: =IFERROR(G14+C14,"") -> 6 | I14: =IFERROR(MIN(MIN(H24:H35),MAX($H$9:$H$20))-H14,"") -> 1 | J14: =IFERROR(IF(ROUND(I14,3)<=0,"Yes","No"),"") -> No | K14: =IFERROR(INDEX('Timeline and Critical Path'!$A$73:$A$84,ROUNDDOWN(MOD($C$5-1+H14,12),0)+1),"") -> July | O14: Runs in PARALLEL with the build-out because it depends on the plans, not the permit. That's what gives it slack: order late and the slack disappears, and equipment starts setting your opening date.
A15: M7 | B15: Equipment installation and start-up | C15: 0.5 | D15: M5 | E15: M6 | F15: - | G15: =IFERROR(MAX(IFERROR(INDEX($H$8:H14,MATCH(D15,$A$8:A14,0)),0),IFERROR(INDEX($H$8:H14,MATCH(E15,$A$8:A14,0)),0),IFERROR(INDEX($H$8:H14,MATCH(F15,$A$8:A14,0)),0)),"") -> 7 | H15: =IFERROR(G15+C15,"") -> 7.5 | I15: =IFERROR(MIN(MIN(I24:I35),MAX($H$9:$H$20))-H15,"") -> 0 | J15: =IFERROR(IF(ROUND(I15,3)<=0,"Yes","No"),"") -> Yes | K15: =IFERROR(INDEX('Timeline and Critical Path'!$A$73:$A$84,ROUNDDOWN(MOD($C$5-1+H15,12),0)+1),"") -> August
A16: M8 | B16: Pre-opening inspection and food permit | C16: 0.5 | D16: M7 | E16: - | F16: - | G16: =IFERROR(MAX(IFERROR(INDEX($H$8:H15,MATCH(D16,$A$8:A15,0)),0),IFERROR(INDEX($H$8:H15,MATCH(E16,$A$8:A15,0)),0),IFERROR(INDEX($H$8:H15,MATCH(F16,$A$8:A15,0)),0)),"") -> 7.5 | H16: =IFERROR(G16+C16,"") -> 8 | I16: =IFERROR(MIN(MIN(J24:J35),MAX($H$9:$H$20))-H16,"") -> 0 | J16: =IFERROR(IF(ROUND(I16,3)<=0,"Yes","No"),"") -> Yes | K16: =IFERROR(INDEX('Timeline and Critical Path'!$A$73:$A$84,ROUNDDOWN(MOD($C$5-1+H16,12),0)+1),"") -> September
A17: M9 | B17: CFPM, food handler cards and food safety plan | C17: 0.5 | D17: M7 | E17: - | F17: - | G17: =IFERROR(MAX(IFERROR(INDEX($H$8:H16,MATCH(D17,$A$8:A16,0)),0),IFERROR(INDEX($H$8:H16,MATCH(E17,$A$8:A16,0)),0),IFERROR(INDEX($H$8:H16,MATCH(F17,$A$8:A16,0)),0)),"") -> 7.5 | H17: =IFERROR(G17+C17,"") -> 8 | I17: =IFERROR(MIN(MIN(K24:K35),MAX($H$9:$H$20))-H17,"") -> 0 | J17: =IFERROR(IF(ROUND(I17,3)<=0,"Yes","No"),"") -> Yes | K17: =IFERROR(INDEX('Timeline and Critical Path'!$A$73:$A$84,ROUNDDOWN(MOD($C$5-1+H17,12),0)+1),"") -> September
A18: M10 | B18: Hiring and payroll setup | C18: 0.5 | D18: M7 | E18: - | F18: - | G18: =IFERROR(MAX(IFERROR(INDEX($H$8:H17,MATCH(D18,$A$8:A17,0)),0),IFERROR(INDEX($H$8:H17,MATCH(E18,$A$8:A17,0)),0),IFERROR(INDEX($H$8:H17,MATCH(F18,$A$8:A17,0)),0)),"") -> 7.5 | H18: =IFERROR(G18+C18,"") -> 8 | I18: =IFERROR(MIN(MIN(L24:L35),MAX($H$9:$H$20))-H18,"") -> 0 | J18: =IFERROR(IF(ROUND(I18,3)<=0,"Yes","No"),"") -> Yes | K18: =IFERROR(INDEX('Timeline and Critical Path'!$A$73:$A$84,ROUNDDOWN(MOD($C$5-1+H18,12),0)+1),"") -> September
A19: M11 | B19: Production trials and final opening menu | C19: 0.5 | D19: M8 | E19: M9 | F19: M10 | G19: =IFERROR(MAX(IFERROR(INDEX($H$8:H18,MATCH(D19,$A$8:A18,0)),0),IFERROR(INDEX($H$8:H18,MATCH(E19,$A$8:A18,0)),0),IFERROR(INDEX($H$8:H18,MATCH(F19,$A$8:A18,0)),0)),"") -> 8 | H19: =IFERROR(G19+C19,"") -> 8.5 | I19: =IFERROR(MIN(MIN(M24:M35),MAX($H$9:$H$20))-H19,"") -> 0 | J19: =IFERROR(IF(ROUND(I19,3)<=0,"Yes","No"),"") -> Yes | K19: =IFERROR(INDEX('Timeline and Critical Path'!$A$73:$A$84,ROUNDDOWN(MOD($C$5-1+H19,12),0)+1),"") -> September
A20: M12 | B20: Opening | C20: 0 | D20: M11 | E20: - | F20: - | G20: =IFERROR(MAX(IFERROR(INDEX($H$8:H19,MATCH(D20,$A$8:A19,0)),0),IFERROR(INDEX($H$8:H19,MATCH(E20,$A$8:A19,0)),0),IFERROR(INDEX($H$8:H19,MATCH(F20,$A$8:A19,0)),0)),"") -> 8.5 | H20: =IFERROR(G20+C20,"") -> 8.5 | I20: =IFERROR(MIN(MIN(N24:N35),MAX($H$9:$H$20))-H20,"") -> 0 | J20: =IFERROR(IF(ROUND(I20,3)<=0,"Yes","No"),"") -> Yes | K20: =IFERROR(INDEX('Timeline and Critical Path'!$A$73:$A$84,ROUNDDOWN(MOD($C$5-1+H20,12),0)+1),"") -> September | O20: Zero duration: opening is a moment, not a task. What comes right before it is the production trials, and those don't get cut.
A22: DEPENDENCY MATRIX: WHICH MILESTONE BLOCKS WHICH
A23: Successor | B23: starts in month... | C23: M1 | D23: M2 | E23: M3 | F23: M4 | G23: M5 | H23: M6 | I23: M7 | J23: M8 | K23: M9 | L23: M10 | M23: M11 | N23: M12 | O23: Notes
A24: M1 | B24: =IFERROR(G9,"") -> 0 | C24: =IFERROR(IF(OR($D$9=$A$9,$E$9=$A$9,$F$9=$A$9),$G$9,$C$6),"") -> 999 | D24: =IFERROR(IF(OR($D$9=$A$10,$E$9=$A$10,$F$9=$A$10),$G$9,$C$6),"") -> 999 | E24: =IFERROR(IF(OR($D$9=$A$11,$E$9=$A$11,$F$9=$A$11),$G$9,$C$6),"") -> 999 | F24: =IFERROR(IF(OR($D$9=$A$12,$E$9=$A$12,$F$9=$A$12),$G$9,$C$6),"") -> 999 | G24: =IFERROR(IF(OR($D$9=$A$13,$E$9=$A$13,$F$9=$A$13),$G$9,$C$6),"") -> 999 | H24: =IFERROR(IF(OR($D$9=$A$14,$E$9=$A$14,$F$9=$A$14),$G$9,$C$6),"") -> 999 | I24: =IFERROR(IF(OR($D$9=$A$15,$E$9=$A$15,$F$9=$A$15),$G$9,$C$6),"") -> 999 | J24: =IFERROR(IF(OR($D$9=$A$16,$E$9=$A$16,$F$9=$A$16),$G$9,$C$6),"") -> 999 | K24: =IFERROR(IF(OR($D$9=$A$17,$E$9=$A$17,$F$9=$A$17),$G$9,$C$6),"") -> 999 | L24: =IFERROR(IF(OR($D$9=$A$18,$E$9=$A$18,$F$9=$A$18),$G$9,$C$6),"") -> 999 | M24: =IFERROR(IF(OR($D$9=$A$19,$E$9=$A$19,$F$9=$A$19),$G$9,$C$6),"") -> 999 | N24: =IFERROR(IF(OR($D$9=$A$20,$E$9=$A$20,$F$9=$A$20),$G$9,$C$6),"") -> 999 | O24: Read it by COLUMNS: the M5 column shows the month in which each milestone that depends on M5 starts. M5's slack is the gap between when it ends and the earliest of those months. The cells that look empty aren't: they hold the sentinel, and the format hides it.
A25: M2 | B25: =IFERROR(G10,"") -> 2 | C25: =IFERROR(IF(OR($D$10=$A$9,$E$10=$A$9,$F$10=$A$9),$G$10,$C$6),"") -> 2 | D25: =IFERROR(IF(OR($D$10=$A$10,$E$10=$A$10,$F$10=$A$10),$G$10,$C$6),"") -> 999 | E25: =IFERROR(IF(OR($D$10=$A$11,$E$10=$A$11,$F$10=$A$11),$G$10,$C$6),"") -> 999 | F25: =IFERROR(IF(OR($D$10=$A$12,$E$10=$A$12,$F$10=$A$12),$G$10,$C$6),"") -> 999 | G25: =IFERROR(IF(OR($D$10=$A$13,$E$10=$A$13,$F$10=$A$13),$G$10,$C$6),"") -> 999 | H25: =IFERROR(IF(OR($D$10=$A$14,$E$10=$A$14,$F$10=$A$14),$G$10,$C$6),"") -> 999 | I25: =IFERROR(IF(OR($D$10=$A$15,$E$10=$A$15,$F$10=$A$15),$G$10,$C$6),"") -> 999 | J25: =IFERROR(IF(OR($D$10=$A$16,$E$10=$A$16,$F$10=$A$16),$G$10,$C$6),"") -> 999 | K25: =IFERROR(IF(OR($D$10=$A$17,$E$10=$A$17,$F$10=$A$17),$G$10,$C$6),"") -> 999 | L25: =IFERROR(IF(OR($D$10=$A$18,$E$10=$A$18,$F$10=$A$18),$G$10,$C$6),"") -> 999 | M25: =IFERROR(IF(OR($D$10=$A$19,$E$10=$A$19,$F$10=$A$19),$G$10,$C$6),"") -> 999 | N25: =IFERROR(IF(OR($D$10=$A$20,$E$10=$A$20,$F$10=$A$20),$G$10,$C$6),"") -> 999
A26: M3 | B26: =IFERROR(G11,"") -> 2.5 | C26: =IFERROR(IF(OR($D$11=$A$9,$E$11=$A$9,$F$11=$A$9),$G$11,$C$6),"") -> 999 | D26: =IFERROR(IF(OR($D$11=$A$10,$E$11=$A$10,$F$11=$A$10),$G$11,$C$6),"") -> 2.5 | E26: =IFERROR(IF(OR($D$11=$A$11,$E$11=$A$11,$F$11=$A$11),$G$11,$C$6),"") -> 999 | F26: =IFERROR(IF(OR($D$11=$A$12,$E$11=$A$12,$F$11=$A$12),$G$11,$C$6),"") -> 999 | G26: =IFERROR(IF(OR($D$11=$A$13,$E$11=$A$13,$F$11=$A$13),$G$11,$C$6),"") -> 999 | H26: =IFERROR(IF(OR($D$11=$A$14,$E$11=$A$14,$F$11=$A$14),$G$11,$C$6),"") -> 999 | I26: =IFERROR(IF(OR($D$11=$A$15,$E$11=$A$15,$F$11=$A$15),$G$11,$C$6),"") -> 999 | J26: =IFERROR(IF(OR($D$11=$A$16,$E$11=$A$16,$F$11=$A$16),$G$11,$C$6),"") -> 999 | K26: =IFERROR(IF(OR($D$11=$A$17,$E$11=$A$17,$F$11=$A$17),$G$11,$C$6),"") -> 999 | L26: =IFERROR(IF(OR($D$11=$A$18,$E$11=$A$18,$F$11=$A$18),$G$11,$C$6),"") -> 999 | M26: =IFERROR(IF(OR($D$11=$A$19,$E$11=$A$19,$F$11=$A$19),$G$11,$C$6),"") -> 999 | N26: =IFERROR(IF(OR($D$11=$A$20,$E$11=$A$20,$F$11=$A$20),$G$11,$C$6),"") -> 999
A27: M4 | B27: =IFERROR(G12,"") -> 3.5 | C27: =IFERROR(IF(OR($D$12=$A$9,$E$12=$A$9,$F$12=$A$9),$G$12,$C$6),"") -> 999 | D27: =IFERROR(IF(OR($D$12=$A$10,$E$12=$A$10,$F$12=$A$10),$G$12,$C$6),"") -> 999 | E27: =IFERROR(IF(OR($D$12=$A$11,$E$12=$A$11,$F$12=$A$11),$G$12,$C$6),"") -> 3.5 | F27: =IFERROR(IF(OR($D$12=$A$12,$E$12=$A$12,$F$12=$A$12),$G$12,$C$6),"") -> 999 | G27: =IFERROR(IF(OR($D$12=$A$13,$E$12=$A$13,$F$12=$A$13),$G$12,$C$6),"") -> 999 | H27: =IFERROR(IF(OR($D$12=$A$14,$E$12=$A$14,$F$12=$A$14),$G$12,$C$6),"") -> 999 | I27: =IFERROR(IF(OR($D$12=$A$15,$E$12=$A$15,$F$12=$A$15),$G$12,$C$6),"") -> 999 | J27: =IFERROR(IF(OR($D$12=$A$16,$E$12=$A$16,$F$12=$A$16),$G$12,$C$6),"") -> 999 | K27: =IFERROR(IF(OR($D$12=$A$17,$E$12=$A$17,$F$12=$A$17),$G$12,$C$6),"") -> 999 | L27: =IFERROR(IF(OR($D$12=$A$18,$E$12=$A$18,$F$12=$A$18),$G$12,$C$6),"") -> 999 | M27: =IFERROR(IF(OR($D$12=$A$19,$E$12=$A$19,$F$12=$A$19),$G$12,$C$6),"") -> 999 | N27: =IFERROR(IF(OR($D$12=$A$20,$E$12=$A$20,$F$12=$A$20),$G$12,$C$6),"") -> 999
A28: M5 | B28: =IFERROR(G13,"") -> 5 | C28: =IFERROR(IF(OR($D$13=$A$9,$E$13=$A$9,$F$13=$A$9),$G$13,$C$6),"") -> 999 | D28: =IFERROR(IF(OR($D$13=$A$10,$E$13=$A$10,$F$13=$A$10),$G$13,$C$6),"") -> 999 | E28: =IFERROR(IF(OR($D$13=$A$11,$E$13=$A$11,$F$13=$A$11),$G$13,$C$6),"") -> 999 | F28: =IFERROR(IF(OR($D$13=$A$12,$E$13=$A$12,$F$13=$A$12),$G$13,$C$6),"") -> 5 | G28: =IFERROR(IF(OR($D$13=$A$13,$E$13=$A$13,$F$13=$A$13),$G$13,$C$6),"") -> 999 | H28: =IFERROR(IF(OR($D$13=$A$14,$E$13=$A$14,$F$13=$A$14),$G$13,$C$6),"") -> 999 | I28: =IFERROR(IF(OR($D$13=$A$15,$E$13=$A$15,$F$13=$A$15),$G$13,$C$6),"") -> 999 | J28: =IFERROR(IF(OR($D$13=$A$16,$E$13=$A$16,$F$13=$A$16),$G$13,$C$6),"") -> 999 | K28: =IFERROR(IF(OR($D$13=$A$17,$E$13=$A$17,$F$13=$A$17),$G$13,$C$6),"") -> 999 | L28: =IFERROR(IF(OR($D$13=$A$18,$E$13=$A$18,$F$13=$A$18),$G$13,$C$6),"") -> 999 | M28: =IFERROR(IF(OR($D$13=$A$19,$E$13=$A$19,$F$13=$A$19),$G$13,$C$6),"") -> 999 | N28: =IFERROR(IF(OR($D$13=$A$20,$E$13=$A$20,$F$13=$A$20),$G$13,$C$6),"") -> 999
A29: M6 | B29: =IFERROR(G14,"") -> 3.5 | C29: =IFERROR(IF(OR($D$14=$A$9,$E$14=$A$9,$F$14=$A$9),$G$14,$C$6),"") -> 999 | D29: =IFERROR(IF(OR($D$14=$A$10,$E$14=$A$10,$F$14=$A$10),$G$14,$C$6),"") -> 999 | E29: =IFERROR(IF(OR($D$14=$A$11,$E$14=$A$11,$F$14=$A$11),$G$14,$C$6),"") -> 3.5 | F29: =IFERROR(IF(OR($D$14=$A$12,$E$14=$A$12,$F$14=$A$12),$G$14,$C$6),"") -> 999 | G29: =IFERROR(IF(OR($D$14=$A$13,$E$14=$A$13,$F$14=$A$13),$G$14,$C$6),"") -> 999 | H29: =IFERROR(IF(OR($D$14=$A$14,$E$14=$A$14,$F$14=$A$14),$G$14,$C$6),"") -> 999 | I29: =IFERROR(IF(OR($D$14=$A$15,$E$14=$A$15,$F$14=$A$15),$G$14,$C$6),"") -> 999 | J29: =IFERROR(IF(OR($D$14=$A$16,$E$14=$A$16,$F$14=$A$16),$G$14,$C$6),"") -> 999 | K29: =IFERROR(IF(OR($D$14=$A$17,$E$14=$A$17,$F$14=$A$17),$G$14,$C$6),"") -> 999 | L29: =IFERROR(IF(OR($D$14=$A$18,$E$14=$A$18,$F$14=$A$18),$G$14,$C$6),"") -> 999 | M29: =IFERROR(IF(OR($D$14=$A$19,$E$14=$A$19,$F$14=$A$19),$G$14,$C$6),"") -> 999 | N29: =IFERROR(IF(OR($D$14=$A$20,$E$14=$A$20,$F$14=$A$20),$G$14,$C$6),"") -> 999
A30: M7 | B30: =IFERROR(G15,"") -> 7 | C30: =IFERROR(IF(OR($D$15=$A$9,$E$15=$A$9,$F$15=$A$9),$G$15,$C$6),"") -> 999 | D30: =IFERROR(IF(OR($D$15=$A$10,$E$15=$A$10,$F$15=$A$10),$G$15,$C$6),"") -> 999 | E30: =IFERROR(IF(OR($D$15=$A$11,$E$15=$A$11,$F$15=$A$11),$G$15,$C$6),"") -> 999 | F30: =IFERROR(IF(OR($D$15=$A$12,$E$15=$A$12,$F$15=$A$12),$G$15,$C$6),"") -> 999 | G30: =IFERROR(IF(OR($D$15=$A$13,$E$15=$A$13,$F$15=$A$13),$G$15,$C$6),"") -> 7 | H30: =IFERROR(IF(OR($D$15=$A$14,$E$15=$A$14,$F$15=$A$14),$G$15,$C$6),"") -> 7 | I30: =IFERROR(IF(OR($D$15=$A$15,$E$15=$A$15,$F$15=$A$15),$G$15,$C$6),"") -> 999 | J30: =IFERROR(IF(OR($D$15=$A$16,$E$15=$A$16,$F$15=$A$16),$G$15,$C$6),"") -> 999 | K30: =IFERROR(IF(OR($D$15=$A$17,$E$15=$A$17,$F$15=$A$17),$G$15,$C$6),"") -> 999 | L30: =IFERROR(IF(OR($D$15=$A$18,$E$15=$A$18,$F$15=$A$18),$G$15,$C$6),"") -> 999 | M30: =IFERROR(IF(OR($D$15=$A$19,$E$15=$A$19,$F$15=$A$19),$G$15,$C$6),"") -> 999 | N30: =IFERROR(IF(OR($D$15=$A$20,$E$15=$A$20,$F$15=$A$20),$G$15,$C$6),"") -> 999
A31: M8 | B31: =IFERROR(G16,"") -> 7.5 | C31: =IFERROR(IF(OR($D$16=$A$9,$E$16=$A$9,$F$16=$A$9),$G$16,$C$6),"") -> 999 | D31: =IFERROR(IF(OR($D$16=$A$10,$E$16=$A$10,$F$16=$A$10),$G$16,$C$6),"") -> 999 | E31: =IFERROR(IF(OR($D$16=$A$11,$E$16=$A$11,$F$16=$A$11),$G$16,$C$6),"") -> 999 | F31: =IFERROR(IF(OR($D$16=$A$12,$E$16=$A$12,$F$16=$A$12),$G$16,$C$6),"") -> 999 | G31: =IFERROR(IF(OR($D$16=$A$13,$E$16=$A$13,$F$16=$A$13),$G$16,$C$6),"") -> 999 | H31: =IFERROR(IF(OR($D$16=$A$14,$E$16=$A$14,$F$16=$A$14),$G$16,$C$6),"") -> 999 | I31: =IFERROR(IF(OR($D$16=$A$15,$E$16=$A$15,$F$16=$A$15),$G$16,$C$6),"") -> 7.5 | J31: =IFERROR(IF(OR($D$16=$A$16,$E$16=$A$16,$F$16=$A$16),$G$16,$C$6),"") -> 999 | K31: =IFERROR(IF(OR($D$16=$A$17,$E$16=$A$17,$F$16=$A$17),$G$16,$C$6),"") -> 999 | L31: =IFERROR(IF(OR($D$16=$A$18,$E$16=$A$18,$F$16=$A$18),$G$16,$C$6),"") -> 999 | M31: =IFERROR(IF(OR($D$16=$A$19,$E$16=$A$19,$F$16=$A$19),$G$16,$C$6),"") -> 999 | N31: =IFERROR(IF(OR($D$16=$A$20,$E$16=$A$20,$F$16=$A$20),$G$16,$C$6),"") -> 999
A32: M9 | B32: =IFERROR(G17,"") -> 7.5 | C32: =IFERROR(IF(OR($D$17=$A$9,$E$17=$A$9,$F$17=$A$9),$G$17,$C$6),"") -> 999 | D32: =IFERROR(IF(OR($D$17=$A$10,$E$17=$A$10,$F$17=$A$10),$G$17,$C$6),"") -> 999 | E32: =IFERROR(IF(OR($D$17=$A$11,$E$17=$A$11,$F$17=$A$11),$G$17,$C$6),"") -> 999 | F32: =IFERROR(IF(OR($D$17=$A$12,$E$17=$A$12,$F$17=$A$12),$G$17,$C$6),"") -> 999 | G32: =IFERROR(IF(OR($D$17=$A$13,$E$17=$A$13,$F$17=$A$13),$G$17,$C$6),"") -> 999 | H32: =IFERROR(IF(OR($D$17=$A$14,$E$17=$A$14,$F$17=$A$14),$G$17,$C$6),"") -> 999 | I32: =IFERROR(IF(OR($D$17=$A$15,$E$17=$A$15,$F$17=$A$15),$G$17,$C$6),"") -> 7.5 | J32: =IFERROR(IF(OR($D$17=$A$16,$E$17=$A$16,$F$17=$A$16),$G$17,$C$6),"") -> 999 | K32: =IFERROR(IF(OR($D$17=$A$17,$E$17=$A$17,$F$17=$A$17),$G$17,$C$6),"") -> 999 | L32: =IFERROR(IF(OR($D$17=$A$18,$E$17=$A$18,$F$17=$A$18),$G$17,$C$6),"") -> 999 | M32: =IFERROR(IF(OR($D$17=$A$19,$E$17=$A$19,$F$17=$A$19),$G$17,$C$6),"") -> 999 | N32: =IFERROR(IF(OR($D$17=$A$20,$E$17=$A$20,$F$17=$A$20),$G$17,$C$6),"") -> 999
A33: M10 | B33: =IFERROR(G18,"") -> 7.5 | C33: =IFERROR(IF(OR($D$18=$A$9,$E$18=$A$9,$F$18=$A$9),$G$18,$C$6),"") -> 999 | D33: =IFERROR(IF(OR($D$18=$A$10,$E$18=$A$10,$F$18=$A$10),$G$18,$C$6),"") -> 999 | E33: =IFERROR(IF(OR($D$18=$A$11,$E$18=$A$11,$F$18=$A$11),$G$18,$C$6),"") -> 999 | F33: =IFERROR(IF(OR($D$18=$A$12,$E$18=$A$12,$F$18=$A$12),$G$18,$C$6),"") -> 999 | G33: =IFERROR(IF(OR($D$18=$A$13,$E$18=$A$13,$F$18=$A$13),$G$18,$C$6),"") -> 999 | H33: =IFERROR(IF(OR($D$18=$A$14,$E$18=$A$14,$F$18=$A$14),$G$18,$C$6),"") -> 999 | I33: =IFERROR(IF(OR($D$18=$A$15,$E$18=$A$15,$F$18=$A$15),$G$18,$C$6),"") -> 7.5 | J33: =IFERROR(IF(OR($D$18=$A$16,$E$18=$A$16,$F$18=$A$16),$G$18,$C$6),"") -> 999 | K33: =IFERROR(IF(OR($D$18=$A$17,$E$18=$A$17,$F$18=$A$17),$G$18,$C$6),"") -> 999 | L33: =IFERROR(IF(OR($D$18=$A$18,$E$18=$A$18,$F$18=$A$18),$G$18,$C$6),"") -> 999 | M33: =IFERROR(IF(OR($D$18=$A$19,$E$18=$A$19,$F$18=$A$19),$G$18,$C$6),"") -> 999 | N33: =IFERROR(IF(OR($D$18=$A$20,$E$18=$A$20,$F$18=$A$20),$G$18,$C$6),"") -> 999
A34: M11 | B34: =IFERROR(G19,"") -> 8 | C34: =IFERROR(IF(OR($D$19=$A$9,$E$19=$A$9,$F$19=$A$9),$G$19,$C$6),"") -> 999 | D34: =IFERROR(IF(OR($D$19=$A$10,$E$19=$A$10,$F$19=$A$10),$G$19,$C$6),"") -> 999 | E34: =IFERROR(IF(OR($D$19=$A$11,$E$19=$A$11,$F$19=$A$11),$G$19,$C$6),"") -> 999 | F34: =IFERROR(IF(OR($D$19=$A$12,$E$19=$A$12,$F$19=$A$12),$G$19,$C$6),"") -> 999 | G34: =IFERROR(IF(OR($D$19=$A$13,$E$19=$A$13,$F$19=$A$13),$G$19,$C$6),"") -> 999 | H34: =IFERROR(IF(OR($D$19=$A$14,$E$19=$A$14,$F$19=$A$14),$G$19,$C$6),"") -> 999 | I34: =IFERROR(IF(OR($D$19=$A$15,$E$19=$A$15,$F$19=$A$15),$G$19,$C$6),"") -> 999 | J34: =IFERROR(IF(OR($D$19=$A$16,$E$19=$A$16,$F$19=$A$16),$G$19,$C$6),"") -> 8 | K34: =IFERROR(IF(OR($D$19=$A$17,$E$19=$A$17,$F$19=$A$17),$G$19,$C$6),"") -> 8 | L34: =IFERROR(IF(OR($D$19=$A$18,$E$19=$A$18,$F$19=$A$18),$G$19,$C$6),"") -> 8 | M34: =IFERROR(IF(OR($D$19=$A$19,$E$19=$A$19,$F$19=$A$19),$G$19,$C$6),"") -> 999 | N34: =IFERROR(IF(OR($D$19=$A$20,$E$19=$A$20,$F$19=$A$20),$G$19,$C$6),"") -> 999
