Workbook

Sheet Instructions
A1: Startup Cost Calculator (CAPEX)
A2: AI Chef Pro · aichef.pro — How to Open a Pastry Shop
A3: What it's for: knowing how much money you really need to open, and whether taking over a bakery beats building new.
A5: How to use it
A6: 1. "Settings" sheet: the square footage of the space, the three build-out prices per square foot, the scenario you choose, the months of cushion and the tax rates. Everything the workbook calculates comes from here.
A7: 2. "Startup Costs by Block" sheet: one row per line item. Enter the lowest and highest quote you've been given and the amount you're working with, say whether THAT amount already includes tax and at what rate, and mark "No" on whatever you're not going to buy. The sheet brings every line to a pre-tax basis before adding up, which is the only way the total means anything.
A8: 3. "Format Variant" sheet: your pastry shop may not be the one in the example. Ten formats with an editable coefficient per block on the central case and, next to them, the published third-party range where there is one, so you can see whether your math and theirs look alike.
A9: 4. "Takeover vs New Build" sheet: a takeover's asking price isn't what the takeover costs. Enter the rent for both options, the months you'll be closed in each and the years of the lease, and compare the full cost. Below, the case's takeover plus fourteen rows for the listings in your area.
A10: 5. "VAT-GST & Cash" sheet: the tax you pay on your startup purchases and how much cash you need the day you open. In the US, sales tax on equipment and build-out is a cost that never comes back; the rows on when the tax comes back are for VAT or GST (UK, Canada, Australia).
A11: 6. "Summary" sheet: the figures to take to the lender, all calculated from the previous sheets.
A13: Green cells = editable fields
A15: Things to know before you start
... A22: Where this workbook ends and another one picks up
A23: What you need | B23: Where it is | C23: Why it isn't here
A24: Who you buy each machine from, at what negotiated price and with what lead time | B24: equipment-and-suppliers-checklist.xlsx | C24: Here a machine only comes in as an amount. The lead time doesn't change startup costs; it changes the opening date, and that's permits-and-licenses-checklist.xlsx.
A25: The 3-year P&L, the month-by-month cash flow and the loan schedule | B25: 3-year-financial-plan.xlsx | C25: That workbook gives you the real monthly fixed cost. Here it comes in as a setting with a default value, only to calculate working capital.
A26: Whether that space works and how many pieces a day the equipment can handle | B26: kitchen-capacity-and-site.xlsx | C26: Buying well starts with knowing what you need, not what it costs. Both workbooks share the same 969 sq ft.
A27: Which permits you need, in what order and when you open | B27: permits-and-licenses-checklist.xlsx | C27: The fees and the plans are here as amounts; the procedure and the timeline, there.
A28: It's a declared COPY, not a link: in the whole guide there isn't a single formula pointing to another file. Where a green cell would bring in data from another workbook, it comes with its own default value, declared as an assumption, and its note tells you what replaces it.
A30: How often to use this workbook
A31: How often: you fill it in ONCE when you prepare the plan and review it every time a new quote comes in, until you sign. After opening you only come back to it to compare what you budgeted with what you really spent, which is what teaches you to budget the next one.
A33: To edit the structure or a cell that isn't green: Review > Unprotect Sheet (no password).
A35: Designed by John Guerrero — chef and restaurant consultant since 2010, in the kitchen since age 17.
A36: Version 1.0 · October 2026 · aichef.pro/en/digital-products/how-to-open-a-pastry-shop · info@aichef.pro

Sheet Settings
A1: Settings
A2: AI Chef Pro · aichef.pro — How to Open a Pastry Shop
A3: Change the build-out scenario and the whole workbook recalculates.
A5: Setting | B5: Value | C5: Unit | D5: Source | E5: What it is and where it comes from
A6: Total floor area of the space | B6: 968.75194 | C6: Square feet | D6: Modeled case | E6: The same 969 sq ft as kitchen-capacity-and-site.xlsx. It's the floor area the three build-out scenarios are built on: at 1,184 sq ft the middle scenario would climb to about $99,000 and the whole comparison would change.
A7: Build-out, low scenario | B7: 55.741824 | C7: $ per sq ft | D7: Case assumption | E7: A space that already comes with systems you can use (an existing hood and duct, enough electrical service, a sound slab and drains) and only needs adapting and finishing.
A8: Build-out, middle scenario | B8: 83.612736 | C8: $ per sq ft | D8: Case assumption | E8: A street-level space that has been empty for a while or comes from another use: neither fully equipped nor completely raw. It's the reference scenario.
A9: Build-out, high scenario | B9: 111.48365 | C9: $ per sq ft | D9: Case assumption | E9: Demolition, a new slab and drains, electrical and plumbing run from scratch, and the whole exhaust system built from the ground up.
A10: Build-out scenario chosen | B10: Middle | C10: Low, Middle or High | D10: Assumption | E10: Change it and the build-out, startup costs, the takeover comparison and the tax paid all recalculate.
A11: Price per sq ft applied | B11: =IF(B10="","",IF(B10="Low",B7,IF(B10="High",B9,IF(B10="Middle",B8,"")))) -> 83.612736 | C11: $ per sq ft | D11: Calculated | E11: The one for the scenario you chose above.
A12: Build-out, calculated | B12: =IFERROR(B6*B11,"") -> 81000 | C12: $ | D12: Calculated | E12: Square feet × price per sq ft. It's the only startup cost line that isn't typed: it comes from the scenario.
A13: Sales tax rate on purchases | B13: 0 | C13: % | D13: Your state + local rate | E13: 0% by default. Type your combined state and local rate (e.g. 8.25%, the Texas maximum combined rate: 6.25% state plus up to 2% local) and the tax columns of "Startup Costs by Block" fill in. It's the default rate for each line's tax column (build-out, equipment, fixtures, plans, professional fees, packaging and marketing), but each line can carry its own. In the US it's a cost: it never comes back. With VAT or GST, type your standard rate.
A14: Tax rate on what you'll sell (VAT/GST countries; 0% in the US) | B14: 0 | C14: % | D14: VAT/GST only | E14: Not part of startup costs. It's here for readers in the UK, Canada or Australia, where the VAT or GST you charge on sales is what the tax you pay now gets offset against. In the US leave it at 0%: bakery items sold to go are generally exempt, sales tax follows how you sell rather than what you sell (chapter 19 of the guide), and it's never netted against what you paid on equipment.
A15: Tax rate on permit and plan-review fees | B15: 0 | C15: % | D15: Assumption | E15: City and county permit fees and the health department's plan review and permit application carry no sales tax. It's a setting so the startup costs sheet doesn't need a hidden exception.
A16: Months of cash cushion | B16: 4 | C16: months | D16: Assumption | E16: Months of fixed costs you need in the bank the day you open. It's a startup cost line, not a tip: without it, the business depends on selling from day one, which is exactly what doesn't happen.
A17: Minimum acceptable cushion before the warning (months) | B17: 3 | C17: months | D17: Assumption | E17: The threshold for the cash verdict further down. If your lender asks for more, raise it here; don't confuse it with the months you actually fund above.
A18: Estimated monthly fixed costs | B18: 15528.82 | C18: $/month | D18: Assumption | E18: Staff (with payroll taxes, workers' comp and benefits), the owner's pay, rent, utilities, insurance, accounting, depreciation and interest IN THE STEADY-STATE YEAR (year 2, after the interest-only months). It's the same monthly fixed cost that 3-year-financial-plan.xlsx calculates, so the two workbooks show the same working capital and the same total investment. If you change this value, change it there too.
A19: Working capital, calculated | B19: =IFERROR(B16*B18,"") -> 62115.28 | C19: $ | D19: Calculated | E19: Months of cushion × monthly fixed costs.
A20: Monthly rent | B20: 1200 | C20: $/month | D20: Assumption | E20: Assumption for a mid-size city: $1,200 a month on 969 sq ft is about $15 per sq ft a year, below the national average asking rent for retail space (CBRE: $24.79 per sq ft a year, Q2 2026). Put in your own, plus NNN charges if your lease has them.
A21: Months of security deposit | B21: 2 | C21: months | D21: Assumption | E21: The security deposit isn't an expense: it's money you get back. It goes into startup costs because you need it the day you sign.
A22: Comparison horizon | B22: 5 | C22: years | D22: Assumption | E22: Years over which the takeover is compared with the new build. Five is a common lease term; put in yours.
A23: How often you file your VAT/GST return (UK, Canada, Australia) | B23: 3 | C23: months | D23: Assumption | E23: Only for VAT/GST. Quarterly is a common filing period for a new business; filing monthly gets the tax on the investment back sooner. Your tax agency sets yours when it registers you. In the US nothing comes back: this row doesn't apply.
A24: Months until you recover the VAT/GST on the investment | B24: 4 | C24: months | D24: Assumption | E24: Only for VAT/GST: the period you buy in plus the time to file. And note: usually it isn't refunded, it's offset against the VAT or GST you charge, so it comes back at the pace you sell. Ask your accountant. In the US, sales tax on what you buy never comes back.
A25: Bank financing available | B25: 60000 | C25: $ | D25: Assumption | E25: All assumption: your lender sets the terms, and they depend on your credit and collateral. The six interest-only months keep the loan from eating your cash during the ramp-up, and they're the first thing to negotiate. During that period you only pay interest.
A27: Validation lists (don't delete them: the dropdowns use them)
A28: Build-out scenario
A29: Low
A30: Middle
A31: High
A33: The three per-square-foot prices are the case's assumptions for a 969-sq-ft space, so they match this floor area without adjustments. If you change the square footage, the build-out changes but the price per sq ft does NOT: ask for it again, because a small space costs more per square foot than a large one.

Sheet Startup Costs by Block
A1: Startup Costs by Block
A2: AI Chef Pro · aichef.pro — How to Open a Pastry Shop
A3: Every line is brought to a pre-tax basis before adding up. Without the tax column, the total comes out wrong.
A5: No. | B5: Block | C5: Line item | D5: Buying it? | E5: Source | F5: Price includes sales tax? | G5: Tax rate | H5: Minimum | I5: Maximum | J5: Your amount | K5: Pre-tax cost | L5: Tax paid | M5: Total with tax | N5: Published range | O5: Note
A6: 1 | B6: Build-out and building systems | C6: Build-out for the chosen scenario | D6: Yes | E6: Build-out scenario | F6: No | G6: ='Settings'!$B$13 -> 0 | H6: ='Settings'!B12 -> 81000 | I6: ='Settings'!B12 -> 81000 | J6: ='Settings'!B12 -> 81000 | K6: =IF(D6="No","",IFERROR(IF(F6="Yes",J6/(1+G6),J6),"")) -> 81000 | L6: =IF(K6="","",IFERROR(K6*G6,"")) -> 0 | M6: =IF(K6="","",IFERROR(K6+L6,"")) -> 81000 | N6: $55.74, $83.61 or $111.48 per sq ft over 969 sq ft | O6: Calculated on the "Settings" sheet from the square footage and the scenario. It's the line that overruns most during construction: whatever isn't in the plans gets billed separately. It doesn't include the hood and its duct, the electrical service upgrade or their permits.
A7: 2 | B7: Production kitchen equipment | C7: Convection oven, 6 trays | D7: Yes | E7: Example price | F7: No | G7: ='Settings'!$B$13 -> 0 | H7: 2772 | I7: 2772 | J7: 2772 | K7: =IF(D7="No","",IFERROR(IF(F7="Yes",J7/(1+G7),J7),"")) -> 2772 | L7: =IF(K7="","",IFERROR(K7*G7,"")) -> 0 | M7: =IF(K7="","",IFERROR(K7+L7,"")) -> 2772 | N7: Example price (dealer spec sheet) | O7: Example price, before sales tax. Check the model's voltage and phase against your electrical service before you order.
A8: 3 | B8: Production kitchen equipment | C8: Convection oven, 4 trays | D8: Yes | E8: Example price | F8: No | G8: ='Settings'!$B$13 -> 0 | H8: 2077.1983 | I8: 2077.1983 | J8: 2077.1983 | K8: =IF(D8="No","",IFERROR(IF(F8="Yes",J8/(1+G8),J8),"")) -> 2077.1983 | L8: =IF(K8="","",IFERROR(K8*G8,"")) -> 0 | M8: =IF(K8="","",IFERROR(K8+L8,"")) -> 2077.1983 | N8: Example price (dealer spec sheet) | O8: Second oven: without it you can't bake at two different temperatures at the same time. Example price, before sales tax.
A9: 4 | B9: Storefront and display | C9: Refrigerated bakery display case, curved glass, about 5 ft | D9: Yes | E9: Example price | F9: No | G9: ='Settings'!$B$13 -> 0 | H9: 2284.1 | I9: 2284.1 | J9: 2284.1 | K9: =IF(D9="No","",IFERROR(IF(F9="Yes",J9/(1+G9),J9),"")) -> 2284.1 | L9: =IF(K9="","",IFERROR(K9*G9,"")) -> 0 | M9: =IF(K9="","",IFERROR(K9+L9,"")) -> 2284.1 | N9: Example price (dealer spec sheet) | O9: About 5 ft wide (1,505 × 900 × 1,305 mm, 452 L), with about 10 sq ft of display area and R-290 refrigerant. The price carried a 30% promotional discount and is DATED: it can expire. If you reuse it, check it again. A single display case, counted only once.
A10: 5 | B10: Storefront and display | C10: Rear sliding doors for the display case (accessory) | D10: No | E10: Example price | F10: No | G10: ='Settings'!$B$13 -> 0 | H10: 120.4 | I10: 120.4 | J10: 120.4 | K10: =IF(D10="No","",IFERROR(IF(F10="Yes",J10/(1+G10),J10),"")) | L10: =IF(K10="","",IFERROR(K10*G10,"")) | M10: =IF(K10="","",IFERROR(K10+L10,"")) | N10: Example price (dealer spec sheet) | O10: OPTIONAL: it ships with "Buying it?" set to No. An accessory: it stays out of the comparable subtotal.
A11: 6 | B11: Production kitchen equipment | C11: Blast chiller, 4 trays — Irinox MultiFresh line | D11: Yes | E11: Example price | F11: No | G11: ='Settings'!$B$13 -> 0 | H11: 10037 | I11: 10037 | J11: 10037 | K11: =IF(D11="No","",IFERROR(IF(F11="Yes",J11/(1+G11),J11),"")) -> 10037 | L11: =IF(K11="","",IFERROR(K11*G11,"")) -> 0 | M11: =IF(K11="","",IFERROR(K11+L11,"")) -> 10037 | N11: Example price (dealer spec sheet) | O11: The most expensive purchase and the most debated (decision 2 of the bonus). Cycles from +185 °F to −40 °F. A chest freezer is NOT a blast chiller: the Food Code's cooling rule (135 °F to 70 °F within 2 hours, and to 41 °F within 6 hours in total) is what a blast chiller is for. US reference: WebstaurantStore listed $5,499 (Avantco reach-in) to $21,729 (Irinox MultiFresh Next S) in October 2026.
A12: 7 | B12: Production kitchen equipment | C12: Dough sheeter, up to 16 in wide | D12: Yes | E12: Example price | F12: No | G12: ='Settings'!$B$13 -> 0 | H12: 1215 | I12: 1215 | J12: 1215 | K12: =IF(D12="No","",IFERROR(IF(F12="Yes",J12/(1+G12),J12),"")) -> 1215 | L12: =IF(K12="","",IFERROR(K12*G12,"")) -> 0 | M12: =IF(K12="","",IFERROR(K12+L12,"")) -> 1215 | N12: Example price (dealer spec sheet) | O12: Example price, before sales tax, from the dealer's own spec sheet.
A13: 8 | B13: Production kitchen equipment | C13: Planetary mixer, 20 qt | D13: Yes | E13: Example price | F13: No | G13: ='Settings'!$B$13 -> 0 | H13: 595.04 | I13: 595.04 | J13: 595.04 | K13: =IF(D13="No","",IFERROR(IF(F13="Yes",J13/(1+G13),J13),"")) -> 595.04 | L13: =IF(K13="","",IFERROR(K13*G13,"")) -> 0 | M13: =IF(K13="","",IFERROR(K13+L13,"")) -> 595.04 | N13: Example price (dealer spec sheet) | O13: The spec sheet does NOT say whether the price includes tax: it's treated as pre-tax and flagged. 900 W, 95-392 rpm, 0-99 min timer. It's exactly the case that makes the column necessary. US reference: WebstaurantStore listed 20-qt planetary mixers from $849 in October 2026.
A14: 9 | B14: Production kitchen equipment | C14: Chocolate tempering machine, 12 kg (26 lb) | D14: No | E14: Example price | F14: No | G14: ='Settings'!$B$13 -> 0 | H14: 7400 | I14: 7400 | J14: 7400 | K14: =IF(D14="No","",IFERROR(IF(F14="Yes",J14/(1+G14),J14),"")) | L14: =IF(K14="","",IFERROR(K14*G14,"")) | M14: =IF(K14="","",IFERROR(K14+L14,"")) | N14: Example price (dealer spec sheet) | O14: OPTIONAL: it ships with "Buying it?" set to No, and it depends on the concept: only if you open a chocolate or bonbon line. That's why it stays OUT of the comparable subtotal: with it in, a single machine was 25% of the subtotal.
A15: 10 | B15: Production kitchen equipment | C15: Modular deck oven, 1 to 5 decks | D15: No | E15: Assumption | F15: No | G15: ='Settings'!$B$13 -> 0 | H15: 12000 | I15: 12000 | J15: 12000 | K15: =IF(D15="No","",IFERROR(IF(F15="Yes",J15/(1+G15),J15),"")) | L15: =IF(K15="","",IFERROR(K15*G15,"")) | M15: =IF(K15="","",IFERROR(K15+L15,"")) | N15: No published price: deck ovens are sold by quote | O15: OPTIONAL: it ships with "Buying it?" set to No. An ASSUMPTION, not a list price: deck ovens are sold through dealers by quote. The default value is an ASSUMPTION so the cell isn't empty: get three quotes. For scale, WebstaurantStore listed electric pizza-style deck ovens at $13,404.50 (one deck) to $32,376.50 (three decks) in October 2026.
A16: 11 | B16: Production kitchen equipment | C16: Retarder-proofer (roll-in) | D16: Yes | E16: Assumption | F16: No | G16: ='Settings'!$B$13 -> 0 | H16: 8500 | I16: 8500 | J16: 8500 | K16: =IF(D16="No","",IFERROR(IF(F16="Yes",J16/(1+G16),J16),"")) -> 8500 | L16: =IF(K16="","",IFERROR(K16*G16,"")) -> 0 | M16: =IF(K16="","",IFERROR(K16+L16,"")) -> 8500 | N16: US: $27,937.80 for a one-section roll-in model (WebstaurantStore, Oct 2026) | O16: An ASSUMPTION, not a list price. It's what lets the viennoiserie be out of the oven by 7:00 without starting at 3. US reference: WebstaurantStore listed a one-section roll-in retarder-proofer (Doyon KDPR11) at $27,937.80 in October 2026, usually shipping in 6 weeks.
A17: 12 | B17: Production kitchen equipment | C17: Stainless steel exhaust duct | D17: Yes | E17: Assumption | F17: No | G17: ='Settings'!$B$13 -> 0 | H17: 6500 | I17: 6500 | J17: 6500 | K17: =IF(D17="No","",IFERROR(IF(F17="Yes",J17/(1+G17),J17),"")) -> 6500 | L17: =IF(K17="","",IFERROR(K17*G17,"")) -> 0 | M17: =IF(K17="","",IFERROR(K17+L17,"")) -> 6500 | N17: Published estimate: a hood at $5,000 to $28,000 installed, plus $3,000 to $12,000 for fire suppression | O17: An ASSUMPTION, not a list price. The line that kills the most spaces, and the one to settle BEFORE you sign (chapter 6 of the guide). A Type I hood's grease duct runs on its own up to the roof and can't share a duct with any other exhaust; your adopted mechanical code and NFPA 96 set the rest.
A18: 13 | B18: Production kitchen equipment | C18: Spiral mixer, 25 kg (55 lb) of dough | D18: Yes | E18: Assumption | F18: No | G18: ='Settings'!$B$13 -> 0 | H18: 5200 | I18: 5200 | J18: 5200 | K18: =IF(D18="No","",IFERROR(IF(F18="Yes",J18/(1+G18),J18),"")) -> 5200 | L18: =IF(K18="","",IFERROR(K18*G18,"")) -> 0 | M18: =IF(K18="","",IFERROR(K18+L18,"")) -> 5200 | N18: US: $2,249 for a 60-qt spiral mixer, 88 lb of dough (WebstaurantStore, Oct 2026) | O18: An ASSUMPTION, not a list price. US dealers list spiral mixers by bowl size and dough capacity: check both, and the voltage, against what you'll really mix in a day.
... A28: 23 | B28: Production kitchen equipment | C28: Probe thermometers, scales and temperature data loggers | D28: Yes | E28: Assumption | F28: No | G28: ='Settings'!$B$13 -> 0 | H28: 900 | I28: 900 | J28: 900 | K28: =IF(D28="No","",IFERROR(IF(F28="Yes",J28/(1+G28),J28),"")) -> 900 | L28: =IF(K28="","",IFERROR(K28*G28,"")) -> 0 | M28: =IF(K28="","",IFERROR(K28+L28,"")) -> 900 | N28: No published price: the default value is an ASSUMPTION | O28: An ASSUMPTION, not a list price. Without a probe you can't prove the temperatures your food safety plan promises (cooking, cooling, holding at 41 °F). It's the cheapest purchase with the most consequences.
A29: 24 | B29: Permits, plans and fees | C29: Plans and specifications for plan review | D29: Yes | E29: Example price | F29: No | G29: ='Settings'!$B$13 -> 0 | H29: 5000 | I29: 5000 | J29: 5000 | K29: =IF(D29="No","",IFERROR(IF(F29="Yes",J29/(1+G29),J29),"")) -> 5000 | L29: =IF(K29="","",IFERROR(K29*G29,"")) -> 0 | M29: =IF(K29="","",IFERROR(K29+L29,"")) -> 5000 | N29: Example amount (the case)
A30: 25 | B30: Permits, plans and fees | C30: Professional advice (CPA, attorney) | D30: Yes | E30: Example price | F30: No | G30: ='Settings'!$B$13 -> 0 | H30: 1000 | I30: 1000 | J30: 1000 | K30: =IF(D30="No","",IFERROR(IF(F30="Yes",J30/(1+G30),J30),"")) -> 1000 | L30: =IF(K30="","",IFERROR(K30*G30,"")) -> 0 | M30: =IF(K30="","",IFERROR(K30+L30,"")) -> 1000 | N30: Example amount (the case)
A31: 26 | B31: Permits, plans and fees | C31: City and county permit fees (building permit, certificate of occupancy) | D31: Yes | E31: Assumption | F31: No | G31: ='Settings'!$B$15 -> 0 | H31: 1800 | I31: 1800 | J31: 1800 | K31: =IF(D31="No","",IFERROR(IF(F31="Yes",J31/(1+G31),J31),"")) -> 1800 | L31: =IF(K31="","",IFERROR(K31*G31,"")) -> 0 | M31: =IF(K31="","",IFERROR(K31+L31,"")) -> 1800 | N31: ASSUMPTION: the amount changes from place to place | O31: Government permit fees carry no sales tax, and the amount changes from one city or county to the next: it's a number to go and find, not copy.
A32: 27 | B32: Permits, plans and fees | C32: Health department plan review and food permit application | D32: Yes | E32: Assumption | F32: No | G32: ='Settings'!$B$15 -> 0 | H32: 120 | I32: 120 | J32: 120 | K32: =IF(D32="No","",IFERROR(IF(F32="Yes",J32/(1+G32),J32),"")) -> 120 | L32: =IF(K32="","",IFERROR(K32*G32,"")) -> 0 | M32: =IF(K32="","",IFERROR(K32+L32,"")) -> 120 | N32: ASSUMPTION: the amount changes from place to place | O32: The health department reviews your plans and inspects before it issues the food permit (Food Code 8-201.11 and Part 8-3): without it you can't open. The amount is an assumption; Austin, for example, charges $312 for plan review of a new food establishment and $178 for the pre-opening inspection (FY 2025-26).
A33: 28 | B33: Security deposit | C33: Lease security deposit (2 months) | D33: Yes | E33: Assumption | F33: No | G33: ='Settings'!$B$15 -> 0 | H33: =IFERROR('Settings'!B20*'Settings'!B21,"") -> 2400 | I33: =IFERROR('Settings'!B20*'Settings'!B21,"") -> 2400 | J33: =IFERROR('Settings'!B20*'Settings'!B21,"") -> 2400 | K33: =IF(D33="No","",IFERROR(IF(F33="Yes",J33/(1+G33),J33),"")) -> 2400 | L33: =IF(K33="","",IFERROR(K33*G33,"")) -> 0 | M33: =IF(K33="","",IFERROR(K33+L33,"")) -> 2400 | N33: Monthly rent × months of deposit | O33: The security deposit isn't an expense: it's money you get back. It goes into startup costs because you need it the day you sign.
A34: 29 | B34: Opening packaging | C34: First packaging order: bags, boxes and labels | D34: Yes | E34: Assumption | F34: No | G34: ='Settings'!$B$13 -> 0 | H34: 2500 | I34: 2500 | J34: 2500 | K34: =IF(D34="No","",IFERROR(IF(F34="Yes",J34/(1+G34),J34),"")) -> 2500 | L34: =IF(K34="","",IFERROR(K34*G34,"")) -> 0 | M34: =IF(K34="","",IFERROR(K34+L34,"")) -> 2500 | N34: ASSUMPTION: the amount changes from place to place | O34: Start with the supplier's minimum: custom-printed packaging means big orders and money sitting in the storeroom.
A35: 30 | B35: Opening marketing | C35: Opening marketing | D35: Yes | E35: Example price | F35: No | G35: ='Settings'!$B$13 -> 0 | H35: 5000 | I35: 5000 | J35: 5000 | K35: =IF(D35="No","",IFERROR(IF(F35="Yes",J35/(1+G35),J35),"")) -> 5000 | L35: =IF(K35="","",IFERROR(K35*G35,"")) -> 0 | M35: =IF(K35="","",IFERROR(K35+L35,"")) -> 5000 | N35: Example amount (the case)
A36: 31 | B36: Working capital | C36: Cash cushion (months of fixed costs) | D36: Yes | E36: Assumption | F36: No | G36: ='Settings'!$B$15 -> 0 | H36: ='Settings'!B19 -> 62115.28 | I36: ='Settings'!B19 -> 62115.28 | J36: ='Settings'!B19 -> 62115.28 | K36: =IF(D36="No","",IFERROR(IF(F36="Yes",J36/(1+G36),J36),"")) -> 62115.28 | L36: =IF(K36="","",IFERROR(K36*G36,"")) -> 0 | M36: =IF(K36="","",IFERROR(K36+L36,"")) -> 62115.28 | N36: Months of cushion × monthly fixed costs | O36: Calculated: months of cushion × monthly fixed costs (both on "Settings").
B38: Summary by block
C39: Build-out and building systems | K39: =SUMIF($B$6:$B$36,C39,K$6:K$36) -> 81000 | L39: =SUMIF($B$6:$B$36,C39,L$6:L$36) -> 0 | M39: =SUMIF($B$6:$B$36,C39,M$6:M$36) -> 81000 | N39: =IFERROR(K39/$K$47,"") -> 0.35539469
C40: Production kitchen equipment | K40: =SUMIF($B$6:$B$36,C40,K$6:K$36) -> 54296.238 | L40: =SUMIF($B$6:$B$36,C40,L$6:L$36) -> 0 | M40: =SUMIF($B$6:$B$36,C40,M$6:M$36) -> 54296.238 | N40: =IFERROR(K40/$K$47,"") -> 0.23822956
C41: Storefront and display | K41: =SUMIF($B$6:$B$36,C41,K$6:K$36) -> 12684.1 | L41: =SUMIF($B$6:$B$36,C41,L$6:L$36) -> 0 | M41: =SUMIF($B$6:$B$36,C41,M$6:M$36) -> 12684.1 | N41: =IFERROR(K41/$K$47,"") -> 0.055652614
C42: Permits, plans and fees | K42: =SUMIF($B$6:$B$36,C42,K$6:K$36) -> 7920 | L42: =SUMIF($B$6:$B$36,C42,L$6:L$36) -> 0 | M42: =SUMIF($B$6:$B$36,C42,M$6:M$36) -> 7920 | N42: =IFERROR(K42/$K$47,"") -> 0.034749703
C43: Security deposit | K43: =SUMIF($B$6:$B$36,C43,K$6:K$36) -> 2400 | L43: =SUMIF($B$6:$B$36,C43,L$6:L$36) -> 0 | M43: =SUMIF($B$6:$B$36,C43,M$6:M$36) -> 2400 | N43: =IFERROR(K43/$K$47,"") -> 0.010530213
C44: Opening packaging | K44: =SUMIF($B$6:$B$36,C44,K$6:K$36) -> 2500 | L44: =SUMIF($B$6:$B$36,C44,L$6:L$36) -> 0 | M44: =SUMIF($B$6:$B$36,C44,M$6:M$36) -> 2500 | N44: =IFERROR(K44/$K$47,"") -> 0.010968972
C45: Opening marketing | K45: =SUMIF($B$6:$B$36,C45,K$6:K$36) -> 5000 | L45: =SUMIF($B$6:$B$36,C45,L$6:L$36) -> 0 | M45: =SUMIF($B$6:$B$36,C45,M$6:M$36) -> 5000 | N45: =IFERROR(K45/$K$47,"") -> 0.021937944
C46: Working capital | K46: =SUMIF($B$6:$B$36,C46,K$6:K$36) -> 62115.28 | L46: =SUMIF($B$6:$B$36,C46,L$6:L$36) -> 0 | M46: =SUMIF($B$6:$B$36,C46,M$6:M$36) -> 62115.28 | N46: =IFERROR(K46/$K$47,"") -> 0.2725363
C47: STARTUP COSTS TOTAL | K47: =SUM(K39:K46) -> 227915.62 | L47: =SUM(L39:L46) -> 0 | M47: =SUM(M39:M46) -> 227915.62
C48: Of which, tax paid on purchases | K48: =L47 -> 0
C49: Total cash out, tax included | K49: =M47 -> 227915.62
C51: Comparable subtotal (build-out, equipment, storefront, permits and marketing) | K51: =K39+K40+K41+K42+K45 -> 160900.34
C52: Published reference for a shop like yours (type in one you trust)
...

Sheet Format Variant
A1: Format Variant
A2: AI Chef Pro · aichef.pro — How to Open a Pastry Shop
A3: Your pastry shop may not be the one in the example. The coefficients are editable assumptions on the central case; the ranges on the right are published third-party estimates. "Opening investment" is startup costs without working capital, which is how those estimates are usually published.
B5: Central case bases (from "Startup Costs by Block")
B6: Build-out and building systems | C6: ='Startup Costs by Block'!K39 -> 81000
B7: Production kitchen equipment | C7: ='Startup Costs by Block'!K40 -> 54296.238
B8: Storefront and display | C8: ='Startup Costs by Block'!K41 -> 12684.1
B9: Permits, plans and fees | C9: ='Startup Costs by Block'!K42 -> 7920
B10: Other opening costs (security deposit, packaging and marketing) | C10: ='Startup Costs by Block'!K43+'Startup Costs by Block'!K44+'Startup Costs by Block'!K45 -> 9900
B11: Working capital | C11: ='Startup Costs by Block'!K46 -> 62115.28
A14: No. | B14: Variant | C14: Main permit (ch. 9) | D14: Build-out coef. | E14: Equipment coef. | F14: Storefront coef. | G14: Permits coef. | H14: Other coef. | I14: Opening investment | J14: With working capital | K14: Published low | L14: Published high | M14: Deviation from the midpoint | N14: What else changes | O14: Does it fit the published range?
A15: 1 | B15: Mid-size pastry shop: its own production kitchen and a front counter on the street (this guide's case) | C15: Retail food permit | D15: 1 | E15: 1 | F15: 1 | G15: 1 | H15: 1 | I15: =IFERROR($C$6*D15+$C$7*E15+$C$8*F15+$C$9*G15+$C$10*H15,"") -> 165800.34 | J15: =IFERROR(I15+$C$11*H15,"") -> 227915.62 | K15: 50000 | L15: 100000 | M15: =IF(OR(K15="",L15=""),"",IFERROR(I15/((K15+L15)/2)-1,"")) -> 1.2106712 | N15: It's the core case: every coefficient is 1.00, so the opening investment is exactly the total on the "Startup Costs by Block" sheet minus working capital, and the next column adds it back to give the total. The published range is for a small retail bakery; the case lands above it because it prices a full production kitchen line by line. | O15: =IF(M15="","",IF(ABS(M15)>1,"More than double apart: check the range before the math","Same order of magnitude")) -> More than double apart: check the range before the math
A16: 2 | B16: Home-based bakery under cottage food, selling direct to customers | C16: Your state's cottage food rules | D16: 0.05 | E16: 0.15 | F16: 0 | G16: 0.1 | H16: 0.2 | I16: =IFERROR($C$6*D16+$C$7*E16+$C$8*F16+$C$9*G16+$C$10*H16,"") -> 14966.436 | J16: =IFERROR(I16+$C$11*H16,"") -> 27389.492 | K16: 15000 | L16: 25000 | M16: =IF(OR(K16="",L16=""),"",IFERROR(I16/((K16+L16)/2)-1,"")) -> -0.25167821 | N16: It isn't a storefront: it's your home, under your state's cottage food law, with its list of allowed foods and its sales cap (2026: California $88,878 for Class A and $177,756 for Class B, Texas $150,000, Florida $250,000; New York's page lists no cap). A registration, a permit or nothing at all, depending on the state. No build-out, no storefront and no lease deposit; the "Cottage Food Route" sheet in permits-and-licenses-checklist.xlsx is the one that rules. | O16: =IF(M16="","",IF(ABS(M16)>1,"More than double apart: check the range before the math","Same order of magnitude")) -> Same order of magnitude
A17: 3 | B17: Closed-door production kitchen, no retail counter | C17: Food permit; FDA registration once wholesale passes half of sales | D17: 0.45 | E17: 0.45 | F17: 0 | G17: 0.6 | H17: 0.5 | I17: =IFERROR($C$6*D17+$C$7*E17+$C$8*F17+$C$9*G17+$C$10*H17,"") -> 70585.307 | J17: =IFERROR(I17+$C$11*H17,"") -> 101642.95 | K17: 75000 | L17: 150000 | M17: =IF(OR(K17="",L17=""),"",IFERROR(I17/((K17+L17)/2)-1,"")) -> -0.37257505 | N17: No display case or retail fixtures, but the 50% line hangs over you: once more than half of your food sales by value go to businesses rather than consumers, you're no longer exempt from FDA food facility registration. The "Selling Wholesale" sheet in permits-and-licenses-checklist.xlsx walks you through it. | O17: =IF(M17="","",IF(ABS(M17)>1,"More than double apart: check the range before the math","Same order of magnitude")) -> Same order of magnitude
A18: 4 | B18: Storefront with a counter but no kitchen of its own | C18: Retail food permit | D18: 0.35 | E18: 0.1 | F18: 1 | G18: 0.7 | H18: 0.6 | I18: =IFERROR($C$6*D18+$C$7*E18+$C$8*F18+$C$9*G18+$C$10*H18,"") -> 57947.724 | J18: =IFERROR(I18+$C$11*H18,"") -> 95216.892 | M18: =IF(OR(K18="",L18=""),"",IFERROR(I18/((K18+L18)/2)-1,"")) | N18: You buy finished or par-baked product: almost all the production equipment goes and the display case stays whole. If you don't bake from scratch, don't say you do: "baked fresh daily" on product you only thaw and finish is a misleading-claim risk. | O18: =IF(M18="","",IF(ABS(M18)>1,"More than double apart: check the range before the math","Same order of magnitude"))
A19: 5 | B19: Bakery-café with its own kitchen | C19: Food service permit (another agency in NY and FL) | D19: 1.25 | E19: 1.05 | F19: 1.6 | G19: 1.3 | H19: 1.2 | I19: =IFERROR($C$6*D19+$C$7*E19+$C$8*F19+$C$9*G19+$C$10*H19,"") -> 200731.61 | J19: =IFERROR(I19+$C$11*H19,"") -> 275269.95 | M19: =IF(OR(K19="",L19=""),"",IFERROR(I19/((K19+L19)/2)-1,"")) | N19: Adds seating, a coffee bar, an espresso machine and customer restrooms. The moment people eat at your tables, two things change: sales tax (pastries to go are generally exempt in the four example states; what's eaten on site generally isn't) and, in New York and Florida, the agency that permits you. | O19: =IF(M19="","",IF(ABS(M19)>1,"More than double apart: check the range before the math","Same order of magnitude"))
A20: 6 | B20: Small bake-off shop | C20: Retail food permit | D20: 0.55 | E20: 0.3 | F20: 1 | G20: 0.7 | H20: 0.7 | I20: =IFERROR($C$6*D20+$C$7*E20+$C$8*F20+$C$9*G20+$C$10*H20,"") -> 85996.972 | J20: =IFERROR(I20+$C$11*H20,"") -> 129477.67 | M20: =IF(OR(K20="",L20=""),"",IFERROR(I20/((K20+L20)/2)-1,"")) | N20: Bakes off frozen product: ovens and a display case, yes; a real production kitchen, no. It doesn't bake from scratch, so it can't claim to either. | O20: =IF(M20="","",IF(ABS(M20)>1,"More than double apart: check the range before the math","Same order of magnitude"))
A21: 7 | B21: Large or prime-location shop | C21: Retail food permit | D21: 1.8 | E21: 1.3 | F21: 1.8 | G21: 1.4 | H21: 1.5 | I21: =IFERROR($C$6*D21+$C$7*E21+$C$8*F21+$C$9*G21+$C$10*H21,"") -> 265154.49 | J21: =IFERROR(I21+$C$11*H21,"") -> 358327.41 | M21: =IF(OR(K21="",L21=""),"",IFERROR(I21/((K21+L21)/2)-1,"")) | N21: Build-out and rent dominate the investment, and the rent that doesn't show here eats the margin every month. Run the "Takeover vs New Build" sheet with the real rent before you fall in love with the street. | O21: =IF(M21="","",IF(ABS(M21)>1,"More than double apart: check the range before the math","Same order of magnitude"))
A22: 8 | B22: Bakery franchise | C22: Retail food permit | D22: 1.1 | E22: 1 | F22: 1.2 | G22: 1 | H22: 1.1 | I22: =IFERROR($C$6*D22+$C$7*E22+$C$8*F22+$C$9*G22+$C$10*H22,"") -> 177427.16 | J22: =IFERROR(I22+$C$11*H22,"") -> 245753.97 | M22: =IF(OR(K22="",L22=""),"",IFERROR(I22/((K22+L22)/2)-1,"")) | N22: Entry figures vary widely by brand and format: get the franchisor's own numbers in writing, from its FDD. And this sheet leaves out what only the franchisor can tell you: the initial franchise fee and the monthly royalty, which is a cost every month, not part of the investment. | O22: =IF(M22="","",IF(ABS(M22)>1,"More than double apart: check the range before the math","Same order of magnitude"))
A23: 9 | B23: Wholesale production kitchen for restaurants and cafés | C23: Food permit + FDA food facility registration | D23: 1.4 | E23: 1.6 | F23: 0.2 | G23: 1.1 | H23: 1.3 | I23: =IFERROR($C$6*D23+$C$7*E23+$C$8*F23+$C$9*G23+$C$10*H23,"") -> 224392.8 | J23: =IFERROR(I23+$C$11*H23,"") -> 305142.67 | M23: =IF(OR(K23="",L23=""),"",IFERROR(I23/((K23+L23)/2)-1,"")) | N23: No published investment figure. Volume production, invoices on credit terms and almost no display. This is the format where wholesale passes half of your food sales by value, so FDA food facility registration applies (21 CFR 1.227). | O23: =IF(M23="","",IF(ABS(M23)>1,"More than double apart: check the range before the math","Same order of magnitude"))
A24: 10 | B24: Ventless pastry shop (no Type I hood) | C24: Retail food permit; hood answer in writing | D24: 0.95 | E24: 1.1 | F24: 1 | G24: 1 | H24: 1 | I24: =IFERROR($C$6*D24+$C$7*E24+$C$8*F24+$C$9*G24+$C$10*H24,"") -> 167179.96 | J24: =IFERROR(I24+$C$11*H24,"") -> 229295.24 | M24: =IF(OR(K24="",L24=""),"",IFERROR(I24/((K24+L24)/2)-1,"")) | N24: It has no published range because it isn't a business format but a constraint of the space: you skip the Type I hood, the duct and the fire suppression in exchange for all-electric enclosed ovens that need only a Type II hood (or none, if listed to UL 710B) and a menu with no frying. Get the answer in writing from the building department and check it on the "Site Visit Checklist" sheet in kitchen-capacity-and-site.xlsx before you sign. | O24: =IF(M24="","",IF(ABS(M24)>1,"More than double apart: check the range before the math","Same order of magnitude"))
B26: Variants with a published range | I26: =COUNT(K15:K24) -> 3
B27: Variants more than 50% away from the published midpoint | I27: =COUNTIF(M15:M24,">0.5")+COUNTIF(M15:M24,"<-0.5") -> 1
B29: THE COEFFICIENTS ARE ASSUMPTIONS, AND EDITABLE ON PURPOSE. They don't come from any statistic: they're each format's reasonable deviation from the central case, there for you to move. What is published data are the two columns on the right: third-party estimates (Zenind, 2026), not an industry average. If your math and the published range are more than double apart, one of the two is wrong, and it's usually the range: almost none of those figures says whether it includes the build-out or counts working capital.
B31: Seven variants carry no range: we found no published US figure we could match to them. In those rows the deviation column is left empty on purpose: a zero there would say the math checks out, when what's really going on is that there's nothing to compare it with. The eleventh format, a rented commissary kitchen, has no row: there's nothing to build, only a monthly rent.

Sheet Takeover vs New Build
A1: Takeover vs. New Build
A2: AI Chef Pro · aichef.pro — How to Open a Pastry Shop
A3: A takeover's asking price isn't what a takeover costs: the rent over the years of the lease weighs more than the price.
A5: The space you're looking at (takeover)
A6: Asking price for the takeover | B6: The seller's listing | C6: 43000 | J6: Seeded with the case's own takeover (915 sq ft), an ASKING price: what the seller wants for the business, its equipment and the lease, not what it would close for.
A7: Fit-out you'd still have to pay for | B7: Assumption | C7: 25000 | J7: A takeover almost never opens as is: paint, display case, sign and the machine that's missing. Walk it with the "Site Visit Checklist" of kitchen-capacity-and-site.xlsx in hand.
A8: Monthly rent of the space you'd take over | B8: The seller's listing | C8: 1250 | J8: Rent from the seller's listing: about $16 per sq ft a year on 915 sq ft. Most listings don't publish the rent, and that already tells you something.
A9: Months closed before opening, takeover | B9: Assumption | C9: 1 | J9: You pay rent from the day you sign and don't sell until you open.
A10: Comparable startup costs of the new build (from "Startup Costs by Block") | C10: ='Startup Costs by Block'!K51 -> 160900.34 | J10: Without the security deposit, packaging or working capital: both sides of the comparison need them equally, so adding them to just one would skew the result.
A11: Monthly rent of the new-build space | C11: ='Settings'!B20 -> 1200
A12: Build-out months without sales | B12: Assumption | C12: 4 | J12: Rent you pay while the space is under construction. It's the line almost nobody includes and the one most like a surprise.
A13: Comparison horizon (years) | C13: ='Settings'!B22 -> 5
A14: The comparison
A15: Cost of the takeover over the horizon | C15: =IFERROR(C6+C7+C8*12*C13,"") -> 143000
A16: Cost of the new build over the horizon | C16: =IFERROR(C10+C11*12*C13,"") -> 232900.34
A17: Rent paid before you're selling, takeover | C17: =IFERROR(C8*C9,"") -> 1250
A18: Rent paid before you're selling, new build | C18: =IFERROR(C11*C12,"") -> 4800
A19: TOTAL for the takeover | C19: =IFERROR(C15+C17,"") -> 144250
A20: TOTAL for the new build | C20: =IFERROR(C16+C18,"") -> 237700.34
A21: Difference (takeover minus new build) | C21: =IFERROR(C19-C20,"") -> -93450.338
A22: VERDICT | C22: =IF(C21="","",IF(C21<0,"The TAKEOVER comes out ahead","The NEW BUILD comes out ahead")) -> The TAKEOVER comes out ahead | J22: The verdict compares money, and money isn't everything: a takeover gives you customers and a space that already worked, and ties you to a layout that may not allow a one-way flow. Run the space through the "Site Visit Checklist" of kitchen-capacity-and-site.xlsx before you trust this cell.
A24: Your local takeover listings: the case plus fourteen rows for your area
A25: City or area | B25: Type of business | C25: Square feet | D25: Asking price | E25: Monthly rent | F25: Dollars per square foot | G25: Cost over the horizon | H25: Source
A26: The space you're looking at (the modeled case) | B26: Pastry and cake shop | C26: 914.93239 | D26: 43000 | E26: 1250 | F26: =IF(ISNUMBER(C26),IFERROR(D26/C26,""),"") -> 46.998008 | G26: =IF(ISNUMBER(E26),IFERROR(D26+E26*12*$C$13,""),"") -> 118000 | H26: The seller's listing
F27: =IF(ISNUMBER(C27),IFERROR(D27/C27,""),"") | G27: =IF(ISNUMBER(E27),IFERROR(D27+E27*12*$C$13,""),"")
F28: =IF(ISNUMBER(C28),IFERROR(D28/C28,""),"") | G28: =IF(ISNUMBER(E28),IFERROR(D28+E28*12*$C$13,""),"")
F29: =IF(ISNUMBER(C29),IFERROR(D29/C29,""),"") | G29: =IF(ISNUMBER(E29),IFERROR(D29+E29*12*$C$13,""),"")
F30: =IF(ISNUMBER(C30),IFERROR(D30/C30,""),"") | G30: =IF(ISNUMBER(E30),IFERROR(D30+E30*12*$C$13,""),"")
F31: =IF(ISNUMBER(C31),IFERROR(D31/C31,""),"") | G31: =IF(ISNUMBER(E31),IFERROR(D31+E31*12*$C$13,""),"")
F32: =IF(ISNUMBER(C32),IFERROR(D32/C32,""),"") | G32: =IF(ISNUMBER(E32),IFERROR(D32+E32*12*$C$13,""),"")
F33: =IF(ISNUMBER(C33),IFERROR(D33/C33,""),"") | G33: =IF(ISNUMBER(E33),IFERROR(D33+E33*12*$C$13,""),"")
F34: =IF(ISNUMBER(C34),IFERROR(D34/C34,""),"") | G34: =IF(ISNUMBER(E34),IFERROR(D34+E34*12*$C$13,""),"")
F35: =IF(ISNUMBER(C35),IFERROR(D35/C35,""),"") | G35: =IF(ISNUMBER(E35),IFERROR(D35+E35*12*$C$13,""),"")
F36: =IF(ISNUMBER(C36),IFERROR(D36/C36,""),"") | G36: =IF(ISNUMBER(E36),IFERROR(D36+E36*12*$C$13,""),"")
F37: =IF(ISNUMBER(C37),IFERROR(D37/C37,""),"") | G37: =IF(ISNUMBER(E37),IFERROR(D37+E37*12*$C$13,""),"")
F38: =IF(ISNUMBER(C38),IFERROR(D38/C38,""),"") | G38: =IF(ISNUMBER(E38),IFERROR(D38+E38*12*$C$13,""),"")
... F40: =IF(ISNUMBER(C40),IFERROR(D40/C40,""),"") | G40: =IF(ISNUMBER(E40),IFERROR(D40+E40*12*$C$13,""),"")
A41: Listings with a published rent | D41: =COUNT(E26:E40) -> 1
A42: Lowest asking price | D42: =IFERROR(MIN(D26:D40),"") -> 43000
A43: Highest asking price | D43: =IFERROR(MAX(D26:D40),"") -> 43000
...

Sheet VAT-GST & Cash
A1: VAT/GST and Startup Cash
A2: AI Chef Pro · aichef.pro — How to Open a Pastry Shop
A3: In the US, sales tax on what you buy is a cost and never comes back; this sheet's recovery rows are for VAT/GST (UK, Canada, Australia). The cash-out rows work everywhere.
A5: Block | B5: Pre-tax cost | C5: Tax paid | D5: Total with tax
A6: Build-out and building systems | B6: ='Startup Costs by Block'!K39 -> 81000 | C6: ='Startup Costs by Block'!L39 -> 0 | D6: ='Startup Costs by Block'!M39 -> 81000
A7: Production kitchen equipment | B7: ='Startup Costs by Block'!K40 -> 54296.238 | C7: ='Startup Costs by Block'!L40 -> 0 | D7: ='Startup Costs by Block'!M40 -> 54296.238
A8: Storefront and display | B8: ='Startup Costs by Block'!K41 -> 12684.1 | C8: ='Startup Costs by Block'!L41 -> 0 | D8: ='Startup Costs by Block'!M41 -> 12684.1
A9: Permits, plans and fees | B9: ='Startup Costs by Block'!K42 -> 7920 | C9: ='Startup Costs by Block'!L42 -> 0 | D9: ='Startup Costs by Block'!M42 -> 7920
A10: Security deposit | B10: ='Startup Costs by Block'!K43 -> 2400 | C10: ='Startup Costs by Block'!L43 -> 0 | D10: ='Startup Costs by Block'!M43 -> 2400
A11: Opening packaging | B11: ='Startup Costs by Block'!K44 -> 2500 | C11: ='Startup Costs by Block'!L44 -> 0 | D11: ='Startup Costs by Block'!M44 -> 2500
A12: Opening marketing | B12: ='Startup Costs by Block'!K45 -> 5000 | C12: ='Startup Costs by Block'!L45 -> 0 | D12: ='Startup Costs by Block'!M45 -> 5000
A13: Working capital | B13: ='Startup Costs by Block'!K46 -> 62115.28 | C13: ='Startup Costs by Block'!L46 -> 0 | D13: ='Startup Costs by Block'!M46 -> 62115.28
A14: STARTUP COSTS TOTAL | B14: =SUM(B6:B13) -> 227915.62 | C14: =SUM(C6:C13) -> 0 | D14: =SUM(D6:D13) -> 227915.62
A15: When it comes back (UK, Canada and Australia only; US sales tax on purchases is a cost and never comes back)
A16: How often you file your VAT/GST return (months) | B16: ='Settings'!B23 -> 3
A17: Months until you recover it | B17: ='Settings'!B24 -> 4
A18: Tax you pay up front (VAT/GST: recovered later; US sales tax: a cost) | B18: =C14 -> 0 | E18: A VAT/GST-registered business usually offsets it on its returns at the pace it collects tax, not on a fixed date; ask your accountant.
A20: The cash you need the day you open
A21: Startup costs before tax | B21: =B14 -> 227915.62
A22: Tax paid | B22: =C14 -> 0
A23: Total cash out, tax included | B23: =D14 -> 227915.62
A24: Of which, working capital (it's cash, not an investment) | B24: ='Startup Costs by Block'!K46 -> 62115.28
A25: Bank financing available | B25: ='Settings'!B25 -> 60000
A26: Owner's cash needed | B26: =IFERROR(B23-B25,"") -> 167915.62
A27: Months of fixed costs the working capital covers | B27: =IFERROR(B24/'Settings'!B18,"") -> 4 | E27: Below the minimum cushion in "Settings", the business depends on selling from the first week. It's the most common reason a shop that otherwise worked has to close.
A28: CASH VERDICT | B28: =IF(B26="","",IF(B26<=0,"The financing covers the cash out",IF(B27<'Settings'!$B$17,"Cushion too thin: review your working capital","You need to put in your own cash"))) -> You need to put in your own cash
A30: Needing your own cash isn't bad news: lenders rarely finance all of an opening, and one that did would leave you no room to maneuver. What is bad news is finding out the month you sign.

Sheet Summary
A1: Summary
A2: AI Chef Pro · aichef.pro — How to Open a Pastry Shop
A3: The figures to take to the lender. All calculated from the previous sheets; nothing is typed here.
A5: Figure | B5: Value | C5: Where it comes from | D5: What it says
A6: Build-out scenario chosen | B6: ='Settings'!B10 -> Middle | C6: Settings | D6: Low, middle or high. Changing it recalculates the whole workbook.
A7: Build-out | B7: ='Settings'!B12 -> 81000 | C7: Settings | D7: Square feet times the scenario's price. The biggest line and the one that overruns most during construction.
A8: Total startup costs before tax | B8: ='Startup Costs by Block'!K47 -> 227915.62 | C8: Startup Costs by Block | D8: Everything on a pre-tax basis: it's the figure you compare with any other budget.
A9: Tax paid | B9: ='Startup Costs by Block'!L47 -> 0 | C9: Startup Costs by Block | D9: In the US, sales tax on purchases is a cost you don't get back; with VAT/GST, money you front and recover at the pace you sell.
A10: Total cash out, tax included | B10: ='Startup Costs by Block'!M47 -> 227915.62 | C10: Startup Costs by Block | D10: What leaves the account. It's the number for the conversation with the lender.
A11: Subtotal comparable with published figures | B11: ='Startup Costs by Block'!K51 -> 160900.34 | C11: Startup Costs by Block | D11: Build-out, equipment, storefront, permits and marketing: what published estimates usually include.
A12: Deviation from the published reference | B12: ='Startup Costs by Block'!K53 | C12: Startup Costs by Block | D12: Compare it with a published reference you trust (K52 on "Startup Costs by Block"): the deviation gets explained, not dressed up.
A13: Production kitchen equipment | B13: ='Startup Costs by Block'!K40 -> 54296.238 | C13: Startup Costs by Block | D13: Without the optional items, which come marked "No".
A14: Storefront and display | B14: ='Startup Costs by Block'!K41 -> 12684.1 | C14: Startup Costs by Block | D14: Display cases, front-counter fixtures and POS.
A15: Working capital | B15: ='Startup Costs by Block'!K46 -> 62115.28 | C15: Startup Costs by Block | D15: Months of cushion times fixed costs. It's a startup cost, not caution.
A16: Owner's cash needed | B16: ='VAT-GST & Cash'!B26 -> 167915.62 | C16: VAT-GST & Cash | D16: Total cash out minus bank financing.
A17: Months of fixed costs covered | B17: ='VAT-GST & Cash'!B27 -> 4 | C17: VAT-GST & Cash | D17: Below three, the business depends on selling from the first week.
A18: Cash verdict | B18: ='VAT-GST & Cash'!B28 -> You need to put in your own cash | C18: VAT-GST & Cash | D18: Whether the financing covers the cash out or you need to put in money.
A19: Cost of the takeover over the horizon | B19: ='Takeover vs New Build'!C19 -> 144250 | C19: Takeover vs New Build | D19: Asking price, fit-out and rent for every year, plus the months closed before opening.
A20: Cost of the new build over the horizon | B20: ='Takeover vs New Build'!C20 -> 237700.34 | C20: Takeover vs New Build | D20: Comparable startup costs and rent for every year, plus the build-out months.
A21: Takeover or new build | B21: ='Takeover vs New Build'!C22 -> The TAKEOVER comes out ahead | C21: Takeover vs New Build | D21: It compares money. The layout of the space and the existing customers don't show up in this cell.
A23: If any of these figures doesn't add up for you, don't change it here: this sheet doesn't have a single editable cell. Go back to the sheet where it's born and change the setting or the amount. That's what keeps a summary and its source from saying different things.
