Workbook

Sheet 0. Assumptions
A1: ASSUMPTIONS — the RATES and DRIVERS of the model are typed here
A2: Change the GREEN cells: the rest of the workbook recalculates on its own. Expense items are typed on their own tab (also in green) and are not repeated here. Amounts are in your currency.
A3: BUSINESS ACTIVITY
A4: Customers per day (year-1 average) | B4: 165 | C4: Customers served per day, averaged over year 1, at the counter, to go and at the patio: about 400 on a busy July Saturday and about 40 on a January Tuesday (Kit estimate). It comes from dividing projected sales by the average check and the days you are open; compare it with the foot traffic on your own street on a summer afternoon and on a February one
A5: Average check (excl. sales tax) | B5: 7.5 | C5: Excl. sales tax, per person who buys: a double scoop, plus hand-packed pints, ice cream cakes to order and the winter hot chocolate. It is per person, not per register ticket: some people buy for two. The case mixes about 70% doubles in a cup or cone, 15% singles and kids' scoops, 10% pints and quarts and 5% sundaes and coffee (Kit estimate). The menu price incl. sales tax is in the row "Menu price incl. sales tax (calculated)" below
A6: Operating days per year | B6: 310 | C6: 365 days minus three weeks closed in January (vacation and refrigeration maintenance), Thanksgiving, Christmas and the Mondays from November to February. It is the SAME figure for the P&L, the break-even, the scenarios and the staffing hours
A7: Volume growth in year 2 | B7: 0.08 | C7: More repeat customers in the second summer, plus more ice cream cakes to order and catering. It applies to customers; payroll does NOT rise with this percentage: it grows with the hires you declare on the "Staffing" tab
A8: Volume growth in year 3 | B8: 0.05 | C8: On top of year 2. Conservative: the ceiling is set by the 18-flavor dipping cabinets and the July and August evenings
A9: Menu price incl. sales tax (calculated) | B9: =IFERROR(IF($B$5="","",$B$5*(1+SUMPRODUCT('3-Year P&L'!$E$10:$E$11,'3-Year P&L'!$G$10:$G$11))),"") -> 8.1 | C9: =IFERROR("Average check excl. sales tax plus the weighted sales tax of your sales lines ("&TEXT(SUMPRODUCT('3-Year P&L'!$E$10:$E$11,'3-Year P&L'!$G$10:$G$11)*100,"0")&"%), rounded. In the US, menu prices usually exclude sales tax and it is added at the register. "&"The example uses one rate for scoops, pints, cakes and drinks; some states tax packaged pints and whole cakes as groceries: then use your blended rate. In the UK, menu prices include VAT.","") -> Average check excl. sales tax plus the weighted sales tax of your sales lines (8%), rounded. In the US, menu prices usually exclude sales tax and it is added at the register. The example uses one rate for scoops, pints, cakes and drinks; some states tax packaged pints and whole cakes as groceries: then use your blended rate. In the UK, menu prices include VAT.
A10: SALES MIX AND COST OF GOODS SOLD
A11: FOOD share of total sales | B11: 0.9 | C11: Share of FOOD in total sales. It is an INPUT: change it here and the P&L, the cash flow and the sales tax collected recalculate on their own
A12: BEVERAGE share of total sales | B12: =IFERROR(IF(COUNT(B11)=0,"",1-B11),"") -> 0.1 | C12: Calculated as the remainder: food + beverage = 100%
A13: Cost of goods sold on FOOD sales | B13: 0.22 | C13: Cost of the ice cream base, flavorings and mix-ins, cones, tasting spoons and shrink as a share of ice cream sales. The case buys a pasteurized base from a licensed dairy, which costs more than making your own mix. Cost out every flavor every season: pistachio, cocoa and vanilla swing with the market
A14: Cost of goods sold on BEVERAGE sales | B14: 0.25 | C14: Espresso, hot chocolate, shakes, sodas and water as a share of their sales: soft drinks run higher than espresso. No alcohol
A15: Disposables and packaging as % of sales | B15: 0.045 | C15: Cups, cones, spoons, pint and quart containers, cake boxes and napkins. Use paper or other compostable cups for dine-in where your city requires it
A16: Delivery share of total sales | B16: 0.04 | C16: Hand-packed pints and quarts through DoorDash or Uber Eats on summer evenings: a pint travels well, a scoop does not. Pickup orders placed directly with you pay no commission
A17: Delivery platform fee | B17: 0.25 | C17: Average marketplace plan (Basic 15%, Premier 30%): check your contract. If you deliver yourself, enter 0
A18: Card processing fee | B18: 0.03 | C18: Card and mobile wallet (contactless) processing fees on total sales. Ask your POS provider for its rate
A19: LABOR
A20: Employer payroll taxes | B20: 0.1 | C20: FICA (Social Security 6.2% + Medicare 1.45%) + federal and state unemployment taxes (FUTA / SUTA) + workers' comp. About 10% in total: adjust it to your state and your insurance carrier
A21: Monthly pay periods per year (keep 12) | B21: 12 | C21: Annual gross pay = monthly gross pay × this number. Keep 12 in the US: it counts the monthly salaries the model pays in a year, not how often you run payroll (weekly or biweekly payroll pays the same annual amount)
A22: Federal minimum wage, annual full-time | B22: 15080 | C22: US federal minimum wage: 7.25 per hour × 2,080 hours = 15,080 per year for a full-time job. Your state or city may set a higher floor: enter it in the state / local minimum wage cell below. Check the current rates at dol.gov
A23: RENT AND FIXED COSTS
A24: Monthly rent | B24: 2500 | C24: About 1,000 sq ft (93 sq m): a production room of about 250 sq ft (23 sq m), a shop with 18-flavor dipping cabinets and 20 seats, storage and a restroom. Second-generation retail on a neighborhood main street or next to a park or school, at about $30 per sq ft per year (Kit estimate; asking rents average about $24.69 plus NNN). The book itself calculates the weight on sales in the "Rent / Sales" row of the P&L
A25: Security deposit (months of rent) | B25: 2 | C25: Two months of rent: commercial leases commonly ask for one to three, so check it with your attorney
A26: Monthly utilities (electricity, water, gas) | B26: 1300 | C26: Mostly electricity: about 30 kW of service, with the dipping cabinets running 24 hours a day, the batch freezer, the hardening cabinet and the air conditioning. Summer sends the bill up; ask the landlord or the utility for the space's billing history
A27: Insurance (per year) | B27: 4500 | C27: General liability (ask your broker for the per-occurrence limit) plus property insurance WITH equipment breakdown and food spoilage: a cabinet that fails in August is a tub lost for every flavor
A28: Miscellaneous and contingency as % of sales | B28: 0.01 | C28: Cushion for unbudgeted running costs (small repairs, tastings and samples)
A29: FINANCING
A30: Owner's equity contributed | B30: 95000 | C30: Owner's cash. Lenders usually expect an owner equity injection (often around 10% for SBA start-ups; many want 20-30%) toward the cash need
A31: Loan requested | B31: 162000 | C31: Principal requested. The "Financing" tab compares what you put in with the cash need on "Startup Costs" and tells you whether you have a surplus or a shortfall: adjust the loan with that figure. The example is an SBA 7(a) loan, which you apply for through your lender (SBA Microloans go up to $50,000)
A32: Nominal annual interest rate (not APR) | B32: 0.1 | C32: Annual nominal rate, not APR. The example is an SBA 7(a) loan through your lender at 10% (Prime plus a margin that depends on the loan size): ask two lenders for a quote before you set it. Refrigeration equipment is often leased: compare that too
A33: Loan term (years) | B33: 10 | C33: Total years, interest-only period included
A34: Interest-only period (years) | B34: 0 | C34: 0 by default: an SBA 7(a) loan is repaid from the start, so the example has no interest-only period. If your lender grants one, enter the years here and check the cash cushion for that year on the "Break-Even" tab
A35: Working capital (months of fixed costs) | B35: 3 | C35: Three months of fixed costs: the cushion for the first winter, when only about 15% of the year's sales come in from November to February while fixed costs stay flat
A36: TAXES
A37: Effective income tax rate (years 1-2) | B37: 0.25 | C37: Example: 21% federal rate for a C corporation plus state tax, rounded to 25%. If you operate as a sole proprietorship, LLC taxed as a pass-through or S corporation, the business itself pays 0% here and you pay tax on the profit personally: set this to 0 and budget for your personal tax separately. The model applies this rate to the first two years with positive taxable income
A38: Effective income tax rate (from year 3) | B38: 0.25 | C38: From the third year with positive taxable income. Same example rate (21% federal C corporation + state). Confirm the rate that applies to you with your accountant and change it here
A39: Sales tax rate on sales | B39: 0.08 | C39: Example rate: state + local sales tax combined. It varies widely by state and city: look up yours. UK: ice cream is standard-rated at 20% VAT, to take away too
A40: Sales tax rate on alcohol to go | B40: 0.08 | C40: One sales tax rate for the example (8%). Check your state and city: the same rate is used for the sales tax collected and for the menu price incl. sales tax. Recoverable input tax on purchases is 0: there is no credit for sales tax paid on purchases, so the book does not credit anything
...

Sheet Startup Costs
A1: ICE CREAM SHOP BUSINESS PLAN
A2: Startup costs — ice cream shop with on-site production
A3: US kit example (2026) — replace with your own quotes.
A5: Item | B5: Amount | C5: % of startup costs | D5: Notes | E5: Taxable / recoverable tax?
A6: STARTUP COSTS | B6: =IFERROR(IF(COUNT(B7:B28)=0,"",SUM(B7:B28)),"") -> 204100 | C6: =IFERROR(B6/$B$31,"") -> 0.79456132
A7: Architect, MEP drawings, plan review & permit fees | B7: 9000 | C7: =IFERROR(B7/$B$31,"") -> 0.035037001 | D7: Architect, MEP drawings, plan review with the health department (Food Code 8-201.11) and permit fees | E7: Yes
A8: Build-out of production room & shop (second-generation retail, ~1,000 sq ft) | B8: 48000 | C8: =IFERROR(B8/$B$31,"") -> 0.18686401 | D8: Build-out of a second-generation retail space of about 1,000 sq ft (93 sq m) with a production room of about 250 sq ft (23 sq m): tile or washable walls, non-slip floor, restroom and ceilings. Kit estimate: replace it with contractor quotes | E8: Yes
A9: Electrical service & panel (about 30 kW) | B9: 9000 | C9: =IFERROR(B9/$B$31,"") -> 0.035037001 | D9: About 30 kW for the dipping cabinets, batch freezer, hardening cabinet and air conditioning. Ask the utility about 3-phase service and amps before signing: a new service connection can take weeks | E9: Yes
A10: Plumbing, floor sinks, hand sinks, HVAC & condenser ventilation | B10: 10000 | C10: =IFERROR(B10/$B$31,"") -> 0.038930001 | D10: Floor sinks and drains in the production room, hand sinks and ventilation for the condenser units | E10: Yes
A11: Signage & storefront | B11: 5000 | C11: =IFERROR(B11/$B$31,"") -> 0.019465001 | D11: Say "made here in small batches" on the sign only if you really make it here; "homemade" or "house-made" only if it is true | E11: Yes
A12: Base refrigerator & flavor prep (41 °F or colder, stick blender, scales) | B12: 4500 | C12: =IFERROR(B12/$B$31,"") -> 0.017518501 | D12: Base case: you buy pasteurized base from a licensed dairy, keep it at 41 °F (5 °C) or colder and add only flavorings and mix-ins. Making your own mix adds a batch pasteurizer (about $25,000-45,000: get quotes) and, in many states, a dairy or frozen dessert manufacturer license: ask your state department of agriculture | E12: Yes
A13: Batch freezer (20 qt, horizontal) | B13: 30000 | C13: =IFERROR(B13/$B$31,"") -> 0.11679 | D13: A 20-qt Carpigiani lists at about $40,800; get two quotes before you close the loan, and reconditioned units cost less. Kit estimate on the low side of what is published, because professional brands rarely publish a price. A smaller 3-gallon (11-liter) countertop unit costs less if you start small | E13: Yes
A14: Hardening cabinet / blast freezer | B14: 9000 | C14: =IFERROR(B14/$B$31,"") -> 0.035037001 | D14: Takes the freshly batch-frozen ice cream to 0 °F (−18 °C) or colder in the core before it goes to the dipping cabinet or the freezer. Kit estimate: the sources on price are weak, so get quotes | E14: Yes
A15: Storage freezers (0 °F or colder) | B15: 7000 | C15: =IFERROR(B15/$B$31,"") -> 0.027251001 | D15: Storage freezers at 0 °F (−18 °C) or colder for the finished ice cream and the stock. There is no aging cabinet: the base arrives already aged and pasteurized from the dairy | E15: Yes
A16: Prep tables, 3-compartment sink, hand sinks, scales, pans & smallwares | B16: 8500 | C16: =IFERROR(B16/$B$31,"") -> 0.033090501 | D16: Stainless prep tables and shelves, a 3-compartment sink, hand sinks, scales, probe thermometers, 3-gallon (11-liter) tubs and pans, and strainers | E16: Yes
A17: Dipping cabinets (18 flavors) | B17: 11000 | C17: =IFERROR(B17/$B$31,"") -> 0.042823001 | D17: Two dipping cabinets with room for 18 flavors, plus two spots for the flavor of the day or a reserve. Cabinets for 12 flavors start at about $1,700-2,500 for budget models and reach about $12,300 for premium ones. Run 6-10 °F (−14 to −12 °C) depending on the manufacturer; 18 flavors in summer and 10-12 in winter is enough in a mid-size city | E17: Yes
A18: Front counter, dipper wells, espresso, waffle cone irons & hot fudge warmers | B18: 9000 | C18: =IFERROR(B18/$B$31,"") -> 0.035037001 | D18: Front counter, dipper wells with running water (Food Code 3-304.12), espresso machine and grinder, waffle cone irons and hot fudge warmers. Waffle cone irons usually need no exhaust hood: confirm it with your plan reviewer | E18: Yes
... A25: Opening inventory (base, flavorings, cones, cups, pint containers) | B25: 5000 | C25: =IFERROR(B25/$B$31,"") -> 0.019465001 | D25: Ice cream base, flavorings, cones, cups and pint containers | E25: Yes
A26: Security deposit | B26: =IFERROR(IF('0. Assumptions'!$B$24="","",'0. Assumptions'!$B$24*'0. Assumptions'!$B$25),"") -> 5000 | C26: =IFERROR(B26/$B$31,"") -> 0.019465001 | D26: =IFERROR(""&TEXT('0. Assumptions'!$B$25,"0")&IF('0. Assumptions'!$B$25=1," month"," months")&" of rent, from ""0. Assumptions"". Refundable when the lease ends: it is not depreciated and carries no tax","") -> 2 months of rent, from "0. Assumptions". Refundable when the lease ends: it is not depreciated and carries no tax | E26: No
A27: Rent paid before opening | B27: =IFERROR(IF('0. Assumptions'!$B$24="","",'0. Assumptions'!$B$24*'0. Assumptions'!$B$54),"") -> 5000 | C27: =IFERROR(B27/$B$31,"") -> 0.019465001 | D27: =IFERROR("Rent "&IF('0. Assumptions'!$B$54=1,"for the month","for the "&TEXT('0. Assumptions'!$B$54,"0")&" months")&" of build-out and permits before opening. It does not overlap the P&L, which starts on opening day: its twelve months are twelve trading months","") -> Rent for the 2 months of build-out and permits before opening. It does not overlap the P&L, which starts on opening day: its twelve months are twelve trading months | E27: Yes
A28: Build-out and setup contingency | B28: =IFERROR(IF(COUNT(B7,B8,B9,B10,B11)=0,"",ROUND((B7+B8+B9+B10+B11)*'0. Assumptions'!$B$55,0)),"") -> 8100 | C28: =IFERROR(B28/$B$31,"") -> 0.031533301 | D28: =IFERROR("At "&TEXT('0. Assumptions'!$B$55,"0%")&" of the BUILD-OUT items of this block (architect, MEP drawings, plan review & permit fees; build-out of production room & shop; electrical service & panel; plumbing, floor sinks, hand sinks, HVAC & condenser ventilation; "&"signage & storefront), not of the whole block: the equipment and the other items are left out. No lender funds a build-out without a cushion: the percentage is in ""0. Assumptions""","") -> At 10% of the BUILD-OUT items of this block (architect, MEP drawings, plan review & permit fees; build-out of production room & shop; electrical service & panel; plumbing, floor sinks, hand sinks, HVAC & condenser ventilation; signage & storefront), not of the whole block: the equipment and the other items are left out. No lender funds a build-out without a cushion: the percentage is in "0. Assumptions" | E28: Yes
A29: WORKING CAPITAL | B29: =IFERROR(IF(B30="","",B30),"") -> 52771.3 | C29: =IFERROR(B29/$B$31,"") -> 0.20543868
A30: Operating cushion until break-even | B30: =IFERROR(IF('0. Assumptions'!$B$35*('3-Year P&L'!$B$38-'3-Year P&L'!$B$36)=0,"",'0. Assumptions'!$B$35*('3-Year P&L'!$B$38-'3-Year P&L'!$B$36)/12),"") -> 52771.3 | C30: =IFERROR(B30/$B$31,"") -> 0.20543868 | D30: =IFERROR("Covers "&TEXT('0. Assumptions'!$B$35,"0")&IF('0. Assumptions'!$B$35=1," month"," months")&" of year-1 CASH fixed costs (the P&L fixed costs minus depreciation, which is not paid out), the minimum the Instructions of this workbook ask for","") -> Covers 3 months of year-1 CASH fixed costs (the P&L fixed costs minus depreciation, which is not paid out), the minimum the Instructions of this workbook ask for | E30: No
A31: TOTAL STARTUP COSTS (sum of the blocks) | B31: =IFERROR(B6+B29,"") -> 256871.3 | D31: =IFERROR("The percentages in column C are read on this figure, which includes the working capital ("&TEXT(C29,"0%")&" of the total). To compare the breakdown with another plan, use the CAPEX row below.","") -> The percentages in column C are read on this figure, which includes the working capital (21% of the total). To compare the breakdown with another plan, use the CAPEX row below.
A32: CAPEX (startup costs excluding working capital) | B32: =IFERROR(B31-B29,"") -> 204100 | D32: What you buy: build-out, equipment, launch and formation costs. The cash cushion is not an investment: it is working capital
A33: Recoverable input tax on capex | B33: =IFERROR(IF(B31="","",SUMIF($E$7:$E$28,"Yes",$B$7:$B$28)*'0. Assumptions'!$B$41),"") -> 0 | D33: =IFERROR("At "&TEXT('0. Assumptions'!$B$41,"0%")&" on the items marked ""Yes"" in the tax column. US: the sales tax you pay on equipment is part of its cost and is not recovered, so this rate is 0. UK (VAT-registered): 20%, reclaimed on your VAT return, but you pay it first, so the loan has to cover it","") -> At 0% on the items marked "Yes" in the tax column. US: the sales tax you pay on equipment is part of its cost and is not recovered, so this rate is 0. UK (VAT-registered): 20%, reclaimed on your VAT return, but you pay it first, so the loan has to cover it
A34: TOTAL CASH NEEDED AT LAUNCH | B34: =IFERROR(B31+B33,"") -> 256871.3 | D34: This is the figure the Financing tab has to cover
A35: DEPRECIATION BASES (not added to startup costs)
A36: Build-out, fixtures and setup | B36: =IFERROR(IF(B7="","",B7+B8+B9+B10+B11+B28),"") -> 89100 | D36: =IFERROR("Depreciated over "&TEXT('0. Assumptions'!$B$44,"0")&" years","") -> Depreciated over 10 years
A37: Machinery, furniture and equipment | B37: =IFERROR(IF(B12="","",B12+B13+B14+B15+B16+B17+B18+B19+B20+B21),"") -> 90000 | D37: =IFERROR("Depreciated over "&TEXT('0. Assumptions'!$B$45,"0")&" years","") -> Depreciated over 7 years
A38: Annual depreciation of fixed assets | B38: =IFERROR(B36/MAX(1,'0. Assumptions'!$B$44)+B37/MAX(1,'0. Assumptions'!$B$45),"") -> 21767.143 | D38: =IFERROR("Not depreciated, because they are not fixed assets: ice cream training course; branding, website, photos & launch; LLC, legal, permits & food safety plan; opening inventory; "&"security deposit; pre-opening rent and the working capital reserve. They add up to "&TEXT(B31-B36-B37,"#,##0")&" of the "&TEXT(B31,"#,##0")&" total investment.","") -> Not depreciated, because they are not fixed assets: ice cream training course; branding, website, photos & launch; LLC, legal, permits & food safety plan; opening inventory; security deposit; pre-opening rent and the working capital reserve. They add up to 77771 of the 256871 total investment.

Sheet 3-Year P&L
A1: PROFIT AND LOSS STATEMENT — 3 YEARS
A2: Base case — ice cream shop with on-site production
A4: Item | B4: Year 1 | C4: Year 2 | D4: Year 3 | E4: % of sales (year 1) | F4: Notes | G4: Sales tax rate on the line (%)
A5: REVENUE
A6: Customers per day (average) | B6: =IFERROR(IF('0. Assumptions'!$B$4="","",'0. Assumptions'!$B$4),"") -> 165 | C6: =IFERROR(B6*(1+'0. Assumptions'!$B$7),"") -> 178.2 | D6: =IFERROR(C6*(1+'0. Assumptions'!$B$8),"") -> 187.11 | F6: Growth for years 2 and 3 is set in "0. Assumptions"
A7: Average check (excl. sales tax) | B7: =IFERROR(IF('0. Assumptions'!$B$5="","",'0. Assumptions'!$B$5),"") -> 7.5 | C7: =IFERROR(IF(B7="","",B7),"") -> 7.5 | D7: =IFERROR(IF(C7="","",C7),"") -> 7.5 | F7: Held constant at year-1 prices: a price increase is a separate decision
A8: Operating days per year | B8: =IFERROR(IF('0. Assumptions'!$B$6="","",'0. Assumptions'!$B$6),"") -> 310 | C8: =IFERROR(IF(B8="","",B8),"") -> 310 | D8: =IFERROR(IF(C8="","",C8),"") -> 310
A9: TOTAL REVENUE (excl. sales tax) | B9: =IFERROR(IF(B6*B7*B8=0,"",B6*B7*B8),"") -> 383625 | C9: =IFERROR(IF(C6*C7*C8=0,"",C6*C7*C8),"") -> 414315 | D9: =IFERROR(IF(D6*D7*D8=0,"",D6*D7*D8),"") -> 435030.75 | E9: =IFERROR(IF(B9="","",1),"") -> 1
A10: Ice cream sales (scoops, sundaes, pints & quarts to go, ice cream cakes, catering) | B10: =IFERROR(IF(B9="","",B9*$E$10),"") -> 345262.5 | C10: =IFERROR(IF(C9="","",C9*$E$10),"") -> 372883.5 | D10: =IFERROR(IF(D9="","",D9*$E$10),"") -> 391527.67 | E10: =IFERROR(IF('0. Assumptions'!$B$11="","",'0. Assumptions'!$B$11),"") -> 0.9 | F10: Share of total sales. Within this line, roughly: scoops, cups, cones and sundaes in the shop 65%, hand-packed pints and quarts to go 15%, ice cream cakes and holiday pies 10%, catering 5% and pints through delivery marketplaces the rest (see "Delivery share of total sales"). One sales tax rate in the example; in some states a packaged pint or a whole cake may be taxed as a grocery, so check your state | G10: =IFERROR(IF(B9="","",'0. Assumptions'!$B$39),"") -> 0.08
A11: Coffee & beverages (espresso, hot chocolate, sodas, water) | B11: =IFERROR(IF(B9="","",B9*$E$11),"") -> 38362.5 | C11: =IFERROR(IF(C9="","",C9*$E$11),"") -> 41431.5 | D11: =IFERROR(IF(D9="","",D9*$E$11),"") -> 43503.075 | E11: =IFERROR(IF('0. Assumptions'!$B$12="","",'0. Assumptions'!$B$12),"") -> 0.1 | F11: Espresso, hot chocolate, shakes, sodas and water. No alcohol | G11: =IFERROR(IF(B9="","",('0. Assumptions'!$B$62*((1-'0. Assumptions'!$B$16)*'0. Assumptions'!$B$63+'0. Assumptions'!$B$16*'0. Assumptions'!$B$40)+(1-'0. Assumptions'!$B$62)*'0. Assumptions'!$B$39)),"") -> 0.08
A12: VARIABLE COSTS
A13: Cost of goods sold — food | B13: =IFERROR(IF(B9="","",B9*'0. Assumptions'!$B$11*'0. Assumptions'!$B$13),"") -> 75957.75 | C13: =IFERROR(IF(C9="","",C9*'0. Assumptions'!$B$11*'0. Assumptions'!$B$13),"") -> 82034.37 | D13: =IFERROR(IF(D9="","",D9*'0. Assumptions'!$B$11*'0. Assumptions'!$B$13),"") -> 86136.088 | E13: =IFERROR(B13/$B$9,"") -> 0.198 | F13: =IFERROR("At "&TEXT('0. Assumptions'!$B$13,"0%")&" of FOOD sales (the ice cream line), not of total sales: beverages have their own line · purchased base, flavorings, mix-ins and toppings, cones, "&"tasting samples and production waste: check it against your dairy and distributor invoices","") -> At 22% of FOOD sales (the ice cream line), not of total sales: beverages have their own line · purchased base, flavorings, mix-ins and toppings, cones, tasting samples and production waste: check it against your dairy and distributor invoices | G13: 0
A14: Cost of goods sold — beverage | B14: =IFERROR(IF(B9="","",B9*'0. Assumptions'!$B$12*'0. Assumptions'!$B$14),"") -> 9590.625 | C14: =IFERROR(IF(C9="","",C9*'0. Assumptions'!$B$12*'0. Assumptions'!$B$14),"") -> 10357.875 | D14: =IFERROR(IF(D9="","",D9*'0. Assumptions'!$B$12*'0. Assumptions'!$B$14),"") -> 10875.769 | E14: =IFERROR(B14/$B$9,"") -> 0.025 | F14: =IFERROR("At "&TEXT('0. Assumptions'!$B$14,"0%")&" of BEVERAGE sales","") -> At 25% of BEVERAGE sales | G14: =IFERROR(IF(B9="","",'0. Assumptions'!$B$41),"") -> 0
A15: Disposables and packaging | B15: =IFERROR(IF(B9="","",B9*'0. Assumptions'!$B$15),"") -> 17263.125 | C15: =IFERROR(IF(C9="","",C9*'0. Assumptions'!$B$15),"") -> 18644.175 | D15: =IFERROR(IF(D9="","",D9*'0. Assumptions'!$B$15),"") -> 19576.384 | E15: =IFERROR(B15/$B$9,"") -> 0.045 | G15: =IFERROR(IF(B9="","",'0. Assumptions'!$B$41),"") -> 0
A16: Delivery platform fees | B16: =IFERROR(IF(B9="","",B9*'0. Assumptions'!$B$16*'0. Assumptions'!$B$17),"") -> 3836.25 | C16: =IFERROR(IF(C9="","",C9*'0. Assumptions'!$B$16*'0. Assumptions'!$B$17),"") -> 4143.15 | D16: =IFERROR(IF(D9="","",D9*'0. Assumptions'!$B$16*'0. Assumptions'!$B$17),"") -> 4350.3075 | E16: =IFERROR(B16/$B$9,"") -> 0.01 | F16: Applied to the sales of THAT CHANNEL. With 0% delivery in Assumptions, this line is zero | G16: =IFERROR(IF(B9="","",'0. Assumptions'!$B$41),"") -> 0
A17: Card processing fees | B17: =IFERROR(IF(B9="","",B9*'0. Assumptions'!$B$18),"") -> 11508.75 | C17: =IFERROR(IF(C9="","",C9*'0. Assumptions'!$B$18),"") -> 12429.45 | D17: =IFERROR(IF(D9="","",D9*'0. Assumptions'!$B$18),"") -> 13050.922 | E17: =IFERROR(B17/$B$9,"") -> 0.03 | F17: Card processing fees are not subject to sales tax: no tax is recovered or deducted for them | G17: 0
A18: Miscellaneous and contingency | B18: =IFERROR(IF(B9="","",B9*'0. Assumptions'!$B$28),"") -> 3836.25 | C18: =IFERROR(IF(C9="","",C9*'0. Assumptions'!$B$28),"") -> 4143.15 | D18: =IFERROR(IF(D9="","",D9*'0. Assumptions'!$B$28),"") -> 4350.3075 | E18: =IFERROR(B18/$B$9,"") -> 0.01 | F18: =IFERROR("At "&TEXT('0. Assumptions'!$B$28,"0%")&" of sales. It is a VARIABLE cost: it moves with revenue, so it cannot sit in fixed costs","") -> At 1% of sales. It is a VARIABLE cost: it moves with revenue, so it cannot sit in fixed costs | G18: =IFERROR(IF(B9="","",'0. Assumptions'!$B$41),"") -> 0
A19: TOTAL VARIABLE COSTS | B19: =IFERROR(IF(B9="","",SUM(B13:B18)),"") -> 121992.75 | C19: =IFERROR(IF(C9="","",SUM(C13:C18)),"") -> 131752.17 | D19: =IFERROR(IF(D9="","",SUM(D13:D18)),"") -> 138339.78 | E19: =IFERROR(B19/$B$9,"") -> 0.318
A20: GROSS MARGIN | B20: =IFERROR(IF(B9="","",B9-B19),"") -> 261632.25 | C20: =IFERROR(IF(C9="","",C9-C19),"") -> 282562.83 | D20: =IFERROR(IF(D9="","",D9-D19),"") -> 296690.97 | E20: =IFERROR(B20/$B$9,"") -> 0.682
A21: FIXED COSTS
A22: Rent | B22: =IFERROR(IF(B9="","",'0. Assumptions'!$B$24*12),"") -> 30000 | C22: =IFERROR(IF(C9="","",B22*(1+'0. Assumptions'!$B$48)),"") -> 30000 | D22: =IFERROR(IF(D9="","",C22*(1+'0. Assumptions'!$B$48)),"") -> 30000 | E22: =IFERROR(B22/$B$9,"") -> 0.078201369 | F22: The monthly amount is on the "0. Assumptions" tab; here it is multiplied by twelve. The two months of rent before opening are on the "Startup Costs" tab and are NOT counted twice | G22: =IFERROR(IF(B9="","",'0. Assumptions'!$B$41),"") -> 0
A23: Labor (wages + employer payroll taxes) | B23: =IFERROR(IF(B9="","",Staffing!$G$11),"") -> 128185.2 | C23: =IFERROR(IF(C9="","",Staffing!$B$15),"") -> 136185.2 | D23: =IFERROR(IF(D9="","",Staffing!$B$16),"") -> 144185.2 | E23: =IFERROR(B23/$B$9,"") -> 0.33414194 | F23: Comes from the Staffing tab: it is the SAME number, not a separate estimate. Years 2 and 3 add the new hires declared on that tab, not a percentage of volume | G23: 0
A24: Utilities (electricity, water, gas) | B24: =IFERROR(IF(B9="","",'0. Assumptions'!$B$26*12),"") -> 15600 | C24: =IFERROR(IF(C9="","",B24*(1+'0. Assumptions'!$B$48)),"") -> 15600 | D24: =IFERROR(IF(D9="","",C24*(1+'0. Assumptions'!$B$48)),"") -> 15600 | E24: =IFERROR(B24/$B$9,"") -> 0.040664712 | F24: Enter the monthly bills excl. sales tax. The workbook applies a single tax treatment to this whole line, the one in the column next to it; if one utility is taxed differently in your area, give it its own line | G24: =IFERROR(IF(B9="","",'0. Assumptions'!$B$41),"") -> 0
A25: Insurance (general liability, property, equipment breakdown + food spoilage) | B25: =IFERROR(IF(B9="","",'0. Assumptions'!$B$27),"") -> 4500 | C25: =IFERROR(IF(C9="","",B25*(1+'0. Assumptions'!$B$48)),"") -> 4500 | D25: =IFERROR(IF(D9="","",C25*(1+'0. Assumptions'!$B$48)),"") -> 4500 | E25: =IFERROR(B25/$B$9,"") -> 0.011730205 | F25: Insurance premiums are not subject to sales tax: there is no recoverable tax on them | G25: 0
A26: Accounting & bookkeeping | B26: 3000 | C26: =IFERROR(IF(C9="","",B26*(1+'0. Assumptions'!$B$48)),"") -> 3000 | D26: =IFERROR(IF(D9="","",C26*(1+'0. Assumptions'!$B$48)),"") -> 3000 | E26: =IFERROR(B26/$B$9,"") -> 0.0078201369 | F26: Bookkeeping, income and sales tax returns, and payroll for your seasonal W-2 staff | G26: =IFERROR(IF(B9="","",'0. Assumptions'!$B$41),"") -> 0
A27: Refrigeration service contract (EPA 608-certified tech) | B27: 2400 | C27: =IFERROR(IF(C9="","",B27*(1+'0. Assumptions'!$B$48)),"") -> 2400 | D27: =IFERROR(IF(D9="","",C27*(1+'0. Assumptions'!$B$48)),"") -> 2400 | E27: =IFERROR(B27/$B$9,"") -> 0.0062561095 | F27: Service on the dipping cabinets, hardening cabinet, batch freezer and freezers before summer and during the January closing. Refrigerant is handled only by an EPA 608-certified technician: your staff never tops it up | G27: =IFERROR(IF(B9="","",'0. Assumptions'!$B$41),"") -> 0
A28: Seasonal marketing | B28: 4500 | C28: =IFERROR(IF(C9="","",B28*(1+'0. Assumptions'!$B$48)),"") -> 4500 | D28: =IFERROR(IF(D9="","",C28*(1+'0. Assumptions'!$B$48)),"") -> 4500 | E28: =IFERROR(B28/$B$9,"") -> 0.011730205 | F28: Social media, Google Business Profile, signage and the opening campaign each season, plus the ice cream cake and holiday pie campaign | G28: =IFERROR(IF(B9="","",'0. Assumptions'!$B$41),"") -> 0
A29: Software, POS & phone | B29: 1800 | C29: =IFERROR(IF(C9="","",B29*(1+'0. Assumptions'!$B$48)),"") -> 1800 | D29: =IFERROR(IF(D9="","",C29*(1+'0. Assumptions'!$B$48)),"") -> 1800 | E29: =IFERROR(B29/$B$9,"") -> 0.0046920821 | F29: POS subscription that reports sales tax, phone and internet | G29: =IFERROR(IF(B9="","",'0. Assumptions'!$B$41),"") -> 0
A30: Cleaning supplies, uniforms & laundry | B30: 1500 | C30: =IFERROR(IF(C9="","",B30*(1+'0. Assumptions'!$B$48)),"") -> 1500 | D30: =IFERROR(IF(D9="","",C30*(1+'0. Assumptions'!$B$48)),"") -> 1500 | E30: =IFERROR(B30/$B$9,"") -> 0.0039100684 | F30: Cleaning and sanitizing supplies, uniform laundry, gloves for working at 0 °F (−18 °C) and any lab tests your food safety plan sets | G30: =IFERROR(IF(B9="","",'0. Assumptions'!$B$41),"") -> 0
A31: Sidewalk café / patio permit (your city's fee) | B31: 500 | C31: =IFERROR(IF(C9="","",B31*(1+'0. Assumptions'!$B$48)),"") -> 500 | D31: =IFERROR(IF(D9="","",C31*(1+'0. Assumptions'!$B$48)),"") -> 500 | E31: =IFERROR(B31/$B$9,"") -> 0.0013033561 | F31: Sidewalk space for 5 tables in season. Every city sets its own fee and this plan has not read any: replace this figure with your city's | G31: =IFERROR(IF(B9="","",'0. Assumptions'!$B$41),"") -> 0
A32: Waste & recycling | B32: 1200 | C32: =IFERROR(IF(C9="","",B32*(1+'0. Assumptions'!$B$48)),"") -> 1200 | D32: =IFERROR(IF(D9="","",C32*(1+'0. Assumptions'!$B$48)),"") -> 1200 | E32: =IFERROR(B32/$B$9,"") -> 0.0031280547 | F32: Cardboard, packaging and organic waste from the production room, through a licensed hauler or the city service | G32: =IFERROR(IF(B9="","",'0. Assumptions'!$B$41),"") -> 0
A33: Pest control | B33: 600 | C33: =IFERROR(IF(C9="","",B33*(1+'0. Assumptions'!$B$48)),"") -> 600 | D33: =IFERROR(IF(D9="","",C33*(1+'0. Assumptions'!$B$48)),"") -> 600 | E33: =IFERROR(B33/$B$9,"") -> 0.0015640274 | F33: Licensed pest control company; part of your HACCP-based food safety plan | G33: =IFERROR(IF(B9="","",'0. Assumptions'!$B$41),"") -> 0
A34: Music licensing (ASCAP/BMI/SESAC) | B34: 600 | C34: =IFERROR(IF(C9="","",B34*(1+'0. Assumptions'!$B$48)),"") -> 600 | D34: =IFERROR(IF(D9="","",C34*(1+'0. Assumptions'!$B$48)),"") -> 600 | E34: =IFERROR(B34/$B$9,"") -> 0.0015640274 | F34: ASCAP, BMI and SESAC are separate licensing organizations; the fee depends on the size and capacity of your shop. Only needed if you play music | G34: =IFERROR(IF(B9="","",'0. Assumptions'!$B$41),"") -> 0
A35: Food safety & OSHA training (CFPM, food handler cards, allergens) | B35: 500 | C35: =IFERROR(IF(C9="","",B35*(1+'0. Assumptions'!$B$48)),"") -> 500 | D35: =IFERROR(IF(D9="","",C35*(1+'0. Assumptions'!$B$48)),"") -> 500 | E35: =IFERROR(B35/$B$9,"") -> 0.0013033561 | F35: Certified Food Protection Manager and food handler cards, allergen training and OSHA basics (cold, slips, cuts) | G35: =IFERROR(IF(B9="","",'0. Assumptions'!$B$41),"") -> 0
A36: Depreciation of fixed assets | B36: =IFERROR(IF(B9="","",'Startup Costs'!$B$38),"") -> 21767.143 | C36: =IFERROR(IF(C9="","",B36),"") -> 21767.143 | D36: =IFERROR(IF(D9="","",B36),"") -> 21767.143 | E36: =IFERROR(B36/$B$9,"") -> 0.056740679 | F36: Comes from the depreciation bases on the Startup Costs tab: real fixed assets only. It does NOT rise with inflation: it is a charge on the HISTORICAL cost of the assets | G36: 0
A37: Interest expense (loan interest) | B37: =IFERROR(IF(B9="","",Financing!$B$44),"") -> 16200 | C37: =IFERROR(IF(C9="","",Financing!$B$46),"") -> 15183.525 | D37: =IFERROR(IF(D9="","",Financing!$B$48),"") -> 14065.402 | E37: =IFERROR(B37/$B$9,"") -> 0.042228739 | F37: Only INTEREST is an expense. Principal repaid appears on the cash flow tab | G37: 0
A38: TOTAL FIXED COSTS | B38: =IFERROR(IF(B9="","",SUM(B22:B37)),"") -> 232852.34 | C38: =IFERROR(IF(C9="","",SUM(C22:C37)),"") -> 239835.87 | D38: =IFERROR(IF(D9="","",SUM(D22:D37)),"") -> 246717.74 | E38: =IFERROR(B38/$B$9,"") -> 0.60697906
A39: Recoverable input tax on variable costs | B39: =IFERROR(IF(B9="","",SUMPRODUCT(B13:B18,G13:G18)),"") -> 0 | C39: =IFERROR(IF(C9="","",SUMPRODUCT(C13:C18,G13:G18)),"") -> 0 | D39: =IFERROR(IF(D9="","",SUMPRODUCT(D13:D18,G13:G18)),"") -> 0 | F39: Each line at ITS OWN rate, read from the column next to it. It is what the cash flow tab overpays to suppliers and later deducts (zero wherever no tax is recoverable)
A40: Recoverable input tax on fixed costs | B40: =IFERROR(IF(B9="","",SUMPRODUCT(B22:B37,G22:G37)),"") -> 0 | C40: =IFERROR(IF(C9="","",SUMPRODUCT(C22:C37,G22:G37)),"") -> 0 | D40: =IFERROR(IF(D9="","",SUMPRODUCT(D22:D37,G22:G37)),"") -> 0
A41: PRE-TAX INCOME (EBT) | B41: =IFERROR(IF(B9="","",B20-B38),"") -> 28779.907 | C41: =IFERROR(IF(C9="","",C20-C38),"") -> 42726.963 | D41: =IFERROR(IF(D9="","",D20-D38),"") -> 49973.227 | E41: =IFERROR(B41/$B$9,"") -> 0.075020937
...

Sheet Break-Even
A1: BREAK-EVEN
A2: Break-even — ice cream shop with on-site production
A4: Variable | B4: Year 1 | C4: Year 2 | D4: Year 3 | E4: Notes
A5: BASE DATA BY YEAR
A6: Annual fixed costs | B6: =IFERROR(IF('3-Year P&L'!$B$9="","",'3-Year P&L'!$B$38),"") -> 232852.34 | C6: =IFERROR(IF('3-Year P&L'!$C$9="","",'3-Year P&L'!$C$38),"") -> 239835.87 | D6: =IFERROR(IF('3-Year P&L'!$D$9="","",'3-Year P&L'!$D$38),"") -> 246717.74 | E6: The SAME fixed costs as the P&L. Each year has its own, which is why the threshold cannot be a single one for all three years
A7: Monthly fixed costs | B7: =IFERROR(IF('3-Year P&L'!$B$9="","",B6/12),"") -> 19404.362 | C7: =IFERROR(IF('3-Year P&L'!$C$9="","",C6/12),"") -> 19986.322 | D7: =IFERROR(IF('3-Year P&L'!$D$9="","",D6/12),"") -> 20559.812
A8: Average check (excl. sales tax) | B8: =IFERROR(IF('3-Year P&L'!$B$9="","",'3-Year P&L'!$B$7),"") -> 7.5 | C8: =IFERROR(IF('3-Year P&L'!$C$9="","",'3-Year P&L'!$C$7),"") -> 7.5 | D8: =IFERROR(IF('3-Year P&L'!$D$9="","",'3-Year P&L'!$D$7),"") -> 7.5
A9: Variable cost per customer | B9: =IFERROR(IF('3-Year P&L'!$B$9="","",'3-Year P&L'!$B$19/('3-Year P&L'!$B$6*'3-Year P&L'!$B$8)),"") -> 2.385 | C9: =IFERROR(IF('3-Year P&L'!$C$9="","",'3-Year P&L'!$C$19/('3-Year P&L'!$C$6*'3-Year P&L'!$C$8)),"") -> 2.385 | D9: =IFERROR(IF('3-Year P&L'!$D$9="","",'3-Year P&L'!$D$19/('3-Year P&L'!$D$6*'3-Year P&L'!$D$8)),"") -> 2.385 | E9: Comes from the P&L total variable costs, not from a separate estimate. It includes miscellaneous and contingency, which is a percentage of sales
A10: Contribution margin per customer | B10: =IFERROR(IF('3-Year P&L'!$B$9="","",B8-B9),"") -> 5.115 | C10: =IFERROR(IF('3-Year P&L'!$C$9="","",C8-C9),"") -> 5.115 | D10: =IFERROR(IF('3-Year P&L'!$D$9="","",D8-D9),"") -> 5.115 | E10: Average check minus unit variable cost
A11: Operating days per year | B11: =IFERROR(IF('3-Year P&L'!$B$9="","",'3-Year P&L'!$B$8),"") -> 310 | C11: =IFERROR(IF('3-Year P&L'!$C$9="","",'3-Year P&L'!$C$8),"") -> 310 | D11: =IFERROR(IF('3-Year P&L'!$D$9="","",'3-Year P&L'!$D$8),"") -> 310 | E11: The same calendar as the P&L and the scenarios
A12: Principal repaid in the year | B12: =IFERROR(IF('3-Year P&L'!$B$9="","",Financing!$B$45),"") -> 10164.754 | C12: =IFERROR(IF('3-Year P&L'!$C$9="","",Financing!$B$47),"") -> 11181.229 | D12: =IFERROR(IF('3-Year P&L'!$D$9="","",Financing!$B$49),"") -> 12299.352 | E12: Principal is NOT a P&L expense, but it leaves the cash account. Without it, the published break-even threshold would sit below the real one
A13: ACCOUNTING BREAK-EVEN (includes depreciation)
A14: Customers needed per year | B14: =IFERROR(IF('3-Year P&L'!$B$9="","",IF(B10<=0,"",B6/B10)),"") -> 45523.43 | C14: =IFERROR(IF('3-Year P&L'!$C$9="","",IF(C10<=0,"",C6/C10)),"") -> 46888.733 | D14: =IFERROR(IF('3-Year P&L'!$D$9="","",IF(D10<=0,"",D6/D10)),"") -> 48234.163
A15: Customers needed per day | B15: =IFERROR(IF('3-Year P&L'!$B$9="","",B14/B11),"") -> 146.84977 | C15: =IFERROR(IF('3-Year P&L'!$C$9="","",C14/C11),"") -> 151.25398 | D15: =IFERROR(IF('3-Year P&L'!$D$9="","",D14/D11),"") -> 155.59407
A16: Revenue needed per year | B16: =IFERROR(IF('3-Year P&L'!$B$9="","",B14*B8),"") -> 341425.72 | C16: =IFERROR(IF('3-Year P&L'!$C$9="","",C14*C8),"") -> 351665.49 | D16: =IFERROR(IF('3-Year P&L'!$D$9="","",D14*D8),"") -> 361756.22
A17: CASH BREAK-EVEN (loan payments in, depreciation out)
A18: Cash fixed costs + principal repaid for the year | B18: =IFERROR(IF('3-Year P&L'!$B$9="","",B6-'3-Year P&L'!$B$36+B12),"") -> 221249.95 | C18: =IFERROR(IF('3-Year P&L'!$C$9="","",C6-'3-Year P&L'!$C$36+C12),"") -> 229249.95 | D18: =IFERROR(IF('3-Year P&L'!$D$9="","",D6-'3-Year P&L'!$D$36+D12),"") -> 237249.95 | E18: The P&L fixed costs without depreciation (which is not paid in cash) and WITH principal repaid (which is). This is the threshold that decides whether cash holds up
A19: Customers needed per year (cash) | B19: =IFERROR(IF('3-Year P&L'!$B$9="","",IF(B10<=0,"",B18/B10)),"") -> 43255.123 | C19: =IFERROR(IF('3-Year P&L'!$C$9="","",IF(C10<=0,"",C18/C10)),"") -> 44819.15 | D19: =IFERROR(IF('3-Year P&L'!$D$9="","",IF(D10<=0,"",D18/D10)),"") -> 46383.178
A20: Customers needed per day (cash) | B20: =IFERROR(IF('3-Year P&L'!$B$9="","",B19/B11),"") -> 139.53265 | C20: =IFERROR(IF('3-Year P&L'!$C$9="","",C19/C11),"") -> 144.5779 | D20: =IFERROR(IF('3-Year P&L'!$D$9="","",D19/D11),"") -> 149.62315
A21: Revenue needed per year (cash) | B21: =IFERROR(IF('3-Year P&L'!$B$9="","",B19*B8),"") -> 324413.42 | C21: =IFERROR(IF('3-Year P&L'!$C$9="","",C19*C8),"") -> 336143.63 | D21: =IFERROR(IF('3-Year P&L'!$D$9="","",D19*D8),"") -> 347873.83
A22: COMPARISON WITH THE PLAN
A23: Customers per day forecast in the plan | B23: =IFERROR(IF('3-Year P&L'!$B$9="","",'3-Year P&L'!$B$6),"") -> 165 | C23: =IFERROR(IF('3-Year P&L'!$C$9="","",'3-Year P&L'!$C$6),"") -> 178.2 | D23: =IFERROR(IF('3-Year P&L'!$D$9="","",'3-Year P&L'!$D$6),"") -> 187.11
A24: Cushion above CASH break-even (%) | B24: =IFERROR(IF('3-Year P&L'!$B$9="","",B23/B20-1),"") -> 0.18251889 | C24: =IFERROR(IF('3-Year P&L'!$C$9="","",C23/C20-1),"") -> 0.23255349 | D24: =IFERROR(IF('3-Year P&L'!$D$9="","",D23/D20-1),"") -> 0.25054175 | E24: How far you can fall before you cannot pay the fixed costs and the loan payment. The required minimum is set in the "0. Assumptions" tab
A25: INTERPRETATION
A26: =IFERROR("With the average check excl. sales tax above, you need "&TEXT(ROUNDUP(B15,0),"0")&" customers a day over your "&TEXT(B11,"0")&" opening days to avoid losing money (accounting break-even, depreciation included), and "&TEXT(ROUNDUP(B20,0),"0")&" for cash to hold (cash break-even: depreciation out, because it is not paid, and the year's loan payment in"&IF(B12=0,"; no principal is repaid this year (interest-only period or no loan)","")&"). The ""Revenue needed per year"" rows show the same figures in your currency.","") -> With the average check excl. sales tax above, you need 147 customers a day over your 310 opening days to avoid losing money (accounting break-even, depreciation included), and 140 for cash to hold (cash break-even: depreciation out, because it is not paid, and the year's loan payment in). The "Revenue needed per year" rows show the same figures in your currency.
A28: BREAK-EVEN SENSITIVITY
A29: Customers per day needed to cover costs for each average check (columns) and each variable cost per customer (rows). Green cells are below the customers per day the plan forecasts.
A31: Customers per day needed: average check excl. sales tax (columns) × variable cost per customer (rows) | B31: =IFERROR($B$8-2,"") -> 5.5 | C31: =IFERROR(IF($B$8="","",$B$8),"") -> 7.5 | D31: =IFERROR($B$8+2,"") -> 9.5 | E31: =IFERROR($B$8+4,"") -> 11.5
A32: =IFERROR($B$9*0.85,"") -> 2.02725 | B32: =IFERROR(IF($B$31-$A32<=0,"",$B$6/($B$31-$A32)/$B$11),"") -> 216.29446 | C32: =IFERROR(IF($C$31-$A32<=0,"",$B$6/($C$31-$A32)/$B$11),"") -> 137.2503 | D32: =IFERROR(IF($D$31-$A32<=0,"",$B$6/($D$31-$A32)/$B$11),"") -> 100.51676 | E32: =IFERROR(IF($E$31-$A32<=0,"",$B$6/($E$31-$A32)/$B$11),"") -> 79.294459
A33: =IFERROR($B$9*0.925,"") -> 2.206125 | B33: =IFERROR(IF($B$31-$A33<=0,"",$B$6/($B$31-$A33)/$B$11),"") -> 228.04041 | C33: =IFERROR(IF($C$31-$A33<=0,"",$B$6/($C$31-$A33)/$B$11),"") -> 141.88786 | D33: =IFERROR(IF($D$31-$A33<=0,"",$B$6/($D$31-$A33)/$B$11),"") -> 102.98183 | E33: =IFERROR(IF($E$31-$A33<=0,"",$B$6/($E$31-$A33)/$B$11),"") -> 80.820604
A34: =IFERROR($B$9*1.0,"") -> 2.385 | B34: =IFERROR(IF($B$31-$A34<=0,"",$B$6/($B$31-$A34)/$B$11),"") -> 241.13534 | C34: =IFERROR(IF($C$31-$A34<=0,"",$B$6/($C$31-$A34)/$B$11),"") -> 146.84977 | D34: =IFERROR(IF($D$31-$A34<=0,"",$B$6/($D$31-$A34)/$B$11),"") -> 105.57085 | E34: =IFERROR(IF($E$31-$A34<=0,"",$B$6/($E$31-$A34)/$B$11),"") -> 82.406647
A35: =IFERROR($B$9*1.075,"") -> 2.563875 | B35: =IFERROR(IF($B$31-$A35<=0,"",$B$6/($B$31-$A35)/$B$11),"") -> 255.82582 | C35: =IFERROR(IF($C$31-$A35<=0,"",$B$6/($C$31-$A35)/$B$11),"") -> 152.17131 | D35: =IFERROR(IF($D$31-$A35<=0,"",$B$6/($D$31-$A35)/$B$11),"") -> 108.2934 | E35: =IFERROR(IF($E$31-$A35<=0,"",$B$6/($E$31-$A35)/$B$11),"") -> 84.056187
A36: =IFERROR($B$9*1.15,"") -> 2.74275 | B36: =IFERROR(IF($B$31-$A36<=0,"",$B$6/($B$31-$A36)/$B$11),"") -> 272.42237 | C36: =IFERROR(IF($C$31-$A36<=0,"",$B$6/($C$31-$A36)/$B$11),"") -> 157.89302 | D36: =IFERROR(IF($D$31-$A36<=0,"",$B$6/($D$31-$A36)/$B$11),"") -> 111.1601 | E36: =IFERROR(IF($E$31-$A36<=0,"",$B$6/($E$31-$A36)/$B$11),"") -> 85.773113

Sheet Scenarios
A1: SCENARIOS
A4: Metric | B4: Pessimistic | C4: Base | D4: Optimistic | E4: Notes
A5: Customers per day | B5: 140 | C5: =IFERROR(IF('3-Year P&L'!$B$6="","",'3-Year P&L'!$B$6),"") -> 165 | D5: 190
A6: Average check (excl. sales tax) | B6: 7 | C6: =IFERROR(IF('3-Year P&L'!$B$7="","",'3-Year P&L'!$B$7),"") -> 7.5 | D6: 8
A7: Operating days per year | B7: 300 | C7: =IFERROR(IF('3-Year P&L'!$B$8="","",'3-Year P&L'!$B$8),"") -> 310 | D7: 320
A8: ANNUAL REVENUE (excl. sales tax) | B8: =IFERROR(IF(B5*B6*B7=0,"",B5*B6*B7),"") -> 294000 | C8: =IFERROR(IF(C5*C6*C7=0,"",C5*C6*C7),"") -> 383625 | D8: =IFERROR(IF(D5*D6*D7=0,"",D5*D6*D7),"") -> 486400
A9: Cost of goods sold — food | B9: =IFERROR(IF(B8="","",B8*'0. Assumptions'!$B$11*'0. Assumptions'!$B$13),"") -> 58212 | C9: =IFERROR(IF(C8="","",C8*'0. Assumptions'!$B$11*'0. Assumptions'!$B$13),"") -> 75957.75 | D9: =IFERROR(IF(D8="","",D8*'0. Assumptions'!$B$11*'0. Assumptions'!$B$13),"") -> 96307.2
A10: Cost of goods sold — beverage | B10: =IFERROR(IF(B8="","",B8*'0. Assumptions'!$B$12*'0. Assumptions'!$B$14),"") -> 7350 | C10: =IFERROR(IF(C8="","",C8*'0. Assumptions'!$B$12*'0. Assumptions'!$B$14),"") -> 9590.625 | D10: =IFERROR(IF(D8="","",D8*'0. Assumptions'!$B$12*'0. Assumptions'!$B$14),"") -> 12160
A11: Disposables and packaging | B11: =IFERROR(IF(B8="","",B8*'0. Assumptions'!$B$15),"") -> 13230 | C11: =IFERROR(IF(C8="","",C8*'0. Assumptions'!$B$15),"") -> 17263.125 | D11: =IFERROR(IF(D8="","",D8*'0. Assumptions'!$B$15),"") -> 21888
A12: Delivery platform fees | B12: =IFERROR(IF(B8="","",B8*'0. Assumptions'!$B$16*'0. Assumptions'!$B$17),"") -> 2940 | C12: =IFERROR(IF(C8="","",C8*'0. Assumptions'!$B$16*'0. Assumptions'!$B$17),"") -> 3836.25 | D12: =IFERROR(IF(D8="","",D8*'0. Assumptions'!$B$16*'0. Assumptions'!$B$17),"") -> 4864
A13: Card processing fees | B13: =IFERROR(IF(B8="","",B8*'0. Assumptions'!$B$18),"") -> 8820 | C13: =IFERROR(IF(C8="","",C8*'0. Assumptions'!$B$18),"") -> 11508.75 | D13: =IFERROR(IF(D8="","",D8*'0. Assumptions'!$B$18),"") -> 14592
A14: Miscellaneous and contingency | B14: =IFERROR(IF(B8="","",B8*'0. Assumptions'!$B$28),"") -> 2940 | C14: =IFERROR(IF(C8="","",C8*'0. Assumptions'!$B$28),"") -> 3836.25 | D14: =IFERROR(IF(D8="","",D8*'0. Assumptions'!$B$28),"") -> 4864
A15: TOTAL VARIABLE COSTS | B15: =IFERROR(IF(B8="","",SUM(B9:B14)),"") -> 93492 | C15: =IFERROR(IF(C8="","",SUM(C9:C14)),"") -> 121992.75 | D15: =IFERROR(IF(D8="","",SUM(D9:D14)),"") -> 154675.2
A16: GROSS MARGIN | B16: =IFERROR(IF(B8="","",B8-B15),"") -> 200508 | C16: =IFERROR(IF(C8="","",C8-C15),"") -> 261632.25 | D16: =IFERROR(IF(D8="","",D8-D15),"") -> 331724.8
A17: FIXED COSTS (the P&L's) | B17: =IFERROR(IF(B8="","",'3-Year P&L'!$B$38),"") -> 232852.34 | C17: =IFERROR(IF(C8="","",'3-Year P&L'!$B$38),"") -> 232852.34 | D17: =IFERROR(IF(D8="","",'3-Year P&L'!$B$38),"") -> 232852.34 | E17: Fixed costs do not change with the scenario: that is why they are fixed
A18: PRE-TAX INCOME (EBT) | B18: =IFERROR(IF(B8="","",B16-B17),"") -> -32344.343 | C18: =IFERROR(IF(C8="","",C16-C17),"") -> 28779.907 | D18: =IFERROR(IF(D8="","",D16-D17),"") -> 98872.457
A19: Income tax | B19: =IFERROR(IF(B8="","",MAX(0,B18-'0. Assumptions'!$B$42)*'0. Assumptions'!$B$37),"") -> 0 | C19: =IFERROR(IF(C8="","",MAX(0,C18-'0. Assumptions'!$B$42)*'0. Assumptions'!$B$37),"") -> 7194.9768 | D19: =IFERROR(IF(D8="","",MAX(0,D18-'0. Assumptions'!$B$42)*'0. Assumptions'!$B$37),"") -> 24718.114 | E19: At the "years 1-2" effective income tax rate, offsetting prior net operating losses
A20: NET INCOME | B20: =IFERROR(IF(B8="","",B18-B19),"") -> -32344.343 | C20: =IFERROR(IF(C8="","",C18-C19),"") -> 21584.93 | D20: =IFERROR(IF(D8="","",D18-D19),"") -> 74154.343
A21: Customers per day to break even | B21: =IFERROR(IF(B8="","",IF(B6-B15/(B5*B7)<=0,"",B17/(B6-B15/(B5*B7))/B7)),"") -> 162.58368 | C21: =IFERROR(IF(C8="","",IF(C6-C15/(C5*C7)<=0,"",C17/(C6-C15/(C5*C7))/C7)),"") -> 146.84977 | D21: =IFERROR(IF(D8="","",IF(D6-D15/(D5*D7)<=0,"",D17/(D6-D15/(D5*D7))/D7)),"") -> 133.36942
A22: WHAT EACH SCENARIO DEMANDS
A23: Labor cost / Sales | B23: =IFERROR(IF(B8="","",'3-Year P&L'!$B$23/B8),"") -> 0.43600408 | C23: =IFERROR(IF(C8="","",'3-Year P&L'!$B$23/C8),"") -> 0.33414194 | D23: =IFERROR(IF(D8="","",'3-Year P&L'!$B$23/D8),"") -> 0.26353865 | E23: The SAME staffing in all three scenarios. If labor cost blows up in the pessimistic case, adjust it in the Staffing tab, not here
A24: Customers per year per full-time equivalent | B24: =IFERROR(IF(B8="","",B5*B7/Staffing!$C$11),"") -> 13770.492 | C24: =IFERROR(IF(C8="","",C5*C7/Staffing!$C$11),"") -> 16770.492 | D24: =IFERROR(IF(D8="","",D5*D7/Staffing!$C$11),"") -> 19934.426 | E24: Customers each full-time employee in the Staffing table would have to serve. In the optimistic scenario it tells you whether you need to hire
A25: Year-1 closing cash balance (estimate, same method in all three scenarios) | B25: =IFERROR(IF(B8="","",'Startup Costs'!$B$30+B20+'3-Year P&L'!$B$36-Financing!$B$45),"") -> 32029.346 | C25: =IFERROR(IF(C8="","",'Startup Costs'!$B$30+C20+'3-Year P&L'!$B$36-Financing!$B$45),"") -> 85958.619 | D25: =IFERROR(IF(D8="","",'Startup Costs'!$B$30+D20+'3-Year P&L'!$B$36-Financing!$B$45),"") -> 138528.03 | E25: ESTIMATED balance: working capital plus the year's result, adding back depreciation (which is not paid) and subtracting loan principal. It does not include the timing gap between receipts and payments or the sales tax settlement, so the three columns can be compared with each other. In red, the scenario runs out of cash
A26: Actual month-12 balance from the 12-Month Cash Flow tab (Base case only) | C26: =IFERROR(IF(C8="","",'12-Month Cash Flow'!$M$22),"") -> 97745.907 | E26: The ACTUAL base-case balance, with its timing of receipts and payments and its sales tax settlement. It exists only for the Base scenario, the only one with its own monthly cash flow: that is why it is not in the row above, where it would be compared against two estimates
A28: The "Base" column reads its three inputs from the "0. Assumptions" tab, so it reproduces EXACTLY year 1 of the P&L. The other two scenarios use the same cost rates: only customers, average check and days change. FIXED COSTS are the same in all three: miscellaneous and contingency, a percentage of sales, sit above with the variable costs and each scenario carries its own.

Sheet Staffing
A1: STAFFING AND LABOR COSTS
A2: =IFERROR("Payroll — "&TEXT('0. Assumptions'!$B$21,"0")&" pay periods + employer taxes "&TEXT('0. Assumptions'!$B$20*100,"0")&"%","") -> Payroll — 12 pay periods + employer taxes 10%
A4: Position | B4: People | C4: FTE | D4: Gross pay per month (total for the position) | E4: Employer payroll taxes (total for the position) | F4: Cost per month (total for the position) | G4: Cost per year | H4: Hours per week per person | I4: Hours per year for the position | J4: Notes
A5: Owner / ice cream maker & GM | B5: 1 | C5: 1 | D5: 4000 | E5: =IFERROR(IF(D5="","",D5*'0. Assumptions'!$B$20),"") -> 400 | F5: =IFERROR(IF(D5="","",D5+E5),"") -> 4400 | G5: =IFERROR(IF(D5="","",F5*MAX(12,'0. Assumptions'!$B$21)),"") -> 52800 | H5: =IFERROR(IF(D5="","",C5*$B$18),"") -> 40 | I5: =IFERROR(IF(D5="","",H5*B5*$B$19),"") -> 1840 | J5: Balances recipes, flavors and mix-ins, runs the batch freezer, buys and runs the business. Works as the ice cream maker and GM but does NOT pasteurize: the base is bought from a licensed dairy. Paid below what a hired manager would earn: plan to draw in addition from net profit. The book loads employer payroll taxes on this salary as if it were payroll, which is the prudent side
A6: Shift lead / counter (year-round) | B6: 1 | C6: 1 | D6: 2946 | E6: =IFERROR(IF(D6="","",D6*'0. Assumptions'!$B$20),"") -> 294.6 | F6: =IFERROR(IF(D6="","",D6+E6),"") -> 3240.6 | G6: =IFERROR(IF(D6="","",F6*MAX(12,'0. Assumptions'!$B$21)),"") -> 38887.2 | H6: =IFERROR(IF(D6="","",C6*$B$18),"") -> 40 | I6: =IFERROR(IF(D6="","",H6*B6*$B$19),"") -> 1840 | J6: Counter, register, dipping cabinets and closing; opens and closes when the owner is in the production room. About $17 per hour
A7: Seasonal scooper (part-time, April-September) | B7: 1 | C7: 0.5 | D7: 1300 | E7: =IFERROR(IF(D7="","",D7*'0. Assumptions'!$B$20),"") -> 130 | F7: =IFERROR(IF(D7="","",D7+E7),"") -> 1430 | G7: =IFERROR(IF(D7="","",F7*MAX(12,'0. Assumptions'!$B$21)),"") -> 17160 | H7: =IFERROR(IF(D7="","",C7*$B$18),"") -> 20 | I7: =IFERROR(IF(D7="","",H7*B7*$B$19),"") -> 920 | J7: Seasonal W-2 employee: about 40 hours a week from April to September, which equals half a full-time position over the year (part-time on a yearly basis). Rehire each spring. Scoopers aged 14-15 only within the FLSA hours (29 CFR 570.35)
A8: Summer scooper (part-time, June-August) | B8: 1 | C8: 0.25 | D8: 650 | E8: =IFERROR(IF(D8="","",D8*'0. Assumptions'!$B$20),"") -> 65 | F8: =IFERROR(IF(D8="","",D8+E8),"") -> 715 | G8: =IFERROR(IF(D8="","",F8*MAX(12,'0. Assumptions'!$B$21)),"") -> 8580 | H8: =IFERROR(IF(D8="","",C8*$B$18),"") -> 10 | I8: =IFERROR(IF(D8="","",H8*B8*$B$19),"") -> 460 | J8: Seasonal part-time W-2 employee from June to August, on the evenings of the peak. Never a 1099 contractor if you set the schedule and give the direction: that is misclassification
A9: Production assistant (part-time, May-September) | B9: 1 | C9: 0.2 | D9: 555 | E9: =IFERROR(IF(D9="","",D9*'0. Assumptions'!$B$20),"") -> 55.5 | F9: =IFERROR(IF(D9="","",D9+E9),"") -> 610.5 | G9: =IFERROR(IF(D9="","",F9*MAX(12,'0. Assumptions'!$B$21)),"") -> 7326 | H9: =IFERROR(IF(D9="","",C9*$B$18),"") -> 8 | I9: =IFERROR(IF(D9="","",H9*B9*$B$19),"") -> 368 | J9: Production assistant from May to September: batch freezing, pack-out, cleaning the batch freezer and the tubs, and support on the summer batches
A10: Relief cover (vacations and days off) | B10: 1 | C10: 0.1 | D10: 260 | E10: =IFERROR(IF(D10="","",D10*'0. Assumptions'!$B$20),"") -> 26 | F10: =IFERROR(IF(D10="","",D10+E10),"") -> 286 | G10: =IFERROR(IF(D10="","",F10*MAX(12,'0. Assumptions'!$B$21)),"") -> 3432 | H10: =IFERROR(IF(D10="","",C10*$B$18),"") -> 4 | I10: =IFERROR(IF(D10="","",H10*B10*$B$19),"") -> 184 | J10: Coverage for vacations and the team's days off through the year. Paid sick leave is required by some states and cities: check yours
A11: TOTAL STAFF | B11: =IFERROR(IF(COUNT(D5:D10)=0,"",SUM(B5:B10)),"") -> 6 | C11: =IFERROR(IF(COUNT(D5:D10)=0,"",SUM(C5:C10)),"") -> 3.05 | D11: =IFERROR(IF(COUNT(D5:D10)=0,"",SUM(D5:D10)),"") -> 9711 | E11: =IFERROR(IF(COUNT(D5:D10)=0,"",SUM(E5:E10)),"") -> 971.1 | F11: =IFERROR(IF(COUNT(D5:D10)=0,"",SUM(F5:F10)),"") -> 10682.1 | G11: =IFERROR(IF(COUNT(D5:D10)=0,"",SUM(G5:G10)),"") -> 128185.2 | I11: =IFERROR(IF(COUNT(D5:D10)=0,"",SUM(I5:I10)),"") -> 5612
A12: STAFF GROWTH (stepped cost)
A13: Annual cost of year-2 hires | B13: 8000 | J13: FULL ANNUAL cost (gross pay + employer payroll taxes, over all pay periods) of whoever you hire that year. The P&L adds it to the previous year's cost: staffing grows by people, not by a percentage
A14: Annual cost of year-3 hires | B14: 8000 | J14: FULL ANNUAL cost (gross pay + employer payroll taxes, over all pay periods) of whoever you hire that year. The P&L adds it to the previous year's cost: staffing grows by people, not by a percentage
A15: Labor cost, year 2 | B15: =IFERROR(IF(G11="","",G11*(1+'0. Assumptions'!$B$48)+B13),"") -> 136185.2
A16: Labor cost, year 3 | B16: =IFERROR(IF(B15="","",B15*(1+'0. Assumptions'!$B$48)+B14),"") -> 144185.2
A17: COVERAGE OF SERVICE HOURS
A18: Full-time week (hours per week) | B18: 40 | J18: 40 hours a week is the FLSA overtime threshold for non-exempt employees; some states add daily overtime rules. Change it if your own full-time week is different
A19: Weeks worked per year per person | B19: 46 | J19: 46 weeks: 52 minus about six weeks for vacation, holidays, the January closure and average absences. There is no federal vacation requirement in the US: adjust it to your own policy
A20: Service hours per day to cover | B20: 9.5 | J20: Average shop hours over the year: more in peak season (Memorial Day to Labor Day), fewer from November to February. The production room goes in the row below
A21: People needed at the same time in each shift | B21: 1.6 | J21: Average staff on the floor at once at the counter: 1.8-2 people in summer, 1.3 in spring and fall and 1 in winter. In July and August the schedule is tight: the owner works shifts or a weekend extra comes in
A22: Production hours per day BEFORE opening | B22: 2 | J22: Production runs before opening: flavoring, batch-freezing and hardening, with no processing of raw mix and no aging: the base arrives pasteurized and aged from a licensed dairy. More in July, less in winter
A23: People on the production shift | B23: 1 | J23: The ice cream maker; in summer the production assistant helps
A24: Service hours to cover per year | B24: =IFERROR(IF(OR(B20="",B21="",'0. Assumptions'!$B$6=""),"",B20*B21*'0. Assumptions'!$B$6+B22*B23*'0. Assumptions'!$B$6),"") -> 5332
A25: Hours hired per year | B25: =IFERROR(IF(I11="","",I11),"") -> 5612
A26: Coverage (hired / needed) | B26: =IFERROR(B25/B24,"") -> 1.0525131 | J26: Below 100% the staff cannot cover the hours the plan declares: either hire more or cut the hours
A28: The gross pay, employer payroll taxes, monthly cost and annual cost columns are TOTALS for the row: for a position with two people they include both. "FTE" is the share of a full-time week and is used to compare pay with the legal floor pro rata. The payroll tax rate and the number of pay periods are in the "0. Assumptions" tab. Tips are not modeled: the shift lead and the scoopers are budgeted at a base wage of at least $15/h
A29: The pay floor is the HIGHER of the federal minimum wage and your state / local minimum wage, both in the "0. Assumptions" tab; part-time positions get it in proportion. There is no single national table above the federal floor: the state / local cell is delivered empty so you can enter the rate for your state and city.

Sheet Instructions
A1: HOW TO USE THIS WORKBOOK — Ice Cream Shop Financial Projections
A3: HOW TO USE THIS WORKBOOK
A4: This financial plan is a MODEL: you type only in the GREEN cells and everything else recalculates on its own.
A5: 1. "0. Assumptions" is the control sheet: customers per day, average check excl. sales tax, operating days, food and beverage mix, cost of goods sold, rent, financing and taxes.
A6: 2. Startup cost items, fixed costs and staffing are typed in their own tab, also in green. No number is typed twice.
A7: 3. Only "Break-Even" is derived entirely from the rest. The other three tabs also have green cells you can edit: the pessimistic and optimistic scenarios in "Scenarios", seasonality and the launch ramp-up in "12-Month Cash Flow", and the other funding sources in "Financing" (rows 8-11 count as sources but are not amortized: Your bank or SBA 7(a) loan goes in "Loan requested" on "0. Assumptions"). Everything else is calculated.
A8: 4. All figures are shown EXCL. SALES TAX. To turn a menu price into a price without tax, divide it by 1 + your sales tax rate (8% in the example, so divide by 1.08). A scoop is generally taxed as prepared food; in some states packaged pints and whole cakes may be taxed as groceries, so check your state. The P&L is excl. sales tax and the cash flow uses what is collected, tax included. Input tax on purchases is not recoverable in this book.
A9: 5. If you change the staffing, the P&L reads it on its own: labor cost comes from the "Staffing" tab, not from a separate estimate.
A10: 6. The "12-Month Cash Flow" tab answers the question that decides a loan: in which month does the cash run out? Its Month 1 is MARCH: the plan opens in season so that the summer cash reaches the first winter. The minimum balance of the year can never be red.
A11: 7. The "Financing" tab matches what you need with what you put in and builds the amortization schedule of the loan. If the difference is red, the plan is not funded.
A12: 8. The Word document in this pack uses the figures from this Excel: if you change a green cell, the Excel rules.
A14: RATIOS AUDITED BY THIS WORKBOOK
A15: Thresholds live in the "Threshold" column of the KEY RATIOS block of the P&L: change them there and the traffic light changes with them.
A17: Ratio | B17: Year 1 value | C17: Threshold | D17: Status
A18: Cost of goods sold / Sales | B18: =IFERROR(IF('3-Year P&L'!$B$53="","",'3-Year P&L'!$B$53),"") -> 0.223 | C18: =IFERROR(IF('3-Year P&L'!$E$53="","",'3-Year P&L'!$E$53),"") -> 0.25 | D18: =IFERROR(IF(OR(B18="",C18=""),"",IF(B18<=C18,"OK","REVIEW")),"") -> OK
A19: Labor cost / Sales | B19: =IFERROR(IF('3-Year P&L'!$B$54="","",'3-Year P&L'!$B$54),"") -> 0.33414194 | C19: =IFERROR(IF('3-Year P&L'!$E$54="","",'3-Year P&L'!$E$54),"") -> 0.35 | D19: =IFERROR(IF(OR(B19="",C19=""),"",IF(B19<=C19,"OK","REVIEW")),"") -> OK
