Workbook

Sheet 0. Assumptions
A1: ASSUMPTIONS — the RATES and DRIVERS of the model are typed here
A2: Change the GREEN cells: the rest of the workbook recalculates on its own. Expense items are typed on their own tab (also in green) and are not repeated here. Amounts are in your currency.
A3: BUSINESS ACTIVITY
A4: Covers per day (year-1 average) | B4: 115 | C4: Equivalent covers per day, year-1 average: about 70 dine-in (sushi bar and tables), about 25 from take-out and pickup (15.6 orders) and about 20 from delivery marketplaces (12.5 orders), counting each order as 1.6 covers. A Friday or Saturday night runs well above the average and a Tuesday well below it (Kit estimate). Compare it with the foot traffic on your street on a Friday night and a Tuesday at lunch
A5: Average check (excl. sales tax) | B5: 32.5 | C5: Per cover, EXCL. sales tax and tip: a dine-in guest spends about $36.00 (food $28.50 plus beverage $7.50); a take-out order averages $41.00 and a marketplace order $46.00 (the menu is about 15% higher there and the order a bit bigger). At 1.6 covers per order, that is $25.60 and $28.75 per cover, and the weighted average of the three channels is $32.48; the example rounds it to $32.50 (Kit estimate). The "Menu price incl. sales tax (calculated)" row below shows the price with your local rate applied
A6: Operating days per year | B6: 310 | C6: 365 days minus 52 Mondays (closed) and three holidays: Thanksgiving, Christmas Day and New Year's Day. It is the SAME figure for the P&L, the break-even, the scenarios and the staffing hours
A7: Volume growth in year 2 | B7: 0.06 | C7: Repeat neighborhood regulars and more pickup in year 2. It applies to covers at the same average check; staffing does NOT rise with this percentage: it comes from the "Staffing" tab
A8: Volume growth in year 3 | B8: 0.04 | C8: On year 2. Conservative: the ceiling is set by the sushi bar (10 seats), the 40 seats on Friday and Saturday nights and what the head sushi chef (itamae) and the sushi team can cut
A9: Menu price incl. sales tax (calculated) | B9: =IFERROR(IF($B$5="","",$B$5*(1+SUMPRODUCT('3-Year P&L'!$E$10:$E$11,'3-Year P&L'!$G$10:$G$11))),"") -> 35.1 | C9: =IFERROR("Average check excl. sales tax plus the weighted sales tax of your sales lines ("&TEXT(SUMPRODUCT('3-Year P&L'!$E$10:$E$11,'3-Year P&L'!$G$10:$G$11)*100,"0")&"%), rounded. In the US, menu prices usually exclude sales tax and it is added at the register; the beverage share in column H of the beverage line of the P&L only moves this average if your state taxes alcohol at another rate. "&"In the UK, menu prices include VAT.","") -> Average check excl. sales tax plus the weighted sales tax of your sales lines (8%), rounded. In the US, menu prices usually exclude sales tax and it is added at the register; the beverage share in column H of the beverage line of the P&L only moves this average if your state taxes alcohol at another rate. In the UK, menu prices include VAT.
A10: SALES MIX AND COST OF GOODS SOLD
A11: FOOD share of total sales | B11: 0.85 | C11: Share of FOOD in total sales. It is an INPUT: change it here and the P&L, the cash flow and the sales tax collected recalculate on their own
A12: BEVERAGE share of total sales | B12: =IFERROR(IF(COUNT(B11)=0,"",1-B11),"") -> 0.15 | C12: Calculated as the remainder: food + beverage = 100%
A13: Cost of goods sold on FOOD sales | B13: 0.32 | C13: Cost of goods sold on food sales: about 32%, on the prudent side. Consulting blogs put sushi food cost at 30-40%. The theoretical cost per piece in the Sushi Fish, Rice & Costing Calculator comes out lower (the salmon nigiri and the California roll are cheap, the spicy tuna is not), but the real number is what you buy against what you sell: it also carries fish that goes unsold in the sushi case, trim that is not reused, rice and nori thrown out at close, staff meals, comps and ordering mistakes, and fish prices are Kit estimates. Measure your usage in the first quarter and change this cell
A14: Cost of goods sold on BEVERAGE sales | B14: 0.24 | C14: Beverage cost of about 24% of menu price (Kit estimate): beer, sake and wine are about 70% of beverage sales, and the rest is soft drinks, water and tea. Ask your distributor for the price of sake and beer in writing: sake often depends on an importer
A15: Disposables and packaging as % of sales | B15: 0.03 | C15: Sushi trays, soy cups, chopsticks, bags, napkins and wipes for every order that leaves the restaurant, plus containers for leftovers. Local packaging ordinances vary (some cities charge for or ban single-use items): check yours before ordering
A16: Delivery share of total sales | B16: 0.15 | C16: Sales through delivery marketplaces (DoorDash, Uber Eats, Grubhub) with their commission, as a share of total sales. Pickup orders placed directly with you (phone or website) pay no commission and do not go here: push them. Rolls and platters travel well; tempura and gyoza arrive worse, so do not go higher without testing
A17: Delivery platform fee | B17: 0.25 | C17: The example uses 25%, a Plus plan on DoorDash or Uber Eats (the Basic plan is about 15% with little visibility, Premier is 30%, and app pickup orders add 6-10%). Check your contract. If you deliver yourself, enter 0 and add the driver to the "Staffing" tab as a W-2 employee, with hired and non-owned auto insurance (check your state)
A18: Card processing fee | B18: 0.03 | C18: Card and mobile wallet (contactless) processing fees on total sales. Ask your POS provider for its rate
A19: LABOR
A20: Employer payroll taxes | B20: 0.1 | C20: FICA (Social Security 6.2% + Medicare 1.45%) + federal and state unemployment taxes (FUTA / SUTA) + workers' comp. About 10% in total: adjust it to your state and your insurance carrier
A21: Monthly pay periods per year (keep 12) | B21: 12 | C21: Annual gross pay = monthly gross pay × this number. Keep 12 in the US: it counts the monthly salaries the model pays in a year, not how often you run payroll (weekly or biweekly payroll pays the same annual amount)
A22: Federal minimum wage, annual full-time | B22: 15080 | C22: US federal minimum wage: 7.25 per hour × 2,080 hours = 15,080 per year for a full-time job. Your state or city may set a higher floor: enter it in the state / local minimum wage cell below. Check the current rates at dol.gov
A23: RENT AND FIXED COSTS
A24: Monthly rent | B24: 4500 | C24: About 1,800 sq ft (167 sq m) of second-generation restaurant space with a Type I hood route to the roof possible: a sushi bar counter in view with 10 seats, a 30-seat dining room, a small hot kitchen, a walk-in cooler and a to-go packing station by the door, in a neighborhood with nightlife in a mid-size city (150,000 to 500,000 people), no key money: about $30 per sq ft a year (Kit estimate, editable). The weight of rent on sales is calculated by the workbook itself in the rent row of the "3-Year P&L"
A25: Security deposit (months of rent) | B25: 2 | C25: Security deposit, in months of rent. The example uses two; commercial leases commonly ask for one to three, and some landlords also want a personal guarantee: check it with your attorney
A26: Monthly utilities (electricity, water, gas) | B26: 1700 | C26: Gas (rice cookers, fryer, range and griddle), electricity (walk-in, reach-ins, freezer and sushi case, hood and HVAC) and water. The example uses $1,700 per month (Kit estimate). Ask the landlord for the space's utility history
A27: Insurance (per year) | B27: 8000 | C27: General liability, product liability (you serve raw fish), liquor liability (beer, sake & wine), property with refrigeration breakdown (spoilage) cover and workers' comp: about $8,000 a year in the example (Kit estimate). Tell your insurance broker you serve raw fish and run a fryer: it changes the premium and the terms
A28: Miscellaneous and contingency as % of sales | B28: 0.01 | C28: Cushion for unbudgeted running costs (small repairs, broken smallwares, menu tests)
A29: FINANCING
A30: Owner's equity contributed | B30: 130000 | C30: Owner's cash. Lenders usually expect an owner equity injection (often around 10% for SBA start-ups; many want 20-30%) toward the cash need
A31: Loan requested | B31: 256000 | C31: Principal requested. The "Financing" tab compares what you put in with the cash need on "Startup Costs" and tells you whether you have a surplus or a shortfall: adjust the loan with that figure. The example is an SBA 7(a) loan, which you apply for through your lender (SBA Microloans go up to $50,000)
A32: Nominal annual interest rate (not APR) | B32: 0.1 | C32: Nominal annual rate, not APR. The example uses 10%. Ask two lenders for a quote before you set it; the refrigeration and the kitchen equipment can also be financed through equipment financing or a lease: compare
A33: Loan term (years) | B33: 10 | C33: Total years, interest-only period included
A34: Interest-only period (years) | B34: 0 | C34: Interest-only period in years. The example uses 0: principal is repaid from the start. If your lender gives you an interest-only period while you build out, enter it here and check the cash cushion of that year on the "Break-Even" tab
A35: Working capital (months of fixed costs) | B35: 3 | C35: Three months of fixed costs: the cushion for the opening ramp-up, which with Month 1 in January runs from January to April, when the calendar is also at its slowest
A36: TAXES
A37: Effective income tax rate (years 1-2) | B37: 0.25 | C37: Example: 21% federal rate for a C corporation plus state tax, rounded to 25%. If you operate as a sole proprietorship, LLC taxed as a pass-through or S corporation, the business itself pays 0% here and you pay tax on the profit personally: set this to 0 and budget for your personal tax separately. The model applies this rate to the first two years with positive taxable income
A38: Effective income tax rate (from year 3) | B38: 0.25 | C38: From the third year with positive taxable income. Same example rate (21% federal C corporation + state). Confirm the rate that applies to you with your accountant and change it here
A39: Sales tax rate on sales | B39: 0.08 | C39: Example rate: state + local sales tax combined. It varies widely by state and city: look up yours. UK: 20% VAT on hot food and dine-in
A40: Sales tax rate on alcohol to go | B40: 0.08 | C40: Rate on alcohol served to go or by delivery. The example uses ONE sales tax rate (8%) for everything, so this cell equals the rate on sales; some states tax food to go or alcohol differently, so check yours. There is no credit for the tax you pay on purchases (see the recoverable input tax cell below)
...

Sheet Startup Costs
A1: SUSHI RESTAURANT BUSINESS PLAN: SUSHI BAR, TAKE-OUT & DELIVERY
A2: Estimated Startup Costs — sushi restaurant with a sushi bar counter, 40 seats, take-out and delivery
A3: US kit example (2026) — replace with your own quotes.
A5: Item | B5: Amount | C5: % of startup costs | D5: Notes | E5: Taxable / recoverable tax?
A6: STARTUP COSTS | B6: =IFERROR(IF(COUNT(B7:B27)=0,"",SUM(B7:B27)),"") -> 255100 | C6: =IFERROR(B6/$B$30,"") -> 0.66232834
A7: Architect, MEP & hood drawings, plan review & permit fees | B7: 14000 | C7: =IFERROR(B7/$B$30,"") -> 0.03634887 | D7: Architect, MEP and hood drawings, plan review (Food Code 8-201.11) and permit fees. If you choose a variance for the sushi rice, ask your health department for the plan review fee of the HACCP plan: in some counties it can pass $2,000 | E7: Yes
A8: Build-out (second-generation space, 1,800 sq ft) with sushi bar counter, signage & facade | B8: 75000 | C8: =IFERROR(B8/$B$30,"") -> 0.19472609 | D8: Build-out of a second-generation restaurant space of 1,800 sq ft: sushi bar counter in view, finished kitchen, walk-in room, slip-resistant floors, restrooms (one ADA-accessible), ceilings and acoustic insulation, plus signage and facade. Kit estimate: get two quotes | E8: Yes
A9: Type I hood (about 10 ft), UL 300 fire suppression & makeup air | B9: 18000 | C9: =IFERROR(B9/$B$30,"") -> 0.046734262 | D9: Type I hood of about 10 ft with UL 300 fire suppression and makeup air over the tempura fryer, the range and the griddle. Ask the fire marshal and the mechanical inspector in writing what your city requires, and whether the gas rice cookers go under the hood. Installers rarely quote by the foot: ask for an offer with your plans | E9: Yes
A10: Electrical service & panel | B10: 11000 | C10: =IFERROR(B10/$B$30,"") -> 0.028559827 | D10: Electrical service for the walk-in, the sushi case, the hood and the lighting. Ask what service is available BEFORE you sign: a new service takes time | E10: Yes
A11: Plumbing, grease interceptor, HVAC & gas lines | B11: 15000 | C11: =IFERROR(B11/$B$30,"") -> 0.038945218 | D11: Hot and cold water in the kitchen and at the sushi bar, drains with a grease interceptor, HVAC for the dining room and the gas lines for the rice cookers and the fryer | E11: Yes
A12: Refrigerated sushi case (6 ft) | B12: 4000 | C12: =IFERROR(B12/$B$30,"") -> 0.010385391 | D12: The case for the neta (the cut fish that goes on top of the rice), in view of the guest and for service only, not for storing fish. A 6 ft Hoshizaki case (70.9 in) lists around $4,045 (read October 2026); the example uses $4,000 | E12: Yes
A13: Commercial gas rice cookers × 2 & rice warmers | B13: 2500 | C13: =IFERROR(B13/$B$30,"") -> 0.0064908697 | D13: Two commercial gas rice cookers and rice warmers. The hangiri, the wooden tub where the sushi rice is seasoned, goes under smallwares. Kit estimate: ask your equipment dealer for quotes | E13: Yes
A14: Freezer (−4 °F or colder) with temperature logger | B14: 3500 | C14: =IFERROR(B14/$B$30,"") -> 0.0090872176 | D14: The parasite rule (FDA Food Code 3-402.11) asks for raw fish to be frozen at −4 °F or below for 7 days, or at −31 °F until solid plus 15 hours, or at −31 °F until solid plus 24 hours at −4 °F. Tuna and feed-raised aquaculture fish are exempt with a written supplier statement, and records are kept 90 days. This freezer HOLDS the fish you buy already treated, at −4 °F or below with a logger; freezing fish yourself takes a lot of freezer space. Kit estimate: ask for the data sheet | E14: Yes
A15: Fryer, range & griddle (tempura, gyoza, miso) | B15: 6000 | C15: =IFERROR(B15/$B$30,"") -> 0.015578087 | D15: Fryer for the tempura, range for the miso and stocks, and griddle for the gyoza and teriyaki, all under the Type I hood. Kit estimate | E15: Yes
A16: Walk-in cooler (6×8) | B16: 12800 | C16: =IFERROR(B16/$B$30,"") -> 0.033233253 | D16: Walk-in cooler (6×8 ft) for the rice, the vegetables, the sauces and the backup fish stock, with cold holding at 41 °F or below. A 6×8 ft walk-in lists around $12,800 (Norlake Kold Locker, read October 2026) | E16: Yes
A17: Reach-in fish refrigerators (32-34 °F), prep tables, beverage & sake cooler, ice machine | B17: 11000 | C17: =IFERROR(B17/$B$30,"") -> 0.028559827 | D17: Reach-in refrigerators for fish held at 32-34 °F (cold holding is 41 °F or below, and tuna must be received at 40 °F or below), refrigerated prep tables for the sushi bar, a beverage and sake cooler and an ice machine | E17: Yes
A18: 3-comp sink, dish machine, hand sinks, shelving & stainless | B18: 11500 | C18: =IFERROR(B18/$B$30,"") -> 0.029858001 | D18: Three-compartment sink, dish machine, hands-free hand sinks, stainless tables and shelving | E18: Yes
... A24: Opening inventory (fish, rice, nori, sauces, disposables, beverage) | B24: 7000 | C24: =IFERROR(B24/$B$30,"") -> 0.018174435 | D24: Fish (bought already treated or exempt, with the supplier's letter), Calrose sushi rice, nori, sauces, the first order of to-go packaging and the beverages, sake included (order early: it often depends on an importer) | E24: Yes
A25: Security deposit | B25: =IFERROR(IF('0. Assumptions'!$B$24="","",'0. Assumptions'!$B$24*'0. Assumptions'!$B$25),"") -> 9000 | C25: =IFERROR(B25/$B$30,"") -> 0.023367131 | D25: =IFERROR(""&TEXT('0. Assumptions'!$B$25,"0")&IF('0. Assumptions'!$B$25=1," month"," months")&" of rent, from ""0. Assumptions"". Refundable when the lease ends: it is not depreciated and carries no tax","") -> 2 months of rent, from "0. Assumptions". Refundable when the lease ends: it is not depreciated and carries no tax | E25: No
A26: Rent paid before opening | B26: =IFERROR(IF('0. Assumptions'!$B$24="","",'0. Assumptions'!$B$24*'0. Assumptions'!$B$54),"") -> 9000 | C26: =IFERROR(B26/$B$30,"") -> 0.023367131 | D26: =IFERROR("Rent "&IF('0. Assumptions'!$B$54=1,"for the month","for the "&TEXT('0. Assumptions'!$B$54,"0")&" months")&" of build-out and permits before opening. It does not overlap the P&L, which starts on opening day: its twelve months are twelve trading months","") -> Rent for the 2 months of build-out and permits before opening. It does not overlap the P&L, which starts on opening day: its twelve months are twelve trading months | E26: Yes
A27: Build-out and setup contingency | B27: =IFERROR(IF(COUNT(B7,B8,B9,B10,B11)=0,"",ROUND((B7+B8+B9+B10+B11)*'0. Assumptions'!$B$55,0)),"") -> 13300 | C27: =IFERROR(B27/$B$30,"") -> 0.034531427 | D27: =IFERROR("At "&TEXT('0. Assumptions'!$B$55,"0%")&" of the BUILD-OUT items of this block (architect, MEP & hood drawings and permit fees; build-out with the sushi bar counter, signage & facade; Type I hood (about 10 ft), UL 300 fire suppression & makeup air; "&"electrical service & panel; plumbing, grease interceptor, HVAC & gas lines), not of the whole block: the sushi case, the rice cookers, the equipment and the other items are left out. "&"No lender funds a build-out without a cushion: the percentage is in ""0. Assumptions""","") -> At 10% of the BUILD-OUT items of this block (architect, MEP & hood drawings and permit fees; build-out with the sushi bar counter, signage & facade; Type I hood (about 10 ft), UL 300 fire suppression & makeup air; electrical service & panel; plumbing, grease interceptor, HVAC & gas lines), not of the whole block: the sushi case, the rice cookers, the equipment and the other items are left out. No lender funds a build-out without a cushion: the percentage is in "0. Assumptions" | E27: Yes
A28: WORKING CAPITAL | B28: =IFERROR(IF(B29="","",B29),"") -> 130056.4 | C28: =IFERROR(B28/$B$30,"") -> 0.33767166
A29: Operating cushion until break-even | B29: =IFERROR(IF('0. Assumptions'!$B$35*('3-Year P&L'!$B$37-'3-Year P&L'!$B$35)=0,"",'0. Assumptions'!$B$35*('3-Year P&L'!$B$37-'3-Year P&L'!$B$35)/12),"") -> 130056.4 | C29: =IFERROR(B29/$B$30,"") -> 0.33767166 | D29: =IFERROR("Covers "&TEXT('0. Assumptions'!$B$35,"0")&IF('0. Assumptions'!$B$35=1," month"," months")&" of year-1 CASH fixed costs (the P&L fixed costs minus depreciation, which is not paid out), the minimum the Instructions of this workbook ask for","") -> Covers 3 months of year-1 CASH fixed costs (the P&L fixed costs minus depreciation, which is not paid out), the minimum the Instructions of this workbook ask for | E29: No
A30: TOTAL STARTUP COSTS (sum of the blocks) | B30: =IFERROR(B6+B28,"") -> 385156.4 | D30: =IFERROR("The percentages in column C are read on this figure, which includes the working capital ("&TEXT(C28,"0%")&" of the total). To compare the breakdown with another plan, use the CAPEX row below.","") -> The percentages in column C are read on this figure, which includes the working capital (34% of the total). To compare the breakdown with another plan, use the CAPEX row below.
A31: CAPEX (startup costs excluding working capital) | B31: =IFERROR(B30-B28,"") -> 255100 | D31: What you buy: build-out, equipment, launch and formation costs. The cash cushion is not an investment: it is working capital
A32: Recoverable input tax on capex | B32: =IFERROR(IF(B30="","",SUMIF($E$7:$E$27,"Yes",$B$7:$B$27)*'0. Assumptions'!$B$41),"") -> 0 | D32: =IFERROR("At "&TEXT('0. Assumptions'!$B$41,"0%")&" on the items marked ""Yes"" in the tax column. US: the sales tax you pay on equipment is part of its cost and is not recovered, so this rate is 0. UK (VAT-registered): 20%, reclaimed on your VAT return, but you pay it first, so the loan has to cover it","") -> At 0% on the items marked "Yes" in the tax column. US: the sales tax you pay on equipment is part of its cost and is not recovered, so this rate is 0. UK (VAT-registered): 20%, reclaimed on your VAT return, but you pay it first, so the loan has to cover it
A33: TOTAL CASH NEEDED AT LAUNCH | B33: =IFERROR(B30+B32,"") -> 385156.4 | D33: This is the figure the Financing tab has to cover
A34: DEPRECIATION BASES (not added to startup costs)
A35: Build-out, fixtures and setup | B35: =IFERROR(IF(B7="","",B7+B8+B9+B10+B11+B27),"") -> 146300 | D35: =IFERROR("Depreciated over "&TEXT('0. Assumptions'!$B$44,"0")&" years","") -> Depreciated over 10 years
A36: Machinery, furniture and equipment | B36: =IFERROR(IF(B12="","",B12+B13+B14+B15+B16+B17+B18+B19+B20+B21),"") -> 75800 | D36: =IFERROR("Depreciated over "&TEXT('0. Assumptions'!$B$45,"0")&" years","") -> Depreciated over 7 years
A37: Annual depreciation of fixed assets | B37: =IFERROR(B35/MAX(1,'0. Assumptions'!$B$44)+B36/MAX(1,'0. Assumptions'!$B$45),"") -> 25458.571 | D37: =IFERROR("Not depreciated, because they are not fixed assets: LLC, legal and food safety plan; branding, website, photos and launch; opening inventory; security deposit; pre-opening rent and the working capital reserve. They add up to "&TEXT(B30-B35-B36,"#,##0")&" of the "&TEXT(B30,"#,##0")&" total investment.","") -> Not depreciated, because they are not fixed assets: LLC, legal and food safety plan; branding, website, photos and launch; opening inventory; security deposit; pre-opening rent and the working capital reserve. They add up to 163056 of the 385156 total investment.

Sheet 3-Year P&L
A1: PRO FORMA P&L — 3 YEARS
A2: Base case — sushi restaurant: sushi bar and tables, take-out and delivery
A4: Item | B4: Year 1 | C4: Year 2 | D4: Year 3 | E4: % of sales (year 1) | F4: Notes | G4: Sales tax rate on the line (%) | H4: Beverage share taxed at the alcohol rate in B40 (%)
A5: REVENUE
A6: Covers per day (average) | B6: =IFERROR(IF('0. Assumptions'!$B$4="","",'0. Assumptions'!$B$4),"") -> 115 | C6: =IFERROR(B6*(1+'0. Assumptions'!$B$7),"") -> 121.9 | D6: =IFERROR(C6*(1+'0. Assumptions'!$B$8),"") -> 126.776 | F6: Growth for years 2 and 3 is set in "0. Assumptions"
A7: Average check (excl. sales tax) | B7: =IFERROR(IF('0. Assumptions'!$B$5="","",'0. Assumptions'!$B$5),"") -> 32.5 | C7: =IFERROR(IF(B7="","",B7),"") -> 32.5 | D7: =IFERROR(IF(C7="","",C7),"") -> 32.5 | F7: Held constant at year-1 prices: a price increase is a separate decision
A8: Operating days per year | B8: =IFERROR(IF('0. Assumptions'!$B$6="","",'0. Assumptions'!$B$6),"") -> 310 | C8: =IFERROR(IF(B8="","",B8),"") -> 310 | D8: =IFERROR(IF(C8="","",C8),"") -> 310
A9: TOTAL REVENUE (excl. sales tax) | B9: =IFERROR(IF(B6*B7*B8=0,"",B6*B7*B8),"") -> 1158625 | C9: =IFERROR(IF(C6*C7*C8=0,"",C6*C7*C8),"") -> 1228142.5 | D9: =IFERROR(IF(D6*D7*D8=0,"",D6*D7*D8),"") -> 1277268.2 | E9: =IFERROR(IF(B9="","",1),"") -> 1
A10: Food sales (sushi, rolls & kitchen: dine-in, take-out & delivery) | B10: =IFERROR(IF(B9="","",B9*$E$10),"") -> 984831.25 | C10: =IFERROR(IF(C9="","",C9*$E$10),"") -> 1043921.1 | D10: =IFERROR(IF(D9="","",D9*$E$10),"") -> 1085678 | E10: =IFERROR(IF('0. Assumptions'!$B$11="","",'0. Assumptions'!$B$11),"") -> 0.85 | F10: Sushi, rolls, sashimi, poke, appetizers (edamame, gyoza, tempura), miso soup and desserts: about 67% of sales dine-in, 17% take-out and 15% through delivery marketplaces. One sales tax rate in the example, whether it is eaten at the sushi bar or taken away | G10: =IFERROR(IF(B9="","",'0. Assumptions'!$B$39),"") -> 0.08
A11: Beverage sales (beer, sake, wine, soft drinks & tea) | B11: =IFERROR(IF(B9="","",B9*$E$11),"") -> 173793.75 | C11: =IFERROR(IF(C9="","",C9*$E$11),"") -> 184221.38 | D11: =IFERROR(IF(D9="","",D9*$E$11),"") -> 191590.23 | E11: =IFERROR(IF('0. Assumptions'!$B$12="","",'0. Assumptions'!$B$12),"") -> 0.15 | F11: Dine-in beverages and the drinks that go out with orders (beer, sake, wine, soft drinks and tea) · Column H is the share of beverage sales taxed at the alcohol rate in "0. Assumptions" B40. With the example rates (B39 = B40 = 8%: state + local) it changes nothing. Some states tax alcohol differently: type your alcohol rate in B40 and the alcohol share of beverage sales here | G11: =IFERROR(IF(B9="","",H11*'0. Assumptions'!$B$40+(1-H11)*'0. Assumptions'!$B$39),"") -> 0.08 | H11: 0.7
A12: VARIABLE COSTS
A13: Cost of goods sold — food | B13: =IFERROR(IF(B9="","",B9*'0. Assumptions'!$B$11*'0. Assumptions'!$B$13),"") -> 315146 | C13: =IFERROR(IF(C9="","",C9*'0. Assumptions'!$B$11*'0. Assumptions'!$B$13),"") -> 334054.76 | D13: =IFERROR(IF(D9="","",D9*'0. Assumptions'!$B$11*'0. Assumptions'!$B$13),"") -> 347416.95 | E13: =IFERROR(B13/$B$9,"") -> 0.272 | F13: =IFERROR("At "&TEXT('0. Assumptions'!$B$13,"0%")&" of FOOD sales, not of total sales: beverages have their own line · "&"fish and seafood, sushi rice, nori, imitation crab, avocado, produce, sauces and tempura ingredients: check it against your distributor invoices and the Sushi Fish, Rice & Costing Calculator","") -> At 32% of FOOD sales, not of total sales: beverages have their own line · fish and seafood, sushi rice, nori, imitation crab, avocado, produce, sauces and tempura ingredients: check it against your distributor invoices and the Sushi Fish, Rice & Costing Calculator | G13: 0
A14: Cost of goods sold — beverage | B14: =IFERROR(IF(B9="","",B9*'0. Assumptions'!$B$12*'0. Assumptions'!$B$14),"") -> 41710.5 | C14: =IFERROR(IF(C9="","",C9*'0. Assumptions'!$B$12*'0. Assumptions'!$B$14),"") -> 44213.13 | D14: =IFERROR(IF(D9="","",D9*'0. Assumptions'!$B$12*'0. Assumptions'!$B$14),"") -> 45981.655 | E14: =IFERROR(B14/$B$9,"") -> 0.036 | F14: =IFERROR("At "&TEXT('0. Assumptions'!$B$14,"0%")&" of BEVERAGE sales","") -> At 24% of BEVERAGE sales | G14: =IFERROR(IF(B9="","",'0. Assumptions'!$B$41),"") -> 0
A15: Disposables and packaging | B15: =IFERROR(IF(B9="","",B9*'0. Assumptions'!$B$15),"") -> 34758.75 | C15: =IFERROR(IF(C9="","",C9*'0. Assumptions'!$B$15),"") -> 36844.275 | D15: =IFERROR(IF(D9="","",D9*'0. Assumptions'!$B$15),"") -> 38318.046 | E15: =IFERROR(B15/$B$9,"") -> 0.03 | G15: =IFERROR(IF(B9="","",'0. Assumptions'!$B$41),"") -> 0
A16: Delivery platform fees | B16: =IFERROR(IF(B9="","",B9*'0. Assumptions'!$B$16*'0. Assumptions'!$B$17),"") -> 43448.438 | C16: =IFERROR(IF(C9="","",C9*'0. Assumptions'!$B$16*'0. Assumptions'!$B$17),"") -> 46055.344 | D16: =IFERROR(IF(D9="","",D9*'0. Assumptions'!$B$16*'0. Assumptions'!$B$17),"") -> 47897.558 | E16: =IFERROR(B16/$B$9,"") -> 0.0375 | F16: Applied to the sales of THAT CHANNEL. With 0% delivery in Assumptions, this line is zero | G16: =IFERROR(IF(B9="","",'0. Assumptions'!$B$41),"") -> 0
A17: Card processing fees | B17: =IFERROR(IF(B9="","",B9*'0. Assumptions'!$B$18),"") -> 34758.75 | C17: =IFERROR(IF(C9="","",C9*'0. Assumptions'!$B$18),"") -> 36844.275 | D17: =IFERROR(IF(D9="","",D9*'0. Assumptions'!$B$18),"") -> 38318.046 | E17: =IFERROR(B17/$B$9,"") -> 0.03 | F17: Card processing fees are not subject to sales tax: no tax is recovered or deducted for them | G17: 0
A18: Miscellaneous and contingency | B18: =IFERROR(IF(B9="","",B9*'0. Assumptions'!$B$28),"") -> 11586.25 | C18: =IFERROR(IF(C9="","",C9*'0. Assumptions'!$B$28),"") -> 12281.425 | D18: =IFERROR(IF(D9="","",D9*'0. Assumptions'!$B$28),"") -> 12772.682 | E18: =IFERROR(B18/$B$9,"") -> 0.01 | F18: =IFERROR("At "&TEXT('0. Assumptions'!$B$28,"0%")&" of sales. It is a VARIABLE cost: it moves with revenue, so it cannot sit in fixed costs","") -> At 1% of sales. It is a VARIABLE cost: it moves with revenue, so it cannot sit in fixed costs | G18: =IFERROR(IF(B9="","",'0. Assumptions'!$B$41),"") -> 0
A19: TOTAL VARIABLE COSTS | B19: =IFERROR(IF(B9="","",SUM(B13:B18)),"") -> 481408.69 | C19: =IFERROR(IF(C9="","",SUM(C13:C18)),"") -> 510293.21 | D19: =IFERROR(IF(D9="","",SUM(D13:D18)),"") -> 530704.94 | E19: =IFERROR(B19/$B$9,"") -> 0.4155
A20: GROSS MARGIN | B20: =IFERROR(IF(B9="","",B9-B19),"") -> 677216.31 | C20: =IFERROR(IF(C9="","",C9-C19),"") -> 717849.29 | D20: =IFERROR(IF(D9="","",D9-D19),"") -> 746563.26 | E20: =IFERROR(B20/$B$9,"") -> 0.5845
A21: FIXED COSTS
A22: Rent | B22: =IFERROR(IF(B9="","",'0. Assumptions'!$B$24*12),"") -> 54000 | C22: =IFERROR(IF(C9="","",B22*(1+'0. Assumptions'!$B$48)),"") -> 54000 | D22: =IFERROR(IF(D9="","",C22*(1+'0. Assumptions'!$B$48)),"") -> 54000 | E22: =IFERROR(B22/$B$9,"") -> 0.046606969 | F22: The monthly amount is on the "0. Assumptions" tab; here it is multiplied by twelve. The two months of rent before opening are on "Startup Costs" and are NOT counted twice | G22: =IFERROR(IF(B9="","",'0. Assumptions'!$B$41),"") -> 0
A23: Labor (wages + employer payroll taxes) | B23: =IFERROR(IF(B9="","",Staffing!$G$12),"") -> 384225.6 | C23: =IFERROR(IF(C9="","",Staffing!$B$16),"") -> 389225.6 | D23: =IFERROR(IF(D9="","",Staffing!$B$17),"") -> 394225.6 | E23: =IFERROR(B23/$B$9,"") -> 0.33162205 | F23: Comes from the Staffing tab: it is the SAME number, not a separate estimate. Years 2 and 3 add the new hires declared on that tab, not a percentage of volume | G23: 0
A24: Utilities (electricity, water, gas) | B24: =IFERROR(IF(B9="","",'0. Assumptions'!$B$26*12),"") -> 20400 | C24: =IFERROR(IF(C9="","",B24*(1+'0. Assumptions'!$B$48)),"") -> 20400 | D24: =IFERROR(IF(D9="","",C24*(1+'0. Assumptions'!$B$48)),"") -> 20400 | E24: =IFERROR(B24/$B$9,"") -> 0.017607077 | F24: Enter the monthly bills excl. sales tax. The workbook applies a single tax treatment to this whole line, the one in the column next to it; if one utility is taxed differently in your area, give it its own line | G24: =IFERROR(IF(B9="","",'0. Assumptions'!$B$41),"") -> 0
A25: Insurance (general + liquor liability + property + workers' comp) | B25: =IFERROR(IF(B9="","",'0. Assumptions'!$B$27),"") -> 8000 | C25: =IFERROR(IF(C9="","",B25*(1+'0. Assumptions'!$B$48)),"") -> 8000 | D25: =IFERROR(IF(D9="","",C25*(1+'0. Assumptions'!$B$48)),"") -> 8000 | E25: =IFERROR(B25/$B$9,"") -> 0.0069047362 | F25: Insurance premiums are not subject to sales tax: there is no recoverable tax on them | G25: 0
A26: Accounting & bookkeeping | B26: 4200 | C26: =IFERROR(IF(C9="","",B26*(1+'0. Assumptions'!$B$48)),"") -> 4200 | D26: =IFERROR(IF(D9="","",C26*(1+'0. Assumptions'!$B$48)),"") -> 4200 | E26: =IFERROR(B26/$B$9,"") -> 0.0036249865 | F26: Bookkeeping, income tax and payroll filings for the LLC, payroll processing and the staff paperwork (offer letters, I-9, W-4) | G26: =IFERROR(IF(B9="","",'0. Assumptions'!$B$41),"") -> 0
A27: Maintenance (semiannual hood cleaning, refrigeration & freezer, rice cookers) | B27: 3600 | C27: =IFERROR(IF(C9="","",B27*(1+'0. Assumptions'!$B$48)),"") -> 3600 | D27: =IFERROR(IF(D9="","",C27*(1+'0. Assumptions'!$B$48)),"") -> 3600 | E27: =IFERROR(B27/$B$9,"") -> 0.0031071313 | F27: The refrigeration technician for the walk-in, the reach-ins, the sushi case, the rice cookers and the freezer (which must hold −4 °F or below for the parasite records); hood and duct cleaning twice a year (NFPA 96: ask your fire marshal); and the calibration solutions for the pH meter if you use one | G27: =IFERROR(IF(B9="","",'0. Assumptions'!$B$41),"") -> 0
A28: Marketing and advertising | B28: 7000 | C28: =IFERROR(IF(C9="","",B28*(1+'0. Assumptions'!$B$48)),"") -> 7000 | D28: =IFERROR(IF(D9="","",C28*(1+'0. Assumptions'!$B$48)),"") -> 7000 | E28: =IFERROR(B28/$B$9,"") -> 0.0060416442 | F28: Google Business Profile, social media, photos, the delivery marketplaces' promotions and the peak dates (Valentine's Day, New Year's Eve platters and holiday parties); the opening campaign is in startup costs | G28: =IFERROR(IF(B9="","",'0. Assumptions'!$B$41),"") -> 0
A29: Software, POS & online ordering | B29: 3600 | C29: =IFERROR(IF(C9="","",B29*(1+'0. Assumptions'!$B$48)),"") -> 3600 | D29: =IFERROR(IF(D9="","",C29*(1+'0. Assumptions'!$B$48)),"") -> 3600 | E29: =IFERROR(B29/$B$9,"") -> 0.0031071313 | F29: POS subscription (a POS that reports sales tax), online ordering, the delivery tablets, phone and internet | G29: =IFERROR(IF(B9="","",'0. Assumptions'!$B$41),"") -> 0
A30: Cleaning, linens & uniforms | B30: 2400 | C30: =IFERROR(IF(C9="","",B30*(1+'0. Assumptions'!$B$48)),"") -> 2400 | D30: =IFERROR(IF(D9="","",C30*(1+'0. Assumptions'!$B$48)),"") -> 2400 | E30: =IFERROR(B30/$B$9,"") -> 0.0020714209 | F30: Cleaning supplies, uniform and towel laundry, gloves and any lab tests or records your written food safety plan calls for | G30: =IFERROR(IF(B9="","",'0. Assumptions'!$B$41),"") -> 0
A31: Waste, grease & used-oil hauling | B31: 1800 | C31: =IFERROR(IF(C9="","",B31*(1+'0. Assumptions'!$B$48)),"") -> 1800 | D31: =IFERROR(IF(D9="","",C31*(1+'0. Assumptions'!$B$48)),"") -> 1800 | E31: =IFERROR(B31/$B$9,"") -> 0.0015535656 | F31: Trash and cardboard pickup, the grease interceptor service and the used fryer oil, with a licensed waste / grease hauler. Enter the rates of your city | G31: =IFERROR(IF(B9="","",'0. Assumptions'!$B$41),"") -> 0
A32: Pest control | B32: 900 | C32: =IFERROR(IF(C9="","",B32*(1+'0. Assumptions'!$B$48)),"") -> 900 | D32: =IFERROR(IF(D9="","",C32*(1+'0. Assumptions'!$B$48)),"") -> 900 | E32: =IFERROR(B32/$B$9,"") -> 0.00077678282 | F32: Contract with a licensed pest control operator: it is part of the prerequisites of your written food safety plan. | G32: =IFERROR(IF(B9="","",'0. Assumptions'!$B$41),"") -> 0
A33: Music licensing (ASCAP/BMI/SESAC) | B33: 1000 | C33: =IFERROR(IF(C9="","",B33*(1+'0. Assumptions'!$B$48)),"") -> 1000 | D33: =IFERROR(IF(D9="","",C33*(1+'0. Assumptions'!$B$48)),"") -> 1000 | E33: =IFERROR(B33/$B$9,"") -> 0.00086309203 | F33: ASCAP, BMI and SESAC are separate licenses; the fee depends on the square footage and the seating of your restaurant | G33: =IFERROR(IF(B9="","",'0. Assumptions'!$B$41),"") -> 0
A34: Training & permit renewals (CFPM, allergens, HACCP plan or variance, OSHA) | B34: 3500 | C34: =IFERROR(IF(C9="","",B34*(1+'0. Assumptions'!$B$48)),"") -> 3500 | D34: =IFERROR(IF(D9="","",C34*(1+'0. Assumptions'!$B$48)),"") -> 3500 | E34: =IFERROR(B34/$B$9,"") -> 0.0030208221 | F34: Certified Food Protection Manager (CFPM) and food handler cards, allergen and raw fish handling training, the renewal of your HACCP plan or variance if you have one, and OSHA basics: knife cuts, fryer and griddle burns, freezer cold and lifting | G34: =IFERROR(IF(B9="","",'0. Assumptions'!$B$41),"") -> 0
A35: Depreciation of fixed assets | B35: =IFERROR(IF(B9="","",'Startup Costs'!$B$37),"") -> 25458.571 | C35: =IFERROR(IF(C9="","",B35),"") -> 25458.571 | D35: =IFERROR(IF(D9="","",B35),"") -> 25458.571 | E35: =IFERROR(B35/$B$9,"") -> 0.02197309 | F35: Comes from the depreciation bases on the Startup Costs tab: real fixed assets only. It does NOT rise with inflation: it is a charge on the HISTORICAL cost of the assets | G35: 0
A36: Interest expense (loan interest) | B36: =IFERROR(IF(B9="","",Financing!$B$44),"") -> 25600 | C36: =IFERROR(IF(C9="","",Financing!$B$46),"") -> 23993.718 | D36: =IFERROR(IF(D9="","",Financing!$B$48),"") -> 22226.808 | E36: =IFERROR(B36/$B$9,"") -> 0.022095156 | F36: Only INTEREST is an expense. Principal repaid appears on the cash flow tab | G36: 0
A37: TOTAL FIXED COSTS | B37: =IFERROR(IF(B9="","",SUM(B22:B36)),"") -> 545684.17 | C37: =IFERROR(IF(C9="","",SUM(C22:C36)),"") -> 549077.89 | D37: =IFERROR(IF(D9="","",SUM(D22:D36)),"") -> 552310.98 | E37: =IFERROR(B37/$B$9,"") -> 0.47097566
A38: Recoverable input tax on variable costs | B38: =IFERROR(IF(B9="","",SUMPRODUCT(B13:B18,G13:G18)),"") -> 0 | C38: =IFERROR(IF(C9="","",SUMPRODUCT(C13:C18,G13:G18)),"") -> 0 | D38: =IFERROR(IF(D9="","",SUMPRODUCT(D13:D18,G13:G18)),"") -> 0 | F38: Each line at ITS OWN rate, read from the column next to it. It is what the cash flow tab overpays to suppliers and later deducts (zero wherever no tax is recoverable)
A39: Recoverable input tax on fixed costs | B39: =IFERROR(IF(B9="","",SUMPRODUCT(B22:B36,G22:G36)),"") -> 0 | C39: =IFERROR(IF(C9="","",SUMPRODUCT(C22:C36,G22:G36)),"") -> 0 | D39: =IFERROR(IF(D9="","",SUMPRODUCT(D22:D36,G22:G36)),"") -> 0
A40: PRE-TAX INCOME (EBT) | B40: =IFERROR(IF(B9="","",B20-B37),"") -> 131532.14 | C40: =IFERROR(IF(C9="","",C20-C37),"") -> 168771.4 | D40: =IFERROR(IF(D9="","",D20-D37),"") -> 194252.28 | E40: =IFERROR(B40/$B$9,"") -> 0.11352434
A41: Net operating losses carried forward (opening) | B41: =IFERROR(IF(B9="","",'0. Assumptions'!$B$42),"") -> 0 | C41: =IFERROR(IF(C9="","",B46),"") -> 0 | D41: =IFERROR(IF(D9="","",C46),"") -> 0 | F41: Federal rules let a year's losses offset the profits of later years (the federal limit is 80% of taxable income; this model offsets 100% as a simplification)
...

Sheet Break-Even
A1: BREAK-EVEN ANALYSIS
A2: Monthly and daily break-even — sushi restaurant with sushi bar, tables, take-out and delivery
A4: Variable | B4: Year 1 | C4: Year 2 | D4: Year 3 | E4: Notes
A5: BASE DATA BY YEAR
A6: Annual fixed costs | B6: =IFERROR(IF('3-Year P&L'!$B$9="","",'3-Year P&L'!$B$37),"") -> 545684.17 | C6: =IFERROR(IF('3-Year P&L'!$C$9="","",'3-Year P&L'!$C$37),"") -> 549077.89 | D6: =IFERROR(IF('3-Year P&L'!$D$9="","",'3-Year P&L'!$D$37),"") -> 552310.98 | E6: The SAME fixed costs as the P&L. Each year has its own, which is why the threshold cannot be a single one for all three years
A7: Monthly fixed costs | B7: =IFERROR(IF('3-Year P&L'!$B$9="","",B6/12),"") -> 45473.681 | C7: =IFERROR(IF('3-Year P&L'!$C$9="","",C6/12),"") -> 45756.491 | D7: =IFERROR(IF('3-Year P&L'!$D$9="","",D6/12),"") -> 46025.915
A8: Average check (excl. sales tax) | B8: =IFERROR(IF('3-Year P&L'!$B$9="","",'3-Year P&L'!$B$7),"") -> 32.5 | C8: =IFERROR(IF('3-Year P&L'!$C$9="","",'3-Year P&L'!$C$7),"") -> 32.5 | D8: =IFERROR(IF('3-Year P&L'!$D$9="","",'3-Year P&L'!$D$7),"") -> 32.5
A9: Variable cost per cover | B9: =IFERROR(IF('3-Year P&L'!$B$9="","",'3-Year P&L'!$B$19/('3-Year P&L'!$B$6*'3-Year P&L'!$B$8)),"") -> 13.50375 | C9: =IFERROR(IF('3-Year P&L'!$C$9="","",'3-Year P&L'!$C$19/('3-Year P&L'!$C$6*'3-Year P&L'!$C$8)),"") -> 13.50375 | D9: =IFERROR(IF('3-Year P&L'!$D$9="","",'3-Year P&L'!$D$19/('3-Year P&L'!$D$6*'3-Year P&L'!$D$8)),"") -> 13.50375 | E9: Comes from the P&L total variable costs, not from a separate estimate. It includes miscellaneous and contingency, which is a percentage of sales
A10: Contribution margin per cover | B10: =IFERROR(IF('3-Year P&L'!$B$9="","",B8-B9),"") -> 18.99625 | C10: =IFERROR(IF('3-Year P&L'!$C$9="","",C8-C9),"") -> 18.99625 | D10: =IFERROR(IF('3-Year P&L'!$D$9="","",D8-D9),"") -> 18.99625 | E10: Average check minus unit variable cost
A11: Operating days per year | B11: =IFERROR(IF('3-Year P&L'!$B$9="","",'3-Year P&L'!$B$8),"") -> 310 | C11: =IFERROR(IF('3-Year P&L'!$C$9="","",'3-Year P&L'!$C$8),"") -> 310 | D11: =IFERROR(IF('3-Year P&L'!$D$9="","",'3-Year P&L'!$D$8),"") -> 310 | E11: The same calendar as the P&L and the scenarios
A12: Principal repaid in the year | B12: =IFERROR(IF('3-Year P&L'!$B$9="","",Financing!$B$45),"") -> 16062.821 | C12: =IFERROR(IF('3-Year P&L'!$C$9="","",Financing!$B$47),"") -> 17669.103 | D12: =IFERROR(IF('3-Year P&L'!$D$9="","",Financing!$B$49),"") -> 19436.014 | E12: Principal is NOT a P&L expense, but it leaves the cash account. Without it, the published break-even threshold would sit below the real one
A13: ACCOUNTING BREAK-EVEN (includes depreciation)
A14: Covers needed per year | B14: =IFERROR(IF('3-Year P&L'!$B$9="","",IF(B10<=0,"",B6/B10)),"") -> 28725.889 | C14: =IFERROR(IF('3-Year P&L'!$C$9="","",IF(C10<=0,"",C6/C10)),"") -> 28904.541 | D14: =IFERROR(IF('3-Year P&L'!$D$9="","",IF(D10<=0,"",D6/D10)),"") -> 29074.737
A15: Covers needed per day | B15: =IFERROR(IF('3-Year P&L'!$B$9="","",B14/B11),"") -> 92.664158 | C15: =IFERROR(IF('3-Year P&L'!$C$9="","",C14/C11),"") -> 93.240455 | D15: =IFERROR(IF('3-Year P&L'!$D$9="","",D14/D11),"") -> 93.789475
A16: Revenue needed per year | B16: =IFERROR(IF('3-Year P&L'!$B$9="","",B14*B8),"") -> 933591.4 | C16: =IFERROR(IF('3-Year P&L'!$C$9="","",C14*C8),"") -> 939397.59 | D16: =IFERROR(IF('3-Year P&L'!$D$9="","",D14*D8),"") -> 944928.96
A17: CASH BREAK-EVEN (loan payments in, depreciation out)
A18: Cash fixed costs + principal repaid for the year | B18: =IFERROR(IF('3-Year P&L'!$B$9="","",B6-'3-Year P&L'!$B$35+B12),"") -> 536288.42 | C18: =IFERROR(IF('3-Year P&L'!$C$9="","",C6-'3-Year P&L'!$C$35+C12),"") -> 541288.42 | D18: =IFERROR(IF('3-Year P&L'!$D$9="","",D6-'3-Year P&L'!$D$35+D12),"") -> 546288.42 | E18: The P&L fixed costs without depreciation (which is not paid in cash) and WITH principal repaid (which is). This is the threshold that decides whether cash holds up
A19: Covers needed per year (cash) | B19: =IFERROR(IF('3-Year P&L'!$B$9="","",IF(B10<=0,"",B18/B10)),"") -> 28231.278 | C19: =IFERROR(IF('3-Year P&L'!$C$9="","",IF(C10<=0,"",C18/C10)),"") -> 28494.488 | D19: =IFERROR(IF('3-Year P&L'!$D$9="","",IF(D10<=0,"",D18/D10)),"") -> 28757.698
A20: Covers needed per day (cash) | B20: =IFERROR(IF('3-Year P&L'!$B$9="","",B19/B11),"") -> 91.06864 | C20: =IFERROR(IF('3-Year P&L'!$C$9="","",C19/C11),"") -> 91.917704 | D20: =IFERROR(IF('3-Year P&L'!$D$9="","",D19/D11),"") -> 92.766768
A21: Revenue needed per year (cash) | B21: =IFERROR(IF('3-Year P&L'!$B$9="","",B19*B8),"") -> 917516.55 | C21: =IFERROR(IF('3-Year P&L'!$C$9="","",C19*C8),"") -> 926070.87 | D21: =IFERROR(IF('3-Year P&L'!$D$9="","",D19*D8),"") -> 934625.19
A22: COMPARISON WITH THE PLAN
A23: Covers per day forecast in the plan | B23: =IFERROR(IF('3-Year P&L'!$B$9="","",'3-Year P&L'!$B$6),"") -> 115 | C23: =IFERROR(IF('3-Year P&L'!$C$9="","",'3-Year P&L'!$C$6),"") -> 121.9 | D23: =IFERROR(IF('3-Year P&L'!$D$9="","",'3-Year P&L'!$D$6),"") -> 126.776
A24: Cushion above CASH break-even (%) | B24: =IFERROR(IF('3-Year P&L'!$B$9="","",B23/B20-1),"") -> 0.26278377 | C24: =IFERROR(IF('3-Year P&L'!$C$9="","",C23/C20-1),"") -> 0.32618631 | D24: =IFERROR(IF('3-Year P&L'!$D$9="","",D23/D20-1),"") -> 0.36661008 | E24: How far your projected sales exceed cash break-even sales. The drop you can absorb before you cannot pay the fixed costs and the loan payment is a bit smaller: with a 25% cushion, 20%. The minimum required is on the "0. Assumptions" tab
A25: Maximum seat turns per day the space allows | B25: 3 | E25: Full services per seat per day you can run with lunch, dinner and a second dinner turn on Friday and Saturday (stays of 45-60 minutes). It is the physical ceiling of the space, not a target
A26: Seat turns per day that the cash break-even requires | B26: =IFERROR(IF('3-Year P&L'!$B$9="","",B20/'0. Assumptions'!$B$51),"") -> 2.276716 | C26: =IFERROR(IF('3-Year P&L'!$C$9="","",C20/'0. Assumptions'!$B$51),"") -> 2.2979426 | D26: =IFERROR(IF('3-Year P&L'!$D$9="","",D20/'0. Assumptions'!$B$51),"") -> 2.3191692 | E26: Break-even covers spread across the seats declared on the "0. Assumptions" tab. If it is above the ceiling in the row above, the break-even is out of reach for the space
A27: INTERPRETATION
A28: =IFERROR("With the average check excl. sales tax above, you need "&TEXT(ROUNDUP(B15,0),"0")&" covers a day over your "&TEXT(B11,"0")&" opening days to avoid losing money (accounting break-even, depreciation included), and "&TEXT(ROUNDUP(B20,0),"0")&" for cash to hold (cash break-even: depreciation out, because it is not paid, and the year's loan payment in"&IF(B12=0,"; no principal is repaid this year (interest-only period or no loan)","")&"). The ""Revenue needed per year"" rows show the same figures in your currency.","") -> With the average check excl. sales tax above, you need 93 covers a day over your 310 opening days to avoid losing money (accounting break-even, depreciation included), and 92 for cash to hold (cash break-even: depreciation out, because it is not paid, and the year's loan payment in). The "Revenue needed per year" rows show the same figures in your currency.
A30: BREAK-EVEN SENSITIVITY
A31: Covers per day needed to cover costs for each average check (columns) and each variable cost per cover (rows). Green cells are below the covers per day the plan forecasts.
A33: Covers per day needed: average check excl. sales tax (columns) × variable cost per cover (rows) | B33: =IFERROR($B$8-2,"") -> 30.5 | C33: =IFERROR(IF($B$8="","",$B$8),"") -> 32.5 | D33: =IFERROR($B$8+2,"") -> 34.5 | E33: =IFERROR($B$8+4,"") -> 36.5
A34: =IFERROR($B$9*0.85,"") -> 11.478188 | B34: =IFERROR(IF($B$33-$A34<=0,"",$B$6/($B$33-$A34)/$B$11),"") -> 92.539632 | C34: =IFERROR(IF($C$33-$A34<=0,"",$B$6/($C$33-$A34)/$B$11),"") -> 83.735478 | D34: =IFERROR(IF($D$33-$A34<=0,"",$B$6/($D$33-$A34)/$B$11),"") -> 76.461031 | E34: =IFERROR(IF($E$33-$A34<=0,"",$B$6/($E$33-$A34)/$B$11),"") -> 70.349481
A35: =IFERROR($B$9*0.925,"") -> 12.490969 | B35: =IFERROR(IF($B$33-$A35<=0,"",$B$6/($B$33-$A35)/$B$11),"") -> 97.743821 | C35: =IFERROR(IF($C$33-$A35<=0,"",$B$6/($C$33-$A35)/$B$11),"") -> 87.97385 | D35: =IFERROR(IF($D$33-$A35<=0,"",$B$6/($D$33-$A35)/$B$11),"") -> 79.979509 | E35: =IFERROR(IF($E$33-$A35<=0,"",$B$6/($E$33-$A35)/$B$11),"") -> 73.317057
A36: =IFERROR($B$9*1.0,"") -> 13.50375 | B36: =IFERROR(IF($B$33-$A36<=0,"",$B$6/($B$33-$A36)/$B$11),"") -> 103.56823 | C36: =IFERROR(IF($C$33-$A36<=0,"",$B$6/($C$33-$A36)/$B$11),"") -> 92.664158 | D36: =IFERROR(IF($D$33-$A36<=0,"",$B$6/($D$33-$A36)/$B$11),"") -> 83.837424 | E36: =IFERROR(IF($E$33-$A36<=0,"",$B$6/($E$33-$A36)/$B$11),"") -> 76.546025
A37: =IFERROR($B$9*1.075,"") -> 14.516531 | B37: =IFERROR(IF($B$33-$A37<=0,"",$B$6/($B$33-$A37)/$B$11),"") -> 110.13076 | C37: =IFERROR(IF($C$33-$A37<=0,"",$B$6/($C$33-$A37)/$B$11),"") -> 97.882758 | D37: =IFERROR(IF($D$33-$A37<=0,"",$B$6/($D$33-$A37)/$B$11),"") -> 88.086385 | E37: =IFERROR(IF($E$33-$A37<=0,"",$B$6/($E$33-$A37)/$B$11),"") -> 80.07251
A38: =IFERROR($B$9*1.15,"") -> 15.529312 | B38: =IFERROR(IF($B$33-$A38<=0,"",$B$6/($B$33-$A38)/$B$11),"") -> 117.58121 | C38: =IFERROR(IF($C$33-$A38<=0,"",$B$6/($C$33-$A38)/$B$11),"") -> 103.72423 | D38: =IFERROR(IF($D$33-$A38<=0,"",$B$6/($D$33-$A38)/$B$11),"") -> 92.789021 | E38: =IFERROR(IF($E$33-$A38<=0,"",$B$6/($E$33-$A38)/$B$11),"") -> 83.939619

Sheet Scenarios
A1: SCENARIO ANALYSIS
A2: Pessimistic / Base / Optimistic — Year 1
A4: Metric | B4: Pessimistic | C4: Base | D4: Optimistic | E4: Notes
A5: Covers per day | B5: 95 | C5: =IFERROR(IF('3-Year P&L'!$B$6="","",'3-Year P&L'!$B$6),"") -> 115 | D5: 135
A6: Average check (excl. sales tax) | B6: 30.5 | C6: =IFERROR(IF('3-Year P&L'!$B$7="","",'3-Year P&L'!$B$7),"") -> 32.5 | D6: 34.5
A7: Operating days per year | B7: 305 | C7: =IFERROR(IF('3-Year P&L'!$B$8="","",'3-Year P&L'!$B$8),"") -> 310 | D7: 312
A8: ANNUAL REVENUE (excl. sales tax) | B8: =IFERROR(IF(B5*B6*B7=0,"",B5*B6*B7),"") -> 883737.5 | C8: =IFERROR(IF(C5*C6*C7=0,"",C5*C6*C7),"") -> 1158625 | D8: =IFERROR(IF(D5*D6*D7=0,"",D5*D6*D7),"") -> 1453140
A9: Cost of goods sold — food | B9: =IFERROR(IF(B8="","",B8*'0. Assumptions'!$B$11*'0. Assumptions'!$B$13),"") -> 240376.6 | C9: =IFERROR(IF(C8="","",C8*'0. Assumptions'!$B$11*'0. Assumptions'!$B$13),"") -> 315146 | D9: =IFERROR(IF(D8="","",D8*'0. Assumptions'!$B$11*'0. Assumptions'!$B$13),"") -> 395254.08
A10: Cost of goods sold — beverage | B10: =IFERROR(IF(B8="","",B8*'0. Assumptions'!$B$12*'0. Assumptions'!$B$14),"") -> 31814.55 | C10: =IFERROR(IF(C8="","",C8*'0. Assumptions'!$B$12*'0. Assumptions'!$B$14),"") -> 41710.5 | D10: =IFERROR(IF(D8="","",D8*'0. Assumptions'!$B$12*'0. Assumptions'!$B$14),"") -> 52313.04
A11: Disposables and packaging | B11: =IFERROR(IF(B8="","",B8*'0. Assumptions'!$B$15),"") -> 26512.125 | C11: =IFERROR(IF(C8="","",C8*'0. Assumptions'!$B$15),"") -> 34758.75 | D11: =IFERROR(IF(D8="","",D8*'0. Assumptions'!$B$15),"") -> 43594.2
A12: Delivery platform fees | B12: =IFERROR(IF(B8="","",B8*'0. Assumptions'!$B$16*'0. Assumptions'!$B$17),"") -> 33140.156 | C12: =IFERROR(IF(C8="","",C8*'0. Assumptions'!$B$16*'0. Assumptions'!$B$17),"") -> 43448.438 | D12: =IFERROR(IF(D8="","",D8*'0. Assumptions'!$B$16*'0. Assumptions'!$B$17),"") -> 54492.75
A13: Card processing fees | B13: =IFERROR(IF(B8="","",B8*'0. Assumptions'!$B$18),"") -> 26512.125 | C13: =IFERROR(IF(C8="","",C8*'0. Assumptions'!$B$18),"") -> 34758.75 | D13: =IFERROR(IF(D8="","",D8*'0. Assumptions'!$B$18),"") -> 43594.2
A14: Miscellaneous and contingency | B14: =IFERROR(IF(B8="","",B8*'0. Assumptions'!$B$28),"") -> 8837.375 | C14: =IFERROR(IF(C8="","",C8*'0. Assumptions'!$B$28),"") -> 11586.25 | D14: =IFERROR(IF(D8="","",D8*'0. Assumptions'!$B$28),"") -> 14531.4
A15: TOTAL VARIABLE COSTS | B15: =IFERROR(IF(B8="","",SUM(B9:B14)),"") -> 367192.93 | C15: =IFERROR(IF(C8="","",SUM(C9:C14)),"") -> 481408.69 | D15: =IFERROR(IF(D8="","",SUM(D9:D14)),"") -> 603779.67
A16: GROSS MARGIN | B16: =IFERROR(IF(B8="","",B8-B15),"") -> 516544.57 | C16: =IFERROR(IF(C8="","",C8-C15),"") -> 677216.31 | D16: =IFERROR(IF(D8="","",D8-D15),"") -> 849360.33
A17: FIXED COSTS (the P&L's) | B17: =IFERROR(IF(B8="","",'3-Year P&L'!$B$37),"") -> 545684.17 | C17: =IFERROR(IF(C8="","",'3-Year P&L'!$B$37),"") -> 545684.17 | D17: =IFERROR(IF(D8="","",'3-Year P&L'!$B$37),"") -> 545684.17 | E17: Fixed costs do not change with the scenario: that is why they are fixed
A18: PRE-TAX INCOME (EBT) | B18: =IFERROR(IF(B8="","",B16-B17),"") -> -29139.603 | C18: =IFERROR(IF(C8="","",C16-C17),"") -> 131532.14 | D18: =IFERROR(IF(D8="","",D16-D17),"") -> 303676.16
A19: Income tax | B19: =IFERROR(IF(B8="","",MAX(0,B18-'0. Assumptions'!$B$42)*'0. Assumptions'!$B$37),"") -> 0 | C19: =IFERROR(IF(C8="","",MAX(0,C18-'0. Assumptions'!$B$42)*'0. Assumptions'!$B$37),"") -> 32883.035 | D19: =IFERROR(IF(D8="","",MAX(0,D18-'0. Assumptions'!$B$42)*'0. Assumptions'!$B$37),"") -> 75919.04 | E19: At the "years 1-2" effective income tax rate, offsetting prior net operating losses
A20: NET INCOME | B20: =IFERROR(IF(B8="","",B18-B19),"") -> -29139.603 | C20: =IFERROR(IF(C8="","",C18-C19),"") -> 98649.106 | D20: =IFERROR(IF(D8="","",D18-D19),"") -> 227757.12
A21: Covers per day to break even | B21: =IFERROR(IF(B8="","",IF(B6-B15/(B5*B7)<=0,"",B17/(B6-B15/(B5*B7))/B7)),"") -> 100.35919 | C21: =IFERROR(IF(C8="","",IF(C6-C15/(C5*C7)<=0,"",C17/(C6-C15/(C5*C7))/C7)),"") -> 92.664158 | D21: =IFERROR(IF(D8="","",IF(D6-D15/(D5*D7)<=0,"",D17/(D6-D15/(D5*D7))/D7)),"") -> 86.732757
A22: WHAT EACH SCENARIO DEMANDS
A23: Labor cost / Sales | B23: =IFERROR(IF(B8="","",'3-Year P&L'!$B$23/B8),"") -> 0.43477345 | C23: =IFERROR(IF(C8="","",'3-Year P&L'!$B$23/C8),"") -> 0.33162205 | D23: =IFERROR(IF(D8="","",'3-Year P&L'!$B$23/D8),"") -> 0.26441059 | E23: The SAME staffing in all three scenarios. If labor cost blows up in the pessimistic case, adjust it in the Staffing tab, not here
A24: Covers per year per full-time equivalent | B24: =IFERROR(IF(B8="","",B5*B7/Staffing!$C$12),"") -> 3369.186 | C24: =IFERROR(IF(C8="","",C5*C7/Staffing!$C$12),"") -> 4145.3488 | D24: =IFERROR(IF(D8="","",D5*D7/Staffing!$C$12),"") -> 4897.6744 | E24: Covers each full-time employee in the "Staffing" tab would have to serve. In the optimistic scenario it tells you whether you need to hire
A25: Year-1 closing cash balance (estimate, same method in all three scenarios) | B25: =IFERROR(IF(B8="","",'Startup Costs'!$B$29+B20+'3-Year P&L'!$B$35-Financing!$B$45),"") -> 110312.55 | C25: =IFERROR(IF(C8="","",'Startup Costs'!$B$29+C20+'3-Year P&L'!$B$35-Financing!$B$45),"") -> 238101.26 | D25: =IFERROR(IF(D8="","",'Startup Costs'!$B$29+D20+'3-Year P&L'!$B$35-Financing!$B$45),"") -> 367209.27 | E25: ESTIMATED balance: working capital plus the year's result, adding back depreciation (which is not paid) and subtracting loan principal. It does not include the timing gap between receipts and payments or the sales tax settlement, so the three columns can be compared with each other. In red, the scenario runs out of cash
A26: Actual month-12 balance from the 12-Month Cash Flow tab (Base case only) | C26: =IFERROR(IF(C8="","",'12-Month Cash Flow'!$M$22),"") -> 309463.28 | E26: The ACTUAL base-case balance, with its timing of receipts and payments and its sales tax settlement. It exists only for the Base scenario, the only one with its own monthly cash flow: that is why it is not in the row above, where it would be compared against two estimates
A28: The "Base" column reads its three inputs from the "0. Assumptions" tab, so it reproduces EXACTLY year 1 of the P&L. The other two scenarios use the same cost rates: the only things that change are covers, average check and days. FIXED COSTS are the same in all three: miscellaneous and contingency, which is a percentage of sales, sits at the top with the variable costs and each scenario carries its own.

Sheet Staffing
A1: STAFFING STRUCTURE AND COSTS
A2: =IFERROR("Payroll — "&TEXT('0. Assumptions'!$B$21,"0")&" pay periods + employer taxes "&TEXT('0. Assumptions'!$B$20*100,"0")&"%","") -> Payroll — 12 pay periods + employer taxes 10%
A4: Position | B4: People | C4: FTE | D4: Gross pay per month (total for the position) | E4: Employer payroll taxes (total for the position) | F4: Cost per month (total for the position) | G4: Cost per year | H4: Hours per week per person | I4: Hours per year for the position | J4: Notes
A5: Owner / GM | B5: 1 | C5: 1 | D5: 4500 | E5: =IFERROR(IF(D5="","",D5*'0. Assumptions'!$B$20),"") -> 450 | F5: =IFERROR(IF(D5="","",D5+E5),"") -> 4950 | G5: =IFERROR(IF(D5="","",F5*MAX(12,'0. Assumptions'!$B$21)),"") -> 59400 | H5: =IFERROR(IF(D5="","",C5*$B$19),"") -> 40 | I5: =IFERROR(IF(D5="","",H5*B5*$B$20),"") -> 1840 | J5: Buys from the fish suppliers and files their letters, runs the floor and the delivery marketplaces and manages. In the US the owner is not the one at the sushi bar: you hire the head sushi chef (next row). The workbook imputes a monthly salary as if on payroll, which is the prudent side; confirm with your CPA how you will pay yourself (owner's draw or W-2 under an S corp). The example pays the owner below a manager: owner's draw in addition from net profit
A6: Head sushi chef (itamae) | B6: 1 | C6: 1 | D6: 5199 | E6: =IFERROR(IF(D6="","",D6*'0. Assumptions'!$B$20),"") -> 519.9 | F6: =IFERROR(IF(D6="","",D6+E6),"") -> 5718.9 | G6: =IFERROR(IF(D6="","",F6*MAX(12,'0. Assumptions'!$B$21)),"") -> 68626.8 | H6: =IFERROR(IF(D6="","",C6*$B$19),"") -> 40 | I6: =IFERROR(IF(D6="","",H6*B6*$B$20),"") -> 1840 | J6: The head sushi chef (itamae) buys and cuts the fish, runs the sushi bar, signs off the menu, the sushi rice SOP and the parasite records. About $30 per hour in the example. Hire this person before the build-out: it is an investment, not an expense
A7: Kitchen line cook (tempura, gyoza, rice) | B7: 1 | C7: 1 | D7: 3119 | E7: =IFERROR(IF(D7="","",D7*'0. Assumptions'!$B$20),"") -> 311.9 | F7: =IFERROR(IF(D7="","",D7+E7),"") -> 3430.9 | G7: =IFERROR(IF(D7="","",F7*MAX(12,'0. Assumptions'!$B$21)),"") -> 41170.8 | H7: =IFERROR(IF(D7="","",C7*$B$19),"") -> 40 | I7: =IFERROR(IF(D7="","",H7*B7*$B$20),"") -> 1840 | J7: The rice cookers, gyoza, tempura, miso soup and teriyaki. About $18 per hour in the example
A8: Sushi chef | B8: 1 | C8: 1 | D8: 3639 | E8: =IFERROR(IF(D8="","",D8*'0. Assumptions'!$B$20),"") -> 363.9 | F8: =IFERROR(IF(D8="","",D8+E8),"") -> 4002.9 | G8: =IFERROR(IF(D8="","",F8*MAX(12,'0. Assumptions'!$B$21)),"") -> 48034.8 | H8: =IFERROR(IF(D8="","",C8*$B$19),"") -> 40 | I8: =IFERROR(IF(D8="","",H8*B8*$B$20),"") -> 1840 | J8: Rolls, platters for the delivery marketplaces and the sushi bar when the head sushi chef is off: about $21 per hour (Indeed lists $20.72). With a single person who can cut and build, one absence closes the sushi bar
A9: Servers, host & to-go packing (W-2, tips on top) | B9: 4 | C9: 0.75 | D9: 7798 | E9: =IFERROR(IF(D9="","",D9*'0. Assumptions'!$B$20),"") -> 779.8 | F9: =IFERROR(IF(D9="","",D9+E9),"") -> 8577.8 | G9: =IFERROR(IF(D9="","",F9*MAX(12,'0. Assumptions'!$B$21)),"") -> 102933.6 | H9: =IFERROR(IF(D9="","",C9*$B$19),"") -> 30 | I9: =IFERROR(IF(D9="","",H9*B9*$B$20),"") -> 5520 | J9: Four servers at 0.75 each: dining room, pickup and to-go packing, $15 per hour. Tips go on top and belong to the team
A10: Sushi chef (part-time W-2, weekends & dinner peaks) | B10: 1 | C10: 0.6 | D10: 2080 | E10: =IFERROR(IF(D10="","",D10*'0. Assumptions'!$B$20),"") -> 208 | F10: =IFERROR(IF(D10="","",D10+E10),"") -> 2288 | G10: =IFERROR(IF(D10="","",F10*MAX(12,'0. Assumptions'!$B$21)),"") -> 27456 | H10: =IFERROR(IF(D10="","",C10*$B$19),"") -> 24 | I10: =IFERROR(IF(D10="","",H10*B10*$B$20),"") -> 1104 | J10: Part-time W-2 sushi chef for Friday and Saturday dinners and platters made to order: about $20 per hour, never as a 1099 contractor. This plan has NO in-house delivery: if you add it, the driver is a W-2 employee with hired and non-owned auto insurance
A11: Dish & prep | B11: 1 | C11: 1 | D11: 2773 | E11: =IFERROR(IF(D11="","",D11*'0. Assumptions'!$B$20),"") -> 277.3 | F11: =IFERROR(IF(D11="","",D11+E11),"") -> 3050.3 | G11: =IFERROR(IF(D11="","",F11*MAX(12,'0. Assumptions'!$B$21)),"") -> 36603.6 | H11: =IFERROR(IF(D11="","",C11*$B$19),"") -> 40 | I11: =IFERROR(IF(D11="","",H11*B11*$B$20),"") -> 1840 | J11: Coverage for vacations and the team's days off through the year. Paid sick leave is required by some states and cities: check yours
A12: TOTAL STAFF | B12: =IFERROR(IF(COUNT(D5:D11)=0,"",SUM(B5:B11)),"") -> 10 | C12: =IFERROR(IF(COUNT(D5:D11)=0,"",SUMPRODUCT(B5:B11,C5:C11)),"") -> 8.6 | D12: =IFERROR(IF(COUNT(D5:D11)=0,"",SUM(D5:D11)),"") -> 29108 | E12: =IFERROR(IF(COUNT(D5:D11)=0,"",SUM(E5:E11)),"") -> 2910.8 | F12: =IFERROR(IF(COUNT(D5:D11)=0,"",SUM(F5:F11)),"") -> 32018.8 | G12: =IFERROR(IF(COUNT(D5:D11)=0,"",SUM(G5:G11)),"") -> 384225.6 | I12: =IFERROR(IF(COUNT(D5:D11)=0,"",SUM(I5:I11)),"") -> 15824
A13: STAFF GROWTH (stepped cost)
A14: Annual cost of year-2 hires | B14: 5000 | J14: FULL ANNUAL cost (gross pay + employer payroll taxes, over all pay periods) of whoever you hire that year. The P&L adds it to the previous year's cost: staffing grows by people, not by a percentage
A15: Annual cost of year-3 hires | B15: 5000 | J15: FULL ANNUAL cost (gross pay + employer payroll taxes, over all pay periods) of whoever you hire that year. The P&L adds it to the previous year's cost: staffing grows by people, not by a percentage
A16: Labor cost, year 2 | B16: =IFERROR(IF(G12="","",G12*(1+'0. Assumptions'!$B$48)+B14),"") -> 389225.6
A17: Labor cost, year 3 | B17: =IFERROR(IF(B16="","",B16*(1+'0. Assumptions'!$B$48)+B15),"") -> 394225.6
A18: COVERAGE OF SERVICE HOURS
A19: Full-time week (hours per week) | B19: 40 | J19: 40 hours a week is the FLSA overtime threshold for non-exempt employees; some states add daily overtime rules. Change it if your own full-time week is different
A20: Weeks worked per year per person | B20: 46 | J20: 46 weeks: 52 minus about six weeks for vacation, holidays and average absences. There is no federal vacation requirement in the US: adjust it to your own policy
A21: Service hours per day to cover | B21: 7.5 | J21: Hours the restaurant is open to the public, adding lunch (11:30-14:30) and dinner (17:00-21:30; 22:00 on Friday and Saturday). The afternoon between the two services is not counted
A22: People needed at the same time in each shift | B22: 4.5 | J22: Average number of people at the same time across the sushi bar, the hot line, the dining room and the to-go orders. On Friday and Saturday nights you need more: the part-time sushi chef and the extra servers come in (the annual roster does not see them: put them in the shift)
A23: Production hours per day BEFORE opening | B23: 3 | J23: The day's sushi rice, cutting and cleaning the fish, sauces and mise en place before opening
A24: People on the production shift | B24: 2 | J24: The head sushi chef and the line cook. Closing, cleaning and purchasing are outside this schedule: they are the margin between the hours you hire and the hours you need
