Workbook

Sheet Instrucciones
A1: Capacidad del obrador, clima y ficha de visita al local
A2: AI Chef Pro · aichef.pro — Cómo Montar una Chocolatería
A3: Para qué sirve: decidir si ESE local sirve, si se puede climatizar y cuántos bombones al día aguanta el equipo que estás comprando.
A5: Instrucciones de uso
A6: 1. Hoja «Parámetros»: lo primero. Horas de turno, turnos al día, piezas que quieres vender, superficie, potencia, temperatura exterior de tu ciudad en agosto y la potencia frigorífica que te ofrezcan. Todo lo demás del libro se recalcula desde aquí; no hay ni un número escondido dentro de una fórmula.
A7: 2. Hoja «Zonas y m²»: reparte los metros entre las seis zonas y numera el recorrido de la marcha adelante, del 1 al 6. La hoja te dice si el reparto cuadra con la superficie declarada, qué parte del local es producción y si el recorrido tiene un cruce.
A8: 3. Hoja «Clima del Obrador»: las cinco temperaturas objetivo, el semáforo de coherencia entre lo que quieres, el agosto de tu ciudad y lo que te ofrece el instalador, y la ficha de preguntas que hay que hacerle. Esta hoja NO calcula la carga térmica de tu obrador, y no lo hace a propósito: lo explica dentro.
A9: 4. Hoja «Capacidad por Equipo»: una fila por máquina y por puesto de trabajo. Di si lo tienes, cuánto cabe en un ciclo, cuántos bombones salen de esa cantidad, cuántos minutos dura el ciclo y qué parte de tu surtido pasa por ahí. La hoja devuelve los bombones al día que ESO permite al obrador entero.
A10: 5. Hoja «Cuello de Botella»: el resultado. Cuál es el equipo que manda, cuántos bombones al día aguanta el conjunto, cuánta holgura te queda y qué pasa en cada una de las doce campañas del año. Aquí se ve si Navidad y San Valentín te caben en el obrador que estás comprando.
A11: 6. Hoja «Ficha de Visita a Local»: imprímela y llévala a cada visita. Dieciocho comprobaciones, seis de ellas eliminatorias. Un solo «No» en un ítem eliminatorio y el veredicto es DESCARTAR: no es pesimismo, es que ese defecto no se arregla con dinero razonable.
A13: Celdas verdes = campos editables
A15: Lo que conviene saber antes de empezar
... A24: Dónde acaba este libro y dónde sigue el Kit de Tareas Chocolatería
A25: Lo que necesitas | B25: Dónde está | C25: Por qué no está aquí
A26: Las curvas de templado de cada cobertura y las fichas de moldeado | B26: kit-tareas-chocolateria/02-partidas-produccion.xlsx | C26: El kit las publica y esta guía NO las repite. Aquí sólo hay capacidad y clima, no técnica de templado.
A27: Las fechas de cada campaña y qué se hace en cada una | B27: kit-tareas-chocolateria/BONUS-02-calendario-anual-tareas.xlsx | C27: El kit pone las fechas y el qué. Aquí la campaña entra sólo como multiplicador de bombones al día; los euros de cada una son el libro 6 de esta guía.
A28: Cuánta gente hace falta y cuánto cuesta con la Seguridad Social | B28: Libro 7 de esta guía, hoja «Personal» | C28: Un obrador de chocolate no tiene jornada de madrugada, así que esta guía no lleva libro de turnos: el personal se resuelve en el plan financiero. Aquí las horas de turno son un parámetro de capacidad.
A29: Cuánto cuesta cada máquina y cuánto tarda en llegar | B29: Libros 2 (CAPEX) y 9 (equipamiento y proveedores) | C29: El precio y el plazo no cambian la capacidad. Se separan a propósito para poder decidir primero qué necesitas y después qué te cuesta.
A30: Qué temperatura y qué vida útil declaras en tu etiqueta | B30: Libro 5 de esta guía: vida útil y rotación | C30: Aquí está el clima del LOCAL. Lo que declaras por referencia -y si va envasada con etiqueta o a granel- es otra decisión y otro libro.
A31: Es COPIA declarada, no vínculo: en toda la guía no hay ni una fórmula que apunte a otro fichero. Un enlace entre libros se rompe en cuanto alguien mueve una carpeta, y entonces el libro miente sin avisar. Donde una celda verde traería un dato del Kit de Tareas Chocolatería o de otro libro, viene con un valor por defecto propio, declarado como supuesto, y su nota te dice qué lo sustituye.
A33: Cada cuánto se usa este libro
A34: Cadencia: la hoja «Ficha de Visita a Local», UNA VEZ POR LOCAL que visites, y se guarda aunque lo descartes -comparar tres fichas es lo que enseña qué estás aceptando sin darte cuenta-. La hoja «Clima del Obrador», una vez por cada oferta de instalador que recibas. Las hojas de capacidad, cada vez que cambies un equipo del presupuesto y, después de abrir, UNA VEZ AL AÑO en septiembre, antes de arrancar la campaña de Navidad.
A36: Para editar la estructura o una celda que no esté en verde: Revisar > Desproteger hoja (no tiene contraseña).
A38: Diseñado por John Guerrero — chef y consultor gastronómico desde 2010, en cocina desde los 17 años.
A39: Versión 1.0 · septiembre 2026 · aichef.pro/guia-chocolateria-obrador · info@aichef.pro

Sheet Parámetros
A1: Parámetros
A2: AI Chef Pro · aichef.pro — Cómo Montar una Chocolatería
A3: Todo lo que el libro calcula sale de aquí. Ni un número vive dentro de una fórmula.
A5: Parámetro | B5: Valor | C5: Unidad | D5: Procedencia | E5: Qué es y de dónde sale
A6: Horas de turno del obrador | B6: 8 | C6: h por turno | D6: supuesto | E6: Duración del turno de obrador. Es el número que multiplica todo lo demás: con dos turnos, la capacidad se duplica sin comprar una sola máquina, y en chocolate el segundo turno es más barato que en pastelería porque no hay madrugada.
A7: Turnos de obrador al día | B7: 1 | C7: turnos | D7: supuesto | E7: La Almendra trabaja a un turno. Súbelo a 2 y mira la hoja «Cuello de Botella» antes de comprar una máquina más grande.
A8: Horas productivas sobre la jornada | B8: 0.85 | C8: % | D8: supuesto | E8: Parte de la jornada que se pasa a pie de mesa. El 15 % restante es recepción, limpieza, formación y reuniones.
A9: Minutos disponibles al día | B9: =IFERROR(B6*B7*B8*60,"") -> 408 | C9: minutos | D9: Se calcula | E9: Horas de turno x turnos x horas productivas x 60. De aquí salen los ciclos al día de cada equipo.
A10: Días de apertura a la semana | B10: 6 | C10: días | D10: supuesto | E10: 6 días por semana x 52 semanas = 312, menos 8 días de cierre por festivos = 304. En agosto la TIENDA NO CIERRA: lo que para es el obrador (D36, y el literal del kit dice «la tienda abre para el turista aunque el obrador pare»). Una bombonería de menos de 300 m² tiene libertad horaria por el art. 5.2 de la Ley 1/2004, no por el 5.1 (`CHN-77`).
A11: Días de apertura al año | B11: 304 | C11: días | D11: supuesto | E11: 6 días por semana x 52 semanas = 312, menos 8 días de cierre por festivos. En agosto la TIENDA no cierra: lo que para es el obrador.
A12: Piezas vendibles al día en velocidad de crucero | B12: 93.8 | C12: piezas al día | D12: supuesto | E12: Clientes al día x piezas por ticket, los dos supuestos: no existe dato público de tráfico de bombonería, y `N-13` prohíbe publicar uno. Una «pieza vendible» es lo que entra en la bolsa: un bombón suelto, una tableta o UNA CAJA. Si ya tienes el Kit de Tareas Chocolatería, sustitúyelo por tu dato real de kit-tareas-chocolateria/02-partidas-produccion.xlsx.
A13: Bombones equivalentes por pieza vendible | B13: 5.03 | C13: bombones por pieza | D13: supuesto derivado de la carta | E13: LA COLUMNA QUE EVITA EL ERROR DE BULTO. Una caja de 35 bombones no es una pieza de obrador: son 35 bombones moldeados más el montaje de la caja. Sale de los minutos de mano de obra por tanda de cada referencia de la carta, medidos contra la tanda de referencia (24 cavidades x 6 moldes en 155 minutos). Con tu propio mix, recalcúlala.
A14: Bombones equivalentes al día en velocidad de crucero | B14: =IFERROR(B12*B13,"") -> 471.814 | C14: bombones al día | D14: Se calcula | E14: Piezas vendibles x bombones equivalentes por pieza. Es el número contra el que se mide TODA la capacidad de este libro.
A15: Margen de seguridad exigido sobre la capacidad | B15: 0.1 | C15: % | D15: supuesto | E15: Holgura mínima que quieres tener sobre el día normal. Por debajo de ella el libro avisa: una avería del frío, una baja o un pedido corporativo te dejan sin género aunque en teoría llegues.
A16: Superficie total del local | B16: 75 | C16: m2 | D16: supuesto | E16: Supuesto declarado, elegido por convergencia de cuatro fuentes CON SU FORMATO DICHO: `CHS-03` (bombonería artesana, 60-100 m²), `CHS-38a` (pasteleria-bomboneria con obrador, 90 m² y 26.000 euros de traspaso: el comparable mas cercano del censo), `CHS-58` (mínimo de franquicia, 55 m²) y, como referencia de OTRO formato, los traspasos de churreria-chocolateria `CHS-37a` (75 m²) y `CHS-37b` (74 m²). Se elige 75 por estar dentro de `CHS-03` y por debajo de `CHS-38a`. El reparto por zona también es supuesto.
A17: Parte mínima del local dedicada a producción | B17: 0.55 | C17: % | D17: supuesto | E17: Criterio de la casa, no norma: por debajo de esto la tienda se come al obrador y acabas comprando bombón hecho. En chocolate la zona de producción son cuatro zonas, no una: obrador, cámara, almacén de cobertura y envasado.
A18: Potencia eléctrica instalada total prevista | B18: 28 | C18: kW | D18: supuesto | E18: Supuesto. Un obrador de chocolate NO tiene hornos: lo que consume es el frío (cámara, nevera de rellenos y vitrina, 24 horas), la climatización con deshumidificación y la atemperadora. La potencia a contratar la fija el proyecto eléctrico, no una tabla: el libro 1 la pide en celda verde.
A19: Temperatura exterior de tu ciudad en agosto | B19: 36 | C19: grados C | D19: supuesto | E19: Supuesto de ciudad media española de interior en agosto. Es una CELDA VERDE del libro 1: el lector pone la de su ciudad, y con ella el semáforo compara la temperatura objetivo del obrador con la potencia frigorífica que le OFREZCA EL INSTALADOR. El libro NO calcula carga térmica (D33): no hay un solo coeficiente con fuente.
A20: Potencia frigorífica que te OFRECE el instalador | B20: 9 | C20: kW | D20: supuesto | E20: LA QUE TE OFRECE ÉL, no la que calcula este libro: este libro NO calcula carga térmica, y lo dice en la hoja «Clima del Obrador». Pídela por escrito con el salto de temperatura de diseño al lado.
A21: Salto de temperatura de diseño que declara el instalador | B21: 16 | C21: grados C | D21: supuesto | E21: El salto de temperatura para el que ha dimensionado su equipo. Es la pregunta que casi nadie hace, y la que decide si esa oferta sirve en agosto: si ha diseñado para un salto menor que el tuyo, el equipo no llega el día que de verdad hace falta.
A22: Altura libre mínima que exiges al local | B22: 2.7 | C22: m | D22: supuesto | E22: Un obrador de chocolate no lleva campana ni conducto a cubierta, así que necesita menos altura que una pastelería. Lo que sí necesita es sitio para la unidad interior de la climatización y para el conducto de la deshumidificación.
A23: Número de zonas del local | B23: 6 | C23: zonas | D23: supuesto | E23: Las seis zonas de La Almendra. NO es el reparto de una pastelería: aquí no hay zona de horno ni de fermentación, y sí cámara climatizada.
A24: Superficie máxima de venta sin licencia previa (Ley 12/2012) | B24: 750 | C24: m2 | D24: CHN-49 + CHN-49b | E24: Ningún ayuntamiento puede exigirte licencia previa de instalación, de funcionamiento o de actividad hasta 750 m² de superficie útil de exposición y venta al público, porque el epígrafe 644.5 «Comercio al por menor de bombones y caramelos» está en el Anexo de la Ley 12/2012. OJO: la chocolatería de TAZA (grupo 676) NO está en ese Anexo (`CHN-49c`), así que la variante de taza y churros no se libra.
A26: Los valores marcados «supuesto» son los de la bombonería de ejemplo «La Almendra» (75 m², 45 de producción y 22 de tienda, un turno, tres personas y 2,5 jornadas). NO son datos de sector: son un punto de partida coherente para que puedas ver el libro funcionando antes de meter los tuyos.
A28: La temperatura exterior de agosto, la potencia frigorífica ofertada y el salto de diseño del instalador son las TRES celdas con las que trabaja el semáforo de coherencia de la hoja «Clima del Obrador». Este libro NO calcula la carga térmica de tu obrador: no existe un coeficiente publicado y verificable para hacerlo, y publicar uno inventado sería peor que no publicar nada. Lo que hace es comprobar que las tres cifras encajan entre sí y darte las preguntas que le tienes que hacer a quien sí puede calcularla.

Sheet Zonas y m2
A1: Zonas y Metros Cuadrados
A2: AI Chef Pro · aichef.pro — Cómo Montar una Chocolatería
A3: Las seis zonas de una bombonería con obrador y el recorrido de marcha adelante. No es el reparto de una pastelería: aquí no hay zona de horno ni de fermentación, y sí cámara climatizada.
A5: Nº | B5: Zona | C5: Bloque | D5: m2 | E5: % del local | F5: Paso del recorrido | G5: Qué tiene que cumplir
A6: 1 | B6: Obrador de templado y moldeado | C6: Producción | D6: 26 | E6: =IFERROR(D6/$D$13,"") -> 0.34666667 | F6: 2 | G6: La zona que manda sobre el local: aquí van la atemperadora, la mesa de mármol o granito, la enrobadora y los moldes. Clima propio (18-20 °C y 50-60 % de humedad, kit-tareas-chocolateria/08-apertura-cierre-negocio.xlsx, hoja «Apertura del Negocio») y marcha adelante: la cobertura entra por un extremo y el bombón acabado sale por el otro sin cruzarse con ella.
A7: 2 | B7: Cámara de chocolate | C7: Producción | D7: 6 | E7: =IFERROR(D7/$D$13,"") -> 0.08 | F7: 3 | G7: Zona propia y climatizada a 15-18 °C con 50-60 % de humedad (kit-tareas-chocolateria/01-apertura-cierre.xlsx, hoja «Apertura»). No es una nevera: el chocolate acabado NO va a 4 °C. Dentro de ella, o al lado, la nevera de rellenos y ganaches a 0-4 °C.
A8: 3 | B8: Almacén de cobertura y materias primas | C8: Producción | D8: 8 | E8: =IFERROR(D8/$D$13,"") -> 0.10666667 | F8: 1 | G8: La cobertura llega en cajas de 5 a 25 kg y es el inmovilizado más grande del obrador: el libro 3 calcula cuántas semanas de stock caben aquí. En oscuridad y lejos de olores fuertes: el cacao los absorbe (kit-tareas-chocolateria/02-partidas-produccion.xlsx, hoja «Moldeado»).
A9: 4 | B9: Envasado y packaging | C9: Producción | D9: 5 | E9: =IFERROR(D9/$D$13,"") -> 0.066666667 | F9: 4 | G9: Mesa de montaje de cajas, etiquetadora y almacén de packaging de campaña. Es la zona que se desborda en Navidad y la que nadie dibuja en el plano.
A10: 5 | B10: Tienda y mostrador | C10: Tienda | D10: 22 | E10: =IFERROR(D10/$D$13,"") -> 0.29333333 | F10: 5 | G10: Sala a 20-22 °C (kit-tareas-chocolateria/01-apertura-cierre.xlsx, hoja «Apertura») con la vitrina de bombonería a 16-18 °C. Los dos climas son distintos y conviven en la misma sala: es el motivo de que la vitrina lleve su propio control.
A11: 6 | B11: Aseos y vestuario | C11: Servicios | D11: 8 | E11: =IFERROR(D11/$D$13,"") -> 0.10666667 | F11: 6 | G11: Vestuario de personal separado del aseo de público. Si no caben los dos, el local no sirve: es una de las eliminatorias de la ficha de visita.
B13: TOTAL repartido | D13: =SUM(D6:D11) -> 75 | E13: =SUM(E6:E11) -> 1
B14: Superficie declarada en «Parámetros» | D14: ='Parámetros'!B16 -> 75
B15: Descuadre (m²) | D15: =IFERROR(D13-D14,"") -> 0 | G15: Si no es cero, o te sobran metros sin asignar o has repartido más de los que tiene el local.
B17: Metros de zona de producción | D17: =SUMIF(C6:C11,"Producción",D6:D11) -> 45
B18: Parte del local dedicada a producción | D18: =IFERROR(D17/D13,"") -> 0.6
B19: Metros de tienda y mostrador | D19: =SUMIF(C6:C11,"Tienda",D6:D11) -> 22 | G19: Es la superficie que se compara con los 750 m² de la Ley 12/2012 en la ficha de visita: la de EXPOSICIÓN Y VENTA al público, no la del local entero.
B20: Parte del local dedicada a venta | D20: =IFERROR(D19/D13,"") -> 0.29333333
B21: Mínimo de producción que te has exigido | D21: ='Parámetros'!B17 -> 0.55
B22: Veredicto del reparto | D22: =IF(D18="","",IF(D18<D21,"La producción se queda corta","Reparto suficiente")) -> Reparto suficiente
B24: Marcha adelante: la cobertura entra por un extremo y el bombón sale por el otro
B25: Suma de los pasos que has numerado | D25: =SUM(F6:F11) -> 21
B26: Suma que debería dar (1 + 2 + ... + n) | D26: =IFERROR('Parámetros'!B23*('Parámetros'!B23+1)/2,"") -> 21
B27: ¿Están numerados del 1 al n sin repetir? | D27: =IF(AND(D25=D26,MIN(F6:F11)=1,MAX(F6:F11)='Parámetros'!B23),"Sí","Revisa la numeración") -> Sí | G27: Comprobación de numeración: la suma tiene que cuadrar y los pasos ir del 1 al número de zonas. No detecta una permutación que sume igual; lo que detecta -y es lo que pasa siempre- es un número repetido o uno saltado.
B28: La cobertura entra antes que el obrador | D28: =IF(F8<F6,"Sí","No") -> Sí
B29: El bombón acabado pasa del obrador a la cámara | D29: =IF(F7>F6,"Sí","No") -> Sí
B30: El envasado va después de la cámara | D30: =IF(F9>F7,"Sí","No") -> Sí
B31: Lo envasado llega a la tienda sin volver atrás | D31: =IF(F9<=F10,"Sí","No") -> Sí
B32: El vestuario no está en mitad del recorrido de producción | D32: =IF(F11>F9,"Sí","No") -> Sí
B34: VEREDICTO DE MARCHA ADELANTE | D34: =IF(COUNTIF(D28:D32,"No")>0,"Hay un cruce en el recorrido","Marcha adelante correcta") -> Marcha adelante correcta
B36: La marcha adelante no es una preferencia de diseño: es que la materia prima y el producto terminado no se crucen nunca. En chocolate tiene además un motivo propio: el cacao absorbe los olores, así que el almacén de cobertura no puede compartir aire con la basura ni con el cuarto de limpieza. Cuando el local no permite el recorrido, no se arregla con un cartel ni con un horario; se arregla con obra o no se arregla. Por eso se dibuja sobre el plano ANTES de firmar.

Sheet Clima del Obrador
A1: Clima del Obrador
A2: AI Chef Pro · aichef.pro — Cómo Montar una Chocolatería
A3: Las cinco temperaturas objetivo son las que ya publica el Kit de Tareas Chocolatería. Esta hoja NO calcula la carga térmica de tu obrador: comprueba que lo que quieres, el agosto de tu ciudad y lo que te ofrece el instalador son coherentes, y te da las preguntas que hay que hacerle.
A5: Las cinco ventanas de temperatura y humedad
A6: Dónde | B6: T mínima | C6: T máxima | D6: HR mínima | E6: HR máxima | F6: De dónde sale | G6: Literal del kit | H6: Qué pasa si te sales
A7: Obrador de templado y moldeado | B7: 18 | C7: 20 | D7: 50 | E7: 60 | F7: kit-tareas-chocolateria/08-apertura-cierre-negocio.xlsx, hoja «Apertura del Negocio» | G7: Verificar la temperatura y la humedad del obrador: objetivo 18-20 °C y 50-60 % | H7: Es la tarea 17 de la hoja, y es el objetivo mas restrictivo que publica el kit: es el que manda. `CHS-44` publica 18-22 °C como rango de trabajo de un tercero, y entra en la prosa del cap. 07 como tal, nunca como objetivo del juego de datos.
A8: Cámara de conservación de chocolate | B8: 15 | C8: 18 | D8: 50 | E8: 60 | F8: kit-tareas-chocolateria/01-apertura-cierre.xlsx, hoja «Apertura» | G8: Comprobar que la cámara de conservación ha funcionado toda la noche (sin cortes ni alarmas) y registrar la temperatura: objetivo 15-18 °C y 50-60 % de humedad | H8: Tarea 2. Es la misma ventana en la que el kit declara las vidas útiles.
A9: Nevera de rellenos y ganaches | B9: 0 | C9: 4 | F9: kit-tareas-chocolateria/01-apertura-cierre.xlsx, hoja «Apertura» | G9: Comprobar que la nevera de rellenos y ganaches ha funcionado toda la noche y registrar la temperatura: objetivo 0-4 °C | H9: Tarea 3. Es la nevera del RELLENO, no la del bombón acabado: el chocolate terminado no va a 4 °C, condensa.
A10: Sala de tienda | B10: 20 | C10: 22 | F10: kit-tareas-chocolateria/01-apertura-cierre.xlsx, hoja «Apertura» | G10: Encender aire acondicionado - mantener sala 20-22 °C | H10: Tarea 6. Confundir la temperatura de la SALA con la de la CÁMARA es uno de los errores de método que la SPEC prohíbe: son dos cosas distintas y conviven en el mismo local.
A11: Vitrina de bombonería | B11: 16 | C11: 18 | E11: 55 | F11: kit-tareas-chocolateria/08-apertura-cierre-negocio.xlsx, hoja «Apertura del Negocio» | G11: Comprobar que las vitrinas temperadas han alcanzado 16-18 °C y menos del 55 % de humedad antes de montar el genero | H11: Tarea 16. Es el OBJETIVO OPERATIVO, lo que se comprueba cada mañana. `CHS-43` publica además el RANGO DE TRABAJO de un equipo real (+14/+17 °C, Docriluc WB-6-6-R, base SIN IVA declarada), que es otra cosa. El semáforo del libro 5 se alimenta del rango que el lector teclea y solo avisa por encima de 20 °C.
A13: NO HAY UNA TEMPERATURA LEGAL DEL CHOCOLATE. El RD 1021/2022 no nombra el chocolate ni una sola vez, y su art. 4.2 se aplica a la temperatura que ponga en su etiqueta quien ha producido y envasado el producto. Para el bombón que despachas a granel no hay etiqueta: la referencia es TU sistema de autocontrol, y la temperatura la declaras tú en él. Las cinco de esta tabla son las que ya publica el Kit de Tareas Chocolatería, y por eso las usa la guía: un concepto, una fuente.
A15: Primera comprobación: ¿son coherentes entre sí las cinco ventanas?
A16: La cámara está por debajo del obrador | F16: =IF(OR(C8="",B7=""),"",IF(C8<=B7,"Sí","No")) -> Sí | H16: El bombón acabado sale del obrador y entra en la cámara: si la cámara está más caliente que el obrador, la cámara no conserva nada.
A17: La sala de tienda está por encima del obrador | F17: =IF(OR(B10="",C7=""),"",IF(B10>=C7,"Sí","No")) -> Sí | H17: La sala es para el cliente y el obrador para el chocolate. Son dos climas distintos que conviven en el mismo local, y por eso la puerta entre los dos importa.
A18: La vitrina está por debajo de la sala | F18: =IF(OR(C11="",B10=""),"",IF(C11<=B10,"Sí","No")) -> Sí | H18: La vitrina tiene su propio control porque la sala la calienta. Si el escaparate da al sol de mediodía, esto deja de cumplirse solo.
A19: La nevera de rellenos está por debajo de la cámara | F19: =IF(OR(C9="",B8=""),"",IF(C9<=B8,"Sí","No")) -> Sí | H19: La nevera es la del RELLENO, a 0-4 °C. El bombón acabado NO va a 4 °C: condensa, y el agua de la condensación disuelve el azúcar de la superficie.
A20: Ventanas incoherentes entre sí | F20: =COUNTIF(F16:F19,"No") -> 0
A22: Segunda comprobación: ¿encaja lo que te ofrece el instalador?
A23: Temperatura objetivo máxima del obrador | F23: =C7 -> 20 | H23: La de la primera fila de la tabla de arriba. Si la subes, el salto baja y la oferta encaja mejor: también te quedas sin margen para templar.
A24: Temperatura exterior de tu ciudad en agosto | F24: ='Parámetros'!B19 -> 36
A25: Salto de temperatura que tiene que vencer el equipo | F25: =IFERROR(F24-F23,"") -> 16 | H25: Aritmética pura, sin ningún coeficiente: la de fuera menos la que quieres dentro. Es el número que hay que llevar a la conversación con el instalador.
A26: Salto de diseño que declara el instalador | F26: ='Parámetros'!B21 -> 16
A27: Potencia frigorífica que te OFRECE el instalador | F27: ='Parámetros'!B20 -> 9
A28: Metros de producción a climatizar | F28: ='Zonas y m2'!D17 -> 45
A29: Potencia ofertada por metro climatizado | F29: =IFERROR(F27/F28,"") -> 0.2 | H29: NO ES UN CRITERIO DE DIMENSIONADO Y POR ESO NO LLEVA SEMÁFORO: es tu propia oferta dividida entre tus propios metros. Sirve para una sola cosa, y es útil: enseñársela al segundo instalador y preguntarle por qué la suya se parece o no se parece. Cualquier tabla que te diga «tantos kW por m² de obrador de chocolate» está inventada.
A30: ¿Te ha dado la potencia por escrito? | F30: Por pedir
A31: ¿Te ha dicho por escrito para qué salto la ha calculado? | F31: Por pedir
A33: SEMÁFORO DE COHERENCIA | F33: =IF(OR(F25="",F26="",F27=""),"",IF(F26<F25,"INCOHERENTE: el salto de diseño se queda corto",IF(F20>0,"REVISA LA VENTANA CLIMÁTICA",IF(OR(F30<>"Sí",F31<>"Sí"),"PIDE LA OFERTA POR ESCRITO","COHERENTE")))) -> PIDE LA OFERTA POR ESCRITO | H33: El semáforo compara TRES cifras que teclea el lector: lo que quiere dentro, lo que hace fuera en agosto y para qué salto ha dimensionado el instalador. No dice si la potencia es suficiente -eso no se puede decir sin calcular la carga térmica, y este libro no la calcula-: dice si la oferta está contestando a tu pregunta o a otra.
A35: Ficha de preguntas al instalador: llévala a la visita técnica
A36: Qué le preguntas | B36: Unidad | C36: Respuesta | D36: ¿Por escrito? | H36: Por qué importa
A37: ¿Qué volumen en m³ has tomado para el obrador? | B37: m3 | C37: 78 | D37: Por pedir | H37: Los metros cuadrados de la hoja «Zonas y m²» por la altura libre. Si el número que ha usado no se parece al tuyo, ha dimensionado otro local.
A38: ¿Para qué salto de temperatura de diseño lo has calculado? | B38: grados C | C38: 16 | D38: Por pedir | H38: Es LA pregunta. Un equipo dimensionado para un salto de 10 grados no sostiene 18-20 °C dentro con 36 fuera, y en agosto es cuando se nota.
A39: ¿Qué aportes internos has contado? | B39: kW | C39: 3.5 | D39: Por pedir | H39: La atemperadora, el temperador, las luces y las personas calientan el obrador desde dentro. Un equipo calculado sin ellos se queda corto justo cuando estás produciendo.
A40: ¿Cuántas renovaciones de aire por hora has previsto? | B40: ren/h | C40: 2 | D40: Por pedir | H40: Cada renovación mete aire de la calle a la temperatura y la humedad de la calle. Es la partida que más sube la potencia y la que menos se mira.
A41: ¿Qué capacidad de deshumidificación lleva, y a qué humedad la mantiene? | B41: litros/24 h | C41: 30 | D41: Por pedir | H41: En chocolate la HUMEDAD es tan importante como la temperatura: por encima del 60 % la cobertura templada pierde brillo y el bombón suda al salir de la cámara.
A42: ¿El equipo deshumidifica SIN bajar la temperatura por debajo del objetivo? | B42: Sí o No | C42: Sí | D42: Por pedir | H42: Muchos equipos deshumidifican enfriando. Si el tuyo baja de 18 grados para secar el aire, la cobertura se te queda dura en la cuba.
A43: ¿Lleva climatizador evaporativo? | B43: Sí o No | C43: No | D43: Por pedir | H43: TIENE QUE SER «No». Un evaporativo enfría AÑADIENDO humedad, que es exactamente lo contrario de lo que necesita un obrador de chocolate. Es el error más caro de esta lista porque parece barato.
A44: ¿Está incluida la puesta en marcha y el equilibrado de la instalación? | B44: Sí o No | C44: Sí | D44: Por pedir | H44: Un equipo bien elegido y mal equilibrado no mantiene la ventana. Que lo diga el presupuesto, no el comercial.
A45: ¿Qué garantía y qué contrato de mantenimiento ofreces? | B45: meses | C45: 24 | D45: Por pedir | H45: El frío y la climatización son lo que no puede pararse un 20 de diciembre. El mantenimiento es un gasto fijo del libro 7, no un extra.
A46: ¿Qué consumo eléctrico tiene en agosto a plena carga? | B46: kW | C46: 4.2 | D46: Por pedir | H46: Va a la potencia a contratar de la ficha de visita y al renglón de suministros del plan financiero. Un obrador de chocolate no tiene hornos: lo que consume es esto y el frío.
...

Sheet Capacidad por Equipo
A1: Capacidad por Equipo
A2: AI Chef Pro · aichef.pro — Cómo Montar una Chocolatería
A3: Un solo modelo para todas las máquinas y todos los puestos: lo que cabe en un ciclo, cuántos bombones salen de eso, cuánto dura el ciclo y qué parte de tu surtido pasa por ahí.
A5: Nº | B5: Equipo o puesto | C5: Categoría | D5: ¿Lo tienes? | E5: Capacidad por ciclo | F5: Unidad de la capacidad | G5: Bombones por unidad | H5: Bombones por ciclo | I5: Minutos por ciclo | J5: Ciclos al día | K5: Bombones al día del equipo | L5: % del surtido que pasa | M5: Bombones/día de obrador que permite | N5: Cuenta para el cuello | O5: Procedencia | P5: Nota
A6: 1 | B6: Atemperadora continua de sobremesa, 12 kg (55 kg/h) — Selmi One | C6: Templado | D6: Sí | E6: 12 | F6: kg de cobertura por carga de cuba | G6: 182 | H6: =IFERROR(E6*G6,"") -> 2184 | I6: 180 | J6: =IFERROR(INT('Parámetros'!$B$9/I6),"") -> 2 | K6: =IFERROR(H6*J6,"") -> 4368 | L6: 1 | M6: =IFERROR(K6/L6,"") -> 4368 | N6: =IF(D6="Sí",M6,"") -> 4368 | O6: CHS-41a | P6: El corazón del obrador, la decisión 2 del bonus 2 y la máquina que más se mira al presupuestar. Fíjate en dónde queda en el cuello de botella: templar NO es lo que limita una bombonería artesana. Los bombones por kilo salen de los 5,5 g de chocolate de la tanda de referencia; cámbialos si tu pieza pesa otra cosa.
A7: 2 | B7: Temperador de baño maría digital, 22 L — segunda cobertura | C7: Templado | D7: Sí | E7: 8 | F7: kg de cobertura por carga | G7: 182 | H7: =IFERROR(E7*G7,"") -> 1456 | I7: 180 | J7: =IFERROR(INT('Parámetros'!$B$9/I7),"") -> 2 | K7: =IFERROR(H7*J7,"") -> 2912 | L7: 0.35 | M7: =IFERROR(K7/L7,"") -> 8320 | N7: =IF(D7="Sí",M7,"") -> 8320 | O7: CHS-41j | P7: La segunda línea de templado. Sin ella no se trabajan dos coberturas a la vez, y el 35 % es la parte del surtido que lleva una cobertura distinta de la principal.
A8: 3 | B8: Mantenedor de 1 cubeta, digital | C8: Templado | D8: Sí | E8: 5 | F8: kg mantenidos a punto | G8: 182 | H8: =IFERROR(E8*G8,"") -> 910 | I8: 240 | J8: =IFERROR(INT('Parámetros'!$B$9/I8),"") -> 1 | K8: =IFERROR(H8*J8,"") -> 910 | L8: 0.2 | M8: =IFERROR(K8/L8,"") -> 4550 | N8: =IF(D8="Sí",M8,"") -> 4550 | O8: CHS-41i | P8: Mantiene la cobertura en curva mientras se moldea. Su precio se publica como un «desde» (libro 2); su capacidad, aquí, en kilos.
A9: 4 | B9: Moldes de policarbonato (24 moldes de 24 cavidades) | C9: Moldeado | D9: Sí | E9: 24 | F9: moldes por ciclo de cristalización | G9: 24 | H9: =IFERROR(E9*G9,"") -> 576 | I9: 90 | J9: =IFERROR(INT('Parámetros'!$B$9/I9),"") -> 4 | K9: =IFERROR(H9*J9,"") -> 2304 | L9: 0.72 | M9: =IFERROR(K9/L9,"") -> 3200 | N9: =IF(D9="Sí",M9,"") -> 3200 | O9: CHS-45a | P9: LOS MOLDES QUE TIENES SON CAPACIDAD, no utillaje. El ciclo incluye llenado, vibrado, raspado, cristalización y desmoldeo: 90 minutos es un supuesto, mídelo con tu cobertura y tu cámara. Los 24 moldes valen entre 580,80 y 1.027,92 euros (libro 2), y comprar 12 más es la forma más barata que hay de subir capacidad.
A10: 5 | B10: Puesto de moldeado y desmoldeo (mesa de mármol o granito) | C10: Moldeado | D10: Sí | E10: 2 | F10: puestos trabajando en paralelo | G10: 144 | H10: =IFERROR(E10*G10,"") -> 288 | I10: 155 | J10: =IFERROR(INT('Parámetros'!$B$9/I10),"") -> 2 | K10: =IFERROR(H10*J10,"") -> 576 | L10: 0.95 | M10: =IFERROR(K10/L10,"") -> 606.31579 | N10: =IF(D10="Sí",M10,"") -> 606.31579 | O10: supuesto | P10: LAS MANOS, QUE SON LO QUE DE VERDAD LIMITA. Dos puestos son las dos personas de obrador de La Almendra (Encargado y Chocolatero). Los minutos por ciclo y las piezas por tanda salen de la tanda de referencia de la carta, no de una estimación: 24 cavidades x 6 moldes en 155 minutos.
A11: 6 | B11: Placa dosificadora de rellenos — Selmi | C11: Moldeado | D11: Sí | E11: 6 | F11: moldes dosificados por ciclo | G11: 24 | H11: =IFERROR(E11*G11,"") -> 144 | I11: 12 | J11: =IFERROR(INT('Parámetros'!$B$9/I11),"") -> 34 | K11: =IFERROR(H11*J11,"") -> 4896 | L11: 0.68 | M11: =IFERROR(K11/L11,"") -> 7200 | N11: =IF(D11="Sí",M11,"") -> 7200 | O11: CHS-42i | P11: Dosifica el relleno en el molde ya encamisado. Es rápida y por eso no limita: lo que limita es lo que pasa antes y después de ella.
A12: 7 | B12: Enrobadora de banda, 200 mm — Selmi R200 Legend | C12: Bañado | D12: Sí | E12: 1 | F12: horas de banda en marcha | G12: 640 | H12: =IFERROR(E12*G12,"") -> 640 | I12: 60 | J12: =IFERROR(INT('Parámetros'!$B$9/I12),"") -> 6 | K12: =IFERROR(H12*J12,"") -> 3840 | L12: 0.18 | M12: =IFERROR(K12/L12,"") -> 21333.333 | N12: =IF(D12="Sí",M12,"") -> 21333.333 | O12: CHS-42a | P12: Sólo el 18 % del surtido va bañado: el resto es moldeado. Una enrobadora con una banda de 200 mm produce muy por encima de lo que una bombonería artesana necesita, y ése es el dato que hay que tener delante antes de comprarla.
A13: 8 | B13: Cámara climatizada de chocolate, unos 6 m² | C13: Frío y cristalización | D13: Sí | E13: 6 | F13: m³ útiles por rotación | G13: 480 | H13: =IFERROR(E13*G13,"") -> 2880 | I13: 240 | J13: =IFERROR(INT('Parámetros'!$B$9/I13),"") -> 1 | K13: =IFERROR(H13*J13,"") -> 2880 | L13: 0.85 | M13: =IFERROR(K13/L13,"") -> 3388.2353 | N13: =IF(D13="Sí",M13,"") -> 3388.2353 | O13: supuesto | P13: Aquí el «ciclo» es una rotación de la cámara. NO es una nevera: trabaja a 15-18 °C con 50-60 % de humedad, y es lo que sostiene la cristalización y la vida útil que declares en tu APPCC.
A14: 9 | B14: Puesto de envasado y montaje de cajas | C14: Envasado | D14: Sí | E14: 1 | F14: puestos de envasado | G14: 128 | H14: =IFERROR(E14*G14,"") -> 128 | I14: 100 | J14: =IFERROR(INT('Parámetros'!$B$9/I14),"") -> 4 | K14: =IFERROR(H14*J14,"") -> 512 | L14: 1 | M14: =IFERROR(K14/L14,"") -> 512 | N14: =IF(D14="Sí",M14,"") -> 512 | O14: supuesto | P14: LA ZONA QUE NADIE DIBUJA EN EL PLANO Y QUE SE DESBORDA EN NAVIDAD. En bombonería la caja ES el producto en campaña: montarla, pesarla, etiquetarla y cerrarla cuesta tiempo de obrador, y ese tiempo no está en la ficha de ninguna máquina.
A15: 10 | B15: Vitrina refrigerada específica para chocolate — Docriluc WB-6-6-R | C15: Tienda y vitrina | D15: Sí | E15: 0.6 | F15: m² de exposición por reposición | G15: 520 | H15: =IFERROR(E15*G15,"") -> 312 | I15: 150 | J15: =IFERROR(INT('Parámetros'!$B$9/I15),"") -> 2 | K15: =IFERROR(H15*J15,"") -> 624 | L15: 0.55 | M15: =IFERROR(K15/L15,"") -> 1134.5455 | N15: =IF(D15="Sí",M15,"") -> 1134.5455 | O15: CHS-43 | P15: Rango de trabajo del equipo +14/+17 °C. NO son los +2/+4 de una vitrina de pastelería, que arruina el bombón por condensación y pérdida de brillo. El objetivo operativo de cada mañana lo pone el kit: 16-18 °C y menos del 55 % de humedad.
A16: 11 | B16: Atemperadora de arranque, 4,5 L (unos 3 kg) — Pavoni MINITEMPER | C16: Templado | D16: No | E16: 3 | F16: kg de cobertura por carga | G16: 182 | H16: =IFERROR(E16*G16,"") -> 546 | I16: 45 | J16: =IFERROR(INT('Parámetros'!$B$9/I16),"") -> 9 | K16: =IFERROR(H16*J16,"") -> 4914 | L16: 1 | M16: =IFERROR(K16/L16,"") -> 4914 | N16: =IF(D16="Sí",M16,"") | O16: CHS-41h | P16: OPCIONAL, y marcada «No» a propósito: es la máquina del ESCENARIO B, el arranque mínimo. Cámbiala a «Sí» y mira cómo se mueve el cuello de botella antes de gastarte el dinero de la continua.
B18: Minutos disponibles al día (de «Parámetros») | E18: ='Parámetros'!B9 -> 408
B19: Equipos y puestos que dices tener | E19: =COUNTIF(D6:D16,"Sí") -> 10
B20: Equipos que no cuentan (ciclo más largo que la jornada) | E20: =COUNTIF(J6:J16,0) -> 0 | P20: Un cero en «ciclos al día» quiere decir que el ciclo de esa máquina no cabe en la jornada que has declarado. No es un error del libro: es que con ese turno esa máquina no produce nada.
B22: Listas de validación (no las borres: las usan los desplegables)
B23: ¿Lo tienes?
B24: Sí
B25: No
B27: Las columnas verdes de esta hoja son las que tienes que pelear con el comercial: cuánto cabe de verdad en un ciclo, cuánto dura el ciclo COMPLETO -con carga, cristalización y desmoldeo, no el que pone el folleto- y qué parte de tu surtido pasa por ahí. Si ya tienes el Kit de Tareas Chocolatería, los tiempos reales de cada partida los sacas de kit-tareas-chocolateria/02-partidas-produccion.xlsx; mientras tanto, los valores por defecto son supuestos coherentes con la carta de 28 referencias de «La Almendra».
B29: FÍJATE EN DÓNDE QUEDA LA ATEMPERADORA. Es la máquina que más cuesta y la que más se mira, y en una bombonería artesana está lejísimos de ser el cuello de botella: produce chocolate templado muy por encima de lo que dos personas moldean. Los que limitan son los moldes que tienes, los ciclos de cristalización que caben en la jornada y el puesto de envasado, que es el que nadie presupuesta. Comprar una atemperadora más grande cuando el cuello está en el envasado es tener el dinero parado.

Sheet Cuello de Botella
A1: Cuello de Botella
A2: AI Chef Pro · aichef.pro — Cómo Montar una Chocolatería
A3: El equipo que manda y los bombones al día que aguanta el conjunto, en el día normal y en el segundo equipo más justo. Qué pasa en cada una de las doce campañas del año -con su propia demanda y su déficit- lo publica el libro 6 («Campañas y Valle del Año»), que es a quien viaja esta capacidad.
A5: El día normal
A6: Bombones equivalentes al día que quieres sacar | B6: ='Parámetros'!B14 -> 471.814
A7: Bombones al día que permite el conjunto | B7: =IFERROR(MIN('Capacidad por Equipo'!$N$6:$N$16),"") -> 512 | J7: ES LA CIFRA QUE VIAJA AL LIBRO 6 (campañas y valle del año, cruce nº 1): el 6 no puede saber si aguantas Navidad sin esta capacidad. El libro 6 la pide en CELDA VERDE y la cuadra contra este número; en toda la guía no hay una sola fórmula que apunte a otro fichero.
A8: El equipo que limita | B8: =IFERROR(INDEX('Capacidad por Equipo'!$B$6:$B$16,MATCH(B7,'Capacidad por Equipo'!$N$6:$N$16,0)),"") -> Puesto de envasado y montaje de cajas
A9: Holgura sobre el día normal (bombones) | B9: =IFERROR(B7-B6,"") -> 40.186
A10: Holgura sobre el día normal (%) | B10: =IFERROR(B9/B6,"") -> 0.085173395
A11: Margen de seguridad que te has exigido | B11: ='Parámetros'!B15 -> 0.1
A12: VEREDICTO DEL DÍA NORMAL | B12: =IF(B7="","",IF(B7<B6,"NO LLEGAS",IF(B10<B11,"AJUSTADO","SUFICIENTE"))) -> AJUSTADO | J12: «AJUSTADO» quiere decir que pasas el día normal, pero por debajo del margen de seguridad que tú mismo has pedido: una avería del frío, una baja o un pedido corporativo te dejan sin género.
A13: El segundo equipo más justo permite | B13: =IFERROR(SMALL('Capacidad por Equipo'!$N$6:$N$16,2),"") -> 606.31579
A14: Y es | B14: =IFERROR(INDEX('Capacidad por Equipo'!$B$6:$B$16,MATCH(B13,'Capacidad por Equipo'!$N$6:$N$16,0)),"") -> Puesto de moldeado y desmoldeo (mesa de mármol o granito) | J14: Mira los dos juntos antes de comprar: si el segundo está muy cerca del primero, resolver sólo el cuello de botella te sube la capacidad cuatro bombones y te deja el dinero fuera.
A16: LAS DOCE CAMPAÑAS DEL AÑO -demanda, déficit y qué producto manda cada pico- están en el libro 6 («Campañas y Valle del Año»), que es quien pide esta capacidad en celda verde y la cuadra. Aquí sólo vive el día normal y el equipo que lo limita: mézclalos y acabas con dos cifras distintas para la misma pregunta.

Sheet Ficha de Visita a Local
A1: Ficha de Visita a Local
A2: AI Chef Pro · aichef.pro — Cómo Montar una Chocolatería
A3: Imprímela y llévala a cada visita. Un solo «No» en un ítem eliminatorio y el veredicto es DESCARTAR.
A5: Nº | B5: Qué se comprueba | C5: ¿Eliminatorio? | D5: Cómo se comprueba | E5: Respuesta | F5: Dato medido | G5: Umbral | H5: ¿Cumple el dato? | I5: Veredicto | J5: Nota y norma
A6: 1 | B6: La potencia eléctrica contratable llega a la que vas a instalar | C6: Sí | D6: Pide el boletín eléctrico del local y consulta a la distribuidora la potencia disponible en la acometida. | E6: Sí | F6: 34 | G6: ='Parámetros'!B18 -> 28 | H6: =IF(AND(ISNUMBER(F6),ISNUMBER(G6)),IF(F6>=G6,"Sí","No"),"") -> Sí | I6: =IF(H6="No",IF(C6="Sí","DESCARTAR","Punto débil"),IF(E6="","",IF(E6="No",IF(C6="Sí","DESCARTAR","Punto débil"),IF(E6="Por comprobar","Pendiente","OK")))) -> OK | J6: Un obrador de chocolate no tiene hornos, pero tiene TRES equipos de frío y una climatización con deshumidificación funcionando 24 horas. Subir la potencia de una acometida puede costar más que la obra entera y depende de la distribuidora, no de tu presupuesto.
A7: 2 | B7: El local admite climatizar el obrador con deshumidificación | C7: Sí | D7: Lleva la ficha de preguntas de la hoja «Clima del Obrador» a la visita y mira dónde iría la unidad exterior y por dónde saldría el condensado. | E7: Sí | G7: No aplica | I7: =IF(H7="No",IF(C7="Sí","DESCARTAR","Punto débil"),IF(E7="","",IF(E7="No",IF(C7="Sí","DESCARTAR","Punto débil"),IF(E7="Por comprobar","Pendiente","OK")))) -> OK | J7: ES LA ELIMINATORIA PROPIA DE UNA CHOCOLATERÍA. Sin 18-20 °C y 50-60 % de humedad en el obrador, la cobertura no cristaliza y el bombón sale mate o con fat bloom. Un local que no se puede climatizar no es un local barato: es otro negocio.
A8: 3 | B8: La superficie útil llega a los m² que has repartido por zonas | C8: No | D8: Superficie útil real, sin contar muros ni patinillos. Compárala con el total de la hoja «Zonas y m²». | E8: Sí | F8: 77 | G8: ='Parámetros'!B16 -> 75 | H8: =IF(AND(ISNUMBER(F8),ISNUMBER(G8)),IF(F8>=G8,"Sí","No"),"") -> Sí | I8: =IF(H8="No",IF(C8="Sí","DESCARTAR","Punto débil"),IF(E8="","",IF(E8="No",IF(C8="Sí","DESCARTAR","Punto débil"),IF(E8="Por comprobar","Pendiente","OK")))) -> OK | J8: La superficie de un anuncio suele ser construida. La que te sirve es la útil, y entre una y otra se van con facilidad 10 m².
A9: 4 | B9: La altura libre del local llega a la que has fijado | C9: No | D9: Metro láser desde el suelo terminado a la cara inferior del forjado, en el punto más bajo. Mide donde iría la unidad interior del clima. | E9: Sí | F9: 3.1 | G9: ='Parámetros'!B22 -> 2.7 | H9: =IF(AND(ISNUMBER(F9),ISNUMBER(G9)),IF(F9>=G9,"Sí","No"),"") -> Sí | I9: =IF(H9="No",IF(C9="Sí","DESCARTAR","Punto débil"),IF(E9="","",IF(E9="No",IF(C9="Sí","DESCARTAR","Punto débil"),IF(E9="Por comprobar","Pendiente","OK")))) -> OK | J9: Sin campana ni conducto a cubierta, una chocolatería necesita menos altura que una pastelería. Lo que sí necesita es sitio para la climatización y para el conducto de la deshumidificación.
A10: 5 | B10: La superficie de exposición y venta está por debajo del umbral de la Ley 12/2012 | C10: No | D10: Mide sólo la zona a la que entra el público. La de la hoja «Zonas y m²» es la de partida. | E10: Sí | F10: 22 | G10: ='Parámetros'!B24 -> 750 | H10: =IF(AND(ISNUMBER(F10),ISNUMBER(G10)),IF(F10<=G10,"Sí","No"),"") -> Sí | I10: =IF(H10="No",IF(C10="Sí","DESCARTAR","Punto débil"),IF(E10="","",IF(E10="No",IF(C10="Sí","DESCARTAR","Punto débil"),IF(E10="Por comprobar","Pendiente","OK")))) -> OK | J10: Por debajo de 750 m² de superficie útil de exposición y venta al público, ninguna administración puede exigirte licencia previa de instalación, de funcionamiento o de actividad: el epígrafe 644.5 está en el Anexo de la Ley 12/2012. Decir qué trámite pide Madrid o Barcelona está PROHIBIDO en esta guía: no se ha abierto ninguna ordenanza.
A11: 6 | B11: El obrador puede quedar inaccesible al público | C11: Sí | D11: Dibuja las seis zonas sobre el plano antes de firmar. Si no caben con la puerta donde está, no caben. | E11: Sí | G11: No aplica | I11: =IF(H11="No",IF(C11="Sí","DESCARTAR","Punto débil"),IF(E11="","",IF(E11="No",IF(C11="Sí","DESCARTAR","Punto débil"),IF(E11="Por comprobar","Pendiente","OK")))) -> OK | J11: El obrador es zona de elaboración, no una cocina a la vista. Y tu sistema de autocontrol tiene que designar con NOMBRE a la persona responsable: no vale «el encargado».
A12: 7 | B12: El obrador NO necesita salida de humos, porque no hay combustión | C12: No | D12: Comprueba que en tu proyecto no entra ni freidora ni fogón. Si entra, este ítem deja de valer y pasas al siguiente. | E12: Sí | G12: No aplica | I12: =IF(H12="No",IF(C12="Sí","DESCARTAR","Punto débil"),IF(E12="","",IF(E12="No",IF(C12="Sí","DESCARTAR","Punto débil"),IF(E12="Por comprobar","Pendiente","OK")))) -> OK | J12: LA VENTAJA QUE MÁS LOCALES ABRE. Un obrador de chocolate no fríe ni asa: no genera aire de categoría AE4, así que no necesita campana ni conducto a cubierta, que es la partida que tumba la mayoría de los locales de una pastelería. Y ojo con la norma que se cita mal: el CTE DB-HS 3 se aplica a viviendas y, en edificios de otro uso, sólo a aparcamientos y garajes.
A13: 8 | B13: Si vas a montar la variante de taza y churros, el local admite freidora, campana y conducto a cubierta | C13: No | D13: Sube a la cubierta con el propietario. Pídelo por escrito antes de firmar, y pide también el certificado de la última inspección de gas. | E13: Por comprobar | G13: No aplica | I13: =IF(H13="No",IF(C13="Sí","DESCARTAR","Punto débil"),IF(E13="","",IF(E13="No",IF(C13="Sí","DESCARTAR","Punto débil"),IF(E13="Por comprobar","Pendiente","OK")))) -> Pendiente | J13: La chocolatería de TAZA es otro negocio y la norma lo separa sola: el Anexo de la Ley 12/2012 NO incluye ningún grupo de la agrupación 67, así que la bombonería se libra de la licencia previa hasta 750 m² y la de taza no. Y si hay freidora de gas, la instalación receptora se inspecciona cada cinco años.
A14: 9 | B14: Los estatutos de la comunidad de propietarios no prohíben la actividad | C14: Sí | D14: Pide los estatutos inscritos y el acta de la última junta. Que el vecino de al lado sea un bar no basta. | E14: Sí | G14: No aplica | I14: =IF(H14="No",IF(C14="Sí","DESCARTAR","Punto débil"),IF(E14="","",IF(E14="No",IF(C14="Sí","DESCARTAR","Punto débil"),IF(E14="Por comprobar","Pendiente","OK")))) -> OK | J14: Una prohibición estatutaria inscrita se impone aunque el ayuntamiento no te pida nada. Y aquí hay un matiz de chocolatería: la unidad exterior de la climatización va en fachada o en cubierta, las dos zona común, así que la conversación con la comunidad existe igual aunque no haya humos.
A15: 10 | B15: El planeamiento urbanístico admite la actividad en esa finca | C15: Sí | D15: Consulta de compatibilidad urbanística en el ayuntamiento, por escrito y a nombre del local, no una llamada. | E15: Sí | G15: No aplica | I15: =IF(H15="No",IF(C15="Sí","DESCARTAR","Punto débil"),IF(E15="","",IF(E15="No",IF(C15="Sí","DESCARTAR","Punto débil"),IF(E15="Por comprobar","Pendiente","OK")))) -> OK | J15: Un local que hoy es un comercio no admite automáticamente un obrador: es actividad de transformación de alimentos, aunque sea silenciosa y sin humos.
A16: 11 | B16: Caben aseo de público y vestuario de personal separados | C16: No | D16: Cuenta los metros y mira dónde están los bajantes. Un aseo nuevo sin bajante cerca es obra grande. | E16: Sí | G16: No aplica | I16: =IF(H16="No",IF(C16="Sí","DESCARTAR","Punto débil"),IF(E16="","",IF(E16="No",IF(C16="Sí","DESCARTAR","Punto débil"),IF(E16="Por comprobar","Pendiente","OK")))) -> OK | J16: El personal necesita su aseo y su taquilla; el cliente, el suyo. Los 8 m² de la hoja de zonas ya lo contemplan.
A17: 12 | B17: Se puede descargar la cobertura sin cruzar la zona de clientes | C17: No | D17: Ve a la hora a la que descargarías. Mira si hay carga y descarga y si el portal lo permite. | E17: Sí | G17: No aplica | I17: =IF(H17="No",IF(C17="Sí","DESCARTAR","Punto débil"),IF(E17="","",IF(E17="No",IF(C17="Sí","DESCARTAR","Punto débil"),IF(E17="Por comprobar","Pendiente","OK")))) -> OK | J17: La cobertura llega en cajas de 5 a 25 kg y el packaging de campaña llega en palés. Si entra por la puerta de la tienda, entra por delante del cliente.
A18: 13 | B18: La basura y el cartón salen sin abrir al obrador | C18: No | D18: Localiza el cuarto de residuos y su puerta. Debe estar cerrado y con contenedores identificados. | E18: Sí | G18: No aplica | I18: =IF(H18="No",IF(C18="Sí","DESCARTAR","Punto débil"),IF(E18="","",IF(E18="No",IF(C18="Sí","DESCARTAR","Punto débil"),IF(E18="Por comprobar","Pendiente","OK")))) -> OK | J18: En bombonería el residuo de volumen es el CARTÓN del packaging, y se acumula en campaña justo en la zona de envasado.
A19: 14 | B19: Hay acometida de agua fría y caliente y desagüe donde van los equipos | C19: No | D19: Localiza el desagüe existente. Mover un desagüe obliga a levantar el suelo del local entero. | E19: Sí | G19: No aplica | I19: =IF(H19="No",IF(C19="Sí","DESCARTAR","Punto débil"),IF(E19="","",IF(E19="No",IF(C19="Sí","DESCARTAR","Punto débil"),IF(E19="Por comprobar","Pendiente","OK")))) -> OK | J19: El temperador de baño maría, la cámara y el fregadero necesitan desagüe en su punto. Y la climatización necesita evacuación de condensados, que es el desagüe que nadie prevé.
A20: 15 | B20: Suelos y paredes admiten acabado liso, lavable e impermeable | C20: No | D20: Mira el estado real: azulejo roto, yeso, hormigón visto. El acabado del obrador es obra, no pintura. | E20: Sí | G20: No aplica | I20: =IF(H20="No",IF(C20="Sí","DESCARTAR","Punto débil"),IF(E20="","",IF(E20="No",IF(C20="Sí","DESCARTAR","Punto débil"),IF(E20="Por comprobar","Pendiente","OK")))) -> OK | J20: Superficies lisas, lavables e impermeables y lavamanos no manual. No es un extra: es requisito, y en chocolate además importa que el suelo no suelte polvo.
A21: 16 | B21: El escaparate y la vitrina quedan fuera del sol de mediodía | C21: No | D21: Ve al local a las 14:00, no a las 10:00, y mira dónde da el sol. | E21: Sí | G21: No aplica | I21: =IF(H21="No",IF(C21="Sí","DESCARTAR","Punto débil"),IF(E21="","",IF(E21="No",IF(C21="Sí","DESCARTAR","Punto débil"),IF(E21="Por comprobar","Pendiente","OK")))) -> OK | J21: La vitrina de bombonería trabaja a 16-18 °C. Un escaparate a poniente en julio la obliga a ciclar sin parar, sube la humedad interior y te deja el bombón mate. Se arregla con lámina solar y toldo, que son partida del libro 2, pero hay que saberlo antes.
A22: 17 | B22: El local es accesible o admite ajustes razonables | C22: No | D22: Mide el escalón de entrada y el ancho de la puerta. Un escalón en fachada puede depender del ayuntamiento, no de ti. | E22: Sí | G22: No aplica | I22: =IF(H22="No",IF(C22="Sí","DESCARTAR","Punto débil"),IF(E22="","",IF(E22="No",IF(C22="Sí","DESCARTAR","Punto débil"),IF(E22="Por comprobar","Pendiente","OK")))) -> OK | J22: El calendario para titularidad privada es el 1-ene-2029 en bienes y servicios nuevos y el 1-ene-2030 en los existentes, y la obligación de garantizar la accesibilidad o hacer ajustes razonables no tiene umbral de superficie.
A23: 18 | B23: El contrato y las cargas del local están claros antes de firmar | C23: Sí | D23: Nota simple del Registro, contrato de arrendamiento leído entero y quién paga la obra de adecuación. | E23: Por comprobar | G23: No aplica | I23: =IF(H23="No",IF(C23="Sí","DESCARTAR","Punto débil"),IF(E23="","",IF(E23="No",IF(C23="Sí","DESCARTAR","Punto débil"),IF(E23="Por comprobar","Pendiente","OK")))) -> Pendiente | J23: Quién paga la obra, cuántos años dura el contrato y qué pasa con la obra al terminar son tres números del libro 2, no tres detalles.
B25: Ítems de la ficha | E25: =COUNTIF(C6:C23,"Sí")+COUNTIF(C6:C23,"No") -> 18
B26: De los cuales, eliminatorios | E26: =COUNTIF(C6:C23,"Sí") -> 6
B27: Motivos de descarte | E27: =COUNTIF(I6:I23,"DESCARTAR") -> 0
B28: Puntos débiles | E28: =COUNTIF(I6:I23,"Punto débil") -> 0
B29: Pendientes de comprobar | E29: =COUNTIF(I6:I23,"Pendiente") -> 2
B30: Resueltos sin problema | E30: =COUNTIF(I6:I23,"OK") -> 16
B31: Ficha comprobada | E31: =IFERROR((E25-E29)/E25,"") -> 0.88888889
B32: VEREDICTO DEL LOCAL | E32: =IF(E27>0,"DESCARTAR ESTE LOCAL",IF(E29>0,"NO DECIDAS TODAVÍA",IF(E28>0,"SIGUE ADELANTE CON RESERVAS","SIGUE ADELANTE"))) -> NO DECIDAS TODAVÍA
B34: Listas de validación (no las borres: las usan los desplegables)
B35: Respuesta
B36: Sí
B37: No
B38: Por comprobar
B40: Los seis ítems eliminatorios no lo son por gusto: son los defectos que no se arreglan con dinero razonable o que no dependen de ti (la acometida, la climatización, la comunidad, el planeamiento, el contrato). El resto encarecen la obra y hay que llevarlos al libro 2 como partida, no descartar el local por ellos. Y guarda la ficha de los locales que descartes: comparar tres fichas es lo que enseña qué estás aceptando sin darte cuenta.
B42: LA DIFERENCIA CON UNA PASTELERÍA CABE EN DOS LÍNEAS DE ESTA FICHA. Un obrador de chocolate no fríe ni asa, así que no necesita campana ni conducto a cubierta: se cae la partida que tumba la mitad de los locales. A cambio aparece otra que en pastelería no existe, y es eliminatoria: el local tiene que poder climatizarse con deshumidificación a 18-20 °C. Un sótano fresco y húmedo es un mal local para el chocolate aunque esté regalado.
