Workbook

Sheet Instrucciones
A1: Carta de Apertura y Escandallo del Obrador de Bombonería
A2: AI Chef Pro · aichef.pro — Cómo Montar una Chocolatería
A3: Para qué sirve: decidir qué vendes, a cuánto, cómo lo puedes llamar y si la caja te gana o te cuesta dinero.
A5: Instrucciones de uso
A6: 1. Hoja «Parámetros». Empieza por el bloque de personal de obrador: el coste de la hora de obrador NO es un dato del sector y no se teclea, se calcula con el bruto de tu convenio, las pagas, la jornada de cada persona y la Seguridad Social a cargo de la empresa. Justo debajo está el bloque del PRECIO DE COBERTURA, que viene del libro 3 y que es la celda más crítica de todo el paquete, y la tabla de precios de compra: es la única tabla donde se tocan los precios, y de ella beben las 42 líneas de las fórmulas de relleno.
A7: 2. Hoja «Denominaciones y Mínimos Legales». Dos capas, y no son lo mismo. La capa (a) la calcula el libro solo, con los gramos que tú metes en el escandallo: el porcentaje de chocolate sobre el PESO TOTAL de la pieza, con el relleno dentro. La capa (b) son tres celdas verdes por cobertura -materia seca total de cacao, manteca de cacao y materia seca desgrasada- que tienes que COPIAR de la ficha técnica de tu proveedor: la bolsa sólo trae el total, y la norma trabaja con las tres.
A8: 3. Hoja «Escandallo por Molde y Tanda». Arriba, las fórmulas de relleno: una línea por ingrediente, con la cantidad que entra en un kilo. Abajo, una fila por referencia con los gramos de chocolate y los gramos de relleno por pieza. El coste de materia sale solo. Las cajas no tienen escandallo propio: se componen de sus bombones.
A9: 4. Hoja «Merma de Templado y Recortes». Dos tasas por referencia, y son distintas a propósito: el chocolate limpio que recortas vuelve a la cuba y no se pierde; el que lleva ganache o fruta va a residuo. La hoja te dice cuántos kilos al año vuelven, cuántos se van y cuánto te cuesta eso.
A10: 5. Hoja «Coste Hora y Mano de Obra». Piezas por molde, moldes por tanda y minutos de la tanda. De ahí salen el coste de mano de obra por pieza, el coste total, el food cost, el margen en euros y el precio que te pide tu propia regla de margen. Es la hoja que enseña a dejar de regalar el trabajo del obrador.
A11: 6. Hoja «Unidad vs Caja». Escribe cuántos bombones de cada tipo lleva cada caja. El libro compara el precio de la caja con la suma de sus unidades sueltas y te dice si la caja te gana o te cuesta dinero. Y aquí sí entra la mano de obra de los bombones de dentro: una caja no cuesta sólo lo que cuesta montarla.
A12: 7. Hoja «Mix y Ticket Medio». Reparte el 100 % de tus unidades entre las 28 referencias, y otra vez para julio y agosto, que no se vende lo mismo. De ahí sale tu ticket medio, que no se copia de ningún estudio porque no existe un ticket medio publicado de chocolatería.
A13: 8. Hoja «Decisión de Surtido». Cruza margen y rotación y te dice qué mantener, a qué revisarle el precio y qué retirar. Repásala a los tres meses de abrir, con ventas reales, y otra vez al cambiar de temporada.
... A33: Versión 1.0 · septiembre 2026 · aichef.pro/guia-chocolateria-obrador · info@aichef.pro

Sheet Parámetros
A1: Parámetros
A2: AI Chef Pro · aichef.pro — Cómo Montar una Chocolatería
A3: Todo lo que el resto de hojas da por sabido vive aquí. Ninguna fórmula de este libro lleva un número dentro.
A5: Personal de obrador y coste de la hora (se CALCULA, no se teclea)
A6: Perfil (nombre literal del Kit de Tareas Chocolatería) | B6: Jornada (1,0 = completa) | C6: Grupo del convenio | D6: Bruto mensual del grupo (EUR) | E6: Bruto anual con pagas y jornada (EUR) | F6: Coste de empresa con Seguridad Social (EUR) | G6: Horas productivas al año | H6: Nota
A7: Encargado | B7: 1 | C7: 2 - Dirección, jefes y encargados | D7: 1427.89 | E7: =D7*'Parámetros'!$B$11*B7 -> 21418.35 | F7: =E7*(1+'Parámetros'!$B$12) -> 28486.406 | G7: ='Parámetros'!$B$13*B7*'Parámetros'!$B$14 -> 1513 | H7: Turno partido (08:00-13:00 y 17:00-20:00). Tabla salarial de Madrid, marcada EJEMPLO: sustitúyela por la de TU convenio.
A8: Chocolatero | B8: 1 | C8: 3 - Personal especialista | D8: 1376.91 | E8: =D8*'Parámetros'!$B$11*B8 -> 20653.65 | F8: =E8*(1+'Parámetros'!$B$12) -> 27469.355 | G8: ='Parámetros'!$B$13*B8*'Parámetros'!$B$14 -> 1513 | H8: Turno mañana (07:00-15:00). Tabla salarial de Madrid, marcada EJEMPLO: sustitúyela por la de TU convenio.
A9: TOTAL del obrador | E9: =SUM(E7:E8) -> 42072 | F9: =SUM(F7:F8) -> 55955.76 | G9: =SUM(G7:G8) -> 3026
A11: Pagas del convenio al año | B11: 15 | C11: pagas | D11: CHN-65b | E11: El convenio de Madrid paga 15, no 14: cambia el coste mes a mes.
A12: Seguridad Social a cargo de la empresa | B12: 0.33 | C12: sobre bruto | D12: motor.PARAMETROS | E12: Cotización empresarial aproximada sobre el bruto: contingencias comunes, desempleo, FOGASA y formación. Ajústala a tus contratos.
A13: Horas anuales de contrato a jornada completa | B13: 1780 | C13: horas/año | D13: supuesto | E13: 40 horas por 52 semanas son 2.080, menos 30 días naturales de vacaciones y los festivos del calendario laboral.
A14: Parte de la jornada que se pasa a pie de mesa | B14: 0.85 | C14: sobre la jornada | D14: supuesto | E14: El resto es recepción, limpieza, formación y reuniones. Repartir el coste entre las horas de contrato en vez de entre las productivas abarata la hora de obrador y sale un margen que no existe.
A15: COSTE DE LA HORA DE OBRADOR | B15: =IFERROR(F9/G9,"") -> 18.491659 | C15: EUR/hora productiva | D15: calculado | E15: Coste de empresa de las personas de obrador entre sus horas PRODUCTIVAS. Del bruto al coste de empresa hay un 33 %, y es el salto que más sorprende. No es el bruto ni el bruto con Seguridad Social.
A17: IVA por familia (regla 3 de la SPEC)
A18: IVA del chocolate (entrega de un bien) | B18: 0.1 | C18: sobre base | D18: CHN-71 | E18: El chocolate va al 10 % POR EXCLUSIÓN, no porque un precepto lo nombre: la lista del 4 % es cerrada y tiene siete letras, y el chocolate no está en ninguna ni entre las dos exclusiones del 10 %.
A19: IVA del chocolate a la taza servido en sala | B19: 0.1 | C19: sobre base | D19: CHN-71c | E19: Servirlo en sala es prestación de servicio de hostelería, no entrega de un bien: va al 10 % por el art. 91.Uno.2.2.º. Si mañana cambia uno de los dos tipos, el libro no se toca: se cambia aquí.
A21: La regla del margen, que es UNA SOLA
A22: Food cost objetivo (coste de materia sobre PVP) | B22: 0.3 | C22: sobre PVP sin IVA | D22: supuesto | E22: SUPUESTO declarado: no existe dato público de food cost de bombonería. Es el ÚNICO de los dos números que se teclea.
A23: Margen bruto objetivo (se DERIVA del anterior) | B23: =1-'Parámetros'!$B$22 -> 0.7 | C23: sobre PVP sin IVA | D23: calculado | E23: Margen bruto y food cost son la misma regla dicha dos veces. Publicarlos como dos reglas independientes es un error de método: se pueden poner incoherentes y nadie se entera.
A25: Precio de cobertura EN BASE IMPONIBLE: trae aquí la cifra de sensibilidad-al-precio-del-cacao.xlsx!Coste de Cobertura!G7 (negra; G8/G9/G10 para origen/leche/blanca en la fila de cada una, columna de base imponible, nunca la de base con IVA) | H25: Cruce 4 <- 3 de la SPEC: celda verde con su valor por defecto declarado y fila de CUADRE. NO hay fórmula entre ficheros.
A26: Cobertura | B26: Precio en BASE IMPONIBLE traído del libro 3 (EUR/kg) | C26: Precio que publica hoy el libro 3 (EUR/kg) | D26: Desviación | E26: Base de IVA de la fuente, y nota | F26: Celda exacta del libro 3
A27: Cobertura de chocolate negro (marca, 54,5 % de cacao) | B27: 22.7455 | C27: 22.7455 | D27: =IFERROR(ABS(B27-C27)/C27,"") -> 0 | E27: Base de la fuente: con IVA. LA CELDA MAS CRITICA DEL PAQUETE. Base CON IVA declarada por la ficha (`CHS-28a`): el libro 3 la publica en las dos bases y lo que viaja al 4 y al 7 es la base imponible. Las tres magnitudes de arriba son SUPUESTO: pidesela a tu proveedor, la bolsa solo trae el total. | F27: Coste de Cobertura!G7 (cacao del 55 al 70 % según el kit)
A28: Cobertura de chocolate de origen (70 % de cacao) | B28: 37.48 | C28: 37.48 | D28: =IFERROR(ABS(B28-C28)/C28,"") -> 0 | E28: Base de la fuente: no declarada. Factor 1,5 frente a la de marca, y es la decisión de posicionamiento mas cara del negocio (decisión 5 del bonus 2). La pagina no declara si el precio lleva IVA: se trata como base imponible y se marca. | F28: Coste de Cobertura!G8 (cacao del 55 al 70 % según el kit)
A29: Cobertura de chocolate con leche (38 % de cacao) | B29: 19.5 | C29: 19.5 | D29: =IFERROR(ABS(B29-C29)/C29,"") -> 0 | E29: Base de la fuente: sin IVA. SUPUESTO declarado: no hay precio verificado de cobertura con leche en el research. Celda verde con valor por defecto (regla 2 de §2.3: ninguna celda verde vacia). | F29: Coste de Cobertura!G9 (cacao del 35 al 40 % según el kit)
A30: Cobertura de chocolate blanco (30 % de cacao) | B30: 21 | C30: 21 | D30: =IFERROR(ABS(B30-C30)/C30,"") -> 0 | E30: Base de la fuente: sin IVA. SUPUESTO declarado. Ojo al chocolate blanco: NO lleva materia seca desgrasada de cacao, y por eso el art. 6.d) del RD 1055/2003 NO le obliga a la mención «cacao: X % mínimo» (`CHN-07`). | F30: Coste de Cobertura!G10 (cacao del 28 al 33 % según el kit)
A31: CUADRE: lo que has traído frente a lo que publica el libro 3 | B31: =MAX(D27:D30) -> 0 | C31: desviación máxima | D31: =IF(NOT(ISNUMBER(B31)),"",IF(B31<='Parámetros'!$B$40,"CUADRA","REVISA: lo que has traído no es lo que publica el libro 3")) -> CUADRA | E31: Si el libro 3 cambia de escenario de precio, cambian las dos columnas. Esta fila existe para que no se quede una sola.
A33: Volumen, packaging y umbrales
A34: Clientes al día en velocidad de crucero | B34: 67 | C34: clientes/día | D34: supuesto | E34: NO es un dato del sector: no existe ticket medio publicado de chocolatería. Mídelo con tu TPV en dos semanas.
A35: Piezas por ticket | B35: 1.4 | C35: piezas/ticket | D35: supuesto | E35: En bombonería es BAJO porque la unidad de venta real es la caja: quien entra a por un regalo se lleva UNA caja, no ocho bombones.
A36: Días de apertura al año | B36: 304 | C36: días | D36: supuesto | E36: 6 días por semana x 52 semanas = 312, menos 8 días de cierre por festivos = 304. En agosto la TIENDA NO CIERRA: lo que para es el obrador (D36, y el literal del kit dice «la tienda abre para el turista aunque el obrador pare»). Una bombonería de menos de 300 m² tiene libertad horaria por el art. 5.2 de la Ley 1/2004, no por el 5.1 (`CHN-77`).
A37: Piezas vendidas al día | B37: =IFERROR('Parámetros'!$B$34*'Parámetros'!$B$35,"") -> 93.8 | C37: piezas/día | D37: calculado | E37: Clientes al día por piezas por ticket.
A38: Piezas vendidas al año | B38: =IFERROR('Parámetros'!$B$37*'Parámetros'!$B$36,"") -> 28515.2 | C38: piezas/año | D38: calculado | E38: Es el volumen con el que la hoja de merma pasa de euros por pieza a euros al año, y el que reparte el mix en unidades.
A39: Packaging sobre el coste de la pieza | B39: 0.12 | C39: sobre el coste | D39: supuesto | E39: En bombonería pesa más que en pastelería: en las campañas de regalo la caja ES el producto. Es lo que separa el food cost de escandallo del food cost servido.
A40: Tolerancia de las filas de CUADRE | B40: 0.02 | C40: desviación | D40: supuesto | E40: Por encima de esta desviación, la fila de CUADRE avisa de que lo que has traído de otro libro ya no es lo que aquel publica.
A41: Food cost por encima del cual la hoja avisa | B41: 0.35 | C41: sobre PVP | D41: supuesto | E41: Criterio de la casa, no del sector. Una referencia por encima no es necesariamente mala: puede ser la que trae gente. Pero tiene que ser una decisión, no un descuido.
A42: Rotación mínima para no revisar una referencia | B42: 2 | C42: % del mix | D42: supuesto | E42: Por debajo de este peso en el mix, la referencia entra en la decisión de surtido aunque tenga buen margen: ocupa molde, cámara y cabeza.
A43: Merma NO recuperable por encima de la cual avisa | B43: 0.05 | C43: sobre la tanda | D43: supuesto | E43: La recuperable no dispara nada: vuelve a la cuba. La que se tira, sí.
A44: Margen mínimo por pieza | B44: 0.9 | C44: EUR/pieza | D44: supuesto | E44: Umbral de la decisión de surtido. Es el margen en EUROS, no el porcentaje: un 70 % sobre una pieza de 0,40 EUR no paga el alquiler.
A46: Precios de compra: la ÚNICA tabla donde se tocan los precios
A47: Ingrediente | B47: Precio de compra SIN IVA (EUR) | C47: Unidad de compra | D47: De dónde sale | E47: Nota
...

Sheet Denominaciones y Mínimos
A1: Denominaciones y Mínimos Legales
A2: AI Chef Pro · aichef.pro — Cómo Montar una Chocolatería
A3: Capa (a): lo que el escandallo SÍ calcula -el 25 % sobre el PESO TOTAL, relleno incluido-. Capa (b): las tres magnitudes que se COPIAN de la ficha técnica del proveedor, porque la bolsa no las trae.
A5: Capa (a): el mínimo que sale de tus propios gramajes
A6: Id | B6: Referencia | C6: Familia | D6: Denominación legal | E6: Fuente verificada | F6: Mínimo aplicable | G6: ¿Obliga la mención «cacao: X % mínimo»? | H6: Vía de despacho | I6: Gramos de chocolate | J6: Gramos de relleno o materia añadida | K6: Peso total de la pieza (g) | L6: Chocolate sobre el PESO TOTAL | M6: ¿Le aplica el 25 %? | N6: Veredicto | O6: Nota
A7: BC1 | B7: Bombón de ganache de chocolate negro 70 % | C7: Bombones de colección | D7: Bombón de chocolate | E7: CHN-03 | F7: 25 % de chocolate sobre el peso TOTAL | G7: No | H7: a granel | I7: ='Escandallo por Molde y Tanda'!E70 -> 5.5 | J7: ='Escandallo por Molde y Tanda'!F70 -> 6.5 | K7: ='Escandallo por Molde y Tanda'!G70 -> 12 | L7: =IFERROR(I7/K7,"") -> 0.45833333 | M7: Sí | N7: =IF(M7="No","No aplica: su mínimo es el de su denominación",IF(NOT(ISNUMBER(L7)),"",IF(L7>=$B$38,"CUMPLE el 25 % sobre el peso total","NO CUMPLE: no puede llamarse así"))) -> CUMPLE el 25 % sobre el peso total | O7: La referencia que mas margen deja y la que antes caduca. Con 5,5 g de chocolate sobre 12 g de pieza, el chocolate es el 45,8 % del peso total: cumple el 25 % del ap. 1.13 con holgura. En julio y agosto baja a un tercio de su mix: es la primera que sale del catálogo de verano (literal del kit para junio: «menos ganache fresca»).
A8: BC2 | B8: Bombón de ganache de leche y vainilla | C8: Bombones de colección | D8: Bombón de chocolate | E8: CHN-03 | F8: 25 % de chocolate sobre el peso TOTAL | G8: No | H8: a granel | I8: ='Escandallo por Molde y Tanda'!E71 -> 5.5 | J8: ='Escandallo por Molde y Tanda'!F71 -> 6.5 | K8: ='Escandallo por Molde y Tanda'!G71 -> 12 | L8: =IFERROR(I8/K8,"") -> 0.45833333 | M8: Sí | N8: =IF(M8="No","No aplica: su mínimo es el de su denominación",IF(NOT(ISNUMBER(L8)),"",IF(L8>=$B$38,"CUMPLE el 25 % sobre el peso total","NO CUMPLE: no puede llamarse así"))) -> CUMPLE el 25 % sobre el peso total | O8: Misma pieza que BC1 con otra formulación: nata UHT y sorbitol. El kit le da 4-8 semanas frente a los 10-15 días de BC1. Es LA decisión de modelo de negocio del producto, y el libro 5 la cuantifica en euros de merma por caducidad al año.
A9: BC3 | B9: Bombón de praliné de avellana | C9: Bombones de colección | D9: Bombón de chocolate (praliné) | E9: CHN-03 + CHN-82 | F9: 25 % de chocolate sobre el peso TOTAL | G9: No | H9: a granel | I9: ='Escandallo por Molde y Tanda'!E72 -> 5 | J9: ='Escandallo por Molde y Tanda'!F72 -> 7 | K9: ='Escandallo por Molde y Tanda'!G72 -> 12 | L9: =IFERROR(I9/K9,"") -> 0.41666667 | M9: Sí | N9: =IF(M9="No","No aplica: su mínimo es el de su denominación",IF(NOT(ISNUMBER(L9)),"",IF(L9>=$B$38,"CUMPLE el 25 % sobre el peso total","NO CUMPLE: no puede llamarse así"))) -> CUMPLE el 25 % sobre el peso total | O9: «Praline» SI significa algo legalmente: es la denominación de venta europea del bombón de chocolate (`CHN-82`), con el mismo mínimo del 25 %. Escribir lo contrario esta prohibido (§5.1, prohibición 7).
A10: BC4 | B10: Bombón de gianduja de avellana | C10: Bombones de colección | D10: Bombón de chocolate | E10: CHN-03 | F10: 25 % de chocolate sobre el peso TOTAL | G10: No | H10: a granel | I10: ='Escandallo por Molde y Tanda'!E73 -> 5 | J10: ='Escandallo por Molde y Tanda'!F73 -> 7 | K10: ='Escandallo por Molde y Tanda'!G73 -> 12 | L10: =IFERROR(I10/K10,"") -> 0.41666667 | M10: Sí | N10: =IF(M10="No","No aplica: su mínimo es el de su denominación",IF(NOT(ISNUMBER(L10)),"",IF(L10>=$B$38,"CUMPLE el 25 % sobre el peso total","NO CUMPLE: no puede llamarse así"))) -> CUMPLE el 25 % sobre el peso total | O10: La gianduja tiene apartado propio en la norma (1.6.b.3), pero aquí va DENTRO de un bombón: la denominación de venta que manda es la del producto que vendes, no la del relleno.
A11: BC5 | B11: Trufa de chocolate negro al cacao | C11: Bombones de colección | D11: Bombón de chocolate | E11: CHN-03 + CHN-03b | F11: 25 % de chocolate sobre el peso TOTAL | G11: No | H11: a granel | I11: ='Escandallo por Molde y Tanda'!E74 -> 4 | J11: ='Escandallo por Molde y Tanda'!F74 -> 9 | K11: ='Escandallo por Molde y Tanda'!G74 -> 13 | L11: =IFERROR(I11/K11,"") -> 0.30769231 | M11: Sí | N11: =IF(M11="No","No aplica: su mínimo es el de su denominación",IF(NOT(ISNUMBER(L11)),"",IF(L11>=$B$38,"CUMPLE el 25 % sobre el peso total","NO CUMPLE: no puede llamarse así"))) -> CUMPLE el 25 % sobre el peso total | O11: Aquí el 25 % se pelea: 4 g de chocolate sobre 13 g de pieza son el 30,8 %, y bajando el baño un gramo se cae por debajo del mínimo legal. Es el ejemplo con el que el semáforo del libro 4 enseña para que sirve. «Trufa» no es una categoría legal española (`CHN-03b`).
A12: BC6 | B12: Bombón de licor de ron | C12: Bombones de colección | D12: Bombón de chocolate | E12: CHN-03 | F12: 25 % de chocolate sobre el peso TOTAL | G12: No | H12: a granel | I12: ='Escandallo por Molde y Tanda'!E75 -> 6 | J12: ='Escandallo por Molde y Tanda'!F75 -> 8 | K12: ='Escandallo por Molde y Tanda'!G75 -> 14 | L12: =IFERROR(I12/K12,"") -> 0.42857143 | M12: Sí | N12: =IF(M12="No","No aplica: su mínimo es el de su denominación",IF(NOT(ISNUMBER(L12)),"",IF(L12>=$B$38,"CUMPLE el 25 % sobre el peso total","NO CUMPLE: no puede llamarse así"))) -> CUMPLE el 25 % sobre el peso total | O12: Cascara mas gruesa (6 g) porque el licor la ataca. La única del surtido sin leche: si la vendes a granel al lado de las demás, la contaminación cruzada en la pinza se come esa ventaja.
A13: BC7 | B13: Bombón de caramelo salado | C13: Bombones de colección | D13: Bombón de chocolate | E13: CHN-03 | F13: 25 % de chocolate sobre el peso TOTAL | G13: No | H13: a granel | I13: ='Escandallo por Molde y Tanda'!E76 -> 5.5 | J13: ='Escandallo por Molde y Tanda'!F76 -> 6.5 | K13: ='Escandallo por Molde y Tanda'!G76 -> 12 | L13: =IFERROR(I13/K13,"") -> 0.45833333 | M13: Sí | N13: =IF(M13="No","No aplica: su mínimo es el de su denominación",IF(NOT(ISNUMBER(L13)),"",IF(L13>=$B$38,"CUMPLE el 25 % sobre el peso total","NO CUMPLE: no puede llamarse así"))) -> CUMPLE el 25 % sobre el peso total | O13: Azúcar alto y agua baja: aguanta mucho mas que una ganache fresca.
A14: BC8 | B14: Bombón de praliné de cacahuete | C14: Bombones de colección | D14: Bombón de chocolate (praliné) | E14: CHN-03 + CHN-82 | F14: 25 % de chocolate sobre el peso TOTAL | G14: No | H14: a granel | I14: ='Escandallo por Molde y Tanda'!E77 -> 5 | J14: ='Escandallo por Molde y Tanda'!F77 -> 7 | K14: ='Escandallo por Molde y Tanda'!G77 -> 12 | L14: =IFERROR(I14/K14,"") -> 0.41666667 | M14: Sí | N14: =IF(M14="No","No aplica: su mínimo es el de su denominación",IF(NOT(ISNUMBER(L14)),"",IF(L14>=$B$38,"CUMPLE el 25 % sobre el peso total","NO CUMPLE: no puede llamarse así"))) -> CUMPLE el 25 % sobre el peso total | O14: LA REFERENCIA QUE DEMUESTRA POR QUE SON OCHO Y NO CINCO: el cacahuete es el punto 5 del Anexo II y NO es un fruto de cáscara (punto 8). Meterlo dentro de «frutos secos» es un error de etiquetado que puede mandar a alguien al hospital.
A15: BC9 | B15: Bombón crujiente de sésamo y barquillo | C15: Bombones de colección | D15: Bombón de chocolate | E15: CHN-03 | F15: 25 % de chocolate sobre el peso TOTAL | G15: No | H15: a granel | I15: ='Escandallo por Molde y Tanda'!E78 -> 5 | J15: ='Escandallo por Molde y Tanda'!F78 -> 7 | K15: ='Escandallo por Molde y Tanda'!G78 -> 12 | L15: =IFERROR(I15/K15,"") -> 0.41666667 | M15: Sí | N15: =IF(M15="No","No aplica: su mínimo es el de su denominación",IF(NOT(ISNUMBER(L15)),"",IF(L15>=$B$38,"CUMPLE el 25 % sobre el peso total","NO CUMPLE: no puede llamarse así"))) -> CUMPLE el 25 % sobre el peso total | O15: Dos alérgenos mas que sus compañeras, y los dos independientes: granos de sésamo (punto 11) y cereales con gluten del barquillo (punto 1). El kit le da 3-4 semanas, y no por seguridad: pierde el crujiente mucho antes.
A16: BC10 | B16: Bombón de naranja confitada y chocolate negro | C16: Bombones de colección | D16: Bombón de chocolate | E16: CHN-03 | F16: 25 % de chocolate sobre el peso TOTAL | G16: No | H16: a granel | I16: ='Escandallo por Molde y Tanda'!E79 -> 5.5 | J16: ='Escandallo por Molde y Tanda'!F79 -> 6.5 | K16: ='Escandallo por Molde y Tanda'!G79 -> 12 | L16: =IFERROR(I16/K16,"") -> 0.45833333 | M16: Sí | N16: =IF(M16="No","No aplica: su mínimo es el de su denominación",IF(NOT(ISNUMBER(L16)),"",IF(L16>=$B$38,"CUMPLE el 25 % sobre el peso total","NO CUMPLE: no puede llamarse así"))) -> CUMPLE el 25 % sobre el peso total | O16: La única del surtido con SULFITOS, que es el octavo alérgeno y el que mas se olvida: la fruta confitada suele llevarlos y el umbral de declaración es de 10 mg/kg. La fruta además contamina el recorte: su merma NO recuperable es la mas alta de la carta (D40).
A17: TB1 | B17: Tableta de chocolate negro de origen 70 %, 100 g | C17: Tabletas | D17: Chocolate | E17: CHN-02 + CHN-13 | F17: ap. 1.6: mínimos calculados DESCONTANDO los ingredientes añadidos del ap. 3 | G17: Sí | H17: envasado con etiqueta | I17: ='Escandallo por Molde y Tanda'!E80 -> 100 | J17: ='Escandallo por Molde y Tanda'!F80 -> 0 | K17: ='Escandallo por Molde y Tanda'!G80 -> 100 | L17: =IFERROR(I17/K17,"") -> 1 | M17: No | N17: =IF(M17="No","No aplica: su mínimo es el de su denominación",IF(NOT(ISNUMBER(L17)),"",IF(L17>=$B$38,"CUMPLE el 25 % sobre el peso total","NO CUMPLE: no puede llamarse así"))) -> No aplica: su mínimo es el de su denominación | O17: La referencia que vende el posicionamiento: cobertura de origen a 37,48 euros/kg (`CHS-28c`) frente a los 25,02 de la de marca (`CHS-28a`), factor 1,5. Lleva la mención «cacao: X % mínimo» obligatoria (`CHN-07`) y es la que mas sube en verano: no lleva agua, aguanta 12-18 meses y viaja. Y es la referencia con el food cost MAS ALTO de la carta, con diferencia: comprar cobertura de origen y ponerle precio de cobertura de marca es como se regala el trabajo. El libro 3 lo enseña con el escenario de subida del cacao.
A18: TB2 | B18: Tableta de chocolate con leche 38 %, 100 g | C18: Tabletas | D18: Chocolate con leche | E18: CHN-02 + CHN-13 | F18: ap. 1.7: mínimos calculados DESCONTANDO los ingredientes añadidos del ap. 3 | G18: Sí | H18: envasado con etiqueta | I18: ='Escandallo por Molde y Tanda'!E81 -> 100 | J18: ='Escandallo por Molde y Tanda'!F81 -> 0 | K18: ='Escandallo por Molde y Tanda'!G81 -> 100 | L18: =IFERROR(I18/K18,"") -> 1 | M18: No | N18: =IF(M18="No","No aplica: su mínimo es el de su denominación",IF(NOT(ISNUMBER(L18)),"",IF(L18>=$B$38,"CUMPLE el 25 % sobre el peso total","NO CUMPLE: no puede llamarse así"))) -> No aplica: su mínimo es el de su denominación | O18: También lleva la mención «cacao: X % mínimo» (`CHN-07`).
... A30: TF5 | B30: Almendras marcona bañadas en chocolate, bolsa de 150 g | C30: Turrones, figuras y temporada | D30: Grageas o confites de chocolate | E30: CHN-15 | F30: RD 348/2011, ap. 1.3: la denominación de venta se complementa con «relleno», «recubierto» o «grageado» según el caso | G30: No | H30: envasado con etiqueta | I30: ='Escandallo por Molde y Tanda'!E93 -> 88 | J30: ='Escandallo por Molde y Tanda'!F93 -> 62 | K30: ='Escandallo por Molde y Tanda'!G93 -> 150 | L30: =IFERROR(I30/K30,"") -> 0.58666667 | M30: No | N30: =IF(M30="No","No aplica: su mínimo es el de su denominación",IF(NOT(ISNUMBER(L30)),"",IF(L30>=$B$38,"CUMPLE el 25 % sobre el peso total","NO CUMPLE: no puede llamarse así"))) -> No aplica: su mínimo es el de su denominación | O30: La que da nombre a la casa, y su denominación NO sale del RD 1055/2003 sino del RD 348/2011: «grageas o confites de chocolate» (`CHN-15`). Se hace en bombo, no en molde: `moldes_tanda` vale 1 y los 95 minutos son de la tanda entera, de la que salen 40 bolsas. Es la segunda que mas sube en verano: no lleva agua y es souvenir (literal del kit para julio: «packs souvenir y colaboraciones locales»).
A31: CJ1 | B31: Caja surtida de 12 bombones | C31: Cajas y regalo | D31: Chocolates rellenos surtidos | E31: CHN-13 | F31: ap. 6.a) y 6.c): la denominación va por pieza o, si el surtido es de los aps. 1.6 a 1.10 y 1.13, se sustituye por la de surtido, con una única lista de ingredientes. Es una DECISIÓN de etiquetado, no una obligación | G31: No | H31: envasado con etiqueta | I31: ='Escandallo por Molde y Tanda'!E94 -> 62.5 | J31: ='Escandallo por Molde y Tanda'!F94 -> 82.5 | K31: ='Escandallo por Molde y Tanda'!G94 -> 145 | L31: =IFERROR(I31/K31,"") -> 0.43103448 | M31: No | N31: =IF(M31="No","La denominación va por pieza: el 25 % lo comprueba cada bombón en su propia fila, no el agregado de la caja",IF(NOT(ISNUMBER(L31)),"",IF(L31>=$B$38,"CUMPLE el 25 % sobre el peso total","NO CUMPLE: no puede llamarse así"))) -> La denominación va por pieza: el 25 % lo comprueba cada bombón en su propia fila, no el agregado de la caja | O31: PVP de `CHS-29`, precio de MOSTRADOR (con IVA) y base de IVA NO declarada por la fuente: entra con su columna «lleva IVA» y el libro 4 publica el PVP base por fórmula, porque el libro 7 pide el ticket medio SIN IVA. 12 unidades a 20,00 euros son 1,67 euros por bombón. Su coste de materia NO se teclea: se COMPONE de las referencias que lleva dentro (`composicion_caja`), y por eso `g_chocolate` vale 0. Los siete alérgenos son la UNIÓN de lo que va dentro: en un surtido a granel no puedes prometer que una pinza no ha tocado otra cosa.
A32: CJ2 | B32: Caja surtida de 20 bombones | C32: Cajas y regalo | D32: Chocolates rellenos surtidos | E32: CHN-13 | F32: ap. 6.a) y 6.c), igual que CJ1 | G32: No | H32: envasado con etiqueta | I32: ='Escandallo por Molde y Tanda'!E95 -> 102.5 | J32: ='Escandallo por Molde y Tanda'!F95 -> 142.5 | K32: ='Escandallo por Molde y Tanda'!G95 -> 245 | L32: =IFERROR(I32/K32,"") -> 0.41836735 | M32: No | N32: =IF(M32="No","La denominación va por pieza: el 25 % lo comprueba cada bombón en su propia fila, no el agregado de la caja",IF(NOT(ISNUMBER(L32)),"",IF(L32>=$B$38,"CUMPLE el 25 % sobre el peso total","NO CUMPLE: no puede llamarse así"))) -> La denominación va por pieza: el 25 % lo comprueba cada bombón en su propia fila, no el agregado de la caja | O32: 1,40 euros por bombón: un 16 % menos que en la caja de 12.
A33: CJ3 | B33: Caja surtida de 35 bombones | C33: Cajas y regalo | D33: Chocolates rellenos surtidos | E33: CHN-13 | F33: ap. 6.a) y 6.c), igual que CJ1 | G33: No | H33: envasado con etiqueta | I33: ='Escandallo por Molde y Tanda'!E96 -> 181 | J33: ='Escandallo por Molde y Tanda'!F96 -> 247 | K33: ='Escandallo por Molde y Tanda'!G96 -> 428 | L33: =IFERROR(I33/K33,"") -> 0.4228972 | M33: No | N33: =IF(M33="No","La denominación va por pieza: el 25 % lo comprueba cada bombón en su propia fila, no el agregado de la caja",IF(NOT(ISNUMBER(L33)),"",IF(L33>=$B$38,"CUMPLE el 25 % sobre el peso total","NO CUMPLE: no puede llamarse así"))) -> La denominación va por pieza: el 25 % lo comprueba cada bombón en su propia fila, no el agregado de la caja | O33: 1,29 euros por bombón: un 23 % menos que en la caja de 12. Esa escalera es la decisión 4 del bonus 2, y el libro 4 la resuelve comparando el precio de la caja con la suma de sus unidades sueltas.
A34: CJ4 | B34: Estuche corporativo personalizado de 24 bombones | C34: Cajas y regalo | D34: Chocolates rellenos surtidos | E34: CHN-13 | F34: ap. 6.a) y 6.c), igual que CJ1 | G34: No | H34: envasado con etiqueta | I34: ='Escandallo por Molde y Tanda'!E97 -> 123 | J34: ='Escandallo por Molde y Tanda'!F97 -> 170 | K34: ='Escandallo por Molde y Tanda'!G97 -> 293 | L34: =IFERROR(I34/K34,"") -> 0.41979522 | M34: No | N34: =IF(M34="No","La denominación va por pieza: el 25 % lo comprueba cada bombón en su propia fila, no el agregado de la caja",IF(NOT(ISNUMBER(L34)),"",IF(L34>=$B$38,"CUMPLE el 25 % sobre el peso total","NO CUMPLE: no puede llamarse así"))) -> La denominación va por pieza: el 25 % lo comprueba cada bombón en su propia fila, no el agregado de la caja | O34: SUPUESTO: `CHS-29` no cubre el estuche corporativo. Lo que SI esta verificado es su regla operativa: 14 días de plazo mínimo desde la aprobación de la muestra (`CHS-55`), que es lo que decide si aceptas un pedido de empresa en diciembre. Y es el canal que te saca de la nota del epígrafe 644.5 y te mete en la tabla de CLIENTES del art. 5.3.b) del EUDR (`CHN-24`, D48).
A35: ENVASADO CON ETIQUETA: Sale envasado con SU etiqueta. El art. 4.2 del RD 1021/2022 fija la temperatura de conservación POR LA ETIQUETA que pone quien ha producido y envasado: la que tu has escrito te obliga a ti. Y con etiqueta entran además las doce menciones del art. 9.1 del Rgto. 1169/2011 (CHN-35) mas el lote, que NO viene de ese reglamento sino del RD 1808/1991 (CHN-36).
A37: Los mínimos que usa el semáforo
A38: Chocolate mínimo sobre el PESO TOTAL del bombón y del chocolate relleno (aps. 1.10 y 1.13, y la base es el peso total CON el relleno dentro) | B38: 0.25
A39: Materia seca TOTAL de cacao del chocolate a la taza (ap. 1.11) | B39: 0.35
A40: Manteca de cacao del chocolate a la taza (ap. 1.11) | B40: 0.18
A41: Materia seca DESGRASADA de cacao del chocolate a la taza (ap. 1.11) | B41: 0.14
A43: Capa (b): las tres magnitudes que la norma pide y la bolsa no trae. Cópialas de la ficha técnica de tu proveedor
A44: Cobertura | B44: Materia seca TOTAL de cacao | C44: Manteca de cacao | D44: Materia seca DESGRASADA de cacao | E44: ¿Llega a los tres umbrales de materia seca del ap. 1.11? | F44: Qué te dice eso, y qué no | G44: Nota
A45: Cobertura de chocolate negro (marca, 54,5 % de cacao) | B45: 0.545 | C45: 0.31 | D45: 0.235 | E45: =IF(OR(NOT(ISNUMBER(B45)),NOT(ISNUMBER(C45)),NOT(ISNUMBER(D45))),"",IF(AND(B45>=$B$39,C45>=$B$40,D45>=$B$41),"Sí","No")) -> Sí | F45: =IF(E45="","",IF(E45="Sí","Pasa los tres umbrales de materia seca. Eso NO decide la denominación por sí solo: depende además de qué lleva (leche, harina o almidón hasta el 8 %), y lo confirma la ficha técnica de tu proveedor","No llega a los tres umbrales: con esta cobertura no puedes ir por esa denominación")) -> Pasa los tres umbrales de materia seca. Eso NO decide la denominación por sí solo: depende además de qué lleva (leche, harina o almidón hasta el 8 %), y lo confirma la ficha técnica de tu proveedor | G45: LA CELDA MAS CRITICA DEL PAQUETE. Base CON IVA declarada por la ficha (`CHS-28a`): el libro 3 la publica en las dos bases y lo que viaja al 4 y al 7 es la base imponible. Las tres magnitudes de arriba son SUPUESTO: pidesela a tu proveedor, la bolsa solo trae el total.
A46: Cobertura de chocolate de origen (70 % de cacao) | B46: 0.7 | C46: 0.42 | D46: 0.28 | E46: =IF(OR(NOT(ISNUMBER(B46)),NOT(ISNUMBER(C46)),NOT(ISNUMBER(D46))),"",IF(AND(B46>=$B$39,C46>=$B$40,D46>=$B$41),"Sí","No")) -> Sí | F46: =IF(E46="","",IF(E46="Sí","Pasa los tres umbrales de materia seca. Eso NO decide la denominación por sí solo: depende además de qué lleva (leche, harina o almidón hasta el 8 %), y lo confirma la ficha técnica de tu proveedor","No llega a los tres umbrales: con esta cobertura no puedes ir por esa denominación")) -> Pasa los tres umbrales de materia seca. Eso NO decide la denominación por sí solo: depende además de qué lleva (leche, harina o almidón hasta el 8 %), y lo confirma la ficha técnica de tu proveedor | G46: Factor 1,5 frente a la de marca, y es la decisión de posicionamiento mas cara del negocio (decisión 5 del bonus 2). La pagina no declara si el precio lleva IVA: se trata como base imponible y se marca.
A47: Cobertura de chocolate con leche (38 % de cacao) | B47: 0.38 | C47: 0.21 | D47: 0.17 | E47: =IF(OR(NOT(ISNUMBER(B47)),NOT(ISNUMBER(C47)),NOT(ISNUMBER(D47))),"",IF(AND(B47>=$B$39,C47>=$B$40,D47>=$B$41),"Sí","No")) -> Sí | F47: =IF(E47="","",IF(E47="Sí","Pasa los tres umbrales de materia seca. Eso NO decide la denominación por sí solo: depende además de qué lleva (leche, harina o almidón hasta el 8 %), y lo confirma la ficha técnica de tu proveedor","No llega a los tres umbrales: con esta cobertura no puedes ir por esa denominación")) -> Pasa los tres umbrales de materia seca. Eso NO decide la denominación por sí solo: depende además de qué lleva (leche, harina o almidón hasta el 8 %), y lo confirma la ficha técnica de tu proveedor | G47: SUPUESTO declarado: no hay precio verificado de cobertura con leche en el research. Celda verde con valor por defecto (regla 2 de §2.3: ninguna celda verde vacia).
A48: Cobertura de chocolate blanco (30 % de cacao) | B48: 0.3 | C48: 0.3 | D48: 0 | E48: =IF(OR(NOT(ISNUMBER(B48)),NOT(ISNUMBER(C48)),NOT(ISNUMBER(D48))),"",IF(AND(B48>=$B$39,C48>=$B$40,D48>=$B$41),"Sí","No")) -> No | F48: =IF(E48="","",IF(E48="Sí","Pasa los tres umbrales de materia seca. Eso NO decide la denominación por sí solo: depende además de qué lleva (leche, harina o almidón hasta el 8 %), y lo confirma la ficha técnica de tu proveedor","No llega a los tres umbrales: con esta cobertura no puedes ir por esa denominación")) -> No llega a los tres umbrales: con esta cobertura no puedes ir por esa denominación | G48: SUPUESTO declarado. Ojo al chocolate blanco: NO lleva materia seca desgrasada de cacao, y por eso el art. 6.d) del RD 1055/2003 NO le obliga a la mención «cacao: X % mínimo» (`CHN-07`).
A50: Las tres magnitudes de arriba son SUPUESTOS de ejemplo, no un dato de tu proveedor: la bolsa de una cobertura de marca publica un solo número («54,5 %») y la norma necesita tres. Es la misma ficha técnica que te va a pedir el libro de proveedores para el boletín de cadmio, así que se pide una sola vez.
A52: El tope del 40 % de materias añadidas (ap. 3)
A53: Tope de materias añadidas del ap. 3 | B53: 0.4
A55: Id | B55: Referencia | C55: Materia añadida sobre el peso total | D55: Veredicto
A56: TB4 | B56: Tableta de chocolate negro con almendra marcona, 100 g | C56: =IFERROR('Escandallo por Molde y Tanda'!F83/'Escandallo por Molde y Tanda'!G83,"") -> 0.22 | D56: =IF(NOT(ISNUMBER(C56)),"",IF(C56<=$B$53,"CUMPLE el tope del 40 %","NO CUMPLE: revisa el gramaje")) -> CUMPLE el tope del 40 %
A57: TB5 | B57: Tableta de chocolate con leche y avellana, 100 g | C57: =IFERROR('Escandallo por Molde y Tanda'!F84/'Escandallo por Molde y Tanda'!G84,"") -> 0.2 | D57: =IF(NOT(ISNUMBER(C57)),"",IF(C57<=$B$53,"CUMPLE el tope del 40 %","NO CUMPLE: revisa el gramaje")) -> CUMPLE el tope del 40 %
...

Sheet Escandallo por Molde y Tanda
A1: Escandallo por Molde y Tanda
A2: AI Chef Pro · aichef.pro — Cómo Montar una Chocolatería
A3: Arriba, lo que cuesta un kilo de cada relleno. Abajo, lo que cuesta una pieza. Las cajas no tienen escandallo propio: se componen de sus bombones.
A5: Fórmulas de relleno: cantidad que entra en UN KILO
A6: Relleno | B6: Ingrediente | C6: Cantidad por kilo | D6: Precio de compra (EUR) | E6: Unidad de compra | F6: Coste de la línea (EUR) | G6: Nota
A7: ganache negra fresca | B7: Nata 35 % MG fresca | C7: 0.4 | D7: =IFERROR(VLOOKUP(B7,'Parámetros'!$A$48:$B$73,2,FALSE),"") -> 4.2 | E7: L | F7: =IFERROR(C7*D7,"") -> 1.68 | G7: Fórmulas de EJEMPLO, declaradas. Este producto NO es un recetario y no publica curvas de templado: una curva mal publicada arruina producción. Lo que hacen estas líneas es dar al libro algo que costear.
A8: ganache negra fresca | B8: Cobertura negra | C8: 0.52 | D8: =IFERROR(VLOOKUP(B8,'Parámetros'!$A$48:$B$73,2,FALSE),"") -> 22.7455 | E8: kg | F8: =IFERROR(C8*D8,"") -> 11.82766
A9: ganache negra fresca | B9: Mantequilla | C9: 0.06 | D9: =IFERROR(VLOOKUP(B9,'Parámetros'!$A$48:$B$73,2,FALSE),"") -> 9.8 | E9: kg | F9: =IFERROR(C9*D9,"") -> 0.588
A10: ganache negra fresca | B10: Glucosa | C10: 0.04 | D10: =IFERROR(VLOOKUP(B10,'Parámetros'!$A$48:$B$73,2,FALSE),"") -> 3.4 | E10: kg | F10: =IFERROR(C10*D10,"") -> 0.136
A11: ganache leche estabilizada | B11: Nata 35 % MG UHT | C11: 0.34 | D11: =IFERROR(VLOOKUP(B11,'Parámetros'!$A$48:$B$73,2,FALSE),"") -> 3.1 | E11: L | F11: =IFERROR(C11*D11,"") -> 1.054
A12: ganache leche estabilizada | B12: Cobertura con leche | C12: 0.56 | D12: =IFERROR(VLOOKUP(B12,'Parámetros'!$A$48:$B$73,2,FALSE),"") -> 19.5 | E12: kg | F12: =IFERROR(C12*D12,"") -> 10.92
A13: ganache leche estabilizada | B13: Sorbitol | C13: 0.06 | D13: =IFERROR(VLOOKUP(B13,'Parámetros'!$A$48:$B$73,2,FALSE),"") -> 6.2 | E13: kg | F13: =IFERROR(C13*D13,"") -> 0.372
A14: ganache leche estabilizada | B14: Mantequilla | C14: 0.05 | D14: =IFERROR(VLOOKUP(B14,'Parámetros'!$A$48:$B$73,2,FALSE),"") -> 9.8 | E14: kg | F14: =IFERROR(C14*D14,"") -> 0.49
A15: praliné avellana | B15: Praline de avellana 50 % | C15: 0.7 | D15: =IFERROR(VLOOKUP(B15,'Parámetros'!$A$48:$B$73,2,FALSE),"") -> 14.8 | E15: kg | F15: =IFERROR(C15*D15,"") -> 10.36
A16: praliné avellana | B16: Cobertura con leche | C16: 0.28 | D16: =IFERROR(VLOOKUP(B16,'Parámetros'!$A$48:$B$73,2,FALSE),"") -> 19.5 | E16: kg | F16: =IFERROR(C16*D16,"") -> 5.46
A17: praliné avellana | B17: Manteca de cacao | C17: 0.04 | D17: =IFERROR(VLOOKUP(B17,'Parámetros'!$A$48:$B$73,2,FALSE),"") -> 18.6 | E17: kg | F17: =IFERROR(C17*D17,"") -> 0.744
A18: gianduja avellana | B18: Pasta pura de avellana | C18: 0.45 | D18: =IFERROR(VLOOKUP(B18,'Parámetros'!$A$48:$B$73,2,FALSE),"") -> 22.5 | E18: kg | F18: =IFERROR(C18*D18,"") -> 10.125
A19: gianduja avellana | B19: Cobertura con leche | C19: 0.4 | D19: =IFERROR(VLOOKUP(B19,'Parámetros'!$A$48:$B$73,2,FALSE),"") -> 19.5 | E19: kg | F19: =IFERROR(C19*D19,"") -> 7.8
... A48: yema tostada | B48: Almidón de maíz | C48: 0.05 | D48: =IFERROR(VLOOKUP(B48,'Parámetros'!$A$48:$B$73,2,FALSE),"") -> 2.1 | E48: kg | F48: =IFERROR(C48*D48,"") -> 0.105
A50: Coste por kilo de cada relleno y de cada materia añadida
A51: Relleno o materia añadida | B51: Coste por kilo (EUR) | C51: Familia de vida útil del kit (se CITA, no se reescribe) | D51: Plazo orientativo que publica el kit | E51: Nota
A52: ganache negra fresca | B52: =SUM(F7:F10) -> 14.23166 | C52: Bombones de ganache con nata fresca | D52: 10-15 días | E52: La ganache que obliga a decidir el modelo de negocio: agua disponible alta, y el kit le da 10-15 días. Es la que manda en la decisión 3 del bonus 2.
A53: ganache leche estabilizada | B53: =SUM(F11:F14) -> 12.836 | C53: Bombones de ganache con nata UHT, sorbato o alcohol | D53: 4-8 semanas | E53: La misma pieza con otra formulación: el kit le da 4-8 semanas. Entre esta y la anterior hay un factor DE TRES A CINCO, y esa es una decisión de modelo de negocio, no técnica.
A54: praliné avellana | B54: =SUM(F15:F17) -> 16.564 | C54: Bombones de praliné, gianduja y frutos secos | D54: 2-4 meses | E54: «Praline» NO es un nombre comercial: el punto 10 de la parte A del Anexo I de la Directiva 2000/36/CE se titula «Bombón de chocolate o praliné» (`CHN-82`), con el mismo mínimo del 25 %.
A55: gianduja avellana | B55: =SUM(F18:F20) -> 18.1205 | C55: Bombones de praliné, gianduja y frutos secos | D55: 2-4 meses | E55: La gianduja tiene su propio apartado en la norma (1.6.b.3), con avellanas entre 20 y 40 g por 100 g. Aquí es RELLENO de un bombón, así que la denominación de venta es la del bombón.
A56: trufa | B56: =SUM(F21:F24) -> 14.12257 | C56: Trufas y rocas recubiertas | D56: 3-4 semanas | E56: «Trufa» no aparece ni una vez en el RD 1055/2003 (`CHN-03b`): es un TIPO de bombón, no una categoría legal ni un sinonimo de bombón.
A57: licor | B57: =SUM(F25:F27) -> 4.552 | C57: Bombones de licor y cristalizados | D57: 3-6 meses | E57: El alcohol baja la actividad de agua. Vigilar la cristalización del azúcar en la cáscara: revienta y gotea (nota literal del kit).
A58: caramelo salado | B58: =SUM(F28:F32) -> 3.9892 | C58: Bombones de ganache con nata UHT, sorbato o alcohol | D58: 4-8 semanas | E58: Azúcar alto y agua baja: aguanta mas que una ganache fresca.
A59: praliné cacahuete | B59: =SUM(F33:F35) -> 12.726 | C59: Bombones de praliné, gianduja y frutos secos | D59: 2-4 meses | E59: EL CACAHUETE ES EL PUNTO 5 DEL ANEXO II y NO es un fruto de cáscara (`CHN-34b`): esta referencia se etiqueta con su propio alérgeno, no dentro de «frutos secos».
A60: crujiente sésamo | B60: =SUM(F36:F38) -> 13.278 | C60: Barquillos y crujientes bañados | D60: 3-4 semanas | E60: DOS alérgenos independientes en una sola pieza: granos de sésamo (punto 11) y cereales con gluten del barquillo (punto 1). El kit le da 3-4 semanas, y no por seguridad: pierde el crujiente mucho antes.
A61: naranja confitada | B61: =SUM(F39:F40) -> 14.34729 | C61: Frutos secos garrapiñados y frutas confitadas bañadas | D61: 1-3 meses | E61: La fruta confitada suele llevar SULFITOS (punto 12 del Anexo II), que es el octavo alérgeno y el que mas se olvida. Pidele a tu proveedor la ficha técnica: el umbral de declaración es 10 mg/kg.
A62: praliné de tableta | B62: =SUM(F41:F42) -> 16.13 | C62: Bombones de praliné, gianduja y frutos secos | D62: 2-4 meses | E62: En una TABLETA RELLENA la denominación es «chocolate relleno» (ap. 1.10) y el exterior tiene que ser al menos el 25 % del peso total (`CHN-04`), calculado SOBRE EL PESO TOTAL con el relleno dentro (`CHN-10`).
A63: masa a la taza | B63: =SUM(F43:F45) -> 4.331 | C63: Tabletas y chocolate sin relleno | D63: 12-18 meses | E63: NO es un relleno: es la otra mitad de la fórmula del chocolate a la taza, que NO se hace solo con cobertura. Va aquí para que el escandallo pueda costearla. El almidón es DE MAÍZ a propósito: la norma admite trigo, arroz o maíz hasta el 8 %, y con el de trigo habría que declarar gluten.
A64: yema tostada | B64: =SUM(F46:F48) -> 2.589 | C64: Bombones de ganache con nata fresca | D64: 10-15 días | E64: La ÚNICA referencia del surtido con huevo, y va con ovoproducto pasteurizado de establecimiento autorizado, que es la tercera vía del art. 9 del RD 1021/2022 (`CHN-31`). Con huevo crudo habría que llegar a 70 °C durante 2 s en el centro.
A65: Almendra marcona repelada | B65: =IFERROR(VLOOKUP(A65,'Parámetros'!$A$48:$B$73,2,FALSE),"") -> 12.4 | C65: No es un relleno: es materia comestible añadida del ap. 3 | D65: la de la referencia que la lleva | E65: Va en la misma tabla para que el escandallo busque en un solo sitio, lleve relleno o lleve almendra.
A66: Avellana tostada | B66: =IFERROR(VLOOKUP(A66,'Parámetros'!$A$48:$B$73,2,FALSE),"") -> 13.9 | C66: No es un relleno: es materia comestible añadida del ap. 3 | D66: la de la referencia que la lleva | E66: Va en la misma tabla para que el escandallo busque en un solo sitio, lleve relleno o lleve almendra.
A68: Escandallo por referencia
A69: Id | B69: Referencia | C69: Familia | D69: Cobertura | E69: Gramos de chocolate por pieza | F69: Gramos de relleno o materia por pieza | G69: Peso total de la pieza (g) | H69: Relleno o materia añadida | I69: Precio de la cobertura (EUR/kg) | J69: Coste del chocolate (EUR) | K69: Coste por kilo del relleno (EUR) | L69: Coste del relleno (EUR) | M69: COSTE DE MATERIA SIN MERMA (EUR) | N69: Merma NO recuperable | O69: COSTE DE MATERIA CON EL RECORTE QUE NO VUELVE (EUR) | P69: Procedencia y nota
A70: BC1 | B70: Bombón de ganache de chocolate negro 70 % | C70: Bombones de colección | D70: Cobertura negra | E70: 5.5 | F70: 6.5 | G70: =IFERROR(E70+F70,"") -> 12 | H70: ganache negra fresca | I70: =IFERROR(VLOOKUP(D70,'Parámetros'!$A$48:$B$73,2,FALSE),"") -> 22.7455 | J70: =IFERROR(E70/1000*I70,"") -> 0.12510025 | K70: =IFERROR(VLOOKUP(H70,'Escandallo por Molde y Tanda'!$A$52:$B$66,2,FALSE),"") -> 14.23166 | L70: =IFERROR(F70/1000*K70,"") -> 0.09250579 | M70: =IFERROR(J70+L70,"") -> 0.21760604 | N70: ='Merma de Templado y Recortes'!E7 -> 0.03 | O70: =IFERROR(M70/(1-N70),"") -> 0.22433612 | P70: La referencia que mas margen deja y la que antes caduca. Con 5,5 g de chocolate sobre 12 g de pieza, el chocolate es el 45,8 % del peso total: cumple el 25 % del ap. 1.13 con holgura. En julio y agosto baja a un tercio de su mix: es la primera que sale del catálogo de verano (literal del kit para junio: «menos ganache fresca»).
A71: BC2 | B71: Bombón de ganache de leche y vainilla | C71: Bombones de colección | D71: Cobertura con leche | E71: 5.5 | F71: 6.5 | G71: =IFERROR(E71+F71,"") -> 12 | H71: ganache leche estabilizada | I71: =IFERROR(VLOOKUP(D71,'Parámetros'!$A$48:$B$73,2,FALSE),"") -> 19.5 | J71: =IFERROR(E71/1000*I71,"") -> 0.10725 | K71: =IFERROR(VLOOKUP(H71,'Escandallo por Molde y Tanda'!$A$52:$B$66,2,FALSE),"") -> 12.836 | L71: =IFERROR(F71/1000*K71,"") -> 0.083434 | M71: =IFERROR(J71+L71,"") -> 0.190684 | N71: ='Merma de Templado y Recortes'!E8 -> 0.03 | O71: =IFERROR(M71/(1-N71),"") -> 0.19658144 | P71: Misma pieza que BC1 con otra formulación: nata UHT y sorbitol. El kit le da 4-8 semanas frente a los 10-15 días de BC1. Es LA decisión de modelo de negocio del producto, y el libro 5 la cuantifica en euros de merma por caducidad al año.
...

Sheet Merma de Templado y Recortes
A1: Merma de Templado y Recortes
A2: AI Chef Pro · aichef.pro — Cómo Montar una Chocolatería
A3: DOS tasas por referencia, y la regla es del kit: «El chocolate sin relleno y sin contaminar se puede refundir; el que lleva ganache o fruta, a residuo» (02-partidas-produccion.xlsx, hoja «Moldeado»). Lo que vuelve a la cuba no encarece la materia; lo que se tira, sí.
A6: Id | B6: Referencia | C6: ¿Lleva ganache, relleno o fruta? | D6: Merma RECUPERABLE (vuelve a la cuba) | E6: Merma NO RECUPERABLE (a residuo) | F6: Coste de materia sin merma (EUR) | G6: Coste real con el recorte que vuelve (EUR) | H6: Sobrecoste de la merma (EUR) | I6: Sobrecoste sobre el coste | J6: Chocolate limpio que vuelve a la cuba (g/pieza) | K6: Producto que va a residuo (g/pieza) | L6: Unidades al año | M6: Kilos al año que vuelven a la cuba | N6: Kilos al año a residuo | O6: Coste anual de la merma no recuperable (EUR) | P6: Nota
A7: BC1 | B7: Bombón de ganache de chocolate negro 70 % | C7: Sí | D7: 0.04 | E7: 0.03 | F7: ='Escandallo por Molde y Tanda'!M70 -> 0.21760604 | G7: ='Escandallo por Molde y Tanda'!O70 -> 0.22433612 | H7: =IFERROR(G7-F7,"") -> 0.0067300837 | I7: =IFERROR(H7/F7,"") -> 0.030927835 | J7: =IFERROR('Escandallo por Molde y Tanda'!E70*D7,"") -> 0.22 | K7: =IFERROR('Escandallo por Molde y Tanda'!G70*E7,"") -> 0.36 | L7: ='Mix y Ticket Medio'!K7 -> 1710.912 | M7: =IFERROR(J7*L7/1000,"") -> 0.37640064 | N7: =IFERROR(K7*L7/1000,"") -> 0.61592832 | O7: =IFERROR(H7*L7,"") -> 11.514581 | P7: Lleva ganache, relleno o fruta: lo que se recorta va a residuo y se reparte entre las piezas que salen bien.
A8: BC2 | B8: Bombón de ganache de leche y vainilla | C8: Sí | D8: 0.04 | E8: 0.03 | F8: ='Escandallo por Molde y Tanda'!M71 -> 0.190684 | G8: ='Escandallo por Molde y Tanda'!O71 -> 0.19658144 | H8: =IFERROR(G8-F8,"") -> 0.0058974433 | I8: =IFERROR(H8/F8,"") -> 0.030927835 | J8: =IFERROR('Escandallo por Molde y Tanda'!E71*D8,"") -> 0.22 | K8: =IFERROR('Escandallo por Molde y Tanda'!G71*E8,"") -> 0.36 | L8: ='Mix y Ticket Medio'!K8 -> 1425.76 | M8: =IFERROR(J8*L8/1000,"") -> 0.3136672 | N8: =IFERROR(K8*L8/1000,"") -> 0.5132736 | O8: =IFERROR(H8*L8,"") -> 8.4083388 | P8: Lleva ganache, relleno o fruta: lo que se recorta va a residuo y se reparte entre las piezas que salen bien.
A9: BC3 | B9: Bombón de praliné de avellana | C9: Sí | D9: 0.04 | E9: 0.02 | F9: ='Escandallo por Molde y Tanda'!M72 -> 0.213448 | G9: ='Escandallo por Molde y Tanda'!O72 -> 0.21780408 | H9: =IFERROR(G9-F9,"") -> 0.0043560816 | I9: =IFERROR(H9/F9,"") -> 0.020408163 | J9: =IFERROR('Escandallo por Molde y Tanda'!E72*D9,"") -> 0.2 | K9: =IFERROR('Escandallo por Molde y Tanda'!G72*E9,"") -> 0.24 | L9: ='Mix y Ticket Medio'!K9 -> 1710.912 | M9: =IFERROR(J9*L9/1000,"") -> 0.3421824 | N9: =IFERROR(K9*L9/1000,"") -> 0.41061888 | O9: =IFERROR(H9*L9,"") -> 7.4528723 | P9: Lleva ganache, relleno o fruta: lo que se recorta va a residuo y se reparte entre las piezas que salen bien.
A10: BC4 | B10: Bombón de gianduja de avellana | C10: Sí | D10: 0.04 | E10: 0.02 | F10: ='Escandallo por Molde y Tanda'!M73 -> 0.2243435 | G10: ='Escandallo por Molde y Tanda'!O73 -> 0.22892194 | H10: =IFERROR(G10-F10,"") -> 0.0045784388 | I10: =IFERROR(H10/F10,"") -> 0.020408163 | J10: =IFERROR('Escandallo por Molde y Tanda'!E73*D10,"") -> 0.2 | K10: =IFERROR('Escandallo por Molde y Tanda'!G73*E10,"") -> 0.24 | L10: ='Mix y Ticket Medio'!K10 -> 1140.608 | M10: =IFERROR(J10*L10/1000,"") -> 0.2281216 | N10: =IFERROR(K10*L10/1000,"") -> 0.27374592 | O10: =IFERROR(H10*L10,"") -> 5.2222039 | P10: Lleva ganache, relleno o fruta: lo que se recorta va a residuo y se reparte entre las piezas que salen bien.
A11: BC5 | B11: Trufa de chocolate negro al cacao | C11: Sí | D11: 0.03 | E11: 0.04 | F11: ='Escandallo por Molde y Tanda'!M74 -> 0.21808513 | G11: ='Escandallo por Molde y Tanda'!O74 -> 0.22717201 | H11: =IFERROR(G11-F11,"") -> 0.0090868804 | I11: =IFERROR(H11/F11,"") -> 0.041666667 | J11: =IFERROR('Escandallo por Molde y Tanda'!E74*D11,"") -> 0.12 | K11: =IFERROR('Escandallo por Molde y Tanda'!G74*E11,"") -> 0.52 | L11: ='Mix y Ticket Medio'!K11 -> 1425.76 | M11: =IFERROR(J11*L11/1000,"") -> 0.1710912 | N11: =IFERROR(K11*L11/1000,"") -> 0.7413952 | O11: =IFERROR(H11*L11,"") -> 12.955711 | P11: Lleva ganache, relleno o fruta: lo que se recorta va a residuo y se reparte entre las piezas que salen bien.
A12: BC6 | B12: Bombón de licor de ron | C12: Sí | D12: 0.05 | E12: 0.04 | F12: ='Escandallo por Molde y Tanda'!M75 -> 0.172889 | G12: ='Escandallo por Molde y Tanda'!O75 -> 0.18009271 | H12: =IFERROR(G12-F12,"") -> 0.0072037083 | I12: =IFERROR(H12/F12,"") -> 0.041666667 | J12: =IFERROR('Escandallo por Molde y Tanda'!E75*D12,"") -> 0.3 | K12: =IFERROR('Escandallo por Molde y Tanda'!G75*E12,"") -> 0.56 | L12: ='Mix y Ticket Medio'!K12 -> 855.456 | M12: =IFERROR(J12*L12/1000,"") -> 0.2566368 | N12: =IFERROR(K12*L12/1000,"") -> 0.47905536 | O12: =IFERROR(H12*L12,"") -> 6.1624555 | P12: Lleva ganache, relleno o fruta: lo que se recorta va a residuo y se reparte entre las piezas que salen bien.
A13: BC7 | B13: Bombón de caramelo salado | C13: Sí | D13: 0.04 | E13: 0.03 | F13: ='Escandallo por Molde y Tanda'!M76 -> 0.1331798 | G13: ='Escandallo por Molde y Tanda'!O76 -> 0.13729876 | H13: =IFERROR(G13-F13,"") -> 0.0041189629 | I13: =IFERROR(H13/F13,"") -> 0.030927835 | J13: =IFERROR('Escandallo por Molde y Tanda'!E76*D13,"") -> 0.22 | K13: =IFERROR('Escandallo por Molde y Tanda'!G76*E13,"") -> 0.36 | L13: ='Mix y Ticket Medio'!K13 -> 1140.608 | M13: =IFERROR(J13*L13/1000,"") -> 0.25093376 | N13: =IFERROR(K13*L13/1000,"") -> 0.41061888 | O13: =IFERROR(H13*L13,"") -> 4.698122 | P13: Lleva ganache, relleno o fruta: lo que se recorta va a residuo y se reparte entre las piezas que salen bien.
A14: BC8 | B14: Bombón de praliné de cacahuete | C14: Sí | D14: 0.04 | E14: 0.02 | F14: ='Escandallo por Molde y Tanda'!M77 -> 0.186582 | G14: ='Escandallo por Molde y Tanda'!O77 -> 0.1903898 | H14: =IFERROR(G14-F14,"") -> 0.0038077959 | I14: =IFERROR(H14/F14,"") -> 0.020408163 | J14: =IFERROR('Escandallo por Molde y Tanda'!E77*D14,"") -> 0.2 | K14: =IFERROR('Escandallo por Molde y Tanda'!G77*E14,"") -> 0.24 | L14: ='Mix y Ticket Medio'!K14 -> 855.456 | M14: =IFERROR(J14*L14/1000,"") -> 0.1710912 | N14: =IFERROR(K14*L14/1000,"") -> 0.20530944 | O14: =IFERROR(H14*L14,"") -> 3.2574019 | P14: Lleva ganache, relleno o fruta: lo que se recorta va a residuo y se reparte entre las piezas que salen bien.
A15: BC9 | B15: Bombón crujiente de sésamo y barquillo | C15: Sí | D15: 0.04 | E15: 0.02 | F15: ='Escandallo por Molde y Tanda'!M78 -> 0.190446 | G15: ='Escandallo por Molde y Tanda'!O78 -> 0.19433265 | H15: =IFERROR(G15-F15,"") -> 0.0038866531 | I15: =IFERROR(H15/F15,"") -> 0.020408163 | J15: =IFERROR('Escandallo por Molde y Tanda'!E78*D15,"") -> 0.2 | K15: =IFERROR('Escandallo por Molde y Tanda'!G78*E15,"") -> 0.24 | L15: ='Mix y Ticket Medio'!K15 -> 855.456 | M15: =IFERROR(J15*L15/1000,"") -> 0.1710912 | N15: =IFERROR(K15*L15/1000,"") -> 0.20530944 | O15: =IFERROR(H15*L15,"") -> 3.3248607 | P15: Lleva ganache, relleno o fruta: lo que se recorta va a residuo y se reparte entre las piezas que salen bien.
A16: BC10 | B16: Bombón de naranja confitada y chocolate negro | C16: Sí | D16: 0.03 | E16: 0.05 | F16: ='Escandallo por Molde y Tanda'!M79 -> 0.21835763 | G16: ='Escandallo por Molde y Tanda'!O79 -> 0.22985014 | H16: =IFERROR(G16-F16,"") -> 0.011492507 | I16: =IFERROR(H16/F16,"") -> 0.052631579 | J16: =IFERROR('Escandallo por Molde y Tanda'!E79*D16,"") -> 0.165 | K16: =IFERROR('Escandallo por Molde y Tanda'!G79*E16,"") -> 0.6 | L16: ='Mix y Ticket Medio'!K16 -> 855.456 | M16: =IFERROR(J16*L16/1000,"") -> 0.14115024 | N16: =IFERROR(K16*L16/1000,"") -> 0.5132736 | O16: =IFERROR(H16*L16,"") -> 9.8313342 | P16: Lleva ganache, relleno o fruta: lo que se recorta va a residuo y se reparte entre las piezas que salen bien.
A17: TB1 | B17: Tableta de chocolate negro de origen 70 %, 100 g | C17: No | D17: 0.06 | E17: 0.01 | F17: ='Escandallo por Molde y Tanda'!M80 -> 3.748 | G17: ='Escandallo por Molde y Tanda'!O80 -> 3.7858586 | H17: =IFERROR(G17-F17,"") -> 0.037858586 | I17: =IFERROR(H17/F17,"") -> 0.01010101 | J17: =IFERROR('Escandallo por Molde y Tanda'!E80*D17,"") -> 6 | K17: =IFERROR('Escandallo por Molde y Tanda'!G80*E17,"") -> 1 | L17: ='Mix y Ticket Medio'!K17 -> 1996.064 | M17: =IFERROR(J17*L17/1000,"") -> 11.976384 | N17: =IFERROR(K17*L17/1000,"") -> 1.996064 | O17: =IFERROR(H17*L17,"") -> 75.56816 | P17: El recorte limpio vuelve a la cuba: no es coste de materia, pero hay que volver a templarlo y ese trabajo lo paga la mano de obra.
A18: TB2 | B18: Tableta de chocolate con leche 38 %, 100 g | C18: No | D18: 0.06 | E18: 0.01 | F18: ='Escandallo por Molde y Tanda'!M81 -> 1.95 | G18: ='Escandallo por Molde y Tanda'!O81 -> 1.969697 | H18: =IFERROR(G18-F18,"") -> 0.01969697 | I18: =IFERROR(H18/F18,"") -> 0.01010101 | J18: =IFERROR('Escandallo por Molde y Tanda'!E81*D18,"") -> 6 | K18: =IFERROR('Escandallo por Molde y Tanda'!G81*E18,"") -> 1 | L18: ='Mix y Ticket Medio'!K18 -> 1710.912 | M18: =IFERROR(J18*L18/1000,"") -> 10.265472 | N18: =IFERROR(K18*L18/1000,"") -> 1.710912 | O18: =IFERROR(H18*L18,"") -> 33.699782 | P18: El recorte limpio vuelve a la cuba: no es coste de materia, pero hay que volver a templarlo y ese trabajo lo paga la mano de obra.
... A34: CJ4 | B34: Estuche corporativo personalizado de 24 bombones | C34: Sí | D34: 0 | E34: 0.005 | F34: ='Escandallo por Molde y Tanda'!M97 -> 4.7264465 | G34: ='Escandallo por Molde y Tanda'!O97 -> 4.7501975 | H34: =IFERROR(G34-F34,"") -> 0.023750988 | I34: =IFERROR(H34/F34,"") -> 0.0050251256 | J34: =IFERROR('Escandallo por Molde y Tanda'!E97*D34,"") -> 0 | K34: =IFERROR('Escandallo por Molde y Tanda'!G97*E34,"") -> 1.465 | L34: ='Mix y Ticket Medio'!K34 -> 285.152 | M34: =IFERROR(J34*L34/1000,"") -> 0 | N34: =IFERROR(K34*L34/1000,"") -> 0.41774768 | O34: =IFERROR(H34*L34,"") -> 6.7726416 | P34: Lleva ganache, relleno o fruta: lo que se recorta va a residuo y se reparte entre las piezas que salen bien.
A35: TOTAL del año | M35: =SUM(M7:M34) -> 86.413888 | N35: =SUM(N7:N34) -> 38.314448 | O35: =SUM(O7:O34) -> 718.76662
A37: Los kilos que vuelven a la cuba NO son un ahorro que apuntar en ningún sitio: son chocolate que ya has pagado y que no vuelves a pagar. Lo que sí es una decisión es cuánto recortas: si la columna de residuo se dispara, el problema no es el precio del cacao, es el molde o la mano.
A39: Versión 1.0 · septiembre 2026 · aichef.pro/guia-chocolateria-obrador · info@aichef.pro

Sheet Coste Hora y Mano de Obra
A1: Coste Hora y Mano de Obra
A2: AI Chef Pro · aichef.pro — Cómo Montar una Chocolatería
A3: La unidad de costeo es la TANDA: piezas por molde por moldes por tanda. Los minutos se reparten entre las piezas que SALEN BIEN, no entre las que entran.
A6: Id | B6: Referencia | C6: Piezas por molde | D6: Moldes por tanda | E6: Piezas por tanda | F6: Minutos de la tanda | G6: Piezas buenas por tanda | H6: Minutos por pieza buena | I6: Coste de mano de obra de la tanda o el montaje (EUR) | J6: Coste de mano de obra de las piezas de dentro (EUR) | K6: COSTE DE MANO DE OBRA POR PIEZA (EUR) | L6: Coste de materia con merma (EUR) | M6: COSTE TOTAL POR PIEZA (EUR) | N6: PVP con IVA (EUR) | O6: Tipo de IVA | P6: PVP sin IVA (EUR) | Q6: Food cost | R6: Margen (EUR) | S6: Margen sobre PVP | T6: PVP sin IVA que pide tu regla de margen (EUR) | U6: PVP con IVA que pide tu regla de margen (EUR) | V6: Nota
A7: BC1 | B7: Bombón de ganache de chocolate negro 70 % | C7: 24 | D7: 6 | E7: =C7*D7 -> 144 | F7: 155 | G7: =IFERROR(E7*(1-'Merma de Templado y Recortes'!E7),"") -> 139.68 | H7: =IFERROR(F7/G7,"") -> 1.1096793 | I7: =IFERROR(H7/60*'Parámetros'!$B$15,"") -> 0.34199684 | J7: 0 | K7: =IFERROR(I7+J7,"") -> 0.34199684 | L7: ='Escandallo por Molde y Tanda'!O70 -> 0.22433612 | M7: =IFERROR(K7+L7,"") -> 0.56633297 | N7: 2 | O7: ='Parámetros'!$B$18 -> 0.1 | P7: =IFERROR(N7/(1+O7),"") -> 1.8181818 | Q7: =IFERROR(L7/P7,"") -> 0.12338487 | R7: =IFERROR(P7-M7,"") -> 1.2518489 | S7: =IFERROR(R7/P7,"") -> 0.68851687 | T7: =IFERROR(L7/'Parámetros'!$B$22,"") -> 0.74778708 | U7: =IFERROR(T7*(1+O7),"") -> 0.82256579 | V7: Cero real, no «sin dato»: esta referencia no lleva piezas terminadas dentro.
A8: BC2 | B8: Bombón de ganache de leche y vainilla | C8: 24 | D8: 6 | E8: =C8*D8 -> 144 | F8: 155 | G8: =IFERROR(E8*(1-'Merma de Templado y Recortes'!E8),"") -> 139.68 | H8: =IFERROR(F8/G8,"") -> 1.1096793 | I8: =IFERROR(H8/60*'Parámetros'!$B$15,"") -> 0.34199684 | J8: 0 | K8: =IFERROR(I8+J8,"") -> 0.34199684 | L8: ='Escandallo por Molde y Tanda'!O71 -> 0.19658144 | M8: =IFERROR(K8+L8,"") -> 0.53857829 | N8: 1.95 | O8: ='Parámetros'!$B$18 -> 0.1 | P8: =IFERROR(N8/(1+O8),"") -> 1.7727273 | Q8: =IFERROR(L8/P8,"") -> 0.1108921 | R8: =IFERROR(P8-M8,"") -> 1.234149 | S8: =IFERROR(R8/P8,"") -> 0.69618661 | T8: =IFERROR(L8/'Parámetros'!$B$22,"") -> 0.65527148 | U8: =IFERROR(T8*(1+O8),"") -> 0.72079863 | V8: Cero real, no «sin dato»: esta referencia no lleva piezas terminadas dentro.
A9: BC3 | B9: Bombón de praliné de avellana | C9: 24 | D9: 6 | E9: =C9*D9 -> 144 | F9: 140 | G9: =IFERROR(E9*(1-'Merma de Templado y Recortes'!E9),"") -> 141.12 | H9: =IFERROR(F9/G9,"") -> 0.99206349 | I9: =IFERROR(H9/60*'Parámetros'!$B$15,"") -> 0.30574833 | J9: 0 | K9: =IFERROR(I9+J9,"") -> 0.30574833 | L9: ='Escandallo por Molde y Tanda'!O72 -> 0.21780408 | M9: =IFERROR(K9+L9,"") -> 0.52355241 | N9: 2.1 | O9: ='Parámetros'!$B$18 -> 0.1 | P9: =IFERROR(N9/(1+O9),"") -> 1.9090909 | Q9: =IFERROR(L9/P9,"") -> 0.11408785 | R9: =IFERROR(P9-M9,"") -> 1.3855385 | S9: =IFERROR(R9/P9,"") -> 0.72575826 | T9: =IFERROR(L9/'Parámetros'!$B$22,"") -> 0.72601361 | U9: =IFERROR(T9*(1+O9),"") -> 0.79861497 | V9: Cero real, no «sin dato»: esta referencia no lleva piezas terminadas dentro.
