Workbook

Sheet Instrucciones
A1: Checklist de equipamiento y proveedores de cacao
A2: AI Chef Pro · aichef.pro — Cómo Montar una Chocolatería
A3: Para qué sirve: saber qué compras, a quién, a qué precio real, con qué plazo, con qué papeles — y a quién le vendes.
A5: Instrucciones de uso
A6: 1. Hoja «Equipamiento»: las diecisiete líneas de la dotación, con su precio de referencia y SU BASE FISCAL. Marca el estado, escribe el precio real que negocies (siempre SIN IVA), el proveedor y el plazo que te comprometan por escrito. La hoja te dice cuánto te desvías de la referencia, qué línea marca el plazo crítico y si llegas a la apertura.
A7: 2. Hoja «Variante del Formato»: si te planteas bean-to-bar o chocolatería de taza y churros. El bean-to-bar va SIN CIFRAS DE MAQUINARIA a propósito -no existe precio público verificado-: lo que hay es la lista de la compra y las cinco preguntas que hay que hacerle al fabricante, con casilla para apuntar quién te ha contestado.
A8: 3. Hoja «Proveedores y EUDR»: los seis proveedores publicados —cinco con URL comprobada el 12-09-2026 y uno, SelfPackaging, pendiente—, y el árbol que decide qué papeles le tocan a cada uno. Pregúntale a cada proveedor si es operador, operador posterior o comerciante: el número de referencia de su declaración de diligencia debida SÓLO se le pide al primero. Y en las dos últimas columnas, los boletines de cadmio y de HAP.
A9: 4. Hoja «Clientes a los que Suministras»: la otra mitad del mismo artículo, la que casi nadie conoce. Si vendes a hostelería, a empresas o a otra tienda, tienes que registrar a quién le has vendido qué, y conservar ese registro cinco años. La hoja calcula la fecha hasta la que hay que guardarlo.
A10: 5. Hoja «Contador»: el avance de la compra en una pantalla, con el presupuesto, lo que llevas gastado y cuántos papeles te faltan.
A12: Celdas verdes = campos editables
A14: Lo que conviene saber antes de empezar
A15: LA COLUMNA QUE NO TRAE NINGÚN CHECKLIST DEL MERCADO ES «¿LLEVA IVA?». Seis de las diecisiete líneas vienen de fichas de distribuidor que NO declaran su base fiscal: aquí se tratan como base imponible y se marcan como «no declarada», que es lo honesto. Si mezclas precios con IVA y sin IVA en la misma columna, tu inversión sale un 21 % desviada y no lo ves hasta que llega la primera factura.
... A22: Qué hace este libro y qué hace otro (para no teclear dos veces)
A23: Producto o libro | B23: Qué aporta | C23: Qué NO hace este libro
A24: kit-tareas-chocolateria (12 €) | B24: Las curvas de templado, las fichas de moldeado y el calendario anual de campañas, ya construidos. | C24: Este libro decide el obrador que vas a COMPRAR; el kit organiza el que ya tienes montado. Ninguna de sus once plantillas sustituye a esta hoja.
A25: calculadora-capex-chocolateria.xlsx (libro 2 de esta guía) | B25: Los euros de la apertura ordenados en nueve bloques, con su IVA soportado y su calendario de tesorería. | C25: Aquí se anota lo que de verdad pagas, línea a línea, y se compara con lo que aquel libro presupuestó. La comparación viaja por celda verde, nunca por fórmula entre ficheros.
A26: checklist-legal-licencias-y-cacao.xlsx (libro 8 de esta guía) | B26: El expediente legal, el árbol del EUDR completo y el cronograma de apertura con su ruta crítica. | C26: Aquí sólo se resuelve el papel EUDR de cada PROVEEDOR y el registro de tus CLIENTES. Tu propio papel en la cadena lo decide el libro 8.
A27: sensibilidad-al-precio-del-cacao.xlsx (libro 3 de esta guía) | B27: El precio de la cobertura y qué pasa cuando el cacao sube. | C27: Este libro compra MÁQUINAS, no materia prima. El pedido mínimo de cada proveedor sí está aquí, porque es dinero parado en el almacén.
A29: Cada cuánto se usa este libro
A30: Cadencia: la hoja «Equipamiento», UNA VEZ A LA SEMANA desde que pides el primer presupuesto hasta que se instala la última máquina. La de proveedores, cada vez que des de alta a uno nuevo, y entera una vez al año para refrescar los papeles del EUDR. La de clientes, CADA VEZ QUE SIRVAS A UNO NUEVO: es un registro, no un listado comercial, y se conserva cinco años.
A32: Frontera con el Kit de Tareas Chocolatería (12 €): si ya lo tienes, sus plantillas organizan el obrador montado. Este libro es el de la COMPRA, y no repite ninguna de ellas.
A34: Para editar la estructura o una celda que no esté en verde: Revisar > Desproteger hoja (no tiene contraseña).
A36: Diseñado por John Guerrero — chef y consultor gastronómico desde 2010, en cocina desde los 17 años.
A37: Versión 1.0 · septiembre 2026 · aichef.pro/guia-chocolateria-obrador · info@aichef.pro

Sheet Equipamiento
A1: Equipamiento, Línea a Línea
A2: AI Chef Pro · aichef.pro — Cómo Montar una Chocolatería
A3: Diecisiete líneas. Los precios con id `CHS-*` salen de fichas de distribuidor leídas el 12-09-2026; el resto son supuestos declarados. Cada uno con SU base fiscal: mezclarlas desvía la inversión un 21 %.
A5: Parámetros de esta hoja
A6: Parámetro | C6: Valor | D6: Nota
A7: Tipo de IVA general (%) | C7: 0.21 | D7: La maquinaria, el mobiliario y el packaging van al tipo general: no hay tipo reducido para el equipamiento de un obrador. Cámbialo aquí y se recalcula toda la columna K.
A8: Horquilla del precio de referencia (±%) | C8: 0.25 | D8: SUPUESTO. Con cuánta amplitud quieres ver el mínimo y el máximo alrededor del precio de referencia. El 25 % es la banda entre lo que pide una ficha web y lo que se cierra con tres presupuestos. Las líneas que se publican COMO RANGO no la usan: llevan el suyo.
A9: Umbral de desviación admitida (%) | C9: 0.1 | D9: SUPUESTO. Por encima de esta desviación contra el CAPEX del libro 2, la fila de CUADRE se pone en rojo: o has comprado de más, o el plan financiero está calculado con una inversión que ya no es la tuya.
A10: Semanas que faltan hasta la apertura prevista | C10: 36 | D10: SUPUESTO. Cuenta desde hoy hasta la fecha que tienes en la cabeza. El cronograma completo, con la ruta crítica del papeleo y de la obra, lo calcula la hoja «Cronograma y Ruta Crítica» del libro 8.
A11: Margen de seguridad entre la entrega y la apertura (semanas) | C11: 3 | D11: SUPUESTO. Lo que necesitas entre que llega la máquina y que abres: montaje, conexión, puesta en marcha y las pruebas de templado. Con menos de dos semanas, el primer ajuste de curva te pilla con la tienda abierta.
A13: La dotación completa, línea a línea
A14: Estado | B14: Nº | C14: Partida | D14: Marca | E14: Modelo | F14: Categoría | G14: Bloque de CAPEX | H14: Prioridad | I14: Precio de referencia (€) | J14: ¿Lleva IVA? | K14: Tipo de IVA (%) | L14: Precio de referencia SIN IVA (€) | M14: Mínimo (€) | N14: Máximo (€) | O14: Precio real negociado (€, sin IVA) | P14: Desviación sobre la referencia (%) | Q14: Proveedor | R14: Plazo de entrega (semanas) | S14: Margen hasta la apertura (semanas) | T14: Aux · mínimo publicado del rango | U14: Aux · máximo publicado del rango | V14: Aux · plazo de las líneas críticas | W14: Aux · ¿el plazo se pasa? (1 = sí) | X14: Aux · real del bloque de templado | Y14: Cómo se publica el precio | Z14: Fuente del precio | AA14: Nota | AB14: Precio tal como se publica
A15: Pendiente | B15: 1 | C15: Atemperadora continua de sobremesa, 12 kg (55 kg/h) | D15: Selmi | E15: One | F15: Templado | G15: Equipo de templado y moldeado | H15: Crítico | I15: 8500 | J15: no declarada | K15: =$C$7 -> 0.21 | L15: =IFERROR(IF($I15="","",IF($J15=$E$62,$I15/(1+$K15),$I15)),"") -> 8500 | M15: =IF($L15="","",IF($T15>0,$T15,$L15*(1-$C$8))) -> 6375 | N15: =IF($L15="","",IF($U15>0,$U15,$L15*(1+$C$8))) -> 10625 | O15: 8500 | P15: =IFERROR(IF(OR($O15="",$L15=""),"",$O15/$L15-1),"") -> 0 | Q15: Selmi | R15: 10 | S15: =IFERROR(IF(OR($R15="",$C$10="",$C$11=""),"",$C$10-$R15-$C$11),"") -> 23 | T15: 0 | U15: 0 | V15: =IF($H15=$C$61,$R15,"") -> 10 | W15: =IF($S15="","",IF($S15<0,1,0)) -> 0 | X15: =IF(AND($G15=$G$15,$H15=$C$61),$O15,"") -> 8500 | Y15: Precio cerrado | Z15: CHS-41a | AA15: El corazón del obrador y la decisión 2 del bonus 2. Base de IVA NO declarada: la ficha trae el indicio «/Neto» en la línea de embalaje, que no es confirmable. La escalera completa va de esta a la Cento EX de 100 kg (`CHS-41g`), y la elección la decide los kg/semana que salga en la hoja de capacidad del libro 1. | AB15: 8.500 €
A16: Pendiente | B16: 2 | C16: Embalaje, transporte y puesta en marcha de la atemperadora | D16: Selmi | E16: servicio | F16: Templado | G16: Equipo de templado y moldeado | H16: Crítico | I16: 1045 | J16: no declarada | K16: =$C$7 -> 0.21 | L16: =IFERROR(IF($I16="","",IF($J16=$E$62,$I16/(1+$K16),$I16)),"") -> 1045 | M16: =IF($L16="","",IF($T16>0,$T16,$L16*(1-$C$8))) -> 783.75 | N16: =IF($L16="","",IF($U16>0,$U16,$L16*(1+$C$8))) -> 1306.25 | O16: 1045 | P16: =IFERROR(IF(OR($O16="",$L16=""),"",$O16/$L16-1),"") -> 0 | Q16: Selmi | R16: 10 | S16: =IFERROR(IF(OR($R16="",$C$10="",$C$11=""),"",$C$10-$R16-$C$11),"") -> 23 | T16: 0 | U16: 0 | V16: =IF($H16=$C$61,$R16,"") -> 10 | W16: =IF($S16="","",IF($S16<0,1,0)) -> 0 | X16: =IF(AND($G16=$G$15,$H16=$C$61),$O16,"") -> 1045 | Y16: Precio cerrado | Z16: CHS-41a | AA16: La línea que nadie presupuesta: es el 12 % del precio de la máquina. La ficha la marca «Neto», que es un INDICIO de base sin IVA, no una declaración: por eso va como «no declarada». | AB16: 1.045 €
A17: Pendiente | B17: 3 | C17: Enrobadora de banda, 200 mm | D17: Selmi | E17: R200 Legend | F17: Moldeado | G17: Equipo de templado y moldeado | H17: Crítico | I17: 6800 | J17: no declarada | K17: =$C$7 -> 0.21 | L17: =IFERROR(IF($I17="","",IF($J17=$E$62,$I17/(1+$K17),$I17)),"") -> 6800 | M17: =IF($L17="","",IF($T17>0,$T17,$L17*(1-$C$8))) -> 5100 | N17: =IF($L17="","",IF($U17>0,$U17,$L17*(1+$C$8))) -> 8500 | O17: 6800 | P17: =IFERROR(IF(OR($O17="",$L17=""),"",$O17/$L17-1),"") -> 0 | Q17: Selmi | R17: 10 | S17: =IFERROR(IF(OR($R17="",$C$10="",$C$11=""),"",$C$10-$R17-$C$11),"") -> 23 | T17: 0 | U17: 0 | V17: =IF($H17=$C$61,$R17,"") -> 10 | W17: =IF($S17="","",IF($S17<0,1,0)) -> 0 | X17: =IF(AND($G17=$G$15,$H17=$C$61),$O17,"") -> 6800 | Y17: Precio cerrado | Z17: CHS-42a | AA17: Base de IVA NO declarada por la ficha del distribuidor. | AB17: 6.800 €
A18: Pendiente | B18: 4 | C18: Placa dosificadora de rellenos | D18: Selmi | E18: placa dosificadora | F18: Moldeado | G18: Equipo de templado y moldeado | H18: Crítico | I18: 1495 | J18: no declarada | K18: =$C$7 -> 0.21 | L18: =IFERROR(IF($I18="","",IF($J18=$E$62,$I18/(1+$K18),$I18)),"") -> 1495 | M18: =IF($L18="","",IF($T18>0,$T18,$L18*(1-$C$8))) -> 1121.25 | N18: =IF($L18="","",IF($U18>0,$U18,$L18*(1+$C$8))) -> 1868.75 | O18: 1495 | P18: =IFERROR(IF(OR($O18="",$L18=""),"",$O18/$L18-1),"") -> 0 | Q18: Selmi | R18: 8 | S18: =IFERROR(IF(OR($R18="",$C$10="",$C$11=""),"",$C$10-$R18-$C$11),"") -> 25 | T18: 0 | U18: 0 | V18: =IF($H18=$C$61,$R18,"") -> 8 | W18: =IF($S18="","",IF($S18<0,1,0)) -> 0 | X18: =IF(AND($G18=$G$15,$H18=$C$61),$O18,"") -> 1495 | Y18: Precio cerrado | Z18: CHS-42i | AA18: Base de IVA NO declarada por la ficha del distribuidor. | AB18: 1.495 €
A19: Pendiente | B19: 5 | C19: Temperador de baño maría digital, 22 L | D19: Utilcentre | E19: baño maría digital 22 L | F19: Templado | G19: Equipo de templado y moldeado | H19: Crítico | I19: 2650 | J19: no declarada | K19: =$C$7 -> 0.21 | L19: =IFERROR(IF($I19="","",IF($J19=$E$62,$I19/(1+$K19),$I19)),"") -> 2650 | M19: =IF($L19="","",IF($T19>0,$T19,$L19*(1-$C$8))) -> 1987.5 | N19: =IF($L19="","",IF($U19>0,$U19,$L19*(1+$C$8))) -> 3312.5 | O19: 2650 | P19: =IFERROR(IF(OR($O19="",$L19=""),"",$O19/$L19-1),"") -> 0 | Q19: Utilcentre | R19: 6 | S19: =IFERROR(IF(OR($R19="",$C$10="",$C$11=""),"",$C$10-$R19-$C$11),"") -> 27 | T19: 0 | U19: 0 | V19: =IF($H19=$C$61,$R19,"") -> 6 | W19: =IF($S19="","",IF($S19<0,1,0)) -> 0 | X19: =IF(AND($G19=$G$15,$H19=$C$61),$O19,"") -> 2650 | Y19: Precio cerrado | Z19: CHS-41j | AA19: Segunda línea de templado: sin ella no se trabajan dos coberturas a la vez. | AB19: 2.650 €
A20: Pendiente | B20: 6 | C20: Mantenedor de 1 cubeta, digital | D20: Utilcentre | E20: mantenedor 1 cubeta digital | F20: Templado | G20: Equipo de templado y moldeado | H20: Crítico | I20: 570 | J20: no declarada | K20: =$C$7 -> 0.21 | L20: =IFERROR(IF($I20="","",IF($J20=$E$62,$I20/(1+$K20),$I20)),"") -> 570 | M20: =IF($L20="","",IF($T20>0,$T20,$L20*(1-$C$8))) -> 427.5 | N20: =IF($L20="","",IF($U20>0,$U20,$L20*(1+$C$8))) -> 712.5 | O20: 570 | P20: =IFERROR(IF(OR($O20="",$L20=""),"",$O20/$L20-1),"") -> 0 | Q20: Utilcentre | R20: 5 | S20: =IFERROR(IF(OR($R20="",$C$10="",$C$11=""),"",$C$10-$R20-$C$11),"") -> 28 | T20: 0 | U20: 0 | V20: =IF($H20=$C$61,$R20,"") -> 5 | W20: =IF($S20="","",IF($S20<0,1,0)) -> 0 | X20: =IF(AND($G20=$G$15,$H20=$C$61),$O20,"") -> 570 | Y20: DESDE: suelo comercial, presupuestar | Z20: CHS-41i | AA20: ES UN «DESDE», NO UN PRECIO (D23b): la ficha publica «desde 570,00 euros» y eso es un SUELO comercial, no el precio de la unidad que vas a comprar. Se presupuesta. Publicarlo como precio cerrado esta prohibido, y el techo del escenario B solo puede subir por su culpa. | AB20: desde 570 € (suelo, presupuestar)
A21: Pendiente | B21: 7 | C21: Atemperadora de arranque, 4,5 L (unos 3 kg) | D21: Pavoni | E21: MINITEMPER | F21: Templado | G21: Equipo de templado y moldeado | H21: Opcional | I21: 1960 | J21: no declarada | K21: =$C$7 -> 0.21 | L21: =IFERROR(IF($I21="","",IF($J21=$E$62,$I21/(1+$K21),$I21)),"") -> 1960 | M21: =IF($L21="","",IF($T21>0,$T21,$L21*(1-$C$8))) -> 1470 | N21: =IF($L21="","",IF($U21>0,$U21,$L21*(1+$C$8))) -> 2450 | O21: 1960 | P21: =IFERROR(IF(OR($O21="",$L21=""),"",$O21/$L21-1),"") -> 0 | Q21: Pavoni | R21: 4 | S21: =IFERROR(IF(OR($R21="",$C$10="",$C$11=""),"",$C$10-$R21-$C$11),"") -> 29 | T21: 0 | U21: 0 | V21: =IF($H21=$C$61,$R21,"") | W21: =IF($S21="","",IF($S21<0,1,0)) -> 0 | X21: =IF(AND($G21=$G$15,$H21=$C$61),$O21,"") | Y21: Precio cerrado | Z21: CHS-41h | AA21: NO esta en la dotación de La Almendra: es la máquina del ESCENARIO B, el arranque mínimo, y aparece para que el lector vea la escalera. Cubeta adicional, 165,30 euros (`CHS-41h`). | AB21: 1.960 €
A22: Pendiente | B22: 8 | C22: Cubeta adicional para la atemperadora de arranque | D22: Pavoni | E22: cubeta MINITEMPER | F22: Templado | G22: Equipo de templado y moldeado | H22: Opcional | I22: 165.3 | J22: no declarada | K22: =$C$7 -> 0.21 | L22: =IFERROR(IF($I22="","",IF($J22=$E$62,$I22/(1+$K22),$I22)),"") -> 165.3 | M22: =IF($L22="","",IF($T22>0,$T22,$L22*(1-$C$8))) -> 123.975 | N22: =IF($L22="","",IF($U22>0,$U22,$L22*(1+$C$8))) -> 206.625 | O22: 165.3 | P22: =IFERROR(IF(OR($O22="",$L22=""),"",$O22/$L22-1),"") -> 0 | Q22: Pavoni | R22: 4 | S22: =IFERROR(IF(OR($R22="",$C$10="",$C$11=""),"",$C$10-$R22-$C$11),"") -> 29 | T22: 0 | U22: 0 | V22: =IF($H22=$C$61,$R22,"") | W22: =IF($S22="","",IF($S22<0,1,0)) -> 0 | X22: =IF(AND($G22=$G$15,$H22=$C$61),$O22,"") | Y22: Precio cerrado | Z22: CHS-41h | AA22: Accesorio del escenario B. | AB22: 165,30 €
A23: Pendiente | B23: 9 | C23: Vitrina refrigerada específica para chocolate | D23: Docriluc | E23: WB-6-6-R | F23: Frío | G23: Frío | H23: Crítico | I23: 2684.99 | J23: sin IVA | K23: =$C$7 -> 0.21 | L23: =IFERROR(IF($I23="","",IF($J23=$E$62,$I23/(1+$K23),$I23)),"") -> 2684.99 | M23: =IF($L23="","",IF($T23>0,$T23,$L23*(1-$C$8))) -> 2013.7425 | N23: =IF($L23="","",IF($U23>0,$U23,$L23*(1+$C$8))) -> 3356.2375 | O23: 2684.99 | P23: =IFERROR(IF(OR($O23="",$L23=""),"",$O23/$L23-1),"") -> 0 | Q23: Docriluc | R23: 7 | S23: =IFERROR(IF(OR($R23="",$C$10="",$C$11=""),"",$C$10-$R23-$C$11),"") -> 26 | T23: 0 | U23: 0 | V23: =IF($H23=$C$61,$R23,"") -> 7 | W23: =IF($S23="","",IF($S23<0,1,0)) -> 0 | X23: =IF(AND($G23=$G$15,$H23=$C$61),$O23,"") | Y23: Precio cerrado | Z23: CHS-43 | AA23: 600x730x1380 mm. RANGO DE TRABAJO DEL EQUIPO: +14 a +17 °C, con base SIN IVA declarada literalmente por la ficha. NO son los +2/+4 °C de una vitrina de pastelería, que arruina el bombón por condensación, sugar bloom y perdida de brillo. El OBJETIVO OPERATIVO es otra cosa y lo pone el kit: 16-18 °C y menos del 55 % de humedad. El semáforo del libro 5 solo avisa por encima de 20 °C, y queda PROHIBIDO uno que ponga en rojo los 16-18 del propio kit. Precio de oferta (antes 3.487,00 euros): esta FECHADO el 12-09-2026 y puede caducar. | AB23: 2.684,99 €
A24: Pendiente | B24: 10 | C24: Cámara climatizada de chocolate, unos 6 m² | F24: Frío | G24: Frío | H24: Crítico | I24: 6400 | J24: sin IVA | K24: =$C$7 -> 0.21 | L24: =IFERROR(IF($I24="","",IF($J24=$E$62,$I24/(1+$K24),$I24)),"") -> 6400 | M24: =IF($L24="","",IF($T24>0,$T24,$L24*(1-$C$8))) -> 4800 | N24: =IF($L24="","",IF($U24>0,$U24,$L24*(1+$C$8))) -> 8000 | O24: 6400 | P24: =IFERROR(IF(OR($O24="",$L24=""),"",$O24/$L24-1),"") -> 0 | Q24: Pendiente: pide tres presupuestos | R24: 8 | S24: =IFERROR(IF(OR($R24="",$C$10="",$C$11=""),"",$C$10-$R24-$C$11),"") -> 25 | T24: 0 | U24: 0 | V24: =IF($H24=$C$61,$R24,"") -> 8 | W24: =IF($S24="","",IF($S24<0,1,0)) -> 0 | X24: =IF(AND($G24=$G$15,$H24=$C$61),$O24,"") | Y24: SUPUESTO declarado | Z24: supuesto | AA24: SUPUESTO declarado: ninguna fuente del research publica el precio de una cámara de chocolate. Celda verde con valor por defecto. No es una nevera: trabaja a 15-18 °C y 50-60 % de humedad, y ese control de HUMEDAD es lo que la encarece frente a una cámara de pastelería. | AB24: 6.400 €
A25: Pendiente | B25: 11 | C25: Nevera de rellenos y ganaches | F25: Frío | G25: Frío | H25: Crítico | I25: 1450 | J25: sin IVA | K25: =$C$7 -> 0.21 | L25: =IFERROR(IF($I25="","",IF($J25=$E$62,$I25/(1+$K25),$I25)),"") -> 1450 | M25: =IF($L25="","",IF($T25>0,$T25,$L25*(1-$C$8))) -> 1087.5 | N25: =IF($L25="","",IF($U25>0,$U25,$L25*(1+$C$8))) -> 1812.5 | O25: 1450 | P25: =IFERROR(IF(OR($O25="",$L25=""),"",$O25/$L25-1),"") -> 0 | Q25: Pendiente: pide tres presupuestos | R25: 5 | S25: =IFERROR(IF(OR($R25="",$C$10="",$C$11=""),"",$C$10-$R25-$C$11),"") -> 28 | T25: 0 | U25: 0 | V25: =IF($H25=$C$61,$R25,"") -> 5 | W25: =IF($S25="","",IF($S25<0,1,0)) -> 0 | X25: =IF(AND($G25=$G$15,$H25=$C$61),$O25,"") | Y25: SUPUESTO declarado | Z25: supuesto | AA25: SUPUESTO. Es la del RELLENO, a 0-4 °C, no la del bombón acabado. Confundirlas es el error de método que la SPEC persigue. | AB25: 1.450 €
A26: Pendiente | B26: 12 | C26: Moldes de policarbonato para bombonería (24 unidades) | D26: Chocolate World | E26: varios (CF0246, CW12064, CW1000L07) | F26: Moldes | G26: Packaging y moldes | H26: Crítico | I26: 804.36 | J26: no declarada | K26: =$C$7 -> 0.21 | L26: =IFERROR(IF($I26="","",IF($J26=$E$62,$I26/(1+$K26),$I26)),"") -> 804.36 | M26: =IF($L26="","",IF($T26>0,$T26,$L26*(1-$C$8))) -> 580.8 | N26: =IF($L26="","",IF($U26>0,$U26,$L26*(1+$C$8))) -> 1027.92 | O26: 804.36 | P26: =IFERROR(IF(OR($O26="",$L26=""),"",$O26/$L26-1),"") -> 0 | Q26: Chocolate World | R26: 4 | S26: =IFERROR(IF(OR($R26="",$C$10="",$C$11=""),"",$C$10-$R26-$C$11),"") -> 29 | T26: 580.8 | U26: 1027.92 | V26: =IF($H26=$C$61,$R26,"") -> 4 | W26: =IF($S26="","",IF($S26<0,1,0)) -> 0 | X26: =IF(AND($G26=$G$15,$H26=$C$61),$O26,"") | Y26: RANGO publicado (no es un precio) | Z26: CHS-45a | AA26: SE PUBLICA COMO RANGO (D23a). El único dato medido es 24,20-42,83 euros/ud (`CHS-45a`): 24 moldes valen entre 580,80 y 1.027,92 euros. El valor por defecto (804,36) es el punto medio del rango, y es SUPUESTO. Escribir una multiplicación con un precio unitario elegido a ojo esta prohibido. Y los moldes de policarbonato NO pagan el impuesto al plastico: no están sujetos por el art. 73.d) de la Ley 7/2022 (`CHN-62c`), porque no se entregan junto con la mercancía. | AB26: 580,80 - 1.027,92 € (RANGO, no es un precio)
A27: Pendiente | B27: 13 | C27: Primer pedido de packaging: cajas, estuches, cintas y etiquetas | F27: Packaging | G27: Packaging y moldes | H27: Crítico | I27: 2200 | J27: sin IVA | K27: =$C$7 -> 0.21 | L27: =IFERROR(IF($I27="","",IF($J27=$E$62,$I27/(1+$K27),$I27)),"") -> 2200 | M27: =IF($L27="","",IF($T27>0,$T27,$L27*(1-$C$8))) -> 1650 | N27: =IF($L27="","",IF($U27>0,$U27,$L27*(1+$C$8))) -> 2750 | O27: 2200 | P27: =IFERROR(IF(OR($O27="",$L27=""),"",$O27/$L27-1),"") -> 0 | Q27: Pendiente: pide tres presupuestos | R27: 5 | S27: =IFERROR(IF(OR($R27="",$C$10="",$C$11=""),"",$C$10-$R27-$C$11),"") -> 28 | T27: 0 | U27: 0 | V27: =IF($H27=$C$61,$R27,"") -> 5 | W27: =IF($S27="","",IF($S27<0,1,0)) -> 0 | X27: =IF(AND($G27=$G$15,$H27=$C$61),$O27,"") | Y27: SUPUESTO declarado | Z27: supuesto | AA27: SUPUESTO: la web del proveedor de packaging verificado devolvió HTTP 403 y no publica precio (`CHS-54`). En bombonería la caja ES el producto en campana, y el personalizado obliga a pedidos grandes: es dinero parado en el almacén. Si lo compras fuera de España, mira el contador de plastico del libro 2 (`PLASTICO`). | AB27: 2.200 €
A28: Pendiente | B28: 14 | C28: Mobiliario de tienda, mostrador y estantería | F28: Tienda | G28: Mobiliario y tienda | H28: Crítico | I28: 6900 | J28: sin IVA | K28: =$C$7 -> 0.21 | L28: =IFERROR(IF($I28="","",IF($J28=$E$62,$I28/(1+$K28),$I28)),"") -> 6900 | M28: =IF($L28="","",IF($T28>0,$T28,$L28*(1-$C$8))) -> 5175 | N28: =IF($L28="","",IF($U28>0,$U28,$L28*(1+$C$8))) -> 8625 | O28: 6900 | P28: =IFERROR(IF(OR($O28="",$L28=""),"",$O28/$L28-1),"") -> 0 | Q28: Pendiente: pide tres presupuestos | R28: 6 | S28: =IFERROR(IF(OR($R28="",$C$10="",$C$11=""),"",$C$10-$R28-$C$11),"") -> 27 | T28: 0 | U28: 0 | V28: =IF($H28=$C$61,$R28,"") -> 6 | W28: =IF($S28="","",IF($S28<0,1,0)) -> 0 | X28: =IF(AND($G28=$G$15,$H28=$C$61),$O28,"") | Y28: SUPUESTO declarado | Z28: supuesto | AA28: SUPUESTO declarado. Celda verde con valor por defecto. | AB28: 6.900 €
A29: Pendiente | B29: 15 | C29: TPV, ordenador, impresora de etiquetas y rótulo | F29: Tienda | G29: TPV, informática y rótulo | H29: Crítico | I29: 3200 | J29: sin IVA | K29: =$C$7 -> 0.21 | L29: =IFERROR(IF($I29="","",IF($J29=$E$62,$I29/(1+$K29),$I29)),"") -> 3200 | M29: =IF($L29="","",IF($T29>0,$T29,$L29*(1-$C$8))) -> 2400 | N29: =IF($L29="","",IF($U29>0,$U29,$L29*(1+$C$8))) -> 4000 | O29: 3200 | P29: =IFERROR(IF(OR($O29="",$L29=""),"",$O29/$L29-1),"") -> 0 | Q29: Pendiente: pide tres presupuestos | R29: 4 | S29: =IFERROR(IF(OR($R29="",$C$10="",$C$11=""),"",$C$10-$R29-$C$11),"") -> 29 | T29: 0 | U29: 0 | V29: =IF($H29=$C$61,$R29,"") -> 4 | W29: =IF($S29="","",IF($S29<0,1,0)) -> 0 | X29: =IF(AND($G29=$G$15,$H29=$C$61),$O29,"") | Y29: SUPUESTO declarado | Z29: supuesto | AA29: SUPUESTO. La impresora de etiquetas deja de ser opcional en cuanto una sola referencia sale envasada con etiqueta (D47). Y Verifactu no es 2026, es 2027: 1-ene para sociedades y 1-jul para autónomos (`CHN-75`). | AB29: 3.200 €
A30: Pendiente | B30: 16 | C30: Climatización del obrador con deshumidificación | F30: Clima | G30: Climatización y deshumidificación | H30: Crítico | I30: 7600 | J30: sin IVA | K30: =$C$7 -> 0.21 | L30: =IFERROR(IF($I30="","",IF($J30=$E$62,$I30/(1+$K30),$I30)),"") -> 7600 | M30: =IF($L30="","",IF($T30>0,$T30,$L30*(1-$C$8))) -> 5700 | N30: =IF($L30="","",IF($U30>0,$U30,$L30*(1+$C$8))) -> 9500 | O30: 7600 | P30: =IFERROR(IF(OR($O30="",$L30=""),"",$O30/$L30-1),"") -> 0 | Q30: Pendiente: pide tres presupuestos | R30: 9 | S30: =IFERROR(IF(OR($R30="",$C$10="",$C$11=""),"",$C$10-$R30-$C$11),"") -> 24 | T30: 0 | U30: 0 | V30: =IF($H30=$C$61,$R30,"") -> 9 | W30: =IF($S30="","",IF($S30<0,1,0)) -> 0 | X30: =IF(AND($G30=$G$15,$H30=$C$61),$O30,"") | Y30: SUPUESTO declarado | Z30: supuesto | AA30: SUPUESTO declarado, y es la partida que nadie presupuesta. El libro 1 NO calcula carga térmica (D33): no hay un solo coeficiente con fuente ni de transmitancia, ni por m³, ni de aportes, ni de renovaciones. Lo que hace es (a) un semáforo de coherencia entre la temperatura objetivo, la exterior de agosto de TU ciudad y la potencia frigorífica que te OFREZCA EL INSTALADOR, y (b) una ficha de preguntas para el instalador. PROHIBIDO el climatizador evaporativo: añade humedad, que es justo lo contrario de lo que necesita un obrador de chocolate. | AB30: 7.600 €
A31: Pendiente | B31: 17 | C31: Chocolatera de 3 L para la variante de taza | D31: Ugolini | E31: Delice 3 | F31: Taza | G31: Mobiliario y tienda | H31: Opcional | I31: 527 | J31: sin IVA | K31: =$C$7 -> 0.21 | L31: =IFERROR(IF($I31="","",IF($J31=$E$62,$I31/(1+$K31),$I31)),"") -> 527 | M31: =IF($L31="","",IF($T31>0,$T31,$L31*(1-$C$8))) -> 395.25 | N31: =IF($L31="","",IF($U31>0,$U31,$L31*(1+$C$8))) -> 658.75 | O31: 527 | P31: =IFERROR(IF(OR($O31="",$L31=""),"",$O31/$L31-1),"") -> 0 | Q31: Ugolini | R31: 4 | S31: =IFERROR(IF(OR($R31="",$C$10="",$C$11=""),"",$C$10-$R31-$C$11),"") -> 29 | T31: 0 | U31: 0 | V31: =IF($H31=$C$61,$R31,"") | W31: =IF($S31="","",IF($S31<0,1,0)) -> 0 | X31: =IF(AND($G31=$G$15,$H31=$C$61),$O31,"") | Y31: Precio cerrado | Z31: CHS-46a | AA31: Base SIN IVA declarada literalmente por la ficha. Solo entra en el escenario de taza y churros, que es OTRO negocio (D1): la Ley 12/2012 los separa sola, porque su Anexo incluye el epígrafe 644.5 de bombones y caramelos y NO contiene ningún grupo de la agrupación 67, donde esta la chocolatería de taza (`CHN-49c`). | AB31: 527 €
A33: Resumen de la compra
A34: Líneas del checklist | I34: =COUNTIF($C$15:$C$31,"<>") -> 17 | K34: Las diecisiete líneas de la dotación tipo de una bombonería con obrador, opcionales incluidas.
A35: Total de referencia sin IVA, sólo líneas críticas (€) | I35: =SUMPRODUCT(--($H$15:$H$31=$C$61),$L$15:$L$31) -> 52299.35 | K35: Lo que cuesta lo que no puedes dejar de comprar, a precio de referencia y en base imponible.
A36: Total de referencia sin IVA, todas las líneas (€) | I36: =SUM($L$15:$L$31) -> 54951.65 | K36: Con la atemperadora de arranque, su cubeta y la chocolatera de la variante de taza dentro, que son opcionales según el formato.
A37: Total real negociado sin IVA, sólo líneas críticas (€) | I37: =SUMPRODUCT(--($H$15:$H$31=$C$61),$O$15:$O$31) -> 52299.35 | K37: Lo mismo con TUS precios: es el número que se lleva al libro 2.
A38: Total real negociado sin IVA, todas las líneas (€) | I38: =SUM($O$15:$O$31) -> 54951.65 | K38: La base imponible de toda tu compra de equipamiento.
A39: Lo que has ganado (o perdido) negociando (€) | I39: =IFERROR($I$38-$I$36,"") -> 0 | K39: Negativo = has comprado por debajo del precio de referencia. Es el único sitio del paquete donde se mide lo que vale pedir tres presupuestos.
A40: IVA soportado sobre el precio real (€) | I40: =SUMPRODUCT($O$15:$O$31,$K$15:$K$31) -> 11539.846 | K40: Se recupera vía declaraciones, pero hay que ADELANTARLO el día que pagas la máquina. La hoja «IVA y Tesorería» del libro 2 dice cuándo vuelve.
A41: Desembolso real con IVA (€) | I41: =IFERROR($I$38+$I$40,"") -> 66491.497 | K41: Lo que sale de la cuenta corriente.
A42: Líneas que sólo pueden publicarse COMO RANGO | I42: =COUNTIF($Y$15:$Y$31,"RANGO publicado (no es un precio)") -> 1 | K42: Los moldes de policarbonato: el dato medido es 24,20 a 42,83 euros por unidad, y elegir un punto dentro de ese rango sería inventarse un precio. Su mínimo y su máximo van en las columnas T y U y mandan sobre la horquilla.
A43: Líneas que son un «desde» y hay que presupuestar | I43: =COUNTIF($Y$15:$Y$31,"DESDE: suelo comercial, presupuestar") -> 1 | K43: El mantenedor se publica «desde 570,00 euros»: es un suelo comercial, no el precio de la unidad que vas a comprar. Su techo sólo puede subir.
...

Sheet Variante del Formato
A1: Variante del Formato: Bean-to-bar o Taza y Churros
A2: AI Chef Pro · aichef.pro — Cómo Montar una Chocolatería
A3: Dos caminos que NO son este producto y se deciden aquí. El bean-to-bar va SIN CIFRAS DE MAQUINARIA a propósito: no hay precio público verificado, y lo que se entrega es la lista de la compra y las preguntas que hay que hacer.
A5: Tu formato
A6: ¿Qué vas a montar? | C6: Bombonería (el caso del libro) | D6: El libro 2 calcula el CAPEX de cada variante. Aquí sólo se resuelve QUÉ hay que comprar y QUÉ hay que preguntar.
A7: Lo primero que cambia | C7: =IFERROR(IF($C$6=$A$45,"Si importas grano ERES OPERADOR a efectos del EUDR: diligencia debida completa y declaración presentada ANTES de introducir en el mercado",IF($C$6=$A$46,"La chocolatería de taza NO está en el Anexo de la Ley 12/2012: el amparo frente a la licencia previa de actividad NO te cubre","Bombonería: el epígrafe 644.5 SÍ está en ese Anexo, hasta 750 metros cuadrados")),"") -> Bombonería: el epígrafe 644.5 SÍ está en ese Anexo, hasta 750 metros cuadrados
A9: BEAN-TO-BAR: la lista de la compra, SIN precios (D2)
A10: Nº | B10: Equipo del tren bean-to-bar | C10: ¿Lo necesitas? | D10: ¿Tienes precio por escrito? | E10: Plazo prometido (semanas) | F10: Notas
A11: 1 | B11: Tostador de grano | C11: No | D11: No | E11: 0
A12: 2 | B12: Bandeja de enfriado | C12: No | D12: No | E12: 0
A13: 3 | B13: Descascarilladora | C13: No | D13: No | E13: 0
A14: 4 | B14: Winnower (aventadora) | C14: No | D14: No | E14: 0
A15: 5 | B15: Melanger o refinadora de piedra | C15: No | D15: No | E15: 0
A16: 6 | B16: Concha | C16: No | D16: No | E16: 0
A17: 7 | B17: Prensa de manteca (solo si separas manteca) | C17: No | D17: No | E17: 0
A18: 8 | B18: Tamizadora | C18: No | D18: No | E18: 0
A19: 9 | B19: Balanza de precisión para la formulación | C19: No | D19: No | E19: 0
B20: Equipos que dices necesitar | C20: =IFERROR(COUNTIF(C11:C19,"Sí"),"") -> 0 | D20: =IFERROR(COUNTIF(D11:D19,"Sí"),"") -> 0 | E20: =IFERROR(MAX(E11:E19),"") -> 0 | F20: Equipos que necesitas · con precio por escrito · plazo más largo prometido. Mientras las dos primeras cifras no coincidan, no tienes un presupuesto: tienes una intención.
A22: Las cinco preguntas que hay que hacerle al fabricante
A23: Nº | B23: Pregunta | C23: ¿Te la han contestado? | D23: Quién te contestó | E23: Fecha | F23: Por qué importa
A24: 1 | B24: Precio de la máquina puesta en España, con transporte, aduana y puesta en marcha desglosados: los catálogos existen y están verificados, pero los precios NO son publicos (venta a presupuesto o tienda fuera de la UE). | C24: No | D24: Pendiente | E24: 46277
A25: 2 | B25: Plazo de entrega real y quien hace el mantenimiento en España. | C25: No | D25: Pendiente | E25: 46277
A26: 3 | B26: Potencia eléctrica y si necesita trifasica. | C26: No | D26: Pendiente | E26: 46277
A27: 4 | B27: Ruido en dB a un metro: el tostador y el winnower son los dos equipos ruidosos de un obrador que por lo demás es silencioso. | C27: No | D27: Pendiente | E27: 46277
A28: 5 | B28: Rendimiento en kg de grano por hora y merma de cascarilla. | C28: No | D28: Pendiente | E28: 46277
B29: Preguntas contestadas POR ESCRITO | C29: =IFERROR(COUNTIF(C24:C28,"Sí"),"") -> 0
B30: VEREDICTO DEL BEAN-TO-BAR | C30: =IFERROR(IF($C$6<>$A$45,"No es tu variante: no hay nada que presupuestar",IF(AND($C$20>0,$D$20=$C$20,$C$29=5),"Ya puedes presupuestarlo: tienes precio y respuesta de todo lo que necesitas","Te faltan precios por escrito o respuestas: no cierres el CAPEX del bean-to-bar todavía")),"") -> No es tu variante: no hay nada que presupuestar
A32: TAZA Y CHURROS: lo único con precio verificado, y lo que no lo tiene
A33: Nº | B33: Equipo | C33: Precio (€, sin IVA) | D33: ¿Lo necesitas? | E33: Fuente | F33: Notas
A34: 1 | B34: Chocolatera Ugolini Delice 3 (3 L) | C34: 527 | D34: No | E34: CHS-46a | F34: Base sin IVA declarada por la ficha. Es la única línea de esta variante con precio público verificado.
A35: 2 | B35: Churrera | D35: No | E35: CHS-49 (sin verificar) | F35: SIN PRECIO: los precios de churrera, freidora y extracción no están verificados. Presupuéstalo, no lo estimes.
A36: 3 | B36: Freidora | D36: No | E36: CHS-49 (sin verificar) | F36: SIN PRECIO: los precios de churrera, freidora y extracción no están verificados. Presupuéstalo, no lo estimes.
A37: 4 | B37: Extracción de humos | D37: No | E37: CHS-49 (sin verificar) | F37: SIN PRECIO: los precios de churrera, freidora y extracción no están verificados. Presupuéstalo, no lo estimes.
A38: 5 | B38: Campana y conducto a cubierta | D38: No | E38: CHS-49 (sin verificar) | F38: SIN PRECIO: los precios de churrera, freidora y extracción no están verificados. Presupuéstalo, no lo estimes.
B39: Equipos de la variante que necesitas | C39: =IFERROR(COUNTIF(D34:D38,"Sí"),"") -> 0
B40: LO QUE TE OBLIGA ADEMÁS | C40: =IFERROR(IF($C$6<>$A$46,"No es tu variante","Si hay freidora de gas, inspección periódica obligatoria de la instalación receptora CADA CINCO AÑOS, que en instalaciones de hasta 70 kW incluye los aparatos y comprueba la ventilación y el volumen mínimo del local "),"") -> No es tu variante
A42: Listas de validación (no las borres: las usan los desplegables)
A43: Variante | B43: Sí o No
A44: Bombonería (el caso del libro) | B44: Sí
A45: Bombonería + bean-to-bar | B45: No
...

Sheet Proveedores y EUDR
A1: Proveedores: Operador, Operador Posterior o Comerciante
A2: AI Chef Pro · aichef.pro — Cómo Montar una Chocolatería
A3: Cinco con URL comprobada el 12-09-2026 y uno (SelfPackaging) pendiente: HTTP 403 ese día. La columna que decide es la G: el número de referencia de la declaración de diligencia debida SÓLO se le pide a un operador. Pedírselo a un comerciante es pedirle algo que no tiene.
A5: Los seis proveedores publicados
A6: Nº | B6: Proveedor | C6: Qué te vende | D6: URL | E6: Id | F6: ¿Trabajas con él? | G6: ¿Operador, operador posterior o comerciante? | H6: ¿Te ha dado el nº de su DDS? | I6: Nº de referencia de la DDS | J6: ¿Boletín de cadmio? | K6: ¿Boletín de HAP? | L6: Pedido mínimo (€) | M6: Plazo (días) | N6: Qué papeles le tocan a ÉL | O6: Semáforo de documentación | P6: Por qué está en la lista
A7: 1 | B7: Callebaut / Barry Callebaut Ibérica | C7: Coberturas y chocolate profesional | D7: https://www.callebaut.com/es-ES/ | E7: CHS-50 | F7: No | G7: No lo sé | H7: No lo sé | I7: Pendiente de pedir | J7: No lo sé | K7: No lo sé | L7: 250 | M7: 7 | N7: =IFERROR(IF($G7="","",IF($G7=$A$30,"Sus datos Y el nº de referencia de su DDS (art. 5.3.a)",IF($G7="No aplica: no vende producto del Anexo I","No le pidas papeles EUDR: no vende producto del Anexo I",IF($G7="No lo sé","Pregúntaselo por escrito antes de comprar: de su respuesta depende qué papeles pedirle","Sus datos, su dirección y el producto: el nº de DDS NO se le pide por el art. 5.3.a)")))),"") -> Pregúntaselo por escrito antes de comprar: de su respuesta depende qué papeles pedirle | O7: =IFERROR(IF($G7="","",IF($G7=$A$30,IF(AND($H7="Sí",$I7<>"Pendiente de pedir"),"Completa: tienes su nº de DDS","FALTA el nº de referencia de su DDS"),IF($G7="No aplica: no vende producto del Anexo I","No aplica: fuera del ámbito EUDR",IF($G7="No lo sé","Pregúntaselo por escrito antes de comprar",IF(OR($J7="No",$K7="No"),"Pídele los boletines de cadmio y de HAP","Completa para su papel en la cadena"))))),"") -> Pregúntaselo por escrito antes de comprar | P7: Mayor grupo del sector con presencia industrial en España. De aquí sale la referencia de precio del juego de datos (`CHS-28a`): Callebaut 811, bloque de 5 kg a 125,08 euros CON IVA, o sea 25,02 euros/kg.
A8: 2 | B8: Asociación Chocolate Bean to Bar España | C8: Grano de cacao para bean-to-bar | D8: https://www.chocolatebeantobar.com/asociados/ | E8: CHS-51 | F8: No | G8: No lo sé | H8: No lo sé | I8: Pendiente de pedir | J8: No lo sé | K8: No lo sé | L8: 250 | M8: 7 | N8: =IFERROR(IF($G8="","",IF($G8=$A$30,"Sus datos Y el nº de referencia de su DDS (art. 5.3.a)",IF($G8="No aplica: no vende producto del Anexo I","No le pidas papeles EUDR: no vende producto del Anexo I",IF($G8="No lo sé","Pregúntaselo por escrito antes de comprar: de su respuesta depende qué papeles pedirle","Sus datos, su dirección y el producto: el nº de DDS NO se le pide por el art. 5.3.a)")))),"") -> Pregúntaselo por escrito antes de comprar: de su respuesta depende qué papeles pedirle | O8: =IFERROR(IF($G8="","",IF($G8=$A$30,IF(AND($H8="Sí",$I8<>"Pendiente de pedir"),"Completa: tienes su nº de DDS","FALTA el nº de referencia de su DDS"),IF($G8="No aplica: no vende producto del Anexo I","No aplica: fuera del ámbito EUDR",IF($G8="No lo sé","Pregúntaselo por escrito antes de comprar",IF(OR($J8="No",$K8="No"),"Pídele los boletines de cadmio y de HAP","Completa para su papel en la cadena"))))),"") -> Pregúntaselo por escrito antes de comprar | P8: La vía fiable para el grano: su listado publico permite identificar a los makers y a los importadores. Se publica como «MAS DE 40 MIEMBROS», nunca con una cifra cerrada (`N-18` prohíbe «45 miembros»). Ojo: las webs individuales de los proveedores de grano NO se abrieron, así que no se publica ninguna.
A9: 3 | B9: Utilcentre | C9: Maquinaria de chocolate (distribuidor Selmi y Pavoni) | D9: https://www.utilcentre.com/maquinaria-chocolate.html | E9: CHS-52 | F9: No | G9: No aplica: no vende producto del Anexo I | H9: No lo sé | I9: Pendiente de pedir | J9: No lo sé | K9: No lo sé | L9: 250 | M9: 7 | N9: =IFERROR(IF($G9="","",IF($G9=$A$30,"Sus datos Y el nº de referencia de su DDS (art. 5.3.a)",IF($G9="No aplica: no vende producto del Anexo I","No le pidas papeles EUDR: no vende producto del Anexo I",IF($G9="No lo sé","Pregúntaselo por escrito antes de comprar: de su respuesta depende qué papeles pedirle","Sus datos, su dirección y el producto: el nº de DDS NO se le pide por el art. 5.3.a)")))),"") -> No le pidas papeles EUDR: no vende producto del Anexo I | O9: =IFERROR(IF($G9="","",IF($G9=$A$30,IF(AND($H9="Sí",$I9<>"Pendiente de pedir"),"Completa: tienes su nº de DDS","FALTA el nº de referencia de su DDS"),IF($G9="No aplica: no vende producto del Anexo I","No aplica: fuera del ámbito EUDR",IF($G9="No lo sé","Pregúntaselo por escrito antes de comprar",IF(OR($J9="No",$K9="No"),"Pídele los boletines de cadmio y de HAP","Completa para su papel en la cadena"))))),"") -> No aplica: fuera del ámbito EUDR | P9: Precios publicos, y es de donde salen `CHS-41a` a `CHS-41j` y `CHS-42a` a `CHS-42j`. Base de IVA NO declarada en casi todas sus fichas: es exactamente la trampa que explica el cap. 08.
A10: 4 | B10: RestorHome | C10: Moldes de bombonería y utensilios | D10: https://www.restorhome.es/471-moldes-bomboneria-Chocolate-World | E10: CHS-53 | F10: No | G10: No lo sé | H10: No lo sé | I10: Pendiente de pedir | J10: No lo sé | K10: No lo sé | L10: 250 | M10: 7 | N10: =IFERROR(IF($G10="","",IF($G10=$A$30,"Sus datos Y el nº de referencia de su DDS (art. 5.3.a)",IF($G10="No aplica: no vende producto del Anexo I","No le pidas papeles EUDR: no vende producto del Anexo I",IF($G10="No lo sé","Pregúntaselo por escrito antes de comprar: de su respuesta depende qué papeles pedirle","Sus datos, su dirección y el producto: el nº de DDS NO se le pide por el art. 5.3.a)")))),"") -> Pregúntaselo por escrito antes de comprar: de su respuesta depende qué papeles pedirle | O10: =IFERROR(IF($G10="","",IF($G10=$A$30,IF(AND($H10="Sí",$I10<>"Pendiente de pedir"),"Completa: tienes su nº de DDS","FALTA el nº de referencia de su DDS"),IF($G10="No aplica: no vende producto del Anexo I","No aplica: fuera del ámbito EUDR",IF($G10="No lo sé","Pregúntaselo por escrito antes de comprar",IF(OR($J10="No",$K10="No"),"Pídele los boletines de cadmio y de HAP","Completa para su papel en la cadena"))))),"") -> Pregúntaselo por escrito antes de comprar | P10: Moldes Chocolate World, Pavoni y Martellato. De aquí sale el rango de 24,20-42,83 euros/ud (`CHS-45a`) que el juego de datos publica COMO RANGO.
A11: 5 | B11: SelfPackaging | C11: Packaging: cajas y estuches para bombones | D11: https://selfpackaging.es/90-cajas-para-bombones (web no accesible el 12-09-2026, HTTP 403: pendiente de comprobar) | E11: CHS-54 | F11: No | G11: No aplica: no vende producto del Anexo I | H11: No lo sé | I11: Pendiente de pedir | J11: No lo sé | K11: No lo sé | L11: 250 | M11: 7 | N11: =IFERROR(IF($G11="","",IF($G11=$A$30,"Sus datos Y el nº de referencia de su DDS (art. 5.3.a)",IF($G11="No aplica: no vende producto del Anexo I","No le pidas papeles EUDR: no vende producto del Anexo I",IF($G11="No lo sé","Pregúntaselo por escrito antes de comprar: de su respuesta depende qué papeles pedirle","Sus datos, su dirección y el producto: el nº de DDS NO se le pide por el art. 5.3.a)")))),"") -> No le pidas papeles EUDR: no vende producto del Anexo I | O11: =IFERROR(IF($G11="","",IF($G11=$A$30,IF(AND($H11="Sí",$I11<>"Pendiente de pedir"),"Completa: tienes su nº de DDS","FALTA el nº de referencia de su DDS"),IF($G11="No aplica: no vende producto del Anexo I","No aplica: fuera del ámbito EUDR",IF($G11="No lo sé","Pregúntaselo por escrito antes de comprar",IF(OR($J11="No",$K11="No"),"Pídele los boletines de cadmio y de HAP","Completa para su papel en la cadena"))))),"") -> No aplica: fuera del ámbito EUDR | P11: Personalización con logo desde pocas unidades. Su web devolvió HTTP 403 al intentar leer precios, así que el packaging del CAPEX es SUPUESTO.
A12: 6 | B12: Gift Campaign | C12: Regalo corporativo B2B | D12: https://www.giftcampaign.es/dulces-personalizados/chocolates.html | E12: CHS-55 | F12: No | G12: No aplica: no vende producto del Anexo I | H12: No lo sé | I12: Pendiente de pedir | J12: No lo sé | K12: No lo sé | L12: 250 | M12: 7 | N12: =IFERROR(IF($G12="","",IF($G12=$A$30,"Sus datos Y el nº de referencia de su DDS (art. 5.3.a)",IF($G12="No aplica: no vende producto del Anexo I","No le pidas papeles EUDR: no vende producto del Anexo I",IF($G12="No lo sé","Pregúntaselo por escrito antes de comprar: de su respuesta depende qué papeles pedirle","Sus datos, su dirección y el producto: el nº de DDS NO se le pide por el art. 5.3.a)")))),"") -> No le pidas papeles EUDR: no vende producto del Anexo I | O12: =IFERROR(IF($G12="","",IF($G12=$A$30,IF(AND($H12="Sí",$I12<>"Pendiente de pedir"),"Completa: tienes su nº de DDS","FALTA el nº de referencia de su DDS"),IF($G12="No aplica: no vende producto del Anexo I","No aplica: fuera del ámbito EUDR",IF($G12="No lo sé","Pregúntaselo por escrito antes de comprar",IF(OR($J12="No",$K12="No"),"Pídele los boletines de cadmio y de HAP","Completa para su papel en la cadena"))))),"") -> No aplica: fuera del ámbito EUDR | P12: Dos reglas operativas verificadas del canal corporativo: plazo de entrega de 14-16 días desde la aprobación de la muestra virtual, y mínimos de fabricación de 10 a 25 cajas. El plazo es lo que decide si aceptas un pedido de empresa en diciembre.
A14: Resumen de la cartera de proveedores
A15: Proveedores publicados en esta hoja | F15: =COUNTIF($B$7:$B$12,"<>") -> 6 | H15: Cinco con URL comprobada el 12-09-2026 y uno (SelfPackaging) pendiente, marcado en su fila. Los que el research recogió sin verificar no entran.
A16: Proveedores con los que ya trabajas | F16: =COUNTIF($F$7:$F$12,"Sí") -> 0 | H16: Empieza por dos o tres: abrir ficha en seis proveedores a la vez es una semana de papeleo y ningún descuento.
A17: De ellos, OPERADORES (primera comercialización o exportación) | F17: =COUNTIF($G$7:$G$12,"operador") -> 0 | H17: A éstos, y sólo a éstos, hay que pedirles el número de referencia de su declaración de diligencia debida.
A18: De ellos, operadores posteriores | F18: =COUNTIF($G$7:$G$12,"operador posterior") -> 0 | H18: Introducen en el mercado productos elaborados con otros YA amparados por una declaración. Es lo que normalmente será tu proveedor de cobertura.
A19: De ellos, comerciantes | F19: =COUNTIF($G$7:$G$12,"comerciante") -> 0 | H19: Ni introducen ni exportan: comercian dentro.
A20: Proveedores a los que todavía no les has preguntado | F20: =IFERROR($F$15-($F$17+$F$18+$F$19),"") -> 6 | H20: Mientras esta cifra no sea cero, no sabes qué papeles te faltan. Es una pregunta de dos líneas en un correo.
A21: Operadores que todavía no te han dado su nº de DDS | F21: =SUMPRODUCT(--($G$7:$G$12="operador"),--($I$7:$I$12="Pendiente de pedir")) -> 0 | H21: Sólo cuenta a los operadores: a los demás no se les pide, y un semáforo que se lo exigiera suspendería a proveedores que cumplen.
A22: Proveedores que NO te dan boletín de cadmio | F22: =COUNTIF($J$7:$J$12,"No") -> 0 | H22: El boletín del proveedor es la primera línea de defensa: la analítica propia es la segunda. La hoja «Cadmio y Analíticas» del libro 8 decide si te hace falta y con qué frecuencia.
A23: Proveedores que NO te dan boletín de HAP | F23: =COUNTIF($K$7:$K$12,"No") -> 0 | H23: Los hidrocarburos aromáticos policíclicos aparecen en el grano y en la fibra de cacao, no en la cobertura terminada: pídeselo sobre todo a quien te venda grano.
A24: Pedido mínimo acumulado si pides a todos a la vez (€) | F24: =SUM($L$7:$L$12) -> 1500 | H24: Es dinero parado en el almacén el día que menos caja tienes. Los pedidos mínimos que vienen puestos son SUPUESTOS: te los confirma cada comercial.
A25: Plazo medio de entrega comprometido (días) | F25: =IFERROR(AVERAGE($M$7:$M$12),"") -> 7 | H25: Con qué antelación tienes que pedir. La antelación de compra por campaña la calcula «campanas-y-valle-del-ano.xlsx».
A26: VEREDICTO DE LA DOCUMENTACIÓN | F26: =IFERROR(IF($F$20>0,"Te faltan proveedores por clasificar: pregúntales su papel en la cadena",IF($F$21>0,"Te falta el nº de DDS de algún OPERADOR: sin él no puedes acreditar tu diligencia debida","Documentación coherente con tu papel en la cadena")),"") -> Te faltan proveedores por clasificar: pregúntales su papel en la cadena
A28: Listas de validación (no las borres: las usan los desplegables)
A29: Papel en la cadena | B29: Sí, No o No lo sé
A30: operador | B30: Sí
A31: operador posterior | B31: No
A32: comerciante | B32: No lo sé
A33: No lo sé
A34: No aplica: no vende producto del Anexo I
A36: Seis proveedores con URL comprobada el 12-09-2026. El research recogió muchos mas sin verificar y NO se publican. La columna «papel EUDR» va VACIA: la rellena el lector preguntando, y el número de DDS solo se pide en la rama «operador» (D48). Directorio del grupo: hosply.pro, y su TLS se comprueba ANTES de enlazarlo desde el cap. 13 (precedente: ingredientsindex.pro tiene el certificado roto y 62 posts del blog enlazan a un aviso de seguridad).
A37: REDACCION OBLIGATORIA, y el paso es INFERENCIA DECLARADA, no nivel A: «si tu cobertura llega ya comercializada en la UE y amparada por una declaración de diligencia debida, eres operador posterior (art. 2.15 ter) y el aplazamiento del art. 38.3 -que es para operadores- no te alcanza: tu fecha es el 30 de diciembre de 2026. Si tu cobertura NO esta amparada (compra anterior al EUDR, proveedor que no lo acredita), la calificación deja de ser automática y hay que revisarla». Están PROHIBIDAS «siempre eres operador posterior» y «tu fecha es el 30-12-2026 pase lo que pase». Y la exclusión de los operadores posteriores del punto 15 se PARAFRASEA, no se entrecomilla: consta en la nota de `CHN-22`, no entre las 81 citas del gate de literalidad. Verificado a 12-09-2026: comprueba el estado del EUDR antes de comprar cacao.
A38: Directorio HORECA del grupo, con su certificado comprobado antes de publicarlo: https://hosply.pro/?utm_source=guia-chocolateria-obrador&utm_medium=producto&utm_campaign=cap13-proveedores
A39: Los pedidos mínimos, los plazos y la respuesta del papel en la cadena que vienen rellenos son SUPUESTOS para que la hoja funcione desde el primer minuto: no son las condiciones de estas empresas ni su clasificación real. Cada una te dará las suyas.
A41: Diseñado por John Guerrero — chef y consultor gastronómico desde 2010, en cocina desde los 17 años.
A42: Versión 1.0 · septiembre 2026 · aichef.pro/guia-chocolateria-obrador · info@aichef.pro

Sheet Clientes a los que Suministras
A1: Clientes a los que Suministras: El Registro del Art. 5.3.b)
A2: AI Chef Pro · aichef.pro — Cómo Montar una Chocolatería
A3: La tabla que no existe en ningún otro libro del catálogo. El mismo artículo que te hace guardar los datos de tus proveedores te obliga a registrar a los operadores posteriores y comerciantes A LOS QUE TÚ HAS SUMINISTRADO. Se conserva cinco años.
A5: Parámetro de esta hoja
A6: Años que hay que conservar el registro | C6: 5 | D6: Cinco años, y de ahí sale la columna «Conservar hasta». Está en celda verde porque es un parámetro normativo: si cambia, se cambia aquí y no en once fórmulas.
A8: A quién le has suministrado, qué y cuándo
A9: Nº | B9: Nombre del cliente | C9: Dirección o población | D9: Tipo | E9: Canal | F9: Producto suministrado | G9: Primer suministro | H9: ¿Inscrito en el RGSEAA? | I9: Conservar hasta | J9: Notas
A10: 1 | B10: Cafetería El Mirador | C10: Ciudad de ejemplo | D10: Hostelería | E10: B2B a hostelería | F10: Bombones de colección a granel y tabletas | G10: 46277 | H10: No lo sé | I10: =IFERROR(IF($B10="(libre: escribe aquí tu cliente)","",DATE(YEAR($G10)+$C$6,MONTH($G10),DAY($G10))),"") -> 48103 | J10: Cliente de EJEMPLO declarado: sustitúyelo por el tuyo. Lo que no es un ejemplo es la obligación de tener esta tabla.
A11: 2 | B11: Hotel Plaza Mayor (A&B) | C11: Ciudad de ejemplo | D11: Hostelería | E11: B2B a hostelería | F11: Bombón de cortesia de habitación y cajas de 12 | G11: 46277 | H11: No lo sé | I11: =IFERROR(IF($B11="(libre: escribe aquí tu cliente)","",DATE(YEAR($G11)+$C$6,MONTH($G11),DAY($G11))),"") -> 48103 | J11: Cliente de EJEMPLO declarado: sustitúyelo por el tuyo. Lo que no es un ejemplo es la obligación de tener esta tabla.
A12: 3 | B12: Industrias Nogal, S.L. | C12: Ciudad de ejemplo | D12: Empresa | E12: Regalo corporativo | F12: Estuche corporativo personalizado de 24 bombones | G12: 46277 | H12: No lo sé | I12: =IFERROR(IF($B12="(libre: escribe aquí tu cliente)","",DATE(YEAR($G12)+$C$6,MONTH($G12),DAY($G12))),"") -> 48103 | J12: Cliente de EJEMPLO declarado: sustitúyelo por el tuyo. Lo que no es un ejemplo es la obligación de tener esta tabla.
A13: 4 | B13: Tienda gourmet La Despensa | C13: Ciudad de ejemplo | D13: Minorista de distinta titularidad | E13: Minorista de distinta titularidad | F13: Tabletas de origen y almendras bañadas | G13: 46277 | H13: No lo sé | I13: =IFERROR(IF($B13="(libre: escribe aquí tu cliente)","",DATE(YEAR($G13)+$C$6,MONTH($G13),DAY($G13))),"") -> 48103 | J13: Cliente de EJEMPLO declarado: sustitúyelo por el tuyo. Lo que no es un ejemplo es la obligación de tener esta tabla.
A14: 5 | B14: (libre: escribe aquí tu cliente) | C14: Pendiente | D14: Consumidor final | E14: Otro | F14: Pendiente | G14: 46277 | H14: No lo sé | I14: =IFERROR(IF($B14="(libre: escribe aquí tu cliente)","",DATE(YEAR($G14)+$C$6,MONTH($G14),DAY($G14))),"") | J14: Fila libre: escribe aquí tu cliente.
A15: 6 | B15: (libre: escribe aquí tu cliente) | C15: Pendiente | D15: Consumidor final | E15: Otro | F15: Pendiente | G15: 46277 | H15: No lo sé | I15: =IFERROR(IF($B15="(libre: escribe aquí tu cliente)","",DATE(YEAR($G15)+$C$6,MONTH($G15),DAY($G15))),"") | J15: Fila libre: escribe aquí tu cliente.
A16: 7 | B16: (libre: escribe aquí tu cliente) | C16: Pendiente | D16: Consumidor final | E16: Otro | F16: Pendiente | G16: 46277 | H16: No lo sé | I16: =IFERROR(IF($B16="(libre: escribe aquí tu cliente)","",DATE(YEAR($G16)+$C$6,MONTH($G16),DAY($G16))),"") | J16: Fila libre: escribe aquí tu cliente.
A17: 8 | B17: (libre: escribe aquí tu cliente) | C17: Pendiente | D17: Consumidor final | E17: Otro | F17: Pendiente | G17: 46277 | H17: No lo sé | I17: =IFERROR(IF($B17="(libre: escribe aquí tu cliente)","",DATE(YEAR($G17)+$C$6,MONTH($G17),DAY($G17))),"") | J17: Fila libre: escribe aquí tu cliente.
A19: Resumen del registro
A20: Clientes registrados | E20: =SUMPRODUCT(--($B$10:$B$17<>"(libre: escribe aquí tu cliente)")) -> 4 | G20: Las filas libres no cuentan: cuentan las que tienen nombre.
A21: De ellos, B2B de hostelería | E21: =SUMPRODUCT(--($B$10:$B$17<>"(libre: escribe aquí tu cliente)"),--($E$10:$E$17="B2B a hostelería")) -> 2 | G21: Cafeterías, hoteles y restaurantes. Es el canal que puede meterte en el art. 3 del RD 1021/2022.
A22: De ellos, regalo corporativo | E22: =SUMPRODUCT(--($B$10:$B$17<>"(libre: escribe aquí tu cliente)"),--($E$10:$E$17="Regalo corporativo")) -> 1 | G22: El canal de diciembre. Su plazo verificado es de 14 días desde la aprobación de la muestra, con mínimos de 10 a 25 cajas.
A23: De ellos, minoristas de DISTINTA titularidad | E23: =SUMPRODUCT(--($B$10:$B$17<>"(libre: escribe aquí tu cliente)"),--($D$10:$D$17="Minorista de distinta titularidad")) -> 1 | G23: Se cuenta por el TIPO de cliente, no por el canal: a una tienda gourmet se le puede servir por la misma ruta que a una cafetería y sigue siendo un minorista de distinta titularidad. Éstos son los que abren la puerta del art. 3, y si tienes al menos uno la hoja «Suministro a Otros Minoristas» del libro 8 te toca entera.
A24: Clientes inscritos en el RGSEAA | E24: =SUMPRODUCT(--($B$10:$B$17<>"(libre: escribe aquí tu cliente)"),--($H$10:$H$17="Sí")) -> 0 | G24: BASTA UNO para romper el requisito de «restringido» del art. 3, y los tres requisitos son acumulativos. Es la casilla más cara de esta hoja. Los «No lo sé» NO se cuentan aquí: mientras queden, este 0 no significa que ninguno esté inscrito.
A25: Fecha hasta la que hay que conservar el registro | E25: =IFERROR(MAX($I$10:$I$17),"") -> 48103 | G25: La del suministro más reciente más los años del parámetro. Hasta esa fecha, esta tabla es un documento, no una lista de contactos.
A26: VEREDICTO DEL REGISTRO | E26: =IFERROR(IF($E$20=0,"Todavía no suministras a nadie: el art. 5.3.b) no te pide nada","Tienes que conservar este registro, con nombre, dirección y producto, durante los años del parámetro"),"") -> Tienes que conservar este registro, con nombre, dirección y producto, durante los años del parámetro
A27: Y lo que además te cambia de régimen SANITARIO | E27: =IFERROR(IF($E$23=0,"Ninguno de tus clientes es un minorista de distinta titularidad: el art. 3 del RD 1021/2022 no te aplica",IF($E$24>0,"Tienes un cliente inscrito en el RGSEAA: pierdes «restringido» y el art. 3 deja de ampararte","Suministras a otros minoristas: resuelve los TRES semáforos del art. 3 en el libro 8")),"") -> Suministras a otros minoristas: resuelve los TRES semáforos del art. 3 en el libro 8
A29: Listas de validación (no las borres: las usan los desplegables)
A30: Canal | B30: Tipo de cliente | C30: Sí, No o No lo sé
A31: B2B a hostelería | B31: Hostelería | C31: Sí
A32: Regalo corporativo | B32: Empresa | C32: No
A33: Minorista de distinta titularidad | B33: Minorista de distinta titularidad | C33: No lo sé
A34: Otro | B34: Consumidor final
A36: CUATRO CLIENTES FICTICIOS DECLARADOS, para que la tabla del libro 9 tenga forma. Lo que NO es ficticio es la obligación: registrar a quien suministras (art. 5.3.b) del EUDR, `CHN-24`) y conservarlo cinco años. Escribir «basta con registrar a tus proveedores» esta PROHIBIDO (§5.1, prohibición 3). Y el cuarto cliente es el que cambia tu régimen sanitario: «Tienda gourmet La Despensa» es un MINORISTA DE DISTINTA TITULARIDAD, así que activa el art. 3 del RD 1021/2022 (`CHN-41`). Basta con que UNO de tus clientes este inscrito en el RGSEAA para romper el requisito de «restringido», y los tres requisitos son ACUMULATIVOS.
A37: ESTA TABLA CIERRA EL CÍRCULO CON LA HOJA «Checklist Legal» DEL LIBRO 8: los canales que se salen de la nota del epígrafe 644.5 -online con envío, B2B a hostelería y regalo corporativo- son justo los que hay que registrar aquí. Un mismo cliente puede costarte una pregunta al asesor fiscal y una línea en este registro.
A38: Vender online AL CONSUMIDOR FINAL no entra aquí: esto es el registro de los operadores posteriores y comerciantes a los que suministras, no el de tus compradores particulares. Y vender online a toda España tampoco rompe por sí solo el requisito de «localizado» del art. 3, que habla del suministro a otros minoristas.
A40: Diseñado por John Guerrero — chef y consultor gastronómico desde 2010, en cocina desde los 17 años.
A41: Versión 1.0 · septiembre 2026 · aichef.pro/guia-chocolateria-obrador · info@aichef.pro

Sheet Contador
A1: Contador: Cómo Va la Compra
A2: AI Chef Pro · aichef.pro — Cómo Montar una Chocolatería
A3: Todo lo que hay aquí sale de las hojas anteriores. No se teclea nada en esta pantalla.
A5: Avance del equipamiento
A6: Concepto | B6: Valor | D6: Notas
A7: Líneas de equipamiento | B7: ='Equipamiento'!I34 -> 17 | D7: Las diecisiete de la dotación, opcionales incluidas.
A8: Líneas marcadas como N/A | B8: =IFERROR(COUNTIF('Equipamiento'!$A$15:$A$31,"N/A"),"") -> 0 | D8: Las que has decidido que no te tocan.
A9: Líneas que de verdad vas a comprar | B9: =IFERROR(B7-B8,"") -> 17 | D9: Es el denominador del avance: lo que no vas a comprar no puede contar como pendiente.
A10: Líneas en estado «Instalado» | B10: =IFERROR(COUNTIF('Equipamiento'!$A$15:$A$31,"Instalado"),"") -> 0
A11: Líneas en estado «Recibido» | B11: =IFERROR(COUNTIF('Equipamiento'!$A$15:$A$31,"Recibido"),"") -> 0
A12: Líneas en estado «Pedido» | B12: =IFERROR(COUNTIF('Equipamiento'!$A$15:$A$31,"Pedido"),"") -> 0
A13: Líneas en estado «Presupuestado» | B13: =IFERROR(COUNTIF('Equipamiento'!$A$15:$A$31,"Presupuestado"),"") -> 0
A14: Líneas en estado «Pendiente» | B14: =IFERROR(COUNTIF('Equipamiento'!$A$15:$A$31,"Pendiente"),"") -> 17
A15: Avance de la compra (%) | B15: =IFERROR(IF(B9=0,"",B10/B9),"") -> 0 | D15: Sólo cuenta «Instalado»: una máquina pedida y no montada no produce ni un bombón.
A17: El dinero
A18: Concepto | B18: Importe | D18: Notas
A19: Presupuesto de referencia sin IVA, todas las líneas (€) | B19: ='Equipamiento'!I36 -> 54951.65
A20: Compromiso real negociado sin IVA (€) | B20: ='Equipamiento'!I38 -> 54951.65
A21: Diferencia (real menos referencia, €) | B21: =IFERROR(B20-B19,"") -> 0 | D21: Negativo es buena noticia: has negociado por debajo de la referencia.
A23: Los papeles
A24: Concepto | B24: Valor | D24: Notas
A25: Proveedores publicados | B25: ='Proveedores y EUDR'!F15 -> 6
A26: Proveedores sin clasificar en la cadena EUDR | B26: ='Proveedores y EUDR'!F20 -> 6 | D26: Una pregunta de dos líneas en un correo.
A27: Operadores que te deben su nº de DDS | B27: ='Proveedores y EUDR'!F21 -> 0 | D27: Sólo los operadores: a los demás no se les pide.
A28: Clientes registrados (art. 5.3.b) | B28: ='Clientes a los que Suministras'!E20 -> 4
A29: Clientes inscritos en el RGSEAA | B29: ='Clientes a los que Suministras'!E24 -> 0 | D29: Basta uno para perder «restringido» en el art. 3.
A31: Lo que falta para abrir
A32: VEREDICTO | B32: =IFERROR(IF(B15<1,"Todavía te falta equipo por instalar: mira la columna del plazo crítico antes de fijar la fecha",IF(B27>0,"El equipo está, pero te faltan papeles del EUDR","Equipo instalado y papeles coherentes: la fecha ya no depende de la maquinaria")),"") -> Todavía te falta equipo por instalar: mira la columna del plazo crítico antes de fijar la fecha
A34: El plazo crítico de entrega -la celda «Plazo crítico de entrega (semanas)» de la hoja «Equipamiento»- es el dato que se copia en el cronograma del libro «checklist-legal-licencias-y-cacao.xlsx». Si tu ruta crítica de papeleo es más corta que ese plazo, la fecha de apertura la manda la maquinaria, no el ayuntamiento.
A35: Y al revés: si el plazo crítico baja porque encuentras la máquina en stock, la fecha vuelve a mandarla el papeleo. Los dos libros hay que mirarlos juntos una vez por semana.
A38: Diseñado por John Guerrero — chef y consultor gastronómico desde 2010, en cocina desde los 17 años.
A39: Versión 1.0 · septiembre 2026 · aichef.pro/guia-chocolateria-obrador · info@aichef.pro
