Workbook

Sheet Instrucciones
A1: Sensibilidad al Precio del Cacao
A2: AI Chef Pro · aichef.pro — Cómo Montar una Chocolatería
A3: Celdas verdes = campos editables
A5: Qué Decide Este Libro
A6: Qué haces cuando el cacao sube: subir el precio, bajar el gramaje, cambiar de cobertura o aceptar menos margen. El libro no elige por ti: pone las cuatro salidas en euros y te dice cuál de tus referencias se rompe la primera.
A8: La Celda Más Importante del Paquete
A9: El precio de cada cobertura vive SÓLO en este libro, en la hoja «Coste de Cobertura». El libro 4 (carta y escandallo) y el libro 7 (plan financiero) lo COPIAN a mano en una celda verde y lo cuadran: no hay ni una fórmula entre ficheros. Si cambias aquí el precio, cámbialo también allí -las dos hojas te avisan si no cuadran-.
A11: El IVA: por Qué el Precio Sale en Dos Bases
A12: La tarifa del distribuidor puede venir con IVA o sin él, y casi nunca lo dice en la misma línea. Un escandallo se calcula SIEMPRE con precios sin IVA: el que soportas al comprar te lo deduces. Por eso escribes el precio tal y como te lo pasan, marcas en qué base viene, y la hoja te devuelve la base imponible. Mezclar las dos bases infla el food cost alrededor de un 9 %, que es justo el margen que creías tener.
A14: Las Hojas, y Qué Hace Cada Una
A15: Parámetros | B15: Los números que gobiernan todo el libro: IVA, food cost objetivo, food cost máximo, volumen de venta y condiciones de compra. Nada de esto está escrito dentro de una fórmula.
A16: Coste de Cobertura | B16: El precio de las cuatro coberturas en las dos bases, y el coste de cobertura de cada una de las 28 referencias de la carta. De aquí sale todo lo demás.
A17: Escenarios de Precio | B17: Cinco escenarios de subida -hoy, +20 %, +40 %, +60 % y el tuyo- con el coste de materia y el food cost de cada referencia en cada uno.
A18: Repercusión al PVP | B18: Las cuatro salidas, referencia a referencia: subir el PVP, bajar el gramaje, cambiar de cobertura o aguantar. Y la referencia que primero se rompe.
A19: Stock y Cobertura de Compra | B19: Cuánta cobertura tienes que tener parada, qué dinero es eso, cuándo hay que volver a pedir y qué te cuesta comprar por delante para una campaña.
A21: Cada Cuánto Se Usa
A22: Cada vez que tu proveedor te pase tarifa nueva, y como mínimo una vez por trimestre. Son diez minutos: cambias los precios de la hoja «Coste de Cobertura», miras la hoja «Repercusión al PVP» y decides. Antes de Navidad, míralo también con la compra anticipada de la hoja «Stock y Cobertura de Compra».
A24: Frontera con el Kit de Tareas Chocolatería
A25: El Kit de Tareas Chocolatería (12 €) no costea nada: publica las curvas de templado, las fichas de moldeado y los plazos de vida útil. Este libro no repite ninguna de esas tablas; lo que hace es ponerle precio al kilo de cobertura que se va en cada pieza. Si tienes el kit, los porcentajes de cacao de las tres coberturas son los suyos: cobertura negra 55-70 %, con leche 35-40 % y blanca 28-33 % (02-partidas-produccion.xlsx, hoja Templado).
A27: De Dónde Salen los Números del Ejemplo
A28: Todo lo que ves relleno es la bombonería «La Almendra», el caso de ejemplo de la guía: 75 m², obrador y tienda, 28 referencias. Los precios de las coberturas negra y de origen están verificados con su tienda y su fecha; los de leche y blanca son supuestos declarados, porque no hay precio público verificado. Todos los gramajes, el mix y el volumen son supuestos: sustitúyelos por los tuyos en cuanto tengas dos semanas de TPV.
A30: Para editar la estructura o una celda que no esté en verde: Revisar > Desproteger hoja (no tiene contraseña).
A32: Diseñado por John Guerrero — chef y consultor gastronómico desde 2010, en cocina desde los 17 años.
A33: Versión 1.0 · septiembre 2026 · aichef.pro/guia-chocolateria-obrador · info@aichef.pro

Sheet Parámetros
A1: Parámetros
A2: AI Chef Pro · aichef.pro — Cómo Montar una Chocolatería
A3: Ninguna de estas cifras está escrita dentro de una fórmula: se cambian aquí y el libro entero se mueve.
A5: Parámetro | B5: Valor | C5: Unidad | D5: De dónde sale | E5: Nota
A6: IVA de la cobertura y del chocolate | B6: 0.1 | C6: sobre la base | D6: CHN-71 | E6: El chocolate va al 10 % POR EXCLUSION, no porque un precepto lo nombre: la lista del 4 % del art. 91.Dos.1.1.o es cerrada y tiene siete letras, el chocolate no esta en ninguna, y tampoco esta entre las dos exclusiones del 10 % (bebidas alcoholicas y refrescantes).
A7: IVA del producto que vendes en mostrador | B7: 0.1 | C7: sobre la base | D7: CHN-71 | E7: El mismo tipo, y por la misma razón. La taza SERVIDA EN SALA va al 10 % por otra vía -es prestación de servicio de hostelería, no entrega de un bien-, y por eso la nota de esta celda cita las dos.
A8: Food cost objetivo (sobre PVP sin IVA) | B8: 0.3 | C8: sobre PVP | D8: supuesto | E8: REGLA ÚNICA de la casa, y es SUPUESTO: no existe dato publico de food cost de bombonería. `margen_bruto_objetivo()` deriva el margen sobre PVP, que con este food cost es el 70 %. El libro 4 pide UNO de los dos números y calcula el otro: margen bruto y food cost son la misma regla dicha dos veces, y publicarlos como dos reglas es un error de método prohibido. Se calcula SIEMPRE sobre base imponible en los DOS lados del cociente (regla 3 de §2.3).
A9: Margen bruto objetivo sobre PVP | B9: =IFERROR(1-'Parámetros'!$B$8,"") -> 0.7 | C9: sobre PVP | D9: calculado | E9: Es el food cost objetivo dicho al revés. Son la misma regla, no dos: por eso sólo se teclea una y la otra se calcula.
A10: Food cost máximo antes de dar la referencia por rota | B10: 0.35 | C10: sobre PVP | D10: supuesto | E10: El techo que te pones tú. Por encima de él la hoja «Repercusión al PVP» marca la referencia como ROTA. No es un límite del sector: es tu línea roja, y con ella se calcula «la subida máxima que aguanta».
A11: Clientes al día en velocidad de crucero | B11: 67 | C11: tickets/día | D11: supuesto | E11: Clientes por día en velocidad de crucero. NO es un dato del sector: `N-13` prohíbe publicar un ticket medio de chocolatería o un reparto mensual de ventas como dato, porque no existe dato publico. La guía enseña a medirlo con el TPV en dos semanas. Esta calibrado para que el margen neto del año de crucero caiga entre el 9 % y el 11 %: por encima, el caso se lee como optimista y un refutador lo tumba con razón. Es la ÚNICA palanca que se toca para mover el margen; los costes no se maquillan.
A12: Piezas por ticket | B12: 1.4 | C12: piezas/ticket | D12: supuesto | E12: De aquí sale el ticket medio, que NO se teclea: se calcula como PVP medio ponderado de la carta x piezas por ticket. En bombonería es BAJO -1,4- porque la unidad de venta real es la caja, no la pieza: quien entra a por un regalo se lleva UNA caja de 20 euros, no ocho bombones sueltos.
A13: Días de apertura al año | B13: 304 | C13: días/año | D13: supuesto | E13: 6 días por semana x 52 semanas = 312, menos 8 días de cierre por festivos = 304. En agosto la TIENDA NO CIERRA: lo que para es el obrador (D36, y el literal del kit dice «la tienda abre para el turista aunque el obrador pare»). Una bombonería de menos de 300 m² tiene libertad horaria por el art. 5.2 de la Ley 1/2004, no por el 5.1 (`CHN-77`).
A14: Piezas vendibles al año | B14: =IFERROR('Parámetros'!$B$11*'Parámetros'!$B$12*'Parámetros'!$B$13,"") -> 28515.2 | C14: piezas/año | D14: calculado | E14: Clientes al día por piezas por ticket por días de apertura. Es la base sobre la que el mix de cada referencia reparte las unidades. Una caja surtida cuenta como UNA pieza vendible: la unidad de venta de una bombonería es la caja, no el bombón.
A15: Semanas al año | B15: 52 | C15: semanas | D15: supuesto | E15: Se usa para pasar el consumo anual de cobertura a consumo semanal y para prorratear el coste financiero de la compra anticipada.
A16: Semanas de stock de cobertura que quieres tener | B16: 3 | C16: semanas | D16: supuesto | E16: Cuánta cobertura quieres tener parada en el almacén. Tres semanas es el supuesto de partida de La Almendra; súbelo si tu proveedor sirve mal o si entras en campaña.
A17: Plazo de entrega de tu proveedor | B17: 2 | C17: semanas | D17: supuesto | E17: Desde que haces el pedido hasta que lo tienes en el almacén. Es el número que de verdad fija el punto de recompra: pídeselo por escrito a tu comercial, y anótalo también en el libro 9.
A18: Stock de seguridad | B18: 1 | C18: semanas | D18: supuesto | E18: El colchón por encima del plazo de entrega. Sin él, cualquier retraso del proveedor te para el obrador.
A19: Tipo de interés anual del circulante | B19: 0.06 | C19: anual | D19: supuesto | E19: Lo que te cuesta el dinero que tienes parado en existencias. Si tiras de póliza, es el tipo de tu póliza; si tiras de caja, es lo que dejas de ganar con ese dinero.
A20: Semanas de compra anticipada para campaña | B20: 8 | C20: semanas | D20: supuesto | E20: Cuántas semanas de consumo compras por delante cuando llega Navidad. Es la compra que más tesorería inmoviliza del año, y la hoja «Stock y Cobertura de Compra» le pone precio.

Sheet Coste de Cobertura
A1: Coste de Cobertura por Referencia
A2: AI Chef Pro · aichef.pro — Cómo Montar una Chocolatería
A3: El precio de la cobertura vive SÓLO en esta hoja. Lo que copian el libro 4 y el libro 7 es la columna de BASE IMPONIBLE, nunca la de «como lo trae la fuente».
A5: La Celda Única: el Precio de Cada Cobertura en las Dos Bases
A6: Clave | B6: Cobertura | C6: Formato de compra | D6: Precio como lo trae la fuente (€/kg) | E6: Base declarada por la fuente | F6: Tipo de IVA | G6: Precio en BASE IMPONIBLE (€/kg) | H6: Fuente | I6: % de cacao (rango del kit) | J6: Nota
A7: negra | B7: Cobertura de chocolate negro (marca, 54,5 % de cacao) | C7: bloque de 5 kg a 125,08 euros | D7: 25.02 | E7: con IVA | F7: 0.1 | G7: =IFERROR(IF($E7=$A$62,$D7/(1+$F7),$D7),"") -> 22.745455 | H7: CHS-28a | I7: 55-70 % | J7: LA CELDA MAS CRITICA DEL PAQUETE. Base CON IVA declarada por la ficha (`CHS-28a`): el libro 3 la publica en las dos bases y lo que viaja al 4 y al 7 es la base imponible. Las tres magnitudes de arriba son SUPUESTO: pidesela a tu proveedor, la bolsa solo trae el total.
A8: origen | B8: Cobertura de chocolate de origen (70 % de cacao) | C8: pepitas de 400 g a 14,99 euros | D8: 37.48 | E8: no declarada | F8: 0.1 | G8: =IFERROR(IF($E8=$A$62,$D8/(1+$F8),$D8),"") -> 37.48 | H8: CHS-28c | I8: 55-70 % | J8: Factor 1,5 frente a la de marca, y es la decisión de posicionamiento mas cara del negocio (decisión 5 del bonus 2). La pagina no declara si el precio lleva IVA: se trata como base imponible y se marca.
A9: leche | B9: Cobertura de chocolate con leche (38 % de cacao) | C9: saco de 10 kg | D9: 19.5 | E9: sin IVA | F9: 0.1 | G9: =IFERROR(IF($E9=$A$62,$D9/(1+$F9),$D9),"") -> 19.5 | H9: supuesto | I9: 35-40 % | J9: SUPUESTO declarado: no hay precio verificado de cobertura con leche en el research. Celda verde con valor por defecto (regla 2 de §2.3: ninguna celda verde vacia).
A10: blanca | B10: Cobertura de chocolate blanco (30 % de cacao) | C10: saco de 10 kg | D10: 21 | E10: sin IVA | F10: 0.1 | G10: =IFERROR(IF($E10=$A$62,$D10/(1+$F10),$D10),"") -> 21 | H10: supuesto | I10: 28-33 % | J10: SUPUESTO declarado. Ojo al chocolate blanco: NO lleva materia seca desgrasada de cacao, y por eso el art. 6.d) del RD 1055/2003 NO le obliga a la mención «cacao: X % mínimo» (`CHN-07`).
A11: ESTA es la celda que copian el libro 4 y el libro 7: Coste de Cobertura!G7, la de BASE IMPONIBLE. La de la izquierda (D7) viene CON IVA declarado por la ficha, y un escandallo hecho con ella sale un 9 % alto.
A13: Coste de Chocolate por Referencia
A14: Los gramos son los mismos que tecleas en el libro 4 (carta y escandallo); aquí sirven para medir cuánto te expone cada referencia al precio del cacao, e incluyen la cobertura que va DENTRO del relleno. Las cuatro cajas surtidas no tienen gramaje propio: se componen de lo que llevan dentro, se prorratean a su cobertura dominante y la diferencia queda en «demás materias», así que su coste de materia total es el exacto.
A15: Id | B15: Referencia | C15: Familia | D15: Cobertura | E15: Gramos de cobertura en la cáscara | F15: Gramos de cobertura dentro del relleno | G15: Gramos de cobertura por pieza | H15: Peso total de la pieza (g) | I15: % del peso que es cobertura | J15: Precio de su cobertura (€/kg) | K15: Coste de cobertura por pieza (€) | L15: Coste de las demás materias (€) | M15: Coste de materia por pieza (€) | N15: Mix (% de unidades) | O15: Unidades al año | P15: Kg de cobertura al año | Q15: € de cobertura al año | R15: PVP con IVA (€) | S15: IVA | T15: PVP sin IVA (€) | U15: Food cost de materia
A16: BC1 | B16: Bombón de ganache de chocolate negro 70 % | C16: Bombones de colección | D16: negra | E16: 5.5 | F16: 3.38 | G16: =$E16+$F16 -> 8.88 | H16: 12 | I16: =IFERROR($G16/$H16,"") -> 0.74 | J16: =IFERROR(INDEX($G$7:$G$10,MATCH($D16,$A$7:$A$10,0)),"") -> 22.745455 | K16: =IFERROR($G16/1000*$J16,"") -> 0.20197964 | L16: 0.0156 | M16: =IFERROR($K16+$L16,"") -> 0.21757964 | N16: 6 | O16: =IFERROR('Parámetros'!$B$14*$N16/100,"") -> 1710.912 | P16: =IFERROR($G16/1000*$O16,"") -> 15.192899 | Q16: =IFERROR($K16*$O16,"") -> 345.56938 | R16: 2 | S16: 0.1 | T16: =IFERROR($R16/(1+$S16),"") -> 1.8181818 | U16: =IFERROR($M16/$T16,"") -> 0.1196688
A17: BC2 | B17: Bombón de ganache de leche y vainilla | C17: Bombones de colección | D17: leche | E17: 5.5 | F17: 3.64 | G17: =$E17+$F17 -> 9.14 | H17: 12 | I17: =IFERROR($G17/$H17,"") -> 0.76166667 | J17: =IFERROR(INDEX($G$7:$G$10,MATCH($D17,$A$7:$A$10,0)),"") -> 19.5 | K17: =IFERROR($G17/1000*$J17,"") -> 0.17823 | L17: 0.0125 | M17: =IFERROR($K17+$L17,"") -> 0.19073 | N17: 5 | O17: =IFERROR('Parámetros'!$B$14*$N17/100,"") -> 1425.76 | P17: =IFERROR($G17/1000*$O17,"") -> 13.031446 | Q17: =IFERROR($K17*$O17,"") -> 254.1132 | R17: 1.95 | S17: 0.1 | T17: =IFERROR($R17/(1+$S17),"") -> 1.7727273 | U17: =IFERROR($M17/$T17,"") -> 0.10759128
A18: BC3 | B18: Bombón de praliné de avellana | C18: Bombones de colección | D18: leche | E18: 5 | F18: 1.96 | G18: =$E18+$F18 -> 6.96 | H18: 12 | I18: =IFERROR($G18/$H18,"") -> 0.58 | J18: =IFERROR(INDEX($G$7:$G$10,MATCH($D18,$A$7:$A$10,0)),"") -> 19.5 | K18: =IFERROR($G18/1000*$J18,"") -> 0.13572 | L18: 0.0777 | M18: =IFERROR($K18+$L18,"") -> 0.21342 | N18: 6 | O18: =IFERROR('Parámetros'!$B$14*$N18/100,"") -> 1710.912 | P18: =IFERROR($G18/1000*$O18,"") -> 11.907948 | Q18: =IFERROR($K18*$O18,"") -> 232.20498 | R18: 2.1 | S18: 0.1 | T18: =IFERROR($R18/(1+$S18),"") -> 1.9090909 | U18: =IFERROR($M18/$T18,"") -> 0.11179143
A19: BC4 | B19: Bombón de gianduja de avellana | C19: Bombones de colección | D19: leche | E19: 5 | F19: 2.8 | G19: =$E19+$F19 -> 7.8 | H19: 12 | I19: =IFERROR($G19/$H19,"") -> 0.65 | J19: =IFERROR(INDEX($G$7:$G$10,MATCH($D19,$A$7:$A$10,0)),"") -> 19.5 | K19: =IFERROR($G19/1000*$J19,"") -> 0.1521 | L19: 0.0722 | M19: =IFERROR($K19+$L19,"") -> 0.2243 | N19: 4 | O19: =IFERROR('Parámetros'!$B$14*$N19/100,"") -> 1140.608 | P19: =IFERROR($G19/1000*$O19,"") -> 8.8967424 | Q19: =IFERROR($K19*$O19,"") -> 173.48648 | R19: 2.1 | S19: 0.1 | T19: =IFERROR($R19/(1+$S19),"") -> 1.9090909 | U19: =IFERROR($M19/$T19,"") -> 0.11749048
A20: BC5 | B20: Trufa de chocolate negro al cacao | C20: Bombones de colección | D20: negra | E20: 4 | F20: 4.86 | G20: =$E20+$F20 -> 8.86 | H20: 13 | I20: =IFERROR($G20/$H20,"") -> 0.68153846 | J20: =IFERROR(INDEX($G$7:$G$10,MATCH($D20,$A$7:$A$10,0)),"") -> 22.745455 | K20: =IFERROR($G20/1000*$J20,"") -> 0.20152473 | L20: 0.0166 | M20: =IFERROR($K20+$L20,"") -> 0.21812473 | N20: 5 | O20: =IFERROR('Parámetros'!$B$14*$N20/100,"") -> 1425.76 | P20: =IFERROR($G20/1000*$O20,"") -> 12.632234 | Q20: =IFERROR($K20*$O20,"") -> 287.3259 | R20: 1.9 | S20: 0.1 | T20: =IFERROR($R20/(1+$S20),"") -> 1.7272727 | U20: =IFERROR($M20/$T20,"") -> 0.12628274
A21: BC6 | B21: Bombón de licor de ron | C21: Bombones de colección | D21: negra | E21: 6 | F21: 0 | G21: =$E21+$F21 -> 6 | H21: 14 | I21: =IFERROR($G21/$H21,"") -> 0.42857143 | J21: =IFERROR(INDEX($G$7:$G$10,MATCH($D21,$A$7:$A$10,0)),"") -> 22.745455 | K21: =IFERROR($G21/1000*$J21,"") -> 0.13647273 | L21: 0.0364 | M21: =IFERROR($K21+$L21,"") -> 0.17287273 | N21: 3 | O21: =IFERROR('Parámetros'!$B$14*$N21/100,"") -> 855.456 | P21: =IFERROR($G21/1000*$O21,"") -> 5.132736 | Q21: =IFERROR($K21*$O21,"") -> 116.74641 | R21: 2.3 | S21: 0.1 | T21: =IFERROR($R21/(1+$S21),"") -> 2.0909091 | U21: =IFERROR($M21/$T21,"") -> 0.082678261
A22: BC7 | B22: Bombón de caramelo salado | C22: Bombones de colección | D22: leche | E22: 5.5 | F22: 0 | G22: =$E22+$F22 -> 5.5 | H22: 12 | I22: =IFERROR($G22/$H22,"") -> 0.45833333 | J22: =IFERROR(INDEX($G$7:$G$10,MATCH($D22,$A$7:$A$10,0)),"") -> 19.5 | K22: =IFERROR($G22/1000*$J22,"") -> 0.10725 | L22: 0.0259 | M22: =IFERROR($K22+$L22,"") -> 0.13315 | N22: 4 | O22: =IFERROR('Parámetros'!$B$14*$N22/100,"") -> 1140.608 | P22: =IFERROR($G22/1000*$O22,"") -> 6.273344 | Q22: =IFERROR($K22*$O22,"") -> 122.33021 | R22: 2 | S22: 0.1 | T22: =IFERROR($R22/(1+$S22),"") -> 1.8181818 | U22: =IFERROR($M22/$T22,"") -> 0.0732325
A23: BC8 | B23: Bombón de praliné de cacahuete | C23: Bombones de colección | D23: leche | E23: 5 | F23: 1.82 | G23: =$E23+$F23 -> 6.82 | H23: 12 | I23: =IFERROR($G23/$H23,"") -> 0.56833333 | J23: =IFERROR(INDEX($G$7:$G$10,MATCH($D23,$A$7:$A$10,0)),"") -> 19.5 | K23: =IFERROR($G23/1000*$J23,"") -> 0.13299 | L23: 0.0536 | M23: =IFERROR($K23+$L23,"") -> 0.18659 | N23: 3 | O23: =IFERROR('Parámetros'!$B$14*$N23/100,"") -> 855.456 | P23: =IFERROR($G23/1000*$O23,"") -> 5.8342099 | Q23: =IFERROR($K23*$O23,"") -> 113.76709 | R23: 1.95 | S23: 0.1 | T23: =IFERROR($R23/(1+$S23),"") -> 1.7727273 | U23: =IFERROR($M23/$T23,"") -> 0.1052559
A24: BC9 | B24: Bombón crujiente de sésamo y barquillo | C24: Bombones de colección | D24: leche | E24: 5 | F24: 3.08 | G24: =$E24+$F24 -> 8.08 | H24: 12 | I24: =IFERROR($G24/$H24,"") -> 0.67333333 | J24: =IFERROR(INDEX($G$7:$G$10,MATCH($D24,$A$7:$A$10,0)),"") -> 19.5 | K24: =IFERROR($G24/1000*$J24,"") -> 0.15756 | L24: 0.0329 | M24: =IFERROR($K24+$L24,"") -> 0.19046 | N24: 3 | O24: =IFERROR('Parámetros'!$B$14*$N24/100,"") -> 855.456 | P24: =IFERROR($G24/1000*$O24,"") -> 6.9120845 | Q24: =IFERROR($K24*$O24,"") -> 134.78565 | R24: 2.05 | S24: 0.1 | T24: =IFERROR($R24/(1+$S24),"") -> 1.8636364 | U24: =IFERROR($M24/$T24,"") -> 0.10219805
A25: BC10 | B25: Bombón de naranja confitada y chocolate negro | C25: Bombones de colección | D25: negra | E25: 5.5 | F25: 2.47 | G25: =$E25+$F25 -> 7.97 | H25: 12 | I25: =IFERROR($G25/$H25,"") -> 0.66416667 | J25: =IFERROR(INDEX($G$7:$G$10,MATCH($D25,$A$7:$A$10,0)),"") -> 22.745455 | K25: =IFERROR($G25/1000*$J25,"") -> 0.18128127 | L25: 0.0371 | M25: =IFERROR($K25+$L25,"") -> 0.21838127 | N25: 3 | O25: =IFERROR('Parámetros'!$B$14*$N25/100,"") -> 855.456 | P25: =IFERROR($G25/1000*$O25,"") -> 6.8179843 | Q25: =IFERROR($K25*$O25,"") -> 155.07815 | R25: 2.05 | S25: 0.1 | T25: =IFERROR($R25/(1+$S25),"") -> 1.8636364 | U25: =IFERROR($M25/$T25,"") -> 0.1171802
A26: TB1 | B26: Tableta de chocolate negro de origen 70 %, 100 g | C26: Tabletas | D26: origen | E26: 100 | F26: 0 | G26: =$E26+$F26 -> 100 | H26: 100 | I26: =IFERROR($G26/$H26,"") -> 1 | J26: =IFERROR(INDEX($G$7:$G$10,MATCH($D26,$A$7:$A$10,0)),"") -> 37.48 | K26: =IFERROR($G26/1000*$J26,"") -> 3.748 | L26: 0 | M26: =IFERROR($K26+$L26,"") -> 3.748 | N26: 7 | O26: =IFERROR('Parámetros'!$B$14*$N26/100,"") -> 1996.064 | P26: =IFERROR($G26/1000*$O26,"") -> 199.6064 | Q26: =IFERROR($K26*$O26,"") -> 7481.2479 | R26: 8.5 | S26: 0.1 | T26: =IFERROR($R26/(1+$S26),"") -> 7.7272727 | U26: =IFERROR($M26/$T26,"") -> 0.48503529
A27: TB2 | B27: Tableta de chocolate con leche 38 %, 100 g | C27: Tabletas | D27: leche | E27: 100 | F27: 0 | G27: =$E27+$F27 -> 100 | H27: 100 | I27: =IFERROR($G27/$H27,"") -> 1 | J27: =IFERROR(INDEX($G$7:$G$10,MATCH($D27,$A$7:$A$10,0)),"") -> 19.5 | K27: =IFERROR($G27/1000*$J27,"") -> 1.95 | L27: 0 | M27: =IFERROR($K27+$L27,"") -> 1.95 | N27: 6 | O27: =IFERROR('Parámetros'!$B$14*$N27/100,"") -> 1710.912 | P27: =IFERROR($G27/1000*$O27,"") -> 171.0912 | Q27: =IFERROR($K27*$O27,"") -> 3336.2784 | R27: 5.9 | S27: 0.1 | T27: =IFERROR($R27/(1+$S27),"") -> 5.3636364 | U27: =IFERROR($M27/$T27,"") -> 0.36355932
... A43: CJ4 | B43: Estuche corporativo personalizado de 24 bombones | C43: Cajas y regalo | D43: leche | E43: 184.35 | F43: 0 | G43: =$E43+$F43 -> 184.35 | H43: 293 | I43: =IFERROR($G43/$H43,"") -> 0.62918089 | J43: =IFERROR(INDEX($G$7:$G$10,MATCH($D43,$A$7:$A$10,0)),"") -> 19.5 | K43: =IFERROR($G43/1000*$J43,"") -> 3.594825 | L43: 1.1316 | M43: =IFERROR($K43+$L43,"") -> 4.726425 | N43: 1 | O43: =IFERROR('Parámetros'!$B$14*$N43/100,"") -> 285.152 | P43: =IFERROR($G43/1000*$O43,"") -> 52.567771 | Q43: =IFERROR($K43*$O43,"") -> 1025.0715 | R43: 34 | S43: 0.1 | T43: =IFERROR($R43/(1+$S43),"") -> 30.909091 | U43: =IFERROR($M43/$T43,"") -> 0.15291375
A44: TOTAL | B44: Las 28 referencias de la carta | N44: =SUM(N16:N43) -> 100 | O44: =SUM(O16:O43) -> 28515.2 | P44: =SUM(P16:P43) -> 1924.7532 | Q44: =SUM(Q16:Q43) -> 42792.38
A46: Coste de materia de todo el año (€) | D46: =IFERROR(SUMPRODUCT($M$16:$M$43,$O$16:$O$43),"") -> 49482.446 | F46: Suma del coste de materia de cada referencia por sus unidades. Es la cifra contra la que se mide lo que pesa la cobertura.
A47: Parte del coste de materia que es cobertura | D47: =IFERROR($Q$44/$D$46,"") -> 0.86479922 | F47: Cuanto más alto sea este número, más te mueve el precio del cacao. Por encima del 80 % no hay escandallo que te salve de una subida: la decisión es de carta, no de coste.
A49: Consumo por Cobertura
A50: Clave | B50: Cobertura | C50: Kg al año | D50: € al año | E50: Referencias que la llevan
A51: negra | B51: Cobertura de chocolate negro (marca, 54,5 % de cacao) | C51: =IFERROR(SUMIF($D$16:$D$43,$A51,$P$16:$P$43),"") -> 462.08596 | D51: =IFERROR(SUMIF($D$16:$D$43,$A51,$Q$16:$Q$43),"") -> 10510.355 | E51: =COUNTIF($D$16:$D$43,$A51) -> 11
A52: origen | B52: Cobertura de chocolate de origen (70 % de cacao) | C52: =IFERROR(SUMIF($D$16:$D$43,$A52,$P$16:$P$43),"") -> 199.6064 | D52: =IFERROR(SUMIF($D$16:$D$43,$A52,$Q$16:$Q$43),"") -> 7481.2479 | E52: =COUNTIF($D$16:$D$43,$A52) -> 1
A53: leche | B53: Cobertura de chocolate con leche (38 % de cacao) | C53: =IFERROR(SUMIF($D$16:$D$43,$A53,$P$16:$P$43),"") -> 1149 | D53: =IFERROR(SUMIF($D$16:$D$43,$A53,$Q$16:$Q$43),"") -> 22405.5 | E53: =COUNTIF($D$16:$D$43,$A53) -> 15
A54: blanca | B54: Cobertura de chocolate blanco (30 % de cacao) | C54: =IFERROR(SUMIF($D$16:$D$43,$A54,$P$16:$P$43),"") -> 114.0608 | D54: =IFERROR(SUMIF($D$16:$D$43,$A54,$Q$16:$Q$43),"") -> 2395.2768 | E54: =COUNTIF($D$16:$D$43,$A54) -> 1
A60: Listas de validación (no las borres: las usan los desplegables)
A61: Base de IVA declarada
A62: con IVA
A63: sin IVA
A64: no declarada

Sheet Escenarios de Precio
A1: Escenarios de Precio
A2: AI Chef Pro · aichef.pro — Cómo Montar una Chocolatería
A3: Cinco escenarios sobre el MISMO precio de partida. Lo único que se teclea es el porcentaje de subida: los precios y los food cost salen solos.
A6: Escenario | B6: Qué es | C6: Subida sobre el precio de hoy | D6: Factor | E6: Cobertura negra (€/kg) | F6: Cobertura de origen (€/kg) | G6: Cobertura con leche (€/kg) | H6: Cobertura blanca (€/kg)
A7: Precio de hoy | B7: La tarifa que tienes hoy delante. Es el punto de partida, no un escenario: si tu proveedor te ha pasado tarifa nueva, cámbiala arriba. | C7: 0 | D7: =1+$C7 -> 1 | E7: =IFERROR('Coste de Cobertura'!$G$7*$D7,"") -> 22.745455 | F7: =IFERROR('Coste de Cobertura'!$G$8*$D7,"") -> 37.48 | G7: =IFERROR('Coste de Cobertura'!$G$9*$D7,"") -> 19.5 | H7: =IFERROR('Coste de Cobertura'!$G$10*$D7,"") -> 21
A8: Subida moderada | B8: Una subida que el mercado del cacao se ha comido varias veces sin que nadie cambie la carta. Se absorbe con gramaje o con margen. | C8: 0.2 | D8: =1+$C8 -> 1.2 | E8: =IFERROR('Coste de Cobertura'!$G$7*$D8,"") -> 27.294545 | F8: =IFERROR('Coste de Cobertura'!$G$8*$D8,"") -> 44.976 | G8: =IFERROR('Coste de Cobertura'!$G$9*$D8,"") -> 23.4 | H8: =IFERROR('Coste de Cobertura'!$G$10*$D8,"") -> 25.2
A9: Subida fuerte | B9: El escenario de trabajo de esta hoja: el que obliga a decidir. A partir de aquí no hay una sola palanca que lo arregle. | C9: 0.4 | D9: =1+$C9 -> 1.4 | E9: =IFERROR('Coste de Cobertura'!$G$7*$D9,"") -> 31.843636 | F9: =IFERROR('Coste de Cobertura'!$G$8*$D9,"") -> 52.472 | G9: =IFERROR('Coste de Cobertura'!$G$9*$D9,"") -> 27.3 | H9: =IFERROR('Coste de Cobertura'!$G$10*$D9,"") -> 29.4
A10: Crisis del cacao | B10: El peor caso razonable. Sirve para saber qué referencias tendrías que retirar del surtido, no para poner precios. | C10: 0.6 | D10: =1+$C10 -> 1.6 | E10: =IFERROR('Coste de Cobertura'!$G$7*$D10,"") -> 36.392727 | F10: =IFERROR('Coste de Cobertura'!$G$8*$D10,"") -> 59.968 | G10: =IFERROR('Coste de Cobertura'!$G$9*$D10,"") -> 31.2 | H10: =IFERROR('Coste de Cobertura'!$G$10*$D10,"") -> 33.6
A11: Tu escenario | B11: Escribe aquí la subida que te ha comunicado TU proveedor. Es la celda que vas a usar de verdad. | C11: 0.35 | D11: =1+$C11 -> 1.35 | E11: =IFERROR('Coste de Cobertura'!$G$7*$D11,"") -> 30.706364 | F11: =IFERROR('Coste de Cobertura'!$G$8*$D11,"") -> 50.598 | G11: =IFERROR('Coste de Cobertura'!$G$9*$D11,"") -> 26.325 | H11: =IFERROR('Coste de Cobertura'!$G$10*$D11,"") -> 28.35
A13: Coste de Materia y Food Cost, Referencia a Referencia
A14: Lo que sube en cada escenario es SÓLO la parte de cobertura: las demás materias se quedan donde estaban. Por eso una tableta de origen -que es cobertura y poco más- se mueve mucho más que un bombón de praliné.
A15: Id | B15: Referencia | C15: Coste de cobertura hoy (€) | D15: Coste de las demás materias (€) | E15: PVP sin IVA (€) | F15: Coste de materia CON merma · Precio de hoy (€) | G15: Food cost · Precio de hoy | H15: Coste de materia CON merma · Subida moderada (€) | I15: Food cost · Subida moderada | J15: Coste de materia CON merma · Subida fuerte (€) | K15: Food cost · Subida fuerte | L15: Coste de materia CON merma · Crisis del cacao (€) | M15: Food cost · Crisis del cacao | N15: Coste de materia CON merma · Tu escenario (€) | O15: Food cost · Tu escenario | P15: Subida máxima que aguanta | Q15: Veredicto | R15: Merma no recuperable (%)
A16: BC1 | B16: Bombón de ganache de chocolate negro 70 % | C16: ='Coste de Cobertura'!K16 -> 0.20197964 | D16: ='Coste de Cobertura'!L16 -> 0.0156 | E16: ='Coste de Cobertura'!T16 -> 1.8181818 | F16: =IFERROR(($D16+$C16*$D$7)/(1-$R16),"") -> 0.2243089 | G16: =IFERROR(F16/$E16,"") -> 0.1233699 | H16: =IFERROR(($D16+$C16*$D$8)/(1-$R16),"") -> 0.26595419 | I16: =IFERROR(H16/$E16,"") -> 0.1462748 | J16: =IFERROR(($D16+$C16*$D$9)/(1-$R16),"") -> 0.30759948 | K16: =IFERROR(J16/$E16,"") -> 0.16917971 | L16: =IFERROR(($D16+$C16*$D$10)/(1-$R16),"") -> 0.34924476 | M16: =IFERROR(L16/$E16,"") -> 0.19208462 | N16: =IFERROR(($D16+$C16*$D$11)/(1-$R16),"") -> 0.29718815 | O16: =IFERROR(N16/$E16,"") -> 0.16345348 | P16: =IFERROR(($E16*'Parámetros'!$B$10*(1-$R16)-$D16)/$C16-1,"") -> 1.9788782 | Q16: =IF(ISNUMBER($P16),IF($P16<0,"Ya está por encima de tu food cost máximo","Aguanta esa subida sin pasar de tu food cost máximo"),"") -> Aguanta esa subida sin pasar de tu food cost máximo | R16: 0.03
A17: BC2 | B17: Bombón de ganache de leche y vainilla | C17: ='Coste de Cobertura'!K17 -> 0.17823 | D17: ='Coste de Cobertura'!L17 -> 0.0125 | E17: ='Coste de Cobertura'!T17 -> 1.7727273 | F17: =IFERROR(($D17+$C17*$D$7)/(1-$R17),"") -> 0.19662887 | G17: =IFERROR(F17/$E17,"") -> 0.11091885 | H17: =IFERROR(($D17+$C17*$D$8)/(1-$R17),"") -> 0.23337732 | I17: =IFERROR(H17/$E17,"") -> 0.13164874 | J17: =IFERROR(($D17+$C17*$D$9)/(1-$R17),"") -> 0.27012577 | K17: =IFERROR(J17/$E17,"") -> 0.15237864 | L17: =IFERROR(($D17+$C17*$D$10)/(1-$R17),"") -> 0.30687423 | M17: =IFERROR(L17/$E17,"") -> 0.17310854 | N17: =IFERROR(($D17+$C17*$D$11)/(1-$R17),"") -> 0.26093866 | O17: =IFERROR(N17/$E17,"") -> 0.14719617 | P17: =IFERROR(($E17*'Parámetros'!$B$10*(1-$R17)-$D17)/$C17-1,"") -> 2.3066314 | Q17: =IF(ISNUMBER($P17),IF($P17<0,"Ya está por encima de tu food cost máximo","Aguanta esa subida sin pasar de tu food cost máximo"),"") -> Aguanta esa subida sin pasar de tu food cost máximo | R17: 0.03
A18: BC3 | B18: Bombón de praliné de avellana | C18: ='Coste de Cobertura'!K18 -> 0.13572 | D18: ='Coste de Cobertura'!L18 -> 0.0777 | E18: ='Coste de Cobertura'!T18 -> 1.9090909 | F18: =IFERROR(($D18+$C18*$D$7)/(1-$R18),"") -> 0.21777551 | G18: =IFERROR(F18/$E18,"") -> 0.11407289 | H18: =IFERROR(($D18+$C18*$D$8)/(1-$R18),"") -> 0.24547347 | I18: =IFERROR(H18/$E18,"") -> 0.12858134 | J18: =IFERROR(($D18+$C18*$D$9)/(1-$R18),"") -> 0.27317143 | K18: =IFERROR(J18/$E18,"") -> 0.1430898 | L18: =IFERROR(($D18+$C18*$D$10)/(1-$R18),"") -> 0.30086939 | M18: =IFERROR(L18/$E18,"") -> 0.15759825 | N18: =IFERROR(($D18+$C18*$D$11)/(1-$R18),"") -> 0.26624694 | O18: =IFERROR(N18/$E18,"") -> 0.13946268 | P18: =IFERROR(($E18*'Parámetros'!$B$10*(1-$R18)-$D18)/$C18-1,"") -> 3.2522707 | Q18: =IF(ISNUMBER($P18),IF($P18<0,"Ya está por encima de tu food cost máximo","Aguanta esa subida sin pasar de tu food cost máximo"),"") -> Aguanta esa subida sin pasar de tu food cost máximo | R18: 0.02
A19: BC4 | B19: Bombón de gianduja de avellana | C19: ='Coste de Cobertura'!K19 -> 0.1521 | D19: ='Coste de Cobertura'!L19 -> 0.0722 | E19: ='Coste de Cobertura'!T19 -> 1.9090909 | F19: =IFERROR(($D19+$C19*$D$7)/(1-$R19),"") -> 0.22887755 | G19: =IFERROR(F19/$E19,"") -> 0.11988824 | H19: =IFERROR(($D19+$C19*$D$8)/(1-$R19),"") -> 0.25991837 | I19: =IFERROR(H19/$E19,"") -> 0.13614772 | J19: =IFERROR(($D19+$C19*$D$9)/(1-$R19),"") -> 0.29095918 | K19: =IFERROR(J19/$E19,"") -> 0.15240719 | L19: =IFERROR(($D19+$C19*$D$10)/(1-$R19),"") -> 0.322 | M19: =IFERROR(L19/$E19,"") -> 0.16866667 | N19: =IFERROR(($D19+$C19*$D$11)/(1-$R19),"") -> 0.28319898 | O19: =IFERROR(N19/$E19,"") -> 0.14834232 | P19: =IFERROR(($E19*'Parámetros'!$B$10*(1-$R19)-$D19)/$C19-1,"") -> 2.8304943 | Q19: =IF(ISNUMBER($P19),IF($P19<0,"Ya está por encima de tu food cost máximo","Aguanta esa subida sin pasar de tu food cost máximo"),"") -> Aguanta esa subida sin pasar de tu food cost máximo | R19: 0.02
A20: BC5 | B20: Trufa de chocolate negro al cacao | C20: ='Coste de Cobertura'!K20 -> 0.20152473 | D20: ='Coste de Cobertura'!L20 -> 0.0166 | E20: ='Coste de Cobertura'!T20 -> 1.7272727 | F20: =IFERROR(($D20+$C20*$D$7)/(1-$R20),"") -> 0.22721326 | G20: =IFERROR(F20/$E20,"") -> 0.13154452 | H20: =IFERROR(($D20+$C20*$D$8)/(1-$R20),"") -> 0.26919758 | I20: =IFERROR(H20/$E20,"") -> 0.15585123 | J20: =IFERROR(($D20+$C20*$D$9)/(1-$R20),"") -> 0.31118189 | K20: =IFERROR(J20/$E20,"") -> 0.18015794 | L20: =IFERROR(($D20+$C20*$D$10)/(1-$R20),"") -> 0.35316621 | M20: =IFERROR(L20/$E20,"") -> 0.20446465 | N20: =IFERROR(($D20+$C20*$D$11)/(1-$R20),"") -> 0.30068581 | O20: =IFERROR(N20/$E20,"") -> 0.17408126 | P20: =IFERROR(($E20*'Parámetros'!$B$10*(1-$R20)-$D20)/$C20-1,"") -> 1.7974911 | Q20: =IF(ISNUMBER($P20),IF($P20<0,"Ya está por encima de tu food cost máximo","Aguanta esa subida sin pasar de tu food cost máximo"),"") -> Aguanta esa subida sin pasar de tu food cost máximo | R20: 0.04
A21: BC6 | B21: Bombón de licor de ron | C21: ='Coste de Cobertura'!K21 -> 0.13647273 | D21: ='Coste de Cobertura'!L21 -> 0.0364 | E21: ='Coste de Cobertura'!T21 -> 2.0909091 | F21: =IFERROR(($D21+$C21*$D$7)/(1-$R21),"") -> 0.18007576 | G21: =IFERROR(F21/$E21,"") -> 0.086123188 | H21: =IFERROR(($D21+$C21*$D$8)/(1-$R21),"") -> 0.20850758 | I21: =IFERROR(H21/$E21,"") -> 0.099721014 | J21: =IFERROR(($D21+$C21*$D$9)/(1-$R21),"") -> 0.23693939 | K21: =IFERROR(J21/$E21,"") -> 0.11331884 | L21: =IFERROR(($D21+$C21*$D$10)/(1-$R21),"") -> 0.26537121 | M21: =IFERROR(L21/$E21,"") -> 0.12691667 | N21: =IFERROR(($D21+$C21*$D$11)/(1-$R21),"") -> 0.22983144 | O21: =IFERROR(N21/$E21,"") -> 0.10991938 | P21: =IFERROR(($E21*'Parámetros'!$B$10*(1-$R21)-$D21)/$C21-1,"") -> 3.8811617 | Q21: =IF(ISNUMBER($P21),IF($P21<0,"Ya está por encima de tu food cost máximo","Aguanta esa subida sin pasar de tu food cost máximo"),"") -> Aguanta esa subida sin pasar de tu food cost máximo | R21: 0.04
A22: BC7 | B22: Bombón de caramelo salado | C22: ='Coste de Cobertura'!K22 -> 0.10725 | D22: ='Coste de Cobertura'!L22 -> 0.0259 | E22: ='Coste de Cobertura'!T22 -> 1.8181818 | F22: =IFERROR(($D22+$C22*$D$7)/(1-$R22),"") -> 0.13726804 | G22: =IFERROR(F22/$E22,"") -> 0.075497423 | H22: =IFERROR(($D22+$C22*$D$8)/(1-$R22),"") -> 0.15938144 | I22: =IFERROR(H22/$E22,"") -> 0.087659794 | J22: =IFERROR(($D22+$C22*$D$9)/(1-$R22),"") -> 0.18149485 | K22: =IFERROR(J22/$E22,"") -> 0.099822165 | L22: =IFERROR(($D22+$C22*$D$10)/(1-$R22),"") -> 0.20360825 | M22: =IFERROR(L22/$E22,"") -> 0.11198454 | N22: =IFERROR(($D22+$C22*$D$11)/(1-$R22),"") -> 0.17596649 | O22: =IFERROR(N22/$E22,"") -> 0.096781572 | P22: =IFERROR(($E22*'Parámetros'!$B$10*(1-$R22)-$D22)/$C22-1,"") -> 4.5139648 | Q22: =IF(ISNUMBER($P22),IF($P22<0,"Ya está por encima de tu food cost máximo","Aguanta esa subida sin pasar de tu food cost máximo"),"") -> Aguanta esa subida sin pasar de tu food cost máximo | R22: 0.03
A23: BC8 | B23: Bombón de praliné de cacahuete | C23: ='Coste de Cobertura'!K23 -> 0.13299 | D23: ='Coste de Cobertura'!L23 -> 0.0536 | E23: ='Coste de Cobertura'!T23 -> 1.7727273 | F23: =IFERROR(($D23+$C23*$D$7)/(1-$R23),"") -> 0.19039796 | G23: =IFERROR(F23/$E23,"") -> 0.10740398 | H23: =IFERROR(($D23+$C23*$D$8)/(1-$R23),"") -> 0.21753878 | I23: =IFERROR(H23/$E23,"") -> 0.12271418 | J23: =IFERROR(($D23+$C23*$D$9)/(1-$R23),"") -> 0.24467959 | K23: =IFERROR(J23/$E23,"") -> 0.13802439 | L23: =IFERROR(($D23+$C23*$D$10)/(1-$R23),"") -> 0.27182041 | M23: =IFERROR(L23/$E23,"") -> 0.15333459 | N23: =IFERROR(($D23+$C23*$D$11)/(1-$R23),"") -> 0.23789439 | O23: =IFERROR(N23/$E23,"") -> 0.13419683 | P23: =IFERROR(($E23*'Parámetros'!$B$10*(1-$R23)-$D23)/$C23-1,"") -> 3.1690763 | Q23: =IF(ISNUMBER($P23),IF($P23<0,"Ya está por encima de tu food cost máximo","Aguanta esa subida sin pasar de tu food cost máximo"),"") -> Aguanta esa subida sin pasar de tu food cost máximo | R23: 0.02
A24: BC9 | B24: Bombón crujiente de sésamo y barquillo | C24: ='Coste de Cobertura'!K24 -> 0.15756 | D24: ='Coste de Cobertura'!L24 -> 0.0329 | E24: ='Coste de Cobertura'!T24 -> 1.8636364 | F24: =IFERROR(($D24+$C24*$D$7)/(1-$R24),"") -> 0.19434694 | G24: =IFERROR(F24/$E24,"") -> 0.10428372 | H24: =IFERROR(($D24+$C24*$D$8)/(1-$R24),"") -> 0.22650204 | I24: =IFERROR(H24/$E24,"") -> 0.12153768 | J24: =IFERROR(($D24+$C24*$D$9)/(1-$R24),"") -> 0.25865714 | K24: =IFERROR(J24/$E24,"") -> 0.13879164 | L24: =IFERROR(($D24+$C24*$D$10)/(1-$R24),"") -> 0.29081224 | M24: =IFERROR(L24/$E24,"") -> 0.15604559 | N24: =IFERROR(($D24+$C24*$D$11)/(1-$R24),"") -> 0.25061837 | O24: =IFERROR(N24/$E24,"") -> 0.13447815 | P24: =IFERROR(($E24*'Parámetros'!$B$10*(1-$R24)-$D24)/$C24-1,"") -> 2.848231 | Q24: =IF(ISNUMBER($P24),IF($P24<0,"Ya está por encima de tu food cost máximo","Aguanta esa subida sin pasar de tu food cost máximo"),"") -> Aguanta esa subida sin pasar de tu food cost máximo | R24: 0.02
A25: BC10 | B25: Bombón de naranja confitada y chocolate negro | C25: ='Coste de Cobertura'!K25 -> 0.18128127 | D25: ='Coste de Cobertura'!L25 -> 0.0371 | E25: ='Coste de Cobertura'!T25 -> 1.8636364 | F25: =IFERROR(($D25+$C25*$D$7)/(1-$R25),"") -> 0.22987502 | G25: =IFERROR(F25/$E25,"") -> 0.12334757 | H25: =IFERROR(($D25+$C25*$D$8)/(1-$R25),"") -> 0.2680395 | I25: =IFERROR(H25/$E25,"") -> 0.14382607 | J25: =IFERROR(($D25+$C25*$D$9)/(1-$R25),"") -> 0.30620398 | K25: =IFERROR(J25/$E25,"") -> 0.16430458 | L25: =IFERROR(($D25+$C25*$D$10)/(1-$R25),"") -> 0.34436846 | M25: =IFERROR(L25/$E25,"") -> 0.18478308 | N25: =IFERROR(($D25+$C25*$D$11)/(1-$R25),"") -> 0.29666286 | O25: =IFERROR(N25/$E25,"") -> 0.15918495 | P25: =IFERROR(($E25*'Parámetros'!$B$10*(1-$R25)-$D25)/$C25-1,"") -> 2.2135647 | Q25: =IF(ISNUMBER($P25),IF($P25<0,"Ya está por encima de tu food cost máximo","Aguanta esa subida sin pasar de tu food cost máximo"),"") -> Aguanta esa subida sin pasar de tu food cost máximo | R25: 0.05
A26: TB1 | B26: Tableta de chocolate negro de origen 70 %, 100 g | C26: ='Coste de Cobertura'!K26 -> 3.748 | D26: ='Coste de Cobertura'!L26 -> 0 | E26: ='Coste de Cobertura'!T26 -> 7.7272727 | F26: =IFERROR(($D26+$C26*$D$7)/(1-$R26),"") -> 3.7858586 | G26: =IFERROR(F26/$E26,"") -> 0.48993464 | H26: =IFERROR(($D26+$C26*$D$8)/(1-$R26),"") -> 4.5430303 | I26: =IFERROR(H26/$E26,"") -> 0.58792157 | J26: =IFERROR(($D26+$C26*$D$9)/(1-$R26),"") -> 5.300202 | K26: =IFERROR(J26/$E26,"") -> 0.6859085 | L26: =IFERROR(($D26+$C26*$D$10)/(1-$R26),"") -> 6.0573737 | M26: =IFERROR(L26/$E26,"") -> 0.78389542 | N26: =IFERROR(($D26+$C26*$D$11)/(1-$R26),"") -> 5.1109091 | O26: =IFERROR(N26/$E26,"") -> 0.66141176 | P26: =IFERROR(($E26*'Parámetros'!$B$10*(1-$R26)-$D26)/$C26-1,"") -> -0.285619 | Q26: =IF(ISNUMBER($P26),IF($P26<0,"Ya está por encima de tu food cost máximo","Aguanta esa subida sin pasar de tu food cost máximo"),"") -> Ya está por encima de tu food cost máximo | R26: 0.01
A27: TB2 | B27: Tableta de chocolate con leche 38 %, 100 g | C27: ='Coste de Cobertura'!K27 -> 1.95 | D27: ='Coste de Cobertura'!L27 -> 0 | E27: ='Coste de Cobertura'!T27 -> 5.3636364 | F27: =IFERROR(($D27+$C27*$D$7)/(1-$R27),"") -> 1.969697 | G27: =IFERROR(F27/$E27,"") -> 0.36723164 | H27: =IFERROR(($D27+$C27*$D$8)/(1-$R27),"") -> 2.3636364 | I27: =IFERROR(H27/$E27,"") -> 0.44067797 | J27: =IFERROR(($D27+$C27*$D$9)/(1-$R27),"") -> 2.7575758 | K27: =IFERROR(J27/$E27,"") -> 0.51412429 | L27: =IFERROR(($D27+$C27*$D$10)/(1-$R27),"") -> 3.1515152 | M27: =IFERROR(L27/$E27,"") -> 0.58757062 | N27: =IFERROR(($D27+$C27*$D$11)/(1-$R27),"") -> 2.6590909 | O27: =IFERROR(N27/$E27,"") -> 0.49576271 | P27: =IFERROR(($E27*'Parámetros'!$B$10*(1-$R27)-$D27)/$C27-1,"") -> -0.046923077 | Q27: =IF(ISNUMBER($P27),IF($P27<0,"Ya está por encima de tu food cost máximo","Aguanta esa subida sin pasar de tu food cost máximo"),"") -> Ya está por encima de tu food cost máximo | R27: 0.01
... A43: CJ4 | B43: Estuche corporativo personalizado de 24 bombones | C43: ='Coste de Cobertura'!K43 -> 3.594825 | D43: ='Coste de Cobertura'!L43 -> 1.1316 | E43: ='Coste de Cobertura'!T43 -> 30.909091 | F43: =IFERROR(($D43+$C43*$D$7)/(1-$R43),"") -> 4.7501759 | G43: =IFERROR(F43/$E43,"") -> 0.15368216 | H43: =IFERROR(($D43+$C43*$D$8)/(1-$R43),"") -> 5.4727538 | I43: =IFERROR(H43/$E43,"") -> 0.17705968 | J43: =IFERROR(($D43+$C43*$D$9)/(1-$R43),"") -> 6.1953317 | K43: =IFERROR(J43/$E43,"") -> 0.2004372 | L43: =IFERROR(($D43+$C43*$D$10)/(1-$R43),"") -> 6.9179095 | M43: =IFERROR(L43/$E43,"") -> 0.22381472 | N43: =IFERROR(($D43+$C43*$D$11)/(1-$R43),"") -> 6.0146872 | O43: =IFERROR(N43/$E43,"") -> 0.19459282 | P43: =IFERROR(($E43*'Parámetros'!$B$10*(1-$R43)-$D43)/$C43-1,"") -> 1.6795438 | Q43: =IF(ISNUMBER($P43),IF($P43<0,"Ya está por encima de tu food cost máximo","Aguanta esa subida sin pasar de tu food cost máximo"),"") -> Aguanta esa subida sin pasar de tu food cost máximo | R43: 0.005
A44: ROTAS | B44: Referencias que en ese escenario pasan de tu food cost máximo | G44: =COUNTIF(G16:G43,">"&'Parámetros'!$B$10) -> 7 | I44: =COUNTIF(I16:I43,">"&'Parámetros'!$B$10) -> 10 | K44: =COUNTIF(K16:K43,">"&'Parámetros'!$B$10) -> 11 | M44: =COUNTIF(M16:M43,">"&'Parámetros'!$B$10) -> 12 | O44: =COUNTIF(O16:O43,">"&'Parámetros'!$B$10) -> 11

Sheet Repercusión al PVP
A1: Repercusión al PVP
A2: AI Chef Pro · aichef.pro — Cómo Montar una Chocolatería
A3: Las cuatro salidas cuando sube el cacao: subir el PVP, bajar el gramaje, cambiar de cobertura o aguantar. Elige arriba el escenario y la hoja entera se recalcula.
A5: El Escenario con el que Trabajas
A6: Escenario elegido | C6: Subida fuerte | E6: Cambia sólo esta celda: el escenario elegido gobierna las 28 filas de abajo. Si quieres trabajar con la subida que te ha pasado tu proveedor, ponla en «Tu escenario» en la hoja «Escenarios de Precio» y elígelo aquí.
A7: Subida que supone | C7: =IFERROR(INDEX('Escenarios de Precio'!C$7:C$11,MATCH($C$6,'Escenarios de Precio'!A$7:A$11,0)),"") -> 0.4
A8: Factor sobre el precio de hoy | C8: =IFERROR(INDEX('Escenarios de Precio'!D$7:D$11,MATCH($C$6,'Escenarios de Precio'!A$7:A$11,0)),"") -> 1.4
A13: Qué Haces con Cada Referencia
A14: Las columnas I a L suben el precio; las M y N bajan el gramaje; las O y P cambian de cobertura. La columna Q dice cuánto aguanta la referencia antes de romper tu food cost máximo, y es la que ordena la lista: la que menos aguante es la primera que se te rompe.
A15: Id | B15: Referencia | C15: PVP con IVA hoy (€) | D15: PVP sin IVA hoy (€) | E15: Coste de materia hoy (€) | F15: Food cost hoy | G15: Coste de materia en el escenario (€) | H15: Food cost en el escenario | I15: PVP sin IVA necesario (€) | J15: PVP con IVA necesario (€) | K15: Subida de PVP (€) | L15: Subida de PVP (%) | M15: Gramos de cobertura admisibles con el PVP de hoy | N15: Recorte de gramaje necesario (negativo: te sobra margen) | O15: Precio máximo de cobertura que aguanta (€/kg) | P15: ¿Qué cobertura te vale a ese precio? | Q15: Subida máxima que aguanta | R15: Veredicto
A16: BC1 | B16: Bombón de ganache de chocolate negro 70 % | C16: ='Coste de Cobertura'!R16 -> 2 | D16: ='Coste de Cobertura'!T16 -> 1.8181818 | E16: ='Coste de Cobertura'!M16 -> 0.21757964 | F16: ='Coste de Cobertura'!U16 -> 0.1196688 | G16: =IFERROR('Escenarios de Precio'!D16+'Escenarios de Precio'!C16*$C$8,"") -> 0.29837149 | H16: =IFERROR($G16/$D16,"") -> 0.16410432 | I16: =IFERROR($G16/'Parámetros'!$B$8,"") -> 0.99457164 | J16: =IFERROR($I16*(1+'Coste de Cobertura'!S16),"") -> 1.0940288 | K16: =IFERROR($J16-$C16,"") -> -0.9059712 | L16: =IFERROR($J16/$C16-1,"") -> -0.4529856 | M16: =IFERROR(($D16*'Parámetros'!$B$8-'Escenarios de Precio'!D16)/('Coste de Cobertura'!J16*$C$8)*1000,"") -> 16.63926 | N16: =IFERROR(1-$M16/'Coste de Cobertura'!G16,"") -> -0.87379054 | O16: =IFERROR(($D16*'Parámetros'!$B$8-'Escenarios de Precio'!D16)/('Coste de Cobertura'!G16/1000),"") -> 59.668305 | P16: =IF(ISNUMBER($O16),IF($O16>=MAX('Coste de Cobertura'!G$7:G$10),"Cualquiera de las cuatro, incluida la que usas",IF($O16>=MIN('Coste de Cobertura'!G$7:G$10),"Sólo alguna de las más baratas: compáralas arriba","Ninguna: el gramaje o el PVP tienen que moverse")),"") -> Cualquiera de las cuatro, incluida la que usas | Q16: ='Escenarios de Precio'!P16 -> 1.9788782 | R16: =IF(ISNUMBER($H16),IF($H16>'Parámetros'!$B$10,"ROTA: por encima de tu food cost máximo",IF($H16>'Parámetros'!$B$8,"Avisa: por encima del objetivo","Aguanta")),"") -> Aguanta
A17: BC2 | B17: Bombón de ganache de leche y vainilla | C17: ='Coste de Cobertura'!R17 -> 1.95 | D17: ='Coste de Cobertura'!T17 -> 1.7727273 | E17: ='Coste de Cobertura'!M17 -> 0.19073 | F17: ='Coste de Cobertura'!U17 -> 0.10759128 | G17: =IFERROR('Escenarios de Precio'!D17+'Escenarios de Precio'!C17*$C$8,"") -> 0.262022 | H17: =IFERROR($G17/$D17,"") -> 0.14780728 | I17: =IFERROR($G17/'Parámetros'!$B$8,"") -> 0.87340667 | J17: =IFERROR($I17*(1+'Coste de Cobertura'!S17),"") -> 0.96074733 | K17: =IFERROR($J17-$C17,"") -> -0.98925267 | L17: =IFERROR($J17/$C17-1,"") -> -0.50730906 | M17: =IFERROR(($D17*'Parámetros'!$B$8-'Escenarios de Precio'!D17)/('Coste de Cobertura'!J17*$C$8)*1000,"") -> 19.022644 | N17: =IFERROR(1-$M17/'Coste de Cobertura'!G17,"") -> -1.0812521 | O17: =IFERROR(($D17*'Parámetros'!$B$8-'Escenarios de Precio'!D17)/('Coste de Cobertura'!G17/1000),"") -> 56.818182 | P17: =IF(ISNUMBER($O17),IF($O17>=MAX('Coste de Cobertura'!G$7:G$10),"Cualquiera de las cuatro, incluida la que usas",IF($O17>=MIN('Coste de Cobertura'!G$7:G$10),"Sólo alguna de las más baratas: compáralas arriba","Ninguna: el gramaje o el PVP tienen que moverse")),"") -> Cualquiera de las cuatro, incluida la que usas | Q17: ='Escenarios de Precio'!P17 -> 2.3066314 | R17: =IF(ISNUMBER($H17),IF($H17>'Parámetros'!$B$10,"ROTA: por encima de tu food cost máximo",IF($H17>'Parámetros'!$B$8,"Avisa: por encima del objetivo","Aguanta")),"") -> Aguanta
A18: BC3 | B18: Bombón de praliné de avellana | C18: ='Coste de Cobertura'!R18 -> 2.1 | D18: ='Coste de Cobertura'!T18 -> 1.9090909 | E18: ='Coste de Cobertura'!M18 -> 0.21342 | F18: ='Coste de Cobertura'!U18 -> 0.11179143 | G18: =IFERROR('Escenarios de Precio'!D18+'Escenarios de Precio'!C18*$C$8,"") -> 0.267708 | H18: =IFERROR($G18/$D18,"") -> 0.140228 | I18: =IFERROR($G18/'Parámetros'!$B$8,"") -> 0.89236 | J18: =IFERROR($I18*(1+'Coste de Cobertura'!S18),"") -> 0.981596 | K18: =IFERROR($J18-$C18,"") -> -1.118404 | L18: =IFERROR($J18/$C18-1,"") -> -0.53257333 | M18: =IFERROR(($D18*'Parámetros'!$B$8-'Escenarios de Precio'!D18)/('Coste de Cobertura'!J18*$C$8)*1000,"") -> 18.132867 | N18: =IFERROR(1-$M18/'Coste de Cobertura'!G18,"") -> -1.605297 | O18: =IFERROR(($D18*'Parámetros'!$B$8-'Escenarios de Precio'!D18)/('Coste de Cobertura'!G18/1000),"") -> 71.124608 | P18: =IF(ISNUMBER($O18),IF($O18>=MAX('Coste de Cobertura'!G$7:G$10),"Cualquiera de las cuatro, incluida la que usas",IF($O18>=MIN('Coste de Cobertura'!G$7:G$10),"Sólo alguna de las más baratas: compáralas arriba","Ninguna: el gramaje o el PVP tienen que moverse")),"") -> Cualquiera de las cuatro, incluida la que usas | Q18: ='Escenarios de Precio'!P18 -> 3.2522707 | R18: =IF(ISNUMBER($H18),IF($H18>'Parámetros'!$B$10,"ROTA: por encima de tu food cost máximo",IF($H18>'Parámetros'!$B$8,"Avisa: por encima del objetivo","Aguanta")),"") -> Aguanta
A19: BC4 | B19: Bombón de gianduja de avellana | C19: ='Coste de Cobertura'!R19 -> 2.1 | D19: ='Coste de Cobertura'!T19 -> 1.9090909 | E19: ='Coste de Cobertura'!M19 -> 0.2243 | F19: ='Coste de Cobertura'!U19 -> 0.11749048 | G19: =IFERROR('Escenarios de Precio'!D19+'Escenarios de Precio'!C19*$C$8,"") -> 0.28514 | H19: =IFERROR($G19/$D19,"") -> 0.14935905 | I19: =IFERROR($G19/'Parámetros'!$B$8,"") -> 0.95046667 | J19: =IFERROR($I19*(1+'Coste de Cobertura'!S19),"") -> 1.0455133 | K19: =IFERROR($J19-$C19,"") -> -1.0544867 | L19: =IFERROR($J19/$C19-1,"") -> -0.50213651 | M19: =IFERROR(($D19*'Parámetros'!$B$8-'Escenarios de Precio'!D19)/('Coste de Cobertura'!J19*$C$8)*1000,"") -> 18.334332 | N19: =IFERROR(1-$M19/'Coste de Cobertura'!G19,"") -> -1.3505554 | O19: =IFERROR(($D19*'Parámetros'!$B$8-'Escenarios de Precio'!D19)/('Coste de Cobertura'!G19/1000),"") -> 64.170163 | P19: =IF(ISNUMBER($O19),IF($O19>=MAX('Coste de Cobertura'!G$7:G$10),"Cualquiera de las cuatro, incluida la que usas",IF($O19>=MIN('Coste de Cobertura'!G$7:G$10),"Sólo alguna de las más baratas: compáralas arriba","Ninguna: el gramaje o el PVP tienen que moverse")),"") -> Cualquiera de las cuatro, incluida la que usas | Q19: ='Escenarios de Precio'!P19 -> 2.8304943 | R19: =IF(ISNUMBER($H19),IF($H19>'Parámetros'!$B$10,"ROTA: por encima de tu food cost máximo",IF($H19>'Parámetros'!$B$8,"Avisa: por encima del objetivo","Aguanta")),"") -> Aguanta
A20: BC5 | B20: Trufa de chocolate negro al cacao | C20: ='Coste de Cobertura'!R20 -> 1.9 | D20: ='Coste de Cobertura'!T20 -> 1.7272727 | E20: ='Coste de Cobertura'!M20 -> 0.21812473 | F20: ='Coste de Cobertura'!U20 -> 0.12628274 | G20: =IFERROR('Escenarios de Precio'!D20+'Escenarios de Precio'!C20*$C$8,"") -> 0.29873462 | H20: =IFERROR($G20/$D20,"") -> 0.17295162 | I20: =IFERROR($G20/'Parámetros'!$B$8,"") -> 0.99578206 | J20: =IFERROR($I20*(1+'Coste de Cobertura'!S20),"") -> 1.0953603 | K20: =IFERROR($J20-$C20,"") -> -0.80463973 | L20: =IFERROR($J20/$C20-1,"") -> -0.4234946 | M20: =IFERROR(($D20*'Parámetros'!$B$8-'Escenarios de Precio'!D20)/('Coste de Cobertura'!J20*$C$8)*1000,"") -> 15.751399 | N20: =IFERROR(1-$M20/'Coste de Cobertura'!G20,"") -> -0.77781026 | O20: =IFERROR(($D20*'Parámetros'!$B$8-'Escenarios de Precio'!D20)/('Coste de Cobertura'!G20/1000),"") -> 56.611943 | P20: =IF(ISNUMBER($O20),IF($O20>=MAX('Coste de Cobertura'!G$7:G$10),"Cualquiera de las cuatro, incluida la que usas",IF($O20>=MIN('Coste de Cobertura'!G$7:G$10),"Sólo alguna de las más baratas: compáralas arriba","Ninguna: el gramaje o el PVP tienen que moverse")),"") -> Cualquiera de las cuatro, incluida la que usas | Q20: ='Escenarios de Precio'!P20 -> 1.7974911 | R20: =IF(ISNUMBER($H20),IF($H20>'Parámetros'!$B$10,"ROTA: por encima de tu food cost máximo",IF($H20>'Parámetros'!$B$8,"Avisa: por encima del objetivo","Aguanta")),"") -> Aguanta
A21: BC6 | B21: Bombón de licor de ron | C21: ='Coste de Cobertura'!R21 -> 2.3 | D21: ='Coste de Cobertura'!T21 -> 2.0909091 | E21: ='Coste de Cobertura'!M21 -> 0.17287273 | F21: ='Coste de Cobertura'!U21 -> 0.082678261 | G21: =IFERROR('Escenarios de Precio'!D21+'Escenarios de Precio'!C21*$C$8,"") -> 0.22746182 | H21: =IFERROR($G21/$D21,"") -> 0.10878609 | I21: =IFERROR($G21/'Parámetros'!$B$8,"") -> 0.75820606 | J21: =IFERROR($I21*(1+'Coste de Cobertura'!S21),"") -> 0.83402667 | K21: =IFERROR($J21-$C21,"") -> -1.4659733 | L21: =IFERROR($J21/$C21-1,"") -> -0.63737971 | M21: =IFERROR(($D21*'Parámetros'!$B$8-'Escenarios de Precio'!D21)/('Coste de Cobertura'!J21*$C$8)*1000,"") -> 18.555441 | N21: =IFERROR(1-$M21/'Coste de Cobertura'!G21,"") -> -2.0925736 | O21: =IFERROR(($D21*'Parámetros'!$B$8-'Escenarios de Precio'!D21)/('Coste de Cobertura'!G21/1000),"") -> 98.478788 | P21: =IF(ISNUMBER($O21),IF($O21>=MAX('Coste de Cobertura'!G$7:G$10),"Cualquiera de las cuatro, incluida la que usas",IF($O21>=MIN('Coste de Cobertura'!G$7:G$10),"Sólo alguna de las más baratas: compáralas arriba","Ninguna: el gramaje o el PVP tienen que moverse")),"") -> Cualquiera de las cuatro, incluida la que usas | Q21: ='Escenarios de Precio'!P21 -> 3.8811617 | R21: =IF(ISNUMBER($H21),IF($H21>'Parámetros'!$B$10,"ROTA: por encima de tu food cost máximo",IF($H21>'Parámetros'!$B$8,"Avisa: por encima del objetivo","Aguanta")),"") -> Aguanta
A22: BC7 | B22: Bombón de caramelo salado | C22: ='Coste de Cobertura'!R22 -> 2 | D22: ='Coste de Cobertura'!T22 -> 1.8181818 | E22: ='Coste de Cobertura'!M22 -> 0.13315 | F22: ='Coste de Cobertura'!U22 -> 0.0732325 | G22: =IFERROR('Escenarios de Precio'!D22+'Escenarios de Precio'!C22*$C$8,"") -> 0.17605 | H22: =IFERROR($G22/$D22,"") -> 0.0968275 | I22: =IFERROR($G22/'Parámetros'!$B$8,"") -> 0.58683333 | J22: =IFERROR($I22*(1+'Coste de Cobertura'!S22),"") -> 0.64551667 | K22: =IFERROR($J22-$C22,"") -> -1.3544833 | L22: =IFERROR($J22/$C22-1,"") -> -0.67724167 | M22: =IFERROR(($D22*'Parámetros'!$B$8-'Escenarios de Precio'!D22)/('Coste de Cobertura'!J22*$C$8)*1000,"") -> 19.031302 | N22: =IFERROR(1-$M22/'Coste de Cobertura'!G22,"") -> -2.4602367 | O22: =IFERROR(($D22*'Parámetros'!$B$8-'Escenarios de Precio'!D22)/('Coste de Cobertura'!G22/1000),"") -> 94.464463 | P22: =IF(ISNUMBER($O22),IF($O22>=MAX('Coste de Cobertura'!G$7:G$10),"Cualquiera de las cuatro, incluida la que usas",IF($O22>=MIN('Coste de Cobertura'!G$7:G$10),"Sólo alguna de las más baratas: compáralas arriba","Ninguna: el gramaje o el PVP tienen que moverse")),"") -> Cualquiera de las cuatro, incluida la que usas | Q22: ='Escenarios de Precio'!P22 -> 4.5139648 | R22: =IF(ISNUMBER($H22),IF($H22>'Parámetros'!$B$10,"ROTA: por encima de tu food cost máximo",IF($H22>'Parámetros'!$B$8,"Avisa: por encima del objetivo","Aguanta")),"") -> Aguanta
A23: BC8 | B23: Bombón de praliné de cacahuete | C23: ='Coste de Cobertura'!R23 -> 1.95 | D23: ='Coste de Cobertura'!T23 -> 1.7727273 | E23: ='Coste de Cobertura'!M23 -> 0.18659 | F23: ='Coste de Cobertura'!U23 -> 0.1052559 | G23: =IFERROR('Escenarios de Precio'!D23+'Escenarios de Precio'!C23*$C$8,"") -> 0.239786 | H23: =IFERROR($G23/$D23,"") -> 0.1352639 | I23: =IFERROR($G23/'Parámetros'!$B$8,"") -> 0.79928667 | J23: =IFERROR($I23*(1+'Coste de Cobertura'!S23),"") -> 0.87921533 | K23: =IFERROR($J23-$C23,"") -> -1.0707847 | L23: =IFERROR($J23/$C23-1,"") -> -0.54912034 | M23: =IFERROR(($D23*'Parámetros'!$B$8-'Escenarios de Precio'!D23)/('Coste de Cobertura'!J23*$C$8)*1000,"") -> 17.51715 | N23: =IFERROR(1-$M23/'Coste de Cobertura'!G23,"") -> -1.568497 | O23: =IFERROR(($D23*'Parámetros'!$B$8-'Escenarios de Precio'!D23)/('Coste de Cobertura'!G23/1000),"") -> 70.119968 | P23: =IF(ISNUMBER($O23),IF($O23>=MAX('Coste de Cobertura'!G$7:G$10),"Cualquiera de las cuatro, incluida la que usas",IF($O23>=MIN('Coste de Cobertura'!G$7:G$10),"Sólo alguna de las más baratas: compáralas arriba","Ninguna: el gramaje o el PVP tienen que moverse")),"") -> Cualquiera de las cuatro, incluida la que usas | Q23: ='Escenarios de Precio'!P23 -> 3.1690763 | R23: =IF(ISNUMBER($H23),IF($H23>'Parámetros'!$B$10,"ROTA: por encima de tu food cost máximo",IF($H23>'Parámetros'!$B$8,"Avisa: por encima del objetivo","Aguanta")),"") -> Aguanta
A24: BC9 | B24: Bombón crujiente de sésamo y barquillo | C24: ='Coste de Cobertura'!R24 -> 2.05 | D24: ='Coste de Cobertura'!T24 -> 1.8636364 | E24: ='Coste de Cobertura'!M24 -> 0.19046 | F24: ='Coste de Cobertura'!U24 -> 0.10219805 | G24: =IFERROR('Escenarios de Precio'!D24+'Escenarios de Precio'!C24*$C$8,"") -> 0.253484 | H24: =IFERROR($G24/$D24,"") -> 0.1360158 | I24: =IFERROR($G24/'Parámetros'!$B$8,"") -> 0.84494667 | J24: =IFERROR($I24*(1+'Coste de Cobertura'!S24),"") -> 0.92944133 | K24: =IFERROR($J24-$C24,"") -> -1.1205587 | L24: =IFERROR($J24/$C24-1,"") -> -0.54661398 | M24: =IFERROR(($D24*'Parámetros'!$B$8-'Escenarios de Precio'!D24)/('Coste de Cobertura'!J24*$C$8)*1000,"") -> 19.274392 | N24: =IFERROR(1-$M24/'Coste de Cobertura'!G24,"") -> -1.3854446 | O24: =IFERROR(($D24*'Parámetros'!$B$8-'Escenarios de Precio'!D24)/('Coste de Cobertura'!G24/1000),"") -> 65.122637 | P24: =IF(ISNUMBER($O24),IF($O24>=MAX('Coste de Cobertura'!G$7:G$10),"Cualquiera de las cuatro, incluida la que usas",IF($O24>=MIN('Coste de Cobertura'!G$7:G$10),"Sólo alguna de las más baratas: compáralas arriba","Ninguna: el gramaje o el PVP tienen que moverse")),"") -> Cualquiera de las cuatro, incluida la que usas | Q24: ='Escenarios de Precio'!P24 -> 2.848231 | R24: =IF(ISNUMBER($H24),IF($H24>'Parámetros'!$B$10,"ROTA: por encima de tu food cost máximo",IF($H24>'Parámetros'!$B$8,"Avisa: por encima del objetivo","Aguanta")),"") -> Aguanta
A25: BC10 | B25: Bombón de naranja confitada y chocolate negro | C25: ='Coste de Cobertura'!R25 -> 2.05 | D25: ='Coste de Cobertura'!T25 -> 1.8636364 | E25: ='Coste de Cobertura'!M25 -> 0.21838127 | F25: ='Coste de Cobertura'!U25 -> 0.1171802 | G25: =IFERROR('Escenarios de Precio'!D25+'Escenarios de Precio'!C25*$C$8,"") -> 0.29089378 | H25: =IFERROR($G25/$D25,"") -> 0.15608935 | I25: =IFERROR($G25/'Parámetros'!$B$8,"") -> 0.96964594 | J25: =IFERROR($I25*(1+'Coste de Cobertura'!S25),"") -> 1.0666105 | K25: =IFERROR($J25-$C25,"") -> -0.98338947 | L25: =IFERROR($J25/$C25-1,"") -> -0.47970218 | M25: =IFERROR(($D25*'Parámetros'!$B$8-'Escenarios de Precio'!D25)/('Coste de Cobertura'!J25*$C$8)*1000,"") -> 16.392315 | N25: =IFERROR(1-$M25/'Coste de Cobertura'!G25,"") -> -1.0567522 | O25: =IFERROR(($D25*'Parámetros'!$B$8-'Escenarios de Precio'!D25)/('Coste de Cobertura'!G25/1000),"") -> 65.494468 | P25: =IF(ISNUMBER($O25),IF($O25>=MAX('Coste de Cobertura'!G$7:G$10),"Cualquiera de las cuatro, incluida la que usas",IF($O25>=MIN('Coste de Cobertura'!G$7:G$10),"Sólo alguna de las más baratas: compáralas arriba","Ninguna: el gramaje o el PVP tienen que moverse")),"") -> Cualquiera de las cuatro, incluida la que usas | Q25: ='Escenarios de Precio'!P25 -> 2.2135647 | R25: =IF(ISNUMBER($H25),IF($H25>'Parámetros'!$B$10,"ROTA: por encima de tu food cost máximo",IF($H25>'Parámetros'!$B$8,"Avisa: por encima del objetivo","Aguanta")),"") -> Aguanta
A26: TB1 | B26: Tableta de chocolate negro de origen 70 %, 100 g | C26: ='Coste de Cobertura'!R26 -> 8.5 | D26: ='Coste de Cobertura'!T26 -> 7.7272727 | E26: ='Coste de Cobertura'!M26 -> 3.748 | F26: ='Coste de Cobertura'!U26 -> 0.48503529 | G26: =IFERROR('Escenarios de Precio'!D26+'Escenarios de Precio'!C26*$C$8,"") -> 5.2472 | H26: =IFERROR($G26/$D26,"") -> 0.67904941 | I26: =IFERROR($G26/'Parámetros'!$B$8,"") -> 17.490667 | J26: =IFERROR($I26*(1+'Coste de Cobertura'!S26),"") -> 19.239733 | K26: =IFERROR($J26-$C26,"") -> 10.739733 | L26: =IFERROR($J26/$C26-1,"") -> 1.263498 | M26: =IFERROR(($D26*'Parámetros'!$B$8-'Escenarios de Precio'!D26)/('Coste de Cobertura'!J26*$C$8)*1000,"") -> 44.179407 | N26: =IFERROR(1-$M26/'Coste de Cobertura'!G26,"") -> 0.55820593 | O26: =IFERROR(($D26*'Parámetros'!$B$8-'Escenarios de Precio'!D26)/('Coste de Cobertura'!G26/1000),"") -> 23.181818 | P26: =IF(ISNUMBER($O26),IF($O26>=MAX('Coste de Cobertura'!G$7:G$10),"Cualquiera de las cuatro, incluida la que usas",IF($O26>=MIN('Coste de Cobertura'!G$7:G$10),"Sólo alguna de las más baratas: compáralas arriba","Ninguna: el gramaje o el PVP tienen que moverse")),"") -> Sólo alguna de las más baratas: compáralas arriba | Q26: ='Escenarios de Precio'!P26 -> -0.285619 | R26: =IF(ISNUMBER($H26),IF($H26>'Parámetros'!$B$10,"ROTA: por encima de tu food cost máximo",IF($H26>'Parámetros'!$B$8,"Avisa: por encima del objetivo","Aguanta")),"") -> ROTA: por encima de tu food cost máximo
A27: TB2 | B27: Tableta de chocolate con leche 38 %, 100 g | C27: ='Coste de Cobertura'!R27 -> 5.9 | D27: ='Coste de Cobertura'!T27 -> 5.3636364 | E27: ='Coste de Cobertura'!M27 -> 1.95 | F27: ='Coste de Cobertura'!U27 -> 0.36355932 | G27: =IFERROR('Escenarios de Precio'!D27+'Escenarios de Precio'!C27*$C$8,"") -> 2.73 | H27: =IFERROR($G27/$D27,"") -> 0.50898305 | I27: =IFERROR($G27/'Parámetros'!$B$8,"") -> 9.1 | J27: =IFERROR($I27*(1+'Coste de Cobertura'!S27),"") -> 10.01 | K27: =IFERROR($J27-$C27,"") -> 4.11 | L27: =IFERROR($J27/$C27-1,"") -> 0.69661017 | M27: =IFERROR(($D27*'Parámetros'!$B$8-'Escenarios de Precio'!D27)/('Coste de Cobertura'!J27*$C$8)*1000,"") -> 58.941059 | N27: =IFERROR(1-$M27/'Coste de Cobertura'!G27,"") -> 0.41058941 | O27: =IFERROR(($D27*'Parámetros'!$B$8-'Escenarios de Precio'!D27)/('Coste de Cobertura'!G27/1000),"") -> 16.090909 | P27: =IF(ISNUMBER($O27),IF($O27>=MAX('Coste de Cobertura'!G$7:G$10),"Cualquiera de las cuatro, incluida la que usas",IF($O27>=MIN('Coste de Cobertura'!G$7:G$10),"Sólo alguna de las más baratas: compáralas arriba","Ninguna: el gramaje o el PVP tienen que moverse")),"") -> Ninguna: el gramaje o el PVP tienen que moverse | Q27: ='Escenarios de Precio'!P27 -> -0.046923077 | R27: =IF(ISNUMBER($H27),IF($H27>'Parámetros'!$B$10,"ROTA: por encima de tu food cost máximo",IF($H27>'Parámetros'!$B$8,"Avisa: por encima del objetivo","Aguanta")),"") -> ROTA: por encima de tu food cost máximo
... A43: CJ4 | B43: Estuche corporativo personalizado de 24 bombones | C43: ='Coste de Cobertura'!R43 -> 34 | D43: ='Coste de Cobertura'!T43 -> 30.909091 | E43: ='Coste de Cobertura'!M43 -> 4.726425 | F43: ='Coste de Cobertura'!U43 -> 0.15291375 | G43: =IFERROR('Escenarios de Precio'!D43+'Escenarios de Precio'!C43*$C$8,"") -> 6.164355 | H43: =IFERROR($G43/$D43,"") -> 0.19943501 | I43: =IFERROR($G43/'Parámetros'!$B$8,"") -> 20.54785 | J43: =IFERROR($I43*(1+'Coste de Cobertura'!S43),"") -> 22.602635 | K43: =IFERROR($J43-$C43,"") -> -11.397365 | L43: =IFERROR($J43/$C43-1,"") -> -0.33521662 | M43: =IFERROR(($D43*'Parámetros'!$B$8-'Escenarios de Precio'!D43)/('Coste de Cobertura'!J43*$C$8)*1000,"") -> 298.20979 | N43: =IFERROR(1-$M43/'Coste de Cobertura'!G43,"") -> -0.61762837 | O43: =IFERROR(($D43*'Parámetros'!$B$8-'Escenarios de Precio'!D43)/('Coste de Cobertura'!G43/1000),"") -> 44.161255 | P43: =IF(ISNUMBER($O43),IF($O43>=MAX('Coste de Cobertura'!G$7:G$10),"Cualquiera de las cuatro, incluida la que usas",IF($O43>=MIN('Coste de Cobertura'!G$7:G$10),"Sólo alguna de las más baratas: compáralas arriba","Ninguna: el gramaje o el PVP tienen que moverse")),"") -> Cualquiera de las cuatro, incluida la que usas | Q43: ='Escenarios de Precio'!P43 -> 1.6795438 | R43: =IF(ISNUMBER($H43),IF($H43>'Parámetros'!$B$10,"ROTA: por encima de tu food cost máximo",IF($H43>'Parámetros'!$B$8,"Avisa: por encima del objetivo","Aguanta")),"") -> Aguanta
A45: La Referencia que Primero se Rompe
