Workbook

Sheet Instrucciones
A1: Vida Útil de los Rellenos y Rotación
A2: AI Chef Pro · aichef.pro — Cómo Montar una Chocolatería
A3: Celdas verdes = campos editables
A5: Qué Decide Este Libro
A6: Cuánto dura cada referencia, en qué mueble va, con qué papel legal la despachas y de cuánto haces cada tanda. Y, sobre todo, lo que te cuesta al año equivocarte de tamaño de lote: eso es la merma por caducidad, y casi nadie la mide.
A8: La Regla que Manda: la Vida Útil la Declaras Tú
A9: No existe una tabla legal con la vida útil del chocolate. La vida útil de tu producto la fijas TÚ y consta en tu plan de APPCC, con el criterio que puedas defender. Por eso la columna «vida útil que TÚ declaras» es una celda verde y NUNCA la calcula el libro: lo que ves escrito es un valor de partida tomado del extremo bajo del plazo orientativo del kit, para que la hoja funcione desde el primer minuto.
A11: Frontera con el Kit de Tareas Chocolatería
A12: Los diez plazos orientativos por familia son los del Kit de Tareas Chocolatería (12 €), fichero 02-partidas-produccion.xlsx, hoja Moldeado. Esta guía los CITA y no los reescribe: lo que construye es lo que el kit no tiene -la actividad de agua por tipo de relleno, la decisión de etiqueta o granel, el tamaño de lote y la merma por caducidad en euros al año-. Si tienes el kit, ten su tabla al lado; si no lo tienes, aquí está citada fila a fila.
A14: Etiqueta o Granel: No Es el Mismo Papel
A15: Si la referencia sale ENVASADA con su etiqueta, la temperatura de conservación que tú has escrito en esa etiqueta te obliga a ti (art. 4.2 del RD 1021/2022). Si se despacha A GRANEL en la vitrina no hay etiqueta, así que la referencia no es ese artículo: es tu propio sistema de autocontrol, donde la temperatura y la vida útil las declaras tú. No hay una «temperatura legal del chocolate»: el RD 1021/2022 no nombra el chocolate ni una sola vez.
A17: Las Hojas, y Qué Hace Cada Una
A18: Parámetros | B18: El volumen de venta, los umbrales que tú te pones y los dos costes con los que se calcula el lote. Nada de esto está escrito dentro de una fórmula.
A19: Tipo de Relleno y aw | B19: El agua disponible de cada relleno, que es lo que de verdad separa una ganache de diez días de una de dos meses. Se mide con higrómetro; mientras no la midas, es una estimación tuya y la hoja lo dice.
A20: Vida Útil Declarada | B20: La vida útil que TÚ declaras, al lado del plazo orientativo del kit, y la fecha que va a ir en la etiqueta. Con el aviso de las cajas: un surtido caduca con su pieza más corta.
A21: Etiquetado o Granel | B21: Envasado con etiqueta o a granel, referencia a referencia, y qué te toca en cada caso. La salida cambia de columna: no son dos formas de decir lo mismo.
A22: Temperatura y Vitrina | B22: Las cinco temperaturas del kit, el rango de trabajo de TU vitrina y la temperatura que declaras para cada referencia. El semáforo sólo se enciende por encima de 20 °C.
A23: Lote y Merma por Caducidad | B23: De cuánto haces cada tanda, cuánto vendes dentro de la vida útil y lo que se te caduca al año en euros. Es la hoja que paga este libro.
A25: Cada Cuánto Se Usa
A26: La hoja de vida útil y la de etiqueta o granel se revisan cada vez que entra o sale una referencia de la carta, y cuando cambias una formulación. La de lote y merma, una vez al mes con las ventas reales del TPV delante: es la que te dice si estás moldeando tandas que no vendes.
A28: De Dónde Salen los Números del Ejemplo
A29: Las actividades de agua son SUPUESTOS declarados: la aw se mide, y hasta que la midas no es un dato. Los plazos orientativos son los del kit, citados. El coste de materia por pieza es el del caso de ejemplo «La Almendra» y sale del libro 3 (precio de la cobertura) y del libro 4 (escandallo): aquí entra como celda verde, no como fórmula entre ficheros, así que si cambias el escandallo tienes que traerlo a mano.
A31: Para editar la estructura o una celda que no esté en verde: Revisar > Desproteger hoja (no tiene contraseña).
A33: Diseñado por John Guerrero — chef y consultor gastronómico desde 2010, en cocina desde los 17 años.
A34: Versión 1.0 · septiembre 2026 · aichef.pro/guia-chocolateria-obrador · info@aichef.pro

Sheet Parámetros
A1: Parámetros
A2: AI Chef Pro · aichef.pro — Cómo Montar una Chocolatería
A3: Los umbrales de este libro te los pones TÚ: ninguno es un límite legal, y la hoja lo dice en cada nota.
A5: Parámetro | B5: Valor | C5: Unidad | D5: De dónde sale | E5: Nota
A6: Clientes al día en velocidad de crucero | B6: 67 | C6: tickets/día | D6: supuesto | E6: Clientes por día en velocidad de crucero. NO es un dato del sector: `N-13` prohíbe publicar un ticket medio de chocolatería o un reparto mensual de ventas como dato, porque no existe dato publico. La guía enseña a medirlo con el TPV en dos semanas. Esta calibrado para que el margen neto del año de crucero caiga entre el 9 % y el 11 %: por encima, el caso se lee como optimista y un refutador lo tumba con razón. Es la ÚNICA palanca que se toca para mover el margen; los costes no se maquillan.
A7: Piezas por ticket | B7: 1.4 | C7: piezas/ticket | D7: supuesto | E7: De aquí sale el ticket medio, que NO se teclea: se calcula como PVP medio ponderado de la carta x piezas por ticket. En bombonería es BAJO -1,4- porque la unidad de venta real es la caja, no la pieza: quien entra a por un regalo se lleva UNA caja de 20 euros, no ocho bombones sueltos.
A8: Días de apertura al año | B8: 304 | C8: días/año | D8: supuesto | E8: 6 días por semana x 52 semanas = 312, menos 8 días de cierre por festivos = 304. En agosto la TIENDA NO CIERRA: lo que para es el obrador (D36, y el literal del kit dice «la tienda abre para el turista aunque el obrador pare»). Una bombonería de menos de 300 m² tiene libertad horaria por el art. 5.2 de la Ley 1/2004, no por el 5.1 (`CHN-77`).
A9: Piezas vendibles al año | B9: =IFERROR('Parámetros'!$B$6*'Parámetros'!$B$7*'Parámetros'!$B$8,"") -> 28515.2 | C9: piezas/año | D9: calculado | E9: Clientes al día por piezas por ticket por días de apertura. Con el mix de cada referencia se reparte en ventas por semana, que es lo que gobierna el tamaño del lote.
A10: Semanas al año | B10: 52 | C10: semanas | D10: supuesto | E10: Se usa para pasar la venta anual a venta semanal y la vida útil de días a semanas.
A11: Umbral de vigilancia de actividad de agua (aw) | B11: 0.85 | C11: aw | D11: supuesto | E11: El punto a partir del cual TÚ decides tratar la referencia como producto de vida corta y refrigerada. NO es un límite legal ni un umbral microbiológico publicado: es tu criterio, y tiene que constar en tu plan de APPCC con el argumento que lo sostiene.
A12: Temperatura a la que salta la alarma de la vitrina | B12: 20 | C12: grados C | D12: kit 01-apertura-cierre.xlsx | E12: Es el punto en el que la manteca de cacao empieza a fundir, y el que publica el kit en su hoja de apertura. El semáforo de la vitrina SÓLO se enciende por encima de este número: los 16-18 °C de objetivo del propio kit no se ponen nunca en rojo.
A13: Humedad máxima de trabajo de la vitrina | B13: 55 | C13: % de HR | D13: kit 08-apertura-cierre-negocio.xlsx | E13: Objetivo del kit para la vitrina temperada: menos del 55 % antes de montar el género. Por encima, el bombón coge humedad y aparece el velo de azúcar.
A14: Coste de poner en marcha una tanda | B14: 35 | C14: €/tanda | D14: supuesto | E14: Lo que cuesta arrancar una tanda al margen de su tamaño: templar, preparar moldes, limpiar y cambiar de referencia. Es el número que empuja a hacer tandas grandes; la caducidad es el que las frena.
A15: Coste de tener una pieza parada un año | B15: 0.25 | C15: sobre su coste | D15: supuesto | E15: Financiación, espacio de cámara y riesgo, en porcentaje del coste de materia de la pieza. Es la otra mitad del cálculo del lote.
A16: Merma por caducidad a partir de la cual quieres un aviso | B16: 150 | C16: €/año | D16: supuesto | E16: Tu línea roja, no la de nadie más. Por encima de esta cifra la hoja de lote marca la referencia en rojo: no es que esté mal, es que ahí hay dinero que se está yendo a la basura.

Sheet Tipo de Relleno y aw
A1: Tipo de Relleno y Aw
A2: AI Chef Pro · aichef.pro — Cómo Montar una Chocolatería
A3: El agua disponible es lo que separa una ganache de diez días de una de dos meses. Se MIDE con un higrómetro de actividad de agua; mientras no la midas, lo que hay aquí es una estimación tuya, y así se marca.
A5: Qué Mide Esta Hoja
A6: La actividad de agua (aw) va de 0 a 1 y dice cuánta agua del relleno está DISPONIBLE para que crezca algo. No es la humedad: un praliné puede tener grasa de sobra y aw bajísima. Las dos palancas que la bajan son el azúcar y el alcohol, y son las que explican por qué la misma pieza dura tres o cinco veces más según cómo la formules. Esta hoja no calcula la aw: la recoge, la compara con el umbral que tú te has puesto y te dice de qué va a morir cada referencia.
A15: Id | B15: Referencia | C15: Familia de la carta | D15: Tipo de relleno | E15: aw | F15: Origen del dato | G15: Familia de vida útil del kit | H15: Plazo orientativo del kit | I15: De qué va a morir esta referencia | J15: Lo que dice el kit de esa familia
A16: BC1 | B16: Bombón de ganache de chocolate negro 70 % | C16: Bombones de colección | D16: Ganache de chocolate negro con nata fresca | E16: 0.88 | F16: estimada por ti | G16: Bombones de ganache con nata fresca | H16: 10-15 días | I16: =IF(ISNUMBER($E16),IF($E16>='Parámetros'!$B$11,"Agua disponible ALTA: trátala como producto de vida corta y en frío, y justifícalo en tu APPCC","Agua disponible baja: la vida la manda el rancio de la grasa y la humedad del ambiente, no el microbio"),"") -> Agua disponible ALTA: trátala como producto de vida corta y en frío, y justifícalo en tu APPCC | J16: Actividad de agua alta: en refrigeración a 0-4 °C y atemperar CERRADOS antes de abrir, o condensan
A17: BC2 | B17: Bombón de ganache de leche y vainilla | C17: Bombones de colección | D17: Ganache de chocolate con leche, nata UHT y sorbitol | E17: 0.82 | F17: estimada por ti | G17: Bombones de ganache con nata UHT, sorbato o alcohol | H17: 4-8 semanas | I17: =IF(ISNUMBER($E17),IF($E17>='Parámetros'!$B$11,"Agua disponible ALTA: trátala como producto de vida corta y en frío, y justifícalo en tu APPCC","Agua disponible baja: la vida la manda el rancio de la grasa y la humedad del ambiente, no el microbio"),"") -> Agua disponible baja: la vida la manda el rancio de la grasa y la humedad del ambiente, no el microbio | J17: El conservante y el alcohol bajan la actividad de agua; sin ellos no se llega ni a la mitad
A18: BC3 | B18: Bombón de praline de avellana | C18: Bombones de colección | D18: Praline de avellana | E18: 0.42 | F18: estimada por ti | G18: Bombones de praline, gianduja y frutos secos | H18: 2-4 meses | I18: =IF(ISNUMBER($E18),IF($E18>='Parámetros'!$B$11,"Agua disponible ALTA: trátala como producto de vida corta y en frío, y justifícalo en tu APPCC","Agua disponible baja: la vida la manda el rancio de la grasa y la humedad del ambiente, no el microbio"),"") -> Agua disponible baja: la vida la manda el rancio de la grasa y la humedad del ambiente, no el microbio | J18: La grasa del fruto seco se enrancia y el frío no lo evita: manda la fecha, no el aspecto
A19: BC4 | B19: Bombón de gianduja de avellana | C19: Bombones de colección | D19: Gianduja de avellana | E19: 0.38 | F19: estimada por ti | G19: Bombones de praline, gianduja y frutos secos | H19: 2-4 meses | I19: =IF(ISNUMBER($E19),IF($E19>='Parámetros'!$B$11,"Agua disponible ALTA: trátala como producto de vida corta y en frío, y justifícalo en tu APPCC","Agua disponible baja: la vida la manda el rancio de la grasa y la humedad del ambiente, no el microbio"),"") -> Agua disponible baja: la vida la manda el rancio de la grasa y la humedad del ambiente, no el microbio | J19: La grasa del fruto seco se enrancia y el frío no lo evita: manda la fecha, no el aspecto
A20: BC5 | B20: Trufa de chocolate negro al cacao | C20: Bombones de colección | D20: Trufa de chocolate negro | E20: 0.8 | F20: estimada por ti | G20: Trufas y rocas recubiertas | H20: 3-4 semanas | I20: =IF(ISNUMBER($E20),IF($E20>='Parámetros'!$B$11,"Agua disponible ALTA: trátala como producto de vida corta y en frío, y justifícalo en tu APPCC","Agua disponible baja: la vida la manda el rancio de la grasa y la humedad del ambiente, no el microbio"),"") -> Agua disponible baja: la vida la manda el rancio de la grasa y la humedad del ambiente, no el microbio | J20: Si llevan nata o mantequilla, se cuentan como ganache fresca
A21: BC6 | B21: Bombón de licor de ron | C21: Bombones de colección | D21: Licor cristalizado de ron | E21: 0.72 | F21: estimada por ti | G21: Bombones de licor y cristalizados | H21: 3-6 meses | I21: =IF(ISNUMBER($E21),IF($E21>='Parámetros'!$B$11,"Agua disponible ALTA: trátala como producto de vida corta y en frío, y justifícalo en tu APPCC","Agua disponible baja: la vida la manda el rancio de la grasa y la humedad del ambiente, no el microbio"),"") -> Agua disponible baja: la vida la manda el rancio de la grasa y la humedad del ambiente, no el microbio | J21: Vigilar la cristalización del azúcar en la cascara: revienta y gotea
A22: BC7 | B22: Bombón de caramelo salado | C22: Bombones de colección | D22: Caramelo salado | E22: 0.68 | F22: estimada por ti | G22: Bombones de ganache con nata UHT, sorbato o alcohol | H22: 4-8 semanas | I22: =IF(ISNUMBER($E22),IF($E22>='Parámetros'!$B$11,"Agua disponible ALTA: trátala como producto de vida corta y en frío, y justifícalo en tu APPCC","Agua disponible baja: la vida la manda el rancio de la grasa y la humedad del ambiente, no el microbio"),"") -> Agua disponible baja: la vida la manda el rancio de la grasa y la humedad del ambiente, no el microbio | J22: El conservante y el alcohol bajan la actividad de agua; sin ellos no se llega ni a la mitad
A23: BC8 | B23: Bombón de praline de cacahuete | C23: Bombones de colección | D23: Praline de cacahuete | E23: 0.4 | F23: estimada por ti | G23: Bombones de praline, gianduja y frutos secos | H23: 2-4 meses | I23: =IF(ISNUMBER($E23),IF($E23>='Parámetros'!$B$11,"Agua disponible ALTA: trátala como producto de vida corta y en frío, y justifícalo en tu APPCC","Agua disponible baja: la vida la manda el rancio de la grasa y la humedad del ambiente, no el microbio"),"") -> Agua disponible baja: la vida la manda el rancio de la grasa y la humedad del ambiente, no el microbio | J23: La grasa del fruto seco se enrancia y el frío no lo evita: manda la fecha, no el aspecto
A24: BC9 | B24: Bombón crujiente de sesamo y barquillo | C24: Bombones de colección | D24: Crujiente de sesamo y barquillo | E24: 0.28 | F24: estimada por ti | G24: Barquillos y crujientes banados | H24: 3-4 semanas | I24: =IF(ISNUMBER($E24),IF($E24>='Parámetros'!$B$11,"Agua disponible ALTA: trátala como producto de vida corta y en frío, y justifícalo en tu APPCC","Agua disponible baja: la vida la manda el rancio de la grasa y la humedad del ambiente, no el microbio"),"") -> Agua disponible baja: la vida la manda el rancio de la grasa y la humedad del ambiente, no el microbio | J24: Pierden el crujiente mucho antes que la seguridad: se retiran por calidad
A25: BC10 | B25: Bombón de naranja confitada y chocolate negro | C25: Bombones de colección | D25: Naranja confitada | E25: 0.65 | F25: estimada por ti | G25: Frutos secos garrapinados y frutas confitadas banadas | H25: 1-3 meses | I25: =IF(ISNUMBER($E25),IF($E25>='Parámetros'!$B$11,"Agua disponible ALTA: trátala como producto de vida corta y en frío, y justifícalo en tu APPCC","Agua disponible baja: la vida la manda el rancio de la grasa y la humedad del ambiente, no el microbio"),"") -> Agua disponible baja: la vida la manda el rancio de la grasa y la humedad del ambiente, no el microbio | J25: Se apelmazan con la humedad; envasado hermetico con desecante si tu obrador es humedo
A26: TB1 | B26: Tableta de chocolate negro de origen 70 %, 100 g | C26: Tabletas | D26: Sin relleno: chocolate templado | E26: 0.4 | F26: estimada por ti | G26: Tabletas y chocolate sin relleno | H26: 12-18 meses | I26: =IF(ISNUMBER($E26),IF($E26>='Parámetros'!$B$11,"Agua disponible ALTA: trátala como producto de vida corta y en frío, y justifícalo en tu APPCC","Agua disponible baja: la vida la manda el rancio de la grasa y la humedad del ambiente, no el microbio"),"") -> Agua disponible baja: la vida la manda el rancio de la grasa y la humedad del ambiente, no el microbio | J26: El enemigo no es el tiempo: es la humedad, la luz y los olores. Sellado y en oscuridad
A27: TB2 | B27: Tableta de chocolate con leche 38 %, 100 g | C27: Tabletas | D27: Sin relleno: chocolate templado | E27: 0.4 | F27: estimada por ti | G27: Tabletas y chocolate sin relleno | H27: 12-18 meses | I27: =IF(ISNUMBER($E27),IF($E27>='Parámetros'!$B$11,"Agua disponible ALTA: trátala como producto de vida corta y en frío, y justifícalo en tu APPCC","Agua disponible baja: la vida la manda el rancio de la grasa y la humedad del ambiente, no el microbio"),"") -> Agua disponible baja: la vida la manda el rancio de la grasa y la humedad del ambiente, no el microbio | J27: El enemigo no es el tiempo: es la humedad, la luz y los olores. Sellado y en oscuridad
... A43: CJ4 | B43: Estuche corporativo personalizado de 24 bombones | C43: Cajas y regalo | D43: Surtido: varias piezas con rellenos distintos | E43: 0.88 | F43: estimada por ti | G43: Bombones de ganache con nata fresca | H43: 10-15 días | I43: =IF(ISNUMBER($E43),IF($E43>='Parámetros'!$B$11,"Agua disponible ALTA: trátala como producto de vida corta y en frío, y justifícalo en tu APPCC","Agua disponible baja: la vida la manda el rancio de la grasa y la humedad del ambiente, no el microbio"),"") -> Agua disponible ALTA: trátala como producto de vida corta y en frío, y justifícalo en tu APPCC | J43: Actividad de agua alta: en refrigeración a 0-4 °C y atemperar CERRADOS antes de abrir, o condensan
A44: RECUENTO | B44: Referencias con el agua disponible por encima de tu umbral | E44: =COUNTIF(E16:E43,">="&'Parámetros'!$B$11) -> 6 | F44: Medidas de verdad: | G44: =COUNTIF(F16:F43,$A$62) -> 0 | I44: Mientras la segunda cifra sea cero, toda la columna de aw es una estimación: el higrómetro de actividad de agua es la compra que convierte esta hoja en un documento defendible.
A60: Listas de validación (no las borres: las usan los desplegables)
A61: Origen del dato
A62: medida con higrómetro
A63: estimada por ti

Sheet Vida Útil Declarada
A1: Vida Útil Declarada
A2: AI Chef Pro · aichef.pro — Cómo Montar una Chocolatería
A3: La vida útil la declaras TÚ y consta en tu plan de APPCC. Esta hoja NO la calcula: la recoge, la pone al lado del plazo orientativo del kit y te avisa si te has salido.
A5: La Tabla del Kit, Citada Fila a Fila
A6: Los diez plazos de abajo son los del Kit de Tareas Chocolatería, fichero 02-partidas-produccion.xlsx, hoja Moldeado, tabla «vida útil y conservación orientativas a 15-18 °C y 50-60 % de humedad». Son ORIENTATIVOS y de la casa, no de una norma: ninguna norma publica la vida útil del chocolate. La equivalencia en días de la columna E y F es aritmética nuestra -el kit escribe «4-8 semanas»- y está para que el semáforo pueda comparar.
A15: Id | B15: Referencia | C15: Familia de vida útil del kit | D15: Plazo orientativo del kit | E15: Equivalencia mínima (días) | F15: Equivalencia máxima (días) | G15: Vida útil que TÚ declaras (días) | H15: Tipo de fecha | I15: Fecha de elaboración | J15: Fecha que va en la etiqueta | K15: Vida útil (semanas) | L15: Pieza más corta del surtido (días) | M15: Veredicto
A16: BC1 | B16: Bombón de ganache de chocolate negro 70 % | C16: Bombones de ganache con nata fresca | D16: 10-15 días | E16: 10 | F16: 15 | G16: 10 | H16: caducidad | I16: 46279 | J16: =IFERROR($I16+$G16,"") -> 46289 | K16: =IFERROR($G16/7,"") -> 1.4285714 | M16: =IF(ISNUMBER($G16),IF(AND(ISNUMBER($L16),$G16>$L16),"Por encima de la pieza más corta que llevas dentro: un surtido caduca con ella",IF($G16>$F16,"Por encima del plazo orientativo del kit: sostenlo con analítica y con tu APPCC",IF($G16<$E16,"Por debajo del plazo del kit: conservador, y es decisión tuya","Dentro del plazo orientativo del kit"))),"") -> Dentro del plazo orientativo del kit
A17: BC2 | B17: Bombón de ganache de leche y vainilla | C17: Bombones de ganache con nata UHT, sorbato o alcohol | D17: 4-8 semanas | E17: 28 | F17: 56 | G17: 28 | H17: caducidad | I17: 46279 | J17: =IFERROR($I17+$G17,"") -> 46307 | K17: =IFERROR($G17/7,"") -> 4 | M17: =IF(ISNUMBER($G17),IF(AND(ISNUMBER($L17),$G17>$L17),"Por encima de la pieza más corta que llevas dentro: un surtido caduca con ella",IF($G17>$F17,"Por encima del plazo orientativo del kit: sostenlo con analítica y con tu APPCC",IF($G17<$E17,"Por debajo del plazo del kit: conservador, y es decisión tuya","Dentro del plazo orientativo del kit"))),"") -> Dentro del plazo orientativo del kit
A18: BC3 | B18: Bombón de praline de avellana | C18: Bombones de praline, gianduja y frutos secos | D18: 2-4 meses | E18: 60 | F18: 120 | G18: 60 | H18: consumo preferente | I18: 46279 | J18: =IFERROR($I18+$G18,"") -> 46339 | K18: =IFERROR($G18/7,"") -> 8.5714286 | M18: =IF(ISNUMBER($G18),IF(AND(ISNUMBER($L18),$G18>$L18),"Por encima de la pieza más corta que llevas dentro: un surtido caduca con ella",IF($G18>$F18,"Por encima del plazo orientativo del kit: sostenlo con analítica y con tu APPCC",IF($G18<$E18,"Por debajo del plazo del kit: conservador, y es decisión tuya","Dentro del plazo orientativo del kit"))),"") -> Dentro del plazo orientativo del kit
A19: BC4 | B19: Bombón de gianduja de avellana | C19: Bombones de praline, gianduja y frutos secos | D19: 2-4 meses | E19: 60 | F19: 120 | G19: 60 | H19: consumo preferente | I19: 46279 | J19: =IFERROR($I19+$G19,"") -> 46339 | K19: =IFERROR($G19/7,"") -> 8.5714286 | M19: =IF(ISNUMBER($G19),IF(AND(ISNUMBER($L19),$G19>$L19),"Por encima de la pieza más corta que llevas dentro: un surtido caduca con ella",IF($G19>$F19,"Por encima del plazo orientativo del kit: sostenlo con analítica y con tu APPCC",IF($G19<$E19,"Por debajo del plazo del kit: conservador, y es decisión tuya","Dentro del plazo orientativo del kit"))),"") -> Dentro del plazo orientativo del kit
A20: BC5 | B20: Trufa de chocolate negro al cacao | C20: Trufas y rocas recubiertas | D20: 3-4 semanas | E20: 21 | F20: 28 | G20: 21 | H20: caducidad | I20: 46279 | J20: =IFERROR($I20+$G20,"") -> 46300 | K20: =IFERROR($G20/7,"") -> 3 | M20: =IF(ISNUMBER($G20),IF(AND(ISNUMBER($L20),$G20>$L20),"Por encima de la pieza más corta que llevas dentro: un surtido caduca con ella",IF($G20>$F20,"Por encima del plazo orientativo del kit: sostenlo con analítica y con tu APPCC",IF($G20<$E20,"Por debajo del plazo del kit: conservador, y es decisión tuya","Dentro del plazo orientativo del kit"))),"") -> Dentro del plazo orientativo del kit
A21: BC6 | B21: Bombón de licor de ron | C21: Bombones de licor y cristalizados | D21: 3-6 meses | E21: 90 | F21: 180 | G21: 90 | H21: consumo preferente | I21: 46279 | J21: =IFERROR($I21+$G21,"") -> 46369 | K21: =IFERROR($G21/7,"") -> 12.857143 | M21: =IF(ISNUMBER($G21),IF(AND(ISNUMBER($L21),$G21>$L21),"Por encima de la pieza más corta que llevas dentro: un surtido caduca con ella",IF($G21>$F21,"Por encima del plazo orientativo del kit: sostenlo con analítica y con tu APPCC",IF($G21<$E21,"Por debajo del plazo del kit: conservador, y es decisión tuya","Dentro del plazo orientativo del kit"))),"") -> Dentro del plazo orientativo del kit
A22: BC7 | B22: Bombón de caramelo salado | C22: Bombones de ganache con nata UHT, sorbato o alcohol | D22: 4-8 semanas | E22: 28 | F22: 56 | G22: 28 | H22: caducidad | I22: 46279 | J22: =IFERROR($I22+$G22,"") -> 46307 | K22: =IFERROR($G22/7,"") -> 4 | M22: =IF(ISNUMBER($G22),IF(AND(ISNUMBER($L22),$G22>$L22),"Por encima de la pieza más corta que llevas dentro: un surtido caduca con ella",IF($G22>$F22,"Por encima del plazo orientativo del kit: sostenlo con analítica y con tu APPCC",IF($G22<$E22,"Por debajo del plazo del kit: conservador, y es decisión tuya","Dentro del plazo orientativo del kit"))),"") -> Dentro del plazo orientativo del kit
A23: BC8 | B23: Bombón de praline de cacahuete | C23: Bombones de praline, gianduja y frutos secos | D23: 2-4 meses | E23: 60 | F23: 120 | G23: 60 | H23: consumo preferente | I23: 46279 | J23: =IFERROR($I23+$G23,"") -> 46339 | K23: =IFERROR($G23/7,"") -> 8.5714286 | M23: =IF(ISNUMBER($G23),IF(AND(ISNUMBER($L23),$G23>$L23),"Por encima de la pieza más corta que llevas dentro: un surtido caduca con ella",IF($G23>$F23,"Por encima del plazo orientativo del kit: sostenlo con analítica y con tu APPCC",IF($G23<$E23,"Por debajo del plazo del kit: conservador, y es decisión tuya","Dentro del plazo orientativo del kit"))),"") -> Dentro del plazo orientativo del kit
A24: BC9 | B24: Bombón crujiente de sesamo y barquillo | C24: Barquillos y crujientes banados | D24: 3-4 semanas | E24: 21 | F24: 28 | G24: 21 | H24: caducidad | I24: 46279 | J24: =IFERROR($I24+$G24,"") -> 46300 | K24: =IFERROR($G24/7,"") -> 3 | M24: =IF(ISNUMBER($G24),IF(AND(ISNUMBER($L24),$G24>$L24),"Por encima de la pieza más corta que llevas dentro: un surtido caduca con ella",IF($G24>$F24,"Por encima del plazo orientativo del kit: sostenlo con analítica y con tu APPCC",IF($G24<$E24,"Por debajo del plazo del kit: conservador, y es decisión tuya","Dentro del plazo orientativo del kit"))),"") -> Dentro del plazo orientativo del kit
A25: BC10 | B25: Bombón de naranja confitada y chocolate negro | C25: Frutos secos garrapinados y frutas confitadas banadas | D25: 1-3 meses | E25: 30 | F25: 90 | G25: 30 | H25: caducidad | I25: 46279 | J25: =IFERROR($I25+$G25,"") -> 46309 | K25: =IFERROR($G25/7,"") -> 4.2857143 | M25: =IF(ISNUMBER($G25),IF(AND(ISNUMBER($L25),$G25>$L25),"Por encima de la pieza más corta que llevas dentro: un surtido caduca con ella",IF($G25>$F25,"Por encima del plazo orientativo del kit: sostenlo con analítica y con tu APPCC",IF($G25<$E25,"Por debajo del plazo del kit: conservador, y es decisión tuya","Dentro del plazo orientativo del kit"))),"") -> Dentro del plazo orientativo del kit
A26: TB1 | B26: Tableta de chocolate negro de origen 70 %, 100 g | C26: Tabletas y chocolate sin relleno | D26: 12-18 meses | E26: 360 | F26: 540 | G26: 360 | H26: consumo preferente | I26: 46279 | J26: =IFERROR($I26+$G26,"") -> 46639 | K26: =IFERROR($G26/7,"") -> 51.428571 | M26: =IF(ISNUMBER($G26),IF(AND(ISNUMBER($L26),$G26>$L26),"Por encima de la pieza más corta que llevas dentro: un surtido caduca con ella",IF($G26>$F26,"Por encima del plazo orientativo del kit: sostenlo con analítica y con tu APPCC",IF($G26<$E26,"Por debajo del plazo del kit: conservador, y es decisión tuya","Dentro del plazo orientativo del kit"))),"") -> Dentro del plazo orientativo del kit
A27: TB2 | B27: Tableta de chocolate con leche 38 %, 100 g | C27: Tabletas y chocolate sin relleno | D27: 12-18 meses | E27: 360 | F27: 540 | G27: 360 | H27: consumo preferente | I27: 46279 | J27: =IFERROR($I27+$G27,"") -> 46639 | K27: =IFERROR($G27/7,"") -> 51.428571 | M27: =IF(ISNUMBER($G27),IF(AND(ISNUMBER($L27),$G27>$L27),"Por encima de la pieza más corta que llevas dentro: un surtido caduca con ella",IF($G27>$F27,"Por encima del plazo orientativo del kit: sostenlo con analítica y con tu APPCC",IF($G27<$E27,"Por debajo del plazo del kit: conservador, y es decisión tuya","Dentro del plazo orientativo del kit"))),"") -> Dentro del plazo orientativo del kit
... A39: TF5 | B39: Almendras marcona banadas en chocolate, bolsa de 150 g | C39: Frutos secos garrapinados y frutas confitadas banadas | D39: 1-3 meses | E39: 30 | F39: 90 | G39: 30 | H39: caducidad | I39: 46279 | J39: =IFERROR($I39+$G39,"") -> 46309 | K39: =IFERROR($G39/7,"") -> 4.2857143 | M39: =IF(ISNUMBER($G39),IF(AND(ISNUMBER($L39),$G39>$L39),"Por encima de la pieza más corta que llevas dentro: un surtido caduca con ella",IF($G39>$F39,"Por encima del plazo orientativo del kit: sostenlo con analítica y con tu APPCC",IF($G39<$E39,"Por debajo del plazo del kit: conservador, y es decisión tuya","Dentro del plazo orientativo del kit"))),"") -> Dentro del plazo orientativo del kit
A40: CJ1 | B40: Caja surtida de 12 bombones | C40: Bombones de ganache con nata fresca | D40: 10-15 días | E40: 10 | F40: 15 | G40: 10 | H40: caducidad | I40: 46279 | J40: =IFERROR($I40+$G40,"") -> 46289 | K40: =IFERROR($G40/7,"") -> 1.4285714 | L40: =MIN($G$16,$G$17,$G$18,$G$20,$G$22,$G$23,$G$24,$G$25) -> 10 | M40: =IF(ISNUMBER($G40),IF(AND(ISNUMBER($L40),$G40>$L40),"Por encima de la pieza más corta que llevas dentro: un surtido caduca con ella",IF($G40>$F40,"Por encima del plazo orientativo del kit: sostenlo con analítica y con tu APPCC",IF($G40<$E40,"Por debajo del plazo del kit: conservador, y es decisión tuya","Dentro del plazo orientativo del kit"))),"") -> Dentro del plazo orientativo del kit
A41: CJ2 | B41: Caja surtida de 20 bombones | C41: Bombones de ganache con nata fresca | D41: 10-15 días | E41: 10 | F41: 15 | G41: 10 | H41: caducidad | I41: 46279 | J41: =IFERROR($I41+$G41,"") -> 46289 | K41: =IFERROR($G41/7,"") -> 1.4285714 | L41: =MIN($G$16,$G$17,$G$18,$G$19,$G$20,$G$21,$G$22,$G$23,$G$24,$G$25) -> 10 | M41: =IF(ISNUMBER($G41),IF(AND(ISNUMBER($L41),$G41>$L41),"Por encima de la pieza más corta que llevas dentro: un surtido caduca con ella",IF($G41>$F41,"Por encima del plazo orientativo del kit: sostenlo con analítica y con tu APPCC",IF($G41<$E41,"Por debajo del plazo del kit: conservador, y es decisión tuya","Dentro del plazo orientativo del kit"))),"") -> Dentro del plazo orientativo del kit
A42: CJ3 | B42: Caja surtida de 35 bombones | C42: Bombones de ganache con nata fresca | D42: 10-15 días | E42: 10 | F42: 15 | G42: 10 | H42: caducidad | I42: 46279 | J42: =IFERROR($I42+$G42,"") -> 46289 | K42: =IFERROR($G42/7,"") -> 1.4285714 | L42: =MIN($G$16,$G$17,$G$18,$G$19,$G$20,$G$21,$G$22,$G$23,$G$24,$G$25) -> 10 | M42: =IF(ISNUMBER($G42),IF(AND(ISNUMBER($L42),$G42>$L42),"Por encima de la pieza más corta que llevas dentro: un surtido caduca con ella",IF($G42>$F42,"Por encima del plazo orientativo del kit: sostenlo con analítica y con tu APPCC",IF($G42<$E42,"Por debajo del plazo del kit: conservador, y es decisión tuya","Dentro del plazo orientativo del kit"))),"") -> Dentro del plazo orientativo del kit
A43: CJ4 | B43: Estuche corporativo personalizado de 24 bombones | C43: Bombones de ganache con nata fresca | D43: 10-15 días | E43: 10 | F43: 15 | G43: 10 | H43: caducidad | I43: 46279 | J43: =IFERROR($I43+$G43,"") -> 46289 | K43: =IFERROR($G43/7,"") -> 1.4285714 | L43: =MIN($G$16,$G$17,$G$18,$G$19,$G$20,$G$21,$G$22,$G$23,$G$24,$G$25) -> 10 | M43: =IF(ISNUMBER($G43),IF(AND(ISNUMBER($L43),$G43>$L43),"Por encima de la pieza más corta que llevas dentro: un surtido caduca con ella",IF($G43>$F43,"Por encima del plazo orientativo del kit: sostenlo con analítica y con tu APPCC",IF($G43<$E43,"Por debajo del plazo del kit: conservador, y es decisión tuya","Dentro del plazo orientativo del kit"))),"") -> Dentro del plazo orientativo del kit
A44: RECUENTO | B44: Referencias con fecha de CADUCIDAD (las demás, de consumo preferente) | G44: =IFERROR(MIN(G16:G43),"") -> 10 | H44: =COUNTIF(H16:H43,$A$63) -> 12 | K44: La más corta de la carta (días)
A46: Las Diez Filas del Kit, Tal Como Están
A47: Familia | D47: Plazo | F47: Lo que dice el kit
A48: Tabletas y chocolate sin relleno | D48: 12-18 meses | F48: El enemigo no es el tiempo: es la humedad, la luz y los olores. Sellado y en oscuridad
A49: Figuras huecas y piezas macizas | D49: 6-12 meses | F49: Igual que la tableta, pero la pieza hueca se raja con los cambios bruscos de temperatura
A50: Bombones de ganache con nata fresca | D50: 10-15 días | F50: Actividad de agua alta: en refrigeración a 0-4 °C y atemperar CERRADOS antes de abrir, o condensan
A51: Bombones de ganache con nata UHT, sorbato o alcohol | D51: 4-8 semanas | F51: El conservante y el alcohol bajan la actividad de agua; sin ellos no se llega ni a la mitad
A52: Bombones de praline, gianduja y frutos secos | D52: 2-4 meses | F52: La grasa del fruto seco se enrancia y el frío no lo evita: manda la fecha, no el aspecto
A53: Trufas y rocas recubiertas | D53: 3-4 semanas | F53: Si llevan nata o mantequilla, se cuentan como ganache fresca
A54: Bombones de licor y cristalizados | D54: 3-6 meses | F54: Vigilar la cristalización del azúcar en la cascara: revienta y gotea
A55: Frutos secos garrapinados y frutas confitadas banadas | D55: 1-3 meses | F55: Se apelmazan con la humedad; envasado hermetico con desecante si tu obrador es humedo
A56: Barquillos y crujientes banados | D56: 3-4 semanas | F56: Pierden el crujiente mucho antes que la seguridad: se retiran por calidad
A57: Chocolate acabado: NO congelar | D57: Nunca | F57: Al descongelar condensa, el agua disuelve el azúcar de la superficie y deja sugar bloom. Solo el granel de ganache admite -18 °C 1-2 meses, descongelado 24 h en cámara y sin abrir
A58: Fuente: kit-tareas-chocolateria/02-partidas-produccion.xlsx, hoja «Moldeado». La última fila no es un plazo: es una prohibición. El chocolate acabado NO se congela; al descongelar condensa, el agua disuelve el azúcar de la superficie y deja velo. Sólo el granel de ganache admite frío negativo, y con condiciones.
A60: Listas de validación (no las borres: las usan los desplegables)
A61: Tipo de fecha
A62: consumo preferente
...

Sheet Etiquetado o Granel
A1: Etiquetado o Granel
A2: AI Chef Pro · aichef.pro — Cómo Montar una Chocolatería
A3: No son dos formas de decir lo mismo: son dos regímenes. Elige la vía de cada referencia y la hoja cambia de COLUMNA, no de matiz.
A5: Las Dos Vías
A6: Vía | B6: Qué significa | F6: La referencia que te toca
A7: envasado con etiqueta | B7: Sale envasado con SU etiqueta. El art. 4.2 del RD 1021/2022 fija la temperatura de conservación POR LA ETIQUETA que pone quien ha producido y envasado: la que tu has escrito te obliga a ti. Y con etiqueta entran además las doce menciones del art. 9.1 del Rgto. 1169/2011 (`CHN-35`) mas el lote, que NO viene de ese reglamento sino del RD 1808/1991 (`CHN-36`). | F7: Art. 4.2 del RD 1021/2022: la temperatura de conservación que TÚ has puesto en la etiqueta te obliga a ti.
A8: a granel | B8: Se despacha a granel en la vitrina, sin etiqueta. Entonces la referencia NO es el art. 4.2: es TU sistema de autocontrol, y la temperatura y la vida útil las declaras tu y constan en el (`CHN-30`, y `CHN-87`: «chocolate», «cacao», «bombón» y «confitería» aparecen 0 veces en todo el RD 1021/2022). Los alérgenos pueden ir en cartel (`CHN-89`) y el lote tiene tres vías de exención (`CHN-36`). | F8: Tu plan de APPCC: la temperatura y la vida útil las declaras tú y tienen que constar en él.
A10: Y una frontera que conviene tener clara: el RD 1021/2022 no nombra el chocolate ni una sola vez, pero una tarta de chocolate SÍ entra en su tabla de comidas preparadas. Si además de bombones vendes pastelería con nata o crema, esa parte del mostrador va por otro régimen.
A13: Vía de Cada Referencia
A15: Id | B15: Referencia | C15: ¿Cómo la despachas? | D15: Si va ENVASADA CON ETIQUETA, esto te obliga | E15: Si va A GRANEL, esto tiene que constar | F15: La referencia normativa que te toca | G15: ¿Tiene que llevar lote? | H15: Fecha que va en la etiqueta | I15: Cómo se informan los alérgenos
A16: BC1 | B16: Bombón de ganache de chocolate negro 70 % | C16: a granel | D16: =IF($C16=$A$7,$B$7,"") | E16: =IF($C16=$A$8,$B$8,"") -> Se despacha a granel en la vitrina, sin etiqueta. Entonces la referencia NO es el art. 4.2: es TU sistema de autocontrol, y la temperatura y la vida útil las declaras tu y constan en el (`CHN-30`, y `CHN-87`: «chocolate», «cacao», «bombón» y «confitería» aparecen 0 veces en todo el RD 1021/2022). Los alérgenos pueden ir en cartel (`CHN-89`) y el lote tiene tres vías de exención (`CHN-36`). | F16: =IF($C16=$A$7,$F$7,IF($C16=$A$8,$F$8,"")) -> Tu plan de APPCC: la temperatura y la vida útil las declaras tú y tienen que constar en él. | G16: =IF($C16=$A$7,"Sí, y no viene del Rgto. 1169/2011 sino del RD 1808/1991: la letra L delante salvo que el lote sea la propia fecha","Comprueba las tres exenciones del RD 1808/1991; si ninguna te vale, también") -> Comprueba las tres exenciones del RD 1808/1991; si ninguna te vale, también | H16: ='Vida Útil Declarada'!J16 -> 46289 | I16: =IF($C16=$A$7,"En la lista de ingredientes y destacados tipográficamente","Pueden ir en un cartel visible en el punto de venta; la FECHA no puede") -> Pueden ir en un cartel visible en el punto de venta; la FECHA no puede
A17: BC2 | B17: Bombón de ganache de leche y vainilla | C17: a granel | D17: =IF($C17=$A$7,$B$7,"") | E17: =IF($C17=$A$8,$B$8,"") -> Se despacha a granel en la vitrina, sin etiqueta. Entonces la referencia NO es el art. 4.2: es TU sistema de autocontrol, y la temperatura y la vida útil las declaras tu y constan en el (`CHN-30`, y `CHN-87`: «chocolate», «cacao», «bombón» y «confitería» aparecen 0 veces en todo el RD 1021/2022). Los alérgenos pueden ir en cartel (`CHN-89`) y el lote tiene tres vías de exención (`CHN-36`). | F17: =IF($C17=$A$7,$F$7,IF($C17=$A$8,$F$8,"")) -> Tu plan de APPCC: la temperatura y la vida útil las declaras tú y tienen que constar en él. | G17: =IF($C17=$A$7,"Sí, y no viene del Rgto. 1169/2011 sino del RD 1808/1991: la letra L delante salvo que el lote sea la propia fecha","Comprueba las tres exenciones del RD 1808/1991; si ninguna te vale, también") -> Comprueba las tres exenciones del RD 1808/1991; si ninguna te vale, también | H17: ='Vida Útil Declarada'!J17 -> 46307 | I17: =IF($C17=$A$7,"En la lista de ingredientes y destacados tipográficamente","Pueden ir en un cartel visible en el punto de venta; la FECHA no puede") -> Pueden ir en un cartel visible en el punto de venta; la FECHA no puede
A18: BC3 | B18: Bombón de praline de avellana | C18: a granel | D18: =IF($C18=$A$7,$B$7,"") | E18: =IF($C18=$A$8,$B$8,"") -> Se despacha a granel en la vitrina, sin etiqueta. Entonces la referencia NO es el art. 4.2: es TU sistema de autocontrol, y la temperatura y la vida útil las declaras tu y constan en el (`CHN-30`, y `CHN-87`: «chocolate», «cacao», «bombón» y «confitería» aparecen 0 veces en todo el RD 1021/2022). Los alérgenos pueden ir en cartel (`CHN-89`) y el lote tiene tres vías de exención (`CHN-36`). | F18: =IF($C18=$A$7,$F$7,IF($C18=$A$8,$F$8,"")) -> Tu plan de APPCC: la temperatura y la vida útil las declaras tú y tienen que constar en él. | G18: =IF($C18=$A$7,"Sí, y no viene del Rgto. 1169/2011 sino del RD 1808/1991: la letra L delante salvo que el lote sea la propia fecha","Comprueba las tres exenciones del RD 1808/1991; si ninguna te vale, también") -> Comprueba las tres exenciones del RD 1808/1991; si ninguna te vale, también | H18: ='Vida Útil Declarada'!J18 -> 46339 | I18: =IF($C18=$A$7,"En la lista de ingredientes y destacados tipográficamente","Pueden ir en un cartel visible en el punto de venta; la FECHA no puede") -> Pueden ir en un cartel visible en el punto de venta; la FECHA no puede
A19: BC4 | B19: Bombón de gianduja de avellana | C19: a granel | D19: =IF($C19=$A$7,$B$7,"") | E19: =IF($C19=$A$8,$B$8,"") -> Se despacha a granel en la vitrina, sin etiqueta. Entonces la referencia NO es el art. 4.2: es TU sistema de autocontrol, y la temperatura y la vida útil las declaras tu y constan en el (`CHN-30`, y `CHN-87`: «chocolate», «cacao», «bombón» y «confitería» aparecen 0 veces en todo el RD 1021/2022). Los alérgenos pueden ir en cartel (`CHN-89`) y el lote tiene tres vías de exención (`CHN-36`). | F19: =IF($C19=$A$7,$F$7,IF($C19=$A$8,$F$8,"")) -> Tu plan de APPCC: la temperatura y la vida útil las declaras tú y tienen que constar en él. | G19: =IF($C19=$A$7,"Sí, y no viene del Rgto. 1169/2011 sino del RD 1808/1991: la letra L delante salvo que el lote sea la propia fecha","Comprueba las tres exenciones del RD 1808/1991; si ninguna te vale, también") -> Comprueba las tres exenciones del RD 1808/1991; si ninguna te vale, también | H19: ='Vida Útil Declarada'!J19 -> 46339 | I19: =IF($C19=$A$7,"En la lista de ingredientes y destacados tipográficamente","Pueden ir en un cartel visible en el punto de venta; la FECHA no puede") -> Pueden ir en un cartel visible en el punto de venta; la FECHA no puede
A20: BC5 | B20: Trufa de chocolate negro al cacao | C20: a granel | D20: =IF($C20=$A$7,$B$7,"") | E20: =IF($C20=$A$8,$B$8,"") -> Se despacha a granel en la vitrina, sin etiqueta. Entonces la referencia NO es el art. 4.2: es TU sistema de autocontrol, y la temperatura y la vida útil las declaras tu y constan en el (`CHN-30`, y `CHN-87`: «chocolate», «cacao», «bombón» y «confitería» aparecen 0 veces en todo el RD 1021/2022). Los alérgenos pueden ir en cartel (`CHN-89`) y el lote tiene tres vías de exención (`CHN-36`). | F20: =IF($C20=$A$7,$F$7,IF($C20=$A$8,$F$8,"")) -> Tu plan de APPCC: la temperatura y la vida útil las declaras tú y tienen que constar en él. | G20: =IF($C20=$A$7,"Sí, y no viene del Rgto. 1169/2011 sino del RD 1808/1991: la letra L delante salvo que el lote sea la propia fecha","Comprueba las tres exenciones del RD 1808/1991; si ninguna te vale, también") -> Comprueba las tres exenciones del RD 1808/1991; si ninguna te vale, también | H20: ='Vida Útil Declarada'!J20 -> 46300 | I20: =IF($C20=$A$7,"En la lista de ingredientes y destacados tipográficamente","Pueden ir en un cartel visible en el punto de venta; la FECHA no puede") -> Pueden ir en un cartel visible en el punto de venta; la FECHA no puede
A21: BC6 | B21: Bombón de licor de ron | C21: a granel | D21: =IF($C21=$A$7,$B$7,"") | E21: =IF($C21=$A$8,$B$8,"") -> Se despacha a granel en la vitrina, sin etiqueta. Entonces la referencia NO es el art. 4.2: es TU sistema de autocontrol, y la temperatura y la vida útil las declaras tu y constan en el (`CHN-30`, y `CHN-87`: «chocolate», «cacao», «bombón» y «confitería» aparecen 0 veces en todo el RD 1021/2022). Los alérgenos pueden ir en cartel (`CHN-89`) y el lote tiene tres vías de exención (`CHN-36`). | F21: =IF($C21=$A$7,$F$7,IF($C21=$A$8,$F$8,"")) -> Tu plan de APPCC: la temperatura y la vida útil las declaras tú y tienen que constar en él. | G21: =IF($C21=$A$7,"Sí, y no viene del Rgto. 1169/2011 sino del RD 1808/1991: la letra L delante salvo que el lote sea la propia fecha","Comprueba las tres exenciones del RD 1808/1991; si ninguna te vale, también") -> Comprueba las tres exenciones del RD 1808/1991; si ninguna te vale, también | H21: ='Vida Útil Declarada'!J21 -> 46369 | I21: =IF($C21=$A$7,"En la lista de ingredientes y destacados tipográficamente","Pueden ir en un cartel visible en el punto de venta; la FECHA no puede") -> Pueden ir en un cartel visible en el punto de venta; la FECHA no puede
A22: BC7 | B22: Bombón de caramelo salado | C22: a granel | D22: =IF($C22=$A$7,$B$7,"") | E22: =IF($C22=$A$8,$B$8,"") -> Se despacha a granel en la vitrina, sin etiqueta. Entonces la referencia NO es el art. 4.2: es TU sistema de autocontrol, y la temperatura y la vida útil las declaras tu y constan en el (`CHN-30`, y `CHN-87`: «chocolate», «cacao», «bombón» y «confitería» aparecen 0 veces en todo el RD 1021/2022). Los alérgenos pueden ir en cartel (`CHN-89`) y el lote tiene tres vías de exención (`CHN-36`). | F22: =IF($C22=$A$7,$F$7,IF($C22=$A$8,$F$8,"")) -> Tu plan de APPCC: la temperatura y la vida útil las declaras tú y tienen que constar en él. | G22: =IF($C22=$A$7,"Sí, y no viene del Rgto. 1169/2011 sino del RD 1808/1991: la letra L delante salvo que el lote sea la propia fecha","Comprueba las tres exenciones del RD 1808/1991; si ninguna te vale, también") -> Comprueba las tres exenciones del RD 1808/1991; si ninguna te vale, también | H22: ='Vida Útil Declarada'!J22 -> 46307 | I22: =IF($C22=$A$7,"En la lista de ingredientes y destacados tipográficamente","Pueden ir en un cartel visible en el punto de venta; la FECHA no puede") -> Pueden ir en un cartel visible en el punto de venta; la FECHA no puede
A23: BC8 | B23: Bombón de praline de cacahuete | C23: a granel | D23: =IF($C23=$A$7,$B$7,"") | E23: =IF($C23=$A$8,$B$8,"") -> Se despacha a granel en la vitrina, sin etiqueta. Entonces la referencia NO es el art. 4.2: es TU sistema de autocontrol, y la temperatura y la vida útil las declaras tu y constan en el (`CHN-30`, y `CHN-87`: «chocolate», «cacao», «bombón» y «confitería» aparecen 0 veces en todo el RD 1021/2022). Los alérgenos pueden ir en cartel (`CHN-89`) y el lote tiene tres vías de exención (`CHN-36`). | F23: =IF($C23=$A$7,$F$7,IF($C23=$A$8,$F$8,"")) -> Tu plan de APPCC: la temperatura y la vida útil las declaras tú y tienen que constar en él. | G23: =IF($C23=$A$7,"Sí, y no viene del Rgto. 1169/2011 sino del RD 1808/1991: la letra L delante salvo que el lote sea la propia fecha","Comprueba las tres exenciones del RD 1808/1991; si ninguna te vale, también") -> Comprueba las tres exenciones del RD 1808/1991; si ninguna te vale, también | H23: ='Vida Útil Declarada'!J23 -> 46339 | I23: =IF($C23=$A$7,"En la lista de ingredientes y destacados tipográficamente","Pueden ir en un cartel visible en el punto de venta; la FECHA no puede") -> Pueden ir en un cartel visible en el punto de venta; la FECHA no puede
A24: BC9 | B24: Bombón crujiente de sesamo y barquillo | C24: a granel | D24: =IF($C24=$A$7,$B$7,"") | E24: =IF($C24=$A$8,$B$8,"") -> Se despacha a granel en la vitrina, sin etiqueta. Entonces la referencia NO es el art. 4.2: es TU sistema de autocontrol, y la temperatura y la vida útil las declaras tu y constan en el (`CHN-30`, y `CHN-87`: «chocolate», «cacao», «bombón» y «confitería» aparecen 0 veces en todo el RD 1021/2022). Los alérgenos pueden ir en cartel (`CHN-89`) y el lote tiene tres vías de exención (`CHN-36`). | F24: =IF($C24=$A$7,$F$7,IF($C24=$A$8,$F$8,"")) -> Tu plan de APPCC: la temperatura y la vida útil las declaras tú y tienen que constar en él. | G24: =IF($C24=$A$7,"Sí, y no viene del Rgto. 1169/2011 sino del RD 1808/1991: la letra L delante salvo que el lote sea la propia fecha","Comprueba las tres exenciones del RD 1808/1991; si ninguna te vale, también") -> Comprueba las tres exenciones del RD 1808/1991; si ninguna te vale, también | H24: ='Vida Útil Declarada'!J24 -> 46300 | I24: =IF($C24=$A$7,"En la lista de ingredientes y destacados tipográficamente","Pueden ir en un cartel visible en el punto de venta; la FECHA no puede") -> Pueden ir en un cartel visible en el punto de venta; la FECHA no puede
A25: BC10 | B25: Bombón de naranja confitada y chocolate negro | C25: a granel | D25: =IF($C25=$A$7,$B$7,"") | E25: =IF($C25=$A$8,$B$8,"") -> Se despacha a granel en la vitrina, sin etiqueta. Entonces la referencia NO es el art. 4.2: es TU sistema de autocontrol, y la temperatura y la vida útil las declaras tu y constan en el (`CHN-30`, y `CHN-87`: «chocolate», «cacao», «bombón» y «confitería» aparecen 0 veces en todo el RD 1021/2022). Los alérgenos pueden ir en cartel (`CHN-89`) y el lote tiene tres vías de exención (`CHN-36`). | F25: =IF($C25=$A$7,$F$7,IF($C25=$A$8,$F$8,"")) -> Tu plan de APPCC: la temperatura y la vida útil las declaras tú y tienen que constar en él. | G25: =IF($C25=$A$7,"Sí, y no viene del Rgto. 1169/2011 sino del RD 1808/1991: la letra L delante salvo que el lote sea la propia fecha","Comprueba las tres exenciones del RD 1808/1991; si ninguna te vale, también") -> Comprueba las tres exenciones del RD 1808/1991; si ninguna te vale, también | H25: ='Vida Útil Declarada'!J25 -> 46309 | I25: =IF($C25=$A$7,"En la lista de ingredientes y destacados tipográficamente","Pueden ir en un cartel visible en el punto de venta; la FECHA no puede") -> Pueden ir en un cartel visible en el punto de venta; la FECHA no puede
A26: TB1 | B26: Tableta de chocolate negro de origen 70 %, 100 g | C26: envasado con etiqueta | D26: =IF($C26=$A$7,$B$7,"") -> Sale envasado con SU etiqueta. El art. 4.2 del RD 1021/2022 fija la temperatura de conservación POR LA ETIQUETA que pone quien ha producido y envasado: la que tu has escrito te obliga a ti. Y con etiqueta entran además las doce menciones del art. 9.1 del Rgto. 1169/2011 (`CHN-35`) mas el lote, que NO viene de ese reglamento sino del RD 1808/1991 (`CHN-36`). | E26: =IF($C26=$A$8,$B$8,"") | F26: =IF($C26=$A$7,$F$7,IF($C26=$A$8,$F$8,"")) -> Art. 4.2 del RD 1021/2022: la temperatura de conservación que TÚ has puesto en la etiqueta te obliga a ti. | G26: =IF($C26=$A$7,"Sí, y no viene del Rgto. 1169/2011 sino del RD 1808/1991: la letra L delante salvo que el lote sea la propia fecha","Comprueba las tres exenciones del RD 1808/1991; si ninguna te vale, también") -> Sí, y no viene del Rgto. 1169/2011 sino del RD 1808/1991: la letra L delante salvo que el lote sea la propia fecha | H26: ='Vida Útil Declarada'!J26 -> 46639 | I26: =IF($C26=$A$7,"En la lista de ingredientes y destacados tipográficamente","Pueden ir en un cartel visible en el punto de venta; la FECHA no puede") -> En la lista de ingredientes y destacados tipográficamente
A27: TB2 | B27: Tableta de chocolate con leche 38 %, 100 g | C27: envasado con etiqueta | D27: =IF($C27=$A$7,$B$7,"") -> Sale envasado con SU etiqueta. El art. 4.2 del RD 1021/2022 fija la temperatura de conservación POR LA ETIQUETA que pone quien ha producido y envasado: la que tu has escrito te obliga a ti. Y con etiqueta entran además las doce menciones del art. 9.1 del Rgto. 1169/2011 (`CHN-35`) mas el lote, que NO viene de ese reglamento sino del RD 1808/1991 (`CHN-36`). | E27: =IF($C27=$A$8,$B$8,"") | F27: =IF($C27=$A$7,$F$7,IF($C27=$A$8,$F$8,"")) -> Art. 4.2 del RD 1021/2022: la temperatura de conservación que TÚ has puesto en la etiqueta te obliga a ti. | G27: =IF($C27=$A$7,"Sí, y no viene del Rgto. 1169/2011 sino del RD 1808/1991: la letra L delante salvo que el lote sea la propia fecha","Comprueba las tres exenciones del RD 1808/1991; si ninguna te vale, también") -> Sí, y no viene del Rgto. 1169/2011 sino del RD 1808/1991: la letra L delante salvo que el lote sea la propia fecha | H27: ='Vida Útil Declarada'!J27 -> 46639 | I27: =IF($C27=$A$7,"En la lista de ingredientes y destacados tipográficamente","Pueden ir en un cartel visible en el punto de venta; la FECHA no puede") -> En la lista de ingredientes y destacados tipográficamente
... A43: CJ4 | B43: Estuche corporativo personalizado de 24 bombones | C43: envasado con etiqueta | D43: =IF($C43=$A$7,$B$7,"") -> Sale envasado con SU etiqueta. El art. 4.2 del RD 1021/2022 fija la temperatura de conservación POR LA ETIQUETA que pone quien ha producido y envasado: la que tu has escrito te obliga a ti. Y con etiqueta entran además las doce menciones del art. 9.1 del Rgto. 1169/2011 (`CHN-35`) mas el lote, que NO viene de ese reglamento sino del RD 1808/1991 (`CHN-36`). | E43: =IF($C43=$A$8,$B$8,"") | F43: =IF($C43=$A$7,$F$7,IF($C43=$A$8,$F$8,"")) -> Art. 4.2 del RD 1021/2022: la temperatura de conservación que TÚ has puesto en la etiqueta te obliga a ti. | G43: =IF($C43=$A$7,"Sí, y no viene del Rgto. 1169/2011 sino del RD 1808/1991: la letra L delante salvo que el lote sea la propia fecha","Comprueba las tres exenciones del RD 1808/1991; si ninguna te vale, también") -> Sí, y no viene del Rgto. 1169/2011 sino del RD 1808/1991: la letra L delante salvo que el lote sea la propia fecha | H43: ='Vida Útil Declarada'!J43 -> 46289 | I43: =IF($C43=$A$7,"En la lista de ingredientes y destacados tipográficamente","Pueden ir en un cartel visible en el punto de venta; la FECHA no puede") -> En la lista de ingredientes y destacados tipográficamente
A44: RECUENTO | B44: Referencias envasadas con etiqueta | C44: =COUNTIF(C16:C43,$A$62) -> 16 | D44: Referencias a granel | E44: =COUNTIF(C16:C43,$A$63) -> 12 | F44: Cada referencia que pasa de granel a envasada te añade doce menciones obligatorias y el lote. No es una decisión de etiquetado: es una decisión de canal.
A60: Listas de validación (no las borres: las usan los desplegables)
A61: Vías de despacho
A62: envasado con etiqueta
A63: a granel

Sheet Temperatura y Vitrina
A1: Temperatura y Vitrina
A2: AI Chef Pro · aichef.pro — Cómo Montar una Chocolatería
A3: Las cinco temperaturas del kit, el rango de trabajo de TU vitrina y la que declaras para cada referencia. El semáforo sólo se enciende por encima de 20 °C.
A5: Las Cinco Temperaturas del Kit
A6: Zona | C6: Temperatura objetivo | D6: Humedad | E6: De dónde sale | F6: Literal del kit
A7: Obrador de templado y moldeado | C7: 18 a 20 °C | D7: 50 a 60 % | E7: kit-tareas-chocolateria/08-apertura-cierre-negocio.xlsx, hoja «Apertura del Negocio» | F7: Verificar la temperatura y la humedad del obrador: objetivo 18-20 °C y 50-60 %
A8: Cámara de conservación de chocolate | C8: 15 a 18 °C | D8: 50 a 60 % | E8: kit-tareas-chocolateria/01-apertura-cierre.xlsx, hoja «Apertura» | F8: Comprobar que la cámara de conservación ha funcionado toda la noche (sin cortes ni alarmas) y registrar la temperatura: objetivo 15-18 °C y 50-60 % de humedad
A9: Nevera de rellenos y ganaches | C9: 0 a 4 °C | D9: no la fija | E9: kit-tareas-chocolateria/01-apertura-cierre.xlsx, hoja «Apertura» | F9: Comprobar que la nevera de rellenos y ganaches ha funcionado toda la noche y registrar la temperatura: objetivo 0-4 °C
A10: Sala de tienda | C10: 20 a 22 °C | D10: no la fija | E10: kit-tareas-chocolateria/01-apertura-cierre.xlsx, hoja «Apertura» | F10: Encender aire acondicionado - mantener sala 20-22 °C
A11: Vitrina de bombonería | C11: 16 a 18 °C | D11: menos del 55 % | E11: kit-tareas-chocolateria/08-apertura-cierre-negocio.xlsx, hoja «Apertura del Negocio» | F11: Comprobar que las vitrinas temperadas han alcanzado 16-18 °C y menos del 55 % de humedad antes de montar el genero
A12: Confundir la temperatura de la SALA con la de la CÁMARA es uno de los errores que más caro salen: son dos cosas distintas y conviven en el mismo local. Y la nevera de 0-4 °C es la del RELLENO, no la del bombón acabado: el chocolate terminado no va a esa temperatura, condensa.
A13: Tu Vitrina
A14: Dato | D14: Valor | E14: Unidad | F14: Qué dice el libro
A15: Temperatura mínima de trabajo de tu vitrina | D15: 16 | E15: grados C | F15: =IF(AND(ISNUMBER($D15),ISNUMBER($D16)),IF($D15>$D16,"Revisa: el mínimo está por encima del máximo","Rango correcto"),"") -> Rango correcto | H15: El objetivo operativo del kit para la vitrina es 16-18 grados C con menos del 55 % de humedad, y es lo que viene puesto. El RANGO DE TRABAJO del equipo es otra cosa: una vitrina de bombonería real trabaja, por ejemplo, entre +14 y +17 °C. Pon el de la tuya, que viene en su ficha técnica. El semáforo no se enciende por estar en 16-18: sólo por pasar de 20.
A16: Temperatura máxima de trabajo de tu vitrina | D16: 18 | E16: grados C | F16: =IF(AND(ISNUMBER($D16),ISNUMBER($D18)),IF($D16>$D18,"Por encima de la alarma: a esa temperatura la manteca de cacao empieza a fundir y el género se pierde","Dentro de lo que aguanta el chocolate"),"") -> Dentro de lo que aguanta el chocolate
A17: Humedad de trabajo de tu vitrina | D17: 50 | E17: % de HR | F17: =IF(AND(ISNUMBER($D17),ISNUMBER('Parámetros'!$B$13)),IF($D17>'Parámetros'!$B$13,"Por encima del objetivo del kit: el bombón coge humedad y sale velo de azúcar","Dentro del objetivo del kit"),"") -> Dentro del objetivo del kit
A18: Temperatura a la que salta la alarma | D18: ='Parámetros'!$B$12 -> 20 | E18: grados C
A20: Temperatura Declarada de Cada Referencia
A21: Id | B21: Referencia | C21: ¿Cómo la despachas? | D21: Temperatura que TÚ declaras | E21: Dónde va | F21: ¿La mantiene tu vitrina? | G21: Aviso | H21: Qué tiene que constar | I21: aw | J21: Vida útil (días)
A22: BC1 | B22: Bombón de ganache de chocolate negro 70 % | C22: ='Etiquetado o Granel'!C16 -> a granel | D22: 4 | E22: =IF(ISNUMBER($D22),IF($D22<$D$15,"Nevera de rellenos, no vitrina","Vitrina temperada"),"") -> Nevera de rellenos, no vitrina | F22: =IF(AND(ISNUMBER($D22),ISNUMBER($D$15),ISNUMBER($D$16)),IF(AND($D22>=$D$15,$D22<=$D$16),"Sí, está dentro del rango de tu vitrina","No con esta vitrina: o cambias la temperatura declarada o necesitas otro mueble"),"") -> No con esta vitrina: o cambias la temperatura declarada o necesitas otro mueble | G22: =IF(ISNUMBER($D22),IF($D22>'Parámetros'!$B$12,"Por encima de la alarma: a esa temperatura la manteca de cacao funde",""),"") | H22: =IF($C22='Etiquetado o Granel'!A$7,"En la etiqueta, y esa temperatura te obliga a ti","En tu plan de APPCC, con el registro diario que lo demuestre") -> En tu plan de APPCC, con el registro diario que lo demuestre | I22: ='Tipo de Relleno y aw'!E16 -> 0.88 | J22: ='Vida Útil Declarada'!G16 -> 10
A23: BC2 | B23: Bombón de ganache de leche y vainilla | C23: ='Etiquetado o Granel'!C17 -> a granel | D23: 18 | E23: =IF(ISNUMBER($D23),IF($D23<$D$15,"Nevera de rellenos, no vitrina","Vitrina temperada"),"") -> Vitrina temperada | F23: =IF(AND(ISNUMBER($D23),ISNUMBER($D$15),ISNUMBER($D$16)),IF(AND($D23>=$D$15,$D23<=$D$16),"Sí, está dentro del rango de tu vitrina","No con esta vitrina: o cambias la temperatura declarada o necesitas otro mueble"),"") -> Sí, está dentro del rango de tu vitrina | G23: =IF(ISNUMBER($D23),IF($D23>'Parámetros'!$B$12,"Por encima de la alarma: a esa temperatura la manteca de cacao funde",""),"") | H23: =IF($C23='Etiquetado o Granel'!A$7,"En la etiqueta, y esa temperatura te obliga a ti","En tu plan de APPCC, con el registro diario que lo demuestre") -> En tu plan de APPCC, con el registro diario que lo demuestre | I23: ='Tipo de Relleno y aw'!E17 -> 0.82 | J23: ='Vida Útil Declarada'!G17 -> 28
A24: BC3 | B24: Bombón de praline de avellana | C24: ='Etiquetado o Granel'!C18 -> a granel | D24: 18 | E24: =IF(ISNUMBER($D24),IF($D24<$D$15,"Nevera de rellenos, no vitrina","Vitrina temperada"),"") -> Vitrina temperada | F24: =IF(AND(ISNUMBER($D24),ISNUMBER($D$15),ISNUMBER($D$16)),IF(AND($D24>=$D$15,$D24<=$D$16),"Sí, está dentro del rango de tu vitrina","No con esta vitrina: o cambias la temperatura declarada o necesitas otro mueble"),"") -> Sí, está dentro del rango de tu vitrina | G24: =IF(ISNUMBER($D24),IF($D24>'Parámetros'!$B$12,"Por encima de la alarma: a esa temperatura la manteca de cacao funde",""),"") | H24: =IF($C24='Etiquetado o Granel'!A$7,"En la etiqueta, y esa temperatura te obliga a ti","En tu plan de APPCC, con el registro diario que lo demuestre") -> En tu plan de APPCC, con el registro diario que lo demuestre | I24: ='Tipo de Relleno y aw'!E18 -> 0.42 | J24: ='Vida Útil Declarada'!G18 -> 60
A25: BC4 | B25: Bombón de gianduja de avellana | C25: ='Etiquetado o Granel'!C19 -> a granel | D25: 18 | E25: =IF(ISNUMBER($D25),IF($D25<$D$15,"Nevera de rellenos, no vitrina","Vitrina temperada"),"") -> Vitrina temperada | F25: =IF(AND(ISNUMBER($D25),ISNUMBER($D$15),ISNUMBER($D$16)),IF(AND($D25>=$D$15,$D25<=$D$16),"Sí, está dentro del rango de tu vitrina","No con esta vitrina: o cambias la temperatura declarada o necesitas otro mueble"),"") -> Sí, está dentro del rango de tu vitrina | G25: =IF(ISNUMBER($D25),IF($D25>'Parámetros'!$B$12,"Por encima de la alarma: a esa temperatura la manteca de cacao funde",""),"") | H25: =IF($C25='Etiquetado o Granel'!A$7,"En la etiqueta, y esa temperatura te obliga a ti","En tu plan de APPCC, con el registro diario que lo demuestre") -> En tu plan de APPCC, con el registro diario que lo demuestre | I25: ='Tipo de Relleno y aw'!E19 -> 0.38 | J25: ='Vida Útil Declarada'!G19 -> 60
