Workbook

Sheet Masa
A1: CALCULADORA DE MASA PARA PIZZA — A LOS GRAMAJES DEL PLIEGO Y POR % PANADERO
A2: Escribe solo en las celdas VERDES: todo lo demás se calcula. Importes sin IVA. Los precios de los ingredientes son ejemplos (research de octubre 2026 o estimación del kit): cámbialos por los de tu proveedor.
A3: AVISO FIJO. El semáforo de esta hoja solo dice si tus gramajes caben en los del pliego de la Especialidad Tradicional Garantizada (ETG): NO convierte tu pizza en «pizza napolitana». Ese nombre está reservado desde 2022 (Reglamento de Ejecución (UE) 2022/2313) y solo puede usarlo quien cumple TODO el pliego (incluido el horno de leña) y pasa la verificación oficial (Reglamento (UE) 2024/1143, arts. 72 y 73). La asociación AVPN es privada y no sustituye esa verificación. Mientras no la tengas, pon en la carta el nombre de la receta (Margherita, Marinara…).
A5: A. POR LITRO DE AGUA (gramajes del pliego) | B5: Valor | C5: Pliego mín. | D5: Pliego máx. | E5: Notas
A6: Número de bolas de masa que quieres preparar | B6: 60 | E6: Número entero mayor que 0. Una bola, una pizza.
A7: Peso de la bola (g) | B7: 250 | C7: 180 | D7: 250 | E7: El pliego marca bolas de 180 a 250 g, hechas a mano. En gris, el rango del pliego.
A8: Merma de amasado y boleado (%) | B8: 0.03 | E8: Estimación del kit: masa que se queda en la amasadora, el banco y las manos. Se suma a la masa necesaria.
A9: Harina por litro de agua (g) | B9: 1800 | C9: 1600 | D9: 1800 | E9: Pliego: hasta 1.800 g de harina por litro de agua («punto de amasado»). El mínimo de 1.600 g es el que da una absorción del 62 % (cálculo del kit sobre el rango de 55-62 % del pliego).
A10: Sal por litro de agua (g) | B10: 52.5 | C10: 50 | D10: 55 | E10: Pliego: 50 a 55 g de sal por litro de agua.
A11: Levadura de cerveza fresca por litro de agua (g) | B11: 3 | C11: 3 | D11: 3 | E11: Pliego: 3 g por litro de agua.
A12: Agua por litro (g) | B12: 1000 | E12: Constante: un litro de agua pesa 1.000 g. No se edita.
A13: Precio de la harina (€/kg, sin IVA) | B13: 1.39 | E13: Research: harina 00 de pizzería, 1,39 €/kg sin IVA (minorista online, octubre 2026). Pon el de tu proveedor.
A14: Precio de la sal (€/kg, sin IVA) | B14: 0.6 | E14: Estimación del kit. Pon el de tu proveedor.
A15: Precio de la levadura fresca (€/kg, sin IVA) | B15: 3.5 | E15: Estimación del kit (el research no encontró precio fiable). Pon el de tu proveedor.
A17: RESULTADO DEL BLOQUE A | B17: Valor | E17: Notas
A18: Masa total que hay que preparar (g) | B18: =$B$6*$B$7*(1+$B$8) -> 15450 | E18: Bolas × peso × (1 + merma).
A19: Masa que sale de cada litro de agua (g) | B19: =$B$12+$B$9+$B$10+$B$11 -> 2855.5 | E19: Agua + harina + sal + levadura por litro.
A20: Litros de agua que necesitas | B20: =$B$18/$B$19 -> 5.4106111 | E20: Masa total ÷ masa por litro.
A21: Agua (g) | B21: =$B$20*$B$12 -> 5410.6111
A22: Harina (g) | B22: =$B$20*$B$9 -> 9739.1
A23: Sal (g) | B23: =$B$20*$B$10 -> 284.05708
A24: Levadura fresca (g) | B24: =$B$20*$B$11 -> 16.231833
A25: % panadero: hidratación (agua ÷ harina) | B25: =$B$21/$B$22 -> 0.55555556 | E25: Para pasarlo al bloque B.
A26: % panadero: sal (sal ÷ harina) | B26: =$B$23/$B$22 -> 0.029166667
A27: % panadero: levadura (levadura ÷ harina) | B27: =$B$24/$B$22 -> 0.0016666667
A28: Harina por bola (g) | B28: =$B$22/$B$6 -> 162.31833
A29: Bolas que salen de 1 kg de harina | B29: =$B$6*1000/$B$22 -> 6.1607335 | E29: Con la receta del pliego, unas 6 bolas de 250 g.
A30: Coste de la masa (€) | B30: =($B$22*$B$13+$B$23*$B$14+$B$24*$B$15)/1000 -> 13.764595 | E30: Suma de gramos × €/kg ÷ 1.000, con la merma incluida.
A31: Coste de la masa por bola (€) | B31: =$B$30/$B$6 -> 0.22940991
A32: Semáforo del pliego | B32: =IF(AND($B$9>=$C$9,$B$9<=$D$9,$B$10>=$C$10,$B$10<=$D$10,$B$7>=$C$7,$B$7<=$D$7),"Dentro de los gramajes del pliego","Fuera de los gramajes del pliego") -> Dentro de los gramajes del pliego | E32: Mira la harina y la sal por litro y el peso de la bola. Ojo al aviso fijo de arriba: no es un sello.
A34: B. POR % PANADERO (sobre la harina) | B34: Valor | E34: Notas
A35: Hidratación (agua sobre la harina, %) | B35: 0.6 | E35: El pliego deja entre el 55 y el 62 % según la absorción de la harina. 60 % es un ejemplo del kit.
A36: Sal (sobre la harina, %) | B36: 0.028 | E36: Pliego: entre el 2,8 y el 3,1 % sobre la harina (50-55 g por litro).
A37: Levadura fresca (sobre la harina, %) | B37: 0.002 | E37: Pliego: aprox. 0,17 % sobre la harina (3 g por litro de agua). 0,2 % es un ejemplo del kit.
A39: RESULTADO DEL BLOQUE B (misma masa total que el A) | B39: Valor | E39: Notas
A40: Harina (g) | B40: =$B$18/(1+$B$35+$B$36+$B$37) -> 9478.5276 | E40: Masa ÷ (1 + hidratación + sal + levadura), en tanto por uno.
A41: Agua (g) | B41: =$B$40*$B$35 -> 5687.1166
A42: Sal (g) | B42: =$B$40*$B$36 -> 265.39877
A43: Levadura fresca (g) | B43: =$B$40*$B$37 -> 18.957055
A44: Coste de la masa (€) | B44: =($B$40*$B$13+$B$42*$B$14+$B$43*$B$15)/1000 -> 13.400742 | E44: Mismos €/kg del bloque A.
...

Sheet Escandallo
A1: ESCANDALLO POR PIZZA — 8 PIZZAS DE EJEMPLO, EN GRAMOS
A2: Escribe solo en las celdas VERDES (ingredientes, precios, mermas, gramos, nombres y precios de carta). Importes sin IVA salvo el precio de carta. Los precios son ejemplos: pon los de tu proveedor. La carta de ejemplo usa el nombre de la receta, no «napolitana» (ver el aviso de la hoja «Masa»).
A4: DATOS GENERALES | B4: Valor | E4: Notas
A5: IVA de la pizza (%) | B5: 0.1 | E5: Comida preparada, en sala, para llevar y a domicilio: 10 % (Ley 37/1992, art. 91.Uno.2.2.º).
A6: Food cost objetivo (% sobre el precio sin IVA) | B6: 0.25 | E6: Referencia habitual de pizzería: 22-30 %. Pon el que te marque tu plan financiero.
A7: Margen de vigilancia sobre el objetivo (puntos) | B7: 0.05 | E7: Hasta este margen por encima del objetivo, el semáforo dice «Vigila el coste»; más allá, «Por encima».
A8: Coste de la caja para llevar (€, sin IVA) | B8: 1 | E8: Research: caja de pizza de 33 cm aprox. 1 € la unidad. Pon el de tu proveedor.
A9: Coste de la masa por bola (de la hoja «Masa») | B9: ='Masa'!$B$50 -> 0.22940991 | E9: Se calcula en la hoja «Masa» (bloque A o B, según elijas allí).
A11: INGREDIENTE | B11: €/kg sin IVA | C11: Merma | D11: €/kg neto | E11: Margherita | F11: Marinara | G11: Diavola | H11: Capricciosa | I11: Quattro formaggi | J11: Cotto e funghi | K11: Bufalina | L11: Salsiccia e friarielli | M11: ORIGEN DEL PRECIO DE EJEMPLO
A12: Precio de carta con IVA (€) | E12: 10 | F12: 9.5 | G12: 12.5 | H12: 14 | I12: 13.5 | J12: 12.5 | K12: 15.5 | L12: 14.5
A13: Tomate pelado triturado | B13: 2.88 | C13: 0 | D13: =B13/(1-C13) -> 2.88 | E13: 70 | F13: 100 | G13: 70 | H13: 70 | I13: 0 | J13: 70 | K13: 60 | L13: 0 | M13: research: lata de 2,5 kg (Makro)
A14: Fior di latte | B14: 8.82 | C14: 0.03 | D14: =B14/(1-C14) -> 9.0927835 | E14: 90 | F14: 0 | G14: 90 | H14: 80 | I14: 60 | J14: 90 | K14: 0 | L14: 0 | M14: research: juliana de 2,5 kg (Makro)
A15: Mozzarella de búfala | B15: 18 | C15: 0.03 | D15: =B15/(1-C15) -> 18.556701 | E15: 0 | F15: 0 | G15: 0 | H15: 0 | I15: 0 | J15: 0 | K15: 125 | L15: 0 | M15: estimado: el research no halló precio profesional
A16: Aceite de oliva virgen extra | B16: 4.5 | C16: 0 | D16: =B16/(1-C16) -> 4.5 | E16: 5 | F16: 6 | G16: 5 | H16: 5 | I16: 4 | J16: 5 | K16: 5 | L16: 6 | M16: research: garrafa de 5 l, convertido a €/kg y sin IVA
A17: Albahaca fresca | B17: 12 | C17: 0.3 | D17: =B17/(1-C17) -> 17.142857 | E17: 3 | F17: 0 | G17: 2 | H17: 0 | I17: 0 | J17: 0 | K17: 3 | L17: 0 | M17: estimado
A18: Orégano seco | B18: 15 | C18: 0 | D18: =B18/(1-C18) -> 15 | E18: 0 | F18: 0.5 | G18: 0 | H18: 0 | I18: 0 | J18: 0 | K18: 0 | L18: 0 | M18: estimado
A19: Ajo | B19: 4 | C19: 0.2 | D19: =B19/(1-C19) -> 5 | E19: 0 | F19: 3 | G19: 0 | H19: 0 | I19: 0 | J19: 0 | K19: 0 | L19: 2 | M19: estimado
A20: Salami picante | B20: 14 | C20: 0.03 | D20: =B20/(1-C20) -> 14.43299 | E20: 0 | F20: 0 | G20: 50 | H20: 0 | I20: 0 | J20: 0 | K20: 0 | L20: 0 | M20: estimado
A21: Jamón cocido | B21: 9.5 | C21: 0.03 | D21: =B21/(1-C21) -> 9.7938144 | E21: 0 | F21: 0 | G21: 0 | H21: 40 | I21: 0 | J21: 45 | K21: 0 | L21: 0 | M21: estimado
A22: Champiñón laminado | B22: 3.5 | C22: 0.1 | D22: =B22/(1-C22) -> 3.8888889 | E22: 0 | F22: 0 | G22: 0 | H22: 40 | I22: 0 | J22: 50 | K22: 0 | L22: 0 | M22: estimado
A23: Alcachofa en aceite | B23: 9 | C23: 0.1 | D23: =B23/(1-C23) -> 10 | E23: 0 | F23: 0 | G23: 0 | H23: 30 | I23: 0 | J23: 0 | K23: 0 | L23: 0 | M23: estimado
A24: Aceitunas negras | B24: 6.5 | C24: 0.05 | D24: =B24/(1-C24) -> 6.8421053 | E24: 0 | F24: 0 | G24: 0 | H24: 15 | I24: 0 | J24: 0 | K24: 0 | L24: 0 | M24: estimado
... A34: Ricotta | B34: 6 | C34: 0.02 | D34: =B34/(1-C34) -> 6.122449 | E34: 0 | F34: 0 | G34: 0 | H34: 0 | I34: 0 | J34: 0 | K34: 0 | L34: 0 | M34: estimado: libre para tus pizzas
A36: RESULTADO POR PIZZA (gramos en las columnas de arriba) | E36: =E11 -> Margherita | F36: =F11 -> Marinara | G36: =G11 -> Diavola | H36: =H11 -> Capricciosa | I36: =I11 -> Quattro formaggi | J36: =J11 -> Cotto e funghi | K36: =K11 -> Bufalina | L36: =L11 -> Salsiccia e friarielli
A37: Peso en crudo de la pizza (g) | E37: ='Masa'!$B$7+SUM(E$13:E$34) -> 418 | F37: ='Masa'!$B$7+SUM(F$13:F$34) -> 359.5 | G37: ='Masa'!$B$7+SUM(G$13:G$34) -> 467 | H37: ='Masa'!$B$7+SUM(H$13:H$34) -> 530 | I37: ='Masa'!$B$7+SUM(I$13:I$34) -> 414 | J37: ='Masa'!$B$7+SUM(J$13:J$34) -> 510 | K37: ='Masa'!$B$7+SUM(K$13:K$34) -> 473 | L37: ='Masa'!$B$7+SUM(L$13:L$34) -> 478
A38: Coste de la masa (€) | E38: =$B$9 -> 0.22940991 | F38: =$B$9 -> 0.22940991 | G38: =$B$9 -> 0.22940991 | H38: =$B$9 -> 0.22940991 | I38: =$B$9 -> 0.22940991 | J38: =$B$9 -> 0.22940991 | K38: =$B$9 -> 0.22940991 | L38: =$B$9 -> 0.22940991
A39: Coste de los ingredientes (€) | E39: =SUMPRODUCT(E$13:E$34,$D$13:$D$34)/1000 -> 1.0938791 | F39: =SUMPRODUCT(F$13:F$34,$D$13:$D$34)/1000 -> 0.3375 | G39: =SUMPRODUCT(G$13:G$34,$D$13:$D$34)/1000 -> 1.7983857 | H39: =SUMPRODUCT(H$13:H$34,$D$13:$D$34)/1000 -> 1.9014624 | I39: =SUMPRODUCT(I$13:I$34,$D$13:$D$34)/1000 -> 1.682612 | J39: =SUMPRODUCT(J$13:J$34,$D$13:$D$34)/1000 -> 1.6776166 | K39: =SUMPRODUCT(K$13:K$34,$D$13:$D$34)/1000 -> 2.6768425 | L39: =SUMPRODUCT(L$13:L$34,$D$13:$D$34)/1000 -> 1.8629179
A40: COSTE DE LA PIZZA (€) | E40: =E38+E39 -> 1.323289 | F40: =F38+F39 -> 0.56690991 | G40: =G38+G39 -> 2.0277956 | H40: =H38+H39 -> 2.1308723 | I40: =I38+I39 -> 1.912022 | J40: =J38+J39 -> 1.9070265 | K40: =K38+K39 -> 2.9062524 | L40: =L38+L39 -> 2.0923278
A41: Precio de venta sin IVA (€) | E41: =E12/(1+$B$5) -> 9.0909091 | F41: =F12/(1+$B$5) -> 8.6363636 | G41: =G12/(1+$B$5) -> 11.363636 | H41: =H12/(1+$B$5) -> 12.727273 | I41: =I12/(1+$B$5) -> 12.272727 | J41: =J12/(1+$B$5) -> 11.363636 | K41: =K12/(1+$B$5) -> 14.090909 | L41: =L12/(1+$B$5) -> 13.181818
A42: FOOD COST (%) | E42: =E40/E41 -> 0.14556179 | F42: =F40/F41 -> 0.0656422 | G42: =G40/G41 -> 0.17844601 | H42: =H40/H41 -> 0.16742568 | I42: =I40/I41 -> 0.15579438 | J42: =J40/J41 -> 0.16781833 | K42: =K40/K41 -> 0.20625017 | L42: =L40/L41 -> 0.15872832
A43: Semáforo contra el objetivo | E43: =IF(E42<=$B$6,"En objetivo",IF(E42<=$B$6+$B$7,"Vigila el coste","Por encima del objetivo")) -> En objetivo | F43: =IF(F42<=$B$6,"En objetivo",IF(F42<=$B$6+$B$7,"Vigila el coste","Por encima del objetivo")) -> En objetivo | G43: =IF(G42<=$B$6,"En objetivo",IF(G42<=$B$6+$B$7,"Vigila el coste","Por encima del objetivo")) -> En objetivo | H43: =IF(H42<=$B$6,"En objetivo",IF(H42<=$B$6+$B$7,"Vigila el coste","Por encima del objetivo")) -> En objetivo | I43: =IF(I42<=$B$6,"En objetivo",IF(I42<=$B$6+$B$7,"Vigila el coste","Por encima del objetivo")) -> En objetivo | J43: =IF(J42<=$B$6,"En objetivo",IF(J42<=$B$6+$B$7,"Vigila el coste","Por encima del objetivo")) -> En objetivo | K43: =IF(K42<=$B$6,"En objetivo",IF(K42<=$B$6+$B$7,"Vigila el coste","Por encima del objetivo")) -> En objetivo | L43: =IF(L42<=$B$6,"En objetivo",IF(L42<=$B$6+$B$7,"Vigila el coste","Por encima del objetivo")) -> En objetivo
A44: Margen por pizza (€, precio sin IVA − coste) | E44: =E41-E40 -> 7.7676201 | F44: =F41-F40 -> 8.0694537 | G44: =G41-G40 -> 9.3358407 | H44: =H41-H40 -> 10.5964 | I44: =I41-I40 -> 10.360705 | J44: =J41-J40 -> 9.4566098 | K44: =K41-K40 -> 11.184657 | L44: =L41-L40 -> 11.08949
A45: PVP con IVA para llegar al objetivo (€) | E45: =E40/$B$6*(1+$B$5) -> 5.8224716 | F45: =F40/$B$6*(1+$B$5) -> 2.4944036 | G45: =G40/$B$6*(1+$B$5) -> 8.9223007 | H45: =H40/$B$6*(1+$B$5) -> 9.3758381 | I45: =I40/$B$6*(1+$B$5) -> 8.4128966 | J45: =J40/$B$6*(1+$B$5) -> 8.3909167 | K45: =K40/$B$6*(1+$B$5) -> 12.787511 | L45: =L40/$B$6*(1+$B$5) -> 9.2062423
A46: Coste para llevar: pizza + caja (€) | E46: =E40+$B$8 -> 2.323289 | F46: =F40+$B$8 -> 1.5669099 | G46: =G40+$B$8 -> 3.0277956 | H46: =H40+$B$8 -> 3.1308723 | I46: =I40+$B$8 -> 2.912022 | J46: =J40+$B$8 -> 2.9070265 | K46: =K40+$B$8 -> 3.9062524 | L46: =L40+$B$8 -> 3.0923278
A47: Food cost para llevar con la caja (%) | E47: =E46/E41 -> 0.25556179 | F47: =F46/F41 -> 0.18143167 | G47: =G46/G41 -> 0.26644601 | H47: =H46/H41 -> 0.24599711 | I47: =I46/I41 -> 0.23727586 | J47: =J46/J41 -> 0.25581833 | K47: =K46/K41 -> 0.27721791 | L47: =L46/L41 -> 0.23459038
A48: El food cost de la tabla es el de la pizza servida en sala. Para llevar se suma la caja al coste y el precio de carta es el mismo; si cobras más por llevar o a domicilio, cambia el precio de la pizza para ver el efecto. No incluye la comisión de la plataforma de reparto, que se descuenta del precio, no del coste de la pizza.

Sheet Instrucciones
A1: INSTRUCCIONES DE USO — Calculadora de masa y escandallo por pizza
A2: Dos herramientas en un libro: la hoja «Masa» te dice cuánta harina, agua, sal y levadura necesitas para el número de bolas que vas a preparar y cuánto cuesta cada bola; la hoja «Escandallo» calcula el coste de 8 pizzas de ejemplo, su food cost, su margen y el precio de carta que necesitas. Solo se escribe en las celdas VERDES; lo demás se calcula.
A3: AVISO SOBRE EL NOMBRE
A5: AVISO FIJO. El semáforo de esta hoja solo dice si tus gramajes caben en los del pliego de la Especialidad Tradicional Garantizada (ETG): NO convierte tu pizza en «pizza napolitana». Ese nombre está reservado desde 2022 (Reglamento de Ejecución (UE) 2022/2313) y solo puede usarlo quien cumple TODO el pliego (incluido el horno de leña) y pasa la verificación oficial (Reglamento (UE) 2024/1143, arts. 72 y 73). La asociación AVPN es privada y no sustituye esa verificación. Mientras no la tengas, pon en la carta el nombre de la receta (Margherita, Marinara…).
A6: HOJA «MASA»
A8: 1. Bloque A (por litro de agua): escribe cuántas bolas quieres, su peso y la merma de amasado. Las cantidades por litro vienen del pliego de la Especialidad Tradicional Garantizada (Reglamento (UE) n.º 97/2010, anexo II): hasta 1.800 g de harina, 50 a 55 g de sal y 3 g de levadura de cerveza por litro de agua, con bolas de 180 a 250 g. El rango del pliego aparece en gris al lado.
A9: 2. El semáforo del bloque A dice si la harina, la sal y el peso de la bola caben en esos rangos. Verde no significa «pizza napolitana»: el pliego exige además fermentación en ciclo continuo, formado a mano y horno de leña, y la verificación oficial.
A10: 3. Bloque B (por % panadero): escribe la hidratación, la sal y la levadura como porcentaje del peso de la harina, que es como trabaja el oficio. Usa la misma masa total que el bloque A. Si le pones los porcentajes que el bloque A calcula, obtienes lo mismo.
A11: 4. Abajo eliges qué coste de masa por bola alimenta el escandallo: el del pliego (A) o el de tus porcentajes (B).
A12: HOJA «ESCANDALLO»
A14: 1. Escribe el IVA (10 %), el food cost objetivo, el margen de vigilancia y el coste de la caja para llevar.
A15: 2. En la tabla, cada fila es un ingrediente con su precio por kilo sin IVA y su merma (la parte que se pierde al limpiar o recortar). El precio neto por kilo divide el precio entre (1 − merma). Los gramos de cada pizza van en su columna; puedes cambiar los nombres, los gramos y los precios de carta, y usar las filas libres para tus propios ingredientes.
... A27: Versión 1.0 · octubre 2026 · aichef.pro/plan-negocio-pizzeria · info@aichef.pro
