Workbook

Sheet 0. Assumptions
A1: ASSUMPTIONS — the RATES and DRIVERS of the model are typed here
A2: Change the GREEN cells: the rest of the workbook recalculates on its own. Expense items are typed on their own tab (also in green) and are not repeated here. Amounts are in your currency.
A3: BUSINESS ACTIVITY
A4: Customers per day (year-1 average) | B4: 145 | C4: Customers served per day, averaged over the year, counting bar coffee and table brunch. Inside the 100-250 range that the industry benchmarks table of this workbook publishes for a small coffee shop; the seat turns this implies are calculated by the "Implied seat turns per day" cell on this same tab
A5: Average check (excl. sales tax) | B5: 11 | C5: EXCL. SALES TAX. The equivalent menu price is calculated by the "Menu price incl. sales tax (calculated)" cell on this same tab; compare it with the "Combined average check" in the industry benchmarks table, further down on the "Instructions" tab
A6: Operating days per year | B6: 340 | C6: The SAME number feeds the "3-Year P&L", the "Break-Even" tab and the "Scenarios" tab, so all three always work on the same operating calendar
A7: Volume growth in year 2 | B7: 0.07 | C7: Second year, with the neighborhood regulars already loyal. This is peak-hour occupancy, not brand-new customers: year 1 already starts from a steady base of customers per day
A8: Volume growth in year 3 | B8: 0.05 | C8: Third year, close to the seating ceiling during peak hours
A9: Menu price incl. sales tax (calculated) | B9: =IFERROR(IF($B$5="","",$B$5*(1+SUMPRODUCT('3-Year P&L'!$E$10:$E$11,'3-Year P&L'!$G$10:$G$11))),"") -> 11.88 | C9: =IFERROR("Average check excl. sales tax plus the weighted sales tax of your sales lines ("&TEXT(SUMPRODUCT('3-Year P&L'!$E$10:$E$11,'3-Year P&L'!$G$10:$G$11)*100,"0")&"%), rounded. In the US, menu prices usually exclude sales tax and it is added at the register; in the UK, menu prices include VAT.","") -> Average check excl. sales tax plus the weighted sales tax of your sales lines (8%), rounded. In the US, menu prices usually exclude sales tax and it is added at the register; in the UK, menu prices include VAT.
A10: SALES MIX AND COST OF GOODS SOLD
A11: FOOD share of total sales | B11: 0.41 | C11: Share of FOOD in total sales. It is an INPUT: change it here and the P&L, the cash flow and the sales tax collected recalculate on their own
A12: BEVERAGE share of total sales | B12: =IFERROR(IF(COUNT(B11)=0,"",1-B11),"") -> 0.59 | C12: Calculated as the remainder: food + beverage = 100%
A13: Cost of goods sold on FOOD sales | B13: 0.3 | C13: Cost of the food (brunch, pastries, toasts): inside the 30-35% that the industry benchmarks table of this workbook gives for brunch food
A14: Cost of goods sold on BEVERAGE sales | B14: 0.24 | C14: Cost of coffee and beverages (hot and cold) against their own sales: a weighted blend of the coffee and cold-drink ranges in the industry benchmarks table of this workbook
A15: Disposables and packaging as % of sales | B15: 0.03 | C15: Napkins, paper goods, to-go cups and bar cleaning supplies
A16: Delivery share of total sales | B16: 0 | C16: ZERO by default: the checklist for this opening lists delivery as a month 2-3 task ("Launch delivery if there is demand"), not a day-one task. Raise it to the real weight of the channel when you turn it on
A17: Delivery platform fee | B17: 0.25 | C17: Typical DoorDash / Uber Eats commission on orders served through that channel; confirm it in your contract before projecting
A18: Card processing fee | B18: 0.035 | C18: Card and mobile wallet fees on total sales; a counter-service coffee shop takes most tickets by card. The example (3.5%) is a blended rate: a percentage plus a per-transaction fee, which weighs more on small tickets; check your processor's statement and enter your effective rate (kit estimate)
A19: LABOR
A20: Employer payroll taxes | B20: 0.1 | C20: FICA (Social Security 6.2% + Medicare 1.45%) + federal and state unemployment taxes (FUTA / SUTA) + workers' comp. About 10% in total: adjust it to your state and your insurance carrier
A21: Monthly pay periods per year (keep 12) | B21: 12 | C21: Annual gross pay = monthly gross pay × this number. Keep 12 in the US: it counts the monthly salaries the model pays in a year, not how often you run payroll (weekly or biweekly payroll pays the same annual amount)
A22: Federal minimum wage, annual full-time | B22: 15080 | C22: US federal minimum wage: 7.25 per hour × 2,080 hours = 15,080 per year for a full-time job. Your state or city may set a higher floor: enter it in the state / local minimum wage cell below. Check the current rates at dol.gov
A23: RENT AND FIXED COSTS
A24: Monthly rent | B24: 4500 | C24: Space for a coffee shop with brunch: 30-40 indoor seats plus a patio. Include NNN / CAM charges (property tax, building insurance, common-area maintenance) in this cell, not just the base rent. Check it against the 12% of sales threshold in the "3-Year P&L" and the 10% target / 15% maximum in the industry benchmarks table of this workbook
A25: Security deposit (months of rent) | B25: 2 | C25: Months of rent held as a security deposit. It is set in your commercial lease, so check the terms before you sign
A26: Monthly utilities (electricity, water, gas) | B26: 1200 | C26: Electricity, water and gas for a coffee bar with a brunch oven: ask for the space's utility history before you sign
A27: Insurance (per year) | B27: 3500 | C27: General liability (landlords and events often require 1 million per occurrence) and property coverage or a business owner's policy (BOP) for the space
A28: Miscellaneous and contingency as % of sales | B28: 0.02 | C28: Cushion for operating expenses that are not budgeted
A29: FINANCING
A30: Owner's equity contributed | B30: 60000 | C30: Owners' contribution. With too little, lenders pass: they usually expect an owner equity injection (often around 10% for SBA start-ups; many want 20-30%) measured against the cash need calculated on the "Startup Costs" tab
A31: Loan requested | B31: 204000 | C31: Principal requested — bank or SBA 7(a): if your loan is an SBA 7(a), this is the cell. It is the only loan that the amortization schedule, the P&L interest and the DSCR use. The "Financing" tab checks that sources and uses match the cash need calculated on the "Startup Costs" tab, and has a cell that calculates the exact amount that balances them
A32: Nominal annual interest rate (not APR) | B32: 0.1 | C32: Nominal annual rate, not APR; get offers from two lenders, including an SBA-guaranteed loan, before you fix it
A33: Loan term (years) | B33: 10 | C33: Total years, interest-only period included
A34: Interest-only period (years) | B34: 0 | C34: Years in which you pay only interest, usually the first year, when cash is tightest. Zero by default in this workbook
A35: Working capital (months of fixed costs) | B35: 3 | C35: The minimum this workbook requires: a cushion of less than 3 months will not cover a slow season
A36: TAXES
A37: Effective income tax rate (years 1-2) | B37: 0.25 | C37: Example: 21% federal rate for a C corporation plus state tax, rounded to 25%. If you operate as a sole proprietorship, LLC taxed as a pass-through or S corporation, the business itself pays 0% here and you pay tax on the profit personally: set this to 0 and budget for your personal tax separately. The model applies this rate to the first two years with positive taxable income
A38: Effective income tax rate (from year 3) | B38: 0.25 | C38: From the third year with positive taxable income. Same example rate (21% federal C corporation + state). Confirm the rate that applies to you with your accountant and change it here
A39: Sales tax rate on sales | B39: 0.08 | C39: Example rate: state + local sales tax combined. It varies widely by state and city: look up yours. UK: 20% VAT on hot food and dine-in
A40: Sales tax rate on alcohol to go | B40: 0.08 | C40: Same example rate as above. Some states add separate liquor taxes: include them here if they apply to you. Alcohol served on site has its own rate in the sales tax breakdown block, further down. Utilities, equipment and services are handled in the cell below
...

Sheet Startup Costs
A1: BUSINESS PLAN: COFFEE SHOP WITH BRUNCH
A2: Estimated Startup Costs
A3: Adjust the figures to your project. The amounts are reference prices for a US coffee shop: get local quotes before you commit.
A5: Item | B5: Amount | C5: % of startup costs | D5: Notes | E5: Taxable / recoverable tax?
A6: STARTUP COSTS | B6: =IFERROR(IF(COUNT(B7:B32)=0,"",SUM(B7:B32)),"") -> 193800 | C6: =IFERROR(B6/$B$35,"") -> 0.73496312
A7: LLC formation and legal | B7: 1500 | C7: =IFERROR(B7/$B$35,"") -> 0.005688569 | D7: Articles of organization (state filing fee), registered agent and attorney time for the operating agreement. Fees vary by state | E7: No
A8: Licenses and health plan review | B8: 2000 | C8: =IFERROR(B8/$B$35,"") -> 0.0075847587 | D8: Business license, health permit fees and the health department plan review. Requirements vary by city and county | E8: No
A9: Architect and building permits | B9: 8000 | C9: =IFERROR(B9/$B$35,"") -> 0.030339035 | D9: Required in many places for a build-out or a change of use. Covers drawings, specifications and building permit fees | E9: Yes
A10: Construction / build-out | B10: 40000 | C10: =IFERROR(B10/$B$35,"") -> 0.15169517 | D10: Floors, paint, finishes and an accessible restroom (ADA) | E10: Yes
A11: Electrical and HVAC | B11: 15000 | C11: =IFERROR(B11/$B$35,"") -> 0.05688569 | D11: Minimum 15-20 kW of electrical service for the equipment | E11: Yes
A12: Plumbing (grease interceptor, floor drains, handwashing sinks) | B12: 10000 | C12: =IFERROR(B12/$B$35,"") -> 0.037923794 | D12: Water supply, drains, handwashing sinks and a grease interceptor if you cook; local code decides | E12: Yes
A13: Coffee grinders | B13: 3000 | C13: =IFERROR(B13/$B$35,"") -> 0.011377138 | D13: On-demand grinder, essential for specialty coffee | E13: Yes
A14: Oven | B14: 6000 | C14: =IFERROR(B14/$B$35,"") -> 0.022754276 | D14: For pastries, brunch and hot toasts | E14: Yes
A15: Refrigerated display case | B15: 5000 | C15: =IFERROR(B15/$B$35,"") -> 0.018961897 | D15: For sandwiches, cakes and pastries | E15: Yes
A16: Refrigeration | B16: 6000 | C16: =IFERROR(B16/$B$35,"") -> 0.022754276 | D16: 2-3 under-counter units plus 1 storage refrigerator | E16: Yes
A17: Griddle / panini press | B17: 2000 | C17: =IFERROR(B17/$B$35,"") -> 0.0075847587 | D17: For toasts, paninis and brunch eggs | E17: Yes
A18: Blenders, juicer, toaster | B18: 1500 | C18: =IFERROR(B18/$B$35,"") -> 0.005688569 | D18: Fresh juices, smoothies, toast | E18: Yes
... A29: POS and software | B29: 3000 | C29: =IFERROR(B29/$B$35,"") -> 0.011377138 | D29: Touchscreen POS with cash and inventory control software | E29: Yes
A30: Security deposit | B30: =IFERROR(IF('0. Assumptions'!$B$24="","",'0. Assumptions'!$B$24*'0. Assumptions'!$B$25),"") -> 9000 | C30: =IFERROR(B30/$B$35,"") -> 0.034131414 | D30: =IFERROR(""&TEXT('0. Assumptions'!$B$25,"0")&IF('0. Assumptions'!$B$25=1," month"," months")&" of rent, from ""0. Assumptions"". Refundable when the lease ends: it is not depreciated and carries no tax","") -> 2 months of rent, from "0. Assumptions". Refundable when the lease ends: it is not depreciated and carries no tax | E30: No
A31: Rent paid before opening | B31: =IFERROR(IF('0. Assumptions'!$B$24="","",'0. Assumptions'!$B$24*'0. Assumptions'!$B$54),"") -> 4500 | C31: =IFERROR(B31/$B$35,"") -> 0.017065707 | D31: =IFERROR("Rent "&IF('0. Assumptions'!$B$54=1,"for the month","for the "&TEXT('0. Assumptions'!$B$54,"0")&" months")&" of build-out and permits before opening. It does not overlap the P&L, which starts on opening day: its twelve months are twelve trading months","") -> Rent for the month of build-out and permits before opening. It does not overlap the P&L, which starts on opening day: its twelve months are twelve trading months | E31: Yes
A32: Build-out and setup contingency | B32: =IFERROR(IF(COUNT(B9,B10,B11,B12,B24,B25)=0,"",ROUND((B9+B10+B11+B12+B24+B25)*'0. Assumptions'!$B$55,0)),"") -> 8300 | C32: =IFERROR(B32/$B$35,"") -> 0.031476749 | D32: =IFERROR("At "&TEXT('0. Assumptions'!$B$55,"0%")&" of the BUILD-OUT items of this block (architect and building permits, construction, electrical and HVAC, plumbing, decor and lighting, signage), not of the whole block: the other items are left out. No lender funds a build-out without a "&"cushion: the percentage is in ""0. Assumptions""","") -> At 10% of the BUILD-OUT items of this block (architect and building permits, construction, electrical and HVAC, plumbing, decor and lighting, signage), not of the whole block: the other items are left out. No lender funds a build-out without a cushion: the percentage is in "0. Assumptions" | E32: Yes
A33: WORKING CAPITAL | B33: =IFERROR(IF(B34="","",B34),"") -> 69886.7 | C33: =IFERROR(B33/$B$35,"") -> 0.26503688
A34: Operating cushion until break-even | B34: =IFERROR(IF('0. Assumptions'!$B$35*('3-Year P&L'!$B$37-'3-Year P&L'!$B$35)=0,"",'0. Assumptions'!$B$35*('3-Year P&L'!$B$37-'3-Year P&L'!$B$35)/12),"") -> 69886.7 | C34: =IFERROR(B34/$B$35,"") -> 0.26503688 | D34: =IFERROR("Covers "&TEXT('0. Assumptions'!$B$35,"0")&IF('0. Assumptions'!$B$35=1," month"," months")&" of year-1 CASH fixed costs (the P&L fixed costs minus depreciation, which is not paid out), the minimum the Instructions of this workbook ask for","") -> Covers 3 months of year-1 CASH fixed costs (the P&L fixed costs minus depreciation, which is not paid out), the minimum the Instructions of this workbook ask for | E34: No
A35: TOTAL STARTUP COSTS (sum of the blocks) | B35: =IFERROR(B6+B33,"") -> 263686.7 | D35: =IFERROR("The percentages in column C are read on this figure, which includes the working capital ("&TEXT(C33,"0%")&" of the total). To compare the breakdown with another plan, use the CAPEX row below.","") -> The percentages in column C are read on this figure, which includes the working capital (27% of the total). To compare the breakdown with another plan, use the CAPEX row below.
A36: CAPEX (startup costs excluding working capital) | B36: =IFERROR(B35-B33,"") -> 193800 | D36: What you buy: build-out, equipment, launch and formation costs. The cash cushion is not an investment: it is working capital
A37: Recoverable input tax on capex | B37: =IFERROR(IF(B35="","",SUMIF($E$7:$E$32,"Yes",$B$7:$B$32)*'0. Assumptions'!$B$41),"") -> 0 | D37: =IFERROR("At "&TEXT('0. Assumptions'!$B$41,"0%")&" on the items marked ""Yes"" in the tax column. US: the sales tax you pay on equipment is part of its cost and is not recovered, so this rate is 0. UK (VAT-registered): 20%, reclaimed on your VAT return, but you pay it first, so the loan has to cover it","") -> At 0% on the items marked "Yes" in the tax column. US: the sales tax you pay on equipment is part of its cost and is not recovered, so this rate is 0. UK (VAT-registered): 20%, reclaimed on your VAT return, but you pay it first, so the loan has to cover it
A38: TOTAL CASH NEEDED AT LAUNCH | B38: =IFERROR(B35+B37,"") -> 263686.7 | D38: This is the figure the Financing tab has to cover
A39: DEPRECIATION BASES (not added to startup costs)
A40: Build-out, fixtures and setup | B40: =IFERROR(IF(B9="","",B9+B10+B11+B12+B24+B25+B32),"") -> 91300 | D40: =IFERROR("Depreciated over "&TEXT('0. Assumptions'!$B$44,"0")&" years","") -> Depreciated over 10 years
A41: Machinery, furniture and equipment | B41: =IFERROR(IF(B13="","",B13+B14+B15+B16+B17+B18+B19+B20+B21+B22+B23+B28+B29),"") -> 76500 | D41: =IFERROR("Depreciated over "&TEXT('0. Assumptions'!$B$45,"0")&" years","") -> Depreciated over 7 years
A42: Annual depreciation of fixed assets | B42: =IFERROR(B40/MAX(1,'0. Assumptions'!$B$44)+B41/MAX(1,'0. Assumptions'!$B$45),"") -> 20058.571 | D42: =IFERROR("Not depreciated, because they are not fixed assets: entity formation and legal, licenses and health plan review, launch marketing, opening inventory, security deposit, pre-opening rent and the working capital reserve. They add up to "&TEXT(B35-B40-B41,"#,##0")&" of the "&TEXT(B35,"#,##0")&" total investment.","") -> Not depreciated, because they are not fixed assets: entity formation and legal, licenses and health plan review, launch marketing, opening inventory, security deposit, pre-opening rent and the working capital reserve. They add up to 95887 of the 263687 total investment.

Sheet 3-Year P&L
A1: PRO FORMA P&L — 3 YEARS
A2: Base scenario — Coffee shop with brunch, 35-40 seats
A4: Item | B4: Year 1 | C4: Year 2 | D4: Year 3 | E4: % of sales (year 1) | F4: Notes | G4: Sales tax rate on the line (%)
A5: REVENUE
A6: Customers per day (average) | B6: =IFERROR(IF('0. Assumptions'!$B$4="","",'0. Assumptions'!$B$4),"") -> 145 | C6: =IFERROR(B6*(1+'0. Assumptions'!$B$7),"") -> 155.15 | D6: =IFERROR(C6*(1+'0. Assumptions'!$B$8),"") -> 162.9075 | F6: Growth for years 2 and 3 is set in "0. Assumptions"
A7: Average check (excl. sales tax) | B7: =IFERROR(IF('0. Assumptions'!$B$5="","",'0. Assumptions'!$B$5),"") -> 11 | C7: =IFERROR(IF(B7="","",B7),"") -> 11 | D7: =IFERROR(IF(C7="","",C7),"") -> 11 | F7: Held constant at year-1 prices: a price increase is a separate decision
A8: Operating days per year | B8: =IFERROR(IF('0. Assumptions'!$B$6="","",'0. Assumptions'!$B$6),"") -> 340 | C8: =IFERROR(IF(B8="","",B8),"") -> 340 | D8: =IFERROR(IF(C8="","",C8),"") -> 340
A9: TOTAL REVENUE (excl. sales tax) | B9: =IFERROR(IF(B6*B7*B8=0,"",B6*B7*B8),"") -> 542300 | C9: =IFERROR(IF(C6*C7*C8=0,"",C6*C7*C8),"") -> 580261 | D9: =IFERROR(IF(D6*D7*D8=0,"",D6*D7*D8),"") -> 609274.05 | E9: =IFERROR(IF(B9="","",1),"") -> 1
A10: Food sales (brunch, pastries, toasts and other) | B10: =IFERROR(IF(B9="","",B9*$E$10),"") -> 222343 | C10: =IFERROR(IF(C9="","",C9*$E$10),"") -> 237907.01 | D10: =IFERROR(IF(D9="","",D9*$E$10),"") -> 249802.36 | E10: =IFERROR(IF('0. Assumptions'!$B$11="","",'0. Assumptions'!$B$11),"") -> 0.41 | F10: Weekend brunch, pastries and toasts from the morning service, plus smaller seasonal sales (extra takeout, mini catering, merchandise) | G10: =IFERROR(IF(B9="","",'0. Assumptions'!$B$39),"") -> 0.08
A11: Beverage sales (coffee, hot and cold drinks) | B11: =IFERROR(IF(B9="","",B9*$E$11),"") -> 319957 | C11: =IFERROR(IF(C9="","",C9*$E$11),"") -> 342353.99 | D11: =IFERROR(IF(D9="","",D9*$E$11),"") -> 359471.69 | E11: =IFERROR(IF('0. Assumptions'!$B$12="","",'0. Assumptions'!$B$12),"") -> 0.59 | F11: Espresso, milk drinks, teas and brewed drinks from the bar, plus fresh juices and smoothies, which carry the highest cost because they use fresh product | G11: =IFERROR(IF(B9="","",('0. Assumptions'!$B$62*((1-'0. Assumptions'!$B$16)*'0. Assumptions'!$B$63+'0. Assumptions'!$B$16*'0. Assumptions'!$B$40)+(1-'0. Assumptions'!$B$62)*'0. Assumptions'!$B$39)),"") -> 0.08
A12: VARIABLE COSTS
A13: Cost of goods sold — food | B13: =IFERROR(IF(B9="","",B9*'0. Assumptions'!$B$11*'0. Assumptions'!$B$13),"") -> 66702.9 | C13: =IFERROR(IF(C9="","",C9*'0. Assumptions'!$B$11*'0. Assumptions'!$B$13),"") -> 71372.103 | D13: =IFERROR(IF(D9="","",D9*'0. Assumptions'!$B$11*'0. Assumptions'!$B$13),"") -> 74940.708 | E13: =IFERROR(B13/$B$9,"") -> 0.123 | F13: =IFERROR("At "&TEXT('0. Assumptions'!$B$13,"0%")&" of FOOD sales, not of total sales: beverages have their own line","") -> At 30% of FOOD sales, not of total sales: beverages have their own line | G13: =IFERROR(IF(B9="","",'0. Assumptions'!$B$41),"") -> 0
A14: Cost of goods sold — beverage | B14: =IFERROR(IF(B9="","",B9*'0. Assumptions'!$B$12*'0. Assumptions'!$B$14),"") -> 76789.68 | C14: =IFERROR(IF(C9="","",C9*'0. Assumptions'!$B$12*'0. Assumptions'!$B$14),"") -> 82164.958 | D14: =IFERROR(IF(D9="","",D9*'0. Assumptions'!$B$12*'0. Assumptions'!$B$14),"") -> 86273.205 | E14: =IFERROR(B14/$B$9,"") -> 0.1416 | F14: =IFERROR("At "&TEXT('0. Assumptions'!$B$14,"0%")&" of BEVERAGE sales","") -> At 24% of BEVERAGE sales | G14: =IFERROR(IF(B9="","",'0. Assumptions'!$B$41),"") -> 0
A15: Disposables and packaging | B15: =IFERROR(IF(B9="","",B9*'0. Assumptions'!$B$15),"") -> 16269 | C15: =IFERROR(IF(C9="","",C9*'0. Assumptions'!$B$15),"") -> 17407.83 | D15: =IFERROR(IF(D9="","",D9*'0. Assumptions'!$B$15),"") -> 18278.221 | E15: =IFERROR(B15/$B$9,"") -> 0.03 | G15: =IFERROR(IF(B9="","",'0. Assumptions'!$B$41),"") -> 0
A16: Delivery platform fees | B16: =IFERROR(IF(B9="","",B9*'0. Assumptions'!$B$16*'0. Assumptions'!$B$17),"") -> 0 | C16: =IFERROR(IF(C9="","",C9*'0. Assumptions'!$B$16*'0. Assumptions'!$B$17),"") -> 0 | D16: =IFERROR(IF(D9="","",D9*'0. Assumptions'!$B$16*'0. Assumptions'!$B$17),"") -> 0 | E16: =IFERROR(B16/$B$9,"") -> 0 | F16: Applied to the sales of THAT CHANNEL. With 0% delivery in Assumptions, this line is zero | G16: =IFERROR(IF(B9="","",'0. Assumptions'!$B$41),"") -> 0
A17: Card processing fees | B17: =IFERROR(IF(B9="","",B9*'0. Assumptions'!$B$18),"") -> 18980.5 | C17: =IFERROR(IF(C9="","",C9*'0. Assumptions'!$B$18),"") -> 20309.135 | D17: =IFERROR(IF(D9="","",D9*'0. Assumptions'!$B$18),"") -> 21324.592 | E17: =IFERROR(B17/$B$9,"") -> 0.035 | F17: Card processing fees are not subject to sales tax: no tax is recovered or deducted for them | G17: 0
A18: Miscellaneous and contingency | B18: =IFERROR(IF(B9="","",B9*'0. Assumptions'!$B$28),"") -> 10846 | C18: =IFERROR(IF(C9="","",C9*'0. Assumptions'!$B$28),"") -> 11605.22 | D18: =IFERROR(IF(D9="","",D9*'0. Assumptions'!$B$28),"") -> 12185.481 | E18: =IFERROR(B18/$B$9,"") -> 0.02 | F18: =IFERROR("At "&TEXT('0. Assumptions'!$B$28,"0%")&" of sales. It is a VARIABLE cost: it moves with revenue, so it cannot sit in fixed costs","") -> At 2% of sales. It is a VARIABLE cost: it moves with revenue, so it cannot sit in fixed costs | G18: =IFERROR(IF(B9="","",'0. Assumptions'!$B$41),"") -> 0
A19: TOTAL VARIABLE COSTS | B19: =IFERROR(IF(B9="","",SUM(B13:B18)),"") -> 189588.08 | C19: =IFERROR(IF(C9="","",SUM(C13:C18)),"") -> 202859.25 | D19: =IFERROR(IF(D9="","",SUM(D13:D18)),"") -> 213002.21 | E19: =IFERROR(B19/$B$9,"") -> 0.3496
A20: GROSS MARGIN | B20: =IFERROR(IF(B9="","",B9-B19),"") -> 352711.92 | C20: =IFERROR(IF(C9="","",C9-C19),"") -> 377401.75 | D20: =IFERROR(IF(D9="","",D9-D19),"") -> 396271.84 | E20: =IFERROR(B20/$B$9,"") -> 0.6504
A21: FIXED COSTS
A22: Rent | B22: =IFERROR(IF(B9="","",'0. Assumptions'!$B$24*12),"") -> 54000 | C22: =IFERROR(IF(C9="","",B22*(1+'0. Assumptions'!$B$48)),"") -> 54000 | D22: =IFERROR(IF(D9="","",C22*(1+'0. Assumptions'!$B$48)),"") -> 54000 | E22: =IFERROR(B22/$B$9,"") -> 0.099575881 | F22: The monthly amount is on the "0. Assumptions" tab; here it is multiplied by twelve. Rent for the build-out months, which comes before opening, is on the "Startup Costs" tab and is NOT counted twice | G22: =IFERROR(IF(B9="","",'0. Assumptions'!$B$41),"") -> 0
A23: Labor (wages + employer payroll taxes) | B23: =IFERROR(IF(B9="","",Staffing!$G$11),"") -> 168946.8 | C23: =IFERROR(IF(C9="","",Staffing!$B$15),"") -> 174946.8 | D23: =IFERROR(IF(D9="","",Staffing!$B$16),"") -> 180946.8 | E23: =IFERROR(B23/$B$9,"") -> 0.31153753 | F23: Comes from the Staffing tab: it is the SAME number, not a separate estimate. Years 2 and 3 add the new hires declared on that tab, not a percentage of volume | G23: 0
A24: Utilities (electricity, water, gas) | B24: =IFERROR(IF(B9="","",'0. Assumptions'!$B$26*12),"") -> 14400 | C24: =IFERROR(IF(C9="","",B24*(1+'0. Assumptions'!$B$48)),"") -> 14400 | D24: =IFERROR(IF(D9="","",C24*(1+'0. Assumptions'!$B$48)),"") -> 14400 | E24: =IFERROR(B24/$B$9,"") -> 0.026553568 | F24: Enter the monthly bills excl. sales tax. The workbook applies a single tax treatment to this whole line, the one in the column next to it; if one utility is taxed differently in your area, give it its own line | G24: =IFERROR(IF(B9="","",'0. Assumptions'!$B$41),"") -> 0
A25: Insurance (general liability + property / auto) | B25: =IFERROR(IF(B9="","",'0. Assumptions'!$B$27),"") -> 3500 | C25: =IFERROR(IF(C9="","",B25*(1+'0. Assumptions'!$B$48)),"") -> 3500 | D25: =IFERROR(IF(D9="","",C25*(1+'0. Assumptions'!$B$48)),"") -> 3500 | E25: =IFERROR(B25/$B$9,"") -> 0.0064539923 | F25: Insurance premiums are not subject to sales tax: there is no recoverable tax on them | G25: 0
A26: Accounting / bookkeeping | B26: 3000 | C26: =IFERROR(IF(C9="","",B26*(1+'0. Assumptions'!$B$48)),"") -> 3000 | D26: =IFERROR(IF(D9="","",C26*(1+'0. Assumptions'!$B$48)),"") -> 3000 | E26: =IFERROR(B26/$B$9,"") -> 0.0055319934 | G26: =IFERROR(IF(B9="","",'0. Assumptions'!$B$41),"") -> 0
A27: Equipment maintenance | B27: 2000 | C27: =IFERROR(IF(C9="","",B27*(1+'0. Assumptions'!$B$48)),"") -> 2000 | D27: =IFERROR(IF(D9="","",C27*(1+'0. Assumptions'!$B$48)),"") -> 2000 | E27: =IFERROR(B27/$B$9,"") -> 0.0036879956 | G27: =IFERROR(IF(B9="","",'0. Assumptions'!$B$41),"") -> 0
A28: Marketing and advertising | B28: 6000 | C28: =IFERROR(IF(C9="","",B28*(1+'0. Assumptions'!$B$48)),"") -> 6000 | D28: =IFERROR(IF(D9="","",C28*(1+'0. Assumptions'!$B$48)),"") -> 6000 | E28: =IFERROR(B28/$B$9,"") -> 0.011063987 | G28: =IFERROR(IF(B9="","",'0. Assumptions'!$B$41),"") -> 0
A29: Software (POS, website, delivery) | B29: 1800 | C29: =IFERROR(IF(C9="","",B29*(1+'0. Assumptions'!$B$48)),"") -> 1800 | D29: =IFERROR(IF(D9="","",C29*(1+'0. Assumptions'!$B$48)),"") -> 1800 | E29: =IFERROR(B29/$B$9,"") -> 0.003319196 | G29: =IFERROR(IF(B9="","",'0. Assumptions'!$B$41),"") -> 0
A30: Cleaning supplies | B30: 2400 | C30: =IFERROR(IF(C9="","",B30*(1+'0. Assumptions'!$B$48)),"") -> 2400 | D30: =IFERROR(IF(D9="","",C30*(1+'0. Assumptions'!$B$48)),"") -> 2400 | E30: =IFERROR(B30/$B$9,"") -> 0.0044255947 | G30: =IFERROR(IF(B9="","",'0. Assumptions'!$B$41),"") -> 0
A31: Waste and recycling (organic waste, cardboard and used oil if you fry) | B31: 1200 | C31: =IFERROR(IF(C9="","",B31*(1+'0. Assumptions'!$B$48)),"") -> 1200 | D31: =IFERROR(IF(D9="","",C31*(1+'0. Assumptions'!$B$48)),"") -> 1200 | E31: =IFERROR(B31/$B$9,"") -> 0.0022127973 | F31: Licensed waste / grease hauler; the checklist asks for the contract before you open. This coffee shop has no frying line, so the volume is lower than a restaurant's: get a quote in your area | G31: =IFERROR(IF(B9="","",'0. Assumptions'!$B$41),"") -> 0
A32: Pest control | B32: 800 | C32: =IFERROR(IF(C9="","",B32*(1+'0. Assumptions'!$B$48)),"") -> 800 | D32: =IFERROR(IF(D9="","",C32*(1+'0. Assumptions'!$B$48)),"") -> 800 | E32: =IFERROR(B32/$B$9,"") -> 0.0014751982 | F32: Licensed pest control company; part of the HACCP-based food safety plan that the checklist already requires | G32: =IFERROR(IF(B9="","",'0. Assumptions'!$B$41),"") -> 0
A33: Music licensing (ASCAP, BMI, SESAC) | B33: 600 | C33: =IFERROR(IF(C9="","",B33*(1+'0. Assumptions'!$B$48)),"") -> 600 | D33: =IFERROR(IF(D9="","",C33*(1+'0. Assumptions'!$B$48)),"") -> 600 | E33: =IFERROR(B33/$B$9,"") -> 0.0011063987 | F33: ASCAP, BMI and SESAC are separate licensing organizations; the fee depends on the size and capacity of your space | G33: =IFERROR(IF(B9="","",'0. Assumptions'!$B$41),"") -> 0
A34: Training and certifications | B34: 500 | C34: =IFERROR(IF(C9="","",B34*(1+'0. Assumptions'!$B$48)),"") -> 500 | D34: =IFERROR(IF(D9="","",C34*(1+'0. Assumptions'!$B$48)),"") -> 500 | E34: =IFERROR(B34/$B$9,"") -> 0.00092199889 | F34: Food handler cards, Certified Food Protection Manager certification (for example ServSafe) and basic workplace safety training for the team. Requirements vary by state and county | G34: =IFERROR(IF(B9="","",'0. Assumptions'!$B$41),"") -> 0
A35: Depreciation of fixed assets | B35: =IFERROR(IF(B9="","",'Startup Costs'!$B$42),"") -> 20058.571 | C35: =IFERROR(IF(C9="","",B35),"") -> 20058.571 | D35: =IFERROR(IF(D9="","",B35),"") -> 20058.571 | E35: =IFERROR(B35/$B$9,"") -> 0.036987961 | F35: Comes from the depreciation bases on the Startup Costs tab: real fixed assets only. It does NOT rise with inflation: it is a charge on the HISTORICAL cost of the assets | G35: 0
A36: Interest expense (loan interest) | B36: =IFERROR(IF(B9="","",Financing!$B$44),"") -> 20400 | C36: =IFERROR(IF(C9="","",Financing!$B$46),"") -> 19119.994 | D36: =IFERROR(IF(D9="","",Financing!$B$48),"") -> 17711.987 | E36: =IFERROR(B36/$B$9,"") -> 0.037617555 | F36: Only INTEREST is an expense. Principal repaid appears on the cash flow tab | G36: 0
A37: TOTAL FIXED COSTS | B37: =IFERROR(IF(B9="","",SUM(B22:B36)),"") -> 299605.37 | C37: =IFERROR(IF(C9="","",SUM(C22:C36)),"") -> 304325.37 | D37: =IFERROR(IF(D9="","",SUM(D22:D36)),"") -> 308917.36 | E37: =IFERROR(B37/$B$9,"") -> 0.55247164
A38: Recoverable input tax on variable costs | B38: =IFERROR(IF(B9="","",SUMPRODUCT(B13:B18,G13:G18)),"") -> 0 | C38: =IFERROR(IF(C9="","",SUMPRODUCT(C13:C18,G13:G18)),"") -> 0 | D38: =IFERROR(IF(D9="","",SUMPRODUCT(D13:D18,G13:G18)),"") -> 0 | F38: Each line at ITS OWN rate, read from the column next to it. It is what the cash flow tab overpays to suppliers and later deducts (zero wherever no tax is recoverable)
A39: Recoverable input tax on fixed costs | B39: =IFERROR(IF(B9="","",SUMPRODUCT(B22:B36,G22:G36)),"") -> 0 | C39: =IFERROR(IF(C9="","",SUMPRODUCT(C22:C36,G22:G36)),"") -> 0 | D39: =IFERROR(IF(D9="","",SUMPRODUCT(D22:D36,G22:G36)),"") -> 0
A40: PRE-TAX INCOME (EBT) | B40: =IFERROR(IF(B9="","",B20-B37),"") -> 53106.549 | C40: =IFERROR(IF(C9="","",C20-C37),"") -> 73076.389 | D40: =IFERROR(IF(D9="","",D20-D37),"") -> 87354.483 | E40: =IFERROR(B40/$B$9,"") -> 0.097928358
A41: Net operating losses carried forward (opening) | B41: =IFERROR(IF(B9="","",'0. Assumptions'!$B$42),"") -> 0 | C41: =IFERROR(IF(C9="","",B46),"") -> 0 | D41: =IFERROR(IF(D9="","",C46),"") -> 0 | F41: Federal rules let a year's losses offset the profits of later years (the federal limit is 80% of taxable income; this model offsets 100% as a simplification)
...

Sheet Break-Even
A1: BREAK-EVEN ANALYSIS
A2: Monthly and daily break-even — Coffee shop with brunch
A4: Variable | B4: Year 1 | C4: Year 2 | D4: Year 3 | E4: Notes
A5: BASE DATA BY YEAR
A6: Annual fixed costs | B6: =IFERROR(IF('3-Year P&L'!$B$9="","",'3-Year P&L'!$B$37),"") -> 299605.37 | C6: =IFERROR(IF('3-Year P&L'!$C$9="","",'3-Year P&L'!$C$37),"") -> 304325.37 | D6: =IFERROR(IF('3-Year P&L'!$D$9="","",'3-Year P&L'!$D$37),"") -> 308917.36 | E6: The SAME fixed costs as the P&L. Each year has its own, which is why the threshold cannot be a single one for all three years
A7: Monthly fixed costs | B7: =IFERROR(IF('3-Year P&L'!$B$9="","",B6/12),"") -> 24967.114 | C7: =IFERROR(IF('3-Year P&L'!$C$9="","",C6/12),"") -> 25360.447 | D7: =IFERROR(IF('3-Year P&L'!$D$9="","",D6/12),"") -> 25743.113
A8: Average check (excl. sales tax) | B8: =IFERROR(IF('3-Year P&L'!$B$9="","",'3-Year P&L'!$B$7),"") -> 11 | C8: =IFERROR(IF('3-Year P&L'!$C$9="","",'3-Year P&L'!$C$7),"") -> 11 | D8: =IFERROR(IF('3-Year P&L'!$D$9="","",'3-Year P&L'!$D$7),"") -> 11
A9: Variable cost per customer | B9: =IFERROR(IF('3-Year P&L'!$B$9="","",'3-Year P&L'!$B$19/('3-Year P&L'!$B$6*'3-Year P&L'!$B$8)),"") -> 3.8456 | C9: =IFERROR(IF('3-Year P&L'!$C$9="","",'3-Year P&L'!$C$19/('3-Year P&L'!$C$6*'3-Year P&L'!$C$8)),"") -> 3.8456 | D9: =IFERROR(IF('3-Year P&L'!$D$9="","",'3-Year P&L'!$D$19/('3-Year P&L'!$D$6*'3-Year P&L'!$D$8)),"") -> 3.8456 | E9: Comes from the P&L total variable costs, not from a separate estimate. It includes miscellaneous and contingency, which is a percentage of sales
A10: Contribution margin per customer | B10: =IFERROR(IF('3-Year P&L'!$B$9="","",B8-B9),"") -> 7.1544 | C10: =IFERROR(IF('3-Year P&L'!$C$9="","",C8-C9),"") -> 7.1544 | D10: =IFERROR(IF('3-Year P&L'!$D$9="","",D8-D9),"") -> 7.1544 | E10: Average check minus unit variable cost
A11: Operating days per year | B11: =IFERROR(IF('3-Year P&L'!$B$9="","",'3-Year P&L'!$B$8),"") -> 340 | C11: =IFERROR(IF('3-Year P&L'!$C$9="","",'3-Year P&L'!$C$8),"") -> 340 | D11: =IFERROR(IF('3-Year P&L'!$D$9="","",'3-Year P&L'!$D$8),"") -> 340 | E11: The same calendar as the P&L and the scenarios
A12: Principal repaid in the year | B12: =IFERROR(IF('3-Year P&L'!$B$9="","",Financing!$B$45),"") -> 12800.061 | C12: =IFERROR(IF('3-Year P&L'!$C$9="","",Financing!$B$47),"") -> 14080.067 | D12: =IFERROR(IF('3-Year P&L'!$D$9="","",Financing!$B$49),"") -> 15488.073 | E12: Principal is NOT a P&L expense, but it leaves the cash account. Without it, the published break-even threshold would sit below the real one
A13: ACCOUNTING BREAK-EVEN (includes depreciation)
A14: Customers needed per year | B14: =IFERROR(IF('3-Year P&L'!$B$9="","",IF(B10<=0,"",B6/B10)),"") -> 41877.079 | C14: =IFERROR(IF('3-Year P&L'!$C$9="","",IF(C10<=0,"",C6/C10)),"") -> 42536.812 | D14: =IFERROR(IF('3-Year P&L'!$D$9="","",IF(D10<=0,"",D6/D10)),"") -> 43178.654
A15: Customers needed per day | B15: =IFERROR(IF('3-Year P&L'!$B$9="","",B14/B11),"") -> 123.16788 | C15: =IFERROR(IF('3-Year P&L'!$C$9="","",C14/C11),"") -> 125.10827 | D15: =IFERROR(IF('3-Year P&L'!$D$9="","",D14/D11),"") -> 126.99604
A16: Revenue needed per year | B16: =IFERROR(IF('3-Year P&L'!$B$9="","",B14*B8),"") -> 460647.87 | C16: =IFERROR(IF('3-Year P&L'!$C$9="","",C14*C8),"") -> 467904.93 | D16: =IFERROR(IF('3-Year P&L'!$D$9="","",D14*D8),"") -> 474965.19
A17: CASH BREAK-EVEN (loan payments in, depreciation out)
A18: Cash fixed costs + principal repaid for the year | B18: =IFERROR(IF('3-Year P&L'!$B$9="","",B6-'3-Year P&L'!$B$35+B12),"") -> 292346.86 | C18: =IFERROR(IF('3-Year P&L'!$C$9="","",C6-'3-Year P&L'!$C$35+C12),"") -> 298346.86 | D18: =IFERROR(IF('3-Year P&L'!$D$9="","",D6-'3-Year P&L'!$D$35+D12),"") -> 304346.86 | E18: The P&L fixed costs without depreciation (which is not paid in cash) and WITH principal repaid (which is). This is the threshold that decides whether cash holds up
A19: Customers needed per year (cash) | B19: =IFERROR(IF('3-Year P&L'!$B$9="","",IF(B10<=0,"",B18/B10)),"") -> 40862.527 | C19: =IFERROR(IF('3-Year P&L'!$C$9="","",IF(C10<=0,"",C18/C10)),"") -> 41701.171 | D19: =IFERROR(IF('3-Year P&L'!$D$9="","",IF(D10<=0,"",D18/D10)),"") -> 42539.816
A20: Customers needed per day (cash) | B20: =IFERROR(IF('3-Year P&L'!$B$9="","",B19/B11),"") -> 120.1839 | C20: =IFERROR(IF('3-Year P&L'!$C$9="","",C19/C11),"") -> 122.6505 | D20: =IFERROR(IF('3-Year P&L'!$D$9="","",D19/D11),"") -> 125.11711
A21: Revenue needed per year (cash) | B21: =IFERROR(IF('3-Year P&L'!$B$9="","",B19*B8),"") -> 449487.79 | C21: =IFERROR(IF('3-Year P&L'!$C$9="","",C19*C8),"") -> 458712.89 | D21: =IFERROR(IF('3-Year P&L'!$D$9="","",D19*D8),"") -> 467937.98
A22: COMPARISON WITH THE PLAN
A23: Customers per day forecast in the plan | B23: =IFERROR(IF('3-Year P&L'!$B$9="","",'3-Year P&L'!$B$6),"") -> 145 | C23: =IFERROR(IF('3-Year P&L'!$C$9="","",'3-Year P&L'!$C$6),"") -> 155.15 | D23: =IFERROR(IF('3-Year P&L'!$D$9="","",'3-Year P&L'!$D$6),"") -> 162.9075
A24: Cushion above CASH break-even (%) | B24: =IFERROR(IF('3-Year P&L'!$B$9="","",B23/B20-1),"") -> 0.20648438 | C24: =IFERROR(IF('3-Year P&L'!$C$9="","",C23/C20-1),"") -> 0.26497646 | D24: =IFERROR(IF('3-Year P&L'!$D$9="","",D23/D20-1),"") -> 0.30204018 | E24: How far planned sales sit above cash break-even. The drop you can absorb before you cannot pay the fixed costs and the loan payment is somewhat smaller: with a 25% cushion, 20%. The required minimum is set in the "0. Assumptions" tab
A25: Maximum seat turns per day the space allows | B25: 3 | E25: Full table services per seat per day that your opening hours allow. It is the physical ceiling of the space, not a target
A26: Seat turns per day that the cash break-even requires | B26: =IFERROR(IF('3-Year P&L'!$B$9="","",B20/'0. Assumptions'!$B$51),"") -> 2.6707534 | C26: =IFERROR(IF('3-Year P&L'!$C$9="","",C20/'0. Assumptions'!$B$51),"") -> 2.7255668 | D26: =IFERROR(IF('3-Year P&L'!$D$9="","",D20/'0. Assumptions'!$B$51),"") -> 2.7803801 | E26: Break-even customers spread across the seats declared on the "0. Assumptions" tab. If it is above the ceiling in the row above, the break-even is out of reach for the space
A27: INTERPRETATION
A28: =IFERROR("With the average check excl. sales tax above, you need "&TEXT(ROUNDUP(B15,0),"0")&" customers a day over your "&TEXT(B11,"0")&" opening days to avoid losing money (accounting break-even, depreciation included), and "&TEXT(ROUNDUP(B20,0),"0")&" for cash to hold (cash break-even: depreciation out, because it is not paid, and the year's loan payment in"&IF(B12=0,"; no principal is repaid this year (interest-only period or no loan)","")&"). The ""Revenue needed per year"" rows show the same figures in your currency.","") -> With the average check excl. sales tax above, you need 124 customers a day over your 340 opening days to avoid losing money (accounting break-even, depreciation included), and 121 for cash to hold (cash break-even: depreciation out, because it is not paid, and the year's loan payment in). The "Revenue needed per year" rows show the same figures in your currency.
A30: BREAK-EVEN SENSITIVITY
A31: Customers per day needed to cover costs for each average check (columns) and each variable cost per customer (rows). Green cells are below the customers per day the plan forecasts.
A33: Customers per day needed: average check excl. sales tax (columns) × variable cost per customer (rows) | B33: =IFERROR($B$8-2,"") -> 9 | C33: =IFERROR(IF($B$8="","",$B$8),"") -> 11 | D33: =IFERROR($B$8+2,"") -> 13 | E33: =IFERROR($B$8+4,"") -> 15
A34: =IFERROR($B$9*0.85,"") -> 3.26876 | B34: =IFERROR(IF($B$33-$A34<=0,"",$B$6/($B$33-$A34)/$B$11),"") -> 153.75246 | C34: =IFERROR(IF($C$33-$A34<=0,"",$B$6/($C$33-$A34)/$B$11),"") -> 113.97813 | D34: =IFERROR(IF($D$33-$A34<=0,"",$B$6/($D$33-$A34)/$B$11),"") -> 90.552927 | E34: =IFERROR(IF($E$33-$A34<=0,"",$B$6/($E$33-$A34)/$B$11),"") -> 75.115015
A35: =IFERROR($B$9*0.925,"") -> 3.55718 | B35: =IFERROR(IF($B$33-$A35<=0,"",$B$6/($B$33-$A35)/$B$11),"") -> 161.89995 | C35: =IFERROR(IF($C$33-$A35<=0,"",$B$6/($C$33-$A35)/$B$11),"") -> 118.39495 | D35: =IFERROR(IF($D$33-$A35<=0,"",$B$6/($D$33-$A35)/$B$11),"") -> 93.318762 | E35: =IFERROR(IF($E$33-$A35<=0,"",$B$6/($E$33-$A35)/$B$11),"") -> 77.008313
A36: =IFERROR($B$9*1.0,"") -> 3.8456 | B36: =IFERROR(IF($B$33-$A36<=0,"",$B$6/($B$33-$A36)/$B$11),"") -> 170.95923 | C36: =IFERROR(IF($C$33-$A36<=0,"",$B$6/($C$33-$A36)/$B$11),"") -> 123.16788 | D36: =IFERROR(IF($D$33-$A36<=0,"",$B$6/($D$33-$A36)/$B$11),"") -> 96.258878 | E36: =IFERROR(IF($E$33-$A36<=0,"",$B$6/($E$33-$A36)/$B$11),"") -> 78.999522
A37: =IFERROR($B$9*1.075,"") -> 4.13402 | B37: =IFERROR(IF($B$33-$A37<=0,"",$B$6/($B$33-$A37)/$B$11),"") -> 181.09246 | C37: =IFERROR(IF($C$33-$A37<=0,"",$B$6/($C$33-$A37)/$B$11),"") -> 128.34181 | D37: =IFERROR(IF($D$33-$A37<=0,"",$B$6/($D$33-$A37)/$B$11),"") -> 99.390284 | E37: =IFERROR(IF($E$33-$A37<=0,"",$B$6/($E$33-$A37)/$B$11),"") -> 81.096438
A38: =IFERROR($B$9*1.15,"") -> 4.42244 | B38: =IFERROR(IF($B$33-$A38<=0,"",$B$6/($B$33-$A38)/$B$11),"") -> 192.50261 | C38: =IFERROR(IF($C$33-$A38<=0,"",$B$6/($C$33-$A38)/$B$11),"") -> 133.96948 | D38: =IFERROR(IF($D$33-$A38<=0,"",$B$6/($D$33-$A38)/$B$11),"") -> 102.73228 | E38: =IFERROR(IF($E$33-$A38<=0,"",$B$6/($E$33-$A38)/$B$11),"") -> 83.307707

Sheet Scenarios
A1: SCENARIO ANALYSIS
A2: Pessimistic / Base / Optimistic — Year 1
A4: Metric | B4: Pessimistic | C4: Base | D4: Optimistic | E4: Notes
A5: Customers per day | B5: 116 | C5: =IFERROR(IF('3-Year P&L'!$B$6="","",'3-Year P&L'!$B$6),"") -> 145 | D5: 167
A6: Average check (excl. sales tax) | B6: 10.33 | C6: =IFERROR(IF('3-Year P&L'!$B$7="","",'3-Year P&L'!$B$7),"") -> 11 | D6: 11.67
A7: Operating days per year | B7: 329 | C7: =IFERROR(IF('3-Year P&L'!$B$8="","",'3-Year P&L'!$B$8),"") -> 340 | D7: 351
A8: ANNUAL REVENUE (excl. sales tax) | B8: =IFERROR(IF(B5*B6*B7=0,"",B5*B6*B7),"") -> 394234.12 | C8: =IFERROR(IF(C5*C6*C7=0,"",C5*C6*C7),"") -> 542300 | D8: =IFERROR(IF(D5*D6*D7=0,"",D5*D6*D7),"") -> 684060.39
A9: Cost of goods sold — food | B9: =IFERROR(IF(B8="","",B8*'0. Assumptions'!$B$11*'0. Assumptions'!$B$13),"") -> 48490.797 | C9: =IFERROR(IF(C8="","",C8*'0. Assumptions'!$B$11*'0. Assumptions'!$B$13),"") -> 66702.9 | D9: =IFERROR(IF(D8="","",D8*'0. Assumptions'!$B$11*'0. Assumptions'!$B$13),"") -> 84139.428
A10: Cost of goods sold — beverage | B10: =IFERROR(IF(B8="","",B8*'0. Assumptions'!$B$12*'0. Assumptions'!$B$14),"") -> 55823.551 | C10: =IFERROR(IF(C8="","",C8*'0. Assumptions'!$B$12*'0. Assumptions'!$B$14),"") -> 76789.68 | D10: =IFERROR(IF(D8="","",D8*'0. Assumptions'!$B$12*'0. Assumptions'!$B$14),"") -> 96862.951
A11: Disposables and packaging | B11: =IFERROR(IF(B8="","",B8*'0. Assumptions'!$B$15),"") -> 11827.024 | C11: =IFERROR(IF(C8="","",C8*'0. Assumptions'!$B$15),"") -> 16269 | D11: =IFERROR(IF(D8="","",D8*'0. Assumptions'!$B$15),"") -> 20521.812
A12: Delivery platform fees | B12: =IFERROR(IF(B8="","",B8*'0. Assumptions'!$B$16*'0. Assumptions'!$B$17),"") -> 0 | C12: =IFERROR(IF(C8="","",C8*'0. Assumptions'!$B$16*'0. Assumptions'!$B$17),"") -> 0 | D12: =IFERROR(IF(D8="","",D8*'0. Assumptions'!$B$16*'0. Assumptions'!$B$17),"") -> 0
A13: Card processing fees | B13: =IFERROR(IF(B8="","",B8*'0. Assumptions'!$B$18),"") -> 13798.194 | C13: =IFERROR(IF(C8="","",C8*'0. Assumptions'!$B$18),"") -> 18980.5 | D13: =IFERROR(IF(D8="","",D8*'0. Assumptions'!$B$18),"") -> 23942.114
A14: Miscellaneous and contingency | B14: =IFERROR(IF(B8="","",B8*'0. Assumptions'!$B$28),"") -> 7884.6824 | C14: =IFERROR(IF(C8="","",C8*'0. Assumptions'!$B$28),"") -> 10846 | D14: =IFERROR(IF(D8="","",D8*'0. Assumptions'!$B$28),"") -> 13681.208
A15: TOTAL VARIABLE COSTS | B15: =IFERROR(IF(B8="","",SUM(B9:B14)),"") -> 137824.25 | C15: =IFERROR(IF(C8="","",SUM(C9:C14)),"") -> 189588.08 | D15: =IFERROR(IF(D8="","",SUM(D9:D14)),"") -> 239147.51
A16: GROSS MARGIN | B16: =IFERROR(IF(B8="","",B8-B15),"") -> 256409.87 | C16: =IFERROR(IF(C8="","",C8-C15),"") -> 352711.92 | D16: =IFERROR(IF(D8="","",D8-D15),"") -> 444912.88
A17: FIXED COSTS (the P&L's) | B17: =IFERROR(IF(B8="","",'3-Year P&L'!$B$37),"") -> 299605.37 | C17: =IFERROR(IF(C8="","",'3-Year P&L'!$B$37),"") -> 299605.37 | D17: =IFERROR(IF(D8="","",'3-Year P&L'!$B$37),"") -> 299605.37 | E17: Fixed costs do not change with the scenario: that is why they are fixed
A18: PRE-TAX INCOME (EBT) | B18: =IFERROR(IF(B8="","",B16-B17),"") -> -43195.5 | C18: =IFERROR(IF(C8="","",C16-C17),"") -> 53106.549 | D18: =IFERROR(IF(D8="","",D16-D17),"") -> 145307.51
A19: Income tax | B19: =IFERROR(IF(B8="","",MAX(0,B18-'0. Assumptions'!$B$42)*'0. Assumptions'!$B$37),"") -> 0 | C19: =IFERROR(IF(C8="","",MAX(0,C18-'0. Assumptions'!$B$42)*'0. Assumptions'!$B$37),"") -> 13276.637 | D19: =IFERROR(IF(D8="","",MAX(0,D18-'0. Assumptions'!$B$42)*'0. Assumptions'!$B$37),"") -> 36326.877 | E19: At the "years 1-2" effective income tax rate, offsetting prior net operating losses
A20: NET INCOME | B20: =IFERROR(IF(B8="","",B18-B19),"") -> -43195.5 | C20: =IFERROR(IF(C8="","",C18-C19),"") -> 39829.911 | D20: =IFERROR(IF(D8="","",D18-D19),"") -> 108980.63
A21: Customers per day to break even | B21: =IFERROR(IF(B8="","",IF(B6-B15/(B5*B7)<=0,"",B17/(B6-B15/(B5*B7))/B7)),"") -> 135.54167 | C21: =IFERROR(IF(C8="","",IF(C6-C15/(C5*C7)<=0,"",C17/(C6-C15/(C5*C7))/C7)),"") -> 123.16788 | D21: =IFERROR(IF(D8="","",IF(D6-D15/(D5*D7)<=0,"",D17/(D6-D15/(D5*D7))/D7)),"") -> 112.45819
A22: WHAT EACH SCENARIO DEMANDS
A23: Labor cost / Sales | B23: =IFERROR(IF(B8="","",'3-Year P&L'!$B$23/B8),"") -> 0.42854434 | C23: =IFERROR(IF(C8="","",'3-Year P&L'!$B$23/C8),"") -> 0.31153753 | D23: =IFERROR(IF(D8="","",'3-Year P&L'!$B$23/D8),"") -> 0.24697644 | E23: The SAME staffing in all three scenarios. If labor cost blows up in the pessimistic case, adjust it in the Staffing tab, not here
A24: Customers per year per full-time equivalent | B24: =IFERROR(IF(B8="","",B5*B7/Staffing!$C$11),"") -> 8773.3333 | C24: =IFERROR(IF(C8="","",C5*C7/Staffing!$C$11),"") -> 11333.333 | D24: =IFERROR(IF(D8="","",D5*D7/Staffing!$C$11),"") -> 13475.172 | E24: Customers each full-time employee in the Staffing table would have to serve. In the optimistic scenario it tells you whether you need to hire
A25: Year-1 closing cash balance (estimate, same method in all three scenarios) | B25: =IFERROR(IF(B8="","",'Startup Costs'!$B$34+B20+'3-Year P&L'!$B$35-Financing!$B$45),"") -> 33949.711 | C25: =IFERROR(IF(C8="","",'Startup Costs'!$B$34+C20+'3-Year P&L'!$B$35-Financing!$B$45),"") -> 116975.12 | D25: =IFERROR(IF(D8="","",'Startup Costs'!$B$34+D20+'3-Year P&L'!$B$35-Financing!$B$45),"") -> 186125.84 | E25: ESTIMATED balance: working capital plus the year's result, adding back depreciation (which is not paid) and subtracting loan principal. It does not include the timing gap between receipts and payments or the sales tax settlement, so the three columns can be compared with each other. In red, the scenario runs out of cash
A26: Actual month-12 balance from the 12-Month Cash Flow tab (Base case only) | C26: =IFERROR(IF(C8="","",'12-Month Cash Flow'!$M$22),"") -> 152229.56 | E26: The ACTUAL base-case balance, with its timing of receipts and payments and its sales tax settlement. It exists only for the Base scenario, the only one with its own monthly cash flow: that is why it is not in the row above, where it would be compared against two estimates
A28: The "Base" column reads its three inputs from the "0. Assumptions" tab, so it reproduces EXACTLY year 1 of the P&L. The other two scenarios use the same cost rates: only customers, average check and days change. FIXED COSTS are the same in all three: miscellaneous and contingency, a percentage of sales, sit above with the variable costs and each scenario carries its own.

Sheet Staffing
A1: STAFFING STRUCTURE AND COSTS
A2: =IFERROR("Payroll — "&TEXT('0. Assumptions'!$B$21,"0")&" pay periods + employer taxes "&TEXT('0. Assumptions'!$B$20*100,"0")&"%","") -> Payroll — 12 pay periods + employer taxes 10%
A4: Position | B4: People | C4: FTE | D4: Gross pay per month (total for the position) | E4: Employer payroll taxes (total for the position) | F4: Cost per month (total for the position) | G4: Cost per year | H4: Hours per week per person | I4: Hours per year for the position | J4: Notes
A5: Owner and lead barista | B5: 1 | C5: 1 | D5: 3500 | E5: =IFERROR(IF(D5="","",D5*'0. Assumptions'!$B$20),"") -> 350 | F5: =IFERROR(IF(D5="","",D5+E5),"") -> 3850 | G5: =IFERROR(IF(D5="","",F5*MAX(12,'0. Assumptions'!$B$21)),"") -> 46200 | H5: =IFERROR(IF(D5="","",C5*$B$18),"") -> 40 | I5: =IFERROR(IF(D5="","",H5*B5*$B$19),"") -> 2000 | J5: Works the bar during the busy morning shift: purchasing, register, suppliers and social media
A6: Morning barista / floor server | B6: 1 | C6: 1 | D6: 2773 | E6: =IFERROR(IF(D6="","",D6*'0. Assumptions'!$B$20),"") -> 277.3 | F6: =IFERROR(IF(D6="","",D6+E6),"") -> 3050.3 | G6: =IFERROR(IF(D6="","",F6*MAX(12,'0. Assumptions'!$B$21)),"") -> 36603.6 | H6: =IFERROR(IF(D6="","",C6*$B$18),"") -> 40 | I6: =IFERROR(IF(D6="","",H6*B6*$B$19),"") -> 2000 | J6: Coffee specialist with latte art skills. Morning is the strongest shift of a coffee shop: bar coffee, breakfast and pastries
A7: Afternoon barista-server (bar and floor) | B7: 1 | C7: 1 | D7: 2600 | E7: =IFERROR(IF(D7="","",D7*'0. Assumptions'!$B$20),"") -> 260 | F7: =IFERROR(IF(D7="","",D7+E7),"") -> 2860 | G7: =IFERROR(IF(D7="","",F7*MAX(12,'0. Assumptions'!$B$21)),"") -> 34320 | H7: =IFERROR(IF(D7="","",C7*$B$18),"") -> 40 | I7: =IFERROR(IF(D7="","",H7*B7*$B$19),"") -> 2000 | J7: Closes the afternoon service and preps for the next day. Without this position the shop cannot open the hours that this workbook declares
A8: Brunch cook (4 days, weekends included) | B8: 1 | C8: 0.8 | D8: 2496 | E8: =IFERROR(IF(D8="","",D8*'0. Assumptions'!$B$20),"") -> 249.6 | F8: =IFERROR(IF(D8="","",D8+E8),"") -> 2745.6 | G8: =IFERROR(IF(D8="","",F8*MAX(12,'0. Assumptions'!$B$21)),"") -> 32947.2 | H8: =IFERROR(IF(D8="","",C8*$B$18),"") -> 32 | I8: =IFERROR(IF(D8="","",H8*B8*$B$19),"") -> 1600 | J8: Brunch and light kitchen 4 days a week (0.8 FTE = 32 hours), always including Saturday and Sunday, the busiest service, with two or three table turns
A9: Weekend extra (bar and floor) | B9: 1 | C9: 0.45 | D9: 1170 | E9: =IFERROR(IF(D9="","",D9*'0. Assumptions'!$B$20),"") -> 117 | F9: =IFERROR(IF(D9="","",D9+E9),"") -> 1287 | G9: =IFERROR(IF(D9="","",F9*MAX(12,'0. Assumptions'!$B$21)),"") -> 15444 | H9: =IFERROR(IF(D9="","",C9*$B$18),"") -> 18 | I9: =IFERROR(IF(D9="","",H9*B9*$B$19),"") -> 900 | J9: Reinforcement for the Saturday and Sunday peaks, when occupancy rises to 70-90% according to the references in this workbook
A10: Vacation and day-off relief | B10: 1 | C10: 0.1 | D10: 260 | E10: =IFERROR(IF(D10="","",D10*'0. Assumptions'!$B$20),"") -> 26 | F10: =IFERROR(IF(D10="","",D10+E10),"") -> 286 | G10: =IFERROR(IF(D10="","",F10*MAX(12,'0. Assumptions'!$B$21)),"") -> 3432 | H10: =IFERROR(IF(D10="","",C10*$B$18),"") -> 4 | I10: =IFERROR(IF(D10="","",H10*B10*$B$19),"") -> 200 | J10: Covers vacation, paid time off and the weekly day off for the team
A11: TOTAL STAFF | B11: =IFERROR(IF(COUNT(D5:D10)=0,"",SUM(B5:B10)),"") -> 6 | C11: =IFERROR(IF(COUNT(D5:D10)=0,"",SUM(C5:C10)),"") -> 4.35 | D11: =IFERROR(IF(COUNT(D5:D10)=0,"",SUM(D5:D10)),"") -> 12799 | E11: =IFERROR(IF(COUNT(D5:D10)=0,"",SUM(E5:E10)),"") -> 1279.9 | F11: =IFERROR(IF(COUNT(D5:D10)=0,"",SUM(F5:F10)),"") -> 14078.9 | G11: =IFERROR(IF(COUNT(D5:D10)=0,"",SUM(G5:G10)),"") -> 168946.8 | I11: =IFERROR(IF(COUNT(D5:D10)=0,"",SUM(I5:I10)),"") -> 8700
A12: STAFF GROWTH (stepped cost)
A13: Annual cost of year-2 hires | B13: 6000 | J13: FULL ANNUAL cost (gross pay + employer payroll taxes, over all pay periods) of whoever you hire that year. The P&L adds it to the previous year's cost: staffing grows by people, not by a percentage
A14: Annual cost of year-3 hires | B14: 6000 | J14: FULL ANNUAL cost (gross pay + employer payroll taxes, over all pay periods) of whoever you hire that year. The P&L adds it to the previous year's cost: staffing grows by people, not by a percentage
A15: Labor cost, year 2 | B15: =IFERROR(IF(G11="","",G11*(1+'0. Assumptions'!$B$48)+B13),"") -> 174946.8
A16: Labor cost, year 3 | B16: =IFERROR(IF(B15="","",B15*(1+'0. Assumptions'!$B$48)+B14),"") -> 180946.8
A17: COVERAGE OF SERVICE HOURS
A18: Full-time week (hours per week) | B18: 40 | J18: 40 hours a week is the FLSA overtime threshold for non-exempt employees; some states add daily overtime rules. Change it if your own full-time week is different
A19: Weeks worked per year per person | B19: 50 | J19: 50 weeks: 52 minus about two weeks of vacation, holidays and average absences. There is no federal vacation requirement in the US: adjust it to your own policy
A20: Service hours per day to cover | B20: 13 | J20: From opening to closing, bar included. Count them on your real schedule
A21: People needed at the same time in each shift | B21: 2 | J21: Average number of people present at the same time across kitchen, bar and floor. The two busy services need more and mid-afternoon needs fewer
A22: Service hours to cover per year | B22: =IFERROR(IF(OR(B20="",B21="",'0. Assumptions'!$B$6=""),"",B20*B21*'0. Assumptions'!$B$6),"") -> 8840
A23: Hours hired per year | B23: =IFERROR(IF(I11="","",I11),"") -> 8700
A24: Coverage (hired / needed) | B24: =IFERROR(B23/B22,"") -> 0.9841629 | J24: Below 100% the staff cannot cover the hours the plan declares: either hire more or cut the hours
A26: The gross pay, employer payroll taxes, monthly cost and annual cost columns are TOTALS for the row: for a position with two people they include both. FTE is the share of a full-time week, and it is used to compare pay with the legal minimum in proportion. The payroll tax rate and the number of pay periods are in the "0. Assumptions" tab.
A27: The pay floor is the HIGHER of the federal minimum wage and your state / local minimum wage, both in the "0. Assumptions" tab; part-time positions get it in proportion. There is no single national table above the federal floor: the state / local cell is delivered empty so you can enter the rate for your state and city.

Sheet Instructions
A1: INSTRUCTIONS FOR USE — Coffee Shop Financial Projections
A3: HOW TO USE THIS WORKBOOK
A4: This financial plan is a MODEL: you type only in the GREEN cells and everything else recalculates on its own.
A5: 1. "0. Assumptions" is the control sheet: customers per day, average check excl. sales tax, operating days, food and beverage mix, cost of goods sold, rent, financing and taxes.
A6: 2. Startup cost items, fixed costs and staffing are typed in their own tab, also in green. No number is typed twice.
A7: 3. On "Break-Even" you only type the seat-turn ceiling your space allows; everything else derives from the rest. The other three tabs also have green cells you can change: the pessimistic and optimistic scenarios on "Scenarios", the seasonality and the launch ramp-up on "12-Month Cash Flow", and the other financing sources on "Financing" (rows 8-11 count as sources but are not amortized: Your bank or SBA 7(a) loan goes in "Loan requested" on "0. Assumptions"). Everything else is calculated.
A8: 4. All figures are EXCL. SALES TAX. To turn a menu price into a price excl. sales tax, divide it by 1 + your sales tax rate (with an 8% rate, divide by 1.08); if an item is taxed at a different rate (alcohol to go, for instance), use that rate. The rate of each sales line is in the "Sales tax rate on the line (%)" column of the P&L, and from it come the receipts, the sales tax collected and the equivalent menu price incl. sales tax. With the default 0% recoverable input tax, the sales tax you pay on purchases and startup costs is treated as a cost; in the UK, enter 20% if you are VAT-registered.
A9: 5. If you change the staffing, the P&L reads it on its own: labor cost comes from the "Staffing" tab, not from a separate estimate.
A10: 6. The "12-Month Cash Flow" tab answers the question that decides a bank deal: in which month the cash runs out. The minimum balance of the year can never be in red.
A11: 7. The "Financing" tab matches what you need with what you put in and builds the amortization schedule of the loan. If the difference is red, the plan is not funded.
A12: 8. In this workbook, "the P&L" means the "3-Year P&L" tab: the same profit and loss statement, with one column for each of the three years.
A13: 9. The Word business plan that comes with these financial projections uses the same example figures as this workbook. If you change the workbook, update the figures in the Word document too.
... A16: Thresholds live in the "Threshold" column of the KEY RATIOS block of the P&L: change them there and the traffic light changes with them.
A18: Ratio | B18: Year 1 value | C18: Threshold | D18: Status
A19: Cost of goods sold / Sales | B19: =IFERROR(IF('3-Year P&L'!$B$52="","",'3-Year P&L'!$B$52),"") -> 0.2646 | C19: =IFERROR(IF('3-Year P&L'!$E$52="","",'3-Year P&L'!$E$52),"") -> 0.35 | D19: =IFERROR(IF(OR(B19="",C19=""),"",IF(B19<=C19,"OK","REVIEW")),"") -> OK
A20: Labor cost / Sales | B20: =IFERROR(IF('3-Year P&L'!$B$53="","",'3-Year P&L'!$B$53),"") -> 0.31153753 | C20: =IFERROR(IF('3-Year P&L'!$E$53="","",'3-Year P&L'!$E$53),"") -> 0.35 | D20: =IFERROR(IF(OR(B20="",C20=""),"",IF(B20<=C20,"OK","REVIEW")),"") -> OK
A21: Rent / Sales | B21: =IFERROR(IF('3-Year P&L'!$B$54="","",'3-Year P&L'!$B$54),"") -> 0.099575881 | C21: =IFERROR(IF('3-Year P&L'!$E$54="","",'3-Year P&L'!$E$54),"") -> 0.12 | D21: =IFERROR(IF(OR(B21="",C21=""),"",IF(B21<=C21,"OK","REVIEW")),"") -> OK
A22: Net income / Sales | B22: =IFERROR(IF('3-Year P&L'!$B$55="","",'3-Year P&L'!$B$55),"") -> 0.073446269 | C22: =IFERROR(IF('3-Year P&L'!$E$55="","",'3-Year P&L'!$E$55),"") -> 0.06 | D22: =IFERROR(IF(OR(B22="",C22=""),"",IF(B22>=C22,"OK","REVIEW")),"") -> OK
A23: Gross margin / Sales | B23: =IFERROR(IF('3-Year P&L'!$B$50="","",'3-Year P&L'!$B$50),"") -> 0.6504 | C23: =IFERROR(IF('3-Year P&L'!$E$50="","",'3-Year P&L'!$E$50),"") -> 0.65 | D23: =IFERROR(IF(OR(B23="",C23=""),"",IF(B23>=C23,"OK","REVIEW")),"") -> OK
A25: THIS PLAN'S KEY FIGURES
A26: Total startup costs (sum of the blocks) | B26: =IFERROR(IF('Startup Costs'!$B$35="","",'Startup Costs'!$B$35),"") -> 263686.7
A27: Total cash needed at launch | B27: =IFERROR(IF('Startup Costs'!$B$38="","",'Startup Costs'!$B$38),"") -> 263686.7
A28: Working capital funded | B28: =IFERROR(IF('Startup Costs'!$B$34="","",'Startup Costs'!$B$34),"") -> 69886.7
A29: Forecast year-1 revenue | B29: =IFERROR(IF('3-Year P&L'!$B$9="","",'3-Year P&L'!$B$9),"") -> 542300
A30: Year-1 net income | B30: =IFERROR(IF('3-Year P&L'!$B$47="","",'3-Year P&L'!$B$47),"") -> 39829.911
A31: Customers per day for the ACCOUNTING break-even (depreciation included) | B31: =IFERROR(IF('Break-Even'!$B$15="","",'Break-Even'!$B$15),"") -> 123.16788
A32: Project payback (years), before debt | B32: =IFERROR(IF('12-Month Cash Flow'!$B$31="","",'12-Month Cash Flow'!$B$31),"") -> 2.9
A34: WHY THIS MODEL IS BUILT THIS WAY
A35: Item | B35: Common shortcut | C35: This workbook | D35: Why
A36: Labor cost in the P&L | B36: A typed-in number, disconnected from the staffing tab | C36: The total of the "Staffing" tab, by formula | D36: When the P&L and the staffing tab disagree, nobody knows which one to trust. Here both say the same thing, and if you change a salary the result changes on its own.
A37: Staffing | B37: A handful of full-time positions sized by guesswork | C37: Positions, including part-time lines, sized to the service hours you declare | D37: Labor is sized to the hours of service this workbook declares, so the payroll comes from the schedule and is then tested against the labor-cost ceiling in the industry benchmarks table.
A38: Example staff wages | B38: No check against the minimum wage | C38: Every row is compared with the federal minimum wage (and with your state or local rate, if you enter one), in proportion to its FTE | D38: The "Staffing" tab checks row by row and warns in red if you go below that floor. A workbook that proposes wages below the legal minimum cannot be shown to a lender.
A39: Schedule coverage | B39: Staffing is not linked to opening hours | C39: The tab compares the hours your team covers with the service hours you declare | D39: Opening hours multiplied by the people needed at the same time give the hours you need per year. The workbook counts them and warns in red if the roster does not reach them.
A40: Customers per day | B40: Backed out of a revenue target | C40: Typed in as an input and tested against the seat count | D40: Customers per day is a driver, not a plug. Compare it with the range in the industry benchmarks table below and with the seat turns calculated on the "0. Assumptions" tab.
A41: Average check | B41: A single number, without saying whether it includes sales tax | C41: Entered excl. sales tax; the "0. Assumptions" tab calculates the equivalent menu price incl. sales tax | D41: Revenue is booked excl. sales tax, as it appears in your P&L. Declaring the basis avoids comparing a tax-inclusive menu price with a net average check.
A42: Rent | B42: A monthly figure with no link to sales | C42: A monthly rent on the "0. Assumptions" tab, tested as a percentage of sales | D42: The "3-Year P&L" shows rent against the 12% of sales threshold, so you see right away whether the location is viable.
A43: Opening calendar | B43: Two different calendars in the same workbook: a monthly day count on one tab and an annual count on another | C43: A single operating-days input on the "0. Assumptions" tab | D43: The daily break-even, the P&L and the scenarios all use the same number of days, so the daily break-even matches the days you actually plan to open.
A44: Working capital | B44: A round number with a "3 months" label | C44: 3 months of cash fixed costs, by formula | D44: A typed figure can cover far fewer months than its label says. A formula recalculates by itself whenever you change any expense.
