Workbook

Sheet Instructions
B2: 01 · Restaurant Schedule Template: Weekly & Monthly Staff Rota
B4: How to use this template:
B5: ▸ Type your team's names ONCE, in column A of the "Weekly Schedule": the "Monthly Schedule" pulls them in automatically, so there is no typing them five times.
B6: ▸ Assign shifts by code. Shift codes: AM=AM shift · PM=PM shift · N=Night · SP=Split · DBL=Double · OFF=Day off · V=Vacation/PTO · S=Sick.
B7: ▸ The hours are NOT written inside the formula: they come from the "Shifts" sheet. If your AM shift starts at 8:00 AM, change it there and the whole kit recalculates: the "Hours" column of that sheet is a formula (end − start − break), not a number you have to fix by hand.
B8: ▸ Each code has its own color in row 3 of the grid: it is the same legend in the weekly and the monthly schedule.
B9: ▸ The "Monthly Schedule" sheet repeats the grid for five weeks (31-day months do not fit in four), inherits the names from the "Weekly Schedule", adds up each employee's total for the month and shows the weekly average, which is what you compare with their scheduled hours when you spread hours unevenly.
B11: The 4 schedule alerts (columns K to N):
B12: ▸ K · Rest between shifts: compares the END time of each day with the START time of the next, counting the shift that crosses midnight. It fires below 10 h (the "clopening" rule of the Fair Workweek laws; UK: 11 h, Working Time Regulations reg. 10). The threshold is cell Shifts!B3.
B13: ▸ L · Weekly day off: federal law sets no mandatory day off. With zero days off in the week the alert is red; with one, amber (six days on: a 7th day in a row is premium pay in California, Labor Code §§551-552). UK: 24 h off per week (WTR reg. 11).
B14: ▸ M · Weekly hours: compares with the maximum in column J (green, 40 by default, the FLSA overtime threshold), not with a fixed 40: for a part-timer, type their scheduled hours and the alerts fire at 20.
B15: ▸ N · Long shift: federal law sets no daily maximum for adults, so this is the kit's own rule: it fires above 10 h (threshold in Shifts!B2). It is the one that catches the double shift.
... B27: Version 2.0 · October 2026 · aichef.pro/en/digital-products/restaurant-schedule-templates · info@aichef.pro

Sheet Shifts
A1: Shifts & limits: edit them here, they apply to the whole kit
A2: Long-shift alert after (h): | B2: 10 | C2: Kit rule (no federal daily cap)
A3: Minimum rest between shifts (h): | B3: 10 | C3: Fair Workweek "clopening" rule
A4: Code | B4: Description | C4: Start time | D4: End time | E4: Hours | F4: Break (h)
A5: AM | B5: AM shift | C5: 0.29166667 | D5: 0.625 | E5: =IF(OR($C5="",$D5=""),"",ROUND(MOD($D5-$C5,1)*24-IF($F5="",0,$F5),2)) -> 8 | F5: 0
A6: PM | B6: PM shift | C6: 0.625 | D6: 0.95833333 | E6: =IF(OR($C6="",$D6=""),"",ROUND(MOD($D6-$C6,1)*24-IF($F6="",0,$F6),2)) -> 8 | F6: 0
A7: N | B7: Night / overnight | C7: 0.95833333 | D7: 0.29166667 | E7: =IF(OR($C7="",$D7=""),"",ROUND(MOD($D7-$C7,1)*24-IF($F7="",0,$F7),2)) -> 8 | F7: 0
A8: SP | B8: Split shift | C8: 0.41666667 | D8: 0.95833333 | E8: =IF(OR($C8="",$D8=""),"",ROUND(MOD($D8-$C8,1)*24-IF($F8="",0,$F8),2)) -> 9 | F8: 4
A9: DBL | B9: Double | C9: 0.29166667 | D9: 0.95833333 | E9: =IF(OR($C9="",$D9=""),"",ROUND(MOD($D9-$C9,1)*24-IF($F9="",0,$F9),2)) -> 16 | F9: 0
A10: OFF | B10: Day off | C10: 0 | D10: 0 | E10: =IF(OR($C10="",$D10=""),"",ROUND(MOD($D10-$C10,1)*24-IF($F10="",0,$F10),2)) -> 0 | F10: 0
A11: V | B11: Vacation / PTO | C11: 0 | D11: 0 | E11: =IF(OR($C11="",$D11=""),"",ROUND(MOD($D11-$C11,1)*24-IF($F11="",0,$F11),2)) -> 0 | F11: 0
A12: S | B12: Sick | C12: 0 | D12: 0 | E12: =IF(OR($C12="",$D12=""),"",ROUND(MOD($D12-$C12,1)*24-IF($F12="",0,$F12),2)) -> 0 | F12: 0
B13: The SPLIT shift runs 10:00 AM-3:00 PM and 7:00 PM-11:00 PM: 13 h end to end and 9 effective hours, because it carries a 4 h BREAK. The "Hours" column is no longer typed: it comes from end − start minus the break, so changing a time really recalculates the schedule and the alerts. Start and end times are also what measure the rest between shifts.
B14: The DOUBLE (DBL) is the 16 h shift that triggers the long-shift alert. It exists so you can MARK it and make the alert fire, not to plan it.
B15: Type times as clock times: 7:00 AM or 3:30 PM. Column A is not editable: those 8 codes are the ones in the schedule drop-down and in the calendar of file 05 (PTO & Vacation Planner).

Sheet Weekly Schedule
A1: Shift Schedule — Week of ___/___/___ to ___/___/___
A2: AI Chef Pro · aichef.pro — Restaurant Staff Scheduling Kit Pro
B3: AM=AM shift | C3: PM=PM shift | D3: N=Night | E3: SP=Split | F3: DBL=Double | G3: OFF=Day off | H3: V=Vacation/PTO | I3: S=Sick
R4: HELPER — do not edit · hours per day | Y4: start time | AF4: end time | AM4: rest between shifts (h)
A5: Employee | B5: Monday | C5: Tuesday | D5: Wednesday | E5: Thursday | F5: Friday | G5: Saturday | H5: Sunday | I5: Total Hours | J5: Max hours/week (OT after 40) | K5: Rest between shifts | L5: Weekly day off | M5: Weekly hours | N5: Long shift | O5: Minor (under 18) Y/N | P5: Minor alert
I6: =IF(COUNT($R6:$X6)=0,"",ROUND(SUM($R6:$X6),2)) | J6: 40 | K6: =IF(OR(IF($AM6="",Shifts!$B$3,$AM6)<Shifts!$B$3,IF($AN6="",Shifts!$B$3,$AN6)<Shifts!$B$3,IF($AO6="",Shifts!$B$3,$AO6)<Shifts!$B$3,IF($AP6="",Shifts!$B$3,$AP6)<Shifts!$B$3,IF($AQ6="",Shifts!$B$3,$AQ6)<Shifts!$B$3,IF($AR6="",Shifts!$B$3,$AR6)<Shifts!$B$3),"⛔ <"&Shifts!$B$3&" h","") | L6: =IF(7-(IF($R6="",0,IF($R6>0,1,0))+IF($S6="",0,IF($S6>0,1,0))+IF($T6="",0,IF($T6>0,1,0))+IF($U6="",0,IF($U6>0,1,0))+IF($V6="",0,IF($V6>0,1,0))+IF($W6="",0,IF($W6>0,1,0))+IF($X6="",0,IF($X6>0,1,0)))=0,"⛔ 0 days off",IF(7-(IF($R6="",0,IF($R6>0,1,0))+IF($S6="",0,IF($S6>0,1,0))+IF($T6="",0,IF($T6>0,1,0))+IF($U6="",0,IF($U6>0,1,0))+IF($V6="",0,IF($V6>0,1,0))+IF($W6="",0,IF($W6>0,1,0))+IF($X6="",0,IF($X6>0,1,0)))=1,"⚠ 6 days on: a 7th day in a row is premium pay in CA","")) | M6: =IF(OR($I6="",$J6=""),"",IF($I6>$J6,"⛔ +"&TEXT($I6-$J6,"0")&" h","")) | N6: =IF($O6="Y",IF(OR(IF($R6="",0,$R6)>8,IF($S6="",0,$S6)>8,IF($T6="",0,$T6)>8,IF($U6="",0,$U6)>8,IF($V6="",0,$V6)>8,IF($W6="",0,$W6)>8,IF($X6="",0,$X6)>8),"⛔ shift > 8 h (MINOR)",""),IF(OR(IF($R6="",0,$R6)>Shifts!$B$2,IF($S6="",0,$S6)>Shifts!$B$2,IF($T6="",0,$T6)>Shifts!$B$2,IF($U6="",0,$U6)>Shifts!$B$2,IF($V6="",0,$V6)>Shifts!$B$2,IF($W6="",0,$W6)>Shifts!$B$2,IF($X6="",0,$X6)>Shifts!$B$2),"⛔ shift > "&Shifts!$B$2&" h","")) | P6: =IF($O6<>"Y","",IF(OR($B6="N",$B6="DBL",$C6="N",$C6="DBL",$D6="N",$D6="DBL",$E6="N",$E6="DBL",$F6="N",$F6="DBL",$G6="N",$G6="DBL",$H6="N",$H6="DBL"),"⛔ MINOR: no night or double shifts (29 CFR 570.35)","⚠ minor: check federal and state hour limits")) | R6: =IF($B6="","",IFERROR(VLOOKUP($B6,Shifts!$A$5:$E$12,5,FALSE),0)) | S6: =IF($C6="","",IFERROR(VLOOKUP($C6,Shifts!$A$5:$E$12,5,FALSE),0)) | T6: =IF($D6="","",IFERROR(VLOOKUP($D6,Shifts!$A$5:$E$12,5,FALSE),0)) | U6: =IF($E6="","",IFERROR(VLOOKUP($E6,Shifts!$A$5:$E$12,5,FALSE),0)) | V6: =IF($F6="","",IFERROR(VLOOKUP($F6,Shifts!$A$5:$E$12,5,FALSE),0)) | W6: =IF($G6="","",IFERROR(VLOOKUP($G6,Shifts!$A$5:$E$12,5,FALSE),0)) | X6: =IF($H6="","",IFERROR(VLOOKUP($H6,Shifts!$A$5:$E$12,5,FALSE),0)) | Y6: =IF($B6="","",IFERROR(VLOOKUP($B6,Shifts!$A$5:$E$12,3,FALSE),0)) | Z6: =IF($C6="","",IFERROR(VLOOKUP($C6,Shifts!$A$5:$E$12,3,FALSE),0)) | AA6: =IF($D6="","",IFERROR(VLOOKUP($D6,Shifts!$A$5:$E$12,3,FALSE),0)) | AB6: =IF($E6="","",IFERROR(VLOOKUP($E6,Shifts!$A$5:$E$12,3,FALSE),0)) | AC6: =IF($F6="","",IFERROR(VLOOKUP($F6,Shifts!$A$5:$E$12,3,FALSE),0)) | AD6: =IF($G6="","",IFERROR(VLOOKUP($G6,Shifts!$A$5:$E$12,3,FALSE),0)) | AE6: =IF($H6="","",IFERROR(VLOOKUP($H6,Shifts!$A$5:$E$12,3,FALSE),0)) | AF6: =IF($B6="","",IFERROR(VLOOKUP($B6,Shifts!$A$5:$E$12,4,FALSE),0)) | AG6: =IF($C6="","",IFERROR(VLOOKUP($C6,Shifts!$A$5:$E$12,4,FALSE),0)) | AH6: =IF($D6="","",IFERROR(VLOOKUP($D6,Shifts!$A$5:$E$12,4,FALSE),0)) | AI6: =IF($E6="","",IFERROR(VLOOKUP($E6,Shifts!$A$5:$E$12,4,FALSE),0)) | AJ6: =IF($F6="","",IFERROR(VLOOKUP($F6,Shifts!$A$5:$E$12,4,FALSE),0)) | AK6: =IF($G6="","",IFERROR(VLOOKUP($G6,Shifts!$A$5:$E$12,4,FALSE),0)) | AL6: =IF($H6="","",IFERROR(VLOOKUP($H6,Shifts!$A$5:$E$12,4,FALSE),0)) | AM6: =IF(OR($R6="",$S6="",$R6=0,$S6=0),"",ROUND(IF($AF6<=$Y6,$Z6-$AF6,1-$AF6+$Z6)*24,2)) | AN6: =IF(OR($S6="",$T6="",$S6=0,$T6=0),"",ROUND(IF($AG6<=$Z6,$AA6-$AG6,1-$AG6+$AA6)*24,2)) | AO6: =IF(OR($T6="",$U6="",$T6=0,$U6=0),"",ROUND(IF($AH6<=$AA6,$AB6-$AH6,1-$AH6+$AB6)*24,2)) | AP6: =IF(OR($U6="",$V6="",$U6=0,$V6=0),"",ROUND(IF($AI6<=$AB6,$AC6-$AI6,1-$AI6+$AC6)*24,2)) | AQ6: =IF(OR($V6="",$W6="",$V6=0,$W6=0),"",ROUND(IF($AJ6<=$AC6,$AD6-$AJ6,1-$AJ6+$AD6)*24,2)) | AR6: =IF(OR($W6="",$X6="",$W6=0,$X6=0),"",ROUND(IF($AK6<=$AD6,$AE6-$AK6,1-$AK6+$AE6)*24,2))
I7: =IF(COUNT($R7:$X7)=0,"",ROUND(SUM($R7:$X7),2)) | J7: 40 | K7: =IF(OR(IF($AM7="",Shifts!$B$3,$AM7)<Shifts!$B$3,IF($AN7="",Shifts!$B$3,$AN7)<Shifts!$B$3,IF($AO7="",Shifts!$B$3,$AO7)<Shifts!$B$3,IF($AP7="",Shifts!$B$3,$AP7)<Shifts!$B$3,IF($AQ7="",Shifts!$B$3,$AQ7)<Shifts!$B$3,IF($AR7="",Shifts!$B$3,$AR7)<Shifts!$B$3),"⛔ <"&Shifts!$B$3&" h","") | L7: =IF(7-(IF($R7="",0,IF($R7>0,1,0))+IF($S7="",0,IF($S7>0,1,0))+IF($T7="",0,IF($T7>0,1,0))+IF($U7="",0,IF($U7>0,1,0))+IF($V7="",0,IF($V7>0,1,0))+IF($W7="",0,IF($W7>0,1,0))+IF($X7="",0,IF($X7>0,1,0)))=0,"⛔ 0 days off",IF(7-(IF($R7="",0,IF($R7>0,1,0))+IF($S7="",0,IF($S7>0,1,0))+IF($T7="",0,IF($T7>0,1,0))+IF($U7="",0,IF($U7>0,1,0))+IF($V7="",0,IF($V7>0,1,0))+IF($W7="",0,IF($W7>0,1,0))+IF($X7="",0,IF($X7>0,1,0)))=1,"⚠ 6 days on: a 7th day in a row is premium pay in CA","")) | M7: =IF(OR($I7="",$J7=""),"",IF($I7>$J7,"⛔ +"&TEXT($I7-$J7,"0")&" h","")) | N7: =IF($O7="Y",IF(OR(IF($R7="",0,$R7)>8,IF($S7="",0,$S7)>8,IF($T7="",0,$T7)>8,IF($U7="",0,$U7)>8,IF($V7="",0,$V7)>8,IF($W7="",0,$W7)>8,IF($X7="",0,$X7)>8),"⛔ shift > 8 h (MINOR)",""),IF(OR(IF($R7="",0,$R7)>Shifts!$B$2,IF($S7="",0,$S7)>Shifts!$B$2,IF($T7="",0,$T7)>Shifts!$B$2,IF($U7="",0,$U7)>Shifts!$B$2,IF($V7="",0,$V7)>Shifts!$B$2,IF($W7="",0,$W7)>Shifts!$B$2,IF($X7="",0,$X7)>Shifts!$B$2),"⛔ shift > "&Shifts!$B$2&" h","")) | P7: =IF($O7<>"Y","",IF(OR($B7="N",$B7="DBL",$C7="N",$C7="DBL",$D7="N",$D7="DBL",$E7="N",$E7="DBL",$F7="N",$F7="DBL",$G7="N",$G7="DBL",$H7="N",$H7="DBL"),"⛔ MINOR: no night or double shifts (29 CFR 570.35)","⚠ minor: check federal and state hour limits")) | R7: =IF($B7="","",IFERROR(VLOOKUP($B7,Shifts!$A$5:$E$12,5,FALSE),0)) | S7: =IF($C7="","",IFERROR(VLOOKUP($C7,Shifts!$A$5:$E$12,5,FALSE),0)) | T7: =IF($D7="","",IFERROR(VLOOKUP($D7,Shifts!$A$5:$E$12,5,FALSE),0)) | U7: =IF($E7="","",IFERROR(VLOOKUP($E7,Shifts!$A$5:$E$12,5,FALSE),0)) | V7: =IF($F7="","",IFERROR(VLOOKUP($F7,Shifts!$A$5:$E$12,5,FALSE),0)) | W7: =IF($G7="","",IFERROR(VLOOKUP($G7,Shifts!$A$5:$E$12,5,FALSE),0)) | X7: =IF($H7="","",IFERROR(VLOOKUP($H7,Shifts!$A$5:$E$12,5,FALSE),0)) | Y7: =IF($B7="","",IFERROR(VLOOKUP($B7,Shifts!$A$5:$E$12,3,FALSE),0)) | Z7: =IF($C7="","",IFERROR(VLOOKUP($C7,Shifts!$A$5:$E$12,3,FALSE),0)) | AA7: =IF($D7="","",IFERROR(VLOOKUP($D7,Shifts!$A$5:$E$12,3,FALSE),0)) | AB7: =IF($E7="","",IFERROR(VLOOKUP($E7,Shifts!$A$5:$E$12,3,FALSE),0)) | AC7: =IF($F7="","",IFERROR(VLOOKUP($F7,Shifts!$A$5:$E$12,3,FALSE),0)) | AD7: =IF($G7="","",IFERROR(VLOOKUP($G7,Shifts!$A$5:$E$12,3,FALSE),0)) | AE7: =IF($H7="","",IFERROR(VLOOKUP($H7,Shifts!$A$5:$E$12,3,FALSE),0)) | AF7: =IF($B7="","",IFERROR(VLOOKUP($B7,Shifts!$A$5:$E$12,4,FALSE),0)) | AG7: =IF($C7="","",IFERROR(VLOOKUP($C7,Shifts!$A$5:$E$12,4,FALSE),0)) | AH7: =IF($D7="","",IFERROR(VLOOKUP($D7,Shifts!$A$5:$E$12,4,FALSE),0)) | AI7: =IF($E7="","",IFERROR(VLOOKUP($E7,Shifts!$A$5:$E$12,4,FALSE),0)) | AJ7: =IF($F7="","",IFERROR(VLOOKUP($F7,Shifts!$A$5:$E$12,4,FALSE),0)) | AK7: =IF($G7="","",IFERROR(VLOOKUP($G7,Shifts!$A$5:$E$12,4,FALSE),0)) | AL7: =IF($H7="","",IFERROR(VLOOKUP($H7,Shifts!$A$5:$E$12,4,FALSE),0)) | AM7: =IF(OR($R7="",$S7="",$R7=0,$S7=0),"",ROUND(IF($AF7<=$Y7,$Z7-$AF7,1-$AF7+$Z7)*24,2)) | AN7: =IF(OR($S7="",$T7="",$S7=0,$T7=0),"",ROUND(IF($AG7<=$Z7,$AA7-$AG7,1-$AG7+$AA7)*24,2)) | AO7: =IF(OR($T7="",$U7="",$T7=0,$U7=0),"",ROUND(IF($AH7<=$AA7,$AB7-$AH7,1-$AH7+$AB7)*24,2)) | AP7: =IF(OR($U7="",$V7="",$U7=0,$V7=0),"",ROUND(IF($AI7<=$AB7,$AC7-$AI7,1-$AI7+$AC7)*24,2)) | AQ7: =IF(OR($V7="",$W7="",$V7=0,$W7=0),"",ROUND(IF($AJ7<=$AC7,$AD7-$AJ7,1-$AJ7+$AD7)*24,2)) | AR7: =IF(OR($W7="",$X7="",$W7=0,$X7=0),"",ROUND(IF($AK7<=$AD7,$AE7-$AK7,1-$AK7+$AE7)*24,2))
I8: =IF(COUNT($R8:$X8)=0,"",ROUND(SUM($R8:$X8),2)) | J8: 40 | K8: =IF(OR(IF($AM8="",Shifts!$B$3,$AM8)<Shifts!$B$3,IF($AN8="",Shifts!$B$3,$AN8)<Shifts!$B$3,IF($AO8="",Shifts!$B$3,$AO8)<Shifts!$B$3,IF($AP8="",Shifts!$B$3,$AP8)<Shifts!$B$3,IF($AQ8="",Shifts!$B$3,$AQ8)<Shifts!$B$3,IF($AR8="",Shifts!$B$3,$AR8)<Shifts!$B$3),"⛔ <"&Shifts!$B$3&" h","") | L8: =IF(7-(IF($R8="",0,IF($R8>0,1,0))+IF($S8="",0,IF($S8>0,1,0))+IF($T8="",0,IF($T8>0,1,0))+IF($U8="",0,IF($U8>0,1,0))+IF($V8="",0,IF($V8>0,1,0))+IF($W8="",0,IF($W8>0,1,0))+IF($X8="",0,IF($X8>0,1,0)))=0,"⛔ 0 days off",IF(7-(IF($R8="",0,IF($R8>0,1,0))+IF($S8="",0,IF($S8>0,1,0))+IF($T8="",0,IF($T8>0,1,0))+IF($U8="",0,IF($U8>0,1,0))+IF($V8="",0,IF($V8>0,1,0))+IF($W8="",0,IF($W8>0,1,0))+IF($X8="",0,IF($X8>0,1,0)))=1,"⚠ 6 days on: a 7th day in a row is premium pay in CA","")) | M8: =IF(OR($I8="",$J8=""),"",IF($I8>$J8,"⛔ +"&TEXT($I8-$J8,"0")&" h","")) | N8: =IF($O8="Y",IF(OR(IF($R8="",0,$R8)>8,IF($S8="",0,$S8)>8,IF($T8="",0,$T8)>8,IF($U8="",0,$U8)>8,IF($V8="",0,$V8)>8,IF($W8="",0,$W8)>8,IF($X8="",0,$X8)>8),"⛔ shift > 8 h (MINOR)",""),IF(OR(IF($R8="",0,$R8)>Shifts!$B$2,IF($S8="",0,$S8)>Shifts!$B$2,IF($T8="",0,$T8)>Shifts!$B$2,IF($U8="",0,$U8)>Shifts!$B$2,IF($V8="",0,$V8)>Shifts!$B$2,IF($W8="",0,$W8)>Shifts!$B$2,IF($X8="",0,$X8)>Shifts!$B$2),"⛔ shift > "&Shifts!$B$2&" h","")) | P8: =IF($O8<>"Y","",IF(OR($B8="N",$B8="DBL",$C8="N",$C8="DBL",$D8="N",$D8="DBL",$E8="N",$E8="DBL",$F8="N",$F8="DBL",$G8="N",$G8="DBL",$H8="N",$H8="DBL"),"⛔ MINOR: no night or double shifts (29 CFR 570.35)","⚠ minor: check federal and state hour limits")) | R8: =IF($B8="","",IFERROR(VLOOKUP($B8,Shifts!$A$5:$E$12,5,FALSE),0)) | S8: =IF($C8="","",IFERROR(VLOOKUP($C8,Shifts!$A$5:$E$12,5,FALSE),0)) | T8: =IF($D8="","",IFERROR(VLOOKUP($D8,Shifts!$A$5:$E$12,5,FALSE),0)) | U8: =IF($E8="","",IFERROR(VLOOKUP($E8,Shifts!$A$5:$E$12,5,FALSE),0)) | V8: =IF($F8="","",IFERROR(VLOOKUP($F8,Shifts!$A$5:$E$12,5,FALSE),0)) | W8: =IF($G8="","",IFERROR(VLOOKUP($G8,Shifts!$A$5:$E$12,5,FALSE),0)) | X8: =IF($H8="","",IFERROR(VLOOKUP($H8,Shifts!$A$5:$E$12,5,FALSE),0)) | Y8: =IF($B8="","",IFERROR(VLOOKUP($B8,Shifts!$A$5:$E$12,3,FALSE),0)) | Z8: =IF($C8="","",IFERROR(VLOOKUP($C8,Shifts!$A$5:$E$12,3,FALSE),0)) | AA8: =IF($D8="","",IFERROR(VLOOKUP($D8,Shifts!$A$5:$E$12,3,FALSE),0)) | AB8: =IF($E8="","",IFERROR(VLOOKUP($E8,Shifts!$A$5:$E$12,3,FALSE),0)) | AC8: =IF($F8="","",IFERROR(VLOOKUP($F8,Shifts!$A$5:$E$12,3,FALSE),0)) | AD8: =IF($G8="","",IFERROR(VLOOKUP($G8,Shifts!$A$5:$E$12,3,FALSE),0)) | AE8: =IF($H8="","",IFERROR(VLOOKUP($H8,Shifts!$A$5:$E$12,3,FALSE),0)) | AF8: =IF($B8="","",IFERROR(VLOOKUP($B8,Shifts!$A$5:$E$12,4,FALSE),0)) | AG8: =IF($C8="","",IFERROR(VLOOKUP($C8,Shifts!$A$5:$E$12,4,FALSE),0)) | AH8: =IF($D8="","",IFERROR(VLOOKUP($D8,Shifts!$A$5:$E$12,4,FALSE),0)) | AI8: =IF($E8="","",IFERROR(VLOOKUP($E8,Shifts!$A$5:$E$12,4,FALSE),0)) | AJ8: =IF($F8="","",IFERROR(VLOOKUP($F8,Shifts!$A$5:$E$12,4,FALSE),0)) | AK8: =IF($G8="","",IFERROR(VLOOKUP($G8,Shifts!$A$5:$E$12,4,FALSE),0)) | AL8: =IF($H8="","",IFERROR(VLOOKUP($H8,Shifts!$A$5:$E$12,4,FALSE),0)) | AM8: =IF(OR($R8="",$S8="",$R8=0,$S8=0),"",ROUND(IF($AF8<=$Y8,$Z8-$AF8,1-$AF8+$Z8)*24,2)) | AN8: =IF(OR($S8="",$T8="",$S8=0,$T8=0),"",ROUND(IF($AG8<=$Z8,$AA8-$AG8,1-$AG8+$AA8)*24,2)) | AO8: =IF(OR($T8="",$U8="",$T8=0,$U8=0),"",ROUND(IF($AH8<=$AA8,$AB8-$AH8,1-$AH8+$AB8)*24,2)) | AP8: =IF(OR($U8="",$V8="",$U8=0,$V8=0),"",ROUND(IF($AI8<=$AB8,$AC8-$AI8,1-$AI8+$AC8)*24,2)) | AQ8: =IF(OR($V8="",$W8="",$V8=0,$W8=0),"",ROUND(IF($AJ8<=$AC8,$AD8-$AJ8,1-$AJ8+$AD8)*24,2)) | AR8: =IF(OR($W8="",$X8="",$W8=0,$X8=0),"",ROUND(IF($AK8<=$AD8,$AE8-$AK8,1-$AK8+$AE8)*24,2))
I9: =IF(COUNT($R9:$X9)=0,"",ROUND(SUM($R9:$X9),2)) | J9: 40 | K9: =IF(OR(IF($AM9="",Shifts!$B$3,$AM9)<Shifts!$B$3,IF($AN9="",Shifts!$B$3,$AN9)<Shifts!$B$3,IF($AO9="",Shifts!$B$3,$AO9)<Shifts!$B$3,IF($AP9="",Shifts!$B$3,$AP9)<Shifts!$B$3,IF($AQ9="",Shifts!$B$3,$AQ9)<Shifts!$B$3,IF($AR9="",Shifts!$B$3,$AR9)<Shifts!$B$3),"⛔ <"&Shifts!$B$3&" h","") | L9: =IF(7-(IF($R9="",0,IF($R9>0,1,0))+IF($S9="",0,IF($S9>0,1,0))+IF($T9="",0,IF($T9>0,1,0))+IF($U9="",0,IF($U9>0,1,0))+IF($V9="",0,IF($V9>0,1,0))+IF($W9="",0,IF($W9>0,1,0))+IF($X9="",0,IF($X9>0,1,0)))=0,"⛔ 0 days off",IF(7-(IF($R9="",0,IF($R9>0,1,0))+IF($S9="",0,IF($S9>0,1,0))+IF($T9="",0,IF($T9>0,1,0))+IF($U9="",0,IF($U9>0,1,0))+IF($V9="",0,IF($V9>0,1,0))+IF($W9="",0,IF($W9>0,1,0))+IF($X9="",0,IF($X9>0,1,0)))=1,"⚠ 6 days on: a 7th day in a row is premium pay in CA","")) | M9: =IF(OR($I9="",$J9=""),"",IF($I9>$J9,"⛔ +"&TEXT($I9-$J9,"0")&" h","")) | N9: =IF($O9="Y",IF(OR(IF($R9="",0,$R9)>8,IF($S9="",0,$S9)>8,IF($T9="",0,$T9)>8,IF($U9="",0,$U9)>8,IF($V9="",0,$V9)>8,IF($W9="",0,$W9)>8,IF($X9="",0,$X9)>8),"⛔ shift > 8 h (MINOR)",""),IF(OR(IF($R9="",0,$R9)>Shifts!$B$2,IF($S9="",0,$S9)>Shifts!$B$2,IF($T9="",0,$T9)>Shifts!$B$2,IF($U9="",0,$U9)>Shifts!$B$2,IF($V9="",0,$V9)>Shifts!$B$2,IF($W9="",0,$W9)>Shifts!$B$2,IF($X9="",0,$X9)>Shifts!$B$2),"⛔ shift > "&Shifts!$B$2&" h","")) | P9: =IF($O9<>"Y","",IF(OR($B9="N",$B9="DBL",$C9="N",$C9="DBL",$D9="N",$D9="DBL",$E9="N",$E9="DBL",$F9="N",$F9="DBL",$G9="N",$G9="DBL",$H9="N",$H9="DBL"),"⛔ MINOR: no night or double shifts (29 CFR 570.35)","⚠ minor: check federal and state hour limits")) | R9: =IF($B9="","",IFERROR(VLOOKUP($B9,Shifts!$A$5:$E$12,5,FALSE),0)) | S9: =IF($C9="","",IFERROR(VLOOKUP($C9,Shifts!$A$5:$E$12,5,FALSE),0)) | T9: =IF($D9="","",IFERROR(VLOOKUP($D9,Shifts!$A$5:$E$12,5,FALSE),0)) | U9: =IF($E9="","",IFERROR(VLOOKUP($E9,Shifts!$A$5:$E$12,5,FALSE),0)) | V9: =IF($F9="","",IFERROR(VLOOKUP($F9,Shifts!$A$5:$E$12,5,FALSE),0)) | W9: =IF($G9="","",IFERROR(VLOOKUP($G9,Shifts!$A$5:$E$12,5,FALSE),0)) | X9: =IF($H9="","",IFERROR(VLOOKUP($H9,Shifts!$A$5:$E$12,5,FALSE),0)) | Y9: =IF($B9="","",IFERROR(VLOOKUP($B9,Shifts!$A$5:$E$12,3,FALSE),0)) | Z9: =IF($C9="","",IFERROR(VLOOKUP($C9,Shifts!$A$5:$E$12,3,FALSE),0)) | AA9: =IF($D9="","",IFERROR(VLOOKUP($D9,Shifts!$A$5:$E$12,3,FALSE),0)) | AB9: =IF($E9="","",IFERROR(VLOOKUP($E9,Shifts!$A$5:$E$12,3,FALSE),0)) | AC9: =IF($F9="","",IFERROR(VLOOKUP($F9,Shifts!$A$5:$E$12,3,FALSE),0)) | AD9: =IF($G9="","",IFERROR(VLOOKUP($G9,Shifts!$A$5:$E$12,3,FALSE),0)) | AE9: =IF($H9="","",IFERROR(VLOOKUP($H9,Shifts!$A$5:$E$12,3,FALSE),0)) | AF9: =IF($B9="","",IFERROR(VLOOKUP($B9,Shifts!$A$5:$E$12,4,FALSE),0)) | AG9: =IF($C9="","",IFERROR(VLOOKUP($C9,Shifts!$A$5:$E$12,4,FALSE),0)) | AH9: =IF($D9="","",IFERROR(VLOOKUP($D9,Shifts!$A$5:$E$12,4,FALSE),0)) | AI9: =IF($E9="","",IFERROR(VLOOKUP($E9,Shifts!$A$5:$E$12,4,FALSE),0)) | AJ9: =IF($F9="","",IFERROR(VLOOKUP($F9,Shifts!$A$5:$E$12,4,FALSE),0)) | AK9: =IF($G9="","",IFERROR(VLOOKUP($G9,Shifts!$A$5:$E$12,4,FALSE),0)) | AL9: =IF($H9="","",IFERROR(VLOOKUP($H9,Shifts!$A$5:$E$12,4,FALSE),0)) | AM9: =IF(OR($R9="",$S9="",$R9=0,$S9=0),"",ROUND(IF($AF9<=$Y9,$Z9-$AF9,1-$AF9+$Z9)*24,2)) | AN9: =IF(OR($S9="",$T9="",$S9=0,$T9=0),"",ROUND(IF($AG9<=$Z9,$AA9-$AG9,1-$AG9+$AA9)*24,2)) | AO9: =IF(OR($T9="",$U9="",$T9=0,$U9=0),"",ROUND(IF($AH9<=$AA9,$AB9-$AH9,1-$AH9+$AB9)*24,2)) | AP9: =IF(OR($U9="",$V9="",$U9=0,$V9=0),"",ROUND(IF($AI9<=$AB9,$AC9-$AI9,1-$AI9+$AC9)*24,2)) | AQ9: =IF(OR($V9="",$W9="",$V9=0,$W9=0),"",ROUND(IF($AJ9<=$AC9,$AD9-$AJ9,1-$AJ9+$AD9)*24,2)) | AR9: =IF(OR($W9="",$X9="",$W9=0,$X9=0),"",ROUND(IF($AK9<=$AD9,$AE9-$AK9,1-$AK9+$AE9)*24,2))
I10: =IF(COUNT($R10:$X10)=0,"",ROUND(SUM($R10:$X10),2)) | J10: 40 | K10: =IF(OR(IF($AM10="",Shifts!$B$3,$AM10)<Shifts!$B$3,IF($AN10="",Shifts!$B$3,$AN10)<Shifts!$B$3,IF($AO10="",Shifts!$B$3,$AO10)<Shifts!$B$3,IF($AP10="",Shifts!$B$3,$AP10)<Shifts!$B$3,IF($AQ10="",Shifts!$B$3,$AQ10)<Shifts!$B$3,IF($AR10="",Shifts!$B$3,$AR10)<Shifts!$B$3),"⛔ <"&Shifts!$B$3&" h","") | L10: =IF(7-(IF($R10="",0,IF($R10>0,1,0))+IF($S10="",0,IF($S10>0,1,0))+IF($T10="",0,IF($T10>0,1,0))+IF($U10="",0,IF($U10>0,1,0))+IF($V10="",0,IF($V10>0,1,0))+IF($W10="",0,IF($W10>0,1,0))+IF($X10="",0,IF($X10>0,1,0)))=0,"⛔ 0 days off",IF(7-(IF($R10="",0,IF($R10>0,1,0))+IF($S10="",0,IF($S10>0,1,0))+IF($T10="",0,IF($T10>0,1,0))+IF($U10="",0,IF($U10>0,1,0))+IF($V10="",0,IF($V10>0,1,0))+IF($W10="",0,IF($W10>0,1,0))+IF($X10="",0,IF($X10>0,1,0)))=1,"⚠ 6 days on: a 7th day in a row is premium pay in CA","")) | M10: =IF(OR($I10="",$J10=""),"",IF($I10>$J10,"⛔ +"&TEXT($I10-$J10,"0")&" h","")) | N10: =IF($O10="Y",IF(OR(IF($R10="",0,$R10)>8,IF($S10="",0,$S10)>8,IF($T10="",0,$T10)>8,IF($U10="",0,$U10)>8,IF($V10="",0,$V10)>8,IF($W10="",0,$W10)>8,IF($X10="",0,$X10)>8),"⛔ shift > 8 h (MINOR)",""),IF(OR(IF($R10="",0,$R10)>Shifts!$B$2,IF($S10="",0,$S10)>Shifts!$B$2,IF($T10="",0,$T10)>Shifts!$B$2,IF($U10="",0,$U10)>Shifts!$B$2,IF($V10="",0,$V10)>Shifts!$B$2,IF($W10="",0,$W10)>Shifts!$B$2,IF($X10="",0,$X10)>Shifts!$B$2),"⛔ shift > "&Shifts!$B$2&" h","")) | P10: =IF($O10<>"Y","",IF(OR($B10="N",$B10="DBL",$C10="N",$C10="DBL",$D10="N",$D10="DBL",$E10="N",$E10="DBL",$F10="N",$F10="DBL",$G10="N",$G10="DBL",$H10="N",$H10="DBL"),"⛔ MINOR: no night or double shifts (29 CFR 570.35)","⚠ minor: check federal and state hour limits")) | R10: =IF($B10="","",IFERROR(VLOOKUP($B10,Shifts!$A$5:$E$12,5,FALSE),0)) | S10: =IF($C10="","",IFERROR(VLOOKUP($C10,Shifts!$A$5:$E$12,5,FALSE),0)) | T10: =IF($D10="","",IFERROR(VLOOKUP($D10,Shifts!$A$5:$E$12,5,FALSE),0)) | U10: =IF($E10="","",IFERROR(VLOOKUP($E10,Shifts!$A$5:$E$12,5,FALSE),0)) | V10: =IF($F10="","",IFERROR(VLOOKUP($F10,Shifts!$A$5:$E$12,5,FALSE),0)) | W10: =IF($G10="","",IFERROR(VLOOKUP($G10,Shifts!$A$5:$E$12,5,FALSE),0)) | X10: =IF($H10="","",IFERROR(VLOOKUP($H10,Shifts!$A$5:$E$12,5,FALSE),0)) | Y10: =IF($B10="","",IFERROR(VLOOKUP($B10,Shifts!$A$5:$E$12,3,FALSE),0)) | Z10: =IF($C10="","",IFERROR(VLOOKUP($C10,Shifts!$A$5:$E$12,3,FALSE),0)) | AA10: =IF($D10="","",IFERROR(VLOOKUP($D10,Shifts!$A$5:$E$12,3,FALSE),0)) | AB10: =IF($E10="","",IFERROR(VLOOKUP($E10,Shifts!$A$5:$E$12,3,FALSE),0)) | AC10: =IF($F10="","",IFERROR(VLOOKUP($F10,Shifts!$A$5:$E$12,3,FALSE),0)) | AD10: =IF($G10="","",IFERROR(VLOOKUP($G10,Shifts!$A$5:$E$12,3,FALSE),0)) | AE10: =IF($H10="","",IFERROR(VLOOKUP($H10,Shifts!$A$5:$E$12,3,FALSE),0)) | AF10: =IF($B10="","",IFERROR(VLOOKUP($B10,Shifts!$A$5:$E$12,4,FALSE),0)) | AG10: =IF($C10="","",IFERROR(VLOOKUP($C10,Shifts!$A$5:$E$12,4,FALSE),0)) | AH10: =IF($D10="","",IFERROR(VLOOKUP($D10,Shifts!$A$5:$E$12,4,FALSE),0)) | AI10: =IF($E10="","",IFERROR(VLOOKUP($E10,Shifts!$A$5:$E$12,4,FALSE),0)) | AJ10: =IF($F10="","",IFERROR(VLOOKUP($F10,Shifts!$A$5:$E$12,4,FALSE),0)) | AK10: =IF($G10="","",IFERROR(VLOOKUP($G10,Shifts!$A$5:$E$12,4,FALSE),0)) | AL10: =IF($H10="","",IFERROR(VLOOKUP($H10,Shifts!$A$5:$E$12,4,FALSE),0)) | AM10: =IF(OR($R10="",$S10="",$R10=0,$S10=0),"",ROUND(IF($AF10<=$Y10,$Z10-$AF10,1-$AF10+$Z10)*24,2)) | AN10: =IF(OR($S10="",$T10="",$S10=0,$T10=0),"",ROUND(IF($AG10<=$Z10,$AA10-$AG10,1-$AG10+$AA10)*24,2)) | AO10: =IF(OR($T10="",$U10="",$T10=0,$U10=0),"",ROUND(IF($AH10<=$AA10,$AB10-$AH10,1-$AH10+$AB10)*24,2)) | AP10: =IF(OR($U10="",$V10="",$U10=0,$V10=0),"",ROUND(IF($AI10<=$AB10,$AC10-$AI10,1-$AI10+$AC10)*24,2)) | AQ10: =IF(OR($V10="",$W10="",$V10=0,$W10=0),"",ROUND(IF($AJ10<=$AC10,$AD10-$AJ10,1-$AJ10+$AD10)*24,2)) | AR10: =IF(OR($W10="",$X10="",$W10=0,$X10=0),"",ROUND(IF($AK10<=$AD10,$AE10-$AK10,1-$AK10+$AE10)*24,2))
I11: =IF(COUNT($R11:$X11)=0,"",ROUND(SUM($R11:$X11),2)) | J11: 40 | K11: =IF(OR(IF($AM11="",Shifts!$B$3,$AM11)<Shifts!$B$3,IF($AN11="",Shifts!$B$3,$AN11)<Shifts!$B$3,IF($AO11="",Shifts!$B$3,$AO11)<Shifts!$B$3,IF($AP11="",Shifts!$B$3,$AP11)<Shifts!$B$3,IF($AQ11="",Shifts!$B$3,$AQ11)<Shifts!$B$3,IF($AR11="",Shifts!$B$3,$AR11)<Shifts!$B$3),"⛔ <"&Shifts!$B$3&" h","") | L11: =IF(7-(IF($R11="",0,IF($R11>0,1,0))+IF($S11="",0,IF($S11>0,1,0))+IF($T11="",0,IF($T11>0,1,0))+IF($U11="",0,IF($U11>0,1,0))+IF($V11="",0,IF($V11>0,1,0))+IF($W11="",0,IF($W11>0,1,0))+IF($X11="",0,IF($X11>0,1,0)))=0,"⛔ 0 days off",IF(7-(IF($R11="",0,IF($R11>0,1,0))+IF($S11="",0,IF($S11>0,1,0))+IF($T11="",0,IF($T11>0,1,0))+IF($U11="",0,IF($U11>0,1,0))+IF($V11="",0,IF($V11>0,1,0))+IF($W11="",0,IF($W11>0,1,0))+IF($X11="",0,IF($X11>0,1,0)))=1,"⚠ 6 days on: a 7th day in a row is premium pay in CA","")) | M11: =IF(OR($I11="",$J11=""),"",IF($I11>$J11,"⛔ +"&TEXT($I11-$J11,"0")&" h","")) | N11: =IF($O11="Y",IF(OR(IF($R11="",0,$R11)>8,IF($S11="",0,$S11)>8,IF($T11="",0,$T11)>8,IF($U11="",0,$U11)>8,IF($V11="",0,$V11)>8,IF($W11="",0,$W11)>8,IF($X11="",0,$X11)>8),"⛔ shift > 8 h (MINOR)",""),IF(OR(IF($R11="",0,$R11)>Shifts!$B$2,IF($S11="",0,$S11)>Shifts!$B$2,IF($T11="",0,$T11)>Shifts!$B$2,IF($U11="",0,$U11)>Shifts!$B$2,IF($V11="",0,$V11)>Shifts!$B$2,IF($W11="",0,$W11)>Shifts!$B$2,IF($X11="",0,$X11)>Shifts!$B$2),"⛔ shift > "&Shifts!$B$2&" h","")) | P11: =IF($O11<>"Y","",IF(OR($B11="N",$B11="DBL",$C11="N",$C11="DBL",$D11="N",$D11="DBL",$E11="N",$E11="DBL",$F11="N",$F11="DBL",$G11="N",$G11="DBL",$H11="N",$H11="DBL"),"⛔ MINOR: no night or double shifts (29 CFR 570.35)","⚠ minor: check federal and state hour limits")) | R11: =IF($B11="","",IFERROR(VLOOKUP($B11,Shifts!$A$5:$E$12,5,FALSE),0)) | S11: =IF($C11="","",IFERROR(VLOOKUP($C11,Shifts!$A$5:$E$12,5,FALSE),0)) | T11: =IF($D11="","",IFERROR(VLOOKUP($D11,Shifts!$A$5:$E$12,5,FALSE),0)) | U11: =IF($E11="","",IFERROR(VLOOKUP($E11,Shifts!$A$5:$E$12,5,FALSE),0)) | V11: =IF($F11="","",IFERROR(VLOOKUP($F11,Shifts!$A$5:$E$12,5,FALSE),0)) | W11: =IF($G11="","",IFERROR(VLOOKUP($G11,Shifts!$A$5:$E$12,5,FALSE),0)) | X11: =IF($H11="","",IFERROR(VLOOKUP($H11,Shifts!$A$5:$E$12,5,FALSE),0)) | Y11: =IF($B11="","",IFERROR(VLOOKUP($B11,Shifts!$A$5:$E$12,3,FALSE),0)) | Z11: =IF($C11="","",IFERROR(VLOOKUP($C11,Shifts!$A$5:$E$12,3,FALSE),0)) | AA11: =IF($D11="","",IFERROR(VLOOKUP($D11,Shifts!$A$5:$E$12,3,FALSE),0)) | AB11: =IF($E11="","",IFERROR(VLOOKUP($E11,Shifts!$A$5:$E$12,3,FALSE),0)) | AC11: =IF($F11="","",IFERROR(VLOOKUP($F11,Shifts!$A$5:$E$12,3,FALSE),0)) | AD11: =IF($G11="","",IFERROR(VLOOKUP($G11,Shifts!$A$5:$E$12,3,FALSE),0)) | AE11: =IF($H11="","",IFERROR(VLOOKUP($H11,Shifts!$A$5:$E$12,3,FALSE),0)) | AF11: =IF($B11="","",IFERROR(VLOOKUP($B11,Shifts!$A$5:$E$12,4,FALSE),0)) | AG11: =IF($C11="","",IFERROR(VLOOKUP($C11,Shifts!$A$5:$E$12,4,FALSE),0)) | AH11: =IF($D11="","",IFERROR(VLOOKUP($D11,Shifts!$A$5:$E$12,4,FALSE),0)) | AI11: =IF($E11="","",IFERROR(VLOOKUP($E11,Shifts!$A$5:$E$12,4,FALSE),0)) | AJ11: =IF($F11="","",IFERROR(VLOOKUP($F11,Shifts!$A$5:$E$12,4,FALSE),0)) | AK11: =IF($G11="","",IFERROR(VLOOKUP($G11,Shifts!$A$5:$E$12,4,FALSE),0)) | AL11: =IF($H11="","",IFERROR(VLOOKUP($H11,Shifts!$A$5:$E$12,4,FALSE),0)) | AM11: =IF(OR($R11="",$S11="",$R11=0,$S11=0),"",ROUND(IF($AF11<=$Y11,$Z11-$AF11,1-$AF11+$Z11)*24,2)) | AN11: =IF(OR($S11="",$T11="",$S11=0,$T11=0),"",ROUND(IF($AG11<=$Z11,$AA11-$AG11,1-$AG11+$AA11)*24,2)) | AO11: =IF(OR($T11="",$U11="",$T11=0,$U11=0),"",ROUND(IF($AH11<=$AA11,$AB11-$AH11,1-$AH11+$AB11)*24,2)) | AP11: =IF(OR($U11="",$V11="",$U11=0,$V11=0),"",ROUND(IF($AI11<=$AB11,$AC11-$AI11,1-$AI11+$AC11)*24,2)) | AQ11: =IF(OR($V11="",$W11="",$V11=0,$W11=0),"",ROUND(IF($AJ11<=$AC11,$AD11-$AJ11,1-$AJ11+$AD11)*24,2)) | AR11: =IF(OR($W11="",$X11="",$W11=0,$X11=0),"",ROUND(IF($AK11<=$AD11,$AE11-$AK11,1-$AK11+$AE11)*24,2))
I12: =IF(COUNT($R12:$X12)=0,"",ROUND(SUM($R12:$X12),2)) | J12: 40 | K12: =IF(OR(IF($AM12="",Shifts!$B$3,$AM12)<Shifts!$B$3,IF($AN12="",Shifts!$B$3,$AN12)<Shifts!$B$3,IF($AO12="",Shifts!$B$3,$AO12)<Shifts!$B$3,IF($AP12="",Shifts!$B$3,$AP12)<Shifts!$B$3,IF($AQ12="",Shifts!$B$3,$AQ12)<Shifts!$B$3,IF($AR12="",Shifts!$B$3,$AR12)<Shifts!$B$3),"⛔ <"&Shifts!$B$3&" h","") | L12: =IF(7-(IF($R12="",0,IF($R12>0,1,0))+IF($S12="",0,IF($S12>0,1,0))+IF($T12="",0,IF($T12>0,1,0))+IF($U12="",0,IF($U12>0,1,0))+IF($V12="",0,IF($V12>0,1,0))+IF($W12="",0,IF($W12>0,1,0))+IF($X12="",0,IF($X12>0,1,0)))=0,"⛔ 0 days off",IF(7-(IF($R12="",0,IF($R12>0,1,0))+IF($S12="",0,IF($S12>0,1,0))+IF($T12="",0,IF($T12>0,1,0))+IF($U12="",0,IF($U12>0,1,0))+IF($V12="",0,IF($V12>0,1,0))+IF($W12="",0,IF($W12>0,1,0))+IF($X12="",0,IF($X12>0,1,0)))=1,"⚠ 6 days on: a 7th day in a row is premium pay in CA","")) | M12: =IF(OR($I12="",$J12=""),"",IF($I12>$J12,"⛔ +"&TEXT($I12-$J12,"0")&" h","")) | N12: =IF($O12="Y",IF(OR(IF($R12="",0,$R12)>8,IF($S12="",0,$S12)>8,IF($T12="",0,$T12)>8,IF($U12="",0,$U12)>8,IF($V12="",0,$V12)>8,IF($W12="",0,$W12)>8,IF($X12="",0,$X12)>8),"⛔ shift > 8 h (MINOR)",""),IF(OR(IF($R12="",0,$R12)>Shifts!$B$2,IF($S12="",0,$S12)>Shifts!$B$2,IF($T12="",0,$T12)>Shifts!$B$2,IF($U12="",0,$U12)>Shifts!$B$2,IF($V12="",0,$V12)>Shifts!$B$2,IF($W12="",0,$W12)>Shifts!$B$2,IF($X12="",0,$X12)>Shifts!$B$2),"⛔ shift > "&Shifts!$B$2&" h","")) | P12: =IF($O12<>"Y","",IF(OR($B12="N",$B12="DBL",$C12="N",$C12="DBL",$D12="N",$D12="DBL",$E12="N",$E12="DBL",$F12="N",$F12="DBL",$G12="N",$G12="DBL",$H12="N",$H12="DBL"),"⛔ MINOR: no night or double shifts (29 CFR 570.35)","⚠ minor: check federal and state hour limits")) | R12: =IF($B12="","",IFERROR(VLOOKUP($B12,Shifts!$A$5:$E$12,5,FALSE),0)) | S12: =IF($C12="","",IFERROR(VLOOKUP($C12,Shifts!$A$5:$E$12,5,FALSE),0)) | T12: =IF($D12="","",IFERROR(VLOOKUP($D12,Shifts!$A$5:$E$12,5,FALSE),0)) | U12: =IF($E12="","",IFERROR(VLOOKUP($E12,Shifts!$A$5:$E$12,5,FALSE),0)) | V12: =IF($F12="","",IFERROR(VLOOKUP($F12,Shifts!$A$5:$E$12,5,FALSE),0)) | W12: =IF($G12="","",IFERROR(VLOOKUP($G12,Shifts!$A$5:$E$12,5,FALSE),0)) | X12: =IF($H12="","",IFERROR(VLOOKUP($H12,Shifts!$A$5:$E$12,5,FALSE),0)) | Y12: =IF($B12="","",IFERROR(VLOOKUP($B12,Shifts!$A$5:$E$12,3,FALSE),0)) | Z12: =IF($C12="","",IFERROR(VLOOKUP($C12,Shifts!$A$5:$E$12,3,FALSE),0)) | AA12: =IF($D12="","",IFERROR(VLOOKUP($D12,Shifts!$A$5:$E$12,3,FALSE),0)) | AB12: =IF($E12="","",IFERROR(VLOOKUP($E12,Shifts!$A$5:$E$12,3,FALSE),0)) | AC12: =IF($F12="","",IFERROR(VLOOKUP($F12,Shifts!$A$5:$E$12,3,FALSE),0)) | AD12: =IF($G12="","",IFERROR(VLOOKUP($G12,Shifts!$A$5:$E$12,3,FALSE),0)) | AE12: =IF($H12="","",IFERROR(VLOOKUP($H12,Shifts!$A$5:$E$12,3,FALSE),0)) | AF12: =IF($B12="","",IFERROR(VLOOKUP($B12,Shifts!$A$5:$E$12,4,FALSE),0)) | AG12: =IF($C12="","",IFERROR(VLOOKUP($C12,Shifts!$A$5:$E$12,4,FALSE),0)) | AH12: =IF($D12="","",IFERROR(VLOOKUP($D12,Shifts!$A$5:$E$12,4,FALSE),0)) | AI12: =IF($E12="","",IFERROR(VLOOKUP($E12,Shifts!$A$5:$E$12,4,FALSE),0)) | AJ12: =IF($F12="","",IFERROR(VLOOKUP($F12,Shifts!$A$5:$E$12,4,FALSE),0)) | AK12: =IF($G12="","",IFERROR(VLOOKUP($G12,Shifts!$A$5:$E$12,4,FALSE),0)) | AL12: =IF($H12="","",IFERROR(VLOOKUP($H12,Shifts!$A$5:$E$12,4,FALSE),0)) | AM12: =IF(OR($R12="",$S12="",$R12=0,$S12=0),"",ROUND(IF($AF12<=$Y12,$Z12-$AF12,1-$AF12+$Z12)*24,2)) | AN12: =IF(OR($S12="",$T12="",$S12=0,$T12=0),"",ROUND(IF($AG12<=$Z12,$AA12-$AG12,1-$AG12+$AA12)*24,2)) | AO12: =IF(OR($T12="",$U12="",$T12=0,$U12=0),"",ROUND(IF($AH12<=$AA12,$AB12-$AH12,1-$AH12+$AB12)*24,2)) | AP12: =IF(OR($U12="",$V12="",$U12=0,$V12=0),"",ROUND(IF($AI12<=$AB12,$AC12-$AI12,1-$AI12+$AC12)*24,2)) | AQ12: =IF(OR($V12="",$W12="",$V12=0,$W12=0),"",ROUND(IF($AJ12<=$AC12,$AD12-$AJ12,1-$AJ12+$AD12)*24,2)) | AR12: =IF(OR($W12="",$X12="",$W12=0,$X12=0),"",ROUND(IF($AK12<=$AD12,$AE12-$AK12,1-$AK12+$AE12)*24,2))
I13: =IF(COUNT($R13:$X13)=0,"",ROUND(SUM($R13:$X13),2)) | J13: 40 | K13: =IF(OR(IF($AM13="",Shifts!$B$3,$AM13)<Shifts!$B$3,IF($AN13="",Shifts!$B$3,$AN13)<Shifts!$B$3,IF($AO13="",Shifts!$B$3,$AO13)<Shifts!$B$3,IF($AP13="",Shifts!$B$3,$AP13)<Shifts!$B$3,IF($AQ13="",Shifts!$B$3,$AQ13)<Shifts!$B$3,IF($AR13="",Shifts!$B$3,$AR13)<Shifts!$B$3),"⛔ <"&Shifts!$B$3&" h","") | L13: =IF(7-(IF($R13="",0,IF($R13>0,1,0))+IF($S13="",0,IF($S13>0,1,0))+IF($T13="",0,IF($T13>0,1,0))+IF($U13="",0,IF($U13>0,1,0))+IF($V13="",0,IF($V13>0,1,0))+IF($W13="",0,IF($W13>0,1,0))+IF($X13="",0,IF($X13>0,1,0)))=0,"⛔ 0 days off",IF(7-(IF($R13="",0,IF($R13>0,1,0))+IF($S13="",0,IF($S13>0,1,0))+IF($T13="",0,IF($T13>0,1,0))+IF($U13="",0,IF($U13>0,1,0))+IF($V13="",0,IF($V13>0,1,0))+IF($W13="",0,IF($W13>0,1,0))+IF($X13="",0,IF($X13>0,1,0)))=1,"⚠ 6 days on: a 7th day in a row is premium pay in CA","")) | M13: =IF(OR($I13="",$J13=""),"",IF($I13>$J13,"⛔ +"&TEXT($I13-$J13,"0")&" h","")) | N13: =IF($O13="Y",IF(OR(IF($R13="",0,$R13)>8,IF($S13="",0,$S13)>8,IF($T13="",0,$T13)>8,IF($U13="",0,$U13)>8,IF($V13="",0,$V13)>8,IF($W13="",0,$W13)>8,IF($X13="",0,$X13)>8),"⛔ shift > 8 h (MINOR)",""),IF(OR(IF($R13="",0,$R13)>Shifts!$B$2,IF($S13="",0,$S13)>Shifts!$B$2,IF($T13="",0,$T13)>Shifts!$B$2,IF($U13="",0,$U13)>Shifts!$B$2,IF($V13="",0,$V13)>Shifts!$B$2,IF($W13="",0,$W13)>Shifts!$B$2,IF($X13="",0,$X13)>Shifts!$B$2),"⛔ shift > "&Shifts!$B$2&" h","")) | P13: =IF($O13<>"Y","",IF(OR($B13="N",$B13="DBL",$C13="N",$C13="DBL",$D13="N",$D13="DBL",$E13="N",$E13="DBL",$F13="N",$F13="DBL",$G13="N",$G13="DBL",$H13="N",$H13="DBL"),"⛔ MINOR: no night or double shifts (29 CFR 570.35)","⚠ minor: check federal and state hour limits")) | R13: =IF($B13="","",IFERROR(VLOOKUP($B13,Shifts!$A$5:$E$12,5,FALSE),0)) | S13: =IF($C13="","",IFERROR(VLOOKUP($C13,Shifts!$A$5:$E$12,5,FALSE),0)) | T13: =IF($D13="","",IFERROR(VLOOKUP($D13,Shifts!$A$5:$E$12,5,FALSE),0)) | U13: =IF($E13="","",IFERROR(VLOOKUP($E13,Shifts!$A$5:$E$12,5,FALSE),0)) | V13: =IF($F13="","",IFERROR(VLOOKUP($F13,Shifts!$A$5:$E$12,5,FALSE),0)) | W13: =IF($G13="","",IFERROR(VLOOKUP($G13,Shifts!$A$5:$E$12,5,FALSE),0)) | X13: =IF($H13="","",IFERROR(VLOOKUP($H13,Shifts!$A$5:$E$12,5,FALSE),0)) | Y13: =IF($B13="","",IFERROR(VLOOKUP($B13,Shifts!$A$5:$E$12,3,FALSE),0)) | Z13: =IF($C13="","",IFERROR(VLOOKUP($C13,Shifts!$A$5:$E$12,3,FALSE),0)) | AA13: =IF($D13="","",IFERROR(VLOOKUP($D13,Shifts!$A$5:$E$12,3,FALSE),0)) | AB13: =IF($E13="","",IFERROR(VLOOKUP($E13,Shifts!$A$5:$E$12,3,FALSE),0)) | AC13: =IF($F13="","",IFERROR(VLOOKUP($F13,Shifts!$A$5:$E$12,3,FALSE),0)) | AD13: =IF($G13="","",IFERROR(VLOOKUP($G13,Shifts!$A$5:$E$12,3,FALSE),0)) | AE13: =IF($H13="","",IFERROR(VLOOKUP($H13,Shifts!$A$5:$E$12,3,FALSE),0)) | AF13: =IF($B13="","",IFERROR(VLOOKUP($B13,Shifts!$A$5:$E$12,4,FALSE),0)) | AG13: =IF($C13="","",IFERROR(VLOOKUP($C13,Shifts!$A$5:$E$12,4,FALSE),0)) | AH13: =IF($D13="","",IFERROR(VLOOKUP($D13,Shifts!$A$5:$E$12,4,FALSE),0)) | AI13: =IF($E13="","",IFERROR(VLOOKUP($E13,Shifts!$A$5:$E$12,4,FALSE),0)) | AJ13: =IF($F13="","",IFERROR(VLOOKUP($F13,Shifts!$A$5:$E$12,4,FALSE),0)) | AK13: =IF($G13="","",IFERROR(VLOOKUP($G13,Shifts!$A$5:$E$12,4,FALSE),0)) | AL13: =IF($H13="","",IFERROR(VLOOKUP($H13,Shifts!$A$5:$E$12,4,FALSE),0)) | AM13: =IF(OR($R13="",$S13="",$R13=0,$S13=0),"",ROUND(IF($AF13<=$Y13,$Z13-$AF13,1-$AF13+$Z13)*24,2)) | AN13: =IF(OR($S13="",$T13="",$S13=0,$T13=0),"",ROUND(IF($AG13<=$Z13,$AA13-$AG13,1-$AG13+$AA13)*24,2)) | AO13: =IF(OR($T13="",$U13="",$T13=0,$U13=0),"",ROUND(IF($AH13<=$AA13,$AB13-$AH13,1-$AH13+$AB13)*24,2)) | AP13: =IF(OR($U13="",$V13="",$U13=0,$V13=0),"",ROUND(IF($AI13<=$AB13,$AC13-$AI13,1-$AI13+$AC13)*24,2)) | AQ13: =IF(OR($V13="",$W13="",$V13=0,$W13=0),"",ROUND(IF($AJ13<=$AC13,$AD13-$AJ13,1-$AJ13+$AD13)*24,2)) | AR13: =IF(OR($W13="",$X13="",$W13=0,$X13=0),"",ROUND(IF($AK13<=$AD13,$AE13-$AK13,1-$AK13+$AE13)*24,2))
I14: =IF(COUNT($R14:$X14)=0,"",ROUND(SUM($R14:$X14),2)) | J14: 40 | K14: =IF(OR(IF($AM14="",Shifts!$B$3,$AM14)<Shifts!$B$3,IF($AN14="",Shifts!$B$3,$AN14)<Shifts!$B$3,IF($AO14="",Shifts!$B$3,$AO14)<Shifts!$B$3,IF($AP14="",Shifts!$B$3,$AP14)<Shifts!$B$3,IF($AQ14="",Shifts!$B$3,$AQ14)<Shifts!$B$3,IF($AR14="",Shifts!$B$3,$AR14)<Shifts!$B$3),"⛔ <"&Shifts!$B$3&" h","") | L14: =IF(7-(IF($R14="",0,IF($R14>0,1,0))+IF($S14="",0,IF($S14>0,1,0))+IF($T14="",0,IF($T14>0,1,0))+IF($U14="",0,IF($U14>0,1,0))+IF($V14="",0,IF($V14>0,1,0))+IF($W14="",0,IF($W14>0,1,0))+IF($X14="",0,IF($X14>0,1,0)))=0,"⛔ 0 days off",IF(7-(IF($R14="",0,IF($R14>0,1,0))+IF($S14="",0,IF($S14>0,1,0))+IF($T14="",0,IF($T14>0,1,0))+IF($U14="",0,IF($U14>0,1,0))+IF($V14="",0,IF($V14>0,1,0))+IF($W14="",0,IF($W14>0,1,0))+IF($X14="",0,IF($X14>0,1,0)))=1,"⚠ 6 days on: a 7th day in a row is premium pay in CA","")) | M14: =IF(OR($I14="",$J14=""),"",IF($I14>$J14,"⛔ +"&TEXT($I14-$J14,"0")&" h","")) | N14: =IF($O14="Y",IF(OR(IF($R14="",0,$R14)>8,IF($S14="",0,$S14)>8,IF($T14="",0,$T14)>8,IF($U14="",0,$U14)>8,IF($V14="",0,$V14)>8,IF($W14="",0,$W14)>8,IF($X14="",0,$X14)>8),"⛔ shift > 8 h (MINOR)",""),IF(OR(IF($R14="",0,$R14)>Shifts!$B$2,IF($S14="",0,$S14)>Shifts!$B$2,IF($T14="",0,$T14)>Shifts!$B$2,IF($U14="",0,$U14)>Shifts!$B$2,IF($V14="",0,$V14)>Shifts!$B$2,IF($W14="",0,$W14)>Shifts!$B$2,IF($X14="",0,$X14)>Shifts!$B$2),"⛔ shift > "&Shifts!$B$2&" h","")) | P14: =IF($O14<>"Y","",IF(OR($B14="N",$B14="DBL",$C14="N",$C14="DBL",$D14="N",$D14="DBL",$E14="N",$E14="DBL",$F14="N",$F14="DBL",$G14="N",$G14="DBL",$H14="N",$H14="DBL"),"⛔ MINOR: no night or double shifts (29 CFR 570.35)","⚠ minor: check federal and state hour limits")) | R14: =IF($B14="","",IFERROR(VLOOKUP($B14,Shifts!$A$5:$E$12,5,FALSE),0)) | S14: =IF($C14="","",IFERROR(VLOOKUP($C14,Shifts!$A$5:$E$12,5,FALSE),0)) | T14: =IF($D14="","",IFERROR(VLOOKUP($D14,Shifts!$A$5:$E$12,5,FALSE),0)) | U14: =IF($E14="","",IFERROR(VLOOKUP($E14,Shifts!$A$5:$E$12,5,FALSE),0)) | V14: =IF($F14="","",IFERROR(VLOOKUP($F14,Shifts!$A$5:$E$12,5,FALSE),0)) | W14: =IF($G14="","",IFERROR(VLOOKUP($G14,Shifts!$A$5:$E$12,5,FALSE),0)) | X14: =IF($H14="","",IFERROR(VLOOKUP($H14,Shifts!$A$5:$E$12,5,FALSE),0)) | Y14: =IF($B14="","",IFERROR(VLOOKUP($B14,Shifts!$A$5:$E$12,3,FALSE),0)) | Z14: =IF($C14="","",IFERROR(VLOOKUP($C14,Shifts!$A$5:$E$12,3,FALSE),0)) | AA14: =IF($D14="","",IFERROR(VLOOKUP($D14,Shifts!$A$5:$E$12,3,FALSE),0)) | AB14: =IF($E14="","",IFERROR(VLOOKUP($E14,Shifts!$A$5:$E$12,3,FALSE),0)) | AC14: =IF($F14="","",IFERROR(VLOOKUP($F14,Shifts!$A$5:$E$12,3,FALSE),0)) | AD14: =IF($G14="","",IFERROR(VLOOKUP($G14,Shifts!$A$5:$E$12,3,FALSE),0)) | AE14: =IF($H14="","",IFERROR(VLOOKUP($H14,Shifts!$A$5:$E$12,3,FALSE),0)) | AF14: =IF($B14="","",IFERROR(VLOOKUP($B14,Shifts!$A$5:$E$12,4,FALSE),0)) | AG14: =IF($C14="","",IFERROR(VLOOKUP($C14,Shifts!$A$5:$E$12,4,FALSE),0)) | AH14: =IF($D14="","",IFERROR(VLOOKUP($D14,Shifts!$A$5:$E$12,4,FALSE),0)) | AI14: =IF($E14="","",IFERROR(VLOOKUP($E14,Shifts!$A$5:$E$12,4,FALSE),0)) | AJ14: =IF($F14="","",IFERROR(VLOOKUP($F14,Shifts!$A$5:$E$12,4,FALSE),0)) | AK14: =IF($G14="","",IFERROR(VLOOKUP($G14,Shifts!$A$5:$E$12,4,FALSE),0)) | AL14: =IF($H14="","",IFERROR(VLOOKUP($H14,Shifts!$A$5:$E$12,4,FALSE),0)) | AM14: =IF(OR($R14="",$S14="",$R14=0,$S14=0),"",ROUND(IF($AF14<=$Y14,$Z14-$AF14,1-$AF14+$Z14)*24,2)) | AN14: =IF(OR($S14="",$T14="",$S14=0,$T14=0),"",ROUND(IF($AG14<=$Z14,$AA14-$AG14,1-$AG14+$AA14)*24,2)) | AO14: =IF(OR($T14="",$U14="",$T14=0,$U14=0),"",ROUND(IF($AH14<=$AA14,$AB14-$AH14,1-$AH14+$AB14)*24,2)) | AP14: =IF(OR($U14="",$V14="",$U14=0,$V14=0),"",ROUND(IF($AI14<=$AB14,$AC14-$AI14,1-$AI14+$AC14)*24,2)) | AQ14: =IF(OR($V14="",$W14="",$V14=0,$W14=0),"",ROUND(IF($AJ14<=$AC14,$AD14-$AJ14,1-$AJ14+$AD14)*24,2)) | AR14: =IF(OR($W14="",$X14="",$W14=0,$X14=0),"",ROUND(IF($AK14<=$AD14,$AE14-$AK14,1-$AK14+$AE14)*24,2))
I15: =IF(COUNT($R15:$X15)=0,"",ROUND(SUM($R15:$X15),2)) | J15: 40 | K15: =IF(OR(IF($AM15="",Shifts!$B$3,$AM15)<Shifts!$B$3,IF($AN15="",Shifts!$B$3,$AN15)<Shifts!$B$3,IF($AO15="",Shifts!$B$3,$AO15)<Shifts!$B$3,IF($AP15="",Shifts!$B$3,$AP15)<Shifts!$B$3,IF($AQ15="",Shifts!$B$3,$AQ15)<Shifts!$B$3,IF($AR15="",Shifts!$B$3,$AR15)<Shifts!$B$3),"⛔ <"&Shifts!$B$3&" h","") | L15: =IF(7-(IF($R15="",0,IF($R15>0,1,0))+IF($S15="",0,IF($S15>0,1,0))+IF($T15="",0,IF($T15>0,1,0))+IF($U15="",0,IF($U15>0,1,0))+IF($V15="",0,IF($V15>0,1,0))+IF($W15="",0,IF($W15>0,1,0))+IF($X15="",0,IF($X15>0,1,0)))=0,"⛔ 0 days off",IF(7-(IF($R15="",0,IF($R15>0,1,0))+IF($S15="",0,IF($S15>0,1,0))+IF($T15="",0,IF($T15>0,1,0))+IF($U15="",0,IF($U15>0,1,0))+IF($V15="",0,IF($V15>0,1,0))+IF($W15="",0,IF($W15>0,1,0))+IF($X15="",0,IF($X15>0,1,0)))=1,"⚠ 6 days on: a 7th day in a row is premium pay in CA","")) | M15: =IF(OR($I15="",$J15=""),"",IF($I15>$J15,"⛔ +"&TEXT($I15-$J15,"0")&" h","")) | N15: =IF($O15="Y",IF(OR(IF($R15="",0,$R15)>8,IF($S15="",0,$S15)>8,IF($T15="",0,$T15)>8,IF($U15="",0,$U15)>8,IF($V15="",0,$V15)>8,IF($W15="",0,$W15)>8,IF($X15="",0,$X15)>8),"⛔ shift > 8 h (MINOR)",""),IF(OR(IF($R15="",0,$R15)>Shifts!$B$2,IF($S15="",0,$S15)>Shifts!$B$2,IF($T15="",0,$T15)>Shifts!$B$2,IF($U15="",0,$U15)>Shifts!$B$2,IF($V15="",0,$V15)>Shifts!$B$2,IF($W15="",0,$W15)>Shifts!$B$2,IF($X15="",0,$X15)>Shifts!$B$2),"⛔ shift > "&Shifts!$B$2&" h","")) | P15: =IF($O15<>"Y","",IF(OR($B15="N",$B15="DBL",$C15="N",$C15="DBL",$D15="N",$D15="DBL",$E15="N",$E15="DBL",$F15="N",$F15="DBL",$G15="N",$G15="DBL",$H15="N",$H15="DBL"),"⛔ MINOR: no night or double shifts (29 CFR 570.35)","⚠ minor: check federal and state hour limits")) | R15: =IF($B15="","",IFERROR(VLOOKUP($B15,Shifts!$A$5:$E$12,5,FALSE),0)) | S15: =IF($C15="","",IFERROR(VLOOKUP($C15,Shifts!$A$5:$E$12,5,FALSE),0)) | T15: =IF($D15="","",IFERROR(VLOOKUP($D15,Shifts!$A$5:$E$12,5,FALSE),0)) | U15: =IF($E15="","",IFERROR(VLOOKUP($E15,Shifts!$A$5:$E$12,5,FALSE),0)) | V15: =IF($F15="","",IFERROR(VLOOKUP($F15,Shifts!$A$5:$E$12,5,FALSE),0)) | W15: =IF($G15="","",IFERROR(VLOOKUP($G15,Shifts!$A$5:$E$12,5,FALSE),0)) | X15: =IF($H15="","",IFERROR(VLOOKUP($H15,Shifts!$A$5:$E$12,5,FALSE),0)) | Y15: =IF($B15="","",IFERROR(VLOOKUP($B15,Shifts!$A$5:$E$12,3,FALSE),0)) | Z15: =IF($C15="","",IFERROR(VLOOKUP($C15,Shifts!$A$5:$E$12,3,FALSE),0)) | AA15: =IF($D15="","",IFERROR(VLOOKUP($D15,Shifts!$A$5:$E$12,3,FALSE),0)) | AB15: =IF($E15="","",IFERROR(VLOOKUP($E15,Shifts!$A$5:$E$12,3,FALSE),0)) | AC15: =IF($F15="","",IFERROR(VLOOKUP($F15,Shifts!$A$5:$E$12,3,FALSE),0)) | AD15: =IF($G15="","",IFERROR(VLOOKUP($G15,Shifts!$A$5:$E$12,3,FALSE),0)) | AE15: =IF($H15="","",IFERROR(VLOOKUP($H15,Shifts!$A$5:$E$12,3,FALSE),0)) | AF15: =IF($B15="","",IFERROR(VLOOKUP($B15,Shifts!$A$5:$E$12,4,FALSE),0)) | AG15: =IF($C15="","",IFERROR(VLOOKUP($C15,Shifts!$A$5:$E$12,4,FALSE),0)) | AH15: =IF($D15="","",IFERROR(VLOOKUP($D15,Shifts!$A$5:$E$12,4,FALSE),0)) | AI15: =IF($E15="","",IFERROR(VLOOKUP($E15,Shifts!$A$5:$E$12,4,FALSE),0)) | AJ15: =IF($F15="","",IFERROR(VLOOKUP($F15,Shifts!$A$5:$E$12,4,FALSE),0)) | AK15: =IF($G15="","",IFERROR(VLOOKUP($G15,Shifts!$A$5:$E$12,4,FALSE),0)) | AL15: =IF($H15="","",IFERROR(VLOOKUP($H15,Shifts!$A$5:$E$12,4,FALSE),0)) | AM15: =IF(OR($R15="",$S15="",$R15=0,$S15=0),"",ROUND(IF($AF15<=$Y15,$Z15-$AF15,1-$AF15+$Z15)*24,2)) | AN15: =IF(OR($S15="",$T15="",$S15=0,$T15=0),"",ROUND(IF($AG15<=$Z15,$AA15-$AG15,1-$AG15+$AA15)*24,2)) | AO15: =IF(OR($T15="",$U15="",$T15=0,$U15=0),"",ROUND(IF($AH15<=$AA15,$AB15-$AH15,1-$AH15+$AB15)*24,2)) | AP15: =IF(OR($U15="",$V15="",$U15=0,$V15=0),"",ROUND(IF($AI15<=$AB15,$AC15-$AI15,1-$AI15+$AC15)*24,2)) | AQ15: =IF(OR($V15="",$W15="",$V15=0,$W15=0),"",ROUND(IF($AJ15<=$AC15,$AD15-$AJ15,1-$AJ15+$AD15)*24,2)) | AR15: =IF(OR($W15="",$X15="",$W15=0,$X15=0),"",ROUND(IF($AK15<=$AD15,$AE15-$AK15,1-$AK15+$AE15)*24,2))
I16: =IF(COUNT($R16:$X16)=0,"",ROUND(SUM($R16:$X16),2)) | J16: 40 | K16: =IF(OR(IF($AM16="",Shifts!$B$3,$AM16)<Shifts!$B$3,IF($AN16="",Shifts!$B$3,$AN16)<Shifts!$B$3,IF($AO16="",Shifts!$B$3,$AO16)<Shifts!$B$3,IF($AP16="",Shifts!$B$3,$AP16)<Shifts!$B$3,IF($AQ16="",Shifts!$B$3,$AQ16)<Shifts!$B$3,IF($AR16="",Shifts!$B$3,$AR16)<Shifts!$B$3),"⛔ <"&Shifts!$B$3&" h","") | L16: =IF(7-(IF($R16="",0,IF($R16>0,1,0))+IF($S16="",0,IF($S16>0,1,0))+IF($T16="",0,IF($T16>0,1,0))+IF($U16="",0,IF($U16>0,1,0))+IF($V16="",0,IF($V16>0,1,0))+IF($W16="",0,IF($W16>0,1,0))+IF($X16="",0,IF($X16>0,1,0)))=0,"⛔ 0 days off",IF(7-(IF($R16="",0,IF($R16>0,1,0))+IF($S16="",0,IF($S16>0,1,0))+IF($T16="",0,IF($T16>0,1,0))+IF($U16="",0,IF($U16>0,1,0))+IF($V16="",0,IF($V16>0,1,0))+IF($W16="",0,IF($W16>0,1,0))+IF($X16="",0,IF($X16>0,1,0)))=1,"⚠ 6 days on: a 7th day in a row is premium pay in CA","")) | M16: =IF(OR($I16="",$J16=""),"",IF($I16>$J16,"⛔ +"&TEXT($I16-$J16,"0")&" h","")) | N16: =IF($O16="Y",IF(OR(IF($R16="",0,$R16)>8,IF($S16="",0,$S16)>8,IF($T16="",0,$T16)>8,IF($U16="",0,$U16)>8,IF($V16="",0,$V16)>8,IF($W16="",0,$W16)>8,IF($X16="",0,$X16)>8),"⛔ shift > 8 h (MINOR)",""),IF(OR(IF($R16="",0,$R16)>Shifts!$B$2,IF($S16="",0,$S16)>Shifts!$B$2,IF($T16="",0,$T16)>Shifts!$B$2,IF($U16="",0,$U16)>Shifts!$B$2,IF($V16="",0,$V16)>Shifts!$B$2,IF($W16="",0,$W16)>Shifts!$B$2,IF($X16="",0,$X16)>Shifts!$B$2),"⛔ shift > "&Shifts!$B$2&" h","")) | P16: =IF($O16<>"Y","",IF(OR($B16="N",$B16="DBL",$C16="N",$C16="DBL",$D16="N",$D16="DBL",$E16="N",$E16="DBL",$F16="N",$F16="DBL",$G16="N",$G16="DBL",$H16="N",$H16="DBL"),"⛔ MINOR: no night or double shifts (29 CFR 570.35)","⚠ minor: check federal and state hour limits")) | R16: =IF($B16="","",IFERROR(VLOOKUP($B16,Shifts!$A$5:$E$12,5,FALSE),0)) | S16: =IF($C16="","",IFERROR(VLOOKUP($C16,Shifts!$A$5:$E$12,5,FALSE),0)) | T16: =IF($D16="","",IFERROR(VLOOKUP($D16,Shifts!$A$5:$E$12,5,FALSE),0)) | U16: =IF($E16="","",IFERROR(VLOOKUP($E16,Shifts!$A$5:$E$12,5,FALSE),0)) | V16: =IF($F16="","",IFERROR(VLOOKUP($F16,Shifts!$A$5:$E$12,5,FALSE),0)) | W16: =IF($G16="","",IFERROR(VLOOKUP($G16,Shifts!$A$5:$E$12,5,FALSE),0)) | X16: =IF($H16="","",IFERROR(VLOOKUP($H16,Shifts!$A$5:$E$12,5,FALSE),0)) | Y16: =IF($B16="","",IFERROR(VLOOKUP($B16,Shifts!$A$5:$E$12,3,FALSE),0)) | Z16: =IF($C16="","",IFERROR(VLOOKUP($C16,Shifts!$A$5:$E$12,3,FALSE),0)) | AA16: =IF($D16="","",IFERROR(VLOOKUP($D16,Shifts!$A$5:$E$12,3,FALSE),0)) | AB16: =IF($E16="","",IFERROR(VLOOKUP($E16,Shifts!$A$5:$E$12,3,FALSE),0)) | AC16: =IF($F16="","",IFERROR(VLOOKUP($F16,Shifts!$A$5:$E$12,3,FALSE),0)) | AD16: =IF($G16="","",IFERROR(VLOOKUP($G16,Shifts!$A$5:$E$12,3,FALSE),0)) | AE16: =IF($H16="","",IFERROR(VLOOKUP($H16,Shifts!$A$5:$E$12,3,FALSE),0)) | AF16: =IF($B16="","",IFERROR(VLOOKUP($B16,Shifts!$A$5:$E$12,4,FALSE),0)) | AG16: =IF($C16="","",IFERROR(VLOOKUP($C16,Shifts!$A$5:$E$12,4,FALSE),0)) | AH16: =IF($D16="","",IFERROR(VLOOKUP($D16,Shifts!$A$5:$E$12,4,FALSE),0)) | AI16: =IF($E16="","",IFERROR(VLOOKUP($E16,Shifts!$A$5:$E$12,4,FALSE),0)) | AJ16: =IF($F16="","",IFERROR(VLOOKUP($F16,Shifts!$A$5:$E$12,4,FALSE),0)) | AK16: =IF($G16="","",IFERROR(VLOOKUP($G16,Shifts!$A$5:$E$12,4,FALSE),0)) | AL16: =IF($H16="","",IFERROR(VLOOKUP($H16,Shifts!$A$5:$E$12,4,FALSE),0)) | AM16: =IF(OR($R16="",$S16="",$R16=0,$S16=0),"",ROUND(IF($AF16<=$Y16,$Z16-$AF16,1-$AF16+$Z16)*24,2)) | AN16: =IF(OR($S16="",$T16="",$S16=0,$T16=0),"",ROUND(IF($AG16<=$Z16,$AA16-$AG16,1-$AG16+$AA16)*24,2)) | AO16: =IF(OR($T16="",$U16="",$T16=0,$U16=0),"",ROUND(IF($AH16<=$AA16,$AB16-$AH16,1-$AH16+$AB16)*24,2)) | AP16: =IF(OR($U16="",$V16="",$U16=0,$V16=0),"",ROUND(IF($AI16<=$AB16,$AC16-$AI16,1-$AI16+$AC16)*24,2)) | AQ16: =IF(OR($V16="",$W16="",$V16=0,$W16=0),"",ROUND(IF($AJ16<=$AC16,$AD16-$AJ16,1-$AJ16+$AD16)*24,2)) | AR16: =IF(OR($W16="",$X16="",$W16=0,$X16=0),"",ROUND(IF($AK16<=$AD16,$AE16-$AK16,1-$AK16+$AE16)*24,2))
I17: =IF(COUNT($R17:$X17)=0,"",ROUND(SUM($R17:$X17),2)) | J17: 40 | K17: =IF(OR(IF($AM17="",Shifts!$B$3,$AM17)<Shifts!$B$3,IF($AN17="",Shifts!$B$3,$AN17)<Shifts!$B$3,IF($AO17="",Shifts!$B$3,$AO17)<Shifts!$B$3,IF($AP17="",Shifts!$B$3,$AP17)<Shifts!$B$3,IF($AQ17="",Shifts!$B$3,$AQ17)<Shifts!$B$3,IF($AR17="",Shifts!$B$3,$AR17)<Shifts!$B$3),"⛔ <"&Shifts!$B$3&" h","") | L17: =IF(7-(IF($R17="",0,IF($R17>0,1,0))+IF($S17="",0,IF($S17>0,1,0))+IF($T17="",0,IF($T17>0,1,0))+IF($U17="",0,IF($U17>0,1,0))+IF($V17="",0,IF($V17>0,1,0))+IF($W17="",0,IF($W17>0,1,0))+IF($X17="",0,IF($X17>0,1,0)))=0,"⛔ 0 days off",IF(7-(IF($R17="",0,IF($R17>0,1,0))+IF($S17="",0,IF($S17>0,1,0))+IF($T17="",0,IF($T17>0,1,0))+IF($U17="",0,IF($U17>0,1,0))+IF($V17="",0,IF($V17>0,1,0))+IF($W17="",0,IF($W17>0,1,0))+IF($X17="",0,IF($X17>0,1,0)))=1,"⚠ 6 days on: a 7th day in a row is premium pay in CA","")) | M17: =IF(OR($I17="",$J17=""),"",IF($I17>$J17,"⛔ +"&TEXT($I17-$J17,"0")&" h","")) | N17: =IF($O17="Y",IF(OR(IF($R17="",0,$R17)>8,IF($S17="",0,$S17)>8,IF($T17="",0,$T17)>8,IF($U17="",0,$U17)>8,IF($V17="",0,$V17)>8,IF($W17="",0,$W17)>8,IF($X17="",0,$X17)>8),"⛔ shift > 8 h (MINOR)",""),IF(OR(IF($R17="",0,$R17)>Shifts!$B$2,IF($S17="",0,$S17)>Shifts!$B$2,IF($T17="",0,$T17)>Shifts!$B$2,IF($U17="",0,$U17)>Shifts!$B$2,IF($V17="",0,$V17)>Shifts!$B$2,IF($W17="",0,$W17)>Shifts!$B$2,IF($X17="",0,$X17)>Shifts!$B$2),"⛔ shift > "&Shifts!$B$2&" h","")) | P17: =IF($O17<>"Y","",IF(OR($B17="N",$B17="DBL",$C17="N",$C17="DBL",$D17="N",$D17="DBL",$E17="N",$E17="DBL",$F17="N",$F17="DBL",$G17="N",$G17="DBL",$H17="N",$H17="DBL"),"⛔ MINOR: no night or double shifts (29 CFR 570.35)","⚠ minor: check federal and state hour limits")) | R17: =IF($B17="","",IFERROR(VLOOKUP($B17,Shifts!$A$5:$E$12,5,FALSE),0)) | S17: =IF($C17="","",IFERROR(VLOOKUP($C17,Shifts!$A$5:$E$12,5,FALSE),0)) | T17: =IF($D17="","",IFERROR(VLOOKUP($D17,Shifts!$A$5:$E$12,5,FALSE),0)) | U17: =IF($E17="","",IFERROR(VLOOKUP($E17,Shifts!$A$5:$E$12,5,FALSE),0)) | V17: =IF($F17="","",IFERROR(VLOOKUP($F17,Shifts!$A$5:$E$12,5,FALSE),0)) | W17: =IF($G17="","",IFERROR(VLOOKUP($G17,Shifts!$A$5:$E$12,5,FALSE),0)) | X17: =IF($H17="","",IFERROR(VLOOKUP($H17,Shifts!$A$5:$E$12,5,FALSE),0)) | Y17: =IF($B17="","",IFERROR(VLOOKUP($B17,Shifts!$A$5:$E$12,3,FALSE),0)) | Z17: =IF($C17="","",IFERROR(VLOOKUP($C17,Shifts!$A$5:$E$12,3,FALSE),0)) | AA17: =IF($D17="","",IFERROR(VLOOKUP($D17,Shifts!$A$5:$E$12,3,FALSE),0)) | AB17: =IF($E17="","",IFERROR(VLOOKUP($E17,Shifts!$A$5:$E$12,3,FALSE),0)) | AC17: =IF($F17="","",IFERROR(VLOOKUP($F17,Shifts!$A$5:$E$12,3,FALSE),0)) | AD17: =IF($G17="","",IFERROR(VLOOKUP($G17,Shifts!$A$5:$E$12,3,FALSE),0)) | AE17: =IF($H17="","",IFERROR(VLOOKUP($H17,Shifts!$A$5:$E$12,3,FALSE),0)) | AF17: =IF($B17="","",IFERROR(VLOOKUP($B17,Shifts!$A$5:$E$12,4,FALSE),0)) | AG17: =IF($C17="","",IFERROR(VLOOKUP($C17,Shifts!$A$5:$E$12,4,FALSE),0)) | AH17: =IF($D17="","",IFERROR(VLOOKUP($D17,Shifts!$A$5:$E$12,4,FALSE),0)) | AI17: =IF($E17="","",IFERROR(VLOOKUP($E17,Shifts!$A$5:$E$12,4,FALSE),0)) | AJ17: =IF($F17="","",IFERROR(VLOOKUP($F17,Shifts!$A$5:$E$12,4,FALSE),0)) | AK17: =IF($G17="","",IFERROR(VLOOKUP($G17,Shifts!$A$5:$E$12,4,FALSE),0)) | AL17: =IF($H17="","",IFERROR(VLOOKUP($H17,Shifts!$A$5:$E$12,4,FALSE),0)) | AM17: =IF(OR($R17="",$S17="",$R17=0,$S17=0),"",ROUND(IF($AF17<=$Y17,$Z17-$AF17,1-$AF17+$Z17)*24,2)) | AN17: =IF(OR($S17="",$T17="",$S17=0,$T17=0),"",ROUND(IF($AG17<=$Z17,$AA17-$AG17,1-$AG17+$AA17)*24,2)) | AO17: =IF(OR($T17="",$U17="",$T17=0,$U17=0),"",ROUND(IF($AH17<=$AA17,$AB17-$AH17,1-$AH17+$AB17)*24,2)) | AP17: =IF(OR($U17="",$V17="",$U17=0,$V17=0),"",ROUND(IF($AI17<=$AB17,$AC17-$AI17,1-$AI17+$AC17)*24,2)) | AQ17: =IF(OR($V17="",$W17="",$V17=0,$W17=0),"",ROUND(IF($AJ17<=$AC17,$AD17-$AJ17,1-$AJ17+$AD17)*24,2)) | AR17: =IF(OR($W17="",$X17="",$W17=0,$X17=0),"",ROUND(IF($AK17<=$AD17,$AE17-$AK17,1-$AK17+$AE17)*24,2))
... I35: =IF(COUNT($R35:$X35)=0,"",ROUND(SUM($R35:$X35),2)) | J35: 40 | K35: =IF(OR(IF($AM35="",Shifts!$B$3,$AM35)<Shifts!$B$3,IF($AN35="",Shifts!$B$3,$AN35)<Shifts!$B$3,IF($AO35="",Shifts!$B$3,$AO35)<Shifts!$B$3,IF($AP35="",Shifts!$B$3,$AP35)<Shifts!$B$3,IF($AQ35="",Shifts!$B$3,$AQ35)<Shifts!$B$3,IF($AR35="",Shifts!$B$3,$AR35)<Shifts!$B$3),"⛔ <"&Shifts!$B$3&" h","") | L35: =IF(7-(IF($R35="",0,IF($R35>0,1,0))+IF($S35="",0,IF($S35>0,1,0))+IF($T35="",0,IF($T35>0,1,0))+IF($U35="",0,IF($U35>0,1,0))+IF($V35="",0,IF($V35>0,1,0))+IF($W35="",0,IF($W35>0,1,0))+IF($X35="",0,IF($X35>0,1,0)))=0,"⛔ 0 days off",IF(7-(IF($R35="",0,IF($R35>0,1,0))+IF($S35="",0,IF($S35>0,1,0))+IF($T35="",0,IF($T35>0,1,0))+IF($U35="",0,IF($U35>0,1,0))+IF($V35="",0,IF($V35>0,1,0))+IF($W35="",0,IF($W35>0,1,0))+IF($X35="",0,IF($X35>0,1,0)))=1,"⚠ 6 days on: a 7th day in a row is premium pay in CA","")) | M35: =IF(OR($I35="",$J35=""),"",IF($I35>$J35,"⛔ +"&TEXT($I35-$J35,"0")&" h","")) | N35: =IF($O35="Y",IF(OR(IF($R35="",0,$R35)>8,IF($S35="",0,$S35)>8,IF($T35="",0,$T35)>8,IF($U35="",0,$U35)>8,IF($V35="",0,$V35)>8,IF($W35="",0,$W35)>8,IF($X35="",0,$X35)>8),"⛔ shift > 8 h (MINOR)",""),IF(OR(IF($R35="",0,$R35)>Shifts!$B$2,IF($S35="",0,$S35)>Shifts!$B$2,IF($T35="",0,$T35)>Shifts!$B$2,IF($U35="",0,$U35)>Shifts!$B$2,IF($V35="",0,$V35)>Shifts!$B$2,IF($W35="",0,$W35)>Shifts!$B$2,IF($X35="",0,$X35)>Shifts!$B$2),"⛔ shift > "&Shifts!$B$2&" h","")) | P35: =IF($O35<>"Y","",IF(OR($B35="N",$B35="DBL",$C35="N",$C35="DBL",$D35="N",$D35="DBL",$E35="N",$E35="DBL",$F35="N",$F35="DBL",$G35="N",$G35="DBL",$H35="N",$H35="DBL"),"⛔ MINOR: no night or double shifts (29 CFR 570.35)","⚠ minor: check federal and state hour limits")) | R35: =IF($B35="","",IFERROR(VLOOKUP($B35,Shifts!$A$5:$E$12,5,FALSE),0)) | S35: =IF($C35="","",IFERROR(VLOOKUP($C35,Shifts!$A$5:$E$12,5,FALSE),0)) | T35: =IF($D35="","",IFERROR(VLOOKUP($D35,Shifts!$A$5:$E$12,5,FALSE),0)) | U35: =IF($E35="","",IFERROR(VLOOKUP($E35,Shifts!$A$5:$E$12,5,FALSE),0)) | V35: =IF($F35="","",IFERROR(VLOOKUP($F35,Shifts!$A$5:$E$12,5,FALSE),0)) | W35: =IF($G35="","",IFERROR(VLOOKUP($G35,Shifts!$A$5:$E$12,5,FALSE),0)) | X35: =IF($H35="","",IFERROR(VLOOKUP($H35,Shifts!$A$5:$E$12,5,FALSE),0)) | Y35: =IF($B35="","",IFERROR(VLOOKUP($B35,Shifts!$A$5:$E$12,3,FALSE),0)) | Z35: =IF($C35="","",IFERROR(VLOOKUP($C35,Shifts!$A$5:$E$12,3,FALSE),0)) | AA35: =IF($D35="","",IFERROR(VLOOKUP($D35,Shifts!$A$5:$E$12,3,FALSE),0)) | AB35: =IF($E35="","",IFERROR(VLOOKUP($E35,Shifts!$A$5:$E$12,3,FALSE),0)) | AC35: =IF($F35="","",IFERROR(VLOOKUP($F35,Shifts!$A$5:$E$12,3,FALSE),0)) | AD35: =IF($G35="","",IFERROR(VLOOKUP($G35,Shifts!$A$5:$E$12,3,FALSE),0)) | AE35: =IF($H35="","",IFERROR(VLOOKUP($H35,Shifts!$A$5:$E$12,3,FALSE),0)) | AF35: =IF($B35="","",IFERROR(VLOOKUP($B35,Shifts!$A$5:$E$12,4,FALSE),0)) | AG35: =IF($C35="","",IFERROR(VLOOKUP($C35,Shifts!$A$5:$E$12,4,FALSE),0)) | AH35: =IF($D35="","",IFERROR(VLOOKUP($D35,Shifts!$A$5:$E$12,4,FALSE),0)) | AI35: =IF($E35="","",IFERROR(VLOOKUP($E35,Shifts!$A$5:$E$12,4,FALSE),0)) | AJ35: =IF($F35="","",IFERROR(VLOOKUP($F35,Shifts!$A$5:$E$12,4,FALSE),0)) | AK35: =IF($G35="","",IFERROR(VLOOKUP($G35,Shifts!$A$5:$E$12,4,FALSE),0)) | AL35: =IF($H35="","",IFERROR(VLOOKUP($H35,Shifts!$A$5:$E$12,4,FALSE),0)) | AM35: =IF(OR($R35="",$S35="",$R35=0,$S35=0),"",ROUND(IF($AF35<=$Y35,$Z35-$AF35,1-$AF35+$Z35)*24,2)) | AN35: =IF(OR($S35="",$T35="",$S35=0,$T35=0),"",ROUND(IF($AG35<=$Z35,$AA35-$AG35,1-$AG35+$AA35)*24,2)) | AO35: =IF(OR($T35="",$U35="",$T35=0,$U35=0),"",ROUND(IF($AH35<=$AA35,$AB35-$AH35,1-$AH35+$AB35)*24,2)) | AP35: =IF(OR($U35="",$V35="",$U35=0,$V35=0),"",ROUND(IF($AI35<=$AB35,$AC35-$AI35,1-$AI35+$AC35)*24,2)) | AQ35: =IF(OR($V35="",$W35="",$V35=0,$W35=0),"",ROUND(IF($AJ35<=$AC35,$AD35-$AJ35,1-$AJ35+$AD35)*24,2)) | AR35: =IF(OR($W35="",$X35="",$W35=0,$X35=0),"",ROUND(IF($AK35<=$AD35,$AE35-$AK35,1-$AK35+$AE35)*24,2))
A36: TOTAL TEAM HOURS | I36: =IF(COUNT($I$6:$I$35)=0,"",ROUND(SUM($I$6:$I$35),2)) | J36: Average per employee → | K36: =IF(COUNT($I$6:$I$35)=0,"",ROUND(AVERAGE($I$6:$I$35),2))
A38: © 2026 AI Chef Pro · aichef.pro

Sheet Monthly Schedule
A1: Monthly Schedule — Month: _______________
A2: AI Chef Pro · aichef.pro — Restaurant Staff Scheduling Kit Pro
A3: WEEK 1 | B3: AM=AM shift | C3: PM=PM shift | D3: N=Night | E3: SP=Split | F3: DBL=Double | G3: OFF=Day off | H3: V=Vacation/PTO | I3: S=Sick
A4: Employee | B4: Monday | C4: Tuesday | D4: Wednesday | E4: Thursday | F4: Friday | G4: Saturday | H4: Sunday | I4: Total Hours | J4: Weekly alert
A5: =IF('Weekly Schedule'!$A6="","",'Weekly Schedule'!$A6) | I5: =IF($A5="","",ROUND(IFERROR(VLOOKUP($B5,Shifts!$A$5:$E$12,5,FALSE),0)+IFERROR(VLOOKUP($C5,Shifts!$A$5:$E$12,5,FALSE),0)+IFERROR(VLOOKUP($D5,Shifts!$A$5:$E$12,5,FALSE),0)+IFERROR(VLOOKUP($E5,Shifts!$A$5:$E$12,5,FALSE),0)+IFERROR(VLOOKUP($F5,Shifts!$A$5:$E$12,5,FALSE),0)+IFERROR(VLOOKUP($G5,Shifts!$A$5:$E$12,5,FALSE),0)+IFERROR(VLOOKUP($H5,Shifts!$A$5:$E$12,5,FALSE),0),2)) | J5: =IF($A5="","",IF($I5>'Weekly Schedule'!$J6,"⛔ +"&TEXT($I5-'Weekly Schedule'!$J6,"0")&" h",""))
A6: =IF('Weekly Schedule'!$A7="","",'Weekly Schedule'!$A7) | I6: =IF($A6="","",ROUND(IFERROR(VLOOKUP($B6,Shifts!$A$5:$E$12,5,FALSE),0)+IFERROR(VLOOKUP($C6,Shifts!$A$5:$E$12,5,FALSE),0)+IFERROR(VLOOKUP($D6,Shifts!$A$5:$E$12,5,FALSE),0)+IFERROR(VLOOKUP($E6,Shifts!$A$5:$E$12,5,FALSE),0)+IFERROR(VLOOKUP($F6,Shifts!$A$5:$E$12,5,FALSE),0)+IFERROR(VLOOKUP($G6,Shifts!$A$5:$E$12,5,FALSE),0)+IFERROR(VLOOKUP($H6,Shifts!$A$5:$E$12,5,FALSE),0),2)) | J6: =IF($A6="","",IF($I6>'Weekly Schedule'!$J7,"⛔ +"&TEXT($I6-'Weekly Schedule'!$J7,"0")&" h",""))
A7: =IF('Weekly Schedule'!$A8="","",'Weekly Schedule'!$A8) | I7: =IF($A7="","",ROUND(IFERROR(VLOOKUP($B7,Shifts!$A$5:$E$12,5,FALSE),0)+IFERROR(VLOOKUP($C7,Shifts!$A$5:$E$12,5,FALSE),0)+IFERROR(VLOOKUP($D7,Shifts!$A$5:$E$12,5,FALSE),0)+IFERROR(VLOOKUP($E7,Shifts!$A$5:$E$12,5,FALSE),0)+IFERROR(VLOOKUP($F7,Shifts!$A$5:$E$12,5,FALSE),0)+IFERROR(VLOOKUP($G7,Shifts!$A$5:$E$12,5,FALSE),0)+IFERROR(VLOOKUP($H7,Shifts!$A$5:$E$12,5,FALSE),0),2)) | J7: =IF($A7="","",IF($I7>'Weekly Schedule'!$J8,"⛔ +"&TEXT($I7-'Weekly Schedule'!$J8,"0")&" h",""))
A8: =IF('Weekly Schedule'!$A9="","",'Weekly Schedule'!$A9) | I8: =IF($A8="","",ROUND(IFERROR(VLOOKUP($B8,Shifts!$A$5:$E$12,5,FALSE),0)+IFERROR(VLOOKUP($C8,Shifts!$A$5:$E$12,5,FALSE),0)+IFERROR(VLOOKUP($D8,Shifts!$A$5:$E$12,5,FALSE),0)+IFERROR(VLOOKUP($E8,Shifts!$A$5:$E$12,5,FALSE),0)+IFERROR(VLOOKUP($F8,Shifts!$A$5:$E$12,5,FALSE),0)+IFERROR(VLOOKUP($G8,Shifts!$A$5:$E$12,5,FALSE),0)+IFERROR(VLOOKUP($H8,Shifts!$A$5:$E$12,5,FALSE),0),2)) | J8: =IF($A8="","",IF($I8>'Weekly Schedule'!$J9,"⛔ +"&TEXT($I8-'Weekly Schedule'!$J9,"0")&" h",""))
A9: =IF('Weekly Schedule'!$A10="","",'Weekly Schedule'!$A10) | I9: =IF($A9="","",ROUND(IFERROR(VLOOKUP($B9,Shifts!$A$5:$E$12,5,FALSE),0)+IFERROR(VLOOKUP($C9,Shifts!$A$5:$E$12,5,FALSE),0)+IFERROR(VLOOKUP($D9,Shifts!$A$5:$E$12,5,FALSE),0)+IFERROR(VLOOKUP($E9,Shifts!$A$5:$E$12,5,FALSE),0)+IFERROR(VLOOKUP($F9,Shifts!$A$5:$E$12,5,FALSE),0)+IFERROR(VLOOKUP($G9,Shifts!$A$5:$E$12,5,FALSE),0)+IFERROR(VLOOKUP($H9,Shifts!$A$5:$E$12,5,FALSE),0),2)) | J9: =IF($A9="","",IF($I9>'Weekly Schedule'!$J10,"⛔ +"&TEXT($I9-'Weekly Schedule'!$J10,"0")&" h",""))
A10: =IF('Weekly Schedule'!$A11="","",'Weekly Schedule'!$A11) | I10: =IF($A10="","",ROUND(IFERROR(VLOOKUP($B10,Shifts!$A$5:$E$12,5,FALSE),0)+IFERROR(VLOOKUP($C10,Shifts!$A$5:$E$12,5,FALSE),0)+IFERROR(VLOOKUP($D10,Shifts!$A$5:$E$12,5,FALSE),0)+IFERROR(VLOOKUP($E10,Shifts!$A$5:$E$12,5,FALSE),0)+IFERROR(VLOOKUP($F10,Shifts!$A$5:$E$12,5,FALSE),0)+IFERROR(VLOOKUP($G10,Shifts!$A$5:$E$12,5,FALSE),0)+IFERROR(VLOOKUP($H10,Shifts!$A$5:$E$12,5,FALSE),0),2)) | J10: =IF($A10="","",IF($I10>'Weekly Schedule'!$J11,"⛔ +"&TEXT($I10-'Weekly Schedule'!$J11,"0")&" h",""))
A11: =IF('Weekly Schedule'!$A12="","",'Weekly Schedule'!$A12) | I11: =IF($A11="","",ROUND(IFERROR(VLOOKUP($B11,Shifts!$A$5:$E$12,5,FALSE),0)+IFERROR(VLOOKUP($C11,Shifts!$A$5:$E$12,5,FALSE),0)+IFERROR(VLOOKUP($D11,Shifts!$A$5:$E$12,5,FALSE),0)+IFERROR(VLOOKUP($E11,Shifts!$A$5:$E$12,5,FALSE),0)+IFERROR(VLOOKUP($F11,Shifts!$A$5:$E$12,5,FALSE),0)+IFERROR(VLOOKUP($G11,Shifts!$A$5:$E$12,5,FALSE),0)+IFERROR(VLOOKUP($H11,Shifts!$A$5:$E$12,5,FALSE),0),2)) | J11: =IF($A11="","",IF($I11>'Weekly Schedule'!$J12,"⛔ +"&TEXT($I11-'Weekly Schedule'!$J12,"0")&" h",""))
A12: =IF('Weekly Schedule'!$A13="","",'Weekly Schedule'!$A13) | I12: =IF($A12="","",ROUND(IFERROR(VLOOKUP($B12,Shifts!$A$5:$E$12,5,FALSE),0)+IFERROR(VLOOKUP($C12,Shifts!$A$5:$E$12,5,FALSE),0)+IFERROR(VLOOKUP($D12,Shifts!$A$5:$E$12,5,FALSE),0)+IFERROR(VLOOKUP($E12,Shifts!$A$5:$E$12,5,FALSE),0)+IFERROR(VLOOKUP($F12,Shifts!$A$5:$E$12,5,FALSE),0)+IFERROR(VLOOKUP($G12,Shifts!$A$5:$E$12,5,FALSE),0)+IFERROR(VLOOKUP($H12,Shifts!$A$5:$E$12,5,FALSE),0),2)) | J12: =IF($A12="","",IF($I12>'Weekly Schedule'!$J13,"⛔ +"&TEXT($I12-'Weekly Schedule'!$J13,"0")&" h",""))
