Workbook

Sheet Instructions
B2: BONUS: Restaurant Staffing Calculator
B4: How to use this template:
B5: ▸ Enter your business data in the green cells of the "Staffing Calculator" tab. Everything else is formulas.
B6: ▸ The concept is a drop-down with the ten formats on the "Ratios by Concept" tab: it supplies the three ratios and the two traffic-light thresholds.
B7: ▸ Compare the result with your current staff in the block at the end to spot overstaffing or understaffing.
B9: The calculation chain, in one line:
B10: ▸ Covers per day ÷ services = covers per SERVICE → ÷ each position's ratio = staff per service → × services = person-services per day → × paid hours per service × days open = hours per week → ÷ full-time hours per week × coverage factor = FTE.
B11: ▸ With the sample data (80 covers, 2 services, casual dining): 40 covers per service, 5 people per service, 10 person-services per day, 240 h a week and 7 full-time people.
B12: ▸ FTE means full-time contracts, not people per shift. In front of house, 2 are on at the same time.
B14: Why you enter the average check:
B15: ▸ Without it, the calculator can tell you to hire nineteen people without anything warning you that they eat up the whole till. With it, the sheet estimates your sales and puts the labor cost % next to the target for your concept.
B16: ▸ With the sample data: 72,800 in sales per month, 23,356.67 in labor cost and a ratio of 32.1%, within the 28-33% range of casual dining (verdict: EXCELLENT, below the 33% target).
... B27: Version 2.0 · October 2026 · aichef.pro/en/digital-products/restaurant-schedule-templates · info@aichef.pro

Sheet Staffing Calculator
A1: Optimal Staffing Calculator
A2: AI Chef Pro · aichef.pro — Restaurant Staff Scheduling Kit Pro
A4: YOUR BUSINESS DATA — edit only the green cells
A5: Expected covers / day: | B5: 80
A6: Services per day (lunch + dinner): | B6: 2
A7: Days open / week: | B7: 6
A8: Concept: | B8: Casual dining
A9: Average gross pay per pay period (team member, full-time): | B9: 1400
A10: Pay periods per year: | B10: 26
A11: Employer payroll taxes & insurance (%): | B11: 0.1
A12: Paid hours per person per service (the full shift is these hours × the number of services): | B12: 4
A13: Full-time hours (h/week): | B13: 40
A14: Coverage factor (PTO, sick leave and days off): | B14: 1.15
A15: Average check per cover, before sales tax: | B15: 35
A16: PEAK-day covers: | B16: 120
A18: RATIOS APPLIED — they come from the "Ratios by Concept" tab
A19: Covers per line cook per service: | B19: =IFERROR(VLOOKUP($B$8,'Ratios by Concept'!$A$5:$J$14,5,FALSE),0) -> 25 | C19: ← 0 = that concept has no such position
A20: Covers per server per service: | B20: =IFERROR(VLOOKUP($B$8,'Ratios by Concept'!$A$5:$J$14,6,FALSE),0) -> 22
A21: Covers per bartender per service: | B21: =IFERROR(VLOOKUP($B$8,'Ratios by Concept'!$A$5:$J$14,7,FALSE),0) -> 80
A23: FROM COVERS TO STAFFING
A24: Covers per SERVICE: | B24: =IFERROR(IF(OR($B$5="",$B$6="",$B$6=0),"",ROUND($B$5/$B$6,0)),"") -> 40 | C24: ← this is the figure that sizes the shift, not the day's total
B25: Kitchen | C25: FOH | D25: Bar | E25: Total / service
A26: Staff per SERVICE: | B26: =IFERROR(IF(OR($B$24="",$B$19="",$B$19=0),0,CEILING($B$24/$B$19,1)),0) -> 2 | C26: =IFERROR(IF(OR($B$24="",$B$20="",$B$20=0),0,CEILING($B$24/$B$20,1)),0) -> 2 | D26: =IFERROR(IF(OR($B$24="",$B$21="",$B$21=0),0,CEILING($B$24/$B$21,1)),0) -> 1 | E26: =IF($B$24="","",$B$26+$C$26+$D$26) -> 5
A27: Staff shifts per day (people × services): | B27: =IF(OR($E$26="",$B$6=""),"",$E$26*$B$6) -> 10
A28: Staff hours needed / week: | B28: =IF(OR($B$27="",$B$12="",$B$7=""),"",$B$27*$B$12*$B$7) -> 240
A29: Staff needed (FTE): | B29: =IFERROR(IF(OR($B$28="",$B$13="",$B$13=0),"",CEILING($B$28/$B$13*$B$14,1)),"") -> 7
A31: PEAK-DAY BOOST
A32: Covers per service on the peak day: | B32: =IFERROR(IF(OR($B$16="",$B$6="",$B$6=0),"",ROUND($B$16/$B$6,0)),"") -> 60
B33: Kitchen | C33: FOH | D33: Bar | E33: Total / service
A34: Staff per service that day: | B34: =IFERROR(IF(OR($B$32="",$B$19="",$B$19=0),0,CEILING($B$32/$B$19,1)),0) -> 3 | C34: =IFERROR(IF(OR($B$32="",$B$20="",$B$20=0),0,CEILING($B$32/$B$20,1)),0) -> 3 | D34: =IFERROR(IF(OR($B$32="",$B$21="",$B$21=0),0,CEILING($B$32/$B$21,1)),0) -> 1 | E34: =IF($B$32="","",$B$34+$C$34+$D$34) -> 7
A35: BOOST over a normal day (people per service): | B35: =IF(OR($E$34="",$E$26=""),"",MAX(0,$E$34-$E$26)) -> 2 | C35: ← a boost for THAT day, not fixed headcount
A37: LABOR COST AND CHECK AGAINST SALES
A38: Estimated team labor cost (per month): | B38: =IFERROR(IF(OR($B$29="",$B$9="",$B$10=""),"",ROUND($B$29*$B$9*$B$10/12*(1+$B$11),2)),"") -> 23356.67
A39: Estimated labor cost (per year): | B39: =IF($B$38="","",ROUND($B$38*12,2)) -> 280280.04 | C39: ← twelve months of the monthly cost, which already uses your pay periods per year
A40: Estimated sales for the month: | B40: =IFERROR(IF(OR($B$5="",$B$15="",$B$7=""),"",ROUND($B$5*$B$15*$B$7*52/12,2)),"") -> 72800
A41: LABOR COST RATIO: | B41: =IFERROR(IF(OR($B$38="",$B$40="",$B$40=0),"",ROUND($B$38/$B$40,4)),"") -> 0.3208 | C41: Target ratio for your concept: | D41: =IFERROR(VLOOKUP($B$8,'Ratios by Concept'!$A$5:$J$14,9,FALSE),0.33) -> 0.33
C42: Maximum acceptable for your concept: | D42: =IFERROR(VLOOKUP($B$8,'Ratios by Concept'!$A$5:$J$14,10,FALSE),0.35) -> 0.35
A43: Traffic light: | B43: =IF($B$41="","— enter your average check and pick your concept",IF($B$41<$D$41,"🟢 EXCELLENT (below your target)",IF($B$41<=$D$42,"🟡 WATCH (at the limit)","🔴 CORRECTIVE ACTION"))) -> 🟢 EXCELLENT (below your target)
A45: COMPARISON WITH YOUR CURRENT STAFF
A46: Current staff (full-time people):
...

Sheet Ratios by Concept
A1: Staffing Ratios by Concept
A2: AI Chef Pro · aichef.pro — Restaurant Staff Scheduling Kit Pro
A4: Concept | B4: Covers/cook per service (range) | C4: Covers/server per service (range) | D4: Covers/bartender per service (range) | E4: Kitchen: covers (no.) | F4: FOH: covers (no.) | G4: Bar: covers (no.) | H4: Labor Cost Ratio | I4: Target % (number) | J4: Acceptable % (number)
A5: Casual dining | B5: 22-28 | C5: 20-25 | D5: 70-90 | E5: 25 | F5: 22 | G5: 80 | H5: 28-33% | I5: 0.33 | J5: 0.35
A6: Fine dining | B6: 10-14 | C6: 8-12 | D6: 35-45 | E6: 12 | F6: 10 | G6: 40 | H6: 35-40% | I6: 0.4 | J6: 0.42
A7: Fast casual / QSR | B7: 40-50 | C7: 35-45 | D7: 90-110 | E7: 45 | F7: 40 | G7: 100 | H7: 25-28% | I7: 0.28 | J7: 0.3
A8: Café / brunch | B8: 30-40 | C8: 25-35 | D8: 50-70 | E8: 35 | F8: 30 | G8: 60 | H8: 28-32% | I8: 0.32 | J8: 0.35
A9: Bar / cocktail bar | B9: — | C9: 25-35 | D9: 30-40 | E9: 0 | F9: 30 | G9: 35 | H9: 25-30% | I9: 0.3 | J9: 0.33
A10: Pizzeria | B10: 26-34 | C10: 22-28 | D10: 80-100 | E10: 30 | F10: 25 | G10: 90 | H10: 26-30% | I10: 0.3 | J10: 0.32
A11: Ghost kitchen / delivery | B11: 35-45 | C11: — | D11: — | E11: 40 | F11: 0 | G11: 0 | H11: 22-28% | I11: 0.28 | J11: 0.3
A12: Hotel restaurant | B12: 18-24 | C12: 12-18 | D12: 45-55 | E12: 20 | F12: 15 | G12: 50 | H12: 35-42% | I12: 0.42 | J12: 0.44
A13: Catering & events | B13: 20-25 | C13: 12-18 | D13: 50-70 | E13: 22 | F13: 15 | G13: 60 | H13: 30-35% | I13: 0.35 | J13: 0.38
A14: Ice cream shop / bakery | B14: 35-45 | C14: 25-35 | D14: — | E14: 40 | F14: 30 | G14: 0 | H14: 25-30% | I14: 0.3 | J14: 0.32
A16: ▸ The three numbers are COVERS PER EMPLOYEE PER SERVICE, not per day: 80 covers a day over two services is 40 per service, and those 40 are what the shift is sized with.
A17: ▸ A 0 means that concept has no such position: a ghost kitchen has no dining room and a cocktail bar has no full-menu kitchen. The calculator does not ask for staff where the ratio is 0.
A18: ▸ The numeric columns are the ones the calculator reads via VLOOKUP; the ranges beside them are guidelines — adjust them to your menu, your service and your standards.
A19: ▸ In high season lower the ratio (more staff per cover) or raise the calculator's coverage factor to 1.20.
A20: ▸ "Target %" and "Acceptable %" are the same thresholds the traffic light in file 03 "Restaurant Labor Cost Calculator" uses for all ten concepts: the two files cannot contradict each other on the same ratio.
A21: ▸ The labor cost ratio includes employer payroll taxes & insurance, which in the calculator is a green cell (10% by default), not a hidden rate buried in the formula.
A23: © 2026 AI Chef Pro · aichef.pro
