Workbook

Sheet Calculadora
A1: CALCULADORA DE PRECIOS DE PARRILLADA Y ASADO PARA EVENTOS — DE LA CARNE AL PRESUPUESTO
A2: Escribe sólo en las celdas VERDES: todo lo demás se calcula. Importes sin IVA salvo donde la fila diga lo contrario. Los valores por defecto son estimaciones del kit: cámbialos por los tuyos.
A4: DATOS DEL EVENTO | B4: Valor | C4: Notas
A5: Cliente | B5: Particular | C5: Particular, Empresa o Ayuntamiento: cambian el margen objetivo, el cobro y los tramos de cancelación (tabla del final). Las comisiones de fiestas y las peñas cuentan como Empresa.
A6: Invitados previstos | B6: 100 | C6: Número entero de invitados a los que sirves.
A7: Formato del servicio | B7: Asado completo | C7: Fija los gramos de carne cruda por invitado con la tabla del final. No cambia el precio: la materia prima de la experiencia ya trae su carta habitual.
A8: Experiencia | B8: 01 Asado argentino | C8: Las 10 experiencias del kit y la chuletada de fiesta: fijan la materia prima por invitado con la tabla del final.
A9: Estilo de servicio | B9: Cortes en mesa | C9: Buffet: un parrillero por cada 60-80 invitados. Cortes en mesa: uno por cada 40-50.
A10: Bebida por invitado (coste) | B10: 4 | C10: Cerveza, refrescos y vino que pones tú. 0 si la bebida la pone el cliente.
A11: Coste de menaje, desechables y consumibles por invitado | B11: 0.6 | C11: Estimación del kit: platos y cubiertos compostables, aluminio, pan y hielo. Pon 0 si el cliente pone el menaje.
A12: Horas por persona (carga, viaje, montaje, brasa, servicio y recogida) | B12: 9 | C12: Estimación del kit: pon las horas reales de tu equipo.
A13: Coste bruto por hora del personal | B13: 13 | C13: Estimación del kit. Copia tu convenio provincial de hostelería.
A14: Seguridad Social a cargo de la empresa | B14: 0.33 | C14: 30,65 % de contingencias, desempleo, FOGASA, formación y MEI, más AT/EP (fijos discontinuos, art. 16 ET).
A15: Importe de alquileres repercutidos (carpa, mesas, sillas, parrilla extra) | B15: 400 | C15: Lo que te cobra el alquilador para este evento. Si lo facturas aparte sin ser accesorio, ese importe va al 21 % de IVA.
A16: Kilómetros de ida (cocina de apoyo → espacio) | B16: 35 | C16: Se cobran ida y vuelta, en una línea aparte.
A17: Tarifa por kilómetro de desplazamiento | B17: 0.95 | C17: La del contrato del kit: se cobra ida y vuelta y va sin margen.
A18: Importe del suplemento de show de fuego por invitado | B18: 0 | C18: De 8 a 15 € por invitado si abres con provoletas y chorizos flambeados a la vista (experiencia 09). 0 si no hay show. Se suma al precio sin margen objetivo: cubre su materia prima extra y el tiempo del parrillero.
A19: IVA del servicio de comidas | B19: 0.1 | C19: Ley 37/1992, art. 91.Uno.2.2.º: comida y bebida para consumir en el acto, alcohol incluido. Lo que facturas aparte sin ser accesorio (carpa, mobiliario) va al 21 %.
A21: CÁLCULO | B21: Valor | C21: Notas
A22: Carne cruda por invitado (g, de la tabla) | B22: =INDEX('Calculadora'!$B$72:$B$75,MATCH($B$7,'Calculadora'!$A$72:$A$75,0)) -> 500 | C22: Busca el formato en la tabla del final.
A23: Coste de materia prima por invitado de la experiencia (tabla) | B23: =INDEX('Calculadora'!$B$78:$B$88,MATCH($B$8,'Calculadora'!$A$78:$A$88,0)) -> 9.5 | C23: Busca la experiencia en la tabla del final. Cámbiala si tu escandallo es otro.
A24: Invitados por parrillero (del estilo de servicio) | B24: =INDEX('Calculadora'!$B$67:$B$69,MATCH($B$9,'Calculadora'!$A$67:$A$69,0)) -> 45
A25: Invitados por ayudante (del estilo de servicio) | B25: =INDEX('Calculadora'!$C$67:$C$69,MATCH($B$9,'Calculadora'!$A$67:$A$69,0)) -> 50
A26: Margen objetivo del cliente elegido | B26: =INDEX('Calculadora'!$B$91:$D$91,MATCH($B$5,'Calculadora'!$B$90:$D$90,0)) -> 0.42 | C26: De la tabla por cliente del final.
A27: Carne cruda total (kg) | B27: =$B$6*$B$22/1000 -> 50 | C27: Invitados × gramos por invitado.
A28: Carne servida total (kg) | B28: =$B$27*(1-'Calculadora'!$B$63) -> 35 | C28: Carne cruda menos la merma de cocción.
A29: Parrillas necesarias | B29: =MAX(1,ROUNDUP($B$27/'Calculadora'!$B$60,0)) -> 2 | C29: Carne cruda entre lo que asa una parrilla de 120 × 60 cm, hacia arriba. Si no las tienes, alquílalas.
A30: Parrilleros necesarios | B30: =MAX(1,ROUNDUP($B$6/$B$24,0)) -> 3 | C30: Invitados entre invitados por parrillero, hacia arriba.
A31: Ayudantes necesarios | B31: =IF($B$6<'Calculadora'!$B$64,0,ROUNDUP($B$6/$B$25,0)) -> 2 | C31: Desde el mínimo de invitados de la tabla; el resto, invitados entre invitados por ayudante, hacia arriba.
A32: Carbón total (kg) | B32: =$B$27*'Calculadora'!$B$61 -> 40 | C32: Kg de carne cruda × kg de carbón por kg de carne.
A33: Coste de materia prima | B33: =$B$23*$B$6 -> 950
A34: Coste de bebida | B34: =$B$10*$B$6 -> 400
A35: Coste de menaje, desechables y consumibles | B35: =$B$11*$B$6 -> 60
A36: Coste del carbón | B36: =$B$32*'Calculadora'!$B$62 -> 60
A37: Coste de personal (salario + Seguridad Social) | B37: =($B$30+$B$31)*$B$12*$B$13*(1+$B$14) -> 778.05 | C37: Parrilleros y ayudantes. Si el dueño cocina, se cuenta a precio de hora: es su coste de oportunidad.
A38: Importe de alquileres | B38: =$B$15 -> 400
A39: Coste directo total | B39: =$B$33+$B$34+$B$35+$B$36+$B$37+$B$38 -> 2648.05
A40: Coste directo por invitado | B40: =$B$39/$B$6 -> 26.4805
A41: PRECIO POR INVITADO SIN IVA | B41: =ROUNDUP($B$39/(1-$B$26)/$B$6*2,0)/2+$B$18 -> 46 | C41: Coste ÷ (1 − margen) ÷ invitados, redondeado a los 0,50 € de arriba, más el suplemento de show. Es el precio de las empresas («+ IVA»).
A42: PRECIO POR INVITADO CON IVA | B42: =$B$41*(1+$B$19) -> 50.6 | C42: Es el que ve un particular: en una oferta a consumidores el precio va con impuestos incluidos.
...

Sheet Ejemplos
A1: 3 PRESUPUESTOS DE EJEMPLO — con las mismas fórmulas de la hoja «Calculadora»
A2: Estimaciones del kit para ilustrar el cálculo, no precios de mercado: cambia los datos en «Calculadora» para presupuestar tus eventos. Las tablas (margen y cobro por cliente, materia prima, escalado) están al final de esa hoja y también mueven estos ejemplos.
A4: DATOS DEL EVENTO | B4: Boda particular con show de fuego | C4: Team building de empresa con BBQ texano | D4: Fiesta o feria municipal de volumen
A5: Cliente | B5: Particular | C5: Empresa | D5: Ayuntamiento
A6: Invitados previstos | B6: 110 | C6: 70 | D6: 300
A7: Formato del servicio | B7: Asado completo | C7: Plato principal | D7: Chuletada de fiesta
A8: Experiencia | B8: 01 Asado argentino | C8: 04 BBQ texano | D8: 11 Chuletada o costillada de fiesta
A9: Estilo de servicio | B9: Cortes en mesa | C9: Buffet | D9: Fiesta de volumen
A10: Bebida por invitado (coste) | B10: 4 | C10: 3 | D10: 0
A11: Coste de menaje, desechables y consumibles por invitado | B11: 0.6 | C11: 0.6 | D11: 0.4
A12: Horas por persona (carga, viaje, montaje, brasa, servicio y recogida) | B12: 9 | C12: 8 | D12: 9
A13: Coste bruto por hora del personal | B13: 13 | C13: 13 | D13: 13
A14: Seguridad Social a cargo de la empresa | B14: 0.33 | C14: 0.33 | D14: 0.33
A15: Importe de alquileres repercutidos (carpa, mesas, sillas, parrilla extra) | B15: 0 | C15: 0 | D15: 0
A16: Kilómetros de ida (cocina de apoyo → espacio) | B16: 35 | C16: 25 | D16: 30
A17: Tarifa por kilómetro de desplazamiento | B17: 0.95 | C17: 0.95 | D17: 0.95
A18: Importe del suplemento de show de fuego por invitado | B18: 2 | C18: 0 | D18: 0
A19: IVA del servicio de comidas | B19: 0.1 | C19: 0.1 | D19: 0.1
A21: RESULTADO | B21: Boda particular con show de fuego | C21: Team building de empresa con BBQ texano | D21: Fiesta o feria municipal de volumen
A22: Carne cruda por invitado (g, de la tabla) | B22: =INDEX('Calculadora'!$B$72:$B$75,MATCH($B$7,'Calculadora'!$A$72:$A$75,0)) -> 500 | C22: =INDEX('Calculadora'!$B$72:$B$75,MATCH($C$7,'Calculadora'!$A$72:$A$75,0)) -> 400 | D22: =INDEX('Calculadora'!$B$72:$B$75,MATCH($D$7,'Calculadora'!$A$72:$A$75,0)) -> 300
A23: Coste de materia prima por invitado de la experiencia (tabla) | B23: =INDEX('Calculadora'!$B$78:$B$88,MATCH($B$8,'Calculadora'!$A$78:$A$88,0)) -> 9.5 | C23: =INDEX('Calculadora'!$B$78:$B$88,MATCH($C$8,'Calculadora'!$A$78:$A$88,0)) -> 8 | D23: =INDEX('Calculadora'!$B$78:$B$88,MATCH($D$8,'Calculadora'!$A$78:$A$88,0)) -> 2.5
A24: Invitados por parrillero (del estilo de servicio) | B24: =INDEX('Calculadora'!$B$67:$B$69,MATCH($B$9,'Calculadora'!$A$67:$A$69,0)) -> 45 | C24: =INDEX('Calculadora'!$B$67:$B$69,MATCH($C$9,'Calculadora'!$A$67:$A$69,0)) -> 70 | D24: =INDEX('Calculadora'!$B$67:$B$69,MATCH($D$9,'Calculadora'!$A$67:$A$69,0)) -> 150
A25: Invitados por ayudante (del estilo de servicio) | B25: =INDEX('Calculadora'!$C$67:$C$69,MATCH($B$9,'Calculadora'!$A$67:$A$69,0)) -> 50 | C25: =INDEX('Calculadora'!$C$67:$C$69,MATCH($C$9,'Calculadora'!$A$67:$A$69,0)) -> 60 | D25: =INDEX('Calculadora'!$C$67:$C$69,MATCH($D$9,'Calculadora'!$A$67:$A$69,0)) -> 100
A26: Margen objetivo del cliente elegido | B26: =INDEX('Calculadora'!$B$91:$D$91,MATCH($B$5,'Calculadora'!$B$90:$D$90,0)) -> 0.42 | C26: =INDEX('Calculadora'!$B$91:$D$91,MATCH($C$5,'Calculadora'!$B$90:$D$90,0)) -> 0.4 | D26: =INDEX('Calculadora'!$B$91:$D$91,MATCH($D$5,'Calculadora'!$B$90:$D$90,0)) -> 0.4
A27: Carne cruda total (kg) | B27: =$B$6*$B$22/1000 -> 55 | C27: =$C$6*$C$22/1000 -> 28 | D27: =$D$6*$D$22/1000 -> 90
A28: Carne servida total (kg) | B28: =$B$27*(1-'Calculadora'!$B$63) -> 38.5 | C28: =$C$27*(1-'Calculadora'!$B$63) -> 19.6 | D28: =$D$27*(1-'Calculadora'!$B$63) -> 63
A29: Parrillas necesarias | B29: =MAX(1,ROUNDUP($B$27/'Calculadora'!$B$60,0)) -> 2 | C29: =MAX(1,ROUNDUP($C$27/'Calculadora'!$B$60,0)) -> 1 | D29: =MAX(1,ROUNDUP($D$27/'Calculadora'!$B$60,0)) -> 3
A30: Parrilleros necesarios | B30: =MAX(1,ROUNDUP($B$6/$B$24,0)) -> 3 | C30: =MAX(1,ROUNDUP($C$6/$C$24,0)) -> 1 | D30: =MAX(1,ROUNDUP($D$6/$D$24,0)) -> 2
A31: Ayudantes necesarios | B31: =IF($B$6<'Calculadora'!$B$64,0,ROUNDUP($B$6/$B$25,0)) -> 3 | C31: =IF($C$6<'Calculadora'!$B$64,0,ROUNDUP($C$6/$C$25,0)) -> 2 | D31: =IF($D$6<'Calculadora'!$B$64,0,ROUNDUP($D$6/$D$25,0)) -> 3
A32: Carbón total (kg) | B32: =$B$27*'Calculadora'!$B$61 -> 44 | C32: =$C$27*'Calculadora'!$B$61 -> 22.4 | D32: =$D$27*'Calculadora'!$B$61 -> 72
A33: Coste de materia prima | B33: =$B$23*$B$6 -> 1045 | C33: =$C$23*$C$6 -> 560 | D33: =$D$23*$D$6 -> 750
A34: Coste de bebida | B34: =$B$10*$B$6 -> 440 | C34: =$C$10*$C$6 -> 210 | D34: =$D$10*$D$6 -> 0
A35: Coste de menaje, desechables y consumibles | B35: =$B$11*$B$6 -> 66 | C35: =$C$11*$C$6 -> 42 | D35: =$D$11*$D$6 -> 120
A36: Coste del carbón | B36: =$B$32*'Calculadora'!$B$62 -> 66 | C36: =$C$32*'Calculadora'!$B$62 -> 33.6 | D36: =$D$32*'Calculadora'!$B$62 -> 108
A37: Coste de personal (salario + Seguridad Social) | B37: =($B$30+$B$31)*$B$12*$B$13*(1+$B$14) -> 933.66 | C37: =($C$30+$C$31)*$C$12*$C$13*(1+$C$14) -> 414.96 | D37: =($D$30+$D$31)*$D$12*$D$13*(1+$D$14) -> 778.05
A38: Importe de alquileres | B38: =$B$15 -> 0 | C38: =$C$15 -> 0 | D38: =$D$15 -> 0
A39: Coste directo total | B39: =$B$33+$B$34+$B$35+$B$36+$B$37+$B$38 -> 2550.66 | C39: =$C$33+$C$34+$C$35+$C$36+$C$37+$C$38 -> 1260.56 | D39: =$D$33+$D$34+$D$35+$D$36+$D$37+$D$38 -> 1756.05
A40: Coste directo por invitado | B40: =$B$39/$B$6 -> 23.187818 | C40: =$C$39/$C$6 -> 18.008 | D40: =$D$39/$D$6 -> 5.8535
A41: PRECIO POR INVITADO SIN IVA | B41: =ROUNDUP($B$39/(1-$B$26)/$B$6*2,0)/2+$B$18 -> 42 | C41: =ROUNDUP($C$39/(1-$C$26)/$C$6*2,0)/2+$C$18 -> 30.5 | D41: =ROUNDUP($D$39/(1-$D$26)/$D$6*2,0)/2+$D$18 -> 10
A42: PRECIO POR INVITADO CON IVA | B42: =$B$41*(1+$B$19) -> 46.2 | C42: =$C$41*(1+$C$19) -> 33.55 | D42: =$D$41*(1+$D$19) -> 11
...

Sheet Instrucciones
A1: INSTRUCCIONES DE USO — Calculadora de precios de parrillada y asado para eventos
A2: Convierte tu escandallo en un precio por invitado y en un presupuesto completo: kilos de carne, parrillas, parrilleros, ayudantes y carbón, subtotal, IVA, total, cobro por pagos y lo que retienes si el cliente cancela. Sólo se escribe en las celdas VERDES; el margen se calcula.
A3: 1. Elige el cliente (Particular, Empresa o Ayuntamiento; las comisiones de fiestas y las peñas cuentan como Empresa), los invitados, el formato del servicio, la experiencia y el estilo de servicio.
A4: 2. La tabla de escalado y las demás tablas del final de la primera hoja dan los gramos de carne cruda por invitado, la materia prima de la experiencia y los invitados por parrillero y por ayudante. Las parrillas salen de dividir los kilos de carne cruda entre lo que asa una parrilla; los parrilleros, de dividir los invitados entre los que atiende cada uno.
A5: 3. Escribe la bebida que pones tú (0 si la pone el cliente) y el menaje y los consumibles por invitado. El carbón se calcula con los kilos de carne.
A6: 4. Escribe las horas por persona, el coste bruto por hora y la Seguridad Social. Si cocinas tú, cuéntate a precio de hora: es tu coste de oportunidad.
A7: 5. Escribe los alquileres que repercutes y los kilómetros de ida: el desplazamiento se cobra ida y vuelta, en una línea aparte y sin margen.
A8: 6. El margen objetivo de cada cliente está en la tabla «Política por cliente» del final: cámbialo ahí. El precio por invitado es el coste directo dividido entre (1 − margen), redondeado a los 0,50 € de arriba, más el suplemento de show de fuego si lo hay: el margen calculado queda igual o por encima del objetivo.
A9: 7. A una empresa se le presupuesta el precio SIN IVA («+ IVA»); a un particular, el precio CON IVA, porque en una oferta a consumidores el precio va con los impuestos incluidos.
A10: IVA, PROPINAS Y COBROS
A12: El servicio de comidas para consumir en el acto va al 10 % de IVA, bebida y alcohol incluidos (Ley 37/1992, art. 91.Uno.2.2.º). Lo que facturas aparte sin ser accesorio, como la carpa o el mobiliario, va al 21 %. En las facturas a empresas no se practica retención de IRPF por esta actividad.
A13: La propina voluntaria es decisión del cliente y es del equipo: no entra en el precio, en la base imponible ni en el total.
... A29: Versión 2.2 · septiembre 2026 · aichef.pro/plan-negocio-parrillero-asador-eventos · info@aichef.pro
