Workbook

Sheet 0. Supuestos
A1: SUPUESTOS — aquí se teclean las TASAS y los DRIVERS del modelo
A2: Cambia las celdas VERDES: el resto del libro se recalcula solo. Las partidas de gasto se teclean en su hoja (también en verde) y no se repiten aquí.
A3: ACTIVIDAD
A4: Invitados por evento (media del año 1) | B4: 80 | C4: Invitados de media por evento en el año 1. Sale de la mezcla de cuatro tipos de evento de la tabla de referencias de la hoja de Instrucciones: bodas de 110, eventos de empresa de 70, celebraciones privadas de 40 y fiestas o ferias de 300
A5: Precio medio por invitado SIN IVA (€) | B5: 25 | C5: SIN IVA, por invitado. Media ponderada de la misma mezcla: 42 € la boda (entrantes, tres o cuatro cortes con vacuno madurado, guarniciones y postre a la brasa), 31 € el evento de empresa, 25 € la celebración privada y 10 € la chuletada o costillada de una fiesta. Por eso la media baja: no es el precio de una boda. El precio con IVA (10 % en un servicio de comidas) está en la fila «PVP equivalente con IVA» de abajo
A6: Eventos al año | B6: 95 | C6: Eventos servidos en el año: 12 bodas, 30 de empresa (comidas, team building, show cooking y Navidad), 45 celebraciones privadas (cumpleaños, comuniones, peñas, urbanizaciones) y 8 fiestas o ferias por encargo. Es el MISMO dato para la cuenta de resultados, el punto de equilibrio, los escenarios y las horas de personal
A7: Crecimiento de volumen del año 2 | B7: 0.08 | C7: Más volumen el segundo año: empresas que repiten, bodas que llegan por recomendación y planners que ya te conocen. El libro lo aplica a los invitados por evento con los mismos eventos; en euros da lo mismo que hacer más eventos del mismo tamaño
A8: Crecimiento de volumen del año 3 | B8: 0.05 | C8: Sobre el año 2. Conservador: el techo lo ponen los fines de semana de temporada y un solo parrillero titular
A9: PVP equivalente con IVA (calculado) | B9: =IFERROR(IF($B$5="","",$B$5*(1+SUMPRODUCT('PyG 3 Años'!$E$10:$E$11,'PyG 3 Años'!$G$10:$G$11))),"") -> 27.5099 | C9: =IFERROR("Precio por invitado sin IVA más el IVA medio ponderado de tus líneas de venta: "&TEXT(SUMPRODUCT('PyG 3 Años'!$E$10:$E$11,'PyG 3 Años'!$G$10:$G$11)*100,"0")&" %. En el servicio de parrilla todo va al 10 % (art. 91.Uno.2.2.º de la Ley 37/1992, alcohol incluido); el alcohol que sale en el asado para llevar mueve la media. Aquí va redondeado. Compáralo con el rango del sector, que va con IVA.","") -> Precio por invitado sin IVA más el IVA medio ponderado de tus líneas de venta: 10 %. En el servicio de parrilla todo va al 10 % (art. 91.Uno.2.2.º de la Ley 37/1992, alcohol incluido); el alcohol que sale en el asado para llevar mueve la media. Aquí va redondeado. Compáralo con el rango del sector, que va con IVA.
A10: MIX Y COSTE DE MERCANCÍA
A11: Ventas de COMIDA sobre el total | B11: 0.88 | C11: Peso de la COMIDA sobre el total de ventas. Es un INPUT: cámbialo aquí y el P&L, la tesorería y el IVA repercutido se recalculan solos
A12: Ventas de BEBIDA sobre el total | B12: =IFERROR(IF(COUNT(B11)=0,"",1-B11),"") -> 0.12 | C12: Se calcula como el resto: comida + bebida = 100 %
A13: Coste de mercancía sobre las ventas de COMIDA | B13: 0.32 | C13: Materia prima de la comida sobre las ventas de comida: carne (350-450 g crudos por invitado con entrantes), achuras y embutido, verdura, pan, salsas y postre. El escandallo de la mezcla sale al 29,8 %; el plan suma dos puntos por la volatilidad del vacuno y las compras de seguridad. Escandalla cada evento con la calculadora de este kit
A14: Coste de mercancía sobre las ventas de BEBIDA | B14: 0.3 | C14: Bebida sobre las ventas de bebida: cerveza, refrescos, agua y vino del pack. Si el cliente pone la bebida, esta línea baja
A15: Consumibles sobre ventas | B15: 0.045 | C15: Carbón, leña, pastillas de encendido, gas del plan B, papel de aluminio, desechables compostables y hielo: algo más de 1 € por invitado. Se gastan 0,7-1 kg de carbón por kg de carne cruda, y el carbón cuesta de 1,3 a 2 € el kilo
A16: Ventas de asado para llevar (sin servicio) sobre el total | B16: 0.05 | C16: Parte de las ventas que se entrega SIN servicio: asado para llevar en bandejas (cordero, cochinillo, costillar), sin parrillero en el evento. Es entrega de bienes: la comida va al 10 % y el alcohol y los refrescos, zumos y gaseosas con azúcares o edulcorantes añadidos, al 21 % (art. 91.Uno.1.1.º de la Ley 37/1992); el libro lo aplica al alcohol de esta parte
A17: Comisión de la plataforma de pedidos | B17: 0.1 | C17: Comisión media de la parte del asado para llevar que entra por plataformas de pedidos o intermediarios. Si todos los pedidos los vendes tú, pon 0
A18: Comisión de los medios de pago | B18: 0.005 | C18: Casi todo se cobra por transferencia (señales y facturas de empresas y ayuntamientos); el datáfono queda para los cobros del día del evento
A19: PERSONAL
A20: Seguridad Social a cargo de la empresa | B20: 0.33 | C20: Contingencias comunes + AT/EP + desempleo + FOGASA + FP; ajusta a tu convenio y bonificaciones
A21: Número de pagas anuales | B21: 14 | C21: Salario bruto anual = bruto mensual × pagas
A22: SMI anual de referencia (€) | B22: 17094 | C22: SMI 2026: 17.094 € al año (1.221 €/mes en 14 pagas), suelo legal por jornada completa. Comprueba el importe vigente si presentas el plan en otro ejercicio
A23: COCINA DE APOYO Y FIJOS
A24: Cuota mensual de la cocina de apoyo (€) | B24: 1000 | C24: Cuota de una cocina de apoyo compartida y autorizada: unas 30 horas al mes de marinados, salmueras y porcionado, cámara para la carne y almacén de parrillas, carbón y remolque. La carne se asa en el evento, pero lo que se prepara antes no se puede hacer en casa (art. 13.5.b del RD 1021/2022). No hay tarifa pública: pide dos presupuestos en tu zona
A25: Fianza de la cocina de apoyo (meses) | B25: 2 | C25: Dos cuotas de fianza, lo habitual en un contrato de uso de cocina compartida
A26: Suministros mensuales (consumos propios fuera de la cuota) (€) | B26: 50 | C26: Consumos propios fuera de la cuota de la cocina (datos móviles, luz del almacén). El carbón y el gas van en los consumibles, porque suben y bajan con los eventos
A27: Seguros (€/año) | B27: 1950 | C27: Responsabilidad civil de explotación con incendio (brasas y chispas sobre carpas, césped y pavimento) y de producto con intoxicación alimentaria de al menos 600.000 € (unos 750 €); seguro de la furgoneta de uso comercial (900 €), del remolque (150 €) y de los equipos que salen a cada evento (150 €). La cancelación por una prohibición de fuego no se asegura: va en la cláusula de fuerza mayor del contrato, con el plan B de gas
A28: Varios e imprevistos sobre ventas | B28: 0.05 | C28: Combustible de la furgoneta y del remolque (2 puntos), imprevistos (1,5 puntos) y el canon que algunas fincas y wedding planners cobran al proveedor externo (1,5 puntos). Es variable: sube y baja con los eventos
A29: FINANCIACIÓN
A30: Recursos propios aportados (€) | B30: 22000 | C30: Aportación del socio. Un banco pide entre el 25 y el 30 % de la necesidad de caja con dinero propio
A31: Préstamo bancario solicitado (€) | B31: 65400 | C31: Principal solicitado. La hoja de Financiación compara lo que aportas con la necesidad de caja de la hoja de inversión y te dice si sobra o falta: ajústalo con ese dato
A32: Tipo de interés nominal anual | B32: 0.065 | C32: Tipo nominal anual de un préstamo de empresa sin garantía inmobiliaria. Pide oferta a dos entidades y a una línea ICO o ENISA antes de fijarlo
A33: Plazo del préstamo (años) | B33: 6 | C33: Años totales, carencia incluida: el plazo de vida de la furgoneta y del equipo
A34: Carencia de principal (años) | B34: 1 | C34: El primer año sólo intereses: es cuando la caja está más tensa, con la agenda de bodas y empresas aún por llenar. Desde el segundo año se devuelve el principal: mira la holgura de caja de ese año en el Punto de Equilibrio
A35: Fondo de maniobra (meses de costes fijos) | B35: 3 | C35: Tres meses de costes fijos: cubren el invierno (enero, febrero y noviembre son los meses más bajos del año) y los 30 días que tardan en pagar empresas y ayuntamientos
A36: FISCAL
A37: Impuesto de Sociedades, nueva creación | B37: 0.15 | C37: Art. 29.1 LIS: el PRIMER ejercicio con base imponible positiva y el SIGUIENTE. El libro lo aproxima contando los dos primeros ejercicios con base positiva: coincide con la ley salvo que entre ellos haya un ejercicio en pérdidas
A38: Impuesto de Sociedades, tipo general | B38: 0.25 | C38: A partir del tercer ejercicio con base positiva. Es el tipo general del art. 29.1 LIS: si tu cifra de negocios queda por debajo de 1 M € (microempresa) o de 10 M € (reducida dimensión), desde 2025 hay tipos más bajos que se implantan de forma gradual; confirma el de tu ejercicio con tu asesor y cámbialo aquí
A39: IVA repercutido de restauración | B39: 0.1 | C39: Tipo reducido de hostelería
A40: IVA repercutido/soportado general | B40: 0.21 | C40: Tipo general. En este libro lo usan dos cosas: el IVA que soportas al comprar el alcohol (el proveedor lo factura al 21 %) y el que repercutes por el alcohol que sale por asado para llevar (es una entrega de bienes). El alcohol servido en el servicio de parrilla va al reducido: su tipo está en el bloque de desglose del IVA. Suministros, equipamiento y servicios tienen su tipo en la celda de abajo. El libro manda al general sólo el alcohol: si compras refrescos, zumos y gaseosas con azúcares o edulcorantes añadidos, su factura también va al 21 % (art. 91.Uno.1.1.º de la Ley 37/1992)
...

Sheet Inversión Inicial
A1: PLAN DE NEGOCIO: PARRILLERO / ASADOR PARA EVENTOS
A2: Inversión inicial estimada — parrilla y asado en directo para eventos
A3: Ajusta las cifras a tu proyecto.
A5: Concepto | B5: Importe | C5: % s/inversión | D5: Notas | E5: ¿Lleva IVA?
A6: INVERSIÓN | B6: =IFERROR(IF(COUNT(B7:B23)=0,"",SUM(B7:B23)),"") -> 54596 | C6: =IFERROR(B6/$B$26,"") -> 0.71346877
A7: Furgoneta frigorífica usada con certificado ATP | B7: 20000 | C7: =IFERROR(B7/$B$26,"") -> 0.26136302 | D7: Furgoneta usada con caja frigorífica y certificado ATP vigente (RD 237/2000) para llevar la carne a 7 °C o menos. Estimación del kit (18.000-21.950 € en el mercado de ocasión) | E7: Sí
A8: Rotulación, estanterías y anclajes | B8: 1200 | C8: =IFERROR(B8/$B$26,"") -> 0.015681781 | D8: Rotulación con la marca, estanterías con amarres y anclajes para llevar en pie y sujetas las botellas de gas y los sacos de carbón | E8: Sí
A9: Remolque-parrilla homologado con cruz | B9: 7000 | C9: =IFERROR(B9/$B$26,"") -> 0.091477057 | D9: Remolque de hasta 750 kg con parrilla y soporte de cruz: la pieza de las bodas y las fiestas. Estimación del kit (6.000-9.000 €); no hay precio público de referencia | E9: Sí
A10: Parrillas móviles inox de 120 cm y brasero | B10: 3200 | C10: =IFERROR(B10/$B$26,"") -> 0.041818083 | D10: Dos parrillas móviles de carbón y leña de 120 cm (cada una sirve 60-80 invitados en dos o tres tandas) y un brasero para tener brasa de reserva | E10: Sí
A11: Cruces, kit de costillar y ahumador pequeño | B11: 1800 | C11: =IFERROR(B11/$B$26,"") -> 0.023522672 | D11: Cuatro cruces para cordero o cochinillo, el kit de costillar y un ahumador offset pequeño para el BBQ texano | E11: Sí
A12: Plan B de gas y seguridad contra incendios | B12: 2200 | C12: =IFERROR(B12/$B$26,"") -> 0.028749932 | D12: Plancha o parrilla de piedra volcánica de gas con sus botellas y reguladores (una botella de menos de 15 kg por aparato), tres extintores ABC y uno de CO2, mantas ignífugas, contenedor metálico de cenizas y EPI térmicos | E12: Sí
A13: Frío: armario refrigerado portátil, isotermos, acumuladores y sondas | B13: 1800 | C13: =IFERROR(B13/$B$26,"") -> 0.023522672 | D13: Cadena de frío de la carne desde la cocina de apoyo hasta el evento, y sondas para las temperaturas del APPCC | E13: Sí
A14: Carpa, mesas, lavamanos portátil y protector de césped | B14: 1800 | C14: =IFERROR(B14/$B$26,"") -> 0.023522672 | D14: Zona de parrilla bajo carpa (a 3 m o más de la parrilla), mesa de corte y de servicio, lavamanos para el personal y protector del césped o del pavimento | E14: Sí
A15: Cuchillería, tablas de colores, básculas, GN y uniformes | B15: 1900 | C15: =IFERROR(B15/$B$26,"") -> 0.024829487 | D15: Cuchillos de deshuese y de trinchar, tablas por colores, básculas, cubetas GN y uniformes de la plantilla | E15: Sí
A16: Marca, web, fotos, dossier y lanzamiento | B16: 4500 | C16: =IFERROR(B16/$B$26,"") -> 0.058806679 | D16: Identidad, web con formulario de presupuesto, sesión de fotos y vídeo de la brasa, dossier para bodas y empresas, y degustaciones de lanzamiento | E16: Sí
A17: Software, tablet y datáfono | B17: 800 | C17: =IFERROR(B17/$B$26,"") -> 0.010454521 | D17: Presupuestos, agenda y facturación conforme a Veri*factu | E17: Sí
A18: Constitución SL + notaría + registro | B18: 1000 | C18: =IFERROR(B18/$B$26,"") -> 0.013068151 | D18: SL unipersonal. Las tasas y el arancel del Registro no llevan IVA; los honorarios del notario y de la gestoría sí: cambia la columna de al lado a «Sí» si tu presupuesto es sobre todo de honorarios | E18: No
... A20: Stock inicial de producto | B20: 1500 | C20: =IFERROR(B20/$B$26,"") -> 0.019602226 | D20: Primer pedido de carbón y leña, especias, salsas, desechables compostables y la primera carga de gas | E20: Sí
A21: Fianza de la cocina de apoyo | B21: =IFERROR(IF('0. Supuestos'!$B$24="","",'0. Supuestos'!$B$24*'0. Supuestos'!$B$25),"") -> 2000 | C21: =IFERROR(B21/$B$26,"") -> 0.026136302 | D21: =IFERROR(""&TEXT('0. Supuestos'!$B$25,"0")&" meses de renta, al tipo de la hoja de Supuestos. Es un activo recuperable al cerrar: ni se amortiza ni lleva IVA","") -> 2 meses de renta, al tipo de la hoja de Supuestos. Es un activo recuperable al cerrar: ni se amortiza ni lleva IVA | E21: No
A22: Cuota de la cocina de apoyo de los meses previos al arranque | B22: =IFERROR(IF('0. Supuestos'!$B$24="","",'0. Supuestos'!$B$24*'0. Supuestos'!$B$54),"") -> 1000 | C22: =IFERROR(B22/$B$26,"") -> 0.013068151 | D22: =IFERROR("Renta "&IF('0. Supuestos'!$B$54=1,"del mes","de los "&TEXT('0. Supuestos'!$B$54,"0")&" meses")&" de puesta en marcha (pruebas de menú y degustaciones). NO se solapa con el P&L, que arranca el día de la apertura: los doce meses del P&L son los doce de explotación","") -> Renta del mes de puesta en marcha (pruebas de menú y degustaciones). NO se solapa con el P&L, que arranca el día de la apertura: los doce meses del P&L son los doce de explotación | E22: Sí
A23: Imprevistos de la compra y preparación de la furgoneta | B23: =IFERROR(IF(COUNT(B7,B8)=0,"",ROUND((B7+B8)*'0. Supuestos'!$B$55,0)),"") -> 1696 | C23: =IFERROR(B23/$B$26,"") -> 0.022163584 | D23: =IFERROR("Al "&TEXT('0. Supuestos'!$B$55,"0%")&" de las partidas de la furgoneta de este bloque (Furgoneta frigorífica usada con certificado ATP y Rotulación, estanterías y anclajes), no del bloque entero: el resto de partidas del bloque quedan fuera. Un banco no financia una compra así "&"sin colchón: el porcentaje está en la hoja de Supuestos","") -> Al 8% de las partidas de la furgoneta de este bloque (Furgoneta frigorífica usada con certificado ATP y Rotulación, estanterías y anclajes), no del bloque entero: el resto de partidas del bloque quedan fuera. Un banco no financia una compra así sin colchón: el porcentaje está en la hoja de Supuestos | E23: Sí
A24: FONDO DE MANIOBRA | B24: =IFERROR(IF(B25="","",B25),"") -> 21925.92 | C24: =IFERROR(B24/$B$26,"") -> 0.28653123
A25: Colchón operativo hasta alcanzar el equilibrio | B25: =IFERROR(IF('0. Supuestos'!$B$35*('PyG 3 Años'!$B$38-'PyG 3 Años'!$B$36)=0,"",'0. Supuestos'!$B$35*('PyG 3 Años'!$B$38-'PyG 3 Años'!$B$36)/12),"") -> 21925.92 | C25: =IFERROR(B25/$B$26,"") -> 0.28653123 | D25: =IFERROR("Cubre "&TEXT('0. Supuestos'!$B$35,"0")&IF('0. Supuestos'!$B$35=1," mes"," meses")&" de costes fijos DE CAJA del año 1 (los del P&L menos la amortización, que no se paga), que es el mínimo que exigen las Instrucciones de este libro","") -> Cubre 3 meses de costes fijos DE CAJA del año 1 (los del P&L menos la amortización, que no se paga), que es el mínimo que exigen las Instrucciones de este libro | E25: No
A26: INVERSIÓN TOTAL (suma de los bloques) | B26: =IFERROR(B6+B24,"") -> 76521.92 | D26: =IFERROR("Los porcentajes de la columna C se leen sobre esta cifra, que incluye el fondo de maniobra ("&TEXT(C24,"0%")&" del total). Para comparar el desglose con otro plan, usa la fila de CAPEX de abajo.","") -> Los porcentajes de la columna C se leen sobre esta cifra, que incluye el fondo de maniobra (29% del total). Para comparar el desglose con otro plan, usa la fila de CAPEX de abajo.
A27: CAPEX (inversión sin el fondo de maniobra) | B27: =IFERROR(B26-B24,"") -> 54596 | D27: Es lo que se compra: furgoneta, equipamiento, lanzamiento y gastos de constitución. El colchón de caja no es inversión, es circulante
A28: IVA soportado sobre la inversión (recuperable) | B28: =IFERROR(IF(B26="","",SUMIF($E$7:$E$23,"Sí",$B$7:$B$23)*'0. Supuestos'!$B$41),"") -> 10835.16 | D28: =IFERROR("Al "&TEXT('0. Supuestos'!$B$41,"0%")&" sobre las partidas marcadas con «Sí» en la columna de IVA. Las tasas y licencias no están sujetas y los seguros están exentos (art. 20.Uno.16 LIVA). Las tasas y aranceles registrales no llevan IVA; los honorarios de notaría y gestoría sí "&"(21 %, deducible). Se recupera con el modelo 303, pero hay que adelantarlo","") -> Al 21% sobre las partidas marcadas con «Sí» en la columna de IVA. Las tasas y licencias no están sujetas y los seguros están exentos (art. 20.Uno.16 LIVA). Las tasas y aranceles registrales no llevan IVA; los honorarios de notaría y gestoría sí (21 %, deducible). Se recupera con el modelo 303, pero hay que adelantarlo
A29: NECESIDAD TOTAL DE CAJA AL ARRANQUE | B29: =IFERROR(B26+B28,"") -> 87357.08 | D29: Es la cifra que tiene que cubrir la hoja de Financiación
A30: BASES DE AMORTIZACIÓN (no suman a la inversión)
A31: Furgoneta, rotulación e imprevistos | B31: =IFERROR(IF(B7="","",B7+B8+B23),"") -> 22896 | D31: =IFERROR("Se amortiza en "&TEXT('0. Supuestos'!$B$44,"0")&" años","") -> Se amortiza en 8 años
A32: Maquinaria, mobiliario y equipos | B32: =IFERROR(IF(B9="","",B9+B10+B11+B12+B13+B14+B15+B17),"") -> 20500 | D32: =IFERROR("Se amortiza en "&TEXT('0. Supuestos'!$B$45,"0")&" años","") -> Se amortiza en 10 años
A33: Amortización anual del inmovilizado | B33: =IFERROR(B31/MAX(1,'0. Supuestos'!$B$44)+B32/MAX(1,'0. Supuestos'!$B$45),"") -> 4912 | D33: =IFERROR("No se amortizan, por no ser inmovilizado, Marca, web, fotos, dossier y lanzamiento, Constitución SL + notaría + registro, Declaración responsable, plan APPCC, alérgenos y formación, Stock inicial de producto, Fianza de la cocina de apoyo, "&"Cuota de la cocina de apoyo de los meses previos al arranque ni Colchón operativo hasta alcanzar el equilibrio. Suman "&TEXT(B26-B31-B32,"0")&" € de los "&TEXT(B26,"0")&" € de inversión.","") -> No se amortizan, por no ser inmovilizado, Marca, web, fotos, dossier y lanzamiento, Constitución SL + notaría + registro, Declaración responsable, plan APPCC, alérgenos y formación, Stock inicial de producto, Fianza de la cocina de apoyo, Cuota de la cocina de apoyo de los meses previos al arranque ni Colchón operativo hasta alcanzar el equilibrio. Suman 33126 € de los 76522 € de inversión.

Sheet PyG 3 Años
A1: CUENTA DE RESULTADOS PREVISIONAL — 3 AÑOS
A2: Escenario realista — parrillero / asador para eventos
A4: Concepto | B4: Año 1 | C4: Año 2 | D4: Año 3 | E4: % s/ventas (año 1) | F4: Notas | G4: Tipo de IVA de la línea (%)
A5: INGRESOS
A6: Invitados por evento (media) | B6: =IFERROR(IF('0. Supuestos'!$B$4="","",'0. Supuestos'!$B$4),"") -> 80 | C6: =IFERROR(B6*(1+'0. Supuestos'!$B$7),"") -> 86.4 | D6: =IFERROR(C6*(1+'0. Supuestos'!$B$8),"") -> 90.72 | F6: El crecimiento de los años 2 y 3 está en la hoja de Supuestos
A7: Precio medio por invitado sin IVA | B7: =IFERROR(IF('0. Supuestos'!$B$5="","",'0. Supuestos'!$B$5),"") -> 25 | C7: =IFERROR(IF(B7="","",B7),"") -> 25 | D7: =IFERROR(IF(C7="","",C7),"") -> 25 | F7: Constante en euros del año 1: una subida de precios es una decisión aparte
A8: Eventos al año | B8: =IFERROR(IF('0. Supuestos'!$B$6="","",'0. Supuestos'!$B$6),"") -> 95 | C8: =IFERROR(IF(B8="","",B8),"") -> 95 | D8: =IFERROR(IF(C8="","",C8),"") -> 95
A9: INGRESOS TOTALES (sin IVA) | B9: =IFERROR(IF(B6*B7*B8=0,"",B6*B7*B8),"") -> 190000 | C9: =IFERROR(IF(C6*C7*C8=0,"",C6*C7*C8),"") -> 205200 | D9: =IFERROR(IF(D6*D7*D8=0,"",D6*D7*D8),"") -> 215460 | E9: =IFERROR(IF(B9="","",1),"") -> 1
A10: Ventas de comida (parrilla y asado en directo, entrantes y postre) | B10: =IFERROR(IF(B9="","",B9*$E$10),"") -> 167200 | C10: =IFERROR(IF(C9="","",C9*$E$10),"") -> 180576 | D10: =IFERROR(IF(D9="","",D9*$E$10),"") -> 189604.8 | E10: =IFERROR(IF('0. Supuestos'!$B$11="","",'0. Supuestos'!$B$11),"") -> 0.88 | F10: Carne a la brasa cocinada en el evento, con show de fuego cuando se contrata, entrantes, guarniciones, pan, salsas y postre. Las fiestas son chuletada o costillada por invitado | G10: =IFERROR(IF(B9="","",'0. Supuestos'!$B$39),"") -> 0.1
A11: Ventas de bebida (pack de cerveza, refrescos y vino) | B11: =IFERROR(IF(B9="","",B9*$E$11),"") -> 22800 | C11: =IFERROR(IF(C9="","",C9*$E$11),"") -> 24624 | D11: =IFERROR(IF(D9="","",D9*$E$11),"") -> 25855.2 | E11: =IFERROR(IF('0. Supuestos'!$B$12="","",'0. Supuestos'!$B$12),"") -> 0.12 | F11: Pack de bebida que contratan sobre todo las celebraciones privadas y las empresas; en las bodas y en las fiestas la bebida suele ponerla el cliente o el recinto | G11: =IFERROR(IF(B9="","",('0. Supuestos'!$B$62*((1-'0. Supuestos'!$B$16)*'0. Supuestos'!$B$63+'0. Supuestos'!$B$16*'0. Supuestos'!$B$40)+(1-'0. Supuestos'!$B$62)*'0. Supuestos'!$B$39)),"") -> 0.1033
A12: COSTES VARIABLES
A13: Coste de mercancía — comida | B13: =IFERROR(IF(B9="","",B9*'0. Supuestos'!$B$11*'0. Supuestos'!$B$13),"") -> 53504 | C13: =IFERROR(IF(C9="","",C9*'0. Supuestos'!$B$11*'0. Supuestos'!$B$13),"") -> 57784.32 | D13: =IFERROR(IF(D9="","",D9*'0. Supuestos'!$B$11*'0. Supuestos'!$B$13),"") -> 60673.536 | E13: =IFERROR(B13/$B$9,"") -> 0.2816 | F13: =IFERROR("Al "&TEXT('0. Supuestos'!$B$13,"0%")&" de las ventas de COMIDA, no del total: la bebida tiene su propia línea","") -> Al 32% de las ventas de COMIDA, no del total: la bebida tiene su propia línea | G13: =IFERROR(IF(B9="","",'0. Supuestos'!$B$39),"") -> 0.1
A14: Coste de mercancía — bebida | B14: =IFERROR(IF(B9="","",B9*'0. Supuestos'!$B$12*'0. Supuestos'!$B$14),"") -> 6840 | C14: =IFERROR(IF(C9="","",C9*'0. Supuestos'!$B$12*'0. Supuestos'!$B$14),"") -> 7387.2 | D14: =IFERROR(IF(D9="","",D9*'0. Supuestos'!$B$12*'0. Supuestos'!$B$14),"") -> 7756.56 | E14: =IFERROR(B14/$B$9,"") -> 0.036 | F14: =IFERROR("Al "&TEXT('0. Supuestos'!$B$14,"0%")&" de las ventas de BEBIDA","") -> Al 30% de las ventas de BEBIDA | G14: =IFERROR(IF(B9="","",('0. Supuestos'!$B$62*'0. Supuestos'!$B$40+(1-'0. Supuestos'!$B$62)*'0. Supuestos'!$B$39)),"") -> 0.166
A15: Consumibles y envases | B15: =IFERROR(IF(B9="","",B9*'0. Supuestos'!$B$15),"") -> 8550 | C15: =IFERROR(IF(C9="","",C9*'0. Supuestos'!$B$15),"") -> 9234 | D15: =IFERROR(IF(D9="","",D9*'0. Supuestos'!$B$15),"") -> 9695.7 | E15: =IFERROR(B15/$B$9,"") -> 0.045 | G15: =IFERROR(IF(B9="","",'0. Supuestos'!$B$41),"") -> 0.21
A16: Comisiones del asado para llevar | B16: =IFERROR(IF(B9="","",B9*'0. Supuestos'!$B$16*'0. Supuestos'!$B$17),"") -> 950 | C16: =IFERROR(IF(C9="","",C9*'0. Supuestos'!$B$16*'0. Supuestos'!$B$17),"") -> 1026 | D16: =IFERROR(IF(D9="","",D9*'0. Supuestos'!$B$16*'0. Supuestos'!$B$17),"") -> 1077.3 | E16: =IFERROR(B16/$B$9,"") -> 0.005 | F16: Sobre las ventas DEL CANAL. Con 0 % de asado para llevar en Supuestos, esta línea vale cero | G16: =IFERROR(IF(B9="","",'0. Supuestos'!$B$41),"") -> 0.21
A17: Comisiones de los medios de pago | B17: =IFERROR(IF(B9="","",B9*'0. Supuestos'!$B$18),"") -> 950 | C17: =IFERROR(IF(C9="","",C9*'0. Supuestos'!$B$18),"") -> 1026 | D17: =IFERROR(IF(D9="","",D9*'0. Supuestos'!$B$18),"") -> 1077.3 | E17: =IFERROR(B17/$B$9,"") -> 0.005 | F17: Las comisiones de los medios de pago están EXENTAS de IVA (art. 20.Uno.18 LIVA): no se deduce nada por ellas | G17: 0
A18: Varios e imprevistos | B18: =IFERROR(IF(B9="","",B9*'0. Supuestos'!$B$28),"") -> 9500 | C18: =IFERROR(IF(C9="","",C9*'0. Supuestos'!$B$28),"") -> 10260 | D18: =IFERROR(IF(D9="","",D9*'0. Supuestos'!$B$28),"") -> 10773 | E18: =IFERROR(B18/$B$9,"") -> 0.05 | F18: =IFERROR("Al "&TEXT('0. Supuestos'!$B$28,"0%")&" de las ventas. Es un coste VARIABLE: sube y baja con la facturación, así que no puede vivir en los costes fijos","") -> Al 5% de las ventas. Es un coste VARIABLE: sube y baja con la facturación, así que no puede vivir en los costes fijos | G18: =IFERROR(IF(B9="","",'0. Supuestos'!$B$41),"") -> 0.21
A19: TOTAL COSTES VARIABLES | B19: =IFERROR(IF(B9="","",SUM(B13:B18)),"") -> 80294 | C19: =IFERROR(IF(C9="","",SUM(C13:C18)),"") -> 86717.52 | D19: =IFERROR(IF(D9="","",SUM(D13:D18)),"") -> 91053.396 | E19: =IFERROR(B19/$B$9,"") -> 0.4226
A20: MARGEN BRUTO | B20: =IFERROR(IF(B9="","",B9-B19),"") -> 109706 | C20: =IFERROR(IF(C9="","",C9-C19),"") -> 118482.48 | D20: =IFERROR(IF(D9="","",D9-D19),"") -> 124406.6 | E20: =IFERROR(B20/$B$9,"") -> 0.5774
A21: COSTES FIJOS
A22: Cuota de la cocina de apoyo compartida | B22: =IFERROR(IF(B9="","",'0. Supuestos'!$B$24*12),"") -> 12000 | C22: =IFERROR(IF(C9="","",B22*(1+'0. Supuestos'!$B$48)),"") -> 12000 | D22: =IFERROR(IF(D9="","",C22*(1+'0. Supuestos'!$B$48)),"") -> 12000 | E22: =IFERROR(B22/$B$9,"") -> 0.063157895 | F22: El importe mensual está en la hoja de Supuestos; aquí se multiplica por doce. Es el contrato de uso de una cocina de apoyo compartida y autorizada (horas de cocina, cámara para la carne y almacén de parrillas, carbón y remolque). El mes previo al primer evento está en la hoja de Inversión y NO se cuenta dos veces | G22: =IFERROR(IF(B9="","",'0. Supuestos'!$B$41),"") -> 0.21
A23: Personal (nóminas + Seguridad Social) | B23: =IFERROR(IF(B9="","",'Personal'!$G$9),"") -> 57982.68 | C23: =IFERROR(IF(C9="","",'Personal'!$B$13),"") -> 63982.68 | D23: =IFERROR(IF(D9="","",'Personal'!$B$14),"") -> 69982.68 | E23: =IFERROR(B23/$B$9,"") -> 0.305172 | F23: Sale de la hoja de Personal: es el MISMO número, no una estimación aparte. Los años 2 y 3 suman las INCORPORACIONES declaradas en esa hoja, no un porcentaje de volumen | G23: 0
A24: Suministros (consumos propios fuera de la cuota) | B24: =IFERROR(IF(B9="","",'0. Supuestos'!$B$26*12),"") -> 600 | C24: =IFERROR(IF(C9="","",B24*(1+'0. Supuestos'!$B$48)),"") -> 600 | D24: =IFERROR(IF(D9="","",C24*(1+'0. Supuestos'!$B$48)),"") -> 600 | E24: =IFERROR(B24/$B$9,"") -> 0.0031578947 | F24: Consumos propios fuera de la cuota de la cocina. El carbón y el gas del plan B van en los consumibles. Va al 21 % de IVA | G24: =IFERROR(IF(B9="","",'0. Supuestos'!$B$41),"") -> 0.21
A25: Seguros (RC + multirriesgo) | B25: =IFERROR(IF(B9="","",'0. Supuestos'!$B$27),"") -> 1950 | C25: =IFERROR(IF(C9="","",B25*(1+'0. Supuestos'!$B$48)),"") -> 1950 | D25: =IFERROR(IF(D9="","",C25*(1+'0. Supuestos'!$B$48)),"") -> 1950 | E25: =IFERROR(B25/$B$9,"") -> 0.010263158 | F25: Las operaciones de seguro están EXENTAS de IVA (art. 20.Uno.16 LIVA): la prima no lleva IVA deducible | G25: 0
A26: Asesoría fiscal y laboral (nóminas de fijos discontinuos) | B26: 1800 | C26: =IFERROR(IF(C9="","",B26*(1+'0. Supuestos'!$B$48)),"") -> 1800 | D26: =IFERROR(IF(D9="","",C26*(1+'0. Supuestos'!$B$48)),"") -> 1800 | E26: =IFERROR(B26/$B$9,"") -> 0.0094736842 | F26: Contabilidad, impuestos de la SL y nóminas de los fijos discontinuos de cada mes con llamamientos | G26: =IFERROR(IF(B9="","",'0. Supuestos'!$B$41),"") -> 0.21
A27: Furgoneta y remolque: mantenimiento, ITV e inspección ATP | B27: 1400 | C27: =IFERROR(IF(C9="","",B27*(1+'0. Supuestos'!$B$48)),"") -> 1400 | D27: =IFERROR(IF(D9="","",C27*(1+'0. Supuestos'!$B$48)),"") -> 1400 | E27: =IFERROR(B27/$B$9,"") -> 0.0073684211 | F27: Taller, neumáticos, ITV de la furgoneta y del remolque y la inspección periódica del certificado ATP del equipo de frío (RD 237/2000) | G27: =IFERROR(IF(B9="","",'0. Supuestos'!$B$41),"") -> 0.21
A28: Marketing y publicidad | B28: 4500 | C28: =IFERROR(IF(C9="","",B28*(1+'0. Supuestos'!$B$48)),"") -> 4500 | D28: =IFERROR(IF(D9="","",C28*(1+'0. Supuestos'!$B$48)),"") -> 4500 | E28: =IFERROR(B28/$B$9,"") -> 0.023684211 | F28: Directorios de bodas, Google Ads local, redes sociales y una feria al año | G28: =IFERROR(IF(B9="","",'0. Supuestos'!$B$41),"") -> 0.21
A29: Software de gestión comercial, CRM y teléfono | B29: 900 | C29: =IFERROR(IF(C9="","",B29*(1+'0. Supuestos'!$B$48)),"") -> 900 | D29: =IFERROR(IF(D9="","",C29*(1+'0. Supuestos'!$B$48)),"") -> 900 | E29: =IFERROR(B29/$B$9,"") -> 0.0047368421 | F29: Presupuestos, agenda de eventos, CRM de clientes y línea de teléfono | G29: =IFERROR(IF(B9="","",'0. Supuestos'!$B$41),"") -> 0.21
A30: Mantenimiento de extintores y revisión del gas | B30: 170 | C30: =IFERROR(IF(C9="","",B30*(1+'0. Supuestos'!$B$48)),"") -> 170 | D30: =IFERROR(IF(D9="","",C30*(1+'0. Supuestos'!$B$48)),"") -> 170 | E30: =IFERROR(B30/$B$9,"") -> 0.00089473684 | F30: Mantenimiento anual de los extintores por una empresa mantenedora y revisión de reguladores y tubos flexibles del plan B de gas. Estimación del kit | G30: =IFERROR(IF(B9="","",'0. Supuestos'!$B$41),"") -> 0.21
A31: Uniformes, EPI y lavandería | B31: 500 | C31: =IFERROR(IF(C9="","",B31*(1+'0. Supuestos'!$B$48)),"") -> 500 | D31: =IFERROR(IF(D9="","",C31*(1+'0. Supuestos'!$B$48)),"") -> 500 | E31: =IFERROR(B31/$B$9,"") -> 0.0026315789 | F31: Chaquetas, delantales de cuero, guantes térmicos y paños: lavado y reposición | G31: =IFERROR(IF(B9="","",'0. Supuestos'!$B$41),"") -> 0.21
A32: Gestión de residuos (cenizas, grasa y aceite) | B32: 250 | C32: =IFERROR(IF(C9="","",B32*(1+'0. Supuestos'!$B$48)),"") -> 250 | D32: =IFERROR(IF(D9="","",C32*(1+'0. Supuestos'!$B$48)),"") -> 250 | E32: =IFERROR(B32/$B$9,"") -> 0.0013157895 | F32: Retirada de cenizas frías y grasa, y gestor autorizado del aceite usado, salvo que la cocina de apoyo lo incluya en la cuota | G32: =IFERROR(IF(B9="","",'0. Supuestos'!$B$41),"") -> 0.21
A33: Prevención de riesgos laborales y vigilancia de la salud | B33: 400 | C33: =IFERROR(IF(C9="","",B33*(1+'0. Supuestos'!$B$48)),"") -> 400 | D33: =IFERROR(IF(D9="","",C33*(1+'0. Supuestos'!$B$48)),"") -> 400 | E33: =IFERROR(B33/$B$9,"") -> 0.0021052632 | F33: Plan de prevención obligatorio (Ley 31/1995): quemaduras, humo, calor y cargas, y reconocimientos médicos de la plantilla | G33: =IFERROR(IF(B9="","",'0. Supuestos'!$B$41),"") -> 0.21
A34: Degustaciones comerciales y pruebas de menú | B34: 800 | C34: =IFERROR(IF(C9="","",B34*(1+'0. Supuestos'!$B$48)),"") -> 800 | D34: =IFERROR(IF(D9="","",C34*(1+'0. Supuestos'!$B$48)),"") -> 800 | E34: =IFERROR(B34/$B$9,"") -> 0.0042105263 | F34: Carne y horas de las pruebas de menú para novios y de las degustaciones a planners y empresas que no se cobran | G34: =IFERROR(IF(B9="","",'0. Supuestos'!$B$41),"") -> 0.21
A35: Afilado y reposición de cuchillería | B35: 200 | C35: =IFERROR(IF(C9="","",B35*(1+'0. Supuestos'!$B$48)),"") -> 200 | D35: =IFERROR(IF(D9="","",C35*(1+'0. Supuestos'!$B$48)),"") -> 200 | E35: =IFERROR(B35/$B$9,"") -> 0.0010526316 | F35: Afilado profesional periódico y reposición de cuchillos y tablas de corte | G35: =IFERROR(IF(B9="","",'0. Supuestos'!$B$41),"") -> 0.21
A36: Amortización del inmovilizado | B36: =IFERROR(IF(B9="","",'Inversión Inicial'!$B$33),"") -> 4912 | C36: =IFERROR(IF(C9="","",B36),"") -> 4912 | D36: =IFERROR(IF(D9="","",B36),"") -> 4912 | E36: =IFERROR(B36/$B$9,"") -> 0.025852632 | F36: Sale de las bases de amortización de la hoja de Inversión: sólo inmovilizado real. NO sube con el IPC: es una cuota sobre el coste HISTÓRICO del inmovilizado | G36: 0
A37: Gastos financieros (intereses del préstamo) | B37: =IFERROR(IF(B9="","",'Financiación'!$B$44),"") -> 4251 | C37: =IFERROR(IF(C9="","",'Financiación'!$B$46),"") -> 4251 | D37: =IFERROR(IF(D9="","",'Financiación'!$B$48),"") -> 3504.3776 | E37: =IFERROR(B37/$B$9,"") -> 0.022373684 | F37: Sólo los INTERESES son gasto. La devolución del principal va en la hoja de Tesorería | G37: 0
A38: TOTAL COSTES FIJOS | B38: =IFERROR(IF(B9="","",SUM(B22:B37)),"") -> 92615.68 | C38: =IFERROR(IF(C9="","",SUM(C22:C37)),"") -> 98615.68 | D38: =IFERROR(IF(D9="","",SUM(D22:D37)),"") -> 103869.06 | E38: =IFERROR(B38/$B$9,"") -> 0.48745095
A39: IVA soportado de los costes variables | B39: =IFERROR(IF(B9="","",SUMPRODUCT(B13:B18,G13:G18)),"") -> 10475.84 | C39: =IFERROR(IF(C9="","",SUMPRODUCT(C13:C18,G13:G18)),"") -> 11313.907 | D39: =IFERROR(IF(D9="","",SUMPRODUCT(D13:D18,G13:G18)),"") -> 11879.603 | F39: Cada línea a SU tipo, leído de la columna de al lado. Es lo que la hoja de Tesorería paga de más a los proveedores y luego se deduce
A40: IVA soportado de los costes fijos | B40: =IFERROR(IF(B9="","",SUMPRODUCT(B22:B37,G22:G37)),"") -> 4939.2 | C40: =IFERROR(IF(C9="","",SUMPRODUCT(C22:C37,G22:G37)),"") -> 4939.2 | D40: =IFERROR(IF(D9="","",SUMPRODUCT(D22:D37,G22:G37)),"") -> 4939.2
A41: RESULTADO ANTES DE IMPUESTOS | B41: =IFERROR(IF(B9="","",B20-B38),"") -> 17090.32 | C41: =IFERROR(IF(C9="","",C20-C38),"") -> 19866.8 | D41: =IFERROR(IF(D9="","",D20-D38),"") -> 20537.546 | E41: =IFERROR(B41/$B$9,"") -> 0.089949053
...

Sheet Punto Equilibrio
A1: ANÁLISIS DE PUNTO DE EQUILIBRIO
A2: Punto de equilibrio — parrillero / asador para eventos
A4: Variable | B4: Año 1 | C4: Año 2 | D4: Año 3 | E4: Notas
A5: DATOS BASE POR AÑO
A6: Costes fijos anuales | B6: =IFERROR(IF('PyG 3 Años'!$B$9="","",'PyG 3 Años'!$B$38),"") -> 92615.68 | C6: =IFERROR(IF('PyG 3 Años'!$C$9="","",'PyG 3 Años'!$C$38),"") -> 98615.68 | D6: =IFERROR(IF('PyG 3 Años'!$D$9="","",'PyG 3 Años'!$D$38),"") -> 103869.06 | E6: Los MISMOS costes fijos del P&L. Cada año tiene los suyos: por eso el umbral no puede ser uno solo para los tres
A7: Costes fijos mensuales | B7: =IFERROR(IF('PyG 3 Años'!$B$9="","",B6/12),"") -> 7717.9733 | C7: =IFERROR(IF('PyG 3 Años'!$C$9="","",C6/12),"") -> 8217.9733 | D7: =IFERROR(IF('PyG 3 Años'!$D$9="","",D6/12),"") -> 8655.7548
A8: Precio medio por invitado sin IVA | B8: =IFERROR(IF('PyG 3 Años'!$B$9="","",'PyG 3 Años'!$B$7),"") -> 25 | C8: =IFERROR(IF('PyG 3 Años'!$C$9="","",'PyG 3 Años'!$C$7),"") -> 25 | D8: =IFERROR(IF('PyG 3 Años'!$D$9="","",'PyG 3 Años'!$D$7),"") -> 25
A9: Coste variable por invitado | B9: =IFERROR(IF('PyG 3 Años'!$B$9="","",'PyG 3 Años'!$B$19/('PyG 3 Años'!$B$6*'PyG 3 Años'!$B$8)),"") -> 10.565 | C9: =IFERROR(IF('PyG 3 Años'!$C$9="","",'PyG 3 Años'!$C$19/('PyG 3 Años'!$C$6*'PyG 3 Años'!$C$8)),"") -> 10.565 | D9: =IFERROR(IF('PyG 3 Años'!$D$9="","",'PyG 3 Años'!$D$19/('PyG 3 Años'!$D$6*'PyG 3 Años'!$D$8)),"") -> 10.565 | E9: Sale del total de costes variables del P&L, no de una estimación aparte. Incluye los varios e imprevistos, que son un porcentaje de las ventas
A10: Margen de contribución por invitado | B10: =IFERROR(IF('PyG 3 Años'!$B$9="","",B8-B9),"") -> 14.435 | C10: =IFERROR(IF('PyG 3 Años'!$C$9="","",C8-C9),"") -> 14.435 | D10: =IFERROR(IF('PyG 3 Años'!$D$9="","",D8-D9),"") -> 14.435 | E10: Precio por invitado menos coste variable unitario
A11: Eventos al año | B11: =IFERROR(IF('PyG 3 Años'!$B$9="","",'PyG 3 Años'!$B$8),"") -> 95 | C11: =IFERROR(IF('PyG 3 Años'!$C$9="","",'PyG 3 Años'!$C$8),"") -> 95 | D11: =IFERROR(IF('PyG 3 Años'!$D$9="","",'PyG 3 Años'!$D$8),"") -> 95 | E11: El mismo calendario que el P&L y que los escenarios
A12: Devolución de principal del año (cuota) | B12: =IFERROR(IF('PyG 3 Años'!$B$9="","",'Financiación'!$B$45),"") -> 0 | C12: =IFERROR(IF('PyG 3 Años'!$C$9="","",'Financiación'!$B$47),"") -> 11486.499 | D12: =IFERROR(IF('PyG 3 Años'!$D$9="","",'Financiación'!$B$49),"") -> 12233.121 | E12: El principal NO es gasto del P&L, pero sale de la caja. Sin él, el umbral de equilibrio se publica por debajo del real
A13: PUNTO DE EQUILIBRIO CONTABLE (incluye amortización)
A14: Invitados necesarios al año | B14: =IFERROR(IF('PyG 3 Años'!$B$9="","",IF(B10<=0,"",B6/B10)),"") -> 6416.0499 | C14: =IFERROR(IF('PyG 3 Años'!$C$9="","",IF(C10<=0,"",C6/C10)),"") -> 6831.7063 | D14: =IFERROR(IF('PyG 3 Años'!$D$9="","",IF(D10<=0,"",D6/D10)),"") -> 7195.6396
A15: Invitados necesarios por evento | B15: =IFERROR(IF('PyG 3 Años'!$B$9="","",B14/B11),"") -> 67.537367 | C15: =IFERROR(IF('PyG 3 Años'!$C$9="","",C14/C11),"") -> 71.912698 | D15: =IFERROR(IF('PyG 3 Años'!$D$9="","",D14/D11),"") -> 75.743575
A16: Ingresos necesarios al año | B16: =IFERROR(IF('PyG 3 Años'!$B$9="","",B14*B8),"") -> 160401.25 | C16: =IFERROR(IF('PyG 3 Años'!$C$9="","",C14*C8),"") -> 170792.66 | D16: =IFERROR(IF('PyG 3 Años'!$D$9="","",D14*D8),"") -> 179890.99
A17: PUNTO DE EQUILIBRIO DE CAJA (incluye la cuota del préstamo)
A18: Costes fijos de caja + principal del año | B18: =IFERROR(IF('PyG 3 Años'!$B$9="","",B6-'PyG 3 Años'!$B$36+B12),"") -> 87703.68 | C18: =IFERROR(IF('PyG 3 Años'!$C$9="","",C6-'PyG 3 Años'!$C$36+C12),"") -> 105190.18 | D18: =IFERROR(IF('PyG 3 Años'!$D$9="","",D6-'PyG 3 Años'!$D$36+D12),"") -> 111190.18 | E18: Los fijos del P&L sin la amortización (que no se paga) y CON la devolución de principal (que sí). Es el umbral que decide si la caja aguanta
A19: Invitados necesarios al año (caja) | B19: =IFERROR(IF('PyG 3 Años'!$B$9="","",IF(B10<=0,"",B18/B10)),"") -> 6075.7658 | C19: =IFERROR(IF('PyG 3 Años'!$C$9="","",IF(C10<=0,"",C18/C10)),"") -> 7287.1617 | D19: =IFERROR(IF('PyG 3 Años'!$D$9="","",IF(D10<=0,"",D18/D10)),"") -> 7702.8181
A20: Invitados necesarios por evento (caja) | B20: =IFERROR(IF('PyG 3 Años'!$B$9="","",B19/B11),"") -> 63.95543 | C20: =IFERROR(IF('PyG 3 Años'!$C$9="","",C19/C11),"") -> 76.706965 | D20: =IFERROR(IF('PyG 3 Años'!$D$9="","",D19/D11),"") -> 81.082295
A21: Ingresos necesarios al año (caja) | B21: =IFERROR(IF('PyG 3 Años'!$B$9="","",B19*B8),"") -> 151894.15 | C21: =IFERROR(IF('PyG 3 Años'!$C$9="","",C19*C8),"") -> 182179.04 | D21: =IFERROR(IF('PyG 3 Años'!$D$9="","",D19*D8),"") -> 192570.45
A22: CONTRASTE CON EL PLAN
A23: Invitados por evento previstos en el plan | B23: =IFERROR(IF('PyG 3 Años'!$B$9="","",'PyG 3 Años'!$B$6),"") -> 80 | C23: =IFERROR(IF('PyG 3 Años'!$C$9="","",'PyG 3 Años'!$C$6),"") -> 86.4 | D23: =IFERROR(IF('PyG 3 Años'!$D$9="","",'PyG 3 Años'!$D$6),"") -> 90.72
A24: Holgura sobre el equilibrio de CAJA (%) | B24: =IFERROR(IF('PyG 3 Años'!$B$9="","",B23/B20-1),"") -> 0.25087112 | C24: =IFERROR(IF('PyG 3 Años'!$C$9="","",C23/C20-1),"") -> 0.12636447 | D24: =IFERROR(IF('PyG 3 Años'!$D$9="","",D23/D20-1),"") -> 0.11886324 | E24: Cuánto superan tus ventas previstas a las del equilibrio de caja. La caída que aguantas antes de no poder pagar los costes fijos y la cuota es algo menor: con un 25 % de holgura, un 20 %. El mínimo exigible está en la hoja de Supuestos
A25: INTERPRETACIÓN
A26: =IFERROR("Con el precio medio por invitado sin IVA de la fila de arriba necesitas "&TEXT(ROUNDUP(B15,0),"0")&" invitados por evento durante los "&TEXT(B11,"0")&" eventos del año para no perder dinero (equilibrio contable, con la amortización dentro), y "&TEXT(ROUNDUP(B20,0),"0")&" para que la caja aguante (equilibrio de caja: sin la amortización, que no se paga, y con la cuota del préstamo del año"&IF(B12=0,"; este año sólo intereses, porque el préstamo está en carencia","")&"). En las filas «Ingresos necesarios al año» tienes esas mismas cifras en euros.","") -> Con el precio medio por invitado sin IVA de la fila de arriba necesitas 68 invitados por evento durante los 95 eventos del año para no perder dinero (equilibrio contable, con la amortización dentro), y 64 para que la caja aguante (equilibrio de caja: sin la amortización, que no se paga, y con la cuota del préstamo del año; este año sólo intereses, porque el préstamo está en carencia). En las filas «Ingresos necesarios al año» tienes esas mismas cifras en euros.
A28: SENSIBILIDAD DEL PUNTO DE EQUILIBRIO
A29: Invitados por evento necesarios para cubrir costes según el precio medio por invitado (columnas) y el coste variable por invitado (filas). En verde, los que están por debajo de los invitados que prevé el plan.
A31: Invitados por evento necesarios: precio medio por invitado sin IVA (columnas) × coste variable por invitado (filas) | B31: =IFERROR($B$8-2,"") -> 23 | C31: =IFERROR(IF($B$8="","",$B$8),"") -> 25 | D31: =IFERROR($B$8+2,"") -> 27 | E31: =IFERROR($B$8+4,"") -> 29
A32: =IFERROR($B$9*0.85,"") -> 8.98025 | B32: =IFERROR(IF($B$31-$A32<=0,"",$B$6/($B$31-$A32)/$B$11),"") -> 69.537752 | C32: =IFERROR(IF($C$31-$A32<=0,"",$B$6/($C$31-$A32)/$B$11),"") -> 60.856249 | D32: =IFERROR(IF($D$31-$A32<=0,"",$B$6/($D$31-$A32)/$B$11),"") -> 54.101855 | E32: =IFERROR(IF($E$31-$A32<=0,"",$B$6/($E$31-$A32)/$B$11),"") -> 48.697006
A33: =IFERROR($B$9*0.925,"") -> 9.772625 | B33: =IFERROR(IF($B$31-$A33<=0,"",$B$6/($B$31-$A33)/$B$11),"") -> 73.703353 | C33: =IFERROR(IF($C$31-$A33<=0,"",$B$6/($C$31-$A33)/$B$11),"") -> 64.022978 | D33: =IFERROR(IF($D$31-$A33<=0,"",$B$6/($D$31-$A33)/$B$11),"") -> 56.590275 | E33: =IFERROR(IF($E$31-$A33<=0,"",$B$6/($E$31-$A33)/$B$11),"") -> 50.703848
A34: =IFERROR($B$9*1.0,"") -> 10.565 | B34: =IFERROR(IF($B$31-$A34<=0,"",$B$6/($B$31-$A34)/$B$11),"") -> 78.399831 | C34: =IFERROR(IF($C$31-$A34<=0,"",$B$6/($C$31-$A34)/$B$11),"") -> 67.537367 | D34: =IFERROR(IF($D$31-$A34<=0,"",$B$6/($D$31-$A34)/$B$11),"") -> 59.318643 | E34: =IFERROR(IF($E$31-$A34<=0,"",$B$6/($E$31-$A34)/$B$11),"") -> 52.883206
A35: =IFERROR($B$9*1.075,"") -> 11.357375 | B35: =IFERROR(IF($B$31-$A35<=0,"",$B$6/($B$31-$A35)/$B$11),"") -> 83.735575 | C35: =IFERROR(IF($C$31-$A35<=0,"",$B$6/($C$31-$A35)/$B$11),"") -> 71.459994 | D35: =IFERROR(IF($D$31-$A35<=0,"",$B$6/($D$31-$A35)/$B$11),"") -> 62.32342 | E35: =IFERROR(IF($E$31-$A35<=0,"",$B$6/($E$31-$A35)/$B$11),"") -> 55.258324
A36: =IFERROR($B$9*1.15,"") -> 12.14975 | B36: =IFERROR(IF($B$31-$A36<=0,"",$B$6/($B$31-$A36)/$B$11),"") -> 89.850639 | C36: =IFERROR(IF($C$31-$A36<=0,"",$B$6/($C$31-$A36)/$B$11),"") -> 75.866376 | D36: =IFERROR(IF($D$31-$A36<=0,"",$B$6/($D$31-$A36)/$B$11),"") -> 65.648854 | E36: =IFERROR(IF($E$31-$A36<=0,"",$B$6/($E$31-$A36)/$B$11),"") -> 57.856821

Sheet Escenarios
A1: ANÁLISIS DE ESCENARIOS
A4: Métrica | B4: Pesimista | C4: Realista | D4: Optimista | E4: Notas
A5: Invitados por evento | B5: 75 | C5: =IFERROR(IF('PyG 3 Años'!$B$6="","",'PyG 3 Años'!$B$6),"") -> 80 | D5: 85
A6: Precio medio por invitado sin IVA | B6: 23 | C6: =IFERROR(IF('PyG 3 Años'!$B$7="","",'PyG 3 Años'!$B$7),"") -> 25 | D6: 26
A7: Eventos al año | B7: 80 | C7: =IFERROR(IF('PyG 3 Años'!$B$8="","",'PyG 3 Años'!$B$8),"") -> 95 | D7: 110
A8: INGRESOS ANUALES (sin IVA) | B8: =IFERROR(IF(B5*B6*B7=0,"",B5*B6*B7),"") -> 138000 | C8: =IFERROR(IF(C5*C6*C7=0,"",C5*C6*C7),"") -> 190000 | D8: =IFERROR(IF(D5*D6*D7=0,"",D5*D6*D7),"") -> 243100
A9: Coste de mercancía — comida | B9: =IFERROR(IF(B8="","",B8*'0. Supuestos'!$B$11*'0. Supuestos'!$B$13),"") -> 38860.8 | C9: =IFERROR(IF(C8="","",C8*'0. Supuestos'!$B$11*'0. Supuestos'!$B$13),"") -> 53504 | D9: =IFERROR(IF(D8="","",D8*'0. Supuestos'!$B$11*'0. Supuestos'!$B$13),"") -> 68456.96
A10: Coste de mercancía — bebida | B10: =IFERROR(IF(B8="","",B8*'0. Supuestos'!$B$12*'0. Supuestos'!$B$14),"") -> 4968 | C10: =IFERROR(IF(C8="","",C8*'0. Supuestos'!$B$12*'0. Supuestos'!$B$14),"") -> 6840 | D10: =IFERROR(IF(D8="","",D8*'0. Supuestos'!$B$12*'0. Supuestos'!$B$14),"") -> 8751.6
A11: Consumibles y envases | B11: =IFERROR(IF(B8="","",B8*'0. Supuestos'!$B$15),"") -> 6210 | C11: =IFERROR(IF(C8="","",C8*'0. Supuestos'!$B$15),"") -> 8550 | D11: =IFERROR(IF(D8="","",D8*'0. Supuestos'!$B$15),"") -> 10939.5
A12: Comisiones del asado para llevar | B12: =IFERROR(IF(B8="","",B8*'0. Supuestos'!$B$16*'0. Supuestos'!$B$17),"") -> 690 | C12: =IFERROR(IF(C8="","",C8*'0. Supuestos'!$B$16*'0. Supuestos'!$B$17),"") -> 950 | D12: =IFERROR(IF(D8="","",D8*'0. Supuestos'!$B$16*'0. Supuestos'!$B$17),"") -> 1215.5
A13: Comisiones de los medios de pago | B13: =IFERROR(IF(B8="","",B8*'0. Supuestos'!$B$18),"") -> 690 | C13: =IFERROR(IF(C8="","",C8*'0. Supuestos'!$B$18),"") -> 950 | D13: =IFERROR(IF(D8="","",D8*'0. Supuestos'!$B$18),"") -> 1215.5
A14: Varios e imprevistos | B14: =IFERROR(IF(B8="","",B8*'0. Supuestos'!$B$28),"") -> 6900 | C14: =IFERROR(IF(C8="","",C8*'0. Supuestos'!$B$28),"") -> 9500 | D14: =IFERROR(IF(D8="","",D8*'0. Supuestos'!$B$28),"") -> 12155
A15: TOTAL COSTES VARIABLES | B15: =IFERROR(IF(B8="","",SUM(B9:B14)),"") -> 58318.8 | C15: =IFERROR(IF(C8="","",SUM(C9:C14)),"") -> 80294 | D15: =IFERROR(IF(D8="","",SUM(D9:D14)),"") -> 102734.06
A16: MARGEN BRUTO | B16: =IFERROR(IF(B8="","",B8-B15),"") -> 79681.2 | C16: =IFERROR(IF(C8="","",C8-C15),"") -> 109706 | D16: =IFERROR(IF(D8="","",D8-D15),"") -> 140365.94
A17: COSTES FIJOS (los del P&L) | B17: =IFERROR(IF(B8="","",'PyG 3 Años'!$B$38),"") -> 92615.68 | C17: =IFERROR(IF(C8="","",'PyG 3 Años'!$B$38),"") -> 92615.68 | D17: =IFERROR(IF(D8="","",'PyG 3 Años'!$B$38),"") -> 92615.68 | E17: Los costes fijos no cambian con el escenario: por eso son fijos
A18: RESULTADO ANTES DE IMPUESTOS | B18: =IFERROR(IF(B8="","",B16-B17),"") -> -12934.48 | C18: =IFERROR(IF(C8="","",C16-C17),"") -> 17090.32 | D18: =IFERROR(IF(D8="","",D16-D17),"") -> 47750.26
A19: Impuesto de Sociedades | B19: =IFERROR(IF(B8="","",MAX(0,B18-'0. Supuestos'!$B$42)*'0. Supuestos'!$B$37),"") -> 0 | C19: =IFERROR(IF(C8="","",MAX(0,C18-'0. Supuestos'!$B$42)*'0. Supuestos'!$B$37),"") -> 2563.548 | D19: =IFERROR(IF(D8="","",MAX(0,D18-'0. Supuestos'!$B$42)*'0. Supuestos'!$B$37),"") -> 7162.539 | E19: Al tipo de entidad de nueva creación, compensando las bases negativas anteriores
A20: RESULTADO NETO | B20: =IFERROR(IF(B8="","",B18-B19),"") -> -12934.48 | C20: =IFERROR(IF(C8="","",C18-C19),"") -> 14526.772 | D20: =IFERROR(IF(D8="","",D18-D19),"") -> 40587.721
A21: Invitados por evento para el equilibrio | B21: =IFERROR(IF(B8="","",IF(B6-B15/(B5*B7)<=0,"",B17/(B6-B15/(B5*B7))/B7)),"") -> 87.174591 | C21: =IFERROR(IF(C8="","",IF(C6-C15/(C5*C7)<=0,"",C17/(C6-C15/(C5*C7))/C7)),"") -> 67.537367 | D21: =IFERROR(IF(D8="","",IF(D6-D15/(D5*D7)<=0,"",D17/(D6-D15/(D5*D7))/D7)),"") -> 56.084352
A22: LO QUE CADA ESCENARIO EXIGE
A23: Coste de personal / Ventas | B23: =IFERROR(IF(B8="","",'PyG 3 Años'!$B$23/B8),"") -> 0.42016435 | C23: =IFERROR(IF(C8="","",'PyG 3 Años'!$B$23/C8),"") -> 0.305172 | D23: =IFERROR(IF(D8="","",'PyG 3 Años'!$B$23/D8),"") -> 0.2385137 | E23: La MISMA plantilla en los tres escenarios. Si en el pesimista se dispara, el ajuste hay que hacerlo en la hoja de Personal, no aquí
A24: Invitados al año por jornada equivalente | B24: =IFERROR(IF(B8="","",B5*B7/'Personal'!$C$9),"") -> 3092.7835 | C24: =IFERROR(IF(C8="","",C5*C7/'Personal'!$C$9),"") -> 3917.5258 | D24: =IFERROR(IF(D8="","",D5*D7/'Personal'!$C$9),"") -> 4819.5876 | E24: Invitados que tendría que servir cada jornada completa del cuadro de Personal. En el optimista dice si hace falta contratar
A25: Saldo de caja al cierre del año 1 (estimado, el mismo método en los tres escenarios) | B25: =IFERROR(IF(B8="","",'Inversión Inicial'!$B$25+B20+'PyG 3 Años'!$B$36-'Financiación'!$B$45),"") -> 13903.44 | C25: =IFERROR(IF(C8="","",'Inversión Inicial'!$B$25+C20+'PyG 3 Años'!$B$36-'Financiación'!$B$45),"") -> 41364.692 | D25: =IFERROR(IF(D8="","",'Inversión Inicial'!$B$25+D20+'PyG 3 Años'!$B$36-'Financiación'!$B$45),"") -> 67425.641 | E25: Saldo ESTIMADO: fondo de maniobra más el resultado del año, devolviendo la amortización (que no se paga) y restando el principal del préstamo. No incluye el desfase de cobros y pagos ni la liquidación del IVA, así que las tres columnas se pueden comparar entre sí. En rojo, el escenario se queda sin caja
A26: Saldo real del mes 12 de la hoja de Tesorería (sólo realista) | C26: =IFERROR(IF(C8="","",'Tesorería 12 meses'!$M$22),"") -> 42559.785 | E26: El saldo REAL del caso base, con su desfase de cobros y pagos y su liquidación de IVA. Sólo existe para el escenario realista, que es el único con tesorería mensual propia: por eso no está en la fila de arriba, donde se compararía contra dos estimaciones
A28: La columna «Realista» lee sus tres datos de la hoja de Supuestos, así que reproduce EXACTAMENTE el año 1 del P&L. Los otros dos escenarios usan las mismas tasas de coste: lo único que cambia son los invitados, el precio por invitado y los eventos. Los COSTES FIJOS sí son los mismos en los tres: los varios e imprevistos, que son un porcentaje de las ventas, van arriba con los variables y cada escenario carga los suyos.

Sheet Personal
A1: ESTRUCTURA DE PERSONAL Y COSTES
A2: =IFERROR("Convenio Hostelería — "&TEXT('0. Supuestos'!$B$21,"0")&" pagas + SS "&TEXT('0. Supuestos'!$B$20*100,"0")&" %","") -> Convenio Hostelería — 14 pagas + SS 33 %
A4: Puesto | B4: Personas | C4: Jornada | D4: Bruto mes (€, total del puesto) | E4: Seg. Social a cargo de la empresa (€) | F4: Coste mes (€, total del puesto) | G4: Coste año (€) | H4: Horas/semana por persona | I4: Horas/año del puesto | J4: Notas
A5: Propietario/a — parrillero titular, ventas y compras | B5: 1 | C5: 1 | D5: 1800 | E5: =IFERROR(IF(D5="","",D5*'0. Supuestos'!$B$20),"") -> 594 | F5: =IFERROR(IF(D5="","",D5+E5),"") -> 2394 | G5: =IFERROR(IF(D5="","",F5*MAX(12,'0. Supuestos'!$B$21)),"") -> 33516 | H5: =IFERROR(IF(D5="","",C5*$B$16),"") -> 40 | I5: =IFERROR(IF(D5="","",H5*B5*$B$17),"") -> 1840 | J5: Asa en cada evento, vende, compra la carne y lleva la agenda. Como administrador de la SL cotiza en el régimen de autónomos: confirma con tu gestoría la cuota y si te aplica la reducida de inicio
A6: Segundo parrillero y ayudante (fijo discontinuo) | B6: 1 | C6: 0.3 | D6: 450 | E6: =IFERROR(IF(D6="","",D6*'0. Supuestos'!$B$20),"") -> 148.5 | F6: =IFERROR(IF(D6="","",D6+E6),"") -> 598.5 | G6: =IFERROR(IF(D6="","",F6*MAX(12,'0. Supuestos'!$B$21)),"") -> 8379 | H6: =IFERROR(IF(D6="","",C6*$B$16),"") -> 12 | I6: =IFERROR(IF(D6="","",H6*B6*$B$17),"") -> 552 | J6: Contrato fijo discontinuo (art. 16 del Estatuto de los Trabajadores) al 30 % de jornada en cómputo anual: segunda parrilla en bodas, empresas y fiestas, y preparación en la cocina de apoyo. Bruto a jornada completa: 1.500 € en 14 pagas
A7: Auxiliar de parrilla y montaje (fijo discontinuo) | B7: 1 | C7: 0.32 | D7: 432 | E7: =IFERROR(IF(D7="","",D7*'0. Supuestos'!$B$20),"") -> 142.56 | F7: =IFERROR(IF(D7="","",D7+E7),"") -> 574.56 | G7: =IFERROR(IF(D7="","",F7*MAX(12,'0. Supuestos'!$B$21)),"") -> 8043.84 | H7: =IFERROR(IF(D7="","",C7*$B$16),"") -> 12.8 | I7: =IFERROR(IF(D7="","",H7*B7*$B$17),"") -> 588.8 | J7: Llamado para los eventos medianos y grandes: carga, montaje, brasa, emplatado de la carne y recogida. Bruto a jornada completa: 1.350 €. Nunca como autónomo que te factura: con tu horario y tu dirección es falso autónomo (art. 1.1 ET)
A8: Auxiliar de servicio y emplatado (fijo discontinuo) | B8: 1 | C8: 0.32 | D8: 432 | E8: =IFERROR(IF(D8="","",D8*'0. Supuestos'!$B$20),"") -> 142.56 | F8: =IFERROR(IF(D8="","",D8+E8),"") -> 574.56 | G8: =IFERROR(IF(D8="","",F8*MAX(12,'0. Supuestos'!$B$21)),"") -> 8043.84 | H8: =IFERROR(IF(D8="","",C8*$B$16),"") -> 12.8 | I8: =IFERROR(IF(D8="","",H8*B8*$B$17),"") -> 588.8 | J8: Mismo contrato y mismas horas que el anterior: sirve, repone guarniciones y salsas y recoge. Por encima del SMI en proporción a su jornada
A9: TOTAL PLANTILLA | B9: =IFERROR(IF(COUNT(D5:D8)=0,"",SUM(B5:B8)),"") -> 4 | C9: =IFERROR(IF(COUNT(D5:D8)=0,"",SUM(C5:C8)),"") -> 1.94 | D9: =IFERROR(IF(COUNT(D5:D8)=0,"",SUM(D5:D8)),"") -> 3114 | E9: =IFERROR(IF(COUNT(D5:D8)=0,"",SUM(E5:E8)),"") -> 1027.62 | F9: =IFERROR(IF(COUNT(D5:D8)=0,"",SUM(F5:F8)),"") -> 4141.62 | G9: =IFERROR(IF(COUNT(D5:D8)=0,"",SUM(G5:G8)),"") -> 57982.68 | I9: =IFERROR(IF(COUNT(D5:D8)=0,"",SUM(I5:I8)),"") -> 3569.6
A10: CRECIMIENTO DE LA PLANTILLA (coste escalonado)
A11: Coste anual de las incorporaciones del año 2 (€) | B11: 6000 | J11: Coste ANUAL completo (bruto + Seguridad Social × pagas) de lo que se contrate ese año. El P&L lo suma al coste del año anterior: la plantilla no crece con un porcentaje, crece con personas
A12: Coste anual de las incorporaciones del año 3 (€) | B12: 6000 | J12: Coste ANUAL completo (bruto + Seguridad Social × pagas) de lo que se contrate ese año. El P&L lo suma al coste del año anterior: la plantilla no crece con un porcentaje, crece con personas
A13: Coste de personal del año 2 | B13: =IFERROR(IF(G9="","",G9*(1+'0. Supuestos'!$B$48)+B11),"") -> 63982.68
A14: Coste de personal del año 3 | B14: =IFERROR(IF(B13="","",B13*(1+'0. Supuestos'!$B$48)+B12),"") -> 69982.68
A15: COBERTURA POR HORAS DE SERVICIO
A16: Jornada completa del convenio (horas/semana) | B16: 40 | J16: Art. 34.1 del Estatuto de los Trabajadores; tu convenio provincial puede fijar menos
A17: Semanas trabajadas al año por persona | B17: 46 | J17: 46 semanas: 52 menos las vacaciones (30 días naturales, art. 38 ET), los festivos y las ausencias medias
A18: Horas de trabajo por evento que hay que cubrir | B18: 8 | J18: Horas por evento y persona: carga, viaje, montaje, encendido de la brasa, cocción, servicio, recogida de las cenizas y descarga. Los marinados y el porcionado en la cocina de apoyo van aparte
A19: Personas necesarias a la vez en cada evento | B19: 3 | J19: Personas trabajando a la vez en un evento medio de 80 invitados: el parrillero titular, el segundo parrillero y un auxiliar. En bodas y fiestas entran los dos auxiliares (y un tercero de la bolsa o de una ETT si hace falta); en una celebración privada pequeña bastan dos personas: ajústalo y la hoja te dice si llega la plantilla
A20: Horas de servicio a cubrir al año | B20: =IFERROR(IF(OR(B18="",B19="",'0. Supuestos'!$B$6=""),"",B18*B19*'0. Supuestos'!$B$6),"") -> 2280
A21: Horas contratadas al año | B21: =IFERROR(IF(I9="","",I9),"") -> 3569.6
A22: Cobertura (contratadas / necesarias) | B22: =IFERROR(B21/B20,"") -> 1.565614 | J22: Por debajo del 100 % la plantilla no llega a cubrir el horario que declara el plan: o se contrata más o se recorta el horario
A24: Las columnas «Bruto mes», «Seg. Social», «Coste mes» y «Coste año» son TOTALES de la fila: en un puesto con dos personas incluyen a las dos. «Jornada» es el porcentaje sobre la jornada completa del convenio y sirve para comparar el salario con el suelo legal en proporción. El tipo de Seguridad Social y el número de pagas están en la hoja «0. Supuestos».
A25: El suelo salarial es el MAYOR entre el SMI y el salario de convenio, los dos en la hoja «0. Supuestos»; las jornadas parciales lo llevan en proporción. El convenio aplicable es el PROVINCIAL de hostelería: no existe una tabla salarial estatal única, así que la celda del convenio se entrega vacía para que copies la de tu provincia.

Sheet Instrucciones
A1: INSTRUCCIONES DE USO — Plan financiero Parrillero / Asador para Eventos
A3: CÓMO SE USA ESTE LIBRO
A4: Este plan financiero es un MODELO: sólo se teclea en las celdas VERDES y el resto se recalcula solo.
A5: 1. «0. Supuestos» es la hoja de mando: invitados, precio por invitado sin IVA, eventos, mezcla de comida y bebida, coste de mercancía, alquiler, financiación e impuestos.
A6: 2. Las partidas de la inversión, los costes fijos y la plantilla se teclean en su propia hoja, también en verde. Ningún número se escribe dos veces.
A7: 3. Sólo «Punto Equilibrio» se deriva entera de lo anterior. En las otras tres hojas también hay celdas verdes que puedes tocar: el escenario pesimista y el optimista en «Escenarios», la estacionalidad y la rampa de arranque en «Tesorería 12 meses», y las cuatro fuentes alternativas de financiación en «Financiación». Todo lo demás se calcula.
A8: 4. Todas las cifras van SIN IVA. Para pasar un PVP a precio sin IVA, divide por el tipo que le corresponda: entre 1,10 en el servicio de parrilla (comida y bebida, alcohol incluido: art. 91.Uno.2.2.º de la Ley 37/1992 del IVA) y, cuando se venden para llevar, los alimentos, que son productos alimenticios al tipo reducido por el art. 91.Uno.1.1.º; y entre 1,21 el tipo general, que en hostelería sólo alcanza a lo que sale de la cocina de apoyo como entrega de bienes excluida del reducido: el alcohol y los refrescos, zumos y gaseosas con azúcares o edulcorantes añadidos para llevar o a domicilio (la comida para llevar sigue al 10 %); el libro lo aplica al alcohol del canal de asado para llevar. El tipo de cada línea de venta está en la columna «Tipo de IVA de la línea» del P&L y de ahí salen los cobros, el IVA repercutido y el PVP equivalente. El IVA de la inversión se adelanta y se recupera con el modelo 303.
A9: 5. Si cambias la plantilla, el P&L la lee sola: el coste de personal sale de la hoja «Personal», no de una estimación aparte.
A10: 6. La hoja «Tesorería 12 meses» responde la pregunta que decide una operación bancaria: en qué mes se agota la caja. El saldo mínimo del año nunca puede salir en rojo. Las señales de los particulares (30 % al firmar y 40 % siete días antes) no se modelan: tu caja real será algo mejor.
A11: 7. La hoja «Financiación» cuadra lo que hace falta con lo que se aporta y monta el cuadro de amortización del préstamo. Si la diferencia sale en rojo, el plan no está financiado.
A12: 8. El documento Word de este pack y la calculadora de presupuestos usan las cifras de este Excel: si cambias una celda verde, el Excel manda.
A14: RATIOS QUE AUDITA EL LIBRO
A15: Los umbrales viven en la columna «Umbral» del bloque RATIOS CLAVE del P&L: cámbialos ahí y el semáforo cambia con ellos.
A17: Ratio | B17: Valor del año 1 | C17: Umbral | D17: Estado
A18: Coste de mercancía / Ventas | B18: =IFERROR(IF('PyG 3 Años'!$B$53="","",'PyG 3 Años'!$B$53),"") -> 0.3176 | C18: =IFERROR(IF('PyG 3 Años'!$E$53="","",'PyG 3 Años'!$E$53),"") -> 0.34 | D18: =IFERROR(IF(OR(B18="",C18=""),"",IF(B18<=C18,"CUMPLE","REVISAR")),"") -> CUMPLE
A19: Coste de personal / Ventas | B19: =IFERROR(IF('PyG 3 Años'!$B$54="","",'PyG 3 Años'!$B$54),"") -> 0.305172 | C19: =IFERROR(IF('PyG 3 Años'!$E$54="","",'PyG 3 Años'!$E$54),"") -> 0.36 | D19: =IFERROR(IF(OR(B19="",C19=""),"",IF(B19<=C19,"CUMPLE","REVISAR")),"") -> CUMPLE
A20: Cocina de apoyo / Ventas | B20: =IFERROR(IF('PyG 3 Años'!$B$55="","",'PyG 3 Años'!$B$55),"") -> 0.063157895 | C20: =IFERROR(IF('PyG 3 Años'!$E$55="","",'PyG 3 Años'!$E$55),"") -> 0.08 | D20: =IFERROR(IF(OR(B20="",C20=""),"",IF(B20<=C20,"CUMPLE","REVISAR")),"") -> CUMPLE
A21: Resultado neto / Ventas | B21: =IFERROR(IF('PyG 3 Años'!$B$56="","",'PyG 3 Años'!$B$56),"") -> 0.076456695 | C21: =IFERROR(IF('PyG 3 Años'!$E$56="","",'PyG 3 Años'!$E$56),"") -> 0.04 | D21: =IFERROR(IF(OR(B21="",C21=""),"",IF(B21>=C21,"CUMPLE","REVISAR")),"") -> CUMPLE
A22: Margen bruto / Ventas | B22: =IFERROR(IF('PyG 3 Años'!$B$51="","",'PyG 3 Años'!$B$51),"") -> 0.5774 | C22: =IFERROR(IF('PyG 3 Años'!$E$51="","",'PyG 3 Años'!$E$51),"") -> 0.55 | D22: =IFERROR(IF(OR(B22="",C22=""),"",IF(B22>=C22,"CUMPLE","REVISAR")),"") -> CUMPLE
A24: CIFRAS DE ESTE PLAN
A25: Inversión total (suma de los bloques) | B25: =IFERROR(IF('Inversión Inicial'!$B$26="","",'Inversión Inicial'!$B$26),"") -> 76521.92
A26: Necesidad total de caja al arranque | B26: =IFERROR(IF('Inversión Inicial'!$B$29="","",'Inversión Inicial'!$B$29),"") -> 87357.08
A27: Fondo de maniobra dotado | B27: =IFERROR(IF('Inversión Inicial'!$B$25="","",'Inversión Inicial'!$B$25),"") -> 21925.92
A28: Facturación prevista del año 1 | B28: =IFERROR(IF('PyG 3 Años'!$B$9="","",'PyG 3 Años'!$B$9),"") -> 190000
A29: Resultado neto del año 1 | B29: =IFERROR(IF('PyG 3 Años'!$B$48="","",'PyG 3 Años'!$B$48),"") -> 14526.772
A30: Invitados por evento para el punto de equilibrio CONTABLE (con la amortización dentro) | B30: =IFERROR(IF('Punto Equilibrio'!$B$15="","",'Punto Equilibrio'!$B$15),"") -> 67.537367
A31: Payback del proyecto (años), antes de la deuda | B31: =IFERROR(IF('Tesorería 12 meses'!$B$31="","",'Tesorería 12 meses'!$B$31),"") -> Más de 3 años
A33: QUÉ HA CAMBIADO RESPECTO DE LA VERSIÓN 1.1
A34: Concepto | B34: v1.1 | C34: v2.2 | D34: Por qué
