Workbook

Sheet Instrucciones
A1: Banquetes y comidas testigo
A2: AI Chef Pro · aichef.pro — Manual del Chef Ejecutivo
A3: Para qué sirve: saber si este encargo te obliga a guardar comidas testigo, y producir el evento sin calcular nada a ojo.
A5: Instrucciones de uso
A6: 1. Hoja «Registro de Comidas Testigo», bloque de arriba: los cinco parámetros legales vienen puestos (más de 40 comensales, 100 gramos, 7 días, 4 °C en refrigeración y -18 °C en congelación) con la norma y el enlace al lado. Son celdas verdes por si tu comunidad autónoma te exige más, nunca menos.
A7: 2. Bloque «El evento»: escribe el id, la fecha, los comensales, la hora de servicio, quién toma las muestras y dónde se guardan. La casilla «Obligación de comida testigo» se enciende sola.
A8: 3. Bloque «Supuestos»: la obligación NO va solo por el número de comensales. Marca Sí en los supuestos que se te apliquen (residencias, hospitales, comedores escolares, comedores colectivos con menú común, medios de transporte y eventos cuando esa sea tu actividad principal). Con uno solo marcado, la alerta ya se enciende.
A9: 4. Tabla «Muestras tomadas»: una fila por elaboración servida, con su lote, la fecha y la hora de recogida, los gramos, dónde se guarda y a qué temperatura. El libro calcula la fecha de destrucción, los días que faltan, si los gramos llegan al mínimo y si la temperatura es la que toca.
A10: 5. La columna «Estado» es la cuenta atrás: mientras queden días dice NO DESTRUIR; el último día lo avisa; después dice que ya se puede tirar. Son días naturales, no laborables.
A11: 6. La celda verde «Fecha para simular» sirve para ver la cuenta atrás en cualquier día. En el ejemplo trae la fecha del banquete más tres días; bórrala y el libro usará la de hoy.
A12: 7. Hoja «Producción y Ficha de Banquete»: el evento se lee solo de la hoja anterior. Escribe el menú, cuántas raciones sirve cada plato POR COMENSAL y cuántas raciones salen de cada unidad de producción (una olla, una placa, una bandeja).
A13: 8. Las raciones a producir y las unidades de producción se calculan solas. Si el comercial cambia los comensales de 120 a 140, cambia UNA celda y toda la producción se recalcula: eso es lo que evita el pedido a ojo la víspera.
... A31: Versión 1.0 · septiembre 2026 · aichef.pro/manual-chef-ejecutivo · info@aichef.pro

Sheet Registro de Comidas Testigo
A1: Registro de comidas testigo
A2: AI Chef Pro · aichef.pro — Manual del Chef Ejecutivo
A3: Si el encargo obliga, se decide arriba. Lo que hay que guardar, cuánto y hasta cuándo, se calcula abajo.
A5: PARÁMETROS LEGALES DE LAS COMIDAS TESTIGO (celdas verdes)
A6: Parámetro | D6: Valor | E6: Base legal, verificada el 06-09-2026
A7: Comensales a partir de los que obliga (más de) | D7: 40 | E7: Verificado el 06-09-2026 · RD 1086/2020, art. 30, apartados 8, 9 y 10 · https://www.boe.es/buscar/act.php?id=BOE-A-2020-15872
A8: Gramos mínimos por elaboración guardada | D8: 100 | E8: Verificado el 06-09-2026 · RD 1086/2020, art. 30, apartados 8, 9 y 10 · https://www.boe.es/buscar/act.php?id=BOE-A-2020-15872
A9: Días de conservación de la muestra (mínimo) | D9: 7 | E9: Verificado el 06-09-2026 · RD 1086/2020, art. 30, apartados 8, 9 y 10 · https://www.boe.es/buscar/act.php?id=BOE-A-2020-15872
A10: Temperatura máxima en refrigeración (°C) | D10: 4 | E10: Verificado el 06-09-2026 · RD 1086/2020, art. 30, apartados 8, 9 y 10 · https://www.boe.es/buscar/act.php?id=BOE-A-2020-15872
A11: Temperatura máxima en congelación (°C) | D11: -18 | E11: Verificado el 06-09-2026 · RD 1086/2020, art. 30, apartados 8, 9 y 10 · https://www.boe.es/buscar/act.php?id=BOE-A-2020-15872
A12: Fecha para simular (déjala vacía y se usa la de hoy) | D12: 46287 | E12: En el ejemplo trae la fecha del banquete más tres días, para que se vea la cuenta atrás. Bórrala y el libro usará la de hoy.
A13: Hoy (fecha de referencia de la cuenta atrás) | D13: =IFERROR(IF($D$12="",TODAY(),$D$12),"") -> 46287
A17: EL EVENTO
A18: Campo | D18: Valor
A19: Id del evento | D19: EV-2026-014
A20: Nombre del evento | D20: Banquete de boda
A21: Fecha del evento | D21: 46284
A22: Comensales | D22: 120
A23: Hora de servicio | D23: 14:30
A24: Responsable de tomar las muestras | D24: P02
A25: Dónde se guardan las muestras | D25: Cámara 3 (postres), balda superior, caja rotulada COMIDAS TESTIGO
A26: OBLIGACIÓN DE COMIDA TESTIGO | D26: =IF(OR(AND(ISNUMBER($D$22),ISNUMBER($D$7),$D$22>$D$7),AND(ISNUMBER($D$35),$D$35>0)),"COMIDA TESTIGO OBLIGATORIA","Por número de comensales no es obligatoria: revisa igualmente los supuestos de la tabla de abajo") -> COMIDA TESTIGO OBLIGATORIA
A27: ¿Elaboración y servicio en establecimientos distintos? | D27: No | E27: Si es «Sí» (catering: se elabora en un obrador y se sirve en otro sitio), el art. 30.9 exige DOS tomas por elaboración: una a la salida del obrador y otra en el servicio. Verificado el 06-09-2026 · RD 1086/2020, art. 30, apartados 8, 9 y 10 · https://www.boe.es/buscar/act.php?id=BOE-A-2020-15872
A28: SUPUESTOS DEL ARTÍCULO 30.8 — obligan por TIPO DE SERVICIO, sin mirar el número de comensales
A29: Supuesto | D29: ¿Te aplica?
A30: Residencias, hospitales y comedores escolares | D30: No
A31: Comedores colectivos con menú común | D31: No
A32: Medios de transporte | D32: No
A33: Eventos cuando esa sea la actividad principal | D33: No
A34: Cualquier encargo, de quien sea, para grupos o eventos de más de 40 personas | D34: Sí
A35: Supuestos marcados | D35: =COUNTIF($D$30:$D$34,"Sí") -> 1 | E35: Verificado el 06-09-2026 · RD 1086/2020, art. 30, apartados 8, 9 y 10 · https://www.boe.es/buscar/act.php?id=BOE-A-2020-15872
A37: MUESTRAS TOMADAS
A38: Id de muestra | B38: Id del plato | C38: Elaboración | D38: Lote | E38: Fecha de recogida | F38: Hora | G38: Gramos | H38: Ubicación | I38: Temperatura (°C) | J38: Conservación | K38: Fecha de destrucción prevista | L38: Días que faltan | M38: Estado | N38: Gramos suficientes | O38: Temperatura conforme | P38: Responsable | Q38: Momento de la toma (art. 30.9) | R38: Aviso
A39: CT-2026-014-1 | B39: E1 | C39: Croquetas de jamón ibérico | D39: L260918-CRO | E39: 46284 | F39: 14:20 | G39: 120 | H39: Cámara 3, balda superior | I39: 4 | J39: Refrigeración | K39: =IFERROR(IF(OR(NOT(ISNUMBER($E39)),NOT(ISNUMBER($D$9))),"",$E39+$D$9),"") -> 46291 | L39: =IFERROR(IF(OR(NOT(ISNUMBER($K39)),NOT(ISNUMBER($D$13))),"",$K39-$D$13),"") -> 4 | M39: =IF(NOT(ISNUMBER($L39)),"",IF($L39>0,"En conservación: NO destruir",IF($L39=0,"Último día de conservación","Ya se puede destruir"))) -> En conservación: NO destruir | N39: =IF(OR(NOT(ISNUMBER($G39)),NOT(ISNUMBER($D$8))),"",IF($G39>=$D$8,"Sí","NO: por debajo del mínimo")) -> Sí | O39: =IF(OR($J39="",NOT(ISNUMBER($I39))),"",IF($J39=$A$72,IF($I39<=$D$10,"Sí","NO: por encima del máximo"),IF($J39=$A$73,IF($I39<=$D$11,"Sí","NO: por encima del máximo"),""))) -> Sí | P39: P02 | Q39: Toma única | R39: =IF(OR($Q39="",$D$27=""),"",IF(AND($D$27="Sí",$Q39=$A$78),"Revisar: art. 30.9 exige DOS tomas (salida del obrador y servicio) cuando elaboras y sirves en establecimientos distintos",""))
A40: CT-2026-014-2 | B40: E2 | C40: Ensalada de tomate rosa, ventresca y cebolleta | D40: L260919-TOM | E40: 46284 | F40: 14:20 | G40: 110 | H40: Cámara 3, balda superior | I40: 4 | J40: Refrigeración | K40: =IFERROR(IF(OR(NOT(ISNUMBER($E40)),NOT(ISNUMBER($D$9))),"",$E40+$D$9),"") -> 46291 | L40: =IFERROR(IF(OR(NOT(ISNUMBER($K40)),NOT(ISNUMBER($D$13))),"",$K40-$D$13),"") -> 4 | M40: =IF(NOT(ISNUMBER($L40)),"",IF($L40>0,"En conservación: NO destruir",IF($L40=0,"Último día de conservación","Ya se puede destruir"))) -> En conservación: NO destruir | N40: =IF(OR(NOT(ISNUMBER($G40)),NOT(ISNUMBER($D$8))),"",IF($G40>=$D$8,"Sí","NO: por debajo del mínimo")) -> Sí | O40: =IF(OR($J40="",NOT(ISNUMBER($I40))),"",IF($J40=$A$72,IF($I40<=$D$10,"Sí","NO: por encima del máximo"),IF($J40=$A$73,IF($I40<=$D$11,"Sí","NO: por encima del máximo"),""))) -> Sí | P40: P02 | Q40: Toma única | R40: =IF(OR($Q40="",$D$27=""),"",IF(AND($D$27="Sí",$Q40=$A$78),"Revisar: art. 30.9 exige DOS tomas (salida del obrador y servicio) cuando elaboras y sirves en establecimientos distintos",""))
A41: CT-2026-014-3 | B41: E6 | C41: Alcachofas confitadas con jamón | D41: L260918-ALC | E41: 46284 | F41: 14:25 | G41: 105 | H41: Cámara 3, balda superior | I41: 4 | J41: Refrigeración | K41: =IFERROR(IF(OR(NOT(ISNUMBER($E41)),NOT(ISNUMBER($D$9))),"",$E41+$D$9),"") -> 46291 | L41: =IFERROR(IF(OR(NOT(ISNUMBER($K41)),NOT(ISNUMBER($D$13))),"",$K41-$D$13),"") -> 4 | M41: =IF(NOT(ISNUMBER($L41)),"",IF($L41>0,"En conservación: NO destruir",IF($L41=0,"Último día de conservación","Ya se puede destruir"))) -> En conservación: NO destruir | N41: =IF(OR(NOT(ISNUMBER($G41)),NOT(ISNUMBER($D$8))),"",IF($G41>=$D$8,"Sí","NO: por debajo del mínimo")) -> Sí | O41: =IF(OR($J41="",NOT(ISNUMBER($I41))),"",IF($J41=$A$72,IF($I41<=$D$10,"Sí","NO: por encima del máximo"),IF($J41=$A$73,IF($I41<=$D$11,"Sí","NO: por encima del máximo"),""))) -> Sí | P41: P05 | Q41: Toma única | R41: =IF(OR($Q41="",$D$27=""),"",IF(AND($D$27="Sí",$Q41=$A$78),"Revisar: art. 30.9 exige DOS tomas (salida del obrador y servicio) cuando elaboras y sirves en establecimientos distintos",""))
A42: CT-2026-014-4 | B42: P1 | C42: Solomillo de cerdo ibérico con puré de boniato | D42: L260919-SOL | E42: 46284 | F42: 15:10 | G42: 130 | H42: Cámara 3, balda superior | I42: 4 | J42: Refrigeración | K42: =IFERROR(IF(OR(NOT(ISNUMBER($E42)),NOT(ISNUMBER($D$9))),"",$E42+$D$9),"") -> 46291 | L42: =IFERROR(IF(OR(NOT(ISNUMBER($K42)),NOT(ISNUMBER($D$13))),"",$K42-$D$13),"") -> 4 | M42: =IF(NOT(ISNUMBER($L42)),"",IF($L42>0,"En conservación: NO destruir",IF($L42=0,"Último día de conservación","Ya se puede destruir"))) -> En conservación: NO destruir | N42: =IF(OR(NOT(ISNUMBER($G42)),NOT(ISNUMBER($D$8))),"",IF($G42>=$D$8,"Sí","NO: por debajo del mínimo")) -> Sí | O42: =IF(OR($J42="",NOT(ISNUMBER($I42))),"",IF($J42=$A$72,IF($I42<=$D$10,"Sí","NO: por encima del máximo"),IF($J42=$A$73,IF($I42<=$D$11,"Sí","NO: por encima del máximo"),""))) -> Sí | P42: P04 | Q42: Toma única | R42: =IF(OR($Q42="",$D$27=""),"",IF(AND($D$27="Sí",$Q42=$A$78),"Revisar: art. 30.9 exige DOS tomas (salida del obrador y servicio) cuando elaboras y sirves en establecimientos distintos",""))
A43: CT-2026-014-5 | B43: P2 | C43: Bacalao confitado al pil-pil | D43: L260919-BAC | E43: 46284 | F43: 15:10 | G43: 115 | H43: Cámara 3, balda superior | I43: 4 | J43: Refrigeración | K43: =IFERROR(IF(OR(NOT(ISNUMBER($E43)),NOT(ISNUMBER($D$9))),"",$E43+$D$9),"") -> 46291 | L43: =IFERROR(IF(OR(NOT(ISNUMBER($K43)),NOT(ISNUMBER($D$13))),"",$K43-$D$13),"") -> 4 | M43: =IF(NOT(ISNUMBER($L43)),"",IF($L43>0,"En conservación: NO destruir",IF($L43=0,"Último día de conservación","Ya se puede destruir"))) -> En conservación: NO destruir | N43: =IF(OR(NOT(ISNUMBER($G43)),NOT(ISNUMBER($D$8))),"",IF($G43>=$D$8,"Sí","NO: por debajo del mínimo")) -> Sí | O43: =IF(OR($J43="",NOT(ISNUMBER($I43))),"",IF($J43=$A$72,IF($I43<=$D$10,"Sí","NO: por encima del máximo"),IF($J43=$A$73,IF($I43<=$D$11,"Sí","NO: por encima del máximo"),""))) -> Sí | P43: P04 | Q43: Toma única | R43: =IF(OR($Q43="",$D$27=""),"",IF(AND($D$27="Sí",$Q43=$A$78),"Revisar: art. 30.9 exige DOS tomas (salida del obrador y servicio) cuando elaboras y sirves en establecimientos distintos",""))
A44: CT-2026-014-6 | B44: D1 | C44: Tarta de queso cremosa | D44: L260918-TAR | E44: 46284 | F44: 16:00 | G44: 100 | H44: Congelador 1, cesta 2 | I44: -18 | J44: Congelación | K44: =IFERROR(IF(OR(NOT(ISNUMBER($E44)),NOT(ISNUMBER($D$9))),"",$E44+$D$9),"") -> 46291 | L44: =IFERROR(IF(OR(NOT(ISNUMBER($K44)),NOT(ISNUMBER($D$13))),"",$K44-$D$13),"") -> 4 | M44: =IF(NOT(ISNUMBER($L44)),"",IF($L44>0,"En conservación: NO destruir",IF($L44=0,"Último día de conservación","Ya se puede destruir"))) -> En conservación: NO destruir | N44: =IF(OR(NOT(ISNUMBER($G44)),NOT(ISNUMBER($D$8))),"",IF($G44>=$D$8,"Sí","NO: por debajo del mínimo")) -> Sí | O44: =IF(OR($J44="",NOT(ISNUMBER($I44))),"",IF($J44=$A$72,IF($I44<=$D$10,"Sí","NO: por encima del máximo"),IF($J44=$A$73,IF($I44<=$D$11,"Sí","NO: por encima del máximo"),""))) -> Sí | P44: P07 | Q44: Toma única | R44: =IF(OR($Q44="",$D$27=""),"",IF(AND($D$27="Sí",$Q44=$A$78),"Revisar: art. 30.9 exige DOS tomas (salida del obrador y servicio) cuando elaboras y sirves en establecimientos distintos",""))
K45: =IFERROR(IF(OR(NOT(ISNUMBER($E45)),NOT(ISNUMBER($D$9))),"",$E45+$D$9),"") | L45: =IFERROR(IF(OR(NOT(ISNUMBER($K45)),NOT(ISNUMBER($D$13))),"",$K45-$D$13),"") | M45: =IF(NOT(ISNUMBER($L45)),"",IF($L45>0,"En conservación: NO destruir",IF($L45=0,"Último día de conservación","Ya se puede destruir"))) | N45: =IF(OR(NOT(ISNUMBER($G45)),NOT(ISNUMBER($D$8))),"",IF($G45>=$D$8,"Sí","NO: por debajo del mínimo")) | O45: =IF(OR($J45="",NOT(ISNUMBER($I45))),"",IF($J45=$A$72,IF($I45<=$D$10,"Sí","NO: por encima del máximo"),IF($J45=$A$73,IF($I45<=$D$11,"Sí","NO: por encima del máximo"),""))) | R45: =IF(OR($Q45="",$D$27=""),"",IF(AND($D$27="Sí",$Q45=$A$78),"Revisar: art. 30.9 exige DOS tomas (salida del obrador y servicio) cuando elaboras y sirves en establecimientos distintos",""))
...

Sheet Producción y Ficha de Banquete
A1: Producción y ficha de banquete
A2: AI Chef Pro · aichef.pro — Manual del Chef Ejecutivo
A3: Todo se calcula desde los comensales. Si cambian la víspera, cambia una celda y se recalcula la producción entera.
A5: EL EVENTO — se lee de la hoja «Registro de Comidas Testigo»; cámbialo allí, no aquí
A6: Id del evento | C6: =IF('Registro de Comidas Testigo'!$D$19="","",'Registro de Comidas Testigo'!$D$19) -> EV-2026-014
A7: Fecha del evento | C7: =IF('Registro de Comidas Testigo'!$D$21="","",'Registro de Comidas Testigo'!$D$21) -> 46284
A8: Comensales | C8: =IF('Registro de Comidas Testigo'!$D$22="","",'Registro de Comidas Testigo'!$D$22) -> 120
A9: Obligación de comida testigo | C9: =IF('Registro de Comidas Testigo'!$D$26="","",'Registro de Comidas Testigo'!$D$26) -> COMIDA TESTIGO OBLIGATORIA
A11: MENÚ Y PRODUCCIÓN POR PLATO
A12: Momento del menú | B12: Id del plato | C12: Elaboración | D12: Partida | E12: Raciones por comensal | F12: Raciones a producir | G12: Raciones por unidad de producción | H12: Unidades de producción
A13: Aperitivo | B13: E1 | C13: Croquetas de jamón ibérico (6 ud) | D13: Fríos y entrantes | E13: 1 | F13: =IFERROR(IF(OR(NOT(ISNUMBER($E13)),NOT(ISNUMBER($C$8))),"",ROUND($C$8*$E13,0)),"") -> 120 | G13: 30 | H13: =IFERROR(IF(OR(NOT(ISNUMBER($F13)),NOT(ISNUMBER($G13)),$G13=0),"",ROUNDUP($F13/$G13,0)),"") -> 4
A14: Aperitivo | B14: E6 | C14: Alcachofas confitadas con jamón | D14: Fríos y entrantes | E14: 1 | F14: =IFERROR(IF(OR(NOT(ISNUMBER($E14)),NOT(ISNUMBER($C$8))),"",ROUND($C$8*$E14,0)),"") -> 120 | G14: 40 | H14: =IFERROR(IF(OR(NOT(ISNUMBER($F14)),NOT(ISNUMBER($G14)),$G14=0),"",ROUNDUP($F14/$G14,0)),"") -> 3
A15: Entrante | B15: E2 | C15: Ensalada de tomate rosa, ventresca y cebolleta | D15: Fríos y entrantes | E15: 1 | F15: =IFERROR(IF(OR(NOT(ISNUMBER($E15)),NOT(ISNUMBER($C$8))),"",ROUND($C$8*$E15,0)),"") -> 120 | G15: 20 | H15: =IFERROR(IF(OR(NOT(ISNUMBER($F15)),NOT(ISNUMBER($G15)),$G15=0),"",ROUNDUP($F15/$G15,0)),"") -> 6
A16: Principal 1 | B16: P2 | C16: Bacalao confitado al pil-pil | D16: Pase y caliente | E16: 0.4 | F16: =IFERROR(IF(OR(NOT(ISNUMBER($E16)),NOT(ISNUMBER($C$8))),"",ROUND($C$8*$E16,0)),"") -> 48 | G16: 12 | H16: =IFERROR(IF(OR(NOT(ISNUMBER($F16)),NOT(ISNUMBER($G16)),$G16=0),"",ROUNDUP($F16/$G16,0)),"") -> 4
A17: Principal 2 | B17: P1 | C17: Solomillo de cerdo ibérico con puré de boniato | D17: Pase y caliente | E17: 0.6 | F17: =IFERROR(IF(OR(NOT(ISNUMBER($E17)),NOT(ISNUMBER($C$8))),"",ROUND($C$8*$E17,0)),"") -> 72 | G17: 12 | H17: =IFERROR(IF(OR(NOT(ISNUMBER($F17)),NOT(ISNUMBER($G17)),$G17=0),"",ROUNDUP($F17/$G17,0)),"") -> 6
A18: Postre | B18: D1 | C18: Tarta de queso cremosa | D18: Postres y panadería | E18: 1 | F18: =IFERROR(IF(OR(NOT(ISNUMBER($E18)),NOT(ISNUMBER($C$8))),"",ROUND($C$8*$E18,0)),"") -> 120 | G18: 12 | H18: =IFERROR(IF(OR(NOT(ISNUMBER($F18)),NOT(ISNUMBER($G18)),$G18=0),"",ROUNDUP($F18/$G18,0)),"") -> 10
F19: =IFERROR(IF(OR(NOT(ISNUMBER($E19)),NOT(ISNUMBER($C$8))),"",ROUND($C$8*$E19,0)),"") | H19: =IFERROR(IF(OR(NOT(ISNUMBER($F19)),NOT(ISNUMBER($G19)),$G19=0),"",ROUNDUP($F19/$G19,0)),"")
F20: =IFERROR(IF(OR(NOT(ISNUMBER($E20)),NOT(ISNUMBER($C$8))),"",ROUND($C$8*$E20,0)),"") | H20: =IFERROR(IF(OR(NOT(ISNUMBER($F20)),NOT(ISNUMBER($G20)),$G20=0),"",ROUNDUP($F20/$G20,0)),"")
F21: =IFERROR(IF(OR(NOT(ISNUMBER($E21)),NOT(ISNUMBER($C$8))),"",ROUND($C$8*$E21,0)),"") | H21: =IFERROR(IF(OR(NOT(ISNUMBER($F21)),NOT(ISNUMBER($G21)),$G21=0),"",ROUNDUP($F21/$G21,0)),"")
F22: =IFERROR(IF(OR(NOT(ISNUMBER($E22)),NOT(ISNUMBER($C$8))),"",ROUND($C$8*$E22,0)),"") | H22: =IFERROR(IF(OR(NOT(ISNUMBER($F22)),NOT(ISNUMBER($G22)),$G22=0),"",ROUNDUP($F22/$G22,0)),"")
F23: =IFERROR(IF(OR(NOT(ISNUMBER($E23)),NOT(ISNUMBER($C$8))),"",ROUND($C$8*$E23,0)),"") | H23: =IFERROR(IF(OR(NOT(ISNUMBER($F23)),NOT(ISNUMBER($G23)),$G23=0),"",ROUNDUP($F23/$G23,0)),"")
F24: =IFERROR(IF(OR(NOT(ISNUMBER($E24)),NOT(ISNUMBER($C$8))),"",ROUND($C$8*$E24,0)),"") | H24: =IFERROR(IF(OR(NOT(ISNUMBER($F24)),NOT(ISNUMBER($G24)),$G24=0),"",ROUNDUP($F24/$G24,0)),"")
A25: TOTAL | E25: =IF(COUNT(E13:E24)=0,"",SUM(E13:E24)) -> 5 | F25: =IF(COUNT(F13:F24)=0,"",SUM(F13:F24)) -> 600 | H25: =IF(COUNT(H13:H24)=0,"",SUM(H13:H24)) -> 33
A27: PRODUCCIÓN POR PARTIDA — así se manda el trabajo
A28: Partida | C28: Raciones a producir | D28: Unidades de producción | E28: Porcentaje del total
A29: Pase y caliente | C29: =IFERROR(IF(COUNTIF($D$13:$D$24,$A29&"")=0,"",SUMIF($D$13:$D$24,$A29&"",$F$13:$F$24)),"") -> 120 | D29: =IFERROR(IF(COUNTIF($D$13:$D$24,$A29&"")=0,"",SUMIF($D$13:$D$24,$A29&"",$H$13:$H$24)),"") -> 10 | E29: =IFERROR(IF(OR(NOT(ISNUMBER($C29)),NOT(ISNUMBER($C$33)),$C$33=0),"",$C29/$C$33),"") -> 0.2 | G29: Las partidas que no producen nada en este evento se quedan en blanco, no en cero: en esta familia «sin dato» y «cero» no son lo mismo.
A30: Fríos y entrantes | C30: =IFERROR(IF(COUNTIF($D$13:$D$24,$A30&"")=0,"",SUMIF($D$13:$D$24,$A30&"",$F$13:$F$24)),"") -> 360 | D30: =IFERROR(IF(COUNTIF($D$13:$D$24,$A30&"")=0,"",SUMIF($D$13:$D$24,$A30&"",$H$13:$H$24)),"") -> 13 | E30: =IFERROR(IF(OR(NOT(ISNUMBER($C30)),NOT(ISNUMBER($C$33)),$C$33=0),"",$C30/$C$33),"") -> 0.6
A31: Postres y panadería | C31: =IFERROR(IF(COUNTIF($D$13:$D$24,$A31&"")=0,"",SUMIF($D$13:$D$24,$A31&"",$F$13:$F$24)),"") -> 120 | D31: =IFERROR(IF(COUNTIF($D$13:$D$24,$A31&"")=0,"",SUMIF($D$13:$D$24,$A31&"",$H$13:$H$24)),"") -> 10 | E31: =IFERROR(IF(OR(NOT(ISNUMBER($C31)),NOT(ISNUMBER($C$33)),$C$33=0),"",$C31/$C$33),"") -> 0.2
A32: Barra y bebidas | C32: =IFERROR(IF(COUNTIF($D$13:$D$24,$A32&"")=0,"",SUMIF($D$13:$D$24,$A32&"",$F$13:$F$24)),"") | D32: =IFERROR(IF(COUNTIF($D$13:$D$24,$A32&"")=0,"",SUMIF($D$13:$D$24,$A32&"",$H$13:$H$24)),"") | E32: =IFERROR(IF(OR(NOT(ISNUMBER($C32)),NOT(ISNUMBER($C$33)),$C$33=0),"",$C32/$C$33),"")
A33: TOTAL | C33: =IF(COUNT(C29:C32)=0,"",SUM(C29:C32)) -> 600 | D33: =IF(COUNT(D29:D32)=0,"",SUM(D29:D32)) -> 33 | E33: =IF(COUNT($E$29:$E$32)=0,"",SUM($E$29:$E$32)) -> 1
A35: TIMING DEL EVENTO
A36: Fecha | B36: Hora | C36: Hito | D36: Partida o área | E36: Responsable (id) | F36: Nombre
A37: 46283 | B37: 09:00 | C37: Recepción de pescado y verdura; comprobación y etiquetado | D37: Economato | E37: P06 | F37: Omar B.
A38: 46283 | B38: 11:00 | C38: Masa de croqueta, alcachofas confitadas y tarta de queso | D38: Fríos y entrantes | E38: P05 | F38: Laura S.
A39: 46283 | B39: 17:00 | C39: Desalado del bacalao y racionado del solomillo | D39: Pase y caliente | E39: P04 | F39: Diego M.
A40: 46284 | B40: 08:30 | C40: Puré de boniato, salsa de Pedro Ximénez y fondo de pil-pil | D40: Pase y caliente | E40: P04 | F40: Diego M.
A41: 46284 | B41: 10:00 | C41: Montaje de ensaladas en bandeja y frito de croquetas de prueba | D41: Fríos y entrantes | E41: P05 | F41: Laura S.
A42: 46284 | B42: 13:30 | C42: Aperitivo en el jardin | D42: Fríos y entrantes | E42: P05 | F42: Laura S.
A43: 46284 | B43: 14:20 | C43: Toma de las comidas testigo del aperitivo y el entrante | D43: Cocina | E43: P02 | F43: Iván R.
A44: 46284 | B44: 14:30 | C44: Entrante en mesa | D44: Fríos y entrantes | E44: P05 | F44: Laura S.
...
