Workbook

Sheet Instrucciones
A1: Cuadro de mando de cocina
A2: AI Chef Pro · aichef.pro — Manual del Chef Ejecutivo
A3: Para qué sirve: saber qué partida se está comiendo el margen mientras todavía puedes hacer algo con ella.
A5: Instrucciones de uso
A6: 1. Hoja «Parámetros»: escribe el nombre de tu cocina, elige el tipo de carta y di cuántas partidas (estaciones, en el vocabulario de la matriz de polivalencia del Manual del Manager) tienes activas. Ese número, de 3 a 8, es el que enciende las columnas de la hoja «Semana»: si pones 4, las columnas 5 a 8 se quedan sin encabezado y dejan de avisarte, aunque los totales siguen sumando lo que quede escrito en ellas.
A7: 2. En la misma hoja, escribe el nombre de cada partida, si produce raciones, cuántos kilos de materia prima neta lleva una ración media de esa partida y el objetivo de merma que TÚ te pones. Los kilos por ración son lo que convierte la merma (en kg) y la producción (en raciones) en un porcentaje comparable entre partidas.
A8: 3. Debajo están los demás objetivos de la casa: tiempos de pase, incidencias de alérgenos, horas de cocina por cubierto y platos devueltos y retrabajados. Son celdas verdes y son OBLIGATORIAS: mientras una esté vacía, su semáforo se queda GRIS. Este libro no trae ningún objetivo de referencia del sector porque no existe ninguno publicado.
A9: 4. Hoja «Semana»: una fila por semana ISO. Rellena las celdas verdes con lo que registres en cocina: cubiertos, raciones producidas por partida, kilos de merma por partida, tiempos de pase muestreados, incidencias de alérgenos, horas de cocina trabajadas y platos devueltos y retrabajados.
A10: 5. Las columnas grises las calcula el libro: la merma de cada partida en porcentaje, la merma global, las tasas por cubiertos y el recuento de indicadores fuera de objetivo. La última columna te lo dice con palabras.
A11: 6. Hoja «KPI y Definiciones»: qué mide cada indicador, cómo se calcula, con qué cadencia y cuál es el error típico. Es la hoja que se consulta cuando dos personas dan dos números distintos para lo mismo.
A12: 7. Hoja «Comparativa entre Unidades»: si diriges varias cocinas, elige el mes cerrado que quieres comparar. La primera fila es TU cocina y la calcula el libro desde la hoja «Semana»; las otras cinco las tecleas tú copiando de la hoja «Semana» del libro de cada unidad.
A13: 8. Cadencia de uso: este libro se rellena UNA VEZ POR SEMANA, al cerrar la semana, y se lee en la reunión de cocina de la semana siguiente. La comparativa entre unidades, una vez al mes.
... A17: Qué se copia de dónde (y qué NO hay que volver a teclear)
A18: Producto | B18: Qué te da | C18: Qué no hay que volver a teclear
A19: Manual del Manager de Restaurante | B19: Las 12 personas de la plantilla, las 6 unidades (aquí «partidas»), la matriz de polivalencia y las 52 semanas ISO con sus cubiertos | C19: No vuelvas a teclear la plantilla ni los cubiertos: si ya tienes el Manager, copia y pega de su cuadro semanal
A20: Guía Food Cost + Ingeniería de Menú | B20: La carta de 20 platos, el mix de venta de los 12 de ejemplo y el coste por ración de la ficha de escandallo | C20: El coste por ración de la ficha técnica de proceso se COPIA del escandallo (celda verde); este pack no lo recalcula
A21: Este manual | B21: Producción y merma por partida, tiempos de pase, incidencias de alérgenos, horas de cocina, evaluación técnica, banquetes y auditoría de cocina | C21: Es la capa que no cubre ninguno de los dos anteriores
A22: Es una COPIA declarada, no un vínculo: ningún libro de este pack lee una celda de otro fichero. Si mañana mueves un fichero de carpeta, nada se rompe.
A24: Lo que conviene saber antes de empezar
A25: ESTE LIBRO NO LLEVA NI UNA COLUMNA DE DINERO, y es a propósito. Las ventas, el food cost, el labor cost y el prime cost de la misma semana están en el cuadro de mando semanal del «Manual del Manager de Restaurante». Aquel dice CUÁNTO se ha ido; éste dice EN QUÉ PARTIDA.
A26: La merma que se mide aquí es la merma AGREGADA de cada partida contra lo que esa partida ha producido. El rendimiento de un ingrediente concreto (cuánto queda de un lomo después de limpiarlo) vive en la «Guía Food Cost + Ingeniería de Menú», y la merma por producto y la recepción, en el «Kit de Inventario». No son lo mismo y no se suman.
A27: Los objetivos de este libro son TUYOS. No existe un estándar publicado de KPI de cocina en español: ésta es nuestra lista de indicadores y el porqué de cada uno, pero el número contra el que te mides lo pones tú, con tu carta, tu equipo y tu temporada. Mientras la celda del objetivo esté vacía, el semáforo se queda gris.
A28: La semana ISO empieza en lunes y la semana 1 del año es la que contiene el primer jueves de enero. Por eso la semana 1 de 2026 arranca el lunes 29 de diciembre de 2025: es la convención, no una errata.
A29: La columna «Mes» sirve para cerrar el mes en la comparativa entre unidades. La convención es asignar la semana al mes de su JUEVES, que es la que usa la norma ISO; por eso la semana 14 de 2026 (lunes 30 de marzo) cuenta como abril.
A30: Un dato que falta se deja EN BLANCO, nunca a cero: un cero es una medida («esta semana no hubo ninguna incidencia») y un blanco es la ausencia de medida. El libro los trata distinto y los semáforos ignoran los blancos.
A32: Para editar la estructura o una celda que no este en verde, desprotege la hoja (sin contraseña).
A33: Ruta en Excel: Revisar > Desproteger hoja. La protección no tiene contraseña; sirve para no pisar una fórmula sin querer.
A35: Diseñado por John Guerrero — chef y consultor gastronómico desde 2010 · johnguerrero.es
A36: Versión 1.0 · septiembre 2026 · aichef.pro/manual-chef-ejecutivo · info@aichef.pro

Sheet Parámetros
A1: Parámetros del cuadro de mando de cocina
A2: AI Chef Pro · aichef.pro — Manual del Chef Ejecutivo
A3: Todas las celdas verdes son tuyas. Los objetivos son criterio de la casa, no un estándar del sector.
A4: IDENTIFICACIÓN Y ESCALA
A5: Nombre de la cocina o unidad | B5: Restaurante de ejemplo «La Encina»
A6: Tipo de carta | B6: Carta de temporada con menú del mediodía
A7: Partidas activas (de 3 a 8) | B7: 6
A8: Base de las tasas por cubiertos | B8: 1000
A9: Las partidas activas gobiernan los encabezados de la hoja «Semana»: si escribes 4, las columnas de la 5.ª a la 8.ª partida se quedan sin encabezado y sin semáforo. La lista de abajo es la que da el nombre a cada columna.
A10: La base de las tasas es el número de cubiertos sobre el que se expresan las incidencias de alérgenos y los platos devueltos y retrabajados. Viene en 1.000 cubiertos; si tu cocina es pequeña y prefieres leerlo por cada 100, cámbialo aquí y se recalcula toda la hoja «Semana». Los objetivos de más abajo van en esta misma base.
A11: El nombre de la cocina es el que aparece como unidad de referencia en la hoja «Comparativa entre Unidades».
A13: LAS PARTIDAS DE TU COCINA
A14: Partida | B14: ¿Produce raciones? | C14: Kg de materia prima neta por ración | D14: Objetivo de merma (%) | E14: Qué produce
A15: Pase y caliente | B15: Sí | C15: 0.36 | D15: 0.035 | E15: Principales calientes: plancha, brasa, horno, arroces y salsas del pase
A16: Fríos y entrantes | B16: Sí | C16: 0.22 | D16: 0.055 | E16: Entrantes fríos y calientes de entrada: ensaladas, cazuelas, fritos y raciones
A17: Postres y panadería | B17: Sí | C17: 0.14 | D17: 0.03 | E17: Postres de plato, masas y pan de la casa
A18: Barra y bebidas | B18: Sí | C18: 0.09 | D18: 0.045 | E18: Elaboraciones de barra: zumos naturales, vermut, coctelería y aperitivo
A19: Sala y servicio | B19: No | E19: Servicio de sala: no produce raciones, por eso su columna va vacía
A20: Caja y cierre | B20: No | E20: Caja y cierre: no produce raciones, por eso su columna va vacía
A23: Las dos últimas filas están libres: son las ranuras 7 y 8, para cocinas con más partidas. Escribe el nombre y sube «partidas activas» a 7 u 8.
A24: Una partida que no produce raciones (sala, caja, barra sin elaboración) se deja con «No» y sin kilos por ración: su columna de la hoja «Semana» se queda en blanco y el semáforo la ignora. Existe en la lista porque es una partida de tu organigrama, aunque no produzca.
A25: Los kilos por ración son de MATERIA PRIMA NETA y son una media de la partida, no de un plato. Se miden una vez, pesando lo que entra en una ración media de esa partida, y se revisan al cambiar la carta.
A27: OBJETIVOS DE LA CASA (los demás indicadores)
A28: Indicador | B28: Objetivo | C28: Unidad | D28: Cómo se lee
A29: Tiempo de pase de entrantes | B29: 10 | C29: minutos | D29: Media de los muestreos de la semana, de la comanda a la salida.
A30: Tiempo de pase de principales | B30: 18 | C30: minutos | D30: Un arroz y un postre no compiten en la misma liga: por eso hay tres objetivos y no una media de carta.
A31: Tiempo de pase de postres | B31: 8 | C31: minutos | D31: Se mide igual que los otros dos, y casi siempre es el que más se descuida.
A32: Incidencias de alérgenos por base de cubiertos | B32: 0.5 | C32: incidencias | D32: Cuenta también la que se detecta en el pase y no llega al cliente: ésa es la que te enseña dónde falla el proceso.
A33: Horas de cocina por cubierto | B33: 0.26 | C33: horas | D33: Horas del registro de jornada de la brigada, no las del contrato, y sin meter dentro las de sala.
A34: Platos devueltos por base de cubiertos | B34: 6 | C34: platos | D34: El plato que vuelve de la mesa.
A35: Platos retrabajados por base de cubiertos | B35: 16 | C35: platos | D35: El plato que se rehace ANTES de salir. No se ve en ninguna cuenta y suele ser el que más dinero cuesta.
A36: Platos devueltos y retrabajados (objetivo conjunto) | B36: =IFERROR(IF(OR($B$34="",$B$35=""),"",$B$34+$B$35),"") -> 22 | C36: platos | D36: Lo calcula el libro sumando los dos de arriba: es el que gobierna el semáforo de la hoja «Semana».
A37: ESTOS OBJETIVOS SON DE LA CASA. No existe un estándar publicado de KPI de cocina en español, y este producto no cita ninguno: los números que ves son los del restaurante de ejemplo con el que está montado el pack. Cámbialos por los tuyos antes de leer un solo semáforo.
A38: Si borras un objetivo, su semáforo se queda GRIS en vez de verde o rojo. Es deliberado: el libro no dice «bien» ni «mal» mientras nadie haya decidido qué es bien y qué es mal en esta casa.
A39: Qué cuenta como incidencia de alérgenos: cualquier fallo en la declaración al cliente o en la separación de un alérgeno del Anexo II del Reglamento 1169/2011, se haya servido el plato o no. El cartel de «consulte al personal» no basta por sí solo: hace falta soporte escrito o electrónico accesible. Verificado el 06-09-2026 · Reglamento (UE) 1169/2011, Anexo II y art. 44.1; RD 126/2015 art. 6.5 · https://www.boe.es/buscar/act.php?id=BOE-A-2015-2293
A40: Y también cuenta el utensilio o el recipiente que se ha usado con un alérgeno y se reutiliza sin limpieza comprobada: no es un capítulo propio de alérgenos, es el punto 9 del Capítulo IX del Anexo II del Reglamento 852/2004. Verificado el 06-09-2026 · Reglamento (CE) 852/2004, Anexo II, Cap. IX, punto 9 (redacción del Reglamento 2021/382) · https://eur-lex.europa.eu/legal-content/ES/TXT/HTML/?uri=CELEX:02004R0852-20210324
A41: Las horas de cocina salen del registro diario de jornada, que es obligatorio para toda la plantilla y se conserva cuatro años. Verificado el 06-09-2026 · BOE-A-2015-11430 — Real Decreto Legislativo 2/2015, de 23 de octubre, texto refundido de la Ley del Estatuto de los Trabajadores (texto consolidado), art. 34.9 · https://www.boe.es/eli/es/rdlg/2015/10/23/2/con
A42: LISTAS DE LOS DESPLEGABLES (no borres estas celdas)
A43: Tipos de carta
A44: Carta fija
...

Sheet Semana
A1: Las 52 semanas ISO de la cocina
A2: AI Chef Pro · aichef.pro — Manual del Chef Ejecutivo
A3: Aquí no hay ni una cifra de dinero: eso es el cuadro de mando del Manual del Manager. Aquí está la partida.
A4: Semana ISO | B4: Lunes de la semana | C4: Mes | D4: Cubiertos servidos | E4: =IF($E$61="","","Producción · "&$E$61&" (raciones)") -> Producción · Pase y caliente (raciones) | F4: =IF($F$61="","","Producción · "&$F$61&" (raciones)") -> Producción · Fríos y entrantes (raciones) | G4: =IF($G$61="","","Producción · "&$G$61&" (raciones)") -> Producción · Postres y panadería (raciones) | H4: =IF($H$61="","","Producción · "&$H$61&" (raciones)") -> Producción · Barra y bebidas (raciones) | I4: =IF($I$61="","","Producción · "&$I$61&" (raciones)") -> Producción · Sala y servicio (raciones) | J4: =IF($J$61="","","Producción · "&$J$61&" (raciones)") -> Producción · Caja y cierre (raciones) | K4: =IF($K$61="","","Producción · "&$K$61&" (raciones)") | L4: =IF($L$61="","","Producción · "&$L$61&" (raciones)") | M4: Raciones producidas (total) | N4: =IF($E$61="","","Merma · "&$E$61&" (kg)") -> Merma · Pase y caliente (kg) | O4: =IF($F$61="","","Merma · "&$F$61&" (kg)") -> Merma · Fríos y entrantes (kg) | P4: =IF($G$61="","","Merma · "&$G$61&" (kg)") -> Merma · Postres y panadería (kg) | Q4: =IF($H$61="","","Merma · "&$H$61&" (kg)") -> Merma · Barra y bebidas (kg) | R4: =IF($I$61="","","Merma · "&$I$61&" (kg)") -> Merma · Sala y servicio (kg) | S4: =IF($J$61="","","Merma · "&$J$61&" (kg)") -> Merma · Caja y cierre (kg) | T4: =IF($K$61="","","Merma · "&$K$61&" (kg)") | U4: =IF($L$61="","","Merma · "&$L$61&" (kg)") | V4: Merma total (kg) | W4: =IF($E$61="","","Merma · "&$E$61&" (%)") -> Merma · Pase y caliente (%) | X4: =IF($F$61="","","Merma · "&$F$61&" (%)") -> Merma · Fríos y entrantes (%) | Y4: =IF($G$61="","","Merma · "&$G$61&" (%)") -> Merma · Postres y panadería (%) | Z4: =IF($H$61="","","Merma · "&$H$61&" (%)") -> Merma · Barra y bebidas (%) | AA4: =IF($I$61="","","Merma · "&$I$61&" (%)") -> Merma · Sala y servicio (%) | AB4: =IF($J$61="","","Merma · "&$J$61&" (%)") -> Merma · Caja y cierre (%) | AC4: =IF($K$61="","","Merma · "&$K$61&" (%)") | AD4: =IF($L$61="","","Merma · "&$L$61&" (%)") | AE4: Materia prima producida (kg) | AF4: Merma global de la cocina (%) | AG4: Pase de entrantes (min) | AH4: Pase de principales (min) | AI4: Pase de postres (min) | AJ4: Incidencias de alérgenos | AK4: Gravedad máxima (0 a 3) | AL4: Incidencias por base de cubiertos | AM4: Horas de cocina trabajadas | AN4: Horas de cocina por cubierto | AO4: Platos devueltos | AP4: Platos retrabajados | AQ4: Devueltos y retrabajados por base | AR4: Indicadores fuera de objetivo | AS4: Lectura de la semana
A5: 1 | B5: 46020 | C5: 1 | D5: 829 | E5: 441 | F5: 371 | G5: 233 | H5: 296 | M5: =IF(COUNT($E5:$L5)=0,"",SUM($E5:$L5)) -> 1341 | N5: 5.2 | O5: 3.6 | P5: 0.7 | Q5: 1.1 | V5: =IF(COUNT($N5:$U5)=0,"",SUM($N5:$U5)) -> 10.6 | W5: =IFERROR(IF(OR($N5="",$E5="",$E5=0,E$62="",E$62=0),"",$N5/($E5*E$62)),"") -> 0.032753842 | X5: =IFERROR(IF(OR($O5="",$F5="",$F5=0,F$62="",F$62=0),"",$O5/($F5*F$62)),"") -> 0.044106837 | Y5: =IFERROR(IF(OR($P5="",$G5="",$G5=0,G$62="",G$62=0),"",$P5/($G5*G$62)),"") -> 0.021459227 | Z5: =IFERROR(IF(OR($Q5="",$H5="",$H5=0,H$62="",H$62=0),"",$Q5/($H5*H$62)),"") -> 0.041291291 | AA5: =IFERROR(IF(OR($R5="",$I5="",$I5=0,I$62="",I$62=0),"",$R5/($I5*I$62)),"") | AB5: =IFERROR(IF(OR($S5="",$J5="",$J5=0,J$62="",J$62=0),"",$S5/($J5*J$62)),"") | AC5: =IFERROR(IF(OR($T5="",$K5="",$K5=0,K$62="",K$62=0),"",$T5/($K5*K$62)),"") | AD5: =IFERROR(IF(OR($U5="",$L5="",$L5=0,L$62="",L$62=0),"",$U5/($L5*L$62)),"") | AE5: =IF(SUMPRODUCT($E5:$L5,$E$62:$L$62)=0,"",SUMPRODUCT($E5:$L5,$E$62:$L$62)) -> 299.64 | AF5: =IFERROR(IF(OR($V5="",$AE5="",$AE5=0),"",$V5/$AE5),"") -> 0.035375784 | AG5: 9.8 | AH5: 18.2 | AI5: 6.5 | AJ5: 0 | AK5: 0 | AL5: =IFERROR(IF(OR($AJ5="",$D5="",$D5=0,$M$64=""),"",$AJ5/$D5*$M$64),"") -> 0 | AM5: 198 | AN5: =IFERROR(IF(OR($AM5="",$D5="",$D5=0),"",$AM5/$D5),"") -> 0.23884198 | AO5: 5 | AP5: 9 | AQ5: =IFERROR(IF(OR($AO5="",$AP5="",$D5="",$D5=0,$M$64=""),"",($AO5+$AP5)/$D5*$M$64),"") -> 16.887817 | AR5: =IF(NOT(ISNUMBER($D5)),"",SUMPRODUCT(--(ISNUMBER($W5:$AD5)),--(ISNUMBER($W$63:$AD$63)),--($W5:$AD5>$W$63:$AD$63))+IF(AND(ISNUMBER($AG5),ISNUMBER($AG$63),$AG5>$AG$63),1,0)+IF(AND(ISNUMBER($AH5),ISNUMBER($AH$63),$AH5>$AH$63),1,0)+IF(AND(ISNUMBER($AI5),ISNUMBER($AI$63),$AI5>$AI$63),1,0)+IF(AND(ISNUMBER($AL5),ISNUMBER($AL$63),$AL5>$AL$63),1,0)+IF(AND(ISNUMBER($AN5),ISNUMBER($AN$63),$AN5>$AN$63),1,0)+IF(AND(ISNUMBER($AQ5),ISNUMBER($AQ$63),$AQ5>$AQ$63),1,0)) -> 1 | AS5: =IF(NOT(ISNUMBER($AR5)),"",IF($AR5=0,"Semana en objetivo",IF($AR5=1,"1 indicador fuera de objetivo",$AR5&" indicadores fuera de objetivo"))) -> 1 indicador fuera de objetivo
A6: 2 | B6: 46027 | C6: 1 | D6: 785 | E6: 404 | F6: 339 | G6: 222 | H6: 292 | M6: =IF(COUNT($E6:$L6)=0,"",SUM($E6:$L6)) -> 1257 | N6: 4.3 | O6: 3.6 | P6: 0.8 | Q6: 1.1 | V6: =IF(COUNT($N6:$U6)=0,"",SUM($N6:$U6)) -> 9.8 | W6: =IFERROR(IF(OR($N6="",$E6="",$E6=0,E$62="",E$62=0),"",$N6/($E6*E$62)),"") -> 0.029565457 | X6: =IFERROR(IF(OR($O6="",$F6="",$F6=0,F$62="",F$62=0),"",$O6/($F6*F$62)),"") -> 0.048270314 | Y6: =IFERROR(IF(OR($P6="",$G6="",$G6=0,G$62="",G$62=0),"",$P6/($G6*G$62)),"") -> 0.025740026 | Z6: =IFERROR(IF(OR($Q6="",$H6="",$H6=0,H$62="",H$62=0),"",$Q6/($H6*H$62)),"") -> 0.041856925 | AA6: =IFERROR(IF(OR($R6="",$I6="",$I6=0,I$62="",I$62=0),"",$R6/($I6*I$62)),"") | AB6: =IFERROR(IF(OR($S6="",$J6="",$J6=0,J$62="",J$62=0),"",$S6/($J6*J$62)),"") | AC6: =IFERROR(IF(OR($T6="",$K6="",$K6=0,K$62="",K$62=0),"",$T6/($K6*K$62)),"") | AD6: =IFERROR(IF(OR($U6="",$L6="",$L6=0,L$62="",L$62=0),"",$U6/($L6*L$62)),"") | AE6: =IF(SUMPRODUCT($E6:$L6,$E$62:$L$62)=0,"",SUMPRODUCT($E6:$L6,$E$62:$L$62)) -> 277.38 | AF6: =IFERROR(IF(OR($V6="",$AE6="",$AE6=0),"",$V6/$AE6),"") -> 0.035330593 | AG6: 9.7 | AH6: 16.8 | AI6: 5.6 | AJ6: 0 | AK6: 0 | AL6: =IFERROR(IF(OR($AJ6="",$D6="",$D6=0,$M$64=""),"",$AJ6/$D6*$M$64),"") -> 0 | AM6: 193 | AN6: =IFERROR(IF(OR($AM6="",$D6="",$D6=0),"",$AM6/$D6),"") -> 0.24585987 | AO6: 3 | AP6: 6 | AQ6: =IFERROR(IF(OR($AO6="",$AP6="",$D6="",$D6=0,$M$64=""),"",($AO6+$AP6)/$D6*$M$64),"") -> 11.464968 | AR6: =IF(NOT(ISNUMBER($D6)),"",SUMPRODUCT(--(ISNUMBER($W6:$AD6)),--(ISNUMBER($W$63:$AD$63)),--($W6:$AD6>$W$63:$AD$63))+IF(AND(ISNUMBER($AG6),ISNUMBER($AG$63),$AG6>$AG$63),1,0)+IF(AND(ISNUMBER($AH6),ISNUMBER($AH$63),$AH6>$AH$63),1,0)+IF(AND(ISNUMBER($AI6),ISNUMBER($AI$63),$AI6>$AI$63),1,0)+IF(AND(ISNUMBER($AL6),ISNUMBER($AL$63),$AL6>$AL$63),1,0)+IF(AND(ISNUMBER($AN6),ISNUMBER($AN$63),$AN6>$AN$63),1,0)+IF(AND(ISNUMBER($AQ6),ISNUMBER($AQ$63),$AQ6>$AQ$63),1,0)) -> 0 | AS6: =IF(NOT(ISNUMBER($AR6)),"",IF($AR6=0,"Semana en objetivo",IF($AR6=1,"1 indicador fuera de objetivo",$AR6&" indicadores fuera de objetivo"))) -> Semana en objetivo
A7: 3 | B7: 46034 | C7: 1 | D7: 764 | E7: 385 | F7: 338 | G7: 225 | H7: 286 | M7: =IF(COUNT($E7:$L7)=0,"",SUM($E7:$L7)) -> 1234 | N7: 4.8 | O7: 3.8 | P7: 0.7 | Q7: 0.9 | V7: =IF(COUNT($N7:$U7)=0,"",SUM($N7:$U7)) -> 10.2 | W7: =IFERROR(IF(OR($N7="",$E7="",$E7=0,E$62="",E$62=0),"",$N7/($E7*E$62)),"") -> 0.034632035 | X7: =IFERROR(IF(OR($O7="",$F7="",$F7=0,F$62="",F$62=0),"",$O7/($F7*F$62)),"") -> 0.051102743 | Y7: =IFERROR(IF(OR($P7="",$G7="",$G7=0,G$62="",G$62=0),"",$P7/($G7*G$62)),"") -> 0.022222222 | Z7: =IFERROR(IF(OR($Q7="",$H7="",$H7=0,H$62="",H$62=0),"",$Q7/($H7*H$62)),"") -> 0.034965035 | AA7: =IFERROR(IF(OR($R7="",$I7="",$I7=0,I$62="",I$62=0),"",$R7/($I7*I$62)),"") | AB7: =IFERROR(IF(OR($S7="",$J7="",$J7=0,J$62="",J$62=0),"",$S7/($J7*J$62)),"") | AC7: =IFERROR(IF(OR($T7="",$K7="",$K7=0,K$62="",K$62=0),"",$T7/($K7*K$62)),"") | AD7: =IFERROR(IF(OR($U7="",$L7="",$L7=0,L$62="",L$62=0),"",$U7/($L7*L$62)),"") | AE7: =IF(SUMPRODUCT($E7:$L7,$E$62:$L$62)=0,"",SUMPRODUCT($E7:$L7,$E$62:$L$62)) -> 270.2 | AF7: =IFERROR(IF(OR($V7="",$AE7="",$AE7=0),"",$V7/$AE7),"") -> 0.037749815 | AG7: 8.6 | AH7: 15 | AI7: 5.9 | AJ7: 0 | AK7: 0 | AL7: =IFERROR(IF(OR($AJ7="",$D7="",$D7=0,$M$64=""),"",$AJ7/$D7*$M$64),"") -> 0 | AM7: 190 | AN7: =IFERROR(IF(OR($AM7="",$D7="",$D7=0),"",$AM7/$D7),"") -> 0.2486911 | AO7: 2 | AP7: 6 | AQ7: =IFERROR(IF(OR($AO7="",$AP7="",$D7="",$D7=0,$M$64=""),"",($AO7+$AP7)/$D7*$M$64),"") -> 10.471204 | AR7: =IF(NOT(ISNUMBER($D7)),"",SUMPRODUCT(--(ISNUMBER($W7:$AD7)),--(ISNUMBER($W$63:$AD$63)),--($W7:$AD7>$W$63:$AD$63))+IF(AND(ISNUMBER($AG7),ISNUMBER($AG$63),$AG7>$AG$63),1,0)+IF(AND(ISNUMBER($AH7),ISNUMBER($AH$63),$AH7>$AH$63),1,0)+IF(AND(ISNUMBER($AI7),ISNUMBER($AI$63),$AI7>$AI$63),1,0)+IF(AND(ISNUMBER($AL7),ISNUMBER($AL$63),$AL7>$AL$63),1,0)+IF(AND(ISNUMBER($AN7),ISNUMBER($AN$63),$AN7>$AN$63),1,0)+IF(AND(ISNUMBER($AQ7),ISNUMBER($AQ$63),$AQ7>$AQ$63),1,0)) -> 0 | AS7: =IF(NOT(ISNUMBER($AR7)),"",IF($AR7=0,"Semana en objetivo",IF($AR7=1,"1 indicador fuera de objetivo",$AR7&" indicadores fuera de objetivo"))) -> Semana en objetivo
A8: 4 | B8: 46041 | C8: 1 | D8: 792 | E8: 416 | F8: 361 | G8: 229 | H8: 285 | M8: =IF(COUNT($E8:$L8)=0,"",SUM($E8:$L8)) -> 1291 | N8: 4.7 | O8: 3.5 | P8: 0.8 | Q8: 1.1 | V8: =IF(COUNT($N8:$U8)=0,"",SUM($N8:$U8)) -> 10.1 | W8: =IFERROR(IF(OR($N8="",$E8="",$E8=0,E$62="",E$62=0),"",$N8/($E8*E$62)),"") -> 0.031383547 | X8: =IFERROR(IF(OR($O8="",$F8="",$F8=0,F$62="",F$62=0),"",$O8/($F8*F$62)),"") -> 0.044069504 | Y8: =IFERROR(IF(OR($P8="",$G8="",$G8=0,G$62="",G$62=0),"",$P8/($G8*G$62)),"") -> 0.024953213 | Z8: =IFERROR(IF(OR($Q8="",$H8="",$H8=0,H$62="",H$62=0),"",$Q8/($H8*H$62)),"") -> 0.04288499 | AA8: =IFERROR(IF(OR($R8="",$I8="",$I8=0,I$62="",I$62=0),"",$R8/($I8*I$62)),"") | AB8: =IFERROR(IF(OR($S8="",$J8="",$J8=0,J$62="",J$62=0),"",$S8/($J8*J$62)),"") | AC8: =IFERROR(IF(OR($T8="",$K8="",$K8=0,K$62="",K$62=0),"",$T8/($K8*K$62)),"") | AD8: =IFERROR(IF(OR($U8="",$L8="",$L8=0,L$62="",L$62=0),"",$U8/($L8*L$62)),"") | AE8: =IF(SUMPRODUCT($E8:$L8,$E$62:$L$62)=0,"",SUMPRODUCT($E8:$L8,$E$62:$L$62)) -> 286.89 | AF8: =IFERROR(IF(OR($V8="",$AE8="",$AE8=0),"",$V8/$AE8),"") -> 0.035205131 | AG8: 7.4 | AH8: 13.9 | AI8: 7 | AJ8: 1 | AK8: 1 | AL8: =IFERROR(IF(OR($AJ8="",$D8="",$D8=0,$M$64=""),"",$AJ8/$D8*$M$64),"") -> 1.2626263 | AM8: 193 | AN8: =IFERROR(IF(OR($AM8="",$D8="",$D8=0),"",$AM8/$D8),"") -> 0.24368687 | AO8: 3 | AP8: 9 | AQ8: =IFERROR(IF(OR($AO8="",$AP8="",$D8="",$D8=0,$M$64=""),"",($AO8+$AP8)/$D8*$M$64),"") -> 15.151515 | AR8: =IF(NOT(ISNUMBER($D8)),"",SUMPRODUCT(--(ISNUMBER($W8:$AD8)),--(ISNUMBER($W$63:$AD$63)),--($W8:$AD8>$W$63:$AD$63))+IF(AND(ISNUMBER($AG8),ISNUMBER($AG$63),$AG8>$AG$63),1,0)+IF(AND(ISNUMBER($AH8),ISNUMBER($AH$63),$AH8>$AH$63),1,0)+IF(AND(ISNUMBER($AI8),ISNUMBER($AI$63),$AI8>$AI$63),1,0)+IF(AND(ISNUMBER($AL8),ISNUMBER($AL$63),$AL8>$AL$63),1,0)+IF(AND(ISNUMBER($AN8),ISNUMBER($AN$63),$AN8>$AN$63),1,0)+IF(AND(ISNUMBER($AQ8),ISNUMBER($AQ$63),$AQ8>$AQ$63),1,0)) -> 1 | AS8: =IF(NOT(ISNUMBER($AR8)),"",IF($AR8=0,"Semana en objetivo",IF($AR8=1,"1 indicador fuera de objetivo",$AR8&" indicadores fuera de objetivo"))) -> 1 indicador fuera de objetivo
A9: 5 | B9: 46048 | C9: 1 | D9: 774 | E9: 410 | F9: 342 | G9: 216 | H9: 279 | M9: =IF(COUNT($E9:$L9)=0,"",SUM($E9:$L9)) -> 1247 | N9: 4.5 | O9: 3.9 | P9: 0.8 | Q9: 1 | V9: =IF(COUNT($N9:$U9)=0,"",SUM($N9:$U9)) -> 10.2 | W9: =IFERROR(IF(OR($N9="",$E9="",$E9=0,E$62="",E$62=0),"",$N9/($E9*E$62)),"") -> 0.030487805 | X9: =IFERROR(IF(OR($O9="",$F9="",$F9=0,F$62="",F$62=0),"",$O9/($F9*F$62)),"") -> 0.051834131 | Y9: =IFERROR(IF(OR($P9="",$G9="",$G9=0,G$62="",G$62=0),"",$P9/($G9*G$62)),"") -> 0.026455026 | Z9: =IFERROR(IF(OR($Q9="",$H9="",$H9=0,H$62="",H$62=0),"",$Q9/($H9*H$62)),"") -> 0.039824771 | AA9: =IFERROR(IF(OR($R9="",$I9="",$I9=0,I$62="",I$62=0),"",$R9/($I9*I$62)),"") | AB9: =IFERROR(IF(OR($S9="",$J9="",$J9=0,J$62="",J$62=0),"",$S9/($J9*J$62)),"") | AC9: =IFERROR(IF(OR($T9="",$K9="",$K9=0,K$62="",K$62=0),"",$T9/($K9*K$62)),"") | AD9: =IFERROR(IF(OR($U9="",$L9="",$L9=0,L$62="",L$62=0),"",$U9/($L9*L$62)),"") | AE9: =IF(SUMPRODUCT($E9:$L9,$E$62:$L$62)=0,"",SUMPRODUCT($E9:$L9,$E$62:$L$62)) -> 278.19 | AF9: =IFERROR(IF(OR($V9="",$AE9="",$AE9=0),"",$V9/$AE9),"") -> 0.036665588 | AG9: 6.9 | AH9: 14 | AI9: 7.7 | AJ9: 0 | AK9: 0 | AL9: =IFERROR(IF(OR($AJ9="",$D9="",$D9=0,$M$64=""),"",$AJ9/$D9*$M$64),"") -> 0 | AM9: 193 | AN9: =IFERROR(IF(OR($AM9="",$D9="",$D9=0),"",$AM9/$D9),"") -> 0.24935401 | AO9: 4 | AP9: 10 | AQ9: =IFERROR(IF(OR($AO9="",$AP9="",$D9="",$D9=0,$M$64=""),"",($AO9+$AP9)/$D9*$M$64),"") -> 18.087855 | AR9: =IF(NOT(ISNUMBER($D9)),"",SUMPRODUCT(--(ISNUMBER($W9:$AD9)),--(ISNUMBER($W$63:$AD$63)),--($W9:$AD9>$W$63:$AD$63))+IF(AND(ISNUMBER($AG9),ISNUMBER($AG$63),$AG9>$AG$63),1,0)+IF(AND(ISNUMBER($AH9),ISNUMBER($AH$63),$AH9>$AH$63),1,0)+IF(AND(ISNUMBER($AI9),ISNUMBER($AI$63),$AI9>$AI$63),1,0)+IF(AND(ISNUMBER($AL9),ISNUMBER($AL$63),$AL9>$AL$63),1,0)+IF(AND(ISNUMBER($AN9),ISNUMBER($AN$63),$AN9>$AN$63),1,0)+IF(AND(ISNUMBER($AQ9),ISNUMBER($AQ$63),$AQ9>$AQ$63),1,0)) -> 0 | AS9: =IF(NOT(ISNUMBER($AR9)),"",IF($AR9=0,"Semana en objetivo",IF($AR9=1,"1 indicador fuera de objetivo",$AR9&" indicadores fuera de objetivo"))) -> Semana en objetivo
A10: 6 | B10: 46055 | C10: 2 | D10: 807 | E10: 410 | F10: 348 | G10: 231 | H10: 303 | M10: =IF(COUNT($E10:$L10)=0,"",SUM($E10:$L10)) -> 1292 | N10: 5.1 | O10: 3.7 | P10: 0.7 | Q10: 1 | V10: =IF(COUNT($N10:$U10)=0,"",SUM($N10:$U10)) -> 10.5 | W10: =IFERROR(IF(OR($N10="",$E10="",$E10=0,E$62="",E$62=0),"",$N10/($E10*E$62)),"") -> 0.034552846 | X10: =IFERROR(IF(OR($O10="",$F10="",$F10=0,F$62="",F$62=0),"",$O10/($F10*F$62)),"") -> 0.048328109 | Y10: =IFERROR(IF(OR($P10="",$G10="",$G10=0,G$62="",G$62=0),"",$P10/($G10*G$62)),"") -> 0.021645022 | Z10: =IFERROR(IF(OR($Q10="",$H10="",$H10=0,H$62="",H$62=0),"",$Q10/($H10*H$62)),"") -> 0.036670334 | AA10: =IFERROR(IF(OR($R10="",$I10="",$I10=0,I$62="",I$62=0),"",$R10/($I10*I$62)),"") | AB10: =IFERROR(IF(OR($S10="",$J10="",$J10=0,J$62="",J$62=0),"",$S10/($J10*J$62)),"") | AC10: =IFERROR(IF(OR($T10="",$K10="",$K10=0,K$62="",K$62=0),"",$T10/($K10*K$62)),"") | AD10: =IFERROR(IF(OR($U10="",$L10="",$L10=0,L$62="",L$62=0),"",$U10/($L10*L$62)),"") | AE10: =IF(SUMPRODUCT($E10:$L10,$E$62:$L$62)=0,"",SUMPRODUCT($E10:$L10,$E$62:$L$62)) -> 283.77 | AF10: =IFERROR(IF(OR($V10="",$AE10="",$AE10=0),"",$V10/$AE10),"") -> 0.037001797 | AG10: 7.6 | AH10: 15.3 | AI10: 7.1 | AJ10: 0 | AK10: 0 | AL10: =IFERROR(IF(OR($AJ10="",$D10="",$D10=0,$M$64=""),"",$AJ10/$D10*$M$64),"") -> 0 | AM10: 197 | AN10: =IFERROR(IF(OR($AM10="",$D10="",$D10=0),"",$AM10/$D10),"") -> 0.244114 | AO10: 5 | AP10: 10 | AQ10: =IFERROR(IF(OR($AO10="",$AP10="",$D10="",$D10=0,$M$64=""),"",($AO10+$AP10)/$D10*$M$64),"") -> 18.587361 | AR10: =IF(NOT(ISNUMBER($D10)),"",SUMPRODUCT(--(ISNUMBER($W10:$AD10)),--(ISNUMBER($W$63:$AD$63)),--($W10:$AD10>$W$63:$AD$63))+IF(AND(ISNUMBER($AG10),ISNUMBER($AG$63),$AG10>$AG$63),1,0)+IF(AND(ISNUMBER($AH10),ISNUMBER($AH$63),$AH10>$AH$63),1,0)+IF(AND(ISNUMBER($AI10),ISNUMBER($AI$63),$AI10>$AI$63),1,0)+IF(AND(ISNUMBER($AL10),ISNUMBER($AL$63),$AL10>$AL$63),1,0)+IF(AND(ISNUMBER($AN10),ISNUMBER($AN$63),$AN10>$AN$63),1,0)+IF(AND(ISNUMBER($AQ10),ISNUMBER($AQ$63),$AQ10>$AQ$63),1,0)) -> 0 | AS10: =IF(NOT(ISNUMBER($AR10)),"",IF($AR10=0,"Semana en objetivo",IF($AR10=1,"1 indicador fuera de objetivo",$AR10&" indicadores fuera de objetivo"))) -> Semana en objetivo
A11: 7 | B11: 46062 | C11: 2 | D11: 753 | E11: 383 | F11: 338 | G11: 222 | H11: 279 | M11: =IF(COUNT($E11:$L11)=0,"",SUM($E11:$L11)) -> 1222 | N11: 4.1 | O11: 3.3 | P11: 0.8 | Q11: 1.1 | V11: =IF(COUNT($N11:$U11)=0,"",SUM($N11:$U11)) -> 9.3 | W11: =IFERROR(IF(OR($N11="",$E11="",$E11=0,E$62="",E$62=0),"",$N11/($E11*E$62)),"") -> 0.029736002 | X11: =IFERROR(IF(OR($O11="",$F11="",$F11=0,F$62="",F$62=0),"",$O11/($F11*F$62)),"") -> 0.044378698 | Y11: =IFERROR(IF(OR($P11="",$G11="",$G11=0,G$62="",G$62=0),"",$P11/($G11*G$62)),"") -> 0.025740026 | Z11: =IFERROR(IF(OR($Q11="",$H11="",$H11=0,H$62="",H$62=0),"",$Q11/($H11*H$62)),"") -> 0.043807248 | AA11: =IFERROR(IF(OR($R11="",$I11="",$I11=0,I$62="",I$62=0),"",$R11/($I11*I$62)),"") | AB11: =IFERROR(IF(OR($S11="",$J11="",$J11=0,J$62="",J$62=0),"",$S11/($J11*J$62)),"") | AC11: =IFERROR(IF(OR($T11="",$K11="",$K11=0,K$62="",K$62=0),"",$T11/($K11*K$62)),"") | AD11: =IFERROR(IF(OR($U11="",$L11="",$L11=0,L$62="",L$62=0),"",$U11/($L11*L$62)),"") | AE11: =IF(SUMPRODUCT($E11:$L11,$E$62:$L$62)=0,"",SUMPRODUCT($E11:$L11,$E$62:$L$62)) -> 268.43 | AF11: =IFERROR(IF(OR($V11="",$AE11="",$AE11=0),"",$V11/$AE11),"") -> 0.034645904 | AG11: 13.8 | AH11: 25.6 | AI11: 10.9 | AJ11: 1 | AK11: 3 | AL11: =IFERROR(IF(OR($AJ11="",$D11="",$D11=0,$M$64=""),"",$AJ11/$D11*$M$64),"") -> 1.3280212 | AM11: 193 | AN11: =IFERROR(IF(OR($AM11="",$D11="",$D11=0),"",$AM11/$D11),"") -> 0.2563081 | AO11: 9 | AP11: 19 | AQ11: =IFERROR(IF(OR($AO11="",$AP11="",$D11="",$D11=0,$M$64=""),"",($AO11+$AP11)/$D11*$M$64),"") -> 37.184595 | AR11: =IF(NOT(ISNUMBER($D11)),"",SUMPRODUCT(--(ISNUMBER($W11:$AD11)),--(ISNUMBER($W$63:$AD$63)),--($W11:$AD11>$W$63:$AD$63))+IF(AND(ISNUMBER($AG11),ISNUMBER($AG$63),$AG11>$AG$63),1,0)+IF(AND(ISNUMBER($AH11),ISNUMBER($AH$63),$AH11>$AH$63),1,0)+IF(AND(ISNUMBER($AI11),ISNUMBER($AI$63),$AI11>$AI$63),1,0)+IF(AND(ISNUMBER($AL11),ISNUMBER($AL$63),$AL11>$AL$63),1,0)+IF(AND(ISNUMBER($AN11),ISNUMBER($AN$63),$AN11>$AN$63),1,0)+IF(AND(ISNUMBER($AQ11),ISNUMBER($AQ$63),$AQ11>$AQ$63),1,0)) -> 5 | AS11: =IF(NOT(ISNUMBER($AR11)),"",IF($AR11=0,"Semana en objetivo",IF($AR11=1,"1 indicador fuera de objetivo",$AR11&" indicadores fuera de objetivo"))) -> 5 indicadores fuera de objetivo
A12: 8 | B12: 46069 | C12: 2 | D12: 775 | E12: 411 | F12: 352 | G12: 221 | H12: 277 | M12: =IF(COUNT($E12:$L12)=0,"",SUM($E12:$L12)) -> 1261 | N12: 4.8 | O12: 4 | P12: 0.8 | Q12: 0.9 | V12: =IF(COUNT($N12:$U12)=0,"",SUM($N12:$U12)) -> 10.5 | W12: =IFERROR(IF(OR($N12="",$E12="",$E12=0,E$62="",E$62=0),"",$N12/($E12*E$62)),"") -> 0.0324412 | X12: =IFERROR(IF(OR($O12="",$F12="",$F12=0,F$62="",F$62=0),"",$O12/($F12*F$62)),"") -> 0.051652893 | Y12: =IFERROR(IF(OR($P12="",$G12="",$G12=0,G$62="",G$62=0),"",$P12/($G12*G$62)),"") -> 0.025856496 | Z12: =IFERROR(IF(OR($Q12="",$H12="",$H12=0,H$62="",H$62=0),"",$Q12/($H12*H$62)),"") -> 0.036101083 | AA12: =IFERROR(IF(OR($R12="",$I12="",$I12=0,I$62="",I$62=0),"",$R12/($I12*I$62)),"") | AB12: =IFERROR(IF(OR($S12="",$J12="",$J12=0,J$62="",J$62=0),"",$S12/($J12*J$62)),"") | AC12: =IFERROR(IF(OR($T12="",$K12="",$K12=0,K$62="",K$62=0),"",$T12/($K12*K$62)),"") | AD12: =IFERROR(IF(OR($U12="",$L12="",$L12=0,L$62="",L$62=0),"",$U12/($L12*L$62)),"") | AE12: =IF(SUMPRODUCT($E12:$L12,$E$62:$L$62)=0,"",SUMPRODUCT($E12:$L12,$E$62:$L$62)) -> 281.27 | AF12: =IFERROR(IF(OR($V12="",$AE12="",$AE12=0),"",$V12/$AE12),"") -> 0.037330679 | AG12: 9.8 | AH12: 18.4 | AI12: 5.6 | AJ12: 0 | AK12: 0 | AL12: =IFERROR(IF(OR($AJ12="",$D12="",$D12=0,$M$64=""),"",$AJ12/$D12*$M$64),"") -> 0 | AM12: 196 | AN12: =IFERROR(IF(OR($AM12="",$D12="",$D12=0),"",$AM12/$D12),"") -> 0.25290323 | AO12: 2 | AP12: 6 | AQ12: =IFERROR(IF(OR($AO12="",$AP12="",$D12="",$D12=0,$M$64=""),"",($AO12+$AP12)/$D12*$M$64),"") -> 10.322581 | AR12: =IF(NOT(ISNUMBER($D12)),"",SUMPRODUCT(--(ISNUMBER($W12:$AD12)),--(ISNUMBER($W$63:$AD$63)),--($W12:$AD12>$W$63:$AD$63))+IF(AND(ISNUMBER($AG12),ISNUMBER($AG$63),$AG12>$AG$63),1,0)+IF(AND(ISNUMBER($AH12),ISNUMBER($AH$63),$AH12>$AH$63),1,0)+IF(AND(ISNUMBER($AI12),ISNUMBER($AI$63),$AI12>$AI$63),1,0)+IF(AND(ISNUMBER($AL12),ISNUMBER($AL$63),$AL12>$AL$63),1,0)+IF(AND(ISNUMBER($AN12),ISNUMBER($AN$63),$AN12>$AN$63),1,0)+IF(AND(ISNUMBER($AQ12),ISNUMBER($AQ$63),$AQ12>$AQ$63),1,0)) -> 1 | AS12: =IF(NOT(ISNUMBER($AR12)),"",IF($AR12=0,"Semana en objetivo",IF($AR12=1,"1 indicador fuera de objetivo",$AR12&" indicadores fuera de objetivo"))) -> 1 indicador fuera de objetivo
A13: 9 | B13: 46076 | C13: 2 | D13: 795 | E13: 416 | F13: 346 | G13: 222 | H13: 290 | M13: =IF(COUNT($E13:$L13)=0,"",SUM($E13:$L13)) -> 1274 | N13: 5.1 | O13: 3.5 | P13: 0.7 | Q13: 1 | V13: =IF(COUNT($N13:$U13)=0,"",SUM($N13:$U13)) -> 10.3 | W13: =IFERROR(IF(OR($N13="",$E13="",$E13=0,E$62="",E$62=0),"",$N13/($E13*E$62)),"") -> 0.034054487 | X13: =IFERROR(IF(OR($O13="",$F13="",$F13=0,F$62="",F$62=0),"",$O13/($F13*F$62)),"") -> 0.045980032 | Y13: =IFERROR(IF(OR($P13="",$G13="",$G13=0,G$62="",G$62=0),"",$P13/($G13*G$62)),"") -> 0.022522523 | Z13: =IFERROR(IF(OR($Q13="",$H13="",$H13=0,H$62="",H$62=0),"",$Q13/($H13*H$62)),"") -> 0.038314176 | AA13: =IFERROR(IF(OR($R13="",$I13="",$I13=0,I$62="",I$62=0),"",$R13/($I13*I$62)),"") | AB13: =IFERROR(IF(OR($S13="",$J13="",$J13=0,J$62="",J$62=0),"",$S13/($J13*J$62)),"") | AC13: =IFERROR(IF(OR($T13="",$K13="",$K13=0,K$62="",K$62=0),"",$T13/($K13*K$62)),"") | AD13: =IFERROR(IF(OR($U13="",$L13="",$L13=0,L$62="",L$62=0),"",$U13/($L13*L$62)),"") | AE13: =IF(SUMPRODUCT($E13:$L13,$E$62:$L$62)=0,"",SUMPRODUCT($E13:$L13,$E$62:$L$62)) -> 283.06 | AF13: =IFERROR(IF(OR($V13="",$AE13="",$AE13=0),"",$V13/$AE13),"") -> 0.036388045 | AG13: 9.7 | AH13: 18.5 | AI13: 6.5 | AJ13: 0 | AK13: 0 | AL13: =IFERROR(IF(OR($AJ13="",$D13="",$D13=0,$M$64=""),"",$AJ13/$D13*$M$64),"") -> 0 | AM13: 199 | AN13: =IFERROR(IF(OR($AM13="",$D13="",$D13=0),"",$AM13/$D13),"") -> 0.25031447 | AO13: 3 | AP13: 7 | AQ13: =IFERROR(IF(OR($AO13="",$AP13="",$D13="",$D13=0,$M$64=""),"",($AO13+$AP13)/$D13*$M$64),"") -> 12.578616 | AR13: =IF(NOT(ISNUMBER($D13)),"",SUMPRODUCT(--(ISNUMBER($W13:$AD13)),--(ISNUMBER($W$63:$AD$63)),--($W13:$AD13>$W$63:$AD$63))+IF(AND(ISNUMBER($AG13),ISNUMBER($AG$63),$AG13>$AG$63),1,0)+IF(AND(ISNUMBER($AH13),ISNUMBER($AH$63),$AH13>$AH$63),1,0)+IF(AND(ISNUMBER($AI13),ISNUMBER($AI$63),$AI13>$AI$63),1,0)+IF(AND(ISNUMBER($AL13),ISNUMBER($AL$63),$AL13>$AL$63),1,0)+IF(AND(ISNUMBER($AN13),ISNUMBER($AN$63),$AN13>$AN$63),1,0)+IF(AND(ISNUMBER($AQ13),ISNUMBER($AQ$63),$AQ13>$AQ$63),1,0)) -> 1 | AS13: =IF(NOT(ISNUMBER($AR13)),"",IF($AR13=0,"Semana en objetivo",IF($AR13=1,"1 indicador fuera de objetivo",$AR13&" indicadores fuera de objetivo"))) -> 1 indicador fuera de objetivo
A14: 10 | B14: 46083 | C14: 3 | D14: 776 | E14: 391 | F14: 338 | G14: 226 | H14: 292 | M14: =IF(COUNT($E14:$L14)=0,"",SUM($E14:$L14)) -> 1247 | N14: 4.1 | O14: 3.5 | P14: 0.8 | Q14: 1.1 | V14: =IF(COUNT($N14:$U14)=0,"",SUM($N14:$U14)) -> 9.5 | W14: =IFERROR(IF(OR($N14="",$E14="",$E14=0,E$62="",E$62=0),"",$N14/($E14*E$62)),"") -> 0.029127593 | X14: =IFERROR(IF(OR($O14="",$F14="",$F14=0,F$62="",F$62=0),"",$O14/($F14*F$62)),"") -> 0.047068316 | Y14: =IFERROR(IF(OR($P14="",$G14="",$G14=0,G$62="",G$62=0),"",$P14/($G14*G$62)),"") -> 0.02528445 | Z14: =IFERROR(IF(OR($Q14="",$H14="",$H14=0,H$62="",H$62=0),"",$Q14/($H14*H$62)),"") -> 0.041856925 | AA14: =IFERROR(IF(OR($R14="",$I14="",$I14=0,I$62="",I$62=0),"",$R14/($I14*I$62)),"") | AB14: =IFERROR(IF(OR($S14="",$J14="",$J14=0,J$62="",J$62=0),"",$S14/($J14*J$62)),"") | AC14: =IFERROR(IF(OR($T14="",$K14="",$K14=0,K$62="",K$62=0),"",$T14/($K14*K$62)),"") | AD14: =IFERROR(IF(OR($U14="",$L14="",$L14=0,L$62="",L$62=0),"",$U14/($L14*L$62)),"") | AE14: =IF(SUMPRODUCT($E14:$L14,$E$62:$L$62)=0,"",SUMPRODUCT($E14:$L14,$E$62:$L$62)) -> 273.04 | AF14: =IFERROR(IF(OR($V14="",$AE14="",$AE14=0),"",$V14/$AE14),"") -> 0.034793437 | AG14: 8.6 | AH14: 17.4 | AI14: 7.5 | AJ14: 0 | AK14: 0 | AL14: =IFERROR(IF(OR($AJ14="",$D14="",$D14=0,$M$64=""),"",$AJ14/$D14*$M$64),"") -> 0 | AM14: 217 | AN14: =IFERROR(IF(OR($AM14="",$D14="",$D14=0),"",$AM14/$D14),"") -> 0.27963918 | AO14: 4 | AP14: 9 | AQ14: =IFERROR(IF(OR($AO14="",$AP14="",$D14="",$D14=0,$M$64=""),"",($AO14+$AP14)/$D14*$M$64),"") -> 16.752577 | AR14: =IF(NOT(ISNUMBER($D14)),"",SUMPRODUCT(--(ISNUMBER($W14:$AD14)),--(ISNUMBER($W$63:$AD$63)),--($W14:$AD14>$W$63:$AD$63))+IF(AND(ISNUMBER($AG14),ISNUMBER($AG$63),$AG14>$AG$63),1,0)+IF(AND(ISNUMBER($AH14),ISNUMBER($AH$63),$AH14>$AH$63),1,0)+IF(AND(ISNUMBER($AI14),ISNUMBER($AI$63),$AI14>$AI$63),1,0)+IF(AND(ISNUMBER($AL14),ISNUMBER($AL$63),$AL14>$AL$63),1,0)+IF(AND(ISNUMBER($AN14),ISNUMBER($AN$63),$AN14>$AN$63),1,0)+IF(AND(ISNUMBER($AQ14),ISNUMBER($AQ$63),$AQ14>$AQ$63),1,0)) -> 1 | AS14: =IF(NOT(ISNUMBER($AR14)),"",IF($AR14=0,"Semana en objetivo",IF($AR14=1,"1 indicador fuera de objetivo",$AR14&" indicadores fuera de objetivo"))) -> 1 indicador fuera de objetivo
A15: 11 | B15: 46090 | C15: 3 | D15: 802 | E15: 414 | F15: 364 | G15: 236 | H15: 293 | M15: =IF(COUNT($E15:$L15)=0,"",SUM($E15:$L15)) -> 1307 | N15: 5 | O15: 4.1 | P15: 0.8 | Q15: 1 | V15: =IF(COUNT($N15:$U15)=0,"",SUM($N15:$U15)) -> 10.9 | W15: =IFERROR(IF(OR($N15="",$E15="",$E15=0,E$62="",E$62=0),"",$N15/($E15*E$62)),"") -> 0.033548041 | X15: =IFERROR(IF(OR($O15="",$F15="",$F15=0,F$62="",F$62=0),"",$O15/($F15*F$62)),"") -> 0.051198801 | Y15: =IFERROR(IF(OR($P15="",$G15="",$G15=0,G$62="",G$62=0),"",$P15/($G15*G$62)),"") -> 0.024213075 | Z15: =IFERROR(IF(OR($Q15="",$H15="",$H15=0,H$62="",H$62=0),"",$Q15/($H15*H$62)),"") -> 0.037921881 | AA15: =IFERROR(IF(OR($R15="",$I15="",$I15=0,I$62="",I$62=0),"",$R15/($I15*I$62)),"") | AB15: =IFERROR(IF(OR($S15="",$J15="",$J15=0,J$62="",J$62=0),"",$S15/($J15*J$62)),"") | AC15: =IFERROR(IF(OR($T15="",$K15="",$K15=0,K$62="",K$62=0),"",$T15/($K15*K$62)),"") | AD15: =IFERROR(IF(OR($U15="",$L15="",$L15=0,L$62="",L$62=0),"",$U15/($L15*L$62)),"") | AE15: =IF(SUMPRODUCT($E15:$L15,$E$62:$L$62)=0,"",SUMPRODUCT($E15:$L15,$E$62:$L$62)) -> 288.53 | AF15: =IFERROR(IF(OR($V15="",$AE15="",$AE15=0),"",$V15/$AE15),"") -> 0.037777701 | AG15: 7.4 | AH15: 15.7 | AI15: 7.5 | AJ15: 0 | AK15: 0 | AL15: =IFERROR(IF(OR($AJ15="",$D15="",$D15=0,$M$64=""),"",$AJ15/$D15*$M$64),"") -> 0 | AM15: 219 | AN15: =IFERROR(IF(OR($AM15="",$D15="",$D15=0),"",$AM15/$D15),"") -> 0.27306733 | AO15: 4 | AP15: 11 | AQ15: =IFERROR(IF(OR($AO15="",$AP15="",$D15="",$D15=0,$M$64=""),"",($AO15+$AP15)/$D15*$M$64),"") -> 18.703242 | AR15: =IF(NOT(ISNUMBER($D15)),"",SUMPRODUCT(--(ISNUMBER($W15:$AD15)),--(ISNUMBER($W$63:$AD$63)),--($W15:$AD15>$W$63:$AD$63))+IF(AND(ISNUMBER($AG15),ISNUMBER($AG$63),$AG15>$AG$63),1,0)+IF(AND(ISNUMBER($AH15),ISNUMBER($AH$63),$AH15>$AH$63),1,0)+IF(AND(ISNUMBER($AI15),ISNUMBER($AI$63),$AI15>$AI$63),1,0)+IF(AND(ISNUMBER($AL15),ISNUMBER($AL$63),$AL15>$AL$63),1,0)+IF(AND(ISNUMBER($AN15),ISNUMBER($AN$63),$AN15>$AN$63),1,0)+IF(AND(ISNUMBER($AQ15),ISNUMBER($AQ$63),$AQ15>$AQ$63),1,0)) -> 1 | AS15: =IF(NOT(ISNUMBER($AR15)),"",IF($AR15=0,"Semana en objetivo",IF($AR15=1,"1 indicador fuera de objetivo",$AR15&" indicadores fuera de objetivo"))) -> 1 indicador fuera de objetivo
A16: 12 | B16: 46097 | C16: 3 | D16: 824 | E16: 439 | F16: 370 | G16: 232 | H16: 294 | M16: =IF(COUNT($E16:$L16)=0,"",SUM($E16:$L16)) -> 1335 | N16: 5.1 | O16: 3.6 | P16: 0.7 | Q16: 1.1 | V16: =IF(COUNT($N16:$U16)=0,"",SUM($N16:$U16)) -> 10.5 | W16: =IFERROR(IF(OR($N16="",$E16="",$E16=0,E$62="",E$62=0),"",$N16/($E16*E$62)),"") -> 0.032270311 | X16: =IFERROR(IF(OR($O16="",$F16="",$F16=0,F$62="",F$62=0),"",$O16/($F16*F$62)),"") -> 0.044226044 | Y16: =IFERROR(IF(OR($P16="",$G16="",$G16=0,G$62="",G$62=0),"",$P16/($G16*G$62)),"") -> 0.021551724 | Z16: =IFERROR(IF(OR($Q16="",$H16="",$H16=0,H$62="",H$62=0),"",$Q16/($H16*H$62)),"") -> 0.041572184 | AA16: =IFERROR(IF(OR($R16="",$I16="",$I16=0,I$62="",I$62=0),"",$R16/($I16*I$62)),"") | AB16: =IFERROR(IF(OR($S16="",$J16="",$J16=0,J$62="",J$62=0),"",$S16/($J16*J$62)),"") | AC16: =IFERROR(IF(OR($T16="",$K16="",$K16=0,K$62="",K$62=0),"",$T16/($K16*K$62)),"") | AD16: =IFERROR(IF(OR($U16="",$L16="",$L16=0,L$62="",L$62=0),"",$U16/($L16*L$62)),"") | AE16: =IF(SUMPRODUCT($E16:$L16,$E$62:$L$62)=0,"",SUMPRODUCT($E16:$L16,$E$62:$L$62)) -> 298.38 | AF16: =IFERROR(IF(OR($V16="",$AE16="",$AE16=0),"",$V16/$AE16),"") -> 0.035190026 | AG16: 6.9 | AH16: 14.2 | AI16: 6.4 | AJ16: 1 | AK16: 2 | AL16: =IFERROR(IF(OR($AJ16="",$D16="",$D16=0,$M$64=""),"",$AJ16/$D16*$M$64),"") -> 1.2135922 | AM16: 220 | AN16: =IFERROR(IF(OR($AM16="",$D16="",$D16=0),"",$AM16/$D16),"") -> 0.26699029 | AO16: 3 | AP16: 10 | AQ16: =IFERROR(IF(OR($AO16="",$AP16="",$D16="",$D16=0,$M$64=""),"",($AO16+$AP16)/$D16*$M$64),"") -> 15.776699 | AR16: =IF(NOT(ISNUMBER($D16)),"",SUMPRODUCT(--(ISNUMBER($W16:$AD16)),--(ISNUMBER($W$63:$AD$63)),--($W16:$AD16>$W$63:$AD$63))+IF(AND(ISNUMBER($AG16),ISNUMBER($AG$63),$AG16>$AG$63),1,0)+IF(AND(ISNUMBER($AH16),ISNUMBER($AH$63),$AH16>$AH$63),1,0)+IF(AND(ISNUMBER($AI16),ISNUMBER($AI$63),$AI16>$AI$63),1,0)+IF(AND(ISNUMBER($AL16),ISNUMBER($AL$63),$AL16>$AL$63),1,0)+IF(AND(ISNUMBER($AN16),ISNUMBER($AN$63),$AN16>$AN$63),1,0)+IF(AND(ISNUMBER($AQ16),ISNUMBER($AQ$63),$AQ16>$AQ$63),1,0)) -> 2 | AS16: =IF(NOT(ISNUMBER($AR16)),"",IF($AR16=0,"Semana en objetivo",IF($AR16=1,"1 indicador fuera de objetivo",$AR16&" indicadores fuera de objetivo"))) -> 2 indicadores fuera de objetivo
... A56: 52 | B56: 46377 | C56: 12 | D56: 1140 | E56: 597 | F56: 520 | G56: 331 | H56: 411 | M56: =IF(COUNT($E56:$L56)=0,"",SUM($E56:$L56)) -> 1859 | N56: 7.3 | O56: 5.9 | P56: 1.1 | Q56: 1.4 | V56: =IF(COUNT($N56:$U56)=0,"",SUM($N56:$U56)) -> 15.7 | W56: =IFERROR(IF(OR($N56="",$E56="",$E56=0,E$62="",E$62=0),"",$N56/($E56*E$62)),"") -> 0.033966127 | X56: =IFERROR(IF(OR($O56="",$F56="",$F56=0,F$62="",F$62=0),"",$O56/($F56*F$62)),"") -> 0.051573427 | Y56: =IFERROR(IF(OR($P56="",$G56="",$G56=0,G$62="",G$62=0),"",$P56/($G56*G$62)),"") -> 0.023737592 | Z56: =IFERROR(IF(OR($Q56="",$H56="",$H56=0,H$62="",H$62=0),"",$Q56/($H56*H$62)),"") -> 0.037848067 | AA56: =IFERROR(IF(OR($R56="",$I56="",$I56=0,I$62="",I$62=0),"",$R56/($I56*I$62)),"") | AB56: =IFERROR(IF(OR($S56="",$J56="",$J56=0,J$62="",J$62=0),"",$S56/($J56*J$62)),"") | AC56: =IFERROR(IF(OR($T56="",$K56="",$K56=0,K$62="",K$62=0),"",$T56/($K56*K$62)),"") | AD56: =IFERROR(IF(OR($U56="",$L56="",$L56=0,L$62="",L$62=0),"",$U56/($L56*L$62)),"") | AE56: =IF(SUMPRODUCT($E56:$L56,$E$62:$L$62)=0,"",SUMPRODUCT($E56:$L56,$E$62:$L$62)) -> 412.65 | AF56: =IFERROR(IF(OR($V56="",$AE56="",$AE56=0),"",$V56/$AE56),"") -> 0.038046771 | AG56: 8.4 | AH56: 17.2 | AI56: 5.7 | AJ56: 0 | AK56: 0 | AL56: =IFERROR(IF(OR($AJ56="",$D56="",$D56=0,$M$64=""),"",$AJ56/$D56*$M$64),"") -> 0 | AM56: 228 | AN56: =IFERROR(IF(OR($AM56="",$D56="",$D56=0),"",$AM56/$D56),"") -> 0.2 | AO56: 4 | AP56: 13 | AQ56: =IFERROR(IF(OR($AO56="",$AP56="",$D56="",$D56=0,$M$64=""),"",($AO56+$AP56)/$D56*$M$64),"") -> 14.912281 | AR56: =IF(NOT(ISNUMBER($D56)),"",SUMPRODUCT(--(ISNUMBER($W56:$AD56)),--(ISNUMBER($W$63:$AD$63)),--($W56:$AD56>$W$63:$AD$63))+IF(AND(ISNUMBER($AG56),ISNUMBER($AG$63),$AG56>$AG$63),1,0)+IF(AND(ISNUMBER($AH56),ISNUMBER($AH$63),$AH56>$AH$63),1,0)+IF(AND(ISNUMBER($AI56),ISNUMBER($AI$63),$AI56>$AI$63),1,0)+IF(AND(ISNUMBER($AL56),ISNUMBER($AL$63),$AL56>$AL$63),1,0)+IF(AND(ISNUMBER($AN56),ISNUMBER($AN$63),$AN56>$AN$63),1,0)+IF(AND(ISNUMBER($AQ56),ISNUMBER($AQ$63),$AQ56>$AQ$63),1,0)) -> 0 | AS56: =IF(NOT(ISNUMBER($AR56)),"",IF($AR56=0,"Semana en objetivo",IF($AR56=1,"1 indicador fuera de objetivo",$AR56&" indicadores fuera de objetivo"))) -> Semana en objetivo
A57: TOTAL / MEDIA | D57: =IF(COUNT(D5:D56)=0,"",SUM(D5:D56)) -> 46737 | E57: =IF(COUNT(E5:E56)=0,"",SUM(E5:E56)) -> 24209 | F57: =IF(COUNT(F5:F56)=0,"",SUM(F5:F56)) -> 20738 | G57: =IF(COUNT(G5:G56)=0,"",SUM(G5:G56)) -> 13421 | H57: =IF(COUNT(H5:H56)=0,"",SUM(H5:H56)) -> 17132 | I57: =IF(COUNT(I5:I56)=0,"",SUM(I5:I56)) | J57: =IF(COUNT(J5:J56)=0,"",SUM(J5:J56)) | K57: =IF(COUNT(K5:K56)=0,"",SUM(K5:K56)) | ... V57: =IF(COUNT(V5:V56)=0,"",SUM(V5:V56)) -> 616.9 | W57: =IFERROR(IF(OR($N57="",$E57="",$E57=0,E$62="",E$62=0),"",$N57/($E57*E$62)),"") -> 0.032001414 | X57: =IFERROR(IF(OR($O57="",$F57="",$F57=0,F$62="",F$62=0),"",$O57/($F57*F$62)),"") -> 0.050653609 | Y57: =IFERROR(IF(OR($P57="",$G57="",$G57=0,G$62="",G$62=0),"",$P57/($G57*G$62)),"") -> 0.024215781 | Z57: =IFERROR(IF(OR($Q57="",$H57="",$H57=0,H$62="",H$62=0),"",$Q57/($H57*H$62)),"") -> 0.039821517 | AA57: =IFERROR(IF(OR($R57="",$I57="",$I57=0,I$62="",I$62=0),"",$R57/($I57*I$62)),"") | AB57: =IFERROR(IF(OR($S57="",$J57="",$J57=0,J$62="",J$62=0),"",$S57/($J57*J$62)),"") | AC57: =IFERROR(IF(OR($T57="",$K57="",$K57=0,K$62="",K$62=0),"",$T57/($K57*K$62)),"") | AD57: =IFERROR(IF(OR($U57="",$L57="",$L57=0,L$62="",L$62=0),"",$U57/($L57*L$62)),"") | AE57: =IF(COUNT(AE5:AE56)=0,"",SUM(AE5:AE56)) -> 16698.42 | AF57: =IFERROR(IF(OR($V$57="",$AE$57="",$AE$57=0),"",$V$57/$AE$57),"") -> 0.036943615 | AG57: =IF(COUNT(AG5:AG56)=0,"",AVERAGE(AG5:AG56)) -> 8.6230769 | AH57: =IF(COUNT(AH5:AH56)=0,"",AVERAGE(AH5:AH56)) -> 16.519231 | AI57: =IF(COUNT(AI5:AI56)=0,"",AVERAGE(AI5:AI56)) -> 6.6634615 | AJ57: =IF(COUNT(AJ5:AJ56)=0,"",SUM(AJ5:AJ56)) -> 15 | AK57: =IF(COUNT(AK5:AK56)=0,"",MAX(AK5:AK56)) -> 3 | AL57: =IFERROR(IF(OR($AJ$57="",$D$57="",$D$57=0,$M$64=""),"",$AJ$57/$D$57*$M$64),"") -> 0.32094486 | AM57: =IF(COUNT(AM5:AM56)=0,"",SUM(AM5:AM56)) -> 11586 | AN57: =IFERROR(IF(OR($AM$57="",$D$57="",$D$57=0),"",$AM$57/$D$57),"") -> 0.24789781 | AO57: =IF(COUNT(AO5:AO56)=0,"",SUM(AO5:AO56)) -> 221 | AP57: =IF(COUNT(AP5:AP56)=0,"",SUM(AP5:AP56)) -> 516 | AQ57: =IFERROR(IF(OR($AO$57="",$AP$57="",$D$57="",$D$57=0,$M$64=""),"",($AO$57+$AP$57)/$D$57*$M$64),"") -> 15.769091 | AR57: =IF(NOT(ISNUMBER($D57)),"",SUMPRODUCT(--(ISNUMBER($W57:$AD57)),--(ISNUMBER($W$63:$AD$63)),--($W57:$AD57>$W$63:$AD$63))+IF(AND(ISNUMBER($AG57),ISNUMBER($AG$63),$AG57>$AG$63),1,0)+IF(AND(ISNUMBER($AH57),ISNUMBER($AH$63),$AH57>$AH$63),1,0)+IF(AND(ISNUMBER($AI57),ISNUMBER($AI$63),$AI57>$AI$63),1,0)+IF(AND(ISNUMBER($AL57),ISNUMBER($AL$63),$AL57>$AL$63),1,0)+IF(AND(ISNUMBER($AN57),ISNUMBER($AN$63),$AN57>$AN$63),1,0)+IF(AND(ISNUMBER($AQ57),ISNUMBER($AQ$63),$AQ57>$AQ$63),1,0)) -> 0 | AS57: =IF(NOT(ISNUMBER($AR$57)),"",IF($AR$57=0,"Año en objetivo",IF($AR$57=1,"1 indicador fuera de objetivo en el año",$AR$57&" indicadores fuera de objetivo en el año"))) -> Año en objetivo
A58: En la fila TOTAL los porcentajes NO son la media de los 52 porcentajes: la merma del año es la merma en kilos del año dividida entre los kilos producidos del año, que es la media ponderada y la única correcta. Los tiempos de pase sí son una media simple de las semanas medidas, porque cada semana aporta su propio muestreo.
A59: Y ojo con leer sólo esta fila: el año puede cerrar en objetivo con semanas malas dentro. En el restaurante de ejemplo el año entero entra en objetivo y aun así hay cuatro semanas fuera (la 7, por el pase, y la 33, la 34 y la 35, por la merma de la partida de fríos). Por eso este libro se mira por semanas y no por medias del año.
A60: PARÁMETROS EN VIGOR — se leen de la hoja «Parámetros»; cámbialos allí, no aquí
A61: Partida activa | E61: =IFERROR(IF(1>Parámetros!$B$7,"",IF(INDEX(Parámetros!$A$15:$A$22,1)=0,"",INDEX(Parámetros!$A$15:$A$22,1))),"") -> Pase y caliente | F61: =IFERROR(IF(2>Parámetros!$B$7,"",IF(INDEX(Parámetros!$A$15:$A$22,2)=0,"",INDEX(Parámetros!$A$15:$A$22,2))),"") -> Fríos y entrantes | G61: =IFERROR(IF(3>Parámetros!$B$7,"",IF(INDEX(Parámetros!$A$15:$A$22,3)=0,"",INDEX(Parámetros!$A$15:$A$22,3))),"") -> Postres y panadería | H61: =IFERROR(IF(4>Parámetros!$B$7,"",IF(INDEX(Parámetros!$A$15:$A$22,4)=0,"",INDEX(Parámetros!$A$15:$A$22,4))),"") -> Barra y bebidas | I61: =IFERROR(IF(5>Parámetros!$B$7,"",IF(INDEX(Parámetros!$A$15:$A$22,5)=0,"",INDEX(Parámetros!$A$15:$A$22,5))),"") -> Sala y servicio | J61: =IFERROR(IF(6>Parámetros!$B$7,"",IF(INDEX(Parámetros!$A$15:$A$22,6)=0,"",INDEX(Parámetros!$A$15:$A$22,6))),"") -> Caja y cierre | K61: =IFERROR(IF(7>Parámetros!$B$7,"",IF(INDEX(Parámetros!$A$15:$A$22,7)=0,"",INDEX(Parámetros!$A$15:$A$22,7))),"") | L61: =IFERROR(IF(8>Parámetros!$B$7,"",IF(INDEX(Parámetros!$A$15:$A$22,8)=0,"",INDEX(Parámetros!$A$15:$A$22,8))),"")
A62: Kg de materia prima por ración | E62: =IFERROR(IF(1>Parámetros!$B$7,"",IF(INDEX(Parámetros!$C$15:$C$22,1)=0,"",INDEX(Parámetros!$C$15:$C$22,1))),"") -> 0.36 | F62: =IFERROR(IF(2>Parámetros!$B$7,"",IF(INDEX(Parámetros!$C$15:$C$22,2)=0,"",INDEX(Parámetros!$C$15:$C$22,2))),"") -> 0.22 | G62: =IFERROR(IF(3>Parámetros!$B$7,"",IF(INDEX(Parámetros!$C$15:$C$22,3)=0,"",INDEX(Parámetros!$C$15:$C$22,3))),"") -> 0.14 | H62: =IFERROR(IF(4>Parámetros!$B$7,"",IF(INDEX(Parámetros!$C$15:$C$22,4)=0,"",INDEX(Parámetros!$C$15:$C$22,4))),"") -> 0.09 | I62: =IFERROR(IF(5>Parámetros!$B$7,"",IF(INDEX(Parámetros!$C$15:$C$22,5)=0,"",INDEX(Parámetros!$C$15:$C$22,5))),"") | J62: =IFERROR(IF(6>Parámetros!$B$7,"",IF(INDEX(Parámetros!$C$15:$C$22,6)=0,"",INDEX(Parámetros!$C$15:$C$22,6))),"") | K62: =IFERROR(IF(7>Parámetros!$B$7,"",IF(INDEX(Parámetros!$C$15:$C$22,7)=0,"",INDEX(Parámetros!$C$15:$C$22,7))),"") | L62: =IFERROR(IF(8>Parámetros!$B$7,"",IF(INDEX(Parámetros!$C$15:$C$22,8)=0,"",INDEX(Parámetros!$C$15:$C$22,8))),"")
A63: Objetivo de la casa | W63: =IFERROR(IF(1>Parámetros!$B$7,"",IF(INDEX(Parámetros!$D$15:$D$22,1)=0,"",INDEX(Parámetros!$D$15:$D$22,1))),"") -> 0.035 | X63: =IFERROR(IF(2>Parámetros!$B$7,"",IF(INDEX(Parámetros!$D$15:$D$22,2)=0,"",INDEX(Parámetros!$D$15:$D$22,2))),"") -> 0.055 | Y63: =IFERROR(IF(3>Parámetros!$B$7,"",IF(INDEX(Parámetros!$D$15:$D$22,3)=0,"",INDEX(Parámetros!$D$15:$D$22,3))),"") -> 0.03 | Z63: =IFERROR(IF(4>Parámetros!$B$7,"",IF(INDEX(Parámetros!$D$15:$D$22,4)=0,"",INDEX(Parámetros!$D$15:$D$22,4))),"") -> 0.045 | AA63: =IFERROR(IF(5>Parámetros!$B$7,"",IF(INDEX(Parámetros!$D$15:$D$22,5)=0,"",INDEX(Parámetros!$D$15:$D$22,5))),"") | AB63: =IFERROR(IF(6>Parámetros!$B$7,"",IF(INDEX(Parámetros!$D$15:$D$22,6)=0,"",INDEX(Parámetros!$D$15:$D$22,6))),"") | AC63: =IFERROR(IF(7>Parámetros!$B$7,"",IF(INDEX(Parámetros!$D$15:$D$22,7)=0,"",INDEX(Parámetros!$D$15:$D$22,7))),"") | AD63: =IFERROR(IF(8>Parámetros!$B$7,"",IF(INDEX(Parámetros!$D$15:$D$22,8)=0,"",INDEX(Parámetros!$D$15:$D$22,8))),"") | AG63: =IF(Parámetros!$B$29="","",Parámetros!$B$29) -> 10 | AH63: =IF(Parámetros!$B$30="","",Parámetros!$B$30) -> 18 | AI63: =IF(Parámetros!$B$31="","",Parámetros!$B$31) -> 8 | AL63: =IF(Parámetros!$B$32="","",Parámetros!$B$32) -> 0.5 | AN63: =IF(Parámetros!$B$33="","",Parámetros!$B$33) -> 0.26 | AQ63: =IF(Parámetros!$B$36="","",Parámetros!$B$36) -> 22
A64: Base de las tasas por cubiertos | M64: =IF(Parámetros!$B$8="","",Parámetros!$B$8) -> 1000
A65: Partidas activas | M65: =IF(Parámetros!$B$7="","",Parámetros!$B$7) -> 6
A67: Este bloque es un espejo de la hoja «Parámetros». Está aquí porque el formato condicional no puede leer otra hoja sin usar INDIRECT, que esta familia de libros tiene prohibida por frágil.

Sheet KPI y Definiciones
A1: Los siete KPI de cocina
A2: AI Chef Pro · aichef.pro — Manual del Chef Ejecutivo
A3: No existe un estándar publicado de KPI de cocina en español. Ésta es nuestra lista: por qué cada uno y cuál es su error típico. El objetivo lo pones tú.
A4: Indicador | B4: Cómo se calcula | C4: Unidad | D4: Error típico | E4: Cadencia | F4: Objetivo de la casa | G4: De dónde sale el dato
A5: Merma por partida | B5: Merma de la partida (kg) / (raciones producidas x kg por ración de esa partida) | C5: % | D5: Mirar la merma total de la cocina en vez de la de cada partida: la de una partida se compensa con la de otra y el problema no aparece nunca | E5: Semanal | F5: Uno por partida | G5: Semana, columnas «Merma · <partida> (%)»
A6: Tiempo de pase por familia de plato | B6: Media de los tiempos muestreados entre comanda y salida, separando entrantes, principales y postres | C6: minutos | D6: Dar una sola media para toda la carta: un postre y un arroz no compiten en la misma liga y la media los esconde a los dos | E6: Semanal | F6: Tres, uno por familia | G6: Semana, columnas «Pase de entrantes / principales / postres»
A7: Incidencias de alérgenos por 1.000 cubiertos | B7: Incidencias registradas x 1.000 / cubiertos servidos | C7: incidencias/1.000 | D7: Contar solo las que llegaron al cliente: la que se detecta en el pase es la que te dice dónde está el fallo del proceso | E7: Semanal | F7: =IF(Parámetros!$B$32="","",Parámetros!$B$32) -> 0.5 | G7: Semana, columna «Incidencias por base de cubiertos»
A8: Horas de cocina por cubierto | B8: Horas realmente trabajadas por la brigada / cubiertos servidos | C8: h/cubierto | D8: Alimentarlo con las horas del contrato en lugar de las del registro de jornada, y meter dentro las horas de sala | E8: Semanal | F8: =IF(Parámetros!$B$33="","",Parámetros!$B$33) -> 0.26 | G8: Semana, columna «Horas de cocina por cubierto»
A9: Cumplimiento de ficha técnica | B9: Muestreos conformes con la ficha / muestreos hechos en el pase | C9: % | D9: Preguntar «tenemos ficha?» en vez de «se ha seguido?»: tener la ficha escrita no es cumplirla | E9: Semanal | F9: No se mide en este libro | G9: No se mide aquí: hoja «Control de Calidad del Pase» del libro de desarrollo de carta
A10: Platos devueltos y retrabajados por 1.000 cubiertos | B10: (Devueltos + retrabajados) x 1.000 / cubiertos servidos | C10: platos/1.000 | D10: Registrar solo la devolución del cliente: el plato que se rehace antes de salir no se ve en la cuenta y es el que más dinero cuesta | E10: Semanal | F10: =IF(Parámetros!$B$36="","",Parámetros!$B$36) -> 22 | G10: Semana, columna «Devueltos y retrabajados por base»
A11: Rotación de la brigada | B11: Bajas de cocina del periodo / plantilla media de cocina del periodo | C11: % | D11: Mezclarla con la rotación de sala: en un restaurante con temporada son dos realidades distintas y se corrigen distinto | E11: Trimestral | F11: No se mide en este libro | G11: No se mide aquí: cuadro de mando del Manual del Manager, con cadencia trimestral
A13: La columna «Error típico» es la que evita las discusiones: casi siempre que dos personas dan dos números distintos para lo mismo, una de las dos está cometiendo el error de esa columna.
A14: Ninguno de estos siete indicadores se compara con el de otra cocina sin mirar antes qué carta tiene, cuántos servicios hace y con qué brigada: para eso está la hoja «Comparativa entre Unidades», que compara contra el estándar que fija tu grupo, no contra el sector.
A15: Ninguna cifra de este libro es un benchmark de mercado. Este producto no publica ni uno solo de merma, de tiempo de pase ni de horas de formación, porque no existe ninguno verificado en español.

Sheet Comparativa entre Unidades
A1: Comparativa entre unidades
A2: AI Chef Pro · aichef.pro — Manual del Chef Ejecutivo
A3: Una cocina, con las herramientas para comparar varias. La primera fila la calcula el libro desde tu hoja «Semana»; las otras cinco las tecleas copiando del libro de cada unidad.
A4: MES CERRADO QUE SE COMPARA
A5: Mes (1 a 12) | B5: 8
A6: Año | B6: 2026
A7: Base de las tasas por cubiertos | B7: =IF(Parámetros!$B$8="","",Parámetros!$B$8) -> 1000
A8: El mes se busca en la columna «Mes» de la hoja «Semana». El año no entra en el cálculo: este libro cubre un año, y está aquí para que la comparativa quede fechada cuando la imprimas o la copies.
A10: ESTÁNDAR DEL GRUPO
A11: Estándar contra el que se comparan las unidades | C11: Merma global (%) | D11: Pase de principales (min) | E11: Incidencias de alérgenos por base | F11: Horas de cocina por cubierto | G11: Platos devueltos por base
A12: Objetivo del grupo | C12: 0.04 | D12: 18 | E12: 0.5 | F12: 0.26 | G12: 6
A13: Este estándar es del GRUPO, no del sector: no hay ninguno publicado. Viene igualado a los objetivos de la hoja «Parámetros» del restaurante de ejemplo; si tu grupo fija otros, cámbialos aquí y la comparativa se recalcula.
A14: Los cinco indicadores van en el mismo sentido: cuanto MÁS BAJO, mejor. Por eso una desviación positiva es siempre peor que el estándar, y se pinta en rojo.
A15: UNIDADES
A16: Unidad | B16: Cubiertos del mes | C16: Merma global (%) | D16: Pase de principales (min) | E16: Incidencias de alérgenos por base | F16: Horas de cocina por cubierto | G16: Platos devueltos por base | I16: Desviación · Merma global (%) | J16: Desviación · Pase de principales (min) | K16: Desviación · Incidencias de alérgenos por base | L16: Desviación · Horas de cocina por cubierto | M16: Desviación · Platos devueltos por base | N16: Indicadores dentro del estándar (de 5) | O16: Posición
A17: =IF(Parámetros!$B$5="","",Parámetros!$B$5&" (unidad de referencia)") -> Restaurante de ejemplo «La Encina» (unidad de referencia) | B17: =IFERROR(IF(SUMIF(Semana!$C$5:$C$56,$B$5,Semana!$D$5:$D$56)=0,"",SUMIF(Semana!$C$5:$C$56,$B$5,Semana!$D$5:$D$56)),"") -> 3320 | C17: =IFERROR(SUMIF(Semana!$C$5:$C$56,$B$5,Semana!$V$5:$V$56)/SUMIF(Semana!$C$5:$C$56,$B$5,Semana!$AE$5:$AE$56),"") -> 0.046342802 | D17: =IFERROR(AVERAGEIF(Semana!$C$5:$C$56,$B$5,Semana!$AH$5:$AH$56),"") -> 19.225 | E17: =IFERROR(SUMIF(Semana!$C$5:$C$56,$B$5,Semana!$AJ$5:$AJ$56)/SUMIF(Semana!$C$5:$C$56,$B$5,Semana!$D$5:$D$56)*$B$7,"") -> 0.30120482 | F17: =IFERROR(SUMIF(Semana!$C$5:$C$56,$B$5,Semana!$AM$5:$AM$56)/SUMIF(Semana!$C$5:$C$56,$B$5,Semana!$D$5:$D$56),"") -> 0.2686747 | G17: =IFERROR(SUMIF(Semana!$C$5:$C$56,$B$5,Semana!$AO$5:$AO$56)/SUMIF(Semana!$C$5:$C$56,$B$5,Semana!$D$5:$D$56)*$B$7,"") -> 6.626506 | I17: =IFERROR(IF(OR(NOT(ISNUMBER($C17)),NOT(ISNUMBER($C$12)),$C$12=0),"",($C17-$C$12)/$C$12),"") -> 0.15857004 | J17: =IFERROR(IF(OR(NOT(ISNUMBER($D17)),NOT(ISNUMBER($D$12)),$D$12=0),"",($D17-$D$12)/$D$12),"") -> 0.068055556 | K17: =IFERROR(IF(OR(NOT(ISNUMBER($E17)),NOT(ISNUMBER($E$12)),$E$12=0),"",($E17-$E$12)/$E$12),"") -> -0.39759036 | L17: =IFERROR(IF(OR(NOT(ISNUMBER($F17)),NOT(ISNUMBER($F$12)),$F$12=0),"",($F17-$F$12)/$F$12),"") -> 0.033364226 | M17: =IFERROR(IF(OR(NOT(ISNUMBER($G17)),NOT(ISNUMBER($G$12)),$G$12=0),"",($G17-$G$12)/$G$12),"") -> 0.10441767 | N17: =IF(NOT(ISNUMBER($B17)),"",IF(AND(ISNUMBER($C17),ISNUMBER($C$12),$C17<=$C$12),1,0)+IF(AND(ISNUMBER($D17),ISNUMBER($D$12),$D17<=$D$12),1,0)+IF(AND(ISNUMBER($E17),ISNUMBER($E$12),$E17<=$E$12),1,0)+IF(AND(ISNUMBER($F17),ISNUMBER($F$12),$F17<=$F$12),1,0)+IF(AND(ISNUMBER($G17),ISNUMBER($G$12),$G17<=$G$12),1,0)) -> 1 | O17: =IF(NOT(ISNUMBER($N17)),"",SUMPRODUCT(--(ISNUMBER($N$17:$N$22)),--($N$17:$N$22>$N17))+1) -> 2
A18: La Encina Norte | B18: 2860 | C18: 0.0382 | D18: 17.4 | E18: 0.35 | F18: 0.249 | G18: 4.9 | I18: =IFERROR(IF(OR(NOT(ISNUMBER($C18)),NOT(ISNUMBER($C$12)),$C$12=0),"",($C18-$C$12)/$C$12),"") -> -0.045 | J18: =IFERROR(IF(OR(NOT(ISNUMBER($D18)),NOT(ISNUMBER($D$12)),$D$12=0),"",($D18-$D$12)/$D$12),"") -> -0.033333333 | K18: =IFERROR(IF(OR(NOT(ISNUMBER($E18)),NOT(ISNUMBER($E$12)),$E$12=0),"",($E18-$E$12)/$E$12),"") -> -0.3 | L18: =IFERROR(IF(OR(NOT(ISNUMBER($F18)),NOT(ISNUMBER($F$12)),$F$12=0),"",($F18-$F$12)/$F$12),"") -> -0.042307692 | M18: =IFERROR(IF(OR(NOT(ISNUMBER($G18)),NOT(ISNUMBER($G$12)),$G$12=0),"",($G18-$G$12)/$G$12),"") -> -0.18333333 | N18: =IF(NOT(ISNUMBER($B18)),"",IF(AND(ISNUMBER($C18),ISNUMBER($C$12),$C18<=$C$12),1,0)+IF(AND(ISNUMBER($D18),ISNUMBER($D$12),$D18<=$D$12),1,0)+IF(AND(ISNUMBER($E18),ISNUMBER($E$12),$E18<=$E$12),1,0)+IF(AND(ISNUMBER($F18),ISNUMBER($F$12),$F18<=$F$12),1,0)+IF(AND(ISNUMBER($G18),ISNUMBER($G$12),$G18<=$G$12),1,0)) -> 5 | O18: =IF(NOT(ISNUMBER($N18)),"",SUMPRODUCT(--(ISNUMBER($N$17:$N$22)),--($N$17:$N$22>$N18))+1) -> 1
A19: La Encina Playa | B19: 4180 | C19: 0.0541 | D19: 21.3 | E19: 0.72 | F19: 0.288 | G19: 8.61 | I19: =IFERROR(IF(OR(NOT(ISNUMBER($C19)),NOT(ISNUMBER($C$12)),$C$12=0),"",($C19-$C$12)/$C$12),"") -> 0.3525 | J19: =IFERROR(IF(OR(NOT(ISNUMBER($D19)),NOT(ISNUMBER($D$12)),$D$12=0),"",($D19-$D$12)/$D$12),"") -> 0.18333333 | K19: =IFERROR(IF(OR(NOT(ISNUMBER($E19)),NOT(ISNUMBER($E$12)),$E$12=0),"",($E19-$E$12)/$E$12),"") -> 0.44 | L19: =IFERROR(IF(OR(NOT(ISNUMBER($F19)),NOT(ISNUMBER($F$12)),$F$12=0),"",($F19-$F$12)/$F$12),"") -> 0.10769231 | M19: =IFERROR(IF(OR(NOT(ISNUMBER($G19)),NOT(ISNUMBER($G$12)),$G$12=0),"",($G19-$G$12)/$G$12),"") -> 0.435 | N19: =IF(NOT(ISNUMBER($B19)),"",IF(AND(ISNUMBER($C19),ISNUMBER($C$12),$C19<=$C$12),1,0)+IF(AND(ISNUMBER($D19),ISNUMBER($D$12),$D19<=$D$12),1,0)+IF(AND(ISNUMBER($E19),ISNUMBER($E$12),$E19<=$E$12),1,0)+IF(AND(ISNUMBER($F19),ISNUMBER($F$12),$F19<=$F$12),1,0)+IF(AND(ISNUMBER($G19),ISNUMBER($G$12),$G19<=$G$12),1,0)) -> 0 | O19: =IF(NOT(ISNUMBER($N19)),"",SUMPRODUCT(--(ISNUMBER($N$17:$N$22)),--($N$17:$N$22>$N19))+1) -> 3
