Workbook

Sheet Instrucciones
A1: Desarrollo de carta y control de calidad del pase
A2: AI Chef Pro · aichef.pro — Manual del Chef Ejecutivo
A3: Para qué sirve: meter un plato en carta con método, y comprobar que lo que sale por el pase es lo que dice su ficha.
A5: Instrucciones de uso
A6: 1. Hoja «Calendario de Temporada»: una fila por plato nuevo. Escribe las cinco fechas de sus cinco hitos (probar, costear, documentar la ficha, formar a la brigada y lanzar), el estado y si la ficha técnica ya está cerrada. Lo demás lo calcula el libro.
A7: 2. Arriba de esa hoja tienes dos celdas verdes: la fecha para simular (déjala vacía y el libro usa la de hoy) y los días máximos que aceptas que un plato esté en prueba sin ficha cerrada. Vienen a 30 días; es un criterio de la casa, no una cifra de nadie.
A8: 3. La columna «Aviso» se enciende sola. Si un plato lleva más días en prueba de los que has puesto y su ficha sigue abierta, se pone en rojo y lo dice con palabras. Se cuentan días NATURALES: una ficha que lleva 40 días sin cerrar lleva 40 días, abra la cocina o no.
A9: 4. Hoja «Registro de Pruebas de Plato»: una fila por prueba, con su resultado de 1 a 5, el coste estimado por ración de esa prueba y la decisión (repetir, aprobar o descartar). El nombre del plato lo trae solo desde el calendario en cuanto escribes el id.
A10: 5. Las cinco últimas columnas del calendario resumen ese registro plato a plato: cuántas pruebas lleva, qué nota media saca, cuánto cuesta de media la ración, cuántas veces se aprobó y cuántas se descartó. No hay que escribir nada ahí.
A11: 6. El coste por ración de la prueba es ESTIMADO y sirve para descartar pronto lo que no cabe en la carta. El coste bueno sale de tu escandallo (Kit de Escandallos o Guía Food Cost + Ingeniería de Menú) y es el que se copia a la ficha técnica de proceso, en el libro 3 de este pack.
A12: 7. Hoja «Control de Calidad del Pase»: muestrea el servicio. Una fila por plato muestreado, con la hora, la familia, la temperatura de emplatado, los minutos entre comanda y salida, si salió conforme a la ficha y si el cliente lo devolvió.
A13: 8. Al final de esa hoja tienes los objetivos de la casa en celdas verdes (tiempo de pase por familia y % de cumplimiento de ficha) y el resumen del muestreo al lado. Mientras un objetivo esté vacío su semáforo no se enciende: es a propósito.
... A31: Versión 1.0 · septiembre 2026 · aichef.pro/manual-chef-ejecutivo · info@aichef.pro

Sheet Calendario de Temporada
A1: Calendario de temporada: de la prueba a la carta
A2: AI Chef Pro · aichef.pro — Manual del Chef Ejecutivo
A3: Cinco hitos por plato. La columna «Aviso» se enciende sola cuando un plato lleva demasiado tiempo en prueba con la ficha abierta.
B5: PARÁMETROS DE ESTA HOJA
B6: Fecha para simular (déjala vacía y se usa la de hoy) | C6: 46289 | D6: En el ejemplo trae la fecha de la última prueba registrada, para que se vea el cálculo. Bórrala y el libro usará la de hoy.
B7: Hoy (fecha de referencia) | C7: =IFERROR(IF($C$6="",TODAY(),$C$6),"") -> 46289
B8: Días máximos en prueba sin ficha técnica cerrada | C8: 30 | D8: Criterio de la casa, no una cifra publicada por nadie. Son días NATURALES: no se descuentan los cierres ni los festivos.
B10: Los cinco hitos son: probar, costear, documentar, formar, lanzar. El que más se salta es «formar»: un plato que llega al pase sin que la partida sepa hacerlo se paga en tiempo y en devoluciones.
A12: Id | B12: Plato | C12: Partida | D12: Probar (fecha) | E12: Costear (fecha) | F12: Documentar la ficha (fecha) | G12: Formar a la brigada (fecha) | H12: Lanzar (fecha) | I12: Estado | J12: Ficha técnica cerrada | K12: Días naturales desde la primera prueba | L12: Hitos con fecha puesta (de 5) | M12: Aviso | N12: Pruebas hechas | O12: Resultado medio (1-5) | P12: Coste medio estimado por ración | Q12: Veces aprobado | R12: Veces descartado
A13: N1 | B13: Alcachofas confitadas con panceta y yema curada | C13: Fríos y entrantes | D13: 46238 | E13: 46245 | F13: 46256 | G13: 46265 | H13: 46301 | I13: En curso | J13: Sí | K13: =IFERROR(IF(OR($D13="",$C$7=""),"",IF($C$7<$D13,"",$C$7-$D13)),"") -> 51 | L13: =COUNT($D13:$H13) -> 5 | M13: =IF($J13="","",IF(AND($J13=$A$58,ISNUMBER($K13),ISNUMBER($C$8),$K13>$C$8),"REVISAR: demasiados días en prueba sin ficha cerrada",IF($J13=$A$58,"Ficha pendiente","Ficha cerrada"))) -> Ficha cerrada | N13: =IF($A13="","",COUNTIF('Registro de Pruebas de Plato'!$B$6:$B$35,$A13&"")) -> 2 | O13: =IFERROR(IF(OR($N13="",$N13=0),"",SUMIF('Registro de Pruebas de Plato'!$B$6:$B$35,$A13&"",'Registro de Pruebas de Plato'!$F$6:$F$35)/$N13),"") -> 4.5 | P13: =IFERROR(IF(OR($N13="",$N13=0),"",SUMIF('Registro de Pruebas de Plato'!$B$6:$B$35,$A13&"",'Registro de Pruebas de Plato'!$G$6:$G$35)/$N13),"") -> 3.125 | Q13: =IF($A13="","",SUMIF('Registro de Pruebas de Plato'!$B$6:$B$35,$A13&"",'Registro de Pruebas de Plato'!$J$6:$J$35)) -> 1 | R13: =IF($A13="","",SUMIF('Registro de Pruebas de Plato'!$B$6:$B$35,$A13&"",'Registro de Pruebas de Plato'!$K$6:$K$35)) -> 0
A14: N2 | B14: Guiso de carrilleras al vino tinto con puré de apionabo | C14: Pase y caliente | D14: 46240 | E14: 46247 | F14: 46258 | G14: 46267 | H14: 46301 | I14: En curso | J14: Sí | K14: =IFERROR(IF(OR($D14="",$C$7=""),"",IF($C$7<$D14,"",$C$7-$D14)),"") -> 49 | L14: =COUNT($D14:$H14) -> 5 | M14: =IF($J14="","",IF(AND($J14=$A$58,ISNUMBER($K14),ISNUMBER($C$8),$K14>$C$8),"REVISAR: demasiados días en prueba sin ficha cerrada",IF($J14=$A$58,"Ficha pendiente","Ficha cerrada"))) -> Ficha cerrada | N14: =IF($A14="","",COUNTIF('Registro de Pruebas de Plato'!$B$6:$B$35,$A14&"")) -> 3 | O14: =IFERROR(IF(OR($N14="",$N14=0),"",SUMIF('Registro de Pruebas de Plato'!$B$6:$B$35,$A14&"",'Registro de Pruebas de Plato'!$F$6:$F$35)/$N14),"") -> 4.3333333 | P14: =IFERROR(IF(OR($N14="",$N14=0),"",SUMIF('Registro de Pruebas de Plato'!$B$6:$B$35,$A14&"",'Registro de Pruebas de Plato'!$G$6:$G$35)/$N14),"") -> 4.3833333 | Q14: =IF($A14="","",SUMIF('Registro de Pruebas de Plato'!$B$6:$B$35,$A14&"",'Registro de Pruebas de Plato'!$J$6:$J$35)) -> 1 | R14: =IF($A14="","",SUMIF('Registro de Pruebas de Plato'!$B$6:$B$35,$A14&"",'Registro de Pruebas de Plato'!$K$6:$K$35)) -> 0
A15: N3 | B15: Crema de calabaza asada con aceite de pipas | C15: Fríos y entrantes | D15: 46231 | E15: 46245 | I15: Descartado | J15: No | K15: =IFERROR(IF(OR($D15="",$C$7=""),"",IF($C$7<$D15,"",$C$7-$D15)),"") -> 58 | L15: =COUNT($D15:$H15) -> 2 | M15: =IF($J15="","",IF(AND($J15=$A$58,ISNUMBER($K15),ISNUMBER($C$8),$K15>$C$8),"REVISAR: demasiados días en prueba sin ficha cerrada",IF($J15=$A$58,"Ficha pendiente","Ficha cerrada"))) -> REVISAR: demasiados días en prueba sin ficha cerrada | N15: =IF($A15="","",COUNTIF('Registro de Pruebas de Plato'!$B$6:$B$35,$A15&"")) -> 3 | O15: =IFERROR(IF(OR($N15="",$N15=0),"",SUMIF('Registro de Pruebas de Plato'!$B$6:$B$35,$A15&"",'Registro de Pruebas de Plato'!$F$6:$F$35)/$N15),"") -> 2.6666667 | P15: =IFERROR(IF(OR($N15="",$N15=0),"",SUMIF('Registro de Pruebas de Plato'!$B$6:$B$35,$A15&"",'Registro de Pruebas de Plato'!$G$6:$G$35)/$N15),"") -> 1.1 | Q15: =IF($A15="","",SUMIF('Registro de Pruebas de Plato'!$B$6:$B$35,$A15&"",'Registro de Pruebas de Plato'!$J$6:$J$35)) -> 0 | R15: =IF($A15="","",SUMIF('Registro de Pruebas de Plato'!$B$6:$B$35,$A15&"",'Registro de Pruebas de Plato'!$K$6:$K$35)) -> 1
A16: N4 | B16: Arroz de setas de temporada y castañas | C16: Pase y caliente | D16: 46280 | E16: 46287 | F16: 46294 | G16: 46308 | H16: 46315 | I16: Planificado | J16: No | K16: =IFERROR(IF(OR($D16="",$C$7=""),"",IF($C$7<$D16,"",$C$7-$D16)),"") -> 9 | L16: =COUNT($D16:$H16) -> 5 | M16: =IF($J16="","",IF(AND($J16=$A$58,ISNUMBER($K16),ISNUMBER($C$8),$K16>$C$8),"REVISAR: demasiados días en prueba sin ficha cerrada",IF($J16=$A$58,"Ficha pendiente","Ficha cerrada"))) -> Ficha pendiente | N16: =IF($A16="","",COUNTIF('Registro de Pruebas de Plato'!$B$6:$B$35,$A16&"")) -> 0 | O16: =IFERROR(IF(OR($N16="",$N16=0),"",SUMIF('Registro de Pruebas de Plato'!$B$6:$B$35,$A16&"",'Registro de Pruebas de Plato'!$F$6:$F$35)/$N16),"") | P16: =IFERROR(IF(OR($N16="",$N16=0),"",SUMIF('Registro de Pruebas de Plato'!$B$6:$B$35,$A16&"",'Registro de Pruebas de Plato'!$G$6:$G$35)/$N16),"") | Q16: =IF($A16="","",SUMIF('Registro de Pruebas de Plato'!$B$6:$B$35,$A16&"",'Registro de Pruebas de Plato'!$J$6:$J$35)) -> 0 | R16: =IF($A16="","",SUMIF('Registro de Pruebas de Plato'!$B$6:$B$35,$A16&"",'Registro de Pruebas de Plato'!$K$6:$K$35)) -> 0
A17: N5 | B17: Tarta de manzana con helado de canela | C17: Postres y panadería | D17: 46287 | E17: 46294 | F17: 46301 | G17: 46308 | H17: 46315 | I17: Planificado | J17: No | K17: =IFERROR(IF(OR($D17="",$C$7=""),"",IF($C$7<$D17,"",$C$7-$D17)),"") -> 2 | L17: =COUNT($D17:$H17) -> 5 | M17: =IF($J17="","",IF(AND($J17=$A$58,ISNUMBER($K17),ISNUMBER($C$8),$K17>$C$8),"REVISAR: demasiados días en prueba sin ficha cerrada",IF($J17=$A$58,"Ficha pendiente","Ficha cerrada"))) -> Ficha pendiente | N17: =IF($A17="","",COUNTIF('Registro de Pruebas de Plato'!$B$6:$B$35,$A17&"")) -> 0 | O17: =IFERROR(IF(OR($N17="",$N17=0),"",SUMIF('Registro de Pruebas de Plato'!$B$6:$B$35,$A17&"",'Registro de Pruebas de Plato'!$F$6:$F$35)/$N17),"") | P17: =IFERROR(IF(OR($N17="",$N17=0),"",SUMIF('Registro de Pruebas de Plato'!$B$6:$B$35,$A17&"",'Registro de Pruebas de Plato'!$G$6:$G$35)/$N17),"") | Q17: =IF($A17="","",SUMIF('Registro de Pruebas de Plato'!$B$6:$B$35,$A17&"",'Registro de Pruebas de Plato'!$J$6:$J$35)) -> 0 | R17: =IF($A17="","",SUMIF('Registro de Pruebas de Plato'!$B$6:$B$35,$A17&"",'Registro de Pruebas de Plato'!$K$6:$K$35)) -> 0
K18: =IFERROR(IF(OR($D18="",$C$7=""),"",IF($C$7<$D18,"",$C$7-$D18)),"") | L18: =COUNT($D18:$H18) -> 0 | M18: =IF($J18="","",IF(AND($J18=$A$58,ISNUMBER($K18),ISNUMBER($C$8),$K18>$C$8),"REVISAR: demasiados días en prueba sin ficha cerrada",IF($J18=$A$58,"Ficha pendiente","Ficha cerrada"))) | N18: =IF($A18="","",COUNTIF('Registro de Pruebas de Plato'!$B$6:$B$35,$A18&"")) | O18: =IFERROR(IF(OR($N18="",$N18=0),"",SUMIF('Registro de Pruebas de Plato'!$B$6:$B$35,$A18&"",'Registro de Pruebas de Plato'!$F$6:$F$35)/$N18),"") | P18: =IFERROR(IF(OR($N18="",$N18=0),"",SUMIF('Registro de Pruebas de Plato'!$B$6:$B$35,$A18&"",'Registro de Pruebas de Plato'!$G$6:$G$35)/$N18),"") | Q18: =IF($A18="","",SUMIF('Registro de Pruebas de Plato'!$B$6:$B$35,$A18&"",'Registro de Pruebas de Plato'!$J$6:$J$35)) | R18: =IF($A18="","",SUMIF('Registro de Pruebas de Plato'!$B$6:$B$35,$A18&"",'Registro de Pruebas de Plato'!$K$6:$K$35))
K19: =IFERROR(IF(OR($D19="",$C$7=""),"",IF($C$7<$D19,"",$C$7-$D19)),"") | L19: =COUNT($D19:$H19) -> 0 | M19: =IF($J19="","",IF(AND($J19=$A$58,ISNUMBER($K19),ISNUMBER($C$8),$K19>$C$8),"REVISAR: demasiados días en prueba sin ficha cerrada",IF($J19=$A$58,"Ficha pendiente","Ficha cerrada"))) | N19: =IF($A19="","",COUNTIF('Registro de Pruebas de Plato'!$B$6:$B$35,$A19&"")) | O19: =IFERROR(IF(OR($N19="",$N19=0),"",SUMIF('Registro de Pruebas de Plato'!$B$6:$B$35,$A19&"",'Registro de Pruebas de Plato'!$F$6:$F$35)/$N19),"") | P19: =IFERROR(IF(OR($N19="",$N19=0),"",SUMIF('Registro de Pruebas de Plato'!$B$6:$B$35,$A19&"",'Registro de Pruebas de Plato'!$G$6:$G$35)/$N19),"") | Q19: =IF($A19="","",SUMIF('Registro de Pruebas de Plato'!$B$6:$B$35,$A19&"",'Registro de Pruebas de Plato'!$J$6:$J$35)) | R19: =IF($A19="","",SUMIF('Registro de Pruebas de Plato'!$B$6:$B$35,$A19&"",'Registro de Pruebas de Plato'!$K$6:$K$35))
K20: =IFERROR(IF(OR($D20="",$C$7=""),"",IF($C$7<$D20,"",$C$7-$D20)),"") | L20: =COUNT($D20:$H20) -> 0 | M20: =IF($J20="","",IF(AND($J20=$A$58,ISNUMBER($K20),ISNUMBER($C$8),$K20>$C$8),"REVISAR: demasiados días en prueba sin ficha cerrada",IF($J20=$A$58,"Ficha pendiente","Ficha cerrada"))) | N20: =IF($A20="","",COUNTIF('Registro de Pruebas de Plato'!$B$6:$B$35,$A20&"")) | O20: =IFERROR(IF(OR($N20="",$N20=0),"",SUMIF('Registro de Pruebas de Plato'!$B$6:$B$35,$A20&"",'Registro de Pruebas de Plato'!$F$6:$F$35)/$N20),"") | P20: =IFERROR(IF(OR($N20="",$N20=0),"",SUMIF('Registro de Pruebas de Plato'!$B$6:$B$35,$A20&"",'Registro de Pruebas de Plato'!$G$6:$G$35)/$N20),"") | Q20: =IF($A20="","",SUMIF('Registro de Pruebas de Plato'!$B$6:$B$35,$A20&"",'Registro de Pruebas de Plato'!$J$6:$J$35)) | R20: =IF($A20="","",SUMIF('Registro de Pruebas de Plato'!$B$6:$B$35,$A20&"",'Registro de Pruebas de Plato'!$K$6:$K$35))
K21: =IFERROR(IF(OR($D21="",$C$7=""),"",IF($C$7<$D21,"",$C$7-$D21)),"") | L21: =COUNT($D21:$H21) -> 0 | M21: =IF($J21="","",IF(AND($J21=$A$58,ISNUMBER($K21),ISNUMBER($C$8),$K21>$C$8),"REVISAR: demasiados días en prueba sin ficha cerrada",IF($J21=$A$58,"Ficha pendiente","Ficha cerrada"))) | N21: =IF($A21="","",COUNTIF('Registro de Pruebas de Plato'!$B$6:$B$35,$A21&"")) | O21: =IFERROR(IF(OR($N21="",$N21=0),"",SUMIF('Registro de Pruebas de Plato'!$B$6:$B$35,$A21&"",'Registro de Pruebas de Plato'!$F$6:$F$35)/$N21),"") | P21: =IFERROR(IF(OR($N21="",$N21=0),"",SUMIF('Registro de Pruebas de Plato'!$B$6:$B$35,$A21&"",'Registro de Pruebas de Plato'!$G$6:$G$35)/$N21),"") | Q21: =IF($A21="","",SUMIF('Registro de Pruebas de Plato'!$B$6:$B$35,$A21&"",'Registro de Pruebas de Plato'!$J$6:$J$35)) | R21: =IF($A21="","",SUMIF('Registro de Pruebas de Plato'!$B$6:$B$35,$A21&"",'Registro de Pruebas de Plato'!$K$6:$K$35))
K22: =IFERROR(IF(OR($D22="",$C$7=""),"",IF($C$7<$D22,"",$C$7-$D22)),"") | L22: =COUNT($D22:$H22) -> 0 | M22: =IF($J22="","",IF(AND($J22=$A$58,ISNUMBER($K22),ISNUMBER($C$8),$K22>$C$8),"REVISAR: demasiados días en prueba sin ficha cerrada",IF($J22=$A$58,"Ficha pendiente","Ficha cerrada"))) | N22: =IF($A22="","",COUNTIF('Registro de Pruebas de Plato'!$B$6:$B$35,$A22&"")) | O22: =IFERROR(IF(OR($N22="",$N22=0),"",SUMIF('Registro de Pruebas de Plato'!$B$6:$B$35,$A22&"",'Registro de Pruebas de Plato'!$F$6:$F$35)/$N22),"") | P22: =IFERROR(IF(OR($N22="",$N22=0),"",SUMIF('Registro de Pruebas de Plato'!$B$6:$B$35,$A22&"",'Registro de Pruebas de Plato'!$G$6:$G$35)/$N22),"") | Q22: =IF($A22="","",SUMIF('Registro de Pruebas de Plato'!$B$6:$B$35,$A22&"",'Registro de Pruebas de Plato'!$J$6:$J$35)) | R22: =IF($A22="","",SUMIF('Registro de Pruebas de Plato'!$B$6:$B$35,$A22&"",'Registro de Pruebas de Plato'!$K$6:$K$35))
K23: =IFERROR(IF(OR($D23="",$C$7=""),"",IF($C$7<$D23,"",$C$7-$D23)),"") | L23: =COUNT($D23:$H23) -> 0 | M23: =IF($J23="","",IF(AND($J23=$A$58,ISNUMBER($K23),ISNUMBER($C$8),$K23>$C$8),"REVISAR: demasiados días en prueba sin ficha cerrada",IF($J23=$A$58,"Ficha pendiente","Ficha cerrada"))) | N23: =IF($A23="","",COUNTIF('Registro de Pruebas de Plato'!$B$6:$B$35,$A23&"")) | O23: =IFERROR(IF(OR($N23="",$N23=0),"",SUMIF('Registro de Pruebas de Plato'!$B$6:$B$35,$A23&"",'Registro de Pruebas de Plato'!$F$6:$F$35)/$N23),"") | P23: =IFERROR(IF(OR($N23="",$N23=0),"",SUMIF('Registro de Pruebas de Plato'!$B$6:$B$35,$A23&"",'Registro de Pruebas de Plato'!$G$6:$G$35)/$N23),"") | Q23: =IF($A23="","",SUMIF('Registro de Pruebas de Plato'!$B$6:$B$35,$A23&"",'Registro de Pruebas de Plato'!$J$6:$J$35)) | R23: =IF($A23="","",SUMIF('Registro de Pruebas de Plato'!$B$6:$B$35,$A23&"",'Registro de Pruebas de Plato'!$K$6:$K$35))
K24: =IFERROR(IF(OR($D24="",$C$7=""),"",IF($C$7<$D24,"",$C$7-$D24)),"") | L24: =COUNT($D24:$H24) -> 0 | M24: =IF($J24="","",IF(AND($J24=$A$58,ISNUMBER($K24),ISNUMBER($C$8),$K24>$C$8),"REVISAR: demasiados días en prueba sin ficha cerrada",IF($J24=$A$58,"Ficha pendiente","Ficha cerrada"))) | N24: =IF($A24="","",COUNTIF('Registro de Pruebas de Plato'!$B$6:$B$35,$A24&"")) | O24: =IFERROR(IF(OR($N24="",$N24=0),"",SUMIF('Registro de Pruebas de Plato'!$B$6:$B$35,$A24&"",'Registro de Pruebas de Plato'!$F$6:$F$35)/$N24),"") | P24: =IFERROR(IF(OR($N24="",$N24=0),"",SUMIF('Registro de Pruebas de Plato'!$B$6:$B$35,$A24&"",'Registro de Pruebas de Plato'!$G$6:$G$35)/$N24),"") | Q24: =IF($A24="","",SUMIF('Registro de Pruebas de Plato'!$B$6:$B$35,$A24&"",'Registro de Pruebas de Plato'!$J$6:$J$35)) | R24: =IF($A24="","",SUMIF('Registro de Pruebas de Plato'!$B$6:$B$35,$A24&"",'Registro de Pruebas de Plato'!$K$6:$K$35))
B26: RESUMEN DEL DESARROLLO DE CARTA
B27: Indicador | C27: Valor
B28: Platos en desarrollo | C28: =COUNTIF($A$13:$A$24,"<>") -> 5
B29: Platos con ficha técnica cerrada | C29: =COUNTIF($J$13:$J$24,"Sí") -> 2
B30: Porcentaje de platos con ficha cerrada | C30: =IFERROR(IF($C$28=0,"",$C$29/$C$28),"") -> 0.4
B31: Platos que superan los días máximos en prueba | C31: =COUNTIFS($J$13:$J$24,"No",$K$13:$K$24,">"&$C$8) -> 1
B32: Platos ya lanzados | C32: =COUNTIF($I$13:$I$24,"Lanzado") -> 0
B33: Pruebas registradas en total | C33: =SUM($N$13:$N$24) -> 8
B35: La columna «Coste medio estimado por ración» es de las PRUEBAS: sirve para descartar pronto un plato que no cabe en la carta. El coste bueno sale del escandallo y es el que se copia a la ficha técnica de proceso (libro 3). Este pack no lo recalcula.
B36: Qué plato deja más margen y cuál sale de la carta es ingeniería de menú, y vive en la «Guía Food Cost + Ingeniería de Menú». Aquí solo se decide si el plato está listo.
B39: LISTAS DE LOS DESPLEGABLES (no las borres)
A40: Partidas de tu cocina
A41: Pase y caliente
A42: Fríos y entrantes
A43: Postres y panadería
A44: Barra y bebidas
A45: Sala y servicio
A46: Caja y cierre
A47: Son las mismas partidas del cuadro de mando de cocina (libro 1). Cópialas de allí: este libro no lee ningún fichero ajeno.
...

Sheet Registro de Pruebas de Plato
A1: Registro de pruebas de plato
A2: AI Chef Pro · aichef.pro — Manual del Chef Ejecutivo
A3: Una fila por prueba. El nombre del plato lo trae el calendario en cuanto escribes su id.
A5: Fecha | B5: Id del plato | C5: Plato (lo trae el calendario) | D5: Número de prueba | E5: Partida | F5: Resultado (1 a 5) | G5: Coste estimado por ración | H5: Decisión | I5: Observación | J5: Aprobada (1 o 0) | K5: Descartada (1 o 0)
A6: 46231 | B6: N3 | C6: =IFERROR(IF($B6="","",INDEX('Calendario de Temporada'!$B$13:$B$24,MATCH($B6&"",'Calendario de Temporada'!$A$13:$A$24,0))),"") -> Crema de calabaza asada con aceite de pipas | D6: 1 | E6: Fríos y entrantes | F6: 3 | G6: 1.05 | H6: Repetir | I6: Poco sabor de asado; la calabaza suelta agua al triturar | J6: =IF($H6="","",IF($H6="Aprobar",1,0)) -> 0 | K6: =IF($H6="","",IF($H6="Descartar",1,0)) -> 0
A7: 46245 | B7: N3 | C7: =IFERROR(IF($B7="","",INDEX('Calendario de Temporada'!$B$13:$B$24,MATCH($B7&"",'Calendario de Temporada'!$A$13:$A$24,0))),"") -> Crema de calabaza asada con aceite de pipas | D7: 2 | E7: Fríos y entrantes | F7: 3 | G7: 1.15 | H7: Repetir | I7: Mejor con asado a 200 °C, pero el aceite de pipas enrancia en dos días | J7: =IF($H7="","",IF($H7="Aprobar",1,0)) -> 0 | K7: =IF($H7="","",IF($H7="Descartar",1,0)) -> 0
A8: 46273 | B8: N1 | C8: =IFERROR(IF($B8="","",INDEX('Calendario de Temporada'!$B$13:$B$24,MATCH($B8&"",'Calendario de Temporada'!$A$13:$A$24,0))),"") -> Alcachofas confitadas con panceta y yema curada | D8: 1 | E8: Fríos y entrantes | F8: 4 | G8: 3.2 | H8: Repetir | I8: Buen equilibrio; ajustar el punto de la yema curada | J8: =IF($H8="","",IF($H8="Aprobar",1,0)) -> 0 | K8: =IF($H8="","",IF($H8="Descartar",1,0)) -> 0
A9: 46275 | B9: N2 | C9: =IFERROR(IF($B9="","",INDEX('Calendario de Temporada'!$B$13:$B$24,MATCH($B9&"",'Calendario de Temporada'!$A$13:$A$24,0))),"") -> Guiso de carrilleras al vino tinto con puré de apionabo | D9: 1 | E9: Pase y caliente | F9: 4 | G9: 4.6 | H9: Repetir | I9: Guiso correcto; el puré de apionabo queda basto | J9: =IF($H9="","",IF($H9="Aprobar",1,0)) -> 0 | K9: =IF($H9="","",IF($H9="Descartar",1,0)) -> 0
A10: 46279 | B10: N1 | C10: =IFERROR(IF($B10="","",INDEX('Calendario de Temporada'!$B$13:$B$24,MATCH($B10&"",'Calendario de Temporada'!$A$13:$A$24,0))),"") -> Alcachofas confitadas con panceta y yema curada | D10: 2 | E10: Fríos y entrantes | F10: 5 | G10: 3.05 | H10: Aprobar | I10: Yema curada 24 h en sal y azúcar; ración de 4 alcachofas | J10: =IF($H10="","",IF($H10="Aprobar",1,0)) -> 1 | K10: =IF($H10="","",IF($H10="Descartar",1,0)) -> 0
A11: 46281 | B11: N2 | C11: =IFERROR(IF($B11="","",INDEX('Calendario de Temporada'!$B$13:$B$24,MATCH($B11&"",'Calendario de Temporada'!$A$13:$A$24,0))),"") -> Guiso de carrilleras al vino tinto con puré de apionabo | D11: 2 | E11: Pase y caliente | F11: 4 | G11: 4.35 | H11: Repetir | I11: Apionabo pasado por colador fino; se reduce la salsa 10 minutos más | J11: =IF($H11="","",IF($H11="Aprobar",1,0)) -> 0 | K11: =IF($H11="","",IF($H11="Descartar",1,0)) -> 0
A12: 46286 | B12: N2 | C12: =IFERROR(IF($B12="","",INDEX('Calendario de Temporada'!$B$13:$B$24,MATCH($B12&"",'Calendario de Temporada'!$A$13:$A$24,0))),"") -> Guiso de carrilleras al vino tinto con puré de apionabo | D12: 3 | E12: Pase y caliente | F12: 5 | G12: 4.2 | H12: Aprobar | I12: Listo para ficha; rinde 12 raciones por olla | J12: =IF($H12="","",IF($H12="Aprobar",1,0)) -> 1 | K12: =IF($H12="","",IF($H12="Descartar",1,0)) -> 0
A13: 46289 | B13: N3 | C13: =IFERROR(IF($B13="","",INDEX('Calendario de Temporada'!$B$13:$B$24,MATCH($B13&"",'Calendario de Temporada'!$A$13:$A$24,0))),"") -> Crema de calabaza asada con aceite de pipas | D13: 3 | E13: Fríos y entrantes | F13: 2 | G13: 1.1 | H13: Descartar | I13: Sigue sin diferenciarse de la crema de la competencia | J13: =IF($H13="","",IF($H13="Aprobar",1,0)) -> 0 | K13: =IF($H13="","",IF($H13="Descartar",1,0)) -> 1
C14: =IFERROR(IF($B14="","",INDEX('Calendario de Temporada'!$B$13:$B$24,MATCH($B14&"",'Calendario de Temporada'!$A$13:$A$24,0))),"") | J14: =IF($H14="","",IF($H14="Aprobar",1,0)) | K14: =IF($H14="","",IF($H14="Descartar",1,0))
C15: =IFERROR(IF($B15="","",INDEX('Calendario de Temporada'!$B$13:$B$24,MATCH($B15&"",'Calendario de Temporada'!$A$13:$A$24,0))),"") | J15: =IF($H15="","",IF($H15="Aprobar",1,0)) | K15: =IF($H15="","",IF($H15="Descartar",1,0))
C16: =IFERROR(IF($B16="","",INDEX('Calendario de Temporada'!$B$13:$B$24,MATCH($B16&"",'Calendario de Temporada'!$A$13:$A$24,0))),"") | J16: =IF($H16="","",IF($H16="Aprobar",1,0)) | K16: =IF($H16="","",IF($H16="Descartar",1,0))
C17: =IFERROR(IF($B17="","",INDEX('Calendario de Temporada'!$B$13:$B$24,MATCH($B17&"",'Calendario de Temporada'!$A$13:$A$24,0))),"") | J17: =IF($H17="","",IF($H17="Aprobar",1,0)) | K17: =IF($H17="","",IF($H17="Descartar",1,0))
C18: =IFERROR(IF($B18="","",INDEX('Calendario de Temporada'!$B$13:$B$24,MATCH($B18&"",'Calendario de Temporada'!$A$13:$A$24,0))),"") | J18: =IF($H18="","",IF($H18="Aprobar",1,0)) | K18: =IF($H18="","",IF($H18="Descartar",1,0))
C19: =IFERROR(IF($B19="","",INDEX('Calendario de Temporada'!$B$13:$B$24,MATCH($B19&"",'Calendario de Temporada'!$A$13:$A$24,0))),"") | J19: =IF($H19="","",IF($H19="Aprobar",1,0)) | K19: =IF($H19="","",IF($H19="Descartar",1,0))
C20: =IFERROR(IF($B20="","",INDEX('Calendario de Temporada'!$B$13:$B$24,MATCH($B20&"",'Calendario de Temporada'!$A$13:$A$24,0))),"") | J20: =IF($H20="","",IF($H20="Aprobar",1,0)) | K20: =IF($H20="","",IF($H20="Descartar",1,0))
C21: =IFERROR(IF($B21="","",INDEX('Calendario de Temporada'!$B$13:$B$24,MATCH($B21&"",'Calendario de Temporada'!$A$13:$A$24,0))),"") | J21: =IF($H21="","",IF($H21="Aprobar",1,0)) | K21: =IF($H21="","",IF($H21="Descartar",1,0))
C22: =IFERROR(IF($B22="","",INDEX('Calendario de Temporada'!$B$13:$B$24,MATCH($B22&"",'Calendario de Temporada'!$A$13:$A$24,0))),"") | J22: =IF($H22="","",IF($H22="Aprobar",1,0)) | K22: =IF($H22="","",IF($H22="Descartar",1,0))
C23: =IFERROR(IF($B23="","",INDEX('Calendario de Temporada'!$B$13:$B$24,MATCH($B23&"",'Calendario de Temporada'!$A$13:$A$24,0))),"") | J23: =IF($H23="","",IF($H23="Aprobar",1,0)) | K23: =IF($H23="","",IF($H23="Descartar",1,0))
C24: =IFERROR(IF($B24="","",INDEX('Calendario de Temporada'!$B$13:$B$24,MATCH($B24&"",'Calendario de Temporada'!$A$13:$A$24,0))),"") | J24: =IF($H24="","",IF($H24="Aprobar",1,0)) | K24: =IF($H24="","",IF($H24="Descartar",1,0))
C25: =IFERROR(IF($B25="","",INDEX('Calendario de Temporada'!$B$13:$B$24,MATCH($B25&"",'Calendario de Temporada'!$A$13:$A$24,0))),"") | J25: =IF($H25="","",IF($H25="Aprobar",1,0)) | K25: =IF($H25="","",IF($H25="Descartar",1,0))
... C35: =IFERROR(IF($B35="","",INDEX('Calendario de Temporada'!$B$13:$B$24,MATCH($B35&"",'Calendario de Temporada'!$A$13:$A$24,0))),"") | J35: =IF($H35="","",IF($H35="Aprobar",1,0)) | K35: =IF($H35="","",IF($H35="Descartar",1,0))
A37: RESUMEN DEL REGISTRO
A38: Indicador
A39: Pruebas registradas | C39: =COUNTIF($B$6:$B$35,"<>") -> 8
A40: Resultado medio de todas las pruebas (1 a 5) | C40: =IFERROR(IF(COUNT($F$6:$F$35)=0,"",SUM($F$6:$F$35)/COUNT($F$6:$F$35)),"") -> 3.75
A41: Coste estimado medio por ración | C41: =IFERROR(IF(COUNT($G$6:$G$35)=0,"",SUM($G$6:$G$35)/COUNT($G$6:$G$35)),"") -> 2.8375
A42: Pruebas aprobadas | C42: =SUM($J$6:$J$35) -> 2
A43: Pruebas descartadas | C43: =SUM($K$6:$K$35) -> 1
A44: Pruebas que hubo que repetir | C44: =COUNTIF($H$6:$H$35,"Repetir") -> 5
A46: Las columnas «Aprobada» y «Descartada» valen 1 o 0 y están para que el calendario pueda contarlas por plato sin fórmulas raras. No hay que tocarlas.
A48: LISTA DEL DESPLEGABLE (no la borres)
A49: Decisión
A50: Repetir
A51: Aprobar
A52: Descartar

Sheet Control de Calidad del Pase
A1: Control de calidad del pase
A2: AI Chef Pro · aichef.pro — Manual del Chef Ejecutivo
A3: Muestreo del servicio. De aquí salen los tiempos de pase y el cumplimiento de ficha que se copian al cuadro de mando de cocina.
A5: Fecha | B5: Servicio | C5: Id del plato | D5: Familia | E5: Temperatura de emplatado (°C) | F5: Tiempo de pase (min) | G5: Conforme a la ficha | H5: Devuelto por el cliente | I5: Observación | J5: Conforme (1 o 0) | K5: Devuelto (1 o 0) | L5: ¿Se mantiene en caliente? (Sí/No)
A6: 46273 | B6: Cena | C6: P1 | D6: Principales | E6: 68 | F6: 14 | G6: Sí | H6: No | J6: =IF($G6="","",IF($G6=$A$78,1,0)) -> 1 | K6: =IF($H6="","",IF($H6=$A$78,1,0)) -> 0 | L6: Sí
A7: 46273 | B7: Cena | C7: E2 | D7: Entrantes | E7: 9 | F7: 7.5 | G7: Sí | H7: No | J7: =IF($G7="","",IF($G7=$A$78,1,0)) -> 1 | K7: =IF($H7="","",IF($H7=$A$78,1,0)) -> 0 | L7: No
A8: 46274 | B8: Comida | C8: P3 | D8: Principales | E8: 71 | F8: 12.5 | G8: Sí | H8: No | J8: =IF($G8="","",IF($G8=$A$78,1,0)) -> 1 | K8: =IF($H8="","",IF($H8=$A$78,1,0)) -> 0 | L8: No
A9: 46274 | B9: Comida | C9: E1 | D9: Entrantes | E9: 74 | F9: 8 | G9: Sí | H9: No | J9: =IF($G9="","",IF($G9=$A$78,1,0)) -> 1 | K9: =IF($H9="","",IF($H9=$A$78,1,0)) -> 0 | L9: No
A10: 46274 | B10: Cena | C10: P4 | D10: Principales | E10: 76 | F10: 21 | G10: Sí | H10: No | I10: Arroz, tiempo de ficha | J10: =IF($G10="","",IF($G10=$A$78,1,0)) -> 1 | K10: =IF($H10="","",IF($H10=$A$78,1,0)) -> 0 | L10: No
A11: 46274 | B11: Cena | C11: D1 | D11: Postres | E11: 7 | F11: 5.5 | G11: Sí | H11: No | J11: =IF($G11="","",IF($G11=$A$78,1,0)) -> 1 | K11: =IF($H11="","",IF($H11=$A$78,1,0)) -> 0 | L11: No
A12: 46275 | B12: Comida | C12: P2 | D12: Principales | E12: 65 | F12: 15.5 | G12: Sí | H12: No | J12: =IF($G12="","",IF($G12=$A$78,1,0)) -> 1 | K12: =IF($H12="","",IF($H12=$A$78,1,0)) -> 0 | L12: No
A13: 46275 | B13: Comida | C13: E3 | D13: Entrantes | E13: 78 | F13: 9 | G13: Sí | H13: No | J13: =IF($G13="","",IF($G13=$A$78,1,0)) -> 1 | K13: =IF($H13="","",IF($H13=$A$78,1,0)) -> 0 | L13: No
A14: 46275 | B14: Cena | C14: P1 | D14: Principales | E14: 61 | F14: 16 | G14: No | H14: No | I14: Sale por debajo de 63 °C: se rehace | J14: =IF($G14="","",IF($G14=$A$78,1,0)) -> 0 | K14: =IF($H14="","",IF($H14=$A$78,1,0)) -> 0 | L14: Sí
A15: 46275 | B15: Cena | C15: D3 | D15: Postres | E15: 66 | F15: 8.5 | G15: Sí | H15: No | J15: =IF($G15="","",IF($G15=$A$78,1,0)) -> 1 | K15: =IF($H15="","",IF($H15=$A$78,1,0)) -> 0 | L15: No
A16: 46276 | B16: Comida | C16: E4 | D16: Entrantes | E16: 72 | F16: 9.5 | G16: Sí | H16: No | J16: =IF($G16="","",IF($G16=$A$78,1,0)) -> 1 | K16: =IF($H16="","",IF($H16=$A$78,1,0)) -> 0 | L16: No
A17: 46276 | B17: Comida | C17: P3 | D17: Principales | E17: 70 | F17: 13 | G17: Sí | H17: No | J17: =IF($G17="","",IF($G17=$A$78,1,0)) -> 1 | K17: =IF($H17="","",IF($H17=$A$78,1,0)) -> 0 | L17: No
A18: 46276 | B18: Cena | C18: P5 | D18: Principales | E18: 64 | F18: 19.5 | G18: Sí | H18: No | J18: =IF($G18="","",IF($G18=$A$78,1,0)) -> 1 | K18: =IF($H18="","",IF($H18=$A$78,1,0)) -> 0 | L18: No
A19: 46276 | B19: Cena | C19: E2 | D19: Entrantes | E19: 8 | F19: 8 | G19: Sí | H19: No | J19: =IF($G19="","",IF($G19=$A$78,1,0)) -> 1 | K19: =IF($H19="","",IF($H19=$A$78,1,0)) -> 0 | L19: No
A20: 46276 | B20: Cena | C20: D2 | D20: Postres | E20: 58 | F20: 7 | G20: Sí | H20: No | J20: =IF($G20="","",IF($G20=$A$78,1,0)) -> 1 | K20: =IF($H20="","",IF($H20=$A$78,1,0)) -> 0 | L20: No
A21: 46277 | B21: Comida | C21: P1 | D21: Principales | E21: 69 | F21: 15 | G21: Sí | H21: No | J21: =IF($G21="","",IF($G21=$A$78,1,0)) -> 1 | K21: =IF($H21="","",IF($H21=$A$78,1,0)) -> 0 | L21: Sí
A22: 46277 | B22: Comida | C22: E1 | D22: Entrantes | E22: 75 | F22: 8.5 | G22: No | H22: No | I22: Ración de 5 croquetas en vez de 6 | J22: =IF($G22="","",IF($G22=$A$78,1,0)) -> 0 | K22: =IF($H22="","",IF($H22=$A$78,1,0)) -> 0 | L22: No
A23: 46277 | B23: Comida | C23: D1 | D23: Postres | E23: 6 | F23: 6 | G23: Sí | H23: No | J23: =IF($G23="","",IF($G23=$A$78,1,0)) -> 1 | K23: =IF($H23="","",IF($H23=$A$78,1,0)) -> 0 | L23: No
A24: 46277 | B24: Cena | C24: P4 | D24: Principales | E24: 77 | F24: 22.5 | G24: Sí | H24: No | J24: =IF($G24="","",IF($G24=$A$78,1,0)) -> 1 | K24: =IF($H24="","",IF($H24=$A$78,1,0)) -> 0 | L24: No
A25: 46277 | B25: Cena | C25: E3 | D25: Entrantes | E25: 79 | F25: 10.5 | G25: Sí | H25: No | J25: =IF($G25="","",IF($G25=$A$78,1,0)) -> 1 | K25: =IF($H25="","",IF($H25=$A$78,1,0)) -> 0 | L25: No
A26: 46277 | B26: Cena | C26: P2 | D26: Principales | E26: 66 | F26: 17 | G26: Sí | H26: No | J26: =IF($G26="","",IF($G26=$A$78,1,0)) -> 1 | K26: =IF($H26="","",IF($H26=$A$78,1,0)) -> 0 | L26: No
A27: 46277 | B27: Cena | C27: D3 | D27: Postres | E27: 64 | F27: 9 | G27: Sí | H27: No | J27: =IF($G27="","",IF($G27=$A$78,1,0)) -> 1 | K27: =IF($H27="","",IF($H27=$A$78,1,0)) -> 0 | L27: No
A28: 46278 | B28: Comida | C28: P3 | D28: Principales | E28: 68 | F28: 14.5 | G28: Sí | H28: No | J28: =IF($G28="","",IF($G28=$A$78,1,0)) -> 1 | K28: =IF($H28="","",IF($H28=$A$78,1,0)) -> 0 | L28: No
A29: 46278 | B29: Comida | C29: E4 | D29: Entrantes | E29: 71 | F29: 10 | G29: Sí | H29: No | J29: =IF($G29="","",IF($G29=$A$78,1,0)) -> 1 | K29: =IF($H29="","",IF($H29=$A$78,1,0)) -> 0 | L29: No
A30: 46278 | B30: Comida | C30: P1 | D30: Principales | E30: 67 | F30: 18 | G30: No | H30: Sí | I30: Punto pasado: el cliente lo devuelve | J30: =IF($G30="","",IF($G30=$A$78,1,0)) -> 0 | K30: =IF($H30="","",IF($H30=$A$78,1,0)) -> 1 | L30: Sí
A31: 46278 | B31: Comida | C31: D2 | D31: Postres | E31: 57 | F31: 7.5 | G31: Sí | H31: No | J31: =IF($G31="","",IF($G31=$A$78,1,0)) -> 1 | K31: =IF($H31="","",IF($H31=$A$78,1,0)) -> 0 | L31: No
A32: 46278 | B32: Cena | C32: P5 | D32: Principales | E32: 63 | F32: 20 | G32: Sí | H32: No | J32: =IF($G32="","",IF($G32=$A$78,1,0)) -> 1 | K32: =IF($H32="","",IF($H32=$A$78,1,0)) -> 0 | L32: No
A33: 46278 | B33: Cena | C33: E2 | D33: Entrantes | E33: 9 | F33: 8.5 | G33: Sí | H33: No | J33: =IF($G33="","",IF($G33=$A$78,1,0)) -> 1 | K33: =IF($H33="","",IF($H33=$A$78,1,0)) -> 0 | L33: No
A34: 46278 | B34: Cena | C34: P4 | D34: Principales | E34: 75 | F34: 23 | G34: No | H34: No | I34: Sale 5 minutos por encima del tiempo de ficha | J34: =IF($G34="","",IF($G34=$A$78,1,0)) -> 0 | K34: =IF($H34="","",IF($H34=$A$78,1,0)) -> 0 | L34: No
A35: 46278 | B35: Cena | C35: D1 | D35: Postres | E35: 7 | F35: 6.5 | G35: Sí | H35: No | J35: =IF($G35="","",IF($G35=$A$78,1,0)) -> 1 | K35: =IF($H35="","",IF($H35=$A$78,1,0)) -> 0 | L35: No
J36: =IF($G36="","",IF($G36=$A$78,1,0)) | K36: =IF($H36="","",IF($H36=$A$78,1,0))
J37: =IF($G37="","",IF($G37=$A$78,1,0)) | K37: =IF($H37="","",IF($H37=$A$78,1,0))
J38: =IF($G38="","",IF($G38=$A$78,1,0)) | K38: =IF($H38="","",IF($H38=$A$78,1,0))
J39: =IF($G39="","",IF($G39=$A$78,1,0)) | K39: =IF($H39="","",IF($H39=$A$78,1,0))
J40: =IF($G40="","",IF($G40=$A$78,1,0)) | K40: =IF($H40="","",IF($H40=$A$78,1,0))
J41: =IF($G41="","",IF($G41=$A$78,1,0)) | K41: =IF($H41="","",IF($H41=$A$78,1,0))
...
