Workbook

Sheet Calculadora
A1: CALCULADORA DE PRESUPUESTO DEL ESPACIO PARA BODAS Y EVENTOS EN FINCA
A2: Escribe sólo en las celdas VERDES: todo lo demás se calcula. Importes sin IVA salvo donde la fila diga lo contrario. Los valores por defecto son estimaciones de ejemplo del kit: cámbialos por los de tu finca.
A4: DATOS DEL EVENTO | B4: Valor | C4: Notas
A5: Cliente | B5: Particular | C5: Particular o Empresa: cambian el calendario de cobros y los tramos de cancelación (tabla del final). Una empresa recibe el presupuesto «más IVA»; un particular, con el IVA incluido.
A6: Tipología del evento | B6: Boda | C6: Boda, empresa (jornada, comida, Navidad), celebración privada (comunión, bautizo, cumpleaños) o celebración pequeña (preboda, brunch, boda íntima). Fija la tarifa del espacio, el menú del catering y el coste directo con las tablas del final.
A7: Fecha del evento | B7: 46557 | C7: Escribe la fecha completa (dd/mm/aaaa). Fija la temporada y el tipo de día con las tablas de meses y de días de la semana.
A8: Invitados previstos | B8: 110 | C8: Número entero de invitados. Se garantiza el mayor entre este número y el mínimo de la temporada.
A9: Ceremonias en la finca (nº) | B9: 1 | C9: Civil o simbólica, a precio de la tabla de servicios extra.
A10: Horas extra de uso del espacio (nº) | B10: 2 | C10: Las horas que pasan del horario base de tu contrato.
A11: Montajes premium (nº) | B11: 1 | C11: Decoración, mobiliario y luces por encima del montaje básico.
A12: Alojamiento: habitaciones-noche (nº) | B12: 0 | C12: 0 si la finca no tiene habitaciones. Ejemplo: 6 habitaciones × 2 noches = 12.
A13: Horas de personal de la finca en el evento (coordinación y auxiliares) | B13: 16 | C13: Estimación del kit: pon las horas reales de tu equipo (no incluye cocina ni sala: las pone el catering).
A14: Coste bruto por hora del personal | B14: 13 | C14: Estimación del kit. Copia tu convenio provincial de hostelería.
A15: Seguridad Social a cargo de la empresa | B15: 0.33 | C15: 30,65 % de contingencias, desempleo, FOGASA, formación y MEI, más AT/EP (fijos discontinuos, art. 16 ET).
A16: Coste directo de los servicios extra (% sobre su precio) | B16: 0.4 | C16: Estimación del kit: lo que te cuesta prestar la ceremonia, el montaje, las horas extra y el alojamiento.
A17: Redondeo del precio del espacio (múltiplo, en euros) | B17: 50 | C17: El precio del espacio se redondea a este múltiplo, al más cercano.
A18: Canon del catering exclusivo (% de lo que factura el catering) | B18: 0.12 | C18: SUPUESTO editable, no un dato: negócialo con tu catering. Informativo: lo paga el catering a la finca, no el cliente.
... A20: IVA del menú del catering (solo orientativo) | B20: 0.1 | C20: El menú lo factura el catering, no la finca (comida y bebida para consumir en el acto, art. 91.Uno.2.2.º de la Ley 37/1992).
A22: CÁLCULO | B22: Valor | C22: Notas
A23: Temporada de la fecha (de la tabla de meses) | B23: =INDEX('Calculadora'!$B$83:$B$94,MONTH($B$7)) -> Alta | C23: Busca el mes de la fecha en la tabla del final.
A24: Tipo de día (de la tabla de días de la semana) | B24: =INDEX('Calculadora'!$B$97:$B$103,WEEKDAY($B$7)) -> Sábado | C24: Busca el día de la semana de la fecha en la tabla del final.
A25: Ajuste de temporada (suplemento + / descuento −) | B25: =INDEX('Calculadora'!$B$73:$B$75,MATCH($B$23,'Calculadora'!$A$73:$A$75,0)) -> 0.2 | C25: De la tabla de temporadas.
A26: Ajuste de día (suplemento + / descuento −) | B26: =INDEX('Calculadora'!$B$78:$B$80,MATCH($B$24,'Calculadora'!$A$78:$A$80,0)) -> 0 | C26: De la tabla de días.
A27: Tarifa del espacio de la tipología (sábado, temporada media) | B27: =INDEX('Calculadora'!$B$67:$B$70,MATCH($B$6,'Calculadora'!$A$67:$A$70,0)) -> 3600 | C27: De la tabla de tipologías.
A28: ALQUILER DEL ESPACIO SIN IVA | B28: =ROUND($B$27*(1+$B$25)*(1+$B$26)/$B$17,0)*$B$17 -> 4300 | C28: Tarifa × (1 + ajuste de temporada) × (1 + ajuste de día), redondeada al múltiplo elegido.
A29: Mínimo de invitados de la temporada | B29: =INDEX('Calculadora'!$C$73:$C$75,MATCH($B$23,'Calculadora'!$A$73:$A$75,0)) -> 80 | C29: De la tabla de temporadas.
A30: Invitados garantizados | B30: =MAX($B$8,$B$29) -> 110 | C30: El mayor entre los invitados previstos y el mínimo de la temporada.
A31: Aviso del mínimo | B31: =IF($B$8<$B$29,"Por debajo del mínimo: se garantiza el mínimo de la temporada","Cumple el mínimo") -> Cumple el mínimo
A32: Ceremonias | B32: =$B$9*'Calculadora'!$B$106 -> 450 | C32: Nº × precio de la tabla de servicios extra.
A33: Horas extra | B33: =$B$10*'Calculadora'!$B$107 -> 600
A34: Montajes premium | B34: =$B$11*'Calculadora'!$B$108 -> 600
A35: Alojamiento | B35: =$B$12*'Calculadora'!$B$109 -> 0
A36: Servicios extra sin IVA | B36: =$B$32+$B$33+$B$34+$B$35 -> 1650
A37: Base imponible (espacio + servicios) | B37: =$B$28+$B$36 -> 5950
A38: IVA de la finca | B38: =$B$37*$B$19 -> 1249.5
A39: TOTAL DE LA FINCA (con IVA) | B39: =$B$37+$B$38 -> 7199.5 | C39: No incluye el menú ni la bebida: los factura el catering exclusivo, aparte.
A40: Importe que presupuestas (Particular: con IVA · Empresa: más IVA) | B40: =IF($B$5="Particular",$B$39,$B$37) -> 7199.5 | C40: A una empresa se le presupuesta sin IVA («+ IVA»); a un particular, con los impuestos incluidos.
A41: Precio del espacio y servicios por invitado garantizado (sin IVA) | B41: =$B$37/$B$30 -> 54.090909 | C41: Para comparar con otras fincas.
A42: Importe del cobro 1: reserva | B42: =$B$39*INDEX('Calculadora'!$B$112:$C$112,MATCH($B$5,'Calculadora'!$B$111:$C$111,0)) -> 1799.875 | C42: Al firmar el contrato.
A43: Importe del cobro 2: segundo pago | B43: =$B$39*INDEX('Calculadora'!$B$113:$C$113,MATCH($B$5,'Calculadora'!$B$111:$C$111,0)) -> 2519.825
...

Sheet Ejemplos
A1: 3 PRESUPUESTOS DE EJEMPLO — con las mismas fórmulas de la hoja «Calculadora»
A2: Estimaciones del kit para ilustrar el cálculo, no precios de mercado: cambia los datos en «Calculadora» para presupuestar tus eventos. Las tablas (tarifas, temporadas, días, extras, cobros y cancelación) están al final de esa hoja y también mueven estos ejemplos.
A4: DATOS DEL EVENTO | B4: Boda de sábado en temporada alta | C4: Boda de viernes en temporada media | D4: Jornada de empresa entre semana
A5: Cliente | B5: Particular | C5: Particular | D5: Empresa
A6: Tipología del evento | B6: Boda | C6: Boda | D6: Empresa
A7: Fecha del evento | B7: 46557 | C7: 46584 | D7: 46498
A8: Invitados previstos | B8: 110 | C8: 90 | D8: 50
A9: Ceremonias en la finca (nº) | B9: 1 | C9: 1 | D9: 0
A10: Horas extra de uso del espacio (nº) | B10: 2 | C10: 0 | D10: 1
A11: Montajes premium (nº) | B11: 1 | C11: 0 | D11: 0
A12: Alojamiento: habitaciones-noche (nº) | B12: 0 | C12: 12 | D12: 0
A13: Horas de personal de la finca en el evento (coordinación y auxiliares) | B13: 16 | C13: 14 | D13: 10
A14: Coste bruto por hora del personal | B14: 13 | C14: 13 | D14: 13
A15: Seguridad Social a cargo de la empresa | B15: 0.33 | C15: 0.33 | D15: 0.33
A16: Coste directo de los servicios extra (% sobre su precio) | B16: 0.4 | C16: 0.4 | D16: 0.4
A17: Redondeo del precio del espacio (múltiplo, en euros) | B17: 50 | C17: 50 | D17: 50
A18: Canon del catering exclusivo (% de lo que factura el catering) | B18: 0.12 | C18: 0.12 | D18: 0.12
... A20: IVA del menú del catering (solo orientativo) | B20: 0.1 | C20: 0.1 | D20: 0.1
A22: RESULTADO | B22: Boda de sábado en temporada alta | C22: Boda de viernes en temporada media | D22: Jornada de empresa entre semana
A23: Temporada de la fecha (de la tabla de meses) | B23: =INDEX('Calculadora'!$B$83:$B$94,MONTH($B$7)) -> Alta | C23: =INDEX('Calculadora'!$B$83:$B$94,MONTH($C$7)) -> Media | D23: =INDEX('Calculadora'!$B$83:$B$94,MONTH($D$7)) -> Media
A24: Tipo de día (de la tabla de días de la semana) | B24: =INDEX('Calculadora'!$B$97:$B$103,WEEKDAY($B$7)) -> Sábado | C24: =INDEX('Calculadora'!$B$97:$B$103,WEEKDAY($C$7)) -> Viernes o domingo | D24: =INDEX('Calculadora'!$B$97:$B$103,WEEKDAY($D$7)) -> Entre semana
A25: Ajuste de temporada (suplemento + / descuento −) | B25: =INDEX('Calculadora'!$B$73:$B$75,MATCH($B$23,'Calculadora'!$A$73:$A$75,0)) -> 0.2 | C25: =INDEX('Calculadora'!$B$73:$B$75,MATCH($C$23,'Calculadora'!$A$73:$A$75,0)) -> 0 | D25: =INDEX('Calculadora'!$B$73:$B$75,MATCH($D$23,'Calculadora'!$A$73:$A$75,0)) -> 0
A26: Ajuste de día (suplemento + / descuento −) | B26: =INDEX('Calculadora'!$B$78:$B$80,MATCH($B$24,'Calculadora'!$A$78:$A$80,0)) -> 0 | C26: =INDEX('Calculadora'!$B$78:$B$80,MATCH($C$24,'Calculadora'!$A$78:$A$80,0)) -> -0.2 | D26: =INDEX('Calculadora'!$B$78:$B$80,MATCH($D$24,'Calculadora'!$A$78:$A$80,0)) -> -0.3
A27: Tarifa del espacio de la tipología (sábado, temporada media) | B27: =INDEX('Calculadora'!$B$67:$B$70,MATCH($B$6,'Calculadora'!$A$67:$A$70,0)) -> 3600 | C27: =INDEX('Calculadora'!$B$67:$B$70,MATCH($C$6,'Calculadora'!$A$67:$A$70,0)) -> 3600 | D27: =INDEX('Calculadora'!$B$67:$B$70,MATCH($D$6,'Calculadora'!$A$67:$A$70,0)) -> 2300
A28: ALQUILER DEL ESPACIO SIN IVA | B28: =ROUND($B$27*(1+$B$25)*(1+$B$26)/$B$17,0)*$B$17 -> 4300 | C28: =ROUND($C$27*(1+$C$25)*(1+$C$26)/$C$17,0)*$C$17 -> 2900 | D28: =ROUND($D$27*(1+$D$25)*(1+$D$26)/$D$17,0)*$D$17 -> 1600
A29: Mínimo de invitados de la temporada | B29: =INDEX('Calculadora'!$C$73:$C$75,MATCH($B$23,'Calculadora'!$A$73:$A$75,0)) -> 80 | C29: =INDEX('Calculadora'!$C$73:$C$75,MATCH($C$23,'Calculadora'!$A$73:$A$75,0)) -> 60 | D29: =INDEX('Calculadora'!$C$73:$C$75,MATCH($D$23,'Calculadora'!$A$73:$A$75,0)) -> 60
A30: Invitados garantizados | B30: =MAX($B$8,$B$29) -> 110 | C30: =MAX($C$8,$C$29) -> 90 | D30: =MAX($D$8,$D$29) -> 60
A31: Aviso del mínimo | B31: =IF($B$8<$B$29,"Por debajo del mínimo: se garantiza el mínimo de la temporada","Cumple el mínimo") -> Cumple el mínimo | C31: =IF($C$8<$C$29,"Por debajo del mínimo: se garantiza el mínimo de la temporada","Cumple el mínimo") -> Cumple el mínimo | D31: =IF($D$8<$D$29,"Por debajo del mínimo: se garantiza el mínimo de la temporada","Cumple el mínimo") -> Por debajo del mínimo: se garantiza el mínimo de la temporada
A32: Ceremonias | B32: =$B$9*'Calculadora'!$B$106 -> 450 | C32: =$C$9*'Calculadora'!$B$106 -> 450 | D32: =$D$9*'Calculadora'!$B$106 -> 0
A33: Horas extra | B33: =$B$10*'Calculadora'!$B$107 -> 600 | C33: =$C$10*'Calculadora'!$B$107 -> 0 | D33: =$D$10*'Calculadora'!$B$107 -> 300
A34: Montajes premium | B34: =$B$11*'Calculadora'!$B$108 -> 600 | C34: =$C$11*'Calculadora'!$B$108 -> 0 | D34: =$D$11*'Calculadora'!$B$108 -> 0
A35: Alojamiento | B35: =$B$12*'Calculadora'!$B$109 -> 0 | C35: =$C$12*'Calculadora'!$B$109 -> 1800 | D35: =$D$12*'Calculadora'!$B$109 -> 0
A36: Servicios extra sin IVA | B36: =$B$32+$B$33+$B$34+$B$35 -> 1650 | C36: =$C$32+$C$33+$C$34+$C$35 -> 2250 | D36: =$D$32+$D$33+$D$34+$D$35 -> 300
A37: Base imponible (espacio + servicios) | B37: =$B$28+$B$36 -> 5950 | C37: =$C$28+$C$36 -> 5150 | D37: =$D$28+$D$36 -> 1900
A38: IVA de la finca | B38: =$B$37*$B$19 -> 1249.5 | C38: =$C$37*$C$19 -> 1081.5 | D38: =$D$37*$D$19 -> 399
A39: TOTAL DE LA FINCA (con IVA) | B39: =$B$37+$B$38 -> 7199.5 | C39: =$C$37+$C$38 -> 6231.5 | D39: =$D$37+$D$38 -> 2299
A40: Importe que presupuestas (Particular: con IVA · Empresa: más IVA) | B40: =IF($B$5="Particular",$B$39,$B$37) -> 7199.5 | C40: =IF($C$5="Particular",$C$39,$C$37) -> 6231.5 | D40: =IF($D$5="Particular",$D$39,$D$37) -> 1900
A41: Precio del espacio y servicios por invitado garantizado (sin IVA) | B41: =$B$37/$B$30 -> 54.090909 | C41: =$C$37/$C$30 -> 57.222222 | D41: =$D$37/$D$30 -> 31.666667
A42: Importe del cobro 1: reserva | B42: =$B$39*INDEX('Calculadora'!$B$112:$C$112,MATCH($B$5,'Calculadora'!$B$111:$C$111,0)) -> 1799.875 | C42: =$C$39*INDEX('Calculadora'!$B$112:$C$112,MATCH($C$5,'Calculadora'!$B$111:$C$111,0)) -> 1557.875 | D42: =$D$39*INDEX('Calculadora'!$B$112:$C$112,MATCH($D$5,'Calculadora'!$B$111:$C$111,0)) -> 689.7
A43: Importe del cobro 2: segundo pago | B43: =$B$39*INDEX('Calculadora'!$B$113:$C$113,MATCH($B$5,'Calculadora'!$B$111:$C$111,0)) -> 2519.825 | C43: =$C$39*INDEX('Calculadora'!$B$113:$C$113,MATCH($C$5,'Calculadora'!$B$111:$C$111,0)) -> 2181.025 | D43: =$D$39*INDEX('Calculadora'!$B$113:$C$113,MATCH($D$5,'Calculadora'!$B$111:$C$111,0)) -> 689.7
...

Sheet Instrucciones
A1: INSTRUCCIONES DE USO — Calculadora de presupuesto del espacio para bodas y eventos en finca
A2: Convierte tu tarifa de alquiler en un presupuesto completo para un evento concreto: temporada y día de la fecha, mínimo de invitados, servicios extra, IVA, total, calendario de cobros, canon estimado del catering, margen del evento y lo que retienes si el cliente cancela. Sólo se escribe en las celdas VERDES; el margen se calcula.
A3: 1. Elige el cliente (Particular o Empresa), la tipología del evento, la fecha completa y los invitados previstos.
A4: 2. La fecha fija la temporada (tabla de meses) y el tipo de día (tabla de días de la semana). Cada una lleva un suplemento o un descuento visible en su tabla; los dos se multiplican con la tarifa de la tipología.
A5: 3. Cada temporada tiene un mínimo de invitados: se garantiza el mayor entre los previstos y el mínimo, y sobre esos invitados garantizados se estima el canon.
A6: 4. Escribe cuántos servicios extra llevas (ceremonia, horas extra, montaje premium, alojamiento). Sus precios están en la tabla «Servicios extra de la finca» y son de ejemplo: pon los tuyos.
A7: 5. Escribe las horas de personal de la finca, el coste bruto por hora, la Seguridad Social y el coste directo de los extras. El coste directo del evento (limpieza, aseos, gasoil, vigilancia y música) está en la tabla de tipologías.
A8: IVA, CANON Y MENÚ
A10: La finca factura el espacio y los servicios con precio propio al 21 %. El menú y la bebida los factura el catering exclusivo: comida y bebida para consumir en el acto van al 10 % (Ley 37/1992, art. 91.Uno.2.2.º), y no son ingreso de la finca. La calculadora los muestra sólo como orientación para el cliente. Si vendes un paquete que mezcla ambos, consúltalo con tu asesoría.
A11: El canon es lo que el catering exclusivo paga a la finca por tener la exclusiva. Aquí es un supuesto editable (12 % de lo que factura el catering): no es un dato de mercado, negócialo. Lo paga el catering, no el cliente; la finca lo factura con IVA.
A12: El margen del evento es una contribución: no descuenta la renta, el personal fijo, los suministros, los seguros ni la estructura. Eso está en el plan financiero.
A13: COBRO Y CANCELACIÓN
... A25: Versión 1.0 · noviembre 2026 · aichef.pro/plan-negocio-finca-eventos-bodas · info@aichef.pro
