Workbook

Sheet 0. Supuestos
A1: SUPUESTOS — aquí se teclean las TASAS y los DRIVERS del modelo
A2: Cambia las celdas VERDES: el resto del libro se recalcula solo. Las partidas de gasto se teclean en su hoja (también en verde) y no se repiten aquí.
A3: ACTIVIDAD
A4: Invitados por evento (media del año 1) | B4: 82 | C4: Invitados de media por evento en el año 1. Sale de la mezcla de la tabla de referencias de la hoja de Instrucciones: bodas de 120, eventos de empresa de 80, celebraciones privadas de 70 y eventos pequeños de 40. Es una media: el aforo de la finca está más abajo
A5: Precio medio por invitado SIN IVA (€) | B5: 37 | C5: SIN IVA, por invitado: lo que factura la FINCA, no lo que pagan los novios por la boda entera. Suma el espacio y los servicios (ceremonia, montaje, coordinación, limpieza y aparcamiento) y el canon que te paga el catering por cada invitado. Media de la mezcla: 47 € la boda, 34 € el evento de empresa, 29 € la celebración privada y 30 € el evento pequeño. El precio con IVA (21 %) está en la fila de abajo
A6: Eventos al año | B6: 120 | C6: Eventos celebrados en el año: 30 bodas, 35 de empresa (jornadas, comidas, Navidad), 40 celebraciones privadas (comuniones, bautizos, cumpleaños) y 15 pequeños (preboda, brunch, bodas íntimas). Es el MISMO dato para la cuenta de resultados, el punto de equilibrio, los escenarios y las horas de personal
A7: Crecimiento de volumen del año 2 | B7: 0.08 | C7: Más actividad el segundo año: bodas que llegan por recomendación, empresas que repiten y planners que ya te conocen. El libro lo aplica a los invitados por evento con los mismos eventos; en euros es lo mismo que un 8 % más de eventos del mismo tamaño (unos 130). El personal no sube con este porcentaje: crece con las incorporaciones de la hoja Personal
A8: Crecimiento de volumen del año 3 | B8: 0.05 | C8: Sobre el año 2 (unos 136 eventos equivalentes). Conservador: el techo lo ponen los sábados de temporada y el aforo de la finca
A9: PVP equivalente con IVA (calculado) | B9: =IFERROR(IF($B$5="","",$B$5*(1+SUMPRODUCT('PyG 3 Años'!$E$10:$E$11,'PyG 3 Años'!$G$10:$G$11))),"") -> 44.77 | C9: =IFERROR("Precio por invitado sin IVA más el IVA medio ponderado de tus líneas de venta: "&TEXT(SUMPRODUCT('PyG 3 Años'!$E$10:$E$11,'PyG 3 Años'!$G$10:$G$11)*100,"0")&" %. La finca factura el espacio, los servicios y el canon al 21 %, el tipo general; el menú y la barra los factura el catering a los novios, al 10 % (art. 91.Uno.2.2.º de la Ley 37/1992), y no entran en este libro. Aquí va redondeado. "&"Compáralo con el rango del sector, que va con IVA.","") -> Precio por invitado sin IVA más el IVA medio ponderado de tus líneas de venta: 21 %. La finca factura el espacio, los servicios y el canon al 21 %, el tipo general; el menú y la barra los factura el catering a los novios, al 10 % (art. 91.Uno.2.2.º de la Ley 37/1992), y no entran en este libro. Aquí va redondeado. Compáralo con el rango del sector, que va con IVA.
A10: MEZCLA DE VENTAS Y COSTE DIRECTO
A11: Ventas de ESPACIO Y SERVICIOS sobre el total | B11: 0.78 | C11: Peso del ESPACIO Y LOS SERVICIOS sobre el total de ventas. Es un INPUT: cámbialo aquí y el P&L, la tesorería y el IVA repercutido se recalculan solos
A12: Ventas del CANON DEL CATERING sobre el total | B12: =IFERROR(IF(COUNT(B11)=0,"",1-B11),"") -> 0.22 | C12: Se calcula como el resto: espacio y servicios + canon = 100 %
A13: Coste directo del evento sobre las ventas de ESPACIO Y SERVICIOS | B13: 0.163 | C13: Coste directo del evento sobre las ventas de espacio y servicios: limpieza tras el evento, reposición de aseos y consumibles, gasoil del grupo electrógeno, vigilancia y aparcamiento, y la tarifa de SGAE y AGEDI-AIE de cada evento. Unos 650 € por boda, 350 € por evento de empresa, 300 € por celebración privada y 150 € por evento pequeño: 46.000 € al año
A14: Coste del canon sobre las ventas del CANON | B14: 0 | C14: A CERO: el canon no tiene coste para la finca. La comida y la bebida las compra el catering, que es quien las vende a los novios
A15: Consumibles sobre ventas | B15: 0.02 | C15: Velas, flores base, papel y productos de los aseos, y los pequeños consumibles de cada montaje
A16: Ventas que llegan por wedding planners y agencias sobre el total | B16: 0.2 | C16: Parte de las ventas que llega por un wedding planner o una agencia de eventos, que cobra una comisión. No cambia el IVA: todo lo que factura la finca va al 21 %
A17: Comisión de los wedding planners y agencias | B17: 0.125 | C17: Comisión media sobre lo que vende ese canal: el punto medio de un 10-15 %. Si todas las reservas te llegan directas, pon 0
A18: Comisión de los medios de pago | B18: 0.003 | C18: Casi todo se cobra por transferencia (señales, pagos de los novios y facturas de empresa); el datáfono queda para los extras del día
A19: PERSONAL
A20: Seguridad Social a cargo de la empresa | B20: 0.33 | C20: Contingencias comunes + AT/EP + desempleo + FOGASA + FP; ajusta a tu convenio y bonificaciones
A21: Número de pagas anuales | B21: 14 | C21: Salario bruto anual = bruto mensual × pagas
A22: SMI anual de referencia (€) | B22: 17094 | C22: SMI 2026: 17.094 € al año (1.221 €/mes en 14 pagas), suelo legal por jornada completa. Comprueba el importe vigente si presentas el plan en otro ejercicio
A23: FINCA Y FIJOS
A24: Renta mensual de la finca (€) | B24: 3500 | C24: Renta de mercado de una finca con edificaciones existentes (salón, aseos y office) arrendada a una SL, con contrato de quince años o más. Lleva IVA al 21 %. Si la finca es de tu familia, la renta tiene que ser la de mercado igual. El peso sobre las ventas lo calcula el libro en la fila «Renta de la finca / Ventas» del P&L
A25: Fianza del arrendamiento (meses) | B25: 2 | C25: Dos meses de renta como fianza, lo habitual en un arrendamiento de uso distinto del de vivienda; los avales o garantías adicionales se negocian aparte. Compruébalo con tu abogado antes de firmar
A26: Suministros mensuales (luz, agua, gasoil y teléfono) (€) | B26: 1600 | C26: Luz con potencia para el salón y el exterior, agua de riego, gasoil del grupo electrógeno fuera de los eventos y teléfono. Pide al propietario el histórico de consumos
A27: Seguros (€/año) | B27: 5500 | C27: Responsabilidad civil de la actividad con el capital que fije tu comunidad por aforo (en Andalucía, 526.000 € para 101-300 personas), daños a las mejoras de la finca, pérdida de beneficio y accidentes. Exige además al catering su propio seguro de responsabilidad civil e intoxicación
A28: Varios e imprevistos sobre ventas | B28: 0.02 | C28: Roturas, imprevistos de cada montaje y desplazamientos comerciales (ferias y visitas a planners)
A29: FINANCIACIÓN
A30: Recursos propios aportados (€) | B30: 100000 | C30: Aportación de los socios. Un banco pide entre el 25 y el 30 % de la necesidad de caja con dinero propio
A31: Préstamo bancario solicitado (€) | B31: 263000 | C31: Principal solicitado. La hoja de Financiación compara lo que aportas con la necesidad de caja de la hoja de inversión y te dice si sobra o falta: ajústalo con ese dato. La finca no es tuya, así que no hay garantía inmobiliaria: pregunta por avales y por líneas públicas
A32: Tipo de interés nominal anual | B32: 0.065 | C32: Tipo nominal anual de un préstamo de empresa sin garantía inmobiliaria. Pide oferta a dos entidades y a una línea ICO antes de fijarlo
A33: Plazo del préstamo (años) | B33: 8 | C33: Años totales, carencia incluida. Con seis años la cuota no cabe en un negocio con tanta estructura fija
A34: Carencia de principal (años) | B34: 1 | C34: El primer año, sólo intereses: es el año de arranque y la caja va más justa. Desde el segundo año se devuelve el principal: mira la holgura de caja de ese año en el Punto de Equilibrio
A35: Fondo de maniobra (meses de costes fijos) | B35: 3 | C35: Tres meses de costes fijos: son el colchón de los primeros meses, recién pagada la inversión y antes de las bodas de mayo y junio. En un año normal, de noviembre a febrero entra alrededor del 23 % de la venta con la renta y la plantilla planas: ese invierno se pasa con la caja de la temporada
A36: FISCAL
A37: Impuesto de Sociedades, nueva creación | B37: 0.15 | C37: Art. 29.1 LIS: el PRIMER ejercicio con base imponible positiva y el SIGUIENTE. El libro lo aproxima contando los dos primeros ejercicios con base positiva: coincide con la ley salvo que entre ellos haya un ejercicio en pérdidas
A38: Impuesto de Sociedades, tipo general | B38: 0.25 | C38: A partir del tercer ejercicio con base positiva. Es el tipo general del art. 29.1 LIS: si tu cifra de negocios queda por debajo de 1 M € (microempresa) o de 10 M € (reducida dimensión), desde 2025 hay tipos más bajos que se implantan de forma gradual; confirma el de tu ejercicio con tu asesor y cámbialo aquí
A39: IVA repercutido de restauración | B39: 0.1 | C39: No se usa en este plan: la finca no vende comida ni bebida. Es el tipo del menú del catering
A40: IVA repercutido/soportado general | B40: 0.21 | C40: Tipo general. En este plan es el de todo lo que factura la finca (espacio, servicios y canon) y el de casi todo lo que compra; suministros, equipamiento y servicios tienen su tipo en la celda de abajo. La finca no vende comida ni bebida: el menú y la barra los factura el catering, al 10 % (art. 91.Uno.2.2.º de la Ley 37/1992)
...

Sheet Inversión Inicial
A1: PLAN DE NEGOCIO: FINCA DE EVENTOS Y BODAS
A2: Inversión inicial estimada — finca arrendada con edificaciones existentes y catering exclusivo concesionado
A3: Ajusta las cifras a tu proyecto.
A5: Concepto | B5: Importe | C5: % s/inversión | D5: Notas | E5: ¿Lleva IVA?
A6: INVERSIÓN | B6: =IFERROR(IF(COUNT(B7:B28)=0,"",SUM(B7:B28)),"") -> 251780 | C6: =IFERROR(B6/$B$31,"") -> 0.80851935
A7: Proyecto técnico y dirección de obra | B7: 7000 | C7: =IFERROR(B7/$B$31,"") -> 0.022478495 | D7: Proyecto de adecuación y de la actividad, dirección de obra y certificado final. Es la base de la calificación o autorización urbanística y de la licencia | E7: Sí
A8: Licencias, tasas, calificación urbanística y prestación compensatoria o canon | B8: 10000 | C8: =IFERROR(B8/$B$31,"") -> 0.032112136 | D8: Lo que cobra la administración en suelo rústico, distinto en cada comunidad: en Andalucía, prestación compensatoria del 10 % de las obras sin maquinaria (LISTA, art. 22.5); en la C. Valenciana, canon del 2 % (TRLOTUP, art. 221). En Andalucía, sólo la prestación serían unos 13.000 € con la obra del caso: súbela si es tu comunidad. No lleva IVA. Ajusta esta partida a la tuya: compruébalo en tu ayuntamiento y en tu comunidad | E8: No
A9: Adecuación del salón: suelos, cerramientos, carpintería y pintura | B9: 30000 | C9: =IFERROR(B9/$B$31,"") -> 0.096336407 | D9: Sobre edificaciones EXISTENTES: en suelo rústico es lo que exigen Madrid y Cataluña y la vía rápida de la C. Valenciana. Pide dos presupuestos sobre el proyecto | E9: Sí
A10: Acústica y aislamiento del salón | B10: 9000 | C10: =IFERROR(B10/$B$31,"") -> 0.028900922 | D10: Para que el baile final pueda ir dentro y cumplir los 45 dBA de noche al exterior en zona residencial (RD 1367/2007, anexo III) | E10: Sí
A11: Carpa estructural o pérgola para ceremonia y cóctel | B11: 28000 | C11: =IFERROR(B11/$B$31,"") -> 0.08991398 | D11: Es el plan B de lluvia: inversión, no extra. Una carpa es una instalación desmontable: para el plan de autoprotección estatal tiene el mismo umbral que un edificio cerrado, 1.000 personas (Orden INT/1068/2026) | E11: Sí
A12: Aseos: dos bloques y uno adaptado | B12: 22000 | C12: =IFERROR(B12/$B$31,"") -> 0.070646698 | D12: Con un aseo adaptado e itinerario accesible: compruébalo con tu técnico sobre el Código Técnico. Incluye la conexión al saneamiento (fosa séptica o depuradora); si hay que hacerla nueva o ampliarla para el aforo, súbela | E12: Sí
A13: Instalación eléctrica: cuadro, alumbrado exterior y de emergencia | B13: 15000 | C13: =IFERROR(B13/$B$31,"") -> 0.048168203 | D13: Potencia para el salón, la carpa, el office y el exterior, con su boletín. Pregunta la potencia disponible ANTES de firmar: una acometida nueva en el campo tarda | E13: Sí
A14: Grupo electrógeno | B14: 10000 | C14: =IFERROR(B14/$B$31,"") -> 0.032112136 | D14: Respaldo si la red falla o no llega la potencia: un corte de luz en mitad de una boda no tiene arreglo | E14: Sí
A15: Climatización del salón | B15: 17000 | C15: =IFERROR(B15/$B$31,"") -> 0.05459063 | D15: Frío y calor para usar el salón todo el año, también en las bodas de agosto | E15: Sí
A16: Office del catering: cámara, fregaderos, mesas inox, agua y desagüe | B16: 16000 | C16: =IFERROR(B16/$B$31,"") -> 0.051379417 | D16: El espacio donde el catering emplata y friega. La cocina de producción la pone él: por eso el plan no lleva cocina. Lo inscribe en el registro sanitario quien lo usa; compruébalo en tu comunidad | E16: Sí
A17: Mobiliario de ceremonia y banquete: mesas, sillas y mantelería base | B17: 18000 | C17: =IFERROR(B17/$B$31,"") -> 0.057801844 | D17: Mesas redondas e imperiales, 300 sillas y mantelería base. La decoración especial la contratan los novios | E17: Sí
A18: Zona chill-out y decoración base | B18: 4000 | C18: =IFERROR(B18/$B$31,"") -> 0.012844854 | D18: Sofás, iluminación ambiental y elementos fijos de decoración | E18: Sí
... A25: Lanzamiento: feria nupcial, puertas abiertas y escaparate premium | B25: 6000 | C25: =IFERROR(B25/$B$31,"") -> 0.019267281 | D25: La primera feria de novios, la jornada de puertas abiertas con el catering y el escaparate de pago en un portal de bodas durante el primer año | E25: Sí
A26: Fianza del arrendamiento | B26: =IFERROR(IF('0. Supuestos'!$B$24="","",'0. Supuestos'!$B$24*'0. Supuestos'!$B$25),"") -> 7000 | C26: =IFERROR(B26/$B$31,"") -> 0.022478495 | D26: =IFERROR(""&TEXT('0. Supuestos'!$B$25,"0")&" meses de renta, al tipo de la hoja de Supuestos. Es un activo recuperable al cerrar: ni se amortiza ni lleva IVA","") -> 2 meses de renta, al tipo de la hoja de Supuestos. Es un activo recuperable al cerrar: ni se amortiza ni lleva IVA | E26: No
A27: Renta de la finca durante la obra | B27: =IFERROR(IF('0. Supuestos'!$B$24="","",'0. Supuestos'!$B$24*'0. Supuestos'!$B$54),"") -> 3500 | C27: =IFERROR(B27/$B$31,"") -> 0.011239247 | D27: =IFERROR("Renta "&IF('0. Supuestos'!$B$54=1,"del mes","de los "&TEXT('0. Supuestos'!$B$54,"0")&" meses")&" de obra y licencias. NO se solapa con el P&L, que arranca el día de la apertura: los doce meses del P&L son los doce de explotación","") -> Renta del mes de obra y licencias. NO se solapa con el P&L, que arranca el día de la apertura: los doce meses del P&L son los doce de explotación | E27: Sí
A28: Imprevistos de obra y acondicionamiento | B28: =IFERROR(IF(COUNT(B7,B9,B10,B12,B13,B15,B16,B20,B21,B22)=0,"",ROUND((B7+B9+B10+B12+B13+B15+B16+B20+B21+B22)*'0. Supuestos'!$B$55,0)),"") -> 11280 | C28: =IFERROR(B28/$B$31,"") -> 0.036222489 | D28: =IFERROR("Al "&TEXT('0. Supuestos'!$B$55,"0%")&" de las partidas de OBRA Y ACONDICIONAMIENTO de este bloque (Proyecto técnico y dirección de obra, Adecuación del salón: suelos, cerramientos, carpintería y pintura, Acústica y aislamiento del salón, Aseos: dos bloques y uno adaptado, "&"Instalación eléctrica: cuadro, alumbrado exterior y de emergencia, Climatización del salón, Office del catering: cámara, fregaderos, mesas inox, agua y desagüe, Aparcamiento y caminos: zahorra, señalización e iluminación, Jardinería, "&"paisajismo y riego inicial y Protección contra incendios, señalización de evacuación y accesibilidad), no del bloque entero: el resto de partidas del bloque quedan fuera. Un banco no financia una reforma sin colchón: el porcentaje está en "&"la hoja de Supuestos","") -> Al 8% de las partidas de OBRA Y ACONDICIONAMIENTO de este bloque (Proyecto técnico y dirección de obra, Adecuación del salón: suelos, cerramientos, carpintería y pintura, Acústica y aislamiento del salón, Aseos: dos bloques y uno adaptado, Instalación eléctrica: cuadro, alumbrado exterior y de emergencia, Climatización del salón, Office del catering: cámara, fregaderos, mesas inox, agua y desagüe, Aparcamiento y caminos: zahorra, señalización e iluminación, Jardinería, paisajismo y riego inicial y Protección contra incendios, señalización de evacuación y accesibilidad), no del bloque entero: el resto de partidas del bloque quedan fuera. Un banco no financia una reforma sin colchón: el porcentaje está en la hoja de Supuestos | E28: Sí
A29: FONDO DE MANIOBRA | B29: =IFERROR(IF(B30="","",B30),"") -> 59628.75 | C29: =IFERROR(B29/$B$31,"") -> 0.19148065
A30: Colchón operativo hasta alcanzar el equilibrio | B30: =IFERROR(IF('0. Supuestos'!$B$35*('PyG 3 Años'!$B$38-'PyG 3 Años'!$B$36)=0,"",'0. Supuestos'!$B$35*('PyG 3 Años'!$B$38-'PyG 3 Años'!$B$36)/12),"") -> 59628.75 | C30: =IFERROR(B30/$B$31,"") -> 0.19148065 | D30: =IFERROR("Cubre "&TEXT('0. Supuestos'!$B$35,"0")&IF('0. Supuestos'!$B$35=1," mes"," meses")&" de costes fijos DE CAJA del año 1 (los del P&L menos la amortización, que no se paga), que es el mínimo que exigen las Instrucciones de este libro","") -> Cubre 3 meses de costes fijos DE CAJA del año 1 (los del P&L menos la amortización, que no se paga), que es el mínimo que exigen las Instrucciones de este libro | E30: No
A31: INVERSIÓN TOTAL (suma de los bloques) | B31: =IFERROR(B6+B29,"") -> 311408.75 | D31: =IFERROR("Los porcentajes de la columna C se leen sobre esta cifra, que incluye el fondo de maniobra ("&TEXT(C29,"0%")&" del total). Para comparar el desglose con otro plan, usa la fila de CAPEX de abajo.","") -> Los porcentajes de la columna C se leen sobre esta cifra, que incluye el fondo de maniobra (19% del total). Para comparar el desglose con otro plan, usa la fila de CAPEX de abajo.
A32: CAPEX (inversión sin el fondo de maniobra) | B32: =IFERROR(B31-B29,"") -> 251780 | D32: Es lo que se compra: obra, equipamiento, lanzamiento y gastos de constitución. El colchón de caja no es inversión, es circulante
A33: IVA soportado sobre la inversión (recuperable) | B33: =IFERROR(IF(B31="","",SUMIF($E$7:$E$28,"Sí",$B$7:$B$28)*'0. Supuestos'!$B$41),"") -> 49093.8 | D33: =IFERROR("Al "&TEXT('0. Supuestos'!$B$41,"0%")&" sobre las partidas marcadas con «Sí» en la columna de IVA. Las tasas y licencias no están sujetas y los seguros están exentos (art. 20.Uno.16 LIVA). Las tasas y aranceles registrales no llevan IVA; los honorarios de notaría y gestoría sí "&"(21 %, deducible). Se recupera con el modelo 303, pero hay que adelantarlo","") -> Al 21% sobre las partidas marcadas con «Sí» en la columna de IVA. Las tasas y licencias no están sujetas y los seguros están exentos (art. 20.Uno.16 LIVA). Las tasas y aranceles registrales no llevan IVA; los honorarios de notaría y gestoría sí (21 %, deducible). Se recupera con el modelo 303, pero hay que adelantarlo
A34: NECESIDAD TOTAL DE CAJA AL ARRANQUE | B34: =IFERROR(B31+B33,"") -> 360502.55 | D34: Es la cifra que tiene que cubrir la hoja de Financiación
A35: BASES DE AMORTIZACIÓN (no suman a la inversión)
A36: Obra, instalaciones y acondicionamiento | B36: =IFERROR(IF(B7="","",B7+B9+B10+B12+B13+B15+B16+B20+B21+B22+B28),"") -> 152280 | D36: =IFERROR("Se amortiza en "&TEXT('0. Supuestos'!$B$44,"0")&" años","") -> Se amortiza en 15 años
A37: Maquinaria, mobiliario y equipos | B37: =IFERROR(IF(B11="","",B11+B14+B17+B18+B19),"") -> 66000 | D37: =IFERROR("Se amortiza en "&TEXT('0. Supuestos'!$B$45,"0")&" años","") -> Se amortiza en 10 años
A38: Amortización anual del inmovilizado | B38: =IFERROR(B36/MAX(1,'0. Supuestos'!$B$44)+B37/MAX(1,'0. Supuestos'!$B$45),"") -> 16752 | D38: =IFERROR("No se amortizan, por no ser inmovilizado, Licencias, tasas, calificación urbanística y prestación compensatoria o canon, Web, fotos, vídeo y marca, Constitución de la SL, Lanzamiento: feria nupcial, puertas abiertas y escaparate premium, "&"Fianza del arrendamiento, Renta de la finca durante la obra ni Colchón operativo hasta alcanzar el equilibrio. Suman "&TEXT(B31-B36-B37,"0")&" € de los "&TEXT(B31,"0")&" € de inversión.","") -> No se amortizan, por no ser inmovilizado, Licencias, tasas, calificación urbanística y prestación compensatoria o canon, Web, fotos, vídeo y marca, Constitución de la SL, Lanzamiento: feria nupcial, puertas abiertas y escaparate premium, Fianza del arrendamiento, Renta de la finca durante la obra ni Colchón operativo hasta alcanzar el equilibrio. Suman 93129 € de los 311409 € de inversión.

Sheet PyG 3 Años
A1: CUENTA DE RESULTADOS — 3 AÑOS
A2: Escenario realista — finca de eventos y bodas
A4: Concepto | B4: Año 1 | C4: Año 2 | D4: Año 3 | E4: % s/ventas (año 1) | F4: Notas | G4: Tipo de IVA de la línea (%)
A5: INGRESOS
A6: Invitados por evento (media) | B6: =IFERROR(IF('0. Supuestos'!$B$4="","",'0. Supuestos'!$B$4),"") -> 82 | C6: =IFERROR(B6*(1+'0. Supuestos'!$B$7),"") -> 88.56 | D6: =IFERROR(C6*(1+'0. Supuestos'!$B$8),"") -> 92.988 | F6: El crecimiento de los años 2 y 3 está en la hoja de Supuestos
A7: Precio medio por invitado sin IVA | B7: =IFERROR(IF('0. Supuestos'!$B$5="","",'0. Supuestos'!$B$5),"") -> 37 | C7: =IFERROR(IF(B7="","",B7),"") -> 37 | D7: =IFERROR(IF(C7="","",C7),"") -> 37 | F7: Constante en euros del año 1: una subida de precios es una decisión aparte
A8: Eventos al año | B8: =IFERROR(IF('0. Supuestos'!$B$6="","",'0. Supuestos'!$B$6),"") -> 120 | C8: =IFERROR(IF(B8="","",B8),"") -> 120 | D8: =IFERROR(IF(C8="","",C8),"") -> 120
A9: INGRESOS TOTALES (sin IVA) | B9: =IFERROR(IF(B6*B7*B8=0,"",B6*B7*B8),"") -> 364080 | C9: =IFERROR(IF(C6*C7*C8=0,"",C6*C7*C8),"") -> 393206.4 | D9: =IFERROR(IF(D6*D7*D8=0,"",D6*D7*D8),"") -> 412866.72 | E9: =IFERROR(IF(B9="","",1),"") -> 1
A10: Ventas de alquiler del espacio y servicios del evento | B10: =IFERROR(IF(B9="","",B9*$E$10),"") -> 283982.4 | C10: =IFERROR(IF(C9="","",C9*$E$10),"") -> 306700.99 | D10: =IFERROR(IF(D9="","",D9*$E$10),"") -> 322036.04 | E10: =IFERROR(IF('0. Supuestos'!$B$11="","",'0. Supuestos'!$B$11),"") -> 0.78 | F10: Lo que pagan los novios y las empresas a la finca: el espacio, la ceremonia, el montaje, la coordinación del día, la limpieza y el aparcamiento. Con precio propio va al 21 % · El tipo de IVA que REPERCUTE esta línea es un input (celda verde de la derecha): cámbialo sólo si tu asesoría te confirma otro tipo. | G10: 0.21
A11: Canon del catering exclusivo | B11: =IFERROR(IF(B9="","",B9*$E$11),"") -> 80097.6 | C11: =IFERROR(IF(C9="","",C9*$E$11),"") -> 86505.408 | D11: =IFERROR(IF(D9="","",D9*$E$11),"") -> 90830.678 | E11: =IFERROR(IF('0. Supuestos'!$B$12="","",'0. Supuestos'!$B$12),"") -> 0.22 | F11: Lo que te paga el catering de la casa por servir en la finca. El plan supone el 12 % de lo que factura en ella, unos 13 € por invitado en una boda: es un supuesto, negócialo. Factura de la finca al catering, al 21 % · El tipo de IVA que REPERCUTE esta línea es un input (celda verde de la derecha): cámbialo sólo si tu asesoría te confirma otro tipo. | G11: 0.21
A12: COSTES VARIABLES
A13: Coste directo del evento | B13: =IFERROR(IF(B9="","",B9*'0. Supuestos'!$B$11*'0. Supuestos'!$B$13),"") -> 46289.131 | C13: =IFERROR(IF(C9="","",C9*'0. Supuestos'!$B$11*'0. Supuestos'!$B$13),"") -> 49992.262 | D13: =IFERROR(IF(D9="","",D9*'0. Supuestos'!$B$11*'0. Supuestos'!$B$13),"") -> 52491.875 | E13: =IFERROR(B13/$B$9,"") -> 0.12714 | F13: =IFERROR("Al "&TEXT('0. Supuestos'!$B$13,"0%")&" de las ventas de ESPACIO Y SERVICIOS, no del total: el canon tiene su propia línea · El IVA que SOPORTAS en el coste directo del evento: limpieza, consumibles, gasoil, vigilancia y la tarifa de SGAE van al 21 %. Ajústalo a tus facturas","") -> Al 16% de las ventas de ESPACIO Y SERVICIOS, no del total: el canon tiene su propia línea · El IVA que SOPORTAS en el coste directo del evento: limpieza, consumibles, gasoil, vigilancia y la tarifa de SGAE van al 21 %. Ajústalo a tus facturas | G13: 0.21
A14: Coste del canon (no tiene) | B14: =IFERROR(IF(B9="","",B9*'0. Supuestos'!$B$12*'0. Supuestos'!$B$14),"") -> 0 | C14: =IFERROR(IF(C9="","",C9*'0. Supuestos'!$B$12*'0. Supuestos'!$B$14),"") -> 0 | D14: =IFERROR(IF(D9="","",D9*'0. Supuestos'!$B$12*'0. Supuestos'!$B$14),"") -> 0 | E14: =IFERROR(B14/$B$9,"") -> 0 | F14: =IFERROR("Al "&TEXT('0. Supuestos'!$B$14,"0%")&" de las ventas del CANON","") -> Al 0% de las ventas del CANON | G14: =IFERROR(IF(B9="","",('0. Supuestos'!$B$62*'0. Supuestos'!$B$40+(1-'0. Supuestos'!$B$62)*'0. Supuestos'!$B$39)),"") -> 0.1
A15: Consumibles de los montajes | B15: =IFERROR(IF(B9="","",B9*'0. Supuestos'!$B$15),"") -> 7281.6 | C15: =IFERROR(IF(C9="","",C9*'0. Supuestos'!$B$15),"") -> 7864.128 | D15: =IFERROR(IF(D9="","",D9*'0. Supuestos'!$B$15),"") -> 8257.3344 | E15: =IFERROR(B15/$B$9,"") -> 0.02 | G15: =IFERROR(IF(B9="","",'0. Supuestos'!$B$41),"") -> 0.21
A16: Comisiones de wedding planners y agencias | B16: =IFERROR(IF(B9="","",B9*'0. Supuestos'!$B$16*'0. Supuestos'!$B$17),"") -> 9102 | C16: =IFERROR(IF(C9="","",C9*'0. Supuestos'!$B$16*'0. Supuestos'!$B$17),"") -> 9830.16 | D16: =IFERROR(IF(D9="","",D9*'0. Supuestos'!$B$16*'0. Supuestos'!$B$17),"") -> 10321.668 | E16: =IFERROR(B16/$B$9,"") -> 0.025 | F16: Sobre las ventas DEL CANAL. Con 0 % de intermediarios en Supuestos, esta línea vale cero | G16: =IFERROR(IF(B9="","",'0. Supuestos'!$B$41),"") -> 0.21
A17: Comisiones de los medios de pago | B17: =IFERROR(IF(B9="","",B9*'0. Supuestos'!$B$18),"") -> 1092.24 | C17: =IFERROR(IF(C9="","",C9*'0. Supuestos'!$B$18),"") -> 1179.6192 | D17: =IFERROR(IF(D9="","",D9*'0. Supuestos'!$B$18),"") -> 1238.6002 | E17: =IFERROR(B17/$B$9,"") -> 0.003 | F17: Las comisiones de los medios de pago están EXENTAS de IVA (art. 20.Uno.18 LIVA): no se deduce nada por ellas | G17: 0
A18: Varios e imprevistos | B18: =IFERROR(IF(B9="","",B9*'0. Supuestos'!$B$28),"") -> 7281.6 | C18: =IFERROR(IF(C9="","",C9*'0. Supuestos'!$B$28),"") -> 7864.128 | D18: =IFERROR(IF(D9="","",D9*'0. Supuestos'!$B$28),"") -> 8257.3344 | E18: =IFERROR(B18/$B$9,"") -> 0.02 | F18: =IFERROR("Al "&TEXT('0. Supuestos'!$B$28,"0%")&" de las ventas. Es un coste VARIABLE: sube y baja con la facturación, así que no puede vivir en los costes fijos","") -> Al 2% de las ventas. Es un coste VARIABLE: sube y baja con la facturación, así que no puede vivir en los costes fijos | G18: =IFERROR(IF(B9="","",'0. Supuestos'!$B$41),"") -> 0.21
A19: TOTAL COSTES VARIABLES | B19: =IFERROR(IF(B9="","",SUM(B13:B18)),"") -> 71046.571 | C19: =IFERROR(IF(C9="","",SUM(C13:C18)),"") -> 76730.297 | D19: =IFERROR(IF(D9="","",SUM(D13:D18)),"") -> 80566.812 | E19: =IFERROR(B19/$B$9,"") -> 0.19514
A20: MARGEN BRUTO | B20: =IFERROR(IF(B9="","",B9-B19),"") -> 293033.43 | C20: =IFERROR(IF(C9="","",C9-C19),"") -> 316476.1 | D20: =IFERROR(IF(D9="","",D9-D19),"") -> 332299.91 | E20: =IFERROR(B20/$B$9,"") -> 0.80486
A21: COSTES FIJOS
A22: Renta de la finca | B22: =IFERROR(IF(B9="","",'0. Supuestos'!$B$24*12),"") -> 42000 | C22: =IFERROR(IF(C9="","",B22*(1+'0. Supuestos'!$B$48)),"") -> 42000 | D22: =IFERROR(IF(D9="","",C22*(1+'0. Supuestos'!$B$48)),"") -> 42000 | E22: =IFERROR(B22/$B$9,"") -> 0.11535926 | F22: El importe mensual está en la hoja de Supuestos; aquí se multiplica por doce. Lleva IVA al 21 %. El mes de renta previo a la apertura está en la hoja de Inversión y NO se cuenta dos veces | G22: =IFERROR(IF(B9="","",'0. Supuestos'!$B$41),"") -> 0.21
A23: Personal (nóminas + Seguridad Social) | B23: =IFERROR(IF(B9="","",'Personal'!$G$11),"") -> 111720 | C23: =IFERROR(IF(C9="","",'Personal'!$B$15),"") -> 117720 | D23: =IFERROR(IF(D9="","",'Personal'!$B$16),"") -> 123720 | E23: =IFERROR(B23/$B$9,"") -> 0.30685564 | F23: Sale de la hoja de Personal: es el MISMO número, no una estimación aparte. Los años 2 y 3 suman las INCORPORACIONES declaradas en esa hoja, no un porcentaje de volumen | G23: 0
A24: Suministros (luz, agua, gasoil y teléfono) | B24: =IFERROR(IF(B9="","",'0. Supuestos'!$B$26*12),"") -> 19200 | C24: =IFERROR(IF(C9="","",B24*(1+'0. Supuestos'!$B$48)),"") -> 19200 | D24: =IFERROR(IF(D9="","",C24*(1+'0. Supuestos'!$B$48)),"") -> 19200 | E24: =IFERROR(B24/$B$9,"") -> 0.052735662 | F24: Luz y gas van al 21 %; la factura del agua, al 10 %. El libro aplica a toda esta partida el tipo de la columna de al lado (21 %): si el agua pesa mucho en tu finca, sepárala en su línea | G24: =IFERROR(IF(B9="","",'0. Supuestos'!$B$41),"") -> 0.21
A25: Seguros (RC + multirriesgo) | B25: =IFERROR(IF(B9="","",'0. Supuestos'!$B$27),"") -> 5500 | C25: =IFERROR(IF(C9="","",B25*(1+'0. Supuestos'!$B$48)),"") -> 5500 | D25: =IFERROR(IF(D9="","",C25*(1+'0. Supuestos'!$B$48)),"") -> 5500 | E25: =IFERROR(B25/$B$9,"") -> 0.01510657 | F25: Las operaciones de seguro están EXENTAS de IVA (art. 20.Uno.16 LIVA): la prima no lleva IVA deducible | G25: 0
A26: Marketing: portales de bodas, Google Ads y redes | B26: 12000 | C26: =IFERROR(IF(C9="","",B26*(1+'0. Supuestos'!$B$48)),"") -> 12000 | D26: =IFERROR(IF(D9="","",C26*(1+'0. Supuestos'!$B$48)),"") -> 12000 | E26: =IFERROR(B26/$B$9,"") -> 0.032959789 | F26: Escaparate en los portales de bodas, Google Ads y redes sociales. Mide el coste por contacto de cada canal antes de renovar el escaparate premium | G26: =IFERROR(IF(B9="","",'0. Supuestos'!$B$41),"") -> 0.21
A27: Ferias nupciales y jornadas de puertas abiertas | B27: 6000 | C27: =IFERROR(IF(C9="","",B27*(1+'0. Supuestos'!$B$48)),"") -> 6000 | D27: =IFERROR(IF(D9="","",C27*(1+'0. Supuestos'!$B$48)),"") -> 6000 | E27: =IFERROR(B27/$B$9,"") -> 0.016479895 | F27: Dos ferias de novios al año y las jornadas de puertas abiertas de la finca, con el catering | G27: =IFERROR(IF(B9="","",'0. Supuestos'!$B$41),"") -> 0.21
A28: Jardinería y mantenimiento externo (poda, césped y riego) | B28: 8000 | C28: =IFERROR(IF(C9="","",B28*(1+'0. Supuestos'!$B$48)),"") -> 8000 | D28: =IFERROR(IF(D9="","",C28*(1+'0. Supuestos'!$B$48)),"") -> 8000 | E28: =IFERROR(B28/$B$9,"") -> 0.021973193 | F28: Los trabajos grandes que no hace el personal propio: poda, césped, riego y tratamientos | G28: =IFERROR(IF(B9="","",'0. Supuestos'!$B$41),"") -> 0.21
A29: Reparaciones, pintura y reposición de mobiliario | B29: 6000 | C29: =IFERROR(IF(C9="","",B29*(1+'0. Supuestos'!$B$48)),"") -> 6000 | D29: =IFERROR(IF(D9="","",C29*(1+'0. Supuestos'!$B$48)),"") -> 6000 | E29: =IFERROR(B29/$B$9,"") -> 0.016479895 | F29: Pintura, pequeñas obras entre temporadas y reposición de sillas, mesas y mantelería | G29: =IFERROR(IF(B9="","",'0. Supuestos'!$B$41),"") -> 0.21
A30: Gestoría laboral, fiscal y contable | B30: 3000 | C30: =IFERROR(IF(C9="","",B30*(1+'0. Supuestos'!$B$48)),"") -> 3000 | D30: =IFERROR(IF(D9="","",C30*(1+'0. Supuestos'!$B$48)),"") -> 3000 | E30: =IFERROR(B30/$B$9,"") -> 0.0082399473 | F30: Contabilidad, impuestos de la SL y nóminas de los fijos discontinuos, con sus llamamientos de cada temporada | G30: =IFERROR(IF(B9="","",'0. Supuestos'!$B$41),"") -> 0.21
A31: Software de reservas, CRM, web y teléfono | B31: 1800 | C31: =IFERROR(IF(C9="","",B31*(1+'0. Supuestos'!$B$48)),"") -> 1800 | D31: =IFERROR(IF(D9="","",C31*(1+'0. Supuestos'!$B$48)),"") -> 1800 | E31: =IFERROR(B31/$B$9,"") -> 0.0049439684 | F31: Calendario de fechas, presupuestos, CRM de novios y empresas, alojamiento de la web y teléfono | G31: =IFERROR(IF(B9="","",'0. Supuestos'!$B$41),"") -> 0.21
A32: Prevención de riesgos laborales y vigilancia de la salud | B32: 500 | C32: =IFERROR(IF(C9="","",B32*(1+'0. Supuestos'!$B$48)),"") -> 500 | D32: =IFERROR(IF(D9="","",C32*(1+'0. Supuestos'!$B$48)),"") -> 500 | E32: =IFERROR(B32/$B$9,"") -> 0.0013733245 | F32: El plan de prevención es obligatorio (Ley 31/1995): montaje, cargas, trabajo en altura y jardinería, y reconocimientos médicos de la plantilla | G32: =IFERROR(IF(B9="","",'0. Supuestos'!$B$41),"") -> 0.21
A33: Tasas municipales e IBI repercutido | B33: 2500 | C33: =IFERROR(IF(C9="","",B33*(1+'0. Supuestos'!$B$48)),"") -> 2500 | D33: =IFERROR(IF(D9="","",C33*(1+'0. Supuestos'!$B$48)),"") -> 2500 | E33: =IFERROR(B33/$B$9,"") -> 0.0068666227 | F33: Basuras y otras tasas municipales y el IBI que el propietario te repercuta según el contrato. Pon las de tu ayuntamiento | G33: =IFERROR(IF(B9="","",'0. Supuestos'!$B$41),"") -> 0.21
A34: Revisiones de baja tensión, protección contra incendios y grupo electrógeno | B34: 1200 | C34: =IFERROR(IF(C9="","",B34*(1+'0. Supuestos'!$B$48)),"") -> 1200 | D34: =IFERROR(IF(D9="","",C34*(1+'0. Supuestos'!$B$48)),"") -> 1200 | E34: =IFERROR(B34/$B$9,"") -> 0.0032959789 | F34: Inspecciones periódicas de la instalación eléctrica, mantenimiento de extintores y del sistema contra incendios por una empresa mantenedora y revisión del grupo electrógeno | G34: =IFERROR(IF(B9="","",'0. Supuestos'!$B$41),"") -> 0.21
A35: Limpieza general, desinsectación y desratización (DDD) | B35: 2000 | C35: =IFERROR(IF(C9="","",B35*(1+'0. Supuestos'!$B$48)),"") -> 2000 | D35: =IFERROR(IF(D9="","",C35*(1+'0. Supuestos'!$B$48)),"") -> 2000 | E35: =IFERROR(B35/$B$9,"") -> 0.0054932982 | F35: Limpieza a fondo de temporada, productos y control de plagas por una empresa inscrita | G35: =IFERROR(IF(B9="","",'0. Supuestos'!$B$41),"") -> 0.21
A36: Amortización del inmovilizado | B36: =IFERROR(IF(B9="","",'Inversión Inicial'!$B$38),"") -> 16752 | C36: =IFERROR(IF(C9="","",B36),"") -> 16752 | D36: =IFERROR(IF(D9="","",B36),"") -> 16752 | E36: =IFERROR(B36/$B$9,"") -> 0.046011866 | F36: Sale de las bases de amortización de la hoja de Inversión: sólo inmovilizado real. NO sube con el IPC: es una cuota sobre el coste HISTÓRICO del inmovilizado | G36: 0
A37: Gastos financieros (intereses del préstamo) | B37: =IFERROR(IF(B9="","",'Financiación'!$B$44),"") -> 17095 | C37: =IFERROR(IF(C9="","",'Financiación'!$B$46),"") -> 17095 | D37: =IFERROR(IF(D9="","",'Financiación'!$B$48),"") -> 15089.22 | E37: =IFERROR(B37/$B$9,"") -> 0.046953966 | F37: Sólo los INTERESES son gasto. La devolución del principal va en la hoja de Tesorería | G37: 0
A38: TOTAL COSTES FIJOS | B38: =IFERROR(IF(B9="","",SUM(B22:B37)),"") -> 255267 | C38: =IFERROR(IF(C9="","",SUM(C22:C37)),"") -> 261267 | D38: =IFERROR(IF(D9="","",SUM(D22:D37)),"") -> 265261.22 | E38: =IFERROR(B38/$B$9,"") -> 0.70112887
A39: IVA soportado de los costes variables | B39: =IFERROR(IF(B9="","",SUMPRODUCT(B13:B18,G13:G18)),"") -> 14690.41 | C39: =IFERROR(IF(C9="","",SUMPRODUCT(C13:C18,G13:G18)),"") -> 15865.642 | D39: =IFERROR(IF(D9="","",SUMPRODUCT(D13:D18,G13:G18)),"") -> 16658.924 | F39: Cada línea a SU tipo, leído de la columna de al lado. Es lo que la hoja de Tesorería paga de más a los proveedores y luego se deduce
A40: IVA soportado de los costes fijos | B40: =IFERROR(IF(B9="","",SUMPRODUCT(B22:B37,G22:G37)),"") -> 21882 | C40: =IFERROR(IF(C9="","",SUMPRODUCT(C22:C37,G22:G37)),"") -> 21882 | D40: =IFERROR(IF(D9="","",SUMPRODUCT(D22:D37,G22:G37)),"") -> 21882
A41: RESULTADO ANTES DE IMPUESTOS | B41: =IFERROR(IF(B9="","",B20-B38),"") -> 37766.429 | C41: =IFERROR(IF(C9="","",C20-C38),"") -> 55209.103 | D41: =IFERROR(IF(D9="","",D20-D38),"") -> 67038.688 | E41: =IFERROR(B41/$B$9,"") -> 0.10373113
...

Sheet Punto Equilibrio
A1: PUNTO DE EQUILIBRIO
A2: Punto de equilibrio — finca de eventos y bodas
A4: Variable | B4: Año 1 | C4: Año 2 | D4: Año 3 | E4: Notas
A5: DATOS BASE POR AÑO
A6: Costes fijos anuales | B6: =IFERROR(IF('PyG 3 Años'!$B$9="","",'PyG 3 Años'!$B$38),"") -> 255267 | C6: =IFERROR(IF('PyG 3 Años'!$C$9="","",'PyG 3 Años'!$C$38),"") -> 261267 | D6: =IFERROR(IF('PyG 3 Años'!$D$9="","",'PyG 3 Años'!$D$38),"") -> 265261.22 | E6: Los MISMOS costes fijos del P&L. Cada año tiene los suyos: por eso el umbral no puede ser uno solo para los tres
A7: Costes fijos mensuales | B7: =IFERROR(IF('PyG 3 Años'!$B$9="","",B6/12),"") -> 21272.25 | C7: =IFERROR(IF('PyG 3 Años'!$C$9="","",C6/12),"") -> 21772.25 | D7: =IFERROR(IF('PyG 3 Años'!$D$9="","",D6/12),"") -> 22105.102
A8: Precio medio por invitado sin IVA | B8: =IFERROR(IF('PyG 3 Años'!$B$9="","",'PyG 3 Años'!$B$7),"") -> 37 | C8: =IFERROR(IF('PyG 3 Años'!$C$9="","",'PyG 3 Años'!$C$7),"") -> 37 | D8: =IFERROR(IF('PyG 3 Años'!$D$9="","",'PyG 3 Años'!$D$7),"") -> 37
A9: Coste variable por invitado | B9: =IFERROR(IF('PyG 3 Años'!$B$9="","",'PyG 3 Años'!$B$19/('PyG 3 Años'!$B$6*'PyG 3 Años'!$B$8)),"") -> 7.22018 | C9: =IFERROR(IF('PyG 3 Años'!$C$9="","",'PyG 3 Años'!$C$19/('PyG 3 Años'!$C$6*'PyG 3 Años'!$C$8)),"") -> 7.22018 | D9: =IFERROR(IF('PyG 3 Años'!$D$9="","",'PyG 3 Años'!$D$19/('PyG 3 Años'!$D$6*'PyG 3 Años'!$D$8)),"") -> 7.22018 | E9: Sale del total de costes variables del P&L, no de una estimación aparte. Incluye los varios e imprevistos, que son un porcentaje de las ventas
A10: Margen de contribución por invitado | B10: =IFERROR(IF('PyG 3 Años'!$B$9="","",B8-B9),"") -> 29.77982 | C10: =IFERROR(IF('PyG 3 Años'!$C$9="","",C8-C9),"") -> 29.77982 | D10: =IFERROR(IF('PyG 3 Años'!$D$9="","",D8-D9),"") -> 29.77982 | E10: Precio por invitado menos coste variable unitario
A11: Eventos al año | B11: =IFERROR(IF('PyG 3 Años'!$B$9="","",'PyG 3 Años'!$B$8),"") -> 120 | C11: =IFERROR(IF('PyG 3 Años'!$C$9="","",'PyG 3 Años'!$C$8),"") -> 120 | D11: =IFERROR(IF('PyG 3 Años'!$D$9="","",'PyG 3 Años'!$D$8),"") -> 120 | E11: El mismo calendario que el P&L y que los escenarios
A12: Devolución de principal del año (cuota) | B12: =IFERROR(IF('PyG 3 Años'!$B$9="","",'Financiación'!$B$45),"") -> 0 | C12: =IFERROR(IF('PyG 3 Años'!$C$9="","",'Financiación'!$B$47),"") -> 30858.15 | D12: =IFERROR(IF('PyG 3 Años'!$D$9="","",'Financiación'!$B$49),"") -> 32863.93 | E12: El principal NO es gasto del P&L, pero sale de la caja. Sin él, el umbral de equilibrio se publica por debajo del real
A13: PUNTO DE EQUILIBRIO CONTABLE (incluye amortización)
A14: Invitados necesarios al año | B14: =IFERROR(IF('PyG 3 Años'!$B$9="","",IF(B10<=0,"",B6/B10)),"") -> 8571.8114 | C14: =IFERROR(IF('PyG 3 Años'!$C$9="","",IF(C10<=0,"",C6/C10)),"") -> 8773.2901 | D14: =IFERROR(IF('PyG 3 Años'!$D$9="","",IF(D10<=0,"",D6/D10)),"") -> 8907.4152
A15: Invitados necesarios por evento | B15: =IFERROR(IF('PyG 3 Años'!$B$9="","",B14/B11),"") -> 71.431762 | C15: =IFERROR(IF('PyG 3 Años'!$C$9="","",C14/C11),"") -> 73.110751 | D15: =IFERROR(IF('PyG 3 Años'!$D$9="","",D14/D11),"") -> 74.22846
A16: Ingresos necesarios al año | B16: =IFERROR(IF('PyG 3 Años'!$B$9="","",B14*B8),"") -> 317157.02 | C16: =IFERROR(IF('PyG 3 Años'!$C$9="","",C14*C8),"") -> 324611.73 | D16: =IFERROR(IF('PyG 3 Años'!$D$9="","",D14*D8),"") -> 329574.36
A17: PUNTO DE EQUILIBRIO DE CAJA (incluye la cuota del préstamo)
A18: Costes fijos de caja + principal del año | B18: =IFERROR(IF('PyG 3 Años'!$B$9="","",B6-'PyG 3 Años'!$B$36+B12),"") -> 238515 | C18: =IFERROR(IF('PyG 3 Años'!$C$9="","",C6-'PyG 3 Años'!$C$36+C12),"") -> 275373.15 | D18: =IFERROR(IF('PyG 3 Años'!$D$9="","",D6-'PyG 3 Años'!$D$36+D12),"") -> 281373.15 | E18: Los fijos del P&L sin la amortización (que no se paga) y CON la devolución de principal (que sí). Es el umbral que decide si la caja aguanta
A19: Invitados necesarios al año (caja) | B19: =IFERROR(IF('PyG 3 Años'!$B$9="","",IF(B10<=0,"",B18/B10)),"") -> 8009.2828 | C19: =IFERROR(IF('PyG 3 Años'!$C$9="","",IF(C10<=0,"",C18/C10)),"") -> 9246.9716 | D19: =IFERROR(IF('PyG 3 Años'!$D$9="","",IF(D10<=0,"",D18/D10)),"") -> 9448.4503
A20: Invitados necesarios por evento (caja) | B20: =IFERROR(IF('PyG 3 Años'!$B$9="","",B19/B11),"") -> 66.744023 | C20: =IFERROR(IF('PyG 3 Años'!$C$9="","",C19/C11),"") -> 77.058097 | D20: =IFERROR(IF('PyG 3 Años'!$D$9="","",D19/D11),"") -> 78.737086
A21: Ingresos necesarios al año (caja) | B21: =IFERROR(IF('PyG 3 Años'!$B$9="","",B19*B8),"") -> 296343.46 | C21: =IFERROR(IF('PyG 3 Años'!$C$9="","",C19*C8),"") -> 342137.95 | D21: =IFERROR(IF('PyG 3 Años'!$D$9="","",D19*D8),"") -> 349592.66
A22: CONTRASTE CON EL PLAN
A23: Invitados por evento previstos en el plan | B23: =IFERROR(IF('PyG 3 Años'!$B$9="","",'PyG 3 Años'!$B$6),"") -> 82 | C23: =IFERROR(IF('PyG 3 Años'!$C$9="","",'PyG 3 Años'!$C$6),"") -> 88.56 | D23: =IFERROR(IF('PyG 3 Años'!$D$9="","",'PyG 3 Años'!$D$6),"") -> 92.988
A24: Holgura sobre el equilibrio de CAJA (%) | B24: =IFERROR(IF('PyG 3 Años'!$B$9="","",B23/B20-1),"") -> 0.22857442 | C24: =IFERROR(IF('PyG 3 Años'!$C$9="","",C23/C20-1),"") -> 0.14926275 | D24: =IFERROR(IF('PyG 3 Años'!$D$9="","",D23/D20-1),"") -> 0.18099367 | E24: Cuánto superan tus ventas previstas a las del equilibrio de caja. La caída que aguantas antes de no poder pagar los costes fijos y la cuota es algo menor: con un 25 % de holgura, un 20 %. El mínimo exigible está en la hoja de Supuestos
A25: INTERPRETACIÓN
A26: =IFERROR("Con el precio medio por invitado sin IVA de la fila de arriba necesitas "&TEXT(ROUNDUP(B15,0),"0")&" invitados por evento durante los "&TEXT(B11,"0")&" eventos del año para no perder dinero (equilibrio contable, con la amortización dentro), y "&TEXT(ROUNDUP(B20,0),"0")&" para que la caja aguante (equilibrio de caja: sin la amortización, que no se paga, y con la cuota del préstamo del año"&IF(B12=0,"; este año sólo intereses, porque el préstamo está en carencia","")&"). En las filas «Ingresos necesarios al año» tienes esas mismas cifras en euros.","") -> Con el precio medio por invitado sin IVA de la fila de arriba necesitas 72 invitados por evento durante los 120 eventos del año para no perder dinero (equilibrio contable, con la amortización dentro), y 67 para que la caja aguante (equilibrio de caja: sin la amortización, que no se paga, y con la cuota del préstamo del año; este año sólo intereses, porque el préstamo está en carencia). En las filas «Ingresos necesarios al año» tienes esas mismas cifras en euros.
A28: SENSIBILIDAD DEL PUNTO DE EQUILIBRIO
A29: Invitados por evento necesarios para cubrir costes según el precio medio por invitado (columnas) y el coste variable por invitado (filas). En verde, los que están por debajo de los invitados que prevé el plan.
A31: Invitados por evento necesarios: precio medio por invitado sin IVA (columnas) × coste variable por invitado (filas) | B31: =IFERROR($B$8-2,"") -> 35 | C31: =IFERROR(IF($B$8="","",$B$8),"") -> 37 | D31: =IFERROR($B$8+2,"") -> 39 | E31: =IFERROR($B$8+4,"") -> 41
A32: =IFERROR($B$9*0.85,"") -> 6.137153 | B32: =IFERROR(IF($B$31-$A32<=0,"",$B$6/($B$31-$A32)/$B$11),"") -> 73.701149 | C32: =IFERROR(IF($C$31-$A32<=0,"",$B$6/($C$31-$A32)/$B$11),"") -> 68.925106 | D32: =IFERROR(IF($D$31-$A32<=0,"",$B$6/($D$31-$A32)/$B$11),"") -> 64.730393 | E32: =IFERROR(IF($E$31-$A32<=0,"",$B$6/($E$31-$A32)/$B$11),"") -> 61.016962
A33: =IFERROR($B$9*0.925,"") -> 6.6786665 | B33: =IFERROR(IF($B$31-$A33<=0,"",$B$6/($B$31-$A33)/$B$11),"") -> 75.11034 | C33: =IFERROR(IF($C$31-$A33<=0,"",$B$6/($C$31-$A33)/$B$11),"") -> 70.15605 | D33: =IFERROR(IF($D$31-$A33<=0,"",$B$6/($D$31-$A33)/$B$11),"") -> 65.81489 | E33: =IFERROR(IF($E$31-$A33<=0,"",$B$6/($E$31-$A33)/$B$11),"") -> 61.979672
A34: =IFERROR($B$9*1.0,"") -> 7.22018 | B34: =IFERROR(IF($B$31-$A34<=0,"",$B$6/($B$31-$A34)/$B$11),"") -> 76.57447 | C34: =IFERROR(IF($C$31-$A34<=0,"",$B$6/($C$31-$A34)/$B$11),"") -> 71.431762 | D34: =IFERROR(IF($D$31-$A34<=0,"",$B$6/($D$31-$A34)/$B$11),"") -> 66.936345 | E34: =IFERROR(IF($E$31-$A34<=0,"",$B$6/($E$31-$A34)/$B$11),"") -> 62.973249
A35: =IFERROR($B$9*1.075,"") -> 7.7616935 | B35: =IFERROR(IF($B$31-$A35<=0,"",$B$6/($B$31-$A35)/$B$11),"") -> 78.096816 | C35: =IFERROR(IF($C$31-$A35<=0,"",$B$6/($C$31-$A35)/$B$11),"") -> 72.754727 | D35: =IFERROR(IF($D$31-$A35<=0,"",$B$6/($D$31-$A35)/$B$11),"") -> 68.096681 | E35: =IFERROR(IF($E$31-$A35<=0,"",$B$6/($E$31-$A35)/$B$11),"") -> 63.999199
A36: =IFERROR($B$9*1.15,"") -> 8.303207 | B36: =IFERROR(IF($B$31-$A36<=0,"",$B$6/($B$31-$A36)/$B$11),"") -> 79.680919 | C36: =IFERROR(IF($C$31-$A36<=0,"",$B$6/($C$31-$A36)/$B$11),"") -> 74.127621 | D36: =IFERROR(IF($D$31-$A36<=0,"",$B$6/($D$31-$A36)/$B$11),"") -> 69.297956 | E36: =IFERROR(IF($E$31-$A36<=0,"",$B$6/($E$31-$A36)/$B$11),"") -> 65.059133

Sheet Escenarios
A1: ESCENARIOS
A4: Métrica | B4: Pesimista | C4: Realista | D4: Optimista | E4: Notas
A5: Invitados por evento | B5: 78 | C5: =IFERROR(IF('PyG 3 Años'!$B$6="","",'PyG 3 Años'!$B$6),"") -> 82 | D5: 85
A6: Precio medio por invitado sin IVA | B6: 34 | C6: =IFERROR(IF('PyG 3 Años'!$B$7="","",'PyG 3 Años'!$B$7),"") -> 37 | D6: 39
A7: Eventos al año | B7: 100 | C7: =IFERROR(IF('PyG 3 Años'!$B$8="","",'PyG 3 Años'!$B$8),"") -> 120 | D7: 135
A8: INGRESOS ANUALES (sin IVA) | B8: =IFERROR(IF(B5*B6*B7=0,"",B5*B6*B7),"") -> 265200 | C8: =IFERROR(IF(C5*C6*C7=0,"",C5*C6*C7),"") -> 364080 | D8: =IFERROR(IF(D5*D6*D7=0,"",D5*D6*D7),"") -> 447525
A9: Coste directo del evento | B9: =IFERROR(IF(B8="","",B8*'0. Supuestos'!$B$11*'0. Supuestos'!$B$13),"") -> 33717.528 | C9: =IFERROR(IF(C8="","",C8*'0. Supuestos'!$B$11*'0. Supuestos'!$B$13),"") -> 46289.131 | D9: =IFERROR(IF(D8="","",D8*'0. Supuestos'!$B$11*'0. Supuestos'!$B$13),"") -> 56898.329
A10: Coste del canon (no tiene) | B10: =IFERROR(IF(B8="","",B8*'0. Supuestos'!$B$12*'0. Supuestos'!$B$14),"") -> 0 | C10: =IFERROR(IF(C8="","",C8*'0. Supuestos'!$B$12*'0. Supuestos'!$B$14),"") -> 0 | D10: =IFERROR(IF(D8="","",D8*'0. Supuestos'!$B$12*'0. Supuestos'!$B$14),"") -> 0
A11: Consumibles de los montajes | B11: =IFERROR(IF(B8="","",B8*'0. Supuestos'!$B$15),"") -> 5304 | C11: =IFERROR(IF(C8="","",C8*'0. Supuestos'!$B$15),"") -> 7281.6 | D11: =IFERROR(IF(D8="","",D8*'0. Supuestos'!$B$15),"") -> 8950.5
A12: Comisiones de wedding planners y agencias | B12: =IFERROR(IF(B8="","",B8*'0. Supuestos'!$B$16*'0. Supuestos'!$B$17),"") -> 6630 | C12: =IFERROR(IF(C8="","",C8*'0. Supuestos'!$B$16*'0. Supuestos'!$B$17),"") -> 9102 | D12: =IFERROR(IF(D8="","",D8*'0. Supuestos'!$B$16*'0. Supuestos'!$B$17),"") -> 11188.125
A13: Comisiones de los medios de pago | B13: =IFERROR(IF(B8="","",B8*'0. Supuestos'!$B$18),"") -> 795.6 | C13: =IFERROR(IF(C8="","",C8*'0. Supuestos'!$B$18),"") -> 1092.24 | D13: =IFERROR(IF(D8="","",D8*'0. Supuestos'!$B$18),"") -> 1342.575
A14: Varios e imprevistos | B14: =IFERROR(IF(B8="","",B8*'0. Supuestos'!$B$28),"") -> 5304 | C14: =IFERROR(IF(C8="","",C8*'0. Supuestos'!$B$28),"") -> 7281.6 | D14: =IFERROR(IF(D8="","",D8*'0. Supuestos'!$B$28),"") -> 8950.5
A15: TOTAL COSTES VARIABLES | B15: =IFERROR(IF(B8="","",SUM(B9:B14)),"") -> 51751.128 | C15: =IFERROR(IF(C8="","",SUM(C9:C14)),"") -> 71046.571 | D15: =IFERROR(IF(D8="","",SUM(D9:D14)),"") -> 87330.029
A16: MARGEN BRUTO | B16: =IFERROR(IF(B8="","",B8-B15),"") -> 213448.87 | C16: =IFERROR(IF(C8="","",C8-C15),"") -> 293033.43 | D16: =IFERROR(IF(D8="","",D8-D15),"") -> 360194.97
A17: COSTES FIJOS (los del P&L) | B17: =IFERROR(IF(B8="","",'PyG 3 Años'!$B$38),"") -> 255267 | C17: =IFERROR(IF(C8="","",'PyG 3 Años'!$B$38),"") -> 255267 | D17: =IFERROR(IF(D8="","",'PyG 3 Años'!$B$38),"") -> 255267 | E17: Los costes fijos no cambian con el escenario: por eso son fijos
A18: RESULTADO ANTES DE IMPUESTOS | B18: =IFERROR(IF(B8="","",B16-B17),"") -> -41818.128 | C18: =IFERROR(IF(C8="","",C16-C17),"") -> 37766.429 | D18: =IFERROR(IF(D8="","",D16-D17),"") -> 104927.97
A19: Impuesto de Sociedades | B19: =IFERROR(IF(B8="","",MAX(0,B18-'0. Supuestos'!$B$42)*'0. Supuestos'!$B$37),"") -> 0 | C19: =IFERROR(IF(C8="","",MAX(0,C18-'0. Supuestos'!$B$42)*'0. Supuestos'!$B$37),"") -> 5664.9643 | D19: =IFERROR(IF(D8="","",MAX(0,D18-'0. Supuestos'!$B$42)*'0. Supuestos'!$B$37),"") -> 15739.196 | E19: Al tipo de entidad de nueva creación, compensando las bases negativas anteriores
A20: RESULTADO NETO | B20: =IFERROR(IF(B8="","",B18-B19),"") -> -41818.128 | C20: =IFERROR(IF(C8="","",C18-C19),"") -> 32101.464 | D20: =IFERROR(IF(D8="","",D18-D19),"") -> 89188.776
A21: Invitados por evento para el equilibrio | B21: =IFERROR(IF(B8="","",IF(B6-B15/(B5*B7)<=0,"",B17/(B6-B15/(B5*B7))/B7)),"") -> 93.281477 | C21: =IFERROR(IF(C8="","",IF(C6-C15/(C5*C7)<=0,"",C17/(C6-C15/(C5*C7))/C7)),"") -> 71.431762 | D21: =IFERROR(IF(D8="","",IF(D6-D15/(D5*D7)<=0,"",D17/(D6-D15/(D5*D7))/D7)),"") -> 60.23875
A22: LO QUE CADA ESCENARIO EXIGE
A23: Coste de personal / Ventas | B23: =IFERROR(IF(B8="","",'PyG 3 Años'!$B$23/B8),"") -> 0.42126697 | C23: =IFERROR(IF(C8="","",'PyG 3 Años'!$B$23/C8),"") -> 0.30685564 | D23: =IFERROR(IF(D8="","",'PyG 3 Años'!$B$23/D8),"") -> 0.24963968 | E23: La MISMA plantilla en los tres escenarios. Si en el pesimista se dispara, el ajuste hay que hacerlo en la hoja de Personal, no aquí
A24: Invitados al año por jornada equivalente | B24: =IFERROR(IF(B8="","",B5*B7/'Personal'!$C$11),"") -> 2328.3582 | C24: =IFERROR(IF(C8="","",C5*C7/'Personal'!$C$11),"") -> 2937.3134 | D24: =IFERROR(IF(D8="","",D5*D7/'Personal'!$C$11),"") -> 3425.3731 | E24: Invitados que tendría que recibir cada jornada completa del cuadro de Personal. En el optimista dice si hace falta contratar
A25: Saldo de caja al cierre del año 1 (estimado, el mismo método en los tres escenarios) | B25: =IFERROR(IF(B8="","",'Inversión Inicial'!$B$30+B20+'PyG 3 Años'!$B$36-'Financiación'!$B$45),"") -> 34562.622 | C25: =IFERROR(IF(C8="","",'Inversión Inicial'!$B$30+C20+'PyG 3 Años'!$B$36-'Financiación'!$B$45),"") -> 108482.21 | D25: =IFERROR(IF(D8="","",'Inversión Inicial'!$B$30+D20+'PyG 3 Años'!$B$36-'Financiación'!$B$45),"") -> 165569.53 | E25: Saldo ESTIMADO: fondo de maniobra más el resultado del año, devolviendo la amortización (que no se paga) y restando el principal del préstamo. No incluye el desfase de cobros y pagos ni la liquidación del IVA, así que las tres columnas se pueden comparar entre sí. En rojo, el escenario se queda sin caja
A26: Saldo real del mes 12 de la hoja de Tesorería (sólo realista) | C26: =IFERROR(IF(C8="","",'Tesorería 12 meses'!$M$22),"") -> 149910.01 | E26: El saldo REAL del caso base, con su desfase de cobros y pagos y su liquidación de IVA. Sólo existe para el escenario realista, que es el único con tesorería mensual propia: por eso no está en la fila de arriba, donde se compararía contra dos estimaciones
A28: La columna «Realista» lee sus tres datos de la hoja de Supuestos, así que reproduce EXACTAMENTE el año 1 del P&L. Los otros dos escenarios usan las mismas tasas de coste: lo único que cambia son los invitados, el precio por invitado y los eventos. Los COSTES FIJOS sí son los mismos en los tres: los varios e imprevistos, que son un porcentaje de las ventas, van arriba con los variables y cada escenario carga los suyos.

Sheet Personal
A1: PERSONAL Y COSTES
A2: =IFERROR("Convenio Hostelería — "&TEXT('0. Supuestos'!$B$21,"0")&" pagas + SS "&TEXT('0. Supuestos'!$B$20*100,"0")&" %","") -> Convenio Hostelería — 14 pagas + SS 33 %
A4: Puesto | B4: Personas | C4: Jornada | D4: Bruto mes (€, total del puesto) | E4: Seg. Social a cargo de la empresa (€) | F4: Coste mes (€, total del puesto) | G4: Coste año (€) | H4: Horas/semana por persona | I4: Horas/año del puesto | J4: Notas
A5: Titular — gerencia, ventas y visitas | B5: 1 | C5: 1 | D5: 2000 | E5: =IFERROR(IF(D5="","",D5*'0. Supuestos'!$B$20),"") -> 660 | F5: =IFERROR(IF(D5="","",D5+E5),"") -> 2660 | G5: =IFERROR(IF(D5="","",F5*MAX(12,'0. Supuestos'!$B$21)),"") -> 37240 | H5: =IFERROR(IF(D5="","",C5*$B$18),"") -> 40 | I5: =IFERROR(IF(D5="","",H5*B5*$B$19),"") -> 1840 | J5: Vende, enseña la finca, firma los contratos, lleva el calendario y coordina al catering. Como administrador de la SL cotiza en el régimen de autónomos: el libro le imputa el 33 % de Seguridad Social sobre 14 pagas como si fuera nómina, que es el lado prudente. Confirma con tu gestoría la cuota real
A6: Coordinación de bodas y celebraciones (fijo discontinuo, marzo-noviembre) | B6: 1 | C6: 0.75 | D6: 1240 | E6: =IFERROR(IF(D6="","",D6*'0. Supuestos'!$B$20),"") -> 409.2 | F6: =IFERROR(IF(D6="","",D6+E6),"") -> 1649.2 | G6: =IFERROR(IF(D6="","",F6*MAX(12,'0. Supuestos'!$B$21)),"") -> 23088.8 | H6: =IFERROR(IF(D6="","",C6*$B$18),"") -> 30 | I6: =IFERROR(IF(D6="","",H6*B6*$B$19),"") -> 1380 | J6: Contrato fijo discontinuo (art. 16 del Estatuto de los Trabajadores) a jornada completa de marzo a noviembre: equivale al 75 % en cómputo anual. Prepara cada evento con los novios y el catering y lo dirige el día. De diciembre a febrero (comidas de Navidad y eventos de invierno) coordina el titular. Bruto a jornada completa: unos 1.650 €
A7: Mantenimiento y jardinería | B7: 1 | C7: 0.8 | D7: 1120 | E7: =IFERROR(IF(D7="","",D7*'0. Supuestos'!$B$20),"") -> 369.6 | F7: =IFERROR(IF(D7="","",D7+E7),"") -> 1489.6 | G7: =IFERROR(IF(D7="","",F7*MAX(12,'0. Supuestos'!$B$21)),"") -> 20854.4 | H7: =IFERROR(IF(D7="","",C7*$B$18),"") -> 32 | I7: =IFERROR(IF(D7="","",H7*B7*$B$19),"") -> 1472 | J7: Jardines, riego, caminos, pequeñas reparaciones, grupo electrógeno y puesta a punto del salón y de la carpa. Al 80 % de jornada; lo grande (poda, pintura) va en los costes fijos. Bruto a jornada completa: 1.400 €
A8: Auxiliares de montaje, acceso y aseos (fijos discontinuos) | B8: 2 | C8: 0.4 | D8: 1080 | E8: =IFERROR(IF(D8="","",D8*'0. Supuestos'!$B$20),"") -> 356.4 | F8: =IFERROR(IF(D8="","",D8+E8),"") -> 1436.4 | G8: =IFERROR(IF(D8="","",F8*MAX(12,'0. Supuestos'!$B$21)),"") -> 20109.6 | H8: =IFERROR(IF(D8="","",C8*$B$18),"") -> 16 | I8: =IFERROR(IF(D8="","",H8*B8*$B$19),"") -> 1472 | J8: Dos personas al 40 % de jornada en cómputo anual: montaje, control de acceso y aparcamiento, reposición de aseos y recogida. Dos en cada boda y una en el resto. Nunca como autónomos que te facturan: con tu horario y tu dirección es falso autónomo (art. 1.1 ET). Bruto a jornada completa: 1.350 €
A9: Comercial de bodas a tiempo parcial | B9: 1 | C9: 0.2 | D9: 300 | E9: =IFERROR(IF(D9="","",D9*'0. Supuestos'!$B$20),"") -> 99 | F9: =IFERROR(IF(D9="","",D9+E9),"") -> 399 | G9: =IFERROR(IF(D9="","",F9*MAX(12,'0. Supuestos'!$B$21)),"") -> 5586 | H9: =IFERROR(IF(D9="","",C9*$B$18),"") -> 8 | I9: =IFERROR(IF(D9="","",H9*B9*$B$19),"") -> 368 | J9: Al 20 % de jornada: visitas de los sábados por la mañana, ferias nupciales y seguimiento de las peticiones de los portales. Bruto a jornada completa: 1.500 €
A10: Limpieza y puesta a punto a tiempo parcial | B10: 1 | C10: 0.2 | D10: 260 | E10: =IFERROR(IF(D10="","",D10*'0. Supuestos'!$B$20),"") -> 85.8 | F10: =IFERROR(IF(D10="","",D10+E10),"") -> 345.8 | G10: =IFERROR(IF(D10="","",F10*MAX(12,'0. Supuestos'!$B$21)),"") -> 4841.2 | H10: =IFERROR(IF(D10="","",C10*$B$18),"") -> 8 | I10: =IFERROR(IF(D10="","",H10*B10*$B$19),"") -> 368 | J10: Al 20 % de jornada: limpieza entre eventos del salón, los aseos y el office. La limpieza a fondo tras cada boda va en el coste directo del evento. Bruto a jornada completa: 1.300 €
A11: TOTAL PLANTILLA | B11: =IFERROR(IF(COUNT(D5:D10)=0,"",SUM(B5:B10)),"") -> 7 | C11: =IFERROR(IF(COUNT(D5:D10)=0,"",SUM(C5:C10)),"") -> 3.35 | D11: =IFERROR(IF(COUNT(D5:D10)=0,"",SUM(D5:D10)),"") -> 6000 | E11: =IFERROR(IF(COUNT(D5:D10)=0,"",SUM(E5:E10)),"") -> 1980 | F11: =IFERROR(IF(COUNT(D5:D10)=0,"",SUM(F5:F10)),"") -> 7980 | G11: =IFERROR(IF(COUNT(D5:D10)=0,"",SUM(G5:G10)),"") -> 111720 | I11: =IFERROR(IF(COUNT(D5:D10)=0,"",SUM(I5:I10)),"") -> 6900
A12: CRECIMIENTO DE LA PLANTILLA (coste escalonado)
A13: Coste anual de las incorporaciones del año 2 (€) | B13: 6000 | J13: Coste ANUAL completo (bruto + Seguridad Social × pagas) de lo que se contrate ese año. El P&L lo suma al coste del año anterior: la plantilla no crece con un porcentaje, crece con personas
A14: Coste anual de las incorporaciones del año 3 (€) | B14: 6000 | J14: Coste ANUAL completo (bruto + Seguridad Social × pagas) de lo que se contrate ese año. El P&L lo suma al coste del año anterior: la plantilla no crece con un porcentaje, crece con personas
A15: Coste de personal del año 2 | B15: =IFERROR(IF(G11="","",G11*(1+'0. Supuestos'!$B$48)+B13),"") -> 117720
A16: Coste de personal del año 3 | B16: =IFERROR(IF(B15="","",B15*(1+'0. Supuestos'!$B$48)+B14),"") -> 123720
A17: COBERTURA POR HORAS DE SERVICIO
A18: Jornada completa del convenio (horas/semana) | B18: 40 | J18: Art. 34.1 del Estatuto de los Trabajadores; tu convenio provincial puede fijar menos
A19: Semanas trabajadas al año por persona | B19: 46 | J19: 46 semanas: 52 menos las vacaciones (30 días naturales, art. 38 ET), los festivos y las ausencias medias
A20: Horas de trabajo por evento que hay que cubrir | B20: 9.2 | J20: Media del día del evento, de montaje a recogida: boda 13 h, empresa 9 h, celebración privada 8 h y evento pequeño 5 h (9,2 h de media con la mezcla del plan)
A21: Personas necesarias a la vez en cada evento | B21: 2.3 | J21: Personal de la finca a la vez en el evento: coordinación y dos auxiliares en las bodas, y coordinación y un auxiliar en el resto (2,3 de media). Camareros y cocina los pone el catering
A22: Horas de estructura por evento, fuera del día del evento | B22: 12 | J22: Horas por evento fuera del día del evento: visitas y reuniones con los novios, preparación con el catering, mantenimiento, jardín, limpieza y gestión. Es la parte de la plantilla que trabaja todo el año, repartida entre los eventos
A23: Personas de estructura por evento | B23: 3 | J23: Gerencia, mantenimiento y apoyo (comercial o limpieza) a la vez
A24: Horas de servicio a cubrir al año | B24: =IFERROR(IF(OR(B20="",B21="",'0. Supuestos'!$B$6=""),"",B20*B21*'0. Supuestos'!$B$6+B22*B23*'0. Supuestos'!$B$6),"") -> 6859.2
A25: Horas contratadas al año | B25: =IFERROR(IF(I11="","",I11),"") -> 6900
A26: Cobertura (contratadas / necesarias) | B26: =IFERROR(B25/B24,"") -> 1.0059482 | J26: Por debajo del 100 % la plantilla no llega a cubrir el horario que declara el plan: o se contrata más o se recorta el horario
A28: Las columnas «Bruto mes», «Seg. Social», «Coste mes» y «Coste año» son TOTALES de la fila: en un puesto con dos personas incluyen a las dos. «Jornada» es el porcentaje sobre la jornada completa del convenio y sirve para comparar el salario con el suelo legal en proporción. El tipo de Seguridad Social y el número de pagas están en la hoja «0. Supuestos».
A29: El suelo salarial es el MAYOR entre el SMI y el salario de convenio, los dos en la hoja «0. Supuestos»; las jornadas parciales lo llevan en proporción. El convenio aplicable es el PROVINCIAL de hostelería: no existe una tabla salarial estatal única, así que la celda del convenio se entrega vacía para que copies la de tu provincia.

Sheet Instrucciones
A1: INSTRUCCIONES DE USO — Plan financiero Finca de Eventos y Bodas
A3: CÓMO SE USA ESTE LIBRO
A4: Este plan financiero es un MODELO: sólo se teclea en las celdas VERDES y el resto se recalcula solo.
A5: 1. «0. Supuestos» es la hoja de mando: invitados, precio por invitado sin IVA, eventos, mezcla de espacio y canon, coste directo del evento, renta de la finca, financiación e impuestos.
A6: 2. Las partidas de la inversión, los costes fijos y la plantilla se teclean en su propia hoja, también en verde. Ningún número se escribe dos veces.
A7: 3. Sólo «Punto Equilibrio» se deriva entera de lo anterior. En las otras tres hojas también hay celdas verdes que puedes tocar: el escenario pesimista y el optimista en «Escenarios», la estacionalidad y la rampa de arranque en «Tesorería 12 meses», y las cuatro fuentes alternativas de financiación en «Financiación». Todo lo demás se calcula.
A8: 4. Todas las cifras van SIN IVA. Para pasar un PVP a precio sin IVA, divide entre 1,21: todo lo que factura la finca —espacio, servicios y canon— va al tipo general. El menú y la barra los factura el catering a los novios, al 10 % (art. 91.Uno.2.2.º de la Ley 37/1992), y no entran en este libro. El tipo de cada línea de venta está en la columna «Tipo de IVA de la línea» del P&L y de ahí salen los cobros, el IVA repercutido y el PVP equivalente. El IVA de la inversión se adelanta y se recupera con el modelo 303.
A9: 5. Si cambias la plantilla, el P&L la lee sola: el coste de personal sale de la hoja «Personal», no de una estimación aparte.
A10: 6. La hoja «Tesorería 12 meses» responde la pregunta que decide una operación bancaria: en qué mes se agota la caja. Su Mes 1 es MARZO: la finca abre en primavera y llega al primer invierno con la caja de la temporada. El saldo mínimo del año nunca puede salir en rojo. Las señales de los novios no se modelan: tu caja real será algo mejor.
