Workbook

Sheet Trompo
A1: CALCULADORA DEL TROMPO — CUÁNTOS TACOS SALEN DEL CONO Y CUÁNTO CUESTA LA CARNE
A2: Escribe solo en las celdas VERDES: todo lo demás se calcula. Importes sin IVA. Todos los valores por defecto son una estimación del kit, editable: cámbialos por los de tu proveedor y, sobre todo, por lo que midas en tu propio cono.
A3: AVISO FIJO. La merma de cocción y goteo (35 %) no tiene una fuente publicada fiable: es una estimación del kit. Pesa tu primer cono crudo, lo servido y el sobrante, y ajusta la merma hasta que el rendimiento coincida con lo que mides.
A5: A. EL CONO AL PASTOR | B5: Valor | C5: Notas
A6: Carne cruda montada en el cono (kg) | B6: 15 | C6: Pesa la carne antes del adobo, ya cortada y lista para montar. Estimación del kit, editable.
A7: Adobo sobre la carne (%) | B7: 0.08 | C7: Achiote, chiles, especias y piña del adobo, sobre el peso de la carne. Estimación del kit, editable.
A8: Precio de la carne cruda (€/kg, sin IVA) | B8: 5.5 | C8: Cabeza de lomo o paleta de cerdo. Pon el de tu proveedor. Estimación del kit, editable.
A9: Precio del adobo (€/kg, sin IVA) | B9: 6 | C9: Pon el de tu proveedor o el coste de tu receta. Estimación del kit, editable.
A10: Piña de la punta del cono (kg) | B10: 0 | C10: Por defecto 0: la piña de cada taco se cuenta aparte en la hoja «Escandallo». Si pones kilos, suman al coste del cono.
A11: Precio de la piña (€/kg, sin IVA) | B11: 2 | C11: Solo cuenta si pones kilos de piña arriba. Estimación del kit, editable.
A12: Merma de cocción y goteo (%) | B12: 0.35 | C12: Lo que pierde el cono al asarse: grasa y agua. No hay una cifra publicada fiable: mídela con tu primer cono (hoja «Instrucciones»). Estimación del kit, editable.
A13: Recortes no servibles (%) | B13: 0.05 | C13: Puntas quemadas, grasa dura y nervios que no se sirven. Estimación del kit, editable.
A14: Sobrante al cierre (kg) | B14: 0 | C14: Carne cocinada que queda sin servir al cerrar. Pésala; por defecto 0.
A15: Parte del sobrante que se reaprovecha (%) | B15: 0 | C15: Por ejemplo en un guiso del día siguiente. La parte que se tira resta tacos.
A16: Carne servida por taco (g) | B16: 35 | C16: Gramos de carne cocinada y cortada en cada taco. Estimación del kit, editable.
A17: Número de tacos que quieres preparar | B17: 100 | C17: Número entero mayor que 0. Te dice cuánta carne cruda necesitas.
... A19: Referencia: tacos por kg crudo en un puesto de CDMX | B19: 25 | C19: Referencia fija: un trompo de 50 a 100 kg da entre 1.250 y 2.500 tacos, unos 25 por kg crudo (Milenio). No se edita.
A21: RESULTADO DEL CONO | B21: Valor | C21: Notas
A22: Carne marinada (kg) | B22: =$B$6*(1+$B$7) -> 16.2 | C22: Carne cruda más adobo.
A23: Carne servida del cono (kg) | B23: =$B$22*(1-$B$12-$B$13)-$B$14*(1-$B$15) -> 9.72 | C23: Marinada menos la merma y los recortes, menos el sobrante que se tira.
A24: RENDIMIENTO DEL TROMPO (%) | B24: =$B$23/$B$6 -> 0.648 | C24: Servida ÷ carne cruda montada.
A25: TACOS QUE SALEN DEL CONO | B25: =$B$23*$B$18/$B$16 -> 277.71429 | C25: Servida × 1.000 ÷ gramos por taco.
A26: Tacos por kg de carne cruda | B26: =$B$25/$B$6 -> 18.514286 | C26: Compárala con la referencia de CDMX de arriba.
A27: Tus tacos por kg frente a la referencia de CDMX (%) | B27: =$B$26/$B$19 -> 0.74057143 | C27: Por debajo de 100 %: sirves más gramos por taco o pierdes más.
A28: Coste del cono (€) | B28: =$B$6*$B$8+$B$6*$B$7*$B$9+$B$10*$B$11 -> 89.7 | C28: Carne + adobo + piña de la punta.
A29: COSTE POR KG SERVIDO (€) | B29: =$B$28/$B$23 -> 9.2283951 | C29: Coste del cono ÷ kg servidos. Alimenta el escandallo.
A30: COSTE DE CARNE POR TACO (€) | B30: =$B$29*$B$16/$B$18 -> 0.32299383 | C30: Coste por kg servido × gramos por taco ÷ 1.000.
A31: Carne cruda para preparar los N tacos (kg) | B31: =$B$17*$B$16/($B$18*$B$24) -> 5.4012346 | C31: N × gramos por taco ÷ (1.000 × rendimiento).
A33: B. OTRAS PROTEÍNAS (guisos y asados) | B33: kg crudos | C33: €/kg crudo (sin IVA) | D33: Rendimiento tras la cocción (%) | E33: g por taco | F33: kg cocinados | G33: €/kg cocinado | H33: Tacos | I33: € de carne por taco
A34: Carnitas | B34: 10 | C34: 5.2 | D34: 0.6 | E34: 35 | F34: =B34*D34 -> 6 | G34: =C34/D34 -> 8.6666667 | H34: =F34*$B$18/E34 -> 171.42857 | I34: =G34*E34/$B$18 -> 0.30333333
A35: Suadero | B35: 10 | C35: 7.5 | D35: 0.55 | E35: 35 | F35: =B35*D35 -> 5.5 | G35: =C35/D35 -> 13.636364 | H35: =F35*$B$18/E35 -> 157.14286 | I35: =G35*E35/$B$18 -> 0.47727273
A36: Cochinita pibil | B36: 10 | C36: 5.5 | D36: 0.6 | E36: 40 | F36: =B36*D36 -> 6 | G36: =C36/D36 -> 9.1666667 | H36: =F36*$B$18/E36 -> 150 | I36: =G36*E36/$B$18 -> 0.36666667
A37: Barbacoa de res | B37: 10 | C37: 7 | D37: 0.5 | E37: 40 | F37: =B37*D37 -> 5 | G37: =C37/D37 -> 14 | H37: =F37*$B$18/E37 -> 125 | I37: =G37*E37/$B$18 -> 0.56
A38: Tinga de pollo | B38: 10 | C38: 4 | D38: 0.65 | E38: 35 | F38: =B38*D38 -> 6.5 | G38: =C38/D38 -> 6.1538462 | H38: =F38*$B$18/E38 -> 185.71429 | I38: =G38*E38/$B$18 -> 0.21538462
A39: Campechano | B39: 10 | C39: 7 | D39: 0.55 | E39: 35 | F39: =B39*D39 -> 5.5 | G39: =C39/D39 -> 12.727273 | H39: =F39*$B$18/E39 -> 157.14286 | I39: =G39*E39/$B$18 -> 0.44545455
A40: Los guisos de cocción larga (carnitas, barbacoa, cochinita) rinden menos que el cono: el rendimiento y el precio de cada fila son una estimación del kit, editable. El €/kg cocinado de cada fila alimenta la hoja «Escandallo».

Sheet Tortilla
A1: TORTILLA — COMPRADA FRENTE A NIXTAMAL PROPIO Y EQUILIBRIO EN TORTILLAS AL DÍA
A2: Escribe solo en las celdas VERDES. Importes sin IVA. Los valores por defecto son una estimación del kit, editable: cámbialos por los de tu proveedor. A volúmenes de taquería de barrio, comprar suele ganar; esta hoja te dice dónde cambia la cuenta.
A5: A. TORTILLA COMPRADA | B5: Valor | C5: Notas
A6: Precio del paquete de tortillas (€, sin IVA) | B6: 14 | C6: Tortilla de maíz de 12 cm. El minorista cuesta unos 0,21 € la unidad; el profesional, un 30 % menos. Estimación del kit, editable.
A7: Piezas por paquete | B7: 100 | C7: Número entero mayor que 0. Estimación del kit, editable.
A8: Peso de cada tortilla (g) | B8: 22 | C8: Una tortilla de 12 cm pesa unos 22 g. Estimación del kit, editable.
A9: B. NIXTAMAL PROPIO (maíz en grano, molino y prensa) | B9: Valor | C9: Notas
A10: Precio del maíz para nixtamal (€/kg, sin IVA) | B10: 1.2 | C10: Maíz blanco en grano. Pon el de tu proveedor. Estimación del kit, editable.
A11: Masa que sale de 1 kg de maíz (kg) | B11: 2 | C11: El maíz nixtamalizado absorbe agua: de 1 kg de grano salen unos 2 kg de masa. Estimación del kit, editable.
A12: Cal, gas, luz y agua del nixtamal (€ por kg de maíz) | B12: 2 | C12: Todo lo que se gasta en cocer, moler y prensar, por kilo de maíz. Estimación del kit, editable.
A13: Masa por tortilla propia (g) | B13: 22 | C13: Masa cruda que lleva cada tortilla antes de prensarla. Estimación del kit, editable.
A14: Coste anual del tortillero (€, con cargas) | B14: 18900 | C14: Unas tres cuartas partes de una jornada, con seguridad social. Estimación del kit, editable.
A15: Inversión en molino, prensa y mesa (€, sin IVA) | B15: 18000 | C15: Molino de nixtamal, tortilladora y mesa de trabajo. Estimación del kit, editable.
A16: Años de vida de la inversión | B16: 6 | C16: La inversión se reparte en estos años. Estimación del kit, editable.
A17: Días de apertura al año | B17: 300 | C17: Los del caso del plan de negocio. Estimación del kit, editable.
A18: C. TU CASO | B18: Valor | C18: Notas
A19: Tortillas que gastas al día | B19: 280 | C19: Las del caso del plan de negocio. Cámbialas por las tuyas. Estimación del kit, editable.
A21: RESULTADO | B21: Valor | C21: Notas
A22: Coste por tortilla comprada (€) | B22: =$B$6/$B$7 -> 0.14 | C22: Paquete ÷ piezas.
A23: Tortillas que salen de 1 kg comprado | B23: ='Trompo'!$B$18/$B$8 -> 45.454545 | C23: Para pedir al proveedor: 1.000 ÷ gramos por pieza.
A24: Maíz por tortilla propia (g) | B24: =$B$13/$B$11 -> 11 | C24: Masa por tortilla ÷ masa que sale de 1 kg de maíz.
A25: Tortillas que salen de 1 kg de maíz | B25: =$B$11*'Trompo'!$B$18/$B$13 -> 90.909091
A26: Coste por tortilla propia (€, sin la persona ni la inversión) | B26: =$B$24*($B$10+$B$12)/'Trompo'!$B$18 -> 0.0352 | C26: Maíz + cal, gas, luz y agua.
A27: Ahorro por tortilla al hacerla tú (€) | B27: =$B$22-$B$26 -> 0.1048 | C27: Si sale cero o negativo, comprar siempre gana.
A28: Coste fijo diario de hacerlas tú (€) | B28: =($B$14+$B$15/$B$16)/$B$17 -> 73 | C28: Persona + inversión repartida, por día de apertura.
A29: EQUILIBRIO (tortillas al día) | B29: =IF($B$27>0,($B$14+$B$15/$B$16)/($B$27*$B$17),0) -> 696.56489 | C29: Con más tortillas al día que esta cifra, hacerlas compensa. Con menos, compra.
A30: Coste diario con tortilla comprada (€) | B30: =$B$19*$B$22 -> 39.2 | C30: Para las tortillas al día que has puesto.
A31: Coste diario con tortilla propia (€) | B31: =$B$19*$B$26+$B$28 -> 82.856 | C31: Incluye la persona y la inversión.
A32: Qué te conviene | B32: =IF(AND($B$27>0,$B$19>=$B$29),"Hazla tú","Compra la tortilla") -> Compra la tortilla | C32: Según tus tortillas al día frente al equilibrio.

Sheet Escandallo
A1: ESCANDALLO POR TACO — 8 TACOS, UNA ORDEN Y UNA GRINGA DE EJEMPLO, EN GRAMOS
A2: Escribe solo en las celdas VERDES (precios, gramos, nombres, tortillas y precios de carta). Importes sin IVA salvo el precio de carta. Los precios son una estimación del kit, editable: pon los de tu proveedor. Las carnes y la tortilla de maíz vienen de las hojas «Trompo» y «Tortilla».
A4: DATOS GENERALES | B4: Valor | D4: Notas
A5: IVA de la comida (%) | B5: 0.1 | D5: Comida preparada, en sala, para llevar y a domicilio: 10 % (Ley 37/1992, art. 91.Uno.1.1.º y 2.2.º).
A6: Food cost objetivo (% sobre el precio sin IVA) | B6: 0.25 | D6: Referencia de taquería: 22-30 % en el taco al pastor. Estimación del kit, editable.
A7: Margen de vigilancia sobre el objetivo (puntos) | B7: 0.05 | D7: Hasta este margen por encima del objetivo, el semáforo dice «Vigila el coste».
A8: Merma de producción sobre el coste (%) | B8: 0.05 | D8: Salsas crudas que se descartan, tortillas rotas, cebolla y cilantro que no se aprovechan. Estimación del kit, editable.
A9: Tortilla de maíz que usa el escandallo | B9: Tortilla comprada | D9: Elige el coste por tortilla de la hoja «Tortilla»: comprada o nixtamal propio.
A10: Envase por pedido para llevar (€, sin IVA) | B10: 0.5 | D10: Bolsa, caja y tarrinas de salsa de un pedido. Estimación del kit, editable.
A11: Comisión de la plataforma de reparto (%) | B11: 0.3 | D11: Sobre el precio sin IVA del pedido. Uber Eats ronda el 30 %; revisa tu contrato. Estimación del kit, editable.
A13: INGREDIENTE (en gramos) | B13: €/kg sin IVA | C13: Unidad | D13: Taco al pastor | E13: Taco de carnitas | F13: Taco de suadero | G13: Taco de cochinita | H13: Taco de barbacoa | I13: Taco de tinga | J13: Taco campechano | K13: Taco vegetal | L13: Orden de 3 al pastor | M13: Gringa al pastor | N13: ORIGEN DEL PRECIO
A14: Precio de carta con IVA (€) | D14: 3 | E14: 3 | F14: 3 | G14: 3.5 | H14: 3.5 | I14: 3 | J14: 3.5 | K14: 3.5 | L14: 8.5 | M14: 7.5
A15: Carne al pastor (del cono) | B15: ='Trompo'!$B$29 -> 9.2283951 | C15: g | D15: 35 | E15: 0 | F15: 0 | G15: 0 | H15: 0 | I15: 0 | J15: 0 | K15: 0 | L15: 105 | M15: 70 | N15: enlazado desde la hoja Trompo (€/kg servido)
A16: Carnitas | B16: ='Trompo'!$G$34 -> 8.6666667 | C16: g | D16: 0 | E16: 35 | F16: 0 | G16: 0 | H16: 0 | I16: 0 | J16: 0 | K16: 0 | L16: 0 | M16: 0 | N16: enlazado desde la hoja Trompo (€/kg cocinado)
A17: Suadero | B17: ='Trompo'!$G$35 -> 13.636364 | C17: g | D17: 0 | E17: 0 | F17: 35 | G17: 0 | H17: 0 | I17: 0 | J17: 0 | K17: 0 | L17: 0 | M17: 0 | N17: enlazado desde la hoja Trompo (€/kg cocinado)
A18: Cochinita pibil | B18: ='Trompo'!$G$36 -> 9.1666667 | C18: g | D18: 0 | E18: 0 | F18: 0 | G18: 40 | H18: 0 | I18: 0 | J18: 0 | K18: 0 | L18: 0 | M18: 0 | N18: enlazado desde la hoja Trompo (€/kg cocinado)
A19: Barbacoa de res | B19: ='Trompo'!$G$37 -> 14 | C19: g | D19: 0 | E19: 0 | F19: 0 | G19: 0 | H19: 40 | I19: 0 | J19: 0 | K19: 0 | L19: 0 | M19: 0 | N19: enlazado desde la hoja Trompo (€/kg cocinado)
A20: Tinga de pollo | B20: ='Trompo'!$G$38 -> 6.1538462 | C20: g | D20: 0 | E20: 0 | F20: 0 | G20: 0 | H20: 0 | I20: 35 | J20: 0 | K20: 0 | L20: 0 | M20: 0 | N20: enlazado desde la hoja Trompo (€/kg cocinado)
A21: Campechano | B21: ='Trompo'!$G$39 -> 12.727273 | C21: g | D21: 0 | E21: 0 | F21: 0 | G21: 0 | H21: 0 | I21: 0 | J21: 35 | K21: 0 | L21: 0 | M21: 0 | N21: enlazado desde la hoja Trompo (€/kg cocinado)
A22: Cebolla picada | B22: 1.2 | C22: g | D22: 10 | E22: 10 | F22: 10 | G22: 10 | H22: 10 | I22: 5 | J22: 10 | K22: 5 | L22: 30 | M22: 10 | N22: estimación del kit
A23: Cilantro | B23: 12 | C23: g | D23: 3 | E23: 3 | F23: 3 | G23: 0 | H23: 3 | I23: 2 | J23: 3 | K23: 3 | L23: 9 | M23: 3 | N23: estimación del kit
A24: Piña | B24: 2 | C24: g | D24: 8 | E24: 0 | F24: 0 | G24: 0 | H24: 0 | I24: 0 | J24: 0 | K24: 0 | L24: 24 | M24: 15 | N24: estimación del kit
A25: Lima | B25: 2.5 | C25: g | D25: 5 | E25: 5 | F25: 5 | G25: 5 | H25: 5 | I25: 0 | J25: 5 | K25: 5 | L25: 15 | M25: 0 | N25: estimación del kit
A26: Salsa roja | B26: 3 | C26: g | D26: 8 | E26: 7 | F26: 7 | G26: 0 | H26: 10 | I26: 8 | J26: 8 | K26: 0 | L26: 24 | M26: 12 | N26: estimación del kit
A27: Salsa verde | B27: 3 | C27: g | D27: 7 | E27: 8 | F27: 4 | G27: 10 | H27: 0 | I27: 5 | J27: 7 | K27: 10 | L27: 21 | M27: 8 | N27: estimación del kit
A28: Salsa macha | B28: 9 | C28: g | D28: 0 | E28: 0 | F28: 4 | G28: 0 | H28: 0 | I28: 0 | J28: 0 | K28: 0 | L28: 0 | M28: 0 | N28: estimación del kit
A29: Queso Oaxaca o chihuahua | B29: 8.5 | C29: g | D29: 0 | E29: 0 | F29: 0 | G29: 0 | H29: 0 | I29: 10 | J29: 0 | K29: 20 | L29: 0 | M29: 60 | N29: estimación del kit
A30: Guacamole | B30: 11 | C30: g | D30: 0 | E30: 0 | F30: 0 | G30: 0 | H30: 0 | I30: 0 | J30: 0 | K30: 25 | L30: 0 | M30: 0 | N30: estimación del kit (depende del aguacate)
A31: Frijoles de la olla | B31: 3.5 | C31: g | D31: 0 | E31: 0 | F31: 0 | G31: 0 | H31: 0 | I31: 0 | J31: 0 | K31: 40 | L31: 0 | M31: 0 | N31: estimación del kit
A32: INGREDIENTE (en unidades) | B32: €/ud sin IVA | C32: Unidad
A33: Tortilla de maíz (€/ud) | B33: =IF($B$9="Tortilla comprada",'Tortilla'!$B$22,'Tortilla'!$B$26) -> 0.14 | C33: ud | D33: 1 | E33: 1 | F33: 1 | G33: 1 | H33: 1 | I33: 1 | J33: 1 | K33: 1 | L33: 3 | M33: 0 | N33: enlazado desde la hoja Tortilla, según el modo elegido
A34: Tortilla de harina (€/ud) | B34: 0.2 | C34: ud | D34: 0 | E34: 0 | F34: 0 | G34: 0 | H34: 0 | I34: 0 | J34: 0 | K34: 0 | L34: 0 | M34: 1 | N34: estimación del kit
A36: RESULTADO POR PLATO (gramos y unidades en las columnas de arriba) | D36: =D13 -> Taco al pastor | E36: =E13 -> Taco de carnitas | F36: =F13 -> Taco de suadero | G36: =G13 -> Taco de cochinita | H36: =H13 -> Taco de barbacoa | I36: =I13 -> Taco de tinga | J36: =J13 -> Taco campechano | K36: =K13 -> Taco vegetal | ... M36: =M13 -> Gringa al pastor
A37: Peso servido en el plato, sin tortilla (g) | D37: =SUM(D$15:D$31) -> 76 | E37: =SUM(E$15:E$31) -> 68 | F37: =SUM(F$15:F$31) -> 68 | G37: =SUM(G$15:G$31) -> 65 | H37: =SUM(H$15:H$31) -> 68 | I37: =SUM(I$15:I$31) -> 65 | J37: =SUM(J$15:J$31) -> 68 | K37: =SUM(K$15:K$31) -> 108 | ... M37: =SUM(M$15:M$31) -> 178
A38: Coste de materia prima (€) | D38: =SUMPRODUCT(D$15:D$31,$B$15:$B$31)/'Trompo'!$B$18+SUMPRODUCT(D$33:D$34,$B$33:$B$34) -> 0.58449383 | E38: =SUMPRODUCT(E$15:E$31,$B$15:$B$31)/'Trompo'!$B$18+SUMPRODUCT(E$33:E$34,$B$33:$B$34) -> 0.54883333 | F38: =SUMPRODUCT(F$15:F$31,$B$15:$B$31)/'Trompo'!$B$18+SUMPRODUCT(F$33:F$34,$B$33:$B$34) -> 0.74677273 | G38: =SUMPRODUCT(G$15:G$31,$B$15:$B$31)/'Trompo'!$B$18+SUMPRODUCT(G$33:G$34,$B$33:$B$34) -> 0.56116667 | H38: =SUMPRODUCT(H$15:H$31,$B$15:$B$31)/'Trompo'!$B$18+SUMPRODUCT(H$33:H$34,$B$33:$B$34) -> 0.7905 | I38: =SUMPRODUCT(I$15:I$31,$B$15:$B$31)/'Trompo'!$B$18+SUMPRODUCT(I$33:I$34,$B$33:$B$34) -> 0.50938462 | J38: =SUMPRODUCT(J$15:J$31,$B$15:$B$31)/'Trompo'!$B$18+SUMPRODUCT(J$33:J$34,$B$33:$B$34) -> 0.69095455 | K38: =SUMPRODUCT(K$15:K$31,$B$15:$B$31)/'Trompo'!$B$18+SUMPRODUCT(K$33:K$34,$B$33:$B$34) -> 0.8095 | ... M38: =SUMPRODUCT(M$15:M$31,$B$15:$B$31)/'Trompo'!$B$18+SUMPRODUCT(M$33:M$34,$B$33:$B$34) -> 1.4939877
A39: COSTE CON MERMA (€) | D39: =D38*(1+$B$8) -> 0.61371852 | E39: =E38*(1+$B$8) -> 0.576275 | F39: =F38*(1+$B$8) -> 0.78411136 | G39: =G38*(1+$B$8) -> 0.589225 | H39: =H38*(1+$B$8) -> 0.830025 | I39: =I38*(1+$B$8) -> 0.53485385 | J39: =J38*(1+$B$8) -> 0.72550227 | K39: =K38*(1+$B$8) -> 0.849975 | ... M39: =M38*(1+$B$8) -> 1.568687
A40: Precio de venta sin IVA (€) | D40: =D14/(1+$B$5) -> 2.7272727 | E40: =E14/(1+$B$5) -> 2.7272727 | F40: =F14/(1+$B$5) -> 2.7272727 | G40: =G14/(1+$B$5) -> 3.1818182 | H40: =H14/(1+$B$5) -> 3.1818182 | I40: =I14/(1+$B$5) -> 2.7272727 | J40: =J14/(1+$B$5) -> 3.1818182 | K40: =K14/(1+$B$5) -> 3.1818182 | ... M40: =M14/(1+$B$5) -> 6.8181818
A41: FOOD COST (%) | D41: =D39/D40 -> 0.22503012 | E41: =E39/E40 -> 0.21130083 | F41: =F39/F40 -> 0.2875075 | G41: =G39/G40 -> 0.185185 | H41: =H39/H40 -> 0.260865 | I41: =I39/I40 -> 0.19611308 | J41: =J39/J40 -> 0.228015 | K41: =K39/K40 -> 0.267135 | ... M41: =M39/M40 -> 0.2300741
A42: Semáforo contra el objetivo | D42: =IF(D41<=$B$6,"En objetivo",IF(D41<=$B$6+$B$7,"Vigila el coste","Por encima del objetivo")) -> En objetivo | E42: =IF(E41<=$B$6,"En objetivo",IF(E41<=$B$6+$B$7,"Vigila el coste","Por encima del objetivo")) -> En objetivo | F42: =IF(F41<=$B$6,"En objetivo",IF(F41<=$B$6+$B$7,"Vigila el coste","Por encima del objetivo")) -> Vigila el coste | G42: =IF(G41<=$B$6,"En objetivo",IF(G41<=$B$6+$B$7,"Vigila el coste","Por encima del objetivo")) -> En objetivo | H42: =IF(H41<=$B$6,"En objetivo",IF(H41<=$B$6+$B$7,"Vigila el coste","Por encima del objetivo")) -> Vigila el coste | I42: =IF(I41<=$B$6,"En objetivo",IF(I41<=$B$6+$B$7,"Vigila el coste","Por encima del objetivo")) -> En objetivo | J42: =IF(J41<=$B$6,"En objetivo",IF(J41<=$B$6+$B$7,"Vigila el coste","Por encima del objetivo")) -> En objetivo | K42: =IF(K41<=$B$6,"En objetivo",IF(K41<=$B$6+$B$7,"Vigila el coste","Por encima del objetivo")) -> Vigila el coste | ... M42: =IF(M41<=$B$6,"En objetivo",IF(M41<=$B$6+$B$7,"Vigila el coste","Por encima del objetivo")) -> En objetivo
A43: Margen bruto (€, precio sin IVA − coste) | D43: =D40-D39 -> 2.1135542 | E43: =E40-E39 -> 2.1509977 | F43: =F40-F39 -> 1.9431614 | G43: =G40-G39 -> 2.5925932 | H43: =H40-H39 -> 2.3517932 | I43: =I40-I39 -> 2.1924189 | J43: =J40-J39 -> 2.4563159 | K43: =K40-K39 -> 2.3318432 | ... M43: =M40-M39 -> 5.2494948
...

Sheet Instrucciones
A1: INSTRUCCIONES DE USO — Calculadora del trompo y escandallo por taco
A2: Tres herramientas en un libro: la hoja «Trompo» te dice cuántos tacos salen de un cono al pastor y cuánto cuesta la carne de cada uno; la hoja «Tortilla» compara comprar la tortilla con hacerla tú y te da el equilibrio en tortillas al día; la hoja «Escandallo» calcula el coste, el food cost, el margen y el precio de carta de 8 tacos, una orden de 3 y una gringa, con el margen en sala, para llevar y en plataforma. Solo se escribe en las celdas VERDES; lo demás se calcula.
A3: Todos los valores por defecto son una estimación del kit, editable: son ejemplos coherentes con el caso del plan de negocio, no precios de nadie. Cámbialos por los de tu proveedor y por lo que midas en tu cocina antes de decidir precios.
A4: HOJA «TROMPO»
A6: 1. Cómo medir el cono. Pesa la carne cruda que montas en el trompo (antes del adobo) y apunta los kilos. Al cerrar, pesa lo que sobra del cono ya cocinado y anota a dónde va: se reaprovecha en un guiso o se tira. Con esos tres datos y los tacos que vendiste, la hoja te da el rendimiento real.
A7: 2. Cómo ajustar la merma. La merma de cocción y goteo de 35 % es una estimación del kit, sin fuente publicada. Mide tu primer cono: tacos servidos × gramos por taco ÷ 1.000 son los kilos servidos. Mueve la merma hasta que el rendimiento de la hoja coincida con el tuyo.
A8: 3. El resultado más útil es el coste por kg servido y el coste de carne por taco, que alimentan el escandallo. Compara tus tacos por kg crudo con la referencia de un puesto de la Ciudad de México, unos 25 por kg (Milenio). Si sirves más gramos, saldrán menos tacos.
A9: 4. «Carne cruda para los N tacos» te dice cuánta carne montar para un pedido grande. Las otras proteínas (carnitas, suadero, cochinita, barbacoa, tinga y campechano) usan su propio rendimiento tras la cocción, más bajo que el del cono.
A10: 5. Seguridad alimentaria. El cono montado y adobado es un preparado de carne: manténlo a 4 °C como máximo hasta que entre al asador, mide con sonda y registra la temperatura en tu plan de APPCC. Pregunta a tu ayuntamiento y a tu comunidad por lo que exigen en tu zona.
A11: HOJA «TORTILLA»
A13: 1. Escribe el precio del paquete, las piezas y el peso de cada tortilla, y los datos del nixtamal propio. Las tortillas por kg comprado son lo que necesitas para pedir al proveedor.
A14: 2. El equilibrio es el número de tortillas al día a partir del cual hacerlas compensa, contando a la persona que las hace y la inversión. Si gastas menos, compra. Con tu cifra de tortillas al día, la hoja te dice qué te conviene.
... A28: Versión 1.0 · noviembre 2026 · aichef.pro/plan-negocio-taqueria · info@aichef.pro
