Workbook

Sheet 0. Supuestos
A1: SUPUESTOS — aquí se teclean las TASAS y los DRIVERS del modelo
A2: Cambia las celdas VERDES: el resto del libro se recalcula solo. Las partidas de gasto se teclean en su hoja (también en verde) y no se repiten aquí.
A3: ACTIVIDAD
A4: Comensales/día (media del año 1) | B4: 77 | C4: Comensales equivalentes al día, media del año: unos 57 en sala (la terraza incluida de abril a octubre) y unos 20 de para llevar y domicilio, que son los pedidos (unos 15 al día de unos 20,50 € sin IVA) divididos por el ticket. Un sábado, unos 125 con los pedidos; un martes, unos 55. Contrástalo con el paso de gente de tu calle un viernes por la noche y un martes a mediodía
A5: Ticket medio SIN IVA (€) | B5: 15.5 | C5: SIN IVA, por comensal: una orden de 3 tacos (8,50 € con IVA), medio taco suelto, algo de gringa o quesadilla, algún entrante, 1,1 bebidas y algún postre suman unos 17,40 € con IVA en sala; el caso se queda en 15,50 € sin IVA por los combos de mediodía. El taco al pastor del caso cuesta 3,00 € con IVA, dentro de la franja de 2,50-3,50 € de las taquerías casuales de ciudad (cartas leídas en octubre de 2026). El precio con IVA está en la fila «PVP equivalente con IVA» de abajo
A6: Días de apertura al año | B6: 300 | C6: 365 días menos los 52 lunes de cierre, 12 días de cierre en enero (mantenimiento y vacaciones) y el 25 de diciembre. Es el MISMO dato para la cuenta de resultados, el punto de equilibrio, los escenarios y las horas de personal
A7: Crecimiento de volumen del año 2 | B7: 0.06 | C7: Clientela que repite y más pedidos para llevar el segundo año. Se aplica a los comensales con el mismo ticket; el personal NO sube con este porcentaje: sale de la hoja Personal
A8: Crecimiento de volumen del año 3 | B8: 0.04 | C8: Sobre el año 2. Conservador: el techo lo ponen el trompo, la plancha y las 32 plazas los viernes y los sábados por la noche
A9: PVP equivalente con IVA (calculado) | B9: =IFERROR(IF($B$5="","",$B$5*(1+SUMPRODUCT('PyG 3 Años'!$E$10:$E$11,'PyG 3 Años'!$G$10:$G$11))),"") -> 17.075575 | C9: =IFERROR("Ticket sin IVA más el IVA medio ponderado de tus líneas de venta: "&TEXT(SUMPRODUCT('PyG 3 Años'!$E$10:$E$11,'PyG 3 Años'!$G$10:$G$11)*100,"0")&" %. En sala todo va al 10 % (art. 91.Uno.2.2.º de la Ley 37/1992, alcohol incluido); la bebida que sale para llevar o a domicilio (columna H de su línea en el P&L) mueve la media. Aquí va redondeado. Compáralo con el rango del sector, que va con IVA.","") -> Ticket sin IVA más el IVA medio ponderado de tus líneas de venta: 10 %. En sala todo va al 10 % (art. 91.Uno.2.2.º de la Ley 37/1992, alcohol incluido); la bebida que sale para llevar o a domicilio (columna H de su línea en el P&L) mueve la media. Aquí va redondeado. Compáralo con el rango del sector, que va con IVA.
A10: MIX Y COSTE DE MERCANCÍA
A11: Ventas de COMIDA sobre el total | B11: 0.8 | C11: Peso de la COMIDA sobre el total de ventas. Es un INPUT: cámbialo aquí y el P&L, la tesorería y el IVA repercutido se recalculan solos
A12: Ventas de BEBIDA sobre el total | B12: =IFERROR(IF(COUNT(B11)=0,"",1-B11),"") -> 0.2 | C12: Se calcula como el resto: comida + bebida = 100 %
A13: Coste de mercancía sobre las ventas de COMIDA | B13: 0.27 | C13: Materia prima de la comida sobre sus ventas: el taco al pastor sale a un 22,5 % (un 24 % en la orden de 3), las carnitas, el suadero y la barbacoa a un 26-30 %, la gringa a un 23 % y el guacamole a un 22-28 % según el aguacate: un 25 % de media, más 1,5 puntos de merma (el sobrante del trompo y las salsas crudas que se tiran) y medio punto de prudencia, porque la carne y la tortilla son precios estimados por el kit. Escandalla cada taco con la calculadora del pack
A14: Coste de mercancía sobre las ventas de BEBIDA | B14: 0.26 | C14: Aguas frescas al 12 %, cerveza mexicana al 33 %, mezcal y tequila al 28 % y refrescos y agua al 30 % de su precio de venta, en una mezcla de 30/45/10/15. Si la cervecera te cede el equipo de tiraje, pide el precio del barril por escrito
A15: Consumibles sobre ventas | B15: 0.035 | C15: Envases para llevar y a domicilio, tarrinas de salsa, papel, servilletas, guantes y los envases para que el cliente se lleve lo que no consuma (Ley 1/2025, art. 8). El envase de plástico de un solo uso se cobra aparte en el tique (Ley 7/2022, art. 55)
A16: Ventas por delivery sobre el total | B16: 0.12 | C16: Ventas por PLATAFORMA con su reparto (Glovo, Just Eat, Uber Eats) sobre el total. Lo que se recoge en el local NO paga comisión y no va aquí. La tortilla llega peor tras el viaje: la orden «para armar» lo aguanta, pero no subas de aquí sin probarlo
A17: Comisión de la plataforma de delivery | B17: 0.3 | C17: Comisión de la plataforma con su reparto sobre lo que vende ese canal: el plan básico de Uber Eats ronda el 30 % más IVA, Glovo va del 15 al 35 % según la zona y Just Eat, del 25 al 35 % con su reparto. Compruébala en tu contrato. Si repartes tú, pon 0 y suma el repartidor, con contrato laboral, a la hoja Personal
A18: Comisión de los medios de pago | B18: 0.008 | C18: Tarjeta y bizum sobre el total facturado
A19: PERSONAL
A20: Seguridad Social a cargo de la empresa | B20: 0.33 | C20: Contingencias comunes + AT/EP + desempleo + FOGASA + FP; ajusta a tu convenio y bonificaciones
A21: Número de pagas anuales | B21: 14 | C21: Salario bruto anual = bruto mensual × pagas
A22: SMI anual de referencia (€) | B22: 17094 | C22: SMI 2026: 17.094 € al año (1.221 €/mes en 14 pagas), suelo legal por jornada completa. Comprueba el importe vigente si presentas el plan en otro ejercicio
A23: LOCAL Y FIJOS
A24: Alquiler mensual del local (€) | B24: 1450 | C24: Local de 80 m² con salida de humos a cubierta posible (es el filtro del local): sala de 45 m² con 24 plazas en mesa y 8 en barra, cocina de 20 m² a la vista con el trompo, la plancha y el comal, aseos (uno adaptado) y almacén, en una calle con paso cerca de una zona universitaria o de ocio de una ciudad media, sin traspaso: unos 18 € el m². El peso sobre las ventas lo calcula el propio libro en la fila «Alquiler / Ventas» del P&L
A25: Fianza del alquiler (meses) | B25: 2 | C25: Dos meses de renta, lo habitual en un contrato de local de negocio: compruébalo con tu abogado
A26: Suministros mensuales de luz, agua y gas (€) | B26: 850 | C26: Luz (frío, extracción, climatización y cafetera), el gas del trompo, la plancha, el comal y los fogones, y el agua. Pide el histórico del local
A27: Seguros (€/año) | B27: 1400 | C27: Responsabilidad civil de al menos 300.000 € y multirriesgo con incendio y avería del frío. Dile a la aseguradora que trabajas con trompo, plancha y freidora a gas: cambia la prima y las condiciones
A28: Varios e imprevistos sobre ventas | B28: 0.02 | C28: Colchón de gasto corriente no presupuestado (pequeñas reparaciones, utillaje que se rompe, pruebas de carta)
A29: FINANCIACIÓN
A30: Recursos propios aportados (€) | B30: 55000 | C30: Aportación de los socios. Un banco pide entre el 25 y el 30 % de la necesidad de caja con dinero propio
A31: Préstamo bancario solicitado (€) | B31: 118000 | C31: Principal solicitado. La hoja de Financiación compara lo que aportas con la necesidad de caja de la hoja de inversión y te dice si sobra o falta: ajústalo con ese dato
A32: Tipo de interés nominal anual | B32: 0.06 | C32: Tipo nominal anual. Pide oferta a dos entidades y a una línea ICO antes de fijarlo; el frío y el equipo de cocina se pueden pagar con leasing o renting: compáralo
A33: Plazo del préstamo (años) | B33: 7 | C33: Años totales, carencia incluida
A34: Carencia de principal (años) | B34: 1 | C34: El primer año sólo intereses: obra, conducto de humos y cocina antes de facturar. Desde el segundo año se devuelve el principal: mira la holgura de caja de ese año en el Punto de Equilibrio
A35: Fondo de maniobra (meses de costes fijos) | B35: 3 | C35: Tres meses de costes fijos: el colchón para la rampa del arranque, que con el Mes 1 en enero cae sobre los meses más flojos del año (enero y febrero)
A36: FISCAL
A37: Impuesto de Sociedades, nueva creación | B37: 0.15 | C37: Art. 29.1 LIS: el PRIMER ejercicio con base imponible positiva y el SIGUIENTE. El libro lo aproxima contando los dos primeros ejercicios con base positiva: coincide con la ley salvo que entre ellos haya un ejercicio en pérdidas
A38: Impuesto de Sociedades, tipo general | B38: 0.25 | C38: A partir del tercer ejercicio con base positiva. Es el tipo general del art. 29.1 LIS: si tu cifra de negocios queda por debajo de 1 M € (microempresa) o de 10 M € (reducida dimensión), desde 2025 hay tipos más bajos que se implantan de forma gradual; confirma el de tu ejercicio con tu asesor y cámbialo aquí
A39: IVA repercutido de restauración | B39: 0.1 | C39: Tipo reducido de hostelería
A40: IVA repercutido/soportado general | B40: 0.21 | C40: Tipo general. En este libro lo usan dos cosas: el IVA que soportas al comprar el alcohol (el proveedor lo factura al 21 %) y el que repercutes por la bebida que sale para llevar o a domicilio (es una entrega de bienes). El alcohol servido en sala va al reducido, como fija la línea de bebida del P&L. Suministros, equipamiento y servicios tienen su tipo en la celda de abajo. En las compras, el libro manda al general la parte de la bebida que declara la celda «Bebida que compras al 21 %» de esta hoja: la cerveza, el mezcal, el tequila y los refrescos con azúcares o edulcorantes añadidos, cuya factura va al 21 % (art. 91.Uno.1.1.º de la Ley 37/1992)
...

Sheet Inversión Inicial
A1: PLAN DE NEGOCIO: TAQUERÍA
A2: Inversión inicial estimada — taquería con trompo, barra de salsas, 32 plazas y terraza
A3: Ajusta las cifras a tu proyecto: son las de un caso tipo en una ciudad media, sin traspaso. Pon tus presupuestos reales en las celdas de importe.
A5: Concepto | B5: Importe | C5: % s/inversión | D5: Notas | E5: ¿Lleva IVA?
A6: INVERSIÓN | B6: =IFERROR(IF(COUNT(B7:B27)=0,"",SUM(B7:B27)),"") -> 106150 | C6: =IFERROR(B6/$B$30,"") -> 0.70297929
A7: Proyecto técnico de actividad y de salida de humos, y dirección de obra | B7: 3500 | C7: =IFERROR(B7/$B$30,"") -> 0.02317878 | D7: Proyecto de la actividad y del conducto de humos, memoria para la licencia o la declaración responsable y certificado final de obra | E7: Sí
A8: Obra y acondicionamiento del local, rótulo y fachada | B8: 26500 | C8: =IFERROR(B8/$B$30,"") -> 0.17549648 | D8: Cocina alicatada, suelo antideslizante, aseos (uno adaptado), falsos techos y aislamiento acústico, más el rótulo y la fachada (unos 2.500 €). Estimación del kit: pide dos presupuestos | E8: Sí
A9: Conducto de extracción exclusivo hasta cubierta | B9: 6000 | C9: =IFERROR(B9/$B$30,"") -> 0.039735052 | D9: Conducto exclusivo hasta la cubierta para el trompo, la plancha, el comal y la freidora: Madrid pide superar en 1 m lo que haya en 15 m (Ordenanza 4/2021). Con trompo o parrilla de carbón, además, filtro de partículas. Ningún fabricante da precio por metro: pide oferta con tu proyecto | E9: Sí
A10: Instalación eléctrica, cuadro y boletín | B10: 4500 | C10: =IFERROR(B10/$B$30,"") -> 0.029801289 | D10: Frío, extracción, climatización, lavavajillas y cafetera. Pregunta la potencia disponible ANTES de firmar: una acometida nueva tarda | E10: Sí
A11: Fontanería, separador de grasas, climatización e instalación de gas | B11: 8000 | C11: =IFERROR(B11/$B$30,"") -> 0.052980069 | D11: Agua fría y caliente en la cocina, desagües con separador de grasas, climatización de la sala y la instalación de gas del trompo, la plancha, el comal y los fogones por empresa instaladora habilitada, con su certificado (RD 919/2006) | E11: Sí
A12: Trompo: asador vertical de gas de cuatro quemadores | B12: 1800 | C12: =IFERROR(B12/$B$30,"") -> 0.011920516 | D12: Para conos de 30-35 kg, con bandeja, cuchillos de corte y base para la piña. En el catálogo de un distribuidor de hostelería, de 1.279 a 1.784 € sin IVA (octubre de 2026) | E12: Sí
A13: Plancha de acero a gas y comal | B13: 3000 | C13: =IFERROR(B13/$B$30,"") -> 0.019867526 | D13: Plancha lisa de acero para las carnes y comal para calentar la tortilla. Una plancha a gas de 40 cm ronda los 1.040 €; la de 80 cm a gas no tiene precio de referencia: estimación del kit, pide oferta | E13: Sí
A14: Freidora, fogón de carnitas, baño maría y mantenedor de tortillas | B14: 3700 | C14: =IFERROR(B14/$B$30,"") -> 0.024503282 | D14: Freidora para los totopos y los tacos dorados, fogón para las carnitas y los guisados, baño maría GN y mantenedor de tortillas. Estimación del kit | E14: Sí
A15: Campana extractora con motor y filtros | B15: 1500 | C15: =IFERROR(B15/$B$30,"") -> 0.009933763 | D15: Campana extractora de 2,5 m con motor y filtros de grasa sobre el trompo, la plancha, el comal y la freidora (una de 1,5-2 m ronda los 815 € sin IVA) | E15: Sí
A16: Frío: armarios, congelador y mesa refrigerada de salsas | B16: 4500 | C16: =IFERROR(B16/$B$30,"") -> 0.029801289 | D16: Armarios refrigerados (unos 900 € sin IVA el de 400 l), congelador y mesa refrigerada de granito para la barra de salsas y las guarniciones (de 1.180 a 1.950 € sin IVA) | E16: Sí
A17: Lavavajillas de capota, fregaderos, lavamanos, mesas inox y estanterías | B17: 5500 | C17: =IFERROR(B17/$B$30,"") -> 0.036423798 | D17: Lavavajillas, fregaderos, lavamanos de accionamiento no manual, mesas de acero inoxidable y estanterías | E17: Sí
A18: Utillaje y menaje: licuadora, molcajetes, sondas y prensa de tortillas | B18: 3500 | C18: =IFERROR(B18/$B$30,"") -> 0.02317878 | D18: Licuadora industrial para las salsas, molcajetes, termómetros sonda, básculas, recipientes GN, vajilla, cestas, vitroleros para las aguas frescas, una prensa de tortillas (unos 48 € con IVA) y la cartelería de alérgenos | E18: Sí
... A24: Stock inicial: carnes, chiles, tortillas, bebida y envases | B24: 3500 | C24: =IFERROR(B24/$B$30,"") -> 0.02317878 | D24: Carnes, chiles secos y producto mexicano importado (pídelo con su plazo de entrega: tarda semanas), tortillas, bebida, mezcal y envases para llevar | E24: Sí
A25: Fianza del alquiler | B25: =IFERROR(IF('0. Supuestos'!$B$24="","",'0. Supuestos'!$B$24*'0. Supuestos'!$B$25),"") -> 2900 | C25: =IFERROR(B25/$B$30,"") -> 0.019205275 | D25: =IFERROR(""&TEXT('0. Supuestos'!$B$25,"0")&" meses de renta, al tipo de la hoja de Supuestos. Es un activo recuperable al cerrar: ni se amortiza ni lleva IVA","") -> 2 meses de renta, al tipo de la hoja de Supuestos. Es un activo recuperable al cerrar: ni se amortiza ni lleva IVA | E25: No
A26: Alquiler de los meses previos a la apertura | B26: =IFERROR(IF('0. Supuestos'!$B$24="","",'0. Supuestos'!$B$24*'0. Supuestos'!$B$54),"") -> 2900 | C26: =IFERROR(B26/$B$30,"") -> 0.019205275 | D26: =IFERROR("Renta "&IF('0. Supuestos'!$B$54=1,"del mes","de los "&TEXT('0. Supuestos'!$B$54,"0")&" meses")&" de obra y licencias. NO se solapa con el P&L, que arranca el día de la apertura: los doce meses del P&L son los doce de explotación","") -> Renta de los 2 meses de obra y licencias. NO se solapa con el P&L, que arranca el día de la apertura: los doce meses del P&L son los doce de explotación | E26: Sí
A27: Imprevistos de obra y acondicionamiento | B27: =IFERROR(IF(COUNT(B7,B8,B9,B10,B11)=0,"",ROUND((B7+B8+B9+B10+B11)*'0. Supuestos'!$B$55,0)),"") -> 4850 | C27: =IFERROR(B27/$B$30,"") -> 0.032119167 | D27: =IFERROR("Al "&TEXT('0. Supuestos'!$B$55,"0%")&" de las partidas de OBRA Y ACONDICIONAMIENTO de este bloque (Proyecto técnico de actividad y de salida de humos, y dirección de obra, Obra y acondicionamiento del local, rótulo y fachada, Conducto de extracción exclusivo hasta cubierta, Instalación eléctrica, cuadro y boletín y Fontanería, separador de grasas, climatización e instalación de gas), no del bloque entero: el resto de partidas del bloque quedan fuera. Un banco no financia una reforma sin colchón: el porcentaje está en la hoja de Supuestos","") -> Al 10% de las partidas de OBRA Y ACONDICIONAMIENTO de este bloque (Proyecto técnico de actividad y de salida de humos, y dirección de obra, Obra y acondicionamiento del local, rótulo y fachada, Conducto de extracción exclusivo hasta cubierta, Instalación eléctrica, cuadro y boletín y Fontanería, separador de grasas, climatización e instalación de gas), no del bloque entero: el resto de partidas del bloque quedan fuera. Un banco no financia una reforma sin colchón: el porcentaje está en la hoja de Supuestos | E27: Sí
A28: FONDO DE MANIOBRA | B28: =IFERROR(IF(B29="","",B29),"") -> 44850.18 | C28: =IFERROR(B28/$B$30,"") -> 0.29702071
A29: Colchón operativo hasta alcanzar el equilibrio | B29: =IFERROR(IF('0. Supuestos'!$B$35*('PyG 3 Años'!$B$37-'PyG 3 Años'!$B$35)=0,"",'0. Supuestos'!$B$35*('PyG 3 Años'!$B$37-'PyG 3 Años'!$B$35)/12),"") -> 44850.18 | C29: =IFERROR(B29/$B$30,"") -> 0.29702071 | D29: =IFERROR("Cubre "&TEXT('0. Supuestos'!$B$35,"0")&IF('0. Supuestos'!$B$35=1," mes"," meses")&" de costes fijos DE CAJA del año 1 (los del P&L menos la amortización, que no se paga), que es el mínimo que exigen las Instrucciones de este libro","") -> Cubre 3 meses de costes fijos DE CAJA del año 1 (los del P&L menos la amortización, que no se paga), que es el mínimo que exigen las Instrucciones de este libro | E29: No
A30: INVERSIÓN TOTAL (suma de los bloques) | B30: =IFERROR(B6+B28,"") -> 151000.18 | D30: =IFERROR("Los porcentajes de la columna C se leen sobre esta cifra, que incluye el fondo de maniobra ("&TEXT(C28,"0%")&" del total). Para comparar el desglose con otro plan, usa la fila de CAPEX de abajo.","") -> Los porcentajes de la columna C se leen sobre esta cifra, que incluye el fondo de maniobra (30% del total). Para comparar el desglose con otro plan, usa la fila de CAPEX de abajo.
A31: CAPEX (inversión sin el fondo de maniobra) | B31: =IFERROR(B30-B28,"") -> 106150 | D31: Es lo que se compra: obra, equipamiento, lanzamiento y gastos de constitución. El colchón de caja no es inversión, es circulante
A32: IVA soportado sobre la inversión (recuperable) | B32: =IFERROR(IF(B30="","",SUMIF($E$7:$E$27,"Sí",$B$7:$B$27)*'0. Supuestos'!$B$41),"") -> 21052.5 | D32: =IFERROR("Al "&TEXT('0. Supuestos'!$B$41,"0%")&" sobre las partidas marcadas con «Sí» en la columna de IVA. Las tasas y licencias no están sujetas y los seguros están exentos (art. 20.Uno.16 LIVA). Las tasas y aranceles registrales no llevan IVA; los honorarios de notaría y gestoría sí (21 %, deducible). Se recupera con el modelo 303, pero hay que adelantarlo","") -> Al 21% sobre las partidas marcadas con «Sí» en la columna de IVA. Las tasas y licencias no están sujetas y los seguros están exentos (art. 20.Uno.16 LIVA). Las tasas y aranceles registrales no llevan IVA; los honorarios de notaría y gestoría sí (21 %, deducible). Se recupera con el modelo 303, pero hay que adelantarlo
A33: NECESIDAD TOTAL DE CAJA AL ARRANQUE | B33: =IFERROR(B30+B32,"") -> 172052.68 | D33: Es la cifra que tiene que cubrir la hoja de Financiación
A34: BASES DE AMORTIZACIÓN (no suman a la inversión)
A35: Obra, instalaciones y acondicionamiento | B35: =IFERROR(IF(B7="","",B7+B8+B9+B10+B11+B27),"") -> 53350 | D35: =IFERROR("Se amortiza en "&TEXT('0. Supuestos'!$B$44,"0")&" años","") -> Se amortiza en 10 años
A36: Maquinaria, mobiliario y equipos | B36: =IFERROR(IF(B12="","",B12+B13+B14+B15+B16+B17+B18+B19+B20+B21),"") -> 36000 | D36: =IFERROR("Se amortiza en "&TEXT('0. Supuestos'!$B$45,"0")&" años","") -> Se amortiza en 10 años
A37: Amortización anual del inmovilizado | B37: =IFERROR(B35/MAX(1,'0. Supuestos'!$B$44)+B36/MAX(1,'0. Supuestos'!$B$45),"") -> 8935 | D37: =IFERROR("No se amortizan, por no ser inmovilizado, Constitución de la SL, licencia, tasas, registro sanitario y APPCC, Marca, web, fotos y lanzamiento, Stock inicial: carnes, chiles, tortillas, bebida y envases, Fianza del alquiler, Alquiler de los meses previos a la apertura ni Colchón operativo hasta alcanzar el equilibrio. Suman "&TEXT(B30-B35-B36,"0")&" € de los "&TEXT(B30,"0")&" € de inversión.","") -> No se amortizan, por no ser inmovilizado, Constitución de la SL, licencia, tasas, registro sanitario y APPCC, Marca, web, fotos y lanzamiento, Stock inicial: carnes, chiles, tortillas, bebida y envases, Fianza del alquiler, Alquiler de los meses previos a la apertura ni Colchón operativo hasta alcanzar el equilibrio. Suman 61650 € de los 151000 € de inversión.

Sheet PyG 3 Años
A1: CUENTA DE RESULTADOS PREVISIONAL — 3 AÑOS
A2: Escenario realista — taquería con trompo, barra de salsas y para llevar
A4: Concepto | B4: Año 1 | C4: Año 2 | D4: Año 3 | E4: % s/ventas (año 1) | F4: Notas | G4: Tipo de IVA de la línea (%) | H4: Bebida para llevar o a domicilio al 21 % (%)
A5: INGRESOS
A6: Comensales/día (media) | B6: =IFERROR(IF('0. Supuestos'!$B$4="","",'0. Supuestos'!$B$4),"") -> 77 | C6: =IFERROR(B6*(1+'0. Supuestos'!$B$7),"") -> 81.62 | D6: =IFERROR(C6*(1+'0. Supuestos'!$B$8),"") -> 84.8848 | F6: El crecimiento de los años 2 y 3 está en la hoja de Supuestos
A7: Ticket medio sin IVA | B7: =IFERROR(IF('0. Supuestos'!$B$5="","",'0. Supuestos'!$B$5),"") -> 15.5 | C7: =IFERROR(IF(B7="","",B7),"") -> 15.5 | D7: =IFERROR(IF(C7="","",C7),"") -> 15.5 | F7: Constante en euros del año 1: una subida de precios es una decisión aparte
A8: Días de apertura al año | B8: =IFERROR(IF('0. Supuestos'!$B$6="","",'0. Supuestos'!$B$6),"") -> 300 | C8: =IFERROR(IF(B8="","",B8),"") -> 300 | D8: =IFERROR(IF(C8="","",C8),"") -> 300
A9: INGRESOS TOTALES (sin IVA) | B9: =IFERROR(IF(B6*B7*B8=0,"",B6*B7*B8),"") -> 358050 | C9: =IFERROR(IF(C6*C7*C8=0,"",C6*C7*C8),"") -> 379533 | D9: =IFERROR(IF(D6*D7*D8=0,"",D6*D7*D8),"") -> 394714.32 | E9: =IFERROR(IF(B9="","",1),"") -> 1
A10: Ventas de taquería y cocina (sala, para llevar y a domicilio) | B10: =IFERROR(IF(B9="","",B9*$E$10),"") -> 286440 | C10: =IFERROR(IF(C9="","",C9*$E$10),"") -> 303626.4 | D10: =IFERROR(IF(D9="","",D9*$E$10),"") -> 315771.46 | E10: =IFERROR(IF('0. Supuestos'!$B$11="","",'0. Supuestos'!$B$11),"") -> 0.8 | F10: Tacos, gringas y quesadillas, entrantes y postres: en sala unos 74 % de las ventas, para llevar unos 14 % y por plataforma un 12 %. Todo al 10 % de IVA, se coma en la mesa o salga del local (art. 91.Uno.1.1.º y 2.2.º de la Ley 37/1992) | G10: =IFERROR(IF(B9="","",'0. Supuestos'!$B$39),"") -> 0.1
A11: Ventas de bebida (aguas frescas, cerveza, mezcal y tequila, refrescos y agua) | B11: =IFERROR(IF(B9="","",B9*$E$11),"") -> 71610 | C11: =IFERROR(IF(C9="","",C9*$E$11),"") -> 75906.6 | D11: =IFERROR(IF(D9="","",D9*$E$11),"") -> 78942.864 | E11: =IFERROR(IF('0. Supuestos'!$B$12="","",'0. Supuestos'!$B$12),"") -> 0.2 | F11: Bebida de sala y la que sale con los pedidos · La columna H es la parte de la bebida que sale del local y va al 21 %: el alcohol y las aguas frescas y los refrescos con azúcares o edulcorantes añadidos (art. 91.Uno.1.1.º a y b de la Ley 37/1992); el agua y lo que no lleve azúcares ni edulcorantes añadidos, y toda la bebida en sala, al 10 %. Un 7,5 % = un 1,5 % de las ventas | G11: =IFERROR(IF(B9="","",H11*0.21+(1-H11)*'0. Supuestos'!$B$39),"") -> 0.10825 | H11: 0.075
A12: COSTES VARIABLES
A13: Coste de mercancía — comida | B13: =IFERROR(IF(B9="","",B9*'0. Supuestos'!$B$11*'0. Supuestos'!$B$13),"") -> 77338.8 | C13: =IFERROR(IF(C9="","",C9*'0. Supuestos'!$B$11*'0. Supuestos'!$B$13),"") -> 81979.128 | D13: =IFERROR(IF(D9="","",D9*'0. Supuestos'!$B$11*'0. Supuestos'!$B$13),"") -> 85258.293 | E13: =IFERROR(B13/$B$9,"") -> 0.216 | F13: =IFERROR("Al "&TEXT('0. Supuestos'!$B$13,"0%")&" de las ventas de COMIDA, no del total: la bebida tiene su propia línea · Carne, tortilla, chiles y especias al 10 %; verdura, fruta, aguacate y quesos al 4 % (art. 91.Dos.1.1.º de la Ley 37/1992). Ajústalo a tus facturas","") -> Al 27% de las ventas de COMIDA, no del total: la bebida tiene su propia línea · Carne, tortilla, chiles y especias al 10 %; verdura, fruta, aguacate y quesos al 4 % (art. 91.Dos.1.1.º de la Ley 37/1992). Ajústalo a tus facturas | G13: 0.085
A14: Coste de mercancía — bebida | B14: =IFERROR(IF(B9="","",B9*'0. Supuestos'!$B$12*'0. Supuestos'!$B$14),"") -> 18618.6 | C14: =IFERROR(IF(C9="","",C9*'0. Supuestos'!$B$12*'0. Supuestos'!$B$14),"") -> 19735.716 | D14: =IFERROR(IF(D9="","",D9*'0. Supuestos'!$B$12*'0. Supuestos'!$B$14),"") -> 20525.145 | E14: =IFERROR(B14/$B$9,"") -> 0.052 | F14: =IFERROR("Al "&TEXT('0. Supuestos'!$B$14,"0%")&" de las ventas de BEBIDA","") -> Al 26% de las ventas de BEBIDA | G14: =IFERROR(IF(B9="","",('0. Supuestos'!$B$62*'0. Supuestos'!$B$40+(1-'0. Supuestos'!$B$62)*'0. Supuestos'!$B$39)),"") -> 0.1825
A15: Consumibles y envases | B15: =IFERROR(IF(B9="","",B9*'0. Supuestos'!$B$15),"") -> 12531.75 | C15: =IFERROR(IF(C9="","",C9*'0. Supuestos'!$B$15),"") -> 13283.655 | D15: =IFERROR(IF(D9="","",D9*'0. Supuestos'!$B$15),"") -> 13815.001 | E15: =IFERROR(B15/$B$9,"") -> 0.035 | G15: =IFERROR(IF(B9="","",'0. Supuestos'!$B$41),"") -> 0.21
A16: Comisiones de delivery | B16: =IFERROR(IF(B9="","",B9*'0. Supuestos'!$B$16*'0. Supuestos'!$B$17),"") -> 12889.8 | C16: =IFERROR(IF(C9="","",C9*'0. Supuestos'!$B$16*'0. Supuestos'!$B$17),"") -> 13663.188 | D16: =IFERROR(IF(D9="","",D9*'0. Supuestos'!$B$16*'0. Supuestos'!$B$17),"") -> 14209.716 | E16: =IFERROR(B16/$B$9,"") -> 0.036 | F16: Sobre las ventas DEL CANAL. Con 0 % de delivery en Supuestos, esta línea vale cero | G16: =IFERROR(IF(B9="","",'0. Supuestos'!$B$41),"") -> 0.21
A17: Comisiones de los medios de pago | B17: =IFERROR(IF(B9="","",B9*'0. Supuestos'!$B$18),"") -> 2864.4 | C17: =IFERROR(IF(C9="","",C9*'0. Supuestos'!$B$18),"") -> 3036.264 | D17: =IFERROR(IF(D9="","",D9*'0. Supuestos'!$B$18),"") -> 3157.7146 | E17: =IFERROR(B17/$B$9,"") -> 0.008 | F17: Las comisiones de los medios de pago están EXENTAS de IVA (art. 20.Uno.18 LIVA): no se deduce nada por ellas | G17: 0
A18: Varios e imprevistos | B18: =IFERROR(IF(B9="","",B9*'0. Supuestos'!$B$28),"") -> 7161 | C18: =IFERROR(IF(C9="","",C9*'0. Supuestos'!$B$28),"") -> 7590.66 | D18: =IFERROR(IF(D9="","",D9*'0. Supuestos'!$B$28),"") -> 7894.2864 | E18: =IFERROR(B18/$B$9,"") -> 0.02 | F18: =IFERROR("Al "&TEXT('0. Supuestos'!$B$28,"0%")&" de las ventas. Es un coste VARIABLE: sube y baja con la facturación, así que no puede vivir en los costes fijos","") -> Al 2% de las ventas. Es un coste VARIABLE: sube y baja con la facturación, así que no puede vivir en los costes fijos | G18: =IFERROR(IF(B9="","",'0. Supuestos'!$B$41),"") -> 0.21
A19: TOTAL COSTES VARIABLES | B19: =IFERROR(IF(B9="","",SUM(B13:B18)),"") -> 131404.35 | C19: =IFERROR(IF(C9="","",SUM(C13:C18)),"") -> 139288.61 | D19: =IFERROR(IF(D9="","",SUM(D13:D18)),"") -> 144860.16 | E19: =IFERROR(B19/$B$9,"") -> 0.367
A20: MARGEN BRUTO | B20: =IFERROR(IF(B9="","",B9-B19),"") -> 226645.65 | C20: =IFERROR(IF(C9="","",C9-C19),"") -> 240244.39 | D20: =IFERROR(IF(D9="","",D9-D19),"") -> 249854.16 | E20: =IFERROR(B20/$B$9,"") -> 0.633
A21: COSTES FIJOS
A22: Alquiler del local | B22: =IFERROR(IF(B9="","",'0. Supuestos'!$B$24*12),"") -> 17400 | C22: =IFERROR(IF(C9="","",B22*(1+'0. Supuestos'!$B$48)),"") -> 17400 | D22: =IFERROR(IF(D9="","",C22*(1+'0. Supuestos'!$B$48)),"") -> 17400 | E22: =IFERROR(B22/$B$9,"") -> 0.048596565 | F22: El importe mensual está en la hoja de Supuestos; aquí se multiplica por doce. Los dos meses de renta previos a la apertura están en la hoja de Inversión y NO se cuentan dos veces | G22: =IFERROR(IF(B9="","",'0. Supuestos'!$B$41),"") -> 0.21
A23: Personal (nóminas + Seguridad Social) | B23: =IFERROR(IF(B9="","",'Personal'!$G$12),"") -> 129520.72 | C23: =IFERROR(IF(C9="","",'Personal'!$B$16),"") -> 135520.72 | D23: =IFERROR(IF(D9="","",'Personal'!$B$17),"") -> 141520.72 | E23: =IFERROR(B23/$B$9,"") -> 0.3617392 | F23: Sale de la hoja de Personal: es el MISMO número, no una estimación aparte. Los años 2 y 3 suman las INCORPORACIONES declaradas en esa hoja, no un porcentaje de volumen | G23: 0
A24: Suministros (luz, agua, gas) | B24: =IFERROR(IF(B9="","",'0. Supuestos'!$B$26*12),"") -> 10200 | C24: =IFERROR(IF(C9="","",B24*(1+'0. Supuestos'!$B$48)),"") -> 10200 | D24: =IFERROR(IF(D9="","",C24*(1+'0. Supuestos'!$B$48)),"") -> 10200 | E24: =IFERROR(B24/$B$9,"") -> 0.028487641 | F24: Luz y gas van al 21 %; la factura del agua, al 10 %. El libro aplica a toda esta partida el tipo de la columna de al lado (21 %): si el agua pesa mucho en tu local, sepárala en su línea | G24: =IFERROR(IF(B9="","",'0. Supuestos'!$B$41),"") -> 0.21
A25: Seguros (RC + multirriesgo) | B25: =IFERROR(IF(B9="","",'0. Supuestos'!$B$27),"") -> 1400 | C25: =IFERROR(IF(C9="","",B25*(1+'0. Supuestos'!$B$48)),"") -> 1400 | D25: =IFERROR(IF(D9="","",C25*(1+'0. Supuestos'!$B$48)),"") -> 1400 | E25: =IFERROR(B25/$B$9,"") -> 0.0039100684 | F25: Las operaciones de seguro están EXENTAS de IVA (art. 20.Uno.16 LIVA): la prima no lleva IVA deducible | G25: 0
A26: Gestoría laboral, fiscal y contable | B26: 2400 | C26: =IFERROR(IF(C9="","",B26*(1+'0. Supuestos'!$B$48)),"") -> 2400 | D26: =IFERROR(IF(D9="","",C26*(1+'0. Supuestos'!$B$48)),"") -> 2400 | E26: =IFERROR(B26/$B$9,"") -> 0.0067029744 | F26: Contabilidad, impuestos de la SL, nóminas y contratos de la plantilla | G26: =IFERROR(IF(B9="","",'0. Supuestos'!$B$41),"") -> 0.21
A27: Mantenimiento de la campana extractora, el gas y el frío | B27: 1800 | C27: =IFERROR(IF(C9="","",B27*(1+'0. Supuestos'!$B$48)),"") -> 1800 | D27: =IFERROR(IF(D9="","",C27*(1+'0. Supuestos'!$B$48)),"") -> 1800 | E27: =IFERROR(B27/$B$9,"") -> 0.0050272308 | F27: Limpieza de la campana extractora y del conducto al menos una vez al año (Madrid lo exige en su Ordenanza 4/2021, art. 23; mira la de tu ayuntamiento), revisión del gas y del trompo y el frigorista | G27: =IFERROR(IF(B9="","",'0. Supuestos'!$B$41),"") -> 0.21
A28: Marketing y publicidad | B28: 3500 | C28: =IFERROR(IF(C9="","",B28*(1+'0. Supuestos'!$B$48)),"") -> 3500 | D28: =IFERROR(IF(D9="","",C28*(1+'0. Supuestos'!$B$48)),"") -> 3500 | E28: =IFERROR(B28/$B$9,"") -> 0.0097751711 | F28: Ficha de Google Business, redes sociales, fotos y las fechas mexicanas (la Independencia en septiembre, el Día de Muertos en noviembre); la campaña de apertura va en la inversión | G28: =IFERROR(IF(B9="","",'0. Supuestos'!$B$41),"") -> 0.21
A29: Software, TPV, teléfono e internet | B29: 1500 | C29: =IFERROR(IF(C9="","",B29*(1+'0. Supuestos'!$B$48)),"") -> 1500 | D29: =IFERROR(IF(D9="","",C29*(1+'0. Supuestos'!$B$48)),"") -> 1500 | E29: =IFERROR(B29/$B$9,"") -> 0.004189359 | F29: Cuota del TPV con Veri*factu, la tablet de las plataformas, teléfono e internet | G29: =IFERROR(IF(B9="","",'0. Supuestos'!$B$41),"") -> 0.21
A30: Limpieza, lavandería, EPI y análisis de autocontrol | B30: 1200 | C30: =IFERROR(IF(C9="","",B30*(1+'0. Supuestos'!$B$48)),"") -> 1200 | D30: =IFERROR(IF(D9="","",C30*(1+'0. Supuestos'!$B$48)),"") -> 1200 | E30: =IFERROR(B30/$B$9,"") -> 0.0033514872 | F30: Productos de limpieza, lavado de uniformes y paños, guantes y los análisis de autocontrol que fije tu APPCC | G30: =IFERROR(IF(B9="","",'0. Supuestos'!$B$41),"") -> 0.21
A31: Tasa de terraza y gestión de residuos (pon las de tu ayuntamiento) | B31: 1700 | C31: =IFERROR(IF(C9="","",B31*(1+'0. Supuestos'!$B$48)),"") -> 1700 | D31: =IFERROR(IF(D9="","",C31*(1+'0. Supuestos'!$B$48)),"") -> 1700 | E31: =IFERROR(B31/$B$9,"") -> 0.0047479402 | F31: La ocupación de la vía pública con 4 mesas de abril a octubre (unos 1.200 € de ejemplo: cada ayuntamiento tiene su ordenanza fiscal y este plan no ha leído ninguna) y la tasa de basuras, el cartón y el aceite y la grasa usados con gestor autorizado (unos 500 €). Pon las de tu ayuntamiento | G31: =IFERROR(IF(B9="","",'0. Supuestos'!$B$41),"") -> 0.21
A32: Desinsectación, desratización y desinfección (DDD) | B32: 450 | C32: =IFERROR(IF(C9="","",B32*(1+'0. Supuestos'!$B$48)),"") -> 450 | D32: =IFERROR(IF(D9="","",C32*(1+'0. Supuestos'!$B$48)),"") -> 450 | E32: =IFERROR(B32/$B$9,"") -> 0.0012568077 | F32: Contrato con una empresa inscrita en el ROESB: forma parte de los prerrequisitos del APPCC | G32: =IFERROR(IF(B9="","",'0. Supuestos'!$B$41),"") -> 0.21
A33: Derechos de autor por música ambiental (SGAE y AGEDI-AIE) | B33: 500 | C33: =IFERROR(IF(C9="","",B33*(1+'0. Supuestos'!$B$48)),"") -> 500 | D33: =IFERROR(IF(D9="","",C33*(1+'0. Supuestos'!$B$48)),"") -> 500 | E33: =IFERROR(B33/$B$9,"") -> 0.001396453 | F33: SGAE y AGEDI-AIE son dos licencias distintas; el importe depende de los metros y del aforo de tu sala | G33: =IFERROR(IF(B9="","",'0. Supuestos'!$B$41),"") -> 0.21
A34: Prevención de riesgos laborales, vigilancia de la salud y formación | B34: 750 | C34: =IFERROR(IF(C9="","",B34*(1+'0. Supuestos'!$B$48)),"") -> 750 | D34: =IFERROR(IF(D9="","",C34*(1+'0. Supuestos'!$B$48)),"") -> 750 | E34: =IFERROR(B34/$B$9,"") -> 0.0020946795 | F34: El plan de prevención es obligatorio (Ley 31/1995): cortes en el trompo, quemaduras de la plancha y la freidora, gas y calor; los reconocimientos médicos de la plantilla y la formación en higiene y alérgenos | G34: =IFERROR(IF(B9="","",'0. Supuestos'!$B$41),"") -> 0.21
A35: Amortización del inmovilizado | B35: =IFERROR(IF(B9="","",'Inversión Inicial'!$B$37),"") -> 8935 | C35: =IFERROR(IF(C9="","",B35),"") -> 8935 | D35: =IFERROR(IF(D9="","",B35),"") -> 8935 | E35: =IFERROR(B35/$B$9,"") -> 0.024954615 | F35: Sale de las bases de amortización de la hoja de Inversión: sólo inmovilizado real. NO sube con el IPC: es una cuota sobre el coste HISTÓRICO del inmovilizado | G35: 0
A36: Gastos financieros (intereses del préstamo) | B36: =IFERROR(IF(B9="","",'Financiación'!$B$44),"") -> 7080 | C36: =IFERROR(IF(C9="","",'Financiación'!$B$46),"") -> 7080 | D36: =IFERROR(IF(D9="","",'Financiación'!$B$48),"") -> 6064.9926 | E36: =IFERROR(B36/$B$9,"") -> 0.019773775 | F36: Sólo los INTERESES son gasto. La devolución del principal va en la hoja de Tesorería | G36: 0
A37: TOTAL COSTES FIJOS | B37: =IFERROR(IF(B9="","",SUM(B22:B36)),"") -> 188335.72 | C37: =IFERROR(IF(C9="","",SUM(C22:C36)),"") -> 194335.72 | D37: =IFERROR(IF(D9="","",SUM(D22:D36)),"") -> 199320.71 | E37: =IFERROR(B37/$B$9,"") -> 0.52600397
A38: IVA soportado de los costes variables | B38: =IFERROR(IF(B9="","",SUMPRODUCT(B13:B18,G13:G18)),"") -> 16814.028 | C38: =IFERROR(IF(C9="","",SUMPRODUCT(C13:C18,G13:G18)),"") -> 17822.87 | D38: =IFERROR(IF(D9="","",SUMPRODUCT(D13:D18,G13:G18)),"") -> 18535.784 | F38: Cada línea a SU tipo, leído de la columna de al lado. Es lo que la hoja de Tesorería paga de más a los proveedores y luego se deduce
A39: IVA soportado de los costes fijos | B39: =IFERROR(IF(B9="","",SUMPRODUCT(B22:B36,G22:G36)),"") -> 8694 | C39: =IFERROR(IF(C9="","",SUMPRODUCT(C22:C36,G22:G36)),"") -> 8694 | D39: =IFERROR(IF(D9="","",SUMPRODUCT(D22:D36,G22:G36)),"") -> 8694
A40: RESULTADO ANTES DE IMPUESTOS | B40: =IFERROR(IF(B9="","",B20-B37),"") -> 38309.93 | C40: =IFERROR(IF(C9="","",C20-C37),"") -> 45908.669 | D40: =IFERROR(IF(D9="","",D20-D37),"") -> 50533.452 | E40: =IFERROR(B40/$B$9,"") -> 0.10699603
A41: Bases negativas pendientes al inicio | B41: =IFERROR(IF(B9="","",'0. Supuestos'!$B$42),"") -> 0 | C41: =IFERROR(IF(C9="","",B46),"") -> 0 | D41: =IFERROR(IF(D9="","",C46),"") -> 0 | F41: Art. 26 LIS: las pérdidas de un ejercicio se compensan con los beneficios de los siguientes
...

Sheet Punto Equilibrio
A1: ANÁLISIS DE PUNTO DE EQUILIBRIO
A2: Punto de equilibrio mensual y diario — taquería con trompo
A4: Variable | B4: Año 1 | C4: Año 2 | D4: Año 3 | E4: Notas
A5: DATOS BASE POR AÑO
A6: Costes fijos anuales | B6: =IFERROR(IF('PyG 3 Años'!$B$9="","",'PyG 3 Años'!$B$37),"") -> 188335.72 | C6: =IFERROR(IF('PyG 3 Años'!$C$9="","",'PyG 3 Años'!$C$37),"") -> 194335.72 | D6: =IFERROR(IF('PyG 3 Años'!$D$9="","",'PyG 3 Años'!$D$37),"") -> 199320.71 | E6: Los MISMOS costes fijos del P&L. Cada año tiene los suyos: por eso el umbral no puede ser uno solo para los tres
A7: Costes fijos mensuales | B7: =IFERROR(IF('PyG 3 Años'!$B$9="","",B6/12),"") -> 15694.643 | C7: =IFERROR(IF('PyG 3 Años'!$C$9="","",C6/12),"") -> 16194.643 | D7: =IFERROR(IF('PyG 3 Años'!$D$9="","",D6/12),"") -> 16610.059
A8: Ticket medio sin IVA | B8: =IFERROR(IF('PyG 3 Años'!$B$9="","",'PyG 3 Años'!$B$7),"") -> 15.5 | C8: =IFERROR(IF('PyG 3 Años'!$C$9="","",'PyG 3 Años'!$C$7),"") -> 15.5 | D8: =IFERROR(IF('PyG 3 Años'!$D$9="","",'PyG 3 Años'!$D$7),"") -> 15.5
A9: Coste variable por comensal | B9: =IFERROR(IF('PyG 3 Años'!$B$9="","",'PyG 3 Años'!$B$19/('PyG 3 Años'!$B$6*'PyG 3 Años'!$B$8)),"") -> 5.6885 | C9: =IFERROR(IF('PyG 3 Años'!$C$9="","",'PyG 3 Años'!$C$19/('PyG 3 Años'!$C$6*'PyG 3 Años'!$C$8)),"") -> 5.6885 | D9: =IFERROR(IF('PyG 3 Años'!$D$9="","",'PyG 3 Años'!$D$19/('PyG 3 Años'!$D$6*'PyG 3 Años'!$D$8)),"") -> 5.6885 | E9: Sale del total de costes variables del P&L, no de una estimación aparte. Incluye los varios e imprevistos, que son un porcentaje de las ventas
A10: Margen de contribución por comensal | B10: =IFERROR(IF('PyG 3 Años'!$B$9="","",B8-B9),"") -> 9.8115 | C10: =IFERROR(IF('PyG 3 Años'!$C$9="","",C8-C9),"") -> 9.8115 | D10: =IFERROR(IF('PyG 3 Años'!$D$9="","",D8-D9),"") -> 9.8115 | E10: Ticket menos coste variable unitario
A11: Días de apertura al año | B11: =IFERROR(IF('PyG 3 Años'!$B$9="","",'PyG 3 Años'!$B$8),"") -> 300 | C11: =IFERROR(IF('PyG 3 Años'!$C$9="","",'PyG 3 Años'!$C$8),"") -> 300 | D11: =IFERROR(IF('PyG 3 Años'!$D$9="","",'PyG 3 Años'!$D$8),"") -> 300 | E11: El mismo calendario que el P&L y que los escenarios
A12: Devolución de principal del año (cuota) | B12: =IFERROR(IF('PyG 3 Años'!$B$9="","",'Financiación'!$B$45),"") -> 0 | C12: =IFERROR(IF('PyG 3 Años'!$C$9="","",'Financiación'!$B$47),"") -> 16916.79 | D12: =IFERROR(IF('PyG 3 Años'!$D$9="","",'Financiación'!$B$49),"") -> 17931.798 | E12: El principal NO es gasto del P&L, pero sale de la caja. Sin él, el umbral de equilibrio se publica por debajo del real
A13: PUNTO DE EQUILIBRIO CONTABLE (incluye amortización)
A14: Comensales necesarios al año | B14: =IFERROR(IF('PyG 3 Años'!$B$9="","",IF(B10<=0,"",B6/B10)),"") -> 19195.405 | C14: =IFERROR(IF('PyG 3 Años'!$C$9="","",IF(C10<=0,"",C6/C10)),"") -> 19806.933 | D14: =IFERROR(IF('PyG 3 Años'!$D$9="","",IF(D10<=0,"",D6/D10)),"") -> 20315.009
A15: Comensales necesarios al día | B15: =IFERROR(IF('PyG 3 Años'!$B$9="","",B14/B11),"") -> 63.984685 | C15: =IFERROR(IF('PyG 3 Años'!$C$9="","",C14/C11),"") -> 66.023109 | D15: =IFERROR(IF('PyG 3 Años'!$D$9="","",D14/D11),"") -> 67.716697
A16: Ingresos necesarios al año | B16: =IFERROR(IF('PyG 3 Años'!$B$9="","",B14*B8),"") -> 297528.78 | C16: =IFERROR(IF('PyG 3 Años'!$C$9="","",C14*C8),"") -> 307007.46 | D16: =IFERROR(IF('PyG 3 Años'!$D$9="","",D14*D8),"") -> 314882.64
A17: PUNTO DE EQUILIBRIO DE CAJA (incluye la cuota del préstamo)
A18: Costes fijos de caja + principal del año | B18: =IFERROR(IF('PyG 3 Años'!$B$9="","",B6-'PyG 3 Años'!$B$35+B12),"") -> 179400.72 | C18: =IFERROR(IF('PyG 3 Años'!$C$9="","",C6-'PyG 3 Años'!$C$35+C12),"") -> 202317.51 | D18: =IFERROR(IF('PyG 3 Años'!$D$9="","",D6-'PyG 3 Años'!$D$35+D12),"") -> 208317.51 | E18: Los fijos del P&L sin la amortización (que no se paga) y CON la devolución de principal (que sí). Es el umbral que decide si la caja aguanta
A19: Comensales necesarios al año (caja) | B19: =IFERROR(IF('PyG 3 Años'!$B$9="","",IF(B10<=0,"",B18/B10)),"") -> 18284.739 | C19: =IFERROR(IF('PyG 3 Años'!$C$9="","",IF(C10<=0,"",C18/C10)),"") -> 20620.446 | D19: =IFERROR(IF('PyG 3 Años'!$D$9="","",IF(D10<=0,"",D18/D10)),"") -> 21231.974
A20: Comensales necesarios al día (caja) | B20: =IFERROR(IF('PyG 3 Años'!$B$9="","",B19/B11),"") -> 60.949131 | C20: =IFERROR(IF('PyG 3 Años'!$C$9="","",C19/C11),"") -> 68.734821 | D20: =IFERROR(IF('PyG 3 Años'!$D$9="","",D19/D11),"") -> 70.773246
A21: Ingresos necesarios al año (caja) | B21: =IFERROR(IF('PyG 3 Años'!$B$9="","",B19*B8),"") -> 283413.46 | C21: =IFERROR(IF('PyG 3 Años'!$C$9="","",C19*C8),"") -> 319616.92 | D21: =IFERROR(IF('PyG 3 Años'!$D$9="","",D19*D8),"") -> 329095.59
A22: CONTRASTE CON EL PLAN
A23: Comensales/día previstos en el plan | B23: =IFERROR(IF('PyG 3 Años'!$B$9="","",'PyG 3 Años'!$B$6),"") -> 77 | C23: =IFERROR(IF('PyG 3 Años'!$C$9="","",'PyG 3 Años'!$C$6),"") -> 81.62 | D23: =IFERROR(IF('PyG 3 Años'!$D$9="","",'PyG 3 Años'!$D$6),"") -> 84.8848
A24: Holgura sobre el equilibrio de CAJA (%) | B24: =IFERROR(IF('PyG 3 Años'!$B$9="","",B23/B20-1),"") -> 0.26334861 | C24: =IFERROR(IF('PyG 3 Años'!$C$9="","",C23/C20-1),"") -> 0.18746217 | D24: =IFERROR(IF('PyG 3 Años'!$D$9="","",D23/D20-1),"") -> 0.19939109 | E24: Cuánto puedes caer antes de no poder pagar los costes fijos y la cuota. El mínimo exigible está en la hoja de Supuestos
A25: Rotaciones al día que da el local como máximo | B25: 3 | E25: Servicios completos por plaza y día que puedes hacer con comidas, cenas y un segundo turno de cena el sábado (estancias de 35-45 minutos). Es el techo físico del local, no un objetivo
A26: Rotaciones al día que exige el equilibrio de caja | B26: =IFERROR(IF('PyG 3 Años'!$B$9="","",B20/'0. Supuestos'!$B$51),"") -> 1.9046603 | C26: =IFERROR(IF('PyG 3 Años'!$C$9="","",C20/'0. Supuestos'!$B$51),"") -> 2.1479632 | D26: =IFERROR(IF('PyG 3 Años'!$D$9="","",D20/'0. Supuestos'!$B$51),"") -> 2.2116639 | E26: Comensales de equilibrio entre las plazas que declara la hoja de Supuestos. Por encima del techo de arriba, el punto de equilibrio está fuera del alcance del local
A27: INTERPRETACIÓN
A28: =IFERROR("Con el ticket medio sin IVA de la fila de arriba necesitas "&TEXT(ROUNDUP(B15,0),"0")&" comensales al día durante los "&TEXT(B11,"0")&" días que abres para no perder dinero (equilibrio contable, con la amortización dentro), y "&TEXT(ROUNDUP(B20,0),"0")&" para que la caja aguante (equilibrio de caja: sin la amortización, que no se paga, y con la cuota del préstamo del año"&IF(B12=0,"; este año sólo intereses, porque el préstamo está en carencia","")&"). En las filas «Ingresos necesarios al año» tienes esas mismas cifras en euros.","") -> Con el ticket medio sin IVA de la fila de arriba necesitas 64 comensales al día durante los 300 días que abres para no perder dinero (equilibrio contable, con la amortización dentro), y 61 para que la caja aguante (equilibrio de caja: sin la amortización, que no se paga, y con la cuota del préstamo del año; este año sólo intereses, porque el préstamo está en carencia). En las filas «Ingresos necesarios al año» tienes esas mismas cifras en euros.
A30: SENSIBILIDAD DEL PUNTO DE EQUILIBRIO
A31: Comensales/día necesarios para cubrir costes según el ticket medio (columnas) y el coste variable por comensal (filas). En verde, los que están por debajo de los comensales que prevé el plan.
A33: Comensales/día necesarios: ticket medio sin IVA (columnas) × coste variable por comensal (filas) | B33: =IFERROR($B$8-2,"") -> 13.5 | C33: =IFERROR(IF($B$8="","",$B$8),"") -> 15.5 | D33: =IFERROR($B$8+2,"") -> 17.5 | E33: =IFERROR($B$8+4,"") -> 19.5
A34: =IFERROR($B$9*0.85,"") -> 4.835225 | B34: =IFERROR(IF($B$33-$A34<=0,"",$B$6/($B$33-$A34)/$B$11),"") -> 72.45263 | C34: =IFERROR(IF($C$33-$A34<=0,"",$B$6/($C$33-$A34)/$B$11),"") -> 58.865352 | D34: =IFERROR(IF($D$33-$A34<=0,"",$B$6/($D$33-$A34)/$B$11),"") -> 49.569434 | E34: =IFERROR(IF($E$33-$A34<=0,"",$B$6/($E$33-$A34)/$B$11),"") -> 42.809094
A35: =IFERROR($B$9*0.925,"") -> 5.2618625 | B35: =IFERROR(IF($B$33-$A35<=0,"",$B$6/($B$33-$A35)/$B$11),"") -> 76.204814 | C35: =IFERROR(IF($C$33-$A35<=0,"",$B$6/($C$33-$A35)/$B$11),"") -> 61.318353 | D35: =IFERROR(IF($D$33-$A35<=0,"",$B$6/($D$33-$A35)/$B$11),"") -> 51.29749 | E35: =IFERROR(IF($E$33-$A35<=0,"",$B$6/($E$33-$A35)/$B$11),"") -> 44.091844
A36: =IFERROR($B$9*1.0,"") -> 5.6885 | B36: =IFERROR(IF($B$33-$A36<=0,"",$B$6/($B$33-$A36)/$B$11),"") -> 80.366861 | C36: =IFERROR(IF($C$33-$A36<=0,"",$B$6/($C$33-$A36)/$B$11),"") -> 63.984685 | D36: =IFERROR(IF($D$33-$A36<=0,"",$B$6/($D$33-$A36)/$B$11),"") -> 53.150382 | E36: =IFERROR(IF($E$33-$A36<=0,"",$B$6/($E$33-$A36)/$B$11),"") -> 45.453842
A37: =IFERROR($B$9*1.075,"") -> 6.1151375 | B37: =IFERROR(IF($B$33-$A37<=0,"",$B$6/($B$33-$A37)/$B$11),"") -> 85.009807 | C37: =IFERROR(IF($C$33-$A37<=0,"",$B$6/($C$33-$A37)/$B$11),"") -> 66.89344 | D37: =IFERROR(IF($D$33-$A37<=0,"",$B$6/($D$33-$A37)/$B$11),"") -> 55.142145 | E37: =IFERROR(IF($E$33-$A37<=0,"",$B$6/($E$33-$A37)/$B$11),"") -> 46.902666
A38: =IFERROR($B$9*1.15,"") -> 6.541775 | B38: =IFERROR(IF($B$33-$A38<=0,"",$B$6/($B$33-$A38)/$B$11),"") -> 90.222109 | C38: =IFERROR(IF($C$33-$A38<=0,"",$B$6/($C$33-$A38)/$B$11),"") -> 70.079255 | D38: =IFERROR(IF($D$33-$A38<=0,"",$B$6/($D$33-$A38)/$B$11),"") -> 57.288998 | E38: =IFERROR(IF($E$33-$A38<=0,"",$B$6/($E$33-$A38)/$B$11),"") -> 48.446892

Sheet Escenarios
A1: ANÁLISIS DE ESCENARIOS
A2: Pesimista / Realista / Optimista — Año 1
A4: Métrica | B4: Pesimista | C4: Realista | D4: Optimista | E4: Notas
A5: Comensales/día | B5: 65 | C5: =IFERROR(IF('PyG 3 Años'!$B$6="","",'PyG 3 Años'!$B$6),"") -> 77 | D5: 88
A6: Ticket medio sin IVA | B6: 14.75 | C6: =IFERROR(IF('PyG 3 Años'!$B$7="","",'PyG 3 Años'!$B$7),"") -> 15.5 | D6: 16.5
A7: Días de apertura al año | B7: 295 | C7: =IFERROR(IF('PyG 3 Años'!$B$8="","",'PyG 3 Años'!$B$8),"") -> 300 | D7: 305
A8: INGRESOS ANUALES (sin IVA) | B8: =IFERROR(IF(B5*B6*B7=0,"",B5*B6*B7),"") -> 282831.25 | C8: =IFERROR(IF(C5*C6*C7=0,"",C5*C6*C7),"") -> 358050 | D8: =IFERROR(IF(D5*D6*D7=0,"",D5*D6*D7),"") -> 442860
A9: Coste de mercancía — comida | B9: =IFERROR(IF(B8="","",B8*'0. Supuestos'!$B$11*'0. Supuestos'!$B$13),"") -> 61091.55 | C9: =IFERROR(IF(C8="","",C8*'0. Supuestos'!$B$11*'0. Supuestos'!$B$13),"") -> 77338.8 | D9: =IFERROR(IF(D8="","",D8*'0. Supuestos'!$B$11*'0. Supuestos'!$B$13),"") -> 95657.76
A10: Coste de mercancía — bebida | B10: =IFERROR(IF(B8="","",B8*'0. Supuestos'!$B$12*'0. Supuestos'!$B$14),"") -> 14707.225 | C10: =IFERROR(IF(C8="","",C8*'0. Supuestos'!$B$12*'0. Supuestos'!$B$14),"") -> 18618.6 | D10: =IFERROR(IF(D8="","",D8*'0. Supuestos'!$B$12*'0. Supuestos'!$B$14),"") -> 23028.72
A11: Consumibles y envases | B11: =IFERROR(IF(B8="","",B8*'0. Supuestos'!$B$15),"") -> 9899.0938 | C11: =IFERROR(IF(C8="","",C8*'0. Supuestos'!$B$15),"") -> 12531.75 | D11: =IFERROR(IF(D8="","",D8*'0. Supuestos'!$B$15),"") -> 15500.1
A12: Comisiones de delivery | B12: =IFERROR(IF(B8="","",B8*'0. Supuestos'!$B$16*'0. Supuestos'!$B$17),"") -> 10181.925 | C12: =IFERROR(IF(C8="","",C8*'0. Supuestos'!$B$16*'0. Supuestos'!$B$17),"") -> 12889.8 | D12: =IFERROR(IF(D8="","",D8*'0. Supuestos'!$B$16*'0. Supuestos'!$B$17),"") -> 15942.96
A13: Comisiones de los medios de pago | B13: =IFERROR(IF(B8="","",B8*'0. Supuestos'!$B$18),"") -> 2262.65 | C13: =IFERROR(IF(C8="","",C8*'0. Supuestos'!$B$18),"") -> 2864.4 | D13: =IFERROR(IF(D8="","",D8*'0. Supuestos'!$B$18),"") -> 3542.88
A14: Varios e imprevistos | B14: =IFERROR(IF(B8="","",B8*'0. Supuestos'!$B$28),"") -> 5656.625 | C14: =IFERROR(IF(C8="","",C8*'0. Supuestos'!$B$28),"") -> 7161 | D14: =IFERROR(IF(D8="","",D8*'0. Supuestos'!$B$28),"") -> 8857.2
A15: TOTAL COSTES VARIABLES | B15: =IFERROR(IF(B8="","",SUM(B9:B14)),"") -> 103799.07 | C15: =IFERROR(IF(C8="","",SUM(C9:C14)),"") -> 131404.35 | D15: =IFERROR(IF(D8="","",SUM(D9:D14)),"") -> 162529.62
A16: MARGEN BRUTO | B16: =IFERROR(IF(B8="","",B8-B15),"") -> 179032.18 | C16: =IFERROR(IF(C8="","",C8-C15),"") -> 226645.65 | D16: =IFERROR(IF(D8="","",D8-D15),"") -> 280330.38
A17: COSTES FIJOS (los del P&L) | B17: =IFERROR(IF(B8="","",'PyG 3 Años'!$B$37),"") -> 188335.72 | C17: =IFERROR(IF(C8="","",'PyG 3 Años'!$B$37),"") -> 188335.72 | D17: =IFERROR(IF(D8="","",'PyG 3 Años'!$B$37),"") -> 188335.72 | E17: Los costes fijos no cambian con el escenario: por eso son fijos
A18: RESULTADO ANTES DE IMPUESTOS | B18: =IFERROR(IF(B8="","",B16-B17),"") -> -9303.5388 | C18: =IFERROR(IF(C8="","",C16-C17),"") -> 38309.93 | D18: =IFERROR(IF(D8="","",D16-D17),"") -> 91994.66
A19: Impuesto de Sociedades | B19: =IFERROR(IF(B8="","",MAX(0,B18-'0. Supuestos'!$B$42)*'0. Supuestos'!$B$37),"") -> 0 | C19: =IFERROR(IF(C8="","",MAX(0,C18-'0. Supuestos'!$B$42)*'0. Supuestos'!$B$37),"") -> 5746.4895 | D19: =IFERROR(IF(D8="","",MAX(0,D18-'0. Supuestos'!$B$42)*'0. Supuestos'!$B$37),"") -> 13799.199 | E19: Al tipo de entidad de nueva creación, compensando las bases negativas anteriores
A20: RESULTADO NETO | B20: =IFERROR(IF(B8="","",B18-B19),"") -> -9303.5388 | C20: =IFERROR(IF(C8="","",C18-C19),"") -> 32563.44 | D20: =IFERROR(IF(D8="","",D18-D19),"") -> 78195.461
A21: Comensales/día para el equilibrio | B21: =IFERROR(IF(B8="","",IF(B6-B15/(B5*B7)<=0,"",B17/(B6-B15/(B5*B7))/B7)),"") -> 68.377773 | C21: =IFERROR(IF(C8="","",IF(C6-C15/(C5*C7)<=0,"",C17/(C6-C15/(C5*C7))/C7)),"") -> 63.984685 | D21: =IFERROR(IF(D8="","",IF(D6-D15/(D5*D7)<=0,"",D17/(D6-D15/(D5*D7))/D7)),"") -> 59.121467
A22: LO QUE CADA ESCENARIO EXIGE
A23: Coste de personal / Ventas | B23: =IFERROR(IF(B8="","",'PyG 3 Años'!$B$23/B8),"") -> 0.45794346 | C23: =IFERROR(IF(C8="","",'PyG 3 Años'!$B$23/C8),"") -> 0.3617392 | D23: =IFERROR(IF(D8="","",'PyG 3 Años'!$B$23/D8),"") -> 0.29246426 | E23: La MISMA plantilla en los tres escenarios. Si en el pesimista se dispara, el ajuste hay que hacerlo en la hoja de Personal, no aquí
A24: Comensales al año por jornada equivalente | B24: =IFERROR(IF(B8="","",B5*B7/'Personal'!$C$12),"") -> 4168.4783 | C24: =IFERROR(IF(C8="","",C5*C7/'Personal'!$C$12),"") -> 5021.7391 | D24: =IFERROR(IF(D8="","",D5*D7/'Personal'!$C$12),"") -> 5834.7826 | E24: Comensales que tendría que sacar cada jornada completa del cuadro de Personal. En el optimista dice si hace falta contratar
A25: Saldo de caja al cierre del año 1 (estimado, el mismo método en los tres escenarios) | B25: =IFERROR(IF(B8="","",'Inversión Inicial'!$B$29+B20+'PyG 3 Años'!$B$35-'Financiación'!$B$45),"") -> 44481.641 | C25: =IFERROR(IF(C8="","",'Inversión Inicial'!$B$29+C20+'PyG 3 Años'!$B$35-'Financiación'!$B$45),"") -> 86348.62 | D25: =IFERROR(IF(D8="","",'Inversión Inicial'!$B$29+D20+'PyG 3 Años'!$B$35-'Financiación'!$B$45),"") -> 131980.64 | E25: Saldo ESTIMADO: fondo de maniobra más el resultado del año, devolviendo la amortización (que no se paga) y restando el principal del préstamo. No incluye el desfase de cobros y pagos ni la liquidación del IVA, así que las tres columnas se pueden comparar entre sí. En rojo, el escenario se queda sin caja
A26: Saldo real del mes 12 de la hoja de Tesorería (sólo realista) | C26: =IFERROR(IF(C8="","",'Tesorería 12 meses'!$M$22),"") -> 115132.88 | E26: El saldo REAL del caso base, con su desfase de cobros y pagos y su liquidación de IVA. Sólo existe para el escenario realista, que es el único con tesorería mensual propia: por eso no está en la fila de arriba, donde se compararía contra dos estimaciones
A28: La columna «Realista» lee sus tres datos de la hoja de Supuestos, así que reproduce EXACTAMENTE el año 1 del P&L. Los otros dos escenarios usan las mismas tasas de coste: lo único que cambia son los comensales, el ticket y los días. Los COSTES FIJOS sí son los mismos en los tres: los varios e imprevistos, que son un porcentaje de las ventas, van arriba con los variables y cada escenario carga los suyos.

Sheet Personal
A1: ESTRUCTURA DE PERSONAL Y COSTES
A2: =IFERROR("Convenio Hostelería — "&TEXT('0. Supuestos'!$B$21,"0")&" pagas + SS "&TEXT('0. Supuestos'!$B$20*100,"0")&" %","") -> Convenio Hostelería — 14 pagas + SS 33 %
A4: Puesto | B4: Personas | C4: Jornada | D4: Bruto mes (€, total del puesto) | E4: Seg. Social a cargo de la empresa (€) | F4: Coste mes (€, total del puesto) | G4: Coste año (€) | H4: Horas/semana por persona | I4: Horas/año del puesto | J4: Notas
A5: Titular — taquero/a jefe: marinado, trompo, compras y gestión | B5: 1 | C5: 1 | D5: 1900 | E5: =IFERROR(IF(D5="","",D5*'0. Supuestos'!$B$20),"") -> 627 | F5: =IFERROR(IF(D5="","",D5+E5),"") -> 2527 | G5: =IFERROR(IF(D5="","",F5*MAX(12,'0. Supuestos'!$B$21)),"") -> 35378 | H5: =IFERROR(IF(D5="","",C5*$B$19),"") -> 40 | I5: =IFERROR(IF(D5="","",H5*B5*$B$20),"") -> 1840 | J5: Marina y monta el trompo, lleva el corte en el turno fuerte, compra (el importador de chiles y producto mexicano incluido) y gestiona. Como administrador de la SL cotiza en el régimen de autónomos: el libro le imputa el 33 % de Seguridad Social sobre 14 pagas como si fuera nómina, que es el lado prudente. Confirma con tu gestoría la cuota real y si te aplica la reducida de inicio
A6: Taquero/a de trompo, plancha y comal | B6: 1 | C6: 1 | D6: 1450 | E6: =IFERROR(IF(D6="","",D6*'0. Supuestos'!$B$20),"") -> 478.5 | F6: =IFERROR(IF(D6="","",D6+E6),"") -> 1928.5 | G6: =IFERROR(IF(D6="","",F6*MAX(12,'0. Supuestos'!$B$21)),"") -> 26999 | H6: =IFERROR(IF(D6="","",C6*$B$19),"") -> 40 | I6: =IFERROR(IF(D6="","",H6*B6*$B$20),"") -> 1840 | J6: Corta el trompo, lleva la plancha y el comal y sabe marinar con el titular. Es inversión, no gasto: si sólo el titular sabe marinar y cortar el trompo, una baja cierra la taquería
A7: Cocinero/a de producción y salsas | B7: 1 | C7: 0.75 | D7: 1013 | E7: =IFERROR(IF(D7="","",D7*'0. Supuestos'!$B$20),"") -> 334.29 | F7: =IFERROR(IF(D7="","",D7+E7),"") -> 1347.29 | G7: =IFERROR(IF(D7="","",F7*MAX(12,'0. Supuestos'!$B$21)),"") -> 18862.06 | H7: =IFERROR(IF(D7="","",C7*$B$19),"") -> 30 | I7: =IFERROR(IF(D7="","",H7*B7*$B$20),"") -> 1380 | J7: Carnitas y guisados, salsas, aguas frescas, mise en place y friegue, 30 horas a la semana
A8: Encargado/a de sala, barra y mostrador | B8: 1 | C8: 1 | D8: 1450 | E8: =IFERROR(IF(D8="","",D8*'0. Supuestos'!$B$20),"") -> 478.5 | F8: =IFERROR(IF(D8="","",D8+E8),"") -> 1928.5 | G8: =IFERROR(IF(D8="","",F8*MAX(12,'0. Supuestos'!$B$21)),"") -> 26999 | H8: =IFERROR(IF(D8="","",C8*$B$19),"") -> 40 | I8: =IFERROR(IF(D8="","",H8*B8*$B$20),"") -> 1840 | J8: Todo el año: sala, barra, caja, pedidos para llevar, la tablet de las plataformas y la información de alérgenos
A9: Camarero/a de cenas y fines de semana | B9: 1 | C9: 0.5 | D9: 675 | E9: =IFERROR(IF(D9="","",D9*'0. Supuestos'!$B$20),"") -> 222.75 | F9: =IFERROR(IF(D9="","",D9+E9),"") -> 897.75 | G9: =IFERROR(IF(D9="","",F9*MAX(12,'0. Supuestos'!$B$21)),"") -> 12568.5 | H9: =IFERROR(IF(D9="","",C9*$B$19),"") -> 20 | I9: =IFERROR(IF(D9="","",H9*B9*$B$20),"") -> 920 | J9: 20 horas a la semana: las cenas y el fin de semana, cuando la sala se llena
A10: Refuerzo de viernes a domingo: barra, terraza y recogidas | B10: 1 | C10: 0.25 | D10: 338 | E10: =IFERROR(IF(D10="","",D10*'0. Supuestos'!$B$20),"") -> 111.54 | F10: =IFERROR(IF(D10="","",D10+E10),"") -> 449.54 | G10: =IFERROR(IF(D10="","",F10*MAX(12,'0. Supuestos'!$B$21)),"") -> 6293.56 | H10: =IFERROR(IF(D10="","",C10*$B$19),"") -> 10 | I10: =IFERROR(IF(D10="","",H10*B10*$B$20),"") -> 460 | J10: Barra y terraza en temporada y el mostrador de recogidas. Este plan NO tiene reparto propio: si lo pones, el repartidor va con contrato laboral del convenio de hostelería, nunca como autónomo
A11: Suplencias de vacaciones y descansos | B11: 1 | C11: 0.1 | D11: 130 | E11: =IFERROR(IF(D11="","",D11*'0. Supuestos'!$B$20),"") -> 42.9 | F11: =IFERROR(IF(D11="","",D11+E11),"") -> 172.9 | G11: =IFERROR(IF(D11="","",F11*MAX(12,'0. Supuestos'!$B$21)),"") -> 2420.6 | H11: =IFERROR(IF(D11="","",C11*$B$19),"") -> 4 | I11: =IFERROR(IF(D11="","",H11*B11*$B$20),"") -> 184 | J11: Cobertura de los 30 días de vacaciones (art. 38 ET) y del descanso semanal del equipo de todo el año
A12: TOTAL PLANTILLA | B12: =IFERROR(IF(COUNT(D5:D11)=0,"",SUM(B5:B11)),"") -> 7 | C12: =IFERROR(IF(COUNT(D5:D11)=0,"",SUM(C5:C11)),"") -> 4.6 | D12: =IFERROR(IF(COUNT(D5:D11)=0,"",SUM(D5:D11)),"") -> 6956 | E12: =IFERROR(IF(COUNT(D5:D11)=0,"",SUM(E5:E11)),"") -> 2295.48 | F12: =IFERROR(IF(COUNT(D5:D11)=0,"",SUM(F5:F11)),"") -> 9251.48 | G12: =IFERROR(IF(COUNT(D5:D11)=0,"",SUM(G5:G11)),"") -> 129520.72 | I12: =IFERROR(IF(COUNT(D5:D11)=0,"",SUM(I5:I11)),"") -> 8464
A13: CRECIMIENTO DE LA PLANTILLA (coste escalonado)
A14: Coste anual de las incorporaciones del año 2 (€) | B14: 6000 | J14: Coste ANUAL completo (bruto + Seguridad Social × pagas) de lo que se contrate ese año. El P&L lo suma al coste del año anterior: la plantilla no crece con un porcentaje, crece con personas
A15: Coste anual de las incorporaciones del año 3 (€) | B15: 6000 | J15: Coste ANUAL completo (bruto + Seguridad Social × pagas) de lo que se contrate ese año. El P&L lo suma al coste del año anterior: la plantilla no crece con un porcentaje, crece con personas
A16: Coste de personal del año 2 | B16: =IFERROR(IF(G12="","",G12*(1+'0. Supuestos'!$B$48)+B14),"") -> 135520.72
A17: Coste de personal del año 3 | B17: =IFERROR(IF(B16="","",B16*(1+'0. Supuestos'!$B$48)+B15),"") -> 141520.72
A18: COBERTURA POR HORAS DE SERVICIO
A19: Jornada completa del convenio (horas/semana) | B19: 40 | J19: Art. 34.1 del Estatuto de los Trabajadores; tu convenio provincial puede fijar menos
A20: Semanas trabajadas al año por persona | B20: 46 | J20: 46 semanas: 52 menos las vacaciones (30 días naturales, art. 38 ET), los festivos y las ausencias medias
A21: Horas de servicio al día que hay que cubrir | B21: 8.5 | J21: Horas con el local abierto al público, sumando las comidas (13:30-16:30) y las cenas (20:00-23:30) y la preparación de cada servicio. La tarde de cierre entre los dos no se cuenta
A22: Personas necesarias a la vez en cada franja | B22: 2.7 | J22: Presencia media a la vez entre el trompo, la plancha o el comal, la sala y el mostrador. El sábado por la noche hacen falta cinco: entran el refuerzo y el camarero de cenas (el cuadrante anual no lo ve: ponlo en el turno)
A23: Horas de producción al día ANTES de abrir | B23: 2.5 | J23: Marinado del día siguiente, montaje del cono, carnitas y guisados, salsas y mise en place antes de abrir
A24: Personas en el turno de producción | B24: 1.5 | J24: El titular con el cocinero de producción. El cierre, la limpieza y las compras quedan fuera de este cuadrante: son el margen entre las horas contratadas y las necesarias
A25: Horas de servicio a cubrir al año | B25: =IFERROR(IF(OR(B21="",B22="",'0. Supuestos'!$B$6=""),"",B21*B22*'0. Supuestos'!$B$6+B23*B24*'0. Supuestos'!$B$6),"") -> 8010
A26: Horas contratadas al año | B26: =IFERROR(IF(I12="","",I12),"") -> 8464
A27: Cobertura (contratadas / necesarias) | B27: =IFERROR(B26/B25,"") -> 1.0566792 | J27: Por debajo del 100 % la plantilla no llega a cubrir el horario que declara el plan: o se contrata más o se recorta el horario
A29: Las columnas «Bruto mes», «Seg. Social», «Coste mes» y «Coste año» son TOTALES de la fila: en un puesto con dos personas incluyen a las dos. «Jornada» es el porcentaje sobre la jornada completa del convenio y sirve para comparar el salario con el suelo legal en proporción. El tipo de Seguridad Social y el número de pagas están en la hoja «0. Supuestos».
A30: El suelo salarial es el MAYOR entre el SMI y el salario de convenio, los dos en la hoja «0. Supuestos»; las jornadas parciales lo llevan en proporción. El convenio aplicable es el PROVINCIAL de hostelería: no existe una tabla salarial estatal única, así que la celda del convenio se entrega vacía para que copies la de tu provincia.

Sheet Instrucciones
A1: INSTRUCCIONES DE USO — Plan financiero Taquería
A3: CÓMO SE USA ESTE LIBRO
A4: Este plan financiero es un MODELO: sólo se teclea en las celdas VERDES y el resto se recalcula solo.
A5: 1. «0. Supuestos» es la hoja de mando: comensales, ticket sin IVA, días de apertura, mezcla de comida y bebida, coste de mercancía, alquiler, financiación e impuestos.
A6: 2. Las partidas de la inversión, los costes fijos y la plantilla se teclean en su propia hoja, también en verde. Ningún número se escribe dos veces.
A7: 3. En «Punto Equilibrio» sólo se teclea el techo de rotaciones que da tu local; todo lo demás se deriva de lo anterior. En las otras tres hojas también hay celdas verdes que puedes tocar: el escenario pesimista y el optimista en «Escenarios», la estacionalidad y la rampa de arranque en «Tesorería 12 meses», y las cuatro fuentes alternativas de financiación en «Financiación». Todo lo demás se calcula.
