Workbook

Sheet Pricing Calculator
A1: BBQ CATERING PRICING CALCULATOR — POUNDS OF MEAT PER GUEST TO QUOTE
A2: Type in the GREEN cells; everything else is calculated. Pick the package and the five meat lines, type your raw meat prices per lb (left blank on purpose), your staff and your costs: the tab turns them into pounds to buy, a price per guest and a full quote. Amounts are in US dollars (or your own currency) and exclude sales tax unless the row says otherwise. Every default value is a kit estimate: replace it with your own numbers.
A4: INPUTS | B4: Value | C4: Notes
A5: Package | B5: Full-service BBQ buffet (staffed, carving station) | C5: Choose from the list (table at the bottom of this tab): it sets the cooked meat per guest, the suggested staff and the food cost used while your meat prices are blank.
A6: Guests expected | B6: 75 | C6: Whole number. You cook and buy for these guests.
A7: Guest minimum in your contract | B7: 30 | C7: If fewer guests confirm, you bill the minimum (billable guests in the results). Operators read for this kit use 30 (eventective.com, Owen's BBQ) and 75 for full catering (hutchinsbbq.com). 0 = no minimum.
A8: Meat line 1: cut | B8: Packer brisket (whole, untrimmed) | C8: Choose from the cuts on the "Meat Yield & Smoke Schedule" tab (its yield and piece weight are used here).
A9: Meat line 1: share of the cooked meat | B9: 0.35 | C9: The five shares must add up to 100% (check in the results). 0% = line not used.
A10: Meat line 1: your raw price per lb | C10: Left blank on purpose: type your supplier's price per pound of RAW meat. This kit does not guess meat prices.
A11: Meat line 2: cut | B11: Pork butt (bone-in shoulder) | C11: Choose a cut from the list.
A12: Meat line 2: share of the cooked meat | B12: 0.3
A13: Meat line 2: your raw price per lb | C13: Your supplier's price per raw lb.
A14: Meat line 3: cut | B14: St. Louis ribs | C14: Choose a cut from the list.
A15: Meat line 3: share of the cooked meat | B15: 0.15
A16: Meat line 3: your raw price per lb | C16: Your supplier's price per raw lb.
A17: Meat line 4: cut | B17: Chicken thighs (bone-in) | C17: Choose a cut from the list.
A18: Meat line 4: share of the cooked meat | B18: 0.15
A19: Meat line 4: your raw price per lb | C19: Your supplier's price per raw lb.
A20: Meat line 5: cut | B20: Sausage (smoked links) | C20: Choose a cut from the list.
A21: Meat line 5: share of the cooked meat | B21: 0.05
A22: Meat line 5: your raw price per lb | C22: Your supplier's price per raw lb.
A23: Sides per guest (mac and cheese, beans, slaw, potato salad) | B23: 2 | C23: Kit estimate. Used together with your meat prices; while they are blank, the package food cost replaces it.
A24: Bread, pickles, onions and BBQ sauce per guest | B24: 0.6 | C24: Kit estimate. Same rule as the sides.
A25: Disposables per guest (pans, plates, cutlery, butcher paper, foil) | B25: 0.75 | C25: Kit estimate.
A26: Wood or charcoal per raw lb of meat (lb) | B26: 0.6 | C26: Kit estimate: a full cook burns about 60-100 lb of wood. Pellets or charcoal: use your own ratio.
A27: Wood or charcoal cost per lb | B27: 0.15 | C27: Kit estimate: use your supplier's price.
A28: Live pit on site (smoker trailer at the event)? | B28: No | C28: Yes = you tow the smoker trailer and cook or carve at the event, for a flat fee (next row). Ask your county first: cooking at the event can make the trailer a mobile food unit.
A29: Live pit on site fee (flat, per event) | B29: 650 | C29: Charged on top of the per-guest price when the switch above is Yes. A Los Angeles operator charges $650 for the smoker on site (eventective.com, Owen's BBQ).
A30: Pit crew on event day (pitmasters, pit cooks) | B30: 1 | C30: Compare with the suggested number in the results.
A31: Servers, buffet attendants and carvers | B31: 3 | C31: Compare with the suggested number in the results.
A32: Hours each on event day (loading, travel, setup, service, breakdown) | B32: 6 | C32: Kit estimate.
A33: Overnight cook and prep hours (pit cook, total) | B33: 8 | C33: Trimming, rubs and the overnight cook for this event. One pit cook can watch several cooks at once: count only the hours this event takes. Kit estimate.
A34: Pit crew hourly wage | B34: 21 | C34: Kit estimate, about the 75th percentile of restaurant cooks (BLS OEWS, May 2025: $21.45). W-2 employees.
A35: Server / attendant hourly wage | B35: 18 | C35: Kit estimate, about the 75th percentile of nonrestaurant food servers (BLS OEWS, May 2025: $18.51). W-2.
A36: Employer payroll taxes and workers' comp (% of wages) | B36: 0.1 | C36: Kit estimate.
A37: Rentals passed through (tables, linens, chafing dishes, tent) | B37: 0 | C37: What the rental company charges you for this event.
A38: Round-trip miles | B38: 30 | C38: Commissary → venue → commissary.
A39: Cost per mile (van, or pickup + smoker trailer) | B39: 0.7 | C39: Kit estimate: use your real cost per mile or the current IRS standard mileage rate.
A40: Flat event or travel fee charged to the client | B40: 0 | C40: Optional flat charge on top of the per-guest price. 0 = none.
... A44: Sales tax rate (state + local) | B44: 0.08 | C44: Kit estimate: use your own state + local rate.
...

Sheet Meat Yield & Smoke Schedule
A1: MEAT YIELD & SMOKE SCHEDULE — 13 CUTS
A2: Raw weight, pit temperature, cook and rest times and yield for 13 cuts (green cells: kit estimates, edit them with your own test cooks). The QUALITY target (when the meat is done the way guests expect) and the FDA Food Code MINIMUM (the legal safety floor, 2022 Food Code 3-401.11) are different numbers and sit in separate columns. Type your service time below: the tab tells you when to start each cook.
A4: SCHEDULE INPUTS
A5: Service time on event day | B5: 0.75 | C5: Type a time such as 6:00 PM.
A6: Safety cushion before service (hours) | B6: 1 | C6: Extra time for a slow cook or the stall. Kit estimate.
A7: Cooked oz per serving of one meat | B7: 4 | C7: With 2 meats on the plate, 4 oz each = half a pound of cooked meat per guest.
A9: Cut | B9: Raw weight per piece (lb) | C9: Pit or grill temp (°F) | D9: (°C) | E9: Quality target (°F, Kit estimate) | F9: (°C) | G9: FDA Food Code minimum (safety) | H9: Cook hours | I9: Rest and hold hours | J9: Yield (cooked ÷ raw) | K9: Yield source | L9: Servings per raw lb | M9: Cooked lb per piece | N9: Start the pit by | O9: Day
A10: Packer brisket (whole, untrimmed) | B10: 14 | C10: 250 | D10: =ROUND((C10-32)*5/9,0) -> 121 | E10: 203 | F10: =ROUND((E10-32)*5/9,0) -> 95 | G10: 145 °F (63 °C) for 4 min as a whole roast; 155 °F (68 °C) for 17 s if injected | H10: 12 | I10: 2 | J10: 0.5 | K10: fieryfoodscentral.com (about 50% of the fresh weight) | L10: =IF($B$7>0,J10*16/$B$7,0) -> 2 | M10: =B10*J10 -> 7 | N10: =($B$5-(H10+I10+$B$6)/24)-INT(($B$5-(H10+I10+$B$6)/24)) -> 0.125 | O10: =IF(($B$5-(H10+I10+$B$6)/24)>=0,"Event day",IF(($B$5-(H10+I10+$B$6)/24)>=-1,"Day before","2 days before")) -> Event day
A11: Pork butt (bone-in shoulder) | B11: 8 | C11: 250 | D11: =ROUND((C11-32)*5/9,0) -> 121 | E11: 200 | F11: =ROUND((E11-32)*5/9,0) -> 93 | G11: 145 °F (63 °C) for 4 min as a whole roast; 155 °F (68 °C) for 17 s if injected | H11: 10 | I11: 1.5 | J11: 0.5 | K11: fieryfoodscentral.com (about 50% of the fresh weight) | L11: =IF($B$7>0,J11*16/$B$7,0) -> 2 | M11: =B11*J11 -> 4 | N11: =($B$5-(H11+I11+$B$6)/24)-INT(($B$5-(H11+I11+$B$6)/24)) -> 0.22916667 | O11: =IF(($B$5-(H11+I11+$B$6)/24)>=0,"Event day",IF(($B$5-(H11+I11+$B$6)/24)>=-1,"Day before","2 days before")) -> Event day
A12: St. Louis ribs | B12: 3 | C12: 250 | D12: =ROUND((C12-32)*5/9,0) -> 121 | E12: 198 | F12: =ROUND((E12-32)*5/9,0) -> 92 | G12: 145 °F (63 °C) for 15 s; 155 °F (68 °C) for 17 s if injected or tenderized | H12: 5.5 | I12: 0.5 | J12: 0.65 | K12: Kit estimate | L12: =IF($B$7>0,J12*16/$B$7,0) -> 2.6 | M12: =B12*J12 -> 1.95 | N12: =($B$5-(H12+I12+$B$6)/24)-INT(($B$5-(H12+I12+$B$6)/24)) -> 0.45833333 | O12: =IF(($B$5-(H12+I12+$B$6)/24)>=0,"Event day",IF(($B$5-(H12+I12+$B$6)/24)>=-1,"Day before","2 days before")) -> Event day
A13: Baby back ribs | B13: 2.25 | C13: 250 | D13: =ROUND((C13-32)*5/9,0) -> 121 | E13: 195 | F13: =ROUND((E13-32)*5/9,0) -> 91 | G13: 145 °F (63 °C) for 15 s; 155 °F (68 °C) for 17 s if injected or tenderized | H13: 4.5 | I13: 0.5 | J13: 0.6 | K13: Kit estimate | L13: =IF($B$7>0,J13*16/$B$7,0) -> 2.4 | M13: =B13*J13 -> 1.35 | N13: =($B$5-(H13+I13+$B$6)/24)-INT(($B$5-(H13+I13+$B$6)/24)) -> 0.5 | O13: =IF(($B$5-(H13+I13+$B$6)/24)>=0,"Event day",IF(($B$5-(H13+I13+$B$6)/24)>=-1,"Day before","2 days before")) -> Event day
A14: Beef plate ribs (3-bone) | B14: 5.5 | C14: 275 | D14: =ROUND((C14-32)*5/9,0) -> 135 | E14: 203 | F14: =ROUND((E14-32)*5/9,0) -> 95 | G14: 145 °F (63 °C) for 15 s; 155 °F (68 °C) for 17 s if injected or tenderized | H14: 9 | I14: 1 | J14: 0.55 | K14: Kit estimate | L14: =IF($B$7>0,J14*16/$B$7,0) -> 2.2 | M14: =B14*J14 -> 3.025 | N14: =($B$5-(H14+I14+$B$6)/24)-INT(($B$5-(H14+I14+$B$6)/24)) -> 0.29166667 | O14: =IF(($B$5-(H14+I14+$B$6)/24)>=0,"Event day",IF(($B$5-(H14+I14+$B$6)/24)>=-1,"Day before","2 days before")) -> Event day
A15: Chicken thighs (bone-in) | B15: 0.33 | C15: 300 | D15: =ROUND((C15-32)*5/9,0) -> 149 | E15: 185 | F15: =ROUND((E15-32)*5/9,0) -> 85 | G15: 165 °F (74 °C), instantaneous (poultry) | H15: 1.75 | I15: 0.25 | J15: 0.68 | K15: Kit estimate (65-70%) | L15: =IF($B$7>0,J15*16/$B$7,0) -> 2.72 | M15: =B15*J15 -> 0.2244 | N15: =($B$5-(H15+I15+$B$6)/24)-INT(($B$5-(H15+I15+$B$6)/24)) -> 0.625 | O15: =IF(($B$5-(H15+I15+$B$6)/24)>=0,"Event day",IF(($B$5-(H15+I15+$B$6)/24)>=-1,"Day before","2 days before")) -> Event day
A16: Chicken halves | B16: 2 | C16: 300 | D16: =ROUND((C16-32)*5/9,0) -> 149 | E16: 175 | F16: =ROUND((E16-32)*5/9,0) -> 79 | G16: 165 °F (74 °C), instantaneous (poultry) | H16: 2.5 | I16: 0.25 | J16: 0.65 | K16: Kit estimate (65-70%) | L16: =IF($B$7>0,J16*16/$B$7,0) -> 2.6 | M16: =B16*J16 -> 1.3 | N16: =($B$5-(H16+I16+$B$6)/24)-INT(($B$5-(H16+I16+$B$6)/24)) -> 0.59375 | O16: =IF(($B$5-(H16+I16+$B$6)/24)>=0,"Event day",IF(($B$5-(H16+I16+$B$6)/24)>=-1,"Day before","2 days before")) -> Event day
A17: Turkey breast (bone-in) | B17: 7 | C17: 275 | D17: =ROUND((C17-32)*5/9,0) -> 135 | E17: 165 | F17: =ROUND((E17-32)*5/9,0) -> 74 | G17: 165 °F (74 °C), instantaneous (poultry) | H17: 4 | I17: 0.5 | J17: 0.7 | K17: Kit estimate | L17: =IF($B$7>0,J17*16/$B$7,0) -> 2.8 | M17: =B17*J17 -> 4.9 | N17: =($B$5-(H17+I17+$B$6)/24)-INT(($B$5-(H17+I17+$B$6)/24)) -> 0.52083333 | O17: =IF(($B$5-(H17+I17+$B$6)/24)>=0,"Event day",IF(($B$5-(H17+I17+$B$6)/24)>=-1,"Day before","2 days before")) -> Event day
A18: Sausage (smoked links) | B18: 0.25 | C18: 275 | D18: =ROUND((C18-32)*5/9,0) -> 135 | E18: 165 | F18: =ROUND((E18-32)*5/9,0) -> 74 | G18: 155 °F (68 °C) for 17 s (ground meat, sausage included) | H18: 1.5 | I18: 0.25 | J18: 0.88 | K18: Kit estimate (85-90%) | L18: =IF($B$7>0,J18*16/$B$7,0) -> 3.52 | M18: =B18*J18 -> 0.22 | N18: =($B$5-(H18+I18+$B$6)/24)-INT(($B$5-(H18+I18+$B$6)/24)) -> 0.63541667 | O18: =IF(($B$5-(H18+I18+$B$6)/24)>=0,"Event day",IF(($B$5-(H18+I18+$B$6)/24)>=-1,"Day before","2 days before")) -> Event day
A19: Tri-tip (Santa Maria, over red oak) | B19: 2.5 | C19: 375 | D19: =ROUND((C19-32)*5/9,0) -> 191 | E19: 145 | F19: =ROUND((E19-32)*5/9,0) -> 63 | G19: 145 °F (63 °C) for 4 min as a whole roast; 155 °F (68 °C) for 17 s if injected | H19: 1 | I19: 0.25 | J19: 0.75 | K19: Kit estimate | L19: =IF($B$7>0,J19*16/$B$7,0) -> 3 | M19: =B19*J19 -> 1.875 | N19: =($B$5-(H19+I19+$B$6)/24)-INT(($B$5-(H19+I19+$B$6)/24)) -> 0.65625 | O19: =IF(($B$5-(H19+I19+$B$6)/24)>=0,"Event day",IF(($B$5-(H19+I19+$B$6)/24)>=-1,"Day before","2 days before")) -> Event day
A20: Picanha (top sirloin cap) | B20: 3 | C20: 400 | D20: =ROUND((C20-32)*5/9,0) -> 204 | E20: 145 | F20: =ROUND((E20-32)*5/9,0) -> 63 | G20: 145 °F (63 °C) for 4 min as a whole roast; 155 °F (68 °C) for 17 s if injected | H20: 1 | I20: 0.25 | J20: 0.75 | K20: Kit estimate | L20: =IF($B$7>0,J20*16/$B$7,0) -> 3 | M20: =B20*J20 -> 2.25 | N20: =($B$5-(H20+I20+$B$6)/24)-INT(($B$5-(H20+I20+$B$6)/24)) -> 0.65625 | O20: =IF(($B$5-(H20+I20+$B$6)/24)>=0,"Event day",IF(($B$5-(H20+I20+$B$6)/24)>=-1,"Day before","2 days before")) -> Event day
A21: Tomahawk / bone-in ribeye | B21: 3 | C21: 250 | D21: =ROUND((C21-32)*5/9,0) -> 121 | E21: 145 | F21: =ROUND((E21-32)*5/9,0) -> 63 | G21: 145 °F (63 °C) for 15 s; 155 °F (68 °C) for 17 s if injected or tenderized | H21: 1.5 | I21: 0.25 | J21: 0.7 | K21: Kit estimate | L21: =IF($B$7>0,J21*16/$B$7,0) -> 2.8 | M21: =B21*J21 -> 2.1 | N21: =($B$5-(H21+I21+$B$6)/24)-INT(($B$5-(H21+I21+$B$6)/24)) -> 0.63541667 | O21: =IF(($B$5-(H21+I21+$B$6)/24)>=0,"Event day",IF(($B$5-(H21+I21+$B$6)/24)>=-1,"Day before","2 days before")) -> Event day
A22: Whole hog (optional, dressed) | B22: 120 | C22: 250 | D22: =ROUND((C22-32)*5/9,0) -> 121 | E22: 200 | F22: =ROUND((E22-32)*5/9,0) -> 93 | G22: 145 °F (63 °C) for 4 min as a whole roast; 155 °F (68 °C) for 17 s if injected | H22: 14 | I22: 1 | J22: 0.35 | K22: Kit estimate | L22: =IF($B$7>0,J22*16/$B$7,0) -> 1.4 | M22: =B22*J22 -> 42 | N22: =($B$5-(H22+I22+$B$6)/24)-INT(($B$5-(H22+I22+$B$6)/24)) -> 0.083333333 | O22: =IF(($B$5-(H22+I22+$B$6)/24)>=0,"Event day",IF(($B$5-(H22+I22+$B$6)/24)>=-1,"Day before","2 days before")) -> Event day
A24: Quality target = the internal temperature at which the cut is done the way guests expect (Kit estimate: probe-tender brisket around 203 °F). Food Code minimum = the legal safety floor. Pull a cut when it reaches BOTH; never write one in place of the other.
A25: Injecting a brisket or a pork butt makes it non-intact: its minimum becomes 155 °F (68 °C) for 17 seconds. Serving whole-muscle beef below its minimum (a medium-rare tri-tip, picanha or tomahawk): check your county rules before you put it on the menu.
A26: Hot holding: keep cooked meat at 135 °F (57 °C) or above (3-501.16), in insulated food carriers or hot boxes, and probe it before you serve.
A27: Cooling leftovers: to 70 °F (21 °C) within 2 hours and to 41 °F (5 °C) within a total of 6 hours (3-501.14); slice or portion brisket so it cools fast. Reheating cooked meat for hot holding: to 165 °F (74 °C) for 15 seconds (3-403.11).
A28: Yield: brisket and pork butt end up at about 50% of their raw weight (fieryfoodscentral.com, Dr. BBQ); every other yield is a kit estimate. Weigh your own raw and cooked pounds on your test cook and type them here: the "Pricing Calculator" and "Shopping List by Guest Count" tabs follow.
A29: Whole hog: buy it from a USDA- or state-inspected plant; custom-exempt meat is marked "not for sale" (nichemeatprocessing.org).
A30: Start the pit by = service time − cook hours − rest and hold hours − safety cushion. Long cooks start the day before: plan the overnight shift of your pit cook.

Sheet Shopping List by Guest Count
A1: SHOPPING LIST BY GUEST COUNT — WHAT TO BUY AND BRING
A2: It reads the package, the meat lines (cut and share) and the wood ratio from the "Pricing Calculator" tab and the yields and piece weights from the "Meat Yield & Smoke Schedule" tab. Column B is your event; columns C-F are reference sizes (40, 80, 150 and 300 guests: edit them). Green cells are kit estimates: edit them.
A4: ASSUMPTIONS (Kit estimate — edit) | B4: Value | G4: Notes
A5: Number of sides on the menu | B5: 2 | G5: Kit estimate (3 meats + 2 sides is a common package).
A6: Portion of each side per guest (oz) | B6: 4 | G6: Kit estimate.
A7: Oz of sides per half hotel pan (2.5 in deep) | B7: 128 | G7: Kit estimate: about a gallon.
A8: Rolls or bread slices per guest | B8: 1.5 | G8: Kit estimate.
A9: BBQ sauce per guest (oz) | B9: 2 | G9: Kit estimate.
A10: Butcher paper and foil per raw lb (ft of roll) | B10: 1.5 | G10: Kit estimate.
A11: Cooked meat per full hotel pan (lb) | B11: 15 | G11: Kit estimate.
A12: Full hotel pans per insulated food carrier or hot box | B12: 4 | G12: Kit estimate: check your model.
A14: QUANTITIES | B14: Your event | C14: Reference | D14: Reference | E14: Reference | F14: Reference | G14: Notes
A15: Guests | B15: ='Pricing Calculator'!$B$6 -> 75 | C15: 40 | D15: 80 | E15: 150 | F15: 300 | G15: Column B comes from the "Pricing Calculator" tab.
A16: Cooked meat to serve (lb) | B16: =B$15*IFERROR(INDEX('Pricing Calculator'!$B$113:$B$115,MATCH('Pricing Calculator'!$B$5,'Pricing Calculator'!$A$113:$A$115,0)),0)/16 -> 37.5 | C16: =C$15*IFERROR(INDEX('Pricing Calculator'!$B$113:$B$115,MATCH('Pricing Calculator'!$B$5,'Pricing Calculator'!$A$113:$A$115,0)),0)/16 -> 20 | D16: =D$15*IFERROR(INDEX('Pricing Calculator'!$B$113:$B$115,MATCH('Pricing Calculator'!$B$5,'Pricing Calculator'!$A$113:$A$115,0)),0)/16 -> 40 | E16: =E$15*IFERROR(INDEX('Pricing Calculator'!$B$113:$B$115,MATCH('Pricing Calculator'!$B$5,'Pricing Calculator'!$A$113:$A$115,0)),0)/16 -> 75 | F16: =F$15*IFERROR(INDEX('Pricing Calculator'!$B$113:$B$115,MATCH('Pricing Calculator'!$B$5,'Pricing Calculator'!$A$113:$A$115,0)),0)/16 -> 150 | G16: Guests × oz per guest of the package ÷ 16.
A17: ="Raw lb: "&'Pricing Calculator'!$B$8 -> Raw lb: Packer brisket (whole, untrimmed) | B17: =IFERROR(IF(INDEX('Meat Yield & Smoke Schedule'!$J$10:$J$22,MATCH('Pricing Calculator'!$B$8,'Meat Yield & Smoke Schedule'!$A$10:$A$22,0))>0,B$16*'Pricing Calculator'!$B$9/INDEX('Meat Yield & Smoke Schedule'!$J$10:$J$22,MATCH('Pricing Calculator'!$B$8,'Meat Yield & Smoke Schedule'!$A$10:$A$22,0)),0),0) -> 26.25 | C17: =IFERROR(IF(INDEX('Meat Yield & Smoke Schedule'!$J$10:$J$22,MATCH('Pricing Calculator'!$B$8,'Meat Yield & Smoke Schedule'!$A$10:$A$22,0))>0,C$16*'Pricing Calculator'!$B$9/INDEX('Meat Yield & Smoke Schedule'!$J$10:$J$22,MATCH('Pricing Calculator'!$B$8,'Meat Yield & Smoke Schedule'!$A$10:$A$22,0)),0),0) -> 14 | D17: =IFERROR(IF(INDEX('Meat Yield & Smoke Schedule'!$J$10:$J$22,MATCH('Pricing Calculator'!$B$8,'Meat Yield & Smoke Schedule'!$A$10:$A$22,0))>0,D$16*'Pricing Calculator'!$B$9/INDEX('Meat Yield & Smoke Schedule'!$J$10:$J$22,MATCH('Pricing Calculator'!$B$8,'Meat Yield & Smoke Schedule'!$A$10:$A$22,0)),0),0) -> 28 | E17: =IFERROR(IF(INDEX('Meat Yield & Smoke Schedule'!$J$10:$J$22,MATCH('Pricing Calculator'!$B$8,'Meat Yield & Smoke Schedule'!$A$10:$A$22,0))>0,E$16*'Pricing Calculator'!$B$9/INDEX('Meat Yield & Smoke Schedule'!$J$10:$J$22,MATCH('Pricing Calculator'!$B$8,'Meat Yield & Smoke Schedule'!$A$10:$A$22,0)),0),0) -> 52.5 | F17: =IFERROR(IF(INDEX('Meat Yield & Smoke Schedule'!$J$10:$J$22,MATCH('Pricing Calculator'!$B$8,'Meat Yield & Smoke Schedule'!$A$10:$A$22,0))>0,F$16*'Pricing Calculator'!$B$9/INDEX('Meat Yield & Smoke Schedule'!$J$10:$J$22,MATCH('Pricing Calculator'!$B$8,'Meat Yield & Smoke Schedule'!$A$10:$A$22,0)),0),0) -> 105
A18: =" Pieces: "&'Pricing Calculator'!$B$8 -> Pieces: Packer brisket (whole, untrimmed) | B18: =IFERROR(IF(INDEX('Meat Yield & Smoke Schedule'!$B$10:$B$22,MATCH('Pricing Calculator'!$B$8,'Meat Yield & Smoke Schedule'!$A$10:$A$22,0))>0,ROUNDUP(B$17/INDEX('Meat Yield & Smoke Schedule'!$B$10:$B$22,MATCH('Pricing Calculator'!$B$8,'Meat Yield & Smoke Schedule'!$A$10:$A$22,0)),0),0),0) -> 2 | C18: =IFERROR(IF(INDEX('Meat Yield & Smoke Schedule'!$B$10:$B$22,MATCH('Pricing Calculator'!$B$8,'Meat Yield & Smoke Schedule'!$A$10:$A$22,0))>0,ROUNDUP(C$17/INDEX('Meat Yield & Smoke Schedule'!$B$10:$B$22,MATCH('Pricing Calculator'!$B$8,'Meat Yield & Smoke Schedule'!$A$10:$A$22,0)),0),0),0) -> 1 | D18: =IFERROR(IF(INDEX('Meat Yield & Smoke Schedule'!$B$10:$B$22,MATCH('Pricing Calculator'!$B$8,'Meat Yield & Smoke Schedule'!$A$10:$A$22,0))>0,ROUNDUP(D$17/INDEX('Meat Yield & Smoke Schedule'!$B$10:$B$22,MATCH('Pricing Calculator'!$B$8,'Meat Yield & Smoke Schedule'!$A$10:$A$22,0)),0),0),0) -> 2 | E18: =IFERROR(IF(INDEX('Meat Yield & Smoke Schedule'!$B$10:$B$22,MATCH('Pricing Calculator'!$B$8,'Meat Yield & Smoke Schedule'!$A$10:$A$22,0))>0,ROUNDUP(E$17/INDEX('Meat Yield & Smoke Schedule'!$B$10:$B$22,MATCH('Pricing Calculator'!$B$8,'Meat Yield & Smoke Schedule'!$A$10:$A$22,0)),0),0),0) -> 4 | F18: =IFERROR(IF(INDEX('Meat Yield & Smoke Schedule'!$B$10:$B$22,MATCH('Pricing Calculator'!$B$8,'Meat Yield & Smoke Schedule'!$A$10:$A$22,0))>0,ROUNDUP(F$17/INDEX('Meat Yield & Smoke Schedule'!$B$10:$B$22,MATCH('Pricing Calculator'!$B$8,'Meat Yield & Smoke Schedule'!$A$10:$A$22,0)),0),0),0) -> 8
A19: ="Raw lb: "&'Pricing Calculator'!$B$11 -> Raw lb: Pork butt (bone-in shoulder) | B19: =IFERROR(IF(INDEX('Meat Yield & Smoke Schedule'!$J$10:$J$22,MATCH('Pricing Calculator'!$B$11,'Meat Yield & Smoke Schedule'!$A$10:$A$22,0))>0,B$16*'Pricing Calculator'!$B$12/INDEX('Meat Yield & Smoke Schedule'!$J$10:$J$22,MATCH('Pricing Calculator'!$B$11,'Meat Yield & Smoke Schedule'!$A$10:$A$22,0)),0),0) -> 22.5 | C19: =IFERROR(IF(INDEX('Meat Yield & Smoke Schedule'!$J$10:$J$22,MATCH('Pricing Calculator'!$B$11,'Meat Yield & Smoke Schedule'!$A$10:$A$22,0))>0,C$16*'Pricing Calculator'!$B$12/INDEX('Meat Yield & Smoke Schedule'!$J$10:$J$22,MATCH('Pricing Calculator'!$B$11,'Meat Yield & Smoke Schedule'!$A$10:$A$22,0)),0),0) -> 12 | D19: =IFERROR(IF(INDEX('Meat Yield & Smoke Schedule'!$J$10:$J$22,MATCH('Pricing Calculator'!$B$11,'Meat Yield & Smoke Schedule'!$A$10:$A$22,0))>0,D$16*'Pricing Calculator'!$B$12/INDEX('Meat Yield & Smoke Schedule'!$J$10:$J$22,MATCH('Pricing Calculator'!$B$11,'Meat Yield & Smoke Schedule'!$A$10:$A$22,0)),0),0) -> 24 | E19: =IFERROR(IF(INDEX('Meat Yield & Smoke Schedule'!$J$10:$J$22,MATCH('Pricing Calculator'!$B$11,'Meat Yield & Smoke Schedule'!$A$10:$A$22,0))>0,E$16*'Pricing Calculator'!$B$12/INDEX('Meat Yield & Smoke Schedule'!$J$10:$J$22,MATCH('Pricing Calculator'!$B$11,'Meat Yield & Smoke Schedule'!$A$10:$A$22,0)),0),0) -> 45 | F19: =IFERROR(IF(INDEX('Meat Yield & Smoke Schedule'!$J$10:$J$22,MATCH('Pricing Calculator'!$B$11,'Meat Yield & Smoke Schedule'!$A$10:$A$22,0))>0,F$16*'Pricing Calculator'!$B$12/INDEX('Meat Yield & Smoke Schedule'!$J$10:$J$22,MATCH('Pricing Calculator'!$B$11,'Meat Yield & Smoke Schedule'!$A$10:$A$22,0)),0),0) -> 90
A20: =" Pieces: "&'Pricing Calculator'!$B$11 -> Pieces: Pork butt (bone-in shoulder) | B20: =IFERROR(IF(INDEX('Meat Yield & Smoke Schedule'!$B$10:$B$22,MATCH('Pricing Calculator'!$B$11,'Meat Yield & Smoke Schedule'!$A$10:$A$22,0))>0,ROUNDUP(B$19/INDEX('Meat Yield & Smoke Schedule'!$B$10:$B$22,MATCH('Pricing Calculator'!$B$11,'Meat Yield & Smoke Schedule'!$A$10:$A$22,0)),0),0),0) -> 3 | C20: =IFERROR(IF(INDEX('Meat Yield & Smoke Schedule'!$B$10:$B$22,MATCH('Pricing Calculator'!$B$11,'Meat Yield & Smoke Schedule'!$A$10:$A$22,0))>0,ROUNDUP(C$19/INDEX('Meat Yield & Smoke Schedule'!$B$10:$B$22,MATCH('Pricing Calculator'!$B$11,'Meat Yield & Smoke Schedule'!$A$10:$A$22,0)),0),0),0) -> 2 | D20: =IFERROR(IF(INDEX('Meat Yield & Smoke Schedule'!$B$10:$B$22,MATCH('Pricing Calculator'!$B$11,'Meat Yield & Smoke Schedule'!$A$10:$A$22,0))>0,ROUNDUP(D$19/INDEX('Meat Yield & Smoke Schedule'!$B$10:$B$22,MATCH('Pricing Calculator'!$B$11,'Meat Yield & Smoke Schedule'!$A$10:$A$22,0)),0),0),0) -> 3 | E20: =IFERROR(IF(INDEX('Meat Yield & Smoke Schedule'!$B$10:$B$22,MATCH('Pricing Calculator'!$B$11,'Meat Yield & Smoke Schedule'!$A$10:$A$22,0))>0,ROUNDUP(E$19/INDEX('Meat Yield & Smoke Schedule'!$B$10:$B$22,MATCH('Pricing Calculator'!$B$11,'Meat Yield & Smoke Schedule'!$A$10:$A$22,0)),0),0),0) -> 6 | F20: =IFERROR(IF(INDEX('Meat Yield & Smoke Schedule'!$B$10:$B$22,MATCH('Pricing Calculator'!$B$11,'Meat Yield & Smoke Schedule'!$A$10:$A$22,0))>0,ROUNDUP(F$19/INDEX('Meat Yield & Smoke Schedule'!$B$10:$B$22,MATCH('Pricing Calculator'!$B$11,'Meat Yield & Smoke Schedule'!$A$10:$A$22,0)),0),0),0) -> 12
A21: ="Raw lb: "&'Pricing Calculator'!$B$14 -> Raw lb: St. Louis ribs | B21: =IFERROR(IF(INDEX('Meat Yield & Smoke Schedule'!$J$10:$J$22,MATCH('Pricing Calculator'!$B$14,'Meat Yield & Smoke Schedule'!$A$10:$A$22,0))>0,B$16*'Pricing Calculator'!$B$15/INDEX('Meat Yield & Smoke Schedule'!$J$10:$J$22,MATCH('Pricing Calculator'!$B$14,'Meat Yield & Smoke Schedule'!$A$10:$A$22,0)),0),0) -> 8.6538462 | C21: =IFERROR(IF(INDEX('Meat Yield & Smoke Schedule'!$J$10:$J$22,MATCH('Pricing Calculator'!$B$14,'Meat Yield & Smoke Schedule'!$A$10:$A$22,0))>0,C$16*'Pricing Calculator'!$B$15/INDEX('Meat Yield & Smoke Schedule'!$J$10:$J$22,MATCH('Pricing Calculator'!$B$14,'Meat Yield & Smoke Schedule'!$A$10:$A$22,0)),0),0) -> 4.6153846 | D21: =IFERROR(IF(INDEX('Meat Yield & Smoke Schedule'!$J$10:$J$22,MATCH('Pricing Calculator'!$B$14,'Meat Yield & Smoke Schedule'!$A$10:$A$22,0))>0,D$16*'Pricing Calculator'!$B$15/INDEX('Meat Yield & Smoke Schedule'!$J$10:$J$22,MATCH('Pricing Calculator'!$B$14,'Meat Yield & Smoke Schedule'!$A$10:$A$22,0)),0),0) -> 9.2307692 | E21: =IFERROR(IF(INDEX('Meat Yield & Smoke Schedule'!$J$10:$J$22,MATCH('Pricing Calculator'!$B$14,'Meat Yield & Smoke Schedule'!$A$10:$A$22,0))>0,E$16*'Pricing Calculator'!$B$15/INDEX('Meat Yield & Smoke Schedule'!$J$10:$J$22,MATCH('Pricing Calculator'!$B$14,'Meat Yield & Smoke Schedule'!$A$10:$A$22,0)),0),0) -> 17.307692 | F21: =IFERROR(IF(INDEX('Meat Yield & Smoke Schedule'!$J$10:$J$22,MATCH('Pricing Calculator'!$B$14,'Meat Yield & Smoke Schedule'!$A$10:$A$22,0))>0,F$16*'Pricing Calculator'!$B$15/INDEX('Meat Yield & Smoke Schedule'!$J$10:$J$22,MATCH('Pricing Calculator'!$B$14,'Meat Yield & Smoke Schedule'!$A$10:$A$22,0)),0),0) -> 34.615385
A22: =" Pieces: "&'Pricing Calculator'!$B$14 -> Pieces: St. Louis ribs | B22: =IFERROR(IF(INDEX('Meat Yield & Smoke Schedule'!$B$10:$B$22,MATCH('Pricing Calculator'!$B$14,'Meat Yield & Smoke Schedule'!$A$10:$A$22,0))>0,ROUNDUP(B$21/INDEX('Meat Yield & Smoke Schedule'!$B$10:$B$22,MATCH('Pricing Calculator'!$B$14,'Meat Yield & Smoke Schedule'!$A$10:$A$22,0)),0),0),0) -> 3 | C22: =IFERROR(IF(INDEX('Meat Yield & Smoke Schedule'!$B$10:$B$22,MATCH('Pricing Calculator'!$B$14,'Meat Yield & Smoke Schedule'!$A$10:$A$22,0))>0,ROUNDUP(C$21/INDEX('Meat Yield & Smoke Schedule'!$B$10:$B$22,MATCH('Pricing Calculator'!$B$14,'Meat Yield & Smoke Schedule'!$A$10:$A$22,0)),0),0),0) -> 2 | D22: =IFERROR(IF(INDEX('Meat Yield & Smoke Schedule'!$B$10:$B$22,MATCH('Pricing Calculator'!$B$14,'Meat Yield & Smoke Schedule'!$A$10:$A$22,0))>0,ROUNDUP(D$21/INDEX('Meat Yield & Smoke Schedule'!$B$10:$B$22,MATCH('Pricing Calculator'!$B$14,'Meat Yield & Smoke Schedule'!$A$10:$A$22,0)),0),0),0) -> 4 | E22: =IFERROR(IF(INDEX('Meat Yield & Smoke Schedule'!$B$10:$B$22,MATCH('Pricing Calculator'!$B$14,'Meat Yield & Smoke Schedule'!$A$10:$A$22,0))>0,ROUNDUP(E$21/INDEX('Meat Yield & Smoke Schedule'!$B$10:$B$22,MATCH('Pricing Calculator'!$B$14,'Meat Yield & Smoke Schedule'!$A$10:$A$22,0)),0),0),0) -> 6 | F22: =IFERROR(IF(INDEX('Meat Yield & Smoke Schedule'!$B$10:$B$22,MATCH('Pricing Calculator'!$B$14,'Meat Yield & Smoke Schedule'!$A$10:$A$22,0))>0,ROUNDUP(F$21/INDEX('Meat Yield & Smoke Schedule'!$B$10:$B$22,MATCH('Pricing Calculator'!$B$14,'Meat Yield & Smoke Schedule'!$A$10:$A$22,0)),0),0),0) -> 12
A23: ="Raw lb: "&'Pricing Calculator'!$B$17 -> Raw lb: Chicken thighs (bone-in) | B23: =IFERROR(IF(INDEX('Meat Yield & Smoke Schedule'!$J$10:$J$22,MATCH('Pricing Calculator'!$B$17,'Meat Yield & Smoke Schedule'!$A$10:$A$22,0))>0,B$16*'Pricing Calculator'!$B$18/INDEX('Meat Yield & Smoke Schedule'!$J$10:$J$22,MATCH('Pricing Calculator'!$B$17,'Meat Yield & Smoke Schedule'!$A$10:$A$22,0)),0),0) -> 8.2720588 | C23: =IFERROR(IF(INDEX('Meat Yield & Smoke Schedule'!$J$10:$J$22,MATCH('Pricing Calculator'!$B$17,'Meat Yield & Smoke Schedule'!$A$10:$A$22,0))>0,C$16*'Pricing Calculator'!$B$18/INDEX('Meat Yield & Smoke Schedule'!$J$10:$J$22,MATCH('Pricing Calculator'!$B$17,'Meat Yield & Smoke Schedule'!$A$10:$A$22,0)),0),0) -> 4.4117647 | D23: =IFERROR(IF(INDEX('Meat Yield & Smoke Schedule'!$J$10:$J$22,MATCH('Pricing Calculator'!$B$17,'Meat Yield & Smoke Schedule'!$A$10:$A$22,0))>0,D$16*'Pricing Calculator'!$B$18/INDEX('Meat Yield & Smoke Schedule'!$J$10:$J$22,MATCH('Pricing Calculator'!$B$17,'Meat Yield & Smoke Schedule'!$A$10:$A$22,0)),0),0) -> 8.8235294 | E23: =IFERROR(IF(INDEX('Meat Yield & Smoke Schedule'!$J$10:$J$22,MATCH('Pricing Calculator'!$B$17,'Meat Yield & Smoke Schedule'!$A$10:$A$22,0))>0,E$16*'Pricing Calculator'!$B$18/INDEX('Meat Yield & Smoke Schedule'!$J$10:$J$22,MATCH('Pricing Calculator'!$B$17,'Meat Yield & Smoke Schedule'!$A$10:$A$22,0)),0),0) -> 16.544118 | F23: =IFERROR(IF(INDEX('Meat Yield & Smoke Schedule'!$J$10:$J$22,MATCH('Pricing Calculator'!$B$17,'Meat Yield & Smoke Schedule'!$A$10:$A$22,0))>0,F$16*'Pricing Calculator'!$B$18/INDEX('Meat Yield & Smoke Schedule'!$J$10:$J$22,MATCH('Pricing Calculator'!$B$17,'Meat Yield & Smoke Schedule'!$A$10:$A$22,0)),0),0) -> 33.088235
A24: =" Pieces: "&'Pricing Calculator'!$B$17 -> Pieces: Chicken thighs (bone-in) | B24: =IFERROR(IF(INDEX('Meat Yield & Smoke Schedule'!$B$10:$B$22,MATCH('Pricing Calculator'!$B$17,'Meat Yield & Smoke Schedule'!$A$10:$A$22,0))>0,ROUNDUP(B$23/INDEX('Meat Yield & Smoke Schedule'!$B$10:$B$22,MATCH('Pricing Calculator'!$B$17,'Meat Yield & Smoke Schedule'!$A$10:$A$22,0)),0),0),0) -> 26 | C24: =IFERROR(IF(INDEX('Meat Yield & Smoke Schedule'!$B$10:$B$22,MATCH('Pricing Calculator'!$B$17,'Meat Yield & Smoke Schedule'!$A$10:$A$22,0))>0,ROUNDUP(C$23/INDEX('Meat Yield & Smoke Schedule'!$B$10:$B$22,MATCH('Pricing Calculator'!$B$17,'Meat Yield & Smoke Schedule'!$A$10:$A$22,0)),0),0),0) -> 14 | D24: =IFERROR(IF(INDEX('Meat Yield & Smoke Schedule'!$B$10:$B$22,MATCH('Pricing Calculator'!$B$17,'Meat Yield & Smoke Schedule'!$A$10:$A$22,0))>0,ROUNDUP(D$23/INDEX('Meat Yield & Smoke Schedule'!$B$10:$B$22,MATCH('Pricing Calculator'!$B$17,'Meat Yield & Smoke Schedule'!$A$10:$A$22,0)),0),0),0) -> 27 | E24: =IFERROR(IF(INDEX('Meat Yield & Smoke Schedule'!$B$10:$B$22,MATCH('Pricing Calculator'!$B$17,'Meat Yield & Smoke Schedule'!$A$10:$A$22,0))>0,ROUNDUP(E$23/INDEX('Meat Yield & Smoke Schedule'!$B$10:$B$22,MATCH('Pricing Calculator'!$B$17,'Meat Yield & Smoke Schedule'!$A$10:$A$22,0)),0),0),0) -> 51 | F24: =IFERROR(IF(INDEX('Meat Yield & Smoke Schedule'!$B$10:$B$22,MATCH('Pricing Calculator'!$B$17,'Meat Yield & Smoke Schedule'!$A$10:$A$22,0))>0,ROUNDUP(F$23/INDEX('Meat Yield & Smoke Schedule'!$B$10:$B$22,MATCH('Pricing Calculator'!$B$17,'Meat Yield & Smoke Schedule'!$A$10:$A$22,0)),0),0),0) -> 101
A25: ="Raw lb: "&'Pricing Calculator'!$B$20 -> Raw lb: Sausage (smoked links) | B25: =IFERROR(IF(INDEX('Meat Yield & Smoke Schedule'!$J$10:$J$22,MATCH('Pricing Calculator'!$B$20,'Meat Yield & Smoke Schedule'!$A$10:$A$22,0))>0,B$16*'Pricing Calculator'!$B$21/INDEX('Meat Yield & Smoke Schedule'!$J$10:$J$22,MATCH('Pricing Calculator'!$B$20,'Meat Yield & Smoke Schedule'!$A$10:$A$22,0)),0),0) -> 2.1306818 | C25: =IFERROR(IF(INDEX('Meat Yield & Smoke Schedule'!$J$10:$J$22,MATCH('Pricing Calculator'!$B$20,'Meat Yield & Smoke Schedule'!$A$10:$A$22,0))>0,C$16*'Pricing Calculator'!$B$21/INDEX('Meat Yield & Smoke Schedule'!$J$10:$J$22,MATCH('Pricing Calculator'!$B$20,'Meat Yield & Smoke Schedule'!$A$10:$A$22,0)),0),0) -> 1.1363636 | D25: =IFERROR(IF(INDEX('Meat Yield & Smoke Schedule'!$J$10:$J$22,MATCH('Pricing Calculator'!$B$20,'Meat Yield & Smoke Schedule'!$A$10:$A$22,0))>0,D$16*'Pricing Calculator'!$B$21/INDEX('Meat Yield & Smoke Schedule'!$J$10:$J$22,MATCH('Pricing Calculator'!$B$20,'Meat Yield & Smoke Schedule'!$A$10:$A$22,0)),0),0) -> 2.2727273 | E25: =IFERROR(IF(INDEX('Meat Yield & Smoke Schedule'!$J$10:$J$22,MATCH('Pricing Calculator'!$B$20,'Meat Yield & Smoke Schedule'!$A$10:$A$22,0))>0,E$16*'Pricing Calculator'!$B$21/INDEX('Meat Yield & Smoke Schedule'!$J$10:$J$22,MATCH('Pricing Calculator'!$B$20,'Meat Yield & Smoke Schedule'!$A$10:$A$22,0)),0),0) -> 4.2613636 | F25: =IFERROR(IF(INDEX('Meat Yield & Smoke Schedule'!$J$10:$J$22,MATCH('Pricing Calculator'!$B$20,'Meat Yield & Smoke Schedule'!$A$10:$A$22,0))>0,F$16*'Pricing Calculator'!$B$21/INDEX('Meat Yield & Smoke Schedule'!$J$10:$J$22,MATCH('Pricing Calculator'!$B$20,'Meat Yield & Smoke Schedule'!$A$10:$A$22,0)),0),0) -> 8.5227273
A26: =" Pieces: "&'Pricing Calculator'!$B$20 -> Pieces: Sausage (smoked links) | B26: =IFERROR(IF(INDEX('Meat Yield & Smoke Schedule'!$B$10:$B$22,MATCH('Pricing Calculator'!$B$20,'Meat Yield & Smoke Schedule'!$A$10:$A$22,0))>0,ROUNDUP(B$25/INDEX('Meat Yield & Smoke Schedule'!$B$10:$B$22,MATCH('Pricing Calculator'!$B$20,'Meat Yield & Smoke Schedule'!$A$10:$A$22,0)),0),0),0) -> 9 | C26: =IFERROR(IF(INDEX('Meat Yield & Smoke Schedule'!$B$10:$B$22,MATCH('Pricing Calculator'!$B$20,'Meat Yield & Smoke Schedule'!$A$10:$A$22,0))>0,ROUNDUP(C$25/INDEX('Meat Yield & Smoke Schedule'!$B$10:$B$22,MATCH('Pricing Calculator'!$B$20,'Meat Yield & Smoke Schedule'!$A$10:$A$22,0)),0),0),0) -> 5 | D26: =IFERROR(IF(INDEX('Meat Yield & Smoke Schedule'!$B$10:$B$22,MATCH('Pricing Calculator'!$B$20,'Meat Yield & Smoke Schedule'!$A$10:$A$22,0))>0,ROUNDUP(D$25/INDEX('Meat Yield & Smoke Schedule'!$B$10:$B$22,MATCH('Pricing Calculator'!$B$20,'Meat Yield & Smoke Schedule'!$A$10:$A$22,0)),0),0),0) -> 10 | E26: =IFERROR(IF(INDEX('Meat Yield & Smoke Schedule'!$B$10:$B$22,MATCH('Pricing Calculator'!$B$20,'Meat Yield & Smoke Schedule'!$A$10:$A$22,0))>0,ROUNDUP(E$25/INDEX('Meat Yield & Smoke Schedule'!$B$10:$B$22,MATCH('Pricing Calculator'!$B$20,'Meat Yield & Smoke Schedule'!$A$10:$A$22,0)),0),0),0) -> 18 | F26: =IFERROR(IF(INDEX('Meat Yield & Smoke Schedule'!$B$10:$B$22,MATCH('Pricing Calculator'!$B$20,'Meat Yield & Smoke Schedule'!$A$10:$A$22,0))>0,ROUNDUP(F$25/INDEX('Meat Yield & Smoke Schedule'!$B$10:$B$22,MATCH('Pricing Calculator'!$B$20,'Meat Yield & Smoke Schedule'!$A$10:$A$22,0)),0),0),0) -> 35
A27: Raw meat, all lines (lb) | B27: =B$17+B$19+B$21+B$23+B$25 -> 67.806587 | C27: =C$17+C$19+C$21+C$23+C$25 -> 36.163513 | D27: =D$17+D$19+D$21+D$23+D$25 -> 72.327026 | E27: =E$17+E$19+E$21+E$23+E$25 -> 135.61317 | F27: =F$17+F$19+F$21+F$23+F$25 -> 271.22635
A28: Sides (gallons) | B28: =B$15*$B$5*$B$6/128 -> 4.6875 | C28: =C$15*$B$5*$B$6/128 -> 2.5 | D28: =D$15*$B$5*$B$6/128 -> 5 | E28: =E$15*$B$5*$B$6/128 -> 9.375 | F28: =F$15*$B$5*$B$6/128 -> 18.75 | G28: 1 gallon = 128 oz (3.8 liters).
A29: Sides (half hotel pans) | B29: =ROUNDUP(B$15*$B$5*$B$6/$B$7,0) -> 5 | C29: =ROUNDUP(C$15*$B$5*$B$6/$B$7,0) -> 3 | D29: =ROUNDUP(D$15*$B$5*$B$6/$B$7,0) -> 5 | E29: =ROUNDUP(E$15*$B$5*$B$6/$B$7,0) -> 10 | F29: =ROUNDUP(F$15*$B$5*$B$6/$B$7,0) -> 19
A30: Rolls or bread slices | B30: =ROUNDUP(B$15*$B$8,0) -> 113 | C30: =ROUNDUP(C$15*$B$8,0) -> 60 | D30: =ROUNDUP(D$15*$B$8,0) -> 120 | E30: =ROUNDUP(E$15*$B$8,0) -> 225 | F30: =ROUNDUP(F$15*$B$8,0) -> 450
A31: BBQ sauce (gallons) | B31: =B$15*$B$9/128 -> 1.171875 | C31: =C$15*$B$9/128 -> 0.625 | D31: =D$15*$B$9/128 -> 1.25 | E31: =E$15*$B$9/128 -> 2.34375 | F31: =F$15*$B$9/128 -> 4.6875
A32: Wood or charcoal (lb) | B32: =B$27*'Pricing Calculator'!$B$26 -> 40.683952 | C32: =C$27*'Pricing Calculator'!$B$26 -> 21.698108 | D32: =D$27*'Pricing Calculator'!$B$26 -> 43.396216 | E32: =E$27*'Pricing Calculator'!$B$26 -> 81.367904 | F32: =F$27*'Pricing Calculator'!$B$26 -> 162.73581 | G32: Raw lb × the wood ratio of the "Pricing Calculator" tab.
A33: Butcher paper and foil (ft of roll) | B33: =ROUNDUP(B$27*$B$10,0) -> 102 | C33: =ROUNDUP(C$27*$B$10,0) -> 55 | D33: =ROUNDUP(D$27*$B$10,0) -> 109 | E33: =ROUNDUP(E$27*$B$10,0) -> 204 | F33: =ROUNDUP(F$27*$B$10,0) -> 407
A34: Full hotel pans for the meat | B34: =ROUNDUP(B$16/$B$11,0) -> 3 | C34: =ROUNDUP(C$16/$B$11,0) -> 2 | D34: =ROUNDUP(D$16/$B$11,0) -> 3 | E34: =ROUNDUP(E$16/$B$11,0) -> 5 | F34: =ROUNDUP(F$16/$B$11,0) -> 10
A35: Insulated food carriers or hot boxes | B35: =ROUNDUP(B$34/$B$12,0) -> 1 | C35: =ROUNDUP(C$34/$B$12,0) -> 1 | D35: =ROUNDUP(D$34/$B$12,0) -> 1 | E35: =ROUNDUP(E$34/$B$12,0) -> 2 | F35: =ROUNDUP(F$34/$B$12,0) -> 3 | G35: Keep the meat at 135 °F (57 °C) or above until you serve it.
A36: Pit crew (suggested) | B36: =IF(IFERROR(INDEX('Pricing Calculator'!$D$113:$D$115,MATCH('Pricing Calculator'!$B$5,'Pricing Calculator'!$A$113:$A$115,0)),0)>0,ROUNDUP(B$15/IFERROR(INDEX('Pricing Calculator'!$D$113:$D$115,MATCH('Pricing Calculator'!$B$5,'Pricing Calculator'!$A$113:$A$115,0)),0),0),0) -> 1 | C36: =IF(IFERROR(INDEX('Pricing Calculator'!$D$113:$D$115,MATCH('Pricing Calculator'!$B$5,'Pricing Calculator'!$A$113:$A$115,0)),0)>0,ROUNDUP(C$15/IFERROR(INDEX('Pricing Calculator'!$D$113:$D$115,MATCH('Pricing Calculator'!$B$5,'Pricing Calculator'!$A$113:$A$115,0)),0),0),0) -> 1 | D36: =IF(IFERROR(INDEX('Pricing Calculator'!$D$113:$D$115,MATCH('Pricing Calculator'!$B$5,'Pricing Calculator'!$A$113:$A$115,0)),0)>0,ROUNDUP(D$15/IFERROR(INDEX('Pricing Calculator'!$D$113:$D$115,MATCH('Pricing Calculator'!$B$5,'Pricing Calculator'!$A$113:$A$115,0)),0),0),0) -> 1 | E36: =IF(IFERROR(INDEX('Pricing Calculator'!$D$113:$D$115,MATCH('Pricing Calculator'!$B$5,'Pricing Calculator'!$A$113:$A$115,0)),0)>0,ROUNDUP(E$15/IFERROR(INDEX('Pricing Calculator'!$D$113:$D$115,MATCH('Pricing Calculator'!$B$5,'Pricing Calculator'!$A$113:$A$115,0)),0),0),0) -> 2 | F36: =IF(IFERROR(INDEX('Pricing Calculator'!$D$113:$D$115,MATCH('Pricing Calculator'!$B$5,'Pricing Calculator'!$A$113:$A$115,0)),0)>0,ROUNDUP(F$15/IFERROR(INDEX('Pricing Calculator'!$D$113:$D$115,MATCH('Pricing Calculator'!$B$5,'Pricing Calculator'!$A$113:$A$115,0)),0),0),0) -> 3 | G36: From the package table of the "Pricing Calculator" tab.
A37: Servers and attendants (suggested) | B37: =IF(IFERROR(INDEX('Pricing Calculator'!$C$113:$C$115,MATCH('Pricing Calculator'!$B$5,'Pricing Calculator'!$A$113:$A$115,0)),0)>0,ROUNDUP(B$15/IFERROR(INDEX('Pricing Calculator'!$C$113:$C$115,MATCH('Pricing Calculator'!$B$5,'Pricing Calculator'!$A$113:$A$115,0)),0),0),0) -> 3 | C37: =IF(IFERROR(INDEX('Pricing Calculator'!$C$113:$C$115,MATCH('Pricing Calculator'!$B$5,'Pricing Calculator'!$A$113:$A$115,0)),0)>0,ROUNDUP(C$15/IFERROR(INDEX('Pricing Calculator'!$C$113:$C$115,MATCH('Pricing Calculator'!$B$5,'Pricing Calculator'!$A$113:$A$115,0)),0),0),0) -> 2 | D37: =IF(IFERROR(INDEX('Pricing Calculator'!$C$113:$C$115,MATCH('Pricing Calculator'!$B$5,'Pricing Calculator'!$A$113:$A$115,0)),0)>0,ROUNDUP(D$15/IFERROR(INDEX('Pricing Calculator'!$C$113:$C$115,MATCH('Pricing Calculator'!$B$5,'Pricing Calculator'!$A$113:$A$115,0)),0),0),0) -> 3 | E37: =IF(IFERROR(INDEX('Pricing Calculator'!$C$113:$C$115,MATCH('Pricing Calculator'!$B$5,'Pricing Calculator'!$A$113:$A$115,0)),0)>0,ROUNDUP(E$15/IFERROR(INDEX('Pricing Calculator'!$C$113:$C$115,MATCH('Pricing Calculator'!$B$5,'Pricing Calculator'!$A$113:$A$115,0)),0),0),0) -> 5 | F37: =IF(IFERROR(INDEX('Pricing Calculator'!$C$113:$C$115,MATCH('Pricing Calculator'!$B$5,'Pricing Calculator'!$A$113:$A$115,0)),0)>0,ROUNDUP(F$15/IFERROR(INDEX('Pricing Calculator'!$C$113:$C$115,MATCH('Pricing Calculator'!$B$5,'Pricing Calculator'!$A$113:$A$115,0)),0),0),0) -> 10 | G37: 0 for drop-off.

Sheet 3 Example Quotes
A1: 3 EXAMPLE QUOTES — calculated with the same formulas as the "Pricing Calculator" tab
A2: Kit estimates for illustration. No meat price is typed here: until you type yours, the food cost uses the package estimate per guest, as in the "Pricing Calculator" tab. Each quote lands within 10% of the price of its line in the workbook's example mix ($22 drop-off, $35 party, $52 wedding). Change the inputs in "Pricing Calculator" to price your own events.
A4: INPUTS | B4: Corporate drop-off, 40 guests | C4: Graduation party, staffed buffet, 70 guests | D4: Wedding, 130 guests, full-service + live pit on site
A5: Package | B5: Drop-off (delivered & set, disposable pans) | C5: Full-service BBQ buffet (staffed, carving station) | D5: Full-service BBQ buffet (staffed, carving station)
A6: Guests expected | B6: 40 | C6: 70 | D6: 130
A7: Guest minimum in your contract | B7: 20 | C7: 30 | D7: 75
A8: Meat line 1: cut | B8: Packer brisket (whole, untrimmed) | C8: Packer brisket (whole, untrimmed) | D8: Packer brisket (whole, untrimmed)
A9: Meat line 1: share of the cooked meat | B9: 0.35 | C9: 0.35 | D9: 0.35
A10: Meat line 1: your raw price per lb
A11: Meat line 2: cut | B11: Pork butt (bone-in shoulder) | C11: Pork butt (bone-in shoulder) | D11: Pork butt (bone-in shoulder)
A12: Meat line 2: share of the cooked meat | B12: 0.35 | C12: 0.3 | D12: 0.3
A13: Meat line 2: your raw price per lb
A14: Meat line 3: cut | B14: St. Louis ribs | C14: St. Louis ribs | D14: St. Louis ribs
A15: Meat line 3: share of the cooked meat | B15: 0 | C15: 0.15 | D15: 0.15
A16: Meat line 3: your raw price per lb
A17: Meat line 4: cut | B17: Chicken thighs (bone-in) | C17: Chicken thighs (bone-in) | D17: Chicken thighs (bone-in)
A18: Meat line 4: share of the cooked meat | B18: 0.2 | C18: 0.15 | D18: 0.15
A19: Meat line 4: your raw price per lb
A20: Meat line 5: cut | B20: Sausage (smoked links) | C20: Sausage (smoked links) | D20: Sausage (smoked links)
A21: Meat line 5: share of the cooked meat | B21: 0.1 | C21: 0.05 | D21: 0.05
A22: Meat line 5: your raw price per lb
A23: Sides per guest (mac and cheese, beans, slaw, potato salad) | B23: 2 | C23: 2 | D23: 2
A24: Bread, pickles, onions and BBQ sauce per guest | B24: 0.6 | C24: 0.6 | D24: 0.6
A25: Disposables per guest (pans, plates, cutlery, butcher paper, foil) | B25: 0.75 | C25: 0.75 | D25: 0.75
A26: Wood or charcoal per raw lb of meat (lb) | B26: 0.6 | C26: 0.6 | D26: 0.6
A27: Wood or charcoal cost per lb | B27: 0.15 | C27: 0.15 | D27: 0.15
A28: Live pit on site (smoker trailer at the event)? | B28: No | C28: No | D28: Yes
A29: Live pit on site fee (flat, per event) | B29: 650 | C29: 650 | D29: 650
A30: Pit crew on event day (pitmasters, pit cooks) | B30: 1 | C30: 1 | D30: 2
A31: Servers, buffet attendants and carvers | B31: 0 | C31: 2 | D31: 5
A32: Hours each on event day (loading, travel, setup, service, breakdown) | B32: 4 | C32: 6 | D32: 8
A33: Overnight cook and prep hours (pit cook, total) | B33: 6 | C33: 8 | D33: 10
A34: Pit crew hourly wage | B34: 21 | C34: 21 | D34: 21
A35: Server / attendant hourly wage | B35: 18 | C35: 18 | D35: 18
A36: Employer payroll taxes and workers' comp (% of wages) | B36: 0.1 | C36: 0.1 | D36: 0.1
A37: Rentals passed through (tables, linens, chafing dishes, tent) | B37: 0 | C37: 0 | D37: 600
A38: Round-trip miles | B38: 20 | C38: 30 | D38: 60
A39: Cost per mile (van, or pickup + smoker trailer) | B39: 0.7 | C39: 0.7 | D39: 0.7
A40: Flat event or travel fee charged to the client | B40: 0 | C40: 0 | D40: 0
... A44: Sales tax rate (state + local) | B44: 0.08 | C44: 0.08 | D44: 0.08
...

Sheet Instructions
A1: HOW TO USE THE BBQ CATERING PRICING CALCULATOR
A2: This workbook turns pounds of meat into a price per guest and a full quote, tells you when to start each cook and builds the shopping list. You type only in the GREEN cells; the gross margin is calculated, never typed.
A3: 1. "Pricing Calculator": choose the package (drop-off, full-service BBQ buffet or live-fire premium), the guests and your guest minimum. The package sets the cooked meat per guest: 6 oz for drop-off and 8 oz (half a pound) for the buffet and live-fire, inside the "one-third to one-half pound of meat per guest" of hutchinsbbq.com and the 6-8 oz of sonnybryans.com; 1/4 to 1/3 lb of cooked meat (Dr. BBQ, fieryfoodscentral.com) is the floor.
A4: 2. Pick the cut and the share of each of the five meat lines (they must add up to 100%) and type your raw price per lb for every line you use. The prices are blank on purpose: this kit does not guess 2026 meat prices. While any of them is missing, the food cost uses the package estimate per guest and the "Meat prices" row says so.
A5: 3. Enter sides, bread and sauces, disposables, wood, the live pit on site switch and its fee, your staff (event day and overnight cook hours), rentals and mileage. Then the marketplace fee, your target margin, the service charge, the sales tax rate and the switch "Does your state tax the service charge?". The price per guest is the direct cost divided by (1 - target margin - marketplace fee) and by the billable guests, rounded up to the next 0.50; the live pit fee and any event fee go on top. The tab also shows the same price per cooked lb.
A6: 4. Deposit and cancellation: a 50% nonrefundable deposit books the date (the operators read for this kit ask for it: eventective.com, hutchinsbbq.com) and four cancellation tiers with no gaps tell you what you keep. Put the same tiers in your contract, with a force majeure clause for a county burn ban (propane backup or a new date).
A7: 5. "Meat Yield & Smoke Schedule": the raw weight, pit temperature, quality target, Food Code minimum, cook and rest hours and yield of 13 cuts, and the time to start each cook for your service time. The meat lines of the first tab read their yield and piece weight here: replace the kit estimates with the numbers from your own test cook.
A8: 6. "Shopping List by Guest Count": pounds and pieces per meat line, sides, rolls, sauce, wood, butcher paper, hotel pans, hot boxes and the suggested crew for your event and for 40, 80, 150 and 300 guests.
A9: 7. "3 Example Quotes": three complete quotes calculated with the same formulas. To move from these per-package prices to the average price per guest of the financial projections, weight each package price by its guests in the year.
A10: FOOD SAFETY (FDA FOOD CODE 2022)
A12: Cook to the minimum: 145 °F (63 °C) for 15 seconds for intact meat; 145 °F for 4 minutes for whole roasts; 155 °F (68 °C) for 17 seconds for injected, tenderized or ground meat, sausage included; 165 °F (74 °C) for poultry (3-401.11). Hold hot at 135 °F (57 °C) or above (3-501.16). Cool to 70 °F (21 °C) within 2 hours and to 41 °F (5 °C) within a total of 6 hours (3-501.14). Reheat for hot holding to 165 °F (3-403.11). The quality target of each cut is a different number: see the "Meat Yield & Smoke Schedule" tab.
A13: SERVICE CHARGE, GRATUITY AND SALES TAX (US)
... A29: Planning tool, not financial, tax or legal advice. Requirements vary by state, county and city — check with your accountant and local authorities.
