Workbook

Sheet 0. Supuestos
A1: SUPUESTOS — aquí se teclean las TASAS y los DRIVERS del modelo
A2: Cambia las celdas VERDES: el resto del libro se recalcula solo. Las partidas de gasto se teclean en su hoja (también en verde) y no se repiten aquí.
A3: ACTIVIDAD
A4: Invitados por evento (media del año 1) | B4: 94 | C4: Invitados (raciones) de media por evento en el año 1. Sale de la mezcla de cuatro tipos de evento de la tabla de referencias de la hoja de Instrucciones: bodas de 120, comidas de empresa de 70, fiestas privadas de 40 y fiestas populares de 400 raciones
A5: Precio medio por invitado SIN IVA (€) | B5: 16 | C5: SIN IVA, por ración. Media ponderada de la misma mezcla: 28 € la boda (dos variedades y entrantes), 24 € la comida de empresa, 18 € la fiesta privada y 5 € la ración de una fiesta popular. Por eso la media baja: no es el precio de un menú de boda. El precio con IVA (10 % en un servicio de comidas) está en la fila «PVP equivalente con IVA» de abajo
A6: Eventos al año | B6: 105 | C6: Eventos servidos en el año: 15 bodas, 30 comidas de empresa, 50 fiestas privadas (cumpleaños, comuniones, peñas, urbanizaciones) y 10 fiestas populares. Es el MISMO dato para la cuenta de resultados, el punto de equilibrio, los escenarios y las horas de personal
A7: Crecimiento de volumen del año 2 | B7: 0.1 | C7: Más volumen el segundo año: repetición de empresas, peñas y comisiones de fiestas, y bodas que llegan por recomendación. El libro lo aplica a las raciones por evento con los mismos eventos; en euros da lo mismo que hacer más eventos del mismo tamaño
A8: Crecimiento de volumen del año 3 | B8: 0.06 | C8: Sobre el año 2. Conservador: el techo lo ponen los fines de semana de temporada y un solo paellero titular
A9: PVP equivalente con IVA (calculado) | B9: =IFERROR(IF($B$5="","",$B$5*(1+SUMPRODUCT('PyG 3 Años'!$E$10:$E$11,'PyG 3 Años'!$G$10:$G$11))),"") -> 17.60352 | C9: =IFERROR("Precio por invitado sin IVA más el IVA medio ponderado de tus líneas de venta: "&TEXT(SUMPRODUCT('PyG 3 Años'!$E$10:$E$11,'PyG 3 Años'!$G$10:$G$11)*100,"0")&" %. En el servicio de paella todo va al 10 % (art. 91.Uno.2.2.º de la Ley 37/1992, alcohol incluido); el alcohol que sale en la paella para recoger mueve la media. Aquí va redondeado. Compáralo con el rango del sector, que va con IVA.","") -> Precio por invitado sin IVA más el IVA medio ponderado de tus líneas de venta: 10 %. En el servicio de paella todo va al 10 % (art. 91.Uno.2.2.º de la Ley 37/1992, alcohol incluido); el alcohol que sale en la paella para recoger mueve la media. Aquí va redondeado. Compáralo con el rango del sector, que va con IVA.
A10: MIX Y COSTE DE MERCANCÍA
A11: Ventas de COMIDA sobre el total | B11: 0.92 | C11: Peso de la COMIDA sobre el total de ventas. Es un INPUT: cámbialo aquí y el P&L, la tesorería y el IVA repercutido se recalculan solos
A12: Ventas de BEBIDA sobre el total | B12: =IFERROR(IF(COUNT(B11)=0,"",1-B11),"") -> 0.08 | C12: Se calcula como el resto: comida + bebida = 100 %
A13: Coste de mercancía sobre las ventas de COMIDA | B13: 0.28 | C13: Materia prima de la comida sobre las ventas de comida: arroz, carne, marisco, verdura, caldo, azafrán, aceite, entrantes y pan. En las fiestas populares sube al 45 % (paella sola a precio de volumen); la media de la mezcla queda en el 28 %. Escandalla cada arroz con la calculadora de este kit
A14: Coste de mercancía sobre las ventas de BEBIDA | B14: 0.3 | C14: Bebida sobre las ventas de bebida: el pack opcional de vino, cerveza, refrescos y agua. Si el cliente pone la bebida, esta línea baja
A15: Consumibles sobre ventas | B15: 0.03 | C15: Gas, leña, desechables, hielo y papel: unos 45 € por evento. Una paellera de 90 cm gasta 1-1,5 kg de gas por cocción (propano de 35 kg a 78,80 € en julio de 2026, boletín del IDAE)
A16: Ventas de paella para recoger (sin servicio) sobre el total | B16: 0.05 | C16: Parte de las ventas que se entrega SIN servicio: paella para recoger o entregada en su paellera, sin paellero en el evento. Es entrega de bienes: la comida va al 10 % y el alcohol y los refrescos, zumos y gaseosas con azúcares o edulcorantes añadidos, al 21 % (art. 91.Uno.1.1.º de la Ley 37/1992); el libro lo aplica al alcohol de esta parte
A17: Comisión de la plataforma de pedidos | B17: 0.1 | C17: Comisión media de la parte de la paella para recoger que entra por plataformas de pedidos o intermediarios. Si todos los pedidos los vendes tú, pon 0
A18: Comisión de los medios de pago | B18: 0.005 | C18: Casi todo se cobra por transferencia (anticipos y facturas de empresas y ayuntamientos); el datáfono queda para los cobros del día del evento
A19: PERSONAL
A20: Seguridad Social a cargo de la empresa | B20: 0.33 | C20: Contingencias comunes + AT/EP + desempleo + FOGASA + FP; ajusta a tu convenio y bonificaciones
A21: Número de pagas anuales | B21: 14 | C21: Salario bruto anual = bruto mensual × pagas
A22: SMI anual de referencia (€) | B22: 17094 | C22: SMI 2026: 17.094 € al año (1.221 €/mes en 14 pagas), suelo legal por jornada completa. Comprueba el importe vigente si presentas el plan en otro ejercicio
A23: COCINA DE APOYO Y FIJOS
A24: Cuota mensual de la cocina de apoyo (€) | B24: 900 | C24: Cuota de una cocina de apoyo compartida y autorizada: unas 35 horas al mes para caldos, sofritos y preparación, cámara frigorífica y almacén de paelleras y quemadores. La paella se cocina en el evento, pero lo que se prepara antes no se puede hacer en casa (art. 13.5.b del RD 1021/2022). No hay tarifa pública: pide dos presupuestos en tu zona
A25: Fianza de la cocina de apoyo (meses) | B25: 2 | C25: Dos cuotas de fianza, lo habitual en un contrato de uso de cocina compartida
A26: Suministros mensuales (consumos propios fuera de la cuota) (€) | B26: 50 | C26: Consumos propios fuera de la cuota de la cocina (datos móviles, luz del almacén). El gas de las paellas va en los consumibles, porque sube y baja con los eventos
A27: Seguros (€/año) | B27: 1750 | C27: Responsabilidad civil de explotación con incendio y explosión (por el gas) y daños al recinto, y de producto con intoxicación alimentaria de al menos 600.000 € (unos 700 €); seguro de la furgoneta de uso comercial (900 €) y de los equipos que salen a cada evento (150 €). La cancelación por una prohibición de fuego no se asegura: va en la cláusula de fuerza mayor del contrato
A28: Varios e imprevistos sobre ventas | B28: 0.045 | C28: Combustible de la furgoneta e imprevistos (3 puntos) y el canon que algunas fincas y wedding planners cobran al proveedor externo (1,5 puntos). Es variable: sube y baja con los eventos
A29: FINANCIACIÓN
A30: Recursos propios aportados (€) | B30: 20000 | C30: Aportación del socio. Un banco pide entre el 25 y el 30 % de la necesidad de caja con dinero propio
A31: Préstamo bancario solicitado (€) | B31: 51600 | C31: Principal solicitado. La hoja de Financiación compara lo que aportas con la necesidad de caja de la hoja de inversión y te dice si sobra o falta: ajústalo con ese dato
A32: Tipo de interés nominal anual | B32: 0.065 | C32: Tipo nominal anual de un préstamo de empresa sin garantía inmobiliaria. Pide oferta a dos entidades y a una línea ICO o ENISA antes de fijarlo
A33: Plazo del préstamo (años) | B33: 6 | C33: Años totales, carencia incluida: el plazo de vida de la furgoneta y del equipo
A34: Carencia de principal (años) | B34: 1 | C34: El primer año sólo intereses: es cuando la caja está más tensa, con la agenda de bodas y fiestas aún por llenar. Desde el segundo año se devuelve el principal: mira la holgura de caja de ese año en el Punto de Equilibrio
A35: Fondo de maniobra (meses de costes fijos) | B35: 3 | C35: Tres meses de costes fijos: cubren el invierno (enero, febrero y noviembre son los meses más bajos del año) y los 30 días que tardan en pagar empresas y ayuntamientos
A36: FISCAL
A37: Impuesto de Sociedades, nueva creación | B37: 0.15 | C37: Art. 29.1 LIS: el PRIMER ejercicio con base imponible positiva y el SIGUIENTE. El libro lo aproxima contando los dos primeros ejercicios con base positiva: coincide con la ley salvo que entre ellos haya un ejercicio en pérdidas
A38: Impuesto de Sociedades, tipo general | B38: 0.25 | C38: A partir del tercer ejercicio con base positiva. Es el tipo general del art. 29.1 LIS: si tu cifra de negocios queda por debajo de 1 M € (microempresa) o de 10 M € (reducida dimensión), desde 2025 hay tipos más bajos que se implantan de forma gradual; confirma el de tu ejercicio con tu asesor y cámbialo aquí
A39: IVA repercutido de restauración | B39: 0.1 | C39: Tipo reducido de hostelería
A40: IVA repercutido/soportado general | B40: 0.21 | C40: Tipo general. En este libro lo usan dos cosas: el IVA que soportas al comprar el alcohol (el proveedor lo factura al 21 %) y el que repercutes por el alcohol que sale por paella para recoger (es una entrega de bienes). El alcohol servido en el servicio de paella va al reducido: su tipo está en el bloque de desglose del IVA. Suministros, equipamiento y servicios tienen su tipo en la celda de abajo. El libro manda al general sólo el alcohol: si compras refrescos, zumos y gaseosas con azúcares o edulcorantes añadidos, su factura también va al 21 % (art. 91.Uno.1.1.º de la Ley 37/1992)
...

Sheet Inversión Inicial
A1: PLAN DE NEGOCIO: PAELLERO / PAELLA PARA EVENTOS
A2: Inversión inicial estimada — paella y arroces en directo para eventos
A3: Ajusta las cifras a tu proyecto.
A5: Concepto | B5: Importe | C5: % s/inversión | D5: Notas | E5: ¿Lleva IVA?
A6: INVERSIÓN | B6: =IFERROR(IF(COUNT(B7:B23)=0,"",SUM(B7:B23)),"") -> 42686 | C6: =IFERROR(B6/$B$26,"") -> 0.67636231
A7: Furgoneta isoterma usada con certificado ATP | B7: 18000 | C7: =IFERROR(B7/$B$26,"") -> 0.28521111 | D7: Furgoneta usada con caja isoterma y equipo de frío, con el certificado ATP vigente (RD 237/2000) para llevar carne y marisco. Estimación del kit | E7: Sí
A8: Rotulación, estanterías y anclajes de botellas | B8: 1200 | C8: =IFERROR(B8/$B$26,"") -> 0.019014074 | D8: Rotulación con la marca, estanterías con amarres y anclajes para llevar las botellas de gas en pie y sujetas | E8: Sí
A9: Paelleras de 60 a 150 cm | B9: 2400 | C9: =IFERROR(B9/$B$26,"") -> 0.038028149 | D9: Diez paelleras de 60 a 120 cm y una de 150 cm para fiestas populares (90-120 raciones). Una de 90 cm ronda los 61 € (ManoMano, octubre de 2026) | E9: Sí
A10: Quemadores de anillos, patas y trípodes de leña | B10: 2100 | C10: =IFERROR(B10/$B$26,"") -> 0.03327463 | D10: Quemadores de 2 a 5 anillos con sus patas y dos trípodes para cocinar con leña donde esté permitido | E10: Sí
A11: Gas y seguridad: reguladores, flexibles, extintores y manta ignífuga | B11: 950 | C11: =IFERROR(B11/$B$26,"") -> 0.015052809 | D11: Reguladores, tubos flexibles en fecha, tres extintores de polvo ABC, manta ignífuga, cortavientos y el depósito de los envases de propano | E11: Sí
A12: Neveras, isotermos GN, sondas y acumuladores | B12: 1500 | C12: =IFERROR(B12/$B$26,"") -> 0.023767593 | D12: Cadena de frío del marisco y la carne desde la cocina de apoyo hasta el evento, y sondas para el registro del APPCC | E12: Sí
A13: Carpa, mesas plegables, lavamanos portátil y protector de suelo | B13: 1800 | C13: =IFERROR(B13/$B$26,"") -> 0.028521111 | D13: Zona de cocción bajo carpa, mesa de show cooking, lavamanos para el personal y protector del césped o del pavimento | E13: Sí
A14: Utensilios, ollas de caldo, cuchillería y básculas | B14: 1600 | C14: =IFERROR(B14/$B$26,"") -> 0.025352099 | D14: Paletas, cucharas, ollas de caldo de 50 litros, cuchillería, tablas de colores y básculas | E14: Sí
A15: Uniformes y EPI térmicos | B15: 400 | C15: =IFERROR(B15/$B$26,"") -> 0.0063380248 | D15: Chaquetas, delantales y guantes resistentes al calor | E15: Sí
A16: Marca, web, fotos, dossier y lanzamiento | B16: 4500 | C16: =IFERROR(B16/$B$26,"") -> 0.071302779 | D16: Identidad, web con formulario de presupuesto, sesión de fotos y vídeo, dossier para bodas, empresas y ayuntamientos, y degustaciones de lanzamiento | E16: Sí
A17: Software, tablet y datáfono | B17: 800 | C17: =IFERROR(B17/$B$26,"") -> 0.01267605 | D17: Presupuestos, agenda y facturación conforme a Veri*factu | E17: Sí
A18: Constitución SL + notaría + registro | B18: 1000 | C18: =IFERROR(B18/$B$26,"") -> 0.015845062 | D18: SL unipersonal. Las tasas y el arancel del Registro no llevan IVA; los honorarios del notario y de la gestoría sí: cambia la columna de al lado a «Sí» si tu presupuesto es sobre todo de honorarios | E18: No
... A20: Stock inicial de producto | B20: 1000 | C20: =IFERROR(B20/$B$26,"") -> 0.015845062 | D20: Arroz, especias, aceite, desechables y la primera carga de gas | E20: Sí
A21: Fianza de la cocina de apoyo | B21: =IFERROR(IF('0. Supuestos'!$B$24="","",'0. Supuestos'!$B$24*'0. Supuestos'!$B$25),"") -> 1800 | C21: =IFERROR(B21/$B$26,"") -> 0.028521111 | D21: =IFERROR(""&TEXT('0. Supuestos'!$B$25,"0")&" meses de renta, al tipo de la hoja de Supuestos. Es un activo recuperable al cerrar: ni se amortiza ni lleva IVA","") -> 2 meses de renta, al tipo de la hoja de Supuestos. Es un activo recuperable al cerrar: ni se amortiza ni lleva IVA | E21: No
A22: Cuota de la cocina de apoyo de los meses previos al arranque | B22: =IFERROR(IF('0. Supuestos'!$B$24="","",'0. Supuestos'!$B$24*'0. Supuestos'!$B$54),"") -> 900 | C22: =IFERROR(B22/$B$26,"") -> 0.014260556 | D22: =IFERROR("Renta "&IF('0. Supuestos'!$B$54=1,"del mes","de los "&TEXT('0. Supuestos'!$B$54,"0")&" meses")&" de puesta en marcha (pruebas de arroz y degustaciones). NO se solapa con el P&L, que arranca el día de la apertura: los doce meses del P&L son los doce de explotación","") -> Renta del mes de puesta en marcha (pruebas de arroz y degustaciones). NO se solapa con el P&L, que arranca el día de la apertura: los doce meses del P&L son los doce de explotación | E22: Sí
A23: Imprevistos de la compra y preparación de la furgoneta | B23: =IFERROR(IF(COUNT(B7,B8)=0,"",ROUND((B7+B8)*'0. Supuestos'!$B$55,0)),"") -> 1536 | C23: =IFERROR(B23/$B$26,"") -> 0.024338015 | D23: =IFERROR("Al "&TEXT('0. Supuestos'!$B$55,"0%")&" de las partidas de la furgoneta de este bloque (Furgoneta isoterma usada con certificado ATP y Rotulación, estanterías y anclajes de botellas), no del bloque entero: el resto de partidas del bloque quedan fuera. Un banco no financia una compra así sin colchón: el porcentaje está en la hoja de Supuestos","") -> Al 8% de las partidas de la furgoneta de este bloque (Furgoneta isoterma usada con certificado ATP y Rotulación, estanterías y anclajes de botellas), no del bloque entero: el resto de partidas del bloque quedan fuera. Un banco no financia una compra así sin colchón: el porcentaje está en la hoja de Supuestos | E23: Sí
A24: FONDO DE MANIOBRA | B24: =IFERROR(IF(B25="","",B25),"") -> 20425.145 | C24: =IFERROR(B24/$B$26,"") -> 0.32363769
A25: Colchón operativo hasta alcanzar el equilibrio | B25: =IFERROR(IF('0. Supuestos'!$B$35*('PyG 3 Años'!$B$38-'PyG 3 Años'!$B$36)=0,"",'0. Supuestos'!$B$35*('PyG 3 Años'!$B$38-'PyG 3 Años'!$B$36)/12),"") -> 20425.145 | C25: =IFERROR(B25/$B$26,"") -> 0.32363769 | D25: =IFERROR("Cubre "&TEXT('0. Supuestos'!$B$35,"0")&IF('0. Supuestos'!$B$35=1," mes"," meses")&" de costes fijos DE CAJA del año 1 (los del P&L menos la amortización, que no se paga), que es el mínimo que exigen las Instrucciones de este libro","") -> Cubre 3 meses de costes fijos DE CAJA del año 1 (los del P&L menos la amortización, que no se paga), que es el mínimo que exigen las Instrucciones de este libro | E25: No
A26: INVERSIÓN TOTAL (suma de los bloques) | B26: =IFERROR(B6+B24,"") -> 63111.145 | D26: =IFERROR("Los porcentajes de la columna C se leen sobre esta cifra, que incluye el fondo de maniobra ("&TEXT(C24,"0%")&" del total). Para comparar el desglose con otro plan, usa la fila de CAPEX de abajo.","") -> Los porcentajes de la columna C se leen sobre esta cifra, que incluye el fondo de maniobra (32% del total). Para comparar el desglose con otro plan, usa la fila de CAPEX de abajo.
A27: CAPEX (inversión sin el fondo de maniobra) | B27: =IFERROR(B26-B24,"") -> 42686 | D27: Es lo que se compra: furgoneta, equipamiento, lanzamiento y gastos de constitución. El colchón de caja no es inversión, es circulante
A28: IVA soportado sobre la inversión (recuperable) | B28: =IFERROR(IF(B26="","",SUMIF($E$7:$E$23,"Sí",$B$7:$B$23)*'0. Supuestos'!$B$41),"") -> 8376.06 | D28: =IFERROR("Al "&TEXT('0. Supuestos'!$B$41,"0%")&" sobre las partidas marcadas con «Sí» en la columna de IVA. Las tasas y licencias no están sujetas y los seguros están exentos (art. 20.Uno.16 LIVA). Las tasas y aranceles registrales no llevan IVA; los honorarios de notaría y gestoría sí (21 %, deducible). Se recupera con el modelo 303, pero hay que adelantarlo","") -> Al 21% sobre las partidas marcadas con «Sí» en la columna de IVA. Las tasas y licencias no están sujetas y los seguros están exentos (art. 20.Uno.16 LIVA). Las tasas y aranceles registrales no llevan IVA; los honorarios de notaría y gestoría sí (21 %, deducible). Se recupera con el modelo 303, pero hay que adelantarlo
A29: NECESIDAD TOTAL DE CAJA AL ARRANQUE | B29: =IFERROR(B26+B28,"") -> 71487.205 | D29: Es la cifra que tiene que cubrir la hoja de Financiación
A30: BASES DE AMORTIZACIÓN (no suman a la inversión)
A31: Furgoneta, rotulación e imprevistos | B31: =IFERROR(IF(B7="","",B7+B8+B23),"") -> 20736 | D31: =IFERROR("Se amortiza en "&TEXT('0. Supuestos'!$B$44,"0")&" años","") -> Se amortiza en 8 años
A32: Maquinaria, mobiliario y equipos | B32: =IFERROR(IF(B9="","",B9+B10+B11+B12+B13+B14+B15+B17),"") -> 11550 | D32: =IFERROR("Se amortiza en "&TEXT('0. Supuestos'!$B$45,"0")&" años","") -> Se amortiza en 10 años
A33: Amortización anual del inmovilizado | B33: =IFERROR(B31/MAX(1,'0. Supuestos'!$B$44)+B32/MAX(1,'0. Supuestos'!$B$45),"") -> 3747 | D33: =IFERROR("No se amortizan, por no ser inmovilizado, Marca, web, fotos, dossier y lanzamiento, Constitución SL + notaría + registro, Declaración responsable, plan APPCC, alérgenos y formación, Stock inicial de producto, Fianza de la cocina de apoyo, Cuota de la cocina de apoyo de los meses previos al arranque ni Colchón operativo hasta alcanzar el equilibrio. Suman "&TEXT(B26-B31-B32,"0")&" € de los "&TEXT(B26,"0")&" € de inversión.","") -> No se amortizan, por no ser inmovilizado, Marca, web, fotos, dossier y lanzamiento, Constitución SL + notaría + registro, Declaración responsable, plan APPCC, alérgenos y formación, Stock inicial de producto, Fianza de la cocina de apoyo, Cuota de la cocina de apoyo de los meses previos al arranque ni Colchón operativo hasta alcanzar el equilibrio. Suman 30825 € de los 63111 € de inversión.

Sheet PyG 3 Años
A1: CUENTA DE RESULTADOS PREVISIONAL — 3 AÑOS
A2: Escenario realista — paellero para eventos
A4: Concepto | B4: Año 1 | C4: Año 2 | D4: Año 3 | E4: % s/ventas (año 1) | F4: Notas | G4: Tipo de IVA de la línea (%)
A5: INGRESOS
A6: Invitados por evento (media) | B6: =IFERROR(IF('0. Supuestos'!$B$4="","",'0. Supuestos'!$B$4),"") -> 94 | C6: =IFERROR(B6*(1+'0. Supuestos'!$B$7),"") -> 103.4 | D6: =IFERROR(C6*(1+'0. Supuestos'!$B$8),"") -> 109.604 | F6: El crecimiento de los años 2 y 3 está en la hoja de Supuestos
A7: Precio medio por invitado sin IVA | B7: =IFERROR(IF('0. Supuestos'!$B$5="","",'0. Supuestos'!$B$5),"") -> 16 | C7: =IFERROR(IF(B7="","",B7),"") -> 16 | D7: =IFERROR(IF(C7="","",C7),"") -> 16 | F7: Constante en euros del año 1: una subida de precios es una decisión aparte
A8: Eventos al año | B8: =IFERROR(IF('0. Supuestos'!$B$6="","",'0. Supuestos'!$B$6),"") -> 105 | C8: =IFERROR(IF(B8="","",B8),"") -> 105 | D8: =IFERROR(IF(C8="","",C8),"") -> 105
A9: INGRESOS TOTALES (sin IVA) | B9: =IFERROR(IF(B6*B7*B8=0,"",B6*B7*B8),"") -> 157920 | C9: =IFERROR(IF(C6*C7*C8=0,"",C6*C7*C8),"") -> 173712 | D9: =IFERROR(IF(D6*D7*D8=0,"",D6*D7*D8),"") -> 184134.72 | E9: =IFERROR(IF(B9="","",1),"") -> 1
A10: Ventas de comida (paellas y arroces en directo, entrantes y postre) | B10: =IFERROR(IF(B9="","",B9*$E$10),"") -> 145286.4 | C10: =IFERROR(IF(C9="","",C9*$E$10),"") -> 159815.04 | D10: =IFERROR(IF(D9="","",D9*$E$10),"") -> 169403.94 | E10: =IFERROR(IF('0. Supuestos'!$B$11="","",'0. Supuestos'!$B$11),"") -> 0.92 | F10: Paellas y arroces cocinados en el evento, con show cooking cuando se contrata, entrantes, pan, alioli y postre. Las fiestas populares son paella sola por ración | G10: =IFERROR(IF(B9="","",'0. Supuestos'!$B$39),"") -> 0.1
A11: Ventas de bebida (pack opcional de vino, cerveza y refrescos) | B11: =IFERROR(IF(B9="","",B9*$E$11),"") -> 12633.6 | C11: =IFERROR(IF(C9="","",C9*$E$11),"") -> 13896.96 | D11: =IFERROR(IF(D9="","",D9*$E$11),"") -> 14730.778 | E11: =IFERROR(IF('0. Supuestos'!$B$12="","",'0. Supuestos'!$B$12),"") -> 0.08 | F11: Pack de bebida que algunos clientes contratan con la paella; en muchas fiestas la bebida la pone el cliente | G11: =IFERROR(IF(B9="","",('0. Supuestos'!$B$62*((1-'0. Supuestos'!$B$16)*'0. Supuestos'!$B$63+'0. Supuestos'!$B$16*'0. Supuestos'!$B$40)+(1-'0. Supuestos'!$B$62)*'0. Supuestos'!$B$39)),"") -> 0.10275
A12: COSTES VARIABLES
A13: Coste de mercancía — comida | B13: =IFERROR(IF(B9="","",B9*'0. Supuestos'!$B$11*'0. Supuestos'!$B$13),"") -> 40680.192 | C13: =IFERROR(IF(C9="","",C9*'0. Supuestos'!$B$11*'0. Supuestos'!$B$13),"") -> 44748.211 | D13: =IFERROR(IF(D9="","",D9*'0. Supuestos'!$B$11*'0. Supuestos'!$B$13),"") -> 47433.104 | E13: =IFERROR(B13/$B$9,"") -> 0.2576 | F13: =IFERROR("Al "&TEXT('0. Supuestos'!$B$13,"0%")&" de las ventas de COMIDA, no del total: la bebida tiene su propia línea","") -> Al 28% de las ventas de COMIDA, no del total: la bebida tiene su propia línea | G13: =IFERROR(IF(B9="","",'0. Supuestos'!$B$39),"") -> 0.1
A14: Coste de mercancía — bebida | B14: =IFERROR(IF(B9="","",B9*'0. Supuestos'!$B$12*'0. Supuestos'!$B$14),"") -> 3790.08 | C14: =IFERROR(IF(C9="","",C9*'0. Supuestos'!$B$12*'0. Supuestos'!$B$14),"") -> 4169.088 | D14: =IFERROR(IF(D9="","",D9*'0. Supuestos'!$B$12*'0. Supuestos'!$B$14),"") -> 4419.2333 | E14: =IFERROR(B14/$B$9,"") -> 0.024 | F14: =IFERROR("Al "&TEXT('0. Supuestos'!$B$14,"0%")&" de las ventas de BEBIDA","") -> Al 30% de las ventas de BEBIDA | G14: =IFERROR(IF(B9="","",('0. Supuestos'!$B$62*'0. Supuestos'!$B$40+(1-'0. Supuestos'!$B$62)*'0. Supuestos'!$B$39)),"") -> 0.155
A15: Consumibles y envases | B15: =IFERROR(IF(B9="","",B9*'0. Supuestos'!$B$15),"") -> 4737.6 | C15: =IFERROR(IF(C9="","",C9*'0. Supuestos'!$B$15),"") -> 5211.36 | D15: =IFERROR(IF(D9="","",D9*'0. Supuestos'!$B$15),"") -> 5524.0416 | E15: =IFERROR(B15/$B$9,"") -> 0.03 | G15: =IFERROR(IF(B9="","",'0. Supuestos'!$B$41),"") -> 0.21
A16: Comisiones de la paella para recoger | B16: =IFERROR(IF(B9="","",B9*'0. Supuestos'!$B$16*'0. Supuestos'!$B$17),"") -> 789.6 | C16: =IFERROR(IF(C9="","",C9*'0. Supuestos'!$B$16*'0. Supuestos'!$B$17),"") -> 868.56 | D16: =IFERROR(IF(D9="","",D9*'0. Supuestos'!$B$16*'0. Supuestos'!$B$17),"") -> 920.6736 | E16: =IFERROR(B16/$B$9,"") -> 0.005 | F16: Sobre las ventas DEL CANAL. Con 0 % de paella para recoger en Supuestos, esta línea vale cero | G16: =IFERROR(IF(B9="","",'0. Supuestos'!$B$41),"") -> 0.21
A17: Comisiones de los medios de pago | B17: =IFERROR(IF(B9="","",B9*'0. Supuestos'!$B$18),"") -> 789.6 | C17: =IFERROR(IF(C9="","",C9*'0. Supuestos'!$B$18),"") -> 868.56 | D17: =IFERROR(IF(D9="","",D9*'0. Supuestos'!$B$18),"") -> 920.6736 | E17: =IFERROR(B17/$B$9,"") -> 0.005 | F17: Las comisiones de los medios de pago están EXENTAS de IVA (art. 20.Uno.18 LIVA): no se deduce nada por ellas | G17: 0
A18: Varios e imprevistos | B18: =IFERROR(IF(B9="","",B9*'0. Supuestos'!$B$28),"") -> 7106.4 | C18: =IFERROR(IF(C9="","",C9*'0. Supuestos'!$B$28),"") -> 7817.04 | D18: =IFERROR(IF(D9="","",D9*'0. Supuestos'!$B$28),"") -> 8286.0624 | E18: =IFERROR(B18/$B$9,"") -> 0.045 | F18: =IFERROR("Al "&TEXT('0. Supuestos'!$B$28,"0%")&" de las ventas. Es un coste VARIABLE: sube y baja con la facturación, así que no puede vivir en los costes fijos","") -> Al 4% de las ventas. Es un coste VARIABLE: sube y baja con la facturación, así que no puede vivir en los costes fijos | G18: =IFERROR(IF(B9="","",'0. Supuestos'!$B$41),"") -> 0.21
A19: TOTAL COSTES VARIABLES | B19: =IFERROR(IF(B9="","",SUM(B13:B18)),"") -> 57893.472 | C19: =IFERROR(IF(C9="","",SUM(C13:C18)),"") -> 63682.819 | D19: =IFERROR(IF(D9="","",SUM(D13:D18)),"") -> 67503.788 | E19: =IFERROR(B19/$B$9,"") -> 0.3666
A20: MARGEN BRUTO | B20: =IFERROR(IF(B9="","",B9-B19),"") -> 100026.53 | C20: =IFERROR(IF(C9="","",C9-C19),"") -> 110029.18 | D20: =IFERROR(IF(D9="","",D9-D19),"") -> 116630.93 | E20: =IFERROR(B20/$B$9,"") -> 0.6334
A21: COSTES FIJOS
A22: Cuota de la cocina de apoyo compartida | B22: =IFERROR(IF(B9="","",'0. Supuestos'!$B$24*12),"") -> 10800 | C22: =IFERROR(IF(C9="","",B22*(1+'0. Supuestos'!$B$48)),"") -> 10800 | D22: =IFERROR(IF(D9="","",C22*(1+'0. Supuestos'!$B$48)),"") -> 10800 | E22: =IFERROR(B22/$B$9,"") -> 0.068389058 | F22: El importe mensual está en la hoja de Supuestos; aquí se multiplica por doce. Es el contrato de uso de una cocina de apoyo compartida y autorizada (horas de cocina, cámara y almacén de paelleras y quemadores). El mes previo al primer evento está en la hoja de Inversión y NO se cuenta dos veces | G22: =IFERROR(IF(B9="","",'0. Supuestos'!$B$41),"") -> 0.21
A23: Personal (nóminas + Seguridad Social) | B23: =IFERROR(IF(B9="","",'Personal'!$G$9),"") -> 55096.58 | C23: =IFERROR(IF(C9="","",'Personal'!$B$13),"") -> 61096.58 | D23: =IFERROR(IF(D9="","",'Personal'!$B$14),"") -> 67096.58 | E23: =IFERROR(B23/$B$9,"") -> 0.34888918 | F23: Sale de la hoja de Personal: es el MISMO número, no una estimación aparte. Los años 2 y 3 suman las INCORPORACIONES declaradas en esa hoja, no un porcentaje de volumen | G23: 0
A24: Suministros (consumos propios fuera de la cuota) | B24: =IFERROR(IF(B9="","",'0. Supuestos'!$B$26*12),"") -> 600 | C24: =IFERROR(IF(C9="","",B24*(1+'0. Supuestos'!$B$48)),"") -> 600 | D24: =IFERROR(IF(D9="","",C24*(1+'0. Supuestos'!$B$48)),"") -> 600 | E24: =IFERROR(B24/$B$9,"") -> 0.0037993921 | F24: Consumos propios fuera de la cuota de la cocina. El gas de las paellas va en los consumibles. Va al 21 % de IVA | G24: =IFERROR(IF(B9="","",'0. Supuestos'!$B$41),"") -> 0.21
A25: Seguros (RC + multirriesgo) | B25: =IFERROR(IF(B9="","",'0. Supuestos'!$B$27),"") -> 1750 | C25: =IFERROR(IF(C9="","",B25*(1+'0. Supuestos'!$B$48)),"") -> 1750 | D25: =IFERROR(IF(D9="","",C25*(1+'0. Supuestos'!$B$48)),"") -> 1750 | E25: =IFERROR(B25/$B$9,"") -> 0.01108156 | F25: Las operaciones de seguro están EXENTAS de IVA (art. 20.Uno.16 LIVA): la prima no lleva IVA deducible | G25: 0
A26: Asesoría fiscal y laboral (nóminas de fijos discontinuos) | B26: 1800 | C26: =IFERROR(IF(C9="","",B26*(1+'0. Supuestos'!$B$48)),"") -> 1800 | D26: =IFERROR(IF(D9="","",C26*(1+'0. Supuestos'!$B$48)),"") -> 1800 | E26: =IFERROR(B26/$B$9,"") -> 0.011398176 | F26: Contabilidad, impuestos de la SL y nóminas de los fijos discontinuos de cada mes con llamamientos | G26: =IFERROR(IF(B9="","",'0. Supuestos'!$B$41),"") -> 0.21
A27: Furgoneta: mantenimiento, ITV e inspección ATP | B27: 1200 | C27: =IFERROR(IF(C9="","",B27*(1+'0. Supuestos'!$B$48)),"") -> 1200 | D27: =IFERROR(IF(D9="","",C27*(1+'0. Supuestos'!$B$48)),"") -> 1200 | E27: =IFERROR(B27/$B$9,"") -> 0.0075987842 | F27: Taller, neumáticos, ITV y la inspección periódica del certificado ATP del equipo de frío (RD 237/2000) | G27: =IFERROR(IF(B9="","",'0. Supuestos'!$B$41),"") -> 0.21
A28: Marketing y publicidad | B28: 4000 | C28: =IFERROR(IF(C9="","",B28*(1+'0. Supuestos'!$B$48)),"") -> 4000 | D28: =IFERROR(IF(D9="","",C28*(1+'0. Supuestos'!$B$48)),"") -> 4000 | E28: =IFERROR(B28/$B$9,"") -> 0.025329281 | F28: Google Ads local, un escaparate de bodas, redes sociales y una feria al año | G28: =IFERROR(IF(B9="","",'0. Supuestos'!$B$41),"") -> 0.21
A29: Software de gestión comercial, CRM y teléfono | B29: 900 | C29: =IFERROR(IF(C9="","",B29*(1+'0. Supuestos'!$B$48)),"") -> 900 | D29: =IFERROR(IF(D9="","",C29*(1+'0. Supuestos'!$B$48)),"") -> 900 | E29: =IFERROR(B29/$B$9,"") -> 0.0056990881 | F29: Presupuestos, agenda de eventos, CRM de clientes y línea de teléfono | G29: =IFERROR(IF(B9="","",'0. Supuestos'!$B$41),"") -> 0.21
A30: Revisión de gas por instaladora y mantenimiento de extintores | B30: 400 | C30: =IFERROR(IF(C9="","",B30*(1+'0. Supuestos'!$B$48)),"") -> 400 | D30: =IFERROR(IF(D9="","",C30*(1+'0. Supuestos'!$B$48)),"") -> 400 | E30: =IFERROR(B30/$B$9,"") -> 0.0025329281 | F30: Revisión de reguladores, flexibles y quemadores por una empresa instaladora de gas y mantenimiento anual de los extintores por una empresa mantenedora. Estimación del kit | G30: =IFERROR(IF(B9="","",'0. Supuestos'!$B$41),"") -> 0.21
A31: Uniformes y lavandería | B31: 400 | C31: =IFERROR(IF(C9="","",B31*(1+'0. Supuestos'!$B$48)),"") -> 400 | D31: =IFERROR(IF(D9="","",C31*(1+'0. Supuestos'!$B$48)),"") -> 400 | E31: =IFERROR(B31/$B$9,"") -> 0.0025329281 | F31: Chaquetas, delantales y paños: lavado y reposición | G31: =IFERROR(IF(B9="","",'0. Supuestos'!$B$41),"") -> 0.21
A32: Gestión de residuos (orgánico y aceite usado) | B32: 200 | C32: =IFERROR(IF(C9="","",B32*(1+'0. Supuestos'!$B$48)),"") -> 200 | D32: =IFERROR(IF(D9="","",C32*(1+'0. Supuestos'!$B$48)),"") -> 200 | E32: =IFERROR(B32/$B$9,"") -> 0.001266464 | F32: Gestor autorizado del aceite usado, salvo que la cocina de apoyo lo incluya en la cuota | G32: =IFERROR(IF(B9="","",'0. Supuestos'!$B$41),"") -> 0.21
A33: Prevención de riesgos laborales y vigilancia de la salud | B33: 400 | C33: =IFERROR(IF(C9="","",B33*(1+'0. Supuestos'!$B$48)),"") -> 400 | D33: =IFERROR(IF(D9="","",C33*(1+'0. Supuestos'!$B$48)),"") -> 400 | E33: =IFERROR(B33/$B$9,"") -> 0.0025329281 | F33: Plan de prevención obligatorio (Ley 31/1995): quemaduras, gas, calor y cargas, y reconocimientos médicos de la plantilla | G33: =IFERROR(IF(B9="","",'0. Supuestos'!$B$41),"") -> 0.21
A34: Pruebas de arroz y degustaciones comerciales | B34: 600 | C34: =IFERROR(IF(C9="","",B34*(1+'0. Supuestos'!$B$48)),"") -> 600 | D34: =IFERROR(IF(D9="","",C34*(1+'0. Supuestos'!$B$48)),"") -> 600 | E34: =IFERROR(B34/$B$9,"") -> 0.0037993921 | F34: Producto y horas de las pruebas para novios y de las degustaciones a empresas y comisiones de fiestas que no se cobran | G34: =IFERROR(IF(B9="","",'0. Supuestos'!$B$41),"") -> 0.21
A35: Permisos y autorizaciones municipales | B35: 200 | C35: =IFERROR(IF(C9="","",B35*(1+'0. Supuestos'!$B$48)),"") -> 200 | D35: =IFERROR(IF(D9="","",C35*(1+'0. Supuestos'!$B$48)),"") -> 200 | E35: =IFERROR(B35/$B$9,"") -> 0.001266464 | F35: Autorizaciones de ocupación de la vía pública o de uso del fuego y tasas que no repercutes al cliente. Estimación del kit: varía mucho por municipio | G35: =IFERROR(IF(B9="","",'0. Supuestos'!$B$41),"") -> 0.21
A36: Amortización del inmovilizado | B36: =IFERROR(IF(B9="","",'Inversión Inicial'!$B$33),"") -> 3747 | C36: =IFERROR(IF(C9="","",B36),"") -> 3747 | D36: =IFERROR(IF(D9="","",B36),"") -> 3747 | E36: =IFERROR(B36/$B$9,"") -> 0.023727204 | F36: Sale de las bases de amortización de la hoja de Inversión: sólo inmovilizado real. NO sube con el IPC: es una cuota sobre el coste HISTÓRICO del inmovilizado | G36: 0
A37: Gastos financieros (intereses del préstamo) | B37: =IFERROR(IF(B9="","",'Financiación'!$B$44),"") -> 3354 | C37: =IFERROR(IF(C9="","",'Financiación'!$B$46),"") -> 3354 | D37: =IFERROR(IF(D9="","",'Financiación'!$B$48),"") -> 2764.9218 | E37: =IFERROR(B37/$B$9,"") -> 0.021238602 | F37: Sólo los INTERESES son gasto. La devolución del principal va en la hoja de Tesorería | G37: 0
A38: TOTAL COSTES FIJOS | B38: =IFERROR(IF(B9="","",SUM(B22:B37)),"") -> 85447.58 | C38: =IFERROR(IF(C9="","",SUM(C22:C37)),"") -> 91447.58 | D38: =IFERROR(IF(D9="","",SUM(D22:D37)),"") -> 96858.502 | E38: =IFERROR(B38/$B$9,"") -> 0.54108143
A39: IVA soportado de los costes variables | B39: =IFERROR(IF(B9="","",SUMPRODUCT(B13:B18,G13:G18)),"") -> 7308.5376 | C39: =IFERROR(IF(C9="","",SUMPRODUCT(C13:C18,G13:G18)),"") -> 8039.3914 | D39: =IFERROR(IF(D9="","",SUMPRODUCT(D13:D18,G13:G18)),"") -> 8521.7548 | F39: Cada línea a SU tipo, leído de la columna de al lado. Es lo que la hoja de Tesorería paga de más a los proveedores y luego se deduce
A40: IVA soportado de los costes fijos | B40: =IFERROR(IF(B9="","",SUMPRODUCT(B22:B37,G22:G37)),"") -> 4515 | C40: =IFERROR(IF(C9="","",SUMPRODUCT(C22:C37,G22:G37)),"") -> 4515 | D40: =IFERROR(IF(D9="","",SUMPRODUCT(D22:D37,G22:G37)),"") -> 4515
A41: RESULTADO ANTES DE IMPUESTOS | B41: =IFERROR(IF(B9="","",B20-B38),"") -> 14578.948 | C41: =IFERROR(IF(C9="","",C20-C38),"") -> 18581.601 | D41: =IFERROR(IF(D9="","",D20-D38),"") -> 19772.43 | E41: =IFERROR(B41/$B$9,"") -> 0.092318566
...

Sheet Punto Equilibrio
A1: ANÁLISIS DE PUNTO DE EQUILIBRIO
A2: Punto de equilibrio — paellero para eventos
A4: Variable | B4: Año 1 | C4: Año 2 | D4: Año 3 | E4: Notas
A5: DATOS BASE POR AÑO
A6: Costes fijos anuales | B6: =IFERROR(IF('PyG 3 Años'!$B$9="","",'PyG 3 Años'!$B$38),"") -> 85447.58 | C6: =IFERROR(IF('PyG 3 Años'!$C$9="","",'PyG 3 Años'!$C$38),"") -> 91447.58 | D6: =IFERROR(IF('PyG 3 Años'!$D$9="","",'PyG 3 Años'!$D$38),"") -> 96858.502 | E6: Los MISMOS costes fijos del P&L. Cada año tiene los suyos: por eso el umbral no puede ser uno solo para los tres
A7: Costes fijos mensuales | B7: =IFERROR(IF('PyG 3 Años'!$B$9="","",B6/12),"") -> 7120.6317 | C7: =IFERROR(IF('PyG 3 Años'!$C$9="","",C6/12),"") -> 7620.6317 | D7: =IFERROR(IF('PyG 3 Años'!$D$9="","",D6/12),"") -> 8071.5418
A8: Precio medio por invitado sin IVA | B8: =IFERROR(IF('PyG 3 Años'!$B$9="","",'PyG 3 Años'!$B$7),"") -> 16 | C8: =IFERROR(IF('PyG 3 Años'!$C$9="","",'PyG 3 Años'!$C$7),"") -> 16 | D8: =IFERROR(IF('PyG 3 Años'!$D$9="","",'PyG 3 Años'!$D$7),"") -> 16
A9: Coste variable por invitado | B9: =IFERROR(IF('PyG 3 Años'!$B$9="","",'PyG 3 Años'!$B$19/('PyG 3 Años'!$B$6*'PyG 3 Años'!$B$8)),"") -> 5.8656 | C9: =IFERROR(IF('PyG 3 Años'!$C$9="","",'PyG 3 Años'!$C$19/('PyG 3 Años'!$C$6*'PyG 3 Años'!$C$8)),"") -> 5.8656 | D9: =IFERROR(IF('PyG 3 Años'!$D$9="","",'PyG 3 Años'!$D$19/('PyG 3 Años'!$D$6*'PyG 3 Años'!$D$8)),"") -> 5.8656 | E9: Sale del total de costes variables del P&L, no de una estimación aparte. Incluye los varios e imprevistos, que son un porcentaje de las ventas
A10: Margen de contribución por invitado | B10: =IFERROR(IF('PyG 3 Años'!$B$9="","",B8-B9),"") -> 10.1344 | C10: =IFERROR(IF('PyG 3 Años'!$C$9="","",C8-C9),"") -> 10.1344 | D10: =IFERROR(IF('PyG 3 Años'!$D$9="","",D8-D9),"") -> 10.1344 | E10: Precio por invitado menos coste variable unitario
A11: Eventos al año | B11: =IFERROR(IF('PyG 3 Años'!$B$9="","",'PyG 3 Años'!$B$8),"") -> 105 | C11: =IFERROR(IF('PyG 3 Años'!$C$9="","",'PyG 3 Años'!$C$8),"") -> 105 | D11: =IFERROR(IF('PyG 3 Años'!$D$9="","",'PyG 3 Años'!$D$8),"") -> 105 | E11: El mismo calendario que el P&L y que los escenarios
A12: Devolución de principal del año (cuota) | B12: =IFERROR(IF('PyG 3 Años'!$B$9="","",'Financiación'!$B$45),"") -> 0 | C12: =IFERROR(IF('PyG 3 Años'!$C$9="","",'Financiación'!$B$47),"") -> 9062.7421 | D12: =IFERROR(IF('PyG 3 Años'!$D$9="","",'Financiación'!$B$49),"") -> 9651.8204 | E12: El principal NO es gasto del P&L, pero sale de la caja. Sin él, el umbral de equilibrio se publica por debajo del real
A13: PUNTO DE EQUILIBRIO CONTABLE (incluye amortización)
A14: Invitados necesarios al año | B14: =IFERROR(IF('PyG 3 Años'!$B$9="","",IF(B10<=0,"",B6/B10)),"") -> 8431.4395 | C14: =IFERROR(IF('PyG 3 Años'!$C$9="","",IF(C10<=0,"",C6/C10)),"") -> 9023.4824 | D14: =IFERROR(IF('PyG 3 Años'!$D$9="","",IF(D10<=0,"",D6/D10)),"") -> 9557.3987
A15: Invitados necesarios por evento | B15: =IFERROR(IF('PyG 3 Años'!$B$9="","",B14/B11),"") -> 80.299423 | C15: =IFERROR(IF('PyG 3 Años'!$C$9="","",C14/C11),"") -> 85.937928 | D15: =IFERROR(IF('PyG 3 Años'!$D$9="","",D14/D11),"") -> 91.022845
A16: Ingresos necesarios al año | B16: =IFERROR(IF('PyG 3 Años'!$B$9="","",B14*B8),"") -> 134903.03 | C16: =IFERROR(IF('PyG 3 Años'!$C$9="","",C14*C8),"") -> 144375.72 | D16: =IFERROR(IF('PyG 3 Años'!$D$9="","",D14*D8),"") -> 152918.38
A17: PUNTO DE EQUILIBRIO DE CAJA (incluye la cuota del préstamo)
A18: Costes fijos de caja + principal del año | B18: =IFERROR(IF('PyG 3 Años'!$B$9="","",B6-'PyG 3 Años'!$B$36+B12),"") -> 81700.58 | C18: =IFERROR(IF('PyG 3 Años'!$C$9="","",C6-'PyG 3 Años'!$C$36+C12),"") -> 96763.322 | D18: =IFERROR(IF('PyG 3 Años'!$D$9="","",D6-'PyG 3 Años'!$D$36+D12),"") -> 102763.32 | E18: Los fijos del P&L sin la amortización (que no se paga) y CON la devolución de principal (que sí). Es el umbral que decide si la caja aguanta
A19: Invitados necesarios al año (caja) | B19: =IFERROR(IF('PyG 3 Años'!$B$9="","",IF(B10<=0,"",B18/B10)),"") -> 8061.7086 | C19: =IFERROR(IF('PyG 3 Años'!$C$9="","",IF(C10<=0,"",C18/C10)),"") -> 9548.007 | D19: =IFERROR(IF('PyG 3 Años'!$D$9="","",IF(D10<=0,"",D18/D10)),"") -> 10140.05
A20: Invitados necesarios por evento (caja) | B20: =IFERROR(IF('PyG 3 Años'!$B$9="","",B19/B11),"") -> 76.778177 | C20: =IFERROR(IF('PyG 3 Años'!$C$9="","",C19/C11),"") -> 90.9334 | D20: =IFERROR(IF('PyG 3 Años'!$D$9="","",D19/D11),"") -> 96.571904
A21: Ingresos necesarios al año (caja) | B21: =IFERROR(IF('PyG 3 Años'!$B$9="","",B19*B8),"") -> 128987.34 | C21: =IFERROR(IF('PyG 3 Años'!$C$9="","",C19*C8),"") -> 152768.11 | D21: =IFERROR(IF('PyG 3 Años'!$D$9="","",D19*D8),"") -> 162240.8
A22: CONTRASTE CON EL PLAN
A23: Invitados por evento previstos en el plan | B23: =IFERROR(IF('PyG 3 Años'!$B$9="","",'PyG 3 Años'!$B$6),"") -> 94 | C23: =IFERROR(IF('PyG 3 Años'!$C$9="","",'PyG 3 Años'!$C$6),"") -> 103.4 | D23: =IFERROR(IF('PyG 3 Años'!$D$9="","",'PyG 3 Años'!$D$6),"") -> 109.604
A24: Holgura sobre el equilibrio de CAJA (%) | B24: =IFERROR(IF('PyG 3 Años'!$B$9="","",B23/B20-1),"") -> 0.22430622 | C24: =IFERROR(IF('PyG 3 Años'!$C$9="","",C23/C20-1),"") -> 0.13709594 | D24: =IFERROR(IF('PyG 3 Años'!$D$9="","",D23/D20-1),"") -> 0.13494707 | E24: Cuánto puedes caer antes de no poder pagar los costes fijos y la cuota. El mínimo exigible está en la hoja de Supuestos
A25: INTERPRETACIÓN
A26: =IFERROR("Con el precio medio por invitado sin IVA de la fila de arriba necesitas "&TEXT(ROUNDUP(B15,0),"0")&" invitados por evento durante los "&TEXT(B11,"0")&" eventos del año para no perder dinero (equilibrio contable, con la amortización dentro), y "&TEXT(ROUNDUP(B20,0),"0")&" para que la caja aguante (equilibrio de caja: sin la amortización, que no se paga, y con la cuota del préstamo del año"&IF(B12=0,"; este año sólo intereses, porque el préstamo está en carencia","")&"). En las filas «Ingresos necesarios al año» tienes esas mismas cifras en euros.","") -> Con el precio medio por invitado sin IVA de la fila de arriba necesitas 81 invitados por evento durante los 105 eventos del año para no perder dinero (equilibrio contable, con la amortización dentro), y 77 para que la caja aguante (equilibrio de caja: sin la amortización, que no se paga, y con la cuota del préstamo del año; este año sólo intereses, porque el préstamo está en carencia). En las filas «Ingresos necesarios al año» tienes esas mismas cifras en euros.
A28: SENSIBILIDAD DEL PUNTO DE EQUILIBRIO
A29: Invitados por evento necesarios para cubrir costes según el precio medio por invitado (columnas) y el coste variable por invitado (filas). En verde, los que están por debajo de los invitados que prevé el plan.
A31: Invitados por evento necesarios: precio medio por invitado sin IVA (columnas) × coste variable por invitado (filas) | B31: =IFERROR($B$8-2,"") -> 14 | C31: =IFERROR(IF($B$8="","",$B$8),"") -> 16 | D31: =IFERROR($B$8+2,"") -> 18 | E31: =IFERROR($B$8+4,"") -> 20
A32: =IFERROR($B$9*0.85,"") -> 4.98576 | B32: =IFERROR(IF($B$31-$A32<=0,"",$B$6/($B$31-$A32)/$B$11),"") -> 90.27788 | C32: =IFERROR(IF($C$31-$A32<=0,"",$B$6/($C$31-$A32)/$B$11),"") -> 73.884941 | D32: =IFERROR(IF($D$31-$A32<=0,"",$B$6/($D$31-$A32)/$B$11),"") -> 62.530465 | E32: =IFERROR(IF($E$31-$A32<=0,"",$B$6/($E$31-$A32)/$B$11),"") -> 54.200977
A33: =IFERROR($B$9*0.925,"") -> 5.42568 | B33: =IFERROR(IF($B$31-$A33<=0,"",$B$6/($B$31-$A33)/$B$11),"") -> 94.909739 | C33: =IFERROR(IF($C$31-$A33<=0,"",$B$6/($C$31-$A33)/$B$11),"") -> 76.958753 | D33: =IFERROR(IF($D$31-$A33<=0,"",$B$6/($D$31-$A33)/$B$11),"") -> 64.71813 | E33: =IFERROR(IF($E$31-$A33<=0,"",$B$6/($E$31-$A33)/$B$11),"") -> 55.837012
A34: =IFERROR($B$9*1.0,"") -> 5.8656 | B34: =IFERROR(IF($B$31-$A34<=0,"",$B$6/($B$31-$A34)/$B$11),"") -> 100.04259 | C34: =IFERROR(IF($C$31-$A34<=0,"",$B$6/($C$31-$A34)/$B$11),"") -> 80.299423 | D34: =IFERROR(IF($D$31-$A34<=0,"",$B$6/($D$31-$A34)/$B$11),"") -> 67.064418 | E34: =IFERROR(IF($E$31-$A34<=0,"",$B$6/($E$31-$A34)/$B$11),"") -> 57.574887
A35: =IFERROR($B$9*1.075,"") -> 6.30552 | B35: =IFERROR(IF($B$31-$A35<=0,"",$B$6/($B$31-$A35)/$B$11),"") -> 105.76237 | C35: =IFERROR(IF($C$31-$A35<=0,"",$B$6/($C$31-$A35)/$B$11),"") -> 83.943283 | D35: =IFERROR(IF($D$31-$A35<=0,"",$B$6/($D$31-$A35)/$B$11),"") -> 69.587231 | E35: =IFERROR(IF($E$31-$A35<=0,"",$B$6/($E$31-$A35)/$B$11),"") -> 59.424416
A36: =IFERROR($B$9*1.15,"") -> 6.74544 | B36: =IFERROR(IF($B$31-$A36<=0,"",$B$6/($B$31-$A36)/$B$11),"") -> 112.17586 | C36: =IFERROR(IF($C$31-$A36<=0,"",$B$6/($C$31-$A36)/$B$11),"") -> 87.933567 | D36: =IFERROR(IF($D$31-$A36<=0,"",$B$6/($D$31-$A36)/$B$11),"") -> 72.307267 | E36: =IFERROR(IF($E$31-$A36<=0,"",$B$6/($E$31-$A36)/$B$11),"") -> 61.396718

Sheet Escenarios
A1: ANÁLISIS DE ESCENARIOS
A4: Métrica | B4: Pesimista | C4: Realista | D4: Optimista | E4: Notas
A5: Invitados por evento | B5: 85 | C5: =IFERROR(IF('PyG 3 Años'!$B$6="","",'PyG 3 Años'!$B$6),"") -> 94 | D5: 100
A6: Precio medio por invitado sin IVA | B6: 15 | C6: =IFERROR(IF('PyG 3 Años'!$B$7="","",'PyG 3 Años'!$B$7),"") -> 16 | D6: 17
A7: Eventos al año | B7: 85 | C7: =IFERROR(IF('PyG 3 Años'!$B$8="","",'PyG 3 Años'!$B$8),"") -> 105 | D7: 125
A8: INGRESOS ANUALES (sin IVA) | B8: =IFERROR(IF(B5*B6*B7=0,"",B5*B6*B7),"") -> 108375 | C8: =IFERROR(IF(C5*C6*C7=0,"",C5*C6*C7),"") -> 157920 | D8: =IFERROR(IF(D5*D6*D7=0,"",D5*D6*D7),"") -> 212500
A9: Coste de mercancía — comida | B9: =IFERROR(IF(B8="","",B8*'0. Supuestos'!$B$11*'0. Supuestos'!$B$13),"") -> 27917.4 | C9: =IFERROR(IF(C8="","",C8*'0. Supuestos'!$B$11*'0. Supuestos'!$B$13),"") -> 40680.192 | D9: =IFERROR(IF(D8="","",D8*'0. Supuestos'!$B$11*'0. Supuestos'!$B$13),"") -> 54740
A10: Coste de mercancía — bebida | B10: =IFERROR(IF(B8="","",B8*'0. Supuestos'!$B$12*'0. Supuestos'!$B$14),"") -> 2601 | C10: =IFERROR(IF(C8="","",C8*'0. Supuestos'!$B$12*'0. Supuestos'!$B$14),"") -> 3790.08 | D10: =IFERROR(IF(D8="","",D8*'0. Supuestos'!$B$12*'0. Supuestos'!$B$14),"") -> 5100
A11: Consumibles y envases | B11: =IFERROR(IF(B8="","",B8*'0. Supuestos'!$B$15),"") -> 3251.25 | C11: =IFERROR(IF(C8="","",C8*'0. Supuestos'!$B$15),"") -> 4737.6 | D11: =IFERROR(IF(D8="","",D8*'0. Supuestos'!$B$15),"") -> 6375
A12: Comisiones de la paella para recoger | B12: =IFERROR(IF(B8="","",B8*'0. Supuestos'!$B$16*'0. Supuestos'!$B$17),"") -> 541.875 | C12: =IFERROR(IF(C8="","",C8*'0. Supuestos'!$B$16*'0. Supuestos'!$B$17),"") -> 789.6 | D12: =IFERROR(IF(D8="","",D8*'0. Supuestos'!$B$16*'0. Supuestos'!$B$17),"") -> 1062.5
A13: Comisiones de los medios de pago | B13: =IFERROR(IF(B8="","",B8*'0. Supuestos'!$B$18),"") -> 541.875 | C13: =IFERROR(IF(C8="","",C8*'0. Supuestos'!$B$18),"") -> 789.6 | D13: =IFERROR(IF(D8="","",D8*'0. Supuestos'!$B$18),"") -> 1062.5
A14: Varios e imprevistos | B14: =IFERROR(IF(B8="","",B8*'0. Supuestos'!$B$28),"") -> 4876.875 | C14: =IFERROR(IF(C8="","",C8*'0. Supuestos'!$B$28),"") -> 7106.4 | D14: =IFERROR(IF(D8="","",D8*'0. Supuestos'!$B$28),"") -> 9562.5
A15: TOTAL COSTES VARIABLES | B15: =IFERROR(IF(B8="","",SUM(B9:B14)),"") -> 39730.275 | C15: =IFERROR(IF(C8="","",SUM(C9:C14)),"") -> 57893.472 | D15: =IFERROR(IF(D8="","",SUM(D9:D14)),"") -> 77902.5
A16: MARGEN BRUTO | B16: =IFERROR(IF(B8="","",B8-B15),"") -> 68644.725 | C16: =IFERROR(IF(C8="","",C8-C15),"") -> 100026.53 | D16: =IFERROR(IF(D8="","",D8-D15),"") -> 134597.5
A17: COSTES FIJOS (los del P&L) | B17: =IFERROR(IF(B8="","",'PyG 3 Años'!$B$38),"") -> 85447.58 | C17: =IFERROR(IF(C8="","",'PyG 3 Años'!$B$38),"") -> 85447.58 | D17: =IFERROR(IF(D8="","",'PyG 3 Años'!$B$38),"") -> 85447.58 | E17: Los costes fijos no cambian con el escenario: por eso son fijos
A18: RESULTADO ANTES DE IMPUESTOS | B18: =IFERROR(IF(B8="","",B16-B17),"") -> -16802.855 | C18: =IFERROR(IF(C8="","",C16-C17),"") -> 14578.948 | D18: =IFERROR(IF(D8="","",D16-D17),"") -> 49149.92
A19: Impuesto de Sociedades | B19: =IFERROR(IF(B8="","",MAX(0,B18-'0. Supuestos'!$B$42)*'0. Supuestos'!$B$37),"") -> 0 | C19: =IFERROR(IF(C8="","",MAX(0,C18-'0. Supuestos'!$B$42)*'0. Supuestos'!$B$37),"") -> 2186.8422 | D19: =IFERROR(IF(D8="","",MAX(0,D18-'0. Supuestos'!$B$42)*'0. Supuestos'!$B$37),"") -> 7372.488 | E19: Al tipo de entidad de nueva creación, compensando las bases negativas anteriores
A20: RESULTADO NETO | B20: =IFERROR(IF(B8="","",B18-B19),"") -> -16802.855 | C20: =IFERROR(IF(C8="","",C18-C19),"") -> 12392.106 | D20: =IFERROR(IF(D8="","",D18-D19),"") -> 41777.432
A21: Invitados por evento para el equilibrio | B21: =IFERROR(IF(B8="","",IF(B6-B15/(B5*B7)<=0,"",B17/(B6-B15/(B5*B7))/B7)),"") -> 105.8063 | C21: =IFERROR(IF(C8="","",IF(C6-C15/(C5*C7)<=0,"",C17/(C6-C15/(C5*C7))/C7)),"") -> 80.299423 | D21: =IFERROR(IF(D8="","",IF(D6-D15/(D5*D7)<=0,"",D17/(D6-D15/(D5*D7))/D7)),"") -> 63.483779
A22: LO QUE CADA ESCENARIO EXIGE
A23: Coste de personal / Ventas | B23: =IFERROR(IF(B8="","",'PyG 3 Años'!$B$23/B8),"") -> 0.50838828 | C23: =IFERROR(IF(C8="","",'PyG 3 Años'!$B$23/C8),"") -> 0.34888918 | D23: =IFERROR(IF(D8="","",'PyG 3 Años'!$B$23/D8),"") -> 0.25927802 | E23: La MISMA plantilla en los tres escenarios. Si en el pesimista se dispara, el ajuste hay que hacerlo en la hoja de Personal, no aquí
A24: Invitados al año por jornada equivalente | B24: =IFERROR(IF(B8="","",B5*B7/'Personal'!$C$9),"") -> 3991.7127 | C24: =IFERROR(IF(C8="","",C5*C7/'Personal'!$C$9),"") -> 5453.0387 | D24: =IFERROR(IF(D8="","",D5*D7/'Personal'!$C$9),"") -> 6906.0773 | E24: Raciones que tendría que servir cada jornada completa del cuadro de Personal. En el optimista dice si hace falta contratar
A25: Saldo de caja al cierre del año 1 (estimado, el mismo método en los tres escenarios) | B25: =IFERROR(IF(B8="","",'Inversión Inicial'!$B$25+B20+'PyG 3 Años'!$B$36-'Financiación'!$B$45),"") -> 7369.29 | C25: =IFERROR(IF(C8="","",'Inversión Inicial'!$B$25+C20+'PyG 3 Años'!$B$36-'Financiación'!$B$45),"") -> 36564.251 | D25: =IFERROR(IF(D8="","",'Inversión Inicial'!$B$25+D20+'PyG 3 Años'!$B$36-'Financiación'!$B$45),"") -> 65949.577 | E25: Saldo ESTIMADO: fondo de maniobra más el resultado del año, devolviendo la amortización (que no se paga) y restando el principal del préstamo. No incluye el desfase de cobros y pagos ni la liquidación del IVA, así que las tres columnas se pueden comparar entre sí. En rojo, el escenario se queda sin caja
A26: Saldo real del mes 12 de la hoja de Tesorería (sólo realista) | C26: =IFERROR(IF(C8="","",'Tesorería 12 meses'!$M$22),"") -> 37724.78 | E26: El saldo REAL del caso base, con su desfase de cobros y pagos y su liquidación de IVA. Sólo existe para el escenario realista, que es el único con tesorería mensual propia: por eso no está en la fila de arriba, donde se compararía contra dos estimaciones
A28: La columna «Realista» lee sus tres datos de la hoja de Supuestos, así que reproduce EXACTAMENTE el año 1 del P&L. Los otros dos escenarios usan las mismas tasas de coste: lo único que cambia son los invitados, el precio por invitado y los eventos. Los COSTES FIJOS sí son los mismos en los tres: los varios e imprevistos, que son un porcentaje de las ventas, van arriba con los variables y cada escenario carga los suyos.

Sheet Personal
A1: ESTRUCTURA DE PERSONAL Y COSTES
A2: =IFERROR("Convenio Hostelería — "&TEXT('0. Supuestos'!$B$21,"0")&" pagas + SS "&TEXT('0. Supuestos'!$B$20*100,"0")&" %","") -> Convenio Hostelería — 14 pagas + SS 33 %
A4: Puesto | B4: Personas | C4: Jornada | D4: Bruto mes (€, total del puesto) | E4: Seg. Social a cargo de la empresa (€) | F4: Coste mes (€, total del puesto) | G4: Coste año (€) | H4: Horas/semana por persona | I4: Horas/año del puesto | J4: Notas
A5: Propietario/a — paellero titular, ventas y compras | B5: 1 | C5: 1 | D5: 1800 | E5: =IFERROR(IF(D5="","",D5*'0. Supuestos'!$B$20),"") -> 594 | F5: =IFERROR(IF(D5="","",D5+E5),"") -> 2394 | G5: =IFERROR(IF(D5="","",F5*MAX(12,'0. Supuestos'!$B$21)),"") -> 33516 | H5: =IFERROR(IF(D5="","",C5*$B$16),"") -> 40 | I5: =IFERROR(IF(D5="","",H5*B5*$B$17),"") -> 1840 | J5: Cocina en cada evento, vende, compra el producto y lleva la agenda. Como administrador de la SL cotiza en el régimen de autónomos: confirma con tu gestoría la cuota y si te aplica la reducida de inicio
A6: Ayudante de cocina y 2.º paellero (fijo discontinuo) | B6: 1 | C6: 0.65 | D6: 943 | E6: =IFERROR(IF(D6="","",D6*'0. Supuestos'!$B$20),"") -> 311.19 | F6: =IFERROR(IF(D6="","",D6+E6),"") -> 1254.19 | G6: =IFERROR(IF(D6="","",F6*MAX(12,'0. Supuestos'!$B$21)),"") -> 17558.66 | H6: =IFERROR(IF(D6="","",C6*$B$16),"") -> 26 | I6: =IFERROR(IF(D6="","",H6*B6*$B$17),"") -> 1196 | J6: Contrato fijo discontinuo (art. 16 del Estatuto de los Trabajadores) al 65 % de jornada en cómputo anual: caldos y preparación en la cocina de apoyo, montaje, fuegos y la segunda tanda de paelleras. Bruto a jornada completa: 1.450 € en 14 pagas
A7: Auxiliar de evento: montaje y caldo (fijo discontinuo) | B7: 1 | C7: 0.08 | D7: 108 | E7: =IFERROR(IF(D7="","",D7*'0. Supuestos'!$B$20),"") -> 35.64 | F7: =IFERROR(IF(D7="","",D7+E7),"") -> 143.64 | G7: =IFERROR(IF(D7="","",F7*MAX(12,'0. Supuestos'!$B$21)),"") -> 2010.96 | H7: =IFERROR(IF(D7="","",C7*$B$16),"") -> 3.2 | I7: =IFERROR(IF(D7="","",H7*B7*$B$17),"") -> 147.2 | J7: Llamado para las bodas y las fiestas populares (unas 140 horas al año). Bruto a jornada completa: 1.350 €. Nunca como autónomo que te factura: con tu horario y tu dirección es falso autónomo (art. 1.1 ET)
A8: Auxiliar de evento: emplatado y servicio (fijo discontinuo) | B8: 1 | C8: 0.08 | D8: 108 | E8: =IFERROR(IF(D8="","",D8*'0. Supuestos'!$B$20),"") -> 35.64 | F8: =IFERROR(IF(D8="","",D8+E8),"") -> 143.64 | G8: =IFERROR(IF(D8="","",F8*MAX(12,'0. Supuestos'!$B$21)),"") -> 2010.96 | H8: =IFERROR(IF(D8="","",C8*$B$16),"") -> 3.2 | I8: =IFERROR(IF(D8="","",H8*B8*$B$17),"") -> 147.2 | J8: Mismo contrato y mismas horas que el anterior: sirve la paella, repone y recoge. Por encima del SMI en proporción a su jornada
A9: TOTAL PLANTILLA | B9: =IFERROR(IF(COUNT(D5:D8)=0,"",SUM(B5:B8)),"") -> 4 | C9: =IFERROR(IF(COUNT(D5:D8)=0,"",SUM(C5:C8)),"") -> 1.81 | D9: =IFERROR(IF(COUNT(D5:D8)=0,"",SUM(D5:D8)),"") -> 2959 | E9: =IFERROR(IF(COUNT(D5:D8)=0,"",SUM(E5:E8)),"") -> 976.47 | F9: =IFERROR(IF(COUNT(D5:D8)=0,"",SUM(F5:F8)),"") -> 3935.47 | G9: =IFERROR(IF(COUNT(D5:D8)=0,"",SUM(G5:G8)),"") -> 55096.58 | I9: =IFERROR(IF(COUNT(D5:D8)=0,"",SUM(I5:I8)),"") -> 3330.4
A10: CRECIMIENTO DE LA PLANTILLA (coste escalonado)
A11: Coste anual de las incorporaciones del año 2 (€) | B11: 6000 | J11: Coste ANUAL completo (bruto + Seguridad Social × pagas) de lo que se contrate ese año. El P&L lo suma al coste del año anterior: la plantilla no crece con un porcentaje, crece con personas
A12: Coste anual de las incorporaciones del año 3 (€) | B12: 6000 | J12: Coste ANUAL completo (bruto + Seguridad Social × pagas) de lo que se contrate ese año. El P&L lo suma al coste del año anterior: la plantilla no crece con un porcentaje, crece con personas
A13: Coste de personal del año 2 | B13: =IFERROR(IF(G9="","",G9*(1+'0. Supuestos'!$B$48)+B11),"") -> 61096.58
A14: Coste de personal del año 3 | B14: =IFERROR(IF(B13="","",B13*(1+'0. Supuestos'!$B$48)+B12),"") -> 67096.58
A15: COBERTURA POR HORAS DE SERVICIO
A16: Jornada completa del convenio (horas/semana) | B16: 40 | J16: Art. 34.1 del Estatuto de los Trabajadores; tu convenio provincial puede fijar menos
A17: Semanas trabajadas al año por persona | B17: 46 | J17: 46 semanas: 52 menos las vacaciones (30 días naturales, art. 38 ET), los festivos y las ausencias medias
A18: Horas de trabajo por evento que hay que cubrir | B18: 8 | J18: Horas por evento y persona: carga, viaje, montaje, encendido, cocción, servicio, recogida y descarga. Los caldos y la preparación en la cocina de apoyo van aparte
A19: Personas necesarias a la vez en cada evento | B19: 2 | J19: Personas trabajando a la vez en un evento medio de 94 raciones: el paellero titular y el ayudante. En bodas y fiestas populares entran uno o dos auxiliares: súbelo y la hoja te dice si llega la plantilla
A20: Horas de servicio a cubrir al año | B20: =IFERROR(IF(OR(B18="",B19="",'0. Supuestos'!$B$6=""),"",B18*B19*'0. Supuestos'!$B$6),"") -> 1680
A21: Horas contratadas al año | B21: =IFERROR(IF(I9="","",I9),"") -> 3330.4
A22: Cobertura (contratadas / necesarias) | B22: =IFERROR(B21/B20,"") -> 1.982381 | J22: Por debajo del 100 % la plantilla no llega a cubrir el horario que declara el plan: o se contrata más o se recorta el horario
A24: Las columnas «Bruto mes», «Seg. Social», «Coste mes» y «Coste año» son TOTALES de la fila: en un puesto con dos personas incluyen a las dos. «Jornada» es el porcentaje sobre la jornada completa del convenio y sirve para comparar el salario con el suelo legal en proporción. El tipo de Seguridad Social y el número de pagas están en la hoja «0. Supuestos».
A25: El suelo salarial es el MAYOR entre el SMI y el salario de convenio, los dos en la hoja «0. Supuestos»; las jornadas parciales lo llevan en proporción. El convenio aplicable es el PROVINCIAL de hostelería: no existe una tabla salarial estatal única, así que la celda del convenio se entrega vacía para que copies la de tu provincia.

Sheet Instrucciones
A1: INSTRUCCIONES DE USO — Plan financiero Paellero / Paella para Eventos
A3: CÓMO SE USA ESTE LIBRO
A4: Este plan financiero es un MODELO: sólo se teclea en las celdas VERDES y el resto se recalcula solo.
A5: 1. «0. Supuestos» es la hoja de mando: invitados, precio por invitado sin IVA, eventos, mezcla de comida y bebida, coste de mercancía, alquiler, financiación e impuestos.
A6: 2. Las partidas de la inversión, los costes fijos y la plantilla se teclean en su propia hoja, también en verde. Ningún número se escribe dos veces.
A7: 3. Sólo «Punto Equilibrio» se deriva entera de lo anterior. En las otras tres hojas también hay celdas verdes que puedes tocar: el escenario pesimista y el optimista en «Escenarios», la estacionalidad y la rampa de arranque en «Tesorería 12 meses», y las cuatro fuentes alternativas de financiación en «Financiación». Todo lo demás se calcula.
A8: 4. Todas las cifras van SIN IVA. Para pasar un PVP a precio sin IVA, divide por el tipo que le corresponda: entre 1,10 en el servicio de paella (comida y bebida, alcohol incluido: art. 91.Uno.2.2.º de la Ley 37/1992 del IVA) y, cuando se venden para llevar, los alimentos, que son productos alimenticios al tipo reducido por el art. 91.Uno.1.1.º; y entre 1,21 el tipo general, que en hostelería sólo alcanza a lo que sale de la cocina de apoyo como entrega de bienes excluida del reducido: el alcohol y los refrescos, zumos y gaseosas con azúcares o edulcorantes añadidos para llevar o a domicilio (la comida para llevar sigue al 10 %); el libro lo aplica al alcohol del canal de paella para recoger. El tipo de cada línea de venta está en la columna «Tipo de IVA de la línea» del P&L y de ahí salen los cobros, el IVA repercutido y el PVP equivalente. El IVA de la inversión se adelanta y se recupera con el modelo 303.
A9: 5. Si cambias la plantilla, el P&L la lee sola: el coste de personal sale de la hoja «Personal», no de una estimación aparte.
A10: 6. La hoja «Tesorería 12 meses» responde la pregunta que decide una operación bancaria: en qué mes se agota la caja. El saldo mínimo del año nunca puede salir en rojo. Los anticipos de los particulares (30 % al firmar) no se modelan: tu caja real será algo mejor.
A11: 7. La hoja «Financiación» cuadra lo que hace falta con lo que se aporta y monta el cuadro de amortización del préstamo. Si la diferencia sale en rojo, el plan no está financiado.
A12: 8. El documento Word de este pack y la calculadora de precios usan las cifras de este Excel: si cambias una celda verde, el Excel manda.
A14: RATIOS QUE AUDITA EL LIBRO
A15: Los umbrales viven en la columna «Umbral» del bloque RATIOS CLAVE del P&L: cámbialos ahí y el semáforo cambia con ellos.
A17: Ratio | B17: Valor del año 1 | C17: Umbral | D17: Estado
A18: Coste de mercancía / Ventas | B18: =IFERROR(IF('PyG 3 Años'!$B$53="","",'PyG 3 Años'!$B$53),"") -> 0.2816 | C18: =IFERROR(IF('PyG 3 Años'!$E$53="","",'PyG 3 Años'!$E$53),"") -> 0.32 | D18: =IFERROR(IF(OR(B18="",C18=""),"",IF(B18<=C18,"CUMPLE","REVISAR")),"") -> CUMPLE
A19: Coste de personal / Ventas | B19: =IFERROR(IF('PyG 3 Años'!$B$54="","",'PyG 3 Años'!$B$54),"") -> 0.34888918 | C19: =IFERROR(IF('PyG 3 Años'!$E$54="","",'PyG 3 Años'!$E$54),"") -> 0.38 | D19: =IFERROR(IF(OR(B19="",C19=""),"",IF(B19<=C19,"CUMPLE","REVISAR")),"") -> CUMPLE
A20: Cocina de apoyo / Ventas | B20: =IFERROR(IF('PyG 3 Años'!$B$55="","",'PyG 3 Años'!$B$55),"") -> 0.068389058 | C20: =IFERROR(IF('PyG 3 Años'!$E$55="","",'PyG 3 Años'!$E$55),"") -> 0.08 | D20: =IFERROR(IF(OR(B20="",C20=""),"",IF(B20<=C20,"CUMPLE","REVISAR")),"") -> CUMPLE
A21: Resultado neto / Ventas | B21: =IFERROR(IF('PyG 3 Años'!$B$56="","",'PyG 3 Años'!$B$56),"") -> 0.078470781 | C21: =IFERROR(IF('PyG 3 Años'!$E$56="","",'PyG 3 Años'!$E$56),"") -> 0.04 | D21: =IFERROR(IF(OR(B21="",C21=""),"",IF(B21>=C21,"CUMPLE","REVISAR")),"") -> CUMPLE
A22: Margen bruto / Ventas | B22: =IFERROR(IF('PyG 3 Años'!$B$51="","",'PyG 3 Años'!$B$51),"") -> 0.6334 | C22: =IFERROR(IF('PyG 3 Años'!$E$51="","",'PyG 3 Años'!$E$51),"") -> 0.6 | D22: =IFERROR(IF(OR(B22="",C22=""),"",IF(B22>=C22,"CUMPLE","REVISAR")),"") -> CUMPLE
A24: CIFRAS DE ESTE PLAN
A25: Inversión total (suma de los bloques) | B25: =IFERROR(IF('Inversión Inicial'!$B$26="","",'Inversión Inicial'!$B$26),"") -> 63111.145
A26: Necesidad total de caja al arranque | B26: =IFERROR(IF('Inversión Inicial'!$B$29="","",'Inversión Inicial'!$B$29),"") -> 71487.205
A27: Fondo de maniobra dotado | B27: =IFERROR(IF('Inversión Inicial'!$B$25="","",'Inversión Inicial'!$B$25),"") -> 20425.145
A28: Facturación prevista del año 1 | B28: =IFERROR(IF('PyG 3 Años'!$B$9="","",'PyG 3 Años'!$B$9),"") -> 157920
A29: Resultado neto del año 1 | B29: =IFERROR(IF('PyG 3 Años'!$B$48="","",'PyG 3 Años'!$B$48),"") -> 12392.106
A30: Invitados por evento para el punto de equilibrio CONTABLE (con la amortización dentro) | B30: =IFERROR(IF('Punto Equilibrio'!$B$15="","",'Punto Equilibrio'!$B$15),"") -> 80.299423
A31: Payback del proyecto (años), antes de la deuda | B31: =IFERROR(IF('Tesorería 12 meses'!$B$31="","",'Tesorería 12 meses'!$B$31),"") -> 3
A33: QUÉ HA CAMBIADO RESPECTO DE LA VERSIÓN 1.2
A34: Concepto | B34: v1.2 | C34: v2.2 | D34: Por qué
A35: Modelo de ingresos | B35: eventos y tickets medios tecleados, con un margen neto irreal (la mitad de las ventas) | C35: invitados (raciones) por evento × precio por invitado × eventos al año, en la hoja de Supuestos | D35: Ahora cualquier cambio de precio o de volumen recalcula todo el libro
A36: Cocina | B36: no había ninguna: la mise en place se hacía en casa | C36: cuota de una cocina de apoyo compartida y autorizada | D36: Lo que se prepara para un evento no se puede hacer en casa (art. 13.5.b del RD 1021/2022)
A37: Personal | B37: un 12 % de ayudantes subcontratados sobre las ventas y ningún sueldo para el paellero | C37: plantilla con el sueldo del titular, fijos discontinuos y Seguridad Social | D37: Las facturas de autónomo con horario y dirección del empresario son falso autónomo (art. 1.1 ET)
