Workbook

Sheet 0. Assumptions
A1: ASSUMPTIONS — the RATES and DRIVERS of the model are typed here
A2: Change the GREEN cells: the rest of the workbook recalculates on its own. Expense items are typed on their own tab (also in green) and are not repeated here. Amounts are in your currency.
A3: BUSINESS ACTIVITY
A4: Covers per day (year-1 average) | B4: 95 | C4: Average covers served per day over the year, bar and table service combined. Divide it by the seats on this sheet to get the implied seat turns per day (calculated below) and compare them with the seat-turn ceiling on the "Break-Even" tab. Start conservative: a new bar rarely fills its seats from the first month
A5: Average check (excl. sales tax) | B5: 27 | C5: Average check per guest EXCLUDING sales tax: what you ring up before tax is added. The "Menu price incl. sales tax (calculated)" row below shows what the guest sees on the menu once your local rate is applied. Compare both with the average check range in the benchmarks table on "Instructions"
A6: Operating days per year | B6: 360 | C6: One figure feeds the P&L, the break-even and the scenarios, so all three tabs always agree. It assumes the bar opens seven days a week, minus a few closed holidays: enter the days you will really be open. See "3-Year P&L" for how it drives annual sales
A7: Volume growth in year 2 | B7: 0.15 | C7: Growth in daily covers in year 2. Kept deliberately modest: a neighborhood bar takes time to build a base of regulars, so the plan does not lean on the after-work crowd consolidating in year 1
A8: Volume growth in year 3 | B8: 0.1 | C8: Growth in daily covers in year 3. Smaller than in year 2 on purpose: a bar with a fixed number of seats grows into its capacity and growth slows as it fills up
A9: Menu price incl. sales tax (calculated) | B9: =IFERROR(IF($B$5="","",$B$5*(1+SUMPRODUCT('3-Year P&L'!$E$10:$E$11,'3-Year P&L'!$G$10:$G$11))),"") -> 29.16 | C9: =IFERROR("Average check excl. sales tax plus the weighted sales tax of your sales lines ("&TEXT(SUMPRODUCT('3-Year P&L'!$E$10:$E$11,'3-Year P&L'!$G$10:$G$11)*100,"0")&"%), rounded. In the US, menu prices usually exclude sales tax and it is added at the register; in the UK, menu prices include VAT.","") -> Average check excl. sales tax plus the weighted sales tax of your sales lines (8%), rounded. In the US, menu prices usually exclude sales tax and it is added at the register; in the UK, menu prices include VAT.
A10: SALES MIX AND COST OF GOODS SOLD
A11: FOOD share of total sales | B11: 0.35 | C11: Share of FOOD in total sales. It is an INPUT: change it here and the P&L, the cash flow and the sales tax collected recalculate on their own
A12: BEVERAGE share of total sales | B12: =IFERROR(IF(COUNT(B11)=0,"",1-B11),"") -> 0.65 | C12: Calculated as the remainder: food + beverage = 100%
A13: Cost of goods sold on FOOD sales | B13: 0.3 | C13: Food cost on FOOD sales (small plates): ingredients as a share of what the kitchen sells. Stay inside the small-plates range in the benchmarks table on "Instructions"
A14: Cost of goods sold on BEVERAGE sales | B14: 0.22 | C14: Pour cost on BEVERAGE sales: beer, wine, spirits and cocktail ingredients as a share of what the bar sells. It is a weighted blend of the beer and wine pour cost and the cocktail pour cost in the benchmarks on "Instructions", and it includes garnish and spillage
A15: Disposables and packaging as % of sales | B15: 0.01 | C15: Disposable take-out containers, napkins and bar paper, as a share of sales
A16: Delivery share of total sales | B16: 0 | C16: Zero by default: the opening checklist treats delivery as an option for later, only if margins allow it, not for day one. Raise it to the real share of the channel once you turn it on
A17: Delivery platform fee | B17: 0.25 | C17: Percentage a delivery marketplace (DoorDash, Uber Eats) keeps from each order. Confirm your real rate in the platform contract, and add it only if you switch delivery on
A18: Card processing fee | B18: 0.035 | C18: Card and mobile wallet / contactless processing fees on total sales. A neighborhood bar collects most of its drinks by card, so use your processor's effective rate rather than the headline one
A19: LABOR
A20: Employer payroll taxes | B20: 0.1 | C20: FICA (Social Security 6.2% + Medicare 1.45%) + federal and state unemployment taxes (FUTA / SUTA) + workers' comp. About 10% in total: adjust it to your state and your insurance carrier
A21: Monthly pay periods per year (keep 12) | B21: 12 | C21: Annual gross pay = monthly gross pay × this number. Keep 12 in the US: it counts the monthly salaries the model pays in a year, not how often you run payroll (weekly or biweekly payroll pays the same annual amount)
A22: Federal minimum wage, annual full-time | B22: 15080 | C22: US federal minimum wage: 7.25 per hour × 2,080 hours = 15,080 per year for a full-time job. Your state or city may set a higher floor: enter it in the state / local minimum wage cell below. Check the current rates at dol.gov
A23: RENT AND FIXED COSTS
A24: Monthly rent | B24: 6500 | C24: Monthly rent for a space with a bar counter and a patio. It must stay under the rent ceiling in the benchmarks table on "Instructions" and in the traffic light of the "3-Year P&L". Compare it with real quotes in your area, and negotiate the lease terms with your attorney
A25: Security deposit (months of rent) | B25: 2 | C25: Months of rent held as a security deposit. It is set in your commercial lease, so check the terms before you sign
A26: Monthly utilities (electricity, water, gas) | B26: 2000 | C26: Electricity, water and gas for a kitchen with a griddle, fryer and oven, plus the draft beer cooler and the back-bar refrigeration. Ask the landlord or the last tenant for the utility history ahead of signing
A27: Insurance (per year) | B27: 12000 | C27: Annual premium for general liability + liquor liability (dram shop) + property insurance, entered as one figure. Landlords and lenders ask for proof of coverage ahead of opening
A28: Miscellaneous and contingency as % of sales | B28: 0.01 | C28: Cushion for unbudgeted running costs. It is a VARIABLE cost: it rises and falls with sales, so it does not belong among the fixed costs
A29: FINANCING
A30: Owner's equity contributed | B30: 120000 | C30: Cash you and your partners put in. Lenders usually expect an owner equity injection (often around 10% for SBA start-ups; many want 20-30%). Check the equity share of your plan against what your lender asks for
A31: Loan requested | B31: 369000 | C31: Principal you request from your lender, for example an SBA 7(a) loan through a bank. The "Financing" tab checks that sources and uses match the cash need calculated on "Startup Costs", and has a cell that calculates the exact amount that balances them
A32: Nominal annual interest rate (not APR) | B32: 0.1 | C32: Nominal annual rate, not APR; get offers from two lenders, including an SBA-guaranteed loan, before you fix it
A33: Loan term (years) | B33: 10 | C33: Total years, interest-only period included
A34: Interest-only period (years) | B34: 0 | C34: Years you pay interest only, before principal repayment begins. A year of interest only can ease the tightest cash period (build-out and the first weeks of trading); ask your lender whether it offers it
A35: Working capital (months of fixed costs) | B35: 3 | C35: The minimum this workbook requires (see "Instructions"): a cushion of less than 3 months will not cover a slow season
A36: TAXES
A37: Effective income tax rate (years 1-2) | B37: 0.25 | C37: Example: 21% federal rate for a C corporation plus state tax, rounded to 25%. If you operate as a sole proprietorship, LLC taxed as a pass-through or S corporation, the business itself pays 0% here and you pay tax on the profit personally: set this to 0 and budget for your personal tax separately. The model applies this rate to the first two years with positive taxable income
A38: Effective income tax rate (from year 3) | B38: 0.25 | C38: From the third year with positive taxable income. Same example rate (21% federal C corporation + state). Confirm the rate that applies to you with your accountant and change it here
A39: Sales tax rate on sales | B39: 0.08 | C39: Example rate: state + local sales tax combined. It varies widely by state and city: look up yours. UK: 20% VAT on hot food and dine-in
A40: Sales tax rate on alcohol to go | B40: 0.08 | C40: Same example rate as above. Some states add separate liquor taxes: include them here if they apply to you. Alcohol served on site has its own rate in the sales tax breakdown block, further down. Utilities, equipment and services are handled in the cell below
...

Sheet Startup Costs
A1: BAR BUSINESS PLAN: NEIGHBORHOOD BAR WITH SMALL PLATES
A2: Estimated Startup Costs — US kit example (2026)
A3: US kit example (2026) — replace with your own quotes.
A5: Item | B5: Amount | C5: % of startup costs | D5: Notes | E5: Taxable / recoverable tax?
A6: STARTUP COSTS | B6: =IFERROR(IF(COUNT(B7:B27)=0,"",SUM(B7:B27)),"") -> 361700 | C6: =IFERROR(B6/$B$30,"") -> 0.73977598
A7: LLC formation + legal | B7: 2500 | C7: =IFERROR(B7/$B$30,"") -> 0.0051131876 | D7: Articles of organization (state filing fee), registered agent and attorney time for the operating agreement. Fees vary by state | E7: No
A8: Liquor license + local permits (non-quota state example) | B8: 15000 | C8: =IFERROR(B8/$B$30,"") -> 0.030679125 | D8: Beer & wine licenses start around $3,000; full liquor runs $12,000-$400,000. In quota states you buy an existing license at market price, which costs far more; this row is an example for a state WITHOUT a quota. A license bought from another owner is an intangible asset: ask your CPA. Apply right after signing the lease: it often takes 3-12 months. Most states also charge an annual or biennial renewal fee: add it to your fixed costs | E8: No
A9: Architect, MEP drawings + permit fees | B9: 15000 | C9: =IFERROR(B9/$B$30,"") -> 0.030679125 | D9: Architect and MEP drawings plus permit fees, required with a commercial kitchen | E9: Yes
A10: Build-out (second-generation space) | B10: 70000 | C10: =IFERROR(B10/$B$30,"") -> 0.14316925 | D10: Flooring, paint, an accessible restroom (ADA) and the work to adapt a second-generation space | E10: Yes
A11: Electrical + HVAC | B11: 22000 | C11: =IFERROR(B11/$B$30,"") -> 0.044996051 | D11: Electrical service sized for the kitchen and the back bar, plus heating and air conditioning | E11: Yes
A12: Plumbing, grease interceptor + Type I hood | B12: 28000 | C12: =IFERROR(B12/$B$30,"") -> 0.057267701 | D12: Type I hood, exhaust, grease interceptor and plumbing | E12: Yes
A13: Kitchen equipment (griddle, fryer, oven) | B13: 20000 | C13: =IFERROR(B13/$B$30,"") -> 0.040905501 | D13: Commercial griddle, fryer, convection oven and broiler for the small-plates menu | E13: Yes
A14: Refrigeration (walk-in + back-bar coolers) | B14: 18000 | C14: =IFERROR(B14/$B$30,"") -> 0.03681495 | D14: Walk-in cooler plus under-bar and back-bar refrigerators for beer, wine and mixers | E14: Yes
A15: Bar build (bar top + underbar stations) | B15: 35000 | C15: =IFERROR(B15/$B$30,"") -> 0.071584626 | D15: Bar top and underbar stations (ice well, sinks, speed rails), plus a display case for small plates and the draft taps | E15: Yes
A16: Draft beer system + installation | B16: 14000 | C16: =IFERROR(B16/$B$30,"") -> 0.02863385 | D16: Taps, draft lines, keg cooler, kegs and CO2, plus installation | E16: Yes
A17: Furniture (tables, high-tops + bar stools) | B17: 15000 | C17: =IFERROR(B17/$B$30,"") -> 0.030679125 | D17: High-tops, tables and bar stools for the dining room and bar | E17: Yes
A18: Patio (furniture + awning) | B18: 6000 | C18: =IFERROR(B18/$B$30,"") -> 0.01227165 | D18: Tables, chairs and an awning for the patio, if your permit allows it | E18: Yes
... A24: POS + handhelds + software | B24: 5000 | C24: =IFERROR(B24/$B$30,"") -> 0.010226375 | D24: Countertop POS at the bar, wireless handheld POS and management software | E24: Yes
A25: Security deposit | B25: =IFERROR(IF('0. Assumptions'!$B$24="","",'0. Assumptions'!$B$24*'0. Assumptions'!$B$25),"") -> 13000 | C25: =IFERROR(B25/$B$30,"") -> 0.026588575 | D25: =IFERROR(""&TEXT('0. Assumptions'!$B$25,"0")&IF('0. Assumptions'!$B$25=1," month"," months")&" of rent, from ""0. Assumptions"". Refundable when the lease ends: it is not depreciated and carries no tax","") -> 2 months of rent, from "0. Assumptions". Refundable when the lease ends: it is not depreciated and carries no tax | E25: No
A26: Rent paid before opening | B26: =IFERROR(IF('0. Assumptions'!$B$24="","",'0. Assumptions'!$B$24*'0. Assumptions'!$B$54),"") -> 13000 | C26: =IFERROR(B26/$B$30,"") -> 0.026588575 | D26: =IFERROR("Rent "&IF('0. Assumptions'!$B$54=1,"for the month","for the "&TEXT('0. Assumptions'!$B$54,"0")&" months")&" of build-out and permits before opening. It does not overlap the P&L, which starts on opening day: its twelve months are twelve trading months","") -> Rent for the 2 months of build-out and permits before opening. It does not overlap the P&L, which starts on opening day: its twelve months are twelve trading months | E26: Yes
A27: Build-out and setup contingency | B27: =IFERROR(IF(COUNT(B9,B10,B11,B12,B16,B20,B21)=0,"",ROUND((B9+B10+B11+B12+B16+B20+B21)*'0. Assumptions'!$B$55,0)),"") -> 17200 | C27: =IFERROR(B27/$B$30,"") -> 0.03517873 | D27: =IFERROR("At "&TEXT('0. Assumptions'!$B$55,"0%")&" of the BUILD-OUT items of this block (architect and MEP drawings, build-out, electrical and HVAC, plumbing, grease interceptor and hood, draft beer system, decor and lighting, signage), not of the whole block: the other items are left "&"out. No lender funds a build-out without a cushion: the percentage is in ""0. Assumptions""","") -> At 10% of the BUILD-OUT items of this block (architect and MEP drawings, build-out, electrical and HVAC, plumbing, grease interceptor and hood, draft beer system, decor and lighting, signage), not of the whole block: the other items are left out. No lender funds a build-out without a cushion: the percentage is in "0. Assumptions" | E27: Yes
A28: WORKING CAPITAL | B28: =IFERROR(IF(B29="","",B29),"") -> 127231.8 | C28: =IFERROR(B28/$B$30,"") -> 0.26022402
A29: Operating cushion until break-even | B29: =IFERROR(IF('0. Assumptions'!$B$35*('3-Year P&L'!$B$37-'3-Year P&L'!$B$35)=0,"",'0. Assumptions'!$B$35*('3-Year P&L'!$B$37-'3-Year P&L'!$B$35)/12),"") -> 127231.8 | C29: =IFERROR(B29/$B$30,"") -> 0.26022402 | D29: =IFERROR("Covers "&TEXT('0. Assumptions'!$B$35,"0")&IF('0. Assumptions'!$B$35=1," month"," months")&" of year-1 CASH fixed costs (the P&L fixed costs minus depreciation, which is not paid out), the minimum the Instructions of this workbook ask for","") -> Covers 3 months of year-1 CASH fixed costs (the P&L fixed costs minus depreciation, which is not paid out), the minimum the Instructions of this workbook ask for | E29: No
A30: TOTAL STARTUP COSTS (sum of the blocks) | B30: =IFERROR(B6+B28,"") -> 488931.8 | D30: =IFERROR("The percentages in column C are read on this figure, which includes the working capital ("&TEXT(C28,"0%")&" of the total). To compare the breakdown with another plan, use the CAPEX row below.","") -> The percentages in column C are read on this figure, which includes the working capital (26% of the total). To compare the breakdown with another plan, use the CAPEX row below.
A31: CAPEX (startup costs excluding working capital) | B31: =IFERROR(B30-B28,"") -> 361700 | D31: What you buy: build-out, equipment, launch and formation costs. The cash cushion is not an investment: it is working capital
A32: Recoverable input tax on capex | B32: =IFERROR(IF(B30="","",SUMIF($E$7:$E$27,"Yes",$B$7:$B$27)*'0. Assumptions'!$B$41),"") -> 0 | D32: =IFERROR("At "&TEXT('0. Assumptions'!$B$41,"0%")&" on the items marked ""Yes"" in the tax column. US: the sales tax you pay on equipment is part of its cost and is not recovered, so this rate is 0. UK (VAT-registered): 20%, reclaimed on your VAT return, but you pay it first, so the loan has to cover it","") -> At 0% on the items marked "Yes" in the tax column. US: the sales tax you pay on equipment is part of its cost and is not recovered, so this rate is 0. UK (VAT-registered): 20%, reclaimed on your VAT return, but you pay it first, so the loan has to cover it
A33: TOTAL CASH NEEDED AT LAUNCH | B33: =IFERROR(B30+B32,"") -> 488931.8 | D33: This is the figure the Financing tab has to cover
A34: DEPRECIATION BASES (not added to startup costs)
A35: Build-out, fixtures and setup | B35: =IFERROR(IF(B9="","",B9+B10+B11+B12+B16+B20+B21+B27),"") -> 189200 | D35: =IFERROR("Depreciated over "&TEXT('0. Assumptions'!$B$44,"0")&" years","") -> Depreciated over 10 years
A36: Machinery, furniture and equipment | B36: =IFERROR(IF(B13="","",B13+B14+B15+B17+B18+B19+B24),"") -> 107000 | D36: =IFERROR("Depreciated over "&TEXT('0. Assumptions'!$B$45,"0")&" years","") -> Depreciated over 7 years
A37: Annual depreciation of fixed assets | B37: =IFERROR(B35/MAX(1,'0. Assumptions'!$B$44)+B36/MAX(1,'0. Assumptions'!$B$45),"") -> 34205.714 | D37: =IFERROR("Not depreciated, because they are not fixed assets: LLC formation and legal, liquor license and local permits (a license bought from another owner is an intangible asset: ask your CPA), launch marketing, opening inventory, security "&"deposit, pre-opening rent and the working capital reserve. They add up to "&TEXT(B30-B35-B36,"#,##0")&" of the "&TEXT(B30,"#,##0")&" total investment.","") -> Not depreciated, because they are not fixed assets: LLC formation and legal, liquor license and local permits (a license bought from another owner is an intangible asset: ask your CPA), launch marketing, opening inventory, security deposit, pre-opening rent and the working capital reserve. They add up to 192732 of the 488932 total investment.

Sheet 3-Year P&L
A1: PRO FORMA P&L — 3 YEARS
A2: Base case — neighborhood bar with small plates, 60 seats
A4: Item | B4: Year 1 | C4: Year 2 | D4: Year 3 | E4: % of sales (year 1) | F4: Notes | G4: Sales tax rate on the line (%)
A5: REVENUE
A6: Covers per day (average) | B6: =IFERROR(IF('0. Assumptions'!$B$4="","",'0. Assumptions'!$B$4),"") -> 95 | C6: =IFERROR(B6*(1+'0. Assumptions'!$B$7),"") -> 109.25 | D6: =IFERROR(C6*(1+'0. Assumptions'!$B$8),"") -> 120.175 | F6: Growth for years 2 and 3 is set in "0. Assumptions"
A7: Average check (excl. sales tax) | B7: =IFERROR(IF('0. Assumptions'!$B$5="","",'0. Assumptions'!$B$5),"") -> 27 | C7: =IFERROR(IF(B7="","",B7),"") -> 27 | D7: =IFERROR(IF(C7="","",C7),"") -> 27 | F7: Held constant at year-1 prices: a price increase is a separate decision
A8: Operating days per year | B8: =IFERROR(IF('0. Assumptions'!$B$6="","",'0. Assumptions'!$B$6),"") -> 360 | C8: =IFERROR(IF(B8="","",B8),"") -> 360 | D8: =IFERROR(IF(C8="","",C8),"") -> 360
A9: TOTAL REVENUE (excl. sales tax) | B9: =IFERROR(IF(B6*B7*B8=0,"",B6*B7*B8),"") -> 923400 | C9: =IFERROR(IF(C6*C7*C8=0,"",C6*C7*C8),"") -> 1061910 | D9: =IFERROR(IF(D6*D7*D8=0,"",D6*D7*D8),"") -> 1168101 | E9: =IFERROR(IF(B9="","",1),"") -> 1
A10: Food sales (small plates) | B10: =IFERROR(IF(B9="","",B9*$E$10),"") -> 323190 | C10: =IFERROR(IF(C9="","",C9*$E$10),"") -> 371668.5 | D10: =IFERROR(IF(D9="","",D9*$E$10),"") -> 408835.35 | E10: =IFERROR(IF('0. Assumptions'!$B$11="","",'0. Assumptions'!$B$11),"") -> 0.35 | F10: Small plates sold at the bar and at tables, plus events, catering and take-out | G10: =IFERROR(IF(B9="","",'0. Assumptions'!$B$39),"") -> 0.08
A11: Beverage sales (cocktails, beer, wine + non-alcoholic) | B11: =IFERROR(IF(B9="","",B9*$E$11),"") -> 600210 | C11: =IFERROR(IF(C9="","",C9*$E$11),"") -> 690241.5 | D11: =IFERROR(IF(D9="","",D9*$E$11),"") -> 759265.65 | E11: =IFERROR(IF('0. Assumptions'!$B$12="","",'0. Assumptions'!$B$12),"") -> 0.65 | F11: Draft beer, wine and cocktails and spirits (a higher cost per drink because of preparation: see the pour cost range in the benchmarks on "Instructions"), plus non-alcoholic drinks | G11: =IFERROR(IF(B9="","",('0. Assumptions'!$B$62*((1-'0. Assumptions'!$B$16)*'0. Assumptions'!$B$63+'0. Assumptions'!$B$16*'0. Assumptions'!$B$40)+(1-'0. Assumptions'!$B$62)*'0. Assumptions'!$B$39)),"") -> 0.08
A12: VARIABLE COSTS
A13: Cost of goods sold — food | B13: =IFERROR(IF(B9="","",B9*'0. Assumptions'!$B$11*'0. Assumptions'!$B$13),"") -> 96957 | C13: =IFERROR(IF(C9="","",C9*'0. Assumptions'!$B$11*'0. Assumptions'!$B$13),"") -> 111500.55 | D13: =IFERROR(IF(D9="","",D9*'0. Assumptions'!$B$11*'0. Assumptions'!$B$13),"") -> 122650.6 | E13: =IFERROR(B13/$B$9,"") -> 0.105 | F13: =IFERROR("At "&TEXT('0. Assumptions'!$B$13,"0%")&" of FOOD sales, not of total sales: beverages have their own line","") -> At 30% of FOOD sales, not of total sales: beverages have their own line | G13: =IFERROR(IF(B9="","",'0. Assumptions'!$B$41),"") -> 0
A14: Cost of goods sold — beverage | B14: =IFERROR(IF(B9="","",B9*'0. Assumptions'!$B$12*'0. Assumptions'!$B$14),"") -> 132046.2 | C14: =IFERROR(IF(C9="","",C9*'0. Assumptions'!$B$12*'0. Assumptions'!$B$14),"") -> 151853.13 | D14: =IFERROR(IF(D9="","",D9*'0. Assumptions'!$B$12*'0. Assumptions'!$B$14),"") -> 167038.44 | E14: =IFERROR(B14/$B$9,"") -> 0.143 | F14: =IFERROR("At "&TEXT('0. Assumptions'!$B$14,"0%")&" of BEVERAGE sales","") -> At 22% of BEVERAGE sales | G14: =IFERROR(IF(B9="","",'0. Assumptions'!$B$41),"") -> 0
A15: Disposables and packaging | B15: =IFERROR(IF(B9="","",B9*'0. Assumptions'!$B$15),"") -> 9234 | C15: =IFERROR(IF(C9="","",C9*'0. Assumptions'!$B$15),"") -> 10619.1 | D15: =IFERROR(IF(D9="","",D9*'0. Assumptions'!$B$15),"") -> 11681.01 | E15: =IFERROR(B15/$B$9,"") -> 0.01 | G15: =IFERROR(IF(B9="","",'0. Assumptions'!$B$41),"") -> 0
A16: Delivery platform fees | B16: =IFERROR(IF(B9="","",B9*'0. Assumptions'!$B$16*'0. Assumptions'!$B$17),"") -> 0 | C16: =IFERROR(IF(C9="","",C9*'0. Assumptions'!$B$16*'0. Assumptions'!$B$17),"") -> 0 | D16: =IFERROR(IF(D9="","",D9*'0. Assumptions'!$B$16*'0. Assumptions'!$B$17),"") -> 0 | E16: =IFERROR(B16/$B$9,"") -> 0 | F16: Applied to the sales of THAT CHANNEL. With 0% delivery in Assumptions, this line is zero | G16: =IFERROR(IF(B9="","",'0. Assumptions'!$B$41),"") -> 0
A17: Card processing fees | B17: =IFERROR(IF(B9="","",B9*'0. Assumptions'!$B$18),"") -> 32319 | C17: =IFERROR(IF(C9="","",C9*'0. Assumptions'!$B$18),"") -> 37166.85 | D17: =IFERROR(IF(D9="","",D9*'0. Assumptions'!$B$18),"") -> 40883.535 | E17: =IFERROR(B17/$B$9,"") -> 0.035 | F17: Card processing fees are not subject to sales tax: no tax is recovered or deducted for them | G17: 0
A18: Miscellaneous and contingency | B18: =IFERROR(IF(B9="","",B9*'0. Assumptions'!$B$28),"") -> 9234 | C18: =IFERROR(IF(C9="","",C9*'0. Assumptions'!$B$28),"") -> 10619.1 | D18: =IFERROR(IF(D9="","",D9*'0. Assumptions'!$B$28),"") -> 11681.01 | E18: =IFERROR(B18/$B$9,"") -> 0.01 | F18: =IFERROR("At "&TEXT('0. Assumptions'!$B$28,"0%")&" of sales. It is a VARIABLE cost: it moves with revenue, so it cannot sit in fixed costs","") -> At 1% of sales. It is a VARIABLE cost: it moves with revenue, so it cannot sit in fixed costs | G18: =IFERROR(IF(B9="","",'0. Assumptions'!$B$41),"") -> 0
A19: TOTAL VARIABLE COSTS | B19: =IFERROR(IF(B9="","",SUM(B13:B18)),"") -> 279790.2 | C19: =IFERROR(IF(C9="","",SUM(C13:C18)),"") -> 321758.73 | D19: =IFERROR(IF(D9="","",SUM(D13:D18)),"") -> 353934.6 | E19: =IFERROR(B19/$B$9,"") -> 0.303
A20: GROSS MARGIN | B20: =IFERROR(IF(B9="","",B9-B19),"") -> 643609.8 | C20: =IFERROR(IF(C9="","",C9-C19),"") -> 740151.27 | D20: =IFERROR(IF(D9="","",D9-D19),"") -> 814166.4 | E20: =IFERROR(B20/$B$9,"") -> 0.697
A21: FIXED COSTS
A22: Rent | B22: =IFERROR(IF(B9="","",'0. Assumptions'!$B$24*12),"") -> 78000 | C22: =IFERROR(IF(C9="","",B22*(1+'0. Assumptions'!$B$48)),"") -> 78000 | D22: =IFERROR(IF(D9="","",C22*(1+'0. Assumptions'!$B$48)),"") -> 78000 | E22: =IFERROR(B22/$B$9,"") -> 0.084470435 | F22: The monthly amount is on the "0. Assumptions" tab; here it is multiplied by twelve. Rent for the build-out months, which comes before opening, is on the Startup Costs tab and is NOT counted twice | G22: =IFERROR(IF(B9="","",'0. Assumptions'!$B$41),"") -> 0
A23: Labor (wages + employer payroll taxes) | B23: =IFERROR(IF(B9="","",Staffing!$G$12),"") -> 308827.2 | C23: =IFERROR(IF(C9="","",Staffing!$B$16),"") -> 314827.2 | D23: =IFERROR(IF(D9="","",Staffing!$B$17),"") -> 320827.2 | E23: =IFERROR(B23/$B$9,"") -> 0.33444574 | F23: Comes from the Staffing tab: it is the SAME number, not a separate estimate. Years 2 and 3 add the new hires declared on that tab, not a percentage of volume | G23: 0
A24: Utilities (electricity, water, gas) | B24: =IFERROR(IF(B9="","",'0. Assumptions'!$B$26*12),"") -> 24000 | C24: =IFERROR(IF(C9="","",B24*(1+'0. Assumptions'!$B$48)),"") -> 24000 | D24: =IFERROR(IF(D9="","",C24*(1+'0. Assumptions'!$B$48)),"") -> 24000 | E24: =IFERROR(B24/$B$9,"") -> 0.025990903 | F24: Enter the monthly bills excl. sales tax. The workbook applies a single tax treatment to this whole line, the one in the column next to it; if one utility is taxed differently in your area, give it its own line | G24: =IFERROR(IF(B9="","",'0. Assumptions'!$B$41),"") -> 0
A25: Insurance (general + liquor liability + property) | B25: =IFERROR(IF(B9="","",'0. Assumptions'!$B$27),"") -> 12000 | C25: =IFERROR(IF(C9="","",B25*(1+'0. Assumptions'!$B$48)),"") -> 12000 | D25: =IFERROR(IF(D9="","",C25*(1+'0. Assumptions'!$B$48)),"") -> 12000 | E25: =IFERROR(B25/$B$9,"") -> 0.012995452 | F25: Insurance premiums are not subject to sales tax: there is no recoverable tax on them | G25: 0
A26: Accounting + bookkeeping | B26: 6000 | C26: =IFERROR(IF(C9="","",B26*(1+'0. Assumptions'!$B$48)),"") -> 6000 | D26: =IFERROR(IF(D9="","",C26*(1+'0. Assumptions'!$B$48)),"") -> 6000 | E26: =IFERROR(B26/$B$9,"") -> 0.0064977258 | G26: =IFERROR(IF(B9="","",'0. Assumptions'!$B$41),"") -> 0
A27: Equipment maintenance | B27: 8000 | C27: =IFERROR(IF(C9="","",B27*(1+'0. Assumptions'!$B$48)),"") -> 8000 | D27: =IFERROR(IF(D9="","",C27*(1+'0. Assumptions'!$B$48)),"") -> 8000 | E27: =IFERROR(B27/$B$9,"") -> 0.0086636344 | G27: =IFERROR(IF(B9="","",'0. Assumptions'!$B$41),"") -> 0
A28: Marketing and advertising | B28: 15000 | C28: =IFERROR(IF(C9="","",B28*(1+'0. Assumptions'!$B$48)),"") -> 15000 | D28: =IFERROR(IF(D9="","",C28*(1+'0. Assumptions'!$B$48)),"") -> 15000 | E28: =IFERROR(B28/$B$9,"") -> 0.016244314 | G28: =IFERROR(IF(B9="","",'0. Assumptions'!$B$41),"") -> 0
A29: Software (POS, reservations, inventory) | B29: 4800 | C29: =IFERROR(IF(C9="","",B29*(1+'0. Assumptions'!$B$48)),"") -> 4800 | D29: =IFERROR(IF(D9="","",C29*(1+'0. Assumptions'!$B$48)),"") -> 4800 | E29: =IFERROR(B29/$B$9,"") -> 0.0051981806 | G29: =IFERROR(IF(B9="","",'0. Assumptions'!$B$41),"") -> 0
A30: Cleaning supplies + linens | B30: 7200 | C30: =IFERROR(IF(C9="","",B30*(1+'0. Assumptions'!$B$48)),"") -> 7200 | D30: =IFERROR(IF(D9="","",C30*(1+'0. Assumptions'!$B$48)),"") -> 7200 | E30: =IFERROR(B30/$B$9,"") -> 0.007797271 | G30: =IFERROR(IF(B9="","",'0. Assumptions'!$B$41),"") -> 0
A31: Waste + grease hauling (trash, recycling, used oil) | B31: 3000 | C31: =IFERROR(IF(C9="","",B31*(1+'0. Assumptions'!$B$48)),"") -> 3000 | D31: =IFERROR(IF(D9="","",C31*(1+'0. Assumptions'!$B$48)),"") -> 3000 | E31: =IFERROR(B31/$B$9,"") -> 0.0032488629 | F31: Licensed waste / grease hauler; the opening checklist asks for it ahead of opening. With a griddle and fryer running, a bar with a kitchen produces more used oil than a coffee shop, so get a quote for your area | G31: =IFERROR(IF(B9="","",'0. Assumptions'!$B$41),"") -> 0
A32: Pest control | B32: 1200 | C32: =IFERROR(IF(C9="","",B32*(1+'0. Assumptions'!$B$48)),"") -> 1200 | D32: =IFERROR(IF(D9="","",C32*(1+'0. Assumptions'!$B$48)),"") -> 1200 | E32: =IFERROR(B32/$B$9,"") -> 0.0012995452 | F32: Licensed pest control company. It is part of the HACCP-based food safety plan, alongside the allergen and food safety training that the opening checklist asks for in its staff phase | G32: =IFERROR(IF(B9="","",'0. Assumptions'!$B$41),"") -> 0
A33: Music licensing (ASCAP/BMI/SESAC) | B33: 3000 | C33: =IFERROR(IF(C9="","",B33*(1+'0. Assumptions'!$B$48)),"") -> 3000 | D33: =IFERROR(IF(D9="","",C33*(1+'0. Assumptions'!$B$48)),"") -> 3000 | E33: =IFERROR(B33/$B$9,"") -> 0.0032488629 | F33: Public-performance licenses from ASCAP, BMI and SESAC. They are separate from your local permits: budget for them if you play music in the bar or hire a DJ | G33: =IFERROR(IF(B9="","",'0. Assumptions'!$B$41),"") -> 0
A34: Safety + responsible-service training | B34: 1000 | C34: =IFERROR(IF(C9="","",B34*(1+'0. Assumptions'!$B$48)),"") -> 1000 | D34: =IFERROR(IF(D9="","",C34*(1+'0. Assumptions'!$B$48)),"") -> 1000 | E34: =IFERROR(B34/$B$9,"") -> 0.0010829543 | F34: Staff training in responsible beverage service (TIPS / ServSafe Alcohol) and in workplace safety. Check what your state or city requires for people who pour alcohol; it also supports your dram shop liability coverage | G34: =IFERROR(IF(B9="","",'0. Assumptions'!$B$41),"") -> 0
A35: Depreciation of fixed assets | B35: =IFERROR(IF(B9="","",'Startup Costs'!$B$37),"") -> 34205.714 | C35: =IFERROR(IF(C9="","",B35),"") -> 34205.714 | D35: =IFERROR(IF(D9="","",B35),"") -> 34205.714 | E35: =IFERROR(B35/$B$9,"") -> 0.037043225 | F35: Comes from the depreciation bases on the Startup Costs tab: real fixed assets only. It does NOT rise with inflation: it is a charge on the HISTORICAL cost of the assets | G35: 0
A36: Interest expense (loan interest) | B36: =IFERROR(IF(B9="","",Financing!$B$44),"") -> 36900 | C36: =IFERROR(IF(C9="","",Financing!$B$46),"") -> 34584.695 | D36: =IFERROR(IF(D9="","",Financing!$B$48),"") -> 32037.859 | E36: =IFERROR(B36/$B$9,"") -> 0.039961014 | F36: Only INTEREST is an expense. Principal repaid appears on the cash flow tab | G36: 0
A37: TOTAL FIXED COSTS | B37: =IFERROR(IF(B9="","",SUM(B22:B36)),"") -> 543132.91 | C37: =IFERROR(IF(C9="","",SUM(C22:C36)),"") -> 546817.61 | D37: =IFERROR(IF(D9="","",SUM(D22:D36)),"") -> 550270.77 | E37: =IFERROR(B37/$B$9,"") -> 0.58818812
A38: Recoverable input tax on variable costs | B38: =IFERROR(IF(B9="","",SUMPRODUCT(B13:B18,G13:G18)),"") -> 0 | C38: =IFERROR(IF(C9="","",SUMPRODUCT(C13:C18,G13:G18)),"") -> 0 | D38: =IFERROR(IF(D9="","",SUMPRODUCT(D13:D18,G13:G18)),"") -> 0 | F38: Each line at ITS OWN rate, read from the column next to it. It is what the cash flow tab overpays to suppliers and later deducts (zero wherever no tax is recoverable)
A39: Recoverable input tax on fixed costs | B39: =IFERROR(IF(B9="","",SUMPRODUCT(B22:B36,G22:G36)),"") -> 0 | C39: =IFERROR(IF(C9="","",SUMPRODUCT(C22:C36,G22:G36)),"") -> 0 | D39: =IFERROR(IF(D9="","",SUMPRODUCT(D22:D36,G22:G36)),"") -> 0
A40: PRE-TAX INCOME (EBT) | B40: =IFERROR(IF(B9="","",B20-B37),"") -> 100476.89 | C40: =IFERROR(IF(C9="","",C20-C37),"") -> 193333.66 | D40: =IFERROR(IF(D9="","",D20-D37),"") -> 263895.62 | E40: =IFERROR(B40/$B$9,"") -> 0.10881188
A41: Net operating losses carried forward (opening) | B41: =IFERROR(IF(B9="","",'0. Assumptions'!$B$42),"") -> 0 | C41: =IFERROR(IF(C9="","",B46),"") -> 0 | D41: =IFERROR(IF(D9="","",C46),"") -> 0 | F41: Federal rules let a year's losses offset the profits of later years (the federal limit is 80% of taxable income; this model offsets 100% as a simplification)
...

Sheet Break-Even
A1: BREAK-EVEN ANALYSIS
A2: Monthly and daily break-even — neighborhood bar with small plates
A4: Variable | B4: Year 1 | C4: Year 2 | D4: Year 3 | E4: Notes
A5: BASE DATA BY YEAR
A6: Annual fixed costs | B6: =IFERROR(IF('3-Year P&L'!$B$9="","",'3-Year P&L'!$B$37),"") -> 543132.91 | C6: =IFERROR(IF('3-Year P&L'!$C$9="","",'3-Year P&L'!$C$37),"") -> 546817.61 | D6: =IFERROR(IF('3-Year P&L'!$D$9="","",'3-Year P&L'!$D$37),"") -> 550270.77 | E6: The SAME fixed costs as the P&L. Each year has its own, which is why the threshold cannot be a single one for all three years
A7: Monthly fixed costs | B7: =IFERROR(IF('3-Year P&L'!$B$9="","",B6/12),"") -> 45261.076 | C7: =IFERROR(IF('3-Year P&L'!$C$9="","",C6/12),"") -> 45568.134 | D7: =IFERROR(IF('3-Year P&L'!$D$9="","",D6/12),"") -> 45855.898
A8: Average check (excl. sales tax) | B8: =IFERROR(IF('3-Year P&L'!$B$9="","",'3-Year P&L'!$B$7),"") -> 27 | C8: =IFERROR(IF('3-Year P&L'!$C$9="","",'3-Year P&L'!$C$7),"") -> 27 | D8: =IFERROR(IF('3-Year P&L'!$D$9="","",'3-Year P&L'!$D$7),"") -> 27
A9: Variable cost per cover | B9: =IFERROR(IF('3-Year P&L'!$B$9="","",'3-Year P&L'!$B$19/('3-Year P&L'!$B$6*'3-Year P&L'!$B$8)),"") -> 8.181 | C9: =IFERROR(IF('3-Year P&L'!$C$9="","",'3-Year P&L'!$C$19/('3-Year P&L'!$C$6*'3-Year P&L'!$C$8)),"") -> 8.181 | D9: =IFERROR(IF('3-Year P&L'!$D$9="","",'3-Year P&L'!$D$19/('3-Year P&L'!$D$6*'3-Year P&L'!$D$8)),"") -> 8.181 | E9: Comes from the P&L total variable costs, not from a separate estimate. It includes miscellaneous and contingency, which is a percentage of sales
A10: Contribution margin per cover | B10: =IFERROR(IF('3-Year P&L'!$B$9="","",B8-B9),"") -> 18.819 | C10: =IFERROR(IF('3-Year P&L'!$C$9="","",C8-C9),"") -> 18.819 | D10: =IFERROR(IF('3-Year P&L'!$D$9="","",D8-D9),"") -> 18.819 | E10: Average check minus unit variable cost
A11: Operating days per year | B11: =IFERROR(IF('3-Year P&L'!$B$9="","",'3-Year P&L'!$B$8),"") -> 360 | C11: =IFERROR(IF('3-Year P&L'!$C$9="","",'3-Year P&L'!$C$8),"") -> 360 | D11: =IFERROR(IF('3-Year P&L'!$D$9="","",'3-Year P&L'!$D$8),"") -> 360 | E11: The same calendar as the P&L and the scenarios
A12: Principal repaid in the year | B12: =IFERROR(IF('3-Year P&L'!$B$9="","",Financing!$B$45),"") -> 23153.051 | C12: =IFERROR(IF('3-Year P&L'!$C$9="","",Financing!$B$47),"") -> 25468.356 | D12: =IFERROR(IF('3-Year P&L'!$D$9="","",Financing!$B$49),"") -> 28015.191 | E12: Principal is NOT a P&L expense, but it leaves the cash account. Without it, the published break-even threshold would sit below the real one
A13: ACCOUNTING BREAK-EVEN (includes depreciation)
A14: Covers needed per year | B14: =IFERROR(IF('3-Year P&L'!$B$9="","",IF(B10<=0,"",B6/B10)),"") -> 28860.881 | C14: =IFERROR(IF('3-Year P&L'!$C$9="","",IF(C10<=0,"",C6/C10)),"") -> 29056.677 | D14: =IFERROR(IF('3-Year P&L'!$D$9="","",IF(D10<=0,"",D6/D10)),"") -> 29240.171
A15: Covers needed per day | B15: =IFERROR(IF('3-Year P&L'!$B$9="","",B14/B11),"") -> 80.169113 | C15: =IFERROR(IF('3-Year P&L'!$C$9="","",C14/C11),"") -> 80.712992 | D15: =IFERROR(IF('3-Year P&L'!$D$9="","",D14/D11),"") -> 81.222697
A16: Revenue needed per year | B16: =IFERROR(IF('3-Year P&L'!$B$9="","",B14*B8),"") -> 779243.78 | C16: =IFERROR(IF('3-Year P&L'!$C$9="","",C14*C8),"") -> 784530.29 | D16: =IFERROR(IF('3-Year P&L'!$D$9="","",D14*D8),"") -> 789484.61
A17: CASH BREAK-EVEN (loan payments in, depreciation out)
A18: Cash fixed costs + principal repaid for the year | B18: =IFERROR(IF('3-Year P&L'!$B$9="","",B6-'3-Year P&L'!$B$35+B12),"") -> 532080.25 | C18: =IFERROR(IF('3-Year P&L'!$C$9="","",C6-'3-Year P&L'!$C$35+C12),"") -> 538080.25 | D18: =IFERROR(IF('3-Year P&L'!$D$9="","",D6-'3-Year P&L'!$D$35+D12),"") -> 544080.25 | E18: The P&L fixed costs without depreciation (which is not paid in cash) and WITH principal repaid (which is). This is the threshold that decides whether cash holds up
A19: Covers needed per year (cash) | B19: =IFERROR(IF('3-Year P&L'!$B$9="","",IF(B10<=0,"",B18/B10)),"") -> 28273.567 | C19: =IFERROR(IF('3-Year P&L'!$C$9="","",IF(C10<=0,"",C18/C10)),"") -> 28592.393 | D19: =IFERROR(IF('3-Year P&L'!$D$9="","",IF(D10<=0,"",D18/D10)),"") -> 28911.22
A20: Covers needed per day (cash) | B20: =IFERROR(IF('3-Year P&L'!$B$9="","",B19/B11),"") -> 78.537685 | C20: =IFERROR(IF('3-Year P&L'!$C$9="","",C19/C11),"") -> 79.423315 | D20: =IFERROR(IF('3-Year P&L'!$D$9="","",D19/D11),"") -> 80.308945
A21: Revenue needed per year (cash) | B21: =IFERROR(IF('3-Year P&L'!$B$9="","",B19*B8),"") -> 763386.3 | C21: =IFERROR(IF('3-Year P&L'!$C$9="","",C19*C8),"") -> 771994.62 | D21: =IFERROR(IF('3-Year P&L'!$D$9="","",D19*D8),"") -> 780602.94
A22: COMPARISON WITH THE PLAN
A23: Covers per day forecast in the plan | B23: =IFERROR(IF('3-Year P&L'!$B$9="","",'3-Year P&L'!$B$6),"") -> 95 | C23: =IFERROR(IF('3-Year P&L'!$C$9="","",'3-Year P&L'!$C$6),"") -> 109.25 | D23: =IFERROR(IF('3-Year P&L'!$D$9="","",'3-Year P&L'!$D$6),"") -> 120.175
A24: Cushion above CASH break-even (%) | B24: =IFERROR(IF('3-Year P&L'!$B$9="","",B23/B20-1),"") -> 0.20961039 | C24: =IFERROR(IF('3-Year P&L'!$C$9="","",C23/C20-1),"") -> 0.37554067 | D24: =IFERROR(IF('3-Year P&L'!$D$9="","",D23/D20-1),"") -> 0.49640866 | E24: How far planned sales sit above cash break-even. The drop you can absorb before you cannot pay the fixed costs and the loan payment is somewhat smaller: with a 25% cushion, 20%. The required minimum is set in the "0. Assumptions" tab
A25: Maximum seat turns per day the space allows | B25: 3 | E25: Full table services per seat per day that your opening hours allow. It is the physical ceiling of the space, not a target
A26: Seat turns per day that the cash break-even requires | B26: =IFERROR(IF('3-Year P&L'!$B$9="","",B20/'0. Assumptions'!$B$51),"") -> 1.3089614 | C26: =IFERROR(IF('3-Year P&L'!$C$9="","",C20/'0. Assumptions'!$B$51),"") -> 1.3237219 | D26: =IFERROR(IF('3-Year P&L'!$D$9="","",D20/'0. Assumptions'!$B$51),"") -> 1.3384824 | E26: Break-even covers spread across the seats declared on the "0. Assumptions" tab. If it is above the ceiling in the row above, the break-even is out of reach for the space
A27: INTERPRETATION
A28: =IFERROR("With the average check excl. sales tax above, you need "&TEXT(ROUNDUP(B15,0),"0")&" covers a day over your "&TEXT(B11,"0")&" opening days to avoid losing money (accounting break-even, depreciation included), and "&TEXT(ROUNDUP(B20,0),"0")&" for cash to hold (cash break-even: depreciation out, because it is not paid, and the year's loan payment in"&IF(B12=0,"; no principal is repaid this year (interest-only period or no loan)","")&"). The ""Revenue needed per year"" rows show the same figures in your currency.","") -> With the average check excl. sales tax above, you need 81 covers a day over your 360 opening days to avoid losing money (accounting break-even, depreciation included), and 79 for cash to hold (cash break-even: depreciation out, because it is not paid, and the year's loan payment in). The "Revenue needed per year" rows show the same figures in your currency.
A30: BREAK-EVEN SENSITIVITY
A31: Covers per day needed to cover costs for each average check (columns) and each variable cost per cover (rows). Green cells are below the covers per day the plan forecasts.
A33: Covers per day needed: average check excl. sales tax (columns) × variable cost per cover (rows) | B33: =IFERROR($B$8-2,"") -> 25 | C33: =IFERROR(IF($B$8="","",$B$8),"") -> 27 | D33: =IFERROR($B$8+2,"") -> 29 | E33: =IFERROR($B$8+4,"") -> 31
A34: =IFERROR($B$9*0.85,"") -> 6.95385 | B34: =IFERROR(IF($B$33-$A34<=0,"",$B$6/($B$33-$A34)/$B$11),"") -> 83.60246 | C34: =IFERROR(IF($C$33-$A34<=0,"",$B$6/($C$33-$A34)/$B$11),"") -> 75.261461 | D34: =IFERROR(IF($D$33-$A34<=0,"",$B$6/($D$33-$A34)/$B$11),"") -> 68.433833 | E34: =IFERROR(IF($E$33-$A34<=0,"",$B$6/($E$33-$A34)/$B$11),"") -> 62.741958
A35: =IFERROR($B$9*0.925,"") -> 7.567425 | B35: =IFERROR(IF($B$33-$A35<=0,"",$B$6/($B$33-$A35)/$B$11),"") -> 86.545019 | C35: =IFERROR(IF($C$33-$A35<=0,"",$B$6/($C$33-$A35)/$B$11),"") -> 77.637809 | D35: =IFERROR(IF($D$33-$A35<=0,"",$B$6/($D$33-$A35)/$B$11),"") -> 70.392967 | E35: =IFERROR(IF($E$33-$A35<=0,"",$B$6/($E$33-$A35)/$B$11),"") -> 64.384838
A36: =IFERROR($B$9*1.0,"") -> 8.181 | B36: =IFERROR(IF($B$33-$A36<=0,"",$B$6/($B$33-$A36)/$B$11),"") -> 89.702274 | C36: =IFERROR(IF($C$33-$A36<=0,"",$B$6/($C$33-$A36)/$B$11),"") -> 80.169113 | D36: =IFERROR(IF($D$33-$A36<=0,"",$B$6/($D$33-$A36)/$B$11),"") -> 72.46758 | E36: =IFERROR(IF($E$33-$A36<=0,"",$B$6/($E$33-$A36)/$B$11),"") -> 66.116067
A37: =IFERROR($B$9*1.075,"") -> 8.794575 | B37: =IFERROR(IF($B$33-$A37<=0,"",$B$6/($B$33-$A37)/$B$11),"") -> 93.09861 | C37: =IFERROR(IF($C$33-$A37<=0,"",$B$6/($C$33-$A37)/$B$11),"") -> 82.871042 | D37: =IFERROR(IF($D$33-$A37<=0,"",$B$6/($D$33-$A37)/$B$11),"") -> 74.668191 | E37: =IFERROR(IF($E$33-$A37<=0,"",$B$6/($E$33-$A37)/$B$11),"") -> 67.942971
A38: =IFERROR($B$9*1.15,"") -> 9.40815 | B38: =IFERROR(IF($B$33-$A38<=0,"",$B$6/($B$33-$A38)/$B$11),"") -> 96.762253 | C38: =IFERROR(IF($C$33-$A38<=0,"",$B$6/($C$33-$A38)/$B$11),"") -> 85.761449 | D38: =IFERROR(IF($D$33-$A38<=0,"",$B$6/($D$33-$A38)/$B$11),"") -> 77.00664 | E38: =IFERROR(IF($E$33-$A38<=0,"",$B$6/($E$33-$A38)/$B$11),"") -> 69.873704

Sheet Scenarios
A1: SCENARIO ANALYSIS
A2: Pessimistic / Base / Optimistic — Year 1
A4: Metric | B4: Pessimistic | C4: Base | D4: Optimistic | E4: Notes
A5: Covers per day | B5: 71 | C5: =IFERROR(IF('3-Year P&L'!$B$6="","",'3-Year P&L'!$B$6),"") -> 95 | D5: 119
A6: Average check (excl. sales tax) | B6: 25 | C6: =IFERROR(IF('3-Year P&L'!$B$7="","",'3-Year P&L'!$B$7),"") -> 27 | D6: 29
A7: Operating days per year | B7: 340 | C7: =IFERROR(IF('3-Year P&L'!$B$8="","",'3-Year P&L'!$B$8),"") -> 360 | D7: 360
A8: ANNUAL REVENUE (excl. sales tax) | B8: =IFERROR(IF(B5*B6*B7=0,"",B5*B6*B7),"") -> 603500 | C8: =IFERROR(IF(C5*C6*C7=0,"",C5*C6*C7),"") -> 923400 | D8: =IFERROR(IF(D5*D6*D7=0,"",D5*D6*D7),"") -> 1242360
A9: Cost of goods sold — food | B9: =IFERROR(IF(B8="","",B8*'0. Assumptions'!$B$11*'0. Assumptions'!$B$13),"") -> 63367.5 | C9: =IFERROR(IF(C8="","",C8*'0. Assumptions'!$B$11*'0. Assumptions'!$B$13),"") -> 96957 | D9: =IFERROR(IF(D8="","",D8*'0. Assumptions'!$B$11*'0. Assumptions'!$B$13),"") -> 130447.8
A10: Cost of goods sold — beverage | B10: =IFERROR(IF(B8="","",B8*'0. Assumptions'!$B$12*'0. Assumptions'!$B$14),"") -> 86300.5 | C10: =IFERROR(IF(C8="","",C8*'0. Assumptions'!$B$12*'0. Assumptions'!$B$14),"") -> 132046.2 | D10: =IFERROR(IF(D8="","",D8*'0. Assumptions'!$B$12*'0. Assumptions'!$B$14),"") -> 177657.48
A11: Disposables and packaging | B11: =IFERROR(IF(B8="","",B8*'0. Assumptions'!$B$15),"") -> 6035 | C11: =IFERROR(IF(C8="","",C8*'0. Assumptions'!$B$15),"") -> 9234 | D11: =IFERROR(IF(D8="","",D8*'0. Assumptions'!$B$15),"") -> 12423.6
A12: Delivery platform fees | B12: =IFERROR(IF(B8="","",B8*'0. Assumptions'!$B$16*'0. Assumptions'!$B$17),"") -> 0 | C12: =IFERROR(IF(C8="","",C8*'0. Assumptions'!$B$16*'0. Assumptions'!$B$17),"") -> 0 | D12: =IFERROR(IF(D8="","",D8*'0. Assumptions'!$B$16*'0. Assumptions'!$B$17),"") -> 0
A13: Card processing fees | B13: =IFERROR(IF(B8="","",B8*'0. Assumptions'!$B$18),"") -> 21122.5 | C13: =IFERROR(IF(C8="","",C8*'0. Assumptions'!$B$18),"") -> 32319 | D13: =IFERROR(IF(D8="","",D8*'0. Assumptions'!$B$18),"") -> 43482.6
A14: Miscellaneous and contingency | B14: =IFERROR(IF(B8="","",B8*'0. Assumptions'!$B$28),"") -> 6035 | C14: =IFERROR(IF(C8="","",C8*'0. Assumptions'!$B$28),"") -> 9234 | D14: =IFERROR(IF(D8="","",D8*'0. Assumptions'!$B$28),"") -> 12423.6
A15: TOTAL VARIABLE COSTS | B15: =IFERROR(IF(B8="","",SUM(B9:B14)),"") -> 182860.5 | C15: =IFERROR(IF(C8="","",SUM(C9:C14)),"") -> 279790.2 | D15: =IFERROR(IF(D8="","",SUM(D9:D14)),"") -> 376435.08
A16: GROSS MARGIN | B16: =IFERROR(IF(B8="","",B8-B15),"") -> 420639.5 | C16: =IFERROR(IF(C8="","",C8-C15),"") -> 643609.8 | D16: =IFERROR(IF(D8="","",D8-D15),"") -> 865924.92
A17: FIXED COSTS (the P&L's) | B17: =IFERROR(IF(B8="","",'3-Year P&L'!$B$37),"") -> 543132.91 | C17: =IFERROR(IF(C8="","",'3-Year P&L'!$B$37),"") -> 543132.91 | D17: =IFERROR(IF(D8="","",'3-Year P&L'!$B$37),"") -> 543132.91 | E17: Fixed costs do not change with the scenario: that is why they are fixed
A18: PRE-TAX INCOME (EBT) | B18: =IFERROR(IF(B8="","",B16-B17),"") -> -122493.41 | C18: =IFERROR(IF(C8="","",C16-C17),"") -> 100476.89 | D18: =IFERROR(IF(D8="","",D16-D17),"") -> 322792.01
A19: Income tax | B19: =IFERROR(IF(B8="","",MAX(0,B18-'0. Assumptions'!$B$42)*'0. Assumptions'!$B$37),"") -> 0 | C19: =IFERROR(IF(C8="","",MAX(0,C18-'0. Assumptions'!$B$42)*'0. Assumptions'!$B$37),"") -> 25119.221 | D19: =IFERROR(IF(D8="","",MAX(0,D18-'0. Assumptions'!$B$42)*'0. Assumptions'!$B$37),"") -> 80698.001 | E19: At the "years 1-2" effective income tax rate, offsetting prior net operating losses
A20: NET INCOME | B20: =IFERROR(IF(B8="","",B18-B19),"") -> -122493.41 | C20: =IFERROR(IF(C8="","",C18-C19),"") -> 75357.664 | D20: =IFERROR(IF(D8="","",D18-D19),"") -> 242094
A21: Covers per day to break even | B21: =IFERROR(IF(B8="","",IF(B6-B15/(B5*B7)<=0,"",B17/(B6-B15/(B5*B7))/B7)),"") -> 91.675739 | C21: =IFERROR(IF(C8="","",IF(C6-C15/(C5*C7)<=0,"",C17/(C6-C15/(C5*C7))/C7)),"") -> 80.169113 | D21: =IFERROR(IF(D8="","",IF(D6-D15/(D5*D7)<=0,"",D17/(D6-D15/(D5*D7))/D7)),"") -> 74.640209
A22: WHAT EACH SCENARIO DEMANDS
A23: Labor cost / Sales | B23: =IFERROR(IF(B8="","",'3-Year P&L'!$B$23/B8),"") -> 0.51172693 | C23: =IFERROR(IF(C8="","",'3-Year P&L'!$B$23/C8),"") -> 0.33444574 | D23: =IFERROR(IF(D8="","",'3-Year P&L'!$B$23/D8),"") -> 0.24858109 | E23: The SAME staffing in all three scenarios. If labor cost blows up in the pessimistic case, adjust it in the Staffing tab, not here
A24: Covers per year per full-time equivalent | B24: =IFERROR(IF(B8="","",B5*B7/Staffing!$C$12),"") -> 3448.5714 | C24: =IFERROR(IF(C8="","",C5*C7/Staffing!$C$12),"") -> 4885.7143 | D24: =IFERROR(IF(D8="","",D5*D7/Staffing!$C$12),"") -> 6120 | E24: Covers each full-time employee in the "Staffing" tab would have to serve. In the optimistic scenario it tells you whether you need to hire
A25: Year-1 closing cash balance (estimate, same method in all three scenarios) | B25: =IFERROR(IF(B8="","",'Startup Costs'!$B$29+B20+'3-Year P&L'!$B$35-Financing!$B$45),"") -> 15791.049 | C25: =IFERROR(IF(C8="","",'Startup Costs'!$B$29+C20+'3-Year P&L'!$B$35-Financing!$B$45),"") -> 213642.13 | D25: =IFERROR(IF(D8="","",'Startup Costs'!$B$29+D20+'3-Year P&L'!$B$35-Financing!$B$45),"") -> 380378.47 | E25: ESTIMATED balance: working capital plus the year's result, adding back depreciation (which is not paid) and subtracting loan principal. It does not include the timing gap between receipts and payments or the sales tax settlement, so the three columns can be compared with each other. In red, the scenario runs out of cash
A26: Actual month-12 balance from the 12-Month Cash Flow tab (Base case only) | C26: =IFERROR(IF(C8="","",'12-Month Cash Flow'!$M$22),"") -> 270545.64 | E26: The ACTUAL base-case balance, with its timing of receipts and payments and its sales tax settlement. It exists only for the Base scenario, the only one with its own monthly cash flow: that is why it is not in the row above, where it would be compared against two estimates
A28: The "Base" column reads its three inputs from the "0. Assumptions" tab, so it reproduces EXACTLY year 1 of the P&L. The other two scenarios use the same cost rates: the only things that change are covers, average check and days. FIXED COSTS are the same in all three: miscellaneous and contingency, which is a percentage of sales, sits at the top with the variable costs and each scenario carries its own.

Sheet Staffing
A1: STAFFING STRUCTURE AND COSTS
A2: =IFERROR("Payroll — "&TEXT('0. Assumptions'!$B$21,"0")&" pay periods + employer taxes "&TEXT('0. Assumptions'!$B$20*100,"0")&"%","") -> Payroll — 12 pay periods + employer taxes 10%
A4: Position | B4: People | C4: FTE | D4: Gross pay per month (total for the position) | E4: Employer payroll taxes (total for the position) | F4: Cost per month (total for the position) | G4: Cost per year | H4: Hours per week per person | I4: Hours per year for the position | J4: Notes
A5: Owner / general manager | B5: 1 | C5: 1 | D5: 5000 | E5: =IFERROR(IF(D5="","",D5*'0. Assumptions'!$B$20),"") -> 500 | F5: =IFERROR(IF(D5="","",D5+E5),"") -> 5500 | G5: =IFERROR(IF(D5="","",F5*MAX(12,'0. Assumptions'!$B$21)),"") -> 66000 | H5: =IFERROR(IF(D5="","",C5*$B$19),"") -> 40 | I5: =IFERROR(IF(D5="","",H5*B5*$B$20),"") -> 2000 | J5: Handles purchasing, cash, vendors and social media, and covers the bar or the floor during the busy evening shift
A6: Kitchen lead | B6: 1 | C6: 1 | D6: 4200 | E6: =IFERROR(IF(D6="","",D6*'0. Assumptions'!$B$20),"") -> 420 | F6: =IFERROR(IF(D6="","",D6+E6),"") -> 4620 | G6: =IFERROR(IF(D6="","",F6*MAX(12,'0. Assumptions'!$B$21)),"") -> 55440 | H6: =IFERROR(IF(D6="","",C6*$B$19),"") -> 40 | I6: =IFERROR(IF(D6="","",H6*B6*$B$20),"") -> 2000 | J6: Designs the small-plates menu, runs the line and tracks food cost every week, a WEEKLY task in the first 90 days on the checklist. The one skilled role clearly above the wage floor
A7: Bartenders (peak shifts) | B7: 3 | C7: 0.7 | D7: 6188 | E7: =IFERROR(IF(D7="","",D7*'0. Assumptions'!$B$20),"") -> 618.8 | F7: =IFERROR(IF(D7="","",D7+E7),"") -> 6806.8 | G7: =IFERROR(IF(D7="","",F7*MAX(12,'0. Assumptions'!$B$21)),"") -> 81681.6 | H7: =IFERROR(IF(D7="","",C7*$B$19),"") -> 28 | I7: =IFERROR(IF(D7="","",H7*B7*$B$20),"") -> 4200 | J7: Pour draft beer, wine and cocktails. The after-work and evening rush is where a neighborhood bar earns most of its sales
A8: Servers (floor & patio) | B8: 2 | C8: 0.5 | D8: 2600 | E8: =IFERROR(IF(D8="","",D8*'0. Assumptions'!$B$20),"") -> 260 | F8: =IFERROR(IF(D8="","",D8+E8),"") -> 2860 | G8: =IFERROR(IF(D8="","",F8*MAX(12,'0. Assumptions'!$B$21)),"") -> 34320 | H8: =IFERROR(IF(D8="","",C8*$B$19),"") -> 20 | I8: =IFERROR(IF(D8="","",H8*B8*$B$20),"") -> 2000 | J8: Cover table and patio service in the evening shift, on part-time hours matched to the weekday traffic described in "Instructions"
A9: Line / prep cook | B9: 1 | C9: 0.8 | D9: 2496 | E9: =IFERROR(IF(D9="","",D9*'0. Assumptions'!$B$20),"") -> 249.6 | F9: =IFERROR(IF(D9="","",D9+E9),"") -> 2745.6 | G9: =IFERROR(IF(D9="","",F9*MAX(12,'0. Assumptions'!$B$21)),"") -> 32947.2 | H9: =IFERROR(IF(D9="","",C9*$B$19),"") -> 32 | I9: =IFERROR(IF(D9="","",H9*B9*$B$20),"") -> 1600 | J9: Prep, cleaning and support on the griddle and fryer during the busy shift, on part-time hours
A10: Barback / weekend extra | B10: 2 | C10: 0.4 | D10: 2080 | E10: =IFERROR(IF(D10="","",D10*'0. Assumptions'!$B$20),"") -> 208 | F10: =IFERROR(IF(D10="","",D10+E10),"") -> 2288 | G10: =IFERROR(IF(D10="","",F10*MAX(12,'0. Assumptions'!$B$21)),"") -> 27456 | H10: =IFERROR(IF(D10="","",C10*$B$19),"") -> 16 | I10: =IFERROR(IF(D10="","",H10*B10*$B$20),"") -> 1600 | J10: Extra hands for the Friday and Saturday peaks: restocking ice, glassware and kegs and clearing the bar, on a few hours a week, matched to the weekend peaks described in "Instructions"
A11: Relief cover (vacations + days off) | B11: 1 | C11: 0.3 | D11: 832 | E11: =IFERROR(IF(D11="","",D11*'0. Assumptions'!$B$20),"") -> 83.2 | F11: =IFERROR(IF(D11="","",D11+E11),"") -> 915.2 | G11: =IFERROR(IF(D11="","",F11*MAX(12,'0. Assumptions'!$B$21)),"") -> 10982.4 | H11: =IFERROR(IF(D11="","",C11*$B$19),"") -> 12 | I11: =IFERROR(IF(D11="","",H11*B11*$B$20),"") -> 600 | J11: Covers vacation, paid time off and the weekly day off for the team
A12: TOTAL STAFF | B12: =IFERROR(IF(COUNT(D5:D11)=0,"",SUM(B5:B11)),"") -> 11 | C12: =IFERROR(IF(COUNT(D5:D11)=0,"",SUMPRODUCT(B5:B11,C5:C11)),"") -> 7 | D12: =IFERROR(IF(COUNT(D5:D11)=0,"",SUM(D5:D11)),"") -> 23396 | E12: =IFERROR(IF(COUNT(D5:D11)=0,"",SUM(E5:E11)),"") -> 2339.6 | F12: =IFERROR(IF(COUNT(D5:D11)=0,"",SUM(F5:F11)),"") -> 25735.6 | G12: =IFERROR(IF(COUNT(D5:D11)=0,"",SUM(G5:G11)),"") -> 308827.2 | I12: =IFERROR(IF(COUNT(D5:D11)=0,"",SUM(I5:I11)),"") -> 14000
A13: STAFF GROWTH (stepped cost)
A14: Annual cost of year-2 hires | B14: 6000 | J14: FULL ANNUAL cost (gross pay + employer payroll taxes, over all pay periods) of whoever you hire that year. The P&L adds it to the previous year's cost: staffing grows by people, not by a percentage
A15: Annual cost of year-3 hires | B15: 6000 | J15: FULL ANNUAL cost (gross pay + employer payroll taxes, over all pay periods) of whoever you hire that year. The P&L adds it to the previous year's cost: staffing grows by people, not by a percentage
A16: Labor cost, year 2 | B16: =IFERROR(IF(G12="","",G12*(1+'0. Assumptions'!$B$48)+B14),"") -> 314827.2
A17: Labor cost, year 3 | B17: =IFERROR(IF(B16="","",B16*(1+'0. Assumptions'!$B$48)+B15),"") -> 320827.2
A18: COVERAGE OF SERVICE HOURS
A19: Full-time week (hours per week) | B19: 40 | J19: 40 hours a week is the FLSA overtime threshold for non-exempt employees; some states add daily overtime rules. Change it if your own full-time week is different
A20: Weeks worked per year per person | B20: 50 | J20: 50 weeks: 52 minus about two weeks of vacation, holidays and average absences. There is no federal vacation requirement in the US: adjust it to your own policy
A21: Service hours per day to cover | B21: 9 | J21: Hours the bar is open to the public each day, from opening to closing. It is an estimate for a neighborhood bar open from afternoon to late night: count the hours against your real schedule
A22: People needed at the same time in each shift | B22: 3.5 | J22: Average number of people working at the same time across the bar and the floor. Rushes need more people and the end of each shift needs fewer
A23: Production hours per day BEFORE opening | B23: 3 | J23: Prep time ahead of opening: small-plates mise en place, batched syrups and juices, garnish and ice, with the griddle, fryer and oven running. It is work time that does not overlap with serving guests
A24: People on the production shift | B24: 2 | J24: Kitchen lead and line / prep cook. Closing, cleaning and the management of purchasing and cash fall OUTSIDE this schedule: they are the margin between the hours hired and the hours needed
A25: Service hours to cover per year | B25: =IFERROR(IF(OR(B21="",B22="",'0. Assumptions'!$B$6=""),"",B21*B22*'0. Assumptions'!$B$6+B23*B24*'0. Assumptions'!$B$6),"") -> 13500
A26: Hours hired per year | B26: =IFERROR(IF(I12="","",I12),"") -> 14000
A27: Coverage (hired / needed) | B27: =IFERROR(B26/B25,"") -> 1.037037 | J27: Below 100% the staff cannot cover the hours the plan declares: either hire more or cut the hours
A29: The gross pay, employer payroll taxes, monthly cost and annual cost columns are TOTALS for the row: for a position with two people they include both. The payroll tax rate and the number of pay periods are in the "0. Assumptions" tab. Tips are not modeled: bartenders, barbacks and servers are budgeted at a base wage of at least $15/h. Federal rules allow a $2.13/h cash wage with a tip credit of up to $5.12 where the state permits it; CA, OR, WA, AK, MN, MT and NV do not (DOL)
A30: The pay floor is the HIGHER of the federal minimum wage and your state / local minimum wage, both in the "0. Assumptions" tab; part-time positions get it in proportion. There is no single national table above the federal floor: the state / local cell is delivered empty so you can enter the rate for your state and city.

Sheet Instructions
A1: HOW TO USE THIS WORKBOOK — Bar Financial Projections
A3: HOW TO USE THIS WORKBOOK
A4: This financial plan is a MODEL: you type only in the GREEN cells and everything else recalculates on its own.
A5: 1. "0. Assumptions" is the control sheet: covers per day, average check excl. sales tax, operating days, food and beverage mix, cost of goods sold, rent, financing and taxes.
A6: 2. Startup cost items, fixed costs and staffing are typed in their own tab, also in green. No number is typed twice.
A7: 3. On "Break-Even" you only type the seat-turn ceiling your space allows; everything else derives from the rest. The other three tabs also have green cells you can change: the pessimistic and optimistic scenarios on "Scenarios", the seasonality and the launch ramp-up on "12-Month Cash Flow", and the other financing sources on "Financing" (rows 8-11 count as sources but are not amortized: Your bank or SBA 7(a) loan goes in "Loan requested" on "0. Assumptions"). Everything else is calculated.
A8: 4. All figures are EXCL. SALES TAX. To turn a menu price into a price excl. sales tax, divide it by 1 + your sales tax rate (with an 8% rate, divide by 1.08); if an item is taxed at a different rate (alcohol to go, for instance), use that rate. The rate of each sales line is in the "Sales tax rate on the line (%)" column of the P&L, and from it come the receipts, the sales tax collected and the equivalent menu price incl. sales tax. With the default 0% recoverable input tax, the sales tax you pay on purchases and startup costs is treated as a cost; in the UK, enter 20% if you are VAT-registered.
A9: 5. If you change the staffing, the P&L reads it on its own: labor cost comes from the "Staffing" tab, not from a separate estimate.
A10: 6. The "12-Month Cash Flow" tab answers the question that decides a bank deal: in which month the cash runs out. The minimum balance of the year can never be in red.
A11: 7. The "Financing" tab matches what you need with what you put in and builds the amortization schedule of the loan. If the difference shows in red, the plan is not financed; far above zero is not free either, because you pay interest on money you do not use.
A12: 8. The Word document in this pack uses the same example figures as this workbook. If you change a number here, update the Word document to match: where the two differ, this spreadsheet is the one that recalculates.
A14: RATIOS AUDITED BY THIS WORKBOOK
A15: Thresholds live in the "Threshold" column of the KEY RATIOS block of the P&L: change them there and the traffic light changes with them.
A17: Ratio | B17: Year 1 value | C17: Threshold | D17: Status
A18: Cost of goods sold / Sales | B18: =IFERROR(IF('3-Year P&L'!$B$52="","",'3-Year P&L'!$B$52),"") -> 0.248 | C18: =IFERROR(IF('3-Year P&L'!$E$52="","",'3-Year P&L'!$E$52),"") -> 0.28 | D18: =IFERROR(IF(OR(B18="",C18=""),"",IF(B18<=C18,"OK","REVIEW")),"") -> OK
A19: Labor cost / Sales | B19: =IFERROR(IF('3-Year P&L'!$B$53="","",'3-Year P&L'!$B$53),"") -> 0.33444574 | C19: =IFERROR(IF('3-Year P&L'!$E$53="","",'3-Year P&L'!$E$53),"") -> 0.35 | D19: =IFERROR(IF(OR(B19="",C19=""),"",IF(B19<=C19,"OK","REVIEW")),"") -> OK
A20: Rent / Sales | B20: =IFERROR(IF('3-Year P&L'!$B$54="","",'3-Year P&L'!$B$54),"") -> 0.084470435 | C20: =IFERROR(IF('3-Year P&L'!$E$54="","",'3-Year P&L'!$E$54),"") -> 0.1 | D20: =IFERROR(IF(OR(B20="",C20=""),"",IF(B20<=C20,"OK","REVIEW")),"") -> OK
A21: Net income / Sales | B21: =IFERROR(IF('3-Year P&L'!$B$55="","",'3-Year P&L'!$B$55),"") -> 0.081608907 | C21: =IFERROR(IF('3-Year P&L'!$E$55="","",'3-Year P&L'!$E$55),"") -> 0.05 | D21: =IFERROR(IF(OR(B21="",C21=""),"",IF(B21>=C21,"OK","REVIEW")),"") -> OK
A22: Gross margin / Sales | B22: =IFERROR(IF('3-Year P&L'!$B$50="","",'3-Year P&L'!$B$50),"") -> 0.697 | C22: =IFERROR(IF('3-Year P&L'!$E$50="","",'3-Year P&L'!$E$50),"") -> 0.68 | D22: =IFERROR(IF(OR(B22="",C22=""),"",IF(B22>=C22,"OK","REVIEW")),"") -> OK
A24: THIS PLAN'S KEY FIGURES
A25: Total startup costs (sum of the blocks) | B25: =IFERROR(IF('Startup Costs'!$B$30="","",'Startup Costs'!$B$30),"") -> 488931.8
A26: Total cash needed at launch | B26: =IFERROR(IF('Startup Costs'!$B$33="","",'Startup Costs'!$B$33),"") -> 488931.8
A27: Working capital funded | B27: =IFERROR(IF('Startup Costs'!$B$29="","",'Startup Costs'!$B$29),"") -> 127231.8
A28: Forecast year-1 revenue | B28: =IFERROR(IF('3-Year P&L'!$B$9="","",'3-Year P&L'!$B$9),"") -> 923400
A29: Year-1 net income | B29: =IFERROR(IF('3-Year P&L'!$B$47="","",'3-Year P&L'!$B$47),"") -> 75357.664
A30: Covers per day for the ACCOUNTING break-even (depreciation included) | B30: =IFERROR(IF('Break-Even'!$B$15="","",'Break-Even'!$B$15),"") -> 80.169113
A31: Project payback (years), before debt | B31: =IFERROR(IF('12-Month Cash Flow'!$B$31="","",'12-Month Cash Flow'!$B$31),"") -> 2.5
A33: WHY THIS MODEL IS BUILT THIS WAY
A34: Item | B34: Common shortcut | C34: This workbook | D34: Why
