Workbook

Sheet Instrucciones
A1: Aceite de Fritura: Coste y Cambio
A2: AI Chef Pro · aichef.pro — Cómo Montar una Churrería-Chocolatería
A3: Para qué sirve: saber cuánto te cuesta el aceite por ración y al mes, cada cuántos días te sale a cuenta cambiar la cuba, qué te hace una subida del precio y cuánto aceite usado sale hacia el gestor.
A5: Instrucciones de Uso
A6: Celdas verdes = campos editables
A7: Las celdas en crema son resultados que el libro calcula; las blancas con fórmula, también. No escribas encima.
A9: 1. Hoja «Parámetros». Arriba, diez celdas verdes que copias a mano de los libros 3 y 1 (cada una dice de qué celda exacta). Debajo, tus datos del aceite: cada cuántos días cambias la cuba, cuánto repones al día y lo que te cobra el gestor. Al pie, primero el CONTRASTE (si tus copias son coherentes entre sí) y después el CUADRE: anota lo que publica hoy la celda de origen de cada cifra y, si lo que usas se separa, su fila se pone en rojo.
A10: 2. Hoja «Consumo y Reposición». Lo que tiras al cambiar la cuba (la renovación), lo que añades cada día para que no baje (la reposición) y lo que compras al mes. Aquí sale la renovación por ración que copia el libro 6, y la fila de contraste: aceite absorbido (libro 3) más renovación (este libro) igual a aceite total por ración.
A11: 3. Hoja «Punto Económico de Cambio». Cuánto cuesta cada ciclo de cambio, de 3 a 10 días (los días de la tabla se pueden cambiar), lo que te cuesta adelantar un día y lo que ahorras alargando uno. El límite no lo pone el dinero: lo pone el medidor.
A12: 4. Hoja «Escenarios de Precio del Aceite». Tres subidas del precio del aceite (sólo se teclea el porcentaje) y el margen que pierdes por ración, al mes y al año si no tocas el PVP.
A13: 5. Hoja «Gestor de Aceite Usado». Los litros que se lleva el gestor al mes y al año, lo que cuesta, el contraste con tu registro de retiradas y los papeles que tienes que guardar.
A15: Orden de Relleno y Cifras que Viajan
... A43: Versión 1.0 · octubre 2026 · aichef.pro/guia-churreria-chocolateria · info@aichef.pro

Sheet Parámetros
A1: Parámetros
A2: AI Chef Pro · aichef.pro — Cómo Montar una Churrería-Chocolatería
A3: Todo lo que el resto de hojas da por sabido vive aquí. Ninguna fórmula de este libro lleva dentro un precio, un umbral ni un número de días.
A5: Parámetro | B5: Valor | C5: Unidad | D5: De dónde sale | E5: Nota
A6: Lo que Copias del Libro 3 (Carta y Escandallo)
A7: Precio del aceite (base imponible) | B7: 1.996 | C7: EUR/L | D7: cópialo del libro 3: carta-de-apertura-y-escandallo-churro.xlsx!Parámetros!L5 | E7: El precio del aceite vive en UNA celda de todo el paquete, en el libro 3. Aquí se copia; no se vuelve a pedir.
A8: Absorción de aceite, en % del peso frito | B8: 0.1 | C8: del peso frito | D8: cópialo del libro 3: carta-de-apertura-y-escandallo-churro.xlsx!Parámetros!L6 | E8: Supuesto de El Molinete en el libro 3, sin fuente pública: copia el tuyo.
A9: Densidad del aceite | B9: 0.92 | C9: kg/L | D9: cópialo del libro 3: carta-de-apertura-y-escandallo-churro.xlsx!Parámetros!L7 | E9: Supuesto de El Molinete en el libro 3: hace falta porque la absorción va en peso y el aceite se compra por litros.
A10: Kilos de masa por ración media (merma incluida) | B10: 0.097918129 | C10: kg/ración | D10: cópialo del libro 3: carta-de-apertura-y-escandallo-churro.xlsx!Mix y Ticket Canal y Temporada!L5 | E10: Con la merma: es la masa que se fríe por cada ración media de la carta.
A11: Aceite absorbido por ración media | B11: 0.019119579 | C11: EUR/ración | D11: cópialo del libro 3: carta-de-apertura-y-escandallo-churro.xlsx!Absorción de Aceite y Merma!L5 | E11: Lo que se lleva la masa. Ya está dentro del coste de materia del libro 3; aquí sirve para el contraste con la renovación.
A13: Lo que Copias del Libro 1 (Producción y Local)
A14: Kilos fritos en un día tipo | B14: 22.031579 | C14: kg/día | D14: cópialo del libro 1: produccion-hora-punta-y-local.xlsx!Día Tipo y Día Punta!L5 | E14: Lo que sale de la freidora un día de lunes a viernes.
A15: Kilos fritos en un día punta | B15: 35.250526 | C15: kg/día | D15: cópialo del libro 1: produccion-hora-punta-y-local.xlsx!Día Tipo y Día Punta!L6 | E15: Lo que sale de la freidora un sábado, domingo o festivo.
A16: Litros totales de cuba (todas las freidoras) | B16: 25 | C16: L | D16: cópialo del libro 1: produccion-hora-punta-y-local.xlsx!Freidoras, Potencia y Riesgo!L5 | E16: Si tienes dos freidoras, la suma de las dos cubas: es lo que tiras en cada cambio.
A17: Raciones de un día tipo (lunes a viernes) | B17: 250 | C17: raciones | D17: cópialo del libro 1: produccion-hora-punta-y-local.xlsx!Día Tipo y Día Punta!L7 | E17: La demanda base nace en el libro 1.
A18: Raciones de un día punta (sábado, domingo y festivo) | B18: 400 | C18: raciones | D18: cópialo del libro 1: produccion-hora-punta-y-local.xlsx!Día Tipo y Día Punta!L8 | E18: La demanda base nace en el libro 1.
A20: Tus Datos del Aceite
A21: Días entre cambios de aceite (cada cuántos días vacías la cuba) | B21: 6 | C21: días | D21: supuesto declarado de El Molinete | E21: Supuesto declarado de El Molinete. Si tienes el Pack APPCC, usa tu registro: cuenta los días entre dos filas con «cambio de aceite» en su hoja «Control Aceite» (09-control-aceite-fritura.xlsx).
A22: Aceite que repones en un día tipo | B22: 2.39 | C22: L/día | D22: supuesto declarado de El Molinete (calculado con su absorción) | E22: El aceite nuevo que añades para que la cuba no baje. Mídelo una semana: los litros que entran en la freidora sin contar los cambios. La hoja «Consumo y Reposición» lo contrasta con la absorción del libro 3.
A23: Aceite que repones en un día punta | B23: 3.83 | C23: L/día | D23: supuesto declarado de El Molinete (calculado con su absorción) | E23: Lo mismo un sábado, domingo o festivo.
A24: Lo que te cobra el gestor de aceite usado al mes (base imponible) | B24: 0 | C24: EUR/mes | D24: supuesto declarado de El Molinete + CUS-44h | E24: En el ejemplo el gestor recoge a cambio de obsequios, servicios gratuitos o valoración económica: la recogida no cuesta. Si el tuyo cobra, pon aquí su importe sin IVA.
A25: Compuestos polares: el aceite tiene que estar por debajo de | B25: 0.25 | C25: del aceite | D25: CUN-02 | E25: Límite legal, medido con el método del anexo 1 de la norma (cromatografía en columna, en laboratorio). El medidor de mano te dice cuándo cambiar; el 25 % legal se prueba en laboratorio.
A26: Litros que retiró tu gestor el último mes (de tu registro) | B26: 126.7 | C26: L/mes | D26: supuesto declarado de El Molinete (lo que calcula este libro) | E26: Anótalo de la hoja «Retirada de aceite usado» del Pack APPCC 09. La hoja «Gestor de Aceite Usado» lo contrasta con lo que renuevas.
A28: Calendario y Tolerancia
A29: Días tipo a la semana | B29: 5 | C29: días | D29: supuesto declarado de El Molinete (horario: de lunes a viernes) | E29: Los días con las raciones del día tipo. Pesan en la ración media de la semana.
A30: Días punta a la semana | B30: 2 | C30: días | D30: supuesto declarado de El Molinete (horario: sábado y domingo) | E30: Los días con las raciones del día punta. Si cierras un día, réstalo de su grupo.
A31: Días naturales del año | B31: 365 | C31: días | D31: calendario | E31: Los cambios de aceite se cuentan en días de calendario, como en el registro, que va por fechas.
A32: Días naturales por mes (media) | B32: =IFERROR('Parámetros'!$B$31/12,"") -> 30.416667 | C32: días | D32: calculado | E32: Días del año entre los doce meses.
A33: Tolerancia de los contrastes | B33: 0.05 | D33: supuesto declarado de este libro | E33: Cuánto pueden separarse dos cifras que deberían coincidir (lo que repones frente a lo que dice la absorción, las proporciones punta/tipo) antes de que la hoja avise.
A34: Tolerancia de las filas de CUADRE | B34: 0.02 | D34: heredado de la Guía de la Chocolatería (tolerancia de las filas de CUADRE) | E34: Por encima de esta desviación, la fila de CUADRE avisa de que lo que has copiado no es lo que publica el libro de origen.
A36: Contraste entre tus Copias
A37: Aceite absorbido por ración, recalculado con tus copias (kg fritos del día tipo / raciones del día tipo x absorción / densidad x precio) | B37: =IFERROR('Parámetros'!$B$14/'Parámetros'!$B$17*'Parámetros'!$B$8/'Parámetros'!$B$9*'Parámetros'!$B$7,"") -> 0.019119579 | C37: EUR/ración | D37: Con las cifras de El Molinete coinciden al céntimo: salen de los mismos supuestos. Si una se ha copiado de una versión vieja, se separan.
A38: Separación entre el aceite absorbido copiado y el recalculado | B38: =IFERROR(ABS(B37/'Parámetros'!$B$11-1),"") -> 0
A39: Kilos fritos del día punta entre los del día tipo | B39: =IFERROR('Parámetros'!$B$15/'Parámetros'!$B$14,"") -> 1.6 | C39: veces
A40: Raciones del día punta entre las del día tipo | B40: =IFERROR('Parámetros'!$B$18/'Parámetros'!$B$17,"") -> 1.6 | C40: veces
A41: Separación entre las dos proporciones | B41: =IFERROR(ABS(B39/B40-1),"") -> 2.220446e-16
A42: Kilos fritos por kilo de masa que implican tus copias | B42: =IFERROR('Parámetros'!$B$14/('Parámetros'!$B$17*'Parámetros'!$B$10),"") -> 0.9 | C42: kg/kg
A43: Máximo físico con tu absorción: 1 / (1 - absorción) | B43: =IFERROR(1/(1-'Parámetros'!$B$8),"") -> 1.1111111 | C43: kg/kg | D43: La pieza frita pierde agua y gana aceite: por cada kilo de masa no puede salir más de esto.
A44: Litros que repondrías en un día punta según tu absorción | B44: =IFERROR('Parámetros'!$B$15*'Parámetros'!$B$8/'Parámetros'!$B$9,"") -> 3.8315789 | C44: L/día
A45: Contraste | B45: Veredicto | C45: Celdas que compara | D45: Qué compara | E45: Si no es coherente
...

Sheet Consumo y Reposición
A1: Consumo y Reposición
A2: AI Chef Pro · aichef.pro — Cómo Montar una Churrería-Chocolatería
A3: Lo que tiras al cambiar la cuba, lo que añades cada día y lo que compras. El aceite que se lleva la masa (absorbido) está en el libro 3.
A4: Renovación: el Aceite que Tiras al Cambiar la Cuba | K4: Lo que Copian Otros Libros (No Muevas Estas Celdas)
A5: Litros de cuba (todas las freidoras) | B5: ='Parámetros'!$B$16 -> 25 | C5: L | K5: Renovación de aceite por ración (EUR) | L5: =B11 -> 0.028398374 | M5: Lo copia: libro 6 (plan-financiero-3-anos-churreria.xlsx, hoja 0. Supuestos, X12)
A6: Días entre cambios | B6: ='Parámetros'!$B$21 -> 6 | C6: días
A7: Litros renovados por día | B7: =IFERROR(B5/B6,"") -> 4.1666667 | C7: L/día
A8: Precio del aceite (base imponible) | B8: ='Parámetros'!$B$7 -> 1.996 | C8: EUR/L
A9: Renovación en euros por día | B9: =IFERROR(B7*B8,"") -> 8.3166667 | C9: EUR/día
A10: Raciones de un día medio de la semana | B10: =IFERROR(('Parámetros'!$B$29*'Parámetros'!$B$17+'Parámetros'!$B$30*'Parámetros'!$B$18)/('Parámetros'!$B$29+'Parámetros'!$B$30),"") -> 292.85714 | C10: raciones/día
A11: RENOVACIÓN POR RACIÓN | B11: =IFERROR(B9/B10,"") -> 0.028398374 | C11: EUR/ración | D11: La copia el libro 6 (bloque de la derecha). Va sobre la ración media de la semana: cinco días tipo y dos punta, sin festivos ni días cerrados. El libro 6 la multiplica por las raciones del año, que sí los cuentan: por eso su cifra anual y la de este libro pueden separarse en torno a un 0,5 %.
A12: Días naturales por mes (media) | B12: ='Parámetros'!$B$32 -> 30.416667 | C12: días
A13: Renovación en euros al mes | B13: =IFERROR(B9*B12,"") -> 252.96528 | C13: EUR/mes
A15: Reposición: el Aceite que Añades para que la Cuba no Baje
A16: Concepto | B16: Día tipo | C16: Día punta | D16: Media de la semana | E16: Unidad
A17: Kilos fritos (copiados del libro 1) | B17: ='Parámetros'!$B$14 -> 22.031579 | C17: ='Parámetros'!$B$15 -> 35.250526 | D17: =IFERROR(('Parámetros'!$B$29*B17+'Parámetros'!$B$30*C17)/('Parámetros'!$B$29+'Parámetros'!$B$30),"") -> 25.808421 | E17: kg/día
A18: Reposición que mides (Parámetros) | B18: ='Parámetros'!$B$22 -> 2.39 | C18: ='Parámetros'!$B$23 -> 3.83 | D18: =IFERROR(('Parámetros'!$B$29*B18+'Parámetros'!$B$30*C18)/('Parámetros'!$B$29+'Parámetros'!$B$30),"") -> 2.8014286 | E18: L/día | G18: Reponer es una decisión de cocina, no un permiso de la norma: el aceite se cambia cuando el medidor se acerca al límite de compuestos polares. Varios artículos de la norma de aceites calentados están derogados; el que sigue vivo prohíbe añadir al aceite sustancias extrañas y vender el usado para uso alimentario.
A19: Reposición que sale de la absorción del libro 3 (kg fritos x absorción / densidad) | B19: =IFERROR(B17*'Parámetros'!$B$8/'Parámetros'!$B$9,"") -> 2.3947368 | C19: =IFERROR(C17*'Parámetros'!$B$8/'Parámetros'!$B$9,"") -> 3.8315789 | D19: =IFERROR(('Parámetros'!$B$29*B19+'Parámetros'!$B$30*C19)/('Parámetros'!$B$29+'Parámetros'!$B$30),"") -> 2.8052632 | E19: L/día
A20: Lo que repones de más (+) o de menos (-) frente a la absorción | B20: =IFERROR(B18/B19-1,"") -> -0.001978022 | C20: =IFERROR(C18/C19-1,"") -> -0.00041208791 | D20: =IFERROR(D18/D19-1,"") -> -0.0013669258
A21: Contraste | B21: =IF(ISNUMBER(B20),IF(B20>'Parámetros'!$B$33,"Repones más de lo que dice la absorción del libro 3: revísala, o busca derrames y fugas",IF(B20<-'Parámetros'!$B$33,"Repones menos de lo que dice la absorción del libro 3: revísala","Tu reposición cuadra con la absorción del libro 3")),"") -> Tu reposición cuadra con la absorción del libro 3 | C21: =IF(ISNUMBER(C20),IF(C20>'Parámetros'!$B$33,"Repones más de lo que dice la absorción del libro 3: revísala, o busca derrames y fugas",IF(C20<-'Parámetros'!$B$33,"Repones menos de lo que dice la absorción del libro 3: revísala","Tu reposición cuadra con la absorción del libro 3")),"") -> Tu reposición cuadra con la absorción del libro 3 | D21: =IF(ISNUMBER(D20),IF(D20>'Parámetros'!$B$33,"Repones más de lo que dice la absorción del libro 3: revísala, o busca derrames y fugas",IF(D20<-'Parámetros'!$B$33,"Repones menos de lo que dice la absorción del libro 3: revísala","Tu reposición cuadra con la absorción del libro 3")),"") -> Tu reposición cuadra con la absorción del libro 3
A22: Reposición en euros | B22: =IFERROR(B18*'Parámetros'!$B$7,"") -> 4.77044 | C22: =IFERROR(C18*'Parámetros'!$B$7,"") -> 7.64468 | D22: =IFERROR(('Parámetros'!$B$29*B22+'Parámetros'!$B$30*C22)/('Parámetros'!$B$29+'Parámetros'!$B$30),"") -> 5.5916514 | E22: EUR/día
A23: Reposición en euros por ración | B23: =IFERROR(B22/'Parámetros'!$B$17,"") -> 0.01908176 | C23: =IFERROR(C22/'Parámetros'!$B$18,"") -> 0.0191117 | D23: =IFERROR(('Parámetros'!$B$29*B22+'Parámetros'!$B$30*C22)/('Parámetros'!$B$29*'Parámetros'!$B$17+'Parámetros'!$B$30*'Parámetros'!$B$18),"") -> 0.019093444 | E23: EUR/ración
A25: Lo que Compras de Aceite
A26: Concepto | B26: Día tipo | C26: Día punta | D26: Media de la semana | E26: Al mes
A27: Litros que compras (renovación + reposición) | B27: =IFERROR($B$7+B18,"") -> 6.5566667 | C27: =IFERROR($B$7+C18,"") -> 7.9966667 | D27: =IFERROR(('Parámetros'!$B$29*B27+'Parámetros'!$B$30*C27)/('Parámetros'!$B$29+'Parámetros'!$B$30),"") -> 6.9680952 | E27: =IFERROR(D27*$B$12,"") -> 211.94623
A28: Euros de aceite que compras (base imponible) | B28: =IFERROR(B27*'Parámetros'!$B$7,"") -> 13.087107 | C28: =IFERROR(C27*'Parámetros'!$B$7,"") -> 15.961347 | D28: =IFERROR(('Parámetros'!$B$29*B28+'Parámetros'!$B$30*C28)/('Parámetros'!$B$29+'Parámetros'!$B$30),"") -> 13.908318 | E28: =IFERROR(D28*$B$12,"") -> 423.04468
A30: Fila de Contraste: Aceite Absorbido (3) + Renovación (4) = Aceite Total por Ración
A31: Aceite absorbido por ración (libro 3, copiado en Parámetros) | B31: ='Parámetros'!$B$11 -> 0.019119579 | C31: EUR/ración
A32: Renovación por ración (este libro) | B32: =B11 -> 0.028398374 | C32: EUR/ración
A33: ACEITE TOTAL POR RACIÓN | B33: =IFERROR(B31+B32,"") -> 0.047517953 | C33: EUR/ración | D33: El libro 6 suma las dos partes, cada una con su fuente: la absorbida dentro del coste de materia del libro 3 y la renovación con la celda de la derecha. Así no se cuenta dos veces.
A34: Parte del aceite total que es renovación | B34: =IFERROR(B32/B33,"") -> 0.59763463
A35: Reposición que mides, por ración (media de la semana) | B35: =D23 -> 0.019093444 | C35: EUR/ración
A36: Reposición por ración menos aceite absorbido por ración | B36: =IFERROR(B35-B31,"") -> -2.6135045e-05 | C36: EUR/ración | D36: Cerca de cero si tu absorción del libro 3 es realista: lo que repones es, sobre todo, lo que se lleva la masa.
A37: Kilos de masa por ración media (libro 3, copiado en Parámetros) | B37: ='Parámetros'!$B$10 -> 0.097918129 | C37: kg/ración
A38: Aceite absorbido por kilo de masa | B38: =IFERROR(B31/B37,"") -> 0.19526087 | C38: EUR/kg de masa
A39: Renovación por kilo de masa | B39: =IFERROR(B32/B37,"") -> 0.29002162 | C39: EUR/kg de masa
A40: ACEITE TOTAL POR KILO DE MASA | B40: =IFERROR(B38+B39,"") -> 0.48528249 | C40: EUR/kg de masa | D40: Lo que te cuesta el aceite por cada kilo de masa que fríes: lo que se lleva la pieza y lo que tiras al cambiar la cuba. Sirve para comparar con el precio por kilo de tu preparado o de tu mix.
A42: La norma de calidad de los aceites y grasas calentados alcanza a la churrería, sea permanente o de temporada: la nota de esta celda dice dónde.
A44: Versión 1.0 · octubre 2026 · aichef.pro/guia-churreria-chocolateria · info@aichef.pro

Sheet Punto Económico de Cambio
A1: Punto Económico de Cambio
A2: AI Chef Pro · aichef.pro — Cómo Montar una Churrería-Chocolatería
A3: Cuánto cuesta cada ciclo de cambio de la cuba. El dinero te dice cuánto ahorras alargando; el medidor te dice hasta dónde puedes.
A4: Cuánto Te Cuesta Cada Ciclo de Cambio
A6: Días entre cambios (cámbialos) | B6: Litros renovados por día | C6: Renovación en euros por día | D6: Renovación por ración (EUR) | E6: Aceite total por ración: absorbido + renovación (EUR) | F6: Renovación al mes (EUR) | G6: Litros al gestor al mes | H6: Diferencia al mes frente a tu ciclo (EUR) | I6: ¿Es tu ciclo?
A7: 3 | B7: =IFERROR('Consumo y Reposición'!$B$5/A7,"") -> 8.3333333 | C7: =IFERROR(B7*'Consumo y Reposición'!$B$8,"") -> 16.633333 | D7: =IFERROR(C7/'Consumo y Reposición'!$B$10,"") -> 0.056796748 | E7: =IFERROR(D7+'Parámetros'!$B$11,"") -> 0.075916327 | F7: =IFERROR(C7*'Consumo y Reposición'!$B$12,"") -> 505.93056 | G7: =IFERROR(B7*'Consumo y Reposición'!$B$12,"") -> 253.47222 | H7: =IFERROR(F7-'Consumo y Reposición'!$B$13,"") -> 252.96528 | I7: =IF(A7='Parámetros'!$B$21,"Tu ciclo","")
A8: 4 | B8: =IFERROR('Consumo y Reposición'!$B$5/A8,"") -> 6.25 | C8: =IFERROR(B8*'Consumo y Reposición'!$B$8,"") -> 12.475 | D8: =IFERROR(C8/'Consumo y Reposición'!$B$10,"") -> 0.042597561 | E8: =IFERROR(D8+'Parámetros'!$B$11,"") -> 0.06171714 | F8: =IFERROR(C8*'Consumo y Reposición'!$B$12,"") -> 379.44792 | G8: =IFERROR(B8*'Consumo y Reposición'!$B$12,"") -> 190.10417 | H8: =IFERROR(F8-'Consumo y Reposición'!$B$13,"") -> 126.48264 | I8: =IF(A8='Parámetros'!$B$21,"Tu ciclo","")
A9: 5 | B9: =IFERROR('Consumo y Reposición'!$B$5/A9,"") -> 5 | C9: =IFERROR(B9*'Consumo y Reposición'!$B$8,"") -> 9.98 | D9: =IFERROR(C9/'Consumo y Reposición'!$B$10,"") -> 0.034078049 | E9: =IFERROR(D9+'Parámetros'!$B$11,"") -> 0.053197628 | F9: =IFERROR(C9*'Consumo y Reposición'!$B$12,"") -> 303.55833 | G9: =IFERROR(B9*'Consumo y Reposición'!$B$12,"") -> 152.08333 | H9: =IFERROR(F9-'Consumo y Reposición'!$B$13,"") -> 50.593056 | I9: =IF(A9='Parámetros'!$B$21,"Tu ciclo","")
A10: 6 | B10: =IFERROR('Consumo y Reposición'!$B$5/A10,"") -> 4.1666667 | C10: =IFERROR(B10*'Consumo y Reposición'!$B$8,"") -> 8.3166667 | D10: =IFERROR(C10/'Consumo y Reposición'!$B$10,"") -> 0.028398374 | E10: =IFERROR(D10+'Parámetros'!$B$11,"") -> 0.047517953 | F10: =IFERROR(C10*'Consumo y Reposición'!$B$12,"") -> 252.96528 | G10: =IFERROR(B10*'Consumo y Reposición'!$B$12,"") -> 126.73611 | H10: =IFERROR(F10-'Consumo y Reposición'!$B$13,"") -> 0 | I10: =IF(A10='Parámetros'!$B$21,"Tu ciclo","") -> Tu ciclo
A11: 7 | B11: =IFERROR('Consumo y Reposición'!$B$5/A11,"") -> 3.5714286 | C11: =IFERROR(B11*'Consumo y Reposición'!$B$8,"") -> 7.1285714 | D11: =IFERROR(C11/'Consumo y Reposición'!$B$10,"") -> 0.024341463 | E11: =IFERROR(D11+'Parámetros'!$B$11,"") -> 0.043461042 | F11: =IFERROR(C11*'Consumo y Reposición'!$B$12,"") -> 216.82738 | G11: =IFERROR(B11*'Consumo y Reposición'!$B$12,"") -> 108.63095 | H11: =IFERROR(F11-'Consumo y Reposición'!$B$13,"") -> -36.137897 | I11: =IF(A11='Parámetros'!$B$21,"Tu ciclo","")
A12: 8 | B12: =IFERROR('Consumo y Reposición'!$B$5/A12,"") -> 3.125 | C12: =IFERROR(B12*'Consumo y Reposición'!$B$8,"") -> 6.2375 | D12: =IFERROR(C12/'Consumo y Reposición'!$B$10,"") -> 0.02129878 | E12: =IFERROR(D12+'Parámetros'!$B$11,"") -> 0.040418359 | F12: =IFERROR(C12*'Consumo y Reposición'!$B$12,"") -> 189.72396 | G12: =IFERROR(B12*'Consumo y Reposición'!$B$12,"") -> 95.052083 | H12: =IFERROR(F12-'Consumo y Reposición'!$B$13,"") -> -63.241319 | I12: =IF(A12='Parámetros'!$B$21,"Tu ciclo","")
A13: 9 | B13: =IFERROR('Consumo y Reposición'!$B$5/A13,"") -> 2.7777778 | C13: =IFERROR(B13*'Consumo y Reposición'!$B$8,"") -> 5.5444444 | D13: =IFERROR(C13/'Consumo y Reposición'!$B$10,"") -> 0.018932249 | E13: =IFERROR(D13+'Parámetros'!$B$11,"") -> 0.038051828 | F13: =IFERROR(C13*'Consumo y Reposición'!$B$12,"") -> 168.64352 | G13: =IFERROR(B13*'Consumo y Reposición'!$B$12,"") -> 84.490741 | H13: =IFERROR(F13-'Consumo y Reposición'!$B$13,"") -> -84.321759 | I13: =IF(A13='Parámetros'!$B$21,"Tu ciclo","")
A14: 10 | B14: =IFERROR('Consumo y Reposición'!$B$5/A14,"") -> 2.5 | C14: =IFERROR(B14*'Consumo y Reposición'!$B$8,"") -> 4.99 | D14: =IFERROR(C14/'Consumo y Reposición'!$B$10,"") -> 0.017039024 | E14: =IFERROR(D14+'Parámetros'!$B$11,"") -> 0.036158603 | F14: =IFERROR(C14*'Consumo y Reposición'!$B$12,"") -> 151.77917 | G14: =IFERROR(B14*'Consumo y Reposición'!$B$12,"") -> 76.041667 | H14: =IFERROR(F14-'Consumo y Reposición'!$B$13,"") -> -101.18611 | I14: =IF(A14='Parámetros'!$B$21,"Tu ciclo","")
A16: Tu Ciclo y el Punto Económico
A17: Tu ciclo actual (días entre cambios) | F17: ='Parámetros'!$B$21 -> 6 | G17: días
A18: Renovación al mes con tu ciclo | F18: ='Consumo y Reposición'!$B$13 -> 252.96528 | G18: EUR/mes
A19: Lo que te cuesta cambiar un día antes | F19: =IFERROR('Consumo y Reposición'!$B$5*'Consumo y Reposición'!$B$8*'Consumo y Reposición'!$B$12*(1/(F17-1)-1/F17),"") -> 50.593056 | G19: EUR/mes más
A20: Lo que ahorras alargando un día (si el medidor te deja) | F20: =IFERROR('Consumo y Reposición'!$B$5*'Consumo y Reposición'!$B$8*'Consumo y Reposición'!$B$12*(1/F17-1/(F17+1)),"") -> 36.137897 | G20: EUR/mes menos
A21: Días a partir de los cuales lo que tiras al cambiar cuesta menos por ración que lo que se lleva la masa | F21: =IFERROR('Consumo y Reposición'!$B$5*'Consumo y Reposición'!$B$8/('Consumo y Reposición'!$B$10*'Parámetros'!$B$11),"") -> 8.9118199 | G21: días
A22: Veredicto | F22: =IF(AND(ISNUMBER(F17),ISNUMBER(F21)),IF(F17<F21,"Con tu ciclo, el aceite que tiras al cambiar cuesta más por ración que el que se lleva la masa: cada día que alargues, sin pasar del límite del medidor, se nota","Con tu ciclo, lo que tiras al cambiar ya cuesta menos por ración que lo que se lleva la masa: alargar más ahorra poco"),"") -> Con tu ciclo, el aceite que tiras al cambiar cuesta más por ración que el que se lleva la masa: cada día que alargues, sin pasar del límite del medidor, se nota
A23: El límite que no se negocia: compuestos polares por debajo de | F23: ='Parámetros'!$B$25 -> 0.25
A25: El día del cambio lo decide la lectura del medidor de mano, no esta tabla: anótala en tu registro del Pack APPCC (hoja «Control Aceite») y cambia antes de llegar al límite. El medidor es una ayuda para decidir; el 25 % legal se prueba en laboratorio, con el método del anexo 1 de la norma. Esta tabla sólo te dice cuánto dinero hay en juego en cada día que ganes o pierdas.
A27: Versión 1.0 · octubre 2026 · aichef.pro/guia-churreria-chocolateria · info@aichef.pro

Sheet Escenarios de Precio del Aceite
A1: Escenarios de Precio del Aceite
A2: AI Chef Pro · aichef.pro — Cómo Montar una Churrería-Chocolatería
A3: Tres subidas sobre el precio de hoy. Sólo se teclea el porcentaje: lo demás sale solo.
A4: Lo que Te Hace una Subida del Aceite
A6: Escenario | B6: Subida sobre el precio de hoy | C6: Precio del aceite (EUR/L) | D6: Aceite absorbido por ración (EUR) | E6: Renovación por ración (EUR) | F6: Aceite total por ración (EUR) | G6: Aceite que compras al mes (EUR) | H6: Margen que pierdes por ración (EUR) | I6: Margen que pierdes al mes (EUR) | J6: Margen que pierdes al año (EUR)
A7: Hoy | B7: precio de hoy | C7: ='Parámetros'!$B$7 -> 1.996 | D7: =IFERROR('Parámetros'!$B$11*C7/$C$7,"") -> 0.019119579 | E7: =IFERROR('Consumo y Reposición'!$B$7*C7/'Consumo y Reposición'!$B$10,"") -> 0.028398374 | F7: =IFERROR(D7+E7,"") -> 0.047517953 | G7: =IFERROR('Consumo y Reposición'!$E$27*C7,"") -> 423.04468 | H7: =IFERROR(F7-$F$7,"") -> 0 | I7: =IFERROR(G7-$G$7,"") -> 0 | J7: =IFERROR(I7*12,"") -> 0
A8: Subida 1 | B8: 0.1 | C8: =IFERROR($C$7*(1+B8),"") -> 2.1956 | D8: =IFERROR('Parámetros'!$B$11*C8/$C$7,"") -> 0.021031537 | E8: =IFERROR('Consumo y Reposición'!$B$7*C8/'Consumo y Reposición'!$B$10,"") -> 0.031238211 | F8: =IFERROR(D8+E8,"") -> 0.052269748 | G8: =IFERROR('Consumo y Reposición'!$E$27*C8,"") -> 465.34914 | H8: =IFERROR(F8-$F$7,"") -> 0.0047517953 | I8: =IFERROR(G8-$G$7,"") -> 42.304468 | J8: =IFERROR(I8*12,"") -> 507.65361
A9: Subida 2 | B9: 0.2 | C9: =IFERROR($C$7*(1+B9),"") -> 2.3952 | D9: =IFERROR('Parámetros'!$B$11*C9/$C$7,"") -> 0.022943495 | E9: =IFERROR('Consumo y Reposición'!$B$7*C9/'Consumo y Reposición'!$B$10,"") -> 0.034078049 | F9: =IFERROR(D9+E9,"") -> 0.057021544 | G9: =IFERROR('Consumo y Reposición'!$E$27*C9,"") -> 507.65361 | H9: =IFERROR(F9-$F$7,"") -> 0.0095035906 | I9: =IFERROR(G9-$G$7,"") -> 84.608935 | J9: =IFERROR(I9*12,"") -> 1015.3072
A10: Subida 3 | B10: 0.3 | C10: =IFERROR($C$7*(1+B10),"") -> 2.5948 | D10: =IFERROR('Parámetros'!$B$11*C10/$C$7,"") -> 0.024855453 | E10: =IFERROR('Consumo y Reposición'!$B$7*C10/'Consumo y Reposición'!$B$10,"") -> 0.036917886 | F10: =IFERROR(D10+E10,"") -> 0.061773339 | G10: =IFERROR('Consumo y Reposición'!$E$27*C10,"") -> 549.95808 | H10: =IFERROR(F10-$F$7,"") -> 0.014255386 | I10: =IFERROR(G10-$G$7,"") -> 126.9134 | J10: =IFERROR(I10*12,"") -> 1522.9608
A12: Cómo Leerlo
A13: Lo que sube por ración es lo que baja tu margen por ración si no tocas el PVP: para no perderlo, el PVP sin IVA tendría que subir esa misma cantidad. Sólo se mueve el aceite (el que se lleva la masa y el que tiras al cambiar); el resto del escandallo se queda donde estaba.
A14: El margen que pierdes al mes sale del aceite que COMPRAS (la renovación más tu reposición medida), no de las raciones: es lo que de verdad sale de la caja. Si cambias el precio de la garrafa, hazlo en el libro 3 (allí se recalcula todo el coste de materia) y cópialo aquí.
A16: Versión 1.0 · octubre 2026 · aichef.pro/guia-churreria-chocolateria · info@aichef.pro

Sheet Gestor de Aceite Usado
A1: Gestor de Aceite Usado
A2: AI Chef Pro · aichef.pro — Cómo Montar una Churrería-Chocolatería
A3: El aceite que tiras al cambiar la cuba sale por la puerta de atrás hacia un gestor autorizado. Aquí, cuánto, cuánto cuesta y qué papeles guardas.
A4: Lo que Se Lleva el Gestor
A5: Litros renovados por día | B5: ='Consumo y Reposición'!$B$7 -> 4.1666667 | C5: L/día
A6: Días naturales por mes (media) | B6: ='Parámetros'!$B$32 -> 30.416667 | C6: días
A7: LITROS AL GESTOR AL MES | B7: =IFERROR(B5*B6,"") -> 126.73611 | C7: L/mes | D7: Sólo el aceite de los cambios de cuba: la reposición se la lleva la masa.
A8: Litros al gestor al año | B8: =IFERROR(B5*'Parámetros'!$B$31,"") -> 1520.8333 | C8: L/año
A9: Lo que te cobra el gestor al mes (base imponible) | B9: ='Parámetros'!$B$24 -> 0 | C9: EUR/mes
A10: Lo que te cobra el gestor al año | B10: =IFERROR(B9*12,"") -> 0 | C10: EUR/año
A11: Coste del gestor por ración | B11: =IFERROR(B9/('Consumo y Reposición'!$B$10*B6),"") -> 0 | C11: EUR/ración | D11: Con un gestor que recoge sin cobrar, cero. Lo que no puede faltar es el justificante de cada retirada.
A13: Contraste con tu Registro de Retiradas
A14: Litros que retiró tu gestor el último mes (Parámetros) | B14: ='Parámetros'!$B$26 -> 126.7
A15: Diferencia frente a los litros que calcula este libro | B15: =IFERROR(B14/B7-1,"") -> -0.00028493151
A16: Contraste | B16: =IF(ISNUMBER(B15),IF(B15<-'Parámetros'!$B$33,"El gestor se lleva menos aceite del que renuevas: averigua a dónde va el resto",IF(B15>'Parámetros'!$B$33,"El gestor se lleva más aceite del que calcula este libro: revisa los días entre cambios y los litros de cuba","Cuadra con tu registro de retiradas")),"") -> Cuadra con tu registro de retiradas
A18: Obligaciones y Papeles que Guardas
A19: El aceite de cocina usado de la hostelería tiene recogida separada obligatoria desde el 30 de junio de 2022: contrato con un gestor autorizado y archivo de los justificantes de cada retirada.
A20: Cada retirada se anota en el registro del Pack APPCC, fichero 09-control-aceite-fritura.xlsx, hoja «Retirada de aceite usado» (fecha, litros, gestor, número de documento y firma). Este libro no lo duplica: sólo contrasta los litros del mes.
A21: La prohibición de verter el aceite por el desagüe la fijan las ordenanzas municipales: mira la de tu ayuntamiento.
A22: Ejemplo de gestor para Madrid, sin relación comercial: Reseave (Mejorada del Campo, Madrid). Gestor autorizado de aceite de cocina usado. Ejemplo para Madrid, sin relación comercial: entrega documento de identificación, contrato y certificado de eliminación. El de El Molinete recoge sin coste a cambio de obsequios, servicios gratuitos o valoración económica; pide el tuyo en tu ciudad.
A24: Versión 1.0 · octubre 2026 · aichef.pro/guia-churreria-chocolateria · info@aichef.pro
