Workbook

Sheet Instrucciones
A1: Calculadora de CAPEX de la Churrería-Chocolatería
A2: AI Chef Pro · aichef.pro — Cómo Montar una Churrería-Chocolatería
A3: Para qué sirve: saber cuánto necesitas para abrir y en qué formato, línea a línea y en base imponible, con el IVA que adelantas aparte. Responde a una pregunta: ¿cuánto necesito y en qué formato?
A5: Instrucciones de Uso
A6: Celdas verdes = campos editables
A7: Las celdas en crema son resultados que el libro calcula; las blancas con fórmula, también. No escribas encima.
A9: 1. Hoja «Parámetros». Los tipos de IVA, los metros del local, el coste de obra por metro, la RENTA MENSUAL (nace aquí: el libro 6 la copia) y los meses de fianza. Abajo, las celdas verdes que copias de otros libros, cada una con su fila de CUADRE: si necesitas extinción automática y la superficie útil (del libro 1) y los precios del aceite, del mix y de los demás insumos del stock (del libro 3).
A10: 2. Hoja «Equipamiento Línea a Línea». Cada máquina con su precio de referencia, su fuente y la fecha en que se leyó. Pon tu mínimo, tu máximo y TU importe, y di si ese importe lleva IVA: el libro lo pasa a base imponible antes de sumar. «¿La compras?» decide si entra en el CAPEX.
A11: 3. Hoja «CAPEX por Bloque». Lo que no es máquina: la obra, el proyecto, la licencia y las tasas, la extinción automática si te toca, la fianza, el stock inicial y el marketing de apertura. Y abajo, los once bloques sumados: equipamiento más partidas.
A12: 4. Hoja «Variante del Formato». Local con sala, despacho para llevar, caseta de feria o franquicia: la dotación con fuente de cada una y lo que cambia frente al local con sala.
A13: 5. Hoja «Franquicia o Independiente». Lo que publican las enseñas, fechado y como orden de magnitud, frente a tu CAPEX. No es una recomendación de marca.
A14: 6. Hoja «Traspaso vs Obra Nueva». El precio que te piden por un traspaso y lo que te costaría adaptarlo, frente a la obra nueva, primero en inversión y después en el horizonte con la renta.
... A41: Versión 1.0 · octubre 2026 · aichef.pro/guia-churreria-chocolateria · info@aichef.pro

Sheet Parámetros
A1: Parámetros
A2: AI Chef Pro · aichef.pro — Cómo Montar una Churrería-Chocolatería
A3: Lo que vale para todo el libro. Ninguna fórmula lleva un número dentro: los tipos de IVA, los metros, la renta y los umbrales viven aquí.
A4: Parámetro | B4: Valor | C4: Unidad | D4: Procedencia | E4: Nota | K4: Lo que Copian Otros Libros (No Muevas Estas Celdas)
A5: El IVA | K5: Renta mensual del local (nace aquí; la copia el libro 6) | L5: =B12 -> 910 | M5: Lo copia: libro 6 (plan-financiero-3-anos-churreria.xlsx, hoja 0. Supuestos, X18)
A6: Tipo de IVA general (maquinaria, obra, servicios y envases) | B6: 0.21 | C6: % | D6: CHN-71c | E6: El equipamiento, la obra, el proyecto y los envases van al tipo general. Lo que vendes en la carta va a otros tipos: se explica en el capítulo 3 de la guía y lo aplica el libro 3.
A7: Tipo de IVA de los alimentos del stock inicial (mix, aceite, preparado, leche, café...) | B7: 0.1 | C7: % | D7: supuesto declarado | E7: IVA soportado del mix, el aceite y el preparado: compruébalo en cada factura, el aceite ha tenido tipos rebajados temporales.
A8: Tipo de las partidas que no llevan IVA (tasas municipales y fianza) | B8: 0 | C8: % | D8: supuesto declarado | E8: Las tasas del ayuntamiento y la fianza del arrendamiento no llevan IVA: la fianza es un depósito que se recupera, no una compra.
A9: El Local, la Renta y la Obra
A10: Superficie útil del local (copiada del libro 1, más abajo) | B10: ='Parámetros'!$B$31 -> 75 | C10: m² | D10: CHS-37a + CUS-02 | E10: La que copias del libro 1 en la sección «Lo que Copias de Otros Libros» (cruce X9 bis): la superficie tiene una sola fuente. Aquí sólo sirve para el coste de la obra por metro.
A11: Coste de obra y acondicionamiento por m² (local en bruto) | B11: 380 | C11: €/m² | D11: supuesto declarado | E11: Coste de obra y acondicionamiento por m² de local en bruto. Supuesto de El Molinete: ninguna ficha publica un coste de obra por m² de churrería. El conducto a cubierta va en su propia línea.
A12: Renta mensual del local (nace aquí) | B12: 910 | C12: €/mes | D12: CUS-02 | E12: La renta del local de 74 m² del traspaso de Vallecas (CUS-02). De aquí sale la fianza y la copia el libro 6 para sus gastos fijos (bloque de la derecha).
A13: Meses de fianza y garantía | B13: 2 | C13: meses | D13: supuesto declarado | E13: Meses de fianza y garantía que pide el arrendador. Cambia por comunidad y por contrato.
A14: Controles y Conversiones
A15: Meses que tiene un año | B15: 12 | C15: meses | D15: conversión | E15: Conversión de unidades. Vive aquí para que ninguna fórmula lleve un número dentro.
A16: Tolerancia de las filas de CUADRE | B16: 0.02 | C16: desviación | D16: heredado de la hermana | E16: Por encima de esta desviación, la fila de CUADRE avisa de que lo que has copiado ya no es lo que publica el libro de origen.
A17: Desviación admitida de tus importes contra la referencia | B17: 0.1 | C17: desviación | D17: heredado de la hermana | E17: Por encima, la hoja «Equipamiento Línea a Línea» y el «Resumen» avisan: o has comprado más caro, o has elegido otro equipo. No es un error: es una pregunta.
A18: Lo que Copias de Otros Libros
A19: cópialo del libro 1: produccion-hora-punta-y-local.xlsx!Freidoras, Potencia y Riesgo!L6 | B19: 0 | C19: 1/0 | D19: cruce X9 (libro 1) | E19: 1 si tu cocina pasa de 50 kW computables y la extinción automática es obligatoria; 0 si no. El umbral se aplica UNA vez, en el libro 1. Con 1, la línea de extinción automática de «CAPEX por Bloque» suma su importe.
A20: Lo que publica hoy esa celda del libro 1 (anótalo cada vez que lo abras) | B20: 0 | C20: 1/0 | E20: Si arriba usas otra cifra, la fila de CUADRE te avisa en vez de dejar las dos separadas en silencio.
A21: Diferencia entre las dos | B21: =IF(AND(ISNUMBER(B19),ISNUMBER(B20)),ABS(B19-B20),"") -> 0
A22: CUADRE: lo que usas frente a lo que publica el libro 1 (¿necesitas extinción automática? (1 sí, 0 no)) | B22: =IF(NOT(ISNUMBER(B21)),"",IF(B21=0,"CUADRA","REVISA: no es lo que publica el libro 1")) -> CUADRA
A23: cópialo del libro 3: carta-de-apertura-y-escandallo-churro.xlsx!Parámetros!L5 | B23: 1.996 | C23: €/L | D23: cruce X17 (libro 3) | E23: Precio del aceite de fritura en base imponible. Vive en el libro 3 (celda única del paquete): aquí sólo sirve para valorar el stock inicial.
A24: Lo que publica hoy esa celda del libro 3 (anótalo cada vez que lo abras) | B24: 1.996 | C24: €/L | E24: Si arriba usas otra cifra, la fila de CUADRE te avisa en vez de dejar las dos separadas en silencio.
A25: Desviación entre las dos | B25: =IFERROR(ABS(B23-B24)/B24,"") -> 0
A26: CUADRE: lo que usas frente a lo que publica el libro 3 (precio del aceite (base imponible)) | B26: =IF(NOT(ISNUMBER(B25)),"",IF(B25<='Parámetros'!$B$16,"CUADRA","REVISA: no es lo que publica el libro 3")) -> CUADRA
A27: cópialo del libro 3: carta-de-apertura-y-escandallo-churro.xlsx!Parámetros!L8 | B27: 1.45 | C27: €/kg | D27: cruce X17 (libro 3) | E27: Precio del preparado para masa de churro en base imponible, del libro 3. Aquí sólo valora el stock inicial.
A28: Lo que publica hoy esa celda del libro 3 (anótalo cada vez que lo abras) | B28: 1.45 | C28: €/kg | E28: Si arriba usas otra cifra, la fila de CUADRE te avisa en vez de dejar las dos separadas en silencio.
A29: Desviación entre las dos | B29: =IFERROR(ABS(B27-B28)/B28,"") -> 0
A30: CUADRE: lo que usas frente a lo que publica el libro 3 (precio del mix (base imponible)) | B30: =IF(NOT(ISNUMBER(B29)),"",IF(B29<='Parámetros'!$B$16,"CUADRA","REVISA: no es lo que publica el libro 3")) -> CUADRA
A31: cópialo del libro 1: produccion-hora-punta-y-local.xlsx!Zonas y m²!L5 | B31: 75 | C31: m² | D31: cruce X9 bis (libro 1) | E31: La superficie útil del local, del libro 1 (hoja «Zonas y m²»). Mide el coste de la obra: obra por metro por metros.
A32: Lo que publica hoy esa celda del libro 1 (anótalo cada vez que lo abras) | B32: 75 | C32: m² | E32: Si arriba usas otra cifra, la fila de CUADRE te avisa en vez de dejar las dos separadas en silencio.
A33: Desviación entre las dos | B33: =IFERROR(ABS(B31-B32)/B32,"") -> 0
A34: CUADRE: lo que usas frente a lo que publica el libro 1 (superficie útil del local) | B34: =IF(NOT(ISNUMBER(B33)),"",IF(B33<='Parámetros'!$B$16,"CUADRA","REVISA: no es lo que publica el libro 1")) -> CUADRA
A35: cópialo del libro 3: carta-de-apertura-y-escandallo-churro.xlsx!Parámetros!L10 | B35: 7.1875 | C35: €/unidad | D35: cruce X17 (libro 3) | E35: Precio de «Chocolate a la taza en polvo (bolsa de 800 g, rinde 4,3 L)» sin IVA, por unidad, del libro 3 (tabla de insumos de su hoja «Parámetros»). Aquí sólo valora el stock inicial.
A36: Lo que publica hoy esa celda del libro 3 (anótalo cada vez que lo abras) | B36: 7.1875 | C36: €/unidad | E36: Si arriba usas otra cifra, la fila de CUADRE te avisa en vez de dejar las dos separadas en silencio.
A37: Desviación entre las dos | B37: =IFERROR(ABS(B35-B36)/B36,"") -> 0
A38: CUADRE: lo que usas frente a lo que publica el libro 3 (precio del insumo «preparado_taza» del stock inicial (base imponible)) | B38: =IF(NOT(ISNUMBER(B37)),"",IF(B37<='Parámetros'!$B$16,"CUADRA","REVISA: no es lo que publica el libro 3")) -> CUADRA
A39: cópialo del libro 3: carta-de-apertura-y-escandallo-churro.xlsx!Parámetros!L11 | B39: 6.5 | C39: €/unidad | D39: cruce X17 (libro 3) | E39: Precio de «Cobertura de chocolate negro (1 kg)» sin IVA, por unidad, del libro 3 (tabla de insumos de su hoja «Parámetros»). Aquí sólo valora el stock inicial.
A40: Lo que publica hoy esa celda del libro 3 (anótalo cada vez que lo abras) | B40: 6.5 | C40: €/unidad | E40: Si arriba usas otra cifra, la fila de CUADRE te avisa en vez de dejar las dos separadas en silencio.
...

Sheet CAPEX por Bloque
A1: CAPEX por Bloque
A2: AI Chef Pro · aichef.pro — Cómo Montar una Churrería-Chocolatería
A3: Lo que no es máquina, el stock inicial y los once bloques sumados. Sin fondo de maniobra: lo calcula el libro 6.
A5: Nº | B5: Bloque | C5: Partida | D5: Procedencia | E5: ¿La incluyes? | F5: Mínimo | G5: Máximo | H5: Tu importe | I5: ¿Tu importe lleva IVA? | J5: Tipo de IVA | K5: Base sin IVA | L5: IVA soportado | M5: Total con IVA | N5: ¿Se amortiza? | O5: Base amortizable | P5: Nota
A6: 1 | B6: Obra civil y acondicionamiento | C6: Obra y acondicionamiento del local en bruto (380 €/m²) | D6: supuesto declarado | E6: Sí | F6: ='Parámetros'!$B$10*'Parámetros'!$B$11 -> 28500 | G6: ='Parámetros'!$B$10*'Parámetros'!$B$11 -> 28500 | H6: ='Parámetros'!$B$10*'Parámetros'!$B$11 -> 28500 | I6: No | J6: ='Parámetros'!$B$6 -> 0.21 | K6: =IF(E6="No","",IFERROR(IF(I6="Sí",H6/(1+J6),H6),"")) -> 28500 | L6: =IF(K6="","",K6*J6) -> 5985 | M6: =IF(K6="","",K6+L6) -> 34485 | N6: Sí | O6: =IF(AND(N6="Sí",ISNUMBER(K6)),K6,"") -> 28500 | P6: Supuesto declarado: ninguna ficha publica un coste de obra por m² de churrería. Se calcula con los m² de NEGOCIO.
A7: 2 | B7: Licencias, proyecto de actividad y tasas | C7: Proyecto técnico de actividad y de la extracción | D7: supuesto declarado | E7: Sí | F7: 4200 | G7: 4200 | H7: 4200 | I7: No | J7: ='Parámetros'!$B$6 -> 0.21 | K7: =IF(E7="No","",IFERROR(IF(I7="Sí",H7/(1+J7),H7),"")) -> 4200 | L7: =IF(K7="","",K7*J7) -> 882 | M7: =IF(K7="","",K7+L7) -> 5082 | N7: Sí | O7: =IF(AND(N7="Sí",ISNUMBER(K7)),K7,"") -> 4200 | P7: Supuesto declarado.
A8: 3 | B8: Licencias, proyecto de actividad y tasas | C8: Licencia de obra del conducto y tasas municipales | D8: supuesto declarado | E8: Sí | F8: 1900 | G8: 1900 | H8: 1900 | I8: No | J8: ='Parámetros'!$B$8 -> 0 | K8: =IF(E8="No","",IFERROR(IF(I8="Sí",H8/(1+J8),H8),"")) -> 1900 | L8: =IF(K8="","",K8*J8) -> 0 | M8: =IF(K8="","",K8+L8) -> 1900 | N8: Sí | O8: =IF(AND(N8="Sí",ISNUMBER(K8)),K8,"") -> 1900 | P8: Las tasas no llevan IVA y cambian en cada ayuntamiento: es la cifra que hay que ir a buscar, no copiar.
A9: 4 | B9: Licencias, proyecto de actividad y tasas | C9: Sistema automático de extinción en la campana (sólo si X9 = 1) | D9: supuesto declarado | E9: Sí | F9: 2800 | G9: 2800 | H9: 2800 | I9: No | J9: ='Parámetros'!$B$6 -> 0.21 | K9: =IF(E9="No","",IF('Parámetros'!$B$19=1,IFERROR(IF(I9="Sí",H9/(1+J9),H9),""),0)) -> 0 | L9: =IF(K9="","",K9*J9) -> 0 | M9: =IF(K9="","",K9+L9) -> 0 | N9: Sí | O9: =IF(AND(N9="Sí",ISNUMBER(K9)),K9,"") -> 0 | P9: Obligatorio por encima de 50 kW. El Molinete no lo necesita (cruce X9 = 0) y la línea suma cero; es la otra salida de la decisión 4, con su coste.
A10: 5 | B10: Fianza y garantías | C10: Fianza y garantías (meses de fianza por la renta) | D10: calculado | E10: Sí | F10: ='Parámetros'!$B$13*'Parámetros'!$B$12 -> 1820 | G10: ='Parámetros'!$B$13*'Parámetros'!$B$12 -> 1820 | H10: ='Parámetros'!$B$13*'Parámetros'!$B$12 -> 1820 | I10: No | J10: ='Parámetros'!$B$8 -> 0 | K10: =IF(E10="No","",IFERROR(IF(I10="Sí",H10/(1+J10),H10),"")) -> 1820 | L10: =IF(K10="","",K10*J10) -> 0 | M10: =IF(K10="","",K10+L10) -> 1820 | N10: No | O10: =IF(AND(N10="Sí",ISNUMBER(K10)),K10,"") | P10: No es un gasto: se recupera. Por eso no se amortiza.
A11: 6 | B11: Stock inicial y envase | C11: Stock inicial de mix, aceite, preparado, envase y bebida | D11: calculado | E11: Sí | F11: =I30 -> 848.3 | G11: =I30 -> 848.3 | H11: =I30 -> 848.3 | I11: Por línea, abajo | J11: =IFERROR(J30/I30,"") -> 0.13047271 | K11: =IF(E11="No","",H11) -> 848.3 | L11: =IF(K11="","",J30) -> 110.68 | M11: =IF(K11="","",K11+L11) -> 958.98 | N11: No | O11: =IF(AND(N11="Sí",ISNUMBER(K11)),K11,"") | P11: Se calcula con los precios de los insumos (el aceite y el mix llegan por el cruce X17) y las cantidades de STOCK_INICIAL.
A12: 7 | B12: Marketing de apertura | C12: Marketing de apertura | D12: supuesto declarado | E12: Sí | F12: 2000 | G12: 2000 | H12: 2000 | I12: No | J12: ='Parámetros'!$B$6 -> 0.21 | K12: =IF(E12="No","",IFERROR(IF(I12="Sí",H12/(1+J12),H12),"")) -> 2000 | L12: =IF(K12="","",K12*J12) -> 420 | M12: =IF(K12="","",K12+L12) -> 2420 | N12: No | O12: =IF(AND(N12="Sí",ISNUMBER(K12)),K12,"") | P12: Gasto del primer año, no inmovilizado.
A14: Stock Inicial y Envase (Bloque 10), Línea a Línea
A15: Nº | B15: Insumo | C15: Procedencia del precio | D15: Cantidad | E15: Unidad | F15: Precio por unidad, como lo copias | G15: ¿Lleva IVA? | H15: Tipo de IVA | I15: Base sin IVA | J15: IVA soportado | K15: Total con IVA | L15: Nota
A16: 1 | B16: Preparado para masa de churro (caja de 6 sacos de 4 kg) | C16: cruce X17 (libro 3) | D16: 96 | E16: kg | F16: ='Parámetros'!$B$27 -> 1.45 | G16: No | H16: ='Parámetros'!$B$7 -> 0.1 | I16: =IFERROR(IF(G16="Sí",D16*F16/(1+H16),D16*F16),"") -> 139.2 | J16: =IF(I16="","",I16*H16) -> 13.92 | K16: =IF(I16="","",I16+J16) -> 153.12 | L16: El precio llega del libro 3 por la celda verde de «Parámetros»: no se teclea aquí.
A17: 2 | B17: Aceite especial de fritura (garrafa de 25 L) | C17: cruce X17 (libro 3, celda única del precio del aceite) | D17: 75 | E17: L | F17: ='Parámetros'!$B$23 -> 1.996 | G17: No | H17: ='Parámetros'!$B$7 -> 0.1 | I17: =IFERROR(IF(G17="Sí",D17*F17/(1+H17),D17*F17),"") -> 149.7 | J17: =IF(I17="","",I17*H17) -> 14.97 | K17: =IF(I17="","",I17+J17) -> 164.67 | L17: El precio llega del libro 3 por la celda verde de «Parámetros»: no se teclea aquí.
A18: 3 | B18: Chocolate a la taza en polvo (bolsa de 800 g, rinde 4,3 L) | C18: cruce X17 (libro 3) | D18: 8 | E18: kg | F18: ='Parámetros'!$B$35 -> 7.1875 | G18: No | H18: ='Parámetros'!$B$7 -> 0.1 | I18: =IFERROR(IF(G18="Sí",D18*F18/(1+H18),D18*F18),"") -> 57.5 | J18: =IF(I18="","",I18*H18) -> 5.75 | K18: =IF(I18="","",I18+J18) -> 63.25 | L18: El precio llega del libro 3 por la celda verde de «Parámetros»: no se teclea aquí. Base de la fuente: sin IVA, declarada en la ficha («Impuestos excluidos»). El techo por kilo de la ficha. La ficha no dice a qué denominación del RD 1055/2003 corresponde: la carta usa la de la etiqueta.
A19: 4 | B19: Cobertura de chocolate negro (1 kg) | C19: cruce X17 (libro 3) | D19: 5 | E19: kg | F19: ='Parámetros'!$B$39 -> 6.5 | G19: No | H19: ='Parámetros'!$B$7 -> 0.1 | I19: =IFERROR(IF(G19="Sí",D19*F19/(1+H19),D19*F19),"") -> 32.5 | J19: =IF(I19="","",I19*H19) -> 3.25 | K19: =IF(I19="","",I19+J19) -> 35.75 | L19: El precio llega del libro 3 por la celda verde de «Parámetros»: no se teclea aquí. Base de la fuente: sin IVA, declarada en la ficha («Impuestos excluidos»). Para rellenar y bañar churros.
A20: 5 | B20: Cucurucho de cartón para churros (caja de 100) | C20: cruce X17 (libro 3) | D20: 1000 | E20: ud | F20: ='Parámetros'!$B$43 -> 0.15 | G20: No | H20: ='Parámetros'!$B$6 -> 0.21 | I20: =IFERROR(IF(G20="Sí",D20*F20/(1+H20),D20*F20),"") -> 150 | J20: =IF(I20="","",I20*H20) -> 31.5 | K20: =IF(I20="","",I20+J20) -> 181.5 | L20: El precio llega del libro 3 por la celda verde de «Parámetros»: no se teclea aquí. Base de la fuente: sin IVA, inferida (celda «¿lleva IVA?» en verde, «no» por defecto). Su composición está por confirmar: no se presenta como conforme a la ley de plásticos.
A21: 6 | B21: Vaso de papel plastificado con tapa | C21: cruce X17 (libro 3) | D21: 500 | E21: ud | F21: ='Parámetros'!$B$47 -> 0.08 | G21: No | H21: ='Parámetros'!$B$6 -> 0.21 | I21: =IFERROR(IF(G21="Sí",D21*F21/(1+H21),D21*F21),"") -> 40 | J21: =IF(I21="","",I21*H21) -> 8.4 | K21: =IF(I21="","",I21+J21) -> 48.4 | L21: El precio llega del libro 3 por la celda verde de «Parámetros»: no se teclea aquí. Base de la fuente: supuesto, sin IVA. Lleva plástico: se cobra aparte (CUN-41).
A22: 7 | B22: Papel antigrasa para sueltos | C22: cruce X17 (libro 3) | D22: 1000 | E22: ud | F22: ='Parámetros'!$B$51 -> 0.02 | G22: No | H22: ='Parámetros'!$B$6 -> 0.21 | I22: =IFERROR(IF(G22="Sí",D22*F22/(1+H22),D22*F22),"") -> 20 | J22: =IF(I22="","",I22*H22) -> 4.2 | K22: =IF(I22="","",I22+J22) -> 24.2 | L22: El precio llega del libro 3 por la celda verde de «Parámetros»: no se teclea aquí. Base de la fuente: supuesto, sin IVA.
A23: 8 | B23: Caja de cartón para el kilo | C23: cruce X17 (libro 3) | D23: 100 | E23: ud | F23: ='Parámetros'!$B$55 -> 0.25 | G23: No | H23: ='Parámetros'!$B$6 -> 0.21 | I23: =IFERROR(IF(G23="Sí",D23*F23/(1+H23),D23*F23),"") -> 25 | J23: =IF(I23="","",I23*H23) -> 5.25 | K23: =IF(I23="","",I23+J23) -> 30.25 | L23: El precio llega del libro 3 por la celda verde de «Parámetros»: no se teclea aquí. Base de la fuente: supuesto, sin IVA.
A24: 9 | B24: Café en grano | C24: cruce X17 (libro 3) | D24: 6 | E24: kg | F24: ='Parámetros'!$B$59 -> 18 | G24: No | H24: ='Parámetros'!$B$7 -> 0.1 | I24: =IFERROR(IF(G24="Sí",D24*F24/(1+H24),D24*F24),"") -> 108 | J24: =IF(I24="","",I24*H24) -> 10.8 | K24: =IF(I24="","",I24+J24) -> 118.8 | L24: El precio llega del libro 3 por la celda verde de «Parámetros»: no se teclea aquí. Base de la fuente: supuesto, sin IVA. Sin fuente de precio de café en el research.
A25: 10 | B25: Leche | C25: cruce X17 (libro 3) | D25: 60 | E25: L | F25: ='Parámetros'!$B$63 -> 0.85 | G25: No | H25: ='Parámetros'!$B$7 -> 0.1 | I25: =IFERROR(IF(G25="Sí",D25*F25/(1+H25),D25*F25),"") -> 51 | J25: =IF(I25="","",I25*H25) -> 5.1 | K25: =IF(I25="","",I25+J25) -> 56.1 | L25: El precio llega del libro 3 por la celda verde de «Parámetros»: no se teclea aquí. Base de la fuente: supuesto, sin IVA.
A26: 11 | B26: Azúcar para espolvorear y sobres | C26: cruce X17 (libro 3) | D26: 25 | E26: kg | F26: ='Parámetros'!$B$67 -> 1 | G26: No | H26: ='Parámetros'!$B$7 -> 0.1 | I26: =IFERROR(IF(G26="Sí",D26*F26/(1+H26),D26*F26),"") -> 25 | J26: =IF(I26="","",I26*H26) -> 2.5 | K26: =IF(I26="","",I26+J26) -> 27.5 | L26: El precio llega del libro 3 por la celda verde de «Parámetros»: no se teclea aquí. Base de la fuente: supuesto, sin IVA. El azúcar glas que publica CUS-25 es otro producto.
A27: 12 | B27: Cacao soluble | C27: cruce X17 (libro 3) | D27: 3 | E27: kg | F27: ='Parámetros'!$B$71 -> 6 | G27: No | H27: ='Parámetros'!$B$7 -> 0.1 | I27: =IFERROR(IF(G27="Sí",D27*F27/(1+H27),D27*F27),"") -> 18 | J27: =IF(I27="","",I27*H27) -> 1.8 | K27: =IF(I27="","",I27+J27) -> 19.8 | L27: El precio llega del libro 3 por la celda verde de «Parámetros»: no se teclea aquí. Base de la fuente: supuesto, sin IVA.
A28: 13 | B28: Infusión (sobre) | C28: cruce X17 (libro 3) | D28: 100 | E28: ud | F28: ='Parámetros'!$B$75 -> 0.06 | G28: No | H28: ='Parámetros'!$B$7 -> 0.1 | I28: =IFERROR(IF(G28="Sí",D28*F28/(1+H28),D28*F28),"") -> 6 | J28: =IF(I28="","",I28*H28) -> 0.6 | K28: =IF(I28="","",I28+J28) -> 6.6 | L28: El precio llega del libro 3 por la celda verde de «Parámetros»: no se teclea aquí. Base de la fuente: supuesto, sin IVA.
A29: 14 | B29: Agua (botella de 50 cl) | C29: cruce X17 (libro 3) | D29: 120 | E29: ud | F29: ='Parámetros'!$B$79 -> 0.22 | G29: No | H29: ='Parámetros'!$B$7 -> 0.1 | I29: =IFERROR(IF(G29="Sí",D29*F29/(1+H29),D29*F29),"") -> 26.4 | J29: =IF(I29="","",I29*H29) -> 2.64 | K29: =IF(I29="","",I29+J29) -> 29.04 | L29: El precio llega del libro 3 por la celda verde de «Parámetros»: no se teclea aquí. Base de la fuente: supuesto, sin IVA.
B30: TOTAL del stock inicial | I30: =SUM(I16:I29) -> 848.3 | J30: =SUM(J16:J29) -> 110.68 | K30: =SUM(K16:K29) -> 958.98
A32: Los Once Bloques, Equipamiento y Partidas
A33: Nº | B33: Bloque | C33: Equipamiento sin IVA | D33: Otras partidas sin IVA | E33: Base sin IVA | F33: IVA soportado | G33: Total con IVA | H33: % del CAPEX | I33: Inmovilizado amortizable | J33: Procedencia
A34: 1 | B34: Obra civil y acondicionamiento | C34: =SUMIF('Equipamiento Línea a Línea'!$B$6:$B$33,B34,'Equipamiento Línea a Línea'!$O$6:$O$33) -> 0 | D34: =SUMIF($B$6:$B$12,B34,$K$6:$K$12) -> 28500 | E34: =C34+D34 -> 28500 | F34: =SUMIF('Equipamiento Línea a Línea'!$B$6:$B$33,B34,'Equipamiento Línea a Línea'!$P$6:$P$33)+SUMIF($B$6:$B$12,B34,$L$6:$L$12) -> 5985 | G34: =E34+F34 -> 34485 | H34: =IFERROR(E34/$E$45,"") -> 0.32980137 | I34: =C34+SUMIF($B$6:$B$12,B34,$O$6:$O$12) -> 28500 | J34: supuesto (obra por m²)
A35: 2 | B35: Extracción y conducto | C35: =SUMIF('Equipamiento Línea a Línea'!$B$6:$B$33,B35,'Equipamiento Línea a Línea'!$O$6:$O$33) -> 9990 | D35: =SUMIF($B$6:$B$12,B35,$K$6:$K$12) -> 0 | E35: =C35+D35 -> 9990 | F35: =SUMIF('Equipamiento Línea a Línea'!$B$6:$B$33,B35,'Equipamiento Línea a Línea'!$P$6:$P$33)+SUMIF($B$6:$B$12,B35,$L$6:$L$12) -> 2097.9 | G35: =E35+F35 -> 12087.9 | H35: =IFERROR(E35/$E$45,"") -> 0.11560406 | I35: =C35+SUMIF($B$6:$B$12,B35,$O$6:$O$12) -> 9990 | J35: CUS-36a + supuesto (conducto, CUS-36b sin fuente)
A36: 3 | B36: Fritura, dosificación y amasado | C36: =SUMIF('Equipamiento Línea a Línea'!$B$6:$B$33,B36,'Equipamiento Línea a Línea'!$O$6:$O$33) -> 6754.2 | D36: =SUMIF($B$6:$B$12,B36,$K$6:$K$12) -> 0 | E36: =C36+D36 -> 6754.2 | F36: =SUMIF('Equipamiento Línea a Línea'!$B$6:$B$33,B36,'Equipamiento Línea a Línea'!$P$6:$P$33)+SUMIF($B$6:$B$12,B36,$L$6:$L$12) -> 1418.382 | G36: =E36+F36 -> 8172.582 | H36: =IFERROR(E36/$E$45,"") -> 0.078159454 | I36: =C36+SUMIF($B$6:$B$12,B36,$O$6:$O$12) -> 6754.2 | J36: CUS-33a, CUS-34c, CUS-35a, CUS-39
A37: 4 | B37: Chocolate y café | C37: =SUMIF('Equipamiento Línea a Línea'!$B$6:$B$33,B37,'Equipamiento Línea a Línea'!$O$6:$O$33) -> 5675.4 | D37: =SUMIF($B$6:$B$12,B37,$K$6:$K$12) -> 0 | E37: =C37+D37 -> 5675.4 | F37: =SUMIF('Equipamiento Línea a Línea'!$B$6:$B$33,B37,'Equipamiento Línea a Línea'!$P$6:$P$33)+SUMIF($B$6:$B$12,B37,$L$6:$L$12) -> 1191.834 | G37: =E37+F37 -> 6867.234 | H37: =IFERROR(E37/$E$45,"") -> 0.065675604 | I37: =C37+SUMIF($B$6:$B$12,B37,$O$6:$O$12) -> 5675.4 | J37: CUS-37a + supuesto (cafetera, CUS-43)
A38: 5 | B38: Barra, sala y terraza | C38: =SUMIF('Equipamiento Línea a Línea'!$B$6:$B$33,B38,'Equipamiento Línea a Línea'!$O$6:$O$33) -> 20800 | D38: =SUMIF($B$6:$B$12,B38,$K$6:$K$12) -> 0 | E38: =C38+D38 -> 20800 | F38: =SUMIF('Equipamiento Línea a Línea'!$B$6:$B$33,B38,'Equipamiento Línea a Línea'!$P$6:$P$33)+SUMIF($B$6:$B$12,B38,$L$6:$L$12) -> 4368 | G38: =E38+F38 -> 25168 | H38: =IFERROR(E38/$E$45,"") -> 0.24069714 | I38: =C38+SUMIF($B$6:$B$12,B38,$O$6:$O$12) -> 20800 | J38: supuesto (CUS-43: sin precio con fuente)
A39: 6 | B39: Control y seguridad | C39: =SUMIF('Equipamiento Línea a Línea'!$B$6:$B$33,B39,'Equipamiento Línea a Línea'!$O$6:$O$33) -> 1027.75 | D39: =SUMIF($B$6:$B$12,B39,$K$6:$K$12) -> 0 | E39: =C39+D39 -> 1027.75 | F39: =SUMIF('Equipamiento Línea a Línea'!$B$6:$B$33,B39,'Equipamiento Línea a Línea'!$P$6:$P$33)+SUMIF($B$6:$B$12,B39,$L$6:$L$12) -> 215.8275 | G39: =E39+F39 -> 1243.5775 | H39: =IFERROR(E39/$E$45,"") -> 0.0118931 | I39: =C39+SUMIF($B$6:$B$12,B39,$O$6:$O$12) -> 1027.75 | J39: CUS-38, CUS-41 + supuesto
A40: 7 | B40: TPV y rótulo | C40: =SUMIF('Equipamiento Línea a Línea'!$B$6:$B$33,B40,'Equipamiento Línea a Línea'!$O$6:$O$33) -> 2900 | D40: =SUMIF($B$6:$B$12,B40,$K$6:$K$12) -> 0 | E40: =C40+D40 -> 2900 | F40: =SUMIF('Equipamiento Línea a Línea'!$B$6:$B$33,B40,'Equipamiento Línea a Línea'!$P$6:$P$33)+SUMIF($B$6:$B$12,B40,$L$6:$L$12) -> 609 | G40: =E40+F40 -> 3509 | H40: =IFERROR(E40/$E$45,"") -> 0.033558736 | I40: =C40+SUMIF($B$6:$B$12,B40,$O$6:$O$12) -> 2900 | J40: supuesto
A41: 8 | B41: Licencias, proyecto de actividad y tasas | C41: =SUMIF('Equipamiento Línea a Línea'!$B$6:$B$33,B41,'Equipamiento Línea a Línea'!$O$6:$O$33) -> 0 | D41: =SUMIF($B$6:$B$12,B41,$K$6:$K$12) -> 6100 | E41: =C41+D41 -> 6100 | F41: =SUMIF('Equipamiento Línea a Línea'!$B$6:$B$33,B41,'Equipamiento Línea a Línea'!$P$6:$P$33)+SUMIF($B$6:$B$12,B41,$L$6:$L$12) -> 882 | G41: =E41+F41 -> 6982 | H41: =IFERROR(E41/$E$45,"") -> 0.070589066 | I41: =C41+SUMIF($B$6:$B$12,B41,$O$6:$O$12) -> 6100 | J41: supuesto declarado
A42: 9 | B42: Fianza y garantías | C42: =SUMIF('Equipamiento Línea a Línea'!$B$6:$B$33,B42,'Equipamiento Línea a Línea'!$O$6:$O$33) -> 0 | D42: =SUMIF($B$6:$B$12,B42,$K$6:$K$12) -> 1820 | E42: =C42+D42 -> 1820 | F42: =SUMIF('Equipamiento Línea a Línea'!$B$6:$B$33,B42,'Equipamiento Línea a Línea'!$P$6:$P$33)+SUMIF($B$6:$B$12,B42,$L$6:$L$12) -> 0 | G42: =E42+F42 -> 1820 | H42: =IFERROR(E42/$E$45,"") -> 0.021061 | I42: =C42+SUMIF($B$6:$B$12,B42,$O$6:$O$12) -> 0 | J42: meses de fianza por la renta (CUS-02)
A43: 10 | B43: Stock inicial y envase | C43: =SUMIF('Equipamiento Línea a Línea'!$B$6:$B$33,B43,'Equipamiento Línea a Línea'!$O$6:$O$33) -> 0 | D43: =SUMIF($B$6:$B$12,B43,$K$6:$K$12) -> 848.3 | E43: =C43+D43 -> 848.3 | F43: =SUMIF('Equipamiento Línea a Línea'!$B$6:$B$33,B43,'Equipamiento Línea a Línea'!$P$6:$P$33)+SUMIF($B$6:$B$12,B43,$L$6:$L$12) -> 110.68 | G43: =E43+F43 -> 958.98 | H43: =IFERROR(E43/$E$45,"") -> 0.0098165089 | I43: =C43+SUMIF($B$6:$B$12,B43,$O$6:$O$12) -> 0 | J43: precios del libro 3 y de las fichas
...

Sheet Equipamiento Línea a Línea
A1: Equipamiento Línea a Línea
A2: AI Chef Pro · aichef.pro — Cómo Montar una Churrería-Chocolatería
A3: Cada máquina con su fuente, su fecha y su base de IVA. Tu importe se pasa a base imponible antes de sumar. Sin plazo de entrega: vive en el libro 7.
A5: Nº | B5: Bloque | C5: Partida | D5: Procedencia | E5: Cómo publica la fuente el precio | F5: Fecha del precio | G5: ¿La compras? | H5: Uds | I5: Precio de referencia (ud) | J5: Mínimo (ud) | K5: Máximo (ud) | L5: Tu importe (ud) | M5: ¿Tu importe lleva IVA? | N5: Tipo de IVA | O5: Base sin IVA | P5: IVA soportado | Q5: Total con IVA | R5: Referencia sin IVA (ud) | S5: Referencia de la línea | T5: Desviación contra la referencia | U5: ¿Dentro de tu horquilla? | V5: Uds en el local con sala | W5: Uds en el despacho | X5: Dotación del local con sala | Y5: Dotación del despacho | Z5: Nota
A6: 1 | B6: Fritura, dosificación y amasado | C6: Freidora de churros de gas de 25 L (ClimaHosteleria EMPLK002) | D6: CUS-33a | E6: sin IVA declarada en la ficha | F6: 46298 | G6: Sí | H6: 1 | I6: 1907 | J6: 1907 | K6: 1907 | L6: 1907 | M6: No | N6: ='Parámetros'!$B$6 -> 0.21 | O6: =IF(G6="No","",IFERROR(ROUND(IF(M6="Sí",L6/(1+N6),L6),2)*H6,"")) -> 1907 | P6: =IF(O6="","",O6*N6) -> 400.47 | Q6: =IF(O6="","",O6+P6) -> 2307.47 | R6: =IFERROR(ROUND(IF(E6="con IVA en la ficha",I6/(1+N6),I6),2),"") -> 1907 | S6: =IF(OR(G6="No",NOT(ISNUMBER(R6))),"",R6*H6) -> 1907 | T6: =IF(OR(O6="",S6=""),"",IF(S6=0,"",IFERROR(O6/S6-1,""))) -> 0 | U6: =IF(G6="No","",IF(AND(L6>=J6,L6<=K6),"Dentro","Fuera de tu horquilla")) -> Dentro | V6: 1 | W6: 0 | X6: =IF(ISNUMBER(R6),R6*V6,"") -> 1907 | Y6: =IF(ISNUMBER(R6),R6*W6,"") -> 0 | Z6: Gas: le tocan los filtros a 1,20 m (CUN-26).
A7: 2 | B7: Fritura, dosificación y amasado | C7: Dosificadora automática de 5 kg de masa (ClimaHosteleria CH) | D7: CUS-34c | E7: sin IVA declarada en la ficha | F7: 46298 | G7: Sí | H7: 1 | I7: 1798 | J7: 1798 | K7: 1798 | L7: 1798 | M7: No | N7: ='Parámetros'!$B$6 -> 0.21 | O7: =IF(G7="No","",IFERROR(ROUND(IF(M7="Sí",L7/(1+N7),L7),2)*H7,"")) -> 1798 | P7: =IF(O7="","",O7*N7) -> 377.58 | Q7: =IF(O7="","",O7+P7) -> 2175.58 | R7: =IFERROR(ROUND(IF(E7="con IVA en la ficha",I7/(1+N7),I7),2),"") -> 1798 | S7: =IF(OR(G7="No",NOT(ISNUMBER(R7))),"",R7*H7) -> 1798 | T7: =IF(OR(O7="",S7=""),"",IF(S7=0,"",IFERROR(O7/S7-1,""))) -> 0 | U7: =IF(G7="No","",IF(AND(L7>=J7,L7<=K7),"Dentro","Fuera de tu horquilla")) -> Dentro | V7: 1 | W7: 0 | X7: =IF(ISNUMBER(R7),R7*V7,"") -> 1798 | Y7: =IF(ISNUMBER(R7),R7*W7,"") -> 0
A8: 3 | B8: Fritura, dosificación y amasado | C8: Amasadora automática con rascador (30 kg) | D8: CUS-35a | E8: sin IVA declarada en la ficha | F8: 46298 | G8: Sí | H8: 1 | I8: 2550 | J8: 2550 | K8: 2550 | L8: 2550 | M8: No | N8: ='Parámetros'!$B$6 -> 0.21 | O8: =IF(G8="No","",IFERROR(ROUND(IF(M8="Sí",L8/(1+N8),L8),2)*H8,"")) -> 2550 | P8: =IF(O8="","",O8*N8) -> 535.5 | Q8: =IF(O8="","",O8+P8) -> 3085.5 | R8: =IFERROR(ROUND(IF(E8="con IVA en la ficha",I8/(1+N8),I8),2),"") -> 2550 | S8: =IF(OR(G8="No",NOT(ISNUMBER(R8))),"",R8*H8) -> 2550 | T8: =IF(OR(O8="",S8=""),"",IF(S8=0,"",IFERROR(O8/S8-1,""))) -> 0 | U8: =IF(G8="No","",IF(AND(L8>=J8,L8<=K8),"Dentro","Fuera de tu horquilla")) -> Dentro | V8: 1 | W8: 0 | X8: =IF(ISNUMBER(R8),R8*V8,"") -> 2550 | Y8: =IF(ISNUMBER(R8),R8*W8,"") -> 0
A9: 4 | B9: Extracción y conducto | C9: Campana extractora de 1.200 mm con turbina y filtros | D9: CUS-36a | E9: sin IVA declarada en la ficha | F9: 46298 | G9: Sí | H9: 1 | I9: 990 | J9: 990 | K9: 990 | L9: 990 | M9: No | N9: ='Parámetros'!$B$6 -> 0.21 | O9: =IF(G9="No","",IFERROR(ROUND(IF(M9="Sí",L9/(1+N9),L9),2)*H9,"")) -> 990 | P9: =IF(O9="","",O9*N9) -> 207.9 | Q9: =IF(O9="","",O9+P9) -> 1197.9 | R9: =IFERROR(ROUND(IF(E9="con IVA en la ficha",I9/(1+N9),I9),2),"") -> 990 | S9: =IF(OR(G9="No",NOT(ISNUMBER(R9))),"",R9*H9) -> 990 | T9: =IF(OR(O9="",S9=""),"",IF(S9=0,"",IFERROR(O9/S9-1,""))) -> 0 | U9: =IF(G9="No","",IF(AND(L9>=J9,L9<=K9),"Dentro","Fuera de tu horquilla")) -> Dentro | V9: 1 | W9: 1 | X9: =IF(ISNUMBER(R9),R9*V9,"") -> 990 | Y9: =IF(ISNUMBER(R9),R9*W9,"") -> 990 | Z9: No incluye el conducto a cubierta ni el proyecto: van en su propia línea.
A10: 5 | B10: Chocolate y café | C10: Chocolatera Irimar MCH-5 (5 L) | D10: CUS-37a | E10: sin IVA declarada en la ficha | F10: 46298 | G10: Sí | H10: 2 | I10: 412.7 | J10: 412.7 | K10: 412.7 | L10: 412.7 | M10: No | N10: ='Parámetros'!$B$6 -> 0.21 | O10: =IF(G10="No","",IFERROR(ROUND(IF(M10="Sí",L10/(1+N10),L10),2)*H10,"")) -> 825.4 | P10: =IF(O10="","",O10*N10) -> 173.334 | Q10: =IF(O10="","",O10+P10) -> 998.734 | R10: =IFERROR(ROUND(IF(E10="con IVA en la ficha",I10/(1+N10),I10),2),"") -> 412.7 | S10: =IF(OR(G10="No",NOT(ISNUMBER(R10))),"",R10*H10) -> 825.4 | T10: =IF(OR(O10="",S10=""),"",IF(S10=0,"",IFERROR(O10/S10-1,""))) -> 0 | U10: =IF(G10="No","",IF(AND(L10>=J10,L10<=K10),"Dentro","Fuera de tu horquilla")) -> Dentro | V10: 2 | W10: 1 | X10: =IF(ISNUMBER(R10),R10*V10,"") -> 825.4 | Y10: =IF(ISNUMBER(R10),R10*W10,"") -> 412.7 | Z10: Dos en el local con sala; una en el despacho.
A11: 6 | B11: Fritura, dosificación y amasado | C11: Bandeja escurridor de 50 × 60 cm (Inblan) | D11: CUS-39 | E11: sin IVA declarada en la ficha | F11: 46298 | G11: Sí | H11: 1 | I11: 499.2 | J11: 499.2 | K11: 499.2 | L11: 499.2 | M11: No | N11: ='Parámetros'!$B$6 -> 0.21 | O11: =IF(G11="No","",IFERROR(ROUND(IF(M11="Sí",L11/(1+N11),L11),2)*H11,"")) -> 499.2 | P11: =IF(O11="","",O11*N11) -> 104.832 | Q11: =IF(O11="","",O11+P11) -> 604.032 | R11: =IFERROR(ROUND(IF(E11="con IVA en la ficha",I11/(1+N11),I11),2),"") -> 499.2 | S11: =IF(OR(G11="No",NOT(ISNUMBER(R11))),"",R11*H11) -> 499.2 | T11: =IF(OR(O11="",S11=""),"",IF(S11=0,"",IFERROR(O11/S11-1,""))) -> 0 | U11: =IF(G11="No","",IF(AND(L11>=J11,L11<=K11),"Dentro","Fuera de tu horquilla")) -> Dentro | V11: 1 | W11: 0 | X11: =IF(ISNUMBER(R11),R11*V11,"") -> 499.2 | Y11: =IF(ISNUMBER(R11),R11*W11,"") -> 0
A12: 7 | B12: Control y seguridad | C12: Balanza de 6 kg (Baxtran PD LCD) | D12: CUS-41 | E12: sin IVA declarada en la ficha | F12: 46298 | G12: Sí | H12: 1 | I12: 48.75 | J12: 48.75 | K12: 48.75 | L12: 48.75 | M12: No | N12: ='Parámetros'!$B$6 -> 0.21 | O12: =IF(G12="No","",IFERROR(ROUND(IF(M12="Sí",L12/(1+N12),L12),2)*H12,"")) -> 48.75 | P12: =IF(O12="","",O12*N12) -> 10.2375 | Q12: =IF(O12="","",O12+P12) -> 58.9875 | R12: =IFERROR(ROUND(IF(E12="con IVA en la ficha",I12/(1+N12),I12),2),"") -> 48.75 | S12: =IF(OR(G12="No",NOT(ISNUMBER(R12))),"",R12*H12) -> 48.75 | T12: =IF(OR(O12="",S12=""),"",IF(S12=0,"",IFERROR(O12/S12-1,""))) -> 0 | U12: =IF(G12="No","",IF(AND(L12>=J12,L12<=K12),"Dentro","Fuera de tu horquilla")) -> Dentro | V12: 1 | W12: 1 | X12: =IF(ISNUMBER(R12),R12*V12,"") -> 48.75 | Y12: =IF(ISNUMBER(R12),R12*W12,"") -> 48.75
A13: 8 | B13: Control y seguridad | C13: Medidor de compuestos polares Testo 270 BT | D13: CUS-38 | E13: con IVA en la ficha | F13: 46298 | G13: Sí | H13: 1 | I13: 603.79 | J13: 603.79 | K13: 603.79 | L13: 603.79 | M13: Sí | N13: ='Parámetros'!$B$6 -> 0.21 | O13: =IF(G13="No","",IFERROR(ROUND(IF(M13="Sí",L13/(1+N13),L13),2)*H13,"")) -> 499 | P13: =IF(O13="","",O13*N13) -> 104.79 | Q13: =IF(O13="","",O13+P13) -> 603.79 | R13: =IFERROR(ROUND(IF(E13="con IVA en la ficha",I13/(1+N13),I13),2),"") -> 499 | S13: =IF(OR(G13="No",NOT(ISNUMBER(R13))),"",R13*H13) -> 499 | T13: =IF(OR(O13="",S13=""),"",IF(S13=0,"",IFERROR(O13/S13-1,""))) -> 0 | U13: =IF(G13="No","",IF(AND(L13>=J13,L13<=K13),"Dentro","Fuera de tu horquilla")) -> Dentro | V13: 1 | W13: 1 | X13: =IF(ISNUMBER(R13),R13*V13,"") -> 499 | Y13: =IF(ISNUMBER(R13),R13*W13,"") -> 499 | Z13: La tienda lo publica con IVA: la base imponible se calcula. Ayuda a decidir el cambio de aceite; no es la prueba legal del 25 % (CUN-02).
A14: 9 | B14: Control y seguridad | C14: Rellenadora de churros | D14: supuesto declarado | E14: importe del lector | F14: supuesto, sin fecha | G14: No | H14: 1 | I14: 0 | J14: 0 | K14: 0 | L14: 0 | M14: No | N14: ='Parámetros'!$B$6 -> 0.21 | O14: =IF(G14="No","",IFERROR(ROUND(IF(M14="Sí",L14/(1+N14),L14),2)*H14,"")) | P14: =IF(O14="","",O14*N14) | Q14: =IF(O14="","",O14+P14) | R14: =IFERROR(ROUND(IF(E14="con IVA en la ficha",I14/(1+N14),I14),2),"") -> 0 | S14: =IF(OR(G14="No",NOT(ISNUMBER(R14))),"",R14*H14) | T14: =IF(OR(O14="",S14=""),"",IF(S14=0,"",IFERROR(O14/S14-1,""))) | U14: =IF(G14="No","",IF(AND(L14>=J14,L14<=K14),"Dentro","Fuera de tu horquilla")) | V14: 0 | W14: 0 | X14: =IF(ISNUMBER(R14),R14*V14,"") -> 0 | Y14: =IF(ISNUMBER(R14),R14*W14,"") -> 0 | Z14: Sin precio con fuente: pon tu presupuesto. El Molinete rellena con manga y no la compra; por eso su importe por defecto es cero.
A15: 10 | B15: Fritura, dosificación y amasado | C15: Equipo completo de churros Mundigas CH-1-D (dosificador de 1,5 kg y caldero de 14 L) | D15: CUS-32a | E15: sin IVA declarada en la ficha | F15: 46298 | G15: No | H15: 1 | I15: 2188 | J15: 2188 | K15: 2188 | L15: 2188 | M15: No | N15: ='Parámetros'!$B$6 -> 0.21 | O15: =IF(G15="No","",IFERROR(ROUND(IF(M15="Sí",L15/(1+N15),L15),2)*H15,"")) | P15: =IF(O15="","",O15*N15) | Q15: =IF(O15="","",O15+P15) | R15: =IFERROR(ROUND(IF(E15="con IVA en la ficha",I15/(1+N15),I15),2),"") -> 2188 | S15: =IF(OR(G15="No",NOT(ISNUMBER(R15))),"",R15*H15) | T15: =IF(OR(O15="",S15=""),"",IF(S15=0,"",IFERROR(O15/S15-1,""))) | U15: =IF(G15="No","",IF(AND(L15>=J15,L15<=K15),"Dentro","Fuera de tu horquilla")) | V15: 0 | W15: 1 | X15: =IF(ISNUMBER(R15),R15*V15,"") -> 0 | Y15: =IF(ISNUMBER(R15),R15*W15,"") -> 2188 | Z15: La alternativa de la decisión 3: equipo completo frente a línea separada.
A16: 11 | B16: Fritura, dosificación y amasado | C16: Caldero amasador Inhospan CALD50 | D16: CUS-35a | E16: sin IVA declarada en la ficha | F16: 46298 | G16: No | H16: 1 | I16: 247 | J16: 247 | K16: 247 | L16: 247 | M16: No | N16: ='Parámetros'!$B$6 -> 0.21 | O16: =IF(G16="No","",IFERROR(ROUND(IF(M16="Sí",L16/(1+N16),L16),2)*H16,"")) | P16: =IF(O16="","",O16*N16) | Q16: =IF(O16="","",O16+P16) | R16: =IFERROR(ROUND(IF(E16="con IVA en la ficha",I16/(1+N16),I16),2),"") -> 247 | S16: =IF(OR(G16="No",NOT(ISNUMBER(R16))),"",R16*H16) | T16: =IF(OR(O16="",S16=""),"",IF(S16=0,"",IFERROR(O16/S16-1,""))) | U16: =IF(G16="No","",IF(AND(L16>=J16,L16<=K16),"Dentro","Fuera de tu horquilla")) | V16: 0 | W16: 1 | X16: =IF(ISNUMBER(R16),R16*V16,"") -> 0 | Y16: =IF(ISNUMBER(R16),R16*W16,"") -> 247 | Z16: La alternativa artesanal a la amasadora.
A17: 12 | B17: Fritura, dosificación y amasado | C17: Pala de amasar | D17: CUS-35a | E17: sin IVA declarada en la ficha (precio «desde») | F17: 46298 | G17: No | H17: 1 | I17: 39 | J17: 39 | K17: 39 | L17: 39 | M17: No | N17: ='Parámetros'!$B$6 -> 0.21 | O17: =IF(G17="No","",IFERROR(ROUND(IF(M17="Sí",L17/(1+N17),L17),2)*H17,"")) | P17: =IF(O17="","",O17*N17) | Q17: =IF(O17="","",O17+P17) | R17: =IFERROR(ROUND(IF(E17="con IVA en la ficha",I17/(1+N17),I17),2),"") -> 39 | S17: =IF(OR(G17="No",NOT(ISNUMBER(R17))),"",R17*H17) | T17: =IF(OR(O17="",S17=""),"",IF(S17=0,"",IFERROR(O17/S17-1,""))) | U17: =IF(G17="No","",IF(AND(L17>=J17,L17<=K17),"Dentro","Fuera de tu horquilla")) | V17: 0 | W17: 1 | X17: =IF(ISNUMBER(R17),R17*V17,"") -> 0 | Y17: =IF(ISNUMBER(R17),R17*W17,"") -> 39 | Z17: Precio «desde».
A18: 13 | B18: Fritura, dosificación y amasado | C18: Escurridor Inhospan ESCL | D18: CUS-39 | E18: sin IVA declarada en la ficha (precio «desde») | F18: 46298 | G18: No | H18: 1 | I18: 260 | J18: 260 | K18: 260 | L18: 260 | M18: No | N18: ='Parámetros'!$B$6 -> 0.21 | O18: =IF(G18="No","",IFERROR(ROUND(IF(M18="Sí",L18/(1+N18),L18),2)*H18,"")) | P18: =IF(O18="","",O18*N18) | Q18: =IF(O18="","",O18+P18) | R18: =IFERROR(ROUND(IF(E18="con IVA en la ficha",I18/(1+N18),I18),2),"") -> 260 | S18: =IF(OR(G18="No",NOT(ISNUMBER(R18))),"",R18*H18) | T18: =IF(OR(O18="",S18=""),"",IF(S18=0,"",IFERROR(O18/S18-1,""))) | U18: =IF(G18="No","",IF(AND(L18>=J18,L18<=K18),"Dentro","Fuera de tu horquilla")) | V18: 0 | W18: 1 | X18: =IF(ISNUMBER(R18),R18*V18,"") -> 0 | Y18: =IF(ISNUMBER(R18),R18*W18,"") -> 260 | Z18: Precio «desde».
A19: 14 | B19: Fritura, dosificación y amasado | C19: Freidora de churros eléctrica de 25 L (ClimaHosteleria EMPLK003) | D19: CUS-33b | E19: sin IVA declarada en la ficha | F19: 46298 | G19: No | H19: 1 | I19: 2053 | J19: 2053 | K19: 2053 | L19: 2053 | M19: No | N19: ='Parámetros'!$B$6 -> 0.21 | O19: =IF(G19="No","",IFERROR(ROUND(IF(M19="Sí",L19/(1+N19),L19),2)*H19,"")) | P19: =IF(O19="","",O19*N19) | Q19: =IF(O19="","",O19+P19) | R19: =IFERROR(ROUND(IF(E19="con IVA en la ficha",I19/(1+N19),I19),2),"") -> 2053 | S19: =IF(OR(G19="No",NOT(ISNUMBER(R19))),"",R19*H19) | T19: =IF(OR(O19="",S19=""),"",IF(S19=0,"",IFERROR(O19/S19-1,""))) | U19: =IF(G19="No","",IF(AND(L19>=J19,L19<=K19),"Dentro","Fuera de tu horquilla")) | V19: 0 | W19: 0 | X19: =IF(ISNUMBER(R19),R19*V19,"") -> 0 | Y19: =IF(ISNUMBER(R19),R19*W19,"") -> 0 | Z19: La salida eléctrica de la decisión 4: sin instalación de gas, con más potencia contratada.
A20: 15 | B20: Extracción y conducto | C20: Conducto de evacuación a cubierta, obra y proyecto de ventilación | D20: supuesto declarado | E20: supuesto, sin IVA | F20: supuesto, sin fecha | G20: Sí | H20: 1 | I20: 9000 | J20: 9000 | K20: 9000 | L20: 9000 | M20: No | N20: ='Parámetros'!$B$6 -> 0.21 | O20: =IF(G20="No","",IFERROR(ROUND(IF(M20="Sí",L20/(1+N20),L20),2)*H20,"")) -> 9000 | P20: =IF(O20="","",O20*N20) -> 1890 | Q20: =IF(O20="","",O20+P20) -> 10890 | R20: =IFERROR(ROUND(IF(E20="con IVA en la ficha",I20/(1+N20),I20),2),"") -> 9000 | S20: =IF(OR(G20="No",NOT(ISNUMBER(R20))),"",R20*H20) -> 9000 | T20: =IF(OR(O20="",S20=""),"",IF(S20=0,"",IFERROR(O20/S20-1,""))) -> 0 | U20: =IF(G20="No","",IF(AND(L20>=J20,L20<=K20),"Dentro","Fuera de tu horquilla")) -> Dentro | V20: 0 | W20: 0 | X20: =IF(ISNUMBER(R20),R20*V20,"") -> 0 | Y20: =IF(ISNUMBER(R20),R20*W20,"") -> 0 | Z20: Sin precio con fuente (CUS-36b): pide presupuesto al técnico. Es la partida que decide la licencia de obra (CUN-35) y la primera fila del checklist.
A21: 16 | B21: Chocolate y café | C21: Cafetera de dos grupos | D21: supuesto declarado | E21: supuesto, sin IVA | F21: supuesto, sin fecha | G21: Sí | H21: 1 | I21: 4200 | J21: 4200 | K21: 4200 | L21: 4200 | M21: No | N21: ='Parámetros'!$B$6 -> 0.21 | O21: =IF(G21="No","",IFERROR(ROUND(IF(M21="Sí",L21/(1+N21),L21),2)*H21,"")) -> 4200 | P21: =IF(O21="","",O21*N21) -> 882 | Q21: =IF(O21="","",O21+P21) -> 5082 | R21: =IFERROR(ROUND(IF(E21="con IVA en la ficha",I21/(1+N21),I21),2),"") -> 4200 | S21: =IF(OR(G21="No",NOT(ISNUMBER(R21))),"",R21*H21) -> 4200 | T21: =IF(OR(O21="",S21=""),"",IF(S21=0,"",IFERROR(O21/S21-1,""))) -> 0 | U21: =IF(G21="No","",IF(AND(L21>=J21,L21<=K21),"Dentro","Fuera de tu horquilla")) -> Dentro | V21: 0 | W21: 0 | X21: =IF(ISNUMBER(R21),R21*V21,"") -> 0 | Y21: =IF(ISNUMBER(R21),R21*W21,"") -> 0 | Z21: Sin precio con fuente (CUS-43).
A22: 17 | B22: Chocolate y café | C22: Molinillo de café | D22: supuesto declarado | E22: supuesto, sin IVA | F22: supuesto, sin fecha | G22: Sí | H22: 1 | I22: 650 | J22: 650 | K22: 650 | L22: 650 | M22: No | N22: ='Parámetros'!$B$6 -> 0.21 | O22: =IF(G22="No","",IFERROR(ROUND(IF(M22="Sí",L22/(1+N22),L22),2)*H22,"")) -> 650 | P22: =IF(O22="","",O22*N22) -> 136.5 | Q22: =IF(O22="","",O22+P22) -> 786.5 | R22: =IFERROR(ROUND(IF(E22="con IVA en la ficha",I22/(1+N22),I22),2),"") -> 650 | S22: =IF(OR(G22="No",NOT(ISNUMBER(R22))),"",R22*H22) -> 650 | T22: =IF(OR(O22="",S22=""),"",IF(S22=0,"",IFERROR(O22/S22-1,""))) -> 0 | U22: =IF(G22="No","",IF(AND(L22>=J22,L22<=K22),"Dentro","Fuera de tu horquilla")) -> Dentro | V22: 0 | W22: 0 | X22: =IF(ISNUMBER(R22),R22*V22,"") -> 0 | Y22: =IF(ISNUMBER(R22),R22*W22,"") -> 0
A23: 18 | B23: Barra, sala y terraza | C23: Mostrador y barra | D23: supuesto declarado | E23: supuesto, sin IVA | F23: supuesto, sin fecha | G23: Sí | H23: 1 | I23: 6500 | J23: 6500 | K23: 6500 | L23: 6500 | M23: No | N23: ='Parámetros'!$B$6 -> 0.21 | O23: =IF(G23="No","",IFERROR(ROUND(IF(M23="Sí",L23/(1+N23),L23),2)*H23,"")) -> 6500 | P23: =IF(O23="","",O23*N23) -> 1365 | Q23: =IF(O23="","",O23+P23) -> 7865 | R23: =IFERROR(ROUND(IF(E23="con IVA en la ficha",I23/(1+N23),I23),2),"") -> 6500 | S23: =IF(OR(G23="No",NOT(ISNUMBER(R23))),"",R23*H23) -> 6500 | T23: =IF(OR(O23="",S23=""),"",IF(S23=0,"",IFERROR(O23/S23-1,""))) -> 0 | U23: =IF(G23="No","",IF(AND(L23>=J23,L23<=K23),"Dentro","Fuera de tu horquilla")) -> Dentro | V23: 0 | W23: 0 | X23: =IF(ISNUMBER(R23),R23*V23,"") -> 0 | Y23: =IF(ISNUMBER(R23),R23*W23,"") -> 0 | Z23: Sin precio con fuente (CUS-43).
A24: 19 | B24: Barra, sala y terraza | C24: Vitrina calefactada | D24: supuesto declarado | E24: supuesto, sin IVA | F24: supuesto, sin fecha | G24: Sí | H24: 1 | I24: 1400 | J24: 1400 | K24: 1400 | L24: 1400 | M24: No | N24: ='Parámetros'!$B$6 -> 0.21 | O24: =IF(G24="No","",IFERROR(ROUND(IF(M24="Sí",L24/(1+N24),L24),2)*H24,"")) -> 1400 | P24: =IF(O24="","",O24*N24) -> 294 | Q24: =IF(O24="","",O24+P24) -> 1694 | R24: =IFERROR(ROUND(IF(E24="con IVA en la ficha",I24/(1+N24),I24),2),"") -> 1400 | S24: =IF(OR(G24="No",NOT(ISNUMBER(R24))),"",R24*H24) -> 1400 | T24: =IF(OR(O24="",S24=""),"",IF(S24=0,"",IFERROR(O24/S24-1,""))) -> 0 | U24: =IF(G24="No","",IF(AND(L24>=J24,L24<=K24),"Dentro","Fuera de tu horquilla")) -> Dentro | V24: 0 | W24: 0 | X24: =IF(ISNUMBER(R24),R24*V24,"") -> 0 | Y24: =IF(ISNUMBER(R24),R24*W24,"") -> 0
A25: 20 | B25: Barra, sala y terraza | C25: Mesas y sillas de la sala | D25: supuesto declarado | E25: supuesto, sin IVA | F25: supuesto, sin fecha | G25: Sí | H25: 1 | I25: 5500 | J25: 5500 | K25: 5500 | L25: 5500 | M25: No | N25: ='Parámetros'!$B$6 -> 0.21 | O25: =IF(G25="No","",IFERROR(ROUND(IF(M25="Sí",L25/(1+N25),L25),2)*H25,"")) -> 5500 | P25: =IF(O25="","",O25*N25) -> 1155 | Q25: =IF(O25="","",O25+P25) -> 6655 | R25: =IFERROR(ROUND(IF(E25="con IVA en la ficha",I25/(1+N25),I25),2),"") -> 5500 | S25: =IF(OR(G25="No",NOT(ISNUMBER(R25))),"",R25*H25) -> 5500 | T25: =IF(OR(O25="",S25=""),"",IF(S25=0,"",IFERROR(O25/S25-1,""))) -> 0 | U25: =IF(G25="No","",IF(AND(L25>=J25,L25<=K25),"Dentro","Fuera de tu horquilla")) -> Dentro | V25: 0 | W25: 0 | X25: =IF(ISNUMBER(R25),R25*V25,"") -> 0 | Y25: =IF(ISNUMBER(R25),R25*W25,"") -> 0
A26: 21 | B26: Barra, sala y terraza | C26: Mesas, sillas y sombrillas de la terraza | D26: supuesto declarado | E26: supuesto, sin IVA | F26: supuesto, sin fecha | G26: Sí | H26: 1 | I26: 1800 | J26: 1800 | K26: 1800 | L26: 1800 | M26: No | N26: ='Parámetros'!$B$6 -> 0.21 | O26: =IF(G26="No","",IFERROR(ROUND(IF(M26="Sí",L26/(1+N26),L26),2)*H26,"")) -> 1800 | P26: =IF(O26="","",O26*N26) -> 378 | Q26: =IF(O26="","",O26+P26) -> 2178 | R26: =IFERROR(ROUND(IF(E26="con IVA en la ficha",I26/(1+N26),I26),2),"") -> 1800 | S26: =IF(OR(G26="No",NOT(ISNUMBER(R26))),"",R26*H26) -> 1800 | T26: =IF(OR(O26="",S26=""),"",IF(S26=0,"",IFERROR(O26/S26-1,""))) -> 0 | U26: =IF(G26="No","",IF(AND(L26>=J26,L26<=K26),"Dentro","Fuera de tu horquilla")) -> Dentro | V26: 0 | W26: 0 | X26: =IF(ISNUMBER(R26),R26*V26,"") -> 0 | Y26: =IF(ISNUMBER(R26),R26*W26,"") -> 0
A27: 22 | B27: Barra, sala y terraza | C27: Vajilla, tazas y menaje | D27: supuesto declarado | E27: supuesto, sin IVA | F27: supuesto, sin fecha | G27: Sí | H27: 1 | I27: 1500 | J27: 1500 | K27: 1500 | L27: 1500 | M27: No | N27: ='Parámetros'!$B$6 -> 0.21 | O27: =IF(G27="No","",IFERROR(ROUND(IF(M27="Sí",L27/(1+N27),L27),2)*H27,"")) -> 1500 | P27: =IF(O27="","",O27*N27) -> 315 | Q27: =IF(O27="","",O27+P27) -> 1815 | R27: =IFERROR(ROUND(IF(E27="con IVA en la ficha",I27/(1+N27),I27),2),"") -> 1500 | S27: =IF(OR(G27="No",NOT(ISNUMBER(R27))),"",R27*H27) -> 1500 | T27: =IF(OR(O27="",S27=""),"",IF(S27=0,"",IFERROR(O27/S27-1,""))) -> 0 | U27: =IF(G27="No","",IF(AND(L27>=J27,L27<=K27),"Dentro","Fuera de tu horquilla")) -> Dentro | V27: 0 | W27: 0 | X27: =IF(ISNUMBER(R27),R27*V27,"") -> 0 | Y27: =IF(ISNUMBER(R27),R27*W27,"") -> 0
A28: 23 | B28: Barra, sala y terraza | C28: Lavavajillas | D28: supuesto declarado | E28: supuesto, sin IVA | F28: supuesto, sin fecha | G28: Sí | H28: 1 | I28: 2200 | J28: 2200 | K28: 2200 | L28: 2200 | M28: No | N28: ='Parámetros'!$B$6 -> 0.21 | O28: =IF(G28="No","",IFERROR(ROUND(IF(M28="Sí",L28/(1+N28),L28),2)*H28,"")) -> 2200 | P28: =IF(O28="","",O28*N28) -> 462 | Q28: =IF(O28="","",O28+P28) -> 2662 | R28: =IFERROR(ROUND(IF(E28="con IVA en la ficha",I28/(1+N28),I28),2),"") -> 2200 | S28: =IF(OR(G28="No",NOT(ISNUMBER(R28))),"",R28*H28) -> 2200 | T28: =IF(OR(O28="",S28=""),"",IF(S28=0,"",IFERROR(O28/S28-1,""))) -> 0 | U28: =IF(G28="No","",IF(AND(L28>=J28,L28<=K28),"Dentro","Fuera de tu horquilla")) -> Dentro | V28: 0 | W28: 0 | X28: =IF(ISNUMBER(R28),R28*V28,"") -> 0 | Y28: =IF(ISNUMBER(R28),R28*W28,"") -> 0
A29: 24 | B29: Barra, sala y terraza | C29: Frigorífico de barra y arcón para el helado del verano | D29: supuesto declarado | E29: supuesto, sin IVA | F29: supuesto, sin fecha | G29: Sí | H29: 1 | I29: 1900 | J29: 1900 | K29: 1900 | L29: 1900 | M29: No | N29: ='Parámetros'!$B$6 -> 0.21 | O29: =IF(G29="No","",IFERROR(ROUND(IF(M29="Sí",L29/(1+N29),L29),2)*H29,"")) -> 1900 | P29: =IF(O29="","",O29*N29) -> 399 | Q29: =IF(O29="","",O29+P29) -> 2299 | R29: =IFERROR(ROUND(IF(E29="con IVA en la ficha",I29/(1+N29),I29),2),"") -> 1900 | S29: =IF(OR(G29="No",NOT(ISNUMBER(R29))),"",R29*H29) -> 1900 | T29: =IF(OR(O29="",S29=""),"",IF(S29=0,"",IFERROR(O29/S29-1,""))) -> 0 | U29: =IF(G29="No","",IF(AND(L29>=J29,L29<=K29),"Dentro","Fuera de tu horquilla")) -> Dentro | V29: 0 | W29: 0 | X29: =IF(ISNUMBER(R29),R29*V29,"") -> 0 | Y29: =IF(ISNUMBER(R29),R29*W29,"") -> 0
A30: 25 | B30: Control y seguridad | C30: Extintor de clase F para aceites | D30: supuesto declarado | E30: supuesto, sin IVA | F30: supuesto, sin fecha | G30: Sí | H30: 1 | I30: 130 | J30: 130 | K30: 130 | L30: 130 | M30: No | N30: ='Parámetros'!$B$6 -> 0.21 | O30: =IF(G30="No","",IFERROR(ROUND(IF(M30="Sí",L30/(1+N30),L30),2)*H30,"")) -> 130 | P30: =IF(O30="","",O30*N30) -> 27.3 | Q30: =IF(O30="","",O30+P30) -> 157.3 | R30: =IFERROR(ROUND(IF(E30="con IVA en la ficha",I30/(1+N30),I30),2),"") -> 130 | S30: =IF(OR(G30="No",NOT(ISNUMBER(R30))),"",R30*H30) -> 130 | T30: =IF(OR(O30="",S30=""),"",IF(S30=0,"",IFERROR(O30/S30-1,""))) -> 0 | U30: =IF(G30="No","",IF(AND(L30>=J30,L30<=K30),"Dentro","Fuera de tu horquilla")) -> Dentro | V30: 0 | W30: 0 | X30: =IF(ISNUMBER(R30),R30*V30,"") -> 0 | Y30: =IF(ISNUMBER(R30),R30*W30,"") -> 0 | Z30: El agente tiene que ser el adecuado a la clase de fuego (CUN-38); el precio, supuesto.
A31: 26 | B31: Control y seguridad | C31: Filtrado de aceite (filtro y portafiltros) | D31: supuesto declarado | E31: supuesto, sin IVA | F31: supuesto, sin fecha | G31: Sí | H31: 1 | I31: 350 | J31: 350 | K31: 350 | L31: 350 | M31: No | N31: ='Parámetros'!$B$6 -> 0.21 | O31: =IF(G31="No","",IFERROR(ROUND(IF(M31="Sí",L31/(1+N31),L31),2)*H31,"")) -> 350 | P31: =IF(O31="","",O31*N31) -> 73.5 | Q31: =IF(O31="","",O31+P31) -> 423.5 | R31: =IFERROR(ROUND(IF(E31="con IVA en la ficha",I31/(1+N31),I31),2),"") -> 350 | S31: =IF(OR(G31="No",NOT(ISNUMBER(R31))),"",R31*H31) -> 350 | T31: =IF(OR(O31="",S31=""),"",IF(S31=0,"",IFERROR(O31/S31-1,""))) -> 0 | U31: =IF(G31="No","",IF(AND(L31>=J31,L31<=K31),"Dentro","Fuera de tu horquilla")) -> Dentro | V31: 0 | W31: 0 | X31: =IF(ISNUMBER(R31),R31*V31,"") -> 0 | Y31: =IF(ISNUMBER(R31),R31*W31,"") -> 0
A32: 27 | B32: TPV y rótulo | C32: TPV con impresora de tiques | D32: supuesto declarado | E32: supuesto, sin IVA | F32: supuesto, sin fecha | G32: Sí | H32: 1 | I32: 1300 | J32: 1300 | K32: 1300 | L32: 1300 | M32: No | N32: ='Parámetros'!$B$6 -> 0.21 | O32: =IF(G32="No","",IFERROR(ROUND(IF(M32="Sí",L32/(1+N32),L32),2)*H32,"")) -> 1300 | P32: =IF(O32="","",O32*N32) -> 273 | Q32: =IF(O32="","",O32+P32) -> 1573 | R32: =IFERROR(ROUND(IF(E32="con IVA en la ficha",I32/(1+N32),I32),2),"") -> 1300 | S32: =IF(OR(G32="No",NOT(ISNUMBER(R32))),"",R32*H32) -> 1300 | T32: =IF(OR(O32="",S32=""),"",IF(S32=0,"",IFERROR(O32/S32-1,""))) -> 0 | U32: =IF(G32="No","",IF(AND(L32>=J32,L32<=K32),"Dentro","Fuera de tu horquilla")) -> Dentro | V32: 0 | W32: 0 | X32: =IF(ISNUMBER(R32),R32*V32,"") -> 0 | Y32: =IF(ISNUMBER(R32),R32*W32,"") -> 0
A33: 28 | B33: TPV y rótulo | C33: Rótulo de fachada | D33: supuesto declarado | E33: supuesto, sin IVA | F33: supuesto, sin fecha | G33: Sí | H33: 1 | I33: 1600 | J33: 1600 | K33: 1600 | L33: 1600 | M33: No | N33: ='Parámetros'!$B$6 -> 0.21 | O33: =IF(G33="No","",IFERROR(ROUND(IF(M33="Sí",L33/(1+N33),L33),2)*H33,"")) -> 1600 | P33: =IF(O33="","",O33*N33) -> 336 | Q33: =IF(O33="","",O33+P33) -> 1936 | R33: =IFERROR(ROUND(IF(E33="con IVA en la ficha",I33/(1+N33),I33),2),"") -> 1600 | S33: =IF(OR(G33="No",NOT(ISNUMBER(R33))),"",R33*H33) -> 1600 | T33: =IF(OR(O33="",S33=""),"",IF(S33=0,"",IFERROR(O33/S33-1,""))) -> 0 | U33: =IF(G33="No","",IF(AND(L33>=J33,L33<=K33),"Dentro","Fuera de tu horquilla")) -> Dentro | V33: 0 | W33: 0 | X33: =IF(ISNUMBER(R33),R33*V33,"") -> 0 | Y33: =IF(ISNUMBER(R33),R33*W33,"") -> 0
C35: TOTAL del equipamiento que compras | O35: =SUM(O6:O33) -> 47147.35 | P35: =SUM(P6:P33) -> 9900.9435 | Q35: =SUM(Q6:Q33) -> 57048.293 | S35: =SUM(S6:S33) -> 47147.35 | X35: =SUM(X6:X33) -> 9117.35 | Y35: =SUM(Y6:Y33) -> 4684.45
C36: Núcleo con precio de ficha del local con sala, sin el medidor de polares (el que suman las siete líneas de CUS-59) | X36: =IFERROR(X35-X13,"") -> 8618.35 | Y36: =IFERROR(Y35-Y13,"") -> 4185.45
C37: Desviación de tus importes contra la referencia (líneas que compras) | T37: =IF(OR(NOT(ISNUMBER(S35)),S35=0),"",IFERROR(O35/S35-1,"")) -> 0
C38: VEREDICTO DE LA DESVIACIÓN | T38: =IF(NOT(ISNUMBER(T37)),"",IF(ABS(T37)>'Parámetros'!$B$17,"REVISA: te desvías más de lo admitido","Dentro de lo admitido")) -> Dentro de lo admitido
C40: Precios de la ficha el 03-10-2026: los descuentos de las tiendas caducan, así que confirma el precio vigente antes de presupuestar y pon el tuyo en «Tu importe». La columna «Referencia» es el precio que publica la fuente el día de la fecha, en base imponible; «Tu importe» es el de TU presupuesto. Las líneas que El Molinete no compra (el despacho, la freidora eléctrica de la decisión 4, la rellenadora) están para que cambies «¿La compras?» y veas qué pasa con el CAPEX.
C41: Listas de validación (no las borres: las usan los desplegables)
C42: Sí o No
C43: Sí
...

Sheet Variante del Formato
A1: Variante del Formato
A2: AI Chef Pro · aichef.pro — Cómo Montar una Churrería-Chocolatería
A3: Local con sala, despacho para llevar, caseta de feria o franquicia. Sólo el local con sala es caso cifrado; la caseta remite al food truck.
A5: Variante | B5: m² | C5: Dotación con fuente, sin IVA | D5: Diferencia frente al local con sala | E5: Régimen de apertura | F5: Procedencia | G5: ¿Caso cifrado? | H5: Remite a | I5: Nota
A6: Local con sala, terraza y despacho a calle (el caso de El Molinete) | B6: 75 m² | C6: ='Equipamiento Línea a Línea'!$X$35 -> 9117.35 | D6: =C6-$C$6 -> 0 | E6: Con mesas (676 o 673) la actividad sale del Anexo de la Ley 12/2012: manda tu ayuntamiento. Las obras con proyecto, con su licencia. | F6: CUS-59 + CUN-35 + CHN-49c | G6: Sí | H6: esta guía | I6: Las ocho líneas con precio de ficha (CUS-59) más el medidor de polares. Sin la rellenadora, que no tiene cifra con fuente. Es la dotación con fuente, no el CAPEX: el CAPEX entero está en «CAPEX por Bloque».
A7: Despacho para llevar | B7: 25-40 m² | C7: ='Equipamiento Línea a Línea'!$Y$35 -> 4684.45 | D7: =C7-$C$6 -> -4432.9 | E7: La ACTIVIDAD del despacho (644.6, hasta 750 m²) va por declaración responsable; las obras que requieren proyecto, el conducto a cubierta incluido, siguen necesitando su licencia y su técnico. | F7: CUS-58 + CUN-35 + CUN-09 | G7: No | H7: esta guía | I7: La dotación A (CUS-58): equipo completo Mundigas, caldero, pala, escurridor, una chocolatera, campana, balanza y medidor de polares. Sin sala te ahorras mobiliario y vajilla, y pierdes la parte de la venta que se consume en el local.
A8: Caseta, remolque o carrito de feria | B8: el del puesto | C8: =INDEX($F$14:$F$16,$B$12) -> 14800 | D8: =C8-$C$6 -> 5682.65 | E8: 663.1 si sólo vende masas fritas (CUN-11); 675 o 674.7 con mesas (CUN-13). La bombona de menos de 15 kg sólo libra de la instalación receptora a un aparato de utilización móvil (CUN-28). | F8: CUS-42 + CUN-11 + CUN-13 + CUN-28 | G8: No | H8: Plan de Negocio: Food Truck, Tareas: Food Truck | I8: El equipo de feria que elijas abajo. Sin caso cifrado: el capítulo y el checklist del libro 7 te dicen qué papeles hacen falta; las cuentas de un puesto móvil, el plan de negocio del food truck.
A9: Franquicia | B9: el que pida la enseña | C9: No es una dotación | D9: Ver «Franquicia o Independiente» | E9: El de su formato, más el contrato de franquicia. | F9: CUS-M12 + CUS-M14 + CUS-M15 | G9: No | H9: esta guía | I9: La inversión de una franquicia incluye canon, obra y lo que diga cada enseña: no se compara con una dotación de máquinas. Va en su hoja, fechada y como orden de magnitud.
A11: Equipos de Feria (Variante Caseta)
A12: Equipo de feria que miras (1, 2 o 3, por su número de abajo) | B12: 1
A13: Equipo | B13: Nº | C13: Precio publicado | D13: ¿Lleva IVA? | E13: Tipo de IVA | F13: Base sin IVA | G13: Fecha del precio | H13: Procedencia
A14: Remolque de 3 × 2 × 2,10 m con cartel | B14: 1 | C14: 14800 | D14: No | E14: ='Parámetros'!$B$6 -> 0.21 | F14: =IFERROR(IF(D14="Sí",C14/(1+E14),C14),"") -> 14800 | G14: 46298 | H14: CUS-42 (la tienda publica «Impuestos excluidos»)
A15: Mini carrito para eventos y mercados | B15: 2 | C15: 6190 | D15: No | E15: ='Parámetros'!$B$6 -> 0.21 | F15: =IFERROR(IF(D15="Sí",C15/(1+E15),C15),"") -> 6190 | G15: 46298 | H15: CUS-42 (la tienda publica «Impuestos excluidos»)
A16: Churrería portátil para exteriores de cafeterías | B16: 3 | C16: 4190 | D16: No | E16: ='Parámetros'!$B$6 -> 0.21 | F16: =IFERROR(IF(D16="Sí",C16/(1+E16),C16),"") -> 4190 | G16: 46298 | H16: CUS-42 (la tienda publica «Impuestos excluidos»)
A18: Lo que Queda Fuera del Comparador
A19: Churros en una cafetería o un bar | E19: Epígrafe con remisión al Plan de Negocio de Cafetería: la churrería es una línea más de su carta. | H19: Plan de Negocio: Cafetería
A20: Obrador que sirve a otros negocios | E20: Fuera del producto: si fabricas para otros dejas de ser minorista (419.3, CUN-12; la churrería que sirve a la cafetería, CUN-30). | H20: fuera del producto
A23: Listas de validación (no las borres: las usan los desplegables)
A24: Sí o No | B24: Equipo de feria
A25: Sí | B25: 1
A26: No | B26: 2
B27: 3

Sheet Franquicia o Independiente
A1: Franquicia o Independiente
A2: AI Chef Pro · aichef.pro — Cómo Montar una Churrería-Chocolatería
A3: Orden de magnitud publicado por el franquiciador a través de un agregador, consultado el 03-10-2026: no es precio de contrato ni una recomendación de marca.
A5: Enseña | B5: Inversión publicada | C5: Qué incluye, según la enseña | D5: Canon de entrada | E5: Royalty sobre ventas | F5: Locales | G5: Fuente | H5: Consultado el | I5: ¿Base comparable con tu CAPEX? | J5: Diferencia frente a tu CAPEX | K5: Nota
A6: Chocolaterías Valor | B6: 125000 | C6: local en bruto con obra, maquinaria y mobiliario | D6: 24040 | E6: 0.05 | F6: 39 (32 franquiciados) | G6: CUS-M12 + CUS-03 | H6: 46298 | I6: Sí | J6: =IF(I6="Sí",IFERROR(B6-$B$19,""),"") -> 38584.35
A7: Maestro Churrero | B7: 115000 | C7: inversión inicial «desde» | D7: 15000 | E7: 0.05 | F7: no publicado | G7: CUS-M14 | H7: 46298 | I7: No | J7: =IF(I7="Sí",IFERROR(B7-$B$19,""),"") | K7: Más un 1 % de canon publicitario.
A8: Churros Factory | B8: 45000 | C8: inversión total | D8: 12000 | E8: 0.06 | F8: no publicado | G8: CUS-M15 | H8: 46298 | I8: Sí | J8: =IF(I8="Sí",IFERROR(B8-$B$19,""),"") -> -41415.65 | K8: Contrato de 10 años renovables.
A9: Madrid1883 | B9: 96000 | C9: inversión total aproximada | D9: 20000 | E9: 0.04 | F9: no publicado | G9: CUS-M16 | H9: 46298 | I9: Sí | J9: =IF(I9="Sí",IFERROR(B9-$B$19,""),"") -> 9584.35 | K9: Más un 2 % de publicidad. Su facturación esperada es proyección: no entra.
A10: Pinocho Churros Gourmet | B10: 73000 | C10: inversión total según el dossier (58.000 € de capital propio) | D10: no publicado | E10: no publicado | F10: 10 implantaciones | G10: CUS-M17 + CUS-14 | H10: 46298 | I10: Sí | J10: =IF(I10="Sí",IFERROR(B10-$B$19,""),"") -> -13415.65 | K10: El objetivo de expansión del franquiciador no es un dato.
A11: Tejeringo's Coffee | B11: 320000 | C11: inversión aproximada más IVA, canon incluido | D11: 20000 | E11: no publicado | F11: no publicado | G11: CUS-M18 | H11: 46298 | I11: No | J11: =IF(I11="Sí",IFERROR(B11-$B$19,""),"")
A12: Kukuchurro | B12: 75000 | C12: inversión inicial «desde», más IVA, canon incluido | D12: 15000 | E12: no publicado | F12: no publicado | G12: CUS-M19 | H12: 46298 | I12: No | J12: =IF(I12="Sí",IFERROR(B12-$B$19,""),"")
A13: ChurroWay | B13: 75000 | C13: inversión inicial «desde», sin IVA, fianzas ni existencias | D13: 15000 | E13: no publicado | F13: no publicado | G13: CUS-M20 | H13: 46298 | I13: No | J13: =IF(I13="Sí",IFERROR(B13-$B$19,""),"")
A14: Churritopping | B14: 42600 | C14: inversión inicial aproximada, sin la obra | D14: no publicado | E14: 0.05 | F14: no publicado | G14: CUS-M21 | H14: 46298 | I14: No | J14: =IF(I14="Sí",IFERROR(B14-$B$19,""),"") | K14: Más un 2 % de publicidad.
