Workbook

Sheet Instrucciones
A1: Checklist Legal, Fritura y Licencias
A2: AI Chef Pro · aichef.pro — Cómo Montar una Churrería-Chocolatería
A3: Para qué sirve: saber qué papel te toca y en qué orden, antes de firmar el local y hasta el día que abres.
A5: Celdas verdes = campos editables
A7: Instrucciones de uso
A8: 1. «Checklist Legal (F1-F6)»: los 30 trámites en el orden en que hay que hacerlos, en seis fases. LA PRIMERA FILA es «¿la extracción necesita proyecto?»: si sí, licencia de obra y técnico aunque la actividad vaya por declaración responsable. La segunda, si tu actividad está en el Anexo de la Ley 12/2012. Marca el estado, el responsable, lo que te presupuestan y lo que pagas, y las fechas.
A9: 2. «Árbol IAE y CNAE por Formato»: cinco preguntas y los epígrafes que te tocan (644.6, 676 o 673, 663.1, 675, 419.3), la exención del impuesto y LA PREGUNTA DEL CNAE redactada para tu asesor, con los dos códigos que hoy se comunican y la trampa del 47.81.
A10: 3. «Régimen de Apertura y Horario»: por qué régimen va tu actividad, qué pasa con las obras y la terraza, y la norma del horario del ejemplo de Madrid. Tu hora de apertura NO se pone aquí: se pone en el libro de temporada y franjas.
A11: 4. «Licencia, Humos y Gas»: la licencia de obra, la salida de humos del ejemplo de Madrid, el gas (instalación receptora en el local; la bombona pequeña sólo en la feria) y el extintor de clase F, con su lista de papeles.
A12: 5. «Árbol de Registro Sanitario»: registro autonómico o registro general, según a quién vendas.
A13: 6. «Ferias y Venta Ambulante»: si vas a ferias, los requisitos del puesto. Los euros de cada evento se calculan en el libro de temporada y ferias.
A14: 7. «Alérgenos y Aceite Compartido»: qué fríes en la misma freidora, los alérgenos de tu carta por familia, el «sin gluten», la acrilamida y lo que dice la norma del aceite.
... A20: Rellena los libros en este orden: cada uno usa cifras de los anteriores, que se copian a mano en su celda verde de cruce. Este libro, el 7, no depende de ninguno: puedes rellenarlo cuando quieras, y conviene empezarlo antes de firmar el local.
A21: Paso | B21: Libro | C21: Fichero
A22: 1 | B22: Libro 3 | C22: carta-de-apertura-y-escandallo-churro.xlsx
A23: 2 | B23: Libro 1 | C23: produccion-hora-punta-y-local.xlsx
A24: 3 | B24: Libro 4 | C24: aceite-de-fritura-coste-y-cambio.xlsx
A25: 4 | B25: Libro 5 | C25: temporada-franjas-y-ferias.xlsx
A26: 5 | B26: Libro 8 | C26: turnos-plantilla-y-madrugada.xlsx
A27: 6 | B27: Libro 2 | C27: calculadora-capex-churreria.xlsx
A28: 7 | B28: Libro 6 | C28: plan-financiero-3-anos-churreria.xlsx
A29: 8 | B29: Libro 7 | C29: checklist-legal-fritura-y-licencias.xlsx
A31: Lo que conviene saber antes de empezar
A32: LA ACTIVIDAD Y LA OBRA SON DOS PAPELES DISTINTOS. Un despacho de churros para llevar (644.6, hasta 750 metros cuadrados) abre su actividad por declaración responsable, pero si la salida de humos necesita proyecto -casi siempre que el conducto sube a cubierta o cruza fachada o patio-, esa obra va con su licencia y su técnico. Con mesas (676 o 673) la actividad sale del Anexo de la Ley 12/2012 y el modelo lo fija tu ayuntamiento.
A33: EL CNAE NO TE LO DA ESTA HOJA, Y NO ES UN OLVIDO: la correspondencia oficial entre el epígrafe del impuesto y el CNAE-2025 no está publicada para la churrería. Lo que sí te da es la pregunta redactada para tu asesor, con el código de 2025 y el de 2009.
A34: EL HORARIO DE ESTE LIBRO ES UN EJEMPLO DE MADRID y no se extrapola: allí, una cafetería o bar puede abrir desde las 6:00 y una chocolatería desde las 8:00. Busca la orden de horarios de tu comunidad.
A35: LA BOMBONA PEQUEÑA NO TE LIBRA DE NADA EN UN LOCAL. La excepción es para un aparato de utilización móvil, es decir, para el puesto de feria. En un local, gas con instalación receptora e inspección periódica, o freidora eléctrica.
A36: EL REGISTRO DE FORMACIÓN ES LO QUE SE ACREDITA. La obligación es del empresario: garantizar la formación de cada persona según su puesto y poder demostrarla.
A37: ESTE LIBRO NO ES UN DICTAMEN JURÍDICO NI SUSTITUYE AL PROYECTO TÉCNICO DE LA EXTRACCIÓN. Cada dato normativo lleva en su celda un comentario con la norma, el artículo y el enlace, verificados el 03-10-2026 (o el 12-09-2026 los que vienen de la guía de chocolatería). Contrástalos con tu ayuntamiento y tu comunidad.
A39: Qué hace este libro y qué hace otro (para no teclear dos veces)
A40: Producto o libro | B40: Qué aporta | C40: Qué NO hace este libro
A41: Pack Plantillas APPCC, registro 09 (control del aceite de fritura) | B41: El registro de las mediciones del aceite y de la retirada del aceite usado. | C41: Aquí sólo hay una fila que te recuerda llevarlo. El registro es aquel fichero: se cita, no se copia.
A42: produccion-hora-punta-y-local.xlsx (libro 1 de esta guía) | B42: Los kW de tus freidoras, el riesgo de incendio de la cocina, la extinción automática y la distancia de los filtros. | C42: Este libro no vuelve a calcular la potencia: te dice qué papeles salen de ella.
A43: calculadora-capex-churreria.xlsx (libro 2 de esta guía) | B43: Los euros: proyecto, licencias, obra, extintor y equipamiento, con su IVA. | C43: Los costes de este checklist son los de los TRÁMITES y se piden, no se suponen.
A44: temporada-franjas-y-ferias.xlsx (libro 5 de esta guía) | B44: Tu hora de apertura por franja, el semáforo de las 8:00 y los euros de cada feria. | C44: Aquí está la norma del horario y los papeles del puesto; los números, allí.
A45: turnos-plantilla-y-madrugada.xlsx (libro 8 de esta guía) | B45: Las dos figuras de nocturnidad, el convenio y el coste de la plantilla. | C45: Aquí sólo están las filas del checklist que te recuerdan hacerlo.
A46: Plan de Negocio: Food Truck y Tareas: Food Truck | B46: El caso completo de un puesto móvil, con sus números y sus tareas. | C46: La caseta de feria es aquí un capítulo de papeles, sin caso cifrado.
A48: Cada cuánto se usa este libro
A49: El checklist y el cronograma, UNA VEZ A LA SEMANA desde que decides abrir hasta que abres. Los árboles (impuesto, régimen y registro), una vez al principio y otra CADA VEZ QUE CAMBIES DE FORMATO: el día que empieces a servir churros a la cafetería de al lado o a ir a ferias, cambian tus papeles. El registro de formación, cada vez que entra alguien. La hoja de riesgos, cuando cambies de máquina o de distribución.
A51: Para editar la estructura o una celda que no esté en verde: Revisar > Desproteger hoja (no tiene contraseña).
...

Sheet Checklist Legal (F1-F6)
A1: Checklist Legal y de Licencias, en Seis Fases
A2: AI Chef Pro · aichef.pro — Cómo Montar una Churrería-Chocolatería
A3: Los trámites en el orden en que hay que hacerlos. Las dos primeras filas son PREGUNTAS: contéstalas antes de firmar el local, porque deciden el resto. Lo que cambia según tu comunidad va marcado en su columna.
A5: Estado | B5: Fase | C5: Trámite | D5: Responsable | E5: Plazo (días) | F5: Coste previsto (€) | G5: Coste real (€) | H5: Fecha objetivo | I5: Fecha hecha | J5: ¿Cambia por CCAA? | K5: Tu respuesta | L5: Lo que te toca | M5: Notas y fuente
A6: F1 · Antes de firmar: el local, la extracción, el gas y el horario
A7: Pendiente | B7: F1 | C7: ¿La extracción necesita proyecto? | D7: Promotor y técnico | E7: 10 | F7: A presupuestar | G7: Sin pagar | H7: 46298 | I7: 46298 | J7: Sí | K7: Sí | L7: =IFERROR(IF(K7="Sí","Licencia de obra y técnico: el conducto necesita proyecto, aunque la actividad vaya por declaración responsable",IF(K7="No","Sin obra con proyecto: que tu técnico lo deje por escrito antes de firmar","No firmes el local sin que un técnico mire la salida de humos")),"") -> Licencia de obra y técnico: el conducto necesita proyecto, aunque la actividad vaya por declaración responsable | M7: Casi siempre que hay conducto a cubierta, o que cruza fachada o patio: entonces van licencia de obra y técnico, aunque la actividad vaya por declaración responsable (Ley 12/2012, art. 3.3-3.4). [Fuente: CUN-35 + CUN-23 + CUN-24]
A8: Pendiente | B8: F1 | C8: ¿Tu actividad está en el Anexo de la Ley 12/2012? | D8: Promotor | E8: 5 | F8: A presupuestar | G8: Sin pagar | H8: 46298 | I8: 46298 | J8: No | K8: =IFERROR(IF(OR('Árbol IAE y CNAE por Formato'!$B$6="Sí",'Régimen de Apertura y Horario'!$B$6="Sí"),"No","Sí"),"") -> No | L8: =IFERROR(IF(K8="Sí","Tu actividad está en el Anexo (644.6, hasta 750 m²): va por declaración responsable; las obras con proyecto, con su licencia aparte","Tu actividad sale del Anexo (con mesas o barra, o más de 750 m²): el modelo, licencia o declaración, lo fija tu ayuntamiento; y las obras con proyecto, con su licencia aparte"),"") -> Tu actividad sale del Anexo (con mesas o barra, o más de 750 m²): el modelo, licencia o declaración, lo fija tu ayuntamiento; y las obras con proyecto, con su licencia aparte | M8: La actividad de un despacho para llevar (644.6, hasta 750 m²) va por declaración responsable; con mesas (676 o 673) sale del Anexo y manda tu ayuntamiento. [Fuente: CUN-35 + CHN-49b + CHN-49c]
A9: Pendiente | B9: F1 | C9: Comprobar la salida de humos del local | D9: Promotor y técnico | E9: 5 | F9: A presupuestar | G9: Sin pagar | H9: 46298 | I9: 46298 | J9: Sí | M9: En el ejemplo de Madrid: captación, filtrado y conducto a cubierta, con limpieza al menos una vez al año. Los requisitos de otras ciudades no están verificados. [Fuente: CUN-23 + CUN-24]
A10: Pendiente | B10: F1 | C10: Comprobar la potencia de la freidora y el riesgo de incendio | D10: Técnico | E10: 5 | F10: A presupuestar | G10: Sin pagar | H10: 46298 | I10: 46298 | J10: No | M10: Freidoras a 1 kW por litro; local de riesgo especial desde 20 kW; extinción automática por encima de 50 kW; filtros a 1,20 m del foco con gas o parrilla. [Fuente: CUN-26]
A11: Pendiente | B11: F1 | C11: Decidir el gas: instalación receptora o freidora eléctrica | D11: Promotor | E11: 5 | F11: A presupuestar | G11: Sin pagar | H11: 46298 | I11: 46298 | J11: No | M11: En un local, gas con instalación receptora e inspección cada cinco años, o eléctrico con su potencia. La bombona pequeña sólo vale para un aparato de utilización móvil (feria). [Fuente: CHN-48 + CUN-28]
A12: Pendiente | B12: F1 | C12: Comprobar el horario que te permite tu clasificación | D12: Promotor | E12: 3 | F12: A presupuestar | G12: Sin pagar | H12: 46298 | I12: 46298 | J12: Sí | M12: Ejemplo de Madrid: cafetería o bar desde las 6:00; chocolatería desde las 8:00. Tu hora de apertura se pone en la hoja «Franjas del Día» del libro 5. [Fuente: CUN-34]
C13: AVANCE DE LA FASE F1 | D13: =IFERROR(COUNTIF(A7:A12,"Hecho"),"") -> 0 | E13: =IFERROR(COUNTIF(B7:B12,"F1"),"") -> 6 | F13: =IFERROR(SUMIF(F7:F12,">=0"),"") -> 0 | G13: =IFERROR(SUMIF(G7:G12,">=0"),"") -> 0 | J13: =IFERROR(IF(E13=0,"",(D13+COUNTIF(A7:A12,"N/A"))/E13),"") -> 0 | M13: Hechos · trámites de la fase · coste previsto · coste real · % de avance (los «N/A» cuentan como resueltos).
A15: F2 · Sociedad, altas fiscales y proyecto técnico
A16: Pendiente | B16: F2 | C16: Constituir la sociedad o darse de alta como autónomo | D16: Promotor | E16: 20 | F16: A presupuestar | G16: Sin pagar | H16: 46298 | I16: 46298 | J16: No | M16: Verifactu: 2027 para sociedades y autónomos, no 2026. [Fuente: CHN-75]
A17: Pendiente | B17: F2 | C17: Alta censal con doble código CNAE, como pregunta al asesor | D17: Gestoría | E17: 3 | F17: A presupuestar | G17: Sin pagar | H17: 46298 | I17: 46298 | J17: No | M17: La correspondencia del IAE con el CNAE-2025 no está publicada: se pregunta, con el código de 2025 y el de 2009. Ojo: el 47.81 de 2025 es de vehículos de motor. [Fuente: CUN-16 + CHN-74b + CUN-15]
A18: Pendiente | B18: F2 | C18: Alta en el IAE: la sala y la venta al peso | D18: Gestoría | E18: 3 | F18: A presupuestar | G18: Sin pagar | H18: 46298 | I18: 46298 | J18: No | M18: Alta sí, pago casi nunca: exención por debajo de un millón de euros de cifra de negocio. Una cuota faculta sólo para su actividad. [Fuente: CUN-09 + CUN-14 + CHN-73 + CHN-94]
A19: Pendiente | B19: F2 | C19: Encargar el proyecto técnico de actividad y de la extracción | D19: Ingeniería | E19: 30 | F19: A presupuestar | G19: Sin pagar | H19: 46298 | I19: 46298 | J19: No | M19: Su coste es un supuesto del libro 2, bloque 8. [Fuente: CUN-35]
A20: Pendiente | B20: F2 | C20: Firmar el arrendamiento y depositar la fianza | D20: Promotor | E20: 5 | F20: A presupuestar | G20: Sin pagar | H20: 46298 | I20: 46298 | J20: Sí | M20: La fianza se deposita en el organismo de tu comunidad. [Fuente: supuesto]
C21: AVANCE DE LA FASE F2 | D21: =IFERROR(COUNTIF(A16:A20,"Hecho"),"") -> 0 | E21: =IFERROR(COUNTIF(B16:B20,"F2"),"") -> 5 | F21: =IFERROR(SUMIF(F16:F20,">=0"),"") -> 0 | G21: =IFERROR(SUMIF(G16:G20,">=0"),"") -> 0 | J21: =IFERROR(IF(E21=0,"",(D21+COUNTIF(A16:A20,"N/A"))/E21),"") -> 0 | M21: Hechos · trámites de la fase · coste previsto · coste real · % de avance (los «N/A» cuentan como resueltos).
A23: F3 · Licencias de obra y de actividad, gas y terraza
A24: Pendiente | B24: F3 | C24: Pedir la licencia de obra del conducto, si la primera fila dijo que sí | D24: Técnico | E24: 60 | F24: A presupuestar | G24: Sin pagar | H24: 46298 | I24: 46298 | J24: Sí | M24: [Fuente: CUN-35]
A25: Pendiente | B25: F3 | C25: Presentar la declaración responsable o pedir la licencia de actividad | D25: Técnico | E25: 30 | F25: A presupuestar | G25: Sin pagar | H25: 46298 | I25: 46298 | J25: Sí | M25: El modelo depende de la segunda fila: nunca «necesitas licencia» o «no la necesitas» sin decir cuál. [Fuente: CUN-35 + CHN-49c]
A26: Pendiente | B26: F3 | C26: Certificar la instalación receptora de gas | D26: Instalador | E26: 15 | F26: A presupuestar | G26: Sin pagar | H26: 46298 | I26: 46298 | J26: No | M26: [Fuente: CHN-48]
A27: Pendiente | B27: F3 | C27: Pedir la autorización de la terraza | D27: Promotor | E27: 30 | F27: A presupuestar | G27: Sin pagar | H27: 46298 | I27: 46298 | J27: Sí | M27: La ocupación de la vía pública va aparte (art. 2.2 de la Ley 12/2012). [Fuente: CUN-35]
C28: AVANCE DE LA FASE F3 | D28: =IFERROR(COUNTIF(A24:A27,"Hecho"),"") -> 0 | E28: =IFERROR(COUNTIF(B24:B27,"F3"),"") -> 4 | F28: =IFERROR(SUMIF(F24:F27,">=0"),"") -> 0 | G28: =IFERROR(SUMIF(G24:G27,">=0"),"") -> 0 | J28: =IFERROR(IF(E28=0,"",(D28+COUNTIF(A24:A27,"N/A"))/E28),"") -> 0 | M28: Hechos · trámites de la fase · coste previsto · coste real · % de avance (los «N/A» cuentan como resueltos).
A30: F4 · Obra, instalaciones y maquinaria
A31: Pendiente | B31: F4 | C31: Hacer la obra y el conducto | D31: Promotor | E31: 60 | F31: A presupuestar | G31: Sin pagar | H31: 46298 | I31: 46298 | J31: No | M31: [Fuente: CUN-23]
A32: Pendiente | B32: F4 | C32: Instalar la campana con los filtros a su distancia y el extintor de clase F | D32: Instalador | E32: 10 | F32: A presupuestar | G32: Sin pagar | H32: 46298 | I32: 46298 | J32: No | M32: [Fuente: CUN-26 + CUN-38]
A33: Pendiente | B33: F4 | C33: Pedir la maquinaria crítica con el plazo de entrega por escrito | D33: Promotor | E33: =IFERROR('Cronograma y Ruta Crítica'!$C$6*'Cronograma y Ruta Crítica'!$C$7,"") -> 42 | F33: A presupuestar | G33: Sin pagar | H33: 46298 | I33: 46298 | J33: No | M33: El plazo de esta fila sale del plazo de entrega de la maquinaria crítica, que se pone UNA sola vez, en la hoja «Cronograma y Ruta Crítica» (celda C6), en semanas. Pídelo por escrito al proveedor. [Fuente: supuesto]
A34: Pendiente | B34: F4 | C34: Contratar un gestor autorizado del aceite usado y guardar los justificantes | D34: Promotor | E34: 5 | F34: A presupuestar | G34: Sin pagar | H34: 46298 | I34: 46298 | J34: No | M34: La recogida separada del aceite de cocina usado es obligatoria. [Fuente: CUN-27 + CUS-44h]
C35: AVANCE DE LA FASE F4 | D35: =IFERROR(COUNTIF(A31:A34,"Hecho"),"") -> 0 | E35: =IFERROR(COUNTIF(B31:B34,"F4"),"") -> 4 | F35: =IFERROR(SUMIF(F31:F34,">=0"),"") -> 0 | G35: =IFERROR(SUMIF(G31:G34,">=0"),"") -> 0 | J35: =IFERROR(IF(E35=0,"",(D35+COUNTIF(A31:A34,"N/A"))/E35),"") -> 0 | M35: Hechos · trámites de la fase · coste previsto · coste real · % de avance (los «N/A» cuentan como resueltos).
A37: F5 · Registro sanitario, autocontrol, aceite, alérgenos y formación
A38: Pendiente | B38: F5 | C38: Comunicar la actividad al registro sanitario autonómico | D38: Promotor | E38: 15 | F38: A presupuestar | G38: Sin pagar | H38: 46298 | I38: 46298 | J38: Sí | M38: El minorista queda fuera del registro general; si sirves churros a una cafetería de otro titular, cambia la cosa (actividad restringida). [Fuente: CHN-39 + CUN-30]
A39: Pendiente | B39: F5 | C39: Plan de autocontrol con responsable y registro del aceite | D39: Encargado/a | E39: 10 | F39: A presupuestar | G39: Sin pagar | H39: 46298 | I39: 46298 | J39: No | M39: La norma de aceites alcanza a la churrería; polares por debajo del 25 %; el artículo 9 sigue vivo. El registro se lleva en el Pack APPCC 09. [Fuente: CHN-32 + CUN-01 + CUN-02 + CUN-03]
A40: Pendiente | B40: F5 | C40: Alérgenos de la carta por escrito y aceite compartido | D40: Encargado/a | E40: 5 | F40: A presupuestar | G40: Sin pagar | H40: 46298 | I40: 46298 | J40: No | M40: Gluten siempre; la freidora que fríe otra cosa contamina; «sin gluten» casi nunca se puede decir. [Fuente: CHN-34 + CHN-33 + CHN-37]
A41: Pendiente | B41: F5 | C41: Acrilamida: buena práctica en el churro, parte A si fríes patatas | D41: Encargado/a | E41: 5 | F41: A presupuestar | G41: Sin pagar | H41: 46298 | I41: 46298 | J41: No | M41: El churro no está nombrado en el reglamento; la parte B sólo alcanza a quien sigue las instrucciones de un suministro centralizado (art. 2.3). [Fuente: CUN-04 + CUN-05 + CUN-06 + CUN-07]
A42: Pendiente | B42: F5 | C42: Registro de formación del personal | D42: Encargado/a | E42: 5 | F42: A presupuestar | G42: Sin pagar | H42: 46298 | I42: 46298 | J42: No | M42: [Fuente: CHN-69]
A43: Pendiente | B43: F5 | C43: Denominación del chocolate según la etiqueta del preparado | D43: Encargado/a | E43: 3 | F43: A presupuestar | G43: Sin pagar | H43: 46298 | I43: 46298 | J43: No | M43: Qué preparado compras y qué dice su etiqueta; con menos del 35 % de cacao seco total o con grasa vegetal, consulta a tu servicio de consumo antes de imprimir la carta. [Fuente: CUN-42 + CUN-V06]
A44: Pendiente | B44: F5 | C44: Cobrar aparte el vaso de plástico para llevar | D44: Encargado/a | E44: 1 | F44: A presupuestar | G44: Sin pagar | H44: 46298 | I44: 46298 | J44: No | M44: [Fuente: CUN-41]
C45: AVANCE DE LA FASE F5 | D45: =IFERROR(COUNTIF(A38:A44,"Hecho"),"") -> 0 | E45: =IFERROR(COUNTIF(B38:B44,"F5"),"") -> 7 | F45: =IFERROR(SUMIF(F38:F44,">=0"),"") -> 0 | G45: =IFERROR(SUMIF(G38:G44,">=0"),"") -> 0 | J45: =IFERROR(IF(E45=0,"",(D45+COUNTIF(A38:A44,"N/A"))/E45),"") -> 0 | M45: Hechos · trámites de la fase · coste previsto · coste real · % de avance (los «N/A» cuentan como resueltos).
...

Sheet Árbol IAE y CNAE por Formato
A1: Árbol IAE y CNAE por Formato
A2: AI Chef Pro · aichef.pro — Cómo Montar una Churrería-Chocolatería
A3: Cinco preguntas y los epígrafes que te tocan. El CNAE no sale como dato: sale como PREGUNTA para tu asesor, con los dos códigos que hoy se comunican.
A5: LAS PREGUNTAS
A6: ¿Tendrás consumo en el local (mesas, barra o terraza)? | B6: Sí | E6: El Molinete tiene sala, barra y terraza.
A7: ¿Venderás para llevar (al peso, por docena o por ración)? | B7: Sí | E7: El despacho a calle de El Molinete.
A8: ¿Irás a ferias, mercados o casetas? | B8: No | E8: El Molinete no: en verano elige la carta de verano (decisión 9).
A9: ¿Servirás churros a otros negocios (cafeterías, bares, hoteles)? | B9: No | E9: Si lo haces, cambian tu epígrafe y tu registro sanitario.
A10: ¿Tu sala irá al epígrafe de chocolatería o al de café-bar? | B10: Aún no lo sé | E10: El ejemplo deja la decisión abierta a propósito: El Molinete se presenta como cafetería para abrir a las 6:00 (hoja de régimen), pero el epígrafe del impuesto se decide con el asesor.
A11: ¿Tu cifra de negocio superará 1.000.000 €? | B11: No
A13: LOS FORMATOS Y SUS EPÍGRAFES
A14: Formato | B14: ¿Te toca? | C14: Epígrafe del impuesto (candidato) | D14: CNAE para preguntar a tu asesor | E14: Fuente y nota
A15: Local con sala | B15: =IFERROR(IF($B$6="Sí","Sí","No"),"") -> Sí | C15: =IFERROR(IF($B$10="Chocolatería (676)","676 (chocolatería)",IF($B$10="Café-bar (673)","673 (cafés y bares)","676 (chocolatería) o 673 (cafés y bares), más 644.6 si vendes al peso")),"") -> 676 (chocolatería) o 673 (cafés y bares), más 644.6 si vendes al peso | D15: 56.11 o 56.30 (CNAE-2025), con su código de 2009 | E15: [Fuente: CUN-10 + CUN-14 + CUN-09 + CUN-16] La correspondencia oficial IAE-CNAE no está publicada (CUN-16).
A16: Despacho para llevar | B16: =IFERROR(IF($B$7="Sí","Sí","No"),"") -> Sí | C16: 644.6 (masas fritas y preparados de chocolate) | D16: 47.24 o 56.11, con su código de 2009 | E16: [Fuente: CUN-09 + CUN-16] La correspondencia oficial IAE-CNAE no está publicada (CUN-16).
A17: Caseta o feria | B17: =IFERROR(IF($B$8="Sí","Sí","No"),"") -> No | C17: 663.1; 675 o 674.7 con mesas | D17: 56.12, con su código de 2009 (y nunca el 47.81) | E17: [Fuente: CUN-11 + CUN-13 + CUN-15]
A18: Obrador que sirve a otros | B18: =IFERROR(IF($B$9="Sí","Sí","No"),"") -> No | C18: 419.3 (industria de masas fritas) | D18: 10.71, con su código de 2009 | E18: [Fuente: CUN-12 + CUN-16] La correspondencia oficial IAE-CNAE no está publicada (CUN-16).
A20: LO QUE SALE
A21: Formatos que te tocan | B21: =IFERROR(COUNTIF(B15:B18,"Sí"),"") -> 2
A22: ¿Necesitas el 644.6 además del epígrafe de la sala? | B22: =IFERROR(IF(AND(B6="Sí",B7="Sí"),IF(B10="Chocolatería (676)","Con mucha probabilidad sí: el 676 no lleva la nota que deja vender en el propio establecimiento, así que la venta para llevar pide además el 644.6 (inferencia: pregúntalo)",IF(B10="Café-bar (673)","Pregúntalo: el 673 deja vender en el propio establecimiento los productos de su servicio, pero la venta al peso para llevar puede ser otra actividad","Pregúntalo: depende de si tu sala va al 676 o al 673")),IF(B7="Sí","Sin sala, el 644.6 es tu epígrafe candidato","No vendes para llevar: no aplica")),"") -> Pregúntalo: depende de si tu sala va al 676 o al 673 | E22: Una cuota faculta sólo para su actividad: por eso la pregunta.
A23: Epígrafes candidatos que llevas a tu asesor | B23: =IFERROR(IF(B15="Sí",C15&". ","")&IF(B16="Sí",C16&". ","")&IF(B17="Sí",C17&". ","")&IF(B18="Sí",C18&". ",""),"") -> 676 (chocolatería) o 673 (cafés y bares), más 644.6 si vendes al peso. 644.6 (masas fritas y preparados de chocolate). | E23: Una cuota faculta sólo para su actividad: si tienes dos formatos, pregunta si necesitas dos altas.
A24: ¿Pagas el impuesto? | B24: =IFERROR(IF(B11="Sí","Alta y, con más de un millón de euros de cifra de negocio, la exención no te alcanza: pregúntale a tu asesor","Alta sí, pago no: están exentos los dos primeros años de actividad, todas las personas físicas y las sociedades por debajo de un millón de euros de cifra de negocio"),"") -> Alta sí, pago no: están exentos los dos primeros años de actividad, todas las personas físicas y las sociedades por debajo de un millón de euros de cifra de negocio | E24: La nota legal está en la pregunta del millón, más arriba.
A25: LA PREGUNTA DEL CNAE, REDACTADA PARA TU ASESOR | B25: =IFERROR("¿Con qué código del CNAE-2025 me doy de alta, y cuál es su equivalente del CNAE-2009, que también hay que comunicar? Mis candidatos: "&IF(B15="Sí",D15&"; ","")&IF(B16="Sí",D16&"; ","")&IF(B17="Sí",D17&"; ","")&IF(B18="Sí",D18&"; ","")&"y sé que el 47.81 del CNAE-2025 es comercio de vehículos de motor.","") -> ¿Con qué código del CNAE-2025 me doy de alta, y cuál es su equivalente del CNAE-2009, que también hay que comunicar? Mis candidatos: 56.11 o 56.30 (CNAE-2025), con su código de 2009; 47.24 o 56.11, con su código de 2009; y sé que el 47.81 del CNAE-2025 es comercio de vehículos de motor. | E25: Copia esta celda y envíasela. Las notas explicativas del INE describen cada clase por actividad, sin nombrar los churros: por eso se pregunta.
A26: La trampa del 47.81 | B26: Quien copie el «4781, puestos de venta de alimentos» del CNAE-2009 se encuentra en el CNAE-2025 con la clase de vehículos de motor. No lo uses. | E26: La nota legal está en la pregunta de arriba.
A27: Dos códigos, no uno | B27: Al darte de alta comunicas el CNAE-2025 y, además, el CNAE-2009 mientras no entre en vigor la tarifa de primas de accidentes adaptada al de 2025.
A28: Una cuota, una actividad | B28: Cada alta faculta sólo para su actividad. Si haces dos cosas (sala y despacho, o local y feria), pregúntale a tu asesor si son dos altas. | E28: La nota legal está en «Epígrafes candidatos».
A30: ESTA HOJA NO TE DA TU CNAE NI TU CUOTA, Y NO ES UN OLVIDO. La correspondencia oficial entre el epígrafe del impuesto y el CNAE-2025 no está publicada para la churrería, y la cuota no hace falta: casi nadie la paga. Lo que sí tienes es la pregunta escrita para tu asesor.
A31: El obrador que sirve a otros negocios (419.3) queda fuera de este producto: si fabricas para otros dejas de ser minorista. Está aquí sólo para que sepas dónde está la frontera.
A34: Listas de validación (no las borres: las usan los desplegables)
A35: Sí o No | B35: Tu sala
A36: Sí | B36: Chocolatería (676)
A37: No | B37: Café-bar (673)
B38: Aún no lo sé

Sheet Régimen de Apertura y Horario
A1: Régimen de Apertura y Horario
A2: AI Chef Pro · aichef.pro — Cómo Montar una Churrería-Chocolatería
A3: Por qué régimen va tu actividad, qué pasa con la obra y la terraza, y la norma del horario del ejemplo de Madrid. Tu hora de apertura NO se pone aquí.
A5: LO QUE DECIDE TU RÉGIMEN
A6: ¿Tu superficie útil de exposición y venta supera 750 m²? | B6: No
A7: ¿Consumo en el local? (del árbol de formatos) | B7: ='Árbol IAE y CNAE por Formato'!$B$6 -> Sí
A8: ¿Venta para llevar? (del árbol de formatos) | B8: ='Árbol IAE y CNAE por Formato'!$B$7 -> Sí
A9: ¿Terraza o elementos sobre la vía pública? | B9: Sí | E9: El Molinete tiene una terraza de 20 m², aparte de los 75 m² del local.
A10: ¿La extracción necesita proyecto? (1.ª fila del checklist) | B10: ='Checklist Legal (F1-F6)'!$K$7 -> Sí
A12: TU RÉGIMEN
A13: Tu actividad | B13: =IFERROR(IF(B7="Sí","Con mesas o barra (676 o 673) tu actividad sale del Anexo de la Ley 12/2012: el modelo, licencia o declaración responsable, lo fija tu ayuntamiento",IF(B6="Sí","Más de 750 m²: sales del Anexo y manda tu ayuntamiento",IF(B8="Sí","Despacho para llevar (644.6, hasta 750 m²): la actividad va por declaración responsable","Sin consumo ni venta para llevar: revisa el árbol de formatos"))),"") -> Con mesas o barra (676 o 673) tu actividad sale del Anexo de la Ley 12/2012: el modelo, licencia o declaración responsable, lo fija tu ayuntamiento
A14: Tus obras | B14: =IFERROR(IF(B10="Sí","Las obras con proyecto, el conducto a cubierta incluido, van con su licencia de obra y su técnico, aparte de la actividad",IF(B10="No","Sin obra con proyecto según tu respuesta: que tu técnico lo confirme por escrito","Pregúntale a un técnico si tu conducto necesita proyecto antes de firmar")),"") -> Las obras con proyecto, el conducto a cubierta incluido, van con su licencia de obra y su técnico, aparte de la actividad
A15: Tu terraza | B15: =IFERROR(IF(B9="Sí","Autorización de la terraza aparte: la ocupación de la vía pública no entra en el régimen de la Ley 12/2012 (art. 2.2)","Sin terraza: nada que pedir"),"") -> Autorización de la terraza aparte: la ocupación de la vía pública no entra en el régimen de la Ley 12/2012 (art. 2.2)
A17: EL HORARIO: EL EJEMPLO DE MADRID (NO SE EXTRAPOLA)
A18: Clasificación del establecimiento | B18: Desde | C18: Hasta | D18: Fuente | E18: Nota
A19: Cafetería o bar | B19: 0.25 | C19: 0.083333333 | D19: CUN-34 | E19: Cafeterías, bares y cafés-bares: desde las 6:00 hasta las 2:00.
A20: Chocolatería | B20: 0.33333333 | C20: 0.041666667 | D20: CUN-34 | E20: Chocolaterías, heladerías y salones de té: desde las 8:00 hasta la 1:00. No se extrapola a otras comunidades.
A22: ¿Cómo te clasificas en el ejemplo de Madrid? | B22: Cafetería o bar
A23: Hora mínima de apertura de tu clasificación | B23: =IFERROR(INDEX(B19:B20,MATCH(B22,A19:A20,0)),"") -> 0.25
A24: Hora máxima de cierre de tu clasificación | B24: =IFERROR(INDEX(C19:C20,MATCH(B22,A19:A20,0)),"") -> 0.083333333
A25: Lo que significa para tu desayuno (decisión 8) | B25: =IFERROR(IF(B22="Chocolatería","Como chocolatería no abres antes de las 8:00 en el ejemplo de Madrid: si tu desayuno empieza antes, clasifícate como cafetería o bar","Como cafetería o bar puedes abrir desde las 6:00 en el ejemplo de Madrid"),"") -> Como cafetería o bar puedes abrir desde las 6:00 en el ejemplo de Madrid
A26: Dónde pones tu hora de apertura | B26: En temporada-franjas-y-ferias.xlsx, hoja «Franjas del Día»: allí está el semáforo de las 8:00 con tu hora real. Este libro no te pide el horario.
A27: Si tienes despacho para llevar | B27: =IFERROR(IF(B8="Sí","Tu despacho es comercio al por menor: la Ley de Horarios Comerciales da libertad horaria a los comercios de menos de 300 m² (inferencia: confírmalo con tu ayuntamiento; la sala sigue el horario de establecimientos públicos de tu comunidad)","No vendes para llevar: no aplica"),"") -> Tu despacho es comercio al por menor: la Ley de Horarios Comerciales da libertad horaria a los comercios de menos de 300 m² (inferencia: confírmalo con tu ayuntamiento; la sala sigue el horario de establecimientos públicos de tu comunidad)
A29: EL HORARIO DE MADRID ES UN EJEMPLO Y NO SE EXTRAPOLA a otras comunidades: cada una tiene su orden de horarios de establecimientos públicos. Las modificaciones posteriores a la orden de 2022 no se han comprobado.
A30: Las horas de la tabla están en verde porque son las de TU comunidad las que valen: sustitúyelas por las de tu orden de horarios.
A33: Listas de validación (no las borres: las usan los desplegables)
A34: Sí o No | B34: Clasificación
A35: Sí | B35: Cafetería o bar
A36: No | B36: Chocolatería

Sheet Licencia, Humos y Gas
A1: Licencia, Humos y Gas
A2: AI Chef Pro · aichef.pro — Cómo Montar una Churrería-Chocolatería
A3: La licencia de obra del conducto, la salida de humos del ejemplo de Madrid, el gas y el extintor. Los kW y el riesgo de incendio los calcula el libro 1.
A5: TUS RESPUESTAS
A6: ¿Qué formato montas? | B6: Local con sala | E6: El de El Molinete: local con sala, terraza y despacho a calle.
A7: ¿Tu freidora es de gas o eléctrica? | B7: Gas | E7: La freidora de El Molinete es de gas (la de 25 L de la dotación).
A8: ¿El conducto subirá a cubierta o cruzará fachada o patio? | B8: Sí | E8: El Molinete entra en un local sin salida de humos.
A9: ¿Todos tus aparatos son eléctricos y cocinan en su interior sin transmitir olores? | B9: No | E9: Sólo así, y sin pasar de 4 kW en conjunto, el ejemplo de Madrid no exige conducto a cubierta. Una freidora de baño abierto no cocina en su interior.
A10: ¿Tienes un extintor de clase F junto a la freidora? | B10: No | E10: Todavía no: es una fila de la fase F4 del checklist.
A11: Años entre inspecciones de la instalación receptora de gas | B11: 5
A12: Peso de bombona por debajo del cual no hay instalación receptora (kg, sólo con un aparato de utilización móvil) | B12: 15
A13: Fecha del certificado de tu instalación de gas (o la prevista) | B13: 46298
A15: LO QUE TE TOCA
A16: Licencia de obra | B16: =IFERROR(IF(B8="Sí","Licencia de obra y técnico: el conducto necesita proyecto, aunque la actividad vaya por declaración responsable","Sin conducto que suba o cruce: que tu técnico confirme por escrito que no hay obra con proyecto"),"") -> Licencia de obra y técnico: el conducto necesita proyecto, aunque la actividad vaya por declaración responsable
A17: Salida de humos (ejemplo de Madrid) | B17: =IFERROR(IF(B9="Sí","Podrías no necesitar conducto a cubierta si además la potencia conjunta no pasa de 4 kW: compruébalo con tu técnico","Campana con captación, extracción forzada y filtro de grasas, conducto a cubierta y limpieza al menos una vez al año"),"") -> Campana con captación, extracción forzada y filtro de grasas, conducto a cubierta y limpieza al menos una vez al año
A18: Gas | B18: =IFERROR(IF(B7="Eléctrica","Freidora eléctrica: comprueba la potencia contratada con tu comercializadora",IF(B6="Caseta o feria","Bombona de menos de "&B12&" kg conectada a un solo aparato de utilización móvil: no es instalación receptora","Instalación receptora con el certificado del instalador e inspección cada "&B11&" años")),"") -> Instalación receptora con el certificado del instalador e inspección cada 5 años
A19: Próxima inspección de tu instalación de gas | B19: =IFERROR(IF(OR(B7="Eléctrica",B6="Caseta o feria"),"",DATE(YEAR(B13)+B11,MONTH(B13),DAY(B13))),"") -> 48124 | E19: Vacía si tu freidora es eléctrica o si es un puesto con bombona pequeña.
A20: Extintor | B20: =IFERROR(IF(B10="Sí","Tienes el agente adecuado al fuego de aceite: la clase F","Falta: el agente extintor tiene que ser adecuado a la clase de fuego, y el de los aceites y grasas de cocina es la clase F"),"") -> Falta: el agente extintor tiene que ser adecuado a la clase de fuego, y el de los aceites y grasas de cocina es la clase F
A21: Potencia y riesgo de incendio | B21: Los kW computables, el riesgo de la cocina, la extinción automática y la distancia de los filtros los calcula produccion-hora-punta-y-local.xlsx, hoja «Freidoras, Potencia y Riesgo». Aquí no se vuelven a calcular.
A23: TUS PAPELES DE OBRA, HUMOS Y GAS
A24: Papel | B24: ¿Te toca? | C24: Estado | D24: Fecha objetivo | E24: Por qué
A25: Licencia de obra del conducto y proyecto técnico | B25: =IFERROR(IF(B8="Sí","Sí","No"),"") -> Sí | C25: Pendiente | D25: 46298 | E25: Sale de tu respuesta sobre el conducto.
A26: Limpieza anual del conducto y la campana (ejemplo de Madrid) | B26: =IFERROR(IF(B9="Sí","No","Sí"),"") -> Sí | C26: Pendiente | D26: 46298 | E26: Hay conducto salvo que te ampare la excepción de los aparatos eléctricos.
A27: Certificado de la instalación receptora de gas | B27: =IFERROR(IF(OR(B7="Eléctrica",B6="Caseta o feria"),"No","Sí"),"") -> Sí | C27: Pendiente | D27: 46298 | E27: Gas en un local o un despacho: instalación receptora.
A28: Inspección periódica de la instalación de gas | B28: =IFERROR(IF(OR(B7="Eléctrica",B6="Caseta o feria"),"No","Sí"),"") -> Sí | C28: Pendiente | D28: 46298 | E28: Gas en un local o un despacho: instalación receptora.
A29: Extintor de clase F junto a la freidora | B29: =IFERROR(IF(B6="","","Sí"),"") -> Sí | C29: Pendiente | D29: 46298 | E29: Toda freidora: el fuego de aceite es de clase F.
A30: Autorización de la terraza | B30: =IFERROR(IF('Régimen de Apertura y Horario'!$B$9="Sí","Sí","No"),"") -> Sí | C30: Pendiente | D30: 46298 | E30: Sale de tu respuesta en la hoja de régimen.
A31: Papeles que te tocan | B31: =IFERROR(COUNTIF(B25:B30,"Sí"),"") -> 6
A32: De ellos, hechos | B32: =SUMPRODUCT(--(B25:B30="Sí"),--(C25:C30="Hecho")) -> 0
A33: VEREDICTO | B33: =IFERROR(IF(B31=0,"No te toca ningún papel de esta hoja",IF(B32<B31,"Te faltan papeles de obra, humos o gas: "&(B31-B32)&" pendientes","Papeles de obra, humos y gas en regla")),"") -> Te faltan papeles de obra, humos o gas: 6 pendientes
A35: Lo que fija el proyecto técnico -caudal, sección y trazado del conducto- no lo fija este libro. Los requisitos de humos son los de la ordenanza de Madrid, el único municipio verificado para este producto: busca la tuya.
A36: La bombona pequeña NO sirve para la freidora fija de un local ni de un despacho: la excepción es para un aparato de utilización móvil, es decir, para el puesto de feria.
A39: Listas de validación (no las borres: las usan los desplegables)
A40: Sí o No | B40: Formato | C40: Energía | D40: Estado
A41: Sí | B41: Local con sala | C41: Gas | D41: Pendiente
A42: No | B42: Despacho para llevar | C42: Eléctrica | D42: Hecho
B43: Caseta o feria | D43: N/A

Sheet Árbol de Registro Sanitario
A1: ¿Registro Autonómico o Registro General?
A2: AI Chef Pro · aichef.pro — Cómo Montar una Churrería-Chocolatería
A3: Tres preguntas y un veredicto. Dos de ellas salen del árbol de formatos: si cambias de formato allí, cambia aquí.
A5: LAS PREGUNTAS
A6: ¿Vendes al consumidor final en tu propio establecimiento? | B6: Sí
A7: ¿Sirves churros a otros negocios? (del árbol de formatos) | B7: ='Árbol IAE y CNAE por Formato'!$B$9 -> No
A8: ¿Vendes en un puesto, caseta o vehículo? (del árbol de formatos) | B8: ='Árbol IAE y CNAE por Formato'!$B$8 -> No
A10: EL VEREDICTO
A11: Tu régimen sanitario | B11: =IFERROR(IF(B7="Sí","Sirves a otro negocio: la guía de la Comunidad de Madrid lo pone de ejemplo de actividad restringida. Pregunta a tu comunidad qué inscripción te toca",IF(B6="Sí","Comercio al por menor: excluido del registro general (RGSEAA); te inscribes en el de tu comunidad autónoma","Revísalo: si no vendes al consumidor final, no eres un minorista")),"") -> Comercio al por menor: excluido del registro general (RGSEAA); te inscribes en el de tu comunidad autónoma
A12: El trámite que te toca | B12: =IFERROR(IF(B6="Sí","Comunicación o declaración responsable al registro de tu comunidad autónoma: no habilita por sí sola, y cómo funciona cambia en cada comunidad",""),"") -> Comunicación o declaración responsable al registro de tu comunidad autónoma: no habilita por sí sola, y cómo funciona cambia en cada comunidad
A13: Si vas a ferias | B13: =IFERROR(IF(B8="Sí","El puesto, la caseta o el vehículo también es comercio al por menor: mismo registro autonómico y los requisitos de higiene del puesto (hoja de ferias)","No vas a ferias: nada más"),"") -> No vas a ferias: nada más
A14: El autocontrol | B14: Plan de autocontrol basado en el APPCC, que puede ser simplificado, con una persona responsable con nombre. Los registros, en el Pack APPCC (el del aceite es el 09).
A16: LOS TRES CASOS, PARA QUE VEAS DÓNDE CAES
A17: Tu situación | B17: Lo que te toca | C17: Por qué
A18: Vendes al consumidor final en tu local, tu despacho o tu web | B18: Comunicación o declaración responsable al registro de tu comunidad autónoma | C18: El comercio al por menor está excluido del registro general (RGSEAA). Tener obrador de masa a la vista no te saca del régimen minorista.
A19: Tienes además un puesto de feria o una caseta | B19: El mismo registro autonómico para el puesto, y los requisitos de higiene del puesto | C19: El local ambulante o provisional también es comercio al por menor.
A20: Sirves churros a una cafetería o un bar de otro titular | B20: Pregunta a tu comunidad: puede tocarte otra inscripción | C20: La guía de la Comunidad de Madrid pone de ejemplo de actividad restringida «la churrería o pastelería que sirve a la cafetería».
A22: Si vendes al consumidor final desde tu propio establecimiento, tu sitio es el registro de tu comunidad autónoma, no el estatal. Lo que cambia la cosa es servir a OTRO negocio: el obrador que sirve a otros queda fuera de este producto.
A25: Listas de validación (no las borres: las usan los desplegables)
A26: Sí o No
A27: Sí
A28: No

Sheet Ferias y Venta Ambulante
A1: Ferias y Venta Ambulante
A2: AI Chef Pro · aichef.pro — Cómo Montar una Churrería-Chocolatería
A3: Los papeles del puesto, la caseta o el remolque. Los euros de cada evento (tasa, afluencia y punto muerto) están en temporada-franjas-y-ferias.xlsx.
A5: TU PUESTO
A6: ¿Vas a ferias? (del árbol de formatos) | B6: ='Árbol IAE y CNAE por Formato'!$B$8 -> No
A7: Fecha en que caduca tu autorización municipal | B7: 46477
A8: Fecha de control (ponla en «hoy») | B8: 46298
A9: Distancia mínima a cualquier hueco si cocinas con aceite en suelo de uso público (m, ejemplo de Madrid) | B9: 15
A10: Estado de tu autorización | B10: =IFERROR(IF(B6<>"Sí","No vas a ferias",IF(B7<B8,"CADUCADA: la autorización no es indefinida ni se renueva sola","Vigente")),"") -> No vas a ferias
A12: LOS REQUISITOS DEL PUESTO
A13: Requisito | B13: ¿Te aplica? | C13: Estado | D13: Fuente | E13: Nota
A14: Autorización municipal del puesto: con plazo, sin renovación automática y por un procedimiento transparente | B14: =IFERROR(IF($B$6="Sí","Sí","No"),"") -> No | C14: Pendiente | D14: CUN-20
A15: Tus datos y la autorización, expuestos de forma visible para el público | B15: =IFERROR(IF($B$6="Sí","Sí","No"),"") -> No | C15: Pendiente | D15: CUN-20
A16: Comprueba qué norma cita tu ordenanza: el real decreto estatal de venta ambulante de 2010 está derogado desde el 7-8-2021 | B16: =IFERROR(IF($B$6="Sí","Sí","No"),"") -> No | C16: Pendiente | D16: CUN-19 | E16: Lo sustituyó otro real decreto en 2021. Si tu ordenanza cita sus artículos, pregúntale al ayuntamiento qué norma aplica hoy.
A17: Ocupación de dominio público o quiosco: el puesto de churros no siempre va como «venta ambulante»; hay ordenanzas que lo excluyen de los puestos desmontables | B17: =IFERROR(IF($B$6="Sí","Sí","No"),"") -> No | C17: Pendiente | D17: CUN-36
A18: Alta en el IAE del puesto: 663.1, o 675 / 674.7 si pones mesas | B18: =IFERROR(IF($B$6="Sí","Sí","No"),"") -> No | C18: Pendiente | D18: CUN-11 + CUN-13
A19: Registro sanitario autonómico: el puesto también es comercio al por menor | B19: =IFERROR(IF($B$6="Sí","Sí","No"),"") -> No | C19: Pendiente | D19: CUN-21
A20: Higiene del puesto: lavado de manos, superficies lisas y lavables, agua potable caliente y fría, y eliminación higiénica de desechos | B20: =IFERROR(IF($B$6="Sí","Sí","No"),"") -> No | C20: Pendiente | D20: CUN-22
A21: Gas del puesto: la bombona de menos de 15 kg sólo libra de la instalación receptora a un aparato de utilización móvil | B21: =IFERROR(IF($B$6="Sí","Sí","No"),"") -> No | C21: Pendiente | D21: CUN-28
A22: Ejemplo de Madrid: cocinar en suelo de uso público pide autorización previa y captación y filtrado a la distancia de la celda B8 de cualquier hueco | B22: =IFERROR(IF($B$6="Sí","Sí","No"),"") -> No | C22: Pendiente | D22: CUN-25
A23: Tasa de la feria: la fija la ordenanza fiscal de cada municipio (el de la nota es un pueblo pequeño, nunca un orden de magnitud) | B23: =IFERROR(IF($B$6="Sí","Sí","No"),"") -> No | C23: Pendiente | D23: CUN-37 | E23: Los euros de la tasa de cada evento se ponen en el libro de temporada y ferias, no aquí.
A24: Alérgenos por escrito también en el puesto | B24: =IFERROR(IF($B$6="Sí","Sí","No"),"") -> No | C24: Pendiente | D24: CHN-34
A25: Requisitos que te aplican | B25: =IFERROR(COUNTIF(B14:B24,"Sí"),"") -> 0
A26: De ellos, pendientes | B26: =SUMPRODUCT(--(B14:B24="Sí"),--(C14:C24="Pendiente")) -> 0
A27: VEREDICTO | B27: =IFERROR(IF(B6<>"Sí","No vas a ferias: esta hoja no te aplica. Si algún día vas, cambia la respuesta en el árbol de formatos",IF(B26>0,"Te faltan papeles del puesto: "&B26&" pendientes","Papeles del puesto en regla")),"") -> No vas a ferias: esta hoja no te aplica. Si algún día vas, cambia la respuesta en el árbol de formatos
A29: La caseta es aquí un capítulo de papeles, sin caso cifrado. El caso completo de un puesto móvil, con sus números y sus tareas, está en el Plan de Negocio Food Truck y en el Kit de Tareas Food Truck.
A30: Cada ayuntamiento tiene su ordenanza de venta ambulante, de ocupación de la vía pública y su ordenanza fiscal: los requisitos de esta hoja son la lista de lo que hay que preguntar, no la respuesta de tu municipio.
A33: Listas de validación (no las borres: las usan los desplegables)
A34: Estado
A35: Pendiente
A36: Hecho
A37: N/A

Sheet Alérgenos y Aceite Compartido
A1: Alérgenos y Aceite Compartido
A2: AI Chef Pro · aichef.pro — Cómo Montar una Churrería-Chocolatería
A3: Lo que fríes en la misma freidora, los alérgenos de tu carta por familia, el «sin gluten», la acrilamida y lo que dice la norma del aceite.
A5: 1. QUÉ FRÍES EN LA FREIDORA DE CHURROS
A6: Lo que fríes | B6: ¿En la misma freidora? | G6: Nota
A7: Churros y porras | B7: Sí | G7: El Molinete fríe sólo churros y porras en su freidora; los rellenos y la cobertura van después de freír.
A8: Churros rellenos o con cobertura | B8: Sí
A9: Patatas fritas de patata fresca | B9: No
A10: Otros fritos (rebozados, empanados, buñuelos de otra masa) | B10: No
A11: ¿Tu freidora es dedicada o compartida? (decisión 11) | B11: =IFERROR(IF(COUNTIF(B9:B10,"Sí")>0,"Compartida: el aceite arrastra los alérgenos de todo lo que fríes en él. Freidora aparte, o limpieza antes de cambiar de producto","Dedicada al churro y a la porra: el aceite sólo lleva lo que lleva tu masa"),"") -> Dedicada al churro y a la porra: el aceite sólo lleva lo que lleva tu masa
A13: 2. LOS ALÉRGENOS DE TU CARTA, POR FAMILIA
A14: Familia de la carta | B14: Gluten | C14: Leche | D14: Huevo | E14: Soja | F14: Frutos de cáscara | G14: Nota
A15: Churros y porras | B15: Sí | C15: Revisa la etiqueta | D15: Revisa la etiqueta | E15: Revisa la etiqueta | F15: Revisa la etiqueta | G15: Gluten siempre en la masa de trigo. Lo demás depende de la etiqueta del mix y del preparado que compres.
A16: Rellenos y especiales | B16: Sí | C16: Revisa la etiqueta | D16: Revisa la etiqueta | E16: Revisa la etiqueta | F16: Revisa la etiqueta
A17: Chocolate a la taza | B17: Revisa la etiqueta | C17: Sí | D17: Revisa la etiqueta | E17: Revisa la etiqueta | F17: Revisa la etiqueta | G17: Leche en la taza: compruébalo en la etiqueta de tu preparado.
A18: Cafés y bebidas | B18: Revisa la etiqueta | C18: Sí | D18: Revisa la etiqueta | E18: Revisa la etiqueta | F18: Revisa la etiqueta
A19: Carta de verano | B19: Revisa la etiqueta | C19: Revisa la etiqueta | D19: Revisa la etiqueta | E19: Revisa la etiqueta | F19: Revisa la etiqueta
A20: ¿Lo declaras por escrito en la carta o el cartel? | B20: =IFERROR(IF(COUNTIF(B15:B19,"Sí")>0,"Sí","No"),"") -> Sí | C20: =IFERROR(IF(COUNTIF(C15:C19,"Sí")>0,"Sí","No"),"") -> Sí | D20: =IFERROR(IF(COUNTIF(D15:D19,"Sí")>0,"Sí","No"),"") -> No | E20: =IFERROR(IF(COUNTIF(E15:E19,"Sí")>0,"Sí","No"),"") -> No | F20: =IFERROR(IF(COUNTIF(F15:F19,"Sí")>0,"Sí","No"),"") -> No
A21: Casillas pendientes de leer en la etiqueta | B21: =IFERROR(COUNTIF(B15:F19,"Revisa la etiqueta"),"") -> 21 | G21: Mientras no sea cero, tu carta de alérgenos está incompleta. La matriz por elaboración está en el Pack APPCC.
A23: 3. EL «SIN GLUTEN»
A24: ¿Quieres anunciar algo «sin gluten»? | B24: No
A25: Gluten máximo para decir «sin gluten» (mg/kg) | B25: 20
A26: Lo que significa | B26: =IFERROR(IF(B24="Sí","Casi nunca puedes: con una freidora que fríe churros de trigo el aceite contamina. Necesitarías freidora y elaboración aparte, y un análisis por debajo de "&B25&" mg/kg en el producto tal como lo vendes","No lo anuncias: correcto. «Sin gluten» no es un argumento de carta en una churrería"),"") -> No lo anuncias: correcto. «Sin gluten» no es un argumento de carta en una churrería
A28: 4. LA ACRILAMIDA
A29: ¿Fríes patatas fritas de patata fresca? (de la tabla 1) | B29: =B9 -> No
A30: ¿Operas bajo marca o licencia siguiendo las instrucciones de quien te suministra de forma centralizada? | B30: No
A31: El churro | B31: Buena práctica, no obligación expresa: el churro no está nombrado en la lista del reglamento de la acrilamida, que no define «bollería». No se puede afirmar ni que entre ni que quede fuera.
A32: La recomendación de la UE | B32: Una recomendación de la Comisión, no vinculante, incluye los churros en su lista de alimentos en los que se debe vigilar la acrilamida.
A33: Valor de referencia | B33: Un informe oficial recoge que no hay valor de referencia para las masas fritas como los churros: la autoridad ya mira el churro, pero no fija una obligación.
A34: Lo que se mueve | B34: La Comisión revisa el marco de la acrilamida (estado de consultas). Vuelve a mirarlo en el anexo normativo de la guía antes de cada temporada.
A35: Parte A del anexo II | B35: =IFERROR(IF(B29="Sí","Te toca la parte A: las medidas de mitigación de las patatas fritas, porque las fríes","No fríes patatas: la parte A no te alcanza por ellas"),"") -> No fríes patatas: la parte A no te alcanza por ellas
A36: Parte B del anexo II | B36: =IFERROR(IF(AND(B30="Sí",B29="Sí"),"Parte B, además: operas siguiendo las instrucciones de quien te suministra de forma centralizada (art. 2.3)","La parte B no te alcanza: sólo aplica a quien opera bajo marca o licencia siguiendo las instrucciones de un suministro centralizado (art. 2.3)"),"") -> La parte B no te alcanza: sólo aplica a quien opera bajo marca o licencia siguiendo las instrucciones de un suministro centralizado (art. 2.3)
A38: 5. EL ACEITE: LO QUE DICE LA NORMA
A39: La norma de calidad de los aceites calentados alcanza a la churrería | G39: [Fuente: CUN-01]
A40: Compuestos polares por debajo del 25 %: el medidor de mano te dice cuándo cambiar; el 25 % legal se demuestra en laboratorio | G40: [Fuente: CUN-02]
A41: Prohibido añadir sustancias extrañas al aceite y vender el usado para uso alimentario (el artículo 9 sigue vivo) | G41: [Fuente: CUN-03]
A42: Recogida separada obligatoria del aceite usado desde el 30-06-2022: contrato con un gestor autorizado y los justificantes guardados | G42: [Fuente: CUN-27]
A44: El registro de las mediciones del aceite y de la retirada del usado se lleva en el Pack APPCC, registro 09: aquí se cita, no se copia. El coste del aceite y cuándo cambiarlo, en aceite-de-fritura-coste-y-cambio.xlsx.
A45: Cada casilla de la tabla de alérgenos se rellena con la etiqueta del producto que compras en la mano: el mismo mix de churros cambia de composición entre marcas.
A48: Listas de validación (no las borres: las usan los desplegables)
...

Sheet PRL de la Fritura
A1: Riesgos de la Línea de Fritura
A2: AI Chef Pro · aichef.pro — Cómo Montar una Churrería-Chocolatería
A3: Los riesgos de la línea con su probabilidad, su gravedad y su medida. No sustituye a la evaluación de riesgos de tu servicio de prevención: es la lista de lo que tiene que contemplar en la fritura.
B5: Nivel desde el que la prioridad es ALTA (probabilidad por gravedad) | C5: 6 | D5: Supuesto de la casa: con una escala de 1 a 3, un 6 o un 9 piden medida antes de abrir.
B6: Nivel desde el que la prioridad es MEDIA | C6: 3
A8: Nº | B8: Riesgo | C8: Dónde | D8: Medida | E8: Probabilidad (1-3) | F8: Gravedad (1-3) | G8: Nivel | H8: Prioridad | I8: ¿Medida puesta? | J8: Responsable | K8: Fuente
A9: 1 | B9: Quemaduras por salpicadura al cargar la freidora | C9: Fritura | D9: Cargar con la cesta o la dosificadora, guantes y delantal resistentes al calor, nada de agua cerca de la cuba | E9: 2 | F9: 3 | G9: =IFERROR(E9*F9,"") -> 6 | H9: =IFERROR(IF(G9>=$C$5,"Alta",IF(G9>=$C$6,"Media","Baja")),"") -> Alta | I9: No | J9: Titular | K9: [Fuente: supuesto (buena práctica de la casa)]
A10: 2 | B10: Fuego del aceite de la cuba | C10: Fritura | D10: Extintor de clase F junto a la freidora y tapa de la cuba a mano; nunca agua | E10: 1 | F10: 3 | G10: =IFERROR(E10*F10,"") -> 3 | H10: =IFERROR(IF(G10>=$C$5,"Alta",IF(G10>=$C$6,"Media","Baja")),"") -> Media | I10: No | J10: Titular | K10: [Fuente: CUN-38]
A11: 3 | B11: Fuego en la campana o el conducto por grasa acumulada | C11: Campana y conducto | D11: Filtros a su distancia del foco y limpieza del conducto al menos una vez al año (ejemplo de Madrid) | E11: 1 | F11: 3 | G11: =IFERROR(E11*F11,"") -> 3 | H11: =IFERROR(IF(G11>=$C$5,"Alta",IF(G11>=$C$6,"Media","Baja")),"") -> Media | I11: No | J11: Titular | K11: [Fuente: CUN-26 + CUN-23]
A12: 4 | B12: Fuga de gas o mala combustión | C12: Fritura | D12: Instalación receptora certificada e inspeccionada, y ventilación | E12: 1 | F12: 3 | G12: =IFERROR(E12*F12,"") -> 3 | H12: =IFERROR(IF(G12>=$C$5,"Alta",IF(G12>=$C$6,"Media","Baja")),"") -> Media | I12: No | J12: Titular | K12: [Fuente: CHN-48]
A13: 5 | B13: Resbalones en suelo con grasa o harina | C13: Obrador y fritura | D13: Suelo antideslizante, limpieza durante el turno y calzado cerrado | E13: 2 | F13: 2 | G13: =IFERROR(E13*F13,"") -> 4 | H13: =IFERROR(IF(G13>=$C$5,"Alta",IF(G13>=$C$6,"Media","Baja")),"") -> Media | I13: No | J13: Titular | K13: [Fuente: supuesto (buena práctica de la casa)]
A14: 6 | B14: Sobreesfuerzos con sacos de harina y garrafas de aceite | C14: Almacén | D14: Sacos y garrafas a la altura de la cintura, carro, y los pesados entre dos | E14: 2 | F14: 2 | G14: =IFERROR(E14*F14,"") -> 4 | H14: =IFERROR(IF(G14>=$C$5,"Alta",IF(G14>=$C$6,"Media","Baja")),"") -> Media | I14: No | J14: Titular | K14: [Fuente: supuesto (buena práctica de la casa)]
A15: 7 | B15: Cortes y atrapamientos en la amasadora y la dosificadora | C15: Obrador | D15: Protecciones puestas y máquina parada antes de limpiarla | E15: 1 | F15: 3 | G15: =IFERROR(E15*F15,"") -> 3 | H15: =IFERROR(IF(G15>=$C$5,"Alta",IF(G15>=$C$6,"Media","Baja")),"") -> Media | I15: No | J15: Titular | K15: [Fuente: supuesto (buena práctica de la casa)]
A16: 8 | B16: Quemaduras al vaciar y filtrar el aceite usado | C16: Fritura | D16: Dejar enfriar el aceite antes de vaciarlo y usar un bidón estable | E16: 2 | F16: 2 | G16: =IFERROR(E16*F16,"") -> 4 | H16: =IFERROR(IF(G16>=$C$5,"Alta",IF(G16>=$C$6,"Media","Baja")),"") -> Media | I16: No | J16: Titular | K16: [Fuente: supuesto (buena práctica de la casa)]
A17: 9 | B17: Calor y humo en la zona de fritura | C17: Fritura | D17: Campana encendida todo el turno, pausas e hidratación | E17: 2 | F17: 1 | G17: =IFERROR(E17*F17,"") -> 2 | H17: =IFERROR(IF(G17>=$C$5,"Alta",IF(G17>=$C$6,"Media","Baja")),"") -> Baja | I17: No | J17: Titular | K17: [Fuente: supuesto (buena práctica de la casa)]
A18: 10 | B18: Fatiga por madrugada y turnos partidos | C18: Toda la línea | D18: Descanso entre jornadas; las dos figuras de nocturnidad, en el libro de turnos | E18: 2 | F18: 2 | G18: =IFERROR(E18*F18,"") -> 4 | H18: =IFERROR(IF(G18>=$C$5,"Alta",IF(G18>=$C$6,"Media","Baja")),"") -> Media | I18: No | J18: Titular | K18: [Fuente: supuesto (buena práctica de la casa)]
B20: Riesgos de prioridad alta | C20: =IFERROR(COUNTIF(H9:H18,"Alta"),"") -> 1
B21: Riesgos de prioridad media | C21: =IFERROR(COUNTIF(H9:H18,"Media"),"") -> 8
B22: De prioridad alta, sin la medida puesta | C22: =SUMPRODUCT(--(H9:H18="Alta"),--(I9:I18="No")) -> 1
B23: VEREDICTO | C23: =IFERROR(IF(C22>0,"No abras la línea con riesgos altos sin su medida: te faltan "&C22,"Los riesgos altos tienen su medida puesta"),"") -> No abras la línea con riesgos altos sin su medida: te faltan 1
A25: Las probabilidades y gravedades sembradas son SUPUESTOS de la casa para El Molinete: cámbialas con tu servicio de prevención. La nocturnidad y los descansos de la plantilla se calculan en turnos-plantilla-y-madrugada.xlsx.
A26: Nunca agua sobre aceite ardiendo: el extintor de la freidora es de clase F, y la tapa de la cuba, a mano.
A29: Listas de validación (no las borres: las usan los desplegables)
A30: Sí o No | B30: Escala de 1 a 3
A31: Sí | B31: 1
A32: No | B32: 2
B33: 3

Sheet Registro de Formación
A1: Registro de Formación del Personal
A2: AI Chef Pro · aichef.pro — Cómo Montar una Churrería-Chocolatería
A3: Lo que la norma exige es que la EMPRESA garantice la formación de cada persona de acuerdo con su puesto y pueda ACREDITARLA. Eso es esta tabla.
A5: Una línea por persona
A6: Nº | B6: Persona | C6: Puesto | D6: Jornada | E6: Contenido de la formación | F6: Fecha de la formación | G6: Caduca el | H6: Estado | I6: Notas
A7: 1 | B7: Persona 1 | C7: Titular (encargado/a) | D7: 1 | E7: Responsable del autocontrol: higiene, alérgenos, aceite de fritura y registros | F7: 46298 | G7: =IFERROR(IF($B7="(libre: añade aquí a tu persona)","",DATE(YEAR($F7),MONTH($F7)+$C$17,DAY($F7))),"") -> 47029 | H7: =IFERROR(IF($B7="(libre: añade aquí a tu persona)","",IF($G7<$C$18,"CADUCADA",IF($G7<$C$18+$C$19,"Caduca pronto","Vigente"))),"") -> Vigente | I7: Las cinco personas de El Molinete (titular, dos churreros/as, camarero/a y refuerzo). Las filas libres son para tu equipo.
A8: 2 | B8: Persona 2 | C8: Churrero/a 1 | D8: 1 | E8: Higiene, alérgenos, aceite de fritura y extintor, en la línea | F8: 46298 | G8: =IFERROR(IF($B8="(libre: añade aquí a tu persona)","",DATE(YEAR($F8),MONTH($F8)+$C$17,DAY($F8))),"") -> 47029 | H8: =IFERROR(IF($B8="(libre: añade aquí a tu persona)","",IF($G8<$C$18,"CADUCADA",IF($G8<$C$18+$C$19,"Caduca pronto","Vigente"))),"") -> Vigente
A9: 3 | B9: Persona 3 | C9: Churrero/a 2 | D9: 1 | E9: Higiene, alérgenos, aceite de fritura y extintor, en la línea | F9: 46298 | G9: =IFERROR(IF($B9="(libre: añade aquí a tu persona)","",DATE(YEAR($F9),MONTH($F9)+$C$17,DAY($F9))),"") -> 47029 | H9: =IFERROR(IF($B9="(libre: añade aquí a tu persona)","",IF($G9<$C$18,"CADUCADA",IF($G9<$C$18+$C$19,"Caduca pronto","Vigente"))),"") -> Vigente
A10: 4 | B10: Persona 4 | C10: Camarero/a de sala | D10: 1 | E10: Higiene, alérgenos e información al cliente, en la barra y la sala | F10: 46298 | G10: =IFERROR(IF($B10="(libre: añade aquí a tu persona)","",DATE(YEAR($F10),MONTH($F10)+$C$17,DAY($F10))),"") -> 47029 | H10: =IFERROR(IF($B10="(libre: añade aquí a tu persona)","",IF($G10<$C$18,"CADUCADA",IF($G10<$C$18+$C$19,"Caduca pronto","Vigente"))),"") -> Vigente
A11: 5 | B11: Persona 5 | C11: Refuerzo de fin de semana | D11: 0.5 | E11: Higiene, alérgenos y aceite de fritura, en la línea y la barra | F11: 46298 | G11: =IFERROR(IF($B11="(libre: añade aquí a tu persona)","",DATE(YEAR($F11),MONTH($F11)+$C$17,DAY($F11))),"") -> 47029 | H11: =IFERROR(IF($B11="(libre: añade aquí a tu persona)","",IF($G11<$C$18,"CADUCADA",IF($G11<$C$18+$C$19,"Caduca pronto","Vigente"))),"") -> Vigente
A12: 6 | B12: (libre: añade aquí a tu persona) | C12: Pendiente | D12: 1 | E12: Pendiente | F12: 46298 | G12: =IFERROR(IF($B12="(libre: añade aquí a tu persona)","",DATE(YEAR($F12),MONTH($F12)+$C$17,DAY($F12))),"") | H12: =IFERROR(IF($B12="(libre: añade aquí a tu persona)","",IF($G12<$C$18,"CADUCADA",IF($G12<$C$18+$C$19,"Caduca pronto","Vigente"))),"")
A13: 7 | B13: (libre: añade aquí a tu persona) | C13: Pendiente | D13: 1 | E13: Pendiente | F13: 46298 | G13: =IFERROR(IF($B13="(libre: añade aquí a tu persona)","",DATE(YEAR($F13),MONTH($F13)+$C$17,DAY($F13))),"") | H13: =IFERROR(IF($B13="(libre: añade aquí a tu persona)","",IF($G13<$C$18,"CADUCADA",IF($G13<$C$18+$C$19,"Caduca pronto","Vigente"))),"")
A14: 8 | B14: (libre: añade aquí a tu persona) | C14: Pendiente | D14: 1 | E14: Pendiente | F14: 46298 | G14: =IFERROR(IF($B14="(libre: añade aquí a tu persona)","",DATE(YEAR($F14),MONTH($F14)+$C$17,DAY($F14))),"") | H14: =IFERROR(IF($B14="(libre: añade aquí a tu persona)","",IF($G14<$C$18,"CADUCADA",IF($G14<$C$18+$C$19,"Caduca pronto","Vigente"))),"")
A16: Parámetros de esta hoja
A17: Validez que TÚ fijas (meses) | C17: 24 | I17: La norma no fija una caducidad: lo que hay es una obligación continua del empresario. Dos años es un criterio de la casa para que el registro no se quede dormido; déjalo escrito en tu plan de autocontrol.
A18: Fecha de control | C18: 46298 | I18: La fecha desde la que se mira si algo ha caducado. Ponla en «hoy» cada vez que revises el registro.
A19: Aviso de «caduca pronto» (días antes) | C19: 60 | I19: Supuesto: dos meses dan tiempo a organizar una sesión sin parar la línea.
A21: Resumen
B22: Personas con formación registrada | C22: =SUMPRODUCT(--($B$7:$B$14<>"(libre: añade aquí a tu persona)")) -> 5
B23: Formaciones CADUCADAS | C23: =IFERROR(COUNTIF(H7:H14,"CADUCADA"),"") -> 0
B24: Formaciones que caducan pronto | C24: =IFERROR(COUNTIF(H7:H14,"Caduca pronto"),"") -> 0
B25: VEREDICTO | C25: =IFERROR(IF(C23>0,"Tienes formación caducada: es lo primero que se pide en una inspección",IF(C24>0,"Programa ya las que caducan pronto","Registro al día")),"") -> Registro al día
A27: Lo que vale ante una inspección es este registro, con el contenido y la fecha de cada formación, no un papel suelto con un sello. La responsabilidad de tenerlo es de la empresa.
A30: Diseñado por John Guerrero — chef y consultor gastronómico desde 2010, en cocina desde los 17 años.
A31: Versión 1.0 · octubre 2026 · aichef.pro/guia-churreria-chocolateria · info@aichef.pro

Sheet Cronograma y Ruta Crítica
A1: Cronograma y Ruta Crítica de la Apertura
A2: AI Chef Pro · aichef.pro — Cómo Montar una Churrería-Chocolatería
