Workbook

Sheet Instrucciones
A1: Temporada, Franjas y Ferias
A2: AI Chef Pro · aichef.pro — Cómo Montar una Churrería-Chocolatería
A3: Para qué sirve: repartir tus raciones por meses y por franjas, saber si la línea aguanta la hora punta (y la cola del domingo), cuánto refuerzo te toca en Navidad, qué haces en verano y a qué ferias te compensa ir.
A5: Instrucciones de Uso
A6: Celdas verdes = campos editables
A7: Las celdas en crema son resultados que el libro calcula; las blancas con fórmula, también. No escribas encima.
A9: 1. Hoja «Parámetros». Arriba, siete celdas verdes que copias a mano de los libros 1 y 3 (cada una dice de qué celda exacta). Debajo, el calendario del año, la hora punta, la hora mínima de apertura del ejemplo de Madrid y la tolerancia. Al pie, el CUADRE: anota lo que publica hoy cada celda de origen y, si lo que usas se separa, la fila se pone en rojo.
A10: 2. Hoja «Peso sobre el Año». Las raciones de un año normal y doce coeficientes que las reparten por meses (suman 12). Es lo que copia el libro 6 para su tesorería.
A11: 3. Hoja «Franjas del Día». La ÚNICA fuente de las franjas de todo el paquete: a qué hora empieza y acaba cada franja cada día y qué parte de las raciones del día se lleva. De aquí salen la hora punta, el semáforo de la hora de apertura y las horas por franja de la semana tipo (a la derecha, como dato de referencia).
A12: 4. Hojas «Capacidad contra el Pico» y «Cola del Domingo». Mes a mes, si la línea aguanta la hora punta de un día tipo y de un día punta, y cuántas raciones por hora se quedan en cola el domingo. Diciembre y enero son Navidad y Reyes. Al pie de la primera sale el veredicto «¿Una churrera o dos?».
A13: 5. Hoja «Refuerzo por Pico». Las horas de refuerzo de Navidad y Reyes y lo que cuestan. Las copia el libro 8.
A14: 6. Hoja «El Verano (Tres Salidas)». Cerrar, abrir con carta de verano o salir de ferias, comparadas por lo que dejan en euros en julio y agosto. Eliges una y su contribución la copia el libro 6.
... A46: Versión 1.0 · octubre 2026 · aichef.pro/guia-churreria-chocolateria · info@aichef.pro

Sheet Parámetros
A1: Parámetros
A2: AI Chef Pro · aichef.pro — Cómo Montar una Churrería-Chocolatería
A3: Todo lo que el resto de hojas da por sabido vive aquí. Ninguna fórmula de este libro lleva dentro un umbral, una hora ni un número de días.
A5: Parámetro | B5: Valor | C5: Unidad | D5: De dónde sale | E5: Nota
A6: Lo que Copias del Libro 1 (Producción y Local)
A7: Raciones de un día tipo (lunes a viernes) | B7: 250 | C7: raciones | D7: cópialo del libro 1: produccion-hora-punta-y-local.xlsx!Día Tipo y Día Punta!L7 | E7: La demanda base nace en el libro 1; aquí se reparte por mes y por franja.
A8: Raciones de un día punta (sábado, domingo y festivo) | B8: 400 | C8: raciones | D8: cópialo del libro 1: produccion-hora-punta-y-local.xlsx!Día Tipo y Día Punta!L8 | E8: Sábados, domingos y festivos. Nace en el libro 1.
A9: Capacidad de la línea, en raciones por hora | B9: 122.55136 | C9: raciones/h | D9: cópialo del libro 1: produccion-hora-punta-y-local.xlsx!Cuello de Botella!L5 | E9: Lo que aguanta el conjunto (el equipo que manda) con tu masa por ración. Si compras otra máquina, vuelve a copiarla.
A10: Lo que Copias del Libro 3 (Carta y Escandallo)
A11: Ticket sin IVA por ración en julio y agosto (carta de verano) | B11: 2.2067273 | C11: EUR/ración | D11: cópialo del libro 3: carta-de-apertura-y-escandallo-churro.xlsx!Mix y Ticket Canal y Temporada!L6 | E11: Con el mix de julio y agosto del libro 3 (la carta de verano). Es la base imponible media de una ración de la carta.
A12: Coste de materia por ración en julio y agosto (aceite absorbido incluido) | B12: 0.35850072 | C12: EUR/ración | D12: cópialo del libro 3: carta-de-apertura-y-escandallo-churro.xlsx!Mix y Ticket Canal y Temporada!L7 | E12: El coste de materia de esa misma ración media de verano.
A13: Coste de materia por ración para llevar (aceite absorbido incluido) | B13: 0.30546293 | C13: EUR/ración | D13: cópialo del libro 3: carta-de-apertura-y-escandallo-churro.xlsx!Mix y Ticket Canal y Temporada!L8 | E13: El coste de materia de una ración para llevar: es el que se usa en las ferias.
A14: Coste hora de mano de obra | B14: 13.243843 | C14: EUR/h | D14: cópialo del libro 3: carta-de-apertura-y-escandallo-churro.xlsx!Coste Hora!L5 | E14: Valora el refuerzo y el personal de las ferias sin una segunda fuente del salario: es el mismo que usa el escandallo.
A16: Calendario del Año
A17: Días del año | B17: 365 | C17: días | D17: calendario | E17: Un año normal.
A18: Días al año con el local cerrado | B18: 5 | C18: días | D18: supuesto declarado de El Molinete | E18: Cinco días seguidos para la limpieza a fondo y la puesta a punto de la línea. Se restan de los días tipo.
A19: Sábados y domingos del año | B19: 104 | C19: días | D19: calendario (52 semanas) | E19: Son días punta. Si cierras un día de la semana, réstalo aquí o en los días tipo.
A20: Festivos de lunes a viernes que abres como un domingo | B20: 12 | C20: días | D20: supuesto declarado de El Molinete | E20: Cambian cada año y en cada municipio. Se trabajan como un día punta.
A21: Primer mes del verano (número del mes) | B21: 7 | C21: mes | D21: supuesto declarado de El Molinete | E21: El valle: julio. Si tu valle es otro, cambia los dos meses.
A22: Segundo mes del verano (número del mes) | B22: 8 | C22: mes | D22: supuesto declarado de El Molinete | E22: Agosto.
A23: Días de esos dos meses | B23: 62 | C23: días | D23: calendario | E23: Julio y agosto: 31 + 31. Sirve para pasar la contribución del verano a raciones al día en «El Verano (Tres Salidas)».
A25: Hora Punta y Hora Mínima de Apertura
A26: Factor de la hora punta (la hora más cargada frente a la media de su franja) | B26: 1.5 | C26: veces | D26: supuesto declarado de El Molinete | E26: La hora más cargada de una franja lleva un 50 % más que la media de la franja. Míralo en tu TPV: las ventas de la peor hora entre las de la franja.
A27: Minutos de una hora | B27: 60 | C27: min | D27: calendario | E27: Para pasar la cola a minutos de espera.
A28: Hora mínima de apertura como chocolatería (ejemplo de Madrid) | B28: 8 | C28: hora | D28: CUN-34 | E28: Chocolaterías, heladerías y salones de té: desde las 8:00 hasta la 1:00. No se extrapola a otras comunidades. Si tu comunidad tiene otra norma, pon su hora.
A29: Hora mínima de apertura como cafetería o bar (ejemplo de Madrid) | B29: 6 | C29: hora | D29: CUN-34 | E29: Cafeterías, bares y cafés-bares: desde las 6:00 hasta las 2:00. Abrir antes de las 8:00 obliga a clasificarse así.
A31: Temporada, IVA de Feria y Tolerancia
A32: Coeficiente desde el que un mes es temporada alta | B32: 1.1 | C32: veces | D32: supuesto declarado de El Molinete | E32: Con los coeficientes del ejemplo marca de octubre a marzo, la forma que describen las fuentes del sector: el churro vive de octubre a marzo con Navidad arriba.
A33: Coeficiente hasta el que un mes es valle | B33: 0.6 | C33: veces | D33: supuesto declarado de El Molinete | E33: Con el ejemplo marca julio y agosto.
A34: IVA de lo que vendes en una feria (churros para llevar) | B34: 0.1 | D34: FC-IVA-02 | E34: Churros y porras para llevar: entrega de un alimento. El PVP de feria se teclea con IVA y aquí se le quita.
A35: Tolerancia de las filas de CUADRE y de los repartos | B35: 0.02 | D35: heredado de la Guía de la Chocolatería (tolerancia de las filas de CUADRE) | E35: Por encima de esta desviación, la fila de CUADRE avisa de que lo que has copiado no es lo que publica el libro de origen.
A36: Déficit que cubren la masa preparada antes de abrir y una persona más en la línea (en % de la capacidad) | B36: 0.25 | D36: supuesto declarado de El Molinete | E36: Con un déficit de hora punta por debajo de esta parte de la capacidad, el veredicto «¿Una churrera o dos?» de «Capacidad contra el Pico» dice que una basta con refuerzo en el pico. Mide cuánto adelantas con masa preparada y una segunda persona, y pon tu cifra.
A38: Cuadre | B38: Lo que publica hoy la celda de origen (anótalo) | C38: Desviación | D38: Veredicto | E38: Si no cuadra
A39: CUADRE · Raciones de un día tipo (lunes a viernes) (X4) | B39: 250 | C39: =IFERROR(ABS('Parámetros'!$B$7-B39)/B39,"") -> 0 | D39: =IF(NOT(ISNUMBER(C39)),"",IF(C39<='Parámetros'!$B$35,"CUADRA","REVISA: no es lo que publica el libro 1")) -> CUADRA | E39: Vuelve a copiar la cifra de su celda de origen (libro 1, produccion-hora-punta-y-local.xlsx!Día Tipo y Día Punta!L7) en la fila 7, o anota aquí lo que publica hoy.
A40: CUADRE · Raciones de un día punta (sábado, domingo y festivo) (X4) | B40: 400 | C40: =IFERROR(ABS('Parámetros'!$B$8-B40)/B40,"") -> 0 | D40: =IF(NOT(ISNUMBER(C40)),"",IF(C40<='Parámetros'!$B$35,"CUADRA","REVISA: no es lo que publica el libro 1")) -> CUADRA | E40: Vuelve a copiar la cifra de su celda de origen (libro 1, produccion-hora-punta-y-local.xlsx!Día Tipo y Día Punta!L8) en la fila 8, o anota aquí lo que publica hoy.
A41: CUADRE · Capacidad de la línea, en raciones por hora (X4) | B41: 122.55136 | C41: =IFERROR(ABS('Parámetros'!$B$9-B41)/B41,"") -> 0 | D41: =IF(NOT(ISNUMBER(C41)),"",IF(C41<='Parámetros'!$B$35,"CUADRA","REVISA: no es lo que publica el libro 1")) -> CUADRA | E41: Vuelve a copiar la cifra de su celda de origen (libro 1, produccion-hora-punta-y-local.xlsx!Cuello de Botella!L5) en la fila 9, o anota aquí lo que publica hoy.
A42: CUADRE · Ticket sin IVA por ración en julio y agosto (carta de verano) (X5) | B42: 2.2067273 | C42: =IFERROR(ABS('Parámetros'!$B$11-B42)/B42,"") -> 0 | D42: =IF(NOT(ISNUMBER(C42)),"",IF(C42<='Parámetros'!$B$35,"CUADRA","REVISA: no es lo que publica el libro 3")) -> CUADRA | E42: Vuelve a copiar la cifra de su celda de origen (libro 3, carta-de-apertura-y-escandallo-churro.xlsx!Mix y Ticket Canal y Temporada!L6) en la fila 11, o anota aquí lo que publica hoy.
A43: CUADRE · Coste de materia por ración en julio y agosto (aceite absorbido incluido) (X5) | B43: 0.35850072 | C43: =IFERROR(ABS('Parámetros'!$B$12-B43)/B43,"") -> 0 | D43: =IF(NOT(ISNUMBER(C43)),"",IF(C43<='Parámetros'!$B$35,"CUADRA","REVISA: no es lo que publica el libro 3")) -> CUADRA | E43: Vuelve a copiar la cifra de su celda de origen (libro 3, carta-de-apertura-y-escandallo-churro.xlsx!Mix y Ticket Canal y Temporada!L7) en la fila 12, o anota aquí lo que publica hoy.
A44: CUADRE · Coste de materia por ración para llevar (aceite absorbido incluido) (X5) | B44: 0.30546293 | C44: =IFERROR(ABS('Parámetros'!$B$13-B44)/B44,"") -> 0 | D44: =IF(NOT(ISNUMBER(C44)),"",IF(C44<='Parámetros'!$B$35,"CUADRA","REVISA: no es lo que publica el libro 3")) -> CUADRA | E44: Vuelve a copiar la cifra de su celda de origen (libro 3, carta-de-apertura-y-escandallo-churro.xlsx!Mix y Ticket Canal y Temporada!L8) en la fila 13, o anota aquí lo que publica hoy.
A45: CUADRE · Coste hora de mano de obra (X5) | B45: 13.243843 | C45: =IFERROR(ABS('Parámetros'!$B$14-B45)/B45,"") -> 0 | D45: =IF(NOT(ISNUMBER(C45)),"",IF(C45<='Parámetros'!$B$35,"CUADRA","REVISA: no es lo que publica el libro 3")) -> CUADRA | E45: Vuelve a copiar la cifra de su celda de origen (libro 3, carta-de-apertura-y-escandallo-churro.xlsx!Coste Hora!L5) en la fila 14, o anota aquí lo que publica hoy.
...

Sheet Peso sobre el Año
A1: Peso sobre el Año
A2: AI Chef Pro · aichef.pro — Cómo Montar una Churrería-Chocolatería
A3: Las raciones de un año normal y doce coeficientes que las reparten por meses. Los coeficientes son SUPUESTOS: no hay reparto mensual publicado de churrería.
A4: Las Raciones del Año | K4: Lo que Copian Otros Libros (No Muevas Estas Celdas)
A5: Días del año | B5: ='Parámetros'!$B$17 -> 365 | C5: días | K5: Raciones del año | L5: =B12 -> 107400 | M5: Lo copia: libro 6 (plan-financiero-3-anos-churreria.xlsx, hoja 0. Supuestos, X13)
A6: Días con el local cerrado | B6: ='Parámetros'!$B$18 -> 5 | C6: días | K6: Coeficiente de enero | L6: =B18 -> 1.25 | M6: Lo copia: libro 6 (plan-financiero-3-anos-churreria.xlsx, hoja 0. Supuestos, X13)
A7: Días punta: sábados, domingos y festivos que abres | B7: ='Parámetros'!$B$19+'Parámetros'!$B$20 -> 116 | C7: días | K7: Coeficiente de febrero | L7: =B19 -> 1.15 | M7: Lo copia: libro 6 (plan-financiero-3-anos-churreria.xlsx, hoja 0. Supuestos, X13)
A8: Días tipo: el resto de días abiertos | B8: =B5-B6-B7 -> 244 | C8: días | K8: Coeficiente de marzo | L8: =B20 -> 1.1 | M8: Lo copia: libro 6 (plan-financiero-3-anos-churreria.xlsx, hoja 0. Supuestos, X13)
A9: Días de apertura del año | B9: =B5-B6 -> 360 | C9: días | K9: Coeficiente de abril | L9: =B21 -> 0.95 | M9: Lo copia: libro 6 (plan-financiero-3-anos-churreria.xlsx, hoja 0. Supuestos, X13)
A10: Raciones de un día tipo (copiadas del libro 1) | B10: ='Parámetros'!$B$7 -> 250 | C10: raciones | K10: Coeficiente de mayo | L10: =B22 -> 0.85 | M10: Lo copia: libro 6 (plan-financiero-3-anos-churreria.xlsx, hoja 0. Supuestos, X13)
A11: Raciones de un día punta (copiadas del libro 1) | B11: ='Parámetros'!$B$8 -> 400 | C11: raciones | K11: Coeficiente de junio | L11: =B23 -> 0.7 | M11: Lo copia: libro 6 (plan-financiero-3-anos-churreria.xlsx, hoja 0. Supuestos, X13)
A12: RACIONES DEL AÑO | B12: =B8*B10+B7*B11 -> 107400 | C12: raciones | D12: Lo copia el libro 6 (bloque de la derecha, celda L5). | K12: Coeficiente de julio | L12: =B24 -> 0.55 | M12: Lo copia: libro 6 (plan-financiero-3-anos-churreria.xlsx, hoja 0. Supuestos, X13)
A13: Meses con coeficiente | B13: =COUNT(B18:B29) -> 12 | C13: meses | K13: Coeficiente de agosto | L13: =B25 -> 0.5 | M13: Lo copia: libro 6 (plan-financiero-3-anos-churreria.xlsx, hoja 0. Supuestos, X13)
A14: Suma de los doce coeficientes | B14: =SUM(B18:B29) -> 12 | C14: tiene que dar 12 | K14: Coeficiente de septiembre | L14: =B26 -> 0.8 | M14: Lo copia: libro 6 (plan-financiero-3-anos-churreria.xlsx, hoja 0. Supuestos, X13)
A15: ¿Los coeficientes reparten el año entero? | B15: =IF(NOT(ISNUMBER(B14)),"",IF(ABS(B14-B13)<='Parámetros'!$B$35*B13,"CUADRA","REVISA: los doce coeficientes no suman 12 y los meses no suman el año")) -> CUADRA | K15: Coeficiente de octubre | L15: =B27 -> 1.1 | M15: Lo copia: libro 6 (plan-financiero-3-anos-churreria.xlsx, hoja 0. Supuestos, X13)
K16: Coeficiente de noviembre | L16: =B28 -> 1.3 | M16: Lo copia: libro 6 (plan-financiero-3-anos-churreria.xlsx, hoja 0. Supuestos, X13)
A17: Mes | B17: Coeficiente (1 = un mes medio) | C17: Temporada | D17: Raciones del mes | E17: Peso sobre el año | F17: Raciones de un día medio del mes | G17: Raciones de un día tipo del mes | H17: Raciones de un día punta del mes | I17: Nota | K17: Coeficiente de diciembre | L17: =B29 -> 1.75 | M17: Lo copia: libro 6 (plan-financiero-3-anos-churreria.xlsx, hoja 0. Supuestos, X13)
A18: Enero | B18: 1.25 | C18: =IF(NOT(ISNUMBER(B18)),"",IF(B18>='Parámetros'!$B$32,"Temporada alta",IF(B18<='Parámetros'!$B$33,"Valle","Media"))) -> Temporada alta | D18: =IFERROR($B$12*B18/$B$13,"") -> 11187.5 | E18: =IFERROR(D18/$B$12,"") -> 0.10416667 | F18: =IFERROR(D18/($B$9/$B$13),"") -> 372.91667 | G18: =IFERROR($B$10*B18,"") -> 312.5 | H18: =IFERROR($B$11*B18,"") -> 500 | I18: Supuestos declarados con la forma que describen las fuentes del sector: pico de octubre a marzo con Navidad arriba y valle en julio y agosto. La serie de búsquedas en internet no vale como reparto de ventas. Al cerrar tu primer año, pon los tuyos (ventas del mes entre la media).
A19: Febrero | B19: 1.15 | C19: =IF(NOT(ISNUMBER(B19)),"",IF(B19>='Parámetros'!$B$32,"Temporada alta",IF(B19<='Parámetros'!$B$33,"Valle","Media"))) -> Temporada alta | D19: =IFERROR($B$12*B19/$B$13,"") -> 10292.5 | E19: =IFERROR(D19/$B$12,"") -> 0.095833333 | F19: =IFERROR(D19/($B$9/$B$13),"") -> 343.08333 | G19: =IFERROR($B$10*B19,"") -> 287.5 | H19: =IFERROR($B$11*B19,"") -> 460
A20: Marzo | B20: 1.1 | C20: =IF(NOT(ISNUMBER(B20)),"",IF(B20>='Parámetros'!$B$32,"Temporada alta",IF(B20<='Parámetros'!$B$33,"Valle","Media"))) -> Temporada alta | D20: =IFERROR($B$12*B20/$B$13,"") -> 9845 | E20: =IFERROR(D20/$B$12,"") -> 0.091666667 | F20: =IFERROR(D20/($B$9/$B$13),"") -> 328.16667 | G20: =IFERROR($B$10*B20,"") -> 275 | H20: =IFERROR($B$11*B20,"") -> 440
A21: Abril | B21: 0.95 | C21: =IF(NOT(ISNUMBER(B21)),"",IF(B21>='Parámetros'!$B$32,"Temporada alta",IF(B21<='Parámetros'!$B$33,"Valle","Media"))) -> Media | D21: =IFERROR($B$12*B21/$B$13,"") -> 8502.5 | E21: =IFERROR(D21/$B$12,"") -> 0.079166667 | F21: =IFERROR(D21/($B$9/$B$13),"") -> 283.41667 | G21: =IFERROR($B$10*B21,"") -> 237.5 | H21: =IFERROR($B$11*B21,"") -> 380
A22: Mayo | B22: 0.85 | C22: =IF(NOT(ISNUMBER(B22)),"",IF(B22>='Parámetros'!$B$32,"Temporada alta",IF(B22<='Parámetros'!$B$33,"Valle","Media"))) -> Media | D22: =IFERROR($B$12*B22/$B$13,"") -> 7607.5 | E22: =IFERROR(D22/$B$12,"") -> 0.070833333 | F22: =IFERROR(D22/($B$9/$B$13),"") -> 253.58333 | G22: =IFERROR($B$10*B22,"") -> 212.5 | H22: =IFERROR($B$11*B22,"") -> 340
A23: Junio | B23: 0.7 | C23: =IF(NOT(ISNUMBER(B23)),"",IF(B23>='Parámetros'!$B$32,"Temporada alta",IF(B23<='Parámetros'!$B$33,"Valle","Media"))) -> Media | D23: =IFERROR($B$12*B23/$B$13,"") -> 6265 | E23: =IFERROR(D23/$B$12,"") -> 0.058333333 | F23: =IFERROR(D23/($B$9/$B$13),"") -> 208.83333 | G23: =IFERROR($B$10*B23,"") -> 175 | H23: =IFERROR($B$11*B23,"") -> 280
A24: Julio | B24: 0.55 | C24: =IF(NOT(ISNUMBER(B24)),"",IF(B24>='Parámetros'!$B$32,"Temporada alta",IF(B24<='Parámetros'!$B$33,"Valle","Media"))) -> Valle | D24: =IFERROR($B$12*B24/$B$13,"") -> 4922.5 | E24: =IFERROR(D24/$B$12,"") -> 0.045833333 | F24: =IFERROR(D24/($B$9/$B$13),"") -> 164.08333 | G24: =IFERROR($B$10*B24,"") -> 137.5 | H24: =IFERROR($B$11*B24,"") -> 220
A25: Agosto | B25: 0.5 | C25: =IF(NOT(ISNUMBER(B25)),"",IF(B25>='Parámetros'!$B$32,"Temporada alta",IF(B25<='Parámetros'!$B$33,"Valle","Media"))) -> Valle | D25: =IFERROR($B$12*B25/$B$13,"") -> 4475 | E25: =IFERROR(D25/$B$12,"") -> 0.041666667 | F25: =IFERROR(D25/($B$9/$B$13),"") -> 149.16667 | G25: =IFERROR($B$10*B25,"") -> 125 | H25: =IFERROR($B$11*B25,"") -> 200
A26: Septiembre | B26: 0.8 | C26: =IF(NOT(ISNUMBER(B26)),"",IF(B26>='Parámetros'!$B$32,"Temporada alta",IF(B26<='Parámetros'!$B$33,"Valle","Media"))) -> Media | D26: =IFERROR($B$12*B26/$B$13,"") -> 7160 | E26: =IFERROR(D26/$B$12,"") -> 0.066666667 | F26: =IFERROR(D26/($B$9/$B$13),"") -> 238.66667 | G26: =IFERROR($B$10*B26,"") -> 200 | H26: =IFERROR($B$11*B26,"") -> 320
A27: Octubre | B27: 1.1 | C27: =IF(NOT(ISNUMBER(B27)),"",IF(B27>='Parámetros'!$B$32,"Temporada alta",IF(B27<='Parámetros'!$B$33,"Valle","Media"))) -> Temporada alta | D27: =IFERROR($B$12*B27/$B$13,"") -> 9845 | E27: =IFERROR(D27/$B$12,"") -> 0.091666667 | F27: =IFERROR(D27/($B$9/$B$13),"") -> 328.16667 | G27: =IFERROR($B$10*B27,"") -> 275 | H27: =IFERROR($B$11*B27,"") -> 440
A28: Noviembre | B28: 1.3 | C28: =IF(NOT(ISNUMBER(B28)),"",IF(B28>='Parámetros'!$B$32,"Temporada alta",IF(B28<='Parámetros'!$B$33,"Valle","Media"))) -> Temporada alta | D28: =IFERROR($B$12*B28/$B$13,"") -> 11635 | E28: =IFERROR(D28/$B$12,"") -> 0.10833333 | F28: =IFERROR(D28/($B$9/$B$13),"") -> 387.83333 | G28: =IFERROR($B$10*B28,"") -> 325 | H28: =IFERROR($B$11*B28,"") -> 520 | I28: Diciembre es Navidad y Reyes: mira la cola del domingo y el refuerzo.
A29: Diciembre | B29: 1.75 | C29: =IF(NOT(ISNUMBER(B29)),"",IF(B29>='Parámetros'!$B$32,"Temporada alta",IF(B29<='Parámetros'!$B$33,"Valle","Media"))) -> Temporada alta | D29: =IFERROR($B$12*B29/$B$13,"") -> 15662.5 | E29: =IFERROR(D29/$B$12,"") -> 0.14583333 | F29: =IFERROR(D29/($B$9/$B$13),"") -> 522.08333 | G29: =IFERROR($B$10*B29,"") -> 437.5 | H29: =IFERROR($B$11*B29,"") -> 700
A30: TOTAL del año | B30: =SUM(B18:B29) -> 12 | D30: =SUM(D18:D29) -> 107400 | E30: =SUM(E18:E29) -> 1
A32: Julio y Agosto (los Dos Meses del Verano)
A33: Coeficiente del primer mes del verano | B33: =IFERROR(INDEX($B$18:$B$29,'Parámetros'!$B$21),"") -> 0.55
A34: Coeficiente del segundo mes del verano | B34: =IFERROR(INDEX($B$18:$B$29,'Parámetros'!$B$22),"") -> 0.5
A35: Raciones que vendería el local en julio y agosto | B35: =IFERROR((B33+B34)*$B$12/$B$13,"") -> 9397.5 | C35: Si abre con carta de verano. Lo usa la hoja «El Verano (Tres Salidas)».
A37: Versión 1.0 · octubre 2026 · aichef.pro/guia-churreria-chocolateria · info@aichef.pro

Sheet Franjas del Día
A1: Franjas del Día
A2: AI Chef Pro · aichef.pro — Cómo Montar una Churrería-Chocolatería
A3: La franja del día vive SÓLO aquí. Horario y reparto de las raciones de cada día, la hora punta y el semáforo de la hora de apertura.
A4: Los Siete Días | K4: Horas por Franja de la Semana Tipo (Dato de Referencia)
A5: Día | B5: Tipo de día | C5: Raciones del día (mes medio) | D5: Hora de apertura | E5: Hora de apertura frente a la mínima legal (ejemplo de Madrid) | F5: Horas abiertas | G5: Reparto de las raciones (tiene que dar 100 %) | H5: Hora punta del día (raciones/h) | I5: Hora punta si es día tipo | J5: Hora punta si es día punta | K5: Horas a la semana: desayuno | L5: =B53 -> 23
A6: Lunes | B6: Tipo | C6: =IF(B6="Punta",'Parámetros'!$B$8,IF(B6="Tipo",'Parámetros'!$B$7,"")) -> 250 | D6: =C22 -> 7 | E6: =IF(NOT(ISNUMBER(D6)),"",IF(D6<'Parámetros'!$B$29,"Antes de la hora mínima también como cafetería o bar",IF(D6<'Parámetros'!$B$28,"Antes de la hora de chocolatería: sólo como cafetería o bar (ejemplo de Madrid)","Cabe también como chocolatería"))) -> Antes de la hora de chocolatería: sólo como cafetería o bar (ejemplo de Madrid) | F6: =SUMIF($B$22:$B$49,A6,$E$22:$E$49) -> 10.5 | G6: =SUMIF($B$22:$B$49,A6,$F$22:$F$49) -> 1 | H6: =MAX(I22:I25) -> 62.5 | I6: =IF(B6="Tipo",H6,"") -> 62.5 | J6: =IF(B6="Punta",H6,"") | K6: Horas a la semana: media mañana | L6: =B54 -> 21
A7: Martes | B7: Tipo | C7: =IF(B7="Punta",'Parámetros'!$B$8,IF(B7="Tipo",'Parámetros'!$B$7,"")) -> 250 | D7: =C26 -> 7 | E7: =IF(NOT(ISNUMBER(D7)),"",IF(D7<'Parámetros'!$B$29,"Antes de la hora mínima también como cafetería o bar",IF(D7<'Parámetros'!$B$28,"Antes de la hora de chocolatería: sólo como cafetería o bar (ejemplo de Madrid)","Cabe también como chocolatería"))) -> Antes de la hora de chocolatería: sólo como cafetería o bar (ejemplo de Madrid) | F7: =SUMIF($B$22:$B$49,A7,$E$22:$E$49) -> 10.5 | G7: =SUMIF($B$22:$B$49,A7,$F$22:$F$49) -> 1 | H7: =MAX(I26:I29) -> 62.5 | I7: =IF(B7="Tipo",H7,"") -> 62.5 | J7: =IF(B7="Punta",H7,"") | K7: Horas a la semana: merienda | L7: =B55 -> 31.5
A8: Miércoles | B8: Tipo | C8: =IF(B8="Punta",'Parámetros'!$B$8,IF(B8="Tipo",'Parámetros'!$B$7,"")) -> 250 | D8: =C30 -> 7 | E8: =IF(NOT(ISNUMBER(D8)),"",IF(D8<'Parámetros'!$B$29,"Antes de la hora mínima también como cafetería o bar",IF(D8<'Parámetros'!$B$28,"Antes de la hora de chocolatería: sólo como cafetería o bar (ejemplo de Madrid)","Cabe también como chocolatería"))) -> Antes de la hora de chocolatería: sólo como cafetería o bar (ejemplo de Madrid) | F8: =SUMIF($B$22:$B$49,A8,$E$22:$E$49) -> 10.5 | G8: =SUMIF($B$22:$B$49,A8,$F$22:$F$49) -> 1 | H8: =MAX(I30:I33) -> 62.5 | I8: =IF(B8="Tipo",H8,"") -> 62.5 | J8: =IF(B8="Punta",H8,"") | K8: Horas a la semana: noche (viernes y sábado) | L8: =B56 -> 8
A9: Jueves | B9: Tipo | C9: =IF(B9="Punta",'Parámetros'!$B$8,IF(B9="Tipo",'Parámetros'!$B$7,"")) -> 250 | D9: =C34 -> 7 | E9: =IF(NOT(ISNUMBER(D9)),"",IF(D9<'Parámetros'!$B$29,"Antes de la hora mínima también como cafetería o bar",IF(D9<'Parámetros'!$B$28,"Antes de la hora de chocolatería: sólo como cafetería o bar (ejemplo de Madrid)","Cabe también como chocolatería"))) -> Antes de la hora de chocolatería: sólo como cafetería o bar (ejemplo de Madrid) | F9: =SUMIF($B$22:$B$49,A9,$E$22:$E$49) -> 10.5 | G9: =SUMIF($B$22:$B$49,A9,$F$22:$F$49) -> 1 | H9: =MAX(I34:I37) -> 62.5 | I9: =IF(B9="Tipo",H9,"") -> 62.5 | J9: =IF(B9="Punta",H9,"")
A10: Viernes | B10: Tipo | C10: =IF(B10="Punta",'Parámetros'!$B$8,IF(B10="Tipo",'Parámetros'!$B$7,"")) -> 250 | D10: =C38 -> 7 | E10: =IF(NOT(ISNUMBER(D10)),"",IF(D10<'Parámetros'!$B$29,"Antes de la hora mínima también como cafetería o bar",IF(D10<'Parámetros'!$B$28,"Antes de la hora de chocolatería: sólo como cafetería o bar (ejemplo de Madrid)","Cabe también como chocolatería"))) -> Antes de la hora de chocolatería: sólo como cafetería o bar (ejemplo de Madrid) | F10: =SUMIF($B$22:$B$49,A10,$E$22:$E$49) -> 14.5 | G10: =SUMIF($B$22:$B$49,A10,$F$22:$F$49) -> 1 | H10: =MAX(I38:I41) -> 62.5 | I10: =IF(B10="Tipo",H10,"") -> 62.5 | J10: =IF(B10="Punta",H10,"")
A11: Sábado | B11: Punta | C11: =IF(B11="Punta",'Parámetros'!$B$8,IF(B11="Tipo",'Parámetros'!$B$7,"")) -> 400 | D11: =C42 -> 6 | E11: =IF(NOT(ISNUMBER(D11)),"",IF(D11<'Parámetros'!$B$29,"Antes de la hora mínima también como cafetería o bar",IF(D11<'Parámetros'!$B$28,"Antes de la hora de chocolatería: sólo como cafetería o bar (ejemplo de Madrid)","Cabe también como chocolatería"))) -> Antes de la hora de chocolatería: sólo como cafetería o bar (ejemplo de Madrid) | F11: =SUMIF($B$22:$B$49,A11,$E$22:$E$49) -> 15.5 | G11: =SUMIF($B$22:$B$49,A11,$F$22:$F$49) -> 1 | H11: =MAX(I42:I45) -> 75 | I11: =IF(B11="Tipo",H11,"") | J11: =IF(B11="Punta",H11,"") -> 75
A12: Domingo | B12: Punta | C12: =IF(B12="Punta",'Parámetros'!$B$8,IF(B12="Tipo",'Parámetros'!$B$7,"")) -> 400 | D12: =C46 -> 6 | E12: =IF(NOT(ISNUMBER(D12)),"",IF(D12<'Parámetros'!$B$29,"Antes de la hora mínima también como cafetería o bar",IF(D12<'Parámetros'!$B$28,"Antes de la hora de chocolatería: sólo como cafetería o bar (ejemplo de Madrid)","Cabe también como chocolatería"))) -> Antes de la hora de chocolatería: sólo como cafetería o bar (ejemplo de Madrid) | F12: =SUMIF($B$22:$B$49,A12,$E$22:$E$49) -> 11.5 | G12: =SUMIF($B$22:$B$49,A12,$F$22:$F$49) -> 1 | H12: =MAX(I46:I49) -> 75 | I12: =IF(B12="Tipo",H12,"") | J12: =IF(B12="Punta",H12,"") -> 75
A14: Hora punta de un día tipo (la más alta de los días tipo), mes medio | E14: =MAX(I6:I12) -> 62.5 | F14: raciones/h
A15: Hora punta de un día punta (la más alta de los días punta), mes medio | E15: =MAX(J6:J12) -> 75 | F15: raciones/h
A16: Días que abres antes de la hora mínima de chocolatería | E16: =COUNTIF(E6:E12,"Antes de la hora de chocolatería: sólo como cafetería o bar (ejemplo de Madrid)")+COUNTIF(E6:E12,"Antes de la hora mínima también como cafetería o bar") -> 7 | F16: días | G16: El Molinete abre a las 6:00 y a las 7:00: en el ejemplo de Madrid se clasifica como cafetería o bar (decisión 8). El libro 7 cita la norma y remite aquí.
A17: De ellos, días que abres antes de la hora mínima incluso como cafetería o bar | E17: =COUNTIF(E6:E12,"Antes de la hora mínima también como cafetería o bar") -> 0 | F17: días
A18: Días cuyo reparto de raciones no suma el 100 % | E18: =COUNTIF(G6:G12,"<"&(1-'Parámetros'!$B$35))+COUNTIF(G6:G12,">"&(1+'Parámetros'!$B$35)) -> 0 | F18: días
A20: Las Franjas, Día a Día
A21: Franja | B21: Día | C21: Empieza (hora: 16,5 = 16:30) | D21: Acaba (25 = la 1:00 del día siguiente) | E21: Horas | F21: Parte de las raciones del día | G21: Raciones de la franja (mes medio) | H21: Raciones por hora (media) | I21: Raciones por hora en su hora punta | J21: ¿Aguanta la línea? (mes medio)
A22: Desayuno | B22: Lunes | C22: 7 | D22: 10 | E22: =IF(AND(ISNUMBER(C22),ISNUMBER(D22)),MAX(0,D22-C22),"") -> 3 | F22: 0.5 | G22: =IFERROR($C$6*F22,"") -> 125 | H22: =IFERROR(G22/E22,"") -> 41.666667 | I22: =IFERROR(H22*'Parámetros'!$B$26,"") -> 62.5 | J22: =IF(NOT(ISNUMBER(I22)),"",IF(I22<='Parámetros'!$B$9,"Sí","No")) -> Sí | K22: Si un día no abres una franja, pon la misma hora de inicio y de fin y un 0 % de las raciones. El 100 % de cada día se reparte entre sus franjas: el resumen de arriba cuenta los días que no cuadran.
A23: Media mañana | B23: Lunes | C23: 10 | D23: 13 | E23: =IF(AND(ISNUMBER(C23),ISNUMBER(D23)),MAX(0,D23-C23),"") -> 3 | F23: 0.1 | G23: =IFERROR($C$6*F23,"") -> 25 | H23: =IFERROR(G23/E23,"") -> 8.3333333 | I23: =IFERROR(H23*'Parámetros'!$B$26,"") -> 12.5 | J23: =IF(NOT(ISNUMBER(I23)),"",IF(I23<='Parámetros'!$B$9,"Sí","No")) -> Sí
A24: Merienda | B24: Lunes | C24: 16.5 | D24: 21 | E24: =IF(AND(ISNUMBER(C24),ISNUMBER(D24)),MAX(0,D24-C24),"") -> 4.5 | F24: 0.4 | G24: =IFERROR($C$6*F24,"") -> 100 | H24: =IFERROR(G24/E24,"") -> 22.222222 | I24: =IFERROR(H24*'Parámetros'!$B$26,"") -> 33.333333 | J24: =IF(NOT(ISNUMBER(I24)),"",IF(I24<='Parámetros'!$B$9,"Sí","No")) -> Sí
A25: Noche (viernes y sábado) | B25: Lunes | C25: 21 | D25: 21 | E25: =IF(AND(ISNUMBER(C25),ISNUMBER(D25)),MAX(0,D25-C25),"") -> 0 | F25: 0 | G25: =IFERROR($C$6*F25,"") -> 0 | H25: =IFERROR(G25/E25,"") | I25: =IFERROR(H25*'Parámetros'!$B$26,"") | J25: =IF(NOT(ISNUMBER(I25)),"",IF(I25<='Parámetros'!$B$9,"Sí","No"))
A26: Desayuno | B26: Martes | C26: 7 | D26: 10 | E26: =IF(AND(ISNUMBER(C26),ISNUMBER(D26)),MAX(0,D26-C26),"") -> 3 | F26: 0.5 | G26: =IFERROR($C$7*F26,"") -> 125 | H26: =IFERROR(G26/E26,"") -> 41.666667 | I26: =IFERROR(H26*'Parámetros'!$B$26,"") -> 62.5 | J26: =IF(NOT(ISNUMBER(I26)),"",IF(I26<='Parámetros'!$B$9,"Sí","No")) -> Sí
A27: Media mañana | B27: Martes | C27: 10 | D27: 13 | E27: =IF(AND(ISNUMBER(C27),ISNUMBER(D27)),MAX(0,D27-C27),"") -> 3 | F27: 0.1 | G27: =IFERROR($C$7*F27,"") -> 25 | H27: =IFERROR(G27/E27,"") -> 8.3333333 | I27: =IFERROR(H27*'Parámetros'!$B$26,"") -> 12.5 | J27: =IF(NOT(ISNUMBER(I27)),"",IF(I27<='Parámetros'!$B$9,"Sí","No")) -> Sí
A28: Merienda | B28: Martes | C28: 16.5 | D28: 21 | E28: =IF(AND(ISNUMBER(C28),ISNUMBER(D28)),MAX(0,D28-C28),"") -> 4.5 | F28: 0.4 | G28: =IFERROR($C$7*F28,"") -> 100 | H28: =IFERROR(G28/E28,"") -> 22.222222 | I28: =IFERROR(H28*'Parámetros'!$B$26,"") -> 33.333333 | J28: =IF(NOT(ISNUMBER(I28)),"",IF(I28<='Parámetros'!$B$9,"Sí","No")) -> Sí
A29: Noche (viernes y sábado) | B29: Martes | C29: 21 | D29: 21 | E29: =IF(AND(ISNUMBER(C29),ISNUMBER(D29)),MAX(0,D29-C29),"") -> 0 | F29: 0 | G29: =IFERROR($C$7*F29,"") -> 0 | H29: =IFERROR(G29/E29,"") | I29: =IFERROR(H29*'Parámetros'!$B$26,"") | J29: =IF(NOT(ISNUMBER(I29)),"",IF(I29<='Parámetros'!$B$9,"Sí","No"))
A30: Desayuno | B30: Miércoles | C30: 7 | D30: 10 | E30: =IF(AND(ISNUMBER(C30),ISNUMBER(D30)),MAX(0,D30-C30),"") -> 3 | F30: 0.5 | G30: =IFERROR($C$8*F30,"") -> 125 | H30: =IFERROR(G30/E30,"") -> 41.666667 | I30: =IFERROR(H30*'Parámetros'!$B$26,"") -> 62.5 | J30: =IF(NOT(ISNUMBER(I30)),"",IF(I30<='Parámetros'!$B$9,"Sí","No")) -> Sí
A31: Media mañana | B31: Miércoles | C31: 10 | D31: 13 | E31: =IF(AND(ISNUMBER(C31),ISNUMBER(D31)),MAX(0,D31-C31),"") -> 3 | F31: 0.1 | G31: =IFERROR($C$8*F31,"") -> 25 | H31: =IFERROR(G31/E31,"") -> 8.3333333 | I31: =IFERROR(H31*'Parámetros'!$B$26,"") -> 12.5 | J31: =IF(NOT(ISNUMBER(I31)),"",IF(I31<='Parámetros'!$B$9,"Sí","No")) -> Sí
A32: Merienda | B32: Miércoles | C32: 16.5 | D32: 21 | E32: =IF(AND(ISNUMBER(C32),ISNUMBER(D32)),MAX(0,D32-C32),"") -> 4.5 | F32: 0.4 | G32: =IFERROR($C$8*F32,"") -> 100 | H32: =IFERROR(G32/E32,"") -> 22.222222 | I32: =IFERROR(H32*'Parámetros'!$B$26,"") -> 33.333333 | J32: =IF(NOT(ISNUMBER(I32)),"",IF(I32<='Parámetros'!$B$9,"Sí","No")) -> Sí
A33: Noche (viernes y sábado) | B33: Miércoles | C33: 21 | D33: 21 | E33: =IF(AND(ISNUMBER(C33),ISNUMBER(D33)),MAX(0,D33-C33),"") -> 0 | F33: 0 | G33: =IFERROR($C$8*F33,"") -> 0 | H33: =IFERROR(G33/E33,"") | I33: =IFERROR(H33*'Parámetros'!$B$26,"") | J33: =IF(NOT(ISNUMBER(I33)),"",IF(I33<='Parámetros'!$B$9,"Sí","No"))
A34: Desayuno | B34: Jueves | C34: 7 | D34: 10 | E34: =IF(AND(ISNUMBER(C34),ISNUMBER(D34)),MAX(0,D34-C34),"") -> 3 | F34: 0.5 | G34: =IFERROR($C$9*F34,"") -> 125 | H34: =IFERROR(G34/E34,"") -> 41.666667 | I34: =IFERROR(H34*'Parámetros'!$B$26,"") -> 62.5 | J34: =IF(NOT(ISNUMBER(I34)),"",IF(I34<='Parámetros'!$B$9,"Sí","No")) -> Sí
A35: Media mañana | B35: Jueves | C35: 10 | D35: 13 | E35: =IF(AND(ISNUMBER(C35),ISNUMBER(D35)),MAX(0,D35-C35),"") -> 3 | F35: 0.1 | G35: =IFERROR($C$9*F35,"") -> 25 | H35: =IFERROR(G35/E35,"") -> 8.3333333 | I35: =IFERROR(H35*'Parámetros'!$B$26,"") -> 12.5 | J35: =IF(NOT(ISNUMBER(I35)),"",IF(I35<='Parámetros'!$B$9,"Sí","No")) -> Sí
A36: Merienda | B36: Jueves | C36: 16.5 | D36: 21 | E36: =IF(AND(ISNUMBER(C36),ISNUMBER(D36)),MAX(0,D36-C36),"") -> 4.5 | F36: 0.4 | G36: =IFERROR($C$9*F36,"") -> 100 | H36: =IFERROR(G36/E36,"") -> 22.222222 | I36: =IFERROR(H36*'Parámetros'!$B$26,"") -> 33.333333 | J36: =IF(NOT(ISNUMBER(I36)),"",IF(I36<='Parámetros'!$B$9,"Sí","No")) -> Sí
A37: Noche (viernes y sábado) | B37: Jueves | C37: 21 | D37: 21 | E37: =IF(AND(ISNUMBER(C37),ISNUMBER(D37)),MAX(0,D37-C37),"") -> 0 | F37: 0 | G37: =IFERROR($C$9*F37,"") -> 0 | H37: =IFERROR(G37/E37,"") | I37: =IFERROR(H37*'Parámetros'!$B$26,"") | J37: =IF(NOT(ISNUMBER(I37)),"",IF(I37<='Parámetros'!$B$9,"Sí","No"))
A38: Desayuno | B38: Viernes | C38: 7 | D38: 10 | E38: =IF(AND(ISNUMBER(C38),ISNUMBER(D38)),MAX(0,D38-C38),"") -> 3 | F38: 0.5 | G38: =IFERROR($C$10*F38,"") -> 125 | H38: =IFERROR(G38/E38,"") -> 41.666667 | I38: =IFERROR(H38*'Parámetros'!$B$26,"") -> 62.5 | J38: =IF(NOT(ISNUMBER(I38)),"",IF(I38<='Parámetros'!$B$9,"Sí","No")) -> Sí
A39: Media mañana | B39: Viernes | C39: 10 | D39: 13 | E39: =IF(AND(ISNUMBER(C39),ISNUMBER(D39)),MAX(0,D39-C39),"") -> 3 | F39: 0.1 | G39: =IFERROR($C$10*F39,"") -> 25 | H39: =IFERROR(G39/E39,"") -> 8.3333333 | I39: =IFERROR(H39*'Parámetros'!$B$26,"") -> 12.5 | J39: =IF(NOT(ISNUMBER(I39)),"",IF(I39<='Parámetros'!$B$9,"Sí","No")) -> Sí
A40: Merienda | B40: Viernes | C40: 16.5 | D40: 21 | E40: =IF(AND(ISNUMBER(C40),ISNUMBER(D40)),MAX(0,D40-C40),"") -> 4.5 | F40: 0.35 | G40: =IFERROR($C$10*F40,"") -> 87.5 | H40: =IFERROR(G40/E40,"") -> 19.444444 | I40: =IFERROR(H40*'Parámetros'!$B$26,"") -> 29.166667 | J40: =IF(NOT(ISNUMBER(I40)),"",IF(I40<='Parámetros'!$B$9,"Sí","No")) -> Sí
A41: Noche (viernes y sábado) | B41: Viernes | C41: 21 | D41: 25 | E41: =IF(AND(ISNUMBER(C41),ISNUMBER(D41)),MAX(0,D41-C41),"") -> 4 | F41: 0.05 | G41: =IFERROR($C$10*F41,"") -> 12.5 | H41: =IFERROR(G41/E41,"") -> 3.125 | I41: =IFERROR(H41*'Parámetros'!$B$26,"") -> 4.6875 | J41: =IF(NOT(ISNUMBER(I41)),"",IF(I41<='Parámetros'!$B$9,"Sí","No")) -> Sí
A42: Desayuno | B42: Sábado | C42: 6 | D42: 10 | E42: =IF(AND(ISNUMBER(C42),ISNUMBER(D42)),MAX(0,D42-C42),"") -> 4 | F42: 0.5 | G42: =IFERROR($C$11*F42,"") -> 200 | H42: =IFERROR(G42/E42,"") -> 50 | I42: =IFERROR(H42*'Parámetros'!$B$26,"") -> 75 | J42: =IF(NOT(ISNUMBER(I42)),"",IF(I42<='Parámetros'!$B$9,"Sí","No")) -> Sí
...

Sheet Capacidad contra el Pico
A1: Capacidad contra el Pico
A2: AI Chef Pro · aichef.pro — Cómo Montar una Churrería-Chocolatería
A3: Mes a mes, la hora punta de un día tipo y de un día punta frente a lo que saca la línea en una hora. Se mide en raciones, no en tickets.
A6: Mes | B6: Coeficiente | C6: Raciones de un día tipo | D6: Raciones de un día punta | E6: Hora punta de un día tipo (raciones/h) | F6: Hora punta de un día punta (raciones/h) | G6: Capacidad de la línea (raciones/h) | H6: Déficit en un día tipo (raciones/h) | I6: Déficit en un día punta (raciones/h) | J6: ¿Aguanta la línea?
A7: Enero | B7: ='Peso sobre el Año'!$B$18 -> 1.25 | C7: ='Peso sobre el Año'!G18 -> 312.5 | D7: ='Peso sobre el Año'!H18 -> 500 | E7: =IFERROR('Franjas del Día'!$E$14*B7,"") -> 78.125 | F7: =IFERROR('Franjas del Día'!$E$15*B7,"") -> 93.75 | G7: ='Parámetros'!$B$9 -> 122.55136 | H7: =IF(AND(ISNUMBER(E7),ISNUMBER(G7)),MAX(0,E7-G7),"") -> 0 | I7: =IF(AND(ISNUMBER(F7),ISNUMBER(G7)),MAX(0,F7-G7),"") -> 0 | J7: =IF(NOT(AND(ISNUMBER(H7),ISNUMBER(I7))),"",IF(H7>0,"No, tampoco entre semana",IF(I7>0,"No en los días punta","Sí"))) -> Sí | K7: La hora punta de cada mes es la de un mes medio (hoja «Franjas del Día») por el coeficiente del mes. La capacidad es la del conjunto, la que manda el equipo más lento (libro 1, «Cuello de Botella»).
A8: Febrero | B8: ='Peso sobre el Año'!$B$19 -> 1.15 | C8: ='Peso sobre el Año'!G19 -> 287.5 | D8: ='Peso sobre el Año'!H19 -> 460 | E8: =IFERROR('Franjas del Día'!$E$14*B8,"") -> 71.875 | F8: =IFERROR('Franjas del Día'!$E$15*B8,"") -> 86.25 | G8: ='Parámetros'!$B$9 -> 122.55136 | H8: =IF(AND(ISNUMBER(E8),ISNUMBER(G8)),MAX(0,E8-G8),"") -> 0 | I8: =IF(AND(ISNUMBER(F8),ISNUMBER(G8)),MAX(0,F8-G8),"") -> 0 | J8: =IF(NOT(AND(ISNUMBER(H8),ISNUMBER(I8))),"",IF(H8>0,"No, tampoco entre semana",IF(I8>0,"No en los días punta","Sí"))) -> Sí
A9: Marzo | B9: ='Peso sobre el Año'!$B$20 -> 1.1 | C9: ='Peso sobre el Año'!G20 -> 275 | D9: ='Peso sobre el Año'!H20 -> 440 | E9: =IFERROR('Franjas del Día'!$E$14*B9,"") -> 68.75 | F9: =IFERROR('Franjas del Día'!$E$15*B9,"") -> 82.5 | G9: ='Parámetros'!$B$9 -> 122.55136 | H9: =IF(AND(ISNUMBER(E9),ISNUMBER(G9)),MAX(0,E9-G9),"") -> 0 | I9: =IF(AND(ISNUMBER(F9),ISNUMBER(G9)),MAX(0,F9-G9),"") -> 0 | J9: =IF(NOT(AND(ISNUMBER(H9),ISNUMBER(I9))),"",IF(H9>0,"No, tampoco entre semana",IF(I9>0,"No en los días punta","Sí"))) -> Sí
A10: Abril | B10: ='Peso sobre el Año'!$B$21 -> 0.95 | C10: ='Peso sobre el Año'!G21 -> 237.5 | D10: ='Peso sobre el Año'!H21 -> 380 | E10: =IFERROR('Franjas del Día'!$E$14*B10,"") -> 59.375 | F10: =IFERROR('Franjas del Día'!$E$15*B10,"") -> 71.25 | G10: ='Parámetros'!$B$9 -> 122.55136 | H10: =IF(AND(ISNUMBER(E10),ISNUMBER(G10)),MAX(0,E10-G10),"") -> 0 | I10: =IF(AND(ISNUMBER(F10),ISNUMBER(G10)),MAX(0,F10-G10),"") -> 0 | J10: =IF(NOT(AND(ISNUMBER(H10),ISNUMBER(I10))),"",IF(H10>0,"No, tampoco entre semana",IF(I10>0,"No en los días punta","Sí"))) -> Sí
A11: Mayo | B11: ='Peso sobre el Año'!$B$22 -> 0.85 | C11: ='Peso sobre el Año'!G22 -> 212.5 | D11: ='Peso sobre el Año'!H22 -> 340 | E11: =IFERROR('Franjas del Día'!$E$14*B11,"") -> 53.125 | F11: =IFERROR('Franjas del Día'!$E$15*B11,"") -> 63.75 | G11: ='Parámetros'!$B$9 -> 122.55136 | H11: =IF(AND(ISNUMBER(E11),ISNUMBER(G11)),MAX(0,E11-G11),"") -> 0 | I11: =IF(AND(ISNUMBER(F11),ISNUMBER(G11)),MAX(0,F11-G11),"") -> 0 | J11: =IF(NOT(AND(ISNUMBER(H11),ISNUMBER(I11))),"",IF(H11>0,"No, tampoco entre semana",IF(I11>0,"No en los días punta","Sí"))) -> Sí
A12: Junio | B12: ='Peso sobre el Año'!$B$23 -> 0.7 | C12: ='Peso sobre el Año'!G23 -> 175 | D12: ='Peso sobre el Año'!H23 -> 280 | E12: =IFERROR('Franjas del Día'!$E$14*B12,"") -> 43.75 | F12: =IFERROR('Franjas del Día'!$E$15*B12,"") -> 52.5 | G12: ='Parámetros'!$B$9 -> 122.55136 | H12: =IF(AND(ISNUMBER(E12),ISNUMBER(G12)),MAX(0,E12-G12),"") -> 0 | I12: =IF(AND(ISNUMBER(F12),ISNUMBER(G12)),MAX(0,F12-G12),"") -> 0 | J12: =IF(NOT(AND(ISNUMBER(H12),ISNUMBER(I12))),"",IF(H12>0,"No, tampoco entre semana",IF(I12>0,"No en los días punta","Sí"))) -> Sí
A13: Julio | B13: ='Peso sobre el Año'!$B$24 -> 0.55 | C13: ='Peso sobre el Año'!G24 -> 137.5 | D13: ='Peso sobre el Año'!H24 -> 220 | E13: =IFERROR('Franjas del Día'!$E$14*B13,"") -> 34.375 | F13: =IFERROR('Franjas del Día'!$E$15*B13,"") -> 41.25 | G13: ='Parámetros'!$B$9 -> 122.55136 | H13: =IF(AND(ISNUMBER(E13),ISNUMBER(G13)),MAX(0,E13-G13),"") -> 0 | I13: =IF(AND(ISNUMBER(F13),ISNUMBER(G13)),MAX(0,F13-G13),"") -> 0 | J13: =IF(NOT(AND(ISNUMBER(H13),ISNUMBER(I13))),"",IF(H13>0,"No, tampoco entre semana",IF(I13>0,"No en los días punta","Sí"))) -> Sí
A14: Agosto | B14: ='Peso sobre el Año'!$B$25 -> 0.5 | C14: ='Peso sobre el Año'!G25 -> 125 | D14: ='Peso sobre el Año'!H25 -> 200 | E14: =IFERROR('Franjas del Día'!$E$14*B14,"") -> 31.25 | F14: =IFERROR('Franjas del Día'!$E$15*B14,"") -> 37.5 | G14: ='Parámetros'!$B$9 -> 122.55136 | H14: =IF(AND(ISNUMBER(E14),ISNUMBER(G14)),MAX(0,E14-G14),"") -> 0 | I14: =IF(AND(ISNUMBER(F14),ISNUMBER(G14)),MAX(0,F14-G14),"") -> 0 | J14: =IF(NOT(AND(ISNUMBER(H14),ISNUMBER(I14))),"",IF(H14>0,"No, tampoco entre semana",IF(I14>0,"No en los días punta","Sí"))) -> Sí
A15: Septiembre | B15: ='Peso sobre el Año'!$B$26 -> 0.8 | C15: ='Peso sobre el Año'!G26 -> 200 | D15: ='Peso sobre el Año'!H26 -> 320 | E15: =IFERROR('Franjas del Día'!$E$14*B15,"") -> 50 | F15: =IFERROR('Franjas del Día'!$E$15*B15,"") -> 60 | G15: ='Parámetros'!$B$9 -> 122.55136 | H15: =IF(AND(ISNUMBER(E15),ISNUMBER(G15)),MAX(0,E15-G15),"") -> 0 | I15: =IF(AND(ISNUMBER(F15),ISNUMBER(G15)),MAX(0,F15-G15),"") -> 0 | J15: =IF(NOT(AND(ISNUMBER(H15),ISNUMBER(I15))),"",IF(H15>0,"No, tampoco entre semana",IF(I15>0,"No en los días punta","Sí"))) -> Sí
A16: Octubre | B16: ='Peso sobre el Año'!$B$27 -> 1.1 | C16: ='Peso sobre el Año'!G27 -> 275 | D16: ='Peso sobre el Año'!H27 -> 440 | E16: =IFERROR('Franjas del Día'!$E$14*B16,"") -> 68.75 | F16: =IFERROR('Franjas del Día'!$E$15*B16,"") -> 82.5 | G16: ='Parámetros'!$B$9 -> 122.55136 | H16: =IF(AND(ISNUMBER(E16),ISNUMBER(G16)),MAX(0,E16-G16),"") -> 0 | I16: =IF(AND(ISNUMBER(F16),ISNUMBER(G16)),MAX(0,F16-G16),"") -> 0 | J16: =IF(NOT(AND(ISNUMBER(H16),ISNUMBER(I16))),"",IF(H16>0,"No, tampoco entre semana",IF(I16>0,"No en los días punta","Sí"))) -> Sí
A17: Noviembre | B17: ='Peso sobre el Año'!$B$28 -> 1.3 | C17: ='Peso sobre el Año'!G28 -> 325 | D17: ='Peso sobre el Año'!H28 -> 520 | E17: =IFERROR('Franjas del Día'!$E$14*B17,"") -> 81.25 | F17: =IFERROR('Franjas del Día'!$E$15*B17,"") -> 97.5 | G17: ='Parámetros'!$B$9 -> 122.55136 | H17: =IF(AND(ISNUMBER(E17),ISNUMBER(G17)),MAX(0,E17-G17),"") -> 0 | I17: =IF(AND(ISNUMBER(F17),ISNUMBER(G17)),MAX(0,F17-G17),"") -> 0 | J17: =IF(NOT(AND(ISNUMBER(H17),ISNUMBER(I17))),"",IF(H17>0,"No, tampoco entre semana",IF(I17>0,"No en los días punta","Sí"))) -> Sí
A18: Diciembre | B18: ='Peso sobre el Año'!$B$29 -> 1.75 | C18: ='Peso sobre el Año'!G29 -> 437.5 | D18: ='Peso sobre el Año'!H29 -> 700 | E18: =IFERROR('Franjas del Día'!$E$14*B18,"") -> 109.375 | F18: =IFERROR('Franjas del Día'!$E$15*B18,"") -> 131.25 | G18: ='Parámetros'!$B$9 -> 122.55136 | H18: =IF(AND(ISNUMBER(E18),ISNUMBER(G18)),MAX(0,E18-G18),"") -> 0 | I18: =IF(AND(ISNUMBER(F18),ISNUMBER(G18)),MAX(0,F18-G18),"") -> 8.6986383 | J18: =IF(NOT(AND(ISNUMBER(H18),ISNUMBER(I18))),"",IF(H18>0,"No, tampoco entre semana",IF(I18>0,"No en los días punta","Sí"))) -> No en los días punta
A20: Meses que no aguanta en los días punta | E20: =COUNTIF(I7:I18,">0") -> 1
A21: Meses que no aguanta ni entre semana | E21: =COUNTIF(H7:H18,">0") -> 0
A22: Peor déficit de un día punta (raciones/h) | E22: =MAX(I7:I18) -> 8.6986383
A23: ¿UNA CHURRERA O DOS? | E23: =IF(OR(NOT(ISNUMBER(E20)),NOT(ISNUMBER(E21)),NOT(ISNUMBER(E22)),NOT(ISNUMBER('Parámetros'!$B$9))),"",IF(E20=0,"Una basta: la línea aguanta la hora punta todos los meses",IF(AND(E21=0,E22<='Parámetros'!$B$36*'Parámetros'!$B$9),"Una, con refuerzo en el pico: masa preparada antes de abrir y una persona más","Necesitas más línea: activa la segunda freidora en el libro 1 y vuelve a copiar la capacidad (X4)"))) -> Una, con refuerzo en el pico: masa preparada antes de abrir y una persona más
A25: Un «No» no quiere decir que no puedas abrir ese mes: quiere decir que en la peor hora se te forma cola. Las palancas, en este orden: masa preparada antes de abrir, una segunda persona en la línea (hoja «Refuerzo por Pico») y, si no basta, más línea: el veredicto de arriba te dice cuándo.
A27: Versión 1.0 · octubre 2026 · aichef.pro/guia-churreria-chocolateria · info@aichef.pro

Sheet Cola del Domingo
A1: Cola del Domingo
A2: AI Chef Pro · aichef.pro — Cómo Montar una Churrería-Chocolatería
A3: El domingo por la mañana es el día punta del día punta. Mes a mes, las raciones por hora que la línea no llega a servir en esa hora.
A6: Mes | B6: Coeficiente | C6: Raciones del domingo | D6: Hora punta del domingo (raciones/h) | E6: Capacidad de la línea (raciones/h) | F6: COLA: raciones por hora que no llegas a servir | G6: ¿Hay cola? | H6: Espera al final de la hora punta (minutos) | I6: Nota
A7: Enero | B7: ='Peso sobre el Año'!$B$18 -> 1.25 | C7: =IFERROR('Franjas del Día'!$C$12*B7,"") -> 500 | D7: =IFERROR('Franjas del Día'!$H$12*B7,"") -> 93.75 | E7: ='Parámetros'!$B$9 -> 122.55136 | F7: =IF(AND(ISNUMBER(D7),ISNUMBER(E7)),MAX(0,D7-E7),"") -> 0 | G7: =IF(NOT(ISNUMBER(F7)),"",IF(F7>0,"Sí","No")) -> No | H7: =IFERROR(F7/E7*'Parámetros'!$B$27,"") -> 0 | I7: Diciembre y enero son Navidad y Reyes: los domingos y festivos de esas semanas son los de más cola del año.
A8: Febrero | B8: ='Peso sobre el Año'!$B$19 -> 1.15 | C8: =IFERROR('Franjas del Día'!$C$12*B8,"") -> 460 | D8: =IFERROR('Franjas del Día'!$H$12*B8,"") -> 86.25 | E8: ='Parámetros'!$B$9 -> 122.55136 | F8: =IF(AND(ISNUMBER(D8),ISNUMBER(E8)),MAX(0,D8-E8),"") -> 0 | G8: =IF(NOT(ISNUMBER(F8)),"",IF(F8>0,"Sí","No")) -> No | H8: =IFERROR(F8/E8*'Parámetros'!$B$27,"") -> 0
A9: Marzo | B9: ='Peso sobre el Año'!$B$20 -> 1.1 | C9: =IFERROR('Franjas del Día'!$C$12*B9,"") -> 440 | D9: =IFERROR('Franjas del Día'!$H$12*B9,"") -> 82.5 | E9: ='Parámetros'!$B$9 -> 122.55136 | F9: =IF(AND(ISNUMBER(D9),ISNUMBER(E9)),MAX(0,D9-E9),"") -> 0 | G9: =IF(NOT(ISNUMBER(F9)),"",IF(F9>0,"Sí","No")) -> No | H9: =IFERROR(F9/E9*'Parámetros'!$B$27,"") -> 0
A10: Abril | B10: ='Peso sobre el Año'!$B$21 -> 0.95 | C10: =IFERROR('Franjas del Día'!$C$12*B10,"") -> 380 | D10: =IFERROR('Franjas del Día'!$H$12*B10,"") -> 71.25 | E10: ='Parámetros'!$B$9 -> 122.55136 | F10: =IF(AND(ISNUMBER(D10),ISNUMBER(E10)),MAX(0,D10-E10),"") -> 0 | G10: =IF(NOT(ISNUMBER(F10)),"",IF(F10>0,"Sí","No")) -> No | H10: =IFERROR(F10/E10*'Parámetros'!$B$27,"") -> 0 | I10: La cola sale de la franja más cargada del domingo (hoja «Franjas del Día», fila del domingo) por el coeficiente del mes, frente a la capacidad de la línea copiada del libro 1.
A11: Mayo | B11: ='Peso sobre el Año'!$B$22 -> 0.85 | C11: =IFERROR('Franjas del Día'!$C$12*B11,"") -> 340 | D11: =IFERROR('Franjas del Día'!$H$12*B11,"") -> 63.75 | E11: ='Parámetros'!$B$9 -> 122.55136 | F11: =IF(AND(ISNUMBER(D11),ISNUMBER(E11)),MAX(0,D11-E11),"") -> 0 | G11: =IF(NOT(ISNUMBER(F11)),"",IF(F11>0,"Sí","No")) -> No | H11: =IFERROR(F11/E11*'Parámetros'!$B$27,"") -> 0
A12: Junio | B12: ='Peso sobre el Año'!$B$23 -> 0.7 | C12: =IFERROR('Franjas del Día'!$C$12*B12,"") -> 280 | D12: =IFERROR('Franjas del Día'!$H$12*B12,"") -> 52.5 | E12: ='Parámetros'!$B$9 -> 122.55136 | F12: =IF(AND(ISNUMBER(D12),ISNUMBER(E12)),MAX(0,D12-E12),"") -> 0 | G12: =IF(NOT(ISNUMBER(F12)),"",IF(F12>0,"Sí","No")) -> No | H12: =IFERROR(F12/E12*'Parámetros'!$B$27,"") -> 0
A13: Julio | B13: ='Peso sobre el Año'!$B$24 -> 0.55 | C13: =IFERROR('Franjas del Día'!$C$12*B13,"") -> 220 | D13: =IFERROR('Franjas del Día'!$H$12*B13,"") -> 41.25 | E13: ='Parámetros'!$B$9 -> 122.55136 | F13: =IF(AND(ISNUMBER(D13),ISNUMBER(E13)),MAX(0,D13-E13),"") -> 0 | G13: =IF(NOT(ISNUMBER(F13)),"",IF(F13>0,"Sí","No")) -> No | H13: =IFERROR(F13/E13*'Parámetros'!$B$27,"") -> 0
A14: Agosto | B14: ='Peso sobre el Año'!$B$25 -> 0.5 | C14: =IFERROR('Franjas del Día'!$C$12*B14,"") -> 200 | D14: =IFERROR('Franjas del Día'!$H$12*B14,"") -> 37.5 | E14: ='Parámetros'!$B$9 -> 122.55136 | F14: =IF(AND(ISNUMBER(D14),ISNUMBER(E14)),MAX(0,D14-E14),"") -> 0 | G14: =IF(NOT(ISNUMBER(F14)),"",IF(F14>0,"Sí","No")) -> No | H14: =IFERROR(F14/E14*'Parámetros'!$B$27,"") -> 0
A15: Septiembre | B15: ='Peso sobre el Año'!$B$26 -> 0.8 | C15: =IFERROR('Franjas del Día'!$C$12*B15,"") -> 320 | D15: =IFERROR('Franjas del Día'!$H$12*B15,"") -> 60 | E15: ='Parámetros'!$B$9 -> 122.55136 | F15: =IF(AND(ISNUMBER(D15),ISNUMBER(E15)),MAX(0,D15-E15),"") -> 0 | G15: =IF(NOT(ISNUMBER(F15)),"",IF(F15>0,"Sí","No")) -> No | H15: =IFERROR(F15/E15*'Parámetros'!$B$27,"") -> 0
A16: Octubre | B16: ='Peso sobre el Año'!$B$27 -> 1.1 | C16: =IFERROR('Franjas del Día'!$C$12*B16,"") -> 440 | D16: =IFERROR('Franjas del Día'!$H$12*B16,"") -> 82.5 | E16: ='Parámetros'!$B$9 -> 122.55136 | F16: =IF(AND(ISNUMBER(D16),ISNUMBER(E16)),MAX(0,D16-E16),"") -> 0 | G16: =IF(NOT(ISNUMBER(F16)),"",IF(F16>0,"Sí","No")) -> No | H16: =IFERROR(F16/E16*'Parámetros'!$B$27,"") -> 0
A17: Noviembre | B17: ='Peso sobre el Año'!$B$28 -> 1.3 | C17: =IFERROR('Franjas del Día'!$C$12*B17,"") -> 520 | D17: =IFERROR('Franjas del Día'!$H$12*B17,"") -> 97.5 | E17: ='Parámetros'!$B$9 -> 122.55136 | F17: =IF(AND(ISNUMBER(D17),ISNUMBER(E17)),MAX(0,D17-E17),"") -> 0 | G17: =IF(NOT(ISNUMBER(F17)),"",IF(F17>0,"Sí","No")) -> No | H17: =IFERROR(F17/E17*'Parámetros'!$B$27,"") -> 0
A18: Diciembre | B18: ='Peso sobre el Año'!$B$29 -> 1.75 | C18: =IFERROR('Franjas del Día'!$C$12*B18,"") -> 700 | D18: =IFERROR('Franjas del Día'!$H$12*B18,"") -> 131.25 | E18: ='Parámetros'!$B$9 -> 122.55136 | F18: =IF(AND(ISNUMBER(D18),ISNUMBER(E18)),MAX(0,D18-E18),"") -> 8.6986383 | G18: =IF(NOT(ISNUMBER(F18)),"",IF(F18>0,"Sí","No")) -> Sí | H18: =IFERROR(F18/E18*'Parámetros'!$B$27,"") -> 4.2587719
A20: Meses con cola el domingo | E20: =COUNTIF(G7:G18,"Sí") -> 1
A21: Peor cola del año (raciones/h) | E21: =MAX(F7:F18) -> 8.6986383
A22: Mes de la peor cola | E22: =IF(NOT(ISNUMBER(E21)),"",IF(E21>0,INDEX(A7:A18,MATCH(E21,F7:F18,0)),"Ninguno")) -> Diciembre
A24: La cola no se arregla subiendo el precio: se arregla con masa preparada antes de abrir y con una segunda persona en la línea en esas mañanas. Las horas de ese refuerzo están en la hoja «Refuerzo por Pico».
A26: Versión 1.0 · octubre 2026 · aichef.pro/guia-churreria-chocolateria · info@aichef.pro

Sheet Refuerzo por Pico
A1: Refuerzo por Pico
A2: AI Chef Pro · aichef.pro — Cómo Montar una Churrería-Chocolatería
A3: Las horas de refuerzo de Navidad y Reyes, por encima del medio refuerzo fijo de los fines de semana (que está en la plantilla del libro 8), y lo que cuestan.
A4: El Refuerzo de Navidad y Reyes | K4: Lo que Copian Otros Libros (No Muevas Estas Celdas)
A5: Días punta de Navidad y Reyes con una persona más por la mañana | B5: 8 | C5: días | E5: supuesto declarado de El Molinete. Días punta de Navidad y Reyes con una persona más en la mañana, por encima del medio refuerzo fijo. | K5: Horas de refuerzo de Navidad y Reyes al año | L5: =B8 -> 56 | M5: Lo copia: libro 8 (turnos-plantilla-y-madrugada.xlsx, hoja Parámetros, X7)
A6: Horas de refuerzo cada uno de esos días | B6: 7 | C6: h/día | E6: supuesto declarado de El Molinete. De 6:00 a 13:00.
A7: Coste hora de mano de obra (copiado del libro 3) | B7: ='Parámetros'!$B$14 -> 13.243843 | C7: EUR/h
A8: HORAS DE REFUERZO AL AÑO | B8: =IFERROR(B5*B6,"") -> 56 | C8: h/año | E8: Las copia el libro 8 (bloque de la derecha) para el coste de la plantilla.
A9: Lo que cuesta ese refuerzo al año | B9: =IFERROR(B8*B7,"") -> 741.6552 | C9: EUR/año
A10: Peor cola del domingo del año (hoja «Cola del Domingo») | B10: ='Cola del Domingo'!$E$21 -> 8.6986383 | C10: raciones/h
A11: ¿Lo pide la cola? | B11: =IF(NOT(ISNUMBER(B10)),"",IF(B10>0,"Hay cola en algún domingo: el refuerzo tiene sentido","No hay cola en ningún domingo: revisa si necesitas el refuerzo")) -> Hay cola en algún domingo: el refuerzo tiene sentido
A13: Mes | B13: Cola del domingo (raciones/h) | C13: ¿Hay cola? | D13: Temporada | E13: Qué hacer
A14: Enero | B14: ='Cola del Domingo'!F7 -> 0 | C14: ='Cola del Domingo'!G7 -> No | D14: ='Peso sobre el Año'!C18 -> Temporada alta | E14: =IF(C14="Sí","Una persona más en la línea los domingos y festivos por la mañana",IF(D14="Temporada alta","Vigila la cola: estás cerca","Sin refuerzo")) -> Vigila la cola: estás cerca
A15: Febrero | B15: ='Cola del Domingo'!F8 -> 0 | C15: ='Cola del Domingo'!G8 -> No | D15: ='Peso sobre el Año'!C19 -> Temporada alta | E15: =IF(C15="Sí","Una persona más en la línea los domingos y festivos por la mañana",IF(D15="Temporada alta","Vigila la cola: estás cerca","Sin refuerzo")) -> Vigila la cola: estás cerca
A16: Marzo | B16: ='Cola del Domingo'!F9 -> 0 | C16: ='Cola del Domingo'!G9 -> No | D16: ='Peso sobre el Año'!C20 -> Temporada alta | E16: =IF(C16="Sí","Una persona más en la línea los domingos y festivos por la mañana",IF(D16="Temporada alta","Vigila la cola: estás cerca","Sin refuerzo")) -> Vigila la cola: estás cerca
A17: Abril | B17: ='Cola del Domingo'!F10 -> 0 | C17: ='Cola del Domingo'!G10 -> No | D17: ='Peso sobre el Año'!C21 -> Media | E17: =IF(C17="Sí","Una persona más en la línea los domingos y festivos por la mañana",IF(D17="Temporada alta","Vigila la cola: estás cerca","Sin refuerzo")) -> Sin refuerzo
A18: Mayo | B18: ='Cola del Domingo'!F11 -> 0 | C18: ='Cola del Domingo'!G11 -> No | D18: ='Peso sobre el Año'!C22 -> Media | E18: =IF(C18="Sí","Una persona más en la línea los domingos y festivos por la mañana",IF(D18="Temporada alta","Vigila la cola: estás cerca","Sin refuerzo")) -> Sin refuerzo
A19: Junio | B19: ='Cola del Domingo'!F12 -> 0 | C19: ='Cola del Domingo'!G12 -> No | D19: ='Peso sobre el Año'!C23 -> Media | E19: =IF(C19="Sí","Una persona más en la línea los domingos y festivos por la mañana",IF(D19="Temporada alta","Vigila la cola: estás cerca","Sin refuerzo")) -> Sin refuerzo
A20: Julio | B20: ='Cola del Domingo'!F13 -> 0 | C20: ='Cola del Domingo'!G13 -> No | D20: ='Peso sobre el Año'!C24 -> Valle | E20: =IF(C20="Sí","Una persona más en la línea los domingos y festivos por la mañana",IF(D20="Temporada alta","Vigila la cola: estás cerca","Sin refuerzo")) -> Sin refuerzo
A21: Agosto | B21: ='Cola del Domingo'!F14 -> 0 | C21: ='Cola del Domingo'!G14 -> No | D21: ='Peso sobre el Año'!C25 -> Valle | E21: =IF(C21="Sí","Una persona más en la línea los domingos y festivos por la mañana",IF(D21="Temporada alta","Vigila la cola: estás cerca","Sin refuerzo")) -> Sin refuerzo
A22: Septiembre | B22: ='Cola del Domingo'!F15 -> 0 | C22: ='Cola del Domingo'!G15 -> No | D22: ='Peso sobre el Año'!C26 -> Media | E22: =IF(C22="Sí","Una persona más en la línea los domingos y festivos por la mañana",IF(D22="Temporada alta","Vigila la cola: estás cerca","Sin refuerzo")) -> Sin refuerzo
A23: Octubre | B23: ='Cola del Domingo'!F16 -> 0 | C23: ='Cola del Domingo'!G16 -> No | D23: ='Peso sobre el Año'!C27 -> Temporada alta | E23: =IF(C23="Sí","Una persona más en la línea los domingos y festivos por la mañana",IF(D23="Temporada alta","Vigila la cola: estás cerca","Sin refuerzo")) -> Vigila la cola: estás cerca
A24: Noviembre | B24: ='Cola del Domingo'!F17 -> 0 | C24: ='Cola del Domingo'!G17 -> No | D24: ='Peso sobre el Año'!C28 -> Temporada alta | E24: =IF(C24="Sí","Una persona más en la línea los domingos y festivos por la mañana",IF(D24="Temporada alta","Vigila la cola: estás cerca","Sin refuerzo")) -> Vigila la cola: estás cerca
A25: Diciembre | B25: ='Cola del Domingo'!F18 -> 8.6986383 | C25: ='Cola del Domingo'!G18 -> Sí | D25: ='Peso sobre el Año'!C29 -> Temporada alta | E25: =IF(C25="Sí","Una persona más en la línea los domingos y festivos por la mañana",IF(D25="Temporada alta","Vigila la cola: estás cerca","Sin refuerzo")) -> Una persona más en la línea los domingos y festivos por la mañana
A27: El medio refuerzo fijo de los sábados y domingos ya está en la plantilla de El Molinete (libro 8). Aquí sólo van las horas de más de Navidad y Reyes. El coste hora es el del escandallo del libro 3: si el libro 8 te da otro, cuadra los dos.
A29: Versión 1.0 · octubre 2026 · aichef.pro/guia-churreria-chocolateria · info@aichef.pro

Sheet El Verano (Tres Salidas)
A1: El Verano (Tres Salidas)
A2: AI Chef Pro · aichef.pro — Cómo Montar una Churrería-Chocolatería
A3: Julio y agosto: cerrar, abrir con carta de verano o salir de ferias. Se comparan por lo que DEJAN en euros; lo que pagas igual en las tres lo resta el libro 6.
K4: Lo que Copian Otros Libros (No Muevas Estas Celdas)
K5: Contribución de julio y agosto de la salida que eliges | L5: =B21 -> 17368.709 | M5: Lo copia: libro 6 (plan-financiero-3-anos-churreria.xlsx, hoja 0. Supuestos, X16)
A6: Concepto | B6: Salida 1 | C6: Salida 2 | D6: Salida 3 | E6: Nota | K6: Contribución de julio y agosto si cierras | L6: =B16 -> 0 | M6: Lo copia: libro 6 (plan-financiero-3-anos-churreria.xlsx, hoja 0. Supuestos, X16 bis)
A7: Salida | B7: Cerrar | C7: Carta de verano | D7: Ferias | K7: Contribución de julio y agosto con carta de verano | L7: =C16 -> 17368.709 | M7: Lo copia: libro 6 (plan-financiero-3-anos-churreria.xlsx, hoja 0. Supuestos, X16 bis)
A8: ¿Abre el local en julio y agosto? (1 sí, 0 no) | B8: 0 | C8: 1 | D8: 0 | E8: Cerrar y salir de ferias dejan el local cerrado; la carta de verano lo abre. | K8: Contribución de julio y agosto con ferias | L8: =D16 -> 2106.4537 | M8: Lo copia: libro 6 (plan-financiero-3-anos-churreria.xlsx, hoja 0. Supuestos, X16 bis)
A9: ¿Sale a las ferias de julio y agosto? (1 sí, 0 no) | B9: 0 | C9: 0 | D9: 1 | E9: Las de la hoja «Punto Muerto por Evento» cuyo mes es uno de los dos del verano. | K9: Ventas sin IVA de julio y agosto de la salida que eliges | L9: =IFERROR(INDEX($B$12:$D$12,MATCH(B20,$B$7:$D$7,0)),"") -> 20737.72 | M9: Lo copia: libro 6 (plan-financiero-3-anos-churreria.xlsx, hoja 0. Supuestos, X16 ter)
A10: Horas de personal extra del local en julio y agosto | B10: 0 | C10: 0 | D10: 0 | E10: Si la carta de verano necesita a alguien más (heladería, terraza). En El Molinete, ninguna.
A11: Raciones que vende el local | B11: =IFERROR(B8*'Peso sobre el Año'!$B$35,"") -> 0 | C11: =IFERROR(C8*'Peso sobre el Año'!$B$35,"") -> 9397.5 | D11: =IFERROR(D8*'Peso sobre el Año'!$B$35,"") -> 0 | E11: Las de julio y agosto de «Peso sobre el Año».
A12: Ventas del local sin IVA | B12: =IFERROR(B11*'Parámetros'!$B$11,"") -> 0 | C12: =IFERROR(C11*'Parámetros'!$B$11,"") -> 20737.72 | D12: =IFERROR(D11*'Parámetros'!$B$11,"") -> 0 | E12: Raciones por el ticket de verano del libro 3.
A13: Materia de esas raciones (aceite absorbido incluido) | B13: =IFERROR(B11*'Parámetros'!$B$12,"") -> 0 | C13: =IFERROR(C11*'Parámetros'!$B$12,"") -> 3369.0105 | D13: =IFERROR(D11*'Parámetros'!$B$12,"") -> 0 | E13: Raciones por la materia de verano del libro 3.
A14: Personal extra del local | B14: =IFERROR(B10*'Parámetros'!$B$14,"") -> 0 | C14: =IFERROR(C10*'Parámetros'!$B$14,"") -> 0 | D14: =IFERROR(D10*'Parámetros'!$B$14,"") -> 0 | E14: Horas extra por el coste hora del libro 3.
A15: Lo que dejan las ferias de julio y agosto | B15: =IFERROR(B9*'Punto Muerto por Evento'!$B$39,"") -> 0 | C15: =IFERROR(C9*'Punto Muerto por Evento'!$B$39,"") -> 0 | D15: =IFERROR(D9*'Punto Muerto por Evento'!$B$39,"") -> 2106.4537 | E15: Ya descontadas su materia, sus tasas, el desplazamiento, el montaje y su personal.
A16: CONTRIBUCIÓN DE JULIO Y AGOSTO | B16: =IFERROR(B12-B13-B14+B15,"") -> 0 | C16: =IFERROR(C12-C13-C14+C15,"") -> 17368.709 | D16: =IFERROR(D12-D13-D14+D15,"") -> 2106.4537 | E16: Ventas menos materia menos personal extra, más lo que dejan las ferias. Cerrar deja cero: lo que pagas aun cerrado lo resta el libro 6.
A17: ¿La que más deja? | B17: =IF(NOT(ISNUMBER(B16)),"",IF(B16=MAX($B$16:$D$16),"La que más deja","")) | C17: =IF(NOT(ISNUMBER(C16)),"",IF(C16=MAX($B$16:$D$16),"La que más deja","")) -> La que más deja | D17: =IF(NOT(ISNUMBER(D16)),"",IF(D16=MAX($B$16:$D$16),"La que más deja",""))
A19: La Salida que Eliges (lo que Copia el Libro 6)
A20: La salida que eliges | B20: Carta de verano | E20: El Molinete elige la carta de verano (decisión 9).
A21: CONTRIBUCIÓN DE JULIO Y AGOSTO DE LA SALIDA QUE ELIGES | B21: =IFERROR(INDEX($B$16:$D$16,MATCH(B20,$B$7:$D$7,0)),"") -> 17368.709 | E21: La copia el libro 6 (bloque de la derecha, L5): la resta de dos meses de lo que pagas igual la hace él, en «Escenarios».
A22: La salida que más deja | B22: =IFERROR(INDEX($B$7:$D$7,MATCH(MAX($B$16:$D$16),$B$16:$D$16,0)),"") -> Carta de verano
A23: ¿Eliges la que más deja? | B23: =IF(OR(B20="",B22=""),"",IF(B20=B22,"Eliges la que más deja en julio y agosto","REVISA: hay otra salida que deja más en julio y agosto")) -> Eliges la que más deja en julio y agosto
A24: Raciones al día del local por debajo de las cuales la carta de verano deja menos que salir de ferias | B24: =IFERROR(D16/('Parámetros'!$B$11-'Parámetros'!$B$12)/'Parámetros'!$B$23,"") -> 18.382519 | C24: raciones/día | E24: Lo que dejan las ferias del verano entre lo que deja una ración de carta de verano, repartido entre los días de julio y agosto.
A26: Por qué cerrar deja cero y no un número negativo: lo que pagas igual abras o cierres (el local, la plantilla fija, los seguros, las cuotas) es lo mismo en las tres salidas, así que no cambia cuál gana. El libro 6 enseña cada salida con todo eso restado, en su hoja «Escenarios».
A28: Versión 1.0 · octubre 2026 · aichef.pro/guia-churreria-chocolateria · info@aichef.pro

Sheet Punto Muerto por Evento
A1: Punto Muerto por Evento
A2: AI Chef Pro · aichef.pro — Cómo Montar una Churrería-Chocolatería
