Workbook

Sheet Instructions
B2: 12 · Bakery Allergen Chart (9 Major Allergens, UK 14): Matrix, Chart, Case Sign & Labels
B4: This template is delivered as a DRAFT. The symbols come pre-marked in gray as a starting proposal. Do not publish or show anything without checking each item against your actual recipe and your suppliers' spec sheets. The business is responsible for the information.
B6: What the law requires:
B7: ▸ US law: the 9 major allergens (FALCPA + FASTER Act) on packaged food; on unpackaged items (bakery case, counter), written notice per the FDA Food Code 2022 3-602.12(C) where your state has adopted it. UK: 14 allergens (Food Information Regulations 2014).
B8: ▸ For unpackaged products, the information must be IN WRITING and accessible before purchase (3-602.12(C): handout, sign, case label or menu).
B9: ▸ A "may contain" statement is voluntary and must be truthful: it does not replace declaring the allergens you use on purpose.
B11: How to use this template:
B12: ▸ Sheet "Allergen Matrix": go through it item by item. Mark ● if the product contains it and ○ if it may contain traces through cross-contact in your kitchen.
B13: ▸ Record the supplier and the spec sheet number backing each decision, enter the verification date and sign. Until you enter the date, the Status column says DO NOT PUBLISH.
B14: ▸ The Verification notes column tells you what to check on items where the symbol depends on the brand or recipe: pain aux raisins and candied fruit (sulfites, declared at 10 ppm or more), almond nougat / torrone (egg white), chocolate coatings and chips (soy lecithin), polvorones (sesame and butter).
B15: ▸ The cross-contact sentence on the sign and the chart is in a green cell: replace the list with the allergens actually handled in your kitchen. Declaring "all 9" (or "all 14") when you don't work with fish or shellfish is the generic "may contain" that doesn't help.
B16: ▸ Sheet "Allergen Chart": it fills itself in from the matrix. It is the document you show the customer and the one the health inspector asks for. Print it when no item is left unverified.
... B32: Version 2.0 · October 2026 · aichef.pro/en/digital-products/pastry-shop-checklist-templates · info@aichef.pro

Sheet Allergen Matrix
A1: Bakery Case Allergen Matrix — Working Draft
A2: STARTER TEMPLATE — DO NOT PUBLISH IT WITHOUT VERIFYING IT. The symbols come pre-marked in gray as a proposal: check each item against YOUR actual recipe and your suppliers' spec sheets before showing anything to a customer.
A3: ● contains ○ may contain traces empty cell does not contain Gray symbols are the starting proposal; rewrite them when you verify.
A4: Product | B4: Category | C4: Wheat (gluten) | D4: Shellfish | E4: Eggs | F4: Fish | G4: Peanuts | H4: Soy | I4: Milk | J4: Tree nuts | K4: Celery (UK) | L4: Mustard (UK) | M4: Sesame | N4: Sulfites | O4: Lupin (UK) | P4: Mollusks (UK) | Q4: Total ● | R4: Supplier / Spec sheet # | S4: Verified against spec sheet (date) | T4: Initials | U4: Status | V4: Verification notes
A5: Butter croissant | B5: Viennoiserie | C5: ● | E5: ● | H5: ○ | I5: ● | J5: ○ | M5: ○ | Q5: =COUNTIF(C5:P5,"●") -> 3 | U5: =IF($S5="","DO NOT PUBLISH","Verified") -> DO NOT PUBLISH
A6: Pain au chocolat | B6: Viennoiserie | C6: ● | E6: ● | H6: ● | I6: ● | J6: ○ | Q6: =COUNTIF(C6:P6,"●") -> 4 | U6: =IF($S6="","DO NOT PUBLISH","Verified") -> DO NOT PUBLISH
A7: Custard danish | B7: Viennoiserie | C7: ● | E7: ● | H7: ○ | I7: ● | J7: ○ | Q7: =COUNTIF(C7:P7,"●") -> 3 | U7: =IF($S7="","DO NOT PUBLISH","Verified") -> DO NOT PUBLISH
A8: Concha (pan dulce) | B8: Viennoiserie | C8: ● | E8: ● | H8: ○ | I8: ● | J8: ○ | Q8: =COUNTIF(C8:P8,"●") -> 3 | U8: =IF($S8="","DO NOT PUBLISH","Verified") -> DO NOT PUBLISH
A9: Brioche | B9: Viennoiserie | C9: ● | E9: ● | H9: ○ | I9: ● | J9: ○ | Q9: =COUNTIF(C9:P9,"●") -> 3 | U9: =IF($S9="","DO NOT PUBLISH","Verified") -> DO NOT PUBLISH
A10: Pain aux raisins | B10: Viennoiserie | C10: ● | E10: ● | H10: ○ | I10: ● | J10: ○ | N10: ● | Q10: =COUNTIF(C10:P10,"●") -> 4 | U10: =IF($S10="","DO NOT PUBLISH","Verified") -> DO NOT PUBLISH | V10: Sulfites: raisins are often sulfited; declared at 10 ppm or more (check the spec sheet).
A11: Palmier | B11: Viennoiserie | C11: ● | E11: ○ | H11: ○ | I11: ● | J11: ○ | Q11: =COUNTIF(C11:P11,"●") -> 2 | U11: =IF($S11="","DO NOT PUBLISH","Verified") -> DO NOT PUBLISH
A12: Cream-filled croissant | B12: Viennoiserie | C12: ● | E12: ● | H12: ○ | I12: ● | J12: ○ | Q12: =COUNTIF(C12:P12,"●") -> 3 | U12: =IF($S12="","DO NOT PUBLISH","Verified") -> DO NOT PUBLISH
A13: Cheesecake | B13: Cakes & pastries | C13: ● | E13: ● | H13: ○ | I13: ● | J13: ○ | Q13: =COUNTIF(C13:P13,"●") -> 3 | U13: =IF($S13="","DO NOT PUBLISH","Verified") -> DO NOT PUBLISH
A14: Apple pie | B14: Cakes & pastries | C14: ● | E14: ● | I14: ● | J14: ○ | N14: ○ | Q14: =COUNTIF(C14:P14,"●") -> 3 | U14: =IF($S14="","DO NOT PUBLISH","Verified") -> DO NOT PUBLISH
A15: Napoleon | B15: Cakes & pastries | C15: ● | E15: ● | H15: ○ | I15: ● | J15: ○ | Q15: =COUNTIF(C15:P15,"●") -> 3 | U15: =IF($S15="","DO NOT PUBLISH","Verified") -> DO NOT PUBLISH
A16: Eclair | B16: Cakes & pastries | C16: ● | E16: ● | H16: ○ | I16: ● | J16: ○ | Q16: =COUNTIF(C16:P16,"●") -> 3 | U16: =IF($S16="","DO NOT PUBLISH","Verified") -> DO NOT PUBLISH
A17: Carrot cake | B17: Cakes & pastries | C17: ● | E17: ● | H17: ○ | I17: ● | J17: ● | Q17: =COUNTIF(C17:P17,"●") -> 4 | U17: =IF($S17="","DO NOT PUBLISH","Verified") -> DO NOT PUBLISH
A18: Chocolate layer cake | B18: Cakes & pastries | C18: ● | E18: ● | H18: ● | I18: ● | J18: ○ | Q18: =COUNTIF(C18:P18,"●") -> 4 | U18: =IF($S18="","DO NOT PUBLISH","Verified") -> DO NOT PUBLISH
A19: Individual mousse cake | B19: Cakes & pastries | C19: ● | E19: ● | H19: ● | I19: ● | J19: ○ | Q19: =COUNTIF(C19:P19,"●") -> 4 | U19: =IF($S19="","DO NOT PUBLISH","Verified") -> DO NOT PUBLISH
A20: French macarons (box of 6) | B20: Cakes & pastries | C20: ○ | E20: ● | H20: ○ | I20: ● | J20: ● | Q20: =COUNTIF(C20:P20,"●") -> 3 | U20: =IF($S20="","DO NOT PUBLISH","Verified") -> DO NOT PUBLISH | V20: Tree nuts: almond as a main ingredient is never a trace.
A21: Fresh fruit tart | B21: Cakes & pastries | C21: ● | E21: ● | I21: ● | J21: ○ | N21: ○ | Q21: =COUNTIF(C21:P21,"●") -> 3 | U21: =IF($S21="","DO NOT PUBLISH","Verified") -> DO NOT PUBLISH
A22: Cream puff | B22: Cakes & pastries | C22: ● | E22: ● | H22: ○ | I22: ● | J22: ○ | Q22: =COUNTIF(C22:P22,"●") -> 3 | U22: =IF($S22="","DO NOT PUBLISH","Verified") -> DO NOT PUBLISH
A23: Three Kings bread (rosca) | B23: Seasonal | C23: ● | E23: ● | H23: ○ | I23: ● | J23: ● | N23: ● | Q23: =COUNTIF(C23:P23,"●") -> 5 | U23: =IF($S23="","DO NOT PUBLISH","Verified") -> DO NOT PUBLISH | V23: Sulfites: check the spec sheet of the candied fruit and the ate (quince or guava paste).
A24: Hot cross buns | B24: Seasonal | C24: ● | E24: ● | I24: ● | J24: ○ | N24: ● | Q24: =COUNTIF(C24:P24,"●") -> 4 | U24: =IF($S24="","DO NOT PUBLISH","Verified") -> DO NOT PUBLISH | V24: Sulfites: candied peel and raisins are usually sulfited (10 ppm or more): declare them as an ingredient (●), not as a trace.
A25: Paczki (filled doughnuts) | B25: Seasonal | C25: ● | E25: ● | H25: ○ | I25: ● | J25: ○ | Q25: =COUNTIF(C25:P25,"●") -> 3 | U25: =IF($S25="","DO NOT PUBLISH","Verified") -> DO NOT PUBLISH
A26: Amaretti cookies | B26: Seasonal | C26: ○ | E26: ● | I26: ○ | J26: ● | Q26: =COUNTIF(C26:P26,"●") -> 2 | U26: =IF($S26="","DO NOT PUBLISH","Verified") -> DO NOT PUBLISH
A27: Pignoli cookies | B27: Seasonal | C27: ○ | E27: ● | I27: ○ | J27: ● | Q27: =COUNTIF(C27:P27,"●") -> 2 | U27: =IF($S27="","DO NOT PUBLISH","Verified") -> DO NOT PUBLISH
A28: Polvorones (Mexican wedding cookies) | B28: Seasonal | C28: ● | E28: ○ | I28: ● | J28: ● | M28: ○ | Q28: =COUNTIF(C28:P28,"●") -> 3 | U28: =IF($S28="","DO NOT PUBLISH","Verified") -> DO NOT PUBLISH | V28: Milk: Mexican wedding cookies are usually made with butter (●); only with lard or shortening is it ○. Sesame: some polvorones contain it — check yours.
A29: Almond nougat (torrone) | B29: Seasonal | E29: ● | H29: ○ | I29: ○ | J29: ● | M29: ○ | Q29: =COUNTIF(C29:P29,"●") -> 2 | U29: =IF($S29="","DO NOT PUBLISH","Verified") -> DO NOT PUBLISH | V29: Egg white: hard torrone contains it; some soft nougats don't — check the recipe or brand.
A30: Chocolate Easter cake | B30: Seasonal | C30: ● | E30: ● | H30: ● | I30: ● | J30: ○ | Q30: =COUNTIF(C30:P30,"●") -> 4 | U30: =IF($S30="","DO NOT PUBLISH","Verified") -> DO NOT PUBLISH
A31: Brownie | B31: Cookies & small cakes | C31: ● | E31: ● | H31: ● | I31: ● | J31: ● | Q31: =COUNTIF(C31:P31,"●") -> 5 | U31: =IF($S31="","DO NOT PUBLISH","Verified") -> DO NOT PUBLISH | V31: Soy: lecithin in the chocolate coating — check your coating's spec sheet.
A32: Chocolate chip cookie | B32: Cookies & small cakes | C32: ● | E32: ● | H32: ● | I32: ● | J32: ○ | Q32: =COUNTIF(C32:P32,"●") -> 4 | U32: =IF($S32="","DO NOT PUBLISH","Verified") -> DO NOT PUBLISH | V32: Soy: lecithin in the chocolate chips — check the spec sheet.
A33: Muffin | B33: Cookies & small cakes | C33: ● | E33: ● | H33: ○ | I33: ● | J33: ○ | Q33: =COUNTIF(C33:P33,"●") -> 3 | U33: =IF($S33="","DO NOT PUBLISH","Verified") -> DO NOT PUBLISH
A34: Pound cake | B34: Cookies & small cakes | C34: ● | E34: ● | H34: ○ | I34: ● | J34: ○ | Q34: =COUNTIF(C34:P34,"●") -> 3 | U34: =IF($S34="","DO NOT PUBLISH","Verified") -> DO NOT PUBLISH
A35: Butter cookie | B35: Cookies & small cakes | C35: ● | E35: ● | H35: ○ | I35: ● | J35: ○ | Q35: =COUNTIF(C35:P35,"●") -> 3 | U35: =IF($S35="","DO NOT PUBLISH","Verified") -> DO NOT PUBLISH
A36: Almond financier | B36: Cookies & small cakes | C36: ● | E36: ● | H36: ○ | I36: ● | J36: ● | Q36: =COUNTIF(C36:P36,"●") -> 4 | U36: =IF($S36="","DO NOT PUBLISH","Verified") -> DO NOT PUBLISH
A37: Quiche | B37: Savory | C37: ● | E37: ● | H37: ○ | I37: ● | K37: ○ | L37: ○ | Q37: =COUNTIF(C37:P37,"●") -> 3 | U37: =IF($S37="","DO NOT PUBLISH","Verified") -> DO NOT PUBLISH
A38: Tuna empanada | B38: Savory | C38: ● | E38: ○ | F38: ● | K38: ○ | N38: ○ | Q38: =COUNTIF(C38:P38,"●") -> 2 | U38: =IF($S38="","DO NOT PUBLISH","Verified") -> DO NOT PUBLISH | V38: Fish: only if the filling is tuna. Change the item if yours is meat.
A39: Ham & cheese croissant | B39: Savory | C39: ● | E39: ● | H39: ○ | I39: ● | L39: ○ | Q39: =COUNTIF(C39:P39,"●") -> 3 | U39: =IF($S39="","DO NOT PUBLISH","Verified") -> DO NOT PUBLISH | V39: Egg: it comes from the same egg-washed laminated dough as the butter croissant.
A40: Sandwich loaf | B40: Bread | C40: ● | H40: ○ | I40: ○ | M40: ○ | Q40: =COUNTIF(C40:P40,"●") -> 1 | U40: =IF($S40="","DO NOT PUBLISH","Verified") -> DO NOT PUBLISH
...

Sheet Allergen Chart
A1: Allergen Chart
A2: Business: ______________________________ Review date: ____/____/________
A3: Document to show the customer. It fills itself in from the sheet "Allergen Matrix": verify each item there before printing this chart. ● contains ○ may contain traces
A5: Product | B5: Wheat (gluten) | C5: Shellfish | D5: Eggs | E5: Fish | F5: Peanuts | G5: Soy | H5: Milk | I5: Tree nuts | J5: Celery (UK) | K5: Mustard (UK) | L5: Sesame | M5: Sulfites | N5: Lupin (UK) | O5: Mollusks (UK)
A6: =IF('Allergen Matrix'!A5="","",'Allergen Matrix'!A5) -> Butter croissant | B6: =IF('Allergen Matrix'!C5="","",'Allergen Matrix'!C5) -> ● | C6: =IF('Allergen Matrix'!D5="","",'Allergen Matrix'!D5) | D6: =IF('Allergen Matrix'!E5="","",'Allergen Matrix'!E5) -> ● | E6: =IF('Allergen Matrix'!F5="","",'Allergen Matrix'!F5) | F6: =IF('Allergen Matrix'!G5="","",'Allergen Matrix'!G5) | G6: =IF('Allergen Matrix'!H5="","",'Allergen Matrix'!H5) -> ○ | H6: =IF('Allergen Matrix'!I5="","",'Allergen Matrix'!I5) -> ● | I6: =IF('Allergen Matrix'!J5="","",'Allergen Matrix'!J5) -> ○ | ... O6: =IF('Allergen Matrix'!P5="","",'Allergen Matrix'!P5)
A7: =IF('Allergen Matrix'!A6="","",'Allergen Matrix'!A6) -> Pain au chocolat | B7: =IF('Allergen Matrix'!C6="","",'Allergen Matrix'!C6) -> ● | C7: =IF('Allergen Matrix'!D6="","",'Allergen Matrix'!D6) | D7: =IF('Allergen Matrix'!E6="","",'Allergen Matrix'!E6) -> ● | E7: =IF('Allergen Matrix'!F6="","",'Allergen Matrix'!F6) | F7: =IF('Allergen Matrix'!G6="","",'Allergen Matrix'!G6) | G7: =IF('Allergen Matrix'!H6="","",'Allergen Matrix'!H6) -> ● | H7: =IF('Allergen Matrix'!I6="","",'Allergen Matrix'!I6) -> ● | I7: =IF('Allergen Matrix'!J6="","",'Allergen Matrix'!J6) -> ○ | ... O7: =IF('Allergen Matrix'!P6="","",'Allergen Matrix'!P6)
A8: =IF('Allergen Matrix'!A7="","",'Allergen Matrix'!A7) -> Custard danish | B8: =IF('Allergen Matrix'!C7="","",'Allergen Matrix'!C7) -> ● | C8: =IF('Allergen Matrix'!D7="","",'Allergen Matrix'!D7) | D8: =IF('Allergen Matrix'!E7="","",'Allergen Matrix'!E7) -> ● | E8: =IF('Allergen Matrix'!F7="","",'Allergen Matrix'!F7) | F8: =IF('Allergen Matrix'!G7="","",'Allergen Matrix'!G7) | G8: =IF('Allergen Matrix'!H7="","",'Allergen Matrix'!H7) -> ○ | H8: =IF('Allergen Matrix'!I7="","",'Allergen Matrix'!I7) -> ● | I8: =IF('Allergen Matrix'!J7="","",'Allergen Matrix'!J7) -> ○ | ... O8: =IF('Allergen Matrix'!P7="","",'Allergen Matrix'!P7)
A9: =IF('Allergen Matrix'!A8="","",'Allergen Matrix'!A8) -> Concha (pan dulce) | B9: =IF('Allergen Matrix'!C8="","",'Allergen Matrix'!C8) -> ● | C9: =IF('Allergen Matrix'!D8="","",'Allergen Matrix'!D8) | D9: =IF('Allergen Matrix'!E8="","",'Allergen Matrix'!E8) -> ● | E9: =IF('Allergen Matrix'!F8="","",'Allergen Matrix'!F8) | F9: =IF('Allergen Matrix'!G8="","",'Allergen Matrix'!G8) | G9: =IF('Allergen Matrix'!H8="","",'Allergen Matrix'!H8) -> ○ | H9: =IF('Allergen Matrix'!I8="","",'Allergen Matrix'!I8) -> ● | I9: =IF('Allergen Matrix'!J8="","",'Allergen Matrix'!J8) -> ○ | ... O9: =IF('Allergen Matrix'!P8="","",'Allergen Matrix'!P8)
A10: =IF('Allergen Matrix'!A9="","",'Allergen Matrix'!A9) -> Brioche | B10: =IF('Allergen Matrix'!C9="","",'Allergen Matrix'!C9) -> ● | C10: =IF('Allergen Matrix'!D9="","",'Allergen Matrix'!D9) | D10: =IF('Allergen Matrix'!E9="","",'Allergen Matrix'!E9) -> ● | E10: =IF('Allergen Matrix'!F9="","",'Allergen Matrix'!F9) | F10: =IF('Allergen Matrix'!G9="","",'Allergen Matrix'!G9) | G10: =IF('Allergen Matrix'!H9="","",'Allergen Matrix'!H9) -> ○ | H10: =IF('Allergen Matrix'!I9="","",'Allergen Matrix'!I9) -> ● | I10: =IF('Allergen Matrix'!J9="","",'Allergen Matrix'!J9) -> ○ | ... O10: =IF('Allergen Matrix'!P9="","",'Allergen Matrix'!P9)
A11: =IF('Allergen Matrix'!A10="","",'Allergen Matrix'!A10) -> Pain aux raisins | B11: =IF('Allergen Matrix'!C10="","",'Allergen Matrix'!C10) -> ● | C11: =IF('Allergen Matrix'!D10="","",'Allergen Matrix'!D10) | D11: =IF('Allergen Matrix'!E10="","",'Allergen Matrix'!E10) -> ● | E11: =IF('Allergen Matrix'!F10="","",'Allergen Matrix'!F10) | F11: =IF('Allergen Matrix'!G10="","",'Allergen Matrix'!G10) | G11: =IF('Allergen Matrix'!H10="","",'Allergen Matrix'!H10) -> ○ | H11: =IF('Allergen Matrix'!I10="","",'Allergen Matrix'!I10) -> ● | I11: =IF('Allergen Matrix'!J10="","",'Allergen Matrix'!J10) -> ○ | ... O11: =IF('Allergen Matrix'!P10="","",'Allergen Matrix'!P10)
A12: =IF('Allergen Matrix'!A11="","",'Allergen Matrix'!A11) -> Palmier | B12: =IF('Allergen Matrix'!C11="","",'Allergen Matrix'!C11) -> ● | C12: =IF('Allergen Matrix'!D11="","",'Allergen Matrix'!D11) | D12: =IF('Allergen Matrix'!E11="","",'Allergen Matrix'!E11) -> ○ | E12: =IF('Allergen Matrix'!F11="","",'Allergen Matrix'!F11) | F12: =IF('Allergen Matrix'!G11="","",'Allergen Matrix'!G11) | G12: =IF('Allergen Matrix'!H11="","",'Allergen Matrix'!H11) -> ○ | H12: =IF('Allergen Matrix'!I11="","",'Allergen Matrix'!I11) -> ● | I12: =IF('Allergen Matrix'!J11="","",'Allergen Matrix'!J11) -> ○ | ... O12: =IF('Allergen Matrix'!P11="","",'Allergen Matrix'!P11)
A13: =IF('Allergen Matrix'!A12="","",'Allergen Matrix'!A12) -> Cream-filled croissant | B13: =IF('Allergen Matrix'!C12="","",'Allergen Matrix'!C12) -> ● | C13: =IF('Allergen Matrix'!D12="","",'Allergen Matrix'!D12) | D13: =IF('Allergen Matrix'!E12="","",'Allergen Matrix'!E12) -> ● | E13: =IF('Allergen Matrix'!F12="","",'Allergen Matrix'!F12) | F13: =IF('Allergen Matrix'!G12="","",'Allergen Matrix'!G12) | G13: =IF('Allergen Matrix'!H12="","",'Allergen Matrix'!H12) -> ○ | H13: =IF('Allergen Matrix'!I12="","",'Allergen Matrix'!I12) -> ● | I13: =IF('Allergen Matrix'!J12="","",'Allergen Matrix'!J12) -> ○ | ... O13: =IF('Allergen Matrix'!P12="","",'Allergen Matrix'!P12)
A14: =IF('Allergen Matrix'!A13="","",'Allergen Matrix'!A13) -> Cheesecake | B14: =IF('Allergen Matrix'!C13="","",'Allergen Matrix'!C13) -> ● | C14: =IF('Allergen Matrix'!D13="","",'Allergen Matrix'!D13) | D14: =IF('Allergen Matrix'!E13="","",'Allergen Matrix'!E13) -> ● | E14: =IF('Allergen Matrix'!F13="","",'Allergen Matrix'!F13) | F14: =IF('Allergen Matrix'!G13="","",'Allergen Matrix'!G13) | G14: =IF('Allergen Matrix'!H13="","",'Allergen Matrix'!H13) -> ○ | H14: =IF('Allergen Matrix'!I13="","",'Allergen Matrix'!I13) -> ● | I14: =IF('Allergen Matrix'!J13="","",'Allergen Matrix'!J13) -> ○ | ... O14: =IF('Allergen Matrix'!P13="","",'Allergen Matrix'!P13)
A15: =IF('Allergen Matrix'!A14="","",'Allergen Matrix'!A14) -> Apple pie | B15: =IF('Allergen Matrix'!C14="","",'Allergen Matrix'!C14) -> ● | C15: =IF('Allergen Matrix'!D14="","",'Allergen Matrix'!D14) | D15: =IF('Allergen Matrix'!E14="","",'Allergen Matrix'!E14) -> ● | E15: =IF('Allergen Matrix'!F14="","",'Allergen Matrix'!F14) | F15: =IF('Allergen Matrix'!G14="","",'Allergen Matrix'!G14) | G15: =IF('Allergen Matrix'!H14="","",'Allergen Matrix'!H14) | H15: =IF('Allergen Matrix'!I14="","",'Allergen Matrix'!I14) -> ● | I15: =IF('Allergen Matrix'!J14="","",'Allergen Matrix'!J14) -> ○ | ... O15: =IF('Allergen Matrix'!P14="","",'Allergen Matrix'!P14)
A16: =IF('Allergen Matrix'!A15="","",'Allergen Matrix'!A15) -> Napoleon | B16: =IF('Allergen Matrix'!C15="","",'Allergen Matrix'!C15) -> ● | C16: =IF('Allergen Matrix'!D15="","",'Allergen Matrix'!D15) | D16: =IF('Allergen Matrix'!E15="","",'Allergen Matrix'!E15) -> ● | E16: =IF('Allergen Matrix'!F15="","",'Allergen Matrix'!F15) | F16: =IF('Allergen Matrix'!G15="","",'Allergen Matrix'!G15) | G16: =IF('Allergen Matrix'!H15="","",'Allergen Matrix'!H15) -> ○ | H16: =IF('Allergen Matrix'!I15="","",'Allergen Matrix'!I15) -> ● | I16: =IF('Allergen Matrix'!J15="","",'Allergen Matrix'!J15) -> ○ | ... O16: =IF('Allergen Matrix'!P15="","",'Allergen Matrix'!P15)
A17: =IF('Allergen Matrix'!A16="","",'Allergen Matrix'!A16) -> Eclair | B17: =IF('Allergen Matrix'!C16="","",'Allergen Matrix'!C16) -> ● | C17: =IF('Allergen Matrix'!D16="","",'Allergen Matrix'!D16) | D17: =IF('Allergen Matrix'!E16="","",'Allergen Matrix'!E16) -> ● | E17: =IF('Allergen Matrix'!F16="","",'Allergen Matrix'!F16) | F17: =IF('Allergen Matrix'!G16="","",'Allergen Matrix'!G16) | G17: =IF('Allergen Matrix'!H16="","",'Allergen Matrix'!H16) -> ○ | H17: =IF('Allergen Matrix'!I16="","",'Allergen Matrix'!I16) -> ● | I17: =IF('Allergen Matrix'!J16="","",'Allergen Matrix'!J16) -> ○ | ... O17: =IF('Allergen Matrix'!P16="","",'Allergen Matrix'!P16)
... A52: =IF('Allergen Matrix'!A51="","",'Allergen Matrix'!A51) | B52: =IF('Allergen Matrix'!C51="","",'Allergen Matrix'!C51) | C52: =IF('Allergen Matrix'!D51="","",'Allergen Matrix'!D51) | D52: =IF('Allergen Matrix'!E51="","",'Allergen Matrix'!E51) | E52: =IF('Allergen Matrix'!F51="","",'Allergen Matrix'!F51) | F52: =IF('Allergen Matrix'!G51="","",'Allergen Matrix'!G51) | G52: =IF('Allergen Matrix'!H51="","",'Allergen Matrix'!H51) | H52: =IF('Allergen Matrix'!I51="","",'Allergen Matrix'!I51) | I52: =IF('Allergen Matrix'!J51="","",'Allergen Matrix'!J51) | ... O52: =IF('Allergen Matrix'!P51="","",'Allergen Matrix'!P51)
A54: Our kitchen handles, among others, wheat (gluten), eggs, milk, tree nuts, soy, sesame and fish (replace with your own list), so cross-contact is possible. This notice complements the written information: it does not replace it.
A57: Reviewed by: _________________________ Signature: _________________________
A59: — Pastry Shop Checklists Kit Pro · AI Chef Pro · aichef.pro

Sheet Case Sign
B2: Allergen Information
B4: ALLERGEN INFORMATION AVAILABLE IN WRITING — ASK OUR STAFF
B7: Our kitchen handles, among others, wheat (gluten), eggs, milk, tree nuts, soy, sesame and fish (replace with your own list), so cross-contact is possible. This notice complements the written information: it does not replace it.
B10: The 9 major food allergens (US) + 5 more for UK customers
B11: Allergen | C11: What it includes | D11: Our products that contain it
B12: Wheat (gluten) | C12: Wheat and wheat products (US); for UK customers, all cereals with gluten: rye, barley, oats, spelt
B13: Shellfish | C13: Crustacean shellfish: crab, lobster, shrimp and products made from them
B14: Eggs | C14: Eggs and egg products
B15: Fish | C15: Fish (such as tuna, cod, salmon) and fish products
B16: Peanuts | C16: Peanuts and peanut products
B17: Soy | C17: Soybeans and soy products, including soy lecithin
B18: Milk | C18: Milk and milk products, including butter, cream and lactose
B19: Tree nuts | C19: Almonds, hazelnuts, walnuts, cashews, pistachios, pecans, Brazil nuts, macadamias, pine nuts
B20: Celery (UK) | C20: Celery and celery products (UK allergen; not a US major allergen)
B21: Mustard (UK) | C21: Mustard and mustard products (UK allergen; not a US major allergen)
B22: Sesame | C22: Sesame seeds and sesame products (US major allergen since 2023)
B23: Sulfites | C23: Sulfites at 10 ppm or more (declared in the US; a UK allergen)
... B25: Mollusks (UK) | C25: Mollusks such as clams, mussels, squid (UK allergen; not a US major allergen)
B27: Business: ______________________________ Last review: ____/____/________
B28: US: FALCPA + FASTER Act (9 major food allergens); FDA Food Code 2022 §3-602.12(C), written notice for unpackaged food where your state has adopted it. UK: Food Information Regulations 2014 (14).
B30: — Pastry Shop Checklists Kit Pro · AI Chef Pro · aichef.pro

Sheet Case Labels
B1: Case Labels
B2: Fill in, print on card stock and cut along the edge. Abbreviate the allergens: W wheat · E eggs · M milk · TN tree nuts · P peanuts · S soy · SE sesame · F fish · SH shellfish · SU sulfites.
B29: Each label: first line the product, second line the unit price, third line the allergens (→ sheet "Allergen Chart").
B31: — Pastry Shop Checklists Kit Pro · AI Chef Pro · aichef.pro
