Workbook

Sheet Pricing Calculator
A1: PAELLA CATERING PRICING CALCULATOR — PANS, RICE AND PRICE PER GUEST TO QUOTE
A2: Type in the GREEN cells; everything else is calculated. Pick the package, the menu style and the pan size, your staff and your costs: the tab turns them into pans to cook, rice, stock and propane to bring, a price per guest and a full quote. Ingredient prices are typed on the "Paella Yield & Pan Sizing" tab (left blank on purpose). Amounts are in US dollars (or your own currency) and exclude sales tax unless the row says otherwise. Every default value is a kit estimate: replace it with your own numbers.
A4: INPUTS | B4: Value | C4: Notes
A5: Package | B5: Live paella party (cooked on site, salad & bread) | C5: Choose from the list (table at the bottom of this tab): it sets the suggested servers. All three are priced per guest with the same formulas.
A6: Menu style | B6: Chicken & seafood | C6: Choose one of the 8 styles on the "Paella Yield & Pan Sizing" tab: it sets the ingredients per guest and the food cost.
A7: Guests expected | B7: 58 | C7: Whole number. You cook and buy for these guests.
A8: Guest minimum in your contract | B8: 20 | C8: If fewer guests confirm, you bill the minimum (billable guests in the results). Operators read for this kit ask for 20 to 30 guests (tasteofpaella.com, zola.com). 0 = no minimum.
A9: Paella pan size | B9: 36 in (90 cm) | C9: Choose from the list on the "Paella Yield & Pan Sizing" tab: it sets the guests per pan, the rice and stock per pan and the propane.
A10: Uncooked rice per guest (oz) | B10: 3.25 | C10: Kit estimate: 3 to 3.5 oz (85-100 g) of uncooked bomba rice per guest, a little more for big groups. 3.25 oz = 92 g.
A11: Tapas hour? | B11: No | C11: Yes = a tapas hour before the paella (patatas bravas, Spanish tortilla, cheese and cold cuts, Serrano ham), costed per guest in the next row and priced with your margin.
A12: Tapas food cost per guest | B12: 4.5 | C12: Kit estimate: $3-6 per guest. Used only when the switch above is Yes.
A13: Salad, bread, lemons and garlic aioli per guest | B13: 1.25 | C13: Kit estimate: $1-1.50 per guest.
A14: Disposables per guest (plates, cutlery, napkins, delivery trays) | B14: 0.75 | C14: Kit estimate. Put 0 if the client rents dishes and flatware (then add the rental below).
A15: Propane cost per lb | B15: 1.75 | C15: Kit estimate for 20-lb cylinder refills or exchanges ($10-15 for the 6-8 lb a 60-guest event burns). Use your own price.
A16: Paella chefs on event day | B16: 1 | C16: Compare with the suggested number in the results.
A17: Helpers (prep cook or second cook) | B17: 0 | C17: Compare with the suggested number in the results.
A18: Servers and buffet attendants | B18: 0 | C18: Compare with the suggested number in the results.
A19: Hours each on event day (loading, travel, setup, cooking, service, breakdown) | B19: 6 | C19: Kit estimate: arrive 2-3 hours before service; about 1 hour of cooking, 2 hours of service and 1 hour of breakdown (miamigrillcatering.com).
A20: Commissary prep hours for this event (sofrito, stock, seafood) | B20: 3 | C20: Total hours the day before, paid at the helper wage. Kit estimate.
A21: Paella chef hourly wage | B21: 22 | C21: Kit estimate, about the 75th percentile of restaurant cooks (BLS OEWS, May 2025: mean $18.62, 75th percentile $21.45). W-2 employees; if you cook yourself, count your hours too.
A22: Helper hourly wage | B22: 19 | C22: Kit estimate, about the mean wage of restaurant cooks (BLS OEWS, May 2025: $18.62). W-2.
A23: Server / attendant hourly wage | B23: 18 | C23: Kit estimate, about the 75th percentile of nonrestaurant food servers (BLS OEWS, May 2025: $18.51). W-2.
... A32: Sales tax rate (state + local) | B32: 0.08 | C32: Kit estimate: use your own state + local rate.
A33: Does your state tax the service charge? | B33: Yes | C33: Sales tax always applies to the food & service subtotal here. CA: a mandatory service charge is taxable. NY: not taxable only if it is separately stated, identified as a gratuity and all of it goes to the staff. TX: not taxable up to 20% if separately stated and paid to the staff. Check your state.
A34: Deposit to book the date (% of total) | B34: 0.5 | C34: Kit estimate: US caterers ask 25-50% to hold the date; the balance is due before the event. Put the same figure in your contract.
A35: Cancellation tier 1 starts at (days before the event) | B35: 60 | C35: Tiers run with no gaps: tier 1 = this many days or more; tier 2 = from the next threshold up to here; and so on.
A36: Cancellation tier 2 starts at (days before the event) | B36: 30
A37: Cancellation tier 3 starts at (days before the event) | B37: 14 | C37: Tier 4 = fewer days than this, or a no-show.
A38: Share of the total you keep in tier 1 | B38: 0.5 | C38: Kit estimate: the deposit.
A39: Share of the total you keep in tier 2 | B39: 0.75 | C39: Kit estimate.
A40: Share of the total you keep in tier 3 | B40: 0.9 | C40: Kit estimate.
A41: Share of the total you keep in tier 4 | B41: 1 | C41: Kit estimate: the seafood is already bought.
A43: CALCULATION | B43: Value | C43: Notes
A44: Billable guests | B44: =MAX($B$7,$B$8) -> 58 | C44: The larger of guests expected and the minimum.
A45: Guests per pan for this size | B45: =IFERROR(INDEX('Paella Yield & Pan Sizing'!$C$9:$C$15,MATCH($B$9,'Paella Yield & Pan Sizing'!$A$9:$A$15,0)),1) -> 40 | C45: From the pan table on the "Paella Yield & Pan Sizing" tab.
A46: Paella pans to cook | B46: =ROUNDUP($B$7/$B$45,0) -> 2 | C46: Guests ÷ guests per pan, rounded up. One burner per pan.
A47: Uncooked rice (lb) | B47: =$B$7*$B$10/16 -> 11.78125 | C47: Guests × oz per guest ÷ 16 (1 lb = 0.454 kg).
A48: Stock (gallons) | B48: =$B$47*'Paella Yield & Pan Sizing'!$B$5/4 -> 3.534375 | C48: Uncooked rice × the stock ratio on the "Paella Yield & Pan Sizing" tab (1 gallon = 3.8 liters).
A49: Propane for the cook (lb) | B49: =$B$46*IFERROR(INDEX('Paella Yield & Pan Sizing'!$I$9:$I$15,MATCH($B$9,'Paella Yield & Pan Sizing'!$A$9:$A$15,0)),0) -> 6 | C49: Pans × propane per cook for this size.
A50: 20-lb propane cylinders to bring (plus one spare) | B50: =ROUNDUP($B$49/20,0)+1 -> 2 | C50: Never run a pan on a nearly empty cylinder.
...

Sheet Paella Yield & Pan Sizing
A1: PAELLA YIELD & PAN SIZING — 7 PAN SIZES AND 8 MENU STYLES
A2: Guests, rice, stock and propane per pan size, and the ingredients per guest of 8 menu styles (green cells: kit estimates, edit them with your own test cooks). Type your ingredient prices in the green row under the styles: they are blank on purpose. The FDA Food Code MINIMUM cooking temperature (the legal safety floor, 2022 Food Code 3-401.11) and the hot holding rule sit in their own columns.
A4: SIZING INPUT
A5: Stock per lb of uncooked rice (quarts) | B5: 1.2 | C5: Kit estimate: 1.2 quarts per lb (2.5 liters per kg); bomba rice absorbs up to 3 times its volume. The uncooked rice per guest comes from the "Pricing Calculator" tab.
A8: Pan size (in, cm) | B8: Diameter (cm) | C8: Guests per pan (Kit estimate) | D8: Burner rings | E8: Uncooked rice per pan (lb) | F8: (kg) | G8: Stock per pan (gallons) | H8: (liters) | I8: Propane per cook (lb) | J8: (kg) | K8: Notes
A9: 18 in (46 cm) | B9: 46 | C9: 8 | D9: 1 | E9: =C9*'Pricing Calculator'!$B$10/16 -> 1.625 | F9: =E9*0.4536 -> 0.7371 | G9: =E9*$B$5/4 -> 0.4875 | H9: =G9*3.785 -> 1.8451875 | I9: 0.8 | J9: =I9*0.4536 -> 0.36288 | K9: Side dish or a small backyard party.
A10: 22 in (55 cm) | B10: 55 | C10: 12 | D10: 2 | E10: =C10*'Pricing Calculator'!$B$10/16 -> 2.4375 | F10: =E10*0.4536 -> 1.10565 | G10: =E10*$B$5/4 -> 0.73125 | H10: =G10*3.785 -> 2.7677813 | I10: 1.2 | J10: =I10*0.4536 -> 0.54432
A11: 26 in (65 cm) | B11: 65 | C11: 18 | D11: 2 | E11: =C11*'Pricing Calculator'!$B$10/16 -> 3.65625 | F11: =E11*0.4536 -> 1.658475 | G11: =E11*$B$5/4 -> 1.096875 | H11: =G11*3.785 -> 4.1516719 | I11: 1.6 | J11: =I11*0.4536 -> 0.72576 | K11: Research figure (Kit estimate): about 18 guests.
A12: 28 in (70 cm) | B12: 70 | C12: 21 | D12: 2 | E12: =C12*'Pricing Calculator'!$B$10/16 -> 4.265625 | F12: =E12*0.4536 -> 1.9348875 | G12: =E12*$B$5/4 -> 1.2796875 | H12: =G12*3.785 -> 4.8436172 | I12: 1.8 | J12: =I12*0.4536 -> 0.81648
A13: 32 in (80 cm) | B13: 80 | C13: 30 | D13: 3 | E13: =C13*'Pricing Calculator'!$B$10/16 -> 6.09375 | F13: =E13*0.4536 -> 2.764125 | G13: =E13*$B$5/4 -> 1.828125 | H13: =G13*3.785 -> 6.9194531 | I13: 2.4 | J13: =I13*0.4536 -> 1.08864 | K13: Research figure (Kit estimate): about 30 guests.
A14: 36 in (90 cm) | B14: 90 | C14: 40 | D14: 3 | E14: =C14*'Pricing Calculator'!$B$10/16 -> 8.125 | F14: =E14*0.4536 -> 3.6855 | G14: =E14*$B$5/4 -> 2.4375 | H14: =G14*3.785 -> 9.2259375 | I14: 3 | J14: =I14*0.4536 -> 1.3608 | K14: Research figure (Kit estimate): about 40 guests; a retailer says 40 to 50.
A15: 40 in (100 cm) | B15: 100 | C15: 50 | D15: 3 | E15: =C15*'Pricing Calculator'!$B$10/16 -> 10.15625 | F15: =E15*0.4536 -> 4.606875 | G15: =E15*$B$5/4 -> 3.046875 | H15: =G15*3.785 -> 11.532422 | I15: 3.7 | J15: =I15*0.4536 -> 1.67832 | K15: Needs an XL 3-ring burner and wind guards; check that your burner fits it.
A18: MENU STYLES — ingredients per guest (oz; saffron in grams), Kit estimate
A19: Menu style | B19: Chicken thighs, boneless (oz) | C19: Spanish chorizo, cured (oz) | D19: Rabbit (oz) | E19: Shrimp (oz) | F19: Mussels & clams, in shell (oz) | G19: Squid or cuttlefish (oz) | H19: Lobster, in shell (oz) | I19: Firm white fish (oz) | J19: Vegetables: green beans, lima beans, peppers, artichokes (oz) | K19: Sofrito base: tomato, onion, garlic, olive oil (oz) | L19: Saffron (g) | M19: Kit food cost per guest (excl. salad & bread) | N19: Food cost per guest with your prices | O19: Ingredients with no price (rice included) | P19: FDA Food Code minimum (safety) | Q19: Hot holding (Food Code) | R19: Typical allergens
A20: Seafood (paella marinera) | B20: 0 | C20: 0 | D20: 0 | E20: 2 | F20: 3 | G20: 1.5 | H20: 0 | I20: 1 | J20: 0.5 | K20: 1.5 | L20: 0.08 | M20: 8.5 | N20: =IF(ISNUMBER($B$33),$B$33,0)*'Pricing Calculator'!$B$10/16+B20*B$30+C20*C$30+D20*D$30+E20*E$30+F20*F$30+G20*G$30+H20*H$30+I20*I$30+J20*J$30+K20*K$30+L20*L$30 -> 0 | O20: =IF(ISNUMBER($B$33),IF($B$33>0,0,1),1)+IF(B20>0,B$31,0)+IF(C20>0,C$31,0)+IF(D20>0,D$31,0)+IF(E20>0,E$31,0)+IF(F20>0,F$31,0)+IF(G20>0,G$31,0)+IF(H20>0,H$31,0)+IF(I20>0,I$31,0)+IF(J20>0,J$31,0)+IF(K20>0,K$31,0)+IF(L20>0,L$31,0) -> 8 | P20: 145 °F (63 °C) for 15 s: fish and shellfish | Q20: 135 °F (57 °C) or above, or time as a public health control: 4 hours, then discard | R20: Crustacean shellfish, fish, mollusks (not a major US allergen, declare them anyway); sulfites in some frozen shrimp. Verify with your recipe and suppliers.
A21: Chicken & seafood | B21: 2.5 | C21: 0 | D21: 0 | E21: 1.5 | F21: 2 | G21: 0.75 | H21: 0 | I21: 0 | J21: 1 | K21: 1.5 | L21: 0.08 | M21: 7 | N21: =IF(ISNUMBER($B$33),$B$33,0)*'Pricing Calculator'!$B$10/16+B21*B$30+C21*C$30+D21*D$30+E21*E$30+F21*F$30+G21*G$30+H21*H$30+I21*I$30+J21*J$30+K21*K$30+L21*L$30 -> 0 | O21: =IF(ISNUMBER($B$33),IF($B$33>0,0,1),1)+IF(B21>0,B$31,0)+IF(C21>0,C$31,0)+IF(D21>0,D$31,0)+IF(E21>0,E$31,0)+IF(F21>0,F$31,0)+IF(G21>0,G$31,0)+IF(H21>0,H$31,0)+IF(I21>0,I$31,0)+IF(J21>0,J$31,0)+IF(K21>0,K$31,0)+IF(L21>0,L$31,0) -> 8 | P21: 165 °F (74 °C): chicken; 145 °F (63 °C) for 15 s: fish and shellfish | Q21: 135 °F (57 °C) or above, or time as a public health control: 4 hours, then discard | R21: Crustacean shellfish, mollusks (not a major US allergen, declare them anyway); sulfites in some frozen shrimp. Verify with your recipe and suppliers.
A22: Chicken & chorizo | B22: 3.5 | C22: 1 | D22: 0 | E22: 0 | F22: 0 | G22: 0 | H22: 0 | I22: 0 | J22: 1.5 | K22: 1.5 | L22: 0.08 | M22: 5 | N22: =IF(ISNUMBER($B$33),$B$33,0)*'Pricing Calculator'!$B$10/16+B22*B$30+C22*C$30+D22*D$30+E22*E$30+F22*F$30+G22*G$30+H22*H$30+I22*I$30+J22*J$30+K22*K$30+L22*L$30 -> 0 | O22: =IF(ISNUMBER($B$33),IF($B$33>0,0,1),1)+IF(B22>0,B$31,0)+IF(C22>0,C$31,0)+IF(D22>0,D$31,0)+IF(E22>0,E$31,0)+IF(F22>0,F$31,0)+IF(G22>0,G$31,0)+IF(H22>0,H$31,0)+IF(I22>0,I$31,0)+IF(J22>0,J$31,0)+IF(K22>0,K$31,0)+IF(L22>0,L$31,0) -> 6 | P22: 165 °F (74 °C): chicken. Spanish cured chorizo is ready to eat; raw Mexican-style chorizo is ground meat: 155 °F (68 °C) for 17 s | Q22: 135 °F (57 °C) or above, or time as a public health control: 4 hours, then discard | R22: Check the chorizo label (some brands add milk, soy or wheat). Verify with your recipe and suppliers.
A23: Valencian (chicken; rabbit on request) | B23: 3 | C23: 0 | D23: 1.5 | E23: 0 | F23: 0 | G23: 0 | H23: 0 | I23: 0 | J23: 2.5 | K23: 1 | L23: 0.08 | M23: 6 | N23: =IF(ISNUMBER($B$33),$B$33,0)*'Pricing Calculator'!$B$10/16+B23*B$30+C23*C$30+D23*D$30+E23*E$30+F23*F$30+G23*G$30+H23*H$30+I23*I$30+J23*J$30+K23*K$30+L23*L$30 -> 0 | O23: =IF(ISNUMBER($B$33),IF($B$33>0,0,1),1)+IF(B23>0,B$31,0)+IF(C23>0,C$31,0)+IF(D23>0,D$31,0)+IF(E23>0,E$31,0)+IF(F23>0,F$31,0)+IF(G23>0,G$31,0)+IF(H23>0,H$31,0)+IF(I23>0,I$31,0)+IF(J23>0,J$31,0)+IF(K23>0,K$31,0)+IF(L23>0,L$31,0) -> 6 | P23: 165 °F (74 °C): chicken. Rabbit: check your county rules (cooking it with the chicken to 165 °F (74 °C) covers it) | Q23: 135 °F (57 °C) or above, or time as a public health control: 4 hours, then discard | R23: None of the 9 major allergens in a classic recipe. Verify with your recipe and suppliers.
A24: Farm vegetable (vegan) | B24: 0 | C24: 0 | D24: 0 | E24: 0 | F24: 0 | G24: 0 | H24: 0 | I24: 0 | J24: 5 | K24: 2 | L24: 0.08 | M24: 4 | N24: =IF(ISNUMBER($B$33),$B$33,0)*'Pricing Calculator'!$B$10/16+B24*B$30+C24*C$30+D24*D$30+E24*E$30+F24*F$30+G24*G$30+H24*H$30+I24*I$30+J24*J$30+K24*K$30+L24*L$30 -> 0 | O24: =IF(ISNUMBER($B$33),IF($B$33>0,0,1),1)+IF(B24>0,B$31,0)+IF(C24>0,C$31,0)+IF(D24>0,D$31,0)+IF(E24>0,E$31,0)+IF(F24>0,F$31,0)+IF(G24>0,G$31,0)+IF(H24>0,H$31,0)+IF(I24>0,I$31,0)+IF(J24>0,J$31,0)+IF(K24>0,K$31,0)+IF(L24>0,L$31,0) -> 4 | P24: 135 °F (57 °C): plant foods cooked for hot holding | Q24: 135 °F (57 °C) or above, or time as a public health control: 4 hours, then discard | R24: Check the vegetable stock base (some add celery, soy or wheat). Verify with your recipe and suppliers.
A25: Paella negra (squid ink) | B25: 0 | C25: 0 | D25: 0 | E25: 1 | F25: 0 | G25: 3 | H25: 0 | I25: 0 | J25: 0.5 | K25: 1.5 | L25: 0 | M25: 6.5 | N25: =IF(ISNUMBER($B$33),$B$33,0)*'Pricing Calculator'!$B$10/16+B25*B$30+C25*C$30+D25*D$30+E25*E$30+F25*F$30+G25*G$30+H25*H$30+I25*I$30+J25*J$30+K25*K$30+L25*L$30 -> 0 | O25: =IF(ISNUMBER($B$33),IF($B$33>0,0,1),1)+IF(B25>0,B$31,0)+IF(C25>0,C$31,0)+IF(D25>0,D$31,0)+IF(E25>0,E$31,0)+IF(F25>0,F$31,0)+IF(G25>0,G$31,0)+IF(H25>0,H$31,0)+IF(I25>0,I$31,0)+IF(J25>0,J$31,0)+IF(K25>0,K$31,0)+IF(L25>0,L$31,0) -> 5 | P25: 145 °F (63 °C) for 15 s: fish and shellfish | Q25: 135 °F (57 °C) or above, or time as a public health control: 4 hours, then discard | R25: Crustacean shellfish, mollusks (not a major US allergen, declare them anyway) (squid and its ink). Verify with your recipe and suppliers.
A26: Lobster & seafood (premium) | B26: 0 | C26: 0 | D26: 0 | E26: 1.5 | F26: 2 | G26: 1 | H26: 4 | I26: 0 | J26: 0.5 | K26: 1.5 | L26: 0.08 | M26: 16.5 | N26: =IF(ISNUMBER($B$33),$B$33,0)*'Pricing Calculator'!$B$10/16+B26*B$30+C26*C$30+D26*D$30+E26*E$30+F26*F$30+G26*G$30+H26*H$30+I26*I$30+J26*J$30+K26*K$30+L26*L$30 -> 0 | O26: =IF(ISNUMBER($B$33),IF($B$33>0,0,1),1)+IF(B26>0,B$31,0)+IF(C26>0,C$31,0)+IF(D26>0,D$31,0)+IF(E26>0,E$31,0)+IF(F26>0,F$31,0)+IF(G26>0,G$31,0)+IF(H26>0,H$31,0)+IF(I26>0,I$31,0)+IF(J26>0,J$31,0)+IF(K26>0,K$31,0)+IF(L26>0,L$31,0) -> 8 | P26: 145 °F (63 °C) for 15 s: fish and shellfish | Q26: 135 °F (57 °C) or above, or time as a public health control: 4 hours, then discard | R26: Crustacean shellfish, mollusks (not a major US allergen, declare them anyway). Verify with your recipe and suppliers.
A27: Easy-eat peeled seafood | B27: 0 | C27: 0 | D27: 0 | E27: 2.5 | F27: 0 | G27: 1.5 | H27: 0 | I27: 1.5 | J27: 0.5 | K27: 1.5 | L27: 0.08 | M27: 9 | N27: =IF(ISNUMBER($B$33),$B$33,0)*'Pricing Calculator'!$B$10/16+B27*B$30+C27*C$30+D27*D$30+E27*E$30+F27*F$30+G27*G$30+H27*H$30+I27*I$30+J27*J$30+K27*K$30+L27*L$30 -> 0 | O27: =IF(ISNUMBER($B$33),IF($B$33>0,0,1),1)+IF(B27>0,B$31,0)+IF(C27>0,C$31,0)+IF(D27>0,D$31,0)+IF(E27>0,E$31,0)+IF(F27>0,F$31,0)+IF(G27>0,G$31,0)+IF(H27>0,H$31,0)+IF(I27>0,I$31,0)+IF(J27>0,J$31,0)+IF(K27>0,K$31,0)+IF(L27>0,L$31,0) -> 7 | P27: 145 °F (63 °C) for 15 s: fish and shellfish | Q27: 135 °F (57 °C) or above, or time as a public health control: 4 hours, then discard | R27: Crustacean shellfish, fish, mollusks (not a major US allergen, declare them anyway). Verify with your recipe and suppliers.
A29: YOUR PRICES: per lb (saffron: per gram). Blank on purpose: type your supplier prices
A30: Calculated: your price per oz (saffron: per gram) | B30: =IF(ISNUMBER(B29),B29/16,0) -> 0 | C30: =IF(ISNUMBER(C29),C29/16,0) -> 0 | D30: =IF(ISNUMBER(D29),D29/16,0) -> 0 | E30: =IF(ISNUMBER(E29),E29/16,0) -> 0 | F30: =IF(ISNUMBER(F29),F29/16,0) -> 0 | G30: =IF(ISNUMBER(G29),G29/16,0) -> 0 | H30: =IF(ISNUMBER(H29),H29/16,0) -> 0 | I30: =IF(ISNUMBER(I29),I29/16,0) -> 0 | ... K30: =IF(ISNUMBER(K29),K29/16,0) -> 0 | L30: =IF(ISNUMBER(L29),L29,0) -> 0
A31: Calculated: price missing? (1 = yes) | B31: =IF(ISNUMBER(B29),IF(B29>0,0,1),1) -> 1 | C31: =IF(ISNUMBER(C29),IF(C29>0,0,1),1) -> 1 | D31: =IF(ISNUMBER(D29),IF(D29>0,0,1),1) -> 1 | E31: =IF(ISNUMBER(E29),IF(E29>0,0,1),1) -> 1 | F31: =IF(ISNUMBER(F29),IF(F29>0,0,1),1) -> 1 | G31: =IF(ISNUMBER(G29),IF(G29>0,0,1),1) -> 1 | H31: =IF(ISNUMBER(H29),IF(H29>0,0,1),1) -> 1 | I31: =IF(ISNUMBER(I29),IF(I29>0,0,1),1) -> 1 | ... L31: =IF(ISNUMBER(L29),IF(L29>0,0,1),1) -> 1
A33: YOUR PRICE: bomba rice per lb (blank on purpose) | C33: Bomba or another short-grain Spanish rice, from an importer or a cash-and-carry.
A35: Food Code minimum = the legal safety floor for each ingredient (3-401.11): chicken 165 °F (74 °C); fish and shellfish, crustaceans and mollusks included, 145 °F (63 °C) for 15 seconds; raw Mexican-style chorizo is ground meat, 155 °F (68 °C) for 17 seconds. Spanish cured chorizo is ready to eat. Probe the thickest piece of chicken in every pan.
A36: Cooked rice needs time and temperature control: Bacillus cereus is common in outbreaks from poor hot holding of starchy foods like rice (Food Code, Annex 3). Serve at 135 °F (57 °C) or above (3-501.16), or use time as a public health control with a written procedure: mark the time, discard after 4 hours (3-501.19), if your county accepts it.
A37: Leftover paella goes in the trash: do not cool it down to serve it again.
A38: Mussels and clams: buy them from an approved source with the dealer tag, keep them in the container until it is empty, write the date of the last one served and keep the tag for 90 days (3-203.12). Keep raw seafood at 41 °F (5 °C) or below.
A39: Allergens: the 9 major US allergens include fish and crustacean shellfish (crab, lobster, shrimp); mollusks are not one of them, but declare them anyway. Garlic aioli has egg; bread and fideua (noodle paella) have wheat. In the UK, mollusks, celery and sulphites are among the 14 allergens. The column above lists what is typical: verify with your recipe and suppliers.
A40: Guests per pan, propane and ingredients per guest are kit estimates: weigh your own rice, stock and propane on your test cooks and type them here; the "Pricing Calculator" and "Shopping List by Guest Count" tabs follow.

Sheet Shopping List by Guest Count
A1: SHOPPING LIST BY GUEST COUNT — WHAT TO BUY AND BRING
A2: It reads the package, the menu style, the pan size, the rice per guest and the tapas hour switch from the "Pricing Calculator" tab and the pans and ingredients from the "Paella Yield & Pan Sizing" tab. Column B is your event; columns C-F are reference sizes (40, 80, 150 and 300 guests: edit them). Green cells are kit estimates: edit them.
A4: ASSUMPTIONS (Kit estimate — edit) | B4: Value | G4: Notes
A5: Lemons per guest (wedges for the pan) | B5: 0.25 | G5: Kit estimate: one lemon cut in 4 wedges.
A6: Bread rolls or slices per guest | B6: 1.5 | G6: Kit estimate.
A7: Salad greens per guest (oz) | B7: 1.5 | G7: Kit estimate.
A8: Garlic aioli per guest (oz) | B8: 0.75 | G8: Kit estimate: contains egg (allergen).
A9: Plates and forks per guest | B9: 1.1 | G9: Kit estimate: 10% extra.
A10: Ice per lb of raw seafood (lb) | B10: 1 | G10: Kit estimate: keep raw seafood at 41 °F (5 °C) or below.
A11: Seafood and ice per cooler (lb) | B11: 40 | G11: Kit estimate: check your cooler size.
A12: Guests per chafing dish for the tapas hour | B12: 25 | G12: Kit estimate. Used only with a tapas hour.
A14: QUANTITIES | B14: Your event | C14: Reference | D14: Reference | E14: Reference | F14: Reference | G14: Notes
A15: Guests | B15: ='Pricing Calculator'!$B$7 -> 58 | C15: 40 | D15: 80 | E15: 150 | F15: 300 | G15: Column B comes from the "Pricing Calculator" tab.
A16: ="Paella pans and burners: "&'Pricing Calculator'!$B$9 -> Paella pans and burners: 36 in (90 cm) | B16: =ROUNDUP(B$15/IFERROR(INDEX('Paella Yield & Pan Sizing'!$C$9:$C$15,MATCH('Pricing Calculator'!$B$9,'Paella Yield & Pan Sizing'!$A$9:$A$15,0)),1),0) -> 2 | C16: =ROUNDUP(C$15/IFERROR(INDEX('Paella Yield & Pan Sizing'!$C$9:$C$15,MATCH('Pricing Calculator'!$B$9,'Paella Yield & Pan Sizing'!$A$9:$A$15,0)),1),0) -> 1 | D16: =ROUNDUP(D$15/IFERROR(INDEX('Paella Yield & Pan Sizing'!$C$9:$C$15,MATCH('Pricing Calculator'!$B$9,'Paella Yield & Pan Sizing'!$A$9:$A$15,0)),1),0) -> 2 | E16: =ROUNDUP(E$15/IFERROR(INDEX('Paella Yield & Pan Sizing'!$C$9:$C$15,MATCH('Pricing Calculator'!$B$9,'Paella Yield & Pan Sizing'!$A$9:$A$15,0)),1),0) -> 4 | F16: =ROUNDUP(F$15/IFERROR(INDEX('Paella Yield & Pan Sizing'!$C$9:$C$15,MATCH('Pricing Calculator'!$B$9,'Paella Yield & Pan Sizing'!$A$9:$A$15,0)),1),0) -> 8 | G16: One 3-ring or 2-ring burner per pan (see the pan table).
A17: Uncooked bomba rice (lb) | B17: =B$15*'Pricing Calculator'!$B$10/16 -> 11.78125 | C17: =C$15*'Pricing Calculator'!$B$10/16 -> 8.125 | D17: =D$15*'Pricing Calculator'!$B$10/16 -> 16.25 | E17: =E$15*'Pricing Calculator'!$B$10/16 -> 30.46875 | F17: =F$15*'Pricing Calculator'!$B$10/16 -> 60.9375 | G17: Guests × oz per guest ÷ 16 (1 lb = 0.454 kg).
A18: Stock (gallons) | B18: =B$17*'Paella Yield & Pan Sizing'!$B$5/4 -> 3.534375 | C18: =C$17*'Paella Yield & Pan Sizing'!$B$5/4 -> 2.4375 | D18: =D$17*'Paella Yield & Pan Sizing'!$B$5/4 -> 4.875 | E18: =E$17*'Paella Yield & Pan Sizing'!$B$5/4 -> 9.140625 | F18: =F$17*'Paella Yield & Pan Sizing'!$B$5/4 -> 18.28125 | G18: Make it the day before at the commissary and keep it cold (1 gallon = 3.8 liters).
A19: Chicken thighs, boneless (lb) | B19: =IFERROR(B$15*INDEX('Paella Yield & Pan Sizing'!$B$20:$B$27,MATCH('Pricing Calculator'!$B$6,'Paella Yield & Pan Sizing'!$A$20:$A$27,0))/16,0) -> 9.0625 | C19: =IFERROR(C$15*INDEX('Paella Yield & Pan Sizing'!$B$20:$B$27,MATCH('Pricing Calculator'!$B$6,'Paella Yield & Pan Sizing'!$A$20:$A$27,0))/16,0) -> 6.25 | D19: =IFERROR(D$15*INDEX('Paella Yield & Pan Sizing'!$B$20:$B$27,MATCH('Pricing Calculator'!$B$6,'Paella Yield & Pan Sizing'!$A$20:$A$27,0))/16,0) -> 12.5 | E19: =IFERROR(E$15*INDEX('Paella Yield & Pan Sizing'!$B$20:$B$27,MATCH('Pricing Calculator'!$B$6,'Paella Yield & Pan Sizing'!$A$20:$A$27,0))/16,0) -> 23.4375 | F19: =IFERROR(F$15*INDEX('Paella Yield & Pan Sizing'!$B$20:$B$27,MATCH('Pricing Calculator'!$B$6,'Paella Yield & Pan Sizing'!$A$20:$A$27,0))/16,0) -> 46.875 | G19: For the menu style on the "Pricing Calculator" tab.
A20: Spanish chorizo, cured (lb) | B20: =IFERROR(B$15*INDEX('Paella Yield & Pan Sizing'!$C$20:$C$27,MATCH('Pricing Calculator'!$B$6,'Paella Yield & Pan Sizing'!$A$20:$A$27,0))/16,0) -> 0 | C20: =IFERROR(C$15*INDEX('Paella Yield & Pan Sizing'!$C$20:$C$27,MATCH('Pricing Calculator'!$B$6,'Paella Yield & Pan Sizing'!$A$20:$A$27,0))/16,0) -> 0 | D20: =IFERROR(D$15*INDEX('Paella Yield & Pan Sizing'!$C$20:$C$27,MATCH('Pricing Calculator'!$B$6,'Paella Yield & Pan Sizing'!$A$20:$A$27,0))/16,0) -> 0 | E20: =IFERROR(E$15*INDEX('Paella Yield & Pan Sizing'!$C$20:$C$27,MATCH('Pricing Calculator'!$B$6,'Paella Yield & Pan Sizing'!$A$20:$A$27,0))/16,0) -> 0 | F20: =IFERROR(F$15*INDEX('Paella Yield & Pan Sizing'!$C$20:$C$27,MATCH('Pricing Calculator'!$B$6,'Paella Yield & Pan Sizing'!$A$20:$A$27,0))/16,0) -> 0
A21: Rabbit (lb) | B21: =IFERROR(B$15*INDEX('Paella Yield & Pan Sizing'!$D$20:$D$27,MATCH('Pricing Calculator'!$B$6,'Paella Yield & Pan Sizing'!$A$20:$A$27,0))/16,0) -> 0 | C21: =IFERROR(C$15*INDEX('Paella Yield & Pan Sizing'!$D$20:$D$27,MATCH('Pricing Calculator'!$B$6,'Paella Yield & Pan Sizing'!$A$20:$A$27,0))/16,0) -> 0 | D21: =IFERROR(D$15*INDEX('Paella Yield & Pan Sizing'!$D$20:$D$27,MATCH('Pricing Calculator'!$B$6,'Paella Yield & Pan Sizing'!$A$20:$A$27,0))/16,0) -> 0 | E21: =IFERROR(E$15*INDEX('Paella Yield & Pan Sizing'!$D$20:$D$27,MATCH('Pricing Calculator'!$B$6,'Paella Yield & Pan Sizing'!$A$20:$A$27,0))/16,0) -> 0 | F21: =IFERROR(F$15*INDEX('Paella Yield & Pan Sizing'!$D$20:$D$27,MATCH('Pricing Calculator'!$B$6,'Paella Yield & Pan Sizing'!$A$20:$A$27,0))/16,0) -> 0
A22: Shrimp (lb) | B22: =IFERROR(B$15*INDEX('Paella Yield & Pan Sizing'!$E$20:$E$27,MATCH('Pricing Calculator'!$B$6,'Paella Yield & Pan Sizing'!$A$20:$A$27,0))/16,0) -> 5.4375 | C22: =IFERROR(C$15*INDEX('Paella Yield & Pan Sizing'!$E$20:$E$27,MATCH('Pricing Calculator'!$B$6,'Paella Yield & Pan Sizing'!$A$20:$A$27,0))/16,0) -> 3.75 | D22: =IFERROR(D$15*INDEX('Paella Yield & Pan Sizing'!$E$20:$E$27,MATCH('Pricing Calculator'!$B$6,'Paella Yield & Pan Sizing'!$A$20:$A$27,0))/16,0) -> 7.5 | E22: =IFERROR(E$15*INDEX('Paella Yield & Pan Sizing'!$E$20:$E$27,MATCH('Pricing Calculator'!$B$6,'Paella Yield & Pan Sizing'!$A$20:$A$27,0))/16,0) -> 14.0625 | F22: =IFERROR(F$15*INDEX('Paella Yield & Pan Sizing'!$E$20:$E$27,MATCH('Pricing Calculator'!$B$6,'Paella Yield & Pan Sizing'!$A$20:$A$27,0))/16,0) -> 28.125
A23: Mussels & clams, in shell (lb) | B23: =IFERROR(B$15*INDEX('Paella Yield & Pan Sizing'!$F$20:$F$27,MATCH('Pricing Calculator'!$B$6,'Paella Yield & Pan Sizing'!$A$20:$A$27,0))/16,0) -> 7.25 | C23: =IFERROR(C$15*INDEX('Paella Yield & Pan Sizing'!$F$20:$F$27,MATCH('Pricing Calculator'!$B$6,'Paella Yield & Pan Sizing'!$A$20:$A$27,0))/16,0) -> 5 | D23: =IFERROR(D$15*INDEX('Paella Yield & Pan Sizing'!$F$20:$F$27,MATCH('Pricing Calculator'!$B$6,'Paella Yield & Pan Sizing'!$A$20:$A$27,0))/16,0) -> 10 | E23: =IFERROR(E$15*INDEX('Paella Yield & Pan Sizing'!$F$20:$F$27,MATCH('Pricing Calculator'!$B$6,'Paella Yield & Pan Sizing'!$A$20:$A$27,0))/16,0) -> 18.75 | F23: =IFERROR(F$15*INDEX('Paella Yield & Pan Sizing'!$F$20:$F$27,MATCH('Pricing Calculator'!$B$6,'Paella Yield & Pan Sizing'!$A$20:$A$27,0))/16,0) -> 37.5
A24: Squid or cuttlefish (lb) | B24: =IFERROR(B$15*INDEX('Paella Yield & Pan Sizing'!$G$20:$G$27,MATCH('Pricing Calculator'!$B$6,'Paella Yield & Pan Sizing'!$A$20:$A$27,0))/16,0) -> 2.71875 | C24: =IFERROR(C$15*INDEX('Paella Yield & Pan Sizing'!$G$20:$G$27,MATCH('Pricing Calculator'!$B$6,'Paella Yield & Pan Sizing'!$A$20:$A$27,0))/16,0) -> 1.875 | D24: =IFERROR(D$15*INDEX('Paella Yield & Pan Sizing'!$G$20:$G$27,MATCH('Pricing Calculator'!$B$6,'Paella Yield & Pan Sizing'!$A$20:$A$27,0))/16,0) -> 3.75 | E24: =IFERROR(E$15*INDEX('Paella Yield & Pan Sizing'!$G$20:$G$27,MATCH('Pricing Calculator'!$B$6,'Paella Yield & Pan Sizing'!$A$20:$A$27,0))/16,0) -> 7.03125 | F24: =IFERROR(F$15*INDEX('Paella Yield & Pan Sizing'!$G$20:$G$27,MATCH('Pricing Calculator'!$B$6,'Paella Yield & Pan Sizing'!$A$20:$A$27,0))/16,0) -> 14.0625
A25: Lobster, in shell (lb) | B25: =IFERROR(B$15*INDEX('Paella Yield & Pan Sizing'!$H$20:$H$27,MATCH('Pricing Calculator'!$B$6,'Paella Yield & Pan Sizing'!$A$20:$A$27,0))/16,0) -> 0 | C25: =IFERROR(C$15*INDEX('Paella Yield & Pan Sizing'!$H$20:$H$27,MATCH('Pricing Calculator'!$B$6,'Paella Yield & Pan Sizing'!$A$20:$A$27,0))/16,0) -> 0 | D25: =IFERROR(D$15*INDEX('Paella Yield & Pan Sizing'!$H$20:$H$27,MATCH('Pricing Calculator'!$B$6,'Paella Yield & Pan Sizing'!$A$20:$A$27,0))/16,0) -> 0 | E25: =IFERROR(E$15*INDEX('Paella Yield & Pan Sizing'!$H$20:$H$27,MATCH('Pricing Calculator'!$B$6,'Paella Yield & Pan Sizing'!$A$20:$A$27,0))/16,0) -> 0 | F25: =IFERROR(F$15*INDEX('Paella Yield & Pan Sizing'!$H$20:$H$27,MATCH('Pricing Calculator'!$B$6,'Paella Yield & Pan Sizing'!$A$20:$A$27,0))/16,0) -> 0
A26: Firm white fish (lb) | B26: =IFERROR(B$15*INDEX('Paella Yield & Pan Sizing'!$I$20:$I$27,MATCH('Pricing Calculator'!$B$6,'Paella Yield & Pan Sizing'!$A$20:$A$27,0))/16,0) -> 0 | C26: =IFERROR(C$15*INDEX('Paella Yield & Pan Sizing'!$I$20:$I$27,MATCH('Pricing Calculator'!$B$6,'Paella Yield & Pan Sizing'!$A$20:$A$27,0))/16,0) -> 0 | D26: =IFERROR(D$15*INDEX('Paella Yield & Pan Sizing'!$I$20:$I$27,MATCH('Pricing Calculator'!$B$6,'Paella Yield & Pan Sizing'!$A$20:$A$27,0))/16,0) -> 0 | E26: =IFERROR(E$15*INDEX('Paella Yield & Pan Sizing'!$I$20:$I$27,MATCH('Pricing Calculator'!$B$6,'Paella Yield & Pan Sizing'!$A$20:$A$27,0))/16,0) -> 0 | F26: =IFERROR(F$15*INDEX('Paella Yield & Pan Sizing'!$I$20:$I$27,MATCH('Pricing Calculator'!$B$6,'Paella Yield & Pan Sizing'!$A$20:$A$27,0))/16,0) -> 0
A27: Vegetables: green beans, lima beans, peppers, artichokes (lb) | B27: =IFERROR(B$15*INDEX('Paella Yield & Pan Sizing'!$J$20:$J$27,MATCH('Pricing Calculator'!$B$6,'Paella Yield & Pan Sizing'!$A$20:$A$27,0))/16,0) -> 3.625 | C27: =IFERROR(C$15*INDEX('Paella Yield & Pan Sizing'!$J$20:$J$27,MATCH('Pricing Calculator'!$B$6,'Paella Yield & Pan Sizing'!$A$20:$A$27,0))/16,0) -> 2.5 | D27: =IFERROR(D$15*INDEX('Paella Yield & Pan Sizing'!$J$20:$J$27,MATCH('Pricing Calculator'!$B$6,'Paella Yield & Pan Sizing'!$A$20:$A$27,0))/16,0) -> 5 | E27: =IFERROR(E$15*INDEX('Paella Yield & Pan Sizing'!$J$20:$J$27,MATCH('Pricing Calculator'!$B$6,'Paella Yield & Pan Sizing'!$A$20:$A$27,0))/16,0) -> 9.375 | F27: =IFERROR(F$15*INDEX('Paella Yield & Pan Sizing'!$J$20:$J$27,MATCH('Pricing Calculator'!$B$6,'Paella Yield & Pan Sizing'!$A$20:$A$27,0))/16,0) -> 18.75
A28: Sofrito base: tomato, onion, garlic, olive oil (lb) | B28: =IFERROR(B$15*INDEX('Paella Yield & Pan Sizing'!$K$20:$K$27,MATCH('Pricing Calculator'!$B$6,'Paella Yield & Pan Sizing'!$A$20:$A$27,0))/16,0) -> 5.4375 | C28: =IFERROR(C$15*INDEX('Paella Yield & Pan Sizing'!$K$20:$K$27,MATCH('Pricing Calculator'!$B$6,'Paella Yield & Pan Sizing'!$A$20:$A$27,0))/16,0) -> 3.75 | D28: =IFERROR(D$15*INDEX('Paella Yield & Pan Sizing'!$K$20:$K$27,MATCH('Pricing Calculator'!$B$6,'Paella Yield & Pan Sizing'!$A$20:$A$27,0))/16,0) -> 7.5 | E28: =IFERROR(E$15*INDEX('Paella Yield & Pan Sizing'!$K$20:$K$27,MATCH('Pricing Calculator'!$B$6,'Paella Yield & Pan Sizing'!$A$20:$A$27,0))/16,0) -> 14.0625 | F28: =IFERROR(F$15*INDEX('Paella Yield & Pan Sizing'!$K$20:$K$27,MATCH('Pricing Calculator'!$B$6,'Paella Yield & Pan Sizing'!$A$20:$A$27,0))/16,0) -> 28.125
A29: Saffron (g) | B29: =IFERROR(B$15*INDEX('Paella Yield & Pan Sizing'!$L$20:$L$27,MATCH('Pricing Calculator'!$B$6,'Paella Yield & Pan Sizing'!$A$20:$A$27,0)),0) -> 4.64 | C29: =IFERROR(C$15*INDEX('Paella Yield & Pan Sizing'!$L$20:$L$27,MATCH('Pricing Calculator'!$B$6,'Paella Yield & Pan Sizing'!$A$20:$A$27,0)),0) -> 3.2 | D29: =IFERROR(D$15*INDEX('Paella Yield & Pan Sizing'!$L$20:$L$27,MATCH('Pricing Calculator'!$B$6,'Paella Yield & Pan Sizing'!$A$20:$A$27,0)),0) -> 6.4 | E29: =IFERROR(E$15*INDEX('Paella Yield & Pan Sizing'!$L$20:$L$27,MATCH('Pricing Calculator'!$B$6,'Paella Yield & Pan Sizing'!$A$20:$A$27,0)),0) -> 12 | F29: =IFERROR(F$15*INDEX('Paella Yield & Pan Sizing'!$L$20:$L$27,MATCH('Pricing Calculator'!$B$6,'Paella Yield & Pan Sizing'!$A$20:$A$27,0)),0) -> 24
A30: Raw seafood, all lines (lb) | B30: =B$22+B$23+B$24+B$25+B$26 -> 15.40625 | C30: =C$22+C$23+C$24+C$25+C$26 -> 10.625 | D30: =D$22+D$23+D$24+D$25+D$26 -> 21.25 | E30: =E$22+E$23+E$24+E$25+E$26 -> 39.84375 | F30: =F$22+F$23+F$24+F$25+F$26 -> 79.6875
A31: Lemons | B31: =ROUNDUP(B$15*$B$5,0) -> 15 | C31: =ROUNDUP(C$15*$B$5,0) -> 10 | D31: =ROUNDUP(D$15*$B$5,0) -> 20 | E31: =ROUNDUP(E$15*$B$5,0) -> 38 | F31: =ROUNDUP(F$15*$B$5,0) -> 75
A32: Bread rolls or slices | B32: =ROUNDUP(B$15*$B$6,0) -> 87 | C32: =ROUNDUP(C$15*$B$6,0) -> 60 | D32: =ROUNDUP(D$15*$B$6,0) -> 120 | E32: =ROUNDUP(E$15*$B$6,0) -> 225 | F32: =ROUNDUP(F$15*$B$6,0) -> 450
A33: Salad greens (lb) | B33: =B$15*$B$7/16 -> 5.4375 | C33: =C$15*$B$7/16 -> 3.75 | D33: =D$15*$B$7/16 -> 7.5 | E33: =E$15*$B$7/16 -> 14.0625 | F33: =F$15*$B$7/16 -> 28.125
A34: Garlic aioli (quarts) | B34: =B$15*$B$8/32 -> 1.359375 | C34: =C$15*$B$8/32 -> 0.9375 | D34: =D$15*$B$8/32 -> 1.875 | E34: =E$15*$B$8/32 -> 3.515625 | F34: =F$15*$B$8/32 -> 7.03125 | G34: Egg allergen (1 quart = 0.95 liters).
A35: Propane (lb) | B35: =B$16*IFERROR(INDEX('Paella Yield & Pan Sizing'!$I$9:$I$15,MATCH('Pricing Calculator'!$B$9,'Paella Yield & Pan Sizing'!$A$9:$A$15,0)),0) -> 6 | C35: =C$16*IFERROR(INDEX('Paella Yield & Pan Sizing'!$I$9:$I$15,MATCH('Pricing Calculator'!$B$9,'Paella Yield & Pan Sizing'!$A$9:$A$15,0)),0) -> 3 | D35: =D$16*IFERROR(INDEX('Paella Yield & Pan Sizing'!$I$9:$I$15,MATCH('Pricing Calculator'!$B$9,'Paella Yield & Pan Sizing'!$A$9:$A$15,0)),0) -> 6 | E35: =E$16*IFERROR(INDEX('Paella Yield & Pan Sizing'!$I$9:$I$15,MATCH('Pricing Calculator'!$B$9,'Paella Yield & Pan Sizing'!$A$9:$A$15,0)),0) -> 12 | F35: =F$16*IFERROR(INDEX('Paella Yield & Pan Sizing'!$I$9:$I$15,MATCH('Pricing Calculator'!$B$9,'Paella Yield & Pan Sizing'!$A$9:$A$15,0)),0) -> 24
A36: 20-lb propane cylinders (plus one spare) | B36: =ROUNDUP(B$35/20,0)+1 -> 2 | C36: =ROUNDUP(C$35/20,0)+1 -> 2 | D36: =ROUNDUP(D$35/20,0)+1 -> 2 | E36: =ROUNDUP(E$35/20,0)+1 -> 2 | F36: =ROUNDUP(F$35/20,0)+1 -> 3 | G36: They travel upright and secured in the van.
A37: Plates and forks | B37: =ROUNDUP(B$15*$B$9,0) -> 64 | C37: =ROUNDUP(C$15*$B$9,0) -> 44 | D37: =ROUNDUP(D$15*$B$9,0) -> 88 | E37: =ROUNDUP(E$15*$B$9,0) -> 165 | F37: =ROUNDUP(F$15*$B$9,0) -> 330
A38: Ice for the raw seafood (lb) | B38: =B$30*$B$10 -> 15.40625 | C38: =C$30*$B$10 -> 10.625 | D38: =D$30*$B$10 -> 21.25 | E38: =E$30*$B$10 -> 39.84375 | F38: =F$30*$B$10 -> 79.6875
A39: Coolers for the raw seafood | B39: =IF($B$11>0,ROUNDUP((B$30+B$38)/$B$11,0),0) -> 1 | C39: =IF($B$11>0,ROUNDUP((C$30+C$38)/$B$11,0),0) -> 1 | D39: =IF($B$11>0,ROUNDUP((D$30+D$38)/$B$11,0),0) -> 2 | E39: =IF($B$11>0,ROUNDUP((E$30+E$38)/$B$11,0),0) -> 2 | F39: =IF($B$11>0,ROUNDUP((F$30+F$38)/$B$11,0),0) -> 4
A40: Chafing dishes for the tapas hour | B40: =IF(AND('Pricing Calculator'!$B$11="Yes",$B$12>0),ROUNDUP(B$15/$B$12,0),0) -> 0 | C40: =IF(AND('Pricing Calculator'!$B$11="Yes",$B$12>0),ROUNDUP(C$15/$B$12,0),0) -> 0 | D40: =IF(AND('Pricing Calculator'!$B$11="Yes",$B$12>0),ROUNDUP(D$15/$B$12,0),0) -> 0 | E40: =IF(AND('Pricing Calculator'!$B$11="Yes",$B$12>0),ROUNDUP(E$15/$B$12,0),0) -> 0 | F40: =IF(AND('Pricing Calculator'!$B$11="Yes",$B$12>0),ROUNDUP(F$15/$B$12,0),0) -> 0 | G40: 0 without a tapas hour.
A41: Paella chefs (suggested: one per 3 pans) | B41: =ROUNDUP(B$16/3,0) -> 1 | C41: =ROUNDUP(C$16/3,0) -> 1 | D41: =ROUNDUP(D$16/3,0) -> 1 | E41: =ROUNDUP(E$16/3,0) -> 2 | F41: =ROUNDUP(F$16/3,0) -> 3 | G41: Kit estimate.
A42: Helper (suggested: from 4 pans or 80 guests) | B42: =IF(OR(B$16>=4,B$15>=80),1,0) -> 0 | C42: =IF(OR(C$16>=4,C$15>=80),1,0) -> 0 | D42: =IF(OR(D$16>=4,D$15>=80),1,0) -> 1 | E42: =IF(OR(E$16>=4,E$15>=80),1,0) -> 1 | F42: =IF(OR(F$16>=4,F$15>=80),1,0) -> 1 | G42: Kit estimate.
...

Sheet 3 Example Quotes
A1: 3 EXAMPLE QUOTES — calculated with the same formulas as the "Pricing Calculator" tab
A2: Kit estimates for illustration. No ingredient price is typed: until you type yours on the "Paella Yield & Pan Sizing" tab, the food cost uses the style estimate per guest. Each quote lands within 10% of the price of its line in the example mix in the Word plan (section 3) ($22 drop-off, $34 backyard party, $52 wedding). Change the inputs in "Pricing Calculator" to price your own events.
A4: INPUTS | B4: Corporate drop-off, 30 guests | C4: Backyard paella party, 45 guests | D4: Wedding, 110 guests, tapas hour + full staff
A5: Package | B5: Drop-off paella (cooked at the commissary, delivered hot) | C5: Live paella party (cooked on site, salad & bread) | D5: Full-service live paella (paella chef & staff; weddings & corporate)
A6: Menu style | B6: Chicken & seafood | C6: Seafood (paella marinera) | D6: Chicken & seafood
A7: Guests expected | B7: 30 | C7: 45 | D7: 110
A8: Guest minimum in your contract | B8: 20 | C8: 20 | D8: 50
A9: Paella pan size | B9: 36 in (90 cm) | C9: 36 in (90 cm) | D9: 36 in (90 cm)
A10: Uncooked rice per guest (oz) | B10: 3.25 | C10: 3.25 | D10: 3.25
A11: Tapas hour? | B11: No | C11: No | D11: Yes
A12: Tapas food cost per guest | B12: 4.5 | C12: 4.5 | D12: 4.5
A13: Salad, bread, lemons and garlic aioli per guest | B13: 1.25 | C13: 1.25 | D13: 1.25
A14: Disposables per guest (plates, cutlery, napkins, delivery trays) | B14: 0.75 | C14: 0.75 | D14: 0
A15: Propane cost per lb | B15: 1.75 | C15: 1.75 | D15: 1.75
A16: Paella chefs on event day | B16: 1 | C16: 1 | D16: 2
A17: Helpers (prep cook or second cook) | B17: 0 | C17: 0 | D17: 1
A18: Servers and buffet attendants | B18: 0 | C18: 0 | D18: 5
A19: Hours each on event day (loading, travel, setup, cooking, service, breakdown) | B19: 3 | C19: 6 | D19: 7
A20: Commissary prep hours for this event (sofrito, stock, seafood) | B20: 2 | C20: 3 | D20: 6
A21: Paella chef hourly wage | B21: 22 | C21: 22 | D21: 22
A22: Helper hourly wage | B22: 19 | C22: 19 | D22: 19
A23: Server / attendant hourly wage | B23: 18 | C23: 18 | D23: 18
... A32: Sales tax rate (state + local) | B32: 0.08 | C32: 0.08 | D32: 0.08
A33: Does your state tax the service charge? | B33: Yes | C33: Yes | D33: Yes
A34: Deposit to book the date (% of total) | B34: 0.5 | C34: 0.5 | D34: 0.5
A35: Cancellation tier 1 starts at (days before the event) | B35: 60 | C35: 60 | D35: 60
A36: Cancellation tier 2 starts at (days before the event) | B36: 30 | C36: 30 | D36: 30
A37: Cancellation tier 3 starts at (days before the event) | B37: 14 | C37: 14 | D37: 14
A38: Share of the total you keep in tier 1 | B38: 0.5 | C38: 0.5 | D38: 0.5
A39: Share of the total you keep in tier 2 | B39: 0.75 | C39: 0.75 | D39: 0.75
A40: Share of the total you keep in tier 3 | B40: 0.9 | C40: 0.9 | D40: 0.9
A41: Share of the total you keep in tier 4 | B41: 1 | C41: 1 | D41: 1
A43: RESULT | B43: Corporate drop-off, 30 guests | C43: Backyard paella party, 45 guests | D43: Wedding, 110 guests, tapas hour + full staff
A44: Billable guests | B44: =MAX($B$7,$B$8) -> 30 | C44: =MAX($C$7,$C$8) -> 45 | D44: =MAX($D$7,$D$8) -> 110
A45: Guests per pan for this size | B45: =IFERROR(INDEX('Paella Yield & Pan Sizing'!$C$9:$C$15,MATCH($B$9,'Paella Yield & Pan Sizing'!$A$9:$A$15,0)),1) -> 40 | C45: =IFERROR(INDEX('Paella Yield & Pan Sizing'!$C$9:$C$15,MATCH($C$9,'Paella Yield & Pan Sizing'!$A$9:$A$15,0)),1) -> 40 | D45: =IFERROR(INDEX('Paella Yield & Pan Sizing'!$C$9:$C$15,MATCH($D$9,'Paella Yield & Pan Sizing'!$A$9:$A$15,0)),1) -> 40
A46: Paella pans to cook | B46: =ROUNDUP($B$7/$B$45,0) -> 1 | C46: =ROUNDUP($C$7/$C$45,0) -> 2 | D46: =ROUNDUP($D$7/$D$45,0) -> 3
A47: Uncooked rice (lb) | B47: =$B$7*$B$10/16 -> 6.09375 | C47: =$C$7*$C$10/16 -> 9.140625 | D47: =$D$7*$D$10/16 -> 22.34375
A48: Stock (gallons) | B48: =$B$47*'Paella Yield & Pan Sizing'!$B$5/4 -> 1.828125 | C48: =$C$47*'Paella Yield & Pan Sizing'!$B$5/4 -> 2.7421875 | D48: =$D$47*'Paella Yield & Pan Sizing'!$B$5/4 -> 6.703125
A49: Propane for the cook (lb) | B49: =$B$46*IFERROR(INDEX('Paella Yield & Pan Sizing'!$I$9:$I$15,MATCH($B$9,'Paella Yield & Pan Sizing'!$A$9:$A$15,0)),0) -> 3 | C49: =$C$46*IFERROR(INDEX('Paella Yield & Pan Sizing'!$I$9:$I$15,MATCH($C$9,'Paella Yield & Pan Sizing'!$A$9:$A$15,0)),0) -> 6 | D49: =$D$46*IFERROR(INDEX('Paella Yield & Pan Sizing'!$I$9:$I$15,MATCH($D$9,'Paella Yield & Pan Sizing'!$A$9:$A$15,0)),0) -> 9
A50: 20-lb propane cylinders to bring (plus one spare) | B50: =ROUNDUP($B$49/20,0)+1 -> 2 | C50: =ROUNDUP($C$49/20,0)+1 -> 2 | D50: =ROUNDUP($D$49/20,0)+1 -> 2
...

Sheet Instructions
A1: HOW TO USE THE PAELLA CATERING PRICING CALCULATOR
A2: This workbook turns guests into paella pans, rice, stock and propane, prices each guest and builds a full quote and the shopping list. You type only in the GREEN cells; the gross margin is calculated, never typed.
A3: 1. "Pricing Calculator": choose the package (drop-off paella, live paella party or full-service live paella), the menu style, the guests, your guest minimum and the pan size. The pan size sets the guests per pan (36 in (90 cm) = about 40, Kit estimate). The rice per guest is 3.25 oz (92 g) of uncooked bomba rice by default, inside the 3 to 3.5 oz (85-100 g) that serves a crowd.
A4: 2. "Paella Yield & Pan Sizing": type your supplier prices for the rice and the ingredients of your styles (per lb; saffron per gram). They are blank on purpose: this kit does not guess 2026 seafood or saffron prices. While any ingredient of the chosen style has no price, the food cost uses the style estimate per guest (Kit: about $5 chicken & chorizo, $8.50 seafood, $16.50 lobster) and the "Ingredient prices" row says so.
A5: 3. Back on the first tab, enter the tapas hour switch and its cost, salad and bread, disposables, propane, your staff (event day and commissary prep hours), rentals and mileage. Then the marketplace fee, your target margin, the service charge, the sales tax rate and the switch "Does your state tax the service charge?". The price per guest is the direct cost divided by (1 - target margin - marketplace fee) and by the billable guests, rounded up to the next 0.50; any event fee goes on top.
A6: 4. Deposit and cancellation: US caterers ask 25-50% to hold the date (the calculator uses 50%, a kit estimate) and four cancellation tiers with no gaps tell you what you keep. Put the same tiers in your contract, with a plan B for wind, rain or a venue that does not allow open flame.
A7: 5. "Paella Yield & Pan Sizing": guests, rice, stock and propane per pan for 7 sizes, and the ingredients per guest, the Food Code minimum, the hot holding rule and the typical allergens of 8 menu styles. Replace the kit estimates with the numbers from your own test cooks.
A8: 6. "Shopping List by Guest Count": pans and burners, rice, stock, every ingredient of the style, saffron, lemons, bread, salad, aioli, propane and cylinders, plates, ice and coolers for the seafood, chafing dishes for the tapas hour and the suggested team, for your event and for 40, 80, 150 and 300 guests.
A9: 7. "3 Example Quotes": three complete quotes calculated with the same formulas. To move from these per-package prices to the average price per guest of the financial projections, weight each package price by its guests in the year.
A10: FOOD SAFETY (FDA FOOD CODE 2022)
A12: Cook to the minimum (3-401.11): chicken 165 °F (74 °C); fish and shellfish 145 °F (63 °C) for 15 seconds; raw Mexican-style chorizo 155 °F (68 °C) for 17 seconds (Spanish cured chorizo is ready to eat). Cooked rice needs time and temperature control: hold it at 135 °F (57 °C) or above (3-501.16) or use time as a public health control with a written procedure and discard it after 4 hours (3-501.19, if your county accepts it). Leftovers go in the trash. Keep the shellstock tags of mussels and clams for 90 days (3-203.12).
A13: SERVICE CHARGE, GRATUITY AND SALES TAX (US)
... A29: Planning tool, not financial, tax or legal advice. Requirements vary by state, county and city — check with your accountant and local authorities.
