Workbook

Sheet Instrucciones
A1: Calculadora de inversión inicial (CAPEX)
A2: AI Chef Pro · aichef.pro — Cómo Montar una Chocolatería
A3: Para qué sirve: saber cuánto dinero necesitas de verdad para abrir una chocolatería, y si sale mejor un traspaso o una obra nueva.
A5: Instrucciones de uso
A6: 1. Hoja «Parámetros»: los metros del local, el precio por m² de la obra, los tipos de IVA, la renta, el horizonte de comparación y los kilos de plástico que importas. Todo lo que calcula el libro sale de aquí.
A7: 2. Hoja «CAPEX por Bloque»: una fila por partida. Escribe el mínimo y el máximo que te hayan presupuestado y el importe con el que trabajas, di si ESE importe lleva IVA y a qué tipo, y marca «No» en lo que no vayas a comprar. La hoja lleva todo a base imponible antes de sumar, que es la única forma de que el total signifique algo. Abajo va el cruce con el libro 7: el fondo de maniobra llega YA CALCULADO de allí.
A8: 3. Hoja «Variante del Formato»: tu chocolatería puede no ser la del ejemplo. Tres variantes -bombonería, bean-to-bar y taza y churros-, la lista de la compra del bean-to-bar SIN precios inventados, y la comparación con la franquicia.
A9: 4. Hoja «Traspaso vs Obra Nueva»: el precio del traspaso no es lo que cuesta el traspaso. Mete la renta de los dos casos, los meses que estarás parado en cada uno y los años del contrato, y compara el coste completo. Abajo, ocho traspasos reales para que veas la horquilla.
A10: 5. Hoja «IVA y Tesorería»: cuánto IVA adelantas, cuándo vuelve, cuánta caja tienes que tener el día que abres y si el impuesto al plástico te afecta o no. Es la hoja que más sorprende.
A11: 6. Hoja «Resumen»: las cifras que hay que llevar al banco, todas calculadas desde las hojas anteriores.
A13: Celdas verdes = campos editables
A15: Lo que conviene saber antes de empezar
... A23: Dónde acaba este libro y dónde sigue otro
A24: Lo que necesitas | B24: Dónde está | C24: Por qué no está aquí
A25: A quién compras cada máquina, a qué precio negociado y con qué plazo de entrega | B25: Libro 9: checklist-equipamiento-y-proveedores-cacao.xlsx | C25: Aquí la máquina entra sólo por su importe. El plazo de entrega no cambia el CAPEX: cambia la fecha de apertura, y eso es el libro 8.
A26: El P&L a tres años, la tesorería mes a mes, los gastos fijos y el cuadro de la deuda | B26: Libro 7: plan-financiero-3-anos-chocolateria.xlsx | C26: De ese libro sale el FONDO DE MANIOBRA ya calculado, que aquí llega en una celda verde con su fila de cuadre. Los meses de colchón se deciden allí, no aquí: si se decidieran en los dos sitios, el fondo se calcularía dos veces.
A27: Si ese local sirve, si se puede climatizar y cuántos bombones al día aguanta el equipo | B27: Libro 1: capacidad-obrador-y-clima.xlsx | C27: Comprar bien empieza por saber qué necesitas, no cuánto cuesta. Los dos libros comparten los mismos 75 m² y la misma columna de IVA.
A28: Qué papeles te tocan, en qué orden y cuándo abres | B28: Libro 8: checklist-legal-licencias-y-cacao.xlsx | C28: Las tasas, el proyecto técnico y la comunicación al registro autonómico están aquí como IMPORTE; el procedimiento y el calendario, allí.
A29: Cómo funciona el impuesto al plástico y qué tienes que registrar | B29: Capítulo 13 de la guía | C29: Esta hoja sólo emite la ALERTA cuando pasas el umbral de los 5 kg al mes. Explicarlo entero dentro de una calculadora sería esconder la explicación donde nadie la lee.
A30: Presupuestos de proveedor por partida y hoja de compra | B30: kit-tareas-chocolateria/02-partidas-produccion.xlsx (kit de 12 €) | C30: El kit trae la plantilla de negociación por proveedor; esta calculadora sólo suma lo que ya has decidido comprar. No cubre la inversión: es la ficha con la que la negocias.
A31: Es COPIA declarada, no vínculo: en toda la guía no hay ni una fórmula que apunte a otro fichero. Un enlace entre libros se rompe en cuanto alguien mueve una carpeta, y entonces el libro miente sin avisar. Donde una celda verde trae un dato de otro libro, viene con su valor por defecto declarado y con una fila de CUADRE que te avisa si lo que has tecleado se aleja del origen.
A33: Cada cuánto se usa este libro
A34: Cadencia: se rellena UNA VEZ al preparar el plan y se revisa cada vez que entra un presupuesto nuevo, hasta la firma. Después de abrir sólo se vuelve a él para comparar lo presupuestado con lo gastado de verdad -que es la hoja «Equipamiento» del libro 9- y eso es lo que enseña a presupuestar el siguiente.
A36: Para editar la estructura o una celda que no esté en verde: Revisar > Desproteger hoja (no tiene contraseña).
A38: Diseñado por John Guerrero — chef y consultor gastronómico desde 2010, en cocina desde los 17 años.
A39: Versión 1.0 · septiembre 2026 · aichef.pro/guia-chocolateria-obrador · info@aichef.pro

Sheet Parámetros
A1: Parámetros
A2: AI Chef Pro · aichef.pro — Cómo Montar una Chocolatería
A3: Todo lo que el libro calcula sale de aquí. Ni un número vive dentro de una fórmula.
A5: Parámetro | B5: Valor | C5: Unidad | D5: Procedencia | E5: Qué es y de dónde sale
A6: Superficie total del local | B6: 75 | C6: m2 | D6: supuesto | E6: Los mismos 75 m² del libro 1. Si los cambias, cambia la obra: es la única partida del CAPEX que no se teclea.
A7: Coste de obra y adecuación por m² | B7: 380 | C7: €/m² | D7: supuesto | E7: SUPUESTO DECLARADO: ninguna fuente del research publica un coste de obra por m² de obrador de chocolate. Es más barata que la de una pastelería por un motivo estructural, no por suerte: un obrador de chocolate NO genera humos, así que no hay conducto a cubierta ni la conversación con la comunidad de propietarios que lo acompaña. Pide tres presupuestos y sustitúyelo.
A8: Obra y adecuación calculada | B8: =IFERROR(B6*B7,"") -> 28500 | C8: € | D8: Se calcula | E8: Superficie x precio por m².
A9: IVA general | B9: 0.21 | C9: % | D9: art. 90.Uno de la Ley 37/1992 | E9: Tipo general: obra, equipamiento, mobiliario, proyecto y clima. Es el valor por defecto de la columna «tipo de IVA» de cada línea, pero cada línea tiene el suyo.
A10: IVA del chocolate que vas a vender | B10: 0.1 | C10: % | D10: CHN-71 | E10: No entra en el CAPEX: está aquí porque es el IVA que repercutirás y contra el que se compensa el que adelantas ahora. El chocolate va al 10 % POR EXCLUSIÓN, no porque un precepto lo nombre: la lista del 4 % es cerrada y tiene siete letras, y el chocolate no está en ninguna.
A11: IVA de tasas y trámites | B11: 0 | C11: % | D11: supuesto | E11: Las tasas municipales y la comunicación al registro autonómico no llevan IVA. Se declara como parámetro para que la columna de la hoja de CAPEX no tenga que hacer una excepción escondida.
A12: Renta mensual del local | B12: 1300 | C12: €/mes | D12: supuesto | E12: Supuesto para una ciudad media. La renta observada en los ocho traspasos verificados va de 910 euros/mes (`CHS-37b`, 74 m² en Madrid-Vallecas) a 2.200 euros/mes (`CHS-38c`, 180 m² en Barcelona); aquí se toma la parte baja porque ninguna de esas dos ciudades es una ciudad media.
A13: Meses de fianza | B13: 2 | C13: meses | D13: supuesto | E13: La fianza no es un gasto: es un depósito que se recupera. Va en el CAPEX porque hay que tenerla el día de la firma, y por eso no se amortiza.
A14: Horizonte de comparación | B14: 5 | C14: años | D14: supuesto | E14: Años sobre los que se compara el traspaso con la obra nueva. Cinco es lo habitual de un contrato con obligado cumplimiento; ponle los del tuyo.
A15: Periodicidad de la declaración de IVA | B15: 3 | C15: meses | D15: supuesto | E15: Trimestral en el régimen general de una bombonería que arranca. Si te inscribes en el registro de devolución mensual, esto es 1 y el IVA de la inversión vuelve mucho antes.
A16: Meses hasta recuperar el IVA de la inversión | B16: 4 | C16: meses | D16: supuesto | E16: El trimestre en el que compras más el plazo de presentación. Y ojo: en régimen general lo normal no es que te lo devuelvan, es que lo compenses contra el IVA que repercutes, así que tarda lo que tardes en facturar.
A17: Financiación bancaria disponible | B17: 90300 | C17: € | D17: supuesto | E17: El 60 % de la inversión total, que es la estructura 40/60 supuesta en el libro 7. No se teclea allí ni aquí como número fijo: se deriva, para que si cambia una partida del CAPEX la estructura siga saliendo exacta.
A18: Colchón mínimo aceptable antes de avisar | B18: 3 | C18: meses | D18: supuesto | E18: Umbral del veredicto de caja. Es el mínimo que te exiges TÚ, no los meses con los que se dota el fondo: esos se deciden en el libro 7, que es donde están los gastos fijos con los que se multiplican.
A19: Kg de plástico no reciclado importado o adquirido en otro país de la UE | B19: 3.2 | C19: kg al mes | D19: supuesto | E19: Kilos de plástico no reciclado de los ENVASES que importas o compras en otro país de la UE, al mes. NO son los kilos totales de packaging: lo que compras en España a un proveedor español ya lo lleva repercutido. Por eso la pregunta es dónde compras, no cuánto.
A20: Umbral de la exención del impuesto al plástico | B20: 5 | C20: kg al mes | D20: CHN-62b | E20: El art. 75.f) exime la importación o adquisición intracomunitaria que no exceda de 5 kilogramos en un mes, y SÓLO de los envases del art. 68.1.a): NO exime la fabricación, ni los semielaborados, ni los cierres.
A21: Tipo del impuesto al plástico | B21: 0.45 | C21: €/kg | D21: CHN-62 | E21: Se aplica sobre los kilos de plástico NO RECICLADO contenidos en el envase, no sobre el peso del envase entero.
A23: AQUÍ NO ESTÁN LOS MESES DE COLCHÓN DE TESORERÍA, Y NO ES UN OLVIDO. El fondo de maniobra es «meses de colchón x gastos fijos mensuales», y los DOS factores viven en el libro 7, que es donde se calculan los gastos fijos. Este libro recibe el fondo YA CALCULADO en la celda verde del cruce, al pie de la hoja «CAPEX por Bloque». Si lo pidiera aquí, el fondo se calcularía dos veces y los dos libros publicarían dos inversiones totales distintas con el mismo nombre.
A25: Los valores marcados «supuesto» son los de la bombonería de ejemplo «La Almendra» (75 m² en una ciudad media española, obrador propio y tienda a calle). NO son datos de sector: son un punto de partida coherente para que puedas ver el libro funcionando antes de meter los tuyos.

Sheet CAPEX por Bloque
A1: CAPEX por Bloque
A2: AI Chef Pro · aichef.pro — Cómo Montar una Chocolatería
A3: Nueve bloques, y el fondo de maniobra tiene fila propia porque llega del libro 7. Todas las líneas se llevan a base imponible antes de sumar: sin la columna de IVA, el total se desvía un 21 %.
A5: Nº | B5: Bloque | C5: Partida | D5: ¿La compras? | E5: Procedencia | F5: Base declarada por la fuente | G5: ¿Tu precio lleva IVA? | H5: Tipo de IVA | I5: Mínimo | J5: Máximo | K5: Tu importe | L5: Base sin IVA | M5: IVA soportado | N5: Total con IVA | O5: Cómo se publica el precio | P5: Nota
A6: 1 | B6: Obra y adecuación | C6: Obra y adecuación del local (75 m² x 380 euros/m²) | D6: Sí | E6: supuesto | F6: sin IVA | G6: No | H6: ='Parámetros'!$B$9 -> 0.21 | I6: ='Parámetros'!B8 -> 28500 | J6: ='Parámetros'!B8 -> 28500 | K6: ='Parámetros'!B8 -> 28500 | L6: =IF(D6="No","",IFERROR(IF(G6="Sí",K6/(1+H6),K6),"")) -> 28500 | M6: =IF(L6="","",IFERROR(L6*H6,"")) -> 5985 | N6: =IF(L6="","",IFERROR(L6+M6,"")) -> 34485 | O6: La calcula «Parámetros» con tus metros y tu precio por m² | P6: SUPUESTO declarado: ninguna fuente del research publica un coste de obra por m² de obrador de chocolate. Es mas barata que la de una pastelería por un motivo estructural: un obrador de chocolate NO genera humos, así que no hay conducto a cubierta ni la conversación con la comunidad de propietarios que lo acompaña. Publicar esta cifra como dato verificado esta prohibido (§5.1, 28).
A7: 2 | B7: Equipo de templado y moldeado | C7: Atemperadora continua de sobremesa, 12 kg (55 kg/h) — Selmi One | D7: Sí | E7: CHS-41a | F7: no declarada | G7: No | H7: ='Parámetros'!$B$9 -> 0.21 | I7: 8500 | J7: 8500 | K7: 8500 | L7: =IF(D7="No","",IFERROR(IF(G7="Sí",K7/(1+H7),K7),"")) -> 8500 | M7: =IF(L7="","",IFERROR(L7*H7,"")) -> 1785 | N7: =IF(L7="","",IFERROR(L7+M7,"")) -> 10285 | O7: Precio de ficha de distribuidor (CHS-41a) | P7: La ficha NO declara si el precio lleva IVA: se trata como base imponible y SE MARCA, que es lo honesto. El corazón del obrador y la decisión 2 del bonus 2. Base de IVA NO declarada: la ficha trae el indicio «/Neto» en la línea de embalaje, que no es confirmable. La escalera completa va de esta a la Cento EX de 100 kg (`CHS-41g`), y la elección la decide los kg/semana que salga en la hoja de capacidad del libro 1.
A8: 3 | B8: Equipo de templado y moldeado | C8: Embalaje, transporte y puesta en marcha de la atemperadora — Selmi servicio | D8: Sí | E8: CHS-41a | F8: no declarada | G8: No | H8: ='Parámetros'!$B$9 -> 0.21 | I8: 1045 | J8: 1045 | K8: 1045 | L8: =IF(D8="No","",IFERROR(IF(G8="Sí",K8/(1+H8),K8),"")) -> 1045 | M8: =IF(L8="","",IFERROR(L8*H8,"")) -> 219.45 | N8: =IF(L8="","",IFERROR(L8+M8,"")) -> 1264.45 | O8: Precio de ficha de distribuidor (CHS-41a) | P8: La ficha NO declara si el precio lleva IVA: se trata como base imponible y SE MARCA, que es lo honesto. La línea que nadie presupuesta: es el 12 % del precio de la máquina. La ficha la marca «Neto», que es un INDICIO de base sin IVA, no una declaración: por eso va como «no declarada».
A9: 4 | B9: Equipo de templado y moldeado | C9: Enrobadora de banda, 200 mm — Selmi R200 Legend | D9: Sí | E9: CHS-42a | F9: no declarada | G9: No | H9: ='Parámetros'!$B$9 -> 0.21 | I9: 6800 | J9: 6800 | K9: 6800 | L9: =IF(D9="No","",IFERROR(IF(G9="Sí",K9/(1+H9),K9),"")) -> 6800 | M9: =IF(L9="","",IFERROR(L9*H9,"")) -> 1428 | N9: =IF(L9="","",IFERROR(L9+M9,"")) -> 8228 | O9: Precio de ficha de distribuidor (CHS-42a) | P9: La ficha NO declara si el precio lleva IVA: se trata como base imponible y SE MARCA, que es lo honesto. Base de IVA NO declarada por la ficha del distribuidor.
A10: 5 | B10: Equipo de templado y moldeado | C10: Placa dosificadora de rellenos — Selmi placa dosificadora | D10: Sí | E10: CHS-42i | F10: no declarada | G10: No | H10: ='Parámetros'!$B$9 -> 0.21 | I10: 1495 | J10: 1495 | K10: 1495 | L10: =IF(D10="No","",IFERROR(IF(G10="Sí",K10/(1+H10),K10),"")) -> 1495 | M10: =IF(L10="","",IFERROR(L10*H10,"")) -> 313.95 | N10: =IF(L10="","",IFERROR(L10+M10,"")) -> 1808.95 | O10: Precio de ficha de distribuidor (CHS-42i) | P10: La ficha NO declara si el precio lleva IVA: se trata como base imponible y SE MARCA, que es lo honesto. Base de IVA NO declarada por la ficha del distribuidor.
A11: 6 | B11: Equipo de templado y moldeado | C11: Temperador de baño maria digital, 22 L — Utilcentre baño maria digital 22 L | D11: Sí | E11: CHS-41j | F11: no declarada | G11: No | H11: ='Parámetros'!$B$9 -> 0.21 | I11: 2650 | J11: 2650 | K11: 2650 | L11: =IF(D11="No","",IFERROR(IF(G11="Sí",K11/(1+H11),K11),"")) -> 2650 | M11: =IF(L11="","",IFERROR(L11*H11,"")) -> 556.5 | N11: =IF(L11="","",IFERROR(L11+M11,"")) -> 3206.5 | O11: Precio de ficha de distribuidor (CHS-41j) | P11: La ficha NO declara si el precio lleva IVA: se trata como base imponible y SE MARCA, que es lo honesto. Segunda línea de templado: sin ella no se trabajan dos coberturas a la vez.
A12: 7 | B12: Equipo de templado y moldeado | C12: Mantenedor de 1 cubeta, digital — Utilcentre mantenedor 1 cubeta digital | D12: Sí | E12: CHS-41i | F12: no declarada | G12: No | H12: ='Parámetros'!$B$9 -> 0.21 | I12: 570 | J12: 570 | K12: 570 | L12: =IF(D12="No","",IFERROR(IF(G12="Sí",K12/(1+H12),K12),"")) -> 570 | M12: =IF(L12="","",IFERROR(L12*H12,"")) -> 119.7 | N12: =IF(L12="","",IFERROR(L12+M12,"")) -> 689.7 | O12: «DESDE», suelo comercial: presupuéstalo (CHS-41i, D23b) | P12: La ficha NO declara si el precio lleva IVA: se trata como base imponible y SE MARCA, que es lo honesto. ES UN «DESDE», NO UN PRECIO (D23b): la ficha publica «desde 570,00 euros» y eso es un SUELO comercial, no el precio de la unidad que vas a comprar. Se presupuesta. Publicarlo como precio cerrado esta prohibido, y el techo del escenario B solo puede subir por su culpa.
A13: 8 | B13: Equipo de templado y moldeado | C13: Atemperadora de arranque, 4,5 L (unos 3 kg) — Pavoni MINITEMPER | D13: No | E13: CHS-41h | F13: no declarada | G13: No | H13: ='Parámetros'!$B$9 -> 0.21 | I13: 1960 | J13: 1960 | K13: 1960 | L13: =IF(D13="No","",IFERROR(IF(G13="Sí",K13/(1+H13),K13),"")) | M13: =IF(L13="","",IFERROR(L13*H13,"")) | N13: =IF(L13="","",IFERROR(L13+M13,"")) | O13: Precio de ficha de distribuidor (CHS-41h) | P13: OPCIONAL: viene con «¿la compras?» en No. La ficha NO declara si el precio lleva IVA: se trata como base imponible y SE MARCA, que es lo honesto. NO esta en la dotación de La Almendra: es la máquina del ESCENARIO B, el arranque mínimo, y aparece para que el lector vea la escalera. Cubeta adicional, 165,30 euros (`CHS-41h`).
A14: 9 | B14: Equipo de templado y moldeado | C14: Cubeta adicional para la atemperadora de arranque — Pavoni cubeta MINITEMPER | D14: No | E14: CHS-41h | F14: no declarada | G14: No | H14: ='Parámetros'!$B$9 -> 0.21 | I14: 165.3 | J14: 165.3 | K14: 165.3 | L14: =IF(D14="No","",IFERROR(IF(G14="Sí",K14/(1+H14),K14),"")) | M14: =IF(L14="","",IFERROR(L14*H14,"")) | N14: =IF(L14="","",IFERROR(L14+M14,"")) | O14: Precio de ficha de distribuidor (CHS-41h) | P14: OPCIONAL: viene con «¿la compras?» en No. La ficha NO declara si el precio lleva IVA: se trata como base imponible y SE MARCA, que es lo honesto. Accesorio del escenario B.
A15: 10 | B15: Frío (cámara, nevera de rellenos y vitrina) | C15: Vitrina refrigerada específica para chocolate — Docriluc WB-6-6-R | D15: Sí | E15: CHS-43 | F15: sin IVA | G15: No | H15: ='Parámetros'!$B$9 -> 0.21 | I15: 2684.99 | J15: 2684.99 | K15: 2684.99 | L15: =IF(D15="No","",IFERROR(IF(G15="Sí",K15/(1+H15),K15),"")) -> 2684.99 | M15: =IF(L15="","",IFERROR(L15*H15,"")) -> 563.8479 | N15: =IF(L15="","",IFERROR(L15+M15,"")) -> 3248.8379 | O15: Precio de ficha de distribuidor (CHS-43) | P15: 600x730x1380 mm. RANGO DE TRABAJO DEL EQUIPO: +14 a +17 °C, con base SIN IVA declarada literalmente por la ficha. NO son los +2/+4 °C de una vitrina de pastelería, que arruina el bombón por condensación, sugar bloom y perdida de brillo. El OBJETIVO OPERATIVO es otra cosa y lo pone el kit: 16-18 °C y menos del 55 % de humedad. El semáforo del libro 5 solo avisa por encima de 20 °C, y queda PROHIBIDO uno que ponga en rojo los 16-18 del propio kit. Precio de oferta (antes 3.487,00 euros): esta FECHADO el 12-09-2026 y puede caducar.
A16: 11 | B16: Frío (cámara, nevera de rellenos y vitrina) | C16: Cámara climatizada de chocolate, unos 6 m² | D16: Sí | E16: supuesto | F16: sin IVA | G16: No | H16: ='Parámetros'!$B$9 -> 0.21 | I16: 6400 | J16: 6400 | K16: 6400 | L16: =IF(D16="No","",IFERROR(IF(G16="Sí",K16/(1+H16),K16),"")) -> 6400 | M16: =IF(L16="","",IFERROR(L16*H16,"")) -> 1344 | N16: =IF(L16="","",IFERROR(L16+M16,"")) -> 7744 | O16: Sin precio publicado: valor por defecto SUPUESTO | P16: SUPUESTO, no precio de ficha. SUPUESTO declarado: ninguna fuente del research publica el precio de una cámara de chocolate. Celda verde con valor por defecto. No es una nevera: trabaja a 15-18 °C y 50-60 % de humedad, y ese control de HUMEDAD es lo que la encarece frente a una cámara de pastelería.
A17: 12 | B17: Frío (cámara, nevera de rellenos y vitrina) | C17: Nevera de rellenos y ganaches | D17: Sí | E17: supuesto | F17: sin IVA | G17: No | H17: ='Parámetros'!$B$9 -> 0.21 | I17: 1450 | J17: 1450 | K17: 1450 | L17: =IF(D17="No","",IFERROR(IF(G17="Sí",K17/(1+H17),K17),"")) -> 1450 | M17: =IF(L17="","",IFERROR(L17*H17,"")) -> 304.5 | N17: =IF(L17="","",IFERROR(L17+M17,"")) -> 1754.5 | O17: Sin precio publicado: valor por defecto SUPUESTO | P17: SUPUESTO, no precio de ficha. SUPUESTO. Es la del RELLENO, a 0-4 °C, no la del bombón acabado. Confundirlas es el error de método que la SPEC persigue.
A18: 13 | B18: Packaging y moldes | C18: Moldes de policarbonato para bombonería (24 unidades) — Chocolate World varios (CF0246, CW12064, CW1000L07) | D18: Sí | E18: CHS-45a | F18: no declarada | G18: No | H18: ='Parámetros'!$B$9 -> 0.21 | I18: 580.8 | J18: 1027.92 | K18: 804.36 | L18: =IF(D18="No","",IFERROR(IF(G18="Sí",K18/(1+H18),K18),"")) -> 804.36 | M18: =IF(L18="","",IFERROR(L18*H18,"")) -> 168.9156 | N18: =IF(L18="","",IFERROR(L18+M18,"")) -> 973.2756 | O18: RANGO, no precio cerrado: CHS-45a (D23a) | P18: La ficha NO declara si el precio lleva IVA: se trata como base imponible y SE MARCA, que es lo honesto. SE PUBLICA COMO RANGO (D23a). El único dato medido es 24,20-42,83 euros/ud (`CHS-45a`): 24 moldes valen entre 580,80 y 1.027,92 euros. El valor por defecto (804,36) es el punto medio del rango, y es SUPUESTO. Escribir una multiplicación con un precio unitario elegido a ojo esta prohibido. Y los moldes de policarbonato NO pagan el impuesto al plastico: no están sujetos por el art. 73.d) de la Ley 7/2022 (`CHN-62c`), porque no se entregan junto con la mercancía.
... A23: 18 | B23: Mobiliario y tienda | C23: Chocolatera de 3 L para la variante de taza — Ugolini Delice 3 | D23: No | E23: CHS-46a | F23: sin IVA | G23: No | H23: ='Parámetros'!$B$9 -> 0.21 | I23: 527 | J23: 527 | K23: 527 | L23: =IF(D23="No","",IFERROR(IF(G23="Sí",K23/(1+H23),K23),"")) | M23: =IF(L23="","",IFERROR(L23*H23,"")) | N23: =IF(L23="","",IFERROR(L23+M23,"")) | O23: Precio de ficha de distribuidor (CHS-46a) | P23: OPCIONAL: viene con «¿la compras?» en No. Base SIN IVA declarada literalmente por la ficha. Solo entra en el escenario de taza y churros, que es OTRO negocio (D1): la Ley 12/2012 los separa sola, porque su Anexo incluye el epígrafe 644.5 de bombones y caramelos y NO contiene ningún grupo de la agrupación 67, donde esta la chocolatería de taza (`CHN-49c`).
A24: 19 | B24: Fianza y licencias | C24: Fianza de arrendamiento (2 meses) | D24: Sí | E24: supuesto | F24: sin IVA | G24: No | H24: ='Parámetros'!$B$11 -> 0 | I24: =IFERROR('Parámetros'!B12*'Parámetros'!B13,"") -> 2600 | J24: =IFERROR('Parámetros'!B12*'Parámetros'!B13,"") -> 2600 | K24: =IFERROR('Parámetros'!B12*'Parámetros'!B13,"") -> 2600 | L24: =IF(D24="No","",IFERROR(IF(G24="Sí",K24/(1+H24),K24),"")) -> 2600 | M24: =IF(L24="","",IFERROR(L24*H24,"")) -> 0 | N24: =IF(L24="","",IFERROR(L24+M24,"")) -> 2600 | O24: Renta mensual x meses de fianza | P24: La fianza NO es un gasto: es un deposito que se recupera. Va en el CAPEX porque hay que tenerla el día de la firma, y por eso no se amortiza.
A25: 20 | B25: Fianza y licencias | C25: Proyecto técnico visado | D25: Sí | E25: supuesto | F25: sin IVA | G25: No | H25: ='Parámetros'!$B$9 -> 0.21 | I25: 4500 | J25: 4500 | K25: 4500 | L25: =IF(D25="No","",IFERROR(IF(G25="Sí",K25/(1+H25),K25),"")) -> 4500 | M25: =IF(L25="","",IFERROR(L25*H25,"")) -> 945 | N25: =IF(L25="","",IFERROR(L25+M25,"")) -> 5445 | O25: SUPUESTO declarado: pídelo, no lo copies | P25: SUPUESTO declarado. `CHN-50` (coste de proyecto técnico) esta en EXCLUIDOS de la verificación legal: no hay fuente, y publicar una cifra de proyecto técnico como dato verificado esta prohibido (§5.1, 28).
A26: 21 | B26: Fianza y licencias | C26: Tasas municipales | D26: Sí | E26: supuesto | F26: sin IVA | G26: No | H26: ='Parámetros'!$B$11 -> 0 | I26: 1200 | J26: 1200 | K26: 1200 | L26: =IF(D26="No","",IFERROR(IF(G26="Sí",K26/(1+H26),K26),"")) -> 1200 | M26: =IF(L26="","",IFERROR(L26*H26,"")) -> 0 | N26: =IF(L26="","",IFERROR(L26+M26,"")) -> 1200 | O26: SUPUESTO declarado: pídelo, no lo copies | P26: Las tasas municipales no llevan IVA y su importe cambia en cada ayuntamiento: es el número que hay que ir a buscar, no copiar. Y ojo: ningún ayuntamiento puede exigirte LICENCIA PREVIA de instalación, funcionamiento o actividad hasta 750 m² de superficie útil de exposición y venta, porque el epígrafe 644.5 esta en el Anexo de la Ley 12/2012 (`CHN-49`, `CHN-49b`). Decir que trámite pide Madrid o Barcelona esta PROHIBIDO: no se ha abierto ninguna ordenanza.
A27: 22 | B27: Fianza y licencias | C27: Comunicación o declaración responsable al registro autonómico | D27: Sí | E27: CHN-39 + supuesto | F27: sin IVA | G27: No | H27: ='Parámetros'!$B$11 -> 0 | I27: 120 | J27: 120 | K27: 120 | L27: =IF(D27="No","",IFERROR(IF(G27="Sí",K27/(1+H27),K27),"")) -> 120 | M27: =IF(L27="","",IFERROR(L27*H27,"")) -> 0 | N27: =IF(L27="","",IFERROR(L27+M27,"")) -> 120 | O27: Importe publicado (CHN-39 + supuesto) | P27: NO es una licencia y NO habilita para abrir: es el trámite de información del minorista, que esta EXCLUIDO del RGSEAA (`CHN-39`). El importe es supuesto y en varias comunidades es gratuito; en la Comunitat Valenciana lleva tasa y es condición única y suficiente para iniciar la actividad, y en Madrid se presenta simultaneamente al inicio y no habilita (`CHN-43`).
A28: 23 | B28: Fondo de maniobra | C28: Fondo de maniobra traído del libro 7 (EUR) | D28: Sí | E28: supuesto | F28: sin IVA | G28: No | H28: ='Parámetros'!$B$11 -> 0 | I28: =$L$51 -> 61273.02 | J28: =$L$51 -> 61273.02 | K28: =$L$51 -> 61273.02 | L28: =IF(D28="No","",IFERROR(IF(G28="Sí",K28/(1+H28),K28),"")) -> 61273.02 | M28: =IF(L28="","",IFERROR(L28*H28,"")) -> 0 | N28: =IF(L28="","",IFERROR(L28+M28,"")) -> 61273.02 | O28: LLEGA DEL LIBRO 7 (cruce 2 <- 7): no se calcula aquí | P28: LLEGA YA CALCULADO DEL LIBRO 7 por celda verde con fila de cuadre (cruce 2 <- 7). El libro 2 NO pide «meses de colchón»: los dos factores del fondo -los meses y los gastos fijos del año de crucero- viven en el libro 7. Es caja, no inversión, y por eso el «Resumen» publica DOS líneas: «CAPEX sin el fondo de maniobra» (la que viaja al libro 7) y «Del cual, fondo de maniobra».
B30: Resumen por bloque (los NUEVE)
C31: Obra y adecuación | L31: =SUMIF($B$6:$B$28,C31,L$6:L$28) -> 28500 | M31: =SUMIF($B$6:$B$28,C31,M$6:M$28) -> 5985 | N31: =SUMIF($B$6:$B$28,C31,N$6:N$28) -> 34485 | O31: =IFERROR(L31/$L$40,"") -> 0.18937837
C32: Climatización y deshumidificación | L32: =SUMIF($B$6:$B$28,C32,L$6:L$28) -> 7600 | M32: =SUMIF($B$6:$B$28,C32,M$6:M$28) -> 1596 | N32: =SUMIF($B$6:$B$28,C32,N$6:N$28) -> 9196 | O32: =IFERROR(L32/$L$40,"") -> 0.050500899
C33: Equipo de templado y moldeado | L33: =SUMIF($B$6:$B$28,C33,L$6:L$28) -> 21060 | M33: =SUMIF($B$6:$B$28,C33,M$6:M$28) -> 4422.6 | N33: =SUMIF($B$6:$B$28,C33,N$6:N$28) -> 25482.6 | O33: =IFERROR(L33/$L$40,"") -> 0.13994065
C34: Frío (cámara, nevera de rellenos y vitrina) | L34: =SUMIF($B$6:$B$28,C34,L$6:L$28) -> 10534.99 | M34: =SUMIF($B$6:$B$28,C34,M$6:M$28) -> 2212.3479 | N34: =SUMIF($B$6:$B$28,C34,N$6:N$28) -> 12747.338 | O34: =IFERROR(L34/$L$40,"") -> 0.070003483
C35: Mobiliario y tienda | L35: =SUMIF($B$6:$B$28,C35,L$6:L$28) -> 6900 | M35: =SUMIF($B$6:$B$28,C35,M$6:M$28) -> 1449 | N35: =SUMIF($B$6:$B$28,C35,N$6:N$28) -> 8349 | O35: =IFERROR(L35/$L$40,"") -> 0.045849501
C36: Packaging y moldes | L36: =SUMIF($B$6:$B$28,C36,L$6:L$28) -> 3004.36 | M36: =SUMIF($B$6:$B$28,C36,M$6:M$28) -> 630.9156 | N36: =SUMIF($B$6:$B$28,C36,N$6:N$28) -> 3635.2756 | O36: =IFERROR(L36/$L$40,"") -> 0.019963537
C37: TPV, informática y rótulo | L37: =SUMIF($B$6:$B$28,C37,L$6:L$28) -> 3200 | M37: =SUMIF($B$6:$B$28,C37,M$6:M$28) -> 672 | N37: =SUMIF($B$6:$B$28,C37,N$6:N$28) -> 3872 | O37: =IFERROR(L37/$L$40,"") -> 0.021263536
C38: Fianza y licencias | L38: =SUMIF($B$6:$B$28,C38,L$6:L$28) -> 8420 | M38: =SUMIF($B$6:$B$28,C38,M$6:M$28) -> 945 | N38: =SUMIF($B$6:$B$28,C38,N$6:N$28) -> 9365 | O38: =IFERROR(L38/$L$40,"") -> 0.05594968
C39: Fondo de maniobra | L39: =SUMIF($B$6:$B$28,C39,L$6:L$28) -> 61273.02 | M39: =SUMIF($B$6:$B$28,C39,M$6:M$28) -> 0 | N39: =SUMIF($B$6:$B$28,C39,N$6:N$28) -> 61273.02 | O39: =IFERROR(L39/$L$40,"") -> 0.40715034
C40: CAPEX TOTAL (los nueve bloques) | L40: =SUM(L31:L39) -> 150492.37 | M40: =SUM(M31:M39) -> 17912.863 | N40: =SUM(N31:N39) -> 168405.23
C41: Del cual, IVA que hay que adelantar | L41: =M40 -> 17912.863
C42: Desembolso total con IVA | L42: =N40 -> 168405.23
C44: CAPEX SIN el fondo de maniobra (la cifra que viaja al libro 7) | L44: =IFERROR(L40-L39,"") -> 89219.35 | P44: ES ESTA LÍNEA, Y NO EL TOTAL, LA QUE VIAJA AL LIBRO 7 (cruce 7 <- 2). El total incluye el bloque «fondo de maniobra», y el libro 7 vuelve a dotar el fondo con sus propios meses de colchón: llevarle el total entero lo contaría DOS VECES y publicaría dos inversiones totales distintas para la misma bombonería.
C45: Del cual, fondo de maniobra (es caja, no inversión) | L45: =L39 -> 61273.02
C46: INVERSIÓN TOTAL (las dos líneas de arriba) | L46: =IFERROR(L44+L45,"") -> 150492.37
C48: Subtotal COMPARABLE con un presupuesto de obra y equipamiento (seis bloques) | L48: =L31+L32+L33+L34+L35+L37 -> 77794.99 | P48: Obra y adecuación, climatización, equipo de templado y moldeado, frío, mobiliario y tienda, y TPV/rótulo. Fuera quedan ENTEROS «fianza y licencias» (un depósito y unas tasas), «packaging y moldes» (existencias) y el fondo de maniobra (caja): un depósito no se compara contra un presupuesto de obra. Y el bloque de fianza y licencias sale entero, no medio: partirlo para rescatar las licencias sería inventar un décimo bloque sin dato propio.
...

Sheet Variante del Formato
A1: Variante del Formato
A2: AI Chef Pro · aichef.pro — Cómo Montar una Chocolatería
A3: Tu chocolatería puede no ser la del ejemplo. Tres variantes, y dos de ellas SIN cifras de maquinaria a propósito: no hay precio público verificado, y lo que se entrega es la lista de la compra y las preguntas.
B5: Las tres variantes, y qué cambia en cada una
B6: Variante | C6: Fuente | D6: ¿Es la tuya? | E6: CAPEX extra cifrable | H6: Qué cambia, y qué NO se puede cifrar
B7: Bombonería con obrador propio y tienda a calle (el caso de esta guía) | C7: CHS-03 | D7: Sí | E7: ='CAPEX por Bloque'!L46 -> 150492.37 | H7: Es el eje del producto y el caso que calcula la hoja «CAPEX por Bloque» entera: 60-100 m² y 1-2 empleados. Las otras dos son columnas de escenario, no productos aparte.
B8: Bean-to-bar: del grano a la tableta | C8: CHS-48 + CHS-51 | D8: No | E8: Sin cifra | H8: SIN CIFRAS DE MAQUINARIA A PROPÓSITO: no existe precio público verificado del tren bean-to-bar, y lo que se entrega es la lista de la compra y las preguntas que hay que hacer. Inventar el precio sería justo el patrón que la casa prohíbe. · Y la variante SUBE DE VALOR por dos motivos legales: (1) si importas grano ERES OPERADOR a efectos del EUDR, con diligencia debida completa, declaración presentada previamente y registro cinco años (CHN-25), no operador posterior; (2) el TOSTADO te puede meter en el CAPCA, y la nota (2) de su Anexo sube de grupo C a B cuando la actividad se desarrolla a menos de 500 m de un NÚCLEO DE POBLACIÓN (CHN-47b), es decir, en ciudad SIEMPRE. Ojo: «cacao» y «chocolate» tienen 0 ocurrencias en el CAPCA, así que encajar el tostado de cacao en «café o similares» es INTERPRETACIÓN, no mención expresa (CHN-47).
B9: Chocolatería de taza y churros | C9: CHS-46a + CHN-48 + CHN-49c | D9: No | E9: 527 | F9: Sólo la chocolatera | G9: sin IVA | H9: ES OTRO NEGOCIO, y la norma lo separa sola: el Anexo de la Ley 12/2012 incluye el epígrafe 644.5 «Comercio al por menor de bombones y caramelos» y NO contiene ningún grupo de la agrupación 67, donde está la chocolatería de taza (grupo 676). O sea que la bombonería se libra de la licencia previa hasta 750 m² y la chocolatería de taza no (CHN-49, CHN-49b, CHN-49c). · Lo que SÍ aporta: el chocolate convierte una ración de churros de 2,50 euros en 3,50-4 euros, un 40-60 % más de ticket (CHS-32), y el margen bruto del churro es del 85-90 % (CHS-31) - aunque un maestro churrero citado lo rebaja a «un poco más del 50 %», y los dos números se publican con su por qué, no se elige el más bonito. · Lo que cuesta: freidora, extracción de humos y la licencia que la bombonería se ahorra. Los precios de churrera, freidora y extracción NO están verificados (CHS-49).
B11: Bean-to-bar: la lista de la compra, SIN precios inventados
B12: NO HAY UNA SOLA CIFRA DE MAQUINARIA EN ESTE BLOQUE, Y ES A PROPÓSITO. Los catálogos existen y están verificados, pero los precios NO son públicos: se vende a presupuesto, o la tienda está fuera de la UE y el precio puesto en España depende del transporte y de la aduana. Inventarlos sería justo el patrón que esta casa prohíbe. Lo que sí se entrega es la lista de lo que hay que comprar y las cinco preguntas que hay que hacer antes de pedir un número.
B13: Equipo del tren bean-to-bar | D13: ¿Lo necesitas? | E13: ¿Tienes presupuesto por escrito? | H13: Qué mirar
B14: Tostador de grano | D14: Por decidir | E14: Por pedir | H14: El equipo que te puede meter en el CAPCA: la nota (2) de su Anexo sube de grupo C a B cuando la actividad se desarrolla a menos de 500 m de un núcleo de población, es decir, en ciudad SIEMPRE. Y ojo: «cacao» y «chocolate» tienen 0 ocurrencias en el CAPCA, así que encajar el tostado en «café o similares» es INTERPRETACIÓN, no mención expresa.
B15: Bandeja de enfriado | D15: Por decidir | E15: Por pedir
B16: Descascarilladora | D16: Por decidir | E16: Por pedir
B17: Winnower (aventadora) | D17: Por decidir | E17: Por pedir | H17: Junto con el tostador, el equipo ruidoso de un obrador que por lo demás es silencioso. Pregunta los dB a un metro antes de firmar el alquiler.
B18: Melanger o refinadora de piedra | D18: Por decidir | E18: Por pedir | H18: Trabaja durante días seguidos: su consumo es un gasto fijo del libro 7, no una compra.
B19: Concha | D19: Por decidir | E19: Por pedir
B20: Prensa de manteca (solo si separas manteca) | D20: Por decidir | E20: Por pedir
B21: Tamizadora | D21: Por decidir | E21: Por pedir
B22: Balanza de precisión para la formulación | D22: Por decidir | E22: Por pedir
B24: Las cinco preguntas al proveedor de bean-to-bar
B25: Precio de la máquina puesta en Espana, con transporte, aduana y puesta en marcha desglosados: los catálogos existen y están verificados, pero los precios NO son publicos (venta a presupuesto o tienda fuera de la UE). | E25: Por pedir
B26: Plazo de entrega real y quien hace el mantenimiento en Espana. | E26: Por pedir
B27: Potencia eléctrica y si necesita trifasica. | E27: Por pedir
B28: Ruido en dB a un metro: el tostador y el winnower son los dos equipos ruidosos de un obrador que por lo demás es silencioso. | E28: Por pedir
B29: Rendimiento en kg de grano por hora y merma de cascarilla. | E29: Por pedir
B31: Equipos del tren que dices necesitar | E31: =COUNTIF(D14:D22,"Sí") -> 0
B32: Respuestas que ya tienes por escrito (equipos y preguntas) | E32: =COUNTIF(E14:E22,"Sí")+COUNTIF(E25:E29,"Sí") -> 0
B33: VEREDICTO DEL BEAN-TO-BAR | E33: =IF(E31=0,"No es tu variante: no hay nada que presupuestar",IF(E32=0,"No tienes ni un precio: no puedes presupuestar esto todavía","Tienes presupuestos: llévalos al CAPEX como partidas")) -> No es tu variante: no hay nada que presupuestar
B35: Chocolatería de taza y churros: lo único cifrable y lo que no
B36: Equipo | C36: Fuente | D36: ¿Lo necesitas? | E36: Precio | F36: Base de IVA | H36: Qué mirar
B37: Chocolatera Ugolini Delice 3 (3 L) | C37: CHS-46a | D37: Por decidir | E37: 527 | F37: sin IVA | H37: Base SIN IVA declarada literalmente por la ficha. Es el ÚNICO equipo de esta variante con precio verificado, y por eso es el único que lleva número.
B38: Churrera | C38: CHS-49 (sin precio verificado) | D38: Por decidir | E38: Sin cifra | H38: SIN PRECIO VERIFICADO: no se publica ninguna cifra. Presupuéstalo y llévalo al CAPEX como partida propia.
B39: Freidora | C39: CHS-49 (sin precio verificado) | D39: Por decidir | E39: Sin cifra | H39: SIN PRECIO VERIFICADO: no se publica ninguna cifra. Presupuéstalo y llévalo al CAPEX como partida propia.
B40: Extracción de humos | C40: CHS-49 (sin precio verificado) | D40: Por decidir | E40: Sin cifra | H40: SIN PRECIO VERIFICADO: no se publica ninguna cifra. Presupuéstalo y llévalo al CAPEX como partida propia.
B41: Campana y conducto a cubierta | C41: CHS-49 (sin precio verificado) | D41: Por decidir | E41: Sin cifra | H41: SIN PRECIO VERIFICADO: no se publica ninguna cifra. Presupuéstalo y llévalo al CAPEX como partida propia.
B42: Obligación extra de esta variante | C42: Si hay freidora de gas, inspección periódica obligatoria de la instalación receptora CADA CINCO AÑOS, que en instalaciones de hasta 70 kW incluye los aparatos y comprueba la ventilación y el volumen mínimo del local (`CHN-48`).
B44: Franquicia frente a independiente: orden de magnitud publicado, nunca dato auditado
B45: Marca | C45: Formato | D45: Inversión desde | E45: Canon | F45: m² mínimos | G45: Fuente y fecha | H45: Etiqueta y nota
B46: Chok | C46: casual bakery + casual chocolate boutique | D46: 100000 | E46: 30000 | F46: 55 | G46: CHS-58 · 12-09-2026 | H46: orden de magnitud publicado por el portal de franquicias, no dato auditado — El local mas pequeño de todo el research: 55 m². Prueba que el formato chocolate-boutique cabe donde una pastelería no. Barcelona, 2012.
...

Sheet Traspaso vs Obra Nueva
A1: Traspaso Contra Obra Nueva
A2: AI Chef Pro · aichef.pro — Cómo Montar una Chocolatería
A3: El precio de un traspaso no es lo que cuesta un traspaso: la renta de los años del contrato pesa más que el precio.
A5: El local que estás mirando (traspaso)
A6: Precio de traspaso que te piden | B6: CHS-38a | C6: 26000 | J6: Sembrado con el caso más informativo del censo: 26.000 € por 90 m² de pastelería-bombonería CON OBRADOR EQUIPADO y 40 años de clientela, en El Prat de Llobregat. Es un precio PEDIDO en un anuncio, no un precio pagado.
A7: Inversión de adecuación que aún tendrías que hacer | B7: supuesto | C7: 18000 | J7: Un traspaso casi nunca se abre tal cual. En chocolate hay una partida que casi seguro falta: la CLIMATIZACIÓN con deshumidificación del obrador. Una pastelería traspasada tiene hornos, no clima de 18-20 °C. Míralo con la ficha de visita del libro 1 en la mano.
A8: Renta mensual del local traspasado | B8: CHS-38a | C8: 1100 | J8: La renta consta en tres de los ocho traspasos leídos. En los otros cinco el anuncio no la dice, que ya es un dato.
A9: Meses parado hasta abrir con el traspaso | B9: supuesto | C9: 1 | J9: Pagas renta desde la firma y no facturas hasta que abres.
A10: CAPEX comparable de la obra nueva (de «CAPEX por Bloque») | C10: ='CAPEX por Bloque'!L48 -> 77794.99 | J10: Los seis bloques comparables: sin fianza, sin packaging y sin fondo de maniobra. Los dos lados de la comparación los necesitan igual, así que sumarlos a uno solo falsearía el resultado.
A11: Renta mensual del local en obra nueva | C11: ='Parámetros'!B12 -> 1300
A12: Meses de obra sin facturar | B12: supuesto | C12: 4 | J12: Renta que pagas mientras el local está en obras. Es la partida que casi nadie mete y la que más se parece a una sorpresa.
A13: Horizonte de comparación (años) | C13: ='Parámetros'!B14 -> 5
A14: La comparación
A15: Coste del traspaso a lo largo del horizonte | C15: =IFERROR(C6+C7+C8*12*C13,"") -> 110000
A16: Coste de la obra nueva a lo largo del horizonte | C16: =IFERROR(C10+C11*12*C13,"") -> 155794.99
A17: Renta pagada sin facturar, traspaso | C17: =IFERROR(C8*C9,"") -> 1100
A18: Renta pagada sin facturar, obra nueva | C18: =IFERROR(C11*C12,"") -> 5200
A19: TOTAL del traspaso | C19: =IFERROR(C15+C17,"") -> 111100
A20: TOTAL de la obra nueva | C20: =IFERROR(C16+C18,"") -> 160994.99
A21: Diferencia (traspaso menos obra nueva) | C21: =IFERROR(C19-C20,"") -> -49894.99
A22: VEREDICTO | C22: =IF(C21="","",IF(C21<0,"Sale mejor el TRASPASO","Sale mejor la OBRA NUEVA")) -> Sale mejor el TRASPASO | J22: El veredicto compara dinero, y el dinero no lo es todo: un traspaso te da una clientela y un local que ya funcionó, y te ata a una distribución de zonas que igual no admite marcha adelante ni permite climatizar el obrador. Pasa el local traspasado por la ficha de visita del libro 1 antes de hacerle caso a esta celda.
A24: Ocho traspasos reales, para ver la horquilla. Son precios PEDIDOS, no pagados
A25: Ciudad o zona | B25: Tipo de negocio | C25: m2 | D25: Precio pedido | E25: Renta mensual | F25: € por m² | G25: Coste en el horizonte | H25: Fuente | I25: ¿Mismo formato?
A26: El Prat de Llobregat (Barcelona) | B26: Pastelería-bombonería con obrador (40+ años) | C26: 90 | D26: 26000 | E26: 1100 | F26: =IF(AND(ISNUMBER(C26),ISNUMBER(D26)),IFERROR(D26/C26,""),"") -> 288.88889 | G26: =IF(AND(ISNUMBER(D26),ISNUMBER(E26)),IFERROR(D26+E26*12*$C$13,""),"") -> 92000 | H26: CHS-38a | I26: Sí
A27: Reus (Tarragona) | B27: Pastelería-bombonería historica (34 años) | C27: 300 | D27: 73000 | F27: =IF(AND(ISNUMBER(C27),ISNUMBER(D27)),IFERROR(D27/C27,""),"") -> 243.33333 | G27: =IF(AND(ISNUMBER(D27),ISNUMBER(E27)),IFERROR(D27+E27*12*$C$13,""),"") | H27: CHS-38b | I27: Sí
A28: Barcelona (Sagrada Familia) | B28: Pastelería-bombonería con obrador a la vista | C28: 180 | D28: 140000 | E28: 2200 | F28: =IF(AND(ISNUMBER(C28),ISNUMBER(D28)),IFERROR(D28/C28,""),"") -> 777.77778 | G28: =IF(AND(ISNUMBER(D28),ISNUMBER(E28)),IFERROR(D28+E28*12*$C$13,""),"") -> 272000 | H28: CHS-38c | I28: Sí
A29: Valencia (Abastos) | B29: Pastelería con obrador profesional | C29: 100 | D29: 180000 | F29: =IF(AND(ISNUMBER(C29),ISNUMBER(D29)),IFERROR(D29/C29,""),"") -> 1800 | G29: =IF(AND(ISNUMBER(D29),ISNUMBER(E29)),IFERROR(D29+E29*12*$C$13,""),"") | H29: CHS-38d | I29: Sí
A30: Lliçà d'Amunt (Barcelona) | B30: Obrador de pastelería y panadería | C30: 400 | D30: 210000 | F30: =IF(AND(ISNUMBER(C30),ISNUMBER(D30)),IFERROR(D30/C30,""),"") -> 525 | G30: =IF(AND(ISNUMBER(D30),ISNUMBER(E30)),IFERROR(D30+E30*12*$C$13,""),"") | H30: CHS-38e | I30: Sí
A31: Elche (Alicante) | B31: Churrería-chocolatería | C31: 75 | F31: =IF(AND(ISNUMBER(C31),ISNUMBER(D31)),IFERROR(D31/C31,""),"") | G31: =IF(AND(ISNUMBER(D31),ISNUMBER(E31)),IFERROR(D31+E31*12*$C$13,""),"") | H31: CHS-37a | I31: No
A32: Madrid (Vallecas) | B32: Churrería-chocolatería | C32: 74 | D32: 88500 | E32: 910 | F32: =IF(AND(ISNUMBER(C32),ISNUMBER(D32)),IFERROR(D32/C32,""),"") -> 1195.9459 | G32: =IF(AND(ISNUMBER(D32),ISNUMBER(E32)),IFERROR(D32+E32*12*$C$13,""),"") -> 143100 | H32: CHS-37b | I32: No
A33: Mataró (Barcelona) | B33: Churrería-chocolatería | C33: 118 | D33: 58000 | F33: =IF(AND(ISNUMBER(C33),ISNUMBER(D33)),IFERROR(D33/C33,""),"") -> 491.52542 | G33: =IF(AND(ISNUMBER(D33),ISNUMBER(E33)),IFERROR(D33+E33*12*$C$13,""),"") | H33: CHS-37c | I33: No
A34: Traspasos con renta publicada | D34: =COUNT(E26:E33) -> 3
A35: Precio pedido más bajo | D35: =IFERROR(MIN(D26:D33),"") -> 26000
A36: Precio pedido más alto | D36: =IFERROR(MAX(D26:D33),"") -> 210000
A37: Precio pedido medio | D37: =IFERROR(AVERAGE(D26:D33),"") -> 110785.71
A38: El que te piden, sobre la media | D38: =IFERROR(C6/D37-1,"") -> -0.7653127
A40: Cinco traspasos de pasteleria-bomboneria leídos el 12-09-2026 en portales de anuncios (`CHS-38a` a `CHS-38e`), mas los tres de churreria-chocolateria de `TRASPASOS_VARIANTE_TAZA`, que son de OTRO formato. El rango publicado va de 26.000 a 210.000 euros (`CHS-39`) y la renta observada de 910 a 2.200 euros/mes. Traspasar puede salir mas barato que montar de cero, y esa es la comparación a cinco años que hace el libro 2. Pero son precios PEDIDOS, no pagados.
A42: Y lo que ninguno de los ocho trae: la cuenta de resultados. Un traspaso se valora por lo que gana el negocio, no por lo que pide el anuncio. Pide los modelos 303 y 390 de los tres últimos años y el resumen de la Seguridad Social de la plantilla; si no te los enseñan, ya sabes lo que estás comprando. Y en chocolate, una pregunta más: qué clima tiene el obrador hoy. Un obrador de pastelería traspasado no viene climatizado a 18-20 °C, y esa partida no está en el precio del anuncio.

Sheet IVA y Tesorería
A1: IVA y Tesorería del Arranque
A2: AI Chef Pro · aichef.pro — Cómo Montar una Chocolatería
A3: El IVA de la inversión sale de tu bolsillo meses antes de volver. Y abajo, el contador que dice si el impuesto al plástico te afecta o no: lo que decide es DÓNDE compras, no cuánto.
A5: Bloque | B5: Base sin IVA | C5: IVA soportado | D5: Total con IVA
A6: Obra y adecuación | B6: ='CAPEX por Bloque'!L31 -> 28500 | C6: ='CAPEX por Bloque'!M31 -> 5985 | D6: ='CAPEX por Bloque'!N31 -> 34485
A7: Climatización y deshumidificación | B7: ='CAPEX por Bloque'!L32 -> 7600 | C7: ='CAPEX por Bloque'!M32 -> 1596 | D7: ='CAPEX por Bloque'!N32 -> 9196
A8: Equipo de templado y moldeado | B8: ='CAPEX por Bloque'!L33 -> 21060 | C8: ='CAPEX por Bloque'!M33 -> 4422.6 | D8: ='CAPEX por Bloque'!N33 -> 25482.6
A9: Frío (cámara, nevera de rellenos y vitrina) | B9: ='CAPEX por Bloque'!L34 -> 10534.99 | C9: ='CAPEX por Bloque'!M34 -> 2212.3479 | D9: ='CAPEX por Bloque'!N34 -> 12747.338
A10: Mobiliario y tienda | B10: ='CAPEX por Bloque'!L35 -> 6900 | C10: ='CAPEX por Bloque'!M35 -> 1449 | D10: ='CAPEX por Bloque'!N35 -> 8349
A11: Packaging y moldes | B11: ='CAPEX por Bloque'!L36 -> 3004.36 | C11: ='CAPEX por Bloque'!M36 -> 630.9156 | D11: ='CAPEX por Bloque'!N36 -> 3635.2756
A12: TPV, informática y rótulo | B12: ='CAPEX por Bloque'!L37 -> 3200 | C12: ='CAPEX por Bloque'!M37 -> 672 | D12: ='CAPEX por Bloque'!N37 -> 3872
A13: Fianza y licencias | B13: ='CAPEX por Bloque'!L38 -> 8420 | C13: ='CAPEX por Bloque'!M38 -> 945 | D13: ='CAPEX por Bloque'!N38 -> 9365
A14: Fondo de maniobra | B14: ='CAPEX por Bloque'!L39 -> 61273.02 | C14: ='CAPEX por Bloque'!M39 -> 0 | D14: ='CAPEX por Bloque'!N39 -> 61273.02
A15: TOTAL | B15: =SUM(B6:B14) -> 150492.37 | C15: =SUM(C6:C14) -> 17912.863 | D15: =SUM(D6:D14) -> 168405.23
A16: Cuándo vuelve ese IVA
A17: Periodicidad de tu declaración (meses) | B17: ='Parámetros'!B15 -> 3
A18: Meses hasta recuperarlo | B18: ='Parámetros'!B16 -> 4
A19: IVA que tienes que adelantar | B19: =C15 -> 17912.863 | E19: En régimen general lo normal NO es que Hacienda te lo devuelva: es que lo compenses contra el IVA que repercutes. O sea, que vuelve al ritmo al que factures, no en una fecha. Y el chocolate que vendes va al 10 %, mientras que el IVA que adelantas es del 21 %: la compensación tarda más de lo que parece. Si te inscribes en el registro de devolución mensual, la periodicidad pasa a 1 y la espera se acorta mucho.
A21: La caja del día que abres
A22: CAPEX sin IVA (los nueve bloques) | B22: =B15 -> 150492.37
A23: IVA soportado | B23: =C15 -> 17912.863
A24: Desembolso total con IVA | B24: =D15 -> 168405.23
A25: Del cual, fondo de maniobra (es caja, no inversión) | B25: ='CAPEX por Bloque'!L45 -> 61273.02 | E25: Llega del libro 7 ya calculado, con su fila de cuadre. Este libro NO lo recalcula: si lo hiciera, los dos publicarían dos inversiones totales distintas con el mismo nombre.
A26: Financiación bancaria disponible | B26: ='Parámetros'!B17 -> 90300
A27: Aportación propia necesaria | B27: =IFERROR(B24-B26,"") -> 78105.234
A28: VEREDICTO DE LA CAJA | B28: =IF(B27="","",IF(B27<=0,"La financiación cubre el desembolso","Necesitas aportación propia")) -> Necesitas aportación propia | E28: Que necesites aportación propia no es una mala noticia: ningún banco financia el 100 % de una apertura, y el que lo hiciera te estaría dejando sin margen de maniobra. Lo que sí es mala noticia es descubrirlo el mes de la firma. Cuántos meses de gastos fijos cubre ese fondo te lo dice el libro 7, que es donde viven los gastos fijos: aquí no se recalcula.
A31: Contador del impuesto al plástico: ¿te afecta o no?
A32: Kg al mes de plástico no reciclado IMPORTADO o adquirido en otro país de la UE | B32: ='Parámetros'!B19 -> 3.2 | E32: LO QUE DECIDE ES DÓNDE COMPRAS Y QUÉ COMPRAS, NO CUÁNTO. El impuesto grava la fabricación, la importación y la adquisición intracomunitaria de envases no reutilizables que contengan plástico. Lo que compras en España a un proveedor español ya lo lleva repercutido en la factura: no cuenta aquí.
A33: Umbral de la exención del art. 75.f) | B33: ='Parámetros'!B20 -> 5 | E33: La exención tiene DOS límites, no uno: sólo cubre la importación o adquisición intracomunitaria que no exceda de 5 kg en un mes, y sólo los envases del art. 68.1.a). NO exime la fabricación, ni los semielaborados, ni los cierres.
A34: ¿Superas el umbral? | B34: =IF(OR(B32="",B33=""),"",IF(B32>B33,"SÍ: mira el registro territorial y la liquidación","No: por debajo de la exención del art. 75.f)")) -> No: por debajo de la exención del art. 75.f)
A35: Tipo del impuesto | B35: ='Parámetros'!B21 -> 0.45
A36: Coste anual estimado si estás por encima del umbral | B36: =IF(OR(B32="",B33=""),"",IF(B32<=B33,"",IFERROR(B32*12*B35,""))) | E36: Se queda en blanco mientras estés por debajo del umbral: un cero ahí se leería como «ya lo he calculado y sale cero», y lo que pasa es que no aplica. Cuando aplique, recuerda que el art. 82.3 obliga además a inscribirse en el Registro territorial, «salvo aquellos que se determine mediante Orden».
A37: ALERTA DEL PLÁSTICO | B37: =IF(B32="","",IF(B32>B33,"Revisa el impuesto al plástico con tu asesor","Sin alerta")) -> Sin alerta
A38: Y los moldes de policarbonato NO pagan | B38: No sujetos | E38: No están sujetos por el art. 73.d): pudiendo contener, no están diseñados para entregarse junto con la mercancía, y además el impuesto sólo grava envases NO reutilizables. Están prohibidas las dos frases fáciles, «el impuesto no te afecta si compras los envases» y su contraria «te afecta siempre»: lo que decide es dónde compras y qué compras.
A40: Esta hoja NO explica el impuesto al plástico: emite la alerta cuando pasas el umbral. La explicación entera -qué es un envase a estos efectos, qué papel tiene tu proveedor y qué hay que registrar- está en el capítulo 13 de la guía, que es donde se lee.

Sheet Resumen
A1: Resumen
A2: AI Chef Pro · aichef.pro — Cómo Montar una Chocolatería
A3: Las cifras que hay que llevar al banco. Todas calculadas desde las hojas anteriores; aquí no se teclea nada.
A5: Cifra | B5: Valor | C5: De dónde sale | D5: Qué dice
A6: Obra y adecuación | B6: ='Parámetros'!B8 -> 28500 | C6: Parámetros | D6: Metros por el precio por m². Es la única partida del CAPEX que no se teclea, y la que más se desvía en la ejecución: lo que no está en el proyecto se paga aparte.
A7: CAPEX SIN el fondo de maniobra | B7: ='CAPEX por Bloque'!L44 -> 89219.35 | C7: CAPEX por Bloque | D7: LA CIFRA QUE VIAJA AL LIBRO 7. No es «el CAPEX total»: el total incluye el bloque «fondo de maniobra», y el libro 7 vuelve a dotar el fondo con sus propios meses de colchón.
A8: Del cual, fondo de maniobra (es caja, no inversión) | B8: ='CAPEX por Bloque'!L45 -> 61273.02 | C8: CAPEX por Bloque | D8: Llega del libro 7 ya calculado, en celda verde y con fila de cuadre. Es caja, no una compra: no se consume como el resto de partidas. Pero hay que APORTARLA o FINANCIARLA igual que a ellas, y por eso está dentro del total que se lleva al banco.
A9: INVERSIÓN TOTAL (las dos líneas de arriba) | B9: ='CAPEX por Bloque'!L46 -> 150492.37 | C9: CAPEX por Bloque | D9: La suma de las dos. Sale IDÉNTICA a la del libro 7 por construcción, porque el fondo se calcula UNA sola vez y en un solo sitio.
A10: IVA soportado | B10: ='CAPEX por Bloque'!M40 -> 17912.863 | C10: CAPEX por Bloque | D10: Dinero tuyo que adelantas y que vuelve al ritmo al que factures. Adelantas al 21 % y repercutes al 10 %.
A11: Desembolso total con IVA | B11: ='CAPEX por Bloque'!N40 -> 168405.23 | C11: CAPEX por Bloque | D11: Lo que sale de la cuenta. Es el número de la conversación con el banco.
A12: Subtotal comparable con un presupuesto de obra y equipamiento | B12: ='CAPEX por Bloque'!L48 -> 77794.99 | C12: CAPEX por Bloque | D12: Seis bloques. Sin fianza, sin packaging y sin fondo de maniobra: un depósito, unas existencias y una caja no se comparan contra un presupuesto de obra.
A13: Climatización y deshumidificación | B13: ='CAPEX por Bloque'!L32 -> 7600 | C13: CAPEX por Bloque | D13: LA PARTIDA QUE NADIE PRESUPUESTA, y en chocolate no es confort: es la que decide si la cobertura cristaliza. Su dimensionado se contrasta en el libro 1.
A14: Equipo de templado y moldeado | B14: ='CAPEX por Bloque'!L33 -> 21060 | C14: CAPEX por Bloque | D14: Sin los opcionales, que vienen marcados «No». Es el bloque que se compara con el escenario profesional de entrada.
A15: Frío (cámara, nevera de rellenos y vitrina) | B15: ='CAPEX por Bloque'!L34 -> 10534.99 | C15: CAPEX por Bloque | D15: Tres equipos con tres temperaturas distintas. Sólo la vitrina tiene precio verificado; los otros dos son supuestos declarados.
A16: Cuadre del fondo de maniobra con el libro 7 | B16: ='CAPEX por Bloque'!L54 -> CUADRA | C16: CAPEX por Bloque | D16: Si dice que no cuadra, alguien ha pisado la fila del bloque: arréglalo antes de enseñarle el plan a nadie.
A17: Aportación propia necesaria | B17: ='IVA y Tesorería'!B27 -> 78105.234 | C17: IVA y Tesorería | D17: Desembolso menos financiación bancaria.
A18: Veredicto de la caja | B18: ='IVA y Tesorería'!B28 -> Necesitas aportación propia | C18: IVA y Tesorería | D18: Si la financiación cubre el desembolso o hace falta poner dinero.
A19: Alerta del impuesto al plástico | B19: ='IVA y Tesorería'!B37 -> Sin alerta | C19: IVA y Tesorería | D19: Salta sólo si importas o compras en otro país de la UE más de 5 kg al mes de plástico no reciclado en envases.
A20: Coste del traspaso en el horizonte | B20: ='Traspaso vs Obra Nueva'!C19 -> 111100 | C20: Traspaso vs Obra Nueva | D20: Precio pedido, adecuación y renta de todos los años, más los meses parado.
A21: Coste de la obra nueva en el horizonte | B21: ='Traspaso vs Obra Nueva'!C20 -> 160994.99 | C21: Traspaso vs Obra Nueva | D21: CAPEX comparable y renta de todos los años, más los meses de obra.
A22: Traspaso o obra nueva | B22: ='Traspaso vs Obra Nueva'!C22 -> Sale mejor el TRASPASO | C22: Traspaso vs Obra Nueva | D22: Compara dinero. La distribución del local, la clientela y si el obrador se puede climatizar no salen en esta celda.
A23: Inmovilizado amortizable | B23: ='CAPEX por Bloque'!L44-'CAPEX por Bloque'!L36-'CAPEX por Bloque'!L24 -> 83614.99 | C23: CAPEX por Bloque | D23: CAPEX sin el fondo de maniobra, menos la fianza (es un depósito: se recupera, no se amortiza) y menos «packaging y moldes» (son existencias, no inmovilizado). Es la base que el libro 7 trae en su celda verde: compárala con la suya para comprobar que los dos libros dicen lo mismo.
A25: Si alguna de estas cifras no te cuadra, no la cambies aquí: esta hoja no tiene ni una celda editable. Vuelve a la hoja donde nace y cambia el parámetro o el importe. Es lo que evita que un resumen y su origen digan cosas distintas.
A27: LAS DOS PRIMERAS LÍNEAS DE DINERO SON DOS Y NO UNA A PROPÓSITO. «CAPEX sin el fondo de maniobra» es lo que le llevas al libro 7 y lo que se parece a lo que el sector llama «inversión de apertura»; el fondo de maniobra es caja, no inversión, y lo dota el libro 7 con sus meses de colchón y sus gastos fijos. La suma de las dos es la inversión total, y sale idéntica en los dos libros porque el fondo se calcula UNA vez. Publicar un único «CAPEX total» y pedir además el fondo en el otro libro es el error que hace que un mismo negocio aparezca con dos inversiones distintas en el mismo pack.
