Workbook

Sheet Instrucciones
A1: Plan financiero a 3 años
A2: AI Chef Pro · aichef.pro — Cómo Montar una Chocolatería
A3: Para qué sirve: saber si el negocio se sostiene, qué canal lo sostiene y si el taller da dinero o te ocupa el obrador en el peor momento.
A5: Instrucciones de uso
A6: 1. Hoja «0. Supuestos»: es el cuadro de mandos. Aquí se teclean las TASAS y los DRIVERS —clientes al día, piezas por ticket, días de apertura, tipos de IVA, food cost, condiciones del préstamo, umbrales de control— y el resto del libro se recalcula solo. Las partidas de gasto se teclean en su hoja, no aquí.
A7: 2. Hoja «Inversión Inicial»: NO vuelve a pedirte las nueve partidas del CAPEX. Te pide UNA cifra —el CAPEX SIN el fondo de maniobra, que publica el libro «calculadora-capex-chocolateria»— y dota aquí el fondo de maniobra con TUS meses de colchón y TUS gastos fijos. El fondo se calcula una sola vez en todo el pack, y es esta hoja la que lo calcula.
A8: 3. Hoja «PyG 3 Años»: la cuenta de resultados. El AÑO 2 es el año de crucero; el año 1 lleva la rampa de arranque y el año 3 crece sobre el crucero. La amortización y los intereses van DENTRO de los costes fijos, y la cuota de autónomos del titular también. Abajo, el escenario de formato: bombonería frente a bombonería con taza y churros, lado a lado.
A9: 4. Hoja «Punto de Equilibrio»: cuántos clientes al día hay que hacer para no perder dinero, en dos versiones. La CONTABLE incluye la amortización; la de CAJA le quita la amortización (que no se paga) y le suma la devolución de principal (que sí). La segunda es la que decide si llegas a fin de mes.
A10: 5. Hoja «Escenarios»: el mismo modelo con tres juegos de clientes, ticket medio y días de apertura. La columna «Realista» LEE el año de crucero del P&L, así que no puede desviarse de él.
A11: 6. Hoja «Personal»: tres personas y dos jornadas y media, con el bruto del convenio en celda verde y la Seguridad Social a cargo de la empresa DENTRO. Del bruto al coste empresa hay un tercio más: es el salto que más sorprende. Al lado, los salarios de MERCADO, que son orientativos y no son un convenio.
A12: 7. Hoja «Tesorería 12 meses»: el P&L dice si el negocio gana dinero; esta hoja dice si le queda caja para llegar a fin de mes. Trae la estacionalidad con el valle de agosto dentro, la rampa de arranque, el desfase de cobros y pagos, la liquidación trimestral del IVA y la FECHA LÍMITE de cierre de pedidos de Navidad, calculada hacia atrás desde la capacidad de tu obrador.
A13: 8. Hoja «Financiación»: de dónde sale el dinero y cuánto cuesta devolverlo. El cuadro de amortización es MENSUAL, con 84 filas, porque la carencia de este caso son seis meses y un cuadro anual no sabe expresar medio año. Abajo, el DSCR año a año: es el número que decide la operación bancaria.
... A31: Qué hace este libro y qué hace otro (para no teclear dos veces)
A32: Producto o libro | B32: Qué aporta | C32: Qué NO hace este libro
A33: kit-tareas-chocolateria (12 €) | B33: La operación del obrador que ya tienes: partidas de producción, curvas de templado, calendario anual de campañas y fichas de tarea por perfil. | C33: Este libro NO planifica producción ni templa nada. Toma su resultado en euros y lo proyecta a tres años. Los tres perfiles de la hoja de Personal son los de ese kit, con sus nombres.
A34: El libro «sensibilidad-al-precio-del-cacao» de esta misma guía | B34: El precio de la cobertura, en las dos bases de IVA, y qué pasa con cada referencia si el cacao sube un 40 %. | C34: Aquí el coste de la materia entra como UN porcentaje sobre las ventas. El precio de la cobertura en base imponible se trae de allí por celda verde, con su fila de cuadre.
A35: El libro «calculadora-capex-chocolateria» de esta misma guía | B35: El CAPEX partida a partida, con su columna de IVA por línea, la variante del formato y la comparación entre traspaso y obra nueva. | C35: Aquí entra UNA cifra: el CAPEX SIN el fondo de maniobra. El fondo lo dota esta hoja y vuelve allí ya calculado.
A36: El libro «capacidad-obrador-y-clima» de esta misma guía | B36: Cuántos bombones al día aguanta el equipo que vas a comprar y cuál es el que limita. | C36: Aquí esa capacidad sólo sirve para una cosa, y es importante: calcular hacia atrás la fecha límite de cierre de pedidos de Navidad.
A37: plan-negocio-bar-restaurante y los demás planes de negocio (35 €) | B37: El dossier completo que se le entrega al banco, con memoria escrita. | C37: Este libro es el motor de números de una GUÍA de apertura. Si vas a pedir financiación de verdad, el dossier del banco es aquel producto.
A39: Cada cuánto se usa este libro
A40: Cadencia: «0. Supuestos» e «Inversión Inicial», MIENTRAS BUSCAS LOCAL y pides presupuestos, tantas veces como haga falta. El P&L, el punto de equilibrio y los escenarios, UNA VEZ ANTES DE FIRMAR y otra antes de sentarte con el banco. «Tesorería 12 meses», CADA MES durante el primer año, sustituyendo la previsión por lo que pasó de verdad. «Canales y Punto Muerto» y «Talleres y Regalo Corporativo», cada vez que te plantees abrir o cerrar un canal, y en septiembre, cuando se cierra la agenda corporativa de Navidad.
A42: Para editar la estructura o una celda que no esté en verde: Revisar > Desproteger hoja (no tiene contraseña).
A44: Diseñado por John Guerrero — chef y consultor gastronómico desde 2010, en cocina desde los 17 años.
A45: Versión 1.0 · septiembre 2026 · aichef.pro/guia-chocolateria-obrador · info@aichef.pro

Sheet 0. Supuestos
A1: Supuestos: Las Tasas y los Drivers del Modelo
A2: AI Chef Pro · aichef.pro — Cómo Montar una Chocolatería
A3: Cambia las celdas VERDES y el resto del libro se recalcula solo. Las partidas de gasto se teclean en su hoja, no aquí. Cada supuesto lleva al lado de dónde sale y qué pasa si lo mueves.
A5: ACTIVIDAD
A6: Clientes al día en velocidad de crucero | B6: 67 | C6: SUPUESTO, y de los gordos: no existe dato público de tráfico de una bombonería española, así que este número no es un benchmark. Cuéntalos tú en la puerta de tres bombonerías parecidas a la que quieres abrir, un sábado y un martes, y trae el tuyo. Es la ÚNICA palanca que hay que tocar para mover el resultado: los costes no se maquillan.
A7: Piezas por ticket | B7: 1.4 | C7: SUPUESTO. En bombonería es BAJO -1,4- porque la unidad de venta real es la CAJA, no la pieza: quien entra a por un regalo se lleva una caja de 20 euros, no ocho bombones sueltos. De aquí sale el ticket medio, que NO se teclea: se calcula.
A8: PVP medio ponderado de la carta, CON IVA (€/pieza) | B8: 7.68 | C8: Sale de las 28 referencias del libro «carta-de-apertura-y-escandallo-chocolate», ponderadas por su mix de ventas. Si cambias la carta allí, trae aquí el nuevo PVP medio: es COPIA declarada, no un vínculo entre ficheros.
A9: Ticket medio CON IVA (€) | B9: =IFERROR($B$7*$B$8,"") -> 10.752 | C9: Piezas por ticket x PVP medio ponderado. Es lo que ve el cliente en el datáfono.
A10: Ticket medio SIN IVA (€) | B10: =IFERROR($B$9/(1+$B$20),"") -> 9.7745455 | C10: Es el que entra en el P&L: la cuenta de resultados va siempre sin IVA. Se divide por el IVA MEDIO de la carta, no por un tipo suelto, para que el día que entre una referencia a otro tipo el libro siga cuadrando.
A11: Días de apertura al año | B11: 304 | C11: SUPUESTO: 6 días por semana x 52 semanas = 312, menos 8 días de cierre por festivos. En AGOSTO NO SE CIERRA: lo que para es el obrador, no la tienda, y el literal del kit lo dice («la tienda abre para el turista aunque el obrador pare»). Una bombonería de menos de 300 m² tiene libertad horaria por el art. 5.2 de la Ley de Horarios Comerciales, no por el 5.1.
A12: Actividad del año 1 sobre la de crucero (%) | B12: =IFERROR(SUMPRODUCT('Tesorería 12 meses'!B6:M6,'Tesorería 12 meses'!B7:M7),"") -> 0.88450094 | C12: NO se teclea: sale de la estacionalidad y de la rampa de la hoja de Tesorería. Un local que abre no factura desde el primer día lo que factura a los seis meses, y proyectar el año 1 a velocidad de crucero es el error que más planes de negocio tumba. Aquí además la apertura es el 1 de junio, así que la rampa cae justo sobre el valle de agosto.
A13: Crecimiento de volumen del año 3 (%) | B13: 0.04 | C13: SUPUESTO. El año 2 ya es el de crucero: el año 3 sólo crece lo que dé la clientela fija y la agenda corporativa que repite, no un salto de negocio. Un 4 % es prudente; si pones más, tendrás que decir de dónde sale.
A14: IVA Y TIPOS
A15: IVA del chocolate y la bombonería (%) | B15: 0.1 | C15: El 10 % sale POR EXCLUSIÓN, no porque un precepto nombre al chocolate: la lista del 4 % del art. 91.Dos.1.1.o es cerrada y tiene siete letras, el chocolate no está en ninguna, y tampoco está entre las dos exclusiones del 10 % (bebidas alcohólicas y refrescantes).
A16: IVA del chocolate a la taza SERVIDO en sala (%) | B16: 0.1 | C16: La taza servida en sala es una prestación de servicio de hostelería, no la entrega de un bien: va al 10 % por el art. 91.Uno.2.2.o. La tableta para taza que te llevas a casa es una entrega de bien, y va por la línea de arriba.
A17: IVA de los talleres y catas (%) | B17: Pregúntaselo a tu asesor | C17: VA SIN CIFRA A PROPÓSITO, y no es un olvido. Lo que SÍ está cerrado: un taller de bombonería NO está exento de IVA, porque el art. 20.Uno.10.o excluye de la exención las clases «para cuya realización sea necesario darse de alta en las tarifas de actividades empresariales o artísticas del IAE». Lo que NO está cerrado es el TIPO: el art. 91 no nombra los talleres. Esta guía no publica una cifra que no pueda sostener; escribe tú la que te diga tu asesor.
A18: IVA general (%) | B18: 0.21 | C18: Tipo general del art. 90.Uno de la Ley 37/1992. Es el que soportas en obra, maquinaria, moldes, packaging y servicios. Sin la columna de IVA por línea el CAPEX sale hasta un 21 % desviado, que es el error más caro de todo el proceso.
A19: IVA medio de las compras de materia prima (%) | B19: 0.1 | C19: SUPUESTO de trabajo: la cobertura y los frutos secos van al 10 % y el packaging al 21 %. Sólo afecta a la TESORERÍA (lo que adelantas al proveedor), nunca al resultado. Pídele a tu distribuidor una factura de ejemplo y afínalo.
A20: IVA medio ponderado de la carta (%) | B20: =IFERROR($B$15,"") -> 0.1 | C20: Hoy toda la carta va al 10 %, así que el IVA medio es ése. Esta celda existe para que el día que entres una referencia a otro tipo -una bebida, por ejemplo- no haya que tocar el libro entero: cambias aquí y el ticket sin IVA, la tesorería y el modelo 303 te siguen.
A21: COSTE DE VENTAS
A22: Food cost de escandallo de la carta (%) | B22: 0.252157 | C22: Coste de MATERIA sobre PVP, los dos en BASE IMPONIBLE, ponderado por los euros que vende cada referencia. Sale del libro «carta-de-apertura-y-escandallo-chocolate». Ojo con la base: el precio de la cobertura que publica la fuente lleva el IVA dentro, y un escandallo hecho con esa base sale un 9 % alto.
A23: Peso del packaging sobre el coste de la pieza (%) | B23: 0.12 | C23: SUPUESTO. En bombonería pesa más que en pastelería: la caja ES el producto en las campañas de regalo, y el 23 % de diferencia de precio por bombón entre la caja de 12 y la de 35 se juega ahí.
A24: Coste de ventas sobre las ventas (food cost del P&L, %) | B24: =IFERROR($B$22*(1+$B$23),"") -> 0.28241584 | C24: SE DERIVA: escandallo + packaging. Es el que proyecta el P&L, y es MAYOR que el de una pieza suelta a propósito. Si además revendes producto de terceros o tienes merma de producto fresco por encima de la que ya lleva el escandallo, súbelo tú.
A25: Food cost OBJETIVO de la casa (regla única, %) | B25: 0.3 | C25: SUPUESTO declarado: no existe dato público de food cost de bombonería. Es la regla única de la casa, y el margen bruto objetivo de la línea de abajo se DERIVA de él: guardar los dos por separado es un error de método, porque antes o después dicen cosas distintas.
A26: Margen bruto objetivo (%) | B26: =IFERROR(1-$B$25,"") -> 0.7 | C26: Se DERIVA del food cost objetivo. Margen bruto y food cost son la misma regla dicha dos veces.
A27: Brecha entre el food cost del P&L y el objetivo (puntos) | B27: =IFERROR($B$24-$B$25,"") -> -0.01758416 | C27: En NEGATIVO estás por debajo del objetivo, y esa diferencia es tu colchón. En positivo, tu carta no llega a la regla de la casa: o suben los precios, o baja el coste de la cobertura, o cambia el mix.
A28: PERSONAL
A29: Seguridad Social a cargo de la empresa (%) | B29: 0.33 | C29: Cotización empresarial aproximada sobre el salario bruto (contingencias comunes, desempleo, FOGASA y formación). Ajústala a tu convenio y a tus contratos.
A30: Número de pagas del convenio | B30: 15 | C30: El convenio de referencia paga 15, no 14, y eso cambia el coste mes a mes y el reparto de la tesorería. Busca el tuyo: NO existe convenio estatal del chocolate, está comprobado en el registro oficial.
A31: SMI vigente (€/año, 14 pagas) | B31: 17094 | C31: 1.221 €/mes × 14 pagas = 17.094 €/año — Real Decreto 126/2026, de 18 de febrero (BOE-A-2026-3815), con efectos desde el 1-ene-2026. El convenio provincial de hostelería prevalece si fija un mínimo superior.
A32: Jornada completa (horas/semana) | B32: 40 | C32: SUPUESTO: la jornada anual del convenio de referencia no se ha verificado. Comprueba la del tuyo antes de dimensionar turnos.
A33: LOCAL Y GASTOS FIJOS
A34: Alquiler mensual del local (€) | B34: 1300 | C34: SUPUESTO para una ciudad media. La renta observada en los ocho traspasos verificados va de 910 €/mes (74 m² en Madrid-Vallecas) a 2.200 €/mes (180 m² en Barcelona); aquí se toma la parte baja porque ninguna de esas dos ciudades es una ciudad media.
A35: Fianza del alquiler (meses de renta) | B35: 2 | C35: SUPUESTO. La fianza no es un gasto: es un depósito que se recupera. Está dentro del CAPEX del libro 2 porque hay que tenerla el día de la firma, y por eso no se amortiza.
A36: Suministros mensuales de luz, agua y climatización (€) | B36: 780 | C36: SUPUESTO. Un obrador de chocolate NO tiene hornos, pero tiene TRES equipos de frío y una climatización con deshumidificación funcionando 24 horas, y en agosto a pleno. No se estima: se le pide la simulación a la comercializadora con la potencia del proyecto eléctrico.
A37: Cuota de autónomos del titular (€/mes) | B37: 320 | C37: SUPUESTO, y va como renglón propio de los fijos. El titular de este caso es el Encargado, y su retribución YA está en la nómina de la hoja de Personal: ponerle además una «retribución del propietario» sería contarlo dos veces. Lo que va aparte es la cuota.
A38: Subida anual de los costes fijos (%) | B38: 0 | C38: A CERO: las tres columnas del P&L están en euros del año 1 (términos reales). Súbela si quieres proyectar en euros corrientes, pero entonces sube también el ticket medio o estarás proyectando una pérdida de margen que no has decidido.
A39: FINANCIACIÓN
A40: Recursos propios aportados (€) | B40: 78105.23 | C40: SUPUESTO sembrado para que el plan quede financiado: es la necesidad total de caja menos el préstamo. Míralo dos veces, porque es mucho dinero: si no lo tienes, o baja la inversión (mira la hoja «Traspaso vs Obra Nueva» del libro de CAPEX) o sube el préstamo, y entonces vigila el DSCR de la hoja de Financiación.
A41: Préstamo bancario solicitado (€) | B41: 90300 | C41: SUPUESTO: el 60 % de la inversión total, redondeado a centenas, que es la estructura 40/60 del caso. Las condiciones las pone tu banco y dependen de la garantía. Pide oferta a dos entidades y a una línea ICO antes de fijarlo.
...

Sheet Inversión Inicial
A1: Inversión Inicial: La Cifra que Viene y la que se Dota Aquí
A2: AI Chef Pro · aichef.pro — Cómo Montar una Chocolatería
A3: Esta hoja NO te vuelve a pedir las nueve partidas del CAPEX: eso lo hace el libro «calculadora-capex-chocolateria». Aquí entra UNA cifra suya -el CAPEX SIN el fondo de maniobra- y se DOTA el fondo de maniobra con tus meses de colchón y tus gastos fijos. El fondo se calcula una sola vez en todo el pack, y es aquí.
A5: LO QUE VIENE DEL LIBRO DE CAPEX (cruce 7 <- 2)
A6: CAPEX SIN el fondo de maniobra: trae aquí la cifra de calculadora-capex-chocolateria.xlsx!Resumen!B7 («CAPEX SIN el fondo de maniobra») | B6: 89219.35 | D6: CÓPIALA A MANO. No hay ninguna fórmula entre ficheros: un enlace se rompe en cuanto alguien mueve una carpeta, y entonces el libro miente sin avisar. Y OJO CON CUÁL COPIAS: NO es «el CAPEX total». El total de aquel libro lleva DENTRO el bloque «fondo de maniobra», y este libro vuelve a dotarlo tres filas más abajo: traer el total contaría el fondo dos veces y publicaría dos inversiones totales distintas para la misma bombonería. VALOR POR DEFECTO DECLARADO: el del caso «La Almendra».
A7: Cifra que publica hoy esa celda del libro de CAPEX | B7: 89219.35 | D7: Anota aquí lo que ves en el libro 2 la última vez que lo abriste. Si arriba tecleas otra cosa -porque has cerrado un presupuesto mejor, o porque el instalador te ha subido la climatización-, la fila de CUADRE te avisa en vez de dejar las dos cifras separadas en silencio.
A8: Desviación entre las dos | B8: =IFERROR(ABS(B6-B7)/B7,"") -> 0
A9: CUADRE DEL CAPEX: lo que usas frente a lo que publica el libro 2 | B9: =IFERROR(IF(NOT(ISNUMBER(B8)),"",IF(B8<='0. Supuestos'!$B$72,"CUADRA","REVISA: el CAPEX que estás usando no es el que publica el libro 2")),"") -> CUADRA | D9: Es la red de seguridad de todo el pack: dos libros que dicen cosas distintas sobre la misma inversión es el defecto que más caro sale y el que menos se nota.
A10: IVA soportado sobre la inversión, traído del libro 2 | B10: 17912.86 | D10: Copia de calculadora-capex-chocolateria.xlsx!CAPEX por Bloque!M40 («IVA soportado total»). Se recupera por el modelo 303, pero hay que ADELANTARLO: la hoja de Tesorería lo arrastra trimestre a trimestre, y esa espera es la partida que más sorprende al que abre.
A11: Inmovilizado amortizable, traído del libro 2 | B11: 83614.99 | D11: El CAPEX menos la FIANZA (que es un depósito y se recupera) y menos el primer pedido de packaging y moldes de consumo (que son existencias, no inmovilizado). De aquí sale la amortización anual que entra en los costes fijos.
A13: EL FONDO DE MANIOBRA SE DOTA AQUÍ (y viaja al libro 2 ya calculado: cruce 2 <- 7)
A14: Gastos fijos mensuales del año de crucero (€) | B14: =IFERROR('PyG 3 Años'!C31/12,"") -> 10212.169 | D14: El total de costes fijos del AÑO 2 del P&L dividido entre doce. Es la foto de un mes normal: por eso lleva dentro la amortización y los intereses del AÑO DE CRUCERO, no los del año 1, que es el de la carencia. Ésta es una de las dos celdas que cita el resto del pack.
A15: Meses de colchón (de «0. Supuestos») | B15: =IFERROR('0. Supuestos'!$B$45,"") -> 6 | D15: Se decide en «0. Supuestos», y sólo allí. El libro de CAPEX no lo pregunta.
A16: FONDO DE MANIOBRA (€) | B16: =IFERROR(B14*B15,"") -> 61273.016 | D16: Meses de colchón x gastos fijos mensuales. ES LA CIFRA QUE VIAJA AL LIBRO 2: cópiala allí en su celda verde del cruce, y su fila de CUADRE te dirá si las dos siguen diciendo lo mismo. No es inversión que se compra: es caja, y es lo que te deja llegar a octubre del primer año.
A18: LA INVERSIÓN, EN DOS LÍNEAS
A19: CAPEX (lo que se compra, sin el fondo de maniobra) | B19: =IFERROR(B6,"") -> 89219.35 | C19: =IFERROR(B19/B21,"") -> 0.59284967 | D19: Obra, climatización, equipo de templado, frío, mobiliario, packaging y moldes, TPV y rótulo, fianza y licencias.
A20: Del cual NO forma parte: el fondo de maniobra (es caja) | B20: =IFERROR(B16,"") -> 61273.016 | C20: =IFERROR(B20/B21,"") -> 0.40715033
A21: INVERSIÓN TOTAL (lo que se compra más la caja del arranque) | B21: =IFERROR(B19+B20,"") -> 150492.37 | D21: Esta cifra y la que publica el libro de CAPEX tienen que ser IDÉNTICAS, y lo son por construcción: aquel libro publica el CAPEX ya depurado de fondo y éste le devuelve el fondo ya calculado.
A22: IVA soportado sobre la inversión (recuperable, pero hay que ADELANTARLO) | B22: =IFERROR(B10,"") -> 17912.86
A23: NECESIDAD TOTAL DE CAJA AL ARRANQUE | B23: =IFERROR(B21+B22,"") -> 168405.23 | D23: Es la cifra que tiene que cubrir la hoja de Financiación. Si el origen de fondos no llega aquí, el plan no está financiado, y da igual lo bonito que sea el P&L.
A25: BASES DE AMORTIZACIÓN (no suman a la inversión)
A26: Inmovilizado amortizable | B26: =IFERROR(B11,"") -> 83614.99 | D26: El que has traído del libro 2. Ni la fianza ni el fondo de maniobra se amortizan: la primera se recupera y el segundo es caja.
A27: Amortización anual del inmovilizado | B27: =IFERROR(B26/MAX(1,'0. Supuestos'!$B$51),"") -> 8361.499 | D27: Es la línea que entra en los costes fijos del P&L. Sin ella la rentabilidad publicada es mentira: la atemperadora se gasta, y la cámara de chocolate también.
A29: Todas las cifras van en BASE SIN IVA. El IVA de la inversión se trae aparte, arriba, para que puedas ver cuánto dinero tienes que adelantar y cuánto vas a recuperar. Y una advertencia que vale dinero: la renta que pagues ANTES de abrir no está aquí. Si la vas a pagar, súmala en el libro de CAPEX a la línea de fianza y dilo en su nota, para que los dos libros sigan diciendo lo mismo.

Sheet PyG 3 Años
A1: Cuenta de Resultados a 3 Años
A2: AI Chef Pro · aichef.pro — Cómo Montar una Chocolatería
A3: El AÑO 2 es el año de crucero: es el que citan la guía y el business plan. El año 1 lleva la rampa de arranque -y el valle de agosto dentro- y el año 3 crece sobre el crucero. Amortización, intereses y la cuota de autónomos del titular van DENTRO de los costes fijos.
A5: Concepto | B5: Año 1 (arranque) | C5: Año 2 (crucero) | D5: Año 3 | E5: % s/ventas (año 2) | F5: Tipo de IVA de la línea | G5: Notas
A6: INGRESOS
A7: Clientes al día | B7: =IFERROR('0. Supuestos'!$B$6,"") -> 67 | C7: =IFERROR('0. Supuestos'!$B$6,"") -> 67 | D7: =IFERROR(C7*(1+'0. Supuestos'!$B$13),"") -> 69.68 | G7: Los años 1 y 2 comparten el tráfico de crucero; lo que separa al año 1 es la rampa de la fila de abajo, no menos clientes al día en el mes 12.
A8: Ticket medio sin IVA (€) | B8: =IFERROR('0. Supuestos'!$B$10,"") -> 9.7745455 | C8: =IFERROR('0. Supuestos'!$B$10,"") -> 9.7745455 | D8: =IFERROR('0. Supuestos'!$B$10,"") -> 9.7745455 | G8: Constante en euros del año 1: una subida de precios es una decisión aparte, y se toma en la carta, no aquí.
A9: Días de apertura al año | B9: =IFERROR('0. Supuestos'!$B$11,"") -> 304 | C9: =IFERROR('0. Supuestos'!$B$11,"") -> 304 | D9: =IFERROR('0. Supuestos'!$B$11,"") -> 304
A10: Actividad sobre la velocidad de crucero (%) | B10: =IFERROR('0. Supuestos'!$B$12,"") -> 0.88450094 | C10: 1 | D10: 1 | G10: El año 1 lo calcula «0. Supuestos» desde la rampa y la estacionalidad de la hoja de Tesorería. Los años 2 y 3 están al 100 % porque el año 2 es, por definición, el de crucero: si crees que vas a tardar más en llegar, bájalos.
A11: INGRESOS TOTALES (sin IVA) | B11: =IFERROR(IF(B7*B8*B9*B10=0,"",B7*B8*B9*B10),"") -> 176093.47 | C11: =IFERROR(IF(C7*C8*C9*C10=0,"",C7*C8*C9*C10),"") -> 199087.94 | D11: =IFERROR(IF(D7*D8*D9*D10=0,"",D7*D8*D9*D10),"") -> 207051.46 | E11: =IFERROR(C11/$C$11,"") -> 1 | F11: =IFERROR('0. Supuestos'!$B$20,"") -> 0.1 | G11: Clientes x ticket medio sin IVA x días x actividad. El reparto por canal está en la hoja «Canales y Punto Muerto»: aquí es UNA cifra, porque lo que cambia por canal es el MARGEN, no el precio.
A12: COSTES VARIABLES
A13: Coste de ventas (cobertura, rellenos, packaging y merma) | B13: =IFERROR(IF(B11="","",B11*'0. Supuestos'!$B$24),"") -> 49731.586 | C13: =IFERROR(IF(C11="","",C11*'0. Supuestos'!$B$24),"") -> 56225.588 | D13: =IFERROR(IF(D11="","",D11*'0. Supuestos'!$B$24),"") -> 58474.612 | E13: =IFERROR(C13/$C$11,"") -> 0.28241584 | F13: =IFERROR('0. Supuestos'!$B$19,"") -> 0.1 | G13: Al food cost DERIVADO de «0. Supuestos»: el de escandallo de la carta más el packaging. La materia prima que manda aquí es la cobertura, y su precio vive en el libro «sensibilidad-al-precio-del-cacao» EN BASE IMPONIBLE: si copias el precio con IVA, este renglón sale un 9 % alto.
A14: TOTAL COSTES VARIABLES | B14: =IFERROR(IF(B11="","",B13),"") -> 49731.586 | C14: =IFERROR(IF(C11="","",C13),"") -> 56225.588 | D14: =IFERROR(IF(D11="","",D13),"") -> 58474.612 | E14: =IFERROR(C14/$C$11,"") -> 0.28241584
A15: MARGEN BRUTO | B15: =IFERROR(IF(B11="","",B11-B14),"") -> 126361.89 | C15: =IFERROR(IF(C11="","",C11-C14),"") -> 142862.35 | D15: =IFERROR(IF(D11="","",D11-D14),"") -> 148576.85 | E15: =IFERROR(C15/$C$11,"") -> 0.71758416
A16: COSTES FIJOS
A17: Personal (nóminas y Seguridad Social) | B17: =IFERROR(IF(B11="","",'Personal'!$I$9),"") -> 68418.725 | C17: =IFERROR(IF(C11="","",'Personal'!$I$9),"") -> 68418.725 | D17: =IFERROR(IF(D11="","",'Personal'!$I$9),"") -> 68418.725 | E17: =IFERROR(C17/$C$11,"") -> 0.34366082 | F17: 0 | G17: Sale de la hoja de Personal: es el MISMO número, no una estimación aparte, y dentro va la retribución del titular, que es el Encargado. Las nóminas no llevan IVA. El refuerzo de campañas NO está aquí: se dimensiona en el libro «campanas-y-valle-del-ano».
A18: Cuota de autónomos del titular | B18: =IFERROR(IF(B11="","",'0. Supuestos'!$B$37*12),"") -> 3840 | C18: =IFERROR(IF(C11="","",B18*(1+'0. Supuestos'!$B$38)),"") -> 3840 | D18: =IFERROR(IF(D11="","",C18*(1+'0. Supuestos'!$B$38)),"") -> 3840 | E18: =IFERROR(C18/$C$11,"") -> 0.019287959 | F18: 0 | G18: RENGLÓN PROPIO, y es lo ÚNICO que va aparte del titular: su sueldo ya está en la nómina de arriba, porque el titular de este caso es el Encargado. Ponerle además una «retribución del propietario» sería contarlo dos veces.
A19: Alquiler del local | B19: =IFERROR(IF(B11="","",'0. Supuestos'!$B$34*12),"") -> 15600 | C19: =IFERROR(IF(C11="","",B19*(1+'0. Supuestos'!$B$38)),"") -> 15600 | D19: =IFERROR(IF(D11="","",C19*(1+'0. Supuestos'!$B$38)),"") -> 15600 | E19: =IFERROR(C19/$C$11,"") -> 0.078357332 | F19: =IFERROR('0. Supuestos'!$B$18,"") -> 0.21 | G19: El importe mensual está en «0. Supuestos»; aquí se multiplica por doce. El arrendamiento de local de negocio lleva IVA al tipo general.
A20: Suministros (luz, agua y climatización) | B20: =IFERROR(IF(B11="","",'0. Supuestos'!$B$36*12),"") -> 9360 | C20: =IFERROR(IF(C11="","",B20*(1+'0. Supuestos'!$B$38)),"") -> 9360 | D20: =IFERROR(IF(D11="","",C20*(1+'0. Supuestos'!$B$38)),"") -> 9360 | E20: =IFERROR(C20/$C$11,"") -> 0.047014399 | F20: =IFERROR('0. Supuestos'!$B$18,"") -> 0.21 | G20: Luz va al 21 % y el agua al 10 %. El libro aplica a toda la partida el tipo de la columna de al lado: si el agua te pesa, sepárala en su propia línea. Y ojo en agosto: la climatización con deshumidificación no para aunque pare el obrador.
A21: Seguros | B21: 1320 | C21: =IFERROR(IF(C11="","",B21*(1+'0. Supuestos'!$B$38)),"") -> 1320 | D21: =IFERROR(IF(D11="","",C21*(1+'0. Supuestos'!$B$38)),"") -> 1320 | E21: =IFERROR(C21/$C$11,"") -> 0.0066302358 | F21: 0 | G21: Responsabilidad civil y continente. `CHN-70` (seguro de RC) está en los EXCLUIDOS de la verificación legal: NO está verificado como obligatorio y depende de tu comunidad autónoma, así que aquí va como supuesto y sin cifra de norma detrás. Las operaciones de seguro están exentas de IVA, y por eso su tipo va a cero. Importe ANUAL: el mensual del caso, por doce.
A22: Gestoría y asesoría | B22: 2400 | C22: =IFERROR(IF(C11="","",B22*(1+'0. Supuestos'!$B$38)),"") -> 2400 | D22: =IFERROR(IF(D11="","",C22*(1+'0. Supuestos'!$B$38)),"") -> 2400 | E22: =IFERROR(C22/$C$11,"") -> 0.012054974 | F22: 0.21 | G22: Supuesto. Importe ANUAL: el mensual del caso, por doce.
A23: Software, TPV y pasarela de cobro | B23: 720 | C23: =IFERROR(IF(C11="","",B23*(1+'0. Supuestos'!$B$38)),"") -> 720 | D23: =IFERROR(IF(D11="","",C23*(1+'0. Supuestos'!$B$38)),"") -> 720 | E23: =IFERROR(C23/$C$11,"") -> 0.0036164923 | F23: 0.21 | G23: Supuesto. Con Verifactu en el horizonte (1 de enero de 2027 para sociedades y 1 de julio de 2027 para autónomos, no 2026) esta cuota deja de ser opcional. Importe ANUAL: el mensual del caso, por doce.
A24: Telefonía e internet | B24: 660 | C24: =IFERROR(IF(C11="","",B24*(1+'0. Supuestos'!$B$38)),"") -> 660 | D24: =IFERROR(IF(D11="","",C24*(1+'0. Supuestos'!$B$38)),"") -> 660 | E24: =IFERROR(C24/$C$11,"") -> 0.0033151179 | F24: 0.21 | G24: Supuesto. Importe ANUAL: el mensual del caso, por doce.
A25: Limpieza y consumibles | B25: 1680 | C25: =IFERROR(IF(C11="","",B25*(1+'0. Supuestos'!$B$38)),"") -> 1680 | D25: =IFERROR(IF(D11="","",C25*(1+'0. Supuestos'!$B$38)),"") -> 1680 | E25: =IFERROR(C25/$C$11,"") -> 0.0084384819 | F25: 0.21 | G25: Supuesto. Incluye guantes y utillaje dedicado: el equipo que has usado con un alérgeno no se reutiliza para otro alimento sin limpiarlo. Importe ANUAL: el mensual del caso, por doce.
A26: Mantenimiento de equipos | B26: 1560 | C26: =IFERROR(IF(C11="","",B26*(1+'0. Supuestos'!$B$38)),"") -> 1560 | D26: =IFERROR(IF(D11="","",C26*(1+'0. Supuestos'!$B$38)),"") -> 1560 | E26: =IFERROR(C26/$C$11,"") -> 0.0078357332 | F26: 0.21 | G26: Supuesto. Si montas la variante de taza y churros con freidora de gas, súmale la inspección periódica obligatoria cada cinco años, que se te repercute. Importe ANUAL: el mensual del caso, por doce.
A27: Publicidad y redes | B27: 2160 | C27: =IFERROR(IF(C11="","",B27*(1+'0. Supuestos'!$B$38)),"") -> 2160 | D27: =IFERROR(IF(D11="","",C27*(1+'0. Supuestos'!$B$38)),"") -> 2160 | E27: =IFERROR(C27/$C$11,"") -> 0.010849477 | F27: 0.21 | G27: Supuesto. Importe ANUAL: el mensual del caso, por doce.
A28: Otros gastos de estructura | B28: 1560 | C28: =IFERROR(IF(C11="","",B28*(1+'0. Supuestos'!$B$38)),"") -> 1560 | D28: =IFERROR(IF(D11="","",C28*(1+'0. Supuestos'!$B$38)),"") -> 1560 | E28: =IFERROR(C28/$C$11,"") -> 0.0078357332 | F28: 0.21 | G28: Supuesto. Importe ANUAL: el mensual del caso, por doce.
A29: Amortización del inmovilizado | B29: =IFERROR(IF(B11="","",'Inversión Inicial'!$B$27),"") -> 8361.499 | C29: =IFERROR(IF(C11="","",'Inversión Inicial'!$B$27),"") -> 8361.499 | D29: =IFERROR(IF(D11="","",'Inversión Inicial'!$B$27),"") -> 8361.499 | E29: =IFERROR(C29/$C$11,"") -> 0.041999023 | F29: 0 | G29: Sale de la base de amortización de la hoja de Inversión. No sube con el IPC: es un reparto contable de una inversión ya hecha.
A30: Gastos financieros del préstamo | B30: =IFERROR(IF(B11="","",'Financiación'!$B$116),"") -> 5525.0128 | C30: =IFERROR(IF(C11="","",'Financiación'!$B$117),"") -> 4905.8078 | D30: =IFERROR(IF(D11="","",'Financiación'!$B$118),"") -> 4139.7431 | E30: =IFERROR(C30/$C$11,"") -> 0.024641411 | F30: 0 | G30: Sólo los INTERESES son gasto. La devolución del principal sale de la caja pero no del resultado: va en la hoja de Tesorería. Los que usa el fondo de maniobra son los del AÑO 2, no los del año 1, que es el de la carencia.
A31: TOTAL COSTES FIJOS | B31: =IFERROR(IF(B11="","",SUM(B17:B30)),"") -> 123165.24 | C31: =IFERROR(IF(C11="","",SUM(C17:C30)),"") -> 122546.03 | D31: =IFERROR(IF(D11="","",SUM(D17:D30)),"") -> 121779.97 | E31: =IFERROR(C31/$C$11,"") -> 0.61553719 | G31: De esta celda, columna del año 2 y dividida entre doce, sale el fondo de maniobra de todo el pack.
A32: IVA soportado de los costes variables | B32: =IFERROR(IF(B11="","",B13*$F$13),"") -> 4973.1586 | C32: =IFERROR(IF(C11="","",C13*$F$13),"") -> 5622.5588 | D32: =IFERROR(IF(D11="","",D13*$F$13),"") -> 5847.4612
A33: IVA soportado de los costes fijos | B33: =IFERROR(IF(B11="","",SUMPRODUCT(B17:B30,$F$17:$F$30)),"") -> 7497 | C33: =IFERROR(IF(C11="","",SUMPRODUCT(C17:C30,$F$17:$F$30)),"") -> 7497 | D33: =IFERROR(IF(D11="","",SUMPRODUCT(D17:D30,$F$17:$F$30)),"") -> 7497 | G33: Cada línea a SU tipo, leído de la columna de al lado. Es lo que la hoja de Tesorería paga de más a los proveedores y luego recupera en el modelo 303.
A34: RESULTADO ANTES DE IMPUESTOS | B34: =IFERROR(IF(B11="","",B15-B31),"") -> 3196.6497 | C34: =IFERROR(IF(C11="","",C15-C31),"") -> 20316.322 | D34: =IFERROR(IF(D11="","",D15-D31),"") -> 26796.881 | E34: =IFERROR(C34/$C$11,"") -> 0.10204697
A35: Bases negativas pendientes al inicio | B35: =IFERROR(IF(B11="","",'0. Supuestos'!$B$49),"") -> 0 | C35: =IFERROR(IF(C11="","",B40),"") -> 0 | D35: =IFERROR(IF(D11="","",C40),"") -> 0 | G35: Art. 26 de la Ley del Impuesto sobre Sociedades: las pérdidas de un ejercicio se compensan con los beneficios de los siguientes.
A36: Base imponible (después de compensar) | B36: =IFERROR(IF(B11="","",MAX(0,B34-B35)),"") -> 3196.6497 | C36: =IFERROR(IF(C11="","",MAX(0,C34-C35)),"") -> 20316.322 | D36: =IFERROR(IF(D11="","",MAX(0,D34-D35)),"") -> 26796.881
A37: Ejercicios con base positiva (acumulado) | B37: =IFERROR(IF(B11="","",IF(B36>0,1,0)),"") -> 1 | C37: =IFERROR(IF(C11="","",B37+IF(C36>0,1,0)),"") -> 2 | D37: =IFERROR(IF(D11="","",C37+IF(D36>0,1,0)),"") -> 3
A38: Tipo de Impuesto de Sociedades aplicado | B38: =IFERROR(IF(B11="","",IF(B36<=0,"",IF(B37<=2,'0. Supuestos'!$B$47,'0. Supuestos'!$B$48))),"") -> 0.15 | C38: =IFERROR(IF(C11="","",IF(C36<=0,"",IF(C37<=2,'0. Supuestos'!$B$47,'0. Supuestos'!$B$48))),"") -> 0.15 | D38: =IFERROR(IF(D11="","",IF(D36<=0,"",IF(D37<=2,'0. Supuestos'!$B$47,'0. Supuestos'!$B$48))),"") -> 0.25 | G38: El 15 % de entidad de nueva creación se aplica al PRIMER ejercicio con base positiva y al siguiente, no a los dos primeros años naturales. Si tributas en IRPF, esta línea no te aplica.
A39: Impuesto de Sociedades | B39: =IFERROR(IF(B11="","",IF(B38="",0,B36*B38)),"") -> 479.49746 | C39: =IFERROR(IF(C11="","",IF(C38="",0,C36*C38)),"") -> 3047.4483 | D39: =IFERROR(IF(D11="","",IF(D38="",0,D36*D38)),"") -> 6699.2203
A40: Bases negativas pendientes al cierre | B40: =IFERROR(IF(B11="","",MAX(0,B35-B34)),"") -> 0 | C40: =IFERROR(IF(C11="","",MAX(0,C35-C34)),"") -> 0 | D40: =IFERROR(IF(D11="","",MAX(0,D35-D34)),"") -> 0
A41: RESULTADO NETO | B41: =IFERROR(IF(B11="","",B34-B39),"") -> 2717.1522 | C41: =IFERROR(IF(C11="","",C34-C39),"") -> 17268.874 | D41: =IFERROR(IF(D11="","",D34-D39),"") -> 20097.661 | E41: =IFERROR(C41/$C$11,"") -> 0.086739929
...

Sheet Punto de Equilibrio
A1: Punto de Equilibrio: Cuántos Clientes al Día
A2: AI Chef Pro · aichef.pro — Cómo Montar una Chocolatería
A3: Dos umbrales, y no dicen lo mismo. El CONTABLE incluye la amortización; el de CAJA le quita la amortización (que no se paga) y le suma la devolución de principal (que sí). El segundo es el que decide si llegas a fin de mes.
A5: Variable | B5: Año 1 | C5: Año 2 | D5: Año 3 | E5: Notas
A6: DATOS BASE POR AÑO
A7: Costes fijos anuales | B7: =IFERROR(IF('PyG 3 Años'!B11="","",'PyG 3 Años'!B31),"") -> 123165.24 | C7: =IFERROR(IF('PyG 3 Años'!C11="","",'PyG 3 Años'!C31),"") -> 122546.03 | D7: =IFERROR(IF('PyG 3 Años'!D11="","",'PyG 3 Años'!D31),"") -> 121779.97 | E7: Los MISMOS costes fijos del P&L. Cada año tiene los suyos: por eso el umbral no puede ser uno solo para los tres.
A8: Costes fijos mensuales | B8: =IFERROR(IF('PyG 3 Años'!B11="","",B7/12),"") -> 10263.77 | C8: =IFERROR(IF('PyG 3 Años'!C11="","",C7/12),"") -> 10212.169 | D8: =IFERROR(IF('PyG 3 Años'!D11="","",D7/12),"") -> 10148.331
A9: Ticket medio sin IVA (€) | B9: =IFERROR(IF('PyG 3 Años'!B11="","",'PyG 3 Años'!B8),"") -> 9.7745455 | C9: =IFERROR(IF('PyG 3 Años'!C11="","",'PyG 3 Años'!C8),"") -> 9.7745455 | D9: =IFERROR(IF('PyG 3 Años'!D11="","",'PyG 3 Años'!D8),"") -> 9.7745455
A10: Coste variable por ticket (€) | B10: =IFERROR(IF('PyG 3 Años'!B11="","",'PyG 3 Años'!B14/('PyG 3 Años'!B7*'PyG 3 Años'!B9*'PyG 3 Años'!B10)),"") -> 2.7604865 | C10: =IFERROR(IF('PyG 3 Años'!C11="","",'PyG 3 Años'!C14/('PyG 3 Años'!C7*'PyG 3 Años'!C9*'PyG 3 Años'!C10)),"") -> 2.7604865 | D10: =IFERROR(IF('PyG 3 Años'!D11="","",'PyG 3 Años'!D14/('PyG 3 Años'!D7*'PyG 3 Años'!D9*'PyG 3 Años'!D10)),"") -> 2.7604865 | E10: Sale del total de costes variables del P&L dividido por los clientes de ese año, no de una estimación aparte.
A11: Margen de contribución por ticket (€) | B11: =IFERROR(IF('PyG 3 Años'!B11="","",B9-B10),"") -> 7.014059 | C11: =IFERROR(IF('PyG 3 Años'!C11="","",C9-C10),"") -> 7.014059 | D11: =IFERROR(IF('PyG 3 Años'!D11="","",D9-D10),"") -> 7.014059 | E11: Ticket menos coste variable unitario. Es lo que deja cada cliente para pagar los fijos. En bombonería es alto y los fijos también: las dos cosas van juntas.
A12: Días de apertura al año | B12: =IFERROR(IF('PyG 3 Años'!B11="","",'PyG 3 Años'!B9),"") -> 304 | C12: =IFERROR(IF('PyG 3 Años'!C11="","",'PyG 3 Años'!C9),"") -> 304 | D12: =IFERROR(IF('PyG 3 Años'!D11="","",'PyG 3 Años'!D9),"") -> 304
A13: Devolución de principal del año (sale de caja) | B13: =IFERROR(IF('PyG 3 Años'!B11="","",'Financiación'!$C$116),"") -> 5731.5362 | C13: =IFERROR(IF('PyG 3 Años'!C11="","",'Financiación'!$C$117),"") -> 12008.69 | D13: =IFERROR(IF('PyG 3 Años'!D11="","",'Financiación'!$C$118),"") -> 12774.755 | E13: El principal NO es gasto del P&L, pero sale de la caja. Sin él, el umbral de equilibrio se publica por debajo de lo que de verdad hay que facturar.
A14: PUNTO DE EQUILIBRIO CONTABLE (incluye la amortización)
A15: Clientes necesarios al año | B15: =IFERROR(IF('PyG 3 Años'!B11="","",IF(B11<=0,"",B7/B11)),"") -> 17559.766 | C15: =IFERROR(IF('PyG 3 Años'!C11="","",IF(C11<=0,"",C7/C11)),"") -> 17471.486 | D15: =IFERROR(IF('PyG 3 Años'!D11="","",IF(D11<=0,"",D7/D11)),"") -> 17362.267
A16: Clientes necesarios al día | B16: =IFERROR(IF('PyG 3 Años'!B11="","",B15/B12),"") -> 57.762389 | C16: =IFERROR(IF('PyG 3 Años'!C11="","",C15/C12),"") -> 57.471992 | D16: =IFERROR(IF('PyG 3 Años'!D11="","",D15/D12),"") -> 57.112721
A17: Ingresos necesarios al año (sin IVA) | B17: =IFERROR(IF('PyG 3 Años'!B11="","",B15*B9),"") -> 171638.73 | C17: =IFERROR(IF('PyG 3 Años'!C11="","",C15*C9),"") -> 170775.83 | D17: =IFERROR(IF('PyG 3 Años'!D11="","",D15*D9),"") -> 169708.27
A18: Ingresos necesarios al mes (sin IVA) | B18: =IFERROR(IF('PyG 3 Años'!B11="","",B17/12),"") -> 14303.228 | C18: =IFERROR(IF('PyG 3 Años'!C11="","",C17/12),"") -> 14231.319 | D18: =IFERROR(IF('PyG 3 Años'!D11="","",D17/12),"") -> 14142.356
A19: PUNTO DE EQUILIBRIO DE CAJA (incluye la cuota del préstamo)
A20: Costes fijos de caja más el principal del año | B20: =IFERROR(IF('PyG 3 Años'!B11="","",B7-'PyG 3 Años'!B29+B13),"") -> 120535.27 | C20: =IFERROR(IF('PyG 3 Años'!C11="","",C7-'PyG 3 Años'!C29+C13),"") -> 126193.22 | D20: =IFERROR(IF('PyG 3 Años'!D11="","",D7-'PyG 3 Años'!D29+D13),"") -> 126193.22 | E20: Los fijos del P&L sin la amortización (que no se paga) y CON la devolución de principal (que sí). Es el umbral que decide si sobrevives, no el contable.
A21: Clientes necesarios al año (caja) | B21: =IFERROR(IF('PyG 3 Años'!B11="","",IF(B11<=0,"",B20/B11)),"") -> 17184.81 | C21: =IFERROR(IF('PyG 3 Años'!C11="","",IF(C11<=0,"",C20/C11)),"") -> 17991.469 | D21: =IFERROR(IF('PyG 3 Años'!D11="","",IF(D11<=0,"",D20/D11)),"") -> 17991.469
A22: Clientes necesarios al día (caja) | B22: =IFERROR(IF('PyG 3 Años'!B11="","",B21/B12),"") -> 56.528981 | C22: =IFERROR(IF('PyG 3 Años'!C11="","",C21/C12),"") -> 59.182463 | D22: =IFERROR(IF('PyG 3 Años'!D11="","",D21/D12),"") -> 59.182463
A23: Ingresos necesarios al año (caja, sin IVA) | B23: =IFERROR(IF('PyG 3 Años'!B11="","",B21*B9),"") -> 167973.71 | C23: =IFERROR(IF('PyG 3 Años'!C11="","",C21*C9),"") -> 175858.43 | D23: =IFERROR(IF('PyG 3 Años'!D11="","",D21*D9),"") -> 175858.43
A24: CONTRASTE CON EL PLAN
A25: Clientes al día previstos en el plan | B25: =IFERROR(IF('PyG 3 Años'!B11="","",'PyG 3 Años'!B7*'PyG 3 Años'!B10),"") -> 59.261563 | C25: =IFERROR(IF('PyG 3 Años'!C11="","",'PyG 3 Años'!C7*'PyG 3 Años'!C10),"") -> 67 | D25: =IFERROR(IF('PyG 3 Años'!D11="","",'PyG 3 Años'!D7*'PyG 3 Años'!D10),"") -> 69.68
A26: Holgura sobre el equilibrio de CAJA (%) | B26: =IFERROR(IF('PyG 3 Años'!B11="","",IF(B22<=0,"",B25/B22-1)),"") -> 0.048339481 | C26: =IFERROR(IF('PyG 3 Años'!C11="","",IF(C22<=0,"",C25/C22-1)),"") -> 0.13209213 | D26: =IFERROR(IF('PyG 3 Años'!D11="","",IF(D22<=0,"",D25/D22-1)),"") -> 0.17737581 | E26: Cuánto puedes caer sobre lo previsto antes de no poder pagar los fijos y la cuota. El mínimo exigible está en «0. Supuestos».
A27: Lectura de la holgura | B27: =IFERROR(IF('PyG 3 Años'!B11="","",IF(B26<0,"Por debajo del equilibrio",IF(B26<'0. Supuestos'!$B$66,"Ajustada","Suficiente"))),"") -> Ajustada | C27: =IFERROR(IF('PyG 3 Años'!C11="","",IF(C26<0,"Por debajo del equilibrio",IF(C26<'0. Supuestos'!$B$66,"Ajustada","Suficiente"))),"") -> Ajustada | D27: =IFERROR(IF('PyG 3 Años'!D11="","",IF(D26<0,"Por debajo del equilibrio",IF(D26<'0. Supuestos'!$B$66,"Ajustada","Suficiente"))),"") -> Suficiente
A28: Lectura rápida: si los clientes al día previstos están por debajo de los clientes al día de CAJA, el negocio no genera para pagar los fijos y la cuota, y da igual lo que diga el resultado contable. Si están justo por encima, no tienes margen para un mes malo -y aquí los meses malos están en el calendario, no en la mala suerte-: negocia carencia, baja inversión o revisa el ticket medio antes de firmar nada.
A30: EL PUNTO MUERTO, POR FORMATO (año de crucero)
A31: Concepto | B31: Bombonería | C31: Bombonería + taza y churros | E31: Notas
A32: Costes fijos mensuales (€) | B32: =IFERROR('PyG 3 Años'!B64/12,"") -> 10212.169 | C32: =IFERROR('PyG 3 Años'!C64/12,"") -> 11350.749
A33: Margen de contribución sobre ventas (%) | B33: =IFERROR('PyG 3 Años'!B63/'PyG 3 Años'!B61,"") -> 0.71758416 | C33: =IFERROR('PyG 3 Años'!C63/'PyG 3 Años'!C61,"") -> 0.68596171
A34: PUNTO MUERTO MENSUAL (€ sin IVA) | B34: =IFERROR(IF(B33<=0,"",B32/B33),"") -> 14231.319 | C34: =IFERROR(IF(C33<=0,"",C32/C33),"") -> 16547.205 | E34: El formato con taza y churros factura más, pero también arrastra más fijos y un margen bruto mucho peor en esa línea. Lo que decide no es cuál factura más: es cuál necesita menos para no perder dinero.
A35: Punto muerto por día de apertura (€) | B35: =IFERROR(B34*12/'0. Supuestos'!$B$11,"") -> 561.7626 | C35: =IFERROR(C34*12/'0. Supuestos'!$B$11,"") -> 653.17916
A36: Los dos formatos comparten obrador, alquiler y titular; lo que cambia es la sala, el personal de servicio y la licencia. Si el punto muerto de la derecha sale MÁS ALTO, la taza y los churros te están obligando a facturar más para estar igual: puede seguir mereciendo la pena por tráfico y por horario, pero eso ya es una decisión tuya y no un resultado del libro.
A38: SENSIBILIDAD DEL PUNTO DE EQUILIBRIO (año de crucero)
A39: Clientes al día necesarios: ticket medio (columnas) x coste variable por ticket (filas) | B39: =IFERROR($C$9-1,"") -> 8.7745455 | C39: =IFERROR($C$9,"") -> 9.7745455 | D39: =IFERROR($C$9+1,"") -> 10.774545 | E39: =IFERROR($C$9+2,"") -> 11.774545
A40: =IFERROR($C$10-2*'0. Supuestos'!$B$71,"") -> 2.3604865 | B40: =IFERROR(IF(B$39-$A40<=0,"",$C$7/(B$39-$A40)/$C$12),"") -> 62.848182 | C40: =IFERROR(IF(C$39-$A40<=0,"",$C$7/(C$39-$A40)/$C$12),"") -> 54.371289 | D40: =IFERROR(IF(D$39-$A40<=0,"",$C$7/(D$39-$A40)/$C$12),"") -> 47.909332 | E40: =IFERROR(IF(E$39-$A40<=0,"",$C$7/(E$39-$A40)/$C$12),"") -> 42.820206
A41: =IFERROR($C$10-1*'0. Supuestos'!$B$71,"") -> 2.5604865 | B41: =IFERROR(IF(B$39-$A41<=0,"",$C$7/(B$39-$A41)/$C$12),"") -> 64.870956 | C41: =IFERROR(IF(C$39-$A41<=0,"",$C$7/(C$39-$A41)/$C$12),"") -> 55.878659 | D41: =IFERROR(IF(D$39-$A41<=0,"",$C$7/(D$39-$A41)/$C$12),"") -> 49.075852 | E41: =IFERROR(IF(E$39-$A41<=0,"",$C$7/(E$39-$A41)/$C$12),"") -> 43.74966
A42: =IFERROR($C$10,"") -> 2.7604865 | B42: =IFERROR(IF(B$39-$A42<=0,"",$C$7/(B$39-$A42)/$C$12),"") -> 67.028266 | C42: =IFERROR(IF(C$39-$A42<=0,"",$C$7/(C$39-$A42)/$C$12),"") -> 57.471992 | D42: =IFERROR(IF(D$39-$A42<=0,"",$C$7/(D$39-$A42)/$C$12),"") -> 50.300596 | E42: =IFERROR(IF(E$39-$A42<=0,"",$C$7/(E$39-$A42)/$C$12),"") -> 44.720358
A43: =IFERROR($C$10+1*'0. Supuestos'!$B$71,"") -> 2.9604865 | B43: =IFERROR(IF(B$39-$A43<=0,"",$C$7/(B$39-$A43)/$C$12),"") -> 69.333996 | C43: =IFERROR(IF(C$39-$A43<=0,"",$C$7/(C$39-$A43)/$C$12),"") -> 59.158858 | D43: =IFERROR(IF(D$39-$A43<=0,"",$C$7/(D$39-$A43)/$C$12),"") -> 51.588035 | E43: =IFERROR(IF(E$39-$A43<=0,"",$C$7/(E$39-$A43)/$C$12),"") -> 45.735109
...

Sheet Escenarios
A1: Escenarios: Pesimista, Realista y Optimista
A2: AI Chef Pro · aichef.pro — Cómo Montar una Chocolatería
A3: La columna «Realista» LEE el año de crucero del P&L, así que no puede desviarse de él. Las otras dos son verdes: son tus apuestas, y la de la izquierda es la que hay que poder sobrevivir.
A5: Métrica | B5: Pesimista | C5: Realista | D5: Optimista | E5: Notas
A6: Clientes al día | B6: 48 | C6: =IFERROR('PyG 3 Años'!C7,"") -> 67 | D6: 85 | E6: SUPUESTOS los dos extremos. El pesimista no es «un mal día»: es el año entero yendo mal, con una Navidad floja dentro.
A7: Ticket medio sin IVA (€) | B7: 8.2 | C7: =IFERROR('PyG 3 Años'!C8,"") -> 9.7745455 | D7: 11.5 | E7: SUPUESTOS. En bombonería el ticket lo mueve el MIX, no el precio: si la gente compra cajas de 12 en vez de cajas de 35, el ticket cae sin que hayas bajado un solo precio.
A8: Días de apertura al año | B8: 290 | C8: =IFERROR('PyG 3 Años'!C9,"") -> 304 | D8: 310 | E8: SUPUESTOS. Ojo con creer que abrir más días arregla un año malo: lo que arregla un año malo es Navidad.
A9: INGRESOS ANUALES (sin IVA) | B9: =IFERROR(IF(B6*B7*B8=0,"",B6*B7*B8),"") -> 114144 | C9: =IFERROR(IF(C6*C7*C8=0,"",C6*C7*C8),"") -> 199087.94 | D9: =IFERROR(IF(D6*D7*D8=0,"",D6*D7*D8),"") -> 303025
A10: Coste de ventas (food cost del P&L) | B10: =IFERROR(IF(B9="","",B9*'0. Supuestos'!$B$24),"") -> 32236.074 | C10: =IFERROR(IF(C9="","",C9*'0. Supuestos'!$B$24),"") -> 56225.588 | D10: =IFERROR(IF(D9="","",D9*'0. Supuestos'!$B$24),"") -> 85579.06
A11: TOTAL COSTES VARIABLES | B11: =IFERROR(IF(B9="","",B10),"") -> 32236.074 | C11: =IFERROR(IF(C9="","",C10),"") -> 56225.588 | D11: =IFERROR(IF(D9="","",D10),"") -> 85579.06
A12: MARGEN BRUTO | B12: =IFERROR(IF(B9="","",B9-B11),"") -> 81907.926 | C12: =IFERROR(IF(C9="","",C9-C11),"") -> 142862.35 | D12: =IFERROR(IF(D9="","",D9-D11),"") -> 217445.94
A13: COSTES FIJOS (los del año de crucero del P&L) | B13: =IFERROR(IF(B9="","",'PyG 3 Años'!$C$31),"") -> 122546.03 | C13: =IFERROR(IF(C9="","",'PyG 3 Años'!$C$31),"") -> 122546.03 | D13: =IFERROR(IF(D9="","",'PyG 3 Años'!$C$31),"") -> 122546.03 | E13: Los costes fijos no cambian con el escenario: por eso son fijos. Si en el pesimista se disparan sobre las ventas, el ajuste hay que hacerlo en la hoja de Personal, no aquí.
A14: RESULTADO ANTES DE IMPUESTOS | B14: =IFERROR(IF(B9="","",B12-B13),"") -> -40638.105 | C14: =IFERROR(IF(C9="","",C12-C13),"") -> 20316.322 | D14: =IFERROR(IF(D9="","",D12-D13),"") -> 94899.909
A15: Impuesto de Sociedades | B15: =IFERROR(IF(B9="","",MAX(0,B14-'0. Supuestos'!$B$49)*'0. Supuestos'!$B$47),"") -> 0 | C15: =IFERROR(IF(C9="","",MAX(0,C14-'0. Supuestos'!$B$49)*'0. Supuestos'!$B$47),"") -> 3047.4483 | D15: =IFERROR(IF(D9="","",MAX(0,D14-'0. Supuestos'!$B$49)*'0. Supuestos'!$B$47),"") -> 14234.986 | E15: Al tipo de entidad de nueva creación, compensando las bases negativas anteriores. Con resultado negativo no hay cuota.
A16: RESULTADO NETO | B16: =IFERROR(IF(B9="","",B14-B15),"") -> -40638.105 | C16: =IFERROR(IF(C9="","",C14-C15),"") -> 17268.874 | D16: =IFERROR(IF(D9="","",D14-D15),"") -> 80664.922
A17: Margen neto (%) | B17: =IFERROR(IF(B9="","",B16/B9),"") -> -0.35602489 | C17: =IFERROR(IF(C9="","",C16/C9),"") -> 0.086739929 | D17: =IFERROR(IF(D9="","",D16/D9),"") -> 0.2661989 | E17: Contrástalo con la banda de referencia de «0. Supuestos», que es un supuesto de control y no un dato del sector. El optimista que se va muy por encima suele estar olvidándose de un coste, no descubriendo un negocio mejor.
A18: Clientes al día para el equilibrio | B18: =IFERROR(IF(B9="","",IF(B7-B11/(B6*B8)<=0,"",B13/(B7-B11/(B6*B8))/B8)),"") -> 71.8149 | C18: =IFERROR(IF(C9="","",IF(C7-C11/(C6*C8)<=0,"",C13/(C7-C11/(C6*C8))/C8)),"") -> 57.471992 | D18: =IFERROR(IF(D9="","",IF(D7-D11/(D6*D8)<=0,"",D13/(D7-D11/(D6*D8))/D8)),"") -> 47.903459
A19: LO QUE CADA ESCENARIO EXIGE
A20: Coste de personal / ventas | B20: =IFERROR(IF(B9="","",'PyG 3 Años'!$C$17/B9),"") -> 0.5994071 | C20: =IFERROR(IF(C9="","",'PyG 3 Años'!$C$17/C9),"") -> 0.34366082 | D20: =IFERROR(IF(D9="","",'PyG 3 Años'!$C$17/D9),"") -> 0.22578574 | E20: La MISMA plantilla en los tres escenarios: tres personas y dos jornadas y media. En el pesimista es donde se ve si esa plantilla se sostiene.
A21: Ventas al año por jornada equivalente (€) | B21: =IFERROR(IF(B9="","",B9/'Personal'!$C$9),"") -> 45657.6 | C21: =IFERROR(IF(C9="","",C9/'Personal'!$C$9),"") -> 79635.177 | D21: =IFERROR(IF(D9="","",D9/'Personal'!$C$9),"") -> 121210 | E21: Cuánto tendría que facturar cada jornada completa del cuadro de Personal. En el optimista dice si hace falta contratar antes de llegar ahí -y en bombonería contratar en noviembre ya es tarde-.
A22: Saldo de caja estimado al cierre del año 1 (mismo método en los tres) | B22: =IFERROR(IF(B9="","",'Inversión Inicial'!$B$16+B16+'PyG 3 Años'!$C$29-'Financiación'!$C$116),"") -> 23264.874 | C22: =IFERROR(IF(C9="","",'Inversión Inicial'!$B$16+C16+'PyG 3 Años'!$C$29-'Financiación'!$C$116),"") -> 81171.852 | D22: =IFERROR(IF(D9="","",'Inversión Inicial'!$B$16+D16+'PyG 3 Años'!$C$29-'Financiación'!$C$116),"") -> 144567.9 | E22: Fondo de maniobra más el resultado del año, devolviendo la amortización (que no se paga) y restando el principal (que sí). Es una ESTIMACIÓN: el saldo de verdad, con su desfase de cobros y su liquidación de IVA, está en la hoja de Tesorería.
A23: Saldo real del mes 12 de la hoja de Tesorería (sólo el realista) | C23: =IFERROR(IF(C9="","",'Tesorería 12 meses'!M23),"") -> 72959.294 | E23: Sólo existe para el caso base: la tesorería mes a mes está construida sobre el año 1 del P&L, no sobre los escenarios.
A25: La columna «Realista» lee sus tres datos del año de crucero del P&L, así que reproduce EXACTAMENTE ese año. Si quieres mover el caso base, muévelo en «0. Supuestos» y esta columna te sigue.

Sheet Personal
A1: Personal: Tres Personas y Dos Jornadas y Media
A2: AI Chef Pro · aichef.pro — Cómo Montar una Chocolatería
A3: Los tres perfiles son los del kit de tareas de chocolatería, con sus nombres: Encargado, Chocolatero y Dependiente. El bruto sale del convenio, en celda verde, y la Seguridad Social a cargo de la empresa va DENTRO: del bruto al coste empresa hay un tercio más.
A5: Persona y perfil | B5: Personas | C5: Jornada | D5: Grupo de convenio | E5: Bruto mes del grupo (€) | F5: Bruto mes del puesto (€) | G5: Seguridad Social a cargo de la empresa (€) | H5: Coste mes (€) | I5: Coste año (€) | J5: Horas/semana | K5: Área | L5: Notas
A6: P1 · Encargado | B6: 1 | C6: 1 | D6: Grupo 2 | E6: =IFERROR(INDEX($E$13:$E$17,MATCH(D6,$A$13:$A$17,0)),"") -> 1427.89 | F6: =IFERROR(E6*C6*B6,"") -> 1427.89 | G6: =IFERROR(F6*'0. Supuestos'!$B$29,"") -> 471.2037 | H6: =IFERROR(F6+G6,"") -> 1899.0937 | I6: =IFERROR(H6*MAX(12,'0. Supuestos'!$B$30),"") -> 28486.406 | J6: 40 | K6: OBRADOR | L6: Turno de Partido (08:00-13:00 y 17:00-20:00).
A7: P2 · Chocolatero | B7: 1 | C7: 1 | D7: Grupo 3 | E7: =IFERROR(INDEX($E$13:$E$17,MATCH(D7,$A$13:$A$17,0)),"") -> 1376.91 | F7: =IFERROR(E7*C7*B7,"") -> 1376.91 | G7: =IFERROR(F7*'0. Supuestos'!$B$29,"") -> 454.3803 | H7: =IFERROR(F7+G7,"") -> 1831.2903 | I7: =IFERROR(H7*MAX(12,'0. Supuestos'!$B$30),"") -> 27469.355 | J7: 40 | K7: OBRADOR | L7: Turno de Mañana (07:00-15:00).
A8: P3 · Dependiente | B8: 1 | C8: 0.5 | D8: Grupo 4 | E8: =IFERROR(INDEX($E$13:$E$17,MATCH(D8,$A$13:$A$17,0)),"") -> 1249.42 | F8: =IFERROR(E8*C8*B8,"") -> 624.71 | G8: =IFERROR(F8*'0. Supuestos'!$B$29,"") -> 206.1543 | H8: =IFERROR(F8+G8,"") -> 830.8643 | I8: =IFERROR(H8*MAX(12,'0. Supuestos'!$B$30),"") -> 12462.965 | J8: 20 | K8: TIENDA | L8: Turno de Tarde (16:30-20:30).
A9: TOTAL PLANTILLA | B9: =IFERROR(IF(COUNT(E6:E8)=0,"",SUM(B6:B8)),"") -> 3 | C9: =IFERROR(IF(COUNT(E6:E8)=0,"",SUM(C6:C8)),"") -> 2.5 | F9: =IFERROR(IF(COUNT(E6:E8)=0,"",SUM(F6:F8)),"") -> 3429.51 | G9: =IFERROR(IF(COUNT(E6:E8)=0,"",SUM(G6:G8)),"") -> 1131.7383 | H9: =IFERROR(IF(COUNT(E6:E8)=0,"",SUM(H6:H8)),"") -> 4561.2483 | I9: =IFERROR(IF(COUNT(E6:E8)=0,"",SUM(I6:I8)),"") -> 68418.725 | J9: =IFERROR(IF(COUNT(E6:E8)=0,"",SUM(J6:J8)),"") -> 100 | L9: Este «Coste año» es el que lee el P&L. No hay una segunda estimación de personal en ninguna parte del libro. Y dentro va la retribución del titular, que en este caso es el Encargado: lo único que va aparte, en los fijos, es su cuota de autónomos.
A11: EL CONVENIO DE REFERENCIA (sustitúyelo por el tuyo)
A12: Grupo | B12: Denominación del grupo | E12: Bruto mes (€) | F12: Bruto año (€) | G12: Áreas funcionales | I12: Puestos que cita
A13: Grupo 1 | B13: Técnicos y titulados superiores | E13: 1733.88 | F13: =IFERROR(E13*MAX(12,'0. Supuestos'!$B$30),"") -> 26008.2 | G13: ADMINISTRACION | I13: -
A14: Grupo 2 | B14: Dirección, jefes y encargados | E14: 1427.89 | F14: =IFERROR(E14*MAX(12,'0. Supuestos'!$B$30),"") -> 21418.35 | G14: OBRADOR / TIENDA / ADMINISTRACION | I14: maestro de obrador, encargado
A15: Grupo 3 | B15: Personal especialista | E15: 1376.91 | F15: =IFERROR(E15*MAX(12,'0. Supuestos'!$B$30),"") -> 20653.65 | G15: OBRADOR / TIENDA | I15: especialista de producción, encargado de sección
A16: Grupo 4 | B16: Personal cualificado | E16: 1249.42 | F16: =IFERROR(E16*MAX(12,'0. Supuestos'!$B$30),"") -> 18741.3 | G16: OBRADOR / TIENDA | I16: personal cualificado de producción y de envasado, dependiente
A17: Grupo 5 | B17: Personal de apoyo y ayuda en servicios auxiliares | E17: 1192.42 | F17: =IFERROR(E17*MAX(12,'0. Supuestos'!$B$30),"") -> 17886.3 | G17: OBRADOR / TIENDA | I17: ayudante de producción, ayudante de comercio, peón, limpiador, almacenero
A19: CONTRASTE CON EL SMI
A20: Bruto anual del grupo más bajo (€) | B20: =IFERROR(IF(COUNT(F13:F17)=0,"",MIN(F13:F17)),"") -> 17886.3
A21: SMI anual de referencia (€) | B21: =IFERROR('0. Supuestos'!$B$31,"") -> 17094
A22: ¿Algún grupo queda por debajo del SMI? | B22: =IFERROR(IF(B20="","",IF(B20<B21,"Sí: revísalo con tu asesor","No: aquí manda el convenio")),"") -> No: aquí manda el convenio | L22: El SMI es una referencia ANUAL en cómputo global, no un mínimo por concepto. En este sector manda el convenio: el grupo más bajo de la tabla de ejemplo ya lo supera. Las dos cosas caducan el 31-12-2026.
A24: SALARIOS DE MERCADO (orientativos, y NUNCA un convenio)
A25: Etiqueta de la fuente salarial | B25: Mín. (€/h) | C25: Máx. (€/h) | D25: Equivale a | E25: Coste año a jornada completa (€) | L25: Notas
A26: «Chocolatero / bombonero especializado» | B26: 13 | C26: 16 | D26: Chocolatero | E26: =IFERROR(B26*$B$42*(1+'0. Supuestos'!$B$29),"") -> 30776.2 | L26: Fiabilidad media, y NUNCA se presentan como tabla de convenio. Las etiquetas entrecomilladas son las de la FUENTE salarial, no los perfiles de esta casa: los perfiles son los tres del kit, y la columna «Equivale a» está para eso. Sirven para saber si lo que vas a ofrecer está dentro de mercado; lo que te OBLIGA es tu convenio.
A27: «Oficial de primera» | B27: 11 | C27: 13 | D27: Chocolatero | E27: =IFERROR(B27*$B$42*(1+'0. Supuestos'!$B$29),"") -> 26041.4
A28: «Auxiliar / ayudante» | B28: 8 | C28: 9.5 | D28: Dependiente | E28: =IFERROR(B28*$B$42*(1+'0. Supuestos'!$B$29),"") -> 18939.2
A29: «Encargado / maestro» | B29: 15 | C29: 20 | D29: Encargado | E29: =IFERROR(B29*$B$42*(1+'0. Supuestos'!$B$29),"") -> 35511
A31: LOS CUATRO CONVENIOS DE ÁMBITO PROVINCIAL O SUPERIOR QUE SÍ NOMBRAN CHOCOLATES O BOMBONES
A32: Código | B32: Ámbito | E32: Denominación | L32: Notas
A33: 45000145011981 | B33: Toledo | E33: - | L33: ESTÁ PROBADO que NO existe convenio ESTATAL del chocolate: el registro oficial devuelve «no se ha encontrado ningún acuerdo» para chocolate, bombones, confitería y pastelería, y el control con «turrones» devuelve 29 trámites, así que la consulta funciona. Estos cuatro existen y nombran el producto, pero su ámbito FUNCIONAL es una pregunta para un laboralista, no una respuesta de esta guía.
A34: 80000725012008 | B34: Comunitat Valenciana | E34: CHOCOLATES, TORREFACTORES DE CAFES Y SUCEDANEOS (01/01/2023-31/12/2026)
A35: 01000425011981 | B35: Alava | E35: caducado
A36: 22001125012010 | B36: Huesca | E36: -
A38: HORAS, DIMENSIONADO Y COSTE HORA
A39: Horas contratadas a la semana | B39: =IFERROR(J9,"") -> 100
A40: Jornadas completas equivalentes | B40: =IFERROR(C9,"") -> 2.5
A41: Personas con más horas de las que da su jornada | B41: =IFERROR(SUMPRODUCT((J6:J8>C6:C8*'0. Supuestos'!$B$32)*1),"") -> 0 | L41: Tiene que valer cero. Si se pone en rojo, alguien está contratado a media jornada y trabajando más horas de las que cobra: eso no es un ahorro, es una inspección.
A42: Horas anuales de contrato | B42: 1780 | L42: SUPUESTO: 40 h x 52 semanas = 2.080, menos 30 días naturales de vacaciones y los festivos del calendario laboral.
A43: Parte de la jornada a pie de mesa (%) | B43: 0.85 | L43: SUPUESTO. El resto es recepción de mercancía, limpieza, formación y reuniones. Si lo pones al 100 % estarás repartiendo el coste de personal entre horas que no existen.
A44: COSTE DE UNA HORA DE OBRADOR (€) | B44: =IFERROR(SUMPRODUCT((K6:K8="OBRADOR")*I6:I8)/SUMPRODUCT((K6:K8="OBRADOR")*C6:C8*B6:B8)/$B$42/$B$43,"") -> 18.491659 | L44: Coste empresa de las personas del ÁREA OBRADOR dividido entre sus horas PRODUCTIVAS. No es el bruto ni el bruto con Seguridad Social: es lo que de verdad cuesta un minuto de templado, y es el número que usan el escandallo del libro 4 y la hoja de talleres para saber lo que cuesta un docente.
A46: El refuerzo de las campañas NO está en este cuadro: la estacionalidad manda horas extra en Navidad, en San Valentín y en comuniones, y eso se dimensiona y se cuesta en el libro «campanas-y-valle-del-ano». Aquí está la plantilla ESTABLE, que es la que entra en los costes fijos del P&L. Y una nota de método: los tres nombres de perfil son los de las hojas del kit de tareas -Encargado, Chocolatero y Dependiente-, no «maestro chocolatero» ni «bombonero», que son etiquetas de fuentes salariales y no puestos de esta casa.

Sheet Tesorería 12 meses
A1: Tesorería de los 12 Primeros Meses
A2: AI Chef Pro · aichef.pro — Cómo Montar una Chocolatería
A3: El P&L dice si el negocio gana dinero; esta hoja dice si le queda caja para llegar a fin de mes. Es la primera que mira un banco, y la que más aperturas ha salvado. Abajo, la fecha límite de cierre de pedidos de Navidad, calculada hacia atrás desde la capacidad de tu obrador.
A5: Concepto | B5: Mes 1 | C5: Mes 2 | D5: Mes 3 | E5: Mes 4 | F5: Mes 5 | G5: Mes 6 | H5: Mes 7 | I5: Mes 8 | J5: Mes 9 | K5: Mes 10 | L5: Mes 11 | M5: Mes 12 | N5: Año (€) | O5: Notas
A6: Estacionalidad del mes (tiene que sumar 100 %) | B6: 0.076667 | C6: 0.093333 | D6: 0.085 | E6: 0.09 | F6: 0.091667 | G6: 0.076667 | H6: 0.068333 | I6: 0.05 | J6: 0.071667 | K6: 0.085 | L6: 0.091667 | M6: 0.12 | N6: =IFERROR(SUM(B6:M6),"") -> 1.000001 | O6: DICIEMBRE manda, y AGOSTO es el suelo: son los doce coeficientes del calendario de campañas del kit traducidos a euros, con media 1,000 exacta. Agosto NO vale cero -la tienda abre para el turista aunque el obrador pare-, y por eso el valle se nota en el margen y no en la persiana. SON SUPUESTOS: no existe reparto mensual publicado de las ventas de una chocolatería, y la guía te enseña a medir el tuyo con el TPV.
