Workbook

Sheet Calculator
A1: WEDDING VENUE PRICING & QUOTE CALCULATOR
A2: Type only in the GREEN cells: everything else is calculated. Amounts exclude sales tax unless the row says otherwise. The default values are Kit estimates: replace them with your own venue's.
A4: EVENT DETAILS | B4: Value | C4: Notes
A5: Client | B5: Couple | C5: Couple or Corporate: they change the payment schedule and the cancellation tiers (table at the end). A corporate client gets the quote "plus sales tax"; a couple, with sales tax included.
A6: Event type | B6: Wedding | C6: Wedding, corporate event (meeting, dinner, holiday party), private celebration (shower, milestone birthday, rehearsal dinner) or micro wedding / elopement. It sets the venue rate, the caterer's food & beverage per guest and the direct cost from the tables at the end.
A7: Event date | B7: 46669 | C7: Type the full date (mm/dd/yyyy). It sets the season and the type of day from the month and weekday tables.
A8: Expected guests | B8: 130 | C8: Whole number of guests. The quote uses the higher of this number and the season minimum.
A9: Ceremonies on site (no.) | B9: 1 | C9: At the price in the extra services table.
A10: Additional hours of venue use (no.) | B10: 2 | C10: Hours beyond the base rental window in your agreement.
A11: Premium decor & lighting packages (no.) | B11: 1 | C11: Decor, furniture and lighting beyond the standard setup.
A12: Rehearsals the day before (no.) | B12: 0 | C12: 0 if the couple does not book a rehearsal at the venue.
A13: Venue staff hours on the event (coordinator and attendants) | B13: 16 | C13: Kit estimate: type your team's real hours (servers, bartenders and kitchen staff belong to the caterer).
A14: Hourly wage of venue staff | B14: 18 | C14: Kit estimate. At least your state or local minimum wage.
A15: Employer payroll taxes (% of wages) | B15: 0.1 | C15: FICA 7.65% plus federal and state unemployment taxes, about 10% (Kit estimate): check with your payroll provider.
A16: Direct cost of extra services (% of their price) | B16: 0.4 | C16: Kit estimate: what it costs you to deliver the ceremony, the decor package, the extra hours and the rehearsal.
A17: Rounding of the venue rental fee (multiple, in dollars) | B17: 50 | C17: The venue rental fee is rounded to the nearest multiple of this amount.
A18: Caterer commission (% of the caterer's food & beverage sales) | B18: 0.1 | C18: An editable ASSUMPTION, not a market figure: negotiate it with your caterer. For reference only: the caterer pays it to the venue, not the client.
... A20: Sales tax on the caterer's food & beverage (reference only) | B20: 0.08 | C20: The caterer bills the menu and the bar with its own sales tax, service charge and gratuity; they are not venue revenue.
A22: CALCULATION | B22: Value | C22: Notes
A23: Season of the date (from the month table) | B23: =INDEX('Calculator'!$B$82:$B$93,MONTH($B$7)) -> Peak | C23: Looks up the month of the date in the table at the end.
A24: Type of day (from the weekday table) | B24: =INDEX('Calculator'!$B$96:$B$102,WEEKDAY($B$7)) -> Saturday | C24: Looks up the weekday of the date in the table at the end.
A25: Season adjustment (premium + / discount −) | B25: =INDEX('Calculator'!$B$72:$B$74,MATCH($B$23,'Calculator'!$A$72:$A$74,0)) -> 0.15 | C25: From the season table.
A26: Day adjustment (premium + / discount −) | B26: =INDEX('Calculator'!$B$77:$B$79,MATCH($B$24,'Calculator'!$A$77:$A$79,0)) -> 0 | C26: From the day table.
A27: Venue rate for the event type (Saturday, shoulder season) | B27: =INDEX('Calculator'!$B$66:$B$69,MATCH($B$6,'Calculator'!$A$66:$A$69,0)) -> 8000 | C27: From the event type table.
A28: VENUE RENTAL FEE EXCL. SALES TAX | B28: =ROUND($B$27*(1+$B$25)*(1+$B$26)/$B$17,0)*$B$17 -> 9200 | C28: Rate × (1 + season adjustment) × (1 + day adjustment), rounded to the chosen multiple.
A29: Season minimum (guests) | B29: =INDEX('Calculator'!$C$72:$C$74,MATCH($B$23,'Calculator'!$A$72:$A$74,0)) -> 100 | C29: From the season table.
A30: Guaranteed guest count | B30: =MAX($B$8,$B$29) -> 130 | C30: The higher of the expected guests and the season minimum.
A31: Minimum check | B31: =IF($B$8<$B$29,"Below the minimum: the quote uses the season minimum","Meets the minimum") -> Meets the minimum
A32: Ceremonies | B32: =$B$9*'Calculator'!$B$105 -> 750 | C32: No. × price from the extra services table.
A33: Additional hours | B33: =$B$10*'Calculator'!$B$106 -> 1000
A34: Premium decor & lighting | B34: =$B$11*'Calculator'!$B$107 -> 800
A35: Rehearsals | B35: =$B$12*'Calculator'!$B$108 -> 0
A36: Extra services excl. sales tax | B36: =$B$32+$B$33+$B$34+$B$35 -> 2550
A37: Taxable amount (venue rental + services) | B37: =$B$28+$B$36 -> 11750
A38: Sales tax on venue charges | B38: =$B$37*$B$19 -> 940
A39: VENUE TOTAL (incl. sales tax) | B39: =$B$37+$B$38 -> 12690 | C39: It does not include food or the bar: the exclusive caterer bills them separately.
A40: Amount you quote (Couple: incl. sales tax · Corporate: plus sales tax) | B40: =IF($B$5="Couple",$B$39,$B$37) -> 12690 | C40: A corporate client gets the quote excl. sales tax ("plus sales tax"; if it is tax-exempt, ask for its exemption certificate); a couple, with sales tax included.
A41: Venue rental & services per guaranteed guest (excl. sales tax) | B41: =$B$37/$B$30 -> 90.384615 | C41: To compare with other venues.
A42: Payment 1: retainer | B42: =$B$39*INDEX('Calculator'!$B$111:$C$111,MATCH($B$5,'Calculator'!$B$110:$C$110,0)) -> 3172.5 | C42: At signing.
A43: Payment 2: second installment | B43: =$B$39*INDEX('Calculator'!$B$112:$C$112,MATCH($B$5,'Calculator'!$B$110:$C$110,0)) -> 4441.5
...

Sheet Examples
A1: 3 EXAMPLE QUOTES — with the same formulas as the "Calculator" tab
A2: Kit estimates to show the calculation, not market prices: change the inputs in "Calculator" to quote your own events. The tables (rates, seasons, days, extras, payments and cancellation) are at the end of that tab and also drive these examples.
A4: EVENT DETAILS | B4: Saturday wedding in peak season | C4: Friday wedding in shoulder season | D4: Weekday corporate event
A5: Client | B5: Couple | C5: Couple | D5: Corporate
A6: Event type | B6: Wedding | C6: Wedding | D6: Corporate event
A7: Event date | B7: 46669 | C7: 46584 | D7: 46498
A8: Expected guests | B8: 130 | C8: 100 | D8: 50
A9: Ceremonies on site (no.) | B9: 1 | C9: 1 | D9: 0
A10: Additional hours of venue use (no.) | B10: 2 | C10: 0 | D10: 1
A11: Premium decor & lighting packages (no.) | B11: 1 | C11: 0 | D11: 0
A12: Rehearsals the day before (no.) | B12: 0 | C12: 1 | D12: 0
A13: Venue staff hours on the event (coordinator and attendants) | B13: 16 | C13: 14 | D13: 10
A14: Hourly wage of venue staff | B14: 18 | C14: 18 | D14: 18
A15: Employer payroll taxes (% of wages) | B15: 0.1 | C15: 0.1 | D15: 0.1
A16: Direct cost of extra services (% of their price) | B16: 0.4 | C16: 0.4 | D16: 0.4
A17: Rounding of the venue rental fee (multiple, in dollars) | B17: 50 | C17: 50 | D17: 50
A18: Caterer commission (% of the caterer's food & beverage sales) | B18: 0.1 | C18: 0.1 | D18: 0.1
... A20: Sales tax on the caterer's food & beverage (reference only) | B20: 0.08 | C20: 0.08 | D20: 0.08
A22: RESULT | B22: Saturday wedding in peak season | C22: Friday wedding in shoulder season | D22: Weekday corporate event
A23: Season of the date (from the month table) | B23: =INDEX('Calculator'!$B$82:$B$93,MONTH($B$7)) -> Peak | C23: =INDEX('Calculator'!$B$82:$B$93,MONTH($C$7)) -> Shoulder | D23: =INDEX('Calculator'!$B$82:$B$93,MONTH($D$7)) -> Shoulder
A24: Type of day (from the weekday table) | B24: =INDEX('Calculator'!$B$96:$B$102,WEEKDAY($B$7)) -> Saturday | C24: =INDEX('Calculator'!$B$96:$B$102,WEEKDAY($C$7)) -> Friday or Sunday | D24: =INDEX('Calculator'!$B$96:$B$102,WEEKDAY($D$7)) -> Weekday
A25: Season adjustment (premium + / discount −) | B25: =INDEX('Calculator'!$B$72:$B$74,MATCH($B$23,'Calculator'!$A$72:$A$74,0)) -> 0.15 | C25: =INDEX('Calculator'!$B$72:$B$74,MATCH($C$23,'Calculator'!$A$72:$A$74,0)) -> 0 | D25: =INDEX('Calculator'!$B$72:$B$74,MATCH($D$23,'Calculator'!$A$72:$A$74,0)) -> 0
A26: Day adjustment (premium + / discount −) | B26: =INDEX('Calculator'!$B$77:$B$79,MATCH($B$24,'Calculator'!$A$77:$A$79,0)) -> 0 | C26: =INDEX('Calculator'!$B$77:$B$79,MATCH($C$24,'Calculator'!$A$77:$A$79,0)) -> -0.15 | D26: =INDEX('Calculator'!$B$77:$B$79,MATCH($D$24,'Calculator'!$A$77:$A$79,0)) -> -0.3
A27: Venue rate for the event type (Saturday, shoulder season) | B27: =INDEX('Calculator'!$B$66:$B$69,MATCH($B$6,'Calculator'!$A$66:$A$69,0)) -> 8000 | C27: =INDEX('Calculator'!$B$66:$B$69,MATCH($C$6,'Calculator'!$A$66:$A$69,0)) -> 8000 | D27: =INDEX('Calculator'!$B$66:$B$69,MATCH($D$6,'Calculator'!$A$66:$A$69,0)) -> 3500
A28: VENUE RENTAL FEE EXCL. SALES TAX | B28: =ROUND($B$27*(1+$B$25)*(1+$B$26)/$B$17,0)*$B$17 -> 9200 | C28: =ROUND($C$27*(1+$C$25)*(1+$C$26)/$C$17,0)*$C$17 -> 6800 | D28: =ROUND($D$27*(1+$D$25)*(1+$D$26)/$D$17,0)*$D$17 -> 2450
A29: Season minimum (guests) | B29: =INDEX('Calculator'!$C$72:$C$74,MATCH($B$23,'Calculator'!$A$72:$A$74,0)) -> 100 | C29: =INDEX('Calculator'!$C$72:$C$74,MATCH($C$23,'Calculator'!$A$72:$A$74,0)) -> 75 | D29: =INDEX('Calculator'!$C$72:$C$74,MATCH($D$23,'Calculator'!$A$72:$A$74,0)) -> 75
A30: Guaranteed guest count | B30: =MAX($B$8,$B$29) -> 130 | C30: =MAX($C$8,$C$29) -> 100 | D30: =MAX($D$8,$D$29) -> 75
A31: Minimum check | B31: =IF($B$8<$B$29,"Below the minimum: the quote uses the season minimum","Meets the minimum") -> Meets the minimum | C31: =IF($C$8<$C$29,"Below the minimum: the quote uses the season minimum","Meets the minimum") -> Meets the minimum | D31: =IF($D$8<$D$29,"Below the minimum: the quote uses the season minimum","Meets the minimum") -> Below the minimum: the quote uses the season minimum
A32: Ceremonies | B32: =$B$9*'Calculator'!$B$105 -> 750 | C32: =$C$9*'Calculator'!$B$105 -> 750 | D32: =$D$9*'Calculator'!$B$105 -> 0
A33: Additional hours | B33: =$B$10*'Calculator'!$B$106 -> 1000 | C33: =$C$10*'Calculator'!$B$106 -> 0 | D33: =$D$10*'Calculator'!$B$106 -> 500
A34: Premium decor & lighting | B34: =$B$11*'Calculator'!$B$107 -> 800 | C34: =$C$11*'Calculator'!$B$107 -> 0 | D34: =$D$11*'Calculator'!$B$107 -> 0
A35: Rehearsals | B35: =$B$12*'Calculator'!$B$108 -> 0 | C35: =$C$12*'Calculator'!$B$108 -> 400 | D35: =$D$12*'Calculator'!$B$108 -> 0
A36: Extra services excl. sales tax | B36: =$B$32+$B$33+$B$34+$B$35 -> 2550 | C36: =$C$32+$C$33+$C$34+$C$35 -> 1150 | D36: =$D$32+$D$33+$D$34+$D$35 -> 500
A37: Taxable amount (venue rental + services) | B37: =$B$28+$B$36 -> 11750 | C37: =$C$28+$C$36 -> 7950 | D37: =$D$28+$D$36 -> 2950
A38: Sales tax on venue charges | B38: =$B$37*$B$19 -> 940 | C38: =$C$37*$C$19 -> 636 | D38: =$D$37*$D$19 -> 236
A39: VENUE TOTAL (incl. sales tax) | B39: =$B$37+$B$38 -> 12690 | C39: =$C$37+$C$38 -> 8586 | D39: =$D$37+$D$38 -> 3186
A40: Amount you quote (Couple: incl. sales tax · Corporate: plus sales tax) | B40: =IF($B$5="Couple",$B$39,$B$37) -> 12690 | C40: =IF($C$5="Couple",$C$39,$C$37) -> 8586 | D40: =IF($D$5="Couple",$D$39,$D$37) -> 2950
A41: Venue rental & services per guaranteed guest (excl. sales tax) | B41: =$B$37/$B$30 -> 90.384615 | C41: =$C$37/$C$30 -> 79.5 | D41: =$D$37/$D$30 -> 39.333333
A42: Payment 1: retainer | B42: =$B$39*INDEX('Calculator'!$B$111:$C$111,MATCH($B$5,'Calculator'!$B$110:$C$110,0)) -> 3172.5 | C42: =$C$39*INDEX('Calculator'!$B$111:$C$111,MATCH($C$5,'Calculator'!$B$110:$C$110,0)) -> 2146.5 | D42: =$D$39*INDEX('Calculator'!$B$111:$C$111,MATCH($D$5,'Calculator'!$B$110:$C$110,0)) -> 955.8
A43: Payment 2: second installment | B43: =$B$39*INDEX('Calculator'!$B$112:$C$112,MATCH($B$5,'Calculator'!$B$110:$C$110,0)) -> 4441.5 | C43: =$C$39*INDEX('Calculator'!$B$112:$C$112,MATCH($C$5,'Calculator'!$B$110:$C$110,0)) -> 3005.1 | D43: =$D$39*INDEX('Calculator'!$B$112:$C$112,MATCH($D$5,'Calculator'!$B$110:$C$110,0)) -> 955.8
...

Sheet Instructions
A1: HOW TO USE — Wedding Venue Pricing & Quote Calculator
A2: It turns your rate card into a full quote for a specific event: the season and type of day of the date, the guest minimum, extra services, sales tax, total, payment schedule, the estimated caterer commission, the event contribution and what you keep if the client cancels. Type only in the GREEN cells; the margin is calculated.
A3: 1. Choose the client (Couple or Corporate), the event type, the full date and the expected guests.
A4: 2. The date sets the season (month table) and the type of day (weekday table). Each one carries a premium or a discount in its own visible table; both multiply the event type rate.
A5: 3. Each season has a guest minimum: the quote uses the higher of the expected guests and the minimum, and the commission is estimated on that guaranteed guest count.
A6: 4. Type how many extra services the event takes (ceremony on site, additional hours, premium decor package, rehearsal the day before). Their prices are in the "Venue extra services" table and are Kit examples: type your own.
A7: 5. Type the venue staff hours, the hourly wage, the payroll tax rate and the direct cost of the extras. The direct event cost (cleaning, restrooms, generator fuel, parking and security) is in the event type table.
A8: SALES TAX, COMMISSION AND THE CATERER'S MENU
A10: The venue bills its rental fee and services at the sales tax rate you type (8% in the example). Whether a venue rental fee is taxable depends on the state (taxable in some, exempt in others, sometimes only when it is billed with catering): ask your state's department of revenue. The exclusive caterer bills food and the bar with its own sales tax, service charge and gratuity; they are not venue revenue, and the calculator shows them only as a reference for the client.
A11: The caterer commission is what the exclusive caterer pays the venue for the exclusivity. Here it is an editable assumption (10% of the caterer's food & beverage sales, net of sales tax, service charge and gratuities): it is not a market figure, negotiate it. The caterer pays it, not the client; the plan treats it as a fee between businesses (0% sales tax in the example): confirm it with your CPA.
A12: The event contribution does not deduct rent, salaried staff, utilities, insurance or overhead. Those are in the financial plan.
A13: PAYMENTS AND CANCELLATION
... A26: Planning tool, not financial, tax or legal advice. Requirements vary by state, county and city — check with your accountant and local authorities.
