Workbook

Sheet 0. Assumptions
A1: ASSUMPTIONS — the RATES and DRIVERS of the model are typed here
A2: Change the GREEN cells: the rest of the workbook recalculates on its own. Expense items are typed on their own tab (also in green) and are not repeated here. Amounts are in your currency.
A3: BUSINESS ACTIVITY
A4: Guests per event (year 1 average) | B4: 90 | C4: Average guests per event in year 1. It comes from the mix in the benchmarks table on the "Instructions" tab: weddings of 130 guests, corporate events of 70, private celebrations of 80 and micro weddings of 30. It is an average: the maximum occupancy of the venue is further down
A5: Average revenue per guest excl. sales tax | B5: 68 | C5: Excl. sales tax, per guest: what the VENUE bills, not what the couple pays for the whole wedding. It adds the venue rental fee and services (ceremony site, setup, venue coordination, cleanup and parking) plus the commission the exclusive caterer pays you on each guest's food and beverage. The example works out to about $68 per guest from the event mix: each event type has its own site fee plus a 10% commission on the caterer's per-guest F&B. The price incl. sales tax is in the row below
A6: Events per year | B6: 100 | C6: Events held in the year: 35 weddings, 25 corporate events, 30 private celebrations (anniversaries, birthdays, showers, reunions) and 10 micro weddings and elopements. It is the SAME figure for the P&L, the break-even, the scenarios and the staff hours
A7: Volume growth in year 2 | B7: 0.08 | C7: More activity in year 2: weddings that come by referral, corporate clients who come back and planners who already know you. The workbook applies it to guests per event with the same number of events; in dollars it equals about 8% more events of the same size (about 108). Staff does not rise with this percentage: it grows with the hires on the "Staffing" tab
A8: Volume growth in year 3 | B8: 0.05 | C8: On top of year 2 (about 113 equivalent events). Conservative: the ceiling is set by peak-season Saturdays and the maximum occupancy of the venue
A9: Menu price incl. sales tax (calculated) | B9: =IFERROR(IF($B$5="","",$B$5*(1+SUMPRODUCT('3-Year P&L'!$E$10:$E$11,'3-Year P&L'!$G$10:$G$11))),"") -> 72.7872 | C9: =IFERROR("Revenue per guest excl. sales tax plus the weighted sales tax of your two sales lines ("&TEXT(SUMPRODUCT('3-Year P&L'!$E$10:$E$11,'3-Year P&L'!$G$10:$G$11)*100,"0")&"%), rounded. It is what the venue bills per guest (venue rental & services plus the caterer commission), not what the couple pays for the whole wedding: the caterer bills the menu and the bar, with its own sales tax, and they are not in this workbook. In the UK, prices to private clients include VAT.","") -> Revenue per guest excl. sales tax plus the weighted sales tax of your two sales lines (7%), rounded. It is what the venue bills per guest (venue rental & services plus the caterer commission), not what the couple pays for the whole wedding: the caterer bills the menu and the bar, with its own sales tax, and they are not in this workbook. In the UK, prices to private clients include VAT.
A10: SALES MIX AND DIRECT EVENT COSTS
A11: Venue rental & services share of total sales | B11: 0.88 | C11: Share of VENUE RENTAL & SERVICES in total sales. It is an INPUT: change it here and the P&L, the cash flow and the sales tax collected recalculate on their own
A12: Caterer commission share of total sales | B12: =IFERROR(IF(COUNT(B11)=0,"",1-B11),"") -> 0.12 | C12: Calculated as the remainder: venue rental & services + caterer commission = 100%
A13: Direct event cost on venue rental & services sales | B13: 0.12 | C13: Direct cost of each event as a share of venue rental & services sales: post-event cleaning, restroom supplies, standby generator fuel, parking attendants and security, and setup consumables. Roughly $1,000 for a wedding, $500 for a corporate or private event and $300 for a micro wedding (Kit estimate; the pricing calculator uses the same figures). If you play recorded music at events, add the ASCAP/BMI/SESAC license fees to this line or to fixed costs
A14: Cost of the commission on caterer commission sales | B14: 0 | C14: ZERO: the commission costs the venue nothing. The caterer buys the food and beverages and sells them to the couple
A15: Disposables and packaging as % of sales | B15: 0.015 | C15: Candles, base florals, paper and restroom supplies, and the small consumables of each setup
A16: Sales that come through planners and venue marketplaces, as a share of total | B16: 0.1 | C16: Share of sales that arrives through a wedding planner or a venue marketplace (such as Peerspace) that charges a commission. The Knot / WeddingWire storefronts are a fixed marketing cost, not a commission. It does not change the sales tax: the example rate applies to everything the venue bills as rental and services
A17: Commission to planners and venue marketplaces | B17: 0.15 | C17: Average commission on what that channel sells: 15% in the example (Kit estimate; marketplaces publish 15-20%, so check your contract). If every booking comes direct, enter 0
A18: Card processing fee | B18: 0.02 | C18: Most payments (retainers, couple installments and corporate invoices) arrive by ACH, check or card, and the card terminal or mobile wallet covers the extras on the day. The example uses 2% card processing
A19: LABOR
A20: Employer payroll taxes | B20: 0.1 | C20: FICA (Social Security 6.2% + Medicare 1.45%) + federal and state unemployment taxes (FUTA / SUTA) + workers' comp. About 10% in total: adjust it to your state and your insurance carrier
A21: Monthly pay periods per year (keep 12) | B21: 12 | C21: Annual gross pay = monthly gross pay × this number. Keep 12 in the US: it counts the monthly salaries the model pays in a year, not how often you run payroll (weekly or biweekly payroll pays the same annual amount)
A22: Federal minimum wage, annual full-time | B22: 15080 | C22: US federal minimum wage: 7.25 per hour × 2,080 hours = 15,080 per year for a full-time job. Your state or city may set a higher floor: enter it in the state / local minimum wage cell below. Check the current rates at dol.gov
A23: VENUE AND FIXED COSTS
A24: Monthly rent of the property | B24: 5000 | C24: Rent for a leased property with an unconverted barn or hall: $5,000 a month in the example (Kit estimate, no market source: get local quotes). Negotiate reduced rent during permitting and the build-out. Get a long lease: SBA lenders typically require a term, counting extension options, at least as long as the loan; confirm with your lender. Ask your attorney for a purchase option or right of first refusal, the owner's consent to the build-out and to using the lease as collateral, and a tenant improvement (TI) allowance. If the property belongs to a relative, charge market rent anyway. The "Rent / Sales" row of the "3-Year P&L" calculates the weight on sales
A25: Lease security deposit (months) | B25: 2 | C25: Two months of rent as a security deposit; extra guarantees are negotiated separately. Confirm the terms with your attorney before you sign
A26: Monthly utilities (power, propane, water, internet & trash) | B26: 2000 | C26: Power for the hall and the grounds, propane, water or well, internet and trash outside event days. The example is $2,000 a month (Kit estimate). Ask the owner for past bills. If a well serves your guests, ask your state drinking water program whether it counts as a public water system
A27: Insurance (per year) | B27: 12000 | C27: General liability, property, umbrella, host liquor liability and workers' comp. The example is $12,000 a year (Kit estimate, no rate read: get quotes from an agent who insures venues). Also require the exclusive caterer to carry its own liability and liquor liability with you as additional insured, and a COI from every outside vendor
A28: Miscellaneous and contingency as % of sales | B28: 0.01 | C28: Breakage, setup surprises and sales travel (bridal shows and planner visits)
A29: FINANCING
A30: Owner's equity contributed | B30: 200000 | C30: Owner's cash. Lenders usually expect an owner equity injection (often around 10% for SBA start-ups; many want 20-30%) toward the cash need
A31: Loan requested | B31: 470000 | C31: Principal requested. The "Financing" tab compares what you put in with the cash need on "Startup Costs" and tells you whether you have a surplus or a shortfall: adjust the loan with that figure. The example is an SBA 7(a) loan, which you apply for through your lender. You do not own the property, so there is no real-estate collateral: ask your lender about other collateral and about the lease, since SBA lenders typically require a lease term, counting extension options, at least as long as the loan; confirm with your lender
A32: Nominal annual interest rate (not APR) | B32: 0.1 | C32: Nominal annual rate, not APR. The example uses 10%. Get a quote from two lenders before you set it, and compare an SBA 7(a) loan with conventional financing
A33: Loan term (years) | B33: 10 | C33: Total years of the loan. The example is 10 years. With a six-year term the payment does not fit a business with this much fixed structure
A34: Interest-only period (years) | B34: 0 | C34: Years you pay interest only before principal repayment starts. The example uses 0, because SBA 7(a) loans amortize from the start. A year of interest only could ease the build-out and the first season: ask your lender, and check the cash slack of the first repayment year on the "Break-Even" tab
A35: Working capital (months of fixed costs) | B35: 3 | C35: Three months of fixed costs: the cushion for the first months, right after the build-out is paid and before the busy season. In a normal year the winter months bring in only a small part of annual sales while rent and staff stay flat: that winter is carried by the cash of the season
A36: TAXES
A37: Effective income tax rate (years 1-2) | B37: 0.25 | C37: Example: 21% federal rate for a C corporation plus state tax, rounded to 25%. If you operate as a sole proprietorship, LLC taxed as a pass-through or S corporation, the business itself pays 0% here and you pay tax on the profit personally: set this to 0 and budget for your personal tax separately. The model applies this rate to the first two years with positive taxable income
A38: Effective income tax rate (from year 3) | B38: 0.25 | C38: From the third year with positive taxable income. Same example rate (21% federal C corporation + state). Confirm the rate that applies to you with your accountant and change it here
A39: Sales tax rate on sales | B39: 0.08 | C39: Not used in this plan: the venue sells no food or beverage. It is the rate on the caterer's menu. Varies by state and city: look up yours
A40: Sales tax rate on alcohol to go | B40: 0.08 | C40: General example rate, 8%. In this plan it applies to everything the venue bills as rental and services; the caterer commission is taxed at 0% in the model, and the venue's purchases carry no recoverable credit. The venue does not sell food or beverage: the caterer bills the menu and the bar. Some states do not tax venue fees at all: confirm yours with your state department of revenue
...

Sheet Startup Costs
A1: WEDDING VENUE BUSINESS PLAN: BARN & EVENT VENUE
A2: Estimated Startup Costs — barn conversion on a leased property, 200 guests, exclusive caterer
A3: US kit example (2026) — barn conversion on a leased property; replace with your own quotes.
A5: Item | B5: Amount | C5: % of startup costs | D5: Notes | E5: Taxable / recoverable tax?
A6: STARTUP COSTS | B6: =IFERROR(IF(COUNT(B7:B28)=0,"",SUM(B7:B28)),"") -> 570500 | C6: =IFERROR(B6/$B$31,"") -> 0.85185426
A7: Architect, engineer & code consultant (change of occupancy) | B7: 25000 | C7: =IFERROR(B7/$B$31,"") -> 0.037329284 | D7: Architect, engineer and code consultant drawings for the change of occupancy to assembly use (A-2) and the building permit. They are the base for the zoning approval and the certificate of occupancy | E7: Yes
A8: Conditional use permit, zoning hearing, traffic & septic studies, permit fees | B8: 15000 | C8: =IFERROR(B8/$B$31,"") -> 0.02239757 | D8: Conditional (special) use permit from the county: hearing, traffic and septic studies, and permit fees. No sales tax. Fees and timelines vary widely by county: get local quotes and ask your county planning office | E8: No
A9: Barn renovation: floor, doors, insulation, fixtures & paint | B9: 80000 | C9: =IFERROR(B9/$B$31,"") -> 0.11945371 | D9: On EXISTING buildings. The cosmetic work is the small part: sprinklers, septic, restrooms and accessibility drive the budget. Get two quotes on the architect's drawings | E9: Yes
A10: Fire sprinkler system (city water; a tank and fire pump cost more) | B10: 70000 | C10: =IFERROR(B10/$B$31,"") -> 0.10452199 | D10: Sprinklers need city water; a tank and fire pump, a new septic system or a strict county can double this line. Whether you need them depends on the fire code your county has adopted: ask the building official and the fire marshal in writing, and get local quotes | E10: Yes
A11: Ceremony site: pergola, tent platform & ceremony seating | B11: 25000 | C11: =IFERROR(B11/$B$31,"") -> 0.037329284 | D11: This is the rain plan: an investment, not an extra. A tent platform and a pergola let the ceremony go ahead in bad weather; ask your fire marshal about tent permits and egress | E11: Yes
A12: ADA-compliant restrooms (septic upgrade quoted apart) | B12: 45000 | C12: =IFERROR(B12/$B$31,"") -> 0.067192711 | D12: With ADA-compliant restrooms and an accessible route: check it with your architect against the ADA standards. The septic upgrade (a new or expanded system for your occupant load) is budgeted apart: get an engineer's quote | E12: Yes
A13: Electrical service, exterior, exit & emergency lighting | B13: 30000 | C13: =IFERROR(B13/$B$31,"") -> 0.044795141 | D13: Power for the hall, the tent, the caterer's kitchen and the grounds, plus exit and emergency lighting. Ask the utility about the available capacity BEFORE you sign: a new service in the country takes time | E13: Yes
A14: Standby generator | B14: 15000 | C14: =IFERROR(B14/$B$31,"") -> 0.02239757 | D14: Backup if the grid fails or the power does not reach the property: a blackout in the middle of a wedding has no fix | E14: Yes
A15: HVAC for the hall | B15: 30000 | C15: =IFERROR(B15/$B$31,"") -> 0.044795141 | D15: Heating and cooling to use the hall all year, including August weddings | E15: Yes
A16: Caterer's prep & warming kitchen: sinks, prep tables, ice machine, water & drain | B16: 25000 | C16: =IFERROR(B16/$B$31,"") -> 0.037329284 | D16: The space where the caterer plates and washes: a prep & warming kitchen, not a production kitchen. The caterer cooks in its own commissary, which is why the plan has no full kitchen. The caterer holds the health permit; ask your county whether it requires a plan review of the space | E16: Yes
A17: Tables, chairs for 200 & base linens | B17: 30000 | C17: =IFERROR(B17/$B$31,"") -> 0.044795141 | D17: Round and banquet tables, chairs for 200 and base linens. Special decor is hired by the couple | E17: Yes
A18: Bridal suite & groom's lounge furnishings and decor | B18: 15000 | C18: =IFERROR(B18/$B$31,"") -> 0.02239757 | D18: Sofas, mood lighting, mirrors and fixed decor for the bridal suite and the groom's lounge | E18: Yes
... A25: Launch: bridal shows, open house & listing storefronts | B25: 10000 | C25: =IFERROR(B25/$B$31,"") -> 0.014931714 | D25: The first bridal show, an open house with the caterer and a paid storefront listing on The Knot / WeddingWire for the first year | E25: Yes
A26: Lease security deposit | B26: =IFERROR(IF('0. Assumptions'!$B$24="","",'0. Assumptions'!$B$24*'0. Assumptions'!$B$25),"") -> 10000 | C26: =IFERROR(B26/$B$31,"") -> 0.014931714 | D26: =IFERROR(""&TEXT('0. Assumptions'!$B$25,"0")&IF('0. Assumptions'!$B$25=1," month"," months")&" of rent, from ""0. Assumptions"". Refundable when the lease ends: it is not depreciated and carries no tax","") -> 2 months of rent, from "0. Assumptions". Refundable when the lease ends: it is not depreciated and carries no tax | E26: No
A27: Rent during permitting and build-out | B27: =IFERROR(IF('0. Assumptions'!$B$24="","",'0. Assumptions'!$B$24*'0. Assumptions'!$B$54),"") -> 20000 | C27: =IFERROR(B27/$B$31,"") -> 0.029863427 | D27: =IFERROR("Rent "&IF('0. Assumptions'!$B$54=1,"for the month","for the "&TEXT('0. Assumptions'!$B$54,"0")&" months")&" of build-out and permits before opening. It does not overlap the P&L, which starts on opening day: its twelve months are twelve trading months","") -> Rent for the 4 months of build-out and permits before opening. It does not overlap the P&L, which starts on opening day: its twelve months are twelve trading months | E27: Yes
A28: Build-out contingency | B28: =IFERROR(IF(COUNT(B7,B9,B10,B12,B13,B15,B16,B20,B21,B22)=0,"",ROUND((B7+B9+B10+B12+B13+B15+B16+B20+B21+B22)*'0. Assumptions'!$B$55,0)),"") -> 37000 | C28: =IFERROR(B28/$B$31,"") -> 0.05524734 | D28: =IFERROR("At "&TEXT('0. Assumptions'!$B$55,"0%")&" of the BUILD-OUT items of this block (architect, engineer & code consultant; barn renovation; fire sprinkler system; ADA-compliant restrooms; electrical service & lighting; HVAC; caterer's prep & warming kitchen; parking lot & driveway; landscaping; fire alarm, exit signs & accessible routes), not of the whole block: the other items are left out. Sprinklers on a tank and fire pump, a new septic system or a strict county can push these lines far above the example. No lender funds a build-out without a cushion: the percentage is in ""0. Assumptions""","") -> At 10% of the BUILD-OUT items of this block (architect, engineer & code consultant; barn renovation; fire sprinkler system; ADA-compliant restrooms; electrical service & lighting; HVAC; caterer's prep & warming kitchen; parking lot & driveway; landscaping; fire alarm, exit signs & accessible routes), not of the whole block: the other items are left out. Sprinklers on a tank and fire pump, a new septic system or a strict county can push these lines far above the example. No lender funds a build-out without a cushion: the percentage is in "0. Assumptions" | E28: Yes
A29: WORKING CAPITAL | B29: =IFERROR(IF(B30="","",B30),"") -> 99215.5 | C29: =IFERROR(B29/$B$31,"") -> 0.14814574
A30: Operating cushion until break-even | B30: =IFERROR(IF('0. Assumptions'!$B$35*('3-Year P&L'!$B$38-'3-Year P&L'!$B$36)=0,"",'0. Assumptions'!$B$35*('3-Year P&L'!$B$38-'3-Year P&L'!$B$36)/12),"") -> 99215.5 | C30: =IFERROR(B30/$B$31,"") -> 0.14814574 | D30: =IFERROR("Covers "&TEXT('0. Assumptions'!$B$35,"0")&IF('0. Assumptions'!$B$35=1," month"," months")&" of year-1 CASH fixed costs (the P&L fixed costs minus depreciation, which is not paid out), the minimum the Instructions of this workbook ask for","") -> Covers 3 months of year-1 CASH fixed costs (the P&L fixed costs minus depreciation, which is not paid out), the minimum the Instructions of this workbook ask for | E30: No
A31: TOTAL STARTUP COSTS (sum of the blocks) | B31: =IFERROR(B6+B29,"") -> 669715.5 | D31: =IFERROR("The percentages in column C are read on this figure, which includes the working capital ("&TEXT(C29,"0%")&" of the total). To compare the breakdown with another plan, use the CAPEX row below.","") -> The percentages in column C are read on this figure, which includes the working capital (15% of the total). To compare the breakdown with another plan, use the CAPEX row below.
A32: CAPEX (startup costs excluding working capital) | B32: =IFERROR(B31-B29,"") -> 570500 | D32: What you buy: build-out, equipment, launch and formation costs. The cash cushion is not an investment: it is working capital
A33: Recoverable input tax on capex | B33: =IFERROR(IF(B31="","",SUMIF($E$7:$E$28,"Yes",$B$7:$B$28)*'0. Assumptions'!$B$41),"") -> 0 | D33: =IFERROR("At "&TEXT('0. Assumptions'!$B$41,"0%")&" on the items marked ""Yes"" in the tax column. US: the sales tax you pay on equipment is part of its cost and is not recovered, so this rate is 0. UK (VAT-registered): 20%, reclaimed on your VAT return, but you pay it first, so the loan has to cover it","") -> At 0% on the items marked "Yes" in the tax column. US: the sales tax you pay on equipment is part of its cost and is not recovered, so this rate is 0. UK (VAT-registered): 20%, reclaimed on your VAT return, but you pay it first, so the loan has to cover it
A34: TOTAL CASH NEEDED AT LAUNCH | B34: =IFERROR(B31+B33,"") -> 669715.5 | D34: This is the figure the "Financing" tab has to cover
A35: DEPRECIATION BASES (not added to startup costs)
A36: Build-out, fixtures and setup | B36: =IFERROR(IF(B7="","",B7+B9+B10+B12+B13+B15+B16+B20+B21+B22+B28),"") -> 407000 | D36: =IFERROR("Depreciated over "&TEXT('0. Assumptions'!$B$44,"0")&" years","") -> Depreciated over 15 years
A37: Machinery, furniture and equipment | B37: =IFERROR(IF(B11="","",B11+B14+B17+B18+B19),"") -> 97000 | D37: =IFERROR("Depreciated over "&TEXT('0. Assumptions'!$B$45,"0")&" years","") -> Depreciated over 7 years
A38: Annual depreciation of fixed assets | B38: =IFERROR(B36/MAX(1,'0. Assumptions'!$B$44)+B37/MAX(1,'0. Assumptions'!$B$45),"") -> 40990.476 | D38: =IFERROR("Not depreciated, because they are not fixed assets: conditional use permit, studies and permit fees; website, photography, video & brand; LLC formation & attorney; launch; lease security deposit; rent during permitting and build-out, and the working capital reserve. They add up to "&TEXT(B31-B36-B37,"#,##0")&" of the "&TEXT(B31,"#,##0")&" total investment.","") -> Not depreciated, because they are not fixed assets: conditional use permit, studies and permit fees; website, photography, video & brand; LLC formation & attorney; launch; lease security deposit; rent during permitting and build-out, and the working capital reserve. They add up to 165716 of the 669716 total investment.

Sheet 3-Year P&L
A1: PROFIT AND LOSS STATEMENT — 3 YEARS
A2: Base case — barn wedding & event venue, 200 guests, exclusive caterer
A4: Item | B4: Year 1 | C4: Year 2 | D4: Year 3 | E4: % of sales (year 1) | F4: Notes | G4: Sales tax rate on the line (%)
A5: REVENUE
A6: Guests per event (average) | B6: =IFERROR(IF('0. Assumptions'!$B$4="","",'0. Assumptions'!$B$4),"") -> 90 | C6: =IFERROR(B6*(1+'0. Assumptions'!$B$7),"") -> 97.2 | D6: =IFERROR(C6*(1+'0. Assumptions'!$B$8),"") -> 102.06 | F6: Growth for years 2 and 3 is set in "0. Assumptions"
A7: Average revenue per guest excl. sales tax | B7: =IFERROR(IF('0. Assumptions'!$B$5="","",'0. Assumptions'!$B$5),"") -> 68 | C7: =IFERROR(IF(B7="","",B7),"") -> 68 | D7: =IFERROR(IF(C7="","",C7),"") -> 68 | F7: Held constant at year-1 prices: a price increase is a separate decision
A8: Events per year | B8: =IFERROR(IF('0. Assumptions'!$B$6="","",'0. Assumptions'!$B$6),"") -> 100 | C8: =IFERROR(IF(B8="","",B8),"") -> 100 | D8: =IFERROR(IF(C8="","",C8),"") -> 100
A9: TOTAL REVENUE (excl. sales tax) | B9: =IFERROR(IF(B6*B7*B8=0,"",B6*B7*B8),"") -> 612000 | C9: =IFERROR(IF(C6*C7*C8=0,"",C6*C7*C8),"") -> 660960 | D9: =IFERROR(IF(D6*D7*D8=0,"",D6*D7*D8),"") -> 694008 | E9: =IFERROR(IF(B9="","",1),"") -> 1
A10: Venue rental & event services | B10: =IFERROR(IF(B9="","",B9*$E$10),"") -> 538560 | C10: =IFERROR(IF(C9="","",C9*$E$10),"") -> 581644.8 | D10: =IFERROR(IF(D9="","",D9*$E$10),"") -> 610727.04 | E10: =IFERROR(IF('0. Assumptions'!$B$11="","",'0. Assumptions'!$B$11),"") -> 0.88 | F10: What couples and companies pay the venue: the site fee, the ceremony, setup, venue coordination on the day, cleaning and parking · The sales tax this line COLLECTS is an input (green cell to the right), 8% in the example. Whether a venue rental fee is taxable depends on the state (taxable in some, exempt in others, sometimes only when it is billed together with catering): ask your state's department of revenue. | G10: 0.08
A11: Caterer commission (exclusive caterer) | B11: =IFERROR(IF(B9="","",B9*$E$11),"") -> 73440 | C11: =IFERROR(IF(C9="","",C9*$E$11),"") -> 79315.2 | D11: =IFERROR(IF(D9="","",D9*$E$11),"") -> 83280.96 | E11: =IFERROR(IF('0. Assumptions'!$B$12="","",'0. Assumptions'!$B$12),"") -> 0.12 | F11: What your exclusive caterer pays you for working at the venue. The plan assumes 10% of its food & beverage sales at the venue, net of sales tax, service charge and gratuities: it is an assumption, negotiate it · Sales tax: 0% in the example (green cell to the right), treated as a fee your caterer pays you, not a retail sale to the couple. Confirm the treatment in your state with your CPA. | G11: 0
A12: VARIABLE COSTS
A13: Direct event costs | B13: =IFERROR(IF(B9="","",B9*'0. Assumptions'!$B$11*'0. Assumptions'!$B$13),"") -> 64627.2 | C13: =IFERROR(IF(C9="","",C9*'0. Assumptions'!$B$11*'0. Assumptions'!$B$13),"") -> 69797.376 | D13: =IFERROR(IF(D9="","",D9*'0. Assumptions'!$B$11*'0. Assumptions'!$B$13),"") -> 73287.245 | E13: =IFERROR(B13/$B$9,"") -> 0.1056 | F13: =IFERROR("At "&TEXT('0. Assumptions'!$B$13,"0%")&" of VENUE RENTAL & SERVICES sales, not of total sales: the caterer commission has its own line · Cleaning and turnover, restroom restocking, generator fuel, parking attendants and security for each event: check it against your invoices and the Pricing & Quote Calculator","") -> At 12% of VENUE RENTAL & SERVICES sales, not of total sales: the caterer commission has its own line · Cleaning and turnover, restroom restocking, generator fuel, parking attendants and security for each event: check it against your invoices and the Pricing & Quote Calculator | G13: 0
A14: Cost of the commission (none) | B14: =IFERROR(IF(B9="","",B9*'0. Assumptions'!$B$12*'0. Assumptions'!$B$14),"") -> 0 | C14: =IFERROR(IF(C9="","",C9*'0. Assumptions'!$B$12*'0. Assumptions'!$B$14),"") -> 0 | D14: =IFERROR(IF(D9="","",D9*'0. Assumptions'!$B$12*'0. Assumptions'!$B$14),"") -> 0 | E14: =IFERROR(B14/$B$9,"") -> 0 | F14: =IFERROR("At "&TEXT('0. Assumptions'!$B$14,"0%")&" of CATERER COMMISSION sales: the commission has no cost for the venue","") -> At 0% of CATERER COMMISSION sales: the commission has no cost for the venue | G14: =IFERROR(IF(B9="","",'0. Assumptions'!$B$41),"") -> 0
A15: Event consumables | B15: =IFERROR(IF(B9="","",B9*'0. Assumptions'!$B$15),"") -> 9180 | C15: =IFERROR(IF(C9="","",C9*'0. Assumptions'!$B$15),"") -> 9914.4 | D15: =IFERROR(IF(D9="","",D9*'0. Assumptions'!$B$15),"") -> 10410.12 | E15: =IFERROR(B15/$B$9,"") -> 0.015 | G15: =IFERROR(IF(B9="","",'0. Assumptions'!$B$41),"") -> 0
A16: Commissions to planners and venue marketplaces | B16: =IFERROR(IF(B9="","",B9*'0. Assumptions'!$B$16*'0. Assumptions'!$B$17),"") -> 9180 | C16: =IFERROR(IF(C9="","",C9*'0. Assumptions'!$B$16*'0. Assumptions'!$B$17),"") -> 9914.4 | D16: =IFERROR(IF(D9="","",D9*'0. Assumptions'!$B$16*'0. Assumptions'!$B$17),"") -> 10410.12 | E16: =IFERROR(B16/$B$9,"") -> 0.015 | F16: Applied to the sales of THAT CHANNEL. With 0% of sales through planners and marketplaces in "0. Assumptions", this line is zero | G16: =IFERROR(IF(B9="","",'0. Assumptions'!$B$41),"") -> 0
A17: Card processing fees | B17: =IFERROR(IF(B9="","",B9*'0. Assumptions'!$B$18),"") -> 12240 | C17: =IFERROR(IF(C9="","",C9*'0. Assumptions'!$B$18),"") -> 13219.2 | D17: =IFERROR(IF(D9="","",D9*'0. Assumptions'!$B$18),"") -> 13880.16 | E17: =IFERROR(B17/$B$9,"") -> 0.02 | F17: Card processing fees are not subject to sales tax: no tax is recovered or deducted for them | G17: 0
A18: Miscellaneous and contingency | B18: =IFERROR(IF(B9="","",B9*'0. Assumptions'!$B$28),"") -> 6120 | C18: =IFERROR(IF(C9="","",C9*'0. Assumptions'!$B$28),"") -> 6609.6 | D18: =IFERROR(IF(D9="","",D9*'0. Assumptions'!$B$28),"") -> 6940.08 | E18: =IFERROR(B18/$B$9,"") -> 0.01 | F18: =IFERROR("At "&TEXT('0. Assumptions'!$B$28,"0%")&" of sales. It is a VARIABLE cost: it moves with revenue, so it cannot sit in fixed costs","") -> At 1% of sales. It is a VARIABLE cost: it moves with revenue, so it cannot sit in fixed costs | G18: =IFERROR(IF(B9="","",'0. Assumptions'!$B$41),"") -> 0
A19: TOTAL VARIABLE COSTS | B19: =IFERROR(IF(B9="","",SUM(B13:B18)),"") -> 101347.2 | C19: =IFERROR(IF(C9="","",SUM(C13:C18)),"") -> 109454.98 | D19: =IFERROR(IF(D9="","",SUM(D13:D18)),"") -> 114927.72 | E19: =IFERROR(B19/$B$9,"") -> 0.1656
A20: GROSS MARGIN | B20: =IFERROR(IF(B9="","",B9-B19),"") -> 510652.8 | C20: =IFERROR(IF(C9="","",C9-C19),"") -> 551505.02 | D20: =IFERROR(IF(D9="","",D9-D19),"") -> 579080.28 | E20: =IFERROR(B20/$B$9,"") -> 0.8344
A21: FIXED COSTS
A22: Rent (leased property) | B22: =IFERROR(IF(B9="","",'0. Assumptions'!$B$24*12),"") -> 60000 | C22: =IFERROR(IF(C9="","",B22*(1+'0. Assumptions'!$B$48)),"") -> 60000 | D22: =IFERROR(IF(D9="","",C22*(1+'0. Assumptions'!$B$48)),"") -> 60000 | E22: =IFERROR(B22/$B$9,"") -> 0.098039216 | F22: The monthly amount is on the "0. Assumptions" tab; here it is multiplied by twelve. The months of rent before opening are on "Startup Costs" and are NOT counted twice | G22: =IFERROR(IF(B9="","",'0. Assumptions'!$B$41),"") -> 0
A23: Labor (wages + employer payroll taxes) | B23: =IFERROR(IF(B9="","",Staffing!$G$11),"") -> 191862 | C23: =IFERROR(IF(C9="","",Staffing!$B$15),"") -> 199862 | D23: =IFERROR(IF(D9="","",Staffing!$B$16),"") -> 207862 | E23: =IFERROR(B23/$B$9,"") -> 0.3135 | F23: Comes from the Staffing tab: it is the SAME number, not a separate estimate. Years 2 and 3 add the new hires declared on that tab, not a percentage of volume | G23: 0
A24: Utilities (power, propane, water, internet & trash) | B24: =IFERROR(IF(B9="","",'0. Assumptions'!$B$26*12),"") -> 24000 | C24: =IFERROR(IF(C9="","",B24*(1+'0. Assumptions'!$B$48)),"") -> 24000 | D24: =IFERROR(IF(D9="","",C24*(1+'0. Assumptions'!$B$48)),"") -> 24000 | E24: =IFERROR(B24/$B$9,"") -> 0.039215686 | F24: Enter the monthly bills excl. sales tax. The workbook applies a single tax treatment to this whole line, the one in the column next to it; if one utility is taxed differently in your area, give it its own line | G24: =IFERROR(IF(B9="","",'0. Assumptions'!$B$41),"") -> 0
A25: Insurance (general liability, host liquor liability & property) | B25: =IFERROR(IF(B9="","",'0. Assumptions'!$B$27),"") -> 12000 | C25: =IFERROR(IF(C9="","",B25*(1+'0. Assumptions'!$B$48)),"") -> 12000 | D25: =IFERROR(IF(D9="","",C25*(1+'0. Assumptions'!$B$48)),"") -> 12000 | E25: =IFERROR(B25/$B$9,"") -> 0.019607843 | F25: Insurance premiums are not subject to sales tax: there is no recoverable tax on them | G25: 0
A26: Marketing (The Knot/WeddingWire, Google Ads, social) | B26: 18000 | C26: =IFERROR(IF(C9="","",B26*(1+'0. Assumptions'!$B$48)),"") -> 18000 | D26: =IFERROR(IF(D9="","",C26*(1+'0. Assumptions'!$B$48)),"") -> 18000 | E26: =IFERROR(B26/$B$9,"") -> 0.029411765 | F26: The Knot / WeddingWire storefront, Google Ads and social media. Measure the cost per lead of each channel before you renew the premium storefront | G26: =IFERROR(IF(B9="","",'0. Assumptions'!$B$41),"") -> 0
A27: Bridal shows & open houses | B27: 5000 | C27: =IFERROR(IF(C9="","",B27*(1+'0. Assumptions'!$B$48)),"") -> 5000 | D27: =IFERROR(IF(D9="","",C27*(1+'0. Assumptions'!$B$48)),"") -> 5000 | E27: =IFERROR(B27/$B$9,"") -> 0.0081699346 | F27: Two bridal shows a year and the venue's open houses, with the caterer | G27: =IFERROR(IF(B9="","",'0. Assumptions'!$B$41),"") -> 0
A28: Grounds & landscaping contractors | B28: 10000 | C28: =IFERROR(IF(C9="","",B28*(1+'0. Assumptions'!$B$48)),"") -> 10000 | D28: =IFERROR(IF(D9="","",C28*(1+'0. Assumptions'!$B$48)),"") -> 10000 | E28: =IFERROR(B28/$B$9,"") -> 0.016339869 | F28: The big jobs your own staff does not do: tree trimming, mowing, irrigation and treatments | G28: =IFERROR(IF(B9="","",'0. Assumptions'!$B$41),"") -> 0
A29: Repairs, paint & furniture replacement | B29: 7000 | C29: =IFERROR(IF(C9="","",B29*(1+'0. Assumptions'!$B$48)),"") -> 7000 | D29: =IFERROR(IF(D9="","",C29*(1+'0. Assumptions'!$B$48)),"") -> 7000 | E29: =IFERROR(B29/$B$9,"") -> 0.011437908 | F29: Paint, small projects between seasons and replacement of chairs, tables and linens | G29: =IFERROR(IF(B9="","",'0. Assumptions'!$B$41),"") -> 0
A30: Accounting, payroll & legal | B30: 5000 | C30: =IFERROR(IF(C9="","",B30*(1+'0. Assumptions'!$B$48)),"") -> 5000 | D30: =IFERROR(IF(D9="","",C30*(1+'0. Assumptions'!$B$48)),"") -> 5000 | E30: =IFERROR(B30/$B$9,"") -> 0.0081699346 | F30: Accounting, taxes for the LLC and payroll for the seasonal W-2 employees, including their rehire each season | G30: =IFERROR(IF(B9="","",'0. Assumptions'!$B$41),"") -> 0
A31: Venue management software, CRM, website & phone | B31: 3600 | C31: =IFERROR(IF(C9="","",B31*(1+'0. Assumptions'!$B$48)),"") -> 3600 | D31: =IFERROR(IF(D9="","",C31*(1+'0. Assumptions'!$B$48)),"") -> 3600 | E31: =IFERROR(B31/$B$9,"") -> 0.0058823529 | F31: Venue management software (Tripleseat, Perfect Venue or HoneyBook), booking calendar, proposals, a CRM for couples and companies, website hosting and phone | G31: =IFERROR(IF(B9="","",'0. Assumptions'!$B$41),"") -> 0
A32: Safety training & compliance | B32: 600 | C32: =IFERROR(IF(C9="","",B32*(1+'0. Assumptions'!$B$48)),"") -> 600 | D32: =IFERROR(IF(D9="","",C32*(1+'0. Assumptions'!$B$48)),"") -> 600 | E32: =IFERROR(B32/$B$9,"") -> 0.00098039216 | F32: Safety training for setup, lifting, work at height and grounds work, and the safety programs your state asks of workers' comp policies. Check the requirements with your insurance agent | G32: =IFERROR(IF(B9="","",'0. Assumptions'!$B$41),"") -> 0
A33: Property taxes passed through & local fees | B33: 6000 | C33: =IFERROR(IF(C9="","",B33*(1+'0. Assumptions'!$B$48)),"") -> 6000 | D33: =IFERROR(IF(D9="","",C33*(1+'0. Assumptions'!$B$48)),"") -> 6000 | E33: =IFERROR(B33/$B$9,"") -> 0.0098039216 | F33: Property taxes and other local fees that the owner passes through to you under the lease. Enter those of your county | G33: =IFERROR(IF(B9="","",'0. Assumptions'!$B$41),"") -> 0
A34: Sprinkler, alarm, extinguisher & generator inspections | B34: 2800 | C34: =IFERROR(IF(C9="","",B34*(1+'0. Assumptions'!$B$48)),"") -> 2800 | D34: =IFERROR(IF(D9="","",C34*(1+'0. Assumptions'!$B$48)),"") -> 2800 | E34: =IFERROR(B34/$B$9,"") -> 0.0045751634 | F34: Periodic inspections of the electrical system, extinguishers, sprinkler and alarm system by a licensed contractor, and servicing of the standby generator | G34: =IFERROR(IF(B9="","",'0. Assumptions'!$B$41),"") -> 0
A35: Cleaning supplies, pest control & septic pumping | B35: 4000 | C35: =IFERROR(IF(C9="","",B35*(1+'0. Assumptions'!$B$48)),"") -> 4000 | D35: =IFERROR(IF(D9="","",C35*(1+'0. Assumptions'!$B$48)),"") -> 4000 | E35: =IFERROR(B35/$B$9,"") -> 0.0065359477 | F35: Deep seasonal cleaning, supplies, pest control by a licensed company and septic pumping | G35: =IFERROR(IF(B9="","",'0. Assumptions'!$B$41),"") -> 0
A36: Depreciation of fixed assets | B36: =IFERROR(IF(B9="","",'Startup Costs'!$B$38),"") -> 40990.476 | C36: =IFERROR(IF(C9="","",B36),"") -> 40990.476 | D36: =IFERROR(IF(D9="","",B36),"") -> 40990.476 | E36: =IFERROR(B36/$B$9,"") -> 0.066977902 | F36: Comes from the depreciation bases on the Startup Costs tab: real fixed assets only. It does NOT rise with inflation: it is a charge on the HISTORICAL cost of the assets | G36: 0
A37: Interest expense (loan interest) | B37: =IFERROR(IF(B9="","",Financing!$B$44),"") -> 47000 | C37: =IFERROR(IF(C9="","",Financing!$B$46),"") -> 44050.966 | D37: =IFERROR(IF(D9="","",Financing!$B$48),"") -> 40807.03 | E37: =IFERROR(B37/$B$9,"") -> 0.076797386 | F37: Only INTEREST is an expense. Principal repaid appears on the cash flow tab | G37: 0
A38: TOTAL FIXED COSTS | B38: =IFERROR(IF(B9="","",SUM(B22:B37)),"") -> 437852.48 | C38: =IFERROR(IF(C9="","",SUM(C22:C37)),"") -> 442903.44 | D38: =IFERROR(IF(D9="","",SUM(D22:D37)),"") -> 447659.51 | E38: =IFERROR(B38/$B$9,"") -> 0.71544522
A39: Recoverable input tax on variable costs | B39: =IFERROR(IF(B9="","",SUMPRODUCT(B13:B18,G13:G18)),"") -> 0 | C39: =IFERROR(IF(C9="","",SUMPRODUCT(C13:C18,G13:G18)),"") -> 0 | D39: =IFERROR(IF(D9="","",SUMPRODUCT(D13:D18,G13:G18)),"") -> 0 | F39: Each line at ITS OWN rate, read from the column next to it. It is what the cash flow tab overpays to suppliers and later deducts (zero wherever no tax is recoverable)
A40: Recoverable input tax on fixed costs | B40: =IFERROR(IF(B9="","",SUMPRODUCT(B22:B37,G22:G37)),"") -> 0 | C40: =IFERROR(IF(C9="","",SUMPRODUCT(C22:C37,G22:G37)),"") -> 0 | D40: =IFERROR(IF(D9="","",SUMPRODUCT(D22:D37,G22:G37)),"") -> 0
A41: PRE-TAX INCOME (EBT) | B41: =IFERROR(IF(B9="","",B20-B38),"") -> 72800.324 | C41: =IFERROR(IF(C9="","",C20-C38),"") -> 108601.58 | D41: =IFERROR(IF(D9="","",D20-D38),"") -> 131420.77 | E41: =IFERROR(B41/$B$9,"") -> 0.11895478
...

Sheet Break-Even
A1: BREAK-EVEN
A2: Break-even — wedding & event venue
A4: Variable | B4: Year 1 | C4: Year 2 | D4: Year 3 | E4: Notes
A5: BASE DATA BY YEAR
A6: Annual fixed costs | B6: =IFERROR(IF('3-Year P&L'!$B$9="","",'3-Year P&L'!$B$38),"") -> 437852.48 | C6: =IFERROR(IF('3-Year P&L'!$C$9="","",'3-Year P&L'!$C$38),"") -> 442903.44 | D6: =IFERROR(IF('3-Year P&L'!$D$9="","",'3-Year P&L'!$D$38),"") -> 447659.51 | E6: The SAME fixed costs as the P&L. Each year has its own, which is why the threshold cannot be a single one for all three years
A7: Monthly fixed costs | B7: =IFERROR(IF('3-Year P&L'!$B$9="","",B6/12),"") -> 36487.706 | C7: =IFERROR(IF('3-Year P&L'!$C$9="","",C6/12),"") -> 36908.62 | D7: =IFERROR(IF('3-Year P&L'!$D$9="","",D6/12),"") -> 37304.959
A8: Average revenue per guest excl. sales tax | B8: =IFERROR(IF('3-Year P&L'!$B$9="","",'3-Year P&L'!$B$7),"") -> 68 | C8: =IFERROR(IF('3-Year P&L'!$C$9="","",'3-Year P&L'!$C$7),"") -> 68 | D8: =IFERROR(IF('3-Year P&L'!$D$9="","",'3-Year P&L'!$D$7),"") -> 68
A9: Variable cost per guest | B9: =IFERROR(IF('3-Year P&L'!$B$9="","",'3-Year P&L'!$B$19/('3-Year P&L'!$B$6*'3-Year P&L'!$B$8)),"") -> 11.2608 | C9: =IFERROR(IF('3-Year P&L'!$C$9="","",'3-Year P&L'!$C$19/('3-Year P&L'!$C$6*'3-Year P&L'!$C$8)),"") -> 11.2608 | D9: =IFERROR(IF('3-Year P&L'!$D$9="","",'3-Year P&L'!$D$19/('3-Year P&L'!$D$6*'3-Year P&L'!$D$8)),"") -> 11.2608 | E9: Comes from the P&L total variable costs, not from a separate estimate. It includes miscellaneous and contingency, which is a percentage of sales
A10: Contribution margin per guest | B10: =IFERROR(IF('3-Year P&L'!$B$9="","",B8-B9),"") -> 56.7392 | C10: =IFERROR(IF('3-Year P&L'!$C$9="","",C8-C9),"") -> 56.7392 | D10: =IFERROR(IF('3-Year P&L'!$D$9="","",D8-D9),"") -> 56.7392 | E10: Price per guest minus unit variable cost
A11: Events per year | B11: =IFERROR(IF('3-Year P&L'!$B$9="","",'3-Year P&L'!$B$8),"") -> 100 | C11: =IFERROR(IF('3-Year P&L'!$C$9="","",'3-Year P&L'!$C$8),"") -> 100 | D11: =IFERROR(IF('3-Year P&L'!$D$9="","",'3-Year P&L'!$D$8),"") -> 100 | E11: The same calendar as the P&L and the scenarios
A12: Principal repaid in the year | B12: =IFERROR(IF('3-Year P&L'!$B$9="","",Financing!$B$45),"") -> 29490.336 | C12: =IFERROR(IF('3-Year P&L'!$C$9="","",Financing!$B$47),"") -> 32439.369 | D12: =IFERROR(IF('3-Year P&L'!$D$9="","",Financing!$B$49),"") -> 35683.306 | E12: Principal is NOT a P&L expense, but it leaves the cash account. Without it, the published break-even threshold would sit below the real one
A13: ACCOUNTING BREAK-EVEN (includes depreciation)
A14: Guests needed per year | B14: =IFERROR(IF('3-Year P&L'!$B$9="","",IF(B10<=0,"",B6/B10)),"") -> 7716.9307 | C14: =IFERROR(IF('3-Year P&L'!$C$9="","",IF(C10<=0,"",C6/C10)),"") -> 7805.9515 | D14: =IFERROR(IF('3-Year P&L'!$D$9="","",IF(D10<=0,"",D6/D10)),"") -> 7889.7747
A15: Guests needed per event | B15: =IFERROR(IF('3-Year P&L'!$B$9="","",B14/B11),"") -> 77.169307 | C15: =IFERROR(IF('3-Year P&L'!$C$9="","",C14/C11),"") -> 78.059515 | D15: =IFERROR(IF('3-Year P&L'!$D$9="","",D14/D11),"") -> 78.897747
A16: Revenue needed per year | B16: =IFERROR(IF('3-Year P&L'!$B$9="","",B14*B8),"") -> 524751.29 | C16: =IFERROR(IF('3-Year P&L'!$C$9="","",C14*C8),"") -> 530804.7 | D16: =IFERROR(IF('3-Year P&L'!$D$9="","",D14*D8),"") -> 536504.68
A17: CASH BREAK-EVEN (loan payments in, depreciation out)
A18: Cash fixed costs + principal repaid for the year | B18: =IFERROR(IF('3-Year P&L'!$B$9="","",B6-'3-Year P&L'!$B$36+B12),"") -> 426352.34 | C18: =IFERROR(IF('3-Year P&L'!$C$9="","",C6-'3-Year P&L'!$C$36+C12),"") -> 434352.34 | D18: =IFERROR(IF('3-Year P&L'!$D$9="","",D6-'3-Year P&L'!$D$36+D12),"") -> 442352.34 | E18: The P&L fixed costs without depreciation (which is not paid in cash) and WITH principal repaid (which is). This is the threshold that decides whether cash holds up
A19: Guests needed per year (cash) | B19: =IFERROR(IF('3-Year P&L'!$B$9="","",IF(B10<=0,"",B18/B10)),"") -> 7514.2465 | C19: =IFERROR(IF('3-Year P&L'!$C$9="","",IF(C10<=0,"",C18/C10)),"") -> 7655.2425 | D19: =IFERROR(IF('3-Year P&L'!$D$9="","",IF(D10<=0,"",D18/D10)),"") -> 7796.2385
A20: Guests needed per event (cash) | B20: =IFERROR(IF('3-Year P&L'!$B$9="","",B19/B11),"") -> 75.142465 | C20: =IFERROR(IF('3-Year P&L'!$C$9="","",C19/C11),"") -> 76.552425 | D20: =IFERROR(IF('3-Year P&L'!$D$9="","",D19/D11),"") -> 77.962385
A21: Revenue needed per year (cash) | B21: =IFERROR(IF('3-Year P&L'!$B$9="","",B19*B8),"") -> 510968.76 | C21: =IFERROR(IF('3-Year P&L'!$C$9="","",C19*C8),"") -> 520556.49 | D21: =IFERROR(IF('3-Year P&L'!$D$9="","",D19*D8),"") -> 530144.22
A22: COMPARISON WITH THE PLAN
A23: Guests per event forecast in the plan | B23: =IFERROR(IF('3-Year P&L'!$B$9="","",'3-Year P&L'!$B$6),"") -> 90 | C23: =IFERROR(IF('3-Year P&L'!$C$9="","",'3-Year P&L'!$C$6),"") -> 97.2 | D23: =IFERROR(IF('3-Year P&L'!$D$9="","",'3-Year P&L'!$D$6),"") -> 102.06
A24: Cushion above CASH break-even (%) | B24: =IFERROR(IF('3-Year P&L'!$B$9="","",B23/B20-1),"") -> 0.19772488 | C24: =IFERROR(IF('3-Year P&L'!$C$9="","",C23/C20-1),"") -> 0.2697181 | D24: =IFERROR(IF('3-Year P&L'!$D$9="","",D23/D20-1),"") -> 0.30909284 | E24: How far you can fall before you cannot pay the fixed costs and the loan payment. The required minimum is set in the "0. Assumptions" tab
A25: INTERPRETATION
A26: =IFERROR("With the revenue per guest excl. sales tax above, you need "&TEXT(ROUNDUP(B15,0),"0")&" guests per event over your "&TEXT(B11,"0")&" events a year to avoid losing money (accounting break-even, depreciation included), and "&TEXT(ROUNDUP(B20,0),"0")&" for cash to hold (cash break-even: depreciation out, because it is not paid, and the year's loan payment in"&IF(B12=0,"; no principal is repaid this year (interest-only period or no loan)","")&"). The ""Revenue needed per year"" rows show the same figures in your currency.","") -> With the revenue per guest excl. sales tax above, you need 78 guests per event over your 100 events a year to avoid losing money (accounting break-even, depreciation included), and 76 for cash to hold (cash break-even: depreciation out, because it is not paid, and the year's loan payment in). The "Revenue needed per year" rows show the same figures in your currency.
A28: BREAK-EVEN SENSITIVITY
A29: Guests per event needed to cover costs given the average revenue per guest (columns) and the variable cost per guest (rows). Green cells are below the guests per event the plan forecasts.
A31: Guests per event needed: average revenue per guest excl. sales tax (columns) × variable cost per guest (rows) | B31: =IFERROR($B$8-2,"") -> 66 | C31: =IFERROR(IF($B$8="","",$B$8),"") -> 68 | D31: =IFERROR($B$8+2,"") -> 70 | E31: =IFERROR($B$8+4,"") -> 72
A32: =IFERROR($B$9*0.85,"") -> 9.57168 | B32: =IFERROR(IF($B$31-$A32<=0,"",$B$6/($B$31-$A32)/$B$11),"") -> 77.594455 | C32: =IFERROR(IF($C$31-$A32<=0,"",$B$6/($C$31-$A32)/$B$11),"") -> 74.938399 | D32: =IFERROR(IF($D$31-$A32<=0,"",$B$6/($D$31-$A32)/$B$11),"") -> 72.458158 | E32: =IFERROR(IF($E$31-$A32<=0,"",$B$6/($E$31-$A32)/$B$11),"") -> 70.136835
A33: =IFERROR($B$9*0.925,"") -> 10.41624 | B33: =IFERROR(IF($B$31-$A33<=0,"",$B$6/($B$31-$A33)/$B$11),"") -> 78.773454 | C33: =IFERROR(IF($C$31-$A33<=0,"",$B$6/($C$31-$A33)/$B$11),"") -> 76.037493 | D33: =IFERROR(IF($D$31-$A33<=0,"",$B$6/($D$31-$A33)/$B$11),"") -> 73.485204 | E33: =IFERROR(IF($E$31-$A33<=0,"",$B$6/($E$31-$A33)/$B$11),"") -> 71.098692
A34: =IFERROR($B$9*1.0,"") -> 11.2608 | B34: =IFERROR(IF($B$31-$A34<=0,"",$B$6/($B$31-$A34)/$B$11),"") -> 79.988834 | C34: =IFERROR(IF($C$31-$A34<=0,"",$B$6/($C$31-$A34)/$B$11),"") -> 77.169307 | D34: =IFERROR(IF($D$31-$A34<=0,"",$B$6/($D$31-$A34)/$B$11),"") -> 74.541784 | E34: =IFERROR(IF($E$31-$A34<=0,"",$B$6/($E$31-$A34)/$B$11),"") -> 72.087297
A35: =IFERROR($B$9*1.075,"") -> 12.10536 | B35: =IFERROR(IF($B$31-$A35<=0,"",$B$6/($B$31-$A35)/$B$11),"") -> 81.242305 | C35: =IFERROR(IF($C$31-$A35<=0,"",$B$6/($C$31-$A35)/$B$11),"") -> 78.335324 | D35: =IFERROR(IF($D$31-$A35<=0,"",$B$6/($D$31-$A35)/$B$11),"") -> 75.629191 | E35: =IFERROR(IF($E$31-$A35<=0,"",$B$6/($E$31-$A35)/$B$11),"") -> 73.103783
A36: =IFERROR($B$9*1.15,"") -> 12.94992 | B36: =IFERROR(IF($B$31-$A36<=0,"",$B$6/($B$31-$A36)/$B$11),"") -> 82.535686 | C36: =IFERROR(IF($C$31-$A36<=0,"",$B$6/($C$31-$A36)/$B$11),"") -> 79.537119 | D36: =IFERROR(IF($D$31-$A36<=0,"",$B$6/($D$31-$A36)/$B$11),"") -> 76.748793 | E36: =IFERROR(IF($E$31-$A36<=0,"",$B$6/($E$31-$A36)/$B$11),"") -> 74.149345

Sheet Scenarios
A1: SCENARIOS
A4: Metric | B4: Pessimistic | C4: Base | D4: Optimistic | E4: Notes
A5: Guests per event | B5: 85 | C5: =IFERROR(IF('3-Year P&L'!$B$6="","",'3-Year P&L'!$B$6),"") -> 90 | D5: 95
A6: Average revenue per guest excl. sales tax | B6: 60 | C6: =IFERROR(IF('3-Year P&L'!$B$7="","",'3-Year P&L'!$B$7),"") -> 68 | D6: 72
A7: Events per year | B7: 85 | C7: =IFERROR(IF('3-Year P&L'!$B$8="","",'3-Year P&L'!$B$8),"") -> 100 | D7: 115
A8: ANNUAL REVENUE (excl. sales tax) | B8: =IFERROR(IF(B5*B6*B7=0,"",B5*B6*B7),"") -> 433500 | C8: =IFERROR(IF(C5*C6*C7=0,"",C5*C6*C7),"") -> 612000 | D8: =IFERROR(IF(D5*D6*D7=0,"",D5*D6*D7),"") -> 786600
A9: Direct event costs | B9: =IFERROR(IF(B8="","",B8*'0. Assumptions'!$B$11*'0. Assumptions'!$B$13),"") -> 45777.6 | C9: =IFERROR(IF(C8="","",C8*'0. Assumptions'!$B$11*'0. Assumptions'!$B$13),"") -> 64627.2 | D9: =IFERROR(IF(D8="","",D8*'0. Assumptions'!$B$11*'0. Assumptions'!$B$13),"") -> 83064.96
A10: Cost of the commission (none) | B10: =IFERROR(IF(B8="","",B8*'0. Assumptions'!$B$12*'0. Assumptions'!$B$14),"") -> 0 | C10: =IFERROR(IF(C8="","",C8*'0. Assumptions'!$B$12*'0. Assumptions'!$B$14),"") -> 0 | D10: =IFERROR(IF(D8="","",D8*'0. Assumptions'!$B$12*'0. Assumptions'!$B$14),"") -> 0
A11: Event consumables | B11: =IFERROR(IF(B8="","",B8*'0. Assumptions'!$B$15),"") -> 6502.5 | C11: =IFERROR(IF(C8="","",C8*'0. Assumptions'!$B$15),"") -> 9180 | D11: =IFERROR(IF(D8="","",D8*'0. Assumptions'!$B$15),"") -> 11799
A12: Commissions to planners and venue marketplaces | B12: =IFERROR(IF(B8="","",B8*'0. Assumptions'!$B$16*'0. Assumptions'!$B$17),"") -> 6502.5 | C12: =IFERROR(IF(C8="","",C8*'0. Assumptions'!$B$16*'0. Assumptions'!$B$17),"") -> 9180 | D12: =IFERROR(IF(D8="","",D8*'0. Assumptions'!$B$16*'0. Assumptions'!$B$17),"") -> 11799
A13: Card processing fees | B13: =IFERROR(IF(B8="","",B8*'0. Assumptions'!$B$18),"") -> 8670 | C13: =IFERROR(IF(C8="","",C8*'0. Assumptions'!$B$18),"") -> 12240 | D13: =IFERROR(IF(D8="","",D8*'0. Assumptions'!$B$18),"") -> 15732
A14: Miscellaneous and contingency | B14: =IFERROR(IF(B8="","",B8*'0. Assumptions'!$B$28),"") -> 4335 | C14: =IFERROR(IF(C8="","",C8*'0. Assumptions'!$B$28),"") -> 6120 | D14: =IFERROR(IF(D8="","",D8*'0. Assumptions'!$B$28),"") -> 7866
A15: TOTAL VARIABLE COSTS | B15: =IFERROR(IF(B8="","",SUM(B9:B14)),"") -> 71787.6 | C15: =IFERROR(IF(C8="","",SUM(C9:C14)),"") -> 101347.2 | D15: =IFERROR(IF(D8="","",SUM(D9:D14)),"") -> 130260.96
A16: GROSS MARGIN | B16: =IFERROR(IF(B8="","",B8-B15),"") -> 361712.4 | C16: =IFERROR(IF(C8="","",C8-C15),"") -> 510652.8 | D16: =IFERROR(IF(D8="","",D8-D15),"") -> 656339.04
A17: FIXED COSTS (the P&L's) | B17: =IFERROR(IF(B8="","",'3-Year P&L'!$B$38),"") -> 437852.48 | C17: =IFERROR(IF(C8="","",'3-Year P&L'!$B$38),"") -> 437852.48 | D17: =IFERROR(IF(D8="","",'3-Year P&L'!$B$38),"") -> 437852.48 | E17: Fixed costs do not change with the scenario: that is why they are fixed
A18: PRE-TAX INCOME (EBT) | B18: =IFERROR(IF(B8="","",B16-B17),"") -> -76140.076 | C18: =IFERROR(IF(C8="","",C16-C17),"") -> 72800.324 | D18: =IFERROR(IF(D8="","",D16-D17),"") -> 218486.56
A19: Income tax | B19: =IFERROR(IF(B8="","",MAX(0,B18-'0. Assumptions'!$B$42)*'0. Assumptions'!$B$37),"") -> 0 | C19: =IFERROR(IF(C8="","",MAX(0,C18-'0. Assumptions'!$B$42)*'0. Assumptions'!$B$37),"") -> 18200.081 | D19: =IFERROR(IF(D8="","",MAX(0,D18-'0. Assumptions'!$B$42)*'0. Assumptions'!$B$37),"") -> 54621.641 | E19: At the "years 1-2" effective income tax rate, offsetting prior net operating losses
A20: NET INCOME | B20: =IFERROR(IF(B8="","",B18-B19),"") -> -76140.076 | C20: =IFERROR(IF(C8="","",C18-C19),"") -> 54600.243 | D20: =IFERROR(IF(D8="","",D18-D19),"") -> 163864.92
A21: Guests per event for break-even | B21: =IFERROR(IF(B8="","",IF(B6-B15/(B5*B7)<=0,"",B17/(B6-B15/(B5*B7))/B7)),"") -> 102.89241 | C21: =IFERROR(IF(C8="","",IF(C6-C15/(C5*C7)<=0,"",C17/(C6-C15/(C5*C7))/C7)),"") -> 77.169307 | D21: =IFERROR(IF(D8="","",IF(D6-D15/(D5*D7)<=0,"",D17/(D6-D15/(D5*D7))/D7)),"") -> 63.37576
A22: WHAT EACH SCENARIO DEMANDS
A23: Labor cost / Sales | B23: =IFERROR(IF(B8="","",'3-Year P&L'!$B$23/B8),"") -> 0.44258824 | C23: =IFERROR(IF(C8="","",'3-Year P&L'!$B$23/C8),"") -> 0.3135 | D23: =IFERROR(IF(D8="","",'3-Year P&L'!$B$23/D8),"") -> 0.24391304 | E23: The SAME staffing in all three scenarios. If labor cost blows up in the pessimistic case, adjust it in the Staffing tab, not here
A24: Guests per year per full-time equivalent | B24: =IFERROR(IF(B8="","",B5*B7/Staffing!$C$11),"") -> 1952.7027 | C24: =IFERROR(IF(C8="","",C5*C7/Staffing!$C$11),"") -> 2432.4324 | D24: =IFERROR(IF(D8="","",D5*D7/Staffing!$C$11),"") -> 2952.7027 | E24: Guests each full-time position on the "Staffing" tab would have to host per year. In the optimistic scenario it tells you whether you need to hire
A25: Year-1 closing cash balance (estimate, same method in all three scenarios) | B25: =IFERROR(IF(B8="","",'Startup Costs'!$B$30+B20+'3-Year P&L'!$B$36-Financing!$B$45),"") -> 34575.564 | C25: =IFERROR(IF(C8="","",'Startup Costs'!$B$30+C20+'3-Year P&L'!$B$36-Financing!$B$45),"") -> 165315.88 | D25: =IFERROR(IF(D8="","",'Startup Costs'!$B$30+D20+'3-Year P&L'!$B$36-Financing!$B$45),"") -> 274580.56 | E25: ESTIMATED balance: working capital plus the year's result, adding back depreciation (which is not paid) and subtracting loan principal. It does not include the timing gap between receipts and payments or the sales tax settlement, so the three columns can be compared with each other. In red, the scenario runs out of cash
A26: Actual month-12 balance from the 12-Month Cash Flow tab (Base case only) | C26: =IFERROR(IF(C8="","",'12-Month Cash Flow'!$M$22),"") -> 180685.09 | E26: The ACTUAL base-case balance, with its timing of receipts and payments and its sales tax settlement. It exists only for the Base scenario, the only one with its own monthly cash flow: that is why it is not in the row above, where it would be compared against two estimates
A28: The "Base case" column reads its three inputs from the "0. Assumptions" tab, so it reproduces EXACTLY year 1 of the P&L. The other two scenarios use the same cost rates: the only things that change are guests per event, revenue per guest and events. FIXED COSTS are the same in all three: miscellaneous and contingency, which is a percentage of sales, sits at the top with the variable costs and each scenario carries its own.

Sheet Staffing
A1: STAFFING AND LABOR COSTS
A2: =IFERROR("Payroll — "&TEXT('0. Assumptions'!$B$21,"0")&" pay periods + employer taxes "&TEXT('0. Assumptions'!$B$20*100,"0")&"%","") -> Payroll — 12 pay periods + employer taxes 10%
A4: Position | B4: People | C4: FTE | D4: Gross pay per month (total for the position) | E4: Employer payroll taxes (total for the position) | F4: Cost per month (total for the position) | G4: Cost per year | H4: Hours per week per person | I4: Hours per year for the position | J4: Notes
A5: Owner — GM, sales & tours | B5: 1 | C5: 1 | D5: 4500 | E5: =IFERROR(IF(D5="","",D5*'0. Assumptions'!$B$20),"") -> 450 | F5: =IFERROR(IF(D5="","",D5+E5),"") -> 4950 | G5: =IFERROR(IF(D5="","",F5*MAX(12,'0. Assumptions'!$B$21)),"") -> 59400 | H5: =IFERROR(IF(D5="","",C5*$B$18),"") -> 40 | I5: =IFERROR(IF(D5="","",H5*B5*$B$19),"") -> 1840 | J5: Sells, gives tours, signs contracts, runs the calendar and coordinates the caterer. The workbook imputes a monthly salary as if on payroll, which is the prudent side. The example pays the owner $4,500 a month, below the national median pay for event planners (BLS): draw the rest from profit. How the owner of an LLC is paid depends on the tax election: ask your CPA
A6: Venue coordinator (seasonal, Mar-Nov) | B6: 1 | C6: 0.75 | D6: 3380 | E6: =IFERROR(IF(D6="","",D6*'0. Assumptions'!$B$20),"") -> 338 | F6: =IFERROR(IF(D6="","",D6+E6),"") -> 3718 | G6: =IFERROR(IF(D6="","",F6*MAX(12,'0. Assumptions'!$B$21)),"") -> 44616 | H6: =IFERROR(IF(D6="","",C6*$B$18),"") -> 30 | I6: =IFERROR(IF(D6="","",H6*B6*$B$19),"") -> 1380 | J6: Seasonal W-2 employee, full time from March to November, which equals about 75% over the year. Prepares each event with the couple and the caterer and runs it on the day. From December to February (holiday parties and winter events) the owner coordinates. The example budgets about $3,380 a month for this position
A7: Facilities & grounds | B7: 1 | C7: 0.8 | D7: 3050 | E7: =IFERROR(IF(D7="","",D7*'0. Assumptions'!$B$20),"") -> 305 | F7: =IFERROR(IF(D7="","",D7+E7),"") -> 3355 | G7: =IFERROR(IF(D7="","",F7*MAX(12,'0. Assumptions'!$B$21)),"") -> 40260 | H7: =IFERROR(IF(D7="","",C7*$B$18),"") -> 32 | I7: =IFERROR(IF(D7="","",H7*B7*$B$19),"") -> 1472 | J7: Grounds, irrigation, driveways, small repairs, the standby generator and getting the hall and the tent ready. At 80% of a full-time schedule; the big jobs (tree trimming, painting) go in fixed costs. The example budgets about $3,050 a month for this position
A8: Event attendants: setup, parking & restrooms (seasonal, part-time W-2) | B8: 2 | C8: 0.35 | D8: 2062 | E8: =IFERROR(IF(D8="","",D8*'0. Assumptions'!$B$20),"") -> 206.2 | F8: =IFERROR(IF(D8="","",D8+E8),"") -> 2268.2 | G8: =IFERROR(IF(D8="","",F8*MAX(12,'0. Assumptions'!$B$21)),"") -> 27218.4 | H8: =IFERROR(IF(D8="","",C8*$B$18),"") -> 14 | I8: =IFERROR(IF(D8="","",H8*B8*$B$19),"") -> 1288 | J8: Two seasonal part-time W-2 attendants at about 35% of a full-time schedule each: setup, guest access and parking, restroom restocking and load-out. Two at each wedding and one at the rest. Never as 1099 contractors who invoice you: with your schedule and your direction they are employees. The plan budgets at least $17/h
A9: Weekend sales & tours (part-time) | B9: 1 | C9: 0.2 | D9: 763 | E9: =IFERROR(IF(D9="","",D9*'0. Assumptions'!$B$20),"") -> 76.3 | F9: =IFERROR(IF(D9="","",D9+E9),"") -> 839.3 | G9: =IFERROR(IF(D9="","",F9*MAX(12,'0. Assumptions'!$B$21)),"") -> 10071.6 | H9: =IFERROR(IF(D9="","",C9*$B$18),"") -> 8 | I9: =IFERROR(IF(D9="","",H9*B9*$B$19),"") -> 368 | J9: At 20% of a full-time schedule: Saturday morning tours, bridal shows and follow-up of the leads from your storefront listings. The example budgets about $763 a month for this position
A10: Housekeeping & turnover (part-time) | B10: 1 | C10: 0.25 | D10: 780 | E10: =IFERROR(IF(D10="","",D10*'0. Assumptions'!$B$20),"") -> 78 | F10: =IFERROR(IF(D10="","",D10+E10),"") -> 858 | G10: =IFERROR(IF(D10="","",F10*MAX(12,'0. Assumptions'!$B$21)),"") -> 10296 | H10: =IFERROR(IF(D10="","",C10*$B$18),"") -> 10 | I10: =IFERROR(IF(D10="","",H10*B10*$B$19),"") -> 460 | J10: At 25% of a full-time schedule: turnover cleaning of the hall, restrooms and caterer's kitchen between events. The deep clean after each wedding is in the direct event cost. The example budgets about $780 a month for this position
A11: TOTAL STAFF | B11: =IFERROR(IF(COUNT(D5:D10)=0,"",SUM(B5:B10)),"") -> 7 | C11: =IFERROR(IF(COUNT(D5:D10)=0,"",SUMPRODUCT(B5:B10,C5:C10)),"") -> 3.7 | D11: =IFERROR(IF(COUNT(D5:D10)=0,"",SUM(D5:D10)),"") -> 14535 | E11: =IFERROR(IF(COUNT(D5:D10)=0,"",SUM(E5:E10)),"") -> 1453.5 | F11: =IFERROR(IF(COUNT(D5:D10)=0,"",SUM(F5:F10)),"") -> 15988.5 | G11: =IFERROR(IF(COUNT(D5:D10)=0,"",SUM(G5:G10)),"") -> 191862 | I11: =IFERROR(IF(COUNT(D5:D10)=0,"",SUM(I5:I10)),"") -> 6808
A12: STAFF GROWTH (stepped cost)
A13: Annual cost of year-2 hires | B13: 8000 | J13: FULL ANNUAL cost (gross pay + employer payroll taxes, over all pay periods) of whoever you hire that year. The P&L adds it to the previous year's cost: staffing grows by people, not by a percentage
A14: Annual cost of year-3 hires | B14: 8000 | J14: FULL ANNUAL cost (gross pay + employer payroll taxes, over all pay periods) of whoever you hire that year. The P&L adds it to the previous year's cost: staffing grows by people, not by a percentage
A15: Labor cost, year 2 | B15: =IFERROR(IF(G11="","",G11*(1+'0. Assumptions'!$B$48)+B13),"") -> 199862
A16: Labor cost, year 3 | B16: =IFERROR(IF(B15="","",B15*(1+'0. Assumptions'!$B$48)+B14),"") -> 207862
A17: COVERAGE OF SERVICE HOURS
A18: Full-time week (hours per week) | B18: 40 | J18: 40 hours a week is the FLSA overtime threshold for non-exempt employees; some states add daily overtime rules. Change it if your own full-time week is different
A19: Weeks worked per year per person | B19: 46 | J19: 46 weeks: 52 minus about six weeks for vacation, holidays, the January closure and average absences. There is no federal vacation requirement in the US: adjust it to your own policy
A20: Work hours per event to cover | B20: 9.2 | J20: Average event day, from setup to load-out: wedding 13 hours, corporate 9, private celebration 8 and micro wedding 5 (9.7 hours on average with the plan's mix)
A21: People needed at the same time at each event | B21: 2.3 | J21: Venue staff on site at the same time during the event: the venue coordinator and two event attendants at weddings, the coordinator and one attendant at the rest (about 2.4 on average with the plan's mix). Servers and bartenders belong to the caterer
A22: Overhead hours per event, outside the event day | B22: 12 | J22: Hours per event outside the event day: tours and meetings with couples, planning with the caterer, maintenance, grounds, cleaning and admin. This is the part of the team that works all year, spread across the events
A23: Overhead staff per event | B23: 3 | J23: Manager, maintenance and support (sales or housekeeping) at the same time
A24: Service hours to cover per year | B24: =IFERROR(IF(OR(B20="",B21="",'0. Assumptions'!$B$6=""),"",B20*B21*'0. Assumptions'!$B$6+B22*B23*'0. Assumptions'!$B$6),"") -> 5716
A25: Hours hired per year | B25: =IFERROR(IF(I11="","",I11),"") -> 6808
A26: Coverage (hired / needed) | B26: =IFERROR(B25/B24,"") -> 1.1910427 | J26: Below 100% the staff cannot cover the hours the plan declares: either hire more or cut the hours
A28: The gross pay, employer payroll taxes, monthly cost and annual cost columns are TOTALS for the row: for a position with two people they include both. "FTE" is the share of a full-time week and is used to compare pay with the legal floor pro rata. The payroll tax rate and the number of pay periods are in the "0. Assumptions" tab.
A29: The wage floor is the HIGHER of the federal minimum wage and the state or local floor you type in "0. Assumptions"; part-time positions carry it pro rata. Seasonal staff are W-2 employees: never pay as 1099 contractors the people whose schedule and work the venue directs. Event servers and bartenders belong to the caterer, not to this payroll.

Sheet Instructions
A1: HOW TO USE THIS WORKBOOK — Wedding Venue Financial Projections
A3: HOW TO USE THIS WORKBOOK
