Workbook

Sheet 0. Assumptions
A1: ASSUMPTIONS — the RATES and DRIVERS of the model are typed here
A2: Change the GREEN cells: the rest of the workbook recalculates on its own. Expense items are typed on their own tab (also in green) and are not repeated here. Amounts are in your currency.
A3: BUSINESS ACTIVITY
A4: Transactions per day (average for year 1) | B4: 210 | C4: Transactions served per day on average over the year (bread, pastries and coffee at the counter, plus what the wholesale channel picks up). It is a driver, not a figure backed out of a revenue target, and it should sit between the pessimistic and optimistic scenarios published on the "Scenarios" tab. With fewer transactions, net income falls below the 5% floor this workbook sets, because fixed costs (labor, rent, insurance) do not grow with volume and each extra transaction goes almost entirely to the bottom line. WATCH OUT: the base case is demanding on both sides at once, volume and average check; if either one comes in lower in your area, net income drops below that floor. Compare it with your location before you trust it
A5: Average check (excl. sales tax) | B5: 10 | C5: EXCL. SALES TAX. It sits in the upper part of the range that the industry benchmarks table on the "Instructions" tab gives for a bakery average check (kit estimate), because it combines pastries and coffee with the bread, not just the loaf. Check it against your own menu: if your real average check is lower, lower it here and see what happens to net income
A6: Operating days per year | B6: 310 | C6: The SAME number feeds the "3-Year P&L", the "Break-Even" tab and the "Scenarios" tab, so all three always work on the same operating calendar
A7: Volume growth in year 2 | B7: 0.12 | C7: Second year, with the wholesale channel (cafés and restaurants) already established and no launch spending. Kept moderate on purpose
A8: Volume growth in year 3 | B8: 0.07 | C8: Third year, close to the production ceiling of the oven you installed
A9: Menu price incl. sales tax (calculated) | B9: =IFERROR(IF($B$5="","",$B$5*(1+SUMPRODUCT('3-Year P&L'!$E$10:$E$11,'3-Year P&L'!$G$10:$G$11))),"") -> 10.256 | C9: =IFERROR("Average check excl. sales tax plus the weighted sales tax of your sales lines ("&TEXT(SUMPRODUCT('3-Year P&L'!$E$10:$E$11,'3-Year P&L'!$G$10:$G$11)*100,"0")&"%), rounded: the tax-exempt share of the bakery line (column H of ""3-Year P&L"") lowers it. In the US, prices usually exclude sales tax and it is added at the register; in the UK, prices include VAT.","") -> Average check excl. sales tax plus the weighted sales tax of your sales lines (3%), rounded: the tax-exempt share of the bakery line (column H of "3-Year P&L") lowers it. In the US, prices usually exclude sales tax and it is added at the register; in the UK, prices include VAT.
A10: SALES MIX AND COST OF GOODS SOLD
A11: FOOD share of total sales | B11: 0.85 | C11: Share of FOOD in total sales. It is an INPUT: change it here and the P&L, the cash flow and the sales tax collected recalculate on their own
A12: BEVERAGE share of total sales | B12: =IFERROR(IF(COUNT(B11)=0,"",1-B11),"") -> 0.15 | C12: Calculated as the remainder: food + beverage = 100%
A13: Cost of goods sold on FOOD sales | B13: 0.3 | C13: Cost of goods sold on bread and pastries, weighted with the ranges in the industry benchmarks table on the "Instructions" tab. Bread (25-30%) weighs more in the mix than pastries (32-38%), so the blend sits close to the low end of the pastry range
A14: Cost of goods sold on BEVERAGE sales | B14: 0.22 | C14: Cost of coffee and beverages against their own sales: inside the 20-30% that the industry benchmarks table on the "Instructions" tab gives for coffee (kit estimate)
A15: Disposables and packaging as % of sales | B15: 0.03 | C15: Paper bags, pastry boxes and counter napkins
A16: Delivery share of total sales | B16: 0 | C16: ZERO by default: fresh-baked bread does not travel well and this plan does not deliver on day one. Raise it if you turn on a delivery channel for pastries or breakfast orders
A17: Delivery platform fee | B17: 0.25 | C17: Typical DoorDash / Uber Eats commission on orders served through that channel, if you ever turn it on
A18: Card processing fee | B18: 0.035 | C18: Card and mobile wallet fees on total sales in the shop (the example, 3.5%, is a kit estimate: enter your effective rate)
A19: LABOR
A20: Employer payroll taxes | B20: 0.1 | C20: FICA (Social Security 6.2% + Medicare 1.45%) + federal and state unemployment taxes (FUTA / SUTA) + workers' comp. About 10% in total: adjust it to your state and your insurance carrier
A21: Monthly pay periods per year (keep 12) | B21: 12 | C21: Annual gross pay = monthly gross pay × this number. Keep 12 in the US: it counts the monthly salaries the model pays in a year, not how often you run payroll (weekly or biweekly payroll pays the same annual amount)
A22: Federal minimum wage, annual full-time | B22: 15080 | C22: US federal minimum wage: 7.25 per hour × 2,080 hours = 15,080 per year for a full-time job. Your state or city may set a higher floor: enter it in the state / local minimum wage cell below. Check the current rates at dol.gov
A23: RENT AND FIXED COSTS
A24: Monthly rent | B24: 4200 | C24: Space for a bakery with a production area and a storefront (see Phase 2 of the checklist: plan for about 860 sq ft or more for production, storefront and storage; the example is about 1,800 sq ft). Include NNN / CAM charges (property tax, building insurance, common-area maintenance) in this cell, not just the base rent. The workbook calculates the weight on sales in the "Rent / Sales" row of the ratios block on the "3-Year P&L": in the base case it stays BELOW the 10% ceiling set in the industry benchmarks table on the "Instructions" tab
A25: Security deposit (months of rent) | B25: 2 | C25: Months of rent held as a security deposit. It is set in your commercial lease, so check the terms before you sign
A26: Monthly utilities (electricity, water, gas) | B26: 1500 | C26: Electricity, water and gas: ovens need a heavy electrical load, so ask your utility about three-phase service (see Phase 2 of the checklist). Ask for the space's utility history before you sign
A27: Insurance (per year) | B27: 4500 | C27: General liability (landlords and events often require 1 million per occurrence) plus property coverage or a business owner's policy (BOP) for a space with ovens (fire risk from the ovens, see Phase 2 of the checklist)
A28: Miscellaneous and contingency as % of sales | B28: 0.02 | C28: Cushion for operating expenses that are not budgeted
A29: FINANCING
A30: Owner's equity contributed | B30: 70000 | C30: Owners' contribution. With too little, lenders pass: they usually expect an owner equity injection (often around 10% for SBA start-ups; many want 20-30%) measured against the cash need calculated on the "Startup Costs" tab
A31: Loan requested | B31: 197000 | C31: Principal requested — bank or SBA 7(a): if your loan is an SBA 7(a), this is the cell. It is the only loan that the amortization schedule, the P&L interest and the DSCR use. The "Financing" tab checks that sources and uses match the cash need calculated on the "Startup Costs" tab, and has a cell that calculates the exact amount that balances them
A32: Nominal annual interest rate (not APR) | B32: 0.1 | C32: Nominal annual rate, not APR; get offers from two lenders, including an SBA-guaranteed loan, before you fix it
A33: Loan term (years) | B33: 10 | C33: Total years, interest-only period included
A34: Interest-only period (years) | B34: 0 | C34: Years in which you pay only interest. ZERO by default: repayment starts in year 1, so the year-1 DSCR already measures the full loan payment. If you negotiate an interest-only period, the principal repayment hits all at once when it ends: the "Break-Even" tab measures that cushion year by year
A35: Working capital (months of fixed costs) | B35: 3 | C35: The minimum this workbook requires (see "Instructions"): a cushion of less than 3 months will not cover a slow season
A36: TAXES
A37: Effective income tax rate (years 1-2) | B37: 0.25 | C37: Example: 21% federal rate for a C corporation plus state tax, rounded to 25%. If you operate as a sole proprietorship, LLC taxed as a pass-through or S corporation, the business itself pays 0% here and you pay tax on the profit personally: set this to 0 and budget for your personal tax separately. The model applies this rate to the first two years with positive taxable income
A38: Effective income tax rate (from year 3) | B38: 0.25 | C38: From the third year with positive taxable income. Same example rate (21% federal C corporation + state). Confirm the rate that applies to you with your accountant and change it here
A39: Sales tax rate on sales | B39: 0.08 | C39: Example rate: state + local sales tax combined. It varies widely by state and city: look up yours. UK: 20% VAT on hot food and dine-in
A40: Sales tax rate on alcohol to go | B40: 0.08 | C40: Sales tax rate on alcohol sold to go or delivered. In this workbook it applies only to the ALCOHOLIC part of beverage sales that leaves through the delivery channel, and this bakery sells no alcohol by default, so it does not affect the result. Some states add a separate liquor tax: check yours
...

Sheet Startup Costs
A1: BUSINESS PLAN: BAKERY
A2: Startup Costs — US example (2026)
A3: Adjust the figures to your project.
A5: Item | B5: Amount | C5: % of startup costs | D5: Notes | E5: Taxable / recoverable tax?
A6: STARTUP COSTS | B6: =IFERROR(IF(COUNT(B7:B28)=0,"",SUM(B7:B28)),"") -> 182500 | C6: =IFERROR(B6/$B$31,"") -> 0.68426637
A7: LLC formation and legal | B7: 1500 | C7: =IFERROR(B7/$B$31,"") -> 0.0056241072 | D7: Single-member LLC: filing fee and attorney review (fees vary by state) | E7: No
A8: Licenses and health plan review | B8: 2500 | C8: =IFERROR(B8/$B$31,"") -> 0.009373512 | D8: A bakery with ovens needs a certificate of occupancy and a health department plan review | E8: No
A9: Architect and permit drawings | B9: 6000 | C9: =IFERROR(B9/$B$31,"") -> 0.022496429 | D9: Required: oven ventilation and electrical load drawings | E9: Yes
A10: Build-out | B10: 35000 | C10: =IFERROR(B10/$B$31,"") -> 0.13122917 | D10: Technical flooring, washable wall finishes, production area | E10: Yes
A11: Electrical service upgrade for the ovens | B11: 10000 | C11: =IFERROR(B11/$B$31,"") -> 0.037494048 | D11: Three-phase service, check with your utility | E11: Yes
A12: Oven ventilation and exhaust | B12: 10000 | C12: =IFERROR(B12/$B$31,"") -> 0.037494048 | D12: Required: hood, exhaust fan and filters; ask the city whether a ventilation permit applies | E12: Yes
A13: Deck / rack oven | B13: 25000 | C13: =IFERROR(B13/$B$31,"") -> 0.09373512 | D13: Deck oven (artisan) or rack oven (volume) | E13: Yes
A14: Spiral mixer (55-110 lb) | B14: 9000 | C14: =IFERROR(B14/$B$31,"") -> 0.033744643 | D14: Capacity based on daily production | E14: Yes
A15: Divider-rounder | B15: 7000 | C15: =IFERROR(B15/$B$31,"") -> 0.026245833 | D15: For batch production of uniform pieces | E15: Yes
A16: Proofer / retarder | B16: 10000 | C16: =IFERROR(B16/$B$31,"") -> 0.037494048 | D16: Programmable slow fermentation: key to quality | E16: Yes
A17: Walk-in cooler and freezer | B17: 9000 | C17: =IFERROR(B17/$B$31,"") -> 0.033744643 | D17: Storage for raw ingredients and frozen dough | E17: Yes
A18: Stainless tables and shelving | B18: 5000 | C18: =IFERROR(B18/$B$31,"") -> 0.018747024 | D18: Production work surface | E18: Yes
... A25: Opening ingredients inventory (flour, yeast, etc.) | B25: 3000 | C25: =IFERROR(B25/$B$31,"") -> 0.011248214 | D25: Bread flour, rye, sourdough starter, yeast | E25: Yes
A26: Security deposit | B26: =IFERROR(IF('0. Assumptions'!$B$24="","",'0. Assumptions'!$B$24*'0. Assumptions'!$B$25),"") -> 8400 | C26: =IFERROR(B26/$B$31,"") -> 0.031495 | D26: =IFERROR(""&TEXT('0. Assumptions'!$B$25,"0")&IF('0. Assumptions'!$B$25=1," month"," months")&" of rent, from ""0. Assumptions"". Refundable when the lease ends: it is not depreciated and carries no tax","") -> 2 months of rent, from "0. Assumptions". Refundable when the lease ends: it is not depreciated and carries no tax | E26: No
A27: Rent paid before opening | B27: =IFERROR(IF('0. Assumptions'!$B$24="","",'0. Assumptions'!$B$24*'0. Assumptions'!$B$54),"") -> 4200 | C27: =IFERROR(B27/$B$31,"") -> 0.0157475 | D27: =IFERROR("Rent "&IF('0. Assumptions'!$B$54=1,"for the month","for the "&TEXT('0. Assumptions'!$B$54,"0")&" months")&" of build-out and permits before opening. It does not overlap the P&L, which starts on opening day: its twelve months are twelve trading months","") -> Rent for the month of build-out and permits before opening. It does not overlap the P&L, which starts on opening day: its twelve months are twelve trading months | E27: Yes
A28: Build-out and setup contingency | B28: =IFERROR(IF(COUNT(B9,B10,B11,B12,B23)=0,"",ROUND((B9+B10+B11+B12+B23)*'0. Assumptions'!$B$55,0)),"") -> 6400 | C28: =IFERROR(B28/$B$31,"") -> 0.023996191 | D28: =IFERROR("At "&TEXT('0. Assumptions'!$B$55,"0%")&" of the BUILD-OUT items of this block (architect and building permits, construction, electrical service upgrade for the ovens, oven ventilation and exhaust, signage), not of the whole block: the other items are left out. No lender funds a "&"build-out without a cushion: the percentage is in ""0. Assumptions""","") -> At 10% of the BUILD-OUT items of this block (architect and building permits, construction, electrical service upgrade for the ovens, oven ventilation and exhaust, signage), not of the whole block: the other items are left out. No lender funds a build-out without a cushion: the percentage is in "0. Assumptions" | E28: Yes
A29: WORKING CAPITAL | B29: =IFERROR(IF(B30="","",B30),"") -> 84209 | C29: =IFERROR(B29/$B$31,"") -> 0.31573363
A30: Operating cushion until break-even | B30: =IFERROR(IF('0. Assumptions'!$B$35*('3-Year P&L'!$B$38-'3-Year P&L'!$B$36)=0,"",'0. Assumptions'!$B$35*('3-Year P&L'!$B$38-'3-Year P&L'!$B$36)/12),"") -> 84209 | C30: =IFERROR(B30/$B$31,"") -> 0.31573363 | D30: =IFERROR("Covers "&TEXT('0. Assumptions'!$B$35,"0")&IF('0. Assumptions'!$B$35=1," month"," months")&" of year-1 CASH fixed costs (the P&L fixed costs minus depreciation, which is not paid out), the minimum the Instructions of this workbook ask for","") -> Covers 3 months of year-1 CASH fixed costs (the P&L fixed costs minus depreciation, which is not paid out), the minimum the Instructions of this workbook ask for | E30: No
A31: TOTAL STARTUP COSTS (sum of the blocks) | B31: =IFERROR(B6+B29,"") -> 266709 | D31: =IFERROR("The percentages in column C are read on this figure, which includes the working capital ("&TEXT(C29,"0%")&" of the total). To compare the breakdown with another plan, use the CAPEX row below.","") -> The percentages in column C are read on this figure, which includes the working capital (32% of the total). To compare the breakdown with another plan, use the CAPEX row below.
A32: CAPEX (startup costs excluding working capital) | B32: =IFERROR(B31-B29,"") -> 182500 | D32: What you buy: build-out, equipment, launch and formation costs. The cash cushion is not an investment: it is working capital
A33: Recoverable input tax on capex | B33: =IFERROR(IF(B31="","",SUMIF($E$7:$E$28,"Yes",$B$7:$B$28)*'0. Assumptions'!$B$41),"") -> 0 | D33: =IFERROR("At "&TEXT('0. Assumptions'!$B$41,"0%")&" on the items marked ""Yes"" in the tax column. US: the sales tax you pay on equipment is part of its cost and is not recovered, so this rate is 0. UK (VAT-registered): 20%, reclaimed on your VAT return, but you pay it first, so the loan has to cover it","") -> At 0% on the items marked "Yes" in the tax column. US: the sales tax you pay on equipment is part of its cost and is not recovered, so this rate is 0. UK (VAT-registered): 20%, reclaimed on your VAT return, but you pay it first, so the loan has to cover it
A34: TOTAL CASH NEEDED AT LAUNCH | B34: =IFERROR(B31+B33,"") -> 266709 | D34: This is the figure the Financing tab has to cover
A35: DEPRECIATION BASES (not added to startup costs)
A36: Build-out, fixtures and setup | B36: =IFERROR(IF(B9="","",B9+B10+B11+B12+B23+B28),"") -> 70400 | D36: =IFERROR("Depreciated over "&TEXT('0. Assumptions'!$B$44,"0")&" years","") -> Depreciated over 10 years
A37: Machinery, furniture and equipment | B37: =IFERROR(IF(B13="","",B13+B14+B15+B16+B17+B18+B19+B20+B21+B22),"") -> 88500 | D37: =IFERROR("Depreciated over "&TEXT('0. Assumptions'!$B$45,"0")&" years","") -> Depreciated over 7 years
A38: Annual depreciation of fixed assets | B38: =IFERROR(B36/MAX(1,'0. Assumptions'!$B$44)+B37/MAX(1,'0. Assumptions'!$B$45),"") -> 19682.857 | D38: =IFERROR("Not depreciated, because they are not fixed assets: entity formation and legal, licenses and health plan review, launch marketing, opening inventory, security deposit, pre-opening rent and the working capital reserve. They add up to "&TEXT(B31-B36-B37,"#,##0")&" of the "&TEXT(B31,"#,##0")&" total investment.","") -> Not depreciated, because they are not fixed assets: entity formation and legal, licenses and health plan review, launch marketing, opening inventory, security deposit, pre-opening rent and the working capital reserve. They add up to 107809 of the 266709 total investment.

Sheet 3-Year P&L
A1: PROFIT AND LOSS STATEMENT — 3 YEARS
A2: Base scenario — Bakery with storefront, café corner and wholesale
A4: Item | B4: Year 1 | C4: Year 2 | D4: Year 3 | E4: % of sales (year 1) | F4: Notes | G4: Sales tax rate on the line (%) | H4: Tax-exempt share of the line (%)
A5: REVENUE
A6: Transactions per day (average) | B6: =IFERROR(IF('0. Assumptions'!$B$4="","",'0. Assumptions'!$B$4),"") -> 210 | C6: =IFERROR(B6*(1+'0. Assumptions'!$B$7),"") -> 235.2 | D6: =IFERROR(C6*(1+'0. Assumptions'!$B$8),"") -> 251.664 | F6: Growth for years 2 and 3 is set in "0. Assumptions"
A7: Average check (excl. sales tax) | B7: =IFERROR(IF('0. Assumptions'!$B$5="","",'0. Assumptions'!$B$5),"") -> 10 | C7: =IFERROR(IF(B7="","",B7),"") -> 10 | D7: =IFERROR(IF(C7="","",C7),"") -> 10 | F7: Held constant at year-1 prices: a price increase is a separate decision
A8: Operating days per year | B8: =IFERROR(IF('0. Assumptions'!$B$6="","",'0. Assumptions'!$B$6),"") -> 310 | C8: =IFERROR(IF(B8="","",B8),"") -> 310 | D8: =IFERROR(IF(C8="","",C8),"") -> 310
A9: TOTAL REVENUE (excl. sales tax) | B9: =IFERROR(IF(B6*B7*B8=0,"",B6*B7*B8),"") -> 651000 | C9: =IFERROR(IF(C6*C7*C8=0,"",C6*C7*C8),"") -> 729120 | D9: =IFERROR(IF(D6*D7*D8=0,"",D6*D7*D8),"") -> 780158.4 | E9: =IFERROR(IF(B9="","",1),"") -> 1
A10: Bakery sales: bread, pastries and wholesale to cafés | B10: =IFERROR(IF(B9="","",B9*$E$10),"") -> 553350 | C10: =IFERROR(IF(C9="","",C9*$E$10),"") -> 619752 | D10: =IFERROR(IF(D9="","",D9*$E$10),"") -> 663134.64 | E10: =IFERROR(IF('0. Assumptions'!$B$11="","",'0. Assumptions'!$B$11),"") -> 0.85 | F10: Artisan bread and pastries from the shop, plus the wholesale channel to cafés and restaurants (the bread you sell to another business is the same product line as the bread you sell at the counter; only the channel changes). NOTE: the model projects sales with ONE engine — transactions × average check × days — so a delivery to another business enters here as one more transaction, not as a big order. What the workbook does capture is its effect on cash, through the average collection days on "0. Assumptions". If wholesale weighs heavily in your project, model it separately · The percentage on the right ("Tax-exempt share of the line (%)") is the part of this line that carries no sales tax: bakery goods to go, plus wholesale sales to a café that resells them (with a resale certificate on file). The example is 0.80. Many states exempt bakery goods sold to go and tax what is eaten in the shop, but the rules vary by state: check yours. At 0 the workbook taxes the whole line. In the UK, cold bakery goods to go are zero-rated and on-site consumption carries 20% VAT. It only affects cash flow: the P&L is excl. sales tax | G10: =IFERROR(IF(B9="","",H10*0+(1-H10)*'0. Assumptions'!$B$39),"") -> 0.016 | H10: 0.8
A11: Coffee and beverage sales (no alcohol) | B11: =IFERROR(IF(B9="","",B9*$E$11),"") -> 97650 | C11: =IFERROR(IF(C9="","",C9*$E$11),"") -> 109368 | D11: =IFERROR(IF(D9="","",D9*$E$11),"") -> 117023.76 | E11: =IFERROR(IF('0. Assumptions'!$B$12="","",'0. Assumptions'!$B$12),"") -> 0.15 | F11: Whole-bean coffee, teas and infusions from the counter, to go with breakfast or an afternoon snack: specialty beans cost more than commodity coffee, and the benchmarks table on the "Instructions" tab puts beverage cost at 20-30% of its own sales (kit estimate) | G11: =IFERROR(IF(B9="","",('0. Assumptions'!$B$62*((1-'0. Assumptions'!$B$16)*'0. Assumptions'!$B$63+'0. Assumptions'!$B$16*'0. Assumptions'!$B$40)+(1-'0. Assumptions'!$B$62)*'0. Assumptions'!$B$39)),"") -> 0.08
A12: VARIABLE COSTS
A13: Cost of goods sold — food | B13: =IFERROR(IF(B9="","",B9*'0. Assumptions'!$B$11*'0. Assumptions'!$B$13),"") -> 166005 | C13: =IFERROR(IF(C9="","",C9*'0. Assumptions'!$B$11*'0. Assumptions'!$B$13),"") -> 185925.6 | D13: =IFERROR(IF(D9="","",D9*'0. Assumptions'!$B$11*'0. Assumptions'!$B$13),"") -> 198940.39 | E13: =IFERROR(B13/$B$9,"") -> 0.255 | F13: =IFERROR("At "&TEXT('0. Assumptions'!$B$13,"0%")&" of FOOD sales, not of total sales: beverages have their own line · In the US the sales tax you pay on ingredients is a cost, not a credit, so column G of this row is 0","") -> At 30% of FOOD sales, not of total sales: beverages have their own line · In the US the sales tax you pay on ingredients is a cost, not a credit, so column G of this row is 0 | G13: =IFERROR(IF(B9="","",'0. Assumptions'!$B$41),"") -> 0
A14: Cost of goods sold — beverage | B14: =IFERROR(IF(B9="","",B9*'0. Assumptions'!$B$12*'0. Assumptions'!$B$14),"") -> 21483 | C14: =IFERROR(IF(C9="","",C9*'0. Assumptions'!$B$12*'0. Assumptions'!$B$14),"") -> 24060.96 | D14: =IFERROR(IF(D9="","",D9*'0. Assumptions'!$B$12*'0. Assumptions'!$B$14),"") -> 25745.227 | E14: =IFERROR(B14/$B$9,"") -> 0.033 | F14: =IFERROR("At "&TEXT('0. Assumptions'!$B$14,"0%")&" of BEVERAGE sales","") -> At 22% of BEVERAGE sales | G14: =IFERROR(IF(B9="","",'0. Assumptions'!$B$41),"") -> 0
A15: Disposables and packaging | B15: =IFERROR(IF(B9="","",B9*'0. Assumptions'!$B$15),"") -> 19530 | C15: =IFERROR(IF(C9="","",C9*'0. Assumptions'!$B$15),"") -> 21873.6 | D15: =IFERROR(IF(D9="","",D9*'0. Assumptions'!$B$15),"") -> 23404.752 | E15: =IFERROR(B15/$B$9,"") -> 0.03 | G15: =IFERROR(IF(B9="","",'0. Assumptions'!$B$41),"") -> 0
A16: Delivery platform fees | B16: =IFERROR(IF(B9="","",B9*'0. Assumptions'!$B$16*'0. Assumptions'!$B$17),"") -> 0 | C16: =IFERROR(IF(C9="","",C9*'0. Assumptions'!$B$16*'0. Assumptions'!$B$17),"") -> 0 | D16: =IFERROR(IF(D9="","",D9*'0. Assumptions'!$B$16*'0. Assumptions'!$B$17),"") -> 0 | E16: =IFERROR(B16/$B$9,"") -> 0 | F16: Applied to the sales of THAT CHANNEL. With 0% delivery in Assumptions, this line is zero | G16: =IFERROR(IF(B9="","",'0. Assumptions'!$B$41),"") -> 0
A17: Card processing fees | B17: =IFERROR(IF(B9="","",B9*'0. Assumptions'!$B$18),"") -> 22785 | C17: =IFERROR(IF(C9="","",C9*'0. Assumptions'!$B$18),"") -> 25519.2 | D17: =IFERROR(IF(D9="","",D9*'0. Assumptions'!$B$18),"") -> 27305.544 | E17: =IFERROR(B17/$B$9,"") -> 0.035 | F17: Card processing fees are not subject to sales tax: no tax is recovered or deducted for them | G17: 0
A18: Miscellaneous and contingency | B18: =IFERROR(IF(B9="","",B9*'0. Assumptions'!$B$28),"") -> 13020 | C18: =IFERROR(IF(C9="","",C9*'0. Assumptions'!$B$28),"") -> 14582.4 | D18: =IFERROR(IF(D9="","",D9*'0. Assumptions'!$B$28),"") -> 15603.168 | E18: =IFERROR(B18/$B$9,"") -> 0.02 | F18: =IFERROR("At "&TEXT('0. Assumptions'!$B$28,"0%")&" of sales. It is a VARIABLE cost: it moves with revenue, so it cannot sit in fixed costs","") -> At 2% of sales. It is a VARIABLE cost: it moves with revenue, so it cannot sit in fixed costs | G18: =IFERROR(IF(B9="","",'0. Assumptions'!$B$41),"") -> 0
A19: TOTAL VARIABLE COSTS | B19: =IFERROR(IF(B9="","",SUM(B13:B18)),"") -> 242823 | C19: =IFERROR(IF(C9="","",SUM(C13:C18)),"") -> 271961.76 | D19: =IFERROR(IF(D9="","",SUM(D13:D18)),"") -> 290999.08 | E19: =IFERROR(B19/$B$9,"") -> 0.373
A20: GROSS MARGIN | B20: =IFERROR(IF(B9="","",B9-B19),"") -> 408177 | C20: =IFERROR(IF(C9="","",C9-C19),"") -> 457158.24 | D20: =IFERROR(IF(D9="","",D9-D19),"") -> 489159.32 | E20: =IFERROR(B20/$B$9,"") -> 0.627
A21: FIXED COSTS
A22: Rent | B22: =IFERROR(IF(B9="","",'0. Assumptions'!$B$24*12),"") -> 50400 | C22: =IFERROR(IF(C9="","",B22*(1+'0. Assumptions'!$B$48)),"") -> 50400 | D22: =IFERROR(IF(D9="","",C22*(1+'0. Assumptions'!$B$48)),"") -> 50400 | E22: =IFERROR(B22/$B$9,"") -> 0.077419355 | F22: The monthly amount is on the "0. Assumptions" tab; here it is multiplied by twelve. Rent for the build-out months, which comes before opening, is on the Startup Costs tab and is NOT counted twice | G22: =IFERROR(IF(B9="","",'0. Assumptions'!$B$41),"") -> 0
A23: Labor (wages + employer payroll taxes) | B23: =IFERROR(IF(B9="","",Staffing!$G$11),"") -> 220836 | C23: =IFERROR(IF(C9="","",Staffing!$B$15),"") -> 226836 | D23: =IFERROR(IF(D9="","",Staffing!$B$16),"") -> 232836 | E23: =IFERROR(B23/$B$9,"") -> 0.33922581 | F23: Comes from the Staffing tab: it is the SAME number, not a separate estimate. Years 2 and 3 add the new hires declared on that tab, not a percentage of volume | G23: 0
A24: Utilities (electricity, water, gas) | B24: =IFERROR(IF(B9="","",'0. Assumptions'!$B$26*12),"") -> 18000 | C24: =IFERROR(IF(C9="","",B24*(1+'0. Assumptions'!$B$48)),"") -> 18000 | D24: =IFERROR(IF(D9="","",C24*(1+'0. Assumptions'!$B$48)),"") -> 18000 | E24: =IFERROR(B24/$B$9,"") -> 0.02764977 | F24: Enter the monthly bills excl. sales tax. The workbook applies a single tax treatment to this whole line, the one in the column next to it; if one utility is taxed differently in your area, give it its own line | G24: =IFERROR(IF(B9="","",'0. Assumptions'!$B$41),"") -> 0
A25: Insurance (general liability + property / auto) | B25: =IFERROR(IF(B9="","",'0. Assumptions'!$B$27),"") -> 4500 | C25: =IFERROR(IF(C9="","",B25*(1+'0. Assumptions'!$B$48)),"") -> 4500 | D25: =IFERROR(IF(D9="","",C25*(1+'0. Assumptions'!$B$48)),"") -> 4500 | E25: =IFERROR(B25/$B$9,"") -> 0.0069124424 | F25: Insurance premiums are not subject to sales tax: there is no recoverable tax on them | G25: 0
A26: Accountant | B26: 3600 | C26: =IFERROR(IF(C9="","",B26*(1+'0. Assumptions'!$B$48)),"") -> 3600 | D26: =IFERROR(IF(D9="","",C26*(1+'0. Assumptions'!$B$48)),"") -> 3600 | E26: =IFERROR(B26/$B$9,"") -> 0.0055299539 | G26: =IFERROR(IF(B9="","",'0. Assumptions'!$B$41),"") -> 0
A27: Oven and equipment maintenance | B27: 4000 | C27: =IFERROR(IF(C9="","",B27*(1+'0. Assumptions'!$B$48)),"") -> 4000 | D27: =IFERROR(IF(D9="","",C27*(1+'0. Assumptions'!$B$48)),"") -> 4000 | E27: =IFERROR(B27/$B$9,"") -> 0.0061443932 | G27: =IFERROR(IF(B9="","",'0. Assumptions'!$B$41),"") -> 0
A28: Marketing | B28: 7200 | C28: =IFERROR(IF(C9="","",B28*(1+'0. Assumptions'!$B$48)),"") -> 7200 | D28: =IFERROR(IF(D9="","",C28*(1+'0. Assumptions'!$B$48)),"") -> 7200 | E28: =IFERROR(B28/$B$9,"") -> 0.011059908 | G28: =IFERROR(IF(B9="","",'0. Assumptions'!$B$41),"") -> 0
A29: Software | B29: 1800 | C29: =IFERROR(IF(C9="","",B29*(1+'0. Assumptions'!$B$48)),"") -> 1800 | D29: =IFERROR(IF(D9="","",C29*(1+'0. Assumptions'!$B$48)),"") -> 1800 | E29: =IFERROR(B29/$B$9,"") -> 0.002764977 | G29: =IFERROR(IF(B9="","",'0. Assumptions'!$B$41),"") -> 0
A30: Cleaning | B30: 2400 | C30: =IFERROR(IF(C9="","",B30*(1+'0. Assumptions'!$B$48)),"") -> 2400 | D30: =IFERROR(IF(D9="","",C30*(1+'0. Assumptions'!$B$48)),"") -> 2400 | E30: =IFERROR(B30/$B$9,"") -> 0.0036866359 | G30: =IFERROR(IF(B9="","",'0. Assumptions'!$B$41),"") -> 0
A31: Miscellaneous | B31: 1200 | C31: =IFERROR(IF(C9="","",B31*(1+'0. Assumptions'!$B$48)),"") -> 1200 | D31: =IFERROR(IF(D9="","",C31*(1+'0. Assumptions'!$B$48)),"") -> 1200 | E31: =IFERROR(B31/$B$9,"") -> 0.001843318 | G31: =IFERROR(IF(B9="","",'0. Assumptions'!$B$41),"") -> 0
A32: Waste hauling (organic and cardboard) | B32: 1200 | C32: =IFERROR(IF(C9="","",B32*(1+'0. Assumptions'!$B$48)),"") -> 1200 | D32: =IFERROR(IF(D9="","",C32*(1+'0. Assumptions'!$B$48)),"") -> 1200 | E32: =IFERROR(B32/$B$9,"") -> 0.001843318 | F32: Licensed waste / grease hauler; the checklist asks for the contract before you open. This plan does not fry, so the volume is lower than a restaurant's: get a quote in your area | G32: =IFERROR(IF(B9="","",'0. Assumptions'!$B$41),"") -> 0
A33: Pest control | B33: 900 | C33: =IFERROR(IF(C9="","",B33*(1+'0. Assumptions'!$B$48)),"") -> 900 | D33: =IFERROR(IF(D9="","",C33*(1+'0. Assumptions'!$B$48)),"") -> 900 | E33: =IFERROR(B33/$B$9,"") -> 0.0013824885 | F33: Licensed pest control company; part of the HACCP-based food safety plan that the checklist already requires in the staff phase. Stored flour attracts pests more easily than a restaurant pantry does, so the budget is slightly higher | G33: =IFERROR(IF(B9="","",'0. Assumptions'!$B$41),"") -> 0
A34: Music licensing (ASCAP, BMI, SESAC) | B34: 600 | C34: =IFERROR(IF(C9="","",B34*(1+'0. Assumptions'!$B$48)),"") -> 600 | D34: =IFERROR(IF(D9="","",C34*(1+'0. Assumptions'!$B$48)),"") -> 600 | E34: =IFERROR(B34/$B$9,"") -> 0.00092165899 | F34: ASCAP, BMI and SESAC are separate licensing organizations; the fee depends on the size and capacity of your shop. Only needed if you play music | G34: =IFERROR(IF(B9="","",'0. Assumptions'!$B$41),"") -> 0
A35: Training and certifications | B35: 500 | C35: =IFERROR(IF(C9="","",B35*(1+'0. Assumptions'!$B$48)),"") -> 500 | D35: =IFERROR(IF(D9="","",C35*(1+'0. Assumptions'!$B$48)),"") -> 500 | E35: =IFERROR(B35/$B$9,"") -> 0.00076804916 | F35: Food handler cards, Certified Food Protection Manager certification (for example ServSafe) and workplace safety training for the team. A bakery has specific hazards (burns, heavy lifting, flour dust in the air). Requirements vary by state and county | G35: =IFERROR(IF(B9="","",'0. Assumptions'!$B$41),"") -> 0
A36: Depreciation of fixed assets | B36: =IFERROR(IF(B9="","",'Startup Costs'!$B$38),"") -> 19682.857 | C36: =IFERROR(IF(C9="","",B36),"") -> 19682.857 | D36: =IFERROR(IF(D9="","",B36),"") -> 19682.857 | E36: =IFERROR(B36/$B$9,"") -> 0.030234804 | F36: Comes from the depreciation bases on the Startup Costs tab: real fixed assets only. It does NOT rise with inflation: it is a charge on the HISTORICAL cost of the assets | G36: 0
A37: Interest expense (loan interest) | B37: =IFERROR(IF(B9="","",Financing!$B$44),"") -> 19700 | C37: =IFERROR(IF(C9="","",Financing!$B$46),"") -> 18463.916 | D37: =IFERROR(IF(D9="","",Financing!$B$48),"") -> 17104.223 | E37: =IFERROR(B37/$B$9,"") -> 0.030261137 | F37: Only INTEREST is an expense. Principal repaid appears on the cash flow tab | G37: 0
A38: TOTAL FIXED COSTS | B38: =IFERROR(IF(B9="","",SUM(B22:B37)),"") -> 356518.86 | C38: =IFERROR(IF(C9="","",SUM(C22:C37)),"") -> 361282.77 | D38: =IFERROR(IF(D9="","",SUM(D22:D37)),"") -> 365923.08 | E38: =IFERROR(B38/$B$9,"") -> 0.54764801
A39: Recoverable input tax on variable costs | B39: =IFERROR(IF(B9="","",SUMPRODUCT(B13:B18,G13:G18)),"") -> 0 | C39: =IFERROR(IF(C9="","",SUMPRODUCT(C13:C18,G13:G18)),"") -> 0 | D39: =IFERROR(IF(D9="","",SUMPRODUCT(D13:D18,G13:G18)),"") -> 0 | F39: Each line at ITS OWN rate, read from the column next to it. It is what the cash flow tab overpays to suppliers and later deducts (zero wherever no tax is recoverable)
A40: Recoverable input tax on fixed costs | B40: =IFERROR(IF(B9="","",SUMPRODUCT(B22:B37,G22:G37)),"") -> 0 | C40: =IFERROR(IF(C9="","",SUMPRODUCT(C22:C37,G22:G37)),"") -> 0 | D40: =IFERROR(IF(D9="","",SUMPRODUCT(D22:D37,G22:G37)),"") -> 0
A41: PRE-TAX INCOME (EBT) | B41: =IFERROR(IF(B9="","",B20-B38),"") -> 51658.143 | C41: =IFERROR(IF(C9="","",C20-C38),"") -> 95875.467 | D41: =IFERROR(IF(D9="","",D20-D38),"") -> 123236.24 | E41: =IFERROR(B41/$B$9,"") -> 0.079351986
...

Sheet Break-Even
A1: BREAK-EVEN
A4: Variable | B4: Year 1 | C4: Year 2 | D4: Year 3 | E4: Notes
A5: BASE DATA BY YEAR
A6: Annual fixed costs | B6: =IFERROR(IF('3-Year P&L'!$B$9="","",'3-Year P&L'!$B$38),"") -> 356518.86 | C6: =IFERROR(IF('3-Year P&L'!$C$9="","",'3-Year P&L'!$C$38),"") -> 361282.77 | D6: =IFERROR(IF('3-Year P&L'!$D$9="","",'3-Year P&L'!$D$38),"") -> 365923.08 | E6: The SAME fixed costs as the P&L. Each year has its own, which is why the threshold cannot be a single one for all three years
A7: Monthly fixed costs | B7: =IFERROR(IF('3-Year P&L'!$B$9="","",B6/12),"") -> 29709.905 | C7: =IFERROR(IF('3-Year P&L'!$C$9="","",C6/12),"") -> 30106.898 | D7: =IFERROR(IF('3-Year P&L'!$D$9="","",D6/12),"") -> 30493.59
A8: Average check (excl. sales tax) | B8: =IFERROR(IF('3-Year P&L'!$B$9="","",'3-Year P&L'!$B$7),"") -> 10 | C8: =IFERROR(IF('3-Year P&L'!$C$9="","",'3-Year P&L'!$C$7),"") -> 10 | D8: =IFERROR(IF('3-Year P&L'!$D$9="","",'3-Year P&L'!$D$7),"") -> 10
A9: Variable cost per transaction | B9: =IFERROR(IF('3-Year P&L'!$B$9="","",'3-Year P&L'!$B$19/('3-Year P&L'!$B$6*'3-Year P&L'!$B$8)),"") -> 3.73 | C9: =IFERROR(IF('3-Year P&L'!$C$9="","",'3-Year P&L'!$C$19/('3-Year P&L'!$C$6*'3-Year P&L'!$C$8)),"") -> 3.73 | D9: =IFERROR(IF('3-Year P&L'!$D$9="","",'3-Year P&L'!$D$19/('3-Year P&L'!$D$6*'3-Year P&L'!$D$8)),"") -> 3.73 | E9: Comes from the P&L total variable costs, not from a separate estimate. It includes miscellaneous and contingency, which is a percentage of sales
A10: Contribution margin per transaction | B10: =IFERROR(IF('3-Year P&L'!$B$9="","",B8-B9),"") -> 6.27 | C10: =IFERROR(IF('3-Year P&L'!$C$9="","",C8-C9),"") -> 6.27 | D10: =IFERROR(IF('3-Year P&L'!$D$9="","",D8-D9),"") -> 6.27 | E10: Average check minus unit variable cost
A11: Operating days per year | B11: =IFERROR(IF('3-Year P&L'!$B$9="","",'3-Year P&L'!$B$8),"") -> 310 | C11: =IFERROR(IF('3-Year P&L'!$C$9="","",'3-Year P&L'!$C$8),"") -> 310 | D11: =IFERROR(IF('3-Year P&L'!$D$9="","",'3-Year P&L'!$D$8),"") -> 310 | E11: The same calendar as the P&L and the scenarios
A12: Principal repaid in the year | B12: =IFERROR(IF('3-Year P&L'!$B$9="","",Financing!$B$45),"") -> 12360.843 | C12: =IFERROR(IF('3-Year P&L'!$C$9="","",Financing!$B$47),"") -> 13596.927 | D12: =IFERROR(IF('3-Year P&L'!$D$9="","",Financing!$B$49),"") -> 14956.62 | E12: Principal is NOT a P&L expense, but it leaves the cash account. Without it, the published break-even threshold would sit below the real one
A13: ACCOUNTING BREAK-EVEN (includes depreciation)
A14: Transactions needed per year | B14: =IFERROR(IF('3-Year P&L'!$B$9="","",IF(B10<=0,"",B6/B10)),"") -> 56861.062 | C14: =IFERROR(IF('3-Year P&L'!$C$9="","",IF(C10<=0,"",C6/C10)),"") -> 57620.857 | D14: =IFERROR(IF('3-Year P&L'!$D$9="","",IF(D10<=0,"",D6/D10)),"") -> 58360.938
A15: Transactions needed per day | B15: =IFERROR(IF('3-Year P&L'!$B$9="","",B14/B11),"") -> 183.42278 | C15: =IFERROR(IF('3-Year P&L'!$C$9="","",C14/C11),"") -> 185.87373 | D15: =IFERROR(IF('3-Year P&L'!$D$9="","",D14/D11),"") -> 188.26109
A16: Revenue needed per year | B16: =IFERROR(IF('3-Year P&L'!$B$9="","",B14*B8),"") -> 568610.62 | C16: =IFERROR(IF('3-Year P&L'!$C$9="","",C14*C8),"") -> 576208.57 | D16: =IFERROR(IF('3-Year P&L'!$D$9="","",D14*D8),"") -> 583609.38
A17: CASH BREAK-EVEN (loan payments in, depreciation out)
A18: Cash fixed costs + principal repaid for the year | B18: =IFERROR(IF('3-Year P&L'!$B$9="","",B6-'3-Year P&L'!$B$36+B12),"") -> 349196.84 | C18: =IFERROR(IF('3-Year P&L'!$C$9="","",C6-'3-Year P&L'!$C$36+C12),"") -> 355196.84 | D18: =IFERROR(IF('3-Year P&L'!$D$9="","",D6-'3-Year P&L'!$D$36+D12),"") -> 361196.84 | E18: The P&L fixed costs without depreciation (which is not paid in cash) and WITH principal repaid (which is). This is the threshold that decides whether cash holds up
A19: Transactions needed per year (cash) | B19: =IFERROR(IF('3-Year P&L'!$B$9="","",IF(B10<=0,"",B18/B10)),"") -> 55693.276 | C19: =IFERROR(IF('3-Year P&L'!$C$9="","",IF(C10<=0,"",C18/C10)),"") -> 56650.214 | D19: =IFERROR(IF('3-Year P&L'!$D$9="","",IF(D10<=0,"",D18/D10)),"") -> 57607.152
A20: Transactions needed per day (cash) | B20: =IFERROR(IF('3-Year P&L'!$B$9="","",B19/B11),"") -> 179.65573 | C20: =IFERROR(IF('3-Year P&L'!$C$9="","",C19/C11),"") -> 182.74263 | D20: =IFERROR(IF('3-Year P&L'!$D$9="","",D19/D11),"") -> 185.82952
A21: Revenue needed per year (cash) | B21: =IFERROR(IF('3-Year P&L'!$B$9="","",B19*B8),"") -> 556932.76 | C21: =IFERROR(IF('3-Year P&L'!$C$9="","",C19*C8),"") -> 566502.14 | D21: =IFERROR(IF('3-Year P&L'!$D$9="","",D19*D8),"") -> 576071.52
A22: COMPARISON WITH THE PLAN
A23: Transactions per day forecast in the plan | B23: =IFERROR(IF('3-Year P&L'!$B$9="","",'3-Year P&L'!$B$6),"") -> 210 | C23: =IFERROR(IF('3-Year P&L'!$C$9="","",'3-Year P&L'!$C$6),"") -> 235.2 | D23: =IFERROR(IF('3-Year P&L'!$D$9="","",'3-Year P&L'!$D$6),"") -> 251.664
A24: Cushion above CASH break-even (%) | B24: =IFERROR(IF('3-Year P&L'!$B$9="","",B23/B20-1),"") -> 0.16890232 | C24: =IFERROR(IF('3-Year P&L'!$C$9="","",C23/C20-1),"") -> 0.28705603 | D24: =IFERROR(IF('3-Year P&L'!$D$9="","",D23/D20-1),"") -> 0.35427351 | E24: How far planned sales sit above cash break-even. The drop you can absorb before you cannot pay the fixed costs and the loan payment is somewhat smaller: with a 25% cushion, 20%. The required minimum is set in the "0. Assumptions" tab
A25: INTERPRETATION
A26: =IFERROR("With the average check excl. sales tax above, you need "&TEXT(ROUNDUP(B15,0),"0")&" transactions a day over your "&TEXT(B11,"0")&" opening days to avoid losing money (accounting break-even, depreciation included), and "&TEXT(ROUNDUP(B20,0),"0")&" for cash to hold (cash break-even: depreciation out, because it is not paid, and the year's loan payment in"&IF(B12=0,"; no principal is repaid this year (interest-only period or no loan)","")&"). The ""Revenue needed per year"" rows show the same figures in your currency.","") -> With the average check excl. sales tax above, you need 184 transactions a day over your 310 opening days to avoid losing money (accounting break-even, depreciation included), and 180 for cash to hold (cash break-even: depreciation out, because it is not paid, and the year's loan payment in). The "Revenue needed per year" rows show the same figures in your currency.
A28: BREAK-EVEN SENSITIVITY
A29: Transactions per day needed to cover costs, by average check (columns) and variable cost per transaction (rows). Green cells are below the transactions per day that the plan forecasts.
A31: Transactions per day needed: average check excl. sales tax (columns) × variable cost per transaction (rows) | B31: =IFERROR($B$8-2,"") -> 8 | C31: =IFERROR(IF($B$8="","",$B$8),"") -> 10 | D31: =IFERROR($B$8+2,"") -> 12 | E31: =IFERROR($B$8+4,"") -> 14
A32: =IFERROR($B$9*0.85,"") -> 3.1705 | B32: =IFERROR(IF($B$31-$A32<=0,"",$B$6/($B$31-$A32)/$B$11),"") -> 238.13248 | C32: =IFERROR(IF($C$31-$A32<=0,"",$B$6/($C$31-$A32)/$B$11),"") -> 168.39605 | D32: =IFERROR(IF($D$31-$A32<=0,"",$B$6/($D$31-$A32)/$B$11),"") -> 130.25209 | E32: =IFERROR(IF($E$31-$A32<=0,"",$B$6/($E$31-$A32)/$B$11),"") -> 106.19704
A33: =IFERROR($B$9*0.925,"") -> 3.45025 | B33: =IFERROR(IF($B$31-$A33<=0,"",$B$6/($B$31-$A33)/$B$11),"") -> 252.77451 | C33: =IFERROR(IF($C$31-$A33<=0,"",$B$6/($C$31-$A33)/$B$11),"") -> 175.58851 | D33: =IFERROR(IF($D$31-$A33<=0,"",$B$6/($D$31-$A33)/$B$11),"") -> 134.51397 | E33: =IFERROR(IF($E$31-$A33<=0,"",$B$6/($E$31-$A33)/$B$11),"") -> 109.01309
A34: =IFERROR($B$9*1.0,"") -> 3.73 | B34: =IFERROR(IF($B$31-$A34<=0,"",$B$6/($B$31-$A34)/$B$11),"") -> 269.33509 | C34: =IFERROR(IF($C$31-$A34<=0,"",$B$6/($C$31-$A34)/$B$11),"") -> 183.42278 | D34: =IFERROR(IF($D$31-$A34<=0,"",$B$6/($D$31-$A34)/$B$11),"") -> 139.06419 | E34: =IFERROR(IF($E$31-$A34<=0,"",$B$6/($E$31-$A34)/$B$11),"") -> 111.98255
A35: =IFERROR($B$9*1.075,"") -> 4.00975 | B35: =IFERROR(IF($B$31-$A35<=0,"",$B$6/($B$31-$A35)/$B$11),"") -> 288.21774 | C35: =IFERROR(IF($C$31-$A35<=0,"",$B$6/($C$31-$A35)/$B$11),"") -> 191.98879 | D35: =IFERROR(IF($D$31-$A35<=0,"",$B$6/($D$31-$A35)/$B$11),"") -> 143.93302 | E35: =IFERROR(IF($E$31-$A35<=0,"",$B$6/($E$31-$A35)/$B$11),"") -> 115.11832
A36: =IFERROR($B$9*1.15,"") -> 4.2895 | B36: =IFERROR(IF($B$31-$A36<=0,"",$B$6/($B$31-$A36)/$B$11),"") -> 309.94767 | C36: =IFERROR(IF($C$31-$A36<=0,"",$B$6/($C$31-$A36)/$B$11),"") -> 201.39407 | D36: =IFERROR(IF($D$31-$A36<=0,"",$B$6/($D$31-$A36)/$B$11),"") -> 149.15516 | E36: =IFERROR(IF($E$31-$A36<=0,"",$B$6/($E$31-$A36)/$B$11),"") -> 118.43477

Sheet Scenarios
A1: SCENARIOS
A4: Metric | B4: Pessimistic | C4: Base | D4: Optimistic | E4: Notes
A5: Transactions per day | B5: 140 | C5: =IFERROR(IF('3-Year P&L'!$B$6="","",'3-Year P&L'!$B$6),"") -> 210 | D5: 233
A6: Average check (excl. sales tax) | B6: 7.64 | C6: =IFERROR(IF('3-Year P&L'!$B$7="","",'3-Year P&L'!$B$7),"") -> 10 | D6: 10.91
A7: Operating days per year | B7: 300 | C7: =IFERROR(IF('3-Year P&L'!$B$8="","",'3-Year P&L'!$B$8),"") -> 310 | D7: 320
A8: ANNUAL REVENUE (excl. sales tax) | B8: =IFERROR(IF(B5*B6*B7=0,"",B5*B6*B7),"") -> 320880 | C8: =IFERROR(IF(C5*C6*C7=0,"",C5*C6*C7),"") -> 651000 | D8: =IFERROR(IF(D5*D6*D7=0,"",D5*D6*D7),"") -> 813449.6
A9: Cost of goods sold — food | B9: =IFERROR(IF(B8="","",B8*'0. Assumptions'!$B$11*'0. Assumptions'!$B$13),"") -> 81824.4 | C9: =IFERROR(IF(C8="","",C8*'0. Assumptions'!$B$11*'0. Assumptions'!$B$13),"") -> 166005 | D9: =IFERROR(IF(D8="","",D8*'0. Assumptions'!$B$11*'0. Assumptions'!$B$13),"") -> 207429.65
A10: Cost of goods sold — beverage | B10: =IFERROR(IF(B8="","",B8*'0. Assumptions'!$B$12*'0. Assumptions'!$B$14),"") -> 10589.04 | C10: =IFERROR(IF(C8="","",C8*'0. Assumptions'!$B$12*'0. Assumptions'!$B$14),"") -> 21483 | D10: =IFERROR(IF(D8="","",D8*'0. Assumptions'!$B$12*'0. Assumptions'!$B$14),"") -> 26843.837
A11: Disposables and packaging | B11: =IFERROR(IF(B8="","",B8*'0. Assumptions'!$B$15),"") -> 9626.4 | C11: =IFERROR(IF(C8="","",C8*'0. Assumptions'!$B$15),"") -> 19530 | D11: =IFERROR(IF(D8="","",D8*'0. Assumptions'!$B$15),"") -> 24403.488
A12: Delivery platform fees | B12: =IFERROR(IF(B8="","",B8*'0. Assumptions'!$B$16*'0. Assumptions'!$B$17),"") -> 0 | C12: =IFERROR(IF(C8="","",C8*'0. Assumptions'!$B$16*'0. Assumptions'!$B$17),"") -> 0 | D12: =IFERROR(IF(D8="","",D8*'0. Assumptions'!$B$16*'0. Assumptions'!$B$17),"") -> 0
A13: Card processing fees | B13: =IFERROR(IF(B8="","",B8*'0. Assumptions'!$B$18),"") -> 11230.8 | C13: =IFERROR(IF(C8="","",C8*'0. Assumptions'!$B$18),"") -> 22785 | D13: =IFERROR(IF(D8="","",D8*'0. Assumptions'!$B$18),"") -> 28470.736
A14: Miscellaneous and contingency | B14: =IFERROR(IF(B8="","",B8*'0. Assumptions'!$B$28),"") -> 6417.6 | C14: =IFERROR(IF(C8="","",C8*'0. Assumptions'!$B$28),"") -> 13020 | D14: =IFERROR(IF(D8="","",D8*'0. Assumptions'!$B$28),"") -> 16268.992
A15: TOTAL VARIABLE COSTS | B15: =IFERROR(IF(B8="","",SUM(B9:B14)),"") -> 119688.24 | C15: =IFERROR(IF(C8="","",SUM(C9:C14)),"") -> 242823 | D15: =IFERROR(IF(D8="","",SUM(D9:D14)),"") -> 303416.7
A16: GROSS MARGIN | B16: =IFERROR(IF(B8="","",B8-B15),"") -> 201191.76 | C16: =IFERROR(IF(C8="","",C8-C15),"") -> 408177 | D16: =IFERROR(IF(D8="","",D8-D15),"") -> 510032.9
A17: FIXED COSTS (the P&L's) | B17: =IFERROR(IF(B8="","",'3-Year P&L'!$B$38),"") -> 356518.86 | C17: =IFERROR(IF(C8="","",'3-Year P&L'!$B$38),"") -> 356518.86 | D17: =IFERROR(IF(D8="","",'3-Year P&L'!$B$38),"") -> 356518.86 | E17: Fixed costs do not change with the scenario: that is why they are fixed
A18: PRE-TAX INCOME (EBT) | B18: =IFERROR(IF(B8="","",B16-B17),"") -> -155327.1 | C18: =IFERROR(IF(C8="","",C16-C17),"") -> 51658.143 | D18: =IFERROR(IF(D8="","",D16-D17),"") -> 153514.04
A19: Income tax | B19: =IFERROR(IF(B8="","",MAX(0,B18-'0. Assumptions'!$B$42)*'0. Assumptions'!$B$37),"") -> 0 | C19: =IFERROR(IF(C8="","",MAX(0,C18-'0. Assumptions'!$B$42)*'0. Assumptions'!$B$37),"") -> 12914.536 | D19: =IFERROR(IF(D8="","",MAX(0,D18-'0. Assumptions'!$B$42)*'0. Assumptions'!$B$37),"") -> 38378.511 | E19: At the "years 1-2" effective income tax rate, offsetting prior net operating losses
A20: NET INCOME | B20: =IFERROR(IF(B8="","",B18-B19),"") -> -155327.1 | C20: =IFERROR(IF(C8="","",C18-C19),"") -> 38743.607 | D20: =IFERROR(IF(D8="","",D18-D19),"") -> 115135.53
A21: Transactions per day for break-even | B21: =IFERROR(IF(B8="","",IF(B6-B15/(B5*B7)<=0,"",B17/(B6-B15/(B5*B7))/B7)),"") -> 248.08491 | C21: =IFERROR(IF(C8="","",IF(C6-C15/(C5*C7)<=0,"",C17/(C6-C15/(C5*C7))/C7)),"") -> 183.42278 | D21: =IFERROR(IF(D8="","",IF(D6-D15/(D5*D7)<=0,"",D17/(D6-D15/(D5*D7))/D7)),"") -> 162.86968
A22: WHAT EACH SCENARIO DEMANDS
A23: Labor cost / Sales | B23: =IFERROR(IF(B8="","",'3-Year P&L'!$B$23/B8),"") -> 0.6882199 | C23: =IFERROR(IF(C8="","",'3-Year P&L'!$B$23/C8),"") -> 0.33922581 | D23: =IFERROR(IF(D8="","",'3-Year P&L'!$B$23/D8),"") -> 0.27148086 | E23: The SAME staffing in all three scenarios. If labor cost blows up in the pessimistic case, adjust it in the Staffing tab, not here
A24: Transactions per year per full-time equivalent | B24: =IFERROR(IF(B8="","",B5*B7/Staffing!$C$11),"") -> 7553.9568 | C24: =IFERROR(IF(C8="","",C5*C7/Staffing!$C$11),"") -> 11708.633 | D24: =IFERROR(IF(D8="","",D5*D7/Staffing!$C$11),"") -> 13410.072 | E24: Transactions that each full-time equivalent on the "Staffing" tab would have to handle. In the optimistic scenario it tells you whether you need to hire
A25: Year-1 closing cash balance (estimate, same method in all three scenarios) | B25: =IFERROR(IF(B8="","",'Startup Costs'!$B$30+B20+'3-Year P&L'!$B$36-Financing!$B$45),"") -> -63796.083 | C25: =IFERROR(IF(C8="","",'Startup Costs'!$B$30+C20+'3-Year P&L'!$B$36-Financing!$B$45),"") -> 130274.62 | D25: =IFERROR(IF(D8="","",'Startup Costs'!$B$30+D20+'3-Year P&L'!$B$36-Financing!$B$45),"") -> 206666.55 | E25: ESTIMATED balance: working capital plus the year's result, adding back depreciation (which is not paid) and subtracting loan principal. It does not include the timing gap between receipts and payments or the sales tax settlement, so the three columns can be compared with each other. In red, the scenario runs out of cash
A26: Actual month-12 balance from the 12-Month Cash Flow tab (Base case only) | C26: =IFERROR(IF(C8="","",'12-Month Cash Flow'!$M$22),"") -> 161114.45 | E26: The ACTUAL base-case balance, with its timing of receipts and payments and its sales tax settlement. It exists only for the Base scenario, the only one with its own monthly cash flow: that is why it is not in the row above, where it would be compared against two estimates
A28: The "Base" column reads its three inputs from the "0. Assumptions" tab, so it reproduces EXACTLY year 1 of the P&L. The other two scenarios use the same cost rates: the only things that change are transactions, average check and days. The FIXED COSTS are the same in all three: miscellaneous and contingency, which are a percentage of sales, sit at the top with the variable costs and each scenario carries its own.

Sheet Staffing
A1: STAFFING AND LABOR COSTS
A2: =IFERROR("Payroll — "&TEXT('0. Assumptions'!$B$21,"0")&" pay periods + employer taxes "&TEXT('0. Assumptions'!$B$20*100,"0")&"%","") -> Payroll — 12 pay periods + employer taxes 10%
A4: Position | B4: People | C4: FTE | D4: Gross pay per month (total for the position) | E4: Employer payroll taxes (total for the position) | F4: Cost per month (total for the position) | G4: Cost per year | H4: Hours per week per person | I4: Hours per year for the position | J4: Notes
A5: Head baker / Owner | B5: 1 | C5: 1 | D5: 4000 | E5: =IFERROR(IF(D5="","",D5*'0. Assumptions'!$B$20),"") -> 400 | F5: =IFERROR(IF(D5="","",D5+E5),"") -> 4400 | G5: =IFERROR(IF(D5="","",F5*MAX(12,'0. Assumptions'!$B$21)),"") -> 52800 | H5: =IFERROR(IF(D5="","",C5*$B$18),"") -> 40 | I5: =IFERROR(IF(D5="","",H5*B5*$B$19),"") -> 2000 | J5: Early production shift (4:00-5:00 AM start, see Phase 4 of the checklist): mixing, shaping and baking the first batch, plus management and purchasing. It is the most skilled position in the production area
A6: Baker | B6: 1 | C6: 1 | D6: 3300 | E6: =IFERROR(IF(D6="","",D6*'0. Assumptions'!$B$20),"") -> 330 | F6: =IFERROR(IF(D6="","",D6+E6),"") -> 3630 | G6: =IFERROR(IF(D6="","",F6*MAX(12,'0. Assumptions'!$B$21)),"") -> 43560 | H6: =IFERROR(IF(D6="","",C6*$B$18),"") -> 40 | I6: =IFERROR(IF(D6="","",H6*B6*$B$19),"") -> 2000 | J6: Second batch and morning pastries; covers the head baker on days off
A7: Bakery assistant | B7: 1 | C7: 1 | D7: 2800 | E7: =IFERROR(IF(D7="","",D7*'0. Assumptions'!$B$20),"") -> 280 | F7: =IFERROR(IF(D7="","",D7+E7),"") -> 3080 | G7: =IFERROR(IF(D7="","",F7*MAX(12,'0. Assumptions'!$B$21)),"") -> 36960 | H7: =IFERROR(IF(D7="","",C7*$B$18),"") -> 40 | I7: =IFERROR(IF(D7="","",H7*B7*$B$19),"") -> 2000 | J7: Weighing, cleaning, loading and unloading the ovens, and support with fermentation
A8: Counter staff / baristas | B8: 3 | C8: 0.67 | D8: 5200 | E8: =IFERROR(IF(D8="","",D8*'0. Assumptions'!$B$20),"") -> 520 | F8: =IFERROR(IF(D8="","",D8+E8),"") -> 5720 | G8: =IFERROR(IF(D8="","",F8*MAX(12,'0. Assumptions'!$B$21)),"") -> 68640 | H8: =IFERROR(IF(D8="","",C8*$B$18),"") -> 26.8 | I8: =IFERROR(IF(D8="","",H8*B8*$B$19),"") -> 4020 | J8: Customer service, register and restocking the display case during the whole opening day
A9: Weekend extra | B9: 1 | C9: 0.4 | D9: 1040 | E9: =IFERROR(IF(D9="","",D9*'0. Assumptions'!$B$20),"") -> 104 | F9: =IFERROR(IF(D9="","",D9+E9),"") -> 1144 | G9: =IFERROR(IF(D9="","",F9*MAX(12,'0. Assumptions'!$B$21)),"") -> 13728 | H9: =IFERROR(IF(D9="","",C9*$B$18),"") -> 16 | I9: =IFERROR(IF(D9="","",H9*B9*$B$19),"") -> 800 | J9: Reinforcement for the Saturday and Sunday morning peak, when pastry demand rises
A10: Vacation and day-off relief | B10: 1 | C10: 0.15 | D10: 390 | E10: =IFERROR(IF(D10="","",D10*'0. Assumptions'!$B$20),"") -> 39 | F10: =IFERROR(IF(D10="","",D10+E10),"") -> 429 | G10: =IFERROR(IF(D10="","",F10*MAX(12,'0. Assumptions'!$B$21)),"") -> 5148 | H10: =IFERROR(IF(D10="","",C10*$B$18),"") -> 6 | I10: =IFERROR(IF(D10="","",H10*B10*$B$19),"") -> 300 | J10: Covers paid time off and the weekly day off for the production team. The US sets no federal vacation requirement, so this follows your own policy
A11: TOTAL STAFF | B11: =IFERROR(IF(COUNT(D5:D10)=0,"",SUM(B5:B10)),"") -> 8 | C11: =IFERROR(IF(COUNT(D5:D10)=0,"",SUMPRODUCT(B5:B10,C5:C10)),"") -> 5.56 | D11: =IFERROR(IF(COUNT(D5:D10)=0,"",SUM(D5:D10)),"") -> 16730 | E11: =IFERROR(IF(COUNT(D5:D10)=0,"",SUM(E5:E10)),"") -> 1673 | F11: =IFERROR(IF(COUNT(D5:D10)=0,"",SUM(F5:F10)),"") -> 18403 | G11: =IFERROR(IF(COUNT(D5:D10)=0,"",SUM(G5:G10)),"") -> 220836 | I11: =IFERROR(IF(COUNT(D5:D10)=0,"",SUM(I5:I10)),"") -> 11120
A12: STAFF GROWTH (stepped cost)
A13: Annual cost of year-2 hires | B13: 6000 | J13: FULL ANNUAL cost (gross pay + employer payroll taxes, over all pay periods) of whoever you hire that year. The P&L adds it to the previous year's cost: staffing grows by people, not by a percentage
A14: Annual cost of year-3 hires | B14: 6000 | J14: FULL ANNUAL cost (gross pay + employer payroll taxes, over all pay periods) of whoever you hire that year. The P&L adds it to the previous year's cost: staffing grows by people, not by a percentage
A15: Labor cost, year 2 | B15: =IFERROR(IF(G11="","",G11*(1+'0. Assumptions'!$B$48)+B13),"") -> 226836
A16: Labor cost, year 3 | B16: =IFERROR(IF(B15="","",B15*(1+'0. Assumptions'!$B$48)+B14),"") -> 232836
A17: COVERAGE OF SERVICE HOURS
A18: Full-time week (hours per week) | B18: 40 | J18: 40 hours a week is the FLSA overtime threshold for non-exempt employees; some states add daily overtime rules. Change it if your own full-time week is different
A19: Weeks worked per year per person | B19: 50 | J19: 50 weeks: 52 minus about two weeks of vacation, holidays and average absences. There is no federal vacation requirement in the US: adjust it to your own policy
A20: Service hours per day to cover | B20: 12 | J20: From opening to closing of the SHOP. The production shift goes in the row below and does not overlap with the counter. Count them on your real schedule
A21: People needed at the same time in each shift | B21: 2 | J21: Average number of people at the counter at the same time through the day: two in this example, which covers the morning and afternoon peaks and the coffee corner
A22: Production hours per day BEFORE opening | B22: 4 | J22: Early production shift (4:00-5:00 AM start, see Phase 4 of the checklist): mixing, shaping and baking the first batch BEFORE the shop opens
A23: People on the production shift | B23: 2 | J23: The head baker and the baker. Change it if your production shift has a different number of people
A24: Service hours to cover per year | B24: =IFERROR(IF(OR(B20="",B21="",'0. Assumptions'!$B$6=""),"",B20*B21*'0. Assumptions'!$B$6+B22*B23*'0. Assumptions'!$B$6),"") -> 9920
A25: Hours hired per year | B25: =IFERROR(IF(I11="","",I11),"") -> 11120
A26: Coverage (hired / needed) | B26: =IFERROR(B25/B24,"") -> 1.1209677 | J26: Below 100% the staff cannot cover the hours the plan declares: either hire more or cut the hours
A28: The gross pay, employer payroll taxes, monthly cost and annual cost columns are TOTALS for the row: for a position with two people they include both. FTE is the share of a full-time week for each person, and it is used to compare pay with the legal minimum in proportion; the TOTAL row multiplies it by the people in each position, so it gives the full-time equivalents of the whole team. The payroll tax rate and the number of pay periods are in the "0. Assumptions" tab.
A29: The pay floor is the HIGHER of the federal minimum wage and your state / local minimum wage, both in the "0. Assumptions" tab; part-time positions get it in proportion. There is no single national table above the federal floor: the state / local cell is delivered empty so you can enter the rate for your state and city.

Sheet Instructions
A1: INSTRUCTIONS FOR USE — Bakery Financial Projections
A3: HOW TO USE THIS WORKBOOK
A4: This financial plan is a MODEL: you type only in the GREEN cells and everything else recalculates on its own.
A5: 1. "0. Assumptions" is the control sheet: transactions per day, average check excl. sales tax, operating days, food and beverage mix, cost of goods sold, rent, financing and taxes.
A6: 2. Startup cost items, fixed costs and staffing are typed in their own tab, also in green. No number is typed twice.
A7: 3. Only "Break-Even" is derived entirely from the rest. The other three tabs also have green cells you can edit: the pessimistic and optimistic scenarios in "Scenarios", seasonality and the launch ramp-up in "12-Month Cash Flow", and the other funding sources in "Financing" (rows 8-11 count as sources but are not amortized: Your bank or SBA 7(a) loan goes in "Loan requested" on "0. Assumptions"). Everything else is calculated.
A8: 4. All figures are EXCL. SALES TAX. To turn a menu price into a price excl. sales tax, divide it by 1 + your sales tax rate (with an 8% rate, divide by 1.08); if an item is taxed differently, use its own rate. The rate of each sales line is in the "Sales tax rate on the line (%)" column of the P&L, and from it come the receipts, the sales tax collected and the equivalent menu price incl. sales tax. On the bakery line, the tax-exempt share (bakery goods to go and wholesale for resale) carries no sales tax: check how your state treats it. With the default 0% recoverable input tax, the sales tax you pay on purchases and startup costs is treated as a cost; in the UK, enter 20% if you are VAT-registered.
A9: 5. If you change the staffing, the P&L reads it on its own: labor cost comes from the "Staffing" tab, not from a separate estimate.
A10: 6. The "12-Month Cash Flow" tab answers the question that decides a bank deal: in which month the cash runs out. The minimum balance of the year can never be in red.
A11: 7. The "Financing" tab matches what you need with what you put in and builds the amortization schedule of the loan. If the difference is red, the plan is not funded.
A12: 8. The Word business plan in this kit uses the same example figures as this workbook. The workbook is the one that recalculates on its own when you change a green cell: if you change one, update the matching figures in the Word document.
A14: RATIOS AUDITED BY THIS WORKBOOK
A15: Thresholds live in the "Threshold" column of the KEY RATIOS block of the P&L: change them there and the traffic light changes with them.
A17: Ratio | B17: Year 1 value | C17: Threshold | D17: Status
A18: Cost of goods sold / Sales | B18: =IFERROR(IF('3-Year P&L'!$B$53="","",'3-Year P&L'!$B$53),"") -> 0.288 | C18: =IFERROR(IF('3-Year P&L'!$E$53="","",'3-Year P&L'!$E$53),"") -> 0.33 | D18: =IFERROR(IF(OR(B18="",C18=""),"",IF(B18<=C18,"OK","REVIEW")),"") -> OK
A19: Labor cost / Sales | B19: =IFERROR(IF('3-Year P&L'!$B$54="","",'3-Year P&L'!$B$54),"") -> 0.33922581 | C19: =IFERROR(IF('3-Year P&L'!$E$54="","",'3-Year P&L'!$E$54),"") -> 0.38 | D19: =IFERROR(IF(OR(B19="",C19=""),"",IF(B19<=C19,"OK","REVIEW")),"") -> OK
A20: Rent / Sales | B20: =IFERROR(IF('3-Year P&L'!$B$55="","",'3-Year P&L'!$B$55),"") -> 0.077419355 | C20: =IFERROR(IF('3-Year P&L'!$E$55="","",'3-Year P&L'!$E$55),"") -> 0.1 | D20: =IFERROR(IF(OR(B20="",C20=""),"",IF(B20<=C20,"OK","REVIEW")),"") -> OK
A21: Net income / Sales | B21: =IFERROR(IF('3-Year P&L'!$B$56="","",'3-Year P&L'!$B$56),"") -> 0.059513989 | C21: =IFERROR(IF('3-Year P&L'!$E$56="","",'3-Year P&L'!$E$56),"") -> 0.05 | D21: =IFERROR(IF(OR(B21="",C21=""),"",IF(B21>=C21,"OK","REVIEW")),"") -> OK
A22: Gross margin / Sales | B22: =IFERROR(IF('3-Year P&L'!$B$51="","",'3-Year P&L'!$B$51),"") -> 0.627 | C22: =IFERROR(IF('3-Year P&L'!$E$51="","",'3-Year P&L'!$E$51),"") -> 0.6 | D22: =IFERROR(IF(OR(B22="",C22=""),"",IF(B22>=C22,"OK","REVIEW")),"") -> OK
A24: THIS PLAN'S KEY FIGURES
A25: Total startup costs (sum of the blocks) | B25: =IFERROR(IF('Startup Costs'!$B$31="","",'Startup Costs'!$B$31),"") -> 266709
A26: Total cash needed at launch | B26: =IFERROR(IF('Startup Costs'!$B$34="","",'Startup Costs'!$B$34),"") -> 266709
A27: Working capital funded | B27: =IFERROR(IF('Startup Costs'!$B$30="","",'Startup Costs'!$B$30),"") -> 84209
A28: Forecast year-1 revenue | B28: =IFERROR(IF('3-Year P&L'!$B$9="","",'3-Year P&L'!$B$9),"") -> 651000
A29: Year-1 net income | B29: =IFERROR(IF('3-Year P&L'!$B$48="","",'3-Year P&L'!$B$48),"") -> 38743.607
A30: Transactions per day for the ACCOUNTING break-even (depreciation included) | B30: =IFERROR(IF('Break-Even'!$B$15="","",'Break-Even'!$B$15),"") -> 183.42278
A31: Project payback (years), before debt | B31: =IFERROR(IF('12-Month Cash Flow'!$B$31="","",'12-Month Cash Flow'!$B$31),"") -> 2.6
A33: WHY THIS MODEL IS BUILT THIS WAY
A34: Item | B34: Common shortcut | C34: This workbook | D34: Why
A35: Labor cost in the P&L | B35: A typed-in number, disconnected from the staffing tab | C35: The total of the "Staffing" tab, by formula | D35: When the P&L and the staffing tab disagree, nobody knows which one to trust. Here both say the same thing, and if you change a salary the result changes on its own.
A36: Staffing | B36: A handful of full-time positions sized by guesswork | C36: Positions, including part-time lines, sized to the production shift and the shop hours you declare | D36: Sized to the hours that really have to be covered (the early production shift, the shop's opening hours and a line for vacation and day-off relief) and tested against the labor-cost ceiling in the P&L. No payroll line falls below the minimum wage in proportion to its FTE
