Workbook

Sheet 0. Assumptions
A1: ASSUMPTIONS — the RATES and DRIVERS of the model are typed here
A2: Change the GREEN cells: the rest of the workbook recalculates on its own. Expense items are typed on their own tab (also in green) and are not repeated here. Amounts are in US dollars (or your own currency).
A3: BUSINESS ACTIVITY
A4: Events per year (year-1 average) | B4: 170 | C4: Average number of events you serve per year, counting every corporate booking, wedding, private party and festival or farmers market day. It is the main volume driver of the whole workbook: the P&L, break-even and scenarios all read it, and years 2 and 3 grow in events. The example is a full-time owner-operator with an active corporate sales effort and two stations, not the average first year. Flashquotes shows about 15 bookings per operator per year on its own platform only, so do not read that as the events to expect. Compare this cell with the capacity row further down.
A5: Average price per guest (excl. sales tax, baristas included) | B5: 12.6 | C5: EXCL. sales tax, with the baristas, travel and extras included and the voluntary gratuity left out: the blended price per guest across everything you sell (hosted corporate and wedding bookings, private parties, festival days), not the price of any one package. Price per guest incl. sales tax = this value × (1 + your sales tax rate). Operators quote by booking and by hour, with a base fee plus an hourly rate (see the benchmarks table on the "Instructions" tab). The Pricing Calculator quotes per guest, per service hour and per drink: to bring a quote here, divide the revenue you bill in a year by the guests you serve in that year.
A6: Average guests per event | B6: 95 | C6: Average number of guests per event across your whole mix, from small private parties to weddings of well over a hundred guests. The typical Flashquotes booking is for 100 guests. At a festival or farmers market, every drink sold counts as one guest. Sales per event = guests × price per guest. One cell for the whole workbook: the P&L, break-even and scenarios all read it, so they always agree.
A7: Volume growth in year 2 | B7: 0.1 | C7: Growth in events in year 2 over year 1 (enter 0.10 for 10%). Kept conservative on purpose: repeat corporate clients build up slowly, wedding bookings are made months ahead, and two stations and a small team of baristas limit how fast you can grow.
A8: Volume growth in year 3 | B8: 0.06 | C8: Growth in events in year 3 over year 2, kept conservative for the same reason: corporate repeat business and planner referrals build up slowly, and two stations and your baristas limit how many events you can serve.
A9: Price per guest incl. sales tax (calculated) | B9: =IFERROR(IF($B$5="","",$B$5*(1+SUMPRODUCT('3-Year P&L'!$E$10:$E$11,'3-Year P&L'!$G$10:$G$11))),"") -> 13.608 | C9: =IFERROR("Price per guest excl. sales tax plus the weighted sales tax of your sales lines ("&TEXT(SUMPRODUCT('3-Year P&L'!$E$10:$E$11,'3-Year P&L'!$G$10:$G$11)*100,"0")&"%), rounded. In the US the quote adds sales tax on top, and many states tax the whole catering invoice (coffee service, baristas, add-ons and travel); in the UK, VAT is included in the price.","") -> Price per guest excl. sales tax plus the weighted sales tax of your sales lines (8%), rounded. In the US the quote adds sales tax on top, and many states tax the whole catering invoice (coffee service, baristas, add-ons and travel); in the UK, VAT is included in the price.
A10: SALES MIX AND COST OF GOODS SOLD
A11: COFFEE BAR PACKAGES share of sales (baristas, espresso drinks, batch & cold brew, milks, syrups, cups) | B11: 0.85 | C11: Share of sales that comes from coffee bar packages: the espresso bar with baristas, batch brew and cold brew, milks, syrups and compostable cups. It is an INPUT: change it here and the P&L, the cash flow and the sales tax collected recalculate on their own. The rest of your sales are add-ons.
A12: ADD-ONS share of sales (extra hours, branded cups & latte printing, pastries from a licensed bakery, travel fees) | B12: =IFERROR(IF(COUNT(B11)=0,"",1-B11),"") -> 0.15 | C12: Calculated as the remainder: coffee bar packages + add-ons = 100%. Add-ons are extra service hours, branded cups and latte printing, pastries from a licensed bakery and travel fees.
A13: Cost of goods on COFFEE BAR PACKAGE sales (beans, milks incl. oat milk, syrups, cold brew) | B13: 0.12 | C13: Cost of goods sold on coffee bar package sales: coffee (18 g, or 0.63 oz, per double), milk and oat milk, syrups and cold brew, with a 10% allowance for waste (purging, dialing in, leftover milk). Kit estimate built from an all-in cost of $0.75-1.50 per drink (grindkit.app). The cost of one drink from the calculator is not copied here: this cell is the average of your whole mix, and package revenue also pays for the baristas, so the share is lower than the 20-30% that GrindKit reports on drink revenue. It is the most sensitive lever in the plan: test it at the top of the range before you trust the result.
A14: Cost of goods on ADD-ON sales (pastries, branded cups, printing) | B14: 0.25 | C14: Cost of goods sold on add-ons: pastries bought from a licensed bakery, branded cups and printing ink. Extra hours and travel fees carry almost no cost of goods. Kit estimate.
A15: Compostable cups, lids, sleeves & napkins as % of sales | B15: 0.04 | C15: Compostable cups, lids, sleeves, wooden stirrers and napkins as a % of sales (about $0.30 per drink: Kit estimate). They are compostable because several cities require it (Seattle, as an example): check your local rules. The line scales with the number of drinks you serve. Fuel is NOT here: tow vehicle fuel has its own fixed line on the "3-Year P&L" tab, and generator fuel is in utilities.
A16: FESTIVALS & FARMERS MARKETS share of sales (guest-pay pop-ups) | B16: 0.05 | C16: Share of your sales that comes from festivals and farmers markets where each guest pays for their own drink, often with a minimum sales guarantee from the organizer. This is a side channel, not a delivery or marketplace channel. Set it to 0 if you only work hosted events. The organizer keeps a fee (next row).
A17: Organizer / vendor fee on those sales (booth fees converted to %) | B17: 0.15 | C17: Fee the organizer keeps on your festival and farmers market sales (Kit estimate). If you pay a flat booth fee instead, convert it into a percentage of what you expect to sell there. Not used while the festival share is 0%.
A18: Card processing fee | B18: 0.03 | C18: Card and ACH fees on total sales. Hosts pay their retainer and balance by card, festival guests almost always pay by card, and some companies pay by ACH or check, which lowers the cost. The example is a blended rate: a percentage plus a per-transaction fee, which weighs more on small orders. Check your processor's statement and enter your effective rate (Kit estimate).
A19: LABOR
A20: Employer payroll taxes | B20: 0.1 | C20: FICA (Social Security 6.2% + Medicare 1.45%) + federal and state unemployment taxes (FUTA / SUTA). Workers' comp is in the insurance line. The example uses a lean 10% with no benefits; ask your payroll provider for your rate.
A21: Monthly pay periods per year (keep 12) | B21: 12 | C21: Annual gross pay = monthly gross pay × this number. Keep 12 in the US: it counts the monthly salaries the model pays in a year, not how often you run payroll (weekly or biweekly payroll pays the same annual amount)
A22: Federal minimum wage, annual full-time | B22: 15080 | C22: US federal minimum wage: 7.25 per hour × 2,080 hours = 15,080 per year for a full-time job. Your state or city may set a higher floor: enter it in the state / local minimum wage cell below. Check the current rates at dol.gov
A23: COMMISSARY, CART STORAGE AND FIXED COSTS
A24: Commissary, cart storage & trailer parking, per month | B24: 700 | C24: Monthly cost of your commissary (a permitted shared kitchen), cart storage and trailer parking: one cell for everything you pay for the space. It covers filling potable water, dumping gray water, cold storage for the milk, dry storage and a place for the cart and the trailer. Carts typically pay $200-600 per month (cart-king.com) and shared kitchens charge roughly $15-45 per hour (The Food Corridor, 2023 Shared Kitchen Operator Survey). The deposit and the months before opening are calculated from it. Ask your health department in writing whether your county requires a commissary: many do, and some exempt self-contained units. Get quotes in your area before you sign.
A25: Commissary deposit (months) | B25: 1 | C25: Months of deposit on the commissary agreement. Many shared kitchens ask for one month up front: far less than the deposit on a commercial lease. Negotiate it in the written agreement.
A26: Monthly utilities (generator fuel, water and ice not covered by the commissary) | B26: 100 | C26: Generator fuel, water and ice that the commissary fee does not cover. The generator only runs at outdoor events, because most venues provide power, so this is a small fixed amount. Tow vehicle fuel is not here: it has its own fixed line on the "3-Year P&L" tab. It is the one cell for this cost, so you change it in one place and the rest of the workbook follows.
A27: Insurance (per year) | B27: 3800 | C27: General liability at $1M per occurrence and $2M aggregate with unlimited additional insureds, commercial auto that covers the trailer, workers' comp for your W-2 baristas and coverage for your equipment in transit. Venues ask for a certificate of insurance (COI) naming them as additional insured. There is no liquor liability line because this plan sells no alcohol. Insureon publishes averages for small businesses (see the benchmarks table on the "Instructions" tab); the example is a Kit estimate, so get quotes from an insurance agent. It is counted once, as an annual expense, not also in startup costs.
A28: Miscellaneous and contingency as % of sales | B28: 0.03 | C28: Extra milk, ice, cables and parking at the venue: the unbudgeted costs of each event. It is a VARIABLE cost: it rises and falls with the number of events, so it cannot sit among the fixed costs or it would move the break-even without anyone noticing. Tow vehicle fuel is not here: it has its own fixed line on the "3-Year P&L" tab.
A29: FINANCING
A30: Owner's equity contributed | B30: 30000 | C30: Your own money. Lenders usually expect an owner equity injection (often around 10% for SBA start-ups; many want 20-30%) on the total cash needed in this plan.
A31: Loan requested | B31: 71000 | C31: Principal requested: bank or SBA 7(a). The example loan is above the $50,000 ceiling of the SBA Microloan, so it fits an SBA 7(a) loan or a bank loan (or a Microloan with more of your own money). If your loan is an SBA 7(a), this is the cell. It is the only loan that the amortization schedule, the P&L interest and the DSCR use. The "Financing" tab checks that the sources of funds match the total cash needed on the "Startup Costs" tab (which includes working capital and the cart, portable bar, trailer and plan review contingency): copy the loan suggested there into this cell until the difference reaches zero. A lender will ask for your plan and projections.
A32: Nominal annual interest rate (not APR) | B32: 0.1 | C32: Nominal annual rate (not APR). The example (10%) is the kit's assumption for an SBA 7(a) loan. A smaller loan secured by a cart, a trailer and espresso equipment often prices above a storefront loan: ask two lenders for quotes, and ask about SBA-guaranteed loans, before you set it.
A33: Loan term (years) | B33: 7 | C33: Total years, interest-only period included. A cart, a portable bar, a trailer and espresso machines lose value faster than a storefront build-out, so the term is shorter. SBA 7(a) allows up to 10 years for equipment and working capital.
A34: Interest-only period (years) | B34: 0 | C34: ZERO by default: repayment starts in year 1, so the year-1 DSCR already measures the full loan payment. If you negotiate an interest-only first year, enter it here and read the year-1 DSCR with care.
A35: Working capital (months of fixed costs) | B35: 3 | C35: The minimum this workbook asks for (see "Instructions"): a cushion below 3 months does not cover a slow stretch, such as the summer dip in July and August or a corporate client who pays late.
A36: TAXES
A37: Effective income tax rate (years 1-2) | B37: 0.25 | C37: Example: 21% federal rate for a C corporation plus state tax, rounded to 25%. If you operate as a sole proprietorship, LLC taxed as a pass-through or S corporation, the business itself pays 0% here and you pay tax on the profit personally: set this to 0 and budget for your personal tax separately. The model applies this rate to the first two years with positive taxable income
A38: Effective income tax rate (from year 3) | B38: 0.25 | C38: From the third year with positive taxable income. Same example rate (21% federal C corporation + state). Confirm the rate that applies to you with your accountant and change it here
A39: Sales tax rate on sales | B39: 0.08 | C39: Example rate: state + local sales tax combined, applied to the whole invoice (coffee service, baristas, add-ons and travel). Hosted events are usually taxed as catering; at festivals and markets you collect it drink by drink and may need a permit where you sell. Rates and rules vary widely by state and city: look up yours. UK: 20% VAT applies to catering for events and functions (VAT Notice 709/1).
A40: Sales tax rate on alcohol sold (licensed only) | B40: 0.08 | C40: Same example rate as above. Some states add separate liquor taxes: include them here if they apply to you. Alcohol served on site has its own rate in the sales tax breakdown block, further down. Utilities, equipment and services are handled in the cell below
...

Sheet Startup Costs
A1: BUSINESS PLAN: COFFEE CART & COFFEE CATERING COMPANY
A2: Estimated Startup Costs
A3: US kit example (2026) — replace with your own quotes.
A5: Item | B5: Amount | C5: % of startup costs | D5: Notes | E5: Taxable / recoverable tax?
A6: STARTUP COSTS | B6: =IFERROR(IF(COUNT(B7:B23)=0,"",SUM(B7:B23)),"") -> 71290 | C6: =IFERROR(B6/$B$26,"") -> 0.71083715
A7: Espresso cart (NSF, hand sink, fresh & gray water tanks, pump & filtration, undercounter fridge) | B7: 13400 | C7: =IFERROR(B7/$B$26,"") -> 0.13361226 | D7: Espresso cart with NSF certification, handwashing sink, potable and gray water tanks (your county sets the volume), pump and filter, and an under-counter refrigerator. Prices run from a few thousand dollars for a basic new cart to well above that for a custom build (see the benchmarks table on the "Instructions" tab). Ask your county for its plan review checklist BEFORE you buy the cart. | E7: Yes
A8: Portable espresso bar for the second station (with undercounter fridge) | B8: 5400 | C8: =IFERROR(B8/$B$26,"") -> 0.053843745 | D8: Portable espresso bar for the second station and for indoor rooms, with an under-counter refrigerator (Kit estimate). It travels in the trailer with the cart. | E8: Yes
A9: Espresso machines: 2-group volumetric (220V) + compact 2-group | B9: 15700 | C9: =IFERROR(B9/$B$26,"") -> 0.1565457 | D9: A 2-group volumetric machine at 220V / 3,400 W (about $8,500-9,000 in store prices; NEMA 6-20 plug, 15-17 A, dedicated circuit) plus a compact 2-group machine for the second station (about $7,200, 14 A). Store prices are a Kit estimate: ask for two quotes. A room without a 220V circuit needs a generator. | E9: Yes
A10: Espresso grinders ×4 (house + decaf at each station) | B10: 4800 | C10: =IFERROR(B10/$B$26,"") -> 0.047861107 | D10: Four espresso grinders (house blend and decaf at each station), $300-3,000 each (cart-king.com). Burrs wear out sooner than the grinder: they go in the maintenance line of the "3-Year P&L" tab. | E10: Yes
A11: Enclosed cargo trailer (6×12 ft, ramp door) | B11: 6500 | C11: =IFERROR(B11/$B$26,"") -> 0.064811916 | D11: An enclosed cargo trailer, 6×12 ft with a ramp door, that carries the cart, the portable bar and the gear. Your own vehicle tows it ($0 in the example). If you do not have a tow vehicle, a used one runs about $18,000 and is not in the budget. | E11: Yes
A12: Trailer wrap, hitch, tie-downs & cart loading ramps | B12: 1500 | C12: =IFERROR(B12/$B$26,"") -> 0.014956596 | D12: Trailer wrap, hitch, tie-downs on E-track and ramps to roll the cart in and out. Check your vehicle's towing capacity and that your insurance covers the wrap and the hitch. | E12: Yes
A13: LLC formation, contracts and legal | B13: 1500 | C13: =IFERROR(B13/$B$26,"") -> 0.014956596 | D13: State filing fees for the LLC (Secretary of State) plus an attorney's review of your standard contract (retainer, cancellation tiers, final guest count, service hours, outlet or generator, rain plan) or a filing service; a registered agent is also needed. Fees vary a lot by state. The "Taxable / recoverable tax?" column is set to No: it only matters if you enter a recoverable input tax rate (for example UK VAT). | E13: No
A14: First-year permits and certifications (health permit, food handler cards, CFPM, fire / generator) | B14: 1400 | C14: =IFERROR(B14/$B$26,"") -> 0.01395949 | D14: Varies a lot by city, county and state: get the amounts for yours before you close the budget. Expect the health permit for the mobile food unit, food handler cards, a Certified Food Protection Manager (CFPM) certificate, the business license, the sales tax permit and, where required, a fire marshal permit for the generator. | E14: No
A15: Mobile food unit plan review & cart inspection | B15: 1100 | C15: =IFERROR(B15/$B$26,"") -> 0.01096817 | D15: Plan review of the mobile food unit and inspection of the cart. As an example, Snohomish County, WA charges $1,100 for the plan review (snohd.org); add any electrical approval your state asks for. Rules and fees vary by county, so ask the health department for its fee schedule. If nobody charges for it, enter 0. | E15: Yes
A16: POS, card readers & booking software | B16: 1000 | C16: =IFERROR(B16/$B$26,"") -> 0.009971064 | D16: POS with card readers (also for festivals), plus booking software for quotes, proposals and e-signatures. | E16: Yes
A17: Batch brewer, airpots, cold brew system, smallwares & commissary storage racks | B17: 3300 | C17: =IFERROR(B17/$B$26,"") -> 0.032904511 | D17: Batch brewer, airpots, a cold brew system, milk pitchers, scales, tampers, knock boxes, sanitizer buckets and storage racks for the commissary: the tools that get depreciated. Daily disposables are NOT depreciated: they go in the compostable cups line of the P&L, at the % of sales set in the "0. Assumptions" tab. | E17: Yes
A18: Opening inventory (beans, milks, syrups, compostable cups) | B18: 1500 | C18: =IFERROR(B18/$B$26,"") -> 0.014956596 | D18: Coffee for your tastings and first events, milks, syrups and compostable cups. With 0% recoverable input tax (the US default), any sales tax you pay on this purchase is treated as a cost. | E18: Yes
... A20: Power: inverter generator (5,500 W), cords & power distribution | B20: 5000 | C20: =IFERROR(B20/$B$26,"") -> 0.04985532 | D20: A 5,500 W continuous inverter generator (quiet, for rooms without an outlet and for outdoor events), cords of the right gauge and a power strip with GFCI. Your fire marshal may ask for a minimum distance and a fire extinguisher: ask before you buy. | E20: Yes
A21: Commissary deposit | B21: =IFERROR(IF('0. Assumptions'!$B$24="","",'0. Assumptions'!$B$24*'0. Assumptions'!$B$25),"") -> 700 | C21: =IFERROR(B21/$B$26,"") -> 0.0069797448 | D21: =IFERROR(""&TEXT('0. Assumptions'!$B$25,"0")&IF('0. Assumptions'!$B$25=1," month"," months")&" of rent, from ""0. Assumptions"". Refundable when the commissary agreement ends: it is not depreciated and carries no tax","") -> 1 month of rent, from "0. Assumptions". Refundable when the commissary agreement ends: it is not depreciated and carries no tax | E21: No
A22: Commissary rent before opening | B22: =IFERROR(IF('0. Assumptions'!$B$24="","",'0. Assumptions'!$B$24*'0. Assumptions'!$B$54),"") -> 700 | C22: =IFERROR(B22/$B$26,"") -> 0.0069797448 | D22: =IFERROR("Rent "&IF('0. Assumptions'!$B$54=1,"for the month","for the "&TEXT('0. Assumptions'!$B$54,"0")&" months")&" of plan review, test events and pre-sales before opening. It does not overlap the P&L, which starts on opening day: its twelve months are twelve trading months","") -> Rent for the month of plan review, test events and pre-sales before opening. It does not overlap the P&L, which starts on opening day: its twelve months are twelve trading months | E22: Yes
A23: Cart, bar, trailer and plan review contingency | B23: =IFERROR(IF(COUNT(B7,B8,B11,B12,B15)=0,"",ROUND((B7+B8+B11+B12+B15)*'0. Assumptions'!$B$55,0)),"") -> 2790 | C23: =IFERROR(B23/$B$26,"") -> 0.027819268 | D23: =IFERROR("At "&TEXT('0. Assumptions'!$B$55,"0%")&" of the BUILD-OUT items of this block (espresso cart, portable espresso bar, enclosed cargo trailer, trailer wrap and hitch, and the mobile food unit plan review), not of the whole block: the other items are left out. No lender funds a build-out without a cushion: the percentage is in ""0. Assumptions""","") -> At 10% of the BUILD-OUT items of this block (espresso cart, portable espresso bar, enclosed cargo trailer, trailer wrap and hitch, and the mobile food unit plan review), not of the whole block: the other items are left out. No lender funds a build-out without a cushion: the percentage is in "0. Assumptions" | E23: Yes
A24: WORKING CAPITAL | B24: =IFERROR(IF(B25="","",B25),"") -> 29000.2 | C24: =IFERROR(B24/$B$26,"") -> 0.28916285
A25: Operating cushion until break-even | B25: =IFERROR(IF('0. Assumptions'!$B$35*('3-Year P&L'!$B$38-'3-Year P&L'!$B$36)=0,"",'0. Assumptions'!$B$35*('3-Year P&L'!$B$38-'3-Year P&L'!$B$36)/12),"") -> 29000.2 | C25: =IFERROR(B25/$B$26,"") -> 0.28916285 | D25: =IFERROR("Covers "&TEXT('0. Assumptions'!$B$35,"0")&IF('0. Assumptions'!$B$35=1," month"," months")&" of year-1 CASH fixed costs (the P&L fixed costs minus depreciation, which is not paid out), the minimum the Instructions of this workbook ask for","") -> Covers 3 months of year-1 CASH fixed costs (the P&L fixed costs minus depreciation, which is not paid out), the minimum the Instructions of this workbook ask for | E25: No
A26: TOTAL STARTUP COSTS (sum of the blocks) | B26: =IFERROR(B6+B24,"") -> 100290.2 | D26: =IFERROR("The percentages in column C are read on this figure, which includes the working capital ("&TEXT(C24,"0%")&" of the total). To compare the breakdown with another plan, use the CAPEX row below.","") -> The percentages in column C are read on this figure, which includes the working capital (29% of the total). To compare the breakdown with another plan, use the CAPEX row below.
A27: CAPEX (startup costs excluding working capital) | B27: =IFERROR(B26-B24,"") -> 71290 | D27: What you buy: the cart and the portable bar, the espresso machines and grinders, the trailer, power, launch and formation costs. The cash cushion is not an investment: it is working capital.
A28: Recoverable input tax on capex | B28: =IFERROR(IF(B26="","",SUMIF($E$7:$E$23,"Yes",$B$7:$B$23)*'0. Assumptions'!$B$41),"") -> 0 | D28: =IFERROR("At "&TEXT('0. Assumptions'!$B$41,"0%")&" on the items marked ""Yes"" in the tax column. US: the sales tax you pay on equipment is part of its cost and is not recovered, so this rate is 0. UK (VAT-registered): 20%, reclaimed on your VAT return, but you pay it first, so the loan has to cover it","") -> At 0% on the items marked "Yes" in the tax column. US: the sales tax you pay on equipment is part of its cost and is not recovered, so this rate is 0. UK (VAT-registered): 20%, reclaimed on your VAT return, but you pay it first, so the loan has to cover it
A29: TOTAL CASH NEEDED AT LAUNCH | B29: =IFERROR(B26+B28,"") -> 100290.2 | D29: This is the figure the Financing tab has to cover
A30: DEPRECIATION BASES (not added to startup costs)
A31: Espresso cart, portable bar, trailer, wrap and plan review (depreciated over the cart life) | B31: =IFERROR(IF(B7="","",B7+B8+B11+B12+B15+B23),"") -> 30690 | D31: =IFERROR("Depreciated over "&TEXT('0. Assumptions'!$B$44,"0")&" years","") -> Depreciated over 7 years
A32: Machinery, furniture and equipment | B32: =IFERROR(IF(B9="","",B9+B10+B16+B17+B20),"") -> 29800 | D32: =IFERROR("Depreciated over "&TEXT('0. Assumptions'!$B$45,"0")&" years","") -> Depreciated over 5 years
A33: Annual depreciation of fixed assets | B33: =IFERROR(B31/MAX(1,'0. Assumptions'!$B$44)+B32/MAX(1,'0. Assumptions'!$B$45),"") -> 10344.286 | D33: =IFERROR("Not depreciated, because they are not fixed assets: LLC formation and legal, first-year permits and certifications, opening inventory, website, photos and launch, the commissary deposit, pre-opening commissary rent and the working capital reserve. They add up to "&TEXT(B26-B31-B32,"#,##0")&" of the "&TEXT(B26,"#,##0")&" total investment.","") -> Not depreciated, because they are not fixed assets: LLC formation and legal, first-year permits and certifications, opening inventory, website, photos and launch, the commissary deposit, pre-opening commissary rent and the working capital reserve. They add up to 39800 of the 100290 total investment.

Sheet 3-Year P&L
A1: PRO FORMA P&L — 3 YEARS
A2: Base case — coffee catering company with two espresso stations
A4: Item | B4: Year 1 | C4: Year 2 | D4: Year 3 | E4: % of sales (year 1) | F4: Notes | G4: Sales tax rate on the line (%)
A5: REVENUE
A6: Events per year (average) | B6: =IFERROR(IF('0. Assumptions'!$B$4="","",'0. Assumptions'!$B$4),"") -> 170 | C6: =IFERROR(B6*(1+'0. Assumptions'!$B$7),"") -> 187 | D6: =IFERROR(C6*(1+'0. Assumptions'!$B$8),"") -> 198.22 | F6: Growth for years 2 and 3 is set in "0. Assumptions"
A7: Average price per guest (excl. sales tax) | B7: =IFERROR(IF('0. Assumptions'!$B$5="","",'0. Assumptions'!$B$5),"") -> 12.6 | C7: =IFERROR(IF(B7="","",B7),"") -> 12.6 | D7: =IFERROR(IF(C7="","",C7),"") -> 12.6 | F7: Held constant at year-1 prices: a price increase is a separate decision
A8: Average guests per event | B8: =IFERROR(IF('0. Assumptions'!$B$6="","",'0. Assumptions'!$B$6),"") -> 95 | C8: =IFERROR(IF(B8="","",B8),"") -> 95 | D8: =IFERROR(IF(C8="","",C8),"") -> 95
A9: TOTAL REVENUE (excl. sales tax) | B9: =IFERROR(IF(B6*B7*B8=0,"",B6*B7*B8),"") -> 203490 | C9: =IFERROR(IF(C6*C7*C8=0,"",C6*C7*C8),"") -> 223839 | D9: =IFERROR(IF(D6*D7*D8=0,"",D6*D7*D8),"") -> 237269.34 | E9: =IFERROR(IF(B9="","",1),"") -> 1
A10: Coffee bar package sales (baristas, espresso drinks, batch & cold brew, milks, syrups, cups) | B10: =IFERROR(IF(B9="","",B9*$E$10),"") -> 172966.5 | C10: =IFERROR(IF(C9="","",C9*$E$10),"") -> 190263.15 | D10: =IFERROR(IF(D9="","",D9*$E$10),"") -> 201678.94 | E10: =IFERROR(IF('0. Assumptions'!$B$11="","",'0. Assumptions'!$B$11),"") -> 0.85 | F10: Sales of coffee bar packages: the espresso bar with baristas, batch brew and cold brew, milks, syrups and compostable cups, across corporate events, weddings, private parties and festival days. All of it carries cost of goods sold at the package rate. | G10: =IFERROR(IF(B9="","",'0. Assumptions'!$B$39),"") -> 0.08
A11: Add-on sales (extra hours, branded cups & latte printing, pastries, travel fees) | B11: =IFERROR(IF(B9="","",B9*$E$11),"") -> 30523.5 | C11: =IFERROR(IF(C9="","",C9*$E$11),"") -> 33575.85 | D11: =IFERROR(IF(D9="","",D9*$E$11),"") -> 35590.401 | E11: =IFERROR(IF('0. Assumptions'!$B$12="","",'0. Assumptions'!$B$12),"") -> 0.15 | F11: Sales of add-ons: extra hours, branded cups and latte printing, pastries from a licensed bakery and travel fees. There is no alcohol revenue. | G11: =IFERROR(IF(B9="","",('0. Assumptions'!$B$62*((1-'0. Assumptions'!$B$16)*'0. Assumptions'!$B$63+'0. Assumptions'!$B$16*'0. Assumptions'!$B$40)+(1-'0. Assumptions'!$B$62)*'0. Assumptions'!$B$39)),"") -> 0.08
A12: VARIABLE COSTS
A13: Cost of goods — coffee bar packages (beans, milks, syrups, cold brew) | B13: =IFERROR(IF(B9="","",B9*'0. Assumptions'!$B$11*'0. Assumptions'!$B$13),"") -> 20755.98 | C13: =IFERROR(IF(C9="","",C9*'0. Assumptions'!$B$11*'0. Assumptions'!$B$13),"") -> 22831.578 | D13: =IFERROR(IF(D9="","",D9*'0. Assumptions'!$B$11*'0. Assumptions'!$B$13),"") -> 24201.473 | E13: =IFERROR(B13/$B$9,"") -> 0.102 | F13: =IFERROR("At "&TEXT('0. Assumptions'!$B$13,"0%")&" of COFFEE BAR PACKAGE sales (beans, milks, syrups and cold brew, with waste), not of total sales: add-ons have their own line","") -> At 12% of COFFEE BAR PACKAGE sales (beans, milks, syrups and cold brew, with waste), not of total sales: add-ons have their own line | G13: =IFERROR(IF(B9="","",'0. Assumptions'!$B$41),"") -> 0
A14: Cost of goods — add-ons | B14: =IFERROR(IF(B9="","",B9*'0. Assumptions'!$B$12*'0. Assumptions'!$B$14),"") -> 7630.875 | C14: =IFERROR(IF(C9="","",C9*'0. Assumptions'!$B$12*'0. Assumptions'!$B$14),"") -> 8393.9625 | D14: =IFERROR(IF(D9="","",D9*'0. Assumptions'!$B$12*'0. Assumptions'!$B$14),"") -> 8897.6003 | E14: =IFERROR(B14/$B$9,"") -> 0.0375 | F14: =IFERROR("At "&TEXT('0. Assumptions'!$B$14,"0%")&" of ADD-ON sales","") -> At 25% of ADD-ON sales | G14: =IFERROR(IF(B9="","",'0. Assumptions'!$B$41),"") -> 0
A15: Compostable cups, lids, sleeves & napkins | B15: =IFERROR(IF(B9="","",B9*'0. Assumptions'!$B$15),"") -> 8139.6 | C15: =IFERROR(IF(C9="","",C9*'0. Assumptions'!$B$15),"") -> 8953.56 | D15: =IFERROR(IF(D9="","",D9*'0. Assumptions'!$B$15),"") -> 9490.7736 | E15: =IFERROR(B15/$B$9,"") -> 0.04 | G15: =IFERROR(IF(B9="","",'0. Assumptions'!$B$41),"") -> 0
A16: Festival & market organizer fees | B16: =IFERROR(IF(B9="","",B9*'0. Assumptions'!$B$16*'0. Assumptions'!$B$17),"") -> 1526.175 | C16: =IFERROR(IF(C9="","",C9*'0. Assumptions'!$B$16*'0. Assumptions'!$B$17),"") -> 1678.7925 | D16: =IFERROR(IF(D9="","",D9*'0. Assumptions'!$B$16*'0. Assumptions'!$B$17),"") -> 1779.5201 | E16: =IFERROR(B16/$B$9,"") -> 0.0075 | F16: Applied to the sales of THAT CHANNEL. With 0% festival and farmers market sales in "0. Assumptions", this line is zero | G16: =IFERROR(IF(B9="","",'0. Assumptions'!$B$41),"") -> 0
A17: Card processing fees | B17: =IFERROR(IF(B9="","",B9*'0. Assumptions'!$B$18),"") -> 6104.7 | C17: =IFERROR(IF(C9="","",C9*'0. Assumptions'!$B$18),"") -> 6715.17 | D17: =IFERROR(IF(D9="","",D9*'0. Assumptions'!$B$18),"") -> 7118.0802 | E17: =IFERROR(B17/$B$9,"") -> 0.03 | F17: Card processing fees are not subject to sales tax: no tax is recovered or deducted for them | G17: 0
A18: Miscellaneous and contingency | B18: =IFERROR(IF(B9="","",B9*'0. Assumptions'!$B$28),"") -> 6104.7 | C18: =IFERROR(IF(C9="","",C9*'0. Assumptions'!$B$28),"") -> 6715.17 | D18: =IFERROR(IF(D9="","",D9*'0. Assumptions'!$B$28),"") -> 7118.0802 | E18: =IFERROR(B18/$B$9,"") -> 0.03 | F18: =IFERROR("At "&TEXT('0. Assumptions'!$B$28,"0%")&" of sales: a cushion for unbudgeted event costs (extra milk, ice, cables, venue parking). It is a VARIABLE cost: it moves with the number of events, so it cannot sit in fixed costs (tow vehicle and trailer fuel, maintenance and registration are in row 27; generator fuel is in utilities)","") -> At 3% of sales: a cushion for unbudgeted event costs (extra milk, ice, cables, venue parking). It is a VARIABLE cost: it moves with the number of events, so it cannot sit in fixed costs (tow vehicle and trailer fuel, maintenance and registration are in row 27; generator fuel is in utilities) | G18: =IFERROR(IF(B9="","",'0. Assumptions'!$B$41),"") -> 0
A19: TOTAL VARIABLE COSTS | B19: =IFERROR(IF(B9="","",SUM(B13:B18)),"") -> 50262.03 | C19: =IFERROR(IF(C9="","",SUM(C13:C18)),"") -> 55288.233 | D19: =IFERROR(IF(D9="","",SUM(D13:D18)),"") -> 58605.527 | E19: =IFERROR(B19/$B$9,"") -> 0.247
A20: GROSS MARGIN | B20: =IFERROR(IF(B9="","",B9-B19),"") -> 153227.97 | C20: =IFERROR(IF(C9="","",C9-C19),"") -> 168550.77 | D20: =IFERROR(IF(D9="","",D9-D19),"") -> 178663.81 | E20: =IFERROR(B20/$B$9,"") -> 0.753
A21: FIXED COSTS
A22: Commissary, cart storage & trailer parking | B22: =IFERROR(IF(B9="","",'0. Assumptions'!$B$24*12),"") -> 8400 | C22: =IFERROR(IF(C9="","",B22*(1+'0. Assumptions'!$B$48)),"") -> 8400 | D22: =IFERROR(IF(D9="","",C22*(1+'0. Assumptions'!$B$48)),"") -> 8400 | E22: =IFERROR(B22/$B$9,"") -> 0.04127967 | F22: The monthly amount is typed in "0. Assumptions"; here it is multiplied by twelve. It covers your commissary hours, cart storage and trailer parking, not storefront rent. The months before opening are on the "Startup Costs" tab and are NOT counted twice. | G22: =IFERROR(IF(B9="","",'0. Assumptions'!$B$41),"") -> 0
A23: Labor (wages + employer payroll taxes) | B23: =IFERROR(IF(B9="","",Staffing!$G$9),"") -> 74500.8 | C23: =IFERROR(IF(C9="","",Staffing!$B$13),"") -> 77500.8 | D23: =IFERROR(IF(D9="","",Staffing!$B$14),"") -> 80500.8 | E23: =IFERROR(B23/$B$9,"") -> 0.36611529 | F23: Comes from the Staffing tab: it is the SAME number, not a separate estimate. Years 2 and 3 add the new hires declared on that tab, not a percentage of volume | G23: 0
A24: Utilities (generator fuel, water and ice not covered by the commissary) | B24: =IFERROR(IF(B9="","",'0. Assumptions'!$B$26*12),"") -> 1200 | C24: =IFERROR(IF(C9="","",B24*(1+'0. Assumptions'!$B$48)),"") -> 1200 | D24: =IFERROR(IF(D9="","",C24*(1+'0. Assumptions'!$B$48)),"") -> 1200 | E24: =IFERROR(B24/$B$9,"") -> 0.0058970957 | F24: Generator fuel, water and ice that the commissary fee does not cover. Tow vehicle fuel is not here: it has its own fixed line on this tab. | G24: =IFERROR(IF(B9="","",'0. Assumptions'!$B$41),"") -> 0
A25: Insurance (general liability, commercial auto with the trailer, workers' comp, equipment) | B25: =IFERROR(IF(B9="","",'0. Assumptions'!$B$27),"") -> 3800 | C25: =IFERROR(IF(C9="","",B25*(1+'0. Assumptions'!$B$48)),"") -> 3800 | D25: =IFERROR(IF(D9="","",C25*(1+'0. Assumptions'!$B$48)),"") -> 3800 | E25: =IFERROR(B25/$B$9,"") -> 0.018674136 | F25: Insurance premiums are not subject to sales tax: there is no recoverable tax on them | G25: 0
A26: Annual permits and licenses (health permit renewal, temporary event and fire / generator permits) | B26: 1500 | C26: =IFERROR(IF(C9="","",B26*(1+'0. Assumptions'!$B$48)),"") -> 1500 | D26: =IFERROR(IF(D9="","",C26*(1+'0. Assumptions'!$B$48)),"") -> 1500 | E26: =IFERROR(B26/$B$9,"") -> 0.0073713696 | G26: =IFERROR(IF(B9="","",'0. Assumptions'!$B$41),"") -> 0
A27: Tow vehicle & trailer fuel, maintenance and registration | B27: 3500 | C27: =IFERROR(IF(C9="","",B27*(1+'0. Assumptions'!$B$48)),"") -> 3500 | D27: =IFERROR(IF(D9="","",C27*(1+'0. Assumptions'!$B$48)),"") -> 3500 | E27: =IFERROR(B27/$B$9,"") -> 0.017199862 | G27: =IFERROR(IF(B9="","",'0. Assumptions'!$B$41),"") -> 0
A28: Marketing and advertising | B28: 8000 | C28: =IFERROR(IF(C9="","",B28*(1+'0. Assumptions'!$B$48)),"") -> 8000 | D28: =IFERROR(IF(D9="","",C28*(1+'0. Assumptions'!$B$48)),"") -> 8000 | E28: =IFERROR(B28/$B$9,"") -> 0.039313971 | G28: =IFERROR(IF(B9="","",'0. Assumptions'!$B$41),"") -> 0
A29: Accounting / bookkeeping | B29: 2400 | C29: =IFERROR(IF(C9="","",B29*(1+'0. Assumptions'!$B$48)),"") -> 2400 | D29: =IFERROR(IF(D9="","",C29*(1+'0. Assumptions'!$B$48)),"") -> 2400 | E29: =IFERROR(B29/$B$9,"") -> 0.011794191 | G29: =IFERROR(IF(B9="","",'0. Assumptions'!$B$41),"") -> 0
A30: Software (quotes / booking / CRM, POS, e-signature, website) | B30: 1500 | C30: =IFERROR(IF(C9="","",B30*(1+'0. Assumptions'!$B$48)),"") -> 1500 | D30: =IFERROR(IF(D9="","",C30*(1+'0. Assumptions'!$B$48)),"") -> 1500 | E30: =IFERROR(B30/$B$9,"") -> 0.0073713696 | G30: =IFERROR(IF(B9="","",'0. Assumptions'!$B$41),"") -> 0
A31: Linens, signage, aprons and smallwares replacement | B31: 600 | C31: =IFERROR(IF(C9="","",B31*(1+'0. Assumptions'!$B$48)),"") -> 600 | D31: =IFERROR(IF(D9="","",C31*(1+'0. Assumptions'!$B$48)),"") -> 600 | E31: =IFERROR(B31/$B$9,"") -> 0.0029485478 | G31: =IFERROR(IF(B9="","",'0. Assumptions'!$B$41),"") -> 0
A32: Phone, internet & card-reader data plans | B32: 900 | C32: =IFERROR(IF(C9="","",B32*(1+'0. Assumptions'!$B$48)),"") -> 900 | D32: =IFERROR(IF(D9="","",C32*(1+'0. Assumptions'!$B$48)),"") -> 900 | E32: =IFERROR(B32/$B$9,"") -> 0.0044228218 | F32: Phone, internet and the data plans of your card readers and POS. Small, fixed and easy to forget. | G32: =IFERROR(IF(B9="","",'0. Assumptions'!$B$41),"") -> 0
A33: Espresso machine service, water filters & grinder burrs | B33: 1800 | C33: =IFERROR(IF(C9="","",B33*(1+'0. Assumptions'!$B$48)),"") -> 1800 | D33: =IFERROR(IF(D9="","",C33*(1+'0. Assumptions'!$B$48)),"") -> 1800 | E33: =IFERROR(B33/$B$9,"") -> 0.0088456435 | F33: Service for the espresso machines, water filters and grinder burrs. Gaskets and burrs wear out before the machine does. | G33: =IFERROR(IF(B9="","",'0. Assumptions'!$B$41),"") -> 0
A34: Food safety & barista training (CFPM, food handler cards) | B34: 400 | C34: =IFERROR(IF(C9="","",B34*(1+'0. Assumptions'!$B$48)),"") -> 400 | D34: =IFERROR(IF(D9="","",C34*(1+'0. Assumptions'!$B$48)),"") -> 400 | E34: =IFERROR(B34/$B$9,"") -> 0.0019656986 | F34: Certified Food Protection Manager (CFPM) and food handler cards for you and your team, plus their renewals, and barista training. The required cards vary by state. | G34: =IFERROR(IF(B9="","",'0. Assumptions'!$B$41),"") -> 0
A35: Tastings for prospects (corporate open house, couples) | B35: 400 | C35: =IFERROR(IF(C9="","",B35*(1+'0. Assumptions'!$B$48)),"") -> 400 | D35: =IFERROR(IF(D9="","",C35*(1+'0. Assumptions'!$B$48)),"") -> 400 | E35: =IFERROR(B35/$B$9,"") -> 0.0019656986 | F35: Food cost and labor for the tastings you offer couples and companies (a bridal tasting or a corporate open house). Many operators charge a fee and credit it toward the booking: if you do, lower this line. | G35: =IFERROR(IF(B9="","",'0. Assumptions'!$B$41),"") -> 0
A36: Depreciation of fixed assets | B36: =IFERROR(IF(B9="","",'Startup Costs'!$B$33),"") -> 10344.286 | C36: =IFERROR(IF(C9="","",B36),"") -> 10344.286 | D36: =IFERROR(IF(D9="","",B36),"") -> 10344.286 | E36: =IFERROR(B36/$B$9,"") -> 0.050834369 | F36: Comes from the depreciation bases on the Startup Costs tab: real fixed assets only. It does NOT rise with inflation: it is a charge on the HISTORICAL cost of the assets | G36: 0
A37: Interest expense (loan interest) | B37: =IFERROR(IF(B9="","",Financing!$B$44),"") -> 7100 | C37: =IFERROR(IF(C9="","",Financing!$B$46),"") -> 6351.621 | D37: =IFERROR(IF(D9="","",Financing!$B$48),"") -> 5528.404 | E37: =IFERROR(B37/$B$9,"") -> 0.034891149 | F37: Only INTEREST is an expense. Principal repaid appears on the cash flow tab | G37: 0
A38: TOTAL FIXED COSTS | B38: =IFERROR(IF(B9="","",SUM(B22:B37)),"") -> 126345.09 | C38: =IFERROR(IF(C9="","",SUM(C22:C37)),"") -> 128596.71 | D38: =IFERROR(IF(D9="","",SUM(D22:D37)),"") -> 130773.49 | E38: =IFERROR(B38/$B$9,"") -> 0.62089088
A39: Recoverable input tax on variable costs | B39: =IFERROR(IF(B9="","",SUMPRODUCT(B13:B18,G13:G18)),"") -> 0 | C39: =IFERROR(IF(C9="","",SUMPRODUCT(C13:C18,G13:G18)),"") -> 0 | D39: =IFERROR(IF(D9="","",SUMPRODUCT(D13:D18,G13:G18)),"") -> 0 | F39: Each line at ITS OWN rate, read from the column next to it. It is what the cash flow tab overpays to suppliers and later deducts (zero wherever no tax is recoverable)
A40: Recoverable input tax on fixed costs | B40: =IFERROR(IF(B9="","",SUMPRODUCT(B22:B37,G22:G37)),"") -> 0 | C40: =IFERROR(IF(C9="","",SUMPRODUCT(C22:C37,G22:G37)),"") -> 0 | D40: =IFERROR(IF(D9="","",SUMPRODUCT(D22:D37,G22:G37)),"") -> 0
A41: PRE-TAX INCOME (EBT) | B41: =IFERROR(IF(B9="","",B20-B38),"") -> 26882.884 | C41: =IFERROR(IF(C9="","",C20-C38),"") -> 39954.06 | D41: =IFERROR(IF(D9="","",D20-D38),"") -> 47890.323 | E41: =IFERROR(B41/$B$9,"") -> 0.13210912
...

Sheet Break-Even
A1: BREAK-EVEN ANALYSIS
A2: Break-even — Coffee Cart
A4: Variable | B4: Year 1 | C4: Year 2 | D4: Year 3 | E4: Notes
A5: BASE DATA BY YEAR
A6: Annual fixed costs | B6: =IFERROR(IF('3-Year P&L'!$B$9="","",'3-Year P&L'!$B$38),"") -> 126345.09 | C6: =IFERROR(IF('3-Year P&L'!$C$9="","",'3-Year P&L'!$C$38),"") -> 128596.71 | D6: =IFERROR(IF('3-Year P&L'!$D$9="","",'3-Year P&L'!$D$38),"") -> 130773.49 | E6: The SAME fixed costs as the P&L. Each year has its own, which is why the threshold cannot be a single one for all three years
A7: Monthly fixed costs | B7: =IFERROR(IF('3-Year P&L'!$B$9="","",B6/12),"") -> 10528.757 | C7: =IFERROR(IF('3-Year P&L'!$C$9="","",C6/12),"") -> 10716.392 | D7: =IFERROR(IF('3-Year P&L'!$D$9="","",D6/12),"") -> 10897.791
A8: Average price per guest (excl. sales tax) | B8: =IFERROR(IF('3-Year P&L'!$B$9="","",'3-Year P&L'!$B$7),"") -> 12.6 | C8: =IFERROR(IF('3-Year P&L'!$C$9="","",'3-Year P&L'!$C$7),"") -> 12.6 | D8: =IFERROR(IF('3-Year P&L'!$D$9="","",'3-Year P&L'!$D$7),"") -> 12.6
A9: Variable cost per guest | B9: =IFERROR(IF('3-Year P&L'!$B$9="","",'3-Year P&L'!$B$19/('3-Year P&L'!$B$6*'3-Year P&L'!$B$8)),"") -> 3.1122 | C9: =IFERROR(IF('3-Year P&L'!$C$9="","",'3-Year P&L'!$C$19/('3-Year P&L'!$C$6*'3-Year P&L'!$C$8)),"") -> 3.1122 | D9: =IFERROR(IF('3-Year P&L'!$D$9="","",'3-Year P&L'!$D$19/('3-Year P&L'!$D$6*'3-Year P&L'!$D$8)),"") -> 3.1122 | E9: Comes from the P&L total variable costs, not from a separate estimate. It includes miscellaneous and contingency, which is a percentage of sales
A10: Contribution margin per guest | B10: =IFERROR(IF('3-Year P&L'!$B$9="","",B8-B9),"") -> 9.4878 | C10: =IFERROR(IF('3-Year P&L'!$C$9="","",C8-C9),"") -> 9.4878 | D10: =IFERROR(IF('3-Year P&L'!$D$9="","",D8-D9),"") -> 9.4878 | E10: Price per guest minus variable cost per guest
A11: Average guests per event | B11: =IFERROR(IF('3-Year P&L'!$B$9="","",'3-Year P&L'!$B$8),"") -> 95 | C11: =IFERROR(IF('3-Year P&L'!$C$9="","",'3-Year P&L'!$C$8),"") -> 95 | D11: =IFERROR(IF('3-Year P&L'!$D$9="","",'3-Year P&L'!$D$8),"") -> 95 | E11: The same calendar as the P&L and the scenarios
A12: Principal repaid in the year | B12: =IFERROR(IF('3-Year P&L'!$B$9="","",Financing!$B$45),"") -> 7483.7905 | C12: =IFERROR(IF('3-Year P&L'!$C$9="","",Financing!$B$47),"") -> 8232.1695 | D12: =IFERROR(IF('3-Year P&L'!$D$9="","",Financing!$B$49),"") -> 9055.3865 | E12: Principal is NOT a P&L expense, but it leaves the cash account. Without it, the published break-even threshold would sit below the real one
A13: ACCOUNTING BREAK-EVEN (includes depreciation)
A14: Guests needed per year | B14: =IFERROR(IF('3-Year P&L'!$B$9="","",IF(B10<=0,"",B6/B10)),"") -> 13316.584 | C14: =IFERROR(IF('3-Year P&L'!$C$9="","",IF(C10<=0,"",C6/C10)),"") -> 13553.902 | D14: =IFERROR(IF('3-Year P&L'!$D$9="","",IF(D10<=0,"",D6/D10)),"") -> 13783.331
A15: Events needed per year | B15: =IFERROR(IF('3-Year P&L'!$B$9="","",B14/B11),"") -> 140.17457 | C15: =IFERROR(IF('3-Year P&L'!$C$9="","",C14/C11),"") -> 142.67265 | D15: =IFERROR(IF('3-Year P&L'!$D$9="","",D14/D11),"") -> 145.0877
A16: Revenue needed per year | B16: =IFERROR(IF('3-Year P&L'!$B$9="","",B14*B8),"") -> 167788.96 | C16: =IFERROR(IF('3-Year P&L'!$C$9="","",C14*C8),"") -> 170779.16 | D16: =IFERROR(IF('3-Year P&L'!$D$9="","",D14*D8),"") -> 173669.97
A17: CASH BREAK-EVEN (loan payments in, depreciation out)
A18: Cash fixed costs + principal repaid for the year | B18: =IFERROR(IF('3-Year P&L'!$B$9="","",B6-'3-Year P&L'!$B$36+B12),"") -> 123484.59 | C18: =IFERROR(IF('3-Year P&L'!$C$9="","",C6-'3-Year P&L'!$C$36+C12),"") -> 126484.59 | D18: =IFERROR(IF('3-Year P&L'!$D$9="","",D6-'3-Year P&L'!$D$36+D12),"") -> 129484.59 | E18: The P&L fixed costs without depreciation (which is not paid in cash) and WITH principal repaid (which is). This is the threshold that decides whether cash holds up
A19: Guests needed per year (cash) | B19: =IFERROR(IF('3-Year P&L'!$B$9="","",IF(B10<=0,"",B18/B10)),"") -> 13015.092 | C19: =IFERROR(IF('3-Year P&L'!$C$9="","",IF(C10<=0,"",C18/C10)),"") -> 13331.288 | D19: =IFERROR(IF('3-Year P&L'!$D$9="","",IF(D10<=0,"",D18/D10)),"") -> 13647.483
A20: Events needed per year (cash) | B20: =IFERROR(IF('3-Year P&L'!$B$9="","",B19/B11),"") -> 137.00097 | C20: =IFERROR(IF('3-Year P&L'!$C$9="","",C19/C11),"") -> 140.32934 | D20: =IFERROR(IF('3-Year P&L'!$D$9="","",D19/D11),"") -> 143.65772
A21: Revenue needed per year (cash) | B21: =IFERROR(IF('3-Year P&L'!$B$9="","",B19*B8),"") -> 163990.16 | C21: =IFERROR(IF('3-Year P&L'!$C$9="","",C19*C8),"") -> 167974.22 | D21: =IFERROR(IF('3-Year P&L'!$D$9="","",D19*D8),"") -> 171958.29
A22: COMPARISON WITH THE PLAN
A23: Events per year in the plan | B23: =IFERROR(IF('3-Year P&L'!$B$9="","",'3-Year P&L'!$B$6),"") -> 170 | C23: =IFERROR(IF('3-Year P&L'!$C$9="","",'3-Year P&L'!$C$6),"") -> 187 | D23: =IFERROR(IF('3-Year P&L'!$D$9="","",'3-Year P&L'!$D$6),"") -> 198.22
A24: Cushion above CASH break-even (%) | B24: =IFERROR(IF('3-Year P&L'!$B$9="","",B23/B20-1),"") -> 0.24086713 | C24: =IFERROR(IF('3-Year P&L'!$C$9="","",C23/C20-1),"") -> 0.33257946 | D24: =IFERROR(IF('3-Year P&L'!$D$9="","",D23/D20-1),"") -> 0.37980753 | E24: How far the plan sits above the cash break-even (plan ÷ break-even − 1); the drop you can absorb is 1 − break-even ÷ plan. The required minimum is set in the "0. Assumptions" tab
A25: INTERPRETATION
A26: =IFERROR("With the average price per guest excl. sales tax above, you need "&TEXT(ROUNDUP(B15,0),"0")&" events a year at your average of "&TEXT(B11,"0")&" guests per event to avoid losing money (accounting break-even, depreciation included), and "&TEXT(ROUNDUP(B20,0),"0")&" for cash to hold (cash break-even: depreciation out, because it is not paid, and the year's loan payment in"&IF(B12=0,"; no principal is repaid this year (interest-only period or no loan)","")&"). The ""Revenue needed per year"" rows show the same figures in your currency.","") -> With the average price per guest excl. sales tax above, you need 141 events a year at your average of 95 guests per event to avoid losing money (accounting break-even, depreciation included), and 138 for cash to hold (cash break-even: depreciation out, because it is not paid, and the year's loan payment in). The "Revenue needed per year" rows show the same figures in your currency.
A28: BREAK-EVEN SENSITIVITY
A29: Events per year needed to cover costs for each price per guest (columns, in steps around the plan's price) and each variable cost per guest (rows). Green cells are below the events per year the plan forecasts.
A31: Events per year needed: price per guest excl. sales tax (columns) × variable cost per guest (rows) | B31: =IFERROR($B$8-1,"") -> 11.6 | C31: =IFERROR(IF($B$8="","",$B$8),"") -> 12.6 | D31: =IFERROR($B$8+1,"") -> 13.6 | E31: =IFERROR($B$8+2,"") -> 14.6
A32: =IFERROR($B$9*0.85,"") -> 2.64537 | B32: =IFERROR(IF($B$31-$A32<=0,"",$B$6/($B$31-$A32)/$B$11),"") -> 148.52074 | C32: =IFERROR(IF($C$31-$A32<=0,"",$B$6/($C$31-$A32)/$B$11),"") -> 133.60097 | D32: =IFERROR(IF($D$31-$A32<=0,"",$B$6/($D$31-$A32)/$B$11),"") -> 121.40513 | E32: =IFERROR(IF($E$31-$A32<=0,"",$B$6/($E$31-$A32)/$B$11),"") -> 111.24964
A33: =IFERROR($B$9*0.925,"") -> 2.878785 | B33: =IFERROR(IF($B$31-$A33<=0,"",$B$6/($B$31-$A33)/$B$11),"") -> 152.49576 | C33: =IFERROR(IF($C$31-$A33<=0,"",$B$6/($C$31-$A33)/$B$11),"") -> 136.80885 | D33: =IFERROR(IF($D$31-$A33<=0,"",$B$6/($D$31-$A33)/$B$11),"") -> 124.04828 | E33: =IFERROR(IF($E$31-$A33<=0,"",$B$6/($E$31-$A33)/$B$11),"") -> 113.46505
A34: =IFERROR($B$9*1.0,"") -> 3.1122 | B34: =IFERROR(IF($B$31-$A34<=0,"",$B$6/($B$31-$A34)/$B$11),"") -> 156.6894 | C34: =IFERROR(IF($C$31-$A34<=0,"",$B$6/($C$31-$A34)/$B$11),"") -> 140.17457 | D34: =IFERROR(IF($D$31-$A34<=0,"",$B$6/($D$31-$A34)/$B$11),"") -> 126.80908 | E34: =IFERROR(IF($E$31-$A34<=0,"",$B$6/($E$31-$A34)/$B$11),"") -> 115.77049
A35: =IFERROR($B$9*1.075,"") -> 3.345615 | B35: =IFERROR(IF($B$31-$A35<=0,"",$B$6/($B$31-$A35)/$B$11),"") -> 161.12021 | C35: =IFERROR(IF($C$31-$A35<=0,"",$B$6/($C$31-$A35)/$B$11),"") -> 143.71007 | D35: =IFERROR(IF($D$31-$A35<=0,"",$B$6/($D$31-$A35)/$B$11),"") -> 129.69557 | E35: =IFERROR(IF($E$31-$A35<=0,"",$B$6/($E$31-$A35)/$B$11),"") -> 118.17156
A36: =IFERROR($B$9*1.15,"") -> 3.57903 | B36: =IFERROR(IF($B$31-$A36<=0,"",$B$6/($B$31-$A36)/$B$11),"") -> 165.80891 | C36: =IFERROR(IF($C$31-$A36<=0,"",$B$6/($C$31-$A36)/$B$11),"") -> 147.42852 | D36: =IFERROR(IF($D$31-$A36<=0,"",$B$6/($D$31-$A36)/$B$11),"") -> 132.71652 | E36: =IFERROR(IF($E$31-$A36<=0,"",$B$6/($E$31-$A36)/$B$11),"") -> 120.67434

Sheet Scenarios
A1: SCENARIO ANALYSIS
A4: Metric | B4: Pessimistic | C4: Base | D4: Optimistic | E4: Notes
A5: Events per year | B5: 128 | C5: =IFERROR(IF('3-Year P&L'!$B$6="","",'3-Year P&L'!$B$6),"") -> 170 | D5: 212
A6: Average price per guest (excl. sales tax) | B6: 11.34 | C6: =IFERROR(IF('3-Year P&L'!$B$7="","",'3-Year P&L'!$B$7),"") -> 12.6 | D6: 13.86
A7: Average guests per event | B7: 86 | C7: =IFERROR(IF('3-Year P&L'!$B$8="","",'3-Year P&L'!$B$8),"") -> 95 | D7: 105
A8: ANNUAL REVENUE (excl. sales tax) | B8: =IFERROR(IF(B5*B6*B7=0,"",B5*B6*B7),"") -> 124830.72 | C8: =IFERROR(IF(C5*C6*C7=0,"",C5*C6*C7),"") -> 203490 | D8: =IFERROR(IF(D5*D6*D7=0,"",D5*D6*D7),"") -> 308523.6
A9: Cost of goods — coffee bar packages (beans, milks, syrups, cold brew) | B9: =IFERROR(IF(B8="","",B8*'0. Assumptions'!$B$11*'0. Assumptions'!$B$13),"") -> 12732.733 | C9: =IFERROR(IF(C8="","",C8*'0. Assumptions'!$B$11*'0. Assumptions'!$B$13),"") -> 20755.98 | D9: =IFERROR(IF(D8="","",D8*'0. Assumptions'!$B$11*'0. Assumptions'!$B$13),"") -> 31469.407
A10: Cost of goods — add-ons | B10: =IFERROR(IF(B8="","",B8*'0. Assumptions'!$B$12*'0. Assumptions'!$B$14),"") -> 4681.152 | C10: =IFERROR(IF(C8="","",C8*'0. Assumptions'!$B$12*'0. Assumptions'!$B$14),"") -> 7630.875 | D10: =IFERROR(IF(D8="","",D8*'0. Assumptions'!$B$12*'0. Assumptions'!$B$14),"") -> 11569.635
A11: Compostable cups, lids, sleeves & napkins | B11: =IFERROR(IF(B8="","",B8*'0. Assumptions'!$B$15),"") -> 4993.2288 | C11: =IFERROR(IF(C8="","",C8*'0. Assumptions'!$B$15),"") -> 8139.6 | D11: =IFERROR(IF(D8="","",D8*'0. Assumptions'!$B$15),"") -> 12340.944
A12: Festival & market organizer fees | B12: =IFERROR(IF(B8="","",B8*'0. Assumptions'!$B$16*'0. Assumptions'!$B$17),"") -> 936.2304 | C12: =IFERROR(IF(C8="","",C8*'0. Assumptions'!$B$16*'0. Assumptions'!$B$17),"") -> 1526.175 | D12: =IFERROR(IF(D8="","",D8*'0. Assumptions'!$B$16*'0. Assumptions'!$B$17),"") -> 2313.927
A13: Card processing fees | B13: =IFERROR(IF(B8="","",B8*'0. Assumptions'!$B$18),"") -> 3744.9216 | C13: =IFERROR(IF(C8="","",C8*'0. Assumptions'!$B$18),"") -> 6104.7 | D13: =IFERROR(IF(D8="","",D8*'0. Assumptions'!$B$18),"") -> 9255.708
A14: Miscellaneous and contingency | B14: =IFERROR(IF(B8="","",B8*'0. Assumptions'!$B$28),"") -> 3744.9216 | C14: =IFERROR(IF(C8="","",C8*'0. Assumptions'!$B$28),"") -> 6104.7 | D14: =IFERROR(IF(D8="","",D8*'0. Assumptions'!$B$28),"") -> 9255.708
A15: TOTAL VARIABLE COSTS | B15: =IFERROR(IF(B8="","",SUM(B9:B14)),"") -> 30833.188 | C15: =IFERROR(IF(C8="","",SUM(C9:C14)),"") -> 50262.03 | D15: =IFERROR(IF(D8="","",SUM(D9:D14)),"") -> 76205.329
A16: GROSS MARGIN | B16: =IFERROR(IF(B8="","",B8-B15),"") -> 93997.532 | C16: =IFERROR(IF(C8="","",C8-C15),"") -> 153227.97 | D16: =IFERROR(IF(D8="","",D8-D15),"") -> 232318.27
A17: FIXED COSTS (the P&L's) | B17: =IFERROR(IF(B8="","",'3-Year P&L'!$B$38),"") -> 126345.09 | C17: =IFERROR(IF(C8="","",'3-Year P&L'!$B$38),"") -> 126345.09 | D17: =IFERROR(IF(D8="","",'3-Year P&L'!$B$38),"") -> 126345.09 | E17: Fixed costs do not change with the scenario: that is why they are fixed
A18: PRE-TAX INCOME (EBT) | B18: =IFERROR(IF(B8="","",B16-B17),"") -> -32347.554 | C18: =IFERROR(IF(C8="","",C16-C17),"") -> 26882.884 | D18: =IFERROR(IF(D8="","",D16-D17),"") -> 105973.19
A19: Income tax | B19: =IFERROR(IF(B8="","",MAX(0,B18-'0. Assumptions'!$B$42)*'0. Assumptions'!$B$37),"") -> 0 | C19: =IFERROR(IF(C8="","",MAX(0,C18-'0. Assumptions'!$B$42)*'0. Assumptions'!$B$37),"") -> 6720.7211 | D19: =IFERROR(IF(D8="","",MAX(0,D18-'0. Assumptions'!$B$42)*'0. Assumptions'!$B$37),"") -> 26493.296 | E19: At the "years 1-2" effective income tax rate, offsetting prior net operating losses
A20: NET INCOME | B20: =IFERROR(IF(B8="","",B18-B19),"") -> -32347.554 | C20: =IFERROR(IF(C8="","",C18-C19),"") -> 20162.163 | D20: =IFERROR(IF(D8="","",D18-D19),"") -> 79479.889
A21: Events per year to break even | B21: =IFERROR(IF(B8="","",IF(B6-B15/(B5*B7)<=0,"",B17/(B6-B15/(B5*B7))/B7)),"") -> 172.04889 | C21: =IFERROR(IF(C8="","",IF(C6-C15/(C5*C7)<=0,"",C17/(C6-C15/(C5*C7))/C7)),"") -> 140.17457 | D21: =IFERROR(IF(D8="","",IF(D6-D15/(D5*D7)<=0,"",D17/(D6-D15/(D5*D7))/D7)),"") -> 115.2951
A22: WHAT EACH SCENARIO DEMANDS
A23: Labor cost / Sales | B23: =IFERROR(IF(B8="","",'3-Year P&L'!$B$23/B8),"") -> 0.59681463 | C23: =IFERROR(IF(C8="","",'3-Year P&L'!$B$23/C8),"") -> 0.36611529 | D23: =IFERROR(IF(D8="","",'3-Year P&L'!$B$23/D8),"") -> 0.24147521 | E23: The SAME staffing in all three scenarios. In the pessimistic case your real event-staff cost falls with the number of events (you pay hours per event), so the real result would be somewhat better than shown. If labor cost still blows up, adjust it in the "Staffing" tab, not here
A24: Guests per year per full-time equivalent | B24: =IFERROR(IF(B8="","",B5*B7/Staffing!$C$9),"") -> 7148.0519 | C24: =IFERROR(IF(C8="","",C5*C7/Staffing!$C$9),"") -> 10487.013 | D24: =IFERROR(IF(D8="","",D5*D7/Staffing!$C$9),"") -> 14454.545 | E24: Guests each full-time equivalent in the "Staffing" table would have to serve in a year. In the optimistic scenario it tells you whether you need to hire
A25: Year-1 closing cash balance (estimate, same method in all three scenarios) | B25: =IFERROR(IF(B8="","",'Startup Costs'!$B$25+B20+'3-Year P&L'!$B$36-Financing!$B$45),"") -> -486.85832 | C25: =IFERROR(IF(C8="","",'Startup Costs'!$B$25+C20+'3-Year P&L'!$B$36-Financing!$B$45),"") -> 52022.858 | D25: =IFERROR(IF(D8="","",'Startup Costs'!$B$25+D20+'3-Year P&L'!$B$36-Financing!$B$45),"") -> 111340.58 | E25: ESTIMATED balance: working capital plus the year's result, adding back depreciation (which is not paid) and subtracting loan principal. It does not include the timing gap between receipts and payments or the sales tax settlement, so the three columns can be compared with each other. In red, the scenario runs out of cash
A26: Actual month-12 balance from the 12-Month Cash Flow tab (Base case only) | C26: =IFERROR(IF(C8="","",'12-Month Cash Flow'!$M$22),"") -> 54257.173 | E26: The ACTUAL base-case balance, with its timing of receipts and payments and its sales tax settlement. It exists only for the Base scenario, the only one with its own monthly cash flow: that is why it is not in the row above, where it would be compared against two estimates
A28: The "Base" column reads its three inputs (events per year, price per guest and guests per event) from the "0. Assumptions" tab, so it reproduces EXACTLY year 1 of the P&L. The other two scenarios use the same cost rates: only events, price and guests change. FIXED COSTS are the same in all three, while variable costs follow the sales of each scenario.

Sheet Staffing
A1: STAFFING STRUCTURE AND COSTS
A2: =IFERROR("Payroll — "&TEXT('0. Assumptions'!$B$21,"0")&" pay periods + employer taxes "&TEXT('0. Assumptions'!$B$20*100,"0")&"%","") -> Payroll — 12 pay periods + employer taxes 10%
A4: Position | B4: People | C4: FTE | D4: Gross pay per month (total for the position) | E4: Employer payroll taxes (total for the position) | F4: Cost per month (total for the position) | G4: Cost per year | H4: Hours per week per person | I4: Hours per year for the position | J4: Notes
A5: Owner / Lead Barista & Sales | B5: 1 | C5: 1 | D5: 3813 | E5: =IFERROR(IF(D5="","",D5*'0. Assumptions'!$B$20),"") -> 381.3 | F5: =IFERROR(IF(D5="","",D5+E5),"") -> 4194.3 | G5: =IFERROR(IF(D5="","",F5*MAX(12,'0. Assumptions'!$B$21)),"") -> 50331.6 | H5: =IFERROR(IF(D5="","",C5*$B$16),"") -> 40 | I5: =IFERROR(IF(D5="","",H5*B5*$B$17),"") -> 2000 | J5: Sells to companies and couples, runs the tastings and works the espresso bar at the events. Covers the main shift at every event. The rest of the owner's pay comes from profit.
A6: Lead barista (part-time W-2) | B6: 1 | C6: 0.3 | D6: 1040 | E6: =IFERROR(IF(D6="","",D6*'0. Assumptions'!$B$20),"") -> 104 | F6: =IFERROR(IF(D6="","",D6+E6),"") -> 1144 | G6: =IFERROR(IF(D6="","",F6*MAX(12,'0. Assumptions'!$B$21)),"") -> 13728 | H6: =IFERROR(IF(D6="","",C6*$B$16),"") -> 12 | I6: =IFERROR(IF(D6="","",H6*B6*$B$17),"") -> 600 | J6: Lead barista, part-time W-2: runs the second station and the second event of the day. Paid at or above the pay floor in proportion to FTE, around the 90th percentile of occupation 35-3023 (BLS OEWS, May 2025: $20.51 per hour) because event baristas earn more ($20-35 per hour at grindkit.app).
A7: Event baristas (hourly W-2) | B7: 2 | C7: 0.08 | D7: 527 | E7: =IFERROR(IF(D7="","",D7*'0. Assumptions'!$B$20),"") -> 52.7 | F7: =IFERROR(IF(D7="","",D7+E7),"") -> 579.7 | G7: =IFERROR(IF(D7="","",F7*MAX(12,'0. Assumptions'!$B$21)),"") -> 6956.4 | H7: =IFERROR(IF(D7="","",C7*$B$16),"") -> 3.2 | I7: =IFERROR(IF(D7="","",H7*B7*$B$17),"") -> 320 | J7: Event baristas hired per event and paid hourly as W-2 employees, with one barista for every 50-65 drinks an hour (Flashquotes). Their FTE is a fraction because they only work event hours. Treating them as 1099 contractors is a misclassification risk (FLSA; California AB5). Paid at or above the pay floor in proportion to FTE. Voluntary tips are theirs.
A8: On-call barista / driver (hourly W-2, peak months) | B8: 1 | C8: 0.08 | D8: 264 | E8: =IFERROR(IF(D8="","",D8*'0. Assumptions'!$B$20),"") -> 26.4 | F8: =IFERROR(IF(D8="","",D8+E8),"") -> 290.4 | G8: =IFERROR(IF(D8="","",F8*MAX(12,'0. Assumptions'!$B$21)),"") -> 3484.8 | H8: =IFERROR(IF(D8="","",C8*$B$16),"") -> 3.2 | I8: =IFERROR(IF(D8="","",H8*B8*$B$17),"") -> 160 | J8: On-call barista and driver, hourly W-2: reinforces the team in March-May and December, loads the trailer and tows it to the venue. Paid at or above the pay floor in proportion to FTE.
A9: TOTAL STAFF | B9: =IFERROR(IF(COUNT(D5:D8)=0,"",SUM(B5:B8)),"") -> 5 | C9: =IFERROR(IF(COUNT(D5:D8)=0,"",SUMPRODUCT(B5:B8,C5:C8)),"") -> 1.54 | D9: =IFERROR(IF(COUNT(D5:D8)=0,"",SUM(D5:D8)),"") -> 5644 | E9: =IFERROR(IF(COUNT(D5:D8)=0,"",SUM(E5:E8)),"") -> 564.4 | F9: =IFERROR(IF(COUNT(D5:D8)=0,"",SUM(F5:F8)),"") -> 6208.4 | G9: =IFERROR(IF(COUNT(D5:D8)=0,"",SUM(G5:G8)),"") -> 74500.8 | I9: =IFERROR(IF(COUNT(D5:D8)=0,"",SUM(I5:I8)),"") -> 3080
A10: STAFF GROWTH (stepped cost)
A11: Annual cost of year-2 hires | B11: 3000 | J11: FULL ANNUAL cost (gross pay + employer payroll taxes, over all pay periods) of whoever you hire that year. The P&L adds it to the previous year's cost: staffing grows by people, not by a percentage
A12: Annual cost of year-3 hires | B12: 3000 | J12: FULL ANNUAL cost (gross pay + employer payroll taxes, over all pay periods) of whoever you hire that year. The P&L adds it to the previous year's cost: staffing grows by people, not by a percentage
A13: Labor cost, year 2 | B13: =IFERROR(IF(G9="","",G9*(1+'0. Assumptions'!$B$48)+B11),"") -> 77500.8
A14: Labor cost, year 3 | B14: =IFERROR(IF(B13="","",B13*(1+'0. Assumptions'!$B$48)+B12),"") -> 80500.8
A15: COVERAGE OF EVENT HOURS
A16: Full-time week (hours per week) | B16: 40 | J16: 40 hours a week is the FLSA overtime threshold for non-exempt employees; some states add daily overtime rules. Change it if your own full-time week is different
A17: Weeks worked per year per person | B17: 50 | J17: 50 weeks: 52 minus about two weeks of vacation, holidays and average absences. There is no federal vacation requirement in the US: adjust it to your own policy
