Workbook

Sheet Trompo Yield
A1: TROMPO YIELD CALCULATOR: HOW MANY TACOS COME OUT OF THE CONE AND WHAT THE MEAT COSTS
A2: Type only in the GREEN cells: everything else is calculated. Amounts before sales tax. Every default value is a kit estimate, editable: replace it with your supplier's numbers and, above all, with what you measure on your own cone.
A3: FIXED NOTICE. The cooking and drip loss (35 %) has no reliable published source: it is a kit estimate. Weigh your first raw cone, what you serve and the leftover, and adjust the loss until the yield matches what you measure.
A5: A. THE AL PASTOR CONE | B5: Value | C5: Notes
A6: Raw meat stacked on the cone (lb) | B6: 30 | C6: Weigh the sliced meat before the marinade, ready to stack. Kit estimate, editable.
A7: Marinade over the meat (%) | B7: 0.08 | C7: Achiote, chiles, spices and pineapple in the marinade, over the weight of the meat. Kit estimate, editable.
A8: Raw meat price ($/lb, before tax) | B8: 3 | C8: Pork shoulder. Type your supplier's price. Kit estimate, editable.
A9: Marinade price ($/lb, before tax) | B9: 3 | C9: Type your supplier's price or the cost of your own recipe. Kit estimate, editable.
A10: Pineapple on top of the cone (lb) | B10: 0 | C10: Default 0: the pineapple on each taco is counted separately on the "Taco Costing" sheet. If you type pounds here, they add to the cone cost.
A11: Pineapple price ($/lb, before tax) | B11: 0.8 | C11: Only counts if you type pounds of pineapple above. Kit estimate, editable.
A12: Cooking and drip loss (%) | B12: 0.35 | C12: What the cone loses as it roasts: fat and water. There is no reliable published figure: measure it with your first cone (see the "Instructions" sheet). Kit estimate, editable.
A13: Trim you cannot serve (%) | B13: 0.05 | C13: Burnt tips, hard fat and gristle that never reach the plate. Kit estimate, editable.
A14: Leftover at close (lb) | B14: 0 | C14: Cooked meat left unserved at close. Weigh it; default 0.
A15: Share of the leftover you reuse (%) | B15: 0 | C15: For example in a next-day stew. The part you throw away takes tacos off the total.
A16: Cooked meat served per taco (oz) | B16: 1.5 | C16: Ounces of cooked, sliced meat on each taco. Kit estimate, editable.
A17: Number of tacos you want to prepare | B17: 100 | C17: Whole number greater than 0. It tells you how much raw meat you need.
... A19: Benchmark: tacos per raw lb at a Mexico City stand | B19: 11 | C19: Fixed benchmark: a 110 to 220 lb trompo yields 1,250 to 2,500 tacos, about 11 per raw lb (Milenio). Not editable.
A20: Your county's al pastor cook temp (°F) | C20: Leave it empty until you have it. Ask your county health department IN WRITING what cook and hold temperature it requires for al pastor off the trompo; counties differ, so the kit gives no single figure. Write it here and keep the answer on file.
A22: CONE RESULT | B22: Value | C22: Notes
A23: Marinated meat (lb) | B23: =$B$6*(1+$B$7) -> 32.4 | C23: Raw meat plus marinade.
A24: Cooked meat served from the cone (lb) | B24: =$B$23*(1-$B$12-$B$13)-$B$14*(1-$B$15) -> 19.44 | C24: Marinated meat minus the loss and the trim, minus the leftover you throw away.
A25: TROMPO YIELD (%) | B25: =$B$24/$B$6 -> 0.648 | C25: Served meat ÷ raw meat stacked.
A26: TACOS FROM THE CONE | B26: =$B$24*$B$18/$B$16 -> 207.36 | C26: Served lb × 16 ÷ ounces per taco.
A27: Tacos per raw lb | B27: =$B$26/$B$6 -> 6.912 | C27: Compare it with the Mexico City benchmark above.
A28: Your tacos per lb against the Mexico City benchmark (%) | B28: =$B$27/$B$19 -> 0.62836364 | C28: Below 100 %: you serve more ounces per taco or lose more.
A29: Cone cost ($) | B29: =$B$6*$B$8+$B$6*$B$7*$B$9+$B$10*$B$11 -> 97.2 | C29: Meat + marinade + pineapple on top.
A30: COST PER SERVED LB ($) | B30: =$B$29/$B$24 -> 5 | C30: Cone cost ÷ served lb. It feeds the taco costing.
A31: MEAT COST PER TACO ($) | B31: =$B$30*$B$16/$B$18 -> 0.46875 | C31: Cost per served lb × ounces per taco ÷ 16.
A32: Raw meat to prepare the N tacos (lb) | B32: =$B$17*$B$16/($B$18*$B$25) -> 14.467593 | C32: N × ounces per taco ÷ (16 × yield).
A34: B. OTHER PROTEINS (stews and roasts) | B34: Raw lb | C34: $/raw lb (before tax) | D34: Yield after cooking (%) | E34: Oz per taco | F34: Cooked lb | G34: $/cooked lb | H34: Tacos | I34: $ of meat per taco
A35: Carnitas | B35: 20 | C35: 2.8 | D35: 0.6 | E35: 1.5 | F35: =B35*D35 -> 12 | G35: =C35/D35 -> 4.6666667 | H35: =F35*$B$18/E35 -> 128 | I35: =G35*E35/$B$18 -> 0.4375
A36: Suadero (beef navel) | B36: 20 | C36: 4.2 | D36: 0.55 | E36: 1.5 | F36: =B36*D36 -> 11 | G36: =C36/D36 -> 7.6363636 | H36: =F36*$B$18/E36 -> 117.33333 | I36: =G36*E36/$B$18 -> 0.71590909
A37: Cochinita pibil | B37: 20 | C37: 3 | D37: 0.6 | E37: 1.75 | F37: =B37*D37 -> 12 | G37: =C37/D37 -> 5 | H37: =F37*$B$18/E37 -> 109.71429 | I37: =G37*E37/$B$18 -> 0.546875
A38: Beef barbacoa | B38: 20 | C38: 4 | D38: 0.55 | E38: 1.75 | F38: =B38*D38 -> 11 | G38: =C38/D38 -> 7.2727273 | H38: =F38*$B$18/E38 -> 100.57143 | I38: =G38*E38/$B$18 -> 0.79545455
A39: Chicken tinga | B39: 20 | C39: 2.2 | D39: 0.65 | E39: 1.5 | F39: =B39*D39 -> 13 | G39: =C39/D39 -> 3.3846154 | H39: =F39*$B$18/E39 -> 138.66667 | I39: =G39*E39/$B$18 -> 0.31730769
A40: Campechano (steak and chorizo) | B40: 20 | C40: 4.5 | D40: 0.6 | E40: 1.5 | F40: =B40*D40 -> 12 | G40: =C40/D40 -> 7.5 | H40: =F40*$B$18/E40 -> 128 | I40: =G40*E40/$B$18 -> 0.703125
A41: Slow-cooked stews (carnitas, barbacoa, cochinita) yield less than the cone: the yield and the price on each row are a kit estimate, editable. The $/cooked lb of each row feeds the "Taco Costing" sheet.

Sheet Tortillas
A1: TORTILLAS: BUY THEM OR MAKE THEM WITH MASA HARINA, AND THE BREAK-EVEN IN TORTILLAS PER DAY
A2: Type only in the GREEN cells. Amounts before sales tax. Every default value is a kit estimate, editable: replace it with your supplier's numbers. At the volume of a neighborhood taco shop, buying usually wins; this sheet shows you where the math flips.
A5: A. BOUGHT TORTILLAS | B5: Value | C5: Notes
A6: Price of a case of corn tortillas ($, before tax) | B6: 58.99 | C6: 6 in white corn tortillas, 360 per case (Mission, case price read in October 2026). Kit estimate, editable.
A7: Tortillas per case | B7: 360 | C7: Whole number greater than 0. Kit estimate, editable.
A8: Weight of each tortilla (oz) | B8: 0.9 | C8: A 6 in corn tortilla weighs about 0.9 oz. Kit estimate, editable.
A9: B. HOMEMADE (masa harina, tortilla machine and a tortillera) | B9: Value | C9: Notes
A10: Masa harina price ($/lb, before tax) | B10: 0.45 | C10: Instant corn masa flour in a 50 lb bag. Type your supplier's price. Kit estimate, editable.
A11: Masa you get from 1 lb of masa harina (lb) | B11: 1.8 | C11: Masa harina absorbs water: 1 lb of flour makes about 1.8 lb of masa. Kit estimate, editable.
A12: Water, power and gas for the press ($ per lb of masa harina) | B12: 0.2 | C12: Everything you spend to mix, press and cook, per pound of masa harina. Kit estimate, editable.
A13: Raw masa per homemade tortilla (oz) | B13: 1 | C13: Raw masa in each tortilla before pressing. Kit estimate, editable.
A14: Yearly cost of a tortillera ($, with payroll costs) | B14: 27450 | C14: About 0.75 FTE at $16 an hour with payroll costs. Kit estimate, editable.
A15: Tortilla machine investment ($, before tax) | B15: 7808 | C15: A commercial countertop tortilla machine with a 6 in cutter. Kit estimate, editable.
A16: Years of life of the machine | B16: 7 | C16: The investment is spread over these years. Kit estimate, editable.
A17: Days open per year | B17: 308 | C17: The days of the kit's business plan case. Kit estimate, editable.
A18: C. YOUR CASE | B18: Value | C18: Notes
A19: Tortillas you use per day | B19: 650 | C19: The kit's case uses about 650 a day (tacos with two tortillas, plus quesadillas). Replace it with yours. Kit estimate, editable.
A21: RESULT | B21: Value | C21: Notes
A22: Cost per bought tortilla ($) | B22: =$B$6/$B$7 -> 0.16386111 | C22: Case price ÷ tortillas per case.
A23: Tortillas in 1 lb bought | B23: ='Trompo Yield'!$B$18/$B$8 -> 17.777778 | C23: To order from your supplier: 16 ÷ ounces per tortilla.
A24: Masa harina per homemade tortilla (oz) | B24: =$B$13/$B$11 -> 0.55555556 | C24: Raw masa per tortilla ÷ masa from 1 lb of flour.
A25: Tortillas from 1 lb of masa harina | B25: =$B$11*'Trompo Yield'!$B$18/$B$13 -> 28.8
A26: Cost per homemade tortilla ($, without the person or the machine) | B26: =$B$24*($B$10+$B$12)/'Trompo Yield'!$B$18 -> 0.022569444 | C26: Masa harina + water, power and gas.
A27: Saving per tortilla if you make it ($) | B27: =$B$22-$B$26 -> 0.14129167 | C27: If it is zero or negative, buying always wins.
A28: Fixed daily cost of making them ($) | B28: =($B$14+$B$15/$B$16)/$B$17 -> 92.744898 | C28: Person + machine spread over the days you are open.
A29: BREAK-EVEN (tortillas per day) | B29: =IF($B$27>0,($B$14+$B$15/$B$16)/($B$27*$B$17),0) -> 656.40742 | C29: Above this many tortillas a day, making them pays. Below it, buy.
A30: Daily cost buying them ($) | B30: =$B$19*$B$22 -> 106.50972 | C30: For the tortillas per day you typed.
A31: Daily cost making them ($) | B31: =$B$19*$B$26+$B$28 -> 107.41504 | C31: Includes the person and the machine.
A32: What suits you | B32: =IF(AND($B$27>0,$B$19>=$B$29),"Make them","Buy them") -> Buy them | C32: Your tortillas per day against the break-even.

Sheet Taco Costing
A1: TACO COSTING: 8 TACOS, AN ORDER OF 3 AND A GRINGA AS EXAMPLES, IN OUNCES
A2: Type only in the GREEN cells (prices, ounces, names, tortillas and menu prices). Amounts before sales tax except the menu price. Prices are a kit estimate, editable: type your distributor's. The meats and the corn tortilla come from the "Trompo Yield" and "Tortillas" sheets.
A4: GENERAL DATA | B4: Value | D4: Notes
A5: Sales tax included in your menu prices (%) | B5: 0 | D5: Typically 0 %: a US menu is quoted before tax and the tax is added at the register. Rates vary by state and city; ask your accountant.
A6: Target food cost (% of the price before tax) | B6: 0.25 | D6: Taco shop reference: 22 to 30 % on the al pastor taco. Kit estimate, editable.
A7: Watch margin over the target (points) | B7: 0.05 | D7: Up to this margin above the target, the traffic light says "Watch the cost".
A8: Production waste over the cost (%) | B8: 0.05 | D8: Raw salsas you discard, torn tortillas, onion and cilantro you cannot use. Kit estimate, editable.
A9: Corn tortilla the costing uses | B9: Buy corn tortillas | D9: Picks the cost per tortilla from the "Tortillas" sheet: bought or homemade with masa harina.
A10: Packaging per takeout order ($, before tax) | B10: 0.6 | D10: Bag, container and salsa cups of one order. Kit estimate, editable.
A11: Delivery app commission (%) | B11: 0.25 | D11: Over the price before tax. Check your contract with each app. Kit estimate, editable.
A13: INGREDIENT (in ounces) | B13: $/lb before tax | C13: Unit | D13: Al pastor taco | E13: Carnitas taco | F13: Suadero taco | G13: Cochinita pibil taco | H13: Beef barbacoa taco | I13: Chicken tinga taco | J13: Campechano taco | K13: Veggie taco | L13: Al pastor order (3 tacos) | M13: Al pastor gringa | N13: WHERE THE PRICE COMES FROM
A14: Menu price ($) | D14: 4 | E14: 4 | F14: 4.5 | G14: 4.5 | H14: 4.75 | I14: 4 | J14: 4.75 | K14: 4.5 | L14: 11 | M14: 11.5
A15: Al pastor meat (from the cone) | B15: ='Trompo Yield'!$B$30 -> 5 | C15: oz | D15: 1.5 | E15: 0 | F15: 0 | G15: 0 | H15: 0 | I15: 0 | J15: 0 | K15: 0 | L15: 4.5 | M15: 2.5 | N15: linked from the Trompo Yield sheet ($ per served lb)
A16: Carnitas | B16: ='Trompo Yield'!$G$35 -> 4.6666667 | C16: oz | D16: 0 | E16: 1.5 | F16: 0 | G16: 0 | H16: 0 | I16: 0 | J16: 0 | K16: 0 | L16: 0 | M16: 0 | N16: linked from the Trompo Yield sheet ($ per cooked lb)
A17: Suadero (beef navel) | B17: ='Trompo Yield'!$G$36 -> 7.6363636 | C17: oz | D17: 0 | E17: 0 | F17: 1.5 | G17: 0 | H17: 0 | I17: 0 | J17: 0 | K17: 0 | L17: 0 | M17: 0 | N17: linked from the Trompo Yield sheet ($ per cooked lb)
A18: Cochinita pibil | B18: ='Trompo Yield'!$G$37 -> 5 | C18: oz | D18: 0 | E18: 0 | F18: 0 | G18: 1.75 | H18: 0 | I18: 0 | J18: 0 | K18: 0 | L18: 0 | M18: 0 | N18: linked from the Trompo Yield sheet ($ per cooked lb)
A19: Beef barbacoa | B19: ='Trompo Yield'!$G$38 -> 7.2727273 | C19: oz | D19: 0 | E19: 0 | F19: 0 | G19: 0 | H19: 1.75 | I19: 0 | J19: 0 | K19: 0 | L19: 0 | M19: 0 | N19: linked from the Trompo Yield sheet ($ per cooked lb)
A20: Chicken tinga | B20: ='Trompo Yield'!$G$39 -> 3.3846154 | C20: oz | D20: 0 | E20: 0 | F20: 0 | G20: 0 | H20: 0 | I20: 1.5 | J20: 0 | K20: 0 | L20: 0 | M20: 0 | N20: linked from the Trompo Yield sheet ($ per cooked lb)
A21: Campechano (steak and chorizo) | B21: ='Trompo Yield'!$G$40 -> 7.5 | C21: oz | D21: 0 | E21: 0 | F21: 0 | G21: 0 | H21: 0 | I21: 0 | J21: 1.5 | K21: 0 | L21: 0 | M21: 0 | N21: linked from the Trompo Yield sheet ($ per cooked lb)
A22: Diced white onion | B22: 0.8 | C22: oz | D22: 0.35 | E22: 0.35 | F22: 0.35 | G22: 0.35 | H22: 0.35 | I22: 0.2 | J22: 0.35 | K22: 0.2 | L22: 1.05 | M22: 0.35 | N22: Kit estimate (Oct 2026): replace with your distributor's price
A23: Cilantro | B23: 6 | C23: oz | D23: 0.1 | E23: 0.1 | F23: 0.1 | G23: 0 | H23: 0.1 | I23: 0.1 | J23: 0.1 | K23: 0.1 | L23: 0.3 | M23: 0.1 | N23: Kit estimate (Oct 2026): replace with your distributor's price
A24: Pineapple | B24: 0.8 | C24: oz | D24: 0.3 | E24: 0 | F24: 0 | G24: 0 | H24: 0 | I24: 0 | J24: 0 | K24: 0 | L24: 0.9 | M24: 0.5 | N24: Kit estimate (Oct 2026): replace with your distributor's price
A25: Lime | B25: 1.8 | C25: oz | D25: 0.2 | E25: 0.2 | F25: 0.2 | G25: 0.2 | H25: 0.2 | I25: 0 | J25: 0.2 | K25: 0.2 | L25: 0.6 | M25: 0 | N25: Kit estimate (Oct 2026): replace with your distributor's price
A26: Red salsa | B26: 2 | C26: oz | D26: 0.3 | E26: 0.25 | F26: 0.25 | G26: 0 | H26: 0.4 | I26: 0.3 | J26: 0.3 | K26: 0 | L26: 0.9 | M26: 0.4 | N26: Kit estimate (Oct 2026): replace with your distributor's price
A27: Green salsa | B27: 2 | C27: oz | D27: 0.2 | E27: 0.25 | F27: 0.1 | G27: 0.35 | H27: 0 | I27: 0.2 | J27: 0.2 | K27: 0.35 | L27: 0.6 | M27: 0.3 | N27: Kit estimate (Oct 2026): replace with your distributor's price
A28: Salsa macha (chile oil salsa) | B28: 8 | C28: oz | D28: 0 | E28: 0 | F28: 0.15 | G28: 0 | H28: 0 | I28: 0 | J28: 0 | K28: 0 | L28: 0 | M28: 0 | N28: Kit estimate (Oct 2026): replace with your distributor's price
A29: Oaxaca or Monterey Jack cheese | B29: 6 | C29: oz | D29: 0 | E29: 0 | F29: 0 | G29: 0 | H29: 0 | I29: 0.35 | J29: 0 | K29: 0.7 | L29: 0 | M29: 2 | N29: Kit estimate (Oct 2026): replace with your distributor's price
A30: Guacamole | B30: 6 | C30: oz | D30: 0 | E30: 0 | F30: 0 | G30: 0 | H30: 0 | I30: 0 | J30: 0 | K30: 0.9 | L30: 0 | M30: 0 | N30: Kit estimate (Oct 2026): replace with your distributor's price (depends on the avocado)
A31: Pinto beans | B31: 1.5 | C31: oz | D31: 0 | E31: 0 | F31: 0 | G31: 0 | H31: 0 | I31: 0 | J31: 0 | K31: 1.4 | L31: 0 | M31: 0 | N31: Kit estimate (Oct 2026): replace with your distributor's price
A32: INGREDIENT (in units) | B32: $/ea before tax | C32: Unit
A33: Corn tortilla, 6 in ($/ea) | B33: =IF($B$9="Buy corn tortillas",'Tortillas'!$B$22,'Tortillas'!$B$26) -> 0.16386111 | C33: ea | D33: 2 | E33: 2 | F33: 2 | G33: 2 | H33: 2 | I33: 2 | J33: 2 | K33: 2 | L33: 6 | M33: 0 | N33: linked from the Tortillas sheet, according to the option you pick
A34: Flour tortilla, 10 in ($/ea) | B34: 0.25 | C34: ea | D34: 0 | E34: 0 | F34: 0 | G34: 0 | H34: 0 | I34: 0 | J34: 0 | K34: 0 | L34: 0 | M34: 1 | N34: Kit estimate (Oct 2026): replace with your distributor's price
A36: RESULT PER ITEM (ounces and units in the columns above) | D36: =D13 -> Al pastor taco | E36: =E13 -> Carnitas taco | F36: =F13 -> Suadero taco | G36: =G13 -> Cochinita pibil taco | H36: =H13 -> Beef barbacoa taco | I36: =I13 -> Chicken tinga taco | J36: =J13 -> Campechano taco | K36: =K13 -> Veggie taco | ... M36: =M13 -> Al pastor gringa
A37: Weight served on the plate, without tortilla (oz) | D37: =SUM(D$15:D$31) -> 2.95 | E37: =SUM(E$15:E$31) -> 2.65 | F37: =SUM(F$15:F$31) -> 2.65 | G37: =SUM(G$15:G$31) -> 2.65 | H37: =SUM(H$15:H$31) -> 2.8 | I37: =SUM(I$15:I$31) -> 2.65 | J37: =SUM(J$15:J$31) -> 2.65 | K37: =SUM(K$15:K$31) -> 3.85 | ... M37: =SUM(M$15:M$31) -> 6.15
A38: Raw material cost ($) | D38: =SUMPRODUCT(D$15:D$31,$B$15:$B$31)/'Trompo Yield'!$B$18+SUMPRODUCT(D$33:D$34,$B$33:$B$34) -> 0.95147222 | E38: =SUMPRODUCT(E$15:E$31,$B$15:$B$31)/'Trompo Yield'!$B$18+SUMPRODUCT(E$33:E$34,$B$33:$B$34) -> 0.90522222 | F38: =SUMPRODUCT(F$15:F$31,$B$15:$B$31)/'Trompo Yield'!$B$18+SUMPRODUCT(F$33:F$34,$B$33:$B$34) -> 1.2398813 | G38: =SUMPRODUCT(G$15:G$31,$B$15:$B$31)/'Trompo Yield'!$B$18+SUMPRODUCT(G$33:G$34,$B$33:$B$34) -> 0.95834722 | H38: =SUMPRODUCT(H$15:H$31,$B$15:$B$31)/'Trompo Yield'!$B$18+SUMPRODUCT(H$33:H$34,$B$33:$B$34) -> 1.2506768 | I38: =SUMPRODUCT(I$15:I$31,$B$15:$B$31)/'Trompo Yield'!$B$18+SUMPRODUCT(I$33:I$34,$B$33:$B$34) -> 0.88627991 | J38: =SUMPRODUCT(J$15:J$31,$B$15:$B$31)/'Trompo Yield'!$B$18+SUMPRODUCT(J$33:J$34,$B$33:$B$34) -> 1.1708472 | K38: =SUMPRODUCT(K$15:K$31,$B$15:$B$31)/'Trompo Yield'!$B$18+SUMPRODUCT(K$33:K$34,$B$33:$B$34) -> 1.1727222 | ... M38: =SUMPRODUCT(M$15:M$31,$B$15:$B$31)/'Trompo Yield'!$B$18+SUMPRODUCT(M$33:M$34,$B$33:$B$34) -> 1.94875
A39: COST WITH WASTE ($) | D39: =D38*(1+$B$8) -> 0.99904583 | E39: =E38*(1+$B$8) -> 0.95048333 | F39: =F38*(1+$B$8) -> 1.3018754 | G39: =G38*(1+$B$8) -> 1.0062646 | H39: =H38*(1+$B$8) -> 1.3132106 | I39: =I38*(1+$B$8) -> 0.93059391 | J39: =J38*(1+$B$8) -> 1.2293896 | K39: =K38*(1+$B$8) -> 1.2313583 | ... M39: =M38*(1+$B$8) -> 2.0461875
A40: Menu price before tax ($) | D40: =D14/(1+$B$5) -> 4 | E40: =E14/(1+$B$5) -> 4 | F40: =F14/(1+$B$5) -> 4.5 | G40: =G14/(1+$B$5) -> 4.5 | H40: =H14/(1+$B$5) -> 4.75 | I40: =I14/(1+$B$5) -> 4 | J40: =J14/(1+$B$5) -> 4.75 | K40: =K14/(1+$B$5) -> 4.5 | ... M40: =M14/(1+$B$5) -> 11.5
A41: FOOD COST (%) | D41: =D39/D40 -> 0.24976146 | E41: =E39/E40 -> 0.23762083 | F41: =F39/F40 -> 0.28930564 | G41: =G39/G40 -> 0.22361435 | H41: =H39/H40 -> 0.27646539 | I41: =I39/I40 -> 0.23264848 | J41: =J39/J40 -> 0.25881886 | K41: =K39/K40 -> 0.27363519 | ... M41: =M39/M40 -> 0.17792935
A42: Traffic light against the target | D42: =IF(D41<=$B$6,"On target",IF(D41<=$B$6+$B$7,"Watch the cost","Above target")) -> On target | E42: =IF(E41<=$B$6,"On target",IF(E41<=$B$6+$B$7,"Watch the cost","Above target")) -> On target | F42: =IF(F41<=$B$6,"On target",IF(F41<=$B$6+$B$7,"Watch the cost","Above target")) -> Watch the cost | G42: =IF(G41<=$B$6,"On target",IF(G41<=$B$6+$B$7,"Watch the cost","Above target")) -> On target | H42: =IF(H41<=$B$6,"On target",IF(H41<=$B$6+$B$7,"Watch the cost","Above target")) -> Watch the cost | I42: =IF(I41<=$B$6,"On target",IF(I41<=$B$6+$B$7,"Watch the cost","Above target")) -> On target | J42: =IF(J41<=$B$6,"On target",IF(J41<=$B$6+$B$7,"Watch the cost","Above target")) -> Watch the cost | K42: =IF(K41<=$B$6,"On target",IF(K41<=$B$6+$B$7,"Watch the cost","Above target")) -> Watch the cost | ... M42: =IF(M41<=$B$6,"On target",IF(M41<=$B$6+$B$7,"Watch the cost","Above target")) -> On target
A43: Gross margin ($, price before tax − cost) | D43: =D40-D39 -> 3.0009542 | E43: =E40-E39 -> 3.0495167 | F43: =F40-F39 -> 3.1981246 | G43: =G40-G39 -> 3.4937354 | H43: =H40-H39 -> 3.4367894 | I43: =I40-I39 -> 3.0694061 | J43: =J40-J39 -> 3.5206104 | K43: =K40-K39 -> 3.2686417 | ... M43: =M40-M39 -> 9.4538125
...

Sheet Instructions
A1: INSTRUCTIONS: Taco Cost & Trompo Yield Calculator
A2: Three tools in one workbook: the "Trompo Yield" sheet tells you how many tacos come out of an al pastor cone and what the meat on each one costs; the "Tortillas" sheet compares buying corn tortillas with making them in house and gives you the break-even in tortillas per day; the "Taco Costing" sheet calculates the cost, food cost, margin and menu price of 8 tacos, an order of 3 and a gringa, with the margin dine-in, on takeout and on a delivery app. Type only in the GREEN cells; everything else is calculated. Meat prices are in $/lb and portions in ounces (16 oz per lb, the gray constant).
A3: Every default value is a kit estimate, editable: they are examples consistent with the kit's business plan case, not anyone's prices. Replace them with your supplier's and with what you measure in your kitchen before you decide on prices.
A4: "TROMPO YIELD" SHEET
A6: 1. How to measure the cone. Weigh the raw meat you stack on the trompo (before the marinade) and write down the pounds. At close, weigh what is left of the cooked cone and note where it goes: reused in a stew or thrown away. With those three numbers and the tacos you sold, the sheet gives you your real yield.
A7: 2. How to adjust the loss. The 35 % cooking and drip loss is a kit estimate with no published source. Measure your first cone: tacos served × ounces per taco ÷ 16 is the pounds served. Move the loss until the sheet's yield matches yours.
A8: 3. The most useful results are the cost per served lb and the meat cost per taco, which feed the taco costing. Compare your tacos per raw lb with the benchmark of a Mexico City stand, about 11 per lb (Milenio). If you serve more ounces, you get fewer tacos.
A9: 4. "Raw meat to prepare the N tacos" tells you how much meat to stack for a big order. The other proteins (carnitas, suadero, cochinita pibil, barbacoa, tinga and campechano) use their own yield after cooking, lower than the cone's.
A10: 5. Food safety. A stacked, marinated cone is a raw meat preparation: keep it at 41 °F or below until it goes on the broiler, probe it and log the temperature in your food safety plan. Cook and hold temperatures for al pastor off the trompo are set by your county, and counties differ: ask your county health department IN WRITING, type the answer in the green "Your county's al pastor cook temp (°F)" cell and keep the reply on file. The kit gives no single figure.
A11: "TORTILLAS" SHEET
A13: 1. Type the price of the case, the tortillas per case and the weight of each tortilla, plus the masa harina, machine and tortillera numbers. The tortillas per lb bought are what you need to order from your supplier.
A14: 2. The break-even is the number of tortillas a day above which making them pays, counting the person who makes them and the machine. If you use fewer, buy. With your own tortillas per day, the sheet tells you which suits you.
... A29: Planning tool, not financial, tax or legal advice. Requirements vary by state, county and city — check with your accountant and local authorities.
