Workbook

Sheet Instrucciones
A1: Carta de Apertura y Escandallo por Tanda
A2: AI Chef Pro · aichef.pro — Cómo Montar una Pastelería
A3: Para qué sirve: decidir qué vendes, a cuánto, y con qué vía legal de huevo -con su temperatura y su plazo-.
A5: Instrucciones de uso
A6: 1. Hoja «Parámetros»: empieza por el bloque de personal de obrador. El coste hora de obrador NO es un dato del sector y no se teclea: se calcula con el bruto de tu convenio, las pagas, la jornada de cada persona y la Seguridad Social a cargo de la empresa. Debajo están los precios de compra, uno por ingrediente: es la única tabla donde se tocan los precios y de ella beben las 226 líneas del escandallo.
A7: 2. Hoja «Escandallo por Tanda»: una fila por ingrediente y por referencia. La unidad de costeo es LA TANDA, no la pieza: es como se trabaja en un obrador y es la única forma de que la mano de obra cuadre. Escribe la cantidad neta que usas, el factor que convierte la unidad de compra en la de uso (12 para pasar de docena a unidad, 1 si coinciden) y la merma. El coste de la línea sale solo.
A8: 3. Hoja «Coste Hora y Mano de Obra»: los minutos que te lleva cada tanda y el precio de venta. De ahí salen el coste de mano de obra por pieza, el coste total, el food cost y el margen en euros. Es el capítulo que enseña a dejar de regalar tu trabajo.
A9: 4. Hoja «Decisión de Huevo y Temperatura»: para cada referencia, elige la vía legal del huevo, di si va rellena y si el producto terminado es estable a temperatura ambiente. El libro devuelve la temperatura de conservación, cuál de los dos artículos manda y el plazo legal del art. 9.3. La vida útil la declaras tú.
A10: 5. Hoja «Mix y Ticket Medio»: reparte el 100 % de tus unidades entre las 30 referencias. De ahí sale tu ticket medio, que no se copia de ningún estudio porque no existe un ticket medio publicado de pastelería.
A11: 6. Hoja «Decisión de Surtido»: cruza margen y rotación y te dice qué mantener, a qué revisarle el precio y qué retirar. Repásala a los tres meses de abrir, con ventas reales, y otra vez al cambiar de temporada.
A13: Celdas verdes = campos editables
A15: Lo que conviene saber antes de empezar
... A30: Versión 1.0 · septiembre 2026 · aichef.pro/guia-pasteleria-obrador · info@aichef.pro

Sheet Parámetros
A1: Parámetros
A2: AI Chef Pro · aichef.pro — Cómo Montar una Pastelería
A3: El coste hora de obrador se CALCULA aquí desde tu plantilla y tu convenio. No es un dato del sector.
A5: Personal de obrador | B5: Jornada | C5: Grupo de convenio | D5: Bruto mensual del convenio (€) | E5: Bruto anual con las pagas (€) | F5: Coste de empresa anual con SS (€) | G5: Nota
A6: Jefe Pastelero (P1) | B6: 1 | C6: 2 · Dirección, jefes y encargados | D6: 1427.89 | E6: =IFERROR(D6*'Parámetros'!$B$11,"") -> 21418.35 | F6: =IFERROR(E6*B6*(1+'Parámetros'!$B$12),"") -> 28486.406 | G6: Turno: Madrugada (04:30-12:30). Sólo el área OBRADOR entra en el coste hora: el despacho no fabrica.
A7: Pastelero (P2) | B7: 1 | C7: 3 · Personal especialista | D7: 1376.91 | E7: =IFERROR(D7*'Parámetros'!$B$11,"") -> 20653.65 | F7: =IFERROR(E7*B7*(1+'Parámetros'!$B$12),"") -> 27469.355 | G7: Turno: Madrugada (05:00-13:00). Sólo el área OBRADOR entra en el coste hora: el despacho no fabrica.
A8: Ayudante (P3) | B8: 0.5 | C8: 5 · Personal de apoyo | D8: 1192.42 | E8: =IFERROR(D8*'Parámetros'!$B$11,"") -> 17886.3 | F8: =IFERROR(E8*B8*(1+'Parámetros'!$B$12),"") -> 11894.39 | G8: Turno: Mañana (07:00-11:00). Sólo el área OBRADOR entra en el coste hora: el despacho no fabrica.
A9: TOTAL OBRADOR | B9: =SUM(B6:B8) -> 2.5 | F9: =SUM(F6:F8) -> 67850.15
A11: Pagas del convenio al año | B11: 15 | C11: pagas | D11: PA-33 | G11: El convenio de la Comunidad de Madrid (código 28001025011981, revisión 2026 en el BOCM núm. 50, de 28 de febrero de 2026) paga 15, no 14. Sustitúyelo por el de tu convenio provincial.
A12: Seguridad Social a cargo de la empresa | B12: 0.33 | C12: sobre bruto | D12: motor.PARAMETROS | G12: Cotización empresarial aproximada sobre el bruto: contingencias comunes, desempleo, FOGASA y formación. Es el renglón que convierte un bruto en un coste, y el que más sorprende.
A13: Horas anuales de contrato | B13: 1780 | C13: horas/año | D13: supuesto | G13: 40 horas por 52 semanas son 2.080, menos 30 días naturales de vacaciones y los festivos del calendario laboral.
A14: Horas productivas sobre la jornada | B14: 0.85 | C14: de la jornada | D14: supuesto | G14: Parte de la jornada que se pasa a pie de mesa. El resto es recepción, limpieza, formación y reuniones: horas que pagas y no producen.
A15: Horas productivas del obrador al año | B15: =IFERROR($B$9*'Parámetros'!$B$13*'Parámetros'!$B$14,"") -> 3782.5 | C15: horas/año | D15: calculado | G15: Jornadas de obrador por horas anuales de contrato por el ratio productivo.
A16: COSTE HORA PRODUCTIVA DE OBRADOR | B16: =IFERROR($F$9/'Parámetros'!$B$15,"") -> 17.937911 | C16: €/hora | D16: calculado | G16: Coste de empresa anual del obrador dividido por sus horas PRODUCTIVAS (con el factor de 85 % de más arriba). Éste es el número que hay que meter en cada tanda, y el que casi nadie imputa. NO lo confundas con el «coste medio por hora PAGADA de la plantilla» del libro 8 (14,89 €, plantilla-turnos-y-coste-personal.xlsx) ni con el «coste por hora PAGADA del refuerzo» del libro 3 (13,36 €, estacionalidad-y-picos.xlsx): las tres son correctas y las tres miden un denominador distinto.
A18: IVA por familia de producto
A19: IVA de pastelería, bollería y confitería | B19: 0.1 | C19: sobre base | D19: PA-36 | G19: Regla general de alimentos del art. 91.Uno.1.1.º de la Ley 37/1992: no porque un precepto los nombre, sino porque no están en la lista cerrada del 4 % ni excluidos del 10 %.
A20: IVA del pan del RD 308/2019 | B20: 0.04 | C20: sobre base | D20: PA-36b | G20: Todos los productos del RD 308/2019 -pan común, pan especial y semielaborados, con o sin gluten- van al 4 % desde la Resolución vinculante de la DGT de 24-02-2025, que acoge la STS 1610/2024. El cruasán sigue al 10 %: el RD 308/2019 sólo regula el pan y no menciona la bollería.
A21: IVA en zona de degustación | B21: 0.1 | C21: sobre base | D21: PA-36c | G21: Si pones mesas, ahí no vendes un bien: prestas un servicio de hostelería (art. 91.Uno.2.2.º). Tu TPV tiene que separar los tipos.
A23: La regla del margen: UN número, y el otro se deriva
A24: Food cost objetivo | B24: 0.32 | C24: sobre PVP sin IVA | D24: PS-55 + PS-56 | G24: Éste es el ÚNICO número de margen que se teclea. La banda del sector es 30-35 % de food cost, que es exactamente lo mismo que decir 65-70 % de margen bruto.
A25: Margen bruto objetivo (derivado) | B25: =IFERROR(1-'Parámetros'!$B$24,"") -> 0.68 | C25: sobre PVP sin IVA | D25: calculado | G25: Uno menos el food cost objetivo. No se teclea a propósito: pedir los dos números permite ponerlos incoherentes y es el error de método más repetido del oficio.
A27: Techos y plazos legales (RD 1021/2022, verificado el 10-09-2026)
A28: Techo de la fila 9 del art. 4.1 | B28: 4 | C28: °C | D28: PA-12 | G28: Productos de pastelería RELLENOS, salvo que sean estables a temperatura ambiente. Es el techo más bajo de los dos y por eso suele mandar él.
A29: Techo del art. 9.3 | B29: 8 | C29: °C | D29: PA-15 | G29: Lo elaborado por la vía del art. 9.1.a) que no sea estable a temperatura ambiente, y lo hecho con ovoproducto del art. 9.2.
A30: Plazo de consumo del art. 9.3 | B30: 24 | C30: horas | D30: PA-15 | G30: Desde la elaboración, con REGISTRO de fecha y hora. No es una vida útil: es un plazo legal, y sólo alcanza a lo que dice el propio art. 9.3.
A31: Umbral analítico de «sin gluten» | B31: 20 | C31: mg/kg | D31: PA-23 | G31: No es una declaración libre: por debajo de 20 mg/kg de gluten en el producto tal y como se vende. Con harina de arroz no basta si el obrador comparte utillaje con harina de trigo.
A33: Merma, packaging y comercial
A34: Merma objetivo | B34: 0.05 | C34: de la producción | D34: kit-tareas-pasteleria/10 | G34: Objetivo precargado en el plan de producción del kit. En una pastelería artesanal se mueve entre el 3 y el 8 %; por encima del 10 % hay que revisar el plan de producción, no el escandallo.
A35: Packaging sobre el coste del producto | B35: 0.1 | C35: del coste | D35: PS-59 | G35: Entre el 5 y el 15 % del coste total del producto. Aquí, el punto medio. En pastelería la caja no es un extra: es parte del producto.
A36: Piezas por cliente | B36: 2.6 | C36: piezas/ticket | D36: supuesto | G36: De aquí sale el ticket medio, que NO se teclea. No existe un ticket medio publicado de pastelería: el tuyo se calcula desde tu carta y tu mix, y por eso se puede publicar diciendo lo que es.
A37: Umbral de rotación del semáforo de surtido | B37: 1 | C37: % del mix | D37: supuesto | G37: Por debajo de este porcentaje del mix, la referencia se considera de rotación baja en la hoja «Decisión de Surtido». Criterio de la casa, no del sector: súbelo si tu carta es más corta.
A39: Precios de compra (la única tabla de precios)
A40: Ingrediente | B40: Precio de compra (€) | C40: Unidad de compra | D40: De dónde sale | G40: Nota
A41: Aceite de girasol | B41: 1.8 | C41: L | D41: supuesto
A42: Aceite de oliva virgen extra | B42: 7.2 | C42: L | D42: supuesto
A43: Agua de azahar | B43: 14 | C43: L | D43: supuesto
A44: Almendra marcona cruda | B44: 15.5 | C44: kg | D44: supuesto
A45: Almendra molida | B45: 13.5 | C45: kg | D45: supuesto
A46: Almidón de maíz | B46: 2.1 | C46: kg | D46: supuesto
A47: Azúcar | B47: 1.2 | C47: kg | D47: copiado del kit
...

Sheet Escandallo por Tanda
A1: Escandallo por Tanda
A2: AI Chef Pro · aichef.pro — Cómo Montar una Pastelería
A3: La unidad de costeo es LA TANDA, no la pieza. Los precios salen de la tabla única de «Parámetros».
A5: Ref | B5: Referencia | C5: Familia | D5: Ingrediente | E5: Cantidad neta | F5: Unidad de uso | G5: Factor de conversión | H5: Merma | I5: Cantidad bruta | J5: Precio de compra (€) | K5: Unidad de compra | L5: Coste de la línea (€) | M5: Procedencia
A6: B1 | B6: Croissant de mantequilla | C6: Bollería | D6: Harina de fuerza | E6: 0.5 | F6: kg | G6: 1 | H6: 0.08 | I6: =IFERROR(E6/(1-H6),"") -> 0.54347826 | J6: =IFERROR(VLOOKUP($D6,'Parámetros'!$A$41:$C$89,2,FALSE),"") -> 1.1 | K6: kg | L6: =IFERROR(I6/G6*J6,"") -> 0.59782609 | M6: COPIA EXACTA de kit-escandallos/05-pasteleria.xlsx, hoja «Croissants». Mismo escandallo en los dos productos: un cliente con los dos no puede ver dos costes distintos de la misma pieza.
A7: B1 | D7: Mantequilla seca (82% MG) | E7: 0.28 | F7: kg | G7: 1 | H7: 0.03 | I7: =IFERROR(E7/(1-H7),"") -> 0.28865979 | J7: =IFERROR(VLOOKUP($D7,'Parámetros'!$A$41:$C$89,2,FALSE),"") -> 12 | K7: kg | L7: =IFERROR(I7/G7*J7,"") -> 3.4639175
A8: B1 | D8: Leche entera | E8: 0.15 | F8: L | G8: 1 | H8: 0.03 | I8: =IFERROR(E8/(1-H8),"") -> 0.15463918 | J8: =IFERROR(VLOOKUP($D8,'Parámetros'!$A$41:$C$89,2,FALSE),"") -> 1.1 | K8: L | L8: =IFERROR(I8/G8*J8,"") -> 0.17010309
A9: B1 | D9: Azúcar | E9: 0.06 | F9: kg | G9: 1 | H9: 0.02 | I9: =IFERROR(E9/(1-H9),"") -> 0.06122449 | J9: =IFERROR(VLOOKUP($D9,'Parámetros'!$A$41:$C$89,2,FALSE),"") -> 1.2 | K9: kg | L9: =IFERROR(I9/G9*J9,"") -> 0.073469388
A10: B1 | D10: Levadura fresca | E10: 0.02 | F10: kg | G10: 1 | H10: 0.05 | I10: =IFERROR(E10/(1-H10),"") -> 0.021052632 | J10: =IFERROR(VLOOKUP($D10,'Parámetros'!$A$41:$C$89,2,FALSE),"") -> 5 | K10: kg | L10: =IFERROR(I10/G10*J10,"") -> 0.10526316
A11: B1 | D11: Sal | E11: 0.01 | F11: kg | G11: 1 | H11: 0.02 | I11: =IFERROR(E11/(1-H11),"") -> 0.010204082 | J11: =IFERROR(VLOOKUP($D11,'Parámetros'!$A$41:$C$89,2,FALSE),"") -> 0.6 | K11: kg | L11: =IFERROR(I11/G11*J11,"") -> 0.006122449
A12: B1 | D12: Huevo (para pintar) | E12: 1 | F12: ud | G12: 12 | H12: 0 | I12: =IFERROR(E12/(1-H12),"") -> 1 | J12: =IFERROR(VLOOKUP($D12,'Parámetros'!$A$41:$C$89,2,FALSE),"") -> 3.6 | K12: docena | L12: =IFERROR(I12/G12*J12,"") -> 0.3
A13: B2 | B13: Pain au chocolat | C13: Bollería | D13: Harina de fuerza | E13: 0.5 | F13: kg | G13: 1 | H13: 0.08 | I13: =IFERROR(E13/(1-H13),"") -> 0.54347826 | J13: =IFERROR(VLOOKUP($D13,'Parámetros'!$A$41:$C$89,2,FALSE),"") -> 1.1 | K13: kg | L13: =IFERROR(I13/G13*J13,"") -> 0.59782609 | M13: supuesto (misma masa que B1, del kit, más dos barras por pieza)
A14: B2 | D14: Mantequilla seca (82% MG) | E14: 0.28 | F14: kg | G14: 1 | H14: 0.03 | I14: =IFERROR(E14/(1-H14),"") -> 0.28865979 | J14: =IFERROR(VLOOKUP($D14,'Parámetros'!$A$41:$C$89,2,FALSE),"") -> 12 | K14: kg | L14: =IFERROR(I14/G14*J14,"") -> 3.4639175
A15: B2 | D15: Leche entera | E15: 0.15 | F15: L | G15: 1 | H15: 0.03 | I15: =IFERROR(E15/(1-H15),"") -> 0.15463918 | J15: =IFERROR(VLOOKUP($D15,'Parámetros'!$A$41:$C$89,2,FALSE),"") -> 1.1 | K15: L | L15: =IFERROR(I15/G15*J15,"") -> 0.17010309
A16: B2 | D16: Azúcar | E16: 0.06 | F16: kg | G16: 1 | H16: 0.02 | I16: =IFERROR(E16/(1-H16),"") -> 0.06122449 | J16: =IFERROR(VLOOKUP($D16,'Parámetros'!$A$41:$C$89,2,FALSE),"") -> 1.2 | K16: kg | L16: =IFERROR(I16/G16*J16,"") -> 0.073469388
A17: B2 | D17: Levadura fresca | E17: 0.02 | F17: kg | G17: 1 | H17: 0.05 | I17: =IFERROR(E17/(1-H17),"") -> 0.021052632 | J17: =IFERROR(VLOOKUP($D17,'Parámetros'!$A$41:$C$89,2,FALSE),"") -> 5 | K17: kg | L17: =IFERROR(I17/G17*J17,"") -> 0.10526316
A18: B2 | D18: Sal | E18: 0.01 | F18: kg | G18: 1 | H18: 0.02 | I18: =IFERROR(E18/(1-H18),"") -> 0.010204082 | J18: =IFERROR(VLOOKUP($D18,'Parámetros'!$A$41:$C$89,2,FALSE),"") -> 0.6 | K18: kg | L18: =IFERROR(I18/G18*J18,"") -> 0.006122449
A19: B2 | D19: Chocolate negro 70% | E19: 0.2 | F19: kg | G19: 1 | H19: 0.02 | I19: =IFERROR(E19/(1-H19),"") -> 0.20408163 | J19: =IFERROR(VLOOKUP($D19,'Parámetros'!$A$41:$C$89,2,FALSE),"") -> 18 | K19: kg | L19: =IFERROR(I19/G19*J19,"") -> 3.6734694
A20: B2 | D20: Huevo (para pintar) | E20: 1 | F20: ud | G20: 12 | H20: 0 | I20: =IFERROR(E20/(1-H20),"") -> 1 | J20: =IFERROR(VLOOKUP($D20,'Parámetros'!$A$41:$C$89,2,FALSE),"") -> 3.6 | K20: docena | L20: =IFERROR(I20/G20*J20,"") -> 0.3
A21: B3 | B21: Napolitana de crema | C21: Bollería | D21: Harina de fuerza | E21: 0.5 | F21: kg | G21: 1 | H21: 0.08 | I21: =IFERROR(E21/(1-H21),"") -> 0.54347826 | J21: =IFERROR(VLOOKUP($D21,'Parámetros'!$A$41:$C$89,2,FALSE),"") -> 1.1 | K21: kg | L21: =IFERROR(I21/G21*J21,"") -> 0.59782609 | M21: supuesto (masa del kit más crema pastelera de ejemplo)
A22: B3 | D22: Mantequilla seca (82% MG) | E22: 0.28 | F22: kg | G22: 1 | H22: 0.03 | I22: =IFERROR(E22/(1-H22),"") -> 0.28865979 | J22: =IFERROR(VLOOKUP($D22,'Parámetros'!$A$41:$C$89,2,FALSE),"") -> 12 | K22: kg | L22: =IFERROR(I22/G22*J22,"") -> 3.4639175
A23: B3 | D23: Leche entera | E23: 0.15 | F23: L | G23: 1 | H23: 0.03 | I23: =IFERROR(E23/(1-H23),"") -> 0.15463918 | J23: =IFERROR(VLOOKUP($D23,'Parámetros'!$A$41:$C$89,2,FALSE),"") -> 1.1 | K23: L | L23: =IFERROR(I23/G23*J23,"") -> 0.17010309
A24: B3 | D24: Azúcar | E24: 0.06 | F24: kg | G24: 1 | H24: 0.02 | I24: =IFERROR(E24/(1-H24),"") -> 0.06122449 | J24: =IFERROR(VLOOKUP($D24,'Parámetros'!$A$41:$C$89,2,FALSE),"") -> 1.2 | K24: kg | L24: =IFERROR(I24/G24*J24,"") -> 0.073469388
A25: B3 | D25: Levadura fresca | E25: 0.02 | F25: kg | G25: 1 | H25: 0.05 | I25: =IFERROR(E25/(1-H25),"") -> 0.021052632 | J25: =IFERROR(VLOOKUP($D25,'Parámetros'!$A$41:$C$89,2,FALSE),"") -> 5 | K25: kg | L25: =IFERROR(I25/G25*J25,"") -> 0.10526316
A26: B3 | D26: Sal | E26: 0.01 | F26: kg | G26: 1 | H26: 0.02 | I26: =IFERROR(E26/(1-H26),"") -> 0.010204082 | J26: =IFERROR(VLOOKUP($D26,'Parámetros'!$A$41:$C$89,2,FALSE),"") -> 0.6 | K26: kg | L26: =IFERROR(I26/G26*J26,"") -> 0.006122449
A27: B3 | D27: Leche entera | E27: 0.6 | F27: L | G27: 1 | H27: 0.02 | I27: =IFERROR(E27/(1-H27),"") -> 0.6122449 | J27: =IFERROR(VLOOKUP($D27,'Parámetros'!$A$41:$C$89,2,FALSE),"") -> 1.1 | K27: L | L27: =IFERROR(I27/G27*J27,"") -> 0.67346939
A28: B3 | D28: Azúcar | E28: 0.14 | F28: kg | G28: 1 | H28: 0.02 | I28: =IFERROR(E28/(1-H28),"") -> 0.14285714 | J28: =IFERROR(VLOOKUP($D28,'Parámetros'!$A$41:$C$89,2,FALSE),"") -> 1.2 | K28: kg | L28: =IFERROR(I28/G28*J28,"") -> 0.17142857
A29: B3 | D29: Huevos (unidades) | E29: 4 | F29: ud | G29: 12 | H29: 0 | I29: =IFERROR(E29/(1-H29),"") -> 4 | J29: =IFERROR(VLOOKUP($D29,'Parámetros'!$A$41:$C$89,2,FALSE),"") -> 3.6 | K29: docena | L29: =IFERROR(I29/G29*J29,"") -> 1.2
A30: B3 | D30: Almidón de maíz | E30: 0.05 | F30: kg | G30: 1 | H30: 0.02 | I30: =IFERROR(E30/(1-H30),"") -> 0.051020408 | J30: =IFERROR(VLOOKUP($D30,'Parámetros'!$A$41:$C$89,2,FALSE),"") -> 2.1 | K30: kg | L30: =IFERROR(I30/G30*J30,"") -> 0.10714286
A31: B3 | D31: Vainilla en pasta | E31: 0.002 | F31: kg | G31: 1 | H31: 0 | I31: =IFERROR(E31/(1-H31),"") -> 0.002 | J31: =IFERROR(VLOOKUP($D31,'Parámetros'!$A$41:$C$89,2,FALSE),"") -> 92 | K31: kg | L31: =IFERROR(I31/G31*J31,"") -> 0.184
A32: B3 | D32: Huevo (para pintar) | E32: 1 | F32: ud | G32: 12 | H32: 0 | I32: =IFERROR(E32/(1-H32),"") -> 1 | J32: =IFERROR(VLOOKUP($D32,'Parámetros'!$A$41:$C$89,2,FALSE),"") -> 3.6 | K32: docena | L32: =IFERROR(I32/G32*J32,"") -> 0.3
A33: B4 | B33: Palmera de hojaldre | C33: Bollería | D33: Harina floja | E33: 0.45 | F33: kg | G33: 1 | H33: 0.08 | I33: =IFERROR(E33/(1-H33),"") -> 0.48913043 | J33: =IFERROR(VLOOKUP($D33,'Parámetros'!$A$41:$C$89,2,FALSE),"") -> 0.9 | K33: kg | L33: =IFERROR(I33/G33*J33,"") -> 0.44021739 | M33: supuesto
A34: B4 | D34: Mantequilla seca (82% MG) | E34: 0.36 | F34: kg | G34: 1 | H34: 0.03 | I34: =IFERROR(E34/(1-H34),"") -> 0.37113402 | J34: =IFERROR(VLOOKUP($D34,'Parámetros'!$A$41:$C$89,2,FALSE),"") -> 12 | K34: kg | L34: =IFERROR(I34/G34*J34,"") -> 4.4536082
A35: B4 | D35: Azúcar | E35: 0.3 | F35: kg | G35: 1 | H35: 0.02 | I35: =IFERROR(E35/(1-H35),"") -> 0.30612245 | J35: =IFERROR(VLOOKUP($D35,'Parámetros'!$A$41:$C$89,2,FALSE),"") -> 1.2 | K35: kg | L35: =IFERROR(I35/G35*J35,"") -> 0.36734694
A36: B4 | D36: Sal | E36: 0.01 | F36: kg | G36: 1 | H36: 0.02 | I36: =IFERROR(E36/(1-H36),"") -> 0.010204082 | J36: =IFERROR(VLOOKUP($D36,'Parámetros'!$A$41:$C$89,2,FALSE),"") -> 0.6 | K36: kg | L36: =IFERROR(I36/G36*J36,"") -> 0.006122449
A37: B5 | B37: Caracola de pasas | C37: Bollería | D37: Harina de fuerza | E37: 0.45 | F37: kg | G37: 1 | H37: 0.08 | I37: =IFERROR(E37/(1-H37),"") -> 0.48913043 | J37: =IFERROR(VLOOKUP($D37,'Parámetros'!$A$41:$C$89,2,FALSE),"") -> 1.1 | K37: kg | L37: =IFERROR(I37/G37*J37,"") -> 0.53804348 | M37: supuesto
A38: B5 | D38: Mantequilla seca (82% MG) | E38: 0.22 | F38: kg | G38: 1 | H38: 0.03 | I38: =IFERROR(E38/(1-H38),"") -> 0.22680412 | J38: =IFERROR(VLOOKUP($D38,'Parámetros'!$A$41:$C$89,2,FALSE),"") -> 12 | K38: kg | L38: =IFERROR(I38/G38*J38,"") -> 2.7216495
A39: B5 | D39: Leche entera | E39: 0.14 | F39: L | G39: 1 | H39: 0.03 | I39: =IFERROR(E39/(1-H39),"") -> 0.1443299 | J39: =IFERROR(VLOOKUP($D39,'Parámetros'!$A$41:$C$89,2,FALSE),"") -> 1.1 | K39: L | L39: =IFERROR(I39/G39*J39,"") -> 0.15876289
A40: B5 | D40: Azúcar | E40: 0.05 | F40: kg | G40: 1 | H40: 0.02 | I40: =IFERROR(E40/(1-H40),"") -> 0.051020408 | J40: =IFERROR(VLOOKUP($D40,'Parámetros'!$A$41:$C$89,2,FALSE),"") -> 1.2 | K40: kg | L40: =IFERROR(I40/G40*J40,"") -> 0.06122449
A41: B5 | D41: Levadura fresca | E41: 0.018 | F41: kg | G41: 1 | H41: 0.05 | I41: =IFERROR(E41/(1-H41),"") -> 0.018947368 | J41: =IFERROR(VLOOKUP($D41,'Parámetros'!$A$41:$C$89,2,FALSE),"") -> 5 | K41: kg | L41: =IFERROR(I41/G41*J41,"") -> 0.094736842
...

Sheet Coste Hora y Mano de Obra
A1: Coste Hora y Mano de Obra
A2: AI Chef Pro · aichef.pro — Cómo Montar una Pastelería
A3: La mano de obra imputada por pieza. Es el capítulo que enseña a dejar de regalar tu trabajo.
A5: Ref | B5: Referencia | C5: Familia | D5: Uds por tanda | E5: Minutos de mano de obra por tanda | F5: Horas de mano de obra por tanda | G5: Coste hora de obrador (€) | H5: Coste de mano de obra de la tanda (€) | I5: Coste de mano de obra por unidad (€) | J5: Coste de materia por unidad (€) | K5: Coste total por unidad (€) | L5: PVP con IVA (€) | M5: IVA | N5: PVP sin IVA (€) | O5: Food cost | P5: Margen bruto | Q5: Margen por unidad (€) | R5: Peso de la mano de obra sobre el coste | S5: Minutos por pieza
A6: B1 | B6: Croissant de mantequilla | C6: Bollería | D6: ='Escandallo por Tanda'!D236 -> 20 | E6: 55 | F6: =IFERROR(E6/60,"") -> 0.91666667 | G6: ='Parámetros'!$B$16 -> 17.937911 | H6: =IFERROR(F6*G6,"") -> 16.443085 | I6: =IFERROR(H6/D6,"") -> 0.82215427 | J6: ='Escandallo por Tanda'!G236 -> 0.23583509 | K6: =IFERROR(I6+J6,"") -> 1.0579894 | L6: 1.6 | M6: 0.1 | N6: =IFERROR(L6/(1+M6),"") -> 1.4545455 | O6: =IFERROR(J6/N6,"") -> 0.16213662 | P6: =IFERROR(1-O6,"") -> 0.83786338 | Q6: =IFERROR(N6-K6,"") -> 0.3965561 | R6: =IFERROR(I6/K6,"") -> 0.77709125 | S6: =IFERROR(E6/D6,"") -> 2.75
A7: B2 | B7: Pain au chocolat | C7: Bollería | D7: ='Escandallo por Tanda'!D237 -> 20 | E7: 55 | F7: =IFERROR(E7/60,"") -> 0.91666667 | G7: ='Parámetros'!$B$16 -> 17.937911 | H7: =IFERROR(F7*G7,"") -> 16.443085 | I7: =IFERROR(H7/D7,"") -> 0.82215427 | J7: ='Escandallo por Tanda'!G237 -> 0.41950855 | K7: =IFERROR(I7+J7,"") -> 1.2416628 | L7: 1.85 | M7: 0.1 | N7: =IFERROR(L7/(1+M7),"") -> 1.6818182 | O7: =IFERROR(J7/N7,"") -> 0.24943752 | P7: =IFERROR(1-O7,"") -> 0.75056248 | Q7: =IFERROR(N7-K7,"") -> 0.44015536 | R7: =IFERROR(I7/K7,"") -> 0.66213972 | S7: =IFERROR(E7/D7,"") -> 2.75
A8: B3 | B8: Napolitana de crema | C8: Bollería | D8: ='Escandallo por Tanda'!D238 -> 20 | E8: 65 | F8: =IFERROR(E8/60,"") -> 1.0833333 | G8: ='Parámetros'!$B$16 -> 17.937911 | H8: =IFERROR(F8*G8,"") -> 19.432737 | I8: =IFERROR(H8/D8,"") -> 0.97163686 | J8: ='Escandallo por Tanda'!G238 -> 0.35263713 | K8: =IFERROR(I8+J8,"") -> 1.324274 | L8: 1.85 | M8: 0.1 | N8: =IFERROR(L8/(1+M8),"") -> 1.6818182 | O8: =IFERROR(J8/N8,"") -> 0.20967613 | P8: =IFERROR(1-O8,"") -> 0.79032387 | Q8: =IFERROR(N8-K8,"") -> 0.35754419 | R8: =IFERROR(I8/K8,"") -> 0.73371287 | S8: =IFERROR(E8/D8,"") -> 3.25
A9: B4 | B9: Palmera de hojaldre | C9: Bollería | D9: ='Escandallo por Tanda'!D239 -> 24 | E9: 40 | F9: =IFERROR(E9/60,"") -> 0.66666667 | G9: ='Parámetros'!$B$16 -> 17.937911 | H9: =IFERROR(F9*G9,"") -> 11.958608 | I9: =IFERROR(H9/D9,"") -> 0.49827531 | J9: ='Escandallo por Tanda'!G239 -> 0.21947063 | K9: =IFERROR(I9+J9,"") -> 0.71774594 | L9: 1.7 | M9: 0.1 | N9: =IFERROR(L9/(1+M9),"") -> 1.5454545 | O9: =IFERROR(J9/N9,"") -> 0.14201041 | P9: =IFERROR(1-O9,"") -> 0.85798959 | Q9: =IFERROR(N9-K9,"") -> 0.82770861 | R9: =IFERROR(I9/K9,"") -> 0.69422241 | S9: =IFERROR(E9/D9,"") -> 1.6666667
A10: B5 | B10: Caracola de pasas | C10: Bollería | D10: ='Escandallo por Tanda'!D240 -> 20 | E10: 60 | F10: =IFERROR(E10/60,"") -> 1 | G10: ='Parámetros'!$B$16 -> 17.937911 | H10: =IFERROR(F10*G10,"") -> 17.937911 | I10: =IFERROR(H10/D10,"") -> 0.89689557 | J10: ='Escandallo por Tanda'!G240 -> 0.30624739 | K10: =IFERROR(I10+J10,"") -> 1.203143 | L10: 1.85 | M10: 0.1 | N10: =IFERROR(L10/(1+M10),"") -> 1.6818182 | O10: =IFERROR(J10/N10,"") -> 0.18209304 | P10: =IFERROR(1-O10,"") -> 0.81790696 | Q10: =IFERROR(N10-K10,"") -> 0.47867523 | R10: =IFERROR(I10/K10,"") -> 0.74546051 | S10: =IFERROR(E10/D10,"") -> 3
A11: B6 | B11: Ensaimada | C11: Bollería | D11: ='Escandallo por Tanda'!D241 -> 16 | E11: 70 | F11: =IFERROR(E11/60,"") -> 1.1666667 | G11: ='Parámetros'!$B$16 -> 17.937911 | H11: =IFERROR(F11*G11,"") -> 20.927563 | I11: =IFERROR(H11/D11,"") -> 1.3079727 | J11: ='Escandallo por Tanda'!G241 -> 0.18023428 | K11: =IFERROR(I11+J11,"") -> 1.488207 | L11: 1.95 | M11: 0.1 | N11: =IFERROR(L11/(1+M11),"") -> 1.7727273 | O11: =IFERROR(J11/N11,"") -> 0.10167062 | P11: =IFERROR(1-O11,"") -> 0.89832938 | Q11: =IFERROR(N11-K11,"") -> 0.28452029 | R11: =IFERROR(I11/K11,"") -> 0.87889166 | S11: =IFERROR(E11/D11,"") -> 4.375
A12: PI1 | B12: Milhojas | C12: Pastelería individual | D12: ='Escandallo por Tanda'!D242 -> 18 | E12: 75 | F12: =IFERROR(E12/60,"") -> 1.25 | G12: ='Parámetros'!$B$16 -> 17.937911 | H12: =IFERROR(F12*G12,"") -> 22.422389 | I12: =IFERROR(H12/D12,"") -> 1.2456883 | J12: ='Escandallo por Tanda'!G242 -> 0.44694191 | K12: =IFERROR(I12+J12,"") -> 1.6926302 | L12: 3.6 | M12: 0.1 | N12: =IFERROR(L12/(1+M12),"") -> 3.2727273 | O12: =IFERROR(J12/N12,"") -> 0.13656558 | P12: =IFERROR(1-O12,"") -> 0.86343442 | Q12: =IFERROR(N12-K12,"") -> 1.5800971 | R12: =IFERROR(I12/K12,"") -> 0.73594828 | S12: =IFERROR(E12/D12,"") -> 4.1666667
A13: PI2 | B13: Éclair | C13: Pastelería individual | D13: ='Escandallo por Tanda'!D243 -> 24 | E13: 65 | F13: =IFERROR(E13/60,"") -> 1.0833333 | G13: ='Parámetros'!$B$16 -> 17.937911 | H13: =IFERROR(F13*G13,"") -> 19.432737 | I13: =IFERROR(H13/D13,"") -> 0.80969739 | J13: ='Escandallo por Tanda'!G243 -> 0.33825574 | K13: =IFERROR(I13+J13,"") -> 1.1479531 | L13: 3.2 | M13: 0.1 | N13: =IFERROR(L13/(1+M13),"") -> 2.9090909 | O13: =IFERROR(J13/N13,"") -> 0.11627541 | P13: =IFERROR(1-O13,"") -> 0.88372459 | Q13: =IFERROR(N13-K13,"") -> 1.7611378 | R13: =IFERROR(I13/K13,"") -> 0.70534011 | S13: =IFERROR(E13/D13,"") -> 2.7083333
A14: PI3 | B14: Macarons de frambuesa | C14: Pastelería individual | D14: ='Escandallo por Tanda'!D244 -> 30 | E14: 80 | F14: =IFERROR(E14/60,"") -> 1.3333333 | G14: ='Parámetros'!$B$16 -> 17.937911 | H14: =IFERROR(F14*G14,"") -> 23.917215 | I14: =IFERROR(H14/D14,"") -> 0.7972405 | J14: ='Escandallo por Tanda'!G244 -> 0.19650996 | K14: =IFERROR(I14+J14,"") -> 0.99375046 | L14: 2.1 | M14: 0.1 | N14: =IFERROR(L14/(1+M14),"") -> 1.9090909 | O14: =IFERROR(J14/N14,"") -> 0.10293379 | P14: =IFERROR(1-O14,"") -> 0.89706621 | Q14: =IFERROR(N14-K14,"") -> 0.91534045 | R14: =IFERROR(I14/K14,"") -> 0.80225422 | S14: =IFERROR(E14/D14,"") -> 2.6666667
A15: PI4 | B15: Tartaleta de frutas | C15: Pastelería individual | D15: ='Escandallo por Tanda'!D245 -> 20 | E15: 85 | F15: =IFERROR(E15/60,"") -> 1.4166667 | G15: ='Parámetros'!$B$16 -> 17.937911 | H15: =IFERROR(F15*G15,"") -> 25.412041 | I15: =IFERROR(H15/D15,"") -> 1.2706021 | J15: ='Escandallo por Tanda'!G245 -> 0.52498604 | K15: =IFERROR(I15+J15,"") -> 1.7955881 | L15: 3.8 | M15: 0.1 | N15: =IFERROR(L15/(1+M15),"") -> 3.4545455 | O15: =IFERROR(J15/N15,"") -> 0.15196964 | P15: =IFERROR(1-O15,"") -> 0.84803036 | Q15: =IFERROR(N15-K15,"") -> 1.6589574 | R15: =IFERROR(I15/K15,"") -> 0.70762446 | S15: =IFERROR(E15/D15,"") -> 4.25
A16: PI5 | B16: Lionesa o profiterol | C16: Pastelería individual | D16: ='Escandallo por Tanda'!D246 -> 40 | E16: 60 | F16: =IFERROR(E16/60,"") -> 1 | G16: ='Parámetros'!$B$16 -> 17.937911 | H16: =IFERROR(F16*G16,"") -> 17.937911 | I16: =IFERROR(H16/D16,"") -> 0.44844778 | J16: ='Escandallo por Tanda'!G246 -> 0.19817681 | K16: =IFERROR(I16+J16,"") -> 0.64662459 | L16: 2.3 | M16: 0.1 | N16: =IFERROR(L16/(1+M16),"") -> 2.0909091 | O16: =IFERROR(J16/N16,"") -> 0.094780213 | P16: =IFERROR(1-O16,"") -> 0.90521979 | Q16: =IFERROR(N16-K16,"") -> 1.4442845 | R16: =IFERROR(I16/K16,"") -> 0.69352108 | S16: =IFERROR(E16/D16,"") -> 1.5
A17: PI6 | B17: Entremet individual | C17: Pastelería individual | D17: ='Escandallo por Tanda'!D247 -> 16 | E17: 95 | F17: =IFERROR(E17/60,"") -> 1.5833333 | G17: ='Parámetros'!$B$16 -> 17.937911 | H17: =IFERROR(F17*G17,"") -> 28.401693 | I17: =IFERROR(H17/D17,"") -> 1.7751058 | J17: ='Escandallo por Tanda'!G247 -> 0.82474126 | K17: =IFERROR(I17+J17,"") -> 2.5998471 | L17: 4.5 | M17: 0.1 | N17: =IFERROR(L17/(1+M17),"") -> 4.0909091 | O17: =IFERROR(J17/N17,"") -> 0.20160342 | P17: =IFERROR(1-O17,"") -> 0.79839658 | Q17: =IFERROR(N17-K17,"") -> 1.491062 | R17: =IFERROR(I17/K17,"") -> 0.68277316 | S17: =IFERROR(E17/D17,"") -> 5.9375
... A35: TP8 | B35: Mona de Pascua | C35: Temporada | D35: ='Escandallo por Tanda'!D265 -> 14 | E35: 80 | F35: =IFERROR(E35/60,"") -> 1.3333333 | G35: ='Parámetros'!$B$16 -> 17.937911 | H35: =IFERROR(F35*G35,"") -> 23.917215 | I35: =IFERROR(H35/D35,"") -> 1.7083725 | J35: ='Escandallo por Tanda'!G265 -> 2.0148755 | K35: =IFERROR(I35+J35,"") -> 3.723248 | L35: 13.5 | M35: 0.1 | N35: =IFERROR(L35/(1+M35),"") -> 12.272727 | O35: =IFERROR(J35/N35,"") -> 0.16417504 | P35: =IFERROR(1-O35,"") -> 0.83582496 | Q35: =IFERROR(N35-K35,"") -> 8.5494793 | R35: =IFERROR(I35/K35,"") -> 0.4588393 | S35: =IFERROR(E35/D35,"") -> 5.7142857
A36: MEDIA / TOTAL | H36: =SUM(H6:H35) -> 542.62182 | O36: =IFERROR(AVERAGE(O6:O35),"") -> 0.19140911 | Q36: =IFERROR(AVERAGE(Q6:Q35),"") -> 1.7494637 | R36: =IFERROR(AVERAGE(R6:R35),"") -> 0.63296267
A38: El food cost de esta hoja compara MATERIA con PVP sin IVA, que es la definición del sector. La mano de obra no entra en el food cost: entra en el coste total y se le come el margen. Por eso una referencia puede tener un food cost estupendo y dejarte menos dinero que otra peor: mira siempre las dos columnas juntas.
A39: El margen bruto de la columna P es uno menos el food cost, calculado, no tecleado. Es la misma regla dicha del revés, y por eso el libro no te pide los dos números en ningún sitio.
A40: La columna R es la que duele: en las referencias de más trabajo la mano de obra es más de la mitad del coste. Ahí no se gana bajando el precio de la harina, se gana cambiando el proceso o el precio.
A41: Las celdas en rojo del food cost son las que se pasan de tu objetivo de «Parámetros»; las del margen, las que no dejan dinero. Lo que hacer con ellas está en la hoja «Decisión de Surtido».
A43: Versión 1.0 · septiembre 2026 · aichef.pro/guia-pasteleria-obrador · info@aichef.pro

Sheet Decisión de Huevo y Temperatura
A1: Decisión de Huevo y Temperatura
A2: AI Chef Pro · aichef.pro — Cómo Montar una Pastelería
A3: Dos salidas separadas, cada una con su artículo: la TEMPERATURA (el más bajo de los techos que apliquen) y el PLAZO legal del art. 9.3. La vida útil la declaras tú.
A5: Ref | B5: Referencia | C5: Familia | D5: Vía legal del huevo | E5: ¿Producto relleno? | F5: ¿Estable a temperatura ambiente? | G5: Techo del art. 4.1 fila 9 (°C) | H5: Techo del art. 9.3 (°C) | I5: Temperatura de conservación (°C) | J5: Cuál manda | K5: Plazo legal (art. 9.3) | L5: Vida útil declarada por ti (días) | M5: Dónde va en el mostrador | N5: Qué dice esa vía | O5: Coherencia D / F
A6: B1 | B6: Croissant de mantequilla | C6: Bollería | D6: estable a ambiente | E6: No | F6: Sí | G6: =IF(AND($E6="Sí",$F6="No"),'Parámetros'!$B$28,"") | H6: =IF(AND(OR($D6="70/2",$D6="ovoproducto"),$F6="No"),'Parámetros'!$B$29,"") | I6: =IF(AND(G6="",H6=""),"",IF(G6="",H6,IF(H6="",G6,MIN(G6,H6)))) | J6: =IF(AND(G6="",H6=""),"Ni la fila 9 del art. 4.1 ni el art. 9.3 le fijan techo: vitrina de ambiente.",IF(AND(G6<>"",H6<>""),"Le aplican los DOS techos y manda el más bajo, el de la fila 9 del art. 4.1. No es un conflicto: son dos topes distintos.",IF(G6<>"","Manda la fila 9 del art. 4.1: producto de pastelería relleno que no es estable a temperatura ambiente.","Manda el art. 9.3: elaborado por la vía del art. 9.1.a) sin ser estable, o con ovoproducto del art. 9.2."))) -> Ni la fila 9 del art. 4.1 ni el art. 9.3 le fijan techo: vitrina de ambiente. | K6: =IF(AND(OR($D6="70/2",$D6="ovoproducto"),$F6="No"),'Parámetros'!$B$30,"No aplica") -> No aplica | L6: Por declarar en tu APPCC | M6: =IF(I6="","Vitrina de ambiente","Vitrina refrigerada") -> Vitrina de ambiente | N6: Vía 1.a) y el producto terminado ES estable a temperatura ambiente: el art. 9.3 no le fija ni temperatura ni plazo, y la fila 9 del art. 4.1 lo exceptúa aunque vaya relleno. | O6: =IF(AND($D6="estable a ambiente",$F6="No"),"Incoherente: has elegido la vía de producto estable y luego has dicho que no lo es","")
A7: B2 | B7: Pain au chocolat | C7: Bollería | D7: estable a ambiente | E7: No | F7: Sí | G7: =IF(AND($E7="Sí",$F7="No"),'Parámetros'!$B$28,"") | H7: =IF(AND(OR($D7="70/2",$D7="ovoproducto"),$F7="No"),'Parámetros'!$B$29,"") | I7: =IF(AND(G7="",H7=""),"",IF(G7="",H7,IF(H7="",G7,MIN(G7,H7)))) | J7: =IF(AND(G7="",H7=""),"Ni la fila 9 del art. 4.1 ni el art. 9.3 le fijan techo: vitrina de ambiente.",IF(AND(G7<>"",H7<>""),"Le aplican los DOS techos y manda el más bajo, el de la fila 9 del art. 4.1. No es un conflicto: son dos topes distintos.",IF(G7<>"","Manda la fila 9 del art. 4.1: producto de pastelería relleno que no es estable a temperatura ambiente.","Manda el art. 9.3: elaborado por la vía del art. 9.1.a) sin ser estable, o con ovoproducto del art. 9.2."))) -> Ni la fila 9 del art. 4.1 ni el art. 9.3 le fijan techo: vitrina de ambiente. | K7: =IF(AND(OR($D7="70/2",$D7="ovoproducto"),$F7="No"),'Parámetros'!$B$30,"No aplica") -> No aplica | L7: Por declarar en tu APPCC | M7: =IF(I7="","Vitrina de ambiente","Vitrina refrigerada") -> Vitrina de ambiente | N7: Vía 1.a) y el producto terminado ES estable a temperatura ambiente: el art. 9.3 no le fija ni temperatura ni plazo, y la fila 9 del art. 4.1 lo exceptúa aunque vaya relleno. | O7: =IF(AND($D7="estable a ambiente",$F7="No"),"Incoherente: has elegido la vía de producto estable y luego has dicho que no lo es","")
A8: B3 | B8: Napolitana de crema | C8: Bollería | D8: 70/2 | E8: Sí | F8: No | G8: =IF(AND($E8="Sí",$F8="No"),'Parámetros'!$B$28,"") -> 4 | H8: =IF(AND(OR($D8="70/2",$D8="ovoproducto"),$F8="No"),'Parámetros'!$B$29,"") -> 8 | I8: =IF(AND(G8="",H8=""),"",IF(G8="",H8,IF(H8="",G8,MIN(G8,H8)))) -> 4 | J8: =IF(AND(G8="",H8=""),"Ni la fila 9 del art. 4.1 ni el art. 9.3 le fijan techo: vitrina de ambiente.",IF(AND(G8<>"",H8<>""),"Le aplican los DOS techos y manda el más bajo, el de la fila 9 del art. 4.1. No es un conflicto: son dos topes distintos.",IF(G8<>"","Manda la fila 9 del art. 4.1: producto de pastelería relleno que no es estable a temperatura ambiente.","Manda el art. 9.3: elaborado por la vía del art. 9.1.a) sin ser estable, o con ovoproducto del art. 9.2."))) -> Le aplican los DOS techos y manda el más bajo, el de la fila 9 del art. 4.1. No es un conflicto: son dos topes distintos. | K8: =IF(AND(OR($D8="70/2",$D8="ovoproducto"),$F8="No"),'Parámetros'!$B$30,"No aplica") -> 24 | L8: Por declarar en tu APPCC | M8: =IF(I8="","Vitrina de ambiente","Vitrina refrigerada") -> Vitrina refrigerada | N8: Tratamiento térmico de 70 °C durante 2 s en el centro del producto, o cualquier combinación equivalente (art. 9.1.a). | O8: =IF(AND($D8="estable a ambiente",$F8="No"),"Incoherente: has elegido la vía de producto estable y luego has dicho que no lo es","")
A9: B4 | B9: Palmera de hojaldre | C9: Bollería | D9: sin huevo | E9: No | F9: Sí | G9: =IF(AND($E9="Sí",$F9="No"),'Parámetros'!$B$28,"") | H9: =IF(AND(OR($D9="70/2",$D9="ovoproducto"),$F9="No"),'Parámetros'!$B$29,"") | I9: =IF(AND(G9="",H9=""),"",IF(G9="",H9,IF(H9="",G9,MIN(G9,H9)))) | J9: =IF(AND(G9="",H9=""),"Ni la fila 9 del art. 4.1 ni el art. 9.3 le fijan techo: vitrina de ambiente.",IF(AND(G9<>"",H9<>""),"Le aplican los DOS techos y manda el más bajo, el de la fila 9 del art. 4.1. No es un conflicto: son dos topes distintos.",IF(G9<>"","Manda la fila 9 del art. 4.1: producto de pastelería relleno que no es estable a temperatura ambiente.","Manda el art. 9.3: elaborado por la vía del art. 9.1.a) sin ser estable, o con ovoproducto del art. 9.2."))) -> Ni la fila 9 del art. 4.1 ni el art. 9.3 le fijan techo: vitrina de ambiente. | K9: =IF(AND(OR($D9="70/2",$D9="ovoproducto"),$F9="No"),'Parámetros'!$B$30,"No aplica") -> No aplica | L9: Por declarar en tu APPCC | M9: =IF(I9="","Vitrina de ambiente","Vitrina refrigerada") -> Vitrina de ambiente | N9: La elaboración no lleva huevo en ninguna forma: el art. 9 no le aplica. | O9: =IF(AND($D9="estable a ambiente",$F9="No"),"Incoherente: has elegido la vía de producto estable y luego has dicho que no lo es","")
A10: B5 | B10: Caracola de pasas | C10: Bollería | D10: 70/2 | E10: Sí | F10: No | G10: =IF(AND($E10="Sí",$F10="No"),'Parámetros'!$B$28,"") -> 4 | H10: =IF(AND(OR($D10="70/2",$D10="ovoproducto"),$F10="No"),'Parámetros'!$B$29,"") -> 8 | I10: =IF(AND(G10="",H10=""),"",IF(G10="",H10,IF(H10="",G10,MIN(G10,H10)))) -> 4 | J10: =IF(AND(G10="",H10=""),"Ni la fila 9 del art. 4.1 ni el art. 9.3 le fijan techo: vitrina de ambiente.",IF(AND(G10<>"",H10<>""),"Le aplican los DOS techos y manda el más bajo, el de la fila 9 del art. 4.1. No es un conflicto: son dos topes distintos.",IF(G10<>"","Manda la fila 9 del art. 4.1: producto de pastelería relleno que no es estable a temperatura ambiente.","Manda el art. 9.3: elaborado por la vía del art. 9.1.a) sin ser estable, o con ovoproducto del art. 9.2."))) -> Le aplican los DOS techos y manda el más bajo, el de la fila 9 del art. 4.1. No es un conflicto: son dos topes distintos. | K10: =IF(AND(OR($D10="70/2",$D10="ovoproducto"),$F10="No"),'Parámetros'!$B$30,"No aplica") -> 24 | L10: Por declarar en tu APPCC | M10: =IF(I10="","Vitrina de ambiente","Vitrina refrigerada") -> Vitrina refrigerada | N10: Tratamiento térmico de 70 °C durante 2 s en el centro del producto, o cualquier combinación equivalente (art. 9.1.a). | O10: =IF(AND($D10="estable a ambiente",$F10="No"),"Incoherente: has elegido la vía de producto estable y luego has dicho que no lo es","")
A11: B6 | B11: Ensaimada | C11: Bollería | D11: estable a ambiente | E11: No | F11: Sí | G11: =IF(AND($E11="Sí",$F11="No"),'Parámetros'!$B$28,"") | H11: =IF(AND(OR($D11="70/2",$D11="ovoproducto"),$F11="No"),'Parámetros'!$B$29,"") | I11: =IF(AND(G11="",H11=""),"",IF(G11="",H11,IF(H11="",G11,MIN(G11,H11)))) | J11: =IF(AND(G11="",H11=""),"Ni la fila 9 del art. 4.1 ni el art. 9.3 le fijan techo: vitrina de ambiente.",IF(AND(G11<>"",H11<>""),"Le aplican los DOS techos y manda el más bajo, el de la fila 9 del art. 4.1. No es un conflicto: son dos topes distintos.",IF(G11<>"","Manda la fila 9 del art. 4.1: producto de pastelería relleno que no es estable a temperatura ambiente.","Manda el art. 9.3: elaborado por la vía del art. 9.1.a) sin ser estable, o con ovoproducto del art. 9.2."))) -> Ni la fila 9 del art. 4.1 ni el art. 9.3 le fijan techo: vitrina de ambiente. | K11: =IF(AND(OR($D11="70/2",$D11="ovoproducto"),$F11="No"),'Parámetros'!$B$30,"No aplica") -> No aplica | L11: Por declarar en tu APPCC | M11: =IF(I11="","Vitrina de ambiente","Vitrina refrigerada") -> Vitrina de ambiente | N11: Vía 1.a) y el producto terminado ES estable a temperatura ambiente: el art. 9.3 no le fija ni temperatura ni plazo, y la fila 9 del art. 4.1 lo exceptúa aunque vaya relleno. | O11: =IF(AND($D11="estable a ambiente",$F11="No"),"Incoherente: has elegido la vía de producto estable y luego has dicho que no lo es","")
A12: PI1 | B12: Milhojas | C12: Pastelería individual | D12: 70/2 | E12: Sí | F12: No | G12: =IF(AND($E12="Sí",$F12="No"),'Parámetros'!$B$28,"") -> 4 | H12: =IF(AND(OR($D12="70/2",$D12="ovoproducto"),$F12="No"),'Parámetros'!$B$29,"") -> 8 | I12: =IF(AND(G12="",H12=""),"",IF(G12="",H12,IF(H12="",G12,MIN(G12,H12)))) -> 4 | J12: =IF(AND(G12="",H12=""),"Ni la fila 9 del art. 4.1 ni el art. 9.3 le fijan techo: vitrina de ambiente.",IF(AND(G12<>"",H12<>""),"Le aplican los DOS techos y manda el más bajo, el de la fila 9 del art. 4.1. No es un conflicto: son dos topes distintos.",IF(G12<>"","Manda la fila 9 del art. 4.1: producto de pastelería relleno que no es estable a temperatura ambiente.","Manda el art. 9.3: elaborado por la vía del art. 9.1.a) sin ser estable, o con ovoproducto del art. 9.2."))) -> Le aplican los DOS techos y manda el más bajo, el de la fila 9 del art. 4.1. No es un conflicto: son dos topes distintos. | K12: =IF(AND(OR($D12="70/2",$D12="ovoproducto"),$F12="No"),'Parámetros'!$B$30,"No aplica") -> 24 | L12: Por declarar en tu APPCC | M12: =IF(I12="","Vitrina de ambiente","Vitrina refrigerada") -> Vitrina refrigerada | N12: Tratamiento térmico de 70 °C durante 2 s en el centro del producto, o cualquier combinación equivalente (art. 9.1.a). | O12: =IF(AND($D12="estable a ambiente",$F12="No"),"Incoherente: has elegido la vía de producto estable y luego has dicho que no lo es","")
A13: PI2 | B13: Éclair | C13: Pastelería individual | D13: 70/2 | E13: Sí | F13: No | G13: =IF(AND($E13="Sí",$F13="No"),'Parámetros'!$B$28,"") -> 4 | H13: =IF(AND(OR($D13="70/2",$D13="ovoproducto"),$F13="No"),'Parámetros'!$B$29,"") -> 8 | I13: =IF(AND(G13="",H13=""),"",IF(G13="",H13,IF(H13="",G13,MIN(G13,H13)))) -> 4 | J13: =IF(AND(G13="",H13=""),"Ni la fila 9 del art. 4.1 ni el art. 9.3 le fijan techo: vitrina de ambiente.",IF(AND(G13<>"",H13<>""),"Le aplican los DOS techos y manda el más bajo, el de la fila 9 del art. 4.1. No es un conflicto: son dos topes distintos.",IF(G13<>"","Manda la fila 9 del art. 4.1: producto de pastelería relleno que no es estable a temperatura ambiente.","Manda el art. 9.3: elaborado por la vía del art. 9.1.a) sin ser estable, o con ovoproducto del art. 9.2."))) -> Le aplican los DOS techos y manda el más bajo, el de la fila 9 del art. 4.1. No es un conflicto: son dos topes distintos. | K13: =IF(AND(OR($D13="70/2",$D13="ovoproducto"),$F13="No"),'Parámetros'!$B$30,"No aplica") -> 24 | L13: Por declarar en tu APPCC | M13: =IF(I13="","Vitrina de ambiente","Vitrina refrigerada") -> Vitrina refrigerada | N13: Tratamiento térmico de 70 °C durante 2 s en el centro del producto, o cualquier combinación equivalente (art. 9.1.a). | O13: =IF(AND($D13="estable a ambiente",$F13="No"),"Incoherente: has elegido la vía de producto estable y luego has dicho que no lo es","")
A14: PI3 | B14: Macarons de frambuesa | C14: Pastelería individual | D14: 70/2 | E14: Sí | F14: No | G14: =IF(AND($E14="Sí",$F14="No"),'Parámetros'!$B$28,"") -> 4 | H14: =IF(AND(OR($D14="70/2",$D14="ovoproducto"),$F14="No"),'Parámetros'!$B$29,"") -> 8 | I14: =IF(AND(G14="",H14=""),"",IF(G14="",H14,IF(H14="",G14,MIN(G14,H14)))) -> 4 | J14: =IF(AND(G14="",H14=""),"Ni la fila 9 del art. 4.1 ni el art. 9.3 le fijan techo: vitrina de ambiente.",IF(AND(G14<>"",H14<>""),"Le aplican los DOS techos y manda el más bajo, el de la fila 9 del art. 4.1. No es un conflicto: son dos topes distintos.",IF(G14<>"","Manda la fila 9 del art. 4.1: producto de pastelería relleno que no es estable a temperatura ambiente.","Manda el art. 9.3: elaborado por la vía del art. 9.1.a) sin ser estable, o con ovoproducto del art. 9.2."))) -> Le aplican los DOS techos y manda el más bajo, el de la fila 9 del art. 4.1. No es un conflicto: son dos topes distintos. | K14: =IF(AND(OR($D14="70/2",$D14="ovoproducto"),$F14="No"),'Parámetros'!$B$30,"No aplica") -> 24 | L14: Por declarar en tu APPCC | M14: =IF(I14="","Vitrina de ambiente","Vitrina refrigerada") -> Vitrina refrigerada | N14: Tratamiento térmico de 70 °C durante 2 s en el centro del producto, o cualquier combinación equivalente (art. 9.1.a). | O14: =IF(AND($D14="estable a ambiente",$F14="No"),"Incoherente: has elegido la vía de producto estable y luego has dicho que no lo es","")
A15: PI4 | B15: Tartaleta de frutas | C15: Pastelería individual | D15: 70/2 | E15: Sí | F15: No | G15: =IF(AND($E15="Sí",$F15="No"),'Parámetros'!$B$28,"") -> 4 | H15: =IF(AND(OR($D15="70/2",$D15="ovoproducto"),$F15="No"),'Parámetros'!$B$29,"") -> 8 | I15: =IF(AND(G15="",H15=""),"",IF(G15="",H15,IF(H15="",G15,MIN(G15,H15)))) -> 4 | J15: =IF(AND(G15="",H15=""),"Ni la fila 9 del art. 4.1 ni el art. 9.3 le fijan techo: vitrina de ambiente.",IF(AND(G15<>"",H15<>""),"Le aplican los DOS techos y manda el más bajo, el de la fila 9 del art. 4.1. No es un conflicto: son dos topes distintos.",IF(G15<>"","Manda la fila 9 del art. 4.1: producto de pastelería relleno que no es estable a temperatura ambiente.","Manda el art. 9.3: elaborado por la vía del art. 9.1.a) sin ser estable, o con ovoproducto del art. 9.2."))) -> Le aplican los DOS techos y manda el más bajo, el de la fila 9 del art. 4.1. No es un conflicto: son dos topes distintos. | K15: =IF(AND(OR($D15="70/2",$D15="ovoproducto"),$F15="No"),'Parámetros'!$B$30,"No aplica") -> 24 | L15: Por declarar en tu APPCC | M15: =IF(I15="","Vitrina de ambiente","Vitrina refrigerada") -> Vitrina refrigerada | N15: Tratamiento térmico de 70 °C durante 2 s en el centro del producto, o cualquier combinación equivalente (art. 9.1.a). | O15: =IF(AND($D15="estable a ambiente",$F15="No"),"Incoherente: has elegido la vía de producto estable y luego has dicho que no lo es","")
A16: PI5 | B16: Lionesa o profiterol | C16: Pastelería individual | D16: 70/2 | E16: Sí | F16: No | G16: =IF(AND($E16="Sí",$F16="No"),'Parámetros'!$B$28,"") -> 4 | H16: =IF(AND(OR($D16="70/2",$D16="ovoproducto"),$F16="No"),'Parámetros'!$B$29,"") -> 8 | I16: =IF(AND(G16="",H16=""),"",IF(G16="",H16,IF(H16="",G16,MIN(G16,H16)))) -> 4 | J16: =IF(AND(G16="",H16=""),"Ni la fila 9 del art. 4.1 ni el art. 9.3 le fijan techo: vitrina de ambiente.",IF(AND(G16<>"",H16<>""),"Le aplican los DOS techos y manda el más bajo, el de la fila 9 del art. 4.1. No es un conflicto: son dos topes distintos.",IF(G16<>"","Manda la fila 9 del art. 4.1: producto de pastelería relleno que no es estable a temperatura ambiente.","Manda el art. 9.3: elaborado por la vía del art. 9.1.a) sin ser estable, o con ovoproducto del art. 9.2."))) -> Le aplican los DOS techos y manda el más bajo, el de la fila 9 del art. 4.1. No es un conflicto: son dos topes distintos. | K16: =IF(AND(OR($D16="70/2",$D16="ovoproducto"),$F16="No"),'Parámetros'!$B$30,"No aplica") -> 24 | L16: Por declarar en tu APPCC | M16: =IF(I16="","Vitrina de ambiente","Vitrina refrigerada") -> Vitrina refrigerada | N16: Tratamiento térmico de 70 °C durante 2 s en el centro del producto, o cualquier combinación equivalente (art. 9.1.a). | O16: =IF(AND($D16="estable a ambiente",$F16="No"),"Incoherente: has elegido la vía de producto estable y luego has dicho que no lo es","")
A17: PI6 | B17: Entremet individual | C17: Pastelería individual | D17: ovoproducto | E17: Sí | F17: No | G17: =IF(AND($E17="Sí",$F17="No"),'Parámetros'!$B$28,"") -> 4 | H17: =IF(AND(OR($D17="70/2",$D17="ovoproducto"),$F17="No"),'Parámetros'!$B$29,"") -> 8 | I17: =IF(AND(G17="",H17=""),"",IF(G17="",H17,IF(H17="",G17,MIN(G17,H17)))) -> 4 | J17: =IF(AND(G17="",H17=""),"Ni la fila 9 del art. 4.1 ni el art. 9.3 le fijan techo: vitrina de ambiente.",IF(AND(G17<>"",H17<>""),"Le aplican los DOS techos y manda el más bajo, el de la fila 9 del art. 4.1. No es un conflicto: son dos topes distintos.",IF(G17<>"","Manda la fila 9 del art. 4.1: producto de pastelería relleno que no es estable a temperatura ambiente.","Manda el art. 9.3: elaborado por la vía del art. 9.1.a) sin ser estable, o con ovoproducto del art. 9.2."))) -> Le aplican los DOS techos y manda el más bajo, el de la fila 9 del art. 4.1. No es un conflicto: son dos topes distintos. | K17: =IF(AND(OR($D17="70/2",$D17="ovoproducto"),$F17="No"),'Parámetros'!$B$30,"No aplica") -> 24 | L17: Por declarar en tu APPCC | M17: =IF(I17="","Vitrina de ambiente","Vitrina refrigerada") -> Vitrina refrigerada | N17: El producto se consume sin un tratamiento térmico que cumpla el apartado 1, así que el huevo crudo se sustituye por ovoproducto de establecimiento autorizado (art. 9.2). | O17: =IF(AND($D17="estable a ambiente",$F17="No"),"Incoherente: has elegido la vía de producto estable y luego has dicho que no lo es","")
... A35: TP8 | B35: Mona de Pascua | C35: Temporada | D35: estable a ambiente | E35: No | F35: Sí | G35: =IF(AND($E35="Sí",$F35="No"),'Parámetros'!$B$28,"") | H35: =IF(AND(OR($D35="70/2",$D35="ovoproducto"),$F35="No"),'Parámetros'!$B$29,"") | I35: =IF(AND(G35="",H35=""),"",IF(G35="",H35,IF(H35="",G35,MIN(G35,H35)))) | J35: =IF(AND(G35="",H35=""),"Ni la fila 9 del art. 4.1 ni el art. 9.3 le fijan techo: vitrina de ambiente.",IF(AND(G35<>"",H35<>""),"Le aplican los DOS techos y manda el más bajo, el de la fila 9 del art. 4.1. No es un conflicto: son dos topes distintos.",IF(G35<>"","Manda la fila 9 del art. 4.1: producto de pastelería relleno que no es estable a temperatura ambiente.","Manda el art. 9.3: elaborado por la vía del art. 9.1.a) sin ser estable, o con ovoproducto del art. 9.2."))) -> Ni la fila 9 del art. 4.1 ni el art. 9.3 le fijan techo: vitrina de ambiente. | K35: =IF(AND(OR($D35="70/2",$D35="ovoproducto"),$F35="No"),'Parámetros'!$B$30,"No aplica") -> No aplica | L35: Por declarar en tu APPCC | M35: =IF(I35="","Vitrina de ambiente","Vitrina refrigerada") -> Vitrina de ambiente | N35: Vía 1.a) y el producto terminado ES estable a temperatura ambiente: el art. 9.3 no le fija ni temperatura ni plazo, y la fila 9 del art. 4.1 lo exceptúa aunque vaya relleno. | O35: =IF(AND($D35="estable a ambiente",$F35="No"),"Incoherente: has elegido la vía de producto estable y luego has dicho que no lo es","")
A37: Lo que sale de esta hoja
B38: Referencias que necesitan vitrina REFRIGERADA | G38: =COUNTIF(M6:M35,"Vitrina refrigerada") -> 15 | J38: Cuántos metros de vitrina refrigerada tienes que comprar lo decide esta cuenta, no el gusto.
B39: Referencias que van en vitrina de AMBIENTE | G39: =COUNTIF(M6:M35,"Vitrina de ambiente") -> 15 | J39: Palmeras, Sacher, huesos de santo, turrón y panes. Son las que se pueden adelantar y las que aguantan el pico.
B40: Referencias con el techo de la fila 9 del art. 4.1 | G40: =SUMPRODUCT(--(G6:G35<>"")) -> 13 | J40: Producto relleno que no es estable a temperatura ambiente.
B41: Referencias con el techo del art. 9.3 | G41: =SUMPRODUCT(--(H6:H35<>"")) -> 15 | J41: Vía del art. 9.1.a) sin ser estable, u ovoproducto del art. 9.2.
B42: Referencias a las que aplican LOS DOS techos | G42: =SUMPRODUCT(--(G6:G35<>""),--(H6:H35<>"")) -> 13 | J42: Aquí manda el más bajo. Es el caso que la SERP vende como «conflicto sin resolver» y no lo es.
B43: Referencias con plazo legal de 24 horas | G43: =SUMPRODUCT(--(K6:K35<>"No aplica")) -> 15 | J43: Con registro de fecha y hora de elaboración. Es la obligación del art. 9.3 que casi nadie cuenta.
B44: Referencias que no llevan huevo en ninguna forma | G44: =COUNTIF(D6:D35,"sin huevo") -> 6 | J44: El art. 9 no les aplica.
B45: Referencias por la vía 63/20 con consumo inmediato | G45: =COUNTIF(D6:D35,"63/20") -> 0 | J45: Debería salir cero: la vía del art. 9.1.b) es la de los huevos fritos y las tortillas, no la de la pastelería. Está en la lista para que sepas que existe y que NO es tuya.
A49: Listas de los desplegables (no se tocan)
A50: 70/2 | B50: Tratamiento térmico de 70 °C durante 2 s en el centro del producto, o cualquier combinación equivalente (art. 9.1.a). | D50: Sí
A51: 63/20 | B51: 63 °C durante 20 s en el centro Y servido para consumo inmediato (art. 9.1.b): huevos fritos, tortillas. No es una vía de pastelería. | D51: No
A52: ovoproducto | B52: El producto se consume sin un tratamiento térmico que cumpla el apartado 1, así que el huevo crudo se sustituye por ovoproducto de establecimiento autorizado (art. 9.2).
A53: sin huevo | B53: La elaboración no lleva huevo en ninguna forma: el art. 9 no le aplica.
A54: estable a ambiente | B54: Vía 1.a) y el producto terminado ES estable a temperatura ambiente: el art. 9.3 no le fija ni temperatura ni plazo, y la fila 9 del art. 4.1 lo exceptúa aunque vaya relleno.
A57: CÓMO SE LEE ESTA HOJA. Eliges la vía legal del huevo, dices si la pieza va rellena y si el producto TERMINADO es estable a temperatura ambiente. Con eso el libro te devuelve la temperatura a la que tienes que conservarla, cuál de los dos artículos manda y si te aplica el plazo de 24 horas. Nada más, y nada menos.
A58: LA VIDA ÚTIL ES TUYA. La columna L viene con el texto «Por declarar en tu APPCC» a propósito: el RD 1021/2022 NO establece vidas útiles y este libro no se las va a inventar para tus 30 referencias. La fijas tú, con tu proceso y tus analíticas, y tiene que constar en tu plan de APPCC. El plazo del art. 9.3 de la columna K es otra cosa: es legal, es de 24 horas y sólo alcanza a lo que dice el artículo.
A59: LO QUE ESTA HOJA CAMBIA EN TU DINERO. Cada referencia que sale «Vitrina refrigerada» son metros de mueble frigorífico que hay que comprar, y cada una con plazo de 24 horas es producto que no se puede adelantar: hay que hacerlo el mismo día, también el 5 de enero. Por eso esta hoja se lee ANTES de cerrar la carta y ANTES de comprar la vitrina.
A60: DÓNDE NO ESTÁ LO DEMÁS. Los alérgenos de vitrina son el «12-control-alergenos-vitrina.xlsx» del Kit de Tareas Pastelería y el «08» del Pack APPCC; el registro diario de temperaturas y de vidas útiles es el «13-registro-temperaturas-recepcion.xlsx» del mismo kit. Este libro no los rehace: hace la decisión previa, que no está en ningún fichero del catálogo.
A61: LA NORMA DEROGADA QUE SIGUE VIVA EN INTERNET. Casi todo lo que vas a leer sobre «huevo a 8 °C y 24 horas» cita el RD 1254/1991, derogado el 22 de diciembre de 2022. Y en producto relleno no estable no mandan los 8 °C: mandan los 4 °C de la fila 9 del art. 4.1. Cada celda con dato legal de esta hoja lleva su nota con la norma, el artículo y el enlace al BOE, verificados el 10-09-2026.
A62: ALCANCE LEGAL DE ESTA HOJA: QUÉ NO RESUELVE Y POR QUÉ. La congelación (PA-13, art. 5) es del PROCESO, no de la vitrina: va en el APPCC y en el «13-registro-temperaturas-recepcion.xlsx» del Kit de Tareas, no aquí. Los 14 alérgenos (PA-21) tienen su propia matriz dedicada, el «12-control-alergenos-vitrina.xlsx»: repetirlos en esta tabla sería mantener el mismo dato en dos sitios y que se desincronicen. El RD 496/2010 de calidad (PA-24) fija denominaciones y composición, no temperaturas ni plazos: no cambia ni una celda de esta hoja. Y el RD 308/2019 del pan (PA-25) sólo aplica si tu carta incluye pan de verdad, cosa que decides en el libro 6, no aquí.
A64: Versión 1.0 · septiembre 2026 · aichef.pro/guia-pasteleria-obrador · info@aichef.pro

Sheet Mix y Ticket Medio
A1: Mix y Ticket Medio
A2: AI Chef Pro · aichef.pro — Cómo Montar una Pastelería
A3: No existe un ticket medio publicado de pastelería. El tuyo se calcula desde tu carta y tu mix.
A5: Ref | B5: Referencia | C5: Familia | D5: Mix (% de las unidades) | E5: PVP con IVA (€) | F5: PVP sin IVA (€) | G5: Aporte al PVP medio con IVA (€) | H5: Aporte al ticket medio (€) | I5: Ingresos relativos sin IVA | J5: Materia relativa | K5: Margen relativo | L5: Food cost de la referencia | M5: Qué aporta esta referencia
A6: B1 | B6: Croissant de mantequilla | C6: Bollería | D6: 12 | E6: ='Coste Hora y Mano de Obra'!L6 -> 1.6 | F6: ='Coste Hora y Mano de Obra'!N6 -> 1.4545455 | G6: =IFERROR(E6*D6/100,"") -> 0.192 | H6: =IFERROR(G6*'Parámetros'!$B$36,"") -> 0.4992 | I6: =IFERROR(F6*D6/100,"") -> 0.17454545 | J6: =IFERROR('Escandallo por Tanda'!G236*D6/100,"") -> 0.02830021 | K6: =IFERROR('Coste Hora y Mano de Obra'!Q6*D6/100,"") -> 0.047586732 | L6: ='Coste Hora y Mano de Obra'!O6 -> 0.16213662
A7: B2 | B7: Pain au chocolat | C7: Bollería | D7: 8 | E7: ='Coste Hora y Mano de Obra'!L7 -> 1.85 | F7: ='Coste Hora y Mano de Obra'!N7 -> 1.6818182 | G7: =IFERROR(E7*D7/100,"") -> 0.148 | H7: =IFERROR(G7*'Parámetros'!$B$36,"") -> 0.3848 | I7: =IFERROR(F7*D7/100,"") -> 0.13454545 | J7: =IFERROR('Escandallo por Tanda'!G237*D7/100,"") -> 0.033560684 | K7: =IFERROR('Coste Hora y Mano de Obra'!Q7*D7/100,"") -> 0.035212429 | L7: ='Coste Hora y Mano de Obra'!O7 -> 0.24943752
A8: B3 | B8: Napolitana de crema | C8: Bollería | D8: 7 | E8: ='Coste Hora y Mano de Obra'!L8 -> 1.85 | F8: ='Coste Hora y Mano de Obra'!N8 -> 1.6818182 | G8: =IFERROR(E8*D8/100,"") -> 0.1295 | H8: =IFERROR(G8*'Parámetros'!$B$36,"") -> 0.3367 | I8: =IFERROR(F8*D8/100,"") -> 0.11772727 | J8: =IFERROR('Escandallo por Tanda'!G238*D8/100,"") -> 0.024684599 | K8: =IFERROR('Coste Hora y Mano de Obra'!Q8*D8/100,"") -> 0.025028094 | L8: ='Coste Hora y Mano de Obra'!O8 -> 0.20967613
A9: B4 | B9: Palmera de hojaldre | C9: Bollería | D9: 4.5 | E9: ='Coste Hora y Mano de Obra'!L9 -> 1.7 | F9: ='Coste Hora y Mano de Obra'!N9 -> 1.5454545 | G9: =IFERROR(E9*D9/100,"") -> 0.0765 | H9: =IFERROR(G9*'Parámetros'!$B$36,"") -> 0.1989 | I9: =IFERROR(F9*D9/100,"") -> 0.069545455 | J9: =IFERROR('Escandallo por Tanda'!G239*D9/100,"") -> 0.0098761782 | K9: =IFERROR('Coste Hora y Mano de Obra'!Q9*D9/100,"") -> 0.037246887 | L9: ='Coste Hora y Mano de Obra'!O9 -> 0.14201041
A10: B5 | B10: Caracola de pasas | C10: Bollería | D10: 3.5 | E10: ='Coste Hora y Mano de Obra'!L10 -> 1.85 | F10: ='Coste Hora y Mano de Obra'!N10 -> 1.6818182 | G10: =IFERROR(E10*D10/100,"") -> 0.06475 | H10: =IFERROR(G10*'Parámetros'!$B$36,"") -> 0.16835 | I10: =IFERROR(F10*D10/100,"") -> 0.058863636 | J10: =IFERROR('Escandallo por Tanda'!G240*D10/100,"") -> 0.010718659 | K10: =IFERROR('Coste Hora y Mano de Obra'!Q10*D10/100,"") -> 0.016753633 | L10: ='Coste Hora y Mano de Obra'!O10 -> 0.18209304
A11: B6 | B11: Ensaimada | C11: Bollería | D11: 3 | E11: ='Coste Hora y Mano de Obra'!L11 -> 1.95 | F11: ='Coste Hora y Mano de Obra'!N11 -> 1.7727273 | G11: =IFERROR(E11*D11/100,"") -> 0.0585 | H11: =IFERROR(G11*'Parámetros'!$B$36,"") -> 0.1521 | I11: =IFERROR(F11*D11/100,"") -> 0.053181818 | J11: =IFERROR('Escandallo por Tanda'!G241*D11/100,"") -> 0.0054070285 | K11: =IFERROR('Coste Hora y Mano de Obra'!Q11*D11/100,"") -> 0.0085356088 | L11: ='Coste Hora y Mano de Obra'!O11 -> 0.10167062
A12: PI1 | B12: Milhojas | C12: Pastelería individual | D12: 4 | E12: ='Coste Hora y Mano de Obra'!L12 -> 3.6 | F12: ='Coste Hora y Mano de Obra'!N12 -> 3.2727273 | G12: =IFERROR(E12*D12/100,"") -> 0.144 | H12: =IFERROR(G12*'Parámetros'!$B$36,"") -> 0.3744 | I12: =IFERROR(F12*D12/100,"") -> 0.13090909 | J12: =IFERROR('Escandallo por Tanda'!G242*D12/100,"") -> 0.017877676 | K12: =IFERROR('Coste Hora y Mano de Obra'!Q12*D12/100,"") -> 0.063203883 | L12: ='Coste Hora y Mano de Obra'!O12 -> 0.13656558
A13: PI2 | B13: Éclair | C13: Pastelería individual | D13: 3.5 | E13: ='Coste Hora y Mano de Obra'!L13 -> 3.2 | F13: ='Coste Hora y Mano de Obra'!N13 -> 2.9090909 | G13: =IFERROR(E13*D13/100,"") -> 0.112 | H13: =IFERROR(G13*'Parámetros'!$B$36,"") -> 0.2912 | I13: =IFERROR(F13*D13/100,"") -> 0.10181818 | J13: =IFERROR('Escandallo por Tanda'!G243*D13/100,"") -> 0.011838951 | K13: =IFERROR('Coste Hora y Mano de Obra'!Q13*D13/100,"") -> 0.061639823 | L13: ='Coste Hora y Mano de Obra'!O13 -> 0.11627541
A14: PI3 | B14: Macarons de frambuesa | C14: Pastelería individual | D14: 7 | E14: ='Coste Hora y Mano de Obra'!L14 -> 2.1 | F14: ='Coste Hora y Mano de Obra'!N14 -> 1.9090909 | G14: =IFERROR(E14*D14/100,"") -> 0.147 | H14: =IFERROR(G14*'Parámetros'!$B$36,"") -> 0.3822 | I14: =IFERROR(F14*D14/100,"") -> 0.13363636 | J14: =IFERROR('Escandallo por Tanda'!G244*D14/100,"") -> 0.013755697 | K14: =IFERROR('Coste Hora y Mano de Obra'!Q14*D14/100,"") -> 0.064073831 | L14: ='Coste Hora y Mano de Obra'!O14 -> 0.10293379
A15: PI4 | B15: Tartaleta de frutas | C15: Pastelería individual | D15: 3 | E15: ='Coste Hora y Mano de Obra'!L15 -> 3.8 | F15: ='Coste Hora y Mano de Obra'!N15 -> 3.4545455 | G15: =IFERROR(E15*D15/100,"") -> 0.114 | H15: =IFERROR(G15*'Parámetros'!$B$36,"") -> 0.2964 | I15: =IFERROR(F15*D15/100,"") -> 0.10363636 | J15: =IFERROR('Escandallo por Tanda'!G245*D15/100,"") -> 0.015749581 | K15: =IFERROR('Coste Hora y Mano de Obra'!Q15*D15/100,"") -> 0.049768721 | L15: ='Coste Hora y Mano de Obra'!O15 -> 0.15196964
A16: PI5 | B16: Lionesa o profiterol | C16: Pastelería individual | D16: 3 | E16: ='Coste Hora y Mano de Obra'!L16 -> 2.3 | F16: ='Coste Hora y Mano de Obra'!N16 -> 2.0909091 | G16: =IFERROR(E16*D16/100,"") -> 0.069 | H16: =IFERROR(G16*'Parámetros'!$B$36,"") -> 0.1794 | I16: =IFERROR(F16*D16/100,"") -> 0.062727273 | J16: =IFERROR('Escandallo por Tanda'!G246*D16/100,"") -> 0.0059453042 | K16: =IFERROR('Coste Hora y Mano de Obra'!Q16*D16/100,"") -> 0.043328535 | L16: ='Coste Hora y Mano de Obra'!O16 -> 0.094780213
A17: PI6 | B17: Entremet individual | C17: Pastelería individual | D17: 1.5 | E17: ='Coste Hora y Mano de Obra'!L17 -> 4.5 | F17: ='Coste Hora y Mano de Obra'!N17 -> 4.0909091 | G17: =IFERROR(E17*D17/100,"") -> 0.0675 | H17: =IFERROR(G17*'Parámetros'!$B$36,"") -> 0.1755 | I17: =IFERROR(F17*D17/100,"") -> 0.061363636 | J17: =IFERROR('Escandallo por Tanda'!G247*D17/100,"") -> 0.012371119 | K17: =IFERROR('Coste Hora y Mano de Obra'!Q17*D17/100,"") -> 0.02236593 | L17: ='Coste Hora y Mano de Obra'!O17 -> 0.20160342
