Workbook

Sheet Instructions
A1: 90-Day Action Plan
A2: AI Chef Pro · aichef.pro — Food Cost + Menu Engineering Guide
A4: How to use this workbook
A5: 1. Open "Decisions" and enter what the other tools in the pack have told you: which dish, which sheet it comes from and what you decide to do with it.
A6: 2. Give each decision an owner, by name, and a plan week (1-13). The workbook works out the "Target date" on its own from the "Plan start date" in green cell D36: a decision with no owner and no date doesn't get done.
A7: 3. Estimate the impact in dollars per month. You don't need precision: you need an order of magnitude to know where to start.
A8: 4. Change the "Status" as you go. The workbook counts how many you've closed, how much impact you've achieved and how much is still pending.
A9: 5. "90-Day Calendar" gives you 13 weeks with two milestones each. They're a proposal: rewrite them with whatever your restaurant needs.
A10: 6. Mark "Done" = Yes as you close milestones; the progress of the plan and of each block is calculated on its own.
A11: 7. In "Tracking KPIs", record the month 0 snapshot and then months 1, 2 and 3. The reading tells you whether each KPI is improving or getting worse.
A12: 8. After 90 days, go back to the matrix with the new sales: dishes will have moved quadrant and the cycle starts again.
A14: Green cells = editable fields
... A32: Version 1.0 · October 2026 · aichef.pro/en/digital-products/food-cost-menu-engineering-guide · info@aichef.pro

Sheet Decisions
A1: Decisions — what gets done, by whom and when
A2: AI Chef Pro · aichef.pro — Food Cost + Menu Engineering Guide
E3: Each row comes from a sheet in the pack. Without an owner and a date it isn't a decision: it's an opinion.
A4: # | B4: Dish or area | C4: Source tool | D4: Decision | E4: Owner | F4: Plan week | G4: Target date | H4: Status | I4: Estimated impact (per month) | J4: Impact achieved (per month) | K4: Notes
A5: 1 | B5: Garlic shrimp (S3) | C5: Multi-method matrix | D5: Review | E5: General manager | F5: 2 | G5: =IFERROR(IF(OR($F5="",$D$36=""),"",$D$36+7*($F5-1)),"") -> 46273 | H5: Pending | I5: 180 | J5: =IFERROR(IF(OR($B5="",$I5=""),"",IF($H5="Done",$I5,0)),"") -> 0
A6: 2 | B6: Dry-aged bone-in ribeye (M5) | C6: Multi-method matrix | D6: Redesign | E6: Head chef | F6: 1 | G6: =IFERROR(IF(OR($F6="",$D$36=""),"",$D$36+7*($F6-1)),"") -> 46266 | H6: Pending | I6: 260 | J6: =IFERROR(IF(OR($B6="",$I6=""),"",IF($H6="Done",$I6,0)),"") -> 0
A7: 3 | B7: Local cheese board (S5) | C7: Multi-method matrix | D7: Redesign | E7: General manager | F7: 4 | G7: =IFERROR(IF(OR($F7="",$D$36=""),"",$D$36+7*($F7-1)),"") -> 46287 | H7: Pending | I7: 140 | J7: =IFERROR(IF(OR($B7="",$I7=""),"",IF($H7="Done",$I7,0)),"") -> 0
A8: 4 | B8: Seasonal vegetable lasagna (M8) | C8: Multi-method matrix | D8: Review | E8: Head chef | F8: 3 | G8: =IFERROR(IF(OR($F8="",$D$36=""),"",$D$36+7*($F8-1)),"") -> 46280 | H8: Pending | I8: 120 | J8: =IFERROR(IF(OR($B8="",$I8=""),"",IF($H8="Done",$I8,0)),"") -> 0
A9: 5 | B9: Prepared seasonal fruit (D4) | C9: Multi-method matrix | D9: Remove | E9: Head chef | F9: 3 | G9: =IFERROR(IF(OR($F9="",$D$36=""),"",$D$36+7*($F9-1)),"") -> 46280 | H9: Pending | I9: 60 | J9: =IFERROR(IF(OR($B9="",$I9=""),"",IF($H9="Done",$I9,0)),"") -> 0
A10: 6 | B10: Salt-baked sea bass (M6) on delivery | C10: Multichannel simulator | D10: Remove | E10: General manager | F10: 2 | G10: =IFERROR(IF(OR($F10="",$D$36=""),"",$D$36+7*($F10-1)),"") -> 46273 | H10: Pending | I10: 90 | J10: =IFERROR(IF(OR($B10="",$I10=""),"",IF($H10="Done",$I10,0)),"") -> 0
A11: 7 | B11: Ribeye (M5) on delivery | C11: Multichannel simulator | D11: Remove | E11: General manager | F11: 2 | G11: =IFERROR(IF(OR($F11="",$D$36=""),"",$D$36+7*($F11-1)),"") -> 46273 | H11: Pending | I11: 140 | J11: =IFERROR(IF(OR($B11="",$I11=""),"",IF($H11="Done",$I11,0)),"") -> 0
A12: 8 | B12: Whole fish: switch to fillets | C12: Yield test | D12: Negotiate | E12: Purchasing manager | F12: 5 | G12: =IFERROR(IF(OR($F12="",$D$36=""),"",$D$36+7*($F12-1)),"") -> 46294 | H12: Pending | I12: 260 | J12: =IFERROR(IF(OR($B12="",$I12=""),"",IF($H12="Done",$I12,0)),"") -> 0
A13: 9 | B13: Crianza by the glass: menu price | C13: Beverage menu | D13: Reprice | E13: Front-of-house manager | F13: 2 | G13: =IFERROR(IF(OR($F13="",$D$36=""),"",$D$36+7*($F13-1)),"") -> 46273 | H13: Pending | I13: 210 | J13: =IFERROR(IF(OR($B13="",$I13=""),"",IF($H13="Done",$I13,0)),"") -> 0
A14: 10 | B14: Dine-in staffing schedule in slow months | C14: Prime cost dashboard | D14: Reformulate | E14: General manager | F14: 6 | G14: =IFERROR(IF(OR($F14="",$D$36=""),"",$D$36+7*($F14-1)),"") -> 46301 | H14: Pending | I14: 900 | J14: =IFERROR(IF(OR($B14="",$I14=""),"",IF($H14="Done",$I14,0)),"") -> 0
A15: 11 | G15: =IFERROR(IF(OR($F15="",$D$36=""),"",$D$36+7*($F15-1)),"") | J15: =IFERROR(IF(OR($B15="",$I15=""),"",IF($H15="Done",$I15,0)),"")
A16: 12 | G16: =IFERROR(IF(OR($F16="",$D$36=""),"",$D$36+7*($F16-1)),"") | J16: =IFERROR(IF(OR($B16="",$I16=""),"",IF($H16="Done",$I16,0)),"")
A17: 13 | G17: =IFERROR(IF(OR($F17="",$D$36=""),"",$D$36+7*($F17-1)),"") | J17: =IFERROR(IF(OR($B17="",$I17=""),"",IF($H17="Done",$I17,0)),"")
A18: 14 | G18: =IFERROR(IF(OR($F18="",$D$36=""),"",$D$36+7*($F18-1)),"") | J18: =IFERROR(IF(OR($B18="",$I18=""),"",IF($H18="Done",$I18,0)),"")
A19: 15 | G19: =IFERROR(IF(OR($F19="",$D$36=""),"",$D$36+7*($F19-1)),"") | J19: =IFERROR(IF(OR($B19="",$I19=""),"",IF($H19="Done",$I19,0)),"")
A20: 16 | G20: =IFERROR(IF(OR($F20="",$D$36=""),"",$D$36+7*($F20-1)),"") | J20: =IFERROR(IF(OR($B20="",$I20=""),"",IF($H20="Done",$I20,0)),"")
A21: 17 | G21: =IFERROR(IF(OR($F21="",$D$36=""),"",$D$36+7*($F21-1)),"") | J21: =IFERROR(IF(OR($B21="",$I21=""),"",IF($H21="Done",$I21,0)),"")
A22: 18 | G22: =IFERROR(IF(OR($F22="",$D$36=""),"",$D$36+7*($F22-1)),"") | J22: =IFERROR(IF(OR($B22="",$I22=""),"",IF($H22="Done",$I22,0)),"")
A23: 19 | G23: =IFERROR(IF(OR($F23="",$D$36=""),"",$D$36+7*($F23-1)),"") | J23: =IFERROR(IF(OR($B23="",$I23=""),"",IF($H23="Done",$I23,0)),"")
A24: 20 | G24: =IFERROR(IF(OR($F24="",$D$36=""),"",$D$36+7*($F24-1)),"") | J24: =IFERROR(IF(OR($B24="",$I24=""),"",IF($H24="Done",$I24,0)),"")
A26: SUMMARY AND INPUTS — calculated by the workbook
B27: Decisions logged | D27: =COUNTIF($B$5:$B$24,"<>") -> 10
B28: Decisions closed (status "Done") | D28: =COUNTIF($H$5:$H$24,"Done") -> 0
B29: Decisions dropped | D29: =COUNTIF($H$5:$H$24,"Dropped") -> 0
B30: Decisions closed (%) | D30: =IFERROR(IF($D$27=0,"",$D$28/$D$27),"") -> 0
B31: TOTAL ESTIMATED IMPACT (per month) | D31: =IFERROR(SUM($I$5:$I$24),"") -> 2360
B32: Impact achieved (per month) | D32: =IFERROR(SUMIF($H$5:$H$24,"Done",$I$5:$I$24),"") -> 0
B33: Impact pending (per month) | D33: =IFERROR(IF(OR($D$31="",$D$32=""),"",$D$31-$D$32),"") -> 2360
B34: Total estimated impact over 12 months | D34: =IFERROR(IF($D$31="","",$D$31*12),"") -> 28320
B35: 90-day close target (%) | D35: 0.8 | F35: The share of decisions you commit to closing this quarter. If the closed percentage falls below it, the cell turns red.
B36: Plan start date | D36: 46266 | F36: Week 1 starts on this day; the target dates of the decisions and the calendar come from here. Change it to your real date.
A37: SUMMARY BY DECISION TYPE — calculated by the workbook
B38: Decision | C38: Decisions | D38: Estimated impact (per month) | E38: Impact achieved (per month)
B39: Reformulate | C39: =COUNTIF($D$5:$D$24,$B39) -> 1 | D39: =IFERROR(SUMIF($D$5:$D$24,$B39,$I$5:$I$24),"") -> 900 | E39: =IFERROR(SUMPRODUCT(--($D$5:$D$24=$B39),--($H$5:$H$24="Done"),$I$5:$I$24),"") -> 0
B40: Reprice | C40: =COUNTIF($D$5:$D$24,$B40) -> 1 | D40: =IFERROR(SUMIF($D$5:$D$24,$B40,$I$5:$I$24),"") -> 210 | E40: =IFERROR(SUMPRODUCT(--($D$5:$D$24=$B40),--($H$5:$H$24="Done"),$I$5:$I$24),"") -> 0
B41: Redesign | C41: =COUNTIF($D$5:$D$24,$B41) -> 2 | D41: =IFERROR(SUMIF($D$5:$D$24,$B41,$I$5:$I$24),"") -> 400 | E41: =IFERROR(SUMPRODUCT(--($D$5:$D$24=$B41),--($H$5:$H$24="Done"),$I$5:$I$24),"") -> 0
...

Sheet 90-Day Calendar
A1: 90-day calendar — 13 weeks, two milestones a week
A2: AI Chef Pro · aichef.pro — Food Cost + Menu Engineering Guide
C3: Measure · Cost and Classify · Apply Decisions · Measure the Effect · Review. The milestones are a proposal: rewrite them with whatever your restaurant needs.
A4: Week | B4: Block | C4: Milestone | D4: Owner | E4: Target date | F4: Done | G4: Note
A5: 1 | B5: Measure | C5: Pull last month's sales-by-dish report and enter it on the matrix's "Data" sheet. | D5: General manager | E5: =IFERROR(IF(OR($A5="",'Decisions'!$D$36=""),"",'Decisions'!$D$36+7*($A5-1)),"") -> 46266 | F5: No
A6: 1 | B6: Measure | C6: Take a closing inventory and record the month's beginning inventory, purchases and ending inventory. | D6: Head chef | E6: =IFERROR(IF(OR($A6="",'Decisions'!$D$36=""),"",'Decisions'!$D$36+7*($A6-1)),"") -> 46266 | F6: No
A7: 2 | B7: Measure | C7: Run a yield test on the 10 products that weigh most in your purchasing, with a scale and the yield sheet. | D7: Head chef | E7: =IFERROR(IF(OR($A7="",'Decisions'!$D$36=""),"",'Decisions'!$D$36+7*($A7-1)),"") -> 46273 | F7: No
A8: 2 | B8: Measure | C8: Measure the cooking loss of the five best-selling preparations. | D8: Head chef | E8: =IFERROR(IF(OR($A8="",'Decisions'!$D$36=""),"",'Decisions'!$D$36+7*($A8-1)),"") -> 46273 | F8: No
A9: 3 | B9: Cost and Classify | C9: Cost the best-selling dishes with MEASURED trim loss, not the reference figures. | D9: Head chef | E9: =IFERROR(IF(OR($A9="",'Decisions'!$D$36=""),"",'Decisions'!$D$36+7*($A9-1)),"") -> 46280 | F9: No
A10: 3 | B10: Cost and Classify | C10: Fill in plate cost and pre-tax menu price for the whole menu in the multi-method matrix. | D10: General manager | E10: =IFERROR(IF(OR($A10="",'Decisions'!$D$36=""),"",'Decisions'!$D$36+7*($A10-1)),"") -> 46280 | F10: No
A11: 4 | B11: Cost and Classify | C11: Read the four classifications and the "Comparison" sheet dish by dish. | D11: General manager | E11: =IFERROR(IF(OR($A11="",'Decisions'!$D$36=""),"",'Decisions'!$D$36+7*($A11-1)),"") -> 46287 | F11: No
A12: 4 | B12: Cost and Classify | C12: Move the dishes with three or four readings off the best category to the "Decisions" sheet. | D12: General manager | E12: =IFERROR(IF(OR($A12="",'Decisions'!$D$36=""),"",'Decisions'!$D$36+7*($A12-1)),"") -> 46287 | F12: No
A13: 5 | B13: Apply Decisions | C13: Apply the price increases you decided on and reprint the menu. | D13: General manager | E13: =IFERROR(IF(OR($A13="",'Decisions'!$D$36=""),"",'Decisions'!$D$36+7*($A13-1)),"") -> 46294 | F13: No
A14: 5 | B14: Apply Decisions | C14: Brief the floor staff on the price changes and on which dishes to suggest. | D14: Front-of-house manager | E14: =IFERROR(IF(OR($A14="",'Decisions'!$D$36=""),"",'Decisions'!$D$36+7*($A14-1)),"") -> 46294 | F14: No
A15: 6 | B15: Apply Decisions | C15: Rework the flagged recipes: new cost card and a test in the kitchen. | D15: Head chef | E15: =IFERROR(IF(OR($A15="",'Decisions'!$D$36=""),"",'Decisions'!$D$36+7*($A15-1)),"") -> 46301 | F15: No
A16: 6 | B16: Apply Decisions | C16: Negotiate with the suppliers of the three lines that weigh most in your purchasing. | D16: Purchasing manager | E16: =IFERROR(IF(OR($A16="",'Decisions'!$D$36=""),"",'Decisions'!$D$36+7*($A16-1)),"") -> 46301 | F16: No
... A30: 13 | B30: Review | C30: Decide the next quarter: what stays, what repeats and what comes in new. | D30: General manager | E30: =IFERROR(IF(OR($A30="",'Decisions'!$D$36=""),"",'Decisions'!$D$36+7*($A30-1)),"") -> 46350 | F30: No
A32: SUMMARY — calculated by the workbook
C33: Milestones logged | D33: =COUNTIF($C$5:$C$30,"<>") -> 26
C34: Milestones done | D34: =COUNTIF($F$5:$F$30,"Yes") -> 0
C35: Milestones pending | D35: =IFERROR(IF(OR($D$33="",$D$34=""),"",$D$33-$D$34),"") -> 26
C36: CALENDAR PROGRESS (%) | D36: =IFERROR(IF($D$33=0,"",$D$34/$D$33),"") -> 0
A38: PROGRESS BY BLOCK — calculated by the workbook
C39: Block | D39: Milestones | E39: Done | F39: Progress (%)
C40: Measure | D40: =COUNTIF($B$5:$B$30,$C40) -> 4 | E40: =IFERROR(SUMPRODUCT(--($B$5:$B$30=$C40),--($F$5:$F$30="Yes")),"") -> 0 | F40: =IFERROR(IF($D40=0,"",$E40/$D40),"") -> 0
C41: Cost and Classify | D41: =COUNTIF($B$5:$B$30,$C41) -> 4 | E41: =IFERROR(SUMPRODUCT(--($B$5:$B$30=$C41),--($F$5:$F$30="Yes")),"") -> 0 | F41: =IFERROR(IF($D41=0,"",$E41/$D41),"") -> 0
C42: Apply Decisions | D42: =COUNTIF($B$5:$B$30,$C42) -> 8 | E42: =IFERROR(SUMPRODUCT(--($B$5:$B$30=$C42),--($F$5:$F$30="Yes")),"") -> 0 | F42: =IFERROR(IF($D42=0,"",$E42/$D42),"") -> 0
C43: Measure the Effect | D43: =COUNTIF($B$5:$B$30,$C43) -> 8 | E43: =IFERROR(SUMPRODUCT(--($B$5:$B$30=$C43),--($F$5:$F$30="Yes")),"") -> 0 | F43: =IFERROR(IF($D43=0,"",$E43/$D43),"") -> 0
C44: Review | D44: =COUNTIF($B$5:$B$30,$C44) -> 2 | E44: =IFERROR(SUMPRODUCT(--($B$5:$B$30=$C44),--($F$5:$F$30="Yes")),"") -> 0 | F44: =IFERROR(IF($D44=0,"",$E44/$D44),"") -> 0
C46: A newly opened plan shows 0% progress: that's correct. You earn progress by marking "Done" = Yes.

Sheet Tracking KPIs
A1: Tracking KPIs — month 0 vs. month 3
A2: AI Chef Pro · aichef.pro — Food Cost + Menu Engineering Guide
C3: Month 0 is the starting snapshot. For KPIs in percent, the change is in percentage POINTS.
A4: KPI | B4: Month 0 | C4: Month 1 | D4: Month 2 | E4: Month 3 | F4: Change month 1 vs. month 0 | G4: Change month 2 vs. month 0 | H4: Change month 3 vs. month 0 | I4: Is lower better? | J4: Reading month 3 vs. month 0 | K4: Note
A5: Food cost (%) | B5: 0.331 | C5: 0.322 | D5: 0.311 | E5: 0.298 | F5: =IFERROR(IF(OR($B5="",$C5=""),"",$C5-$B5),"") -> -0.009 | G5: =IFERROR(IF(OR($B5="",$D5=""),"",$D5-$B5),"") -> -0.02 | H5: =IFERROR(IF(OR($B5="",$E5=""),"",$E5-$B5),"") -> -0.033 | I5: Yes | J5: =IFERROR(IF(OR($B5="",$E5="",$I5=""),"",IF($H5=0,"No change",IF(OR(AND($I5="Yes",$H5<0),AND($I5="No",$H5>0)),"Improvement","Decline"))),"") -> Improvement | K5: Product cost over net food sales. The house target is in the prime cost dashboard.
A6: Prime cost (%) | B6: 0.668 | C6: 0.661 | D6: 0.652 | E6: 0.638 | F6: =IFERROR(IF(OR($B6="",$C6=""),"",$C6-$B6),"") -> -0.007 | G6: =IFERROR(IF(OR($B6="",$D6=""),"",$D6-$B6),"") -> -0.016 | H6: =IFERROR(IF(OR($B6="",$E6=""),"",$E6-$B6),"") -> -0.03 | I6: Yes | J6: =IFERROR(IF(OR($B6="",$E6="",$I6=""),"",IF($H6=0,"No change",IF(OR(AND($I6="Yes",$H6<0),AND($I6="No",$H6>0)),"Improvement","Decline"))),"") -> Improvement | K6: Product + labor with payroll taxes and benefits, over net sales.
A7: Average check pre-tax | B7: 27.4 | C7: 27.9 | D7: 28.6 | E7: 29.1 | F7: =IFERROR(IF(OR($B7="",$C7=""),"",$C7-$B7),"") -> 0.5 | G7: =IFERROR(IF(OR($B7="",$D7=""),"",$D7-$B7),"") -> 1.2 | H7: =IFERROR(IF(OR($B7="",$E7=""),"",$E7-$B7),"") -> 1.7 | I7: No | J7: =IFERROR(IF(OR($B7="",$E7="",$I7=""),"",IF($H7=0,"No change",IF(OR(AND($I7="Yes",$H7<0),AND($I7="No",$H7>0)),"Improvement","Decline"))),"") -> Improvement | K7: Net sales ÷ covers. It goes up when the menu pushes the right dishes.
A8: Contribution margin per cover | B8: 18.1 | C8: 18.6 | D8: 19.4 | E8: 20.2 | F8: =IFERROR(IF(OR($B8="",$C8=""),"",$C8-$B8),"") -> 0.5 | G8: =IFERROR(IF(OR($B8="",$D8=""),"",$D8-$B8),"") -> 1.3 | H8: =IFERROR(IF(OR($B8="",$E8=""),"",$E8-$B8),"") -> 2.1 | I8: No | J8: =IFERROR(IF(OR($B8="",$E8="",$I8=""),"",IF($H8=0,"No change",IF(OR(AND($I8="Yes",$H8<0),AND($I8="No",$H8>0)),"Improvement","Decline"))),"") -> Improvement | K8: The dollar each guest leaves to pay for labor, rent and utilities.
A9: Dishes on the menu (no.) | B9: 20 | C9: 20 | D9: 19 | E9: 18 | F9: =IFERROR(IF(OR($B9="",$C9=""),"",$C9-$B9),"") -> 0 | G9: =IFERROR(IF(OR($B9="",$D9=""),"",$D9-$B9),"") -> -1 | H9: =IFERROR(IF(OR($B9="",$E9=""),"",$E9-$B9),"") -> -2 | I9: Yes | J9: =IFERROR(IF(OR($B9="",$E9="",$I9=""),"",IF($H9=0,"No change",IF(OR(AND($I9="Yes",$H9<0),AND($I9="No",$H9>0)),"Improvement","Decline"))),"") -> Improvement | K9: Pruning is a goal, not an accident. Change it to "No" if your plan is to grow the menu.
F10: =IFERROR(IF(OR($B10="",$C10=""),"",$C10-$B10),"") | G10: =IFERROR(IF(OR($B10="",$D10=""),"",$D10-$B10),"") | H10: =IFERROR(IF(OR($B10="",$E10=""),"",$E10-$B10),"") | J10: =IFERROR(IF(OR($B10="",$E10="",$I10=""),"",IF($H10=0,"No change",IF(OR(AND($I10="Yes",$H10<0),AND($I10="No",$H10>0)),"Improvement","Decline"))),"")
F11: =IFERROR(IF(OR($B11="",$C11=""),"",$C11-$B11),"") | G11: =IFERROR(IF(OR($B11="",$D11=""),"",$D11-$B11),"") | H11: =IFERROR(IF(OR($B11="",$E11=""),"",$E11-$B11),"") | J11: =IFERROR(IF(OR($B11="",$E11="",$I11=""),"",IF($H11=0,"No change",IF(OR(AND($I11="Yes",$H11<0),AND($I11="No",$H11>0)),"Improvement","Decline"))),"")
F12: =IFERROR(IF(OR($B12="",$C12=""),"",$C12-$B12),"") | G12: =IFERROR(IF(OR($B12="",$D12=""),"",$D12-$B12),"") | H12: =IFERROR(IF(OR($B12="",$E12=""),"",$E12-$B12),"") | J12: =IFERROR(IF(OR($B12="",$E12="",$I12=""),"",IF($H12=0,"No change",IF(OR(AND($I12="Yes",$H12<0),AND($I12="No",$H12>0)),"Improvement","Decline"))),"")
A14: SUMMARY — calculated by the workbook
A15: KPIs logged | C15: =COUNTIF($A$5:$A$12,"<>") -> 5
A16: KPIs IMPROVING | C16: =COUNTIF($J$5:$J$12,"Improvement") -> 5
A17: KPIs getting worse | C17: =COUNTIF($J$5:$J$12,"Decline") -> 0
A18: KPIs with no change | C18: =COUNTIF($J$5:$J$12,"No change") -> 0
A19: KPIs improving (%) | C19: =IFERROR(IF($C$15=0,"",$C$16/$C$15),"") -> 1
A21: The first four KPIs are read together: a food cost going down while the margin per cover also goes down means you've made the dish cheaper, not that you've made money.
A22: The last three rows are free for your restaurant's own KPIs (table turns, beverage-to-food ratio, waste in dollars…). Mark the direction of each one in "Is lower better?".
