Workbook

Sheet Instructions
A1: Multi-Method Menu Engineering Matrix
A2: AI Chef Pro · aichef.pro — Food Cost + Menu Engineering Guide
A4: How to use this workbook
A5: 1. Enter your menu on the "Data" sheet: dish, category, units sold last month, plate cost and menu price BEFORE tax.
A6: 2. The plate cost comes from your recipe cost card (recipe-cost-card.xlsx, in this same pack). The workbook works out the dine-in menu price with tax.
A7: 3. The Kasavana-Smith, Miller, Pavesic and Goal Value sheets read that data and classify each dish with their own method. You don't type anything there.
A8: 4. Each method is applied WITHIN its category: a dessert is compared with the desserts, not with the ribeyes.
A9: 5. Open "Comparison": it shows the four readings of the same dish, how many fall outside the best category and a diagnosis of what to do.
A10: 6. Take the decisions to 90-day-action-plan.xlsx with an owner and a date. An analysis without a date changes nothing.
A11: 7. The "Prix Fixe Menu" sheet stands apart: on a set-price menu the margin isn't decided by the price, it's decided by the mix of choices your guests make.
A12: 8. Adjust the popularity threshold factor and the labor and other variable cost percentages if your restaurant doesn't look like the example.
A14: Green cells = editable fields
... A30: Version 1.0 · October 2026 · aichef.pro/en/digital-products/food-cost-menu-engineering-guide · info@aichef.pro

Sheet Data
A1: Menu data
A2: AI Chef Pro · aichef.pro — Food Cost + Menu Engineering Guide
E3: The plate cost comes from your recipe cost card; the menu price goes in BEFORE tax.
A4: # | B4: Dish | C4: Category | D4: Units sold (month) | E4: Plate cost | F4: Menu price pre-tax | G4: Contribution margin | H4: Food cost (%) | I4: Dine-in menu price WITH tax | J4: Units in its category | K4: Dishes in its category with sales | L4: Menu Mix in Category (MM%) | M4: Popularity threshold in its category (%) | N4: Category weighted avg CM | O4: Category weighted avg food cost (%) | P4: Dish weighted CM: CM × units | Q4: Category average of weighted CM
A5: 1 | B5: Iberico ham croquettes (6 pcs) | C5: Starters | D5: 420 | E5: 2.1 | F5: 8.6 | G5: =IFERROR(IF(OR($E5="",$F5=""),"",$F5-$E5),"") -> 6.5 | H5: =IFERROR(IF(OR($E5="",$F5="",$F5=0),"",$E5/$F5),"") -> 0.24418605 | I5: =IFERROR(IF(OR($F5="",$D$34=""),"",$F5*(1+$D$34)),"") -> 8.6 | J5: =IFERROR(IF($C5="","",SUMPRODUCT(--($C$5:$C$29=$C5),$D$5:$D$29)),"") -> 1730 | K5: =IFERROR(IF($C5="","",SUMPRODUCT(--($C$5:$C$29=$C5),--($D$5:$D$29>0))),"") -> 7 | L5: =IFERROR(IF(OR($D5="",$J5="",$J5=0),"",$D5/$J5),"") -> 0.24277457 | M5: =IFERROR(IF(OR($K5="",$K5=0,$D$33=""),"",$D$33/$K5),"") -> 0.1 | N5: =IFERROR(IF(OR($J5="",$J5=0),"",SUMPRODUCT(--($C$5:$C$29=$C5),$D$5:$D$29,$G$5:$G$29)/$J5),"") -> 7.4635838 | O5: =IFERROR(IF(SUMPRODUCT(--($C$5:$C$29=$C5),$D$5:$D$29,$F$5:$F$29)=0,"",SUMPRODUCT(--($C$5:$C$29=$C5),$D$5:$D$29,$E$5:$E$29)/SUMPRODUCT(--($C$5:$C$29=$C5),$D$5:$D$29,$F$5:$F$29)),"") -> 0.30714746 | P5: =IFERROR(IF(OR($G5="",$D5=""),"",$G5*$D5),"") -> 2730 | Q5: =IFERROR(IF(OR($K5="",$K5=0),"",SUMPRODUCT(--($C$5:$C$29=$C5),$D$5:$D$29,$G$5:$G$29)/$K5),"") -> 1844.5714
A6: 2 | B6: Heirloom tomato salad with tuna belly and scallions | C6: Starters | D6: 310 | E6: 3.6 | F6: 11.8 | G6: =IFERROR(IF(OR($E6="",$F6=""),"",$F6-$E6),"") -> 8.2 | H6: =IFERROR(IF(OR($E6="",$F6="",$F6=0),"",$E6/$F6),"") -> 0.30508475 | I6: =IFERROR(IF(OR($F6="",$D$34=""),"",$F6*(1+$D$34)),"") -> 11.8 | J6: =IFERROR(IF($C6="","",SUMPRODUCT(--($C$5:$C$29=$C6),$D$5:$D$29)),"") -> 1730 | K6: =IFERROR(IF($C6="","",SUMPRODUCT(--($C$5:$C$29=$C6),--($D$5:$D$29>0))),"") -> 7 | L6: =IFERROR(IF(OR($D6="",$J6="",$J6=0),"",$D6/$J6),"") -> 0.17919075 | M6: =IFERROR(IF(OR($K6="",$K6=0,$D$33=""),"",$D$33/$K6),"") -> 0.1 | N6: =IFERROR(IF(OR($J6="",$J6=0),"",SUMPRODUCT(--($C$5:$C$29=$C6),$D$5:$D$29,$G$5:$G$29)/$J6),"") -> 7.4635838 | O6: =IFERROR(IF(SUMPRODUCT(--($C$5:$C$29=$C6),$D$5:$D$29,$F$5:$F$29)=0,"",SUMPRODUCT(--($C$5:$C$29=$C6),$D$5:$D$29,$E$5:$E$29)/SUMPRODUCT(--($C$5:$C$29=$C6),$D$5:$D$29,$F$5:$F$29)),"") -> 0.30714746 | P6: =IFERROR(IF(OR($G6="",$D6=""),"",$G6*$D6),"") -> 2542 | Q6: =IFERROR(IF(OR($K6="",$K6=0),"",SUMPRODUCT(--($C$5:$C$29=$C6),$D$5:$D$29,$G$5:$G$29)/$K6),"") -> 1844.5714
A7: 3 | B7: Garlic shrimp | C7: Starters | D7: 260 | E7: 6.9 | F7: 15.5 | G7: =IFERROR(IF(OR($E7="",$F7=""),"",$F7-$E7),"") -> 8.6 | H7: =IFERROR(IF(OR($E7="",$F7="",$F7=0),"",$E7/$F7),"") -> 0.44516129 | I7: =IFERROR(IF(OR($F7="",$D$34=""),"",$F7*(1+$D$34)),"") -> 15.5 | J7: =IFERROR(IF($C7="","",SUMPRODUCT(--($C$5:$C$29=$C7),$D$5:$D$29)),"") -> 1730 | K7: =IFERROR(IF($C7="","",SUMPRODUCT(--($C$5:$C$29=$C7),--($D$5:$D$29>0))),"") -> 7 | L7: =IFERROR(IF(OR($D7="",$J7="",$J7=0),"",$D7/$J7),"") -> 0.15028902 | M7: =IFERROR(IF(OR($K7="",$K7=0,$D$33=""),"",$D$33/$K7),"") -> 0.1 | N7: =IFERROR(IF(OR($J7="",$J7=0),"",SUMPRODUCT(--($C$5:$C$29=$C7),$D$5:$D$29,$G$5:$G$29)/$J7),"") -> 7.4635838 | O7: =IFERROR(IF(SUMPRODUCT(--($C$5:$C$29=$C7),$D$5:$D$29,$F$5:$F$29)=0,"",SUMPRODUCT(--($C$5:$C$29=$C7),$D$5:$D$29,$E$5:$E$29)/SUMPRODUCT(--($C$5:$C$29=$C7),$D$5:$D$29,$F$5:$F$29)),"") -> 0.30714746 | P7: =IFERROR(IF(OR($G7="",$D7=""),"",$G7*$D7),"") -> 2236 | Q7: =IFERROR(IF(OR($K7="",$K7=0),"",SUMPRODUCT(--($C$5:$C$29=$C7),$D$5:$D$29,$G$5:$G$29)/$K7),"") -> 1844.5714
A8: 4 | B8: Broken eggs with potatoes and chistorra sausage | C8: Starters | D8: 380 | E8: 2.4 | F8: 9.8 | G8: =IFERROR(IF(OR($E8="",$F8=""),"",$F8-$E8),"") -> 7.4 | H8: =IFERROR(IF(OR($E8="",$F8="",$F8=0),"",$E8/$F8),"") -> 0.24489796 | I8: =IFERROR(IF(OR($F8="",$D$34=""),"",$F8*(1+$D$34)),"") -> 9.8 | J8: =IFERROR(IF($C8="","",SUMPRODUCT(--($C$5:$C$29=$C8),$D$5:$D$29)),"") -> 1730 | K8: =IFERROR(IF($C8="","",SUMPRODUCT(--($C$5:$C$29=$C8),--($D$5:$D$29>0))),"") -> 7 | L8: =IFERROR(IF(OR($D8="",$J8="",$J8=0),"",$D8/$J8),"") -> 0.21965318 | M8: =IFERROR(IF(OR($K8="",$K8=0,$D$33=""),"",$D$33/$K8),"") -> 0.1 | N8: =IFERROR(IF(OR($J8="",$J8=0),"",SUMPRODUCT(--($C$5:$C$29=$C8),$D$5:$D$29,$G$5:$G$29)/$J8),"") -> 7.4635838 | O8: =IFERROR(IF(SUMPRODUCT(--($C$5:$C$29=$C8),$D$5:$D$29,$F$5:$F$29)=0,"",SUMPRODUCT(--($C$5:$C$29=$C8),$D$5:$D$29,$E$5:$E$29)/SUMPRODUCT(--($C$5:$C$29=$C8),$D$5:$D$29,$F$5:$F$29)),"") -> 0.30714746 | P8: =IFERROR(IF(OR($G8="",$D8=""),"",$G8*$D8),"") -> 2812 | Q8: =IFERROR(IF(OR($K8="",$K8=0),"",SUMPRODUCT(--($C$5:$C$29=$C8),$D$5:$D$29,$G$5:$G$29)/$K8),"") -> 1844.5714
A9: 5 | B9: Local cheese board | C9: Starters | D9: 90 | E9: 5.2 | F9: 13.6 | G9: =IFERROR(IF(OR($E9="",$F9=""),"",$F9-$E9),"") -> 8.4 | H9: =IFERROR(IF(OR($E9="",$F9="",$F9=0),"",$E9/$F9),"") -> 0.38235294 | I9: =IFERROR(IF(OR($F9="",$D$34=""),"",$F9*(1+$D$34)),"") -> 13.6 | J9: =IFERROR(IF($C9="","",SUMPRODUCT(--($C$5:$C$29=$C9),$D$5:$D$29)),"") -> 1730 | K9: =IFERROR(IF($C9="","",SUMPRODUCT(--($C$5:$C$29=$C9),--($D$5:$D$29>0))),"") -> 7 | L9: =IFERROR(IF(OR($D9="",$J9="",$J9=0),"",$D9/$J9),"") -> 0.052023121 | M9: =IFERROR(IF(OR($K9="",$K9=0,$D$33=""),"",$D$33/$K9),"") -> 0.1 | N9: =IFERROR(IF(OR($J9="",$J9=0),"",SUMPRODUCT(--($C$5:$C$29=$C9),$D$5:$D$29,$G$5:$G$29)/$J9),"") -> 7.4635838 | O9: =IFERROR(IF(SUMPRODUCT(--($C$5:$C$29=$C9),$D$5:$D$29,$F$5:$F$29)=0,"",SUMPRODUCT(--($C$5:$C$29=$C9),$D$5:$D$29,$E$5:$E$29)/SUMPRODUCT(--($C$5:$C$29=$C9),$D$5:$D$29,$F$5:$F$29)),"") -> 0.30714746 | P9: =IFERROR(IF(OR($G9="",$D9=""),"",$G9*$D9),"") -> 756 | Q9: =IFERROR(IF(OR($K9="",$K9=0),"",SUMPRODUCT(--($C$5:$C$29=$C9),$D$5:$D$29,$G$5:$G$29)/$K9),"") -> 1844.5714
A10: 6 | B10: Confit artichokes with ham | C10: Starters | D10: 120 | E10: 3.1 | F10: 10.9 | G10: =IFERROR(IF(OR($E10="",$F10=""),"",$F10-$E10),"") -> 7.8 | H10: =IFERROR(IF(OR($E10="",$F10="",$F10=0),"",$E10/$F10),"") -> 0.28440367 | I10: =IFERROR(IF(OR($F10="",$D$34=""),"",$F10*(1+$D$34)),"") -> 10.9 | J10: =IFERROR(IF($C10="","",SUMPRODUCT(--($C$5:$C$29=$C10),$D$5:$D$29)),"") -> 1730 | K10: =IFERROR(IF($C10="","",SUMPRODUCT(--($C$5:$C$29=$C10),--($D$5:$D$29>0))),"") -> 7 | L10: =IFERROR(IF(OR($D10="",$J10="",$J10=0),"",$D10/$J10),"") -> 0.069364162 | M10: =IFERROR(IF(OR($K10="",$K10=0,$D$33=""),"",$D$33/$K10),"") -> 0.1 | N10: =IFERROR(IF(OR($J10="",$J10=0),"",SUMPRODUCT(--($C$5:$C$29=$C10),$D$5:$D$29,$G$5:$G$29)/$J10),"") -> 7.4635838 | O10: =IFERROR(IF(SUMPRODUCT(--($C$5:$C$29=$C10),$D$5:$D$29,$F$5:$F$29)=0,"",SUMPRODUCT(--($C$5:$C$29=$C10),$D$5:$D$29,$E$5:$E$29)/SUMPRODUCT(--($C$5:$C$29=$C10),$D$5:$D$29,$F$5:$F$29)),"") -> 0.30714746 | P10: =IFERROR(IF(OR($G10="",$D10=""),"",$G10*$D10),"") -> 936 | Q10: =IFERROR(IF(OR($K10="",$K10=0),"",SUMPRODUCT(--($C$5:$C$29=$C10),$D$5:$D$29,$G$5:$G$29)/$K10),"") -> 1844.5714
A11: 7 | B11: Roasted tomato soup with basil | C11: Starters | D11: 150 | E11: 1.2 | F11: 7.2 | G11: =IFERROR(IF(OR($E11="",$F11=""),"",$F11-$E11),"") -> 6 | H11: =IFERROR(IF(OR($E11="",$F11="",$F11=0),"",$E11/$F11),"") -> 0.16666667 | I11: =IFERROR(IF(OR($F11="",$D$34=""),"",$F11*(1+$D$34)),"") -> 7.2 | J11: =IFERROR(IF($C11="","",SUMPRODUCT(--($C$5:$C$29=$C11),$D$5:$D$29)),"") -> 1730 | K11: =IFERROR(IF($C11="","",SUMPRODUCT(--($C$5:$C$29=$C11),--($D$5:$D$29>0))),"") -> 7 | L11: =IFERROR(IF(OR($D11="",$J11="",$J11=0),"",$D11/$J11),"") -> 0.086705202 | M11: =IFERROR(IF(OR($K11="",$K11=0,$D$33=""),"",$D$33/$K11),"") -> 0.1 | N11: =IFERROR(IF(OR($J11="",$J11=0),"",SUMPRODUCT(--($C$5:$C$29=$C11),$D$5:$D$29,$G$5:$G$29)/$J11),"") -> 7.4635838 | O11: =IFERROR(IF(SUMPRODUCT(--($C$5:$C$29=$C11),$D$5:$D$29,$F$5:$F$29)=0,"",SUMPRODUCT(--($C$5:$C$29=$C11),$D$5:$D$29,$E$5:$E$29)/SUMPRODUCT(--($C$5:$C$29=$C11),$D$5:$D$29,$F$5:$F$29)),"") -> 0.30714746 | P11: =IFERROR(IF(OR($G11="",$D11=""),"",$G11*$D11),"") -> 900 | Q11: =IFERROR(IF(OR($K11="",$K11=0),"",SUMPRODUCT(--($C$5:$C$29=$C11),$D$5:$D$29,$G$5:$G$29)/$K11),"") -> 1844.5714
A12: 8 | B12: Iberico pork tenderloin with sweet potato purée | C12: Mains | D12: 340 | E12: 5.67 | F12: 17.3 | G12: =IFERROR(IF(OR($E12="",$F12=""),"",$F12-$E12),"") -> 11.63 | H12: =IFERROR(IF(OR($E12="",$F12="",$F12=0),"",$E12/$F12),"") -> 0.32774566 | I12: =IFERROR(IF(OR($F12="",$D$34=""),"",$F12*(1+$D$34)),"") -> 17.3 | J12: =IFERROR(IF($C12="","",SUMPRODUCT(--($C$5:$C$29=$C12),$D$5:$D$29)),"") -> 2020 | K12: =IFERROR(IF($C12="","",SUMPRODUCT(--($C$5:$C$29=$C12),--($D$5:$D$29>0))),"") -> 9 | L12: =IFERROR(IF(OR($D12="",$J12="",$J12=0),"",$D12/$J12),"") -> 0.16831683 | M12: =IFERROR(IF(OR($K12="",$K12=0,$D$33=""),"",$D$33/$K12),"") -> 0.077777778 | N12: =IFERROR(IF(OR($J12="",$J12=0),"",SUMPRODUCT(--($C$5:$C$29=$C12),$D$5:$D$29,$G$5:$G$29)/$J12),"") -> 10.795149 | O12: =IFERROR(IF(SUMPRODUCT(--($C$5:$C$29=$C12),$D$5:$D$29,$F$5:$F$29)=0,"",SUMPRODUCT(--($C$5:$C$29=$C12),$D$5:$D$29,$E$5:$E$29)/SUMPRODUCT(--($C$5:$C$29=$C12),$D$5:$D$29,$F$5:$F$29)),"") -> 0.35587523 | P12: =IFERROR(IF(OR($G12="",$D12=""),"",$G12*$D12),"") -> 3954.2 | Q12: =IFERROR(IF(OR($K12="",$K12=0),"",SUMPRODUCT(--($C$5:$C$29=$C12),$D$5:$D$29,$G$5:$G$29)/$K12),"") -> 2422.9111
A13: 9 | B13: Confit cod in pil-pil sauce | C13: Mains | D13: 190 | E13: 7.4 | F13: 19.1 | G13: =IFERROR(IF(OR($E13="",$F13=""),"",$F13-$E13),"") -> 11.7 | H13: =IFERROR(IF(OR($E13="",$F13="",$F13=0),"",$E13/$F13),"") -> 0.38743455 | I13: =IFERROR(IF(OR($F13="",$D$34=""),"",$F13*(1+$D$34)),"") -> 19.1 | J13: =IFERROR(IF($C13="","",SUMPRODUCT(--($C$5:$C$29=$C13),$D$5:$D$29)),"") -> 2020 | K13: =IFERROR(IF($C13="","",SUMPRODUCT(--($C$5:$C$29=$C13),--($D$5:$D$29>0))),"") -> 9 | L13: =IFERROR(IF(OR($D13="",$J13="",$J13=0),"",$D13/$J13),"") -> 0.094059406 | M13: =IFERROR(IF(OR($K13="",$K13=0,$D$33=""),"",$D$33/$K13),"") -> 0.077777778 | N13: =IFERROR(IF(OR($J13="",$J13=0),"",SUMPRODUCT(--($C$5:$C$29=$C13),$D$5:$D$29,$G$5:$G$29)/$J13),"") -> 10.795149 | O13: =IFERROR(IF(SUMPRODUCT(--($C$5:$C$29=$C13),$D$5:$D$29,$F$5:$F$29)=0,"",SUMPRODUCT(--($C$5:$C$29=$C13),$D$5:$D$29,$E$5:$E$29)/SUMPRODUCT(--($C$5:$C$29=$C13),$D$5:$D$29,$F$5:$F$29)),"") -> 0.35587523 | P13: =IFERROR(IF(OR($G13="",$D13=""),"",$G13*$D13),"") -> 2223 | Q13: =IFERROR(IF(OR($K13="",$K13=0),"",SUMPRODUCT(--($C$5:$C$29=$C13),$D$5:$D$29,$G$5:$G$29)/$K13),"") -> 2422.9111
A14: 10 | B14: Dry-aged beef burger with fries | C14: Mains | D14: 460 | E14: 4.3 | F14: 13.6 | G14: =IFERROR(IF(OR($E14="",$F14=""),"",$F14-$E14),"") -> 9.3 | H14: =IFERROR(IF(OR($E14="",$F14="",$F14=0),"",$E14/$F14),"") -> 0.31617647 | I14: =IFERROR(IF(OR($F14="",$D$34=""),"",$F14*(1+$D$34)),"") -> 13.6 | J14: =IFERROR(IF($C14="","",SUMPRODUCT(--($C$5:$C$29=$C14),$D$5:$D$29)),"") -> 2020 | K14: =IFERROR(IF($C14="","",SUMPRODUCT(--($C$5:$C$29=$C14),--($D$5:$D$29>0))),"") -> 9 | L14: =IFERROR(IF(OR($D14="",$J14="",$J14=0),"",$D14/$J14),"") -> 0.22772277 | M14: =IFERROR(IF(OR($K14="",$K14=0,$D$33=""),"",$D$33/$K14),"") -> 0.077777778 | N14: =IFERROR(IF(OR($J14="",$J14=0),"",SUMPRODUCT(--($C$5:$C$29=$C14),$D$5:$D$29,$G$5:$G$29)/$J14),"") -> 10.795149 | O14: =IFERROR(IF(SUMPRODUCT(--($C$5:$C$29=$C14),$D$5:$D$29,$F$5:$F$29)=0,"",SUMPRODUCT(--($C$5:$C$29=$C14),$D$5:$D$29,$E$5:$E$29)/SUMPRODUCT(--($C$5:$C$29=$C14),$D$5:$D$29,$F$5:$F$29)),"") -> 0.35587523 | P14: =IFERROR(IF(OR($G14="",$D14=""),"",$G14*$D14),"") -> 4278 | Q14: =IFERROR(IF(OR($K14="",$K14=0),"",SUMPRODUCT(--($C$5:$C$29=$C14),$D$5:$D$29,$G$5:$G$29)/$K14),"") -> 2422.9111
A15: 11 | B15: Creamy rice with Iberico pork secreto and mushrooms | C15: Mains | D15: 270 | E15: 6.2 | F15: 16.4 | G15: =IFERROR(IF(OR($E15="",$F15=""),"",$F15-$E15),"") -> 10.2 | H15: =IFERROR(IF(OR($E15="",$F15="",$F15=0),"",$E15/$F15),"") -> 0.37804878 | I15: =IFERROR(IF(OR($F15="",$D$34=""),"",$F15*(1+$D$34)),"") -> 16.4 | J15: =IFERROR(IF($C15="","",SUMPRODUCT(--($C$5:$C$29=$C15),$D$5:$D$29)),"") -> 2020 | K15: =IFERROR(IF($C15="","",SUMPRODUCT(--($C$5:$C$29=$C15),--($D$5:$D$29>0))),"") -> 9 | L15: =IFERROR(IF(OR($D15="",$J15="",$J15=0),"",$D15/$J15),"") -> 0.13366337 | M15: =IFERROR(IF(OR($K15="",$K15=0,$D$33=""),"",$D$33/$K15),"") -> 0.077777778 | N15: =IFERROR(IF(OR($J15="",$J15=0),"",SUMPRODUCT(--($C$5:$C$29=$C15),$D$5:$D$29,$G$5:$G$29)/$J15),"") -> 10.795149 | O15: =IFERROR(IF(SUMPRODUCT(--($C$5:$C$29=$C15),$D$5:$D$29,$F$5:$F$29)=0,"",SUMPRODUCT(--($C$5:$C$29=$C15),$D$5:$D$29,$E$5:$E$29)/SUMPRODUCT(--($C$5:$C$29=$C15),$D$5:$D$29,$F$5:$F$29)),"") -> 0.35587523 | P15: =IFERROR(IF(OR($G15="",$D15=""),"",$G15*$D15),"") -> 2754 | Q15: =IFERROR(IF(OR($K15="",$K15=0),"",SUMPRODUCT(--($C$5:$C$29=$C15),$D$5:$D$29,$G$5:$G$29)/$K15),"") -> 2422.9111
A16: 12 | B16: Dry-aged bone-in ribeye (17.64 oz) | C16: Mains | D16: 110 | E16: 14.8 | F16: 32.7 | G16: =IFERROR(IF(OR($E16="",$F16=""),"",$F16-$E16),"") -> 17.9 | H16: =IFERROR(IF(OR($E16="",$F16="",$F16=0),"",$E16/$F16),"") -> 0.45259939 | I16: =IFERROR(IF(OR($F16="",$D$34=""),"",$F16*(1+$D$34)),"") -> 32.7 | J16: =IFERROR(IF($C16="","",SUMPRODUCT(--($C$5:$C$29=$C16),$D$5:$D$29)),"") -> 2020 | K16: =IFERROR(IF($C16="","",SUMPRODUCT(--($C$5:$C$29=$C16),--($D$5:$D$29>0))),"") -> 9 | L16: =IFERROR(IF(OR($D16="",$J16="",$J16=0),"",$D16/$J16),"") -> 0.054455446 | M16: =IFERROR(IF(OR($K16="",$K16=0,$D$33=""),"",$D$33/$K16),"") -> 0.077777778 | N16: =IFERROR(IF(OR($J16="",$J16=0),"",SUMPRODUCT(--($C$5:$C$29=$C16),$D$5:$D$29,$G$5:$G$29)/$J16),"") -> 10.795149 | O16: =IFERROR(IF(SUMPRODUCT(--($C$5:$C$29=$C16),$D$5:$D$29,$F$5:$F$29)=0,"",SUMPRODUCT(--($C$5:$C$29=$C16),$D$5:$D$29,$E$5:$E$29)/SUMPRODUCT(--($C$5:$C$29=$C16),$D$5:$D$29,$F$5:$F$29)),"") -> 0.35587523 | P16: =IFERROR(IF(OR($G16="",$D16=""),"",$G16*$D16),"") -> 1969 | Q16: =IFERROR(IF(OR($K16="",$K16=0),"",SUMPRODUCT(--($C$5:$C$29=$C16),$D$5:$D$29,$G$5:$G$29)/$K16),"") -> 2422.9111
... A24: 20 | B24: Prepared seasonal fruit | C24: Desserts | D24: 60 | E24: 1.4 | F24: 4.5 | G24: =IFERROR(IF(OR($E24="",$F24=""),"",$F24-$E24),"") -> 3.1 | H24: =IFERROR(IF(OR($E24="",$F24="",$F24=0),"",$E24/$F24),"") -> 0.31111111 | I24: =IFERROR(IF(OR($F24="",$D$34=""),"",$F24*(1+$D$34)),"") -> 4.5 | J24: =IFERROR(IF($C24="","",SUMPRODUCT(--($C$5:$C$29=$C24),$D$5:$D$29)),"") -> 1120 | K24: =IFERROR(IF($C24="","",SUMPRODUCT(--($C$5:$C$29=$C24),--($D$5:$D$29>0))),"") -> 4 | L24: =IFERROR(IF(OR($D24="",$J24="",$J24=0),"",$D24/$J24),"") -> 0.053571429 | M24: =IFERROR(IF(OR($K24="",$K24=0,$D$33=""),"",$D$33/$K24),"") -> 0.175 | N24: =IFERROR(IF(OR($J24="",$J24=0),"",SUMPRODUCT(--($C$5:$C$29=$C24),$D$5:$D$29,$G$5:$G$29)/$J24),"") -> 4.4821429 | O24: =IFERROR(IF(SUMPRODUCT(--($C$5:$C$29=$C24),$D$5:$D$29,$F$5:$F$29)=0,"",SUMPRODUCT(--($C$5:$C$29=$C24),$D$5:$D$29,$E$5:$E$29)/SUMPRODUCT(--($C$5:$C$29=$C24),$D$5:$D$29,$F$5:$F$29)),"") -> 0.23229852 | P24: =IFERROR(IF(OR($G24="",$D24=""),"",$G24*$D24),"") -> 186 | Q24: =IFERROR(IF(OR($K24="",$K24=0),"",SUMPRODUCT(--($C$5:$C$29=$C24),$D$5:$D$29,$G$5:$G$29)/$K24),"") -> 1255
A25: 21 | G25: =IFERROR(IF(OR($E25="",$F25=""),"",$F25-$E25),"") | H25: =IFERROR(IF(OR($E25="",$F25="",$F25=0),"",$E25/$F25),"") | I25: =IFERROR(IF(OR($F25="",$D$34=""),"",$F25*(1+$D$34)),"") | J25: =IFERROR(IF($C25="","",SUMPRODUCT(--($C$5:$C$29=$C25),$D$5:$D$29)),"") | K25: =IFERROR(IF($C25="","",SUMPRODUCT(--($C$5:$C$29=$C25),--($D$5:$D$29>0))),"") | L25: =IFERROR(IF(OR($D25="",$J25="",$J25=0),"",$D25/$J25),"") | M25: =IFERROR(IF(OR($K25="",$K25=0,$D$33=""),"",$D$33/$K25),"") | N25: =IFERROR(IF(OR($J25="",$J25=0),"",SUMPRODUCT(--($C$5:$C$29=$C25),$D$5:$D$29,$G$5:$G$29)/$J25),"") | O25: =IFERROR(IF(SUMPRODUCT(--($C$5:$C$29=$C25),$D$5:$D$29,$F$5:$F$29)=0,"",SUMPRODUCT(--($C$5:$C$29=$C25),$D$5:$D$29,$E$5:$E$29)/SUMPRODUCT(--($C$5:$C$29=$C25),$D$5:$D$29,$F$5:$F$29)),"") | P25: =IFERROR(IF(OR($G25="",$D25=""),"",$G25*$D25),"") | Q25: =IFERROR(IF(OR($K25="",$K25=0),"",SUMPRODUCT(--($C$5:$C$29=$C25),$D$5:$D$29,$G$5:$G$29)/$K25),"")
A26: 22 | G26: =IFERROR(IF(OR($E26="",$F26=""),"",$F26-$E26),"") | H26: =IFERROR(IF(OR($E26="",$F26="",$F26=0),"",$E26/$F26),"") | I26: =IFERROR(IF(OR($F26="",$D$34=""),"",$F26*(1+$D$34)),"") | J26: =IFERROR(IF($C26="","",SUMPRODUCT(--($C$5:$C$29=$C26),$D$5:$D$29)),"") | K26: =IFERROR(IF($C26="","",SUMPRODUCT(--($C$5:$C$29=$C26),--($D$5:$D$29>0))),"") | L26: =IFERROR(IF(OR($D26="",$J26="",$J26=0),"",$D26/$J26),"") | M26: =IFERROR(IF(OR($K26="",$K26=0,$D$33=""),"",$D$33/$K26),"") | N26: =IFERROR(IF(OR($J26="",$J26=0),"",SUMPRODUCT(--($C$5:$C$29=$C26),$D$5:$D$29,$G$5:$G$29)/$J26),"") | O26: =IFERROR(IF(SUMPRODUCT(--($C$5:$C$29=$C26),$D$5:$D$29,$F$5:$F$29)=0,"",SUMPRODUCT(--($C$5:$C$29=$C26),$D$5:$D$29,$E$5:$E$29)/SUMPRODUCT(--($C$5:$C$29=$C26),$D$5:$D$29,$F$5:$F$29)),"") | P26: =IFERROR(IF(OR($G26="",$D26=""),"",$G26*$D26),"") | Q26: =IFERROR(IF(OR($K26="",$K26=0),"",SUMPRODUCT(--($C$5:$C$29=$C26),$D$5:$D$29,$G$5:$G$29)/$K26),"")
A27: 23 | G27: =IFERROR(IF(OR($E27="",$F27=""),"",$F27-$E27),"") | H27: =IFERROR(IF(OR($E27="",$F27="",$F27=0),"",$E27/$F27),"") | I27: =IFERROR(IF(OR($F27="",$D$34=""),"",$F27*(1+$D$34)),"") | J27: =IFERROR(IF($C27="","",SUMPRODUCT(--($C$5:$C$29=$C27),$D$5:$D$29)),"") | K27: =IFERROR(IF($C27="","",SUMPRODUCT(--($C$5:$C$29=$C27),--($D$5:$D$29>0))),"") | L27: =IFERROR(IF(OR($D27="",$J27="",$J27=0),"",$D27/$J27),"") | M27: =IFERROR(IF(OR($K27="",$K27=0,$D$33=""),"",$D$33/$K27),"") | N27: =IFERROR(IF(OR($J27="",$J27=0),"",SUMPRODUCT(--($C$5:$C$29=$C27),$D$5:$D$29,$G$5:$G$29)/$J27),"") | O27: =IFERROR(IF(SUMPRODUCT(--($C$5:$C$29=$C27),$D$5:$D$29,$F$5:$F$29)=0,"",SUMPRODUCT(--($C$5:$C$29=$C27),$D$5:$D$29,$E$5:$E$29)/SUMPRODUCT(--($C$5:$C$29=$C27),$D$5:$D$29,$F$5:$F$29)),"") | P27: =IFERROR(IF(OR($G27="",$D27=""),"",$G27*$D27),"") | Q27: =IFERROR(IF(OR($K27="",$K27=0),"",SUMPRODUCT(--($C$5:$C$29=$C27),$D$5:$D$29,$G$5:$G$29)/$K27),"")
A28: 24 | G28: =IFERROR(IF(OR($E28="",$F28=""),"",$F28-$E28),"") | H28: =IFERROR(IF(OR($E28="",$F28="",$F28=0),"",$E28/$F28),"") | I28: =IFERROR(IF(OR($F28="",$D$34=""),"",$F28*(1+$D$34)),"") | J28: =IFERROR(IF($C28="","",SUMPRODUCT(--($C$5:$C$29=$C28),$D$5:$D$29)),"") | K28: =IFERROR(IF($C28="","",SUMPRODUCT(--($C$5:$C$29=$C28),--($D$5:$D$29>0))),"") | L28: =IFERROR(IF(OR($D28="",$J28="",$J28=0),"",$D28/$J28),"") | M28: =IFERROR(IF(OR($K28="",$K28=0,$D$33=""),"",$D$33/$K28),"") | N28: =IFERROR(IF(OR($J28="",$J28=0),"",SUMPRODUCT(--($C$5:$C$29=$C28),$D$5:$D$29,$G$5:$G$29)/$J28),"") | O28: =IFERROR(IF(SUMPRODUCT(--($C$5:$C$29=$C28),$D$5:$D$29,$F$5:$F$29)=0,"",SUMPRODUCT(--($C$5:$C$29=$C28),$D$5:$D$29,$E$5:$E$29)/SUMPRODUCT(--($C$5:$C$29=$C28),$D$5:$D$29,$F$5:$F$29)),"") | P28: =IFERROR(IF(OR($G28="",$D28=""),"",$G28*$D28),"") | Q28: =IFERROR(IF(OR($K28="",$K28=0),"",SUMPRODUCT(--($C$5:$C$29=$C28),$D$5:$D$29,$G$5:$G$29)/$K28),"")
A29: 25 | G29: =IFERROR(IF(OR($E29="",$F29=""),"",$F29-$E29),"") | H29: =IFERROR(IF(OR($E29="",$F29="",$F29=0),"",$E29/$F29),"") | I29: =IFERROR(IF(OR($F29="",$D$34=""),"",$F29*(1+$D$34)),"") | J29: =IFERROR(IF($C29="","",SUMPRODUCT(--($C$5:$C$29=$C29),$D$5:$D$29)),"") | K29: =IFERROR(IF($C29="","",SUMPRODUCT(--($C$5:$C$29=$C29),--($D$5:$D$29>0))),"") | L29: =IFERROR(IF(OR($D29="",$J29="",$J29=0),"",$D29/$J29),"") | M29: =IFERROR(IF(OR($K29="",$K29=0,$D$33=""),"",$D$33/$K29),"") | N29: =IFERROR(IF(OR($J29="",$J29=0),"",SUMPRODUCT(--($C$5:$C$29=$C29),$D$5:$D$29,$G$5:$G$29)/$J29),"") | O29: =IFERROR(IF(SUMPRODUCT(--($C$5:$C$29=$C29),$D$5:$D$29,$F$5:$F$29)=0,"",SUMPRODUCT(--($C$5:$C$29=$C29),$D$5:$D$29,$E$5:$E$29)/SUMPRODUCT(--($C$5:$C$29=$C29),$D$5:$D$29,$F$5:$F$29)),"") | P29: =IFERROR(IF(OR($G29="",$D29=""),"",$G29*$D29),"") | Q29: =IFERROR(IF(OR($K29="",$K29=0),"",SUMPRODUCT(--($C$5:$C$29=$C29),$D$5:$D$29,$G$5:$G$29)/$K29),"")
A31: SUMMARY AND INPUTS — calculated by the workbook
B32: MENU TOTAL | D32: =IFERROR(SUM($D$5:$D$29),"") -> 4870 | G32: =IFERROR(IF($D$32=0,"",SUMPRODUCT($D$5:$D$29,$G$5:$G$29)/$D$32),"") -> 8.1597947 | H32: =IFERROR(IF(SUMPRODUCT($D$5:$D$29,$F$5:$F$29)=0,"",SUMPRODUCT($D$5:$D$29,$E$5:$E$29)/SUMPRODUCT($D$5:$D$29,$F$5:$F$29)),"") -> 0.32680208 | I32: =IFERROR(SUMPRODUCT($D$5:$D$29,$F$5:$F$29),"") -> 59029 | J32: Units · weighted avg CM · weighted avg food cost · net sales for the month
B33: Popularity threshold factor (%) | D33: 0.7 | F33: The classic is 70% of the average mix: each category's threshold = this factor ÷ number of dishes in the category with sales. Raise it if the category is very short.
B34: Tax rate (%) | D34: 0 | F34: Ships at 0%: US and Canadian menus are printed pre-tax. In the UK type 20% (VAT is included in printed prices); in Australia type 10% (GST included). Change it here and the whole workbook recalculates.
B35: Dishes with sales on the menu | D35: =COUNTIF($D$5:$D$29,">0") -> 20
B36: Dishes listed on the menu | D36: =COUNTIF($B$5:$B$29,"<>") -> 20
A38: SUMMARY BY CATEGORY — calculated by the workbook
B39: Category | C39: Dishes on the menu | D39: Dishes with sales | E39: Units sold | F39: Share of menu mix (%) | G39: Weighted avg CM | H39: Weighted avg food cost (%) | I39: Net sales for the month
B40: Starters | C40: =COUNTIF($C$5:$C$29,$B40) -> 7 | D40: =IFERROR(IF($C40=0,"",SUMPRODUCT(--($C$5:$C$29=$B40),--($D$5:$D$29>0))),"") -> 7 | E40: =IFERROR(IF($C40=0,"",SUMIF($C$5:$C$29,$B40,$D$5:$D$29)),"") -> 1730 | F40: =IFERROR(IF(OR($D$32=0,$C40=0),"",$E40/$D$32),"") -> 0.35523614 | G40: =IFERROR(IF($E40=0,"",SUMPRODUCT(--($C$5:$C$29=$B40),$D$5:$D$29,$G$5:$G$29)/$E40),"") -> 7.4635838 | H40: =IFERROR(IF(SUMPRODUCT(--($C$5:$C$29=$B40),$D$5:$D$29,$F$5:$F$29)=0,"",SUMPRODUCT(--($C$5:$C$29=$B40),$D$5:$D$29,$E$5:$E$29)/SUMPRODUCT(--($C$5:$C$29=$B40),$D$5:$D$29,$F$5:$F$29)),"") -> 0.30714746 | I40: =IFERROR(SUMPRODUCT(--($C$5:$C$29=$B40),$D$5:$D$29,$F$5:$F$29),"") -> 18636
B41: Mains | C41: =COUNTIF($C$5:$C$29,$B41) -> 9 | D41: =IFERROR(IF($C41=0,"",SUMPRODUCT(--($C$5:$C$29=$B41),--($D$5:$D$29>0))),"") -> 9 | E41: =IFERROR(IF($C41=0,"",SUMIF($C$5:$C$29,$B41,$D$5:$D$29)),"") -> 2020 | F41: =IFERROR(IF(OR($D$32=0,$C41=0),"",$E41/$D$32),"") -> 0.41478439 | G41: =IFERROR(IF($E41=0,"",SUMPRODUCT(--($C$5:$C$29=$B41),$D$5:$D$29,$G$5:$G$29)/$E41),"") -> 10.795149 | H41: =IFERROR(IF(SUMPRODUCT(--($C$5:$C$29=$B41),$D$5:$D$29,$F$5:$F$29)=0,"",SUMPRODUCT(--($C$5:$C$29=$B41),$D$5:$D$29,$E$5:$E$29)/SUMPRODUCT(--($C$5:$C$29=$B41),$D$5:$D$29,$F$5:$F$29)),"") -> 0.35587523 | I41: =IFERROR(SUMPRODUCT(--($C$5:$C$29=$B41),$D$5:$D$29,$F$5:$F$29),"") -> 33854
B42: Desserts | C42: =COUNTIF($C$5:$C$29,$B42) -> 4 | D42: =IFERROR(IF($C42=0,"",SUMPRODUCT(--($C$5:$C$29=$B42),--($D$5:$D$29>0))),"") -> 4 | E42: =IFERROR(IF($C42=0,"",SUMIF($C$5:$C$29,$B42,$D$5:$D$29)),"") -> 1120 | F42: =IFERROR(IF(OR($D$32=0,$C42=0),"",$E42/$D$32),"") -> 0.22997947 | G42: =IFERROR(IF($E42=0,"",SUMPRODUCT(--($C$5:$C$29=$B42),$D$5:$D$29,$G$5:$G$29)/$E42),"") -> 4.4821429 | H42: =IFERROR(IF(SUMPRODUCT(--($C$5:$C$29=$B42),$D$5:$D$29,$F$5:$F$29)=0,"",SUMPRODUCT(--($C$5:$C$29=$B42),$D$5:$D$29,$E$5:$E$29)/SUMPRODUCT(--($C$5:$C$29=$B42),$D$5:$D$29,$F$5:$F$29)),"") -> 0.23229852 | I42: =IFERROR(SUMPRODUCT(--($C$5:$C$29=$B42),$D$5:$D$29,$F$5:$F$29),"") -> 6539
B43: Prix fixe | C43: =COUNTIF($C$5:$C$29,$B43) -> 0 | D43: =IFERROR(IF($C43=0,"",SUMPRODUCT(--($C$5:$C$29=$B43),--($D$5:$D$29>0))),"") | E43: =IFERROR(IF($C43=0,"",SUMIF($C$5:$C$29,$B43,$D$5:$D$29)),"") | F43: =IFERROR(IF(OR($D$32=0,$C43=0),"",$E43/$D$32),"") | G43: =IFERROR(IF($E43=0,"",SUMPRODUCT(--($C$5:$C$29=$B43),$D$5:$D$29,$G$5:$G$29)/$E43),"") | H43: =IFERROR(IF(SUMPRODUCT(--($C$5:$C$29=$B43),$D$5:$D$29,$F$5:$F$29)=0,"",SUMPRODUCT(--($C$5:$C$29=$B43),$D$5:$D$29,$E$5:$E$29)/SUMPRODUCT(--($C$5:$C$29=$B43),$D$5:$D$29,$F$5:$F$29)),"") | I43: =IFERROR(SUMPRODUCT(--($C$5:$C$29=$B43),$D$5:$D$29,$F$5:$F$29),"") -> 0

Sheet Kasavana-Smith
A1: Kasavana & Smith — popularity × contribution margin
A2: AI Chef Pro · aichef.pro — Food Cost + Menu Engineering Guide
E3: Everything is calculated from the "Data" sheet. You don't type anything here.
A4: # | B4: Dish | C4: Category | D4: Units sold | E4: Menu Mix in Category (MM%) | F4: Popularity threshold in its category (%) | G4: Popularity | H4: Dish CM | I4: Category weighted avg CM | J4: Margin level | K4: Classification | L4: What it means | M4: Recommended action
A5: 1 | B5: =IFERROR(IF('Data'!$B5="","",'Data'!$B5),"") -> Iberico ham croquettes (6 pcs) | C5: =IFERROR(IF('Data'!$C5="","",'Data'!$C5),"") -> Starters | D5: =IFERROR(IF('Data'!$D5="","",'Data'!$D5),"") -> 420 | E5: =IFERROR(IF('Data'!$L5="","",'Data'!$L5),"") -> 0.24277457 | F5: =IFERROR(IF('Data'!$M5="","",'Data'!$M5),"") -> 0.1 | G5: =IFERROR(IF(OR($E5="",$F5=""),"",IF($E5>=$F5,"High","Low")),"") -> High | H5: =IFERROR(IF('Data'!$G5="","",'Data'!$G5),"") -> 6.5 | I5: =IFERROR(IF('Data'!$N5="","",'Data'!$N5),"") -> 7.4635838 | J5: =IFERROR(IF(OR($H5="",$I5=""),"",IF($H5>=$I5,"High","Low")),"") -> Low | K5: =IFERROR(IF(OR($G5="",$J5=""),"",IF(AND($G5="High",$J5="High"),"Star",IF(AND($G5="High",$J5="Low"),"Plowhorse",IF(AND($G5="Low",$J5="High"),"Puzzle","Dog")))),"") -> Plowhorse | L5: =IFERROR(IF($K5="","",IF($K5="Star","It sells and leaves margin: it's the dish that carries its category.",IF($K5="Plowhorse","It sells a lot, but leaves little margin in dollars per unit.",IF($K5="Puzzle","It leaves a good margin in dollars, but few guests order it.","It neither sells nor leaves margin.")))),"") -> It sells a lot, but leaves little margin in dollars per unit. | M5: =IFERROR(IF($K5="","",IF($K5="Star","Keep the recipe and the supplier, and give it a prominent spot on the menu.",IF($K5="Plowhorse","Raise the price carefully or lower the cost without touching the portion.",IF($K5="Puzzle","Move it on the menu, rename it and have the floor staff suggest it.","Remove or rework it: it takes up space on the menu and in the kitchen.")))),"") -> Raise the price carefully or lower the cost without touching the portion.
A6: 2 | B6: =IFERROR(IF('Data'!$B6="","",'Data'!$B6),"") -> Heirloom tomato salad with tuna belly and scallions | C6: =IFERROR(IF('Data'!$C6="","",'Data'!$C6),"") -> Starters | D6: =IFERROR(IF('Data'!$D6="","",'Data'!$D6),"") -> 310 | E6: =IFERROR(IF('Data'!$L6="","",'Data'!$L6),"") -> 0.17919075 | F6: =IFERROR(IF('Data'!$M6="","",'Data'!$M6),"") -> 0.1 | G6: =IFERROR(IF(OR($E6="",$F6=""),"",IF($E6>=$F6,"High","Low")),"") -> High | H6: =IFERROR(IF('Data'!$G6="","",'Data'!$G6),"") -> 8.2 | I6: =IFERROR(IF('Data'!$N6="","",'Data'!$N6),"") -> 7.4635838 | J6: =IFERROR(IF(OR($H6="",$I6=""),"",IF($H6>=$I6,"High","Low")),"") -> High | K6: =IFERROR(IF(OR($G6="",$J6=""),"",IF(AND($G6="High",$J6="High"),"Star",IF(AND($G6="High",$J6="Low"),"Plowhorse",IF(AND($G6="Low",$J6="High"),"Puzzle","Dog")))),"") -> Star | L6: =IFERROR(IF($K6="","",IF($K6="Star","It sells and leaves margin: it's the dish that carries its category.",IF($K6="Plowhorse","It sells a lot, but leaves little margin in dollars per unit.",IF($K6="Puzzle","It leaves a good margin in dollars, but few guests order it.","It neither sells nor leaves margin.")))),"") -> It sells and leaves margin: it's the dish that carries its category. | M6: =IFERROR(IF($K6="","",IF($K6="Star","Keep the recipe and the supplier, and give it a prominent spot on the menu.",IF($K6="Plowhorse","Raise the price carefully or lower the cost without touching the portion.",IF($K6="Puzzle","Move it on the menu, rename it and have the floor staff suggest it.","Remove or rework it: it takes up space on the menu and in the kitchen.")))),"") -> Keep the recipe and the supplier, and give it a prominent spot on the menu.
A7: 3 | B7: =IFERROR(IF('Data'!$B7="","",'Data'!$B7),"") -> Garlic shrimp | C7: =IFERROR(IF('Data'!$C7="","",'Data'!$C7),"") -> Starters | D7: =IFERROR(IF('Data'!$D7="","",'Data'!$D7),"") -> 260 | E7: =IFERROR(IF('Data'!$L7="","",'Data'!$L7),"") -> 0.15028902 | F7: =IFERROR(IF('Data'!$M7="","",'Data'!$M7),"") -> 0.1 | G7: =IFERROR(IF(OR($E7="",$F7=""),"",IF($E7>=$F7,"High","Low")),"") -> High | H7: =IFERROR(IF('Data'!$G7="","",'Data'!$G7),"") -> 8.6 | I7: =IFERROR(IF('Data'!$N7="","",'Data'!$N7),"") -> 7.4635838 | J7: =IFERROR(IF(OR($H7="",$I7=""),"",IF($H7>=$I7,"High","Low")),"") -> High | K7: =IFERROR(IF(OR($G7="",$J7=""),"",IF(AND($G7="High",$J7="High"),"Star",IF(AND($G7="High",$J7="Low"),"Plowhorse",IF(AND($G7="Low",$J7="High"),"Puzzle","Dog")))),"") -> Star | L7: =IFERROR(IF($K7="","",IF($K7="Star","It sells and leaves margin: it's the dish that carries its category.",IF($K7="Plowhorse","It sells a lot, but leaves little margin in dollars per unit.",IF($K7="Puzzle","It leaves a good margin in dollars, but few guests order it.","It neither sells nor leaves margin.")))),"") -> It sells and leaves margin: it's the dish that carries its category. | M7: =IFERROR(IF($K7="","",IF($K7="Star","Keep the recipe and the supplier, and give it a prominent spot on the menu.",IF($K7="Plowhorse","Raise the price carefully or lower the cost without touching the portion.",IF($K7="Puzzle","Move it on the menu, rename it and have the floor staff suggest it.","Remove or rework it: it takes up space on the menu and in the kitchen.")))),"") -> Keep the recipe and the supplier, and give it a prominent spot on the menu.
A8: 4 | B8: =IFERROR(IF('Data'!$B8="","",'Data'!$B8),"") -> Broken eggs with potatoes and chistorra sausage | C8: =IFERROR(IF('Data'!$C8="","",'Data'!$C8),"") -> Starters | D8: =IFERROR(IF('Data'!$D8="","",'Data'!$D8),"") -> 380 | E8: =IFERROR(IF('Data'!$L8="","",'Data'!$L8),"") -> 0.21965318 | F8: =IFERROR(IF('Data'!$M8="","",'Data'!$M8),"") -> 0.1 | G8: =IFERROR(IF(OR($E8="",$F8=""),"",IF($E8>=$F8,"High","Low")),"") -> High | H8: =IFERROR(IF('Data'!$G8="","",'Data'!$G8),"") -> 7.4 | I8: =IFERROR(IF('Data'!$N8="","",'Data'!$N8),"") -> 7.4635838 | J8: =IFERROR(IF(OR($H8="",$I8=""),"",IF($H8>=$I8,"High","Low")),"") -> Low | K8: =IFERROR(IF(OR($G8="",$J8=""),"",IF(AND($G8="High",$J8="High"),"Star",IF(AND($G8="High",$J8="Low"),"Plowhorse",IF(AND($G8="Low",$J8="High"),"Puzzle","Dog")))),"") -> Plowhorse | L8: =IFERROR(IF($K8="","",IF($K8="Star","It sells and leaves margin: it's the dish that carries its category.",IF($K8="Plowhorse","It sells a lot, but leaves little margin in dollars per unit.",IF($K8="Puzzle","It leaves a good margin in dollars, but few guests order it.","It neither sells nor leaves margin.")))),"") -> It sells a lot, but leaves little margin in dollars per unit. | M8: =IFERROR(IF($K8="","",IF($K8="Star","Keep the recipe and the supplier, and give it a prominent spot on the menu.",IF($K8="Plowhorse","Raise the price carefully or lower the cost without touching the portion.",IF($K8="Puzzle","Move it on the menu, rename it and have the floor staff suggest it.","Remove or rework it: it takes up space on the menu and in the kitchen.")))),"") -> Raise the price carefully or lower the cost without touching the portion.
A9: 5 | B9: =IFERROR(IF('Data'!$B9="","",'Data'!$B9),"") -> Local cheese board | C9: =IFERROR(IF('Data'!$C9="","",'Data'!$C9),"") -> Starters | D9: =IFERROR(IF('Data'!$D9="","",'Data'!$D9),"") -> 90 | E9: =IFERROR(IF('Data'!$L9="","",'Data'!$L9),"") -> 0.052023121 | F9: =IFERROR(IF('Data'!$M9="","",'Data'!$M9),"") -> 0.1 | G9: =IFERROR(IF(OR($E9="",$F9=""),"",IF($E9>=$F9,"High","Low")),"") -> Low | H9: =IFERROR(IF('Data'!$G9="","",'Data'!$G9),"") -> 8.4 | I9: =IFERROR(IF('Data'!$N9="","",'Data'!$N9),"") -> 7.4635838 | J9: =IFERROR(IF(OR($H9="",$I9=""),"",IF($H9>=$I9,"High","Low")),"") -> High | K9: =IFERROR(IF(OR($G9="",$J9=""),"",IF(AND($G9="High",$J9="High"),"Star",IF(AND($G9="High",$J9="Low"),"Plowhorse",IF(AND($G9="Low",$J9="High"),"Puzzle","Dog")))),"") -> Puzzle | L9: =IFERROR(IF($K9="","",IF($K9="Star","It sells and leaves margin: it's the dish that carries its category.",IF($K9="Plowhorse","It sells a lot, but leaves little margin in dollars per unit.",IF($K9="Puzzle","It leaves a good margin in dollars, but few guests order it.","It neither sells nor leaves margin.")))),"") -> It leaves a good margin in dollars, but few guests order it. | M9: =IFERROR(IF($K9="","",IF($K9="Star","Keep the recipe and the supplier, and give it a prominent spot on the menu.",IF($K9="Plowhorse","Raise the price carefully or lower the cost without touching the portion.",IF($K9="Puzzle","Move it on the menu, rename it and have the floor staff suggest it.","Remove or rework it: it takes up space on the menu and in the kitchen.")))),"") -> Move it on the menu, rename it and have the floor staff suggest it.
A10: 6 | B10: =IFERROR(IF('Data'!$B10="","",'Data'!$B10),"") -> Confit artichokes with ham | C10: =IFERROR(IF('Data'!$C10="","",'Data'!$C10),"") -> Starters | D10: =IFERROR(IF('Data'!$D10="","",'Data'!$D10),"") -> 120 | E10: =IFERROR(IF('Data'!$L10="","",'Data'!$L10),"") -> 0.069364162 | F10: =IFERROR(IF('Data'!$M10="","",'Data'!$M10),"") -> 0.1 | G10: =IFERROR(IF(OR($E10="",$F10=""),"",IF($E10>=$F10,"High","Low")),"") -> Low | H10: =IFERROR(IF('Data'!$G10="","",'Data'!$G10),"") -> 7.8 | I10: =IFERROR(IF('Data'!$N10="","",'Data'!$N10),"") -> 7.4635838 | J10: =IFERROR(IF(OR($H10="",$I10=""),"",IF($H10>=$I10,"High","Low")),"") -> High | K10: =IFERROR(IF(OR($G10="",$J10=""),"",IF(AND($G10="High",$J10="High"),"Star",IF(AND($G10="High",$J10="Low"),"Plowhorse",IF(AND($G10="Low",$J10="High"),"Puzzle","Dog")))),"") -> Puzzle | L10: =IFERROR(IF($K10="","",IF($K10="Star","It sells and leaves margin: it's the dish that carries its category.",IF($K10="Plowhorse","It sells a lot, but leaves little margin in dollars per unit.",IF($K10="Puzzle","It leaves a good margin in dollars, but few guests order it.","It neither sells nor leaves margin.")))),"") -> It leaves a good margin in dollars, but few guests order it. | M10: =IFERROR(IF($K10="","",IF($K10="Star","Keep the recipe and the supplier, and give it a prominent spot on the menu.",IF($K10="Plowhorse","Raise the price carefully or lower the cost without touching the portion.",IF($K10="Puzzle","Move it on the menu, rename it and have the floor staff suggest it.","Remove or rework it: it takes up space on the menu and in the kitchen.")))),"") -> Move it on the menu, rename it and have the floor staff suggest it.
A11: 7 | B11: =IFERROR(IF('Data'!$B11="","",'Data'!$B11),"") -> Roasted tomato soup with basil | C11: =IFERROR(IF('Data'!$C11="","",'Data'!$C11),"") -> Starters | D11: =IFERROR(IF('Data'!$D11="","",'Data'!$D11),"") -> 150 | E11: =IFERROR(IF('Data'!$L11="","",'Data'!$L11),"") -> 0.086705202 | F11: =IFERROR(IF('Data'!$M11="","",'Data'!$M11),"") -> 0.1 | G11: =IFERROR(IF(OR($E11="",$F11=""),"",IF($E11>=$F11,"High","Low")),"") -> Low | H11: =IFERROR(IF('Data'!$G11="","",'Data'!$G11),"") -> 6 | I11: =IFERROR(IF('Data'!$N11="","",'Data'!$N11),"") -> 7.4635838 | J11: =IFERROR(IF(OR($H11="",$I11=""),"",IF($H11>=$I11,"High","Low")),"") -> Low | K11: =IFERROR(IF(OR($G11="",$J11=""),"",IF(AND($G11="High",$J11="High"),"Star",IF(AND($G11="High",$J11="Low"),"Plowhorse",IF(AND($G11="Low",$J11="High"),"Puzzle","Dog")))),"") -> Dog | L11: =IFERROR(IF($K11="","",IF($K11="Star","It sells and leaves margin: it's the dish that carries its category.",IF($K11="Plowhorse","It sells a lot, but leaves little margin in dollars per unit.",IF($K11="Puzzle","It leaves a good margin in dollars, but few guests order it.","It neither sells nor leaves margin.")))),"") -> It neither sells nor leaves margin. | M11: =IFERROR(IF($K11="","",IF($K11="Star","Keep the recipe and the supplier, and give it a prominent spot on the menu.",IF($K11="Plowhorse","Raise the price carefully or lower the cost without touching the portion.",IF($K11="Puzzle","Move it on the menu, rename it and have the floor staff suggest it.","Remove or rework it: it takes up space on the menu and in the kitchen.")))),"") -> Remove or rework it: it takes up space on the menu and in the kitchen.
A12: 8 | B12: =IFERROR(IF('Data'!$B12="","",'Data'!$B12),"") -> Iberico pork tenderloin with sweet potato purée | C12: =IFERROR(IF('Data'!$C12="","",'Data'!$C12),"") -> Mains | D12: =IFERROR(IF('Data'!$D12="","",'Data'!$D12),"") -> 340 | E12: =IFERROR(IF('Data'!$L12="","",'Data'!$L12),"") -> 0.16831683 | F12: =IFERROR(IF('Data'!$M12="","",'Data'!$M12),"") -> 0.077777778 | G12: =IFERROR(IF(OR($E12="",$F12=""),"",IF($E12>=$F12,"High","Low")),"") -> High | H12: =IFERROR(IF('Data'!$G12="","",'Data'!$G12),"") -> 11.63 | I12: =IFERROR(IF('Data'!$N12="","",'Data'!$N12),"") -> 10.795149 | J12: =IFERROR(IF(OR($H12="",$I12=""),"",IF($H12>=$I12,"High","Low")),"") -> High | K12: =IFERROR(IF(OR($G12="",$J12=""),"",IF(AND($G12="High",$J12="High"),"Star",IF(AND($G12="High",$J12="Low"),"Plowhorse",IF(AND($G12="Low",$J12="High"),"Puzzle","Dog")))),"") -> Star | L12: =IFERROR(IF($K12="","",IF($K12="Star","It sells and leaves margin: it's the dish that carries its category.",IF($K12="Plowhorse","It sells a lot, but leaves little margin in dollars per unit.",IF($K12="Puzzle","It leaves a good margin in dollars, but few guests order it.","It neither sells nor leaves margin.")))),"") -> It sells and leaves margin: it's the dish that carries its category. | M12: =IFERROR(IF($K12="","",IF($K12="Star","Keep the recipe and the supplier, and give it a prominent spot on the menu.",IF($K12="Plowhorse","Raise the price carefully or lower the cost without touching the portion.",IF($K12="Puzzle","Move it on the menu, rename it and have the floor staff suggest it.","Remove or rework it: it takes up space on the menu and in the kitchen.")))),"") -> Keep the recipe and the supplier, and give it a prominent spot on the menu.
A13: 9 | B13: =IFERROR(IF('Data'!$B13="","",'Data'!$B13),"") -> Confit cod in pil-pil sauce | C13: =IFERROR(IF('Data'!$C13="","",'Data'!$C13),"") -> Mains | D13: =IFERROR(IF('Data'!$D13="","",'Data'!$D13),"") -> 190 | E13: =IFERROR(IF('Data'!$L13="","",'Data'!$L13),"") -> 0.094059406 | F13: =IFERROR(IF('Data'!$M13="","",'Data'!$M13),"") -> 0.077777778 | G13: =IFERROR(IF(OR($E13="",$F13=""),"",IF($E13>=$F13,"High","Low")),"") -> High | H13: =IFERROR(IF('Data'!$G13="","",'Data'!$G13),"") -> 11.7 | I13: =IFERROR(IF('Data'!$N13="","",'Data'!$N13),"") -> 10.795149 | J13: =IFERROR(IF(OR($H13="",$I13=""),"",IF($H13>=$I13,"High","Low")),"") -> High | K13: =IFERROR(IF(OR($G13="",$J13=""),"",IF(AND($G13="High",$J13="High"),"Star",IF(AND($G13="High",$J13="Low"),"Plowhorse",IF(AND($G13="Low",$J13="High"),"Puzzle","Dog")))),"") -> Star | L13: =IFERROR(IF($K13="","",IF($K13="Star","It sells and leaves margin: it's the dish that carries its category.",IF($K13="Plowhorse","It sells a lot, but leaves little margin in dollars per unit.",IF($K13="Puzzle","It leaves a good margin in dollars, but few guests order it.","It neither sells nor leaves margin.")))),"") -> It sells and leaves margin: it's the dish that carries its category. | M13: =IFERROR(IF($K13="","",IF($K13="Star","Keep the recipe and the supplier, and give it a prominent spot on the menu.",IF($K13="Plowhorse","Raise the price carefully or lower the cost without touching the portion.",IF($K13="Puzzle","Move it on the menu, rename it and have the floor staff suggest it.","Remove or rework it: it takes up space on the menu and in the kitchen.")))),"") -> Keep the recipe and the supplier, and give it a prominent spot on the menu.
A14: 10 | B14: =IFERROR(IF('Data'!$B14="","",'Data'!$B14),"") -> Dry-aged beef burger with fries | C14: =IFERROR(IF('Data'!$C14="","",'Data'!$C14),"") -> Mains | D14: =IFERROR(IF('Data'!$D14="","",'Data'!$D14),"") -> 460 | E14: =IFERROR(IF('Data'!$L14="","",'Data'!$L14),"") -> 0.22772277 | F14: =IFERROR(IF('Data'!$M14="","",'Data'!$M14),"") -> 0.077777778 | G14: =IFERROR(IF(OR($E14="",$F14=""),"",IF($E14>=$F14,"High","Low")),"") -> High | H14: =IFERROR(IF('Data'!$G14="","",'Data'!$G14),"") -> 9.3 | I14: =IFERROR(IF('Data'!$N14="","",'Data'!$N14),"") -> 10.795149 | J14: =IFERROR(IF(OR($H14="",$I14=""),"",IF($H14>=$I14,"High","Low")),"") -> Low | K14: =IFERROR(IF(OR($G14="",$J14=""),"",IF(AND($G14="High",$J14="High"),"Star",IF(AND($G14="High",$J14="Low"),"Plowhorse",IF(AND($G14="Low",$J14="High"),"Puzzle","Dog")))),"") -> Plowhorse | L14: =IFERROR(IF($K14="","",IF($K14="Star","It sells and leaves margin: it's the dish that carries its category.",IF($K14="Plowhorse","It sells a lot, but leaves little margin in dollars per unit.",IF($K14="Puzzle","It leaves a good margin in dollars, but few guests order it.","It neither sells nor leaves margin.")))),"") -> It sells a lot, but leaves little margin in dollars per unit. | M14: =IFERROR(IF($K14="","",IF($K14="Star","Keep the recipe and the supplier, and give it a prominent spot on the menu.",IF($K14="Plowhorse","Raise the price carefully or lower the cost without touching the portion.",IF($K14="Puzzle","Move it on the menu, rename it and have the floor staff suggest it.","Remove or rework it: it takes up space on the menu and in the kitchen.")))),"") -> Raise the price carefully or lower the cost without touching the portion.
A15: 11 | B15: =IFERROR(IF('Data'!$B15="","",'Data'!$B15),"") -> Creamy rice with Iberico pork secreto and mushrooms | C15: =IFERROR(IF('Data'!$C15="","",'Data'!$C15),"") -> Mains | D15: =IFERROR(IF('Data'!$D15="","",'Data'!$D15),"") -> 270 | E15: =IFERROR(IF('Data'!$L15="","",'Data'!$L15),"") -> 0.13366337 | F15: =IFERROR(IF('Data'!$M15="","",'Data'!$M15),"") -> 0.077777778 | G15: =IFERROR(IF(OR($E15="",$F15=""),"",IF($E15>=$F15,"High","Low")),"") -> High | H15: =IFERROR(IF('Data'!$G15="","",'Data'!$G15),"") -> 10.2 | I15: =IFERROR(IF('Data'!$N15="","",'Data'!$N15),"") -> 10.795149 | J15: =IFERROR(IF(OR($H15="",$I15=""),"",IF($H15>=$I15,"High","Low")),"") -> Low | K15: =IFERROR(IF(OR($G15="",$J15=""),"",IF(AND($G15="High",$J15="High"),"Star",IF(AND($G15="High",$J15="Low"),"Plowhorse",IF(AND($G15="Low",$J15="High"),"Puzzle","Dog")))),"") -> Plowhorse | L15: =IFERROR(IF($K15="","",IF($K15="Star","It sells and leaves margin: it's the dish that carries its category.",IF($K15="Plowhorse","It sells a lot, but leaves little margin in dollars per unit.",IF($K15="Puzzle","It leaves a good margin in dollars, but few guests order it.","It neither sells nor leaves margin.")))),"") -> It sells a lot, but leaves little margin in dollars per unit. | M15: =IFERROR(IF($K15="","",IF($K15="Star","Keep the recipe and the supplier, and give it a prominent spot on the menu.",IF($K15="Plowhorse","Raise the price carefully or lower the cost without touching the portion.",IF($K15="Puzzle","Move it on the menu, rename it and have the floor staff suggest it.","Remove or rework it: it takes up space on the menu and in the kitchen.")))),"") -> Raise the price carefully or lower the cost without touching the portion.
A16: 12 | B16: =IFERROR(IF('Data'!$B16="","",'Data'!$B16),"") -> Dry-aged bone-in ribeye (17.64 oz) | C16: =IFERROR(IF('Data'!$C16="","",'Data'!$C16),"") -> Mains | D16: =IFERROR(IF('Data'!$D16="","",'Data'!$D16),"") -> 110 | E16: =IFERROR(IF('Data'!$L16="","",'Data'!$L16),"") -> 0.054455446 | F16: =IFERROR(IF('Data'!$M16="","",'Data'!$M16),"") -> 0.077777778 | G16: =IFERROR(IF(OR($E16="",$F16=""),"",IF($E16>=$F16,"High","Low")),"") -> Low | H16: =IFERROR(IF('Data'!$G16="","",'Data'!$G16),"") -> 17.9 | I16: =IFERROR(IF('Data'!$N16="","",'Data'!$N16),"") -> 10.795149 | J16: =IFERROR(IF(OR($H16="",$I16=""),"",IF($H16>=$I16,"High","Low")),"") -> High | K16: =IFERROR(IF(OR($G16="",$J16=""),"",IF(AND($G16="High",$J16="High"),"Star",IF(AND($G16="High",$J16="Low"),"Plowhorse",IF(AND($G16="Low",$J16="High"),"Puzzle","Dog")))),"") -> Puzzle | L16: =IFERROR(IF($K16="","",IF($K16="Star","It sells and leaves margin: it's the dish that carries its category.",IF($K16="Plowhorse","It sells a lot, but leaves little margin in dollars per unit.",IF($K16="Puzzle","It leaves a good margin in dollars, but few guests order it.","It neither sells nor leaves margin.")))),"") -> It leaves a good margin in dollars, but few guests order it. | M16: =IFERROR(IF($K16="","",IF($K16="Star","Keep the recipe and the supplier, and give it a prominent spot on the menu.",IF($K16="Plowhorse","Raise the price carefully or lower the cost without touching the portion.",IF($K16="Puzzle","Move it on the menu, rename it and have the floor staff suggest it.","Remove or rework it: it takes up space on the menu and in the kitchen.")))),"") -> Move it on the menu, rename it and have the floor staff suggest it.
... A29: 25 | B29: =IFERROR(IF('Data'!$B29="","",'Data'!$B29),"") | C29: =IFERROR(IF('Data'!$C29="","",'Data'!$C29),"") | D29: =IFERROR(IF('Data'!$D29="","",'Data'!$D29),"") | E29: =IFERROR(IF('Data'!$L29="","",'Data'!$L29),"") | F29: =IFERROR(IF('Data'!$M29="","",'Data'!$M29),"") | G29: =IFERROR(IF(OR($E29="",$F29=""),"",IF($E29>=$F29,"High","Low")),"") | H29: =IFERROR(IF('Data'!$G29="","",'Data'!$G29),"") | I29: =IFERROR(IF('Data'!$N29="","",'Data'!$N29),"") | J29: =IFERROR(IF(OR($H29="",$I29=""),"",IF($H29>=$I29,"High","Low")),"") | K29: =IFERROR(IF(OR($G29="",$J29=""),"",IF(AND($G29="High",$J29="High"),"Star",IF(AND($G29="High",$J29="Low"),"Plowhorse",IF(AND($G29="Low",$J29="High"),"Puzzle","Dog")))),"") | L29: =IFERROR(IF($K29="","",IF($K29="Star","It sells and leaves margin: it's the dish that carries its category.",IF($K29="Plowhorse","It sells a lot, but leaves little margin in dollars per unit.",IF($K29="Puzzle","It leaves a good margin in dollars, but few guests order it.","It neither sells nor leaves margin.")))),"") | M29: =IFERROR(IF($K29="","",IF($K29="Star","Keep the recipe and the supplier, and give it a prominent spot on the menu.",IF($K29="Plowhorse","Raise the price carefully or lower the cost without touching the portion.",IF($K29="Puzzle","Move it on the menu, rename it and have the floor staff suggest it.","Remove or rework it: it takes up space on the menu and in the kitchen.")))),"")
A31: SUMMARY — calculated by the workbook
B32: Classification | C32: Dishes | D32: Units sold | E32: % of menu units | F32: Total CM contributed
B33: Star | C33: =COUNTIF($K$5:$K$29,$B33) -> 6 | D33: =IFERROR(SUMIF($K$5:$K$29,$B33,$D$5:$D$29),"") -> 1950 | E33: =IFERROR(IF(SUM($D$5:$D$29)=0,"",$D33/SUM($D$5:$D$29)),"") -> 0.40041068 | F33: =IFERROR(SUMPRODUCT(--($K$5:$K$29=$B33),$D$5:$D$29,$H$5:$H$29),"") -> 14865.2
B34: Plowhorse | C34: =COUNTIF($K$5:$K$29,$B34) -> 6 | D34: =IFERROR(SUMIF($K$5:$K$29,$B34,$D$5:$D$29),"") -> 2040 | E34: =IFERROR(IF(SUM($D$5:$D$29)=0,"",$D34/SUM($D$5:$D$29)),"") -> 0.41889117 | F34: =IFERROR(SUMPRODUCT(--($K$5:$K$29=$B34),$D$5:$D$29,$H$5:$H$29),"") -> 16198
B35: Puzzle | C35: =COUNTIF($K$5:$K$29,$B35) -> 5 | D35: =IFERROR(SUMIF($K$5:$K$29,$B35,$D$5:$D$29),"") -> 530 | E35: =IFERROR(IF(SUM($D$5:$D$29)=0,"",$D35/SUM($D$5:$D$29)),"") -> 0.10882957 | F35: =IFERROR(SUMPRODUCT(--($K$5:$K$29=$B35),$D$5:$D$29,$H$5:$H$29),"") -> 6357
B36: Dog | C36: =COUNTIF($K$5:$K$29,$B36) -> 3 | D36: =IFERROR(SUMIF($K$5:$K$29,$B36,$D$5:$D$29),"") -> 350 | E36: =IFERROR(IF(SUM($D$5:$D$29)=0,"",$D36/SUM($D$5:$D$29)),"") -> 0.071868583 | F36: =IFERROR(SUMPRODUCT(--($K$5:$K$29=$B36),$D$5:$D$29,$H$5:$H$29),"") -> 2318

Sheet Miller
A1: Miller — popularity × food cost %
A2: AI Chef Pro · aichef.pro — Food Cost + Menu Engineering Guide
E3: Miller rewards low food cost; Kasavana & Smith rewards margin in dollars. They don't always agree.
A4: # | B4: Dish | C4: Category | D4: Units sold | E4: Menu Mix in Category (MM%) | F4: Popularity threshold in its category (%) | G4: Popularity | H4: Dish food cost (%) | I4: Category weighted avg food cost (%) | J4: Food cost level | K4: Classification | L4: What it means | M4: Recommended action
A5: 1 | B5: =IFERROR(IF('Data'!$B5="","",'Data'!$B5),"") -> Iberico ham croquettes (6 pcs) | C5: =IFERROR(IF('Data'!$C5="","",'Data'!$C5),"") -> Starters | D5: =IFERROR(IF('Data'!$D5="","",'Data'!$D5),"") -> 420 | E5: =IFERROR(IF('Data'!$L5="","",'Data'!$L5),"") -> 0.24277457 | F5: =IFERROR(IF('Data'!$M5="","",'Data'!$M5),"") -> 0.1 | G5: =IFERROR(IF(OR($E5="",$F5=""),"",IF($E5>=$F5,"High","Low")),"") -> High | H5: =IFERROR(IF('Data'!$H5="","",'Data'!$H5),"") -> 0.24418605 | I5: =IFERROR(IF('Data'!$O5="","",'Data'!$O5),"") -> 0.30714746 | J5: =IFERROR(IF(OR($H5="",$I5=""),"",IF($H5<=$I5,"Low","High")),"") -> Low | K5: =IFERROR(IF(OR($G5="",$J5=""),"",IF(AND($G5="High",$J5="Low"),"Winner",IF(AND($G5="Low",$J5="High"),"Loser","Marginal"))),"") -> Winner | L5: =IFERROR(IF($K5="","",IF($K5="Winner","Popular, with a food cost below its category's average.",IF($K5="Marginal","It meets only one of the two: either it sells, or its food cost is healthy.","Rarely ordered, with a food cost above its category."))),"") -> Popular, with a food cost below its category's average. | M5: =IFERROR(IF($K5="","",IF($K5="Winner","Keep it and protect its cost card: it's the one that can absorb a supplier increase.",IF($K5="Marginal","Check the other readings before touching it: the problem is either price or menu placement.","Rework the recipe or take it off the menu."))),"") -> Keep it and protect its cost card: it's the one that can absorb a supplier increase.
A6: 2 | B6: =IFERROR(IF('Data'!$B6="","",'Data'!$B6),"") -> Heirloom tomato salad with tuna belly and scallions | C6: =IFERROR(IF('Data'!$C6="","",'Data'!$C6),"") -> Starters | D6: =IFERROR(IF('Data'!$D6="","",'Data'!$D6),"") -> 310 | E6: =IFERROR(IF('Data'!$L6="","",'Data'!$L6),"") -> 0.17919075 | F6: =IFERROR(IF('Data'!$M6="","",'Data'!$M6),"") -> 0.1 | G6: =IFERROR(IF(OR($E6="",$F6=""),"",IF($E6>=$F6,"High","Low")),"") -> High | H6: =IFERROR(IF('Data'!$H6="","",'Data'!$H6),"") -> 0.30508475 | I6: =IFERROR(IF('Data'!$O6="","",'Data'!$O6),"") -> 0.30714746 | J6: =IFERROR(IF(OR($H6="",$I6=""),"",IF($H6<=$I6,"Low","High")),"") -> Low | K6: =IFERROR(IF(OR($G6="",$J6=""),"",IF(AND($G6="High",$J6="Low"),"Winner",IF(AND($G6="Low",$J6="High"),"Loser","Marginal"))),"") -> Winner | L6: =IFERROR(IF($K6="","",IF($K6="Winner","Popular, with a food cost below its category's average.",IF($K6="Marginal","It meets only one of the two: either it sells, or its food cost is healthy.","Rarely ordered, with a food cost above its category."))),"") -> Popular, with a food cost below its category's average. | M6: =IFERROR(IF($K6="","",IF($K6="Winner","Keep it and protect its cost card: it's the one that can absorb a supplier increase.",IF($K6="Marginal","Check the other readings before touching it: the problem is either price or menu placement.","Rework the recipe or take it off the menu."))),"") -> Keep it and protect its cost card: it's the one that can absorb a supplier increase.
A7: 3 | B7: =IFERROR(IF('Data'!$B7="","",'Data'!$B7),"") -> Garlic shrimp | C7: =IFERROR(IF('Data'!$C7="","",'Data'!$C7),"") -> Starters | D7: =IFERROR(IF('Data'!$D7="","",'Data'!$D7),"") -> 260 | E7: =IFERROR(IF('Data'!$L7="","",'Data'!$L7),"") -> 0.15028902 | F7: =IFERROR(IF('Data'!$M7="","",'Data'!$M7),"") -> 0.1 | G7: =IFERROR(IF(OR($E7="",$F7=""),"",IF($E7>=$F7,"High","Low")),"") -> High | H7: =IFERROR(IF('Data'!$H7="","",'Data'!$H7),"") -> 0.44516129 | I7: =IFERROR(IF('Data'!$O7="","",'Data'!$O7),"") -> 0.30714746 | J7: =IFERROR(IF(OR($H7="",$I7=""),"",IF($H7<=$I7,"Low","High")),"") -> High | K7: =IFERROR(IF(OR($G7="",$J7=""),"",IF(AND($G7="High",$J7="Low"),"Winner",IF(AND($G7="Low",$J7="High"),"Loser","Marginal"))),"") -> Marginal | L7: =IFERROR(IF($K7="","",IF($K7="Winner","Popular, with a food cost below its category's average.",IF($K7="Marginal","It meets only one of the two: either it sells, or its food cost is healthy.","Rarely ordered, with a food cost above its category."))),"") -> It meets only one of the two: either it sells, or its food cost is healthy. | M7: =IFERROR(IF($K7="","",IF($K7="Winner","Keep it and protect its cost card: it's the one that can absorb a supplier increase.",IF($K7="Marginal","Check the other readings before touching it: the problem is either price or menu placement.","Rework the recipe or take it off the menu."))),"") -> Check the other readings before touching it: the problem is either price or menu placement.
A8: 4 | B8: =IFERROR(IF('Data'!$B8="","",'Data'!$B8),"") -> Broken eggs with potatoes and chistorra sausage | C8: =IFERROR(IF('Data'!$C8="","",'Data'!$C8),"") -> Starters | D8: =IFERROR(IF('Data'!$D8="","",'Data'!$D8),"") -> 380 | E8: =IFERROR(IF('Data'!$L8="","",'Data'!$L8),"") -> 0.21965318 | F8: =IFERROR(IF('Data'!$M8="","",'Data'!$M8),"") -> 0.1 | G8: =IFERROR(IF(OR($E8="",$F8=""),"",IF($E8>=$F8,"High","Low")),"") -> High | H8: =IFERROR(IF('Data'!$H8="","",'Data'!$H8),"") -> 0.24489796 | I8: =IFERROR(IF('Data'!$O8="","",'Data'!$O8),"") -> 0.30714746 | J8: =IFERROR(IF(OR($H8="",$I8=""),"",IF($H8<=$I8,"Low","High")),"") -> Low | K8: =IFERROR(IF(OR($G8="",$J8=""),"",IF(AND($G8="High",$J8="Low"),"Winner",IF(AND($G8="Low",$J8="High"),"Loser","Marginal"))),"") -> Winner | L8: =IFERROR(IF($K8="","",IF($K8="Winner","Popular, with a food cost below its category's average.",IF($K8="Marginal","It meets only one of the two: either it sells, or its food cost is healthy.","Rarely ordered, with a food cost above its category."))),"") -> Popular, with a food cost below its category's average. | M8: =IFERROR(IF($K8="","",IF($K8="Winner","Keep it and protect its cost card: it's the one that can absorb a supplier increase.",IF($K8="Marginal","Check the other readings before touching it: the problem is either price or menu placement.","Rework the recipe or take it off the menu."))),"") -> Keep it and protect its cost card: it's the one that can absorb a supplier increase.
A9: 5 | B9: =IFERROR(IF('Data'!$B9="","",'Data'!$B9),"") -> Local cheese board | C9: =IFERROR(IF('Data'!$C9="","",'Data'!$C9),"") -> Starters | D9: =IFERROR(IF('Data'!$D9="","",'Data'!$D9),"") -> 90 | E9: =IFERROR(IF('Data'!$L9="","",'Data'!$L9),"") -> 0.052023121 | F9: =IFERROR(IF('Data'!$M9="","",'Data'!$M9),"") -> 0.1 | G9: =IFERROR(IF(OR($E9="",$F9=""),"",IF($E9>=$F9,"High","Low")),"") -> Low | H9: =IFERROR(IF('Data'!$H9="","",'Data'!$H9),"") -> 0.38235294 | I9: =IFERROR(IF('Data'!$O9="","",'Data'!$O9),"") -> 0.30714746 | J9: =IFERROR(IF(OR($H9="",$I9=""),"",IF($H9<=$I9,"Low","High")),"") -> High | K9: =IFERROR(IF(OR($G9="",$J9=""),"",IF(AND($G9="High",$J9="Low"),"Winner",IF(AND($G9="Low",$J9="High"),"Loser","Marginal"))),"") -> Loser | L9: =IFERROR(IF($K9="","",IF($K9="Winner","Popular, with a food cost below its category's average.",IF($K9="Marginal","It meets only one of the two: either it sells, or its food cost is healthy.","Rarely ordered, with a food cost above its category."))),"") -> Rarely ordered, with a food cost above its category. | M9: =IFERROR(IF($K9="","",IF($K9="Winner","Keep it and protect its cost card: it's the one that can absorb a supplier increase.",IF($K9="Marginal","Check the other readings before touching it: the problem is either price or menu placement.","Rework the recipe or take it off the menu."))),"") -> Rework the recipe or take it off the menu.
A10: 6 | B10: =IFERROR(IF('Data'!$B10="","",'Data'!$B10),"") -> Confit artichokes with ham | C10: =IFERROR(IF('Data'!$C10="","",'Data'!$C10),"") -> Starters | D10: =IFERROR(IF('Data'!$D10="","",'Data'!$D10),"") -> 120 | E10: =IFERROR(IF('Data'!$L10="","",'Data'!$L10),"") -> 0.069364162 | F10: =IFERROR(IF('Data'!$M10="","",'Data'!$M10),"") -> 0.1 | G10: =IFERROR(IF(OR($E10="",$F10=""),"",IF($E10>=$F10,"High","Low")),"") -> Low | H10: =IFERROR(IF('Data'!$H10="","",'Data'!$H10),"") -> 0.28440367 | I10: =IFERROR(IF('Data'!$O10="","",'Data'!$O10),"") -> 0.30714746 | J10: =IFERROR(IF(OR($H10="",$I10=""),"",IF($H10<=$I10,"Low","High")),"") -> Low | K10: =IFERROR(IF(OR($G10="",$J10=""),"",IF(AND($G10="High",$J10="Low"),"Winner",IF(AND($G10="Low",$J10="High"),"Loser","Marginal"))),"") -> Marginal | L10: =IFERROR(IF($K10="","",IF($K10="Winner","Popular, with a food cost below its category's average.",IF($K10="Marginal","It meets only one of the two: either it sells, or its food cost is healthy.","Rarely ordered, with a food cost above its category."))),"") -> It meets only one of the two: either it sells, or its food cost is healthy. | M10: =IFERROR(IF($K10="","",IF($K10="Winner","Keep it and protect its cost card: it's the one that can absorb a supplier increase.",IF($K10="Marginal","Check the other readings before touching it: the problem is either price or menu placement.","Rework the recipe or take it off the menu."))),"") -> Check the other readings before touching it: the problem is either price or menu placement.
A11: 7 | B11: =IFERROR(IF('Data'!$B11="","",'Data'!$B11),"") -> Roasted tomato soup with basil | C11: =IFERROR(IF('Data'!$C11="","",'Data'!$C11),"") -> Starters | D11: =IFERROR(IF('Data'!$D11="","",'Data'!$D11),"") -> 150 | E11: =IFERROR(IF('Data'!$L11="","",'Data'!$L11),"") -> 0.086705202 | F11: =IFERROR(IF('Data'!$M11="","",'Data'!$M11),"") -> 0.1 | G11: =IFERROR(IF(OR($E11="",$F11=""),"",IF($E11>=$F11,"High","Low")),"") -> Low | H11: =IFERROR(IF('Data'!$H11="","",'Data'!$H11),"") -> 0.16666667 | I11: =IFERROR(IF('Data'!$O11="","",'Data'!$O11),"") -> 0.30714746 | J11: =IFERROR(IF(OR($H11="",$I11=""),"",IF($H11<=$I11,"Low","High")),"") -> Low | K11: =IFERROR(IF(OR($G11="",$J11=""),"",IF(AND($G11="High",$J11="Low"),"Winner",IF(AND($G11="Low",$J11="High"),"Loser","Marginal"))),"") -> Marginal | L11: =IFERROR(IF($K11="","",IF($K11="Winner","Popular, with a food cost below its category's average.",IF($K11="Marginal","It meets only one of the two: either it sells, or its food cost is healthy.","Rarely ordered, with a food cost above its category."))),"") -> It meets only one of the two: either it sells, or its food cost is healthy. | M11: =IFERROR(IF($K11="","",IF($K11="Winner","Keep it and protect its cost card: it's the one that can absorb a supplier increase.",IF($K11="Marginal","Check the other readings before touching it: the problem is either price or menu placement.","Rework the recipe or take it off the menu."))),"") -> Check the other readings before touching it: the problem is either price or menu placement.
