Workbook

Sheet 0. Supuestos
A1: SUPUESTOS — aquí se teclean las TASAS y los DRIVERS del modelo
A2: Cambia las celdas VERDES: el resto del libro se recalcula solo. Las partidas de gasto se teclean en su hoja (también en verde) y no se repiten aquí.
A3: ACTIVIDAD
A4: Clientes/día (media del año 1) | B4: 143 | C4: Clientes servidos al día de media del año 1, en mostrador, para llevar y en mesa: unos 236 en julio y unos 70 en enero. Sale de dividir la venta prevista entre el ticket y los días de apertura; contrástalo con el paso de gente de tu calle en una tarde de verano y en una de febrero
A5: Ticket medio SIN IVA (€) | B5: 4.9 | C5: SIN IVA, por persona que compra: dos bolas, más las tarrinas de medio litro, las tartas por encargo y las crepes del invierno. Equivale a un tique de caja de unos 7 € sin IVA, porque cada tique es de 1,45 personas de media. El precio con IVA está en la fila «PVP equivalente con IVA» de abajo
A6: Días de apertura al año | B6: 310 | C6: 365 días menos tres semanas de cierre en enero (vacaciones y mantenimiento del frío), los lunes de octubre a marzo y algún festivo. Es el MISMO dato para la cuenta de resultados, el punto de equilibrio, los escenarios y las horas de personal
A7: Crecimiento de volumen del año 2 | B7: 0.08 | C7: Más clientela el segundo verano, las tartas heladas por encargo y el canal de restaurantes ya rodados. El libro lo aplica a los clientes y también al coste de personal
A8: Crecimiento de volumen del año 3 | B8: 0.05 | C8: Sobre el año 2. Conservador: el techo lo ponen la vitrina de 18 cubetas y las tardes de julio y agosto
A9: PVP equivalente con IVA (calculado) | B9: =IFERROR(IF($B$5="","",$B$5*(1+SUMPRODUCT('PyG 3 Años'!$E$10:$E$11,'PyG 3 Años'!$G$10:$G$11))),"") -> 5.39 | C9: =IFERROR("Ticket sin IVA más el IVA medio ponderado de tus líneas de venta: "&TEXT(SUMPRODUCT('PyG 3 Años'!$E$10:$E$11,'PyG 3 Años'!$G$10:$G$11)*100,"0")&" %. En el local todo va al 10 % (art. 91.Uno.2.2.º de la Ley 37/1992, alcohol incluido); sólo el alcohol que saliera por delivery movería la media. Aquí va redondeado. Compáralo con el rango del sector, que va con IVA.","") -> Ticket sin IVA más el IVA medio ponderado de tus líneas de venta: 10 %. En el local todo va al 10 % (art. 91.Uno.2.2.º de la Ley 37/1992, alcohol incluido); sólo el alcohol que saliera por delivery movería la media. Aquí va redondeado. Compáralo con el rango del sector, que va con IVA.
A10: MIX Y COSTE DE MERCANCÍA
A11: Ventas de COMIDA sobre el total | B11: 0.9 | C11: Peso de la COMIDA sobre el total de ventas. Es un INPUT: cámbialo aquí y el P&L, la tesorería y el IVA repercutido se recalculan solos
A12: Ventas de BEBIDA sobre el total | B12: =IFERROR(IF(COUNT(B11)=0,"",1-B11),"") -> 0.1 | C12: Se calcula como el resto: comida + bebida = 100 %
A13: Coste de mercancía sobre las ventas de COMIDA | B13: 0.2 | C13: Materia prima del helado y del obrador sobre sus ventas: el helado de mostrador sale al 16 %, el de llevar al 18 %, las crepes y los gofres al 28 % y lo que vendes a restaurantes al 32 % (18,6 % de media), y el plan suma 1,4 puntos por lo que se mueven el pistacho, el cacao y la vainilla. Escandalla cada sabor cada temporada
A14: Coste de mercancía sobre las ventas de BEBIDA | B14: 0.25 | C14: Café, chocolate a la taza, batidos, granizado y horchata propios, agua y refrescos sobre sus ventas: el granizado propio sale al 15 % y los refrescos, al 35-40 %
A15: Consumibles sobre ventas | B15: 0.04 | C15: Barquillos y cucuruchos, tarrinas, cucharillas de madera, envases isotérmicos de cartón para llevar y servilletas: unos 0,28 € por tique de caja. Sin poliestireno expandido para el consumo inmediato
A16: Ventas por delivery sobre el total | B16: 0.03 | C16: Tarrinas de medio litro y de litro en envase isotérmico por plataforma, las noches de verano: la tarrina viaja bien, la bola no. Es entrega de bienes: el helado va al 10 %
A17: Comisión de la plataforma de delivery | B17: 0.3 | C17: Comisión media de la plataforma sobre lo que vende ese canal. Si repartes tú, pon 0
A18: Comisión de los medios de pago | B18: 0.008 | C18: Tarjeta y bizum sobre el total facturado
A19: PERSONAL
A20: Seguridad Social a cargo de la empresa | B20: 0.33 | C20: Contingencias comunes + AT/EP + desempleo + FOGASA + FP; ajusta a tu convenio y bonificaciones
A21: Número de pagas anuales | B21: 14 | C21: Salario bruto anual = bruto mensual × pagas
A22: SMI anual de referencia (€) | B22: 17094 | C22: SMI 2026: 17.094 € al año (1.221 €/mes en 14 pagas), suelo legal por jornada completa. Comprueba el importe vigente si presentas el plan en otro ejercicio
A23: LOCAL Y FIJOS
A24: Alquiler mensual del local (€) | B24: 1700 | C24: Local de 85 m² (obrador de 20-25 m², tienda con vitrina de 18 cubetas y 20 plazas, almacén y aseo) en una calle comercial de barrio o un paseo de una ciudad media, sin traspaso: unos 20 € el m². El peso sobre las ventas lo calcula el propio libro en la fila «Alquiler / Ventas» del P&L
A25: Fianza del alquiler (meses) | B25: 3 | C25: Tres meses de renta, lo habitual en un contrato de local de negocio
A26: Suministros mensuales de luz, agua y gas (€) | B26: 700 | C26: Sobre todo luz: unos 30 kW en trifásica y las vitrinas encendidas las 24 horas (cada módulo de 10 cubetas gasta unos 23 kWh al día). Unos 800-850 € en verano y 450-500 € en invierno; pide el histórico del local
A27: Seguros (€/año) | B27: 1500 | C27: Responsabilidad civil de al menos 300.000 € y multirriesgo CON avería de maquinaria y deterioro de mercancía en frío: una vitrina parada en agosto es una cubeta perdida por sabor
A28: Varios e imprevistos sobre ventas | B28: 0.02 | C28: Colchón de gasto corriente no presupuestado (pequeñas reparaciones, catas y degustaciones)
A29: FINANCIACIÓN
A30: Recursos propios aportados (€) | B30: 55000 | C30: Aportación de los socios. Un banco pide entre el 25 y el 30 % de la necesidad de caja con dinero propio
A31: Préstamo bancario solicitado (€) | B31: 129000 | C31: Principal solicitado. La hoja de Financiación compara lo que aportas con la necesidad de caja de la hoja de inversión y te dice si sobra o falta: ajústalo con ese dato
A32: Tipo de interés nominal anual | B32: 0.06 | C32: Tipo nominal anual. Pide oferta a dos entidades y a una línea ICO antes de fijarlo; la maquinaria de frío es objeto habitual de leasing o renting: compáralo
A33: Plazo del préstamo (años) | B33: 7 | C33: Años totales, carencia incluida
A34: Carencia de principal (años) | B34: 1 | C34: El primer año sólo intereses: obra y maquinaria antes de facturar y un primer invierno por delante. Desde el segundo año se devuelve el principal: mira la holgura de caja de ese año en el Punto de Equilibrio
A35: Fondo de maniobra (meses de costes fijos) | B35: 3 | C35: Tres meses de costes fijos: son el colchón del primer invierno, cuando de noviembre a febrero entra alrededor del 15 % de la venta del año con los fijos planos
A36: FISCAL
A37: Impuesto de Sociedades, nueva creación | B37: 0.15 | C37: Art. 29.1 LIS: el PRIMER ejercicio con base imponible positiva y el SIGUIENTE. El libro lo aproxima contando los dos primeros ejercicios con base positiva: coincide con la ley salvo que entre ellos haya un ejercicio en pérdidas
A38: Impuesto de Sociedades, tipo general | B38: 0.25 | C38: A partir del tercer ejercicio con base positiva. Es el tipo general del art. 29.1 LIS: si tu cifra de negocios queda por debajo de 1 M € (microempresa) o de 10 M € (reducida dimensión), desde 2025 hay tipos más bajos que se implantan de forma gradual; confirma el de tu ejercicio con tu asesor y cámbialo aquí
A39: IVA repercutido de restauración | B39: 0.1 | C39: Tipo reducido de hostelería
A40: IVA repercutido/soportado general | B40: 0.21 | C40: Tipo general. En este libro lo usan dos cosas: el IVA que soportas al comprar el alcohol (el proveedor lo factura al 21 %) y el que repercutes por el alcohol que sale por delivery (es una entrega de bienes). El alcohol servido en el local va al reducido: su tipo está en el bloque de desglose del IVA. Suministros, equipamiento y servicios tienen su tipo en la celda de abajo. El libro manda al general sólo el alcohol: si compras refrescos, zumos y gaseosas con azúcares o edulcorantes añadidos, su factura también va al 21 % (art. 91.Uno.1.1.º de la Ley 37/1992)
...

Sheet Inversión Inicial
A1: PLAN DE NEGOCIO: HELADERÍA ARTESANAL
A2: Inversión inicial estimada — heladería artesanal con obrador propio
A3: Ajusta las cifras a tu proyecto.
A5: Concepto | B5: Importe | C5: % s/inversión | D5: Notas | E5: ¿Lleva IVA?
A6: INVERSIÓN | B6: =IFERROR(IF(COUNT(B7:B28)=0,"",SUM(B7:B28)),"") -> 125650 | C6: =IFERROR(B6/$B$31,"") -> 0.79387481
A7: Proyecto técnico y dirección de obra | B7: 2500 | C7: =IFERROR(B7/$B$31,"") -> 0.01579536 | D7: Proyecto del obrador y de la tienda, memoria de la actividad y certificado final | E7: Sí
A8: Obra y acondicionamiento del obrador y la tienda | B8: 18500 | C8: =IFERROR(B8/$B$31,"") -> 0.11688567 | D8: Obrador alicatado, suelo antideslizante, aseo y falsos techos. Estimación del kit (reforma de 15.000-50.000 € en las guías publicadas) | E8: Sí
A9: Instalación eléctrica trifásica, cuadro y boletín | B9: 5000 | C9: =IFERROR(B9/$B$31,"") -> 0.031590721 | D9: Unos 30 kW en trifásica para vitrinas, pasteurizador, mantecadora, abatidor y climatización. Pregunta la potencia disponible ANTES de firmar: una acometida nueva tarda | E9: Sí
A10: Fontanería, desagües, climatización y ventilación | B10: 4500 | C10: =IFERROR(B10/$B$31,"") -> 0.028431649 | D10: Desagües del obrador, lavamanos de accionamiento no manual y salida de aire para los condensadores de las máquinas | E10: Sí
A11: Rótulo y escaparate | B11: 2000 | C11: =IFERROR(B11/$B$31,"") -> 0.012636288 | D11: «Artesano» en el rótulo sólo con la calificación artesanal de tu comunidad; si no, «ELABORACIÓN PROPIA» | E11: Sí
A12: Pasteurizador de 30 litros | B12: 14600 | C12: =IFERROR(B12/$B$31,"") -> 0.092244905 | D12: Pasteurizador de 15/30 l por ciclo, 4 kW: 14.601,75 € sin IVA en la tarifa de un distribuidor (Diamond SPS/30A, octubre de 2026). Pasteuriza la mezcla a 85 °C y la enfría a 4 °C | E12: Sí
A13: Mantecadora horizontal de 6-12 litros por ciclo | B13: 14000 | C13: =IFERROR(B13/$B$31,"") -> 0.088454018 | D13: Las marcas profesionales no publican tarifa: estimación del kit. Una vertical de entrada de 26-30 l/h cuesta unos 4.200 € sin IVA, si empiezas con poco | E13: Sí
A14: Abatidor de temperatura para cubetas | B14: 5500 | C14: =IFERROR(B14/$B$31,"") -> 0.034749793 | D14: Lleva el helado recién mantecado a -18 °C en el corazón antes de pasarlo a la vitrina o al armario | E14: Sí
A15: Armarios de conservación y de maduración | B15: 5800 | C15: =IFERROR(B15/$B$31,"") -> 0.036645236 | D15: Dos armarios a -20/-25 °C para el helado y uno a +2/+4 °C para madurar la mezcla y guardar la materia prima | E15: Sí
A16: Mesas inox, fregadero, básculas, refractómetro, sondas, cubetas y carapinas | B16: 6500 | C16: =IFERROR(B16/$B$31,"") -> 0.041067937 | D16: Mesas y estanterías inox, fregadero, lavamanos, turbo, básculas, refractómetro, sondas de temperatura, 60 cubetas de 5 l (44 € cada una) y 10 carapinas | E16: Sí
A17: Vitrina ventilada de 18 cubetas | B17: 10500 | C17: =IFERROR(B17/$B$31,"") -> 0.066340514 | D17: Dos módulos ventilados de -20/-9 °C con gas R290 (unos 5.090 € cada uno en la tarifa del fabricante). Con 18 cubetas en verano y 10-12 en invierno basta en una ciudad media | E17: Sí
A18: Mostrador, lavaporcionador, cafetera, crepera, gofrera y chocolatera | B18: 6000 | C18: =IFERROR(B18/$B$31,"") -> 0.037908865 | D18: Mostrador de venta, lavaporcionador con agua corriente, cafetera y molino, y el equipo del invierno. La crepera y la gofrera dependen de la salida de humos que permita tu ordenanza | E18: Sí
... A25: Stock inicial de materias primas y envases | B25: 3000 | C25: =IFERROR(B25/$B$31,"") -> 0.018954432 | D25: Leche, nata, azúcares, pastas, fruta, barquillos, tarrinas y envases para llevar | E25: Sí
A26: Fianza del alquiler | B26: =IFERROR(IF('0. Supuestos'!$B$24="","",'0. Supuestos'!$B$24*'0. Supuestos'!$B$25),"") -> 5100 | C26: =IFERROR(B26/$B$31,"") -> 0.032222535 | D26: =IFERROR(""&TEXT('0. Supuestos'!$B$25,"0")&" meses de renta, al tipo de la hoja de Supuestos. Es un activo recuperable al cerrar: ni se amortiza ni lleva IVA","") -> 3 meses de renta, al tipo de la hoja de Supuestos. Es un activo recuperable al cerrar: ni se amortiza ni lleva IVA | E26: No
A27: Alquiler de los meses previos a la apertura | B27: =IFERROR(IF('0. Supuestos'!$B$24="","",'0. Supuestos'!$B$24*'0. Supuestos'!$B$54),"") -> 3400 | C27: =IFERROR(B27/$B$31,"") -> 0.02148169 | D27: =IFERROR("Renta "&IF('0. Supuestos'!$B$54=1,"del mes","de los "&TEXT('0. Supuestos'!$B$54,"0")&" meses")&" de obra y licencias. NO se solapa con el P&L, que arranca el día de la apertura: los doce meses del P&L son los doce de explotación","") -> Renta de los 2 meses de obra y licencias. NO se solapa con el P&L, que arranca el día de la apertura: los doce meses del P&L son los doce de explotación | E27: Sí
A28: Imprevistos de obra y acondicionamiento | B28: =IFERROR(IF(COUNT(B7,B8,B9,B10,B11)=0,"",ROUND((B7+B8+B9+B10+B11)*'0. Supuestos'!$B$55,0)),"") -> 3250 | C28: =IFERROR(B28/$B$31,"") -> 0.020533968 | D28: =IFERROR("Al "&TEXT('0. Supuestos'!$B$55,"0%")&" de las partidas de OBRA Y ACONDICIONAMIENTO de este bloque (Proyecto técnico y dirección de obra, Obra y acondicionamiento del obrador y la tienda, Instalación eléctrica trifásica, cuadro y boletín, Fontanería, desagües, climatización y ventilación y Rótulo y escaparate), no del bloque entero: el resto de partidas del bloque quedan fuera. Un banco no financia una reforma sin colchón: el porcentaje está en la hoja de Supuestos","") -> Al 10% de las partidas de OBRA Y ACONDICIONAMIENTO de este bloque (Proyecto técnico y dirección de obra, Obra y acondicionamiento del obrador y la tienda, Instalación eléctrica trifásica, cuadro y boletín, Fontanería, desagües, climatización y ventilación y Rótulo y escaparate), no del bloque entero: el resto de partidas del bloque quedan fuera. Un banco no financia una reforma sin colchón: el porcentaje está en la hoja de Supuestos | E28: Sí
A29: FONDO DE MANIOBRA | B29: =IFERROR(IF(B30="","",B30),"") -> 32624.325 | C29: =IFERROR(B29/$B$31,"") -> 0.20612519
A30: Colchón operativo hasta alcanzar el equilibrio | B30: =IFERROR(IF('0. Supuestos'!$B$35*('PyG 3 Años'!$B$38-'PyG 3 Años'!$B$36)=0,"",'0. Supuestos'!$B$35*('PyG 3 Años'!$B$38-'PyG 3 Años'!$B$36)/12),"") -> 32624.325 | C30: =IFERROR(B30/$B$31,"") -> 0.20612519 | D30: =IFERROR("Cubre "&TEXT('0. Supuestos'!$B$35,"0")&IF('0. Supuestos'!$B$35=1," mes"," meses")&" de costes fijos DE CAJA del año 1 (los del P&L menos la amortización, que no se paga), que es el mínimo que exigen las Instrucciones de este libro","") -> Cubre 3 meses de costes fijos DE CAJA del año 1 (los del P&L menos la amortización, que no se paga), que es el mínimo que exigen las Instrucciones de este libro | E30: No
A31: INVERSIÓN TOTAL (suma de los bloques) | B31: =IFERROR(B6+B29,"") -> 158274.33 | D31: =IFERROR("Los porcentajes de la columna C se leen sobre esta cifra, que incluye el fondo de maniobra ("&TEXT(C29,"0%")&" del total). Para comparar el desglose con otro plan, usa la fila de CAPEX de abajo.","") -> Los porcentajes de la columna C se leen sobre esta cifra, que incluye el fondo de maniobra (21% del total). Para comparar el desglose con otro plan, usa la fila de CAPEX de abajo.
A32: CAPEX (inversión sin el fondo de maniobra) | B32: =IFERROR(B31-B29,"") -> 125650 | D32: Es lo que se compra: obra, equipamiento, lanzamiento y gastos de constitución. El colchón de caja no es inversión, es circulante
A33: IVA soportado sobre la inversión (recuperable) | B33: =IFERROR(IF(B31="","",SUMIF($E$7:$E$28,"Sí",$B$7:$B$28)*'0. Supuestos'!$B$41),"") -> 24895.5 | D33: =IFERROR("Al "&TEXT('0. Supuestos'!$B$41,"0%")&" sobre las partidas marcadas con «Sí» en la columna de IVA. Las tasas y licencias no están sujetas y los seguros están exentos (art. 20.Uno.16 LIVA). Las tasas y aranceles registrales no llevan IVA; los honorarios de notaría y gestoría sí (21 %, deducible). Se recupera con el modelo 303, pero hay que adelantarlo","") -> Al 21% sobre las partidas marcadas con «Sí» en la columna de IVA. Las tasas y licencias no están sujetas y los seguros están exentos (art. 20.Uno.16 LIVA). Las tasas y aranceles registrales no llevan IVA; los honorarios de notaría y gestoría sí (21 %, deducible). Se recupera con el modelo 303, pero hay que adelantarlo
A34: NECESIDAD TOTAL DE CAJA AL ARRANQUE | B34: =IFERROR(B31+B33,"") -> 183169.83 | D34: Es la cifra que tiene que cubrir la hoja de Financiación
A35: BASES DE AMORTIZACIÓN (no suman a la inversión)
A36: Obra, instalaciones y acondicionamiento | B36: =IFERROR(IF(B7="","",B7+B8+B9+B10+B11+B28),"") -> 35750 | D36: =IFERROR("Se amortiza en "&TEXT('0. Supuestos'!$B$44,"0")&" años","") -> Se amortiza en 10 años
A37: Maquinaria, mobiliario y equipos | B37: =IFERROR(IF(B12="","",B12+B13+B14+B15+B16+B17+B18+B19+B20+B21),"") -> 70900 | D37: =IFERROR("Se amortiza en "&TEXT('0. Supuestos'!$B$45,"0")&" años","") -> Se amortiza en 10 años
A38: Amortización anual del inmovilizado | B38: =IFERROR(B36/MAX(1,'0. Supuestos'!$B$44)+B37/MAX(1,'0. Supuestos'!$B$45),"") -> 10665 | D38: =IFERROR("No se amortizan, por no ser inmovilizado, Formación técnica de heladería, Marca, web, fotos y lanzamiento, Constitución de la SL, licencia, tasas, registro sanitario y APPCC, Stock inicial de materias primas y envases, Fianza del alquiler, Alquiler de los meses previos a la apertura ni Colchón operativo hasta alcanzar el equilibrio. Suman "&TEXT(B31-B36-B37,"0")&" € de los "&TEXT(B31,"0")&" € de inversión.","") -> No se amortizan, por no ser inmovilizado, Formación técnica de heladería, Marca, web, fotos y lanzamiento, Constitución de la SL, licencia, tasas, registro sanitario y APPCC, Stock inicial de materias primas y envases, Fianza del alquiler, Alquiler de los meses previos a la apertura ni Colchón operativo hasta alcanzar el equilibrio. Suman 51624 € de los 158274 € de inversión.

Sheet PyG 3 Años
A1: CUENTA DE RESULTADOS — 3 AÑOS
A2: Escenario realista — heladería artesanal
A4: Concepto | B4: Año 1 | C4: Año 2 | D4: Año 3 | E4: % s/ventas (año 1) | F4: Notas | G4: Tipo de IVA de la línea (%)
A5: INGRESOS
A6: Clientes/día (media) | B6: =IFERROR(IF('0. Supuestos'!$B$4="","",'0. Supuestos'!$B$4),"") -> 143 | C6: =IFERROR(B6*(1+'0. Supuestos'!$B$7),"") -> 154.44 | D6: =IFERROR(C6*(1+'0. Supuestos'!$B$8),"") -> 162.162 | F6: El crecimiento de los años 2 y 3 está en la hoja de Supuestos
A7: Ticket medio sin IVA | B7: =IFERROR(IF('0. Supuestos'!$B$5="","",'0. Supuestos'!$B$5),"") -> 4.9 | C7: =IFERROR(IF(B7="","",B7),"") -> 4.9 | D7: =IFERROR(IF(C7="","",C7),"") -> 4.9 | F7: Constante en euros del año 1: una subida de precios es una decisión aparte
A8: Días de apertura al año | B8: =IFERROR(IF('0. Supuestos'!$B$6="","",'0. Supuestos'!$B$6),"") -> 310 | C8: =IFERROR(IF(B8="","",B8),"") -> 310 | D8: =IFERROR(IF(C8="","",C8),"") -> 310
A9: INGRESOS TOTALES (sin IVA) | B9: =IFERROR(IF(B6*B7*B8=0,"",B6*B7*B8),"") -> 217217 | C9: =IFERROR(IF(C6*C7*C8=0,"",C6*C7*C8),"") -> 234594.36 | D9: =IFERROR(IF(D6*D7*D8=0,"",D6*D7*D8),"") -> 246324.08 | E9: =IFERROR(IF(B9="","",1),"") -> 1
A10: Ventas de helado y obrador (mostrador, para llevar, tartas, invierno y restaurantes) | B10: =IFERROR(IF(B9="","",B9*$E$10),"") -> 195495.3 | C10: =IFERROR(IF(C9="","",C9*$E$10),"") -> 211134.92 | D10: =IFERROR(IF(D9="","",D9*$E$10),"") -> 221691.67 | E10: =IFERROR(IF('0. Supuestos'!$B$11="","",'0. Supuestos'!$B$11),"") -> 0.9 | F10: Del total de ventas: helado de mostrador (bola, copa y cucurucho) 58 %, para llevar y tartas heladas 17 %, invierno (crepes y gofres, tartas y turrón helado de Navidad por encargo) 10 % y restaurantes y eventos 5 %. Todo al 10 % de IVA, se tome en el local o se lleve | G10: =IFERROR(IF(B9="","",'0. Supuestos'!$B$39),"") -> 0.1
A11: Ventas de cafetería y bebidas (sin alcohol) | B11: =IFERROR(IF(B9="","",B9*$E$11),"") -> 21721.7 | C11: =IFERROR(IF(C9="","",C9*$E$11),"") -> 23459.436 | D11: =IFERROR(IF(D9="","",D9*$E$11),"") -> 24632.408 | E11: =IFERROR(IF('0. Supuestos'!$B$12="","",'0. Supuestos'!$B$12),"") -> 0.1 | F11: Café, chocolate a la taza, batidos, granizados, horchata, agua y refrescos | G11: =IFERROR(IF(B9="","",('0. Supuestos'!$B$62*((1-'0. Supuestos'!$B$16)*'0. Supuestos'!$B$63+'0. Supuestos'!$B$16*'0. Supuestos'!$B$40)+(1-'0. Supuestos'!$B$62)*'0. Supuestos'!$B$39)),"") -> 0.1
A12: COSTES VARIABLES
A13: Coste de mercancía — comida | B13: =IFERROR(IF(B9="","",B9*'0. Supuestos'!$B$11*'0. Supuestos'!$B$13),"") -> 39099.06 | C13: =IFERROR(IF(C9="","",C9*'0. Supuestos'!$B$11*'0. Supuestos'!$B$13),"") -> 42226.985 | D13: =IFERROR(IF(D9="","",D9*'0. Supuestos'!$B$11*'0. Supuestos'!$B$13),"") -> 44338.334 | E13: =IFERROR(B13/$B$9,"") -> 0.18 | F13: =IFERROR("Al "&TEXT('0. Supuestos'!$B$13,"0%")&" de las ventas de COMIDA, no del total: la bebida tiene su propia línea · El IVA que SOPORTAS al comprar: la leche, los huevos, la fruta y los quesos van al 4 % (art. 91.Dos.1.1.º de la Ley 37/1992) y la nata, el azúcar, el chocolate, las pastas y los barquillos al 10 %; con un 30 % de la compra al 4 % sale un 8,2 %. Ajústalo a tus facturas","") -> Al 20% de las ventas de COMIDA, no del total: la bebida tiene su propia línea · El IVA que SOPORTAS al comprar: la leche, los huevos, la fruta y los quesos van al 4 % (art. 91.Dos.1.1.º de la Ley 37/1992) y la nata, el azúcar, el chocolate, las pastas y los barquillos al 10 %; con un 30 % de la compra al 4 % sale un 8,2 %. Ajústalo a tus facturas | G13: 0.082
A14: Coste de mercancía — bebida | B14: =IFERROR(IF(B9="","",B9*'0. Supuestos'!$B$12*'0. Supuestos'!$B$14),"") -> 5430.425 | C14: =IFERROR(IF(C9="","",C9*'0. Supuestos'!$B$12*'0. Supuestos'!$B$14),"") -> 5864.859 | D14: =IFERROR(IF(D9="","",D9*'0. Supuestos'!$B$12*'0. Supuestos'!$B$14),"") -> 6158.1019 | E14: =IFERROR(B14/$B$9,"") -> 0.025 | F14: =IFERROR("Al "&TEXT('0. Supuestos'!$B$14,"0%")&" de las ventas de BEBIDA","") -> Al 25% de las ventas de BEBIDA | G14: =IFERROR(IF(B9="","",('0. Supuestos'!$B$62*'0. Supuestos'!$B$40+(1-'0. Supuestos'!$B$62)*'0. Supuestos'!$B$39)),"") -> 0.1
A15: Consumibles y envases | B15: =IFERROR(IF(B9="","",B9*'0. Supuestos'!$B$15),"") -> 8688.68 | C15: =IFERROR(IF(C9="","",C9*'0. Supuestos'!$B$15),"") -> 9383.7744 | D15: =IFERROR(IF(D9="","",D9*'0. Supuestos'!$B$15),"") -> 9852.9631 | E15: =IFERROR(B15/$B$9,"") -> 0.04 | G15: =IFERROR(IF(B9="","",'0. Supuestos'!$B$41),"") -> 0.21
A16: Comisiones de delivery | B16: =IFERROR(IF(B9="","",B9*'0. Supuestos'!$B$16*'0. Supuestos'!$B$17),"") -> 1954.953 | C16: =IFERROR(IF(C9="","",C9*'0. Supuestos'!$B$16*'0. Supuestos'!$B$17),"") -> 2111.3492 | D16: =IFERROR(IF(D9="","",D9*'0. Supuestos'!$B$16*'0. Supuestos'!$B$17),"") -> 2216.9167 | E16: =IFERROR(B16/$B$9,"") -> 0.009 | F16: Sobre las ventas DEL CANAL. Con 0 % de delivery en Supuestos, esta línea vale cero | G16: =IFERROR(IF(B9="","",'0. Supuestos'!$B$41),"") -> 0.21
A17: Comisiones de los medios de pago | B17: =IFERROR(IF(B9="","",B9*'0. Supuestos'!$B$18),"") -> 1737.736 | C17: =IFERROR(IF(C9="","",C9*'0. Supuestos'!$B$18),"") -> 1876.7549 | D17: =IFERROR(IF(D9="","",D9*'0. Supuestos'!$B$18),"") -> 1970.5926 | E17: =IFERROR(B17/$B$9,"") -> 0.008 | F17: Las comisiones de los medios de pago están EXENTAS de IVA (art. 20.Uno.18 LIVA): no se deduce nada por ellas | G17: 0
A18: Varios e imprevistos | B18: =IFERROR(IF(B9="","",B9*'0. Supuestos'!$B$28),"") -> 4344.34 | C18: =IFERROR(IF(C9="","",C9*'0. Supuestos'!$B$28),"") -> 4691.8872 | D18: =IFERROR(IF(D9="","",D9*'0. Supuestos'!$B$28),"") -> 4926.4816 | E18: =IFERROR(B18/$B$9,"") -> 0.02 | F18: =IFERROR("Al "&TEXT('0. Supuestos'!$B$28,"0%")&" de las ventas. Es un coste VARIABLE: sube y baja con la facturación, así que no puede vivir en los costes fijos","") -> Al 2% de las ventas. Es un coste VARIABLE: sube y baja con la facturación, así que no puede vivir en los costes fijos | G18: =IFERROR(IF(B9="","",'0. Supuestos'!$B$41),"") -> 0.21
A19: TOTAL COSTES VARIABLES | B19: =IFERROR(IF(B9="","",SUM(B13:B18)),"") -> 61255.194 | C19: =IFERROR(IF(C9="","",SUM(C13:C18)),"") -> 66155.61 | D19: =IFERROR(IF(D9="","",SUM(D13:D18)),"") -> 69463.39 | E19: =IFERROR(B19/$B$9,"") -> 0.282
A20: MARGEN BRUTO | B20: =IFERROR(IF(B9="","",B9-B19),"") -> 155961.81 | C20: =IFERROR(IF(C9="","",C9-C19),"") -> 168438.75 | D20: =IFERROR(IF(D9="","",D9-D19),"") -> 176860.69 | E20: =IFERROR(B20/$B$9,"") -> 0.718
A21: COSTES FIJOS
A22: Alquiler del local | B22: =IFERROR(IF(B9="","",'0. Supuestos'!$B$24*12),"") -> 20400 | C22: =IFERROR(IF(C9="","",B22*(1+'0. Supuestos'!$B$48)),"") -> 20400 | D22: =IFERROR(IF(D9="","",C22*(1+'0. Supuestos'!$B$48)),"") -> 20400 | E22: =IFERROR(B22/$B$9,"") -> 0.093915301 | F22: El importe mensual está en la hoja de Supuestos; aquí se multiplica por doce. Los dos meses de renta previos a la apertura están en la hoja de Inversión y NO se cuentan dos veces | G22: =IFERROR(IF(B9="","",'0. Supuestos'!$B$41),"") -> 0.21
A23: Personal (nóminas + Seguridad Social) | B23: =IFERROR(IF(B9="","",'Personal'!$G$11),"") -> 82207.3 | C23: =IFERROR(IF(C9="","",'Personal'!$B$15),"") -> 88207.3 | D23: =IFERROR(IF(D9="","",'Personal'!$B$16),"") -> 94207.3 | E23: =IFERROR(B23/$B$9,"") -> 0.37845703 | F23: Sale de la hoja de Personal: es el MISMO número, no una estimación aparte. Los años 2 y 3 suman las INCORPORACIONES declaradas en esa hoja, no un porcentaje de volumen | G23: 0
A24: Suministros (luz, agua, gas) | B24: =IFERROR(IF(B9="","",'0. Supuestos'!$B$26*12),"") -> 8400 | C24: =IFERROR(IF(C9="","",B24*(1+'0. Supuestos'!$B$48)),"") -> 8400 | D24: =IFERROR(IF(D9="","",C24*(1+'0. Supuestos'!$B$48)),"") -> 8400 | E24: =IFERROR(B24/$B$9,"") -> 0.038671006 | F24: Luz y gas van al 21 %; la factura del agua, al 10 %. El libro aplica a toda esta partida el tipo de la columna de al lado (21 %): si el agua pesa mucho en tu local, sepárala en su línea | G24: =IFERROR(IF(B9="","",'0. Supuestos'!$B$41),"") -> 0.21
A25: Seguros (RC + multirriesgo) | B25: =IFERROR(IF(B9="","",'0. Supuestos'!$B$27),"") -> 1500 | C25: =IFERROR(IF(C9="","",B25*(1+'0. Supuestos'!$B$48)),"") -> 1500 | D25: =IFERROR(IF(D9="","",C25*(1+'0. Supuestos'!$B$48)),"") -> 1500 | E25: =IFERROR(B25/$B$9,"") -> 0.0069055369 | F25: Las operaciones de seguro están EXENTAS de IVA (art. 20.Uno.16 LIVA): la prima no lleva IVA deducible | G25: 0
A26: Gestoría laboral, fiscal y contable | B26: 1800 | C26: =IFERROR(IF(C9="","",B26*(1+'0. Supuestos'!$B$48)),"") -> 1800 | D26: =IFERROR(IF(D9="","",C26*(1+'0. Supuestos'!$B$48)),"") -> 1800 | E26: =IFERROR(B26/$B$9,"") -> 0.0082866442 | F26: Contabilidad, impuestos de la SL y nóminas de los fijos discontinuos, con sus llamamientos de cada temporada | G26: =IFERROR(IF(B9="","",'0. Supuestos'!$B$41),"") -> 0.21
A27: Mantenimiento del frío (contrato con frigorista certificado) | B27: 1500 | C27: =IFERROR(IF(C9="","",B27*(1+'0. Supuestos'!$B$48)),"") -> 1500 | D27: =IFERROR(IF(D9="","",C27*(1+'0. Supuestos'!$B$48)),"") -> 1500 | E27: =IFERROR(B27/$B$9,"") -> 0.0069055369 | F27: Revisión de vitrinas, abatidor, mantecadora y armarios antes del verano y en las semanas de cierre de enero. La carga de gases refrigerantes la hace sólo un técnico certificado: el personal no la toca | G27: =IFERROR(IF(B9="","",'0. Supuestos'!$B$41),"") -> 0.21
A28: Marketing y publicidad de temporada | B28: 2500 | C28: =IFERROR(IF(C9="","",B28*(1+'0. Supuestos'!$B$48)),"") -> 2500 | D28: =IFERROR(IF(D9="","",C28*(1+'0. Supuestos'!$B$48)),"") -> 2500 | E28: =IFERROR(B28/$B$9,"") -> 0.011509228 | F28: Redes sociales, ficha de Google Business, cartelería y la campaña de apertura de cada temporada, más la de tartas y turrón helado de Navidad | G28: =IFERROR(IF(B9="","",'0. Supuestos'!$B$41),"") -> 0.21
A29: Software, teléfono e internet | B29: 700 | C29: =IFERROR(IF(C9="","",B29*(1+'0. Supuestos'!$B$48)),"") -> 700 | D29: =IFERROR(IF(D9="","",C29*(1+'0. Supuestos'!$B$48)),"") -> 700 | E29: =IFERROR(B29/$B$9,"") -> 0.0032225839 | F29: Cuota del TPV con Veri*factu, teléfono e internet | G29: =IFERROR(IF(B9="","",'0. Supuestos'!$B$41),"") -> 0.21
A30: Limpieza, lavandería, EPI y análisis de autocontrol | B30: 800 | C30: =IFERROR(IF(C9="","",B30*(1+'0. Supuestos'!$B$48)),"") -> 800 | D30: =IFERROR(IF(D9="","",C30*(1+'0. Supuestos'!$B$48)),"") -> 800 | E30: =IFERROR(B30/$B$9,"") -> 0.003682953 | F30: Productos de limpieza y desinfección, lavado de uniformes, guantes para trabajar a −20 °C y los análisis de autocontrol que fije tu APPCC | G30: =IFERROR(IF(B9="","",'0. Supuestos'!$B$41),"") -> 0.21
A31: Tasa de terraza (pon la de tu ayuntamiento) | B31: 1200 | C31: =IFERROR(IF(C9="","",B31*(1+'0. Supuestos'!$B$48)),"") -> 1200 | D31: =IFERROR(IF(D9="","",C31*(1+'0. Supuestos'!$B$48)),"") -> 1200 | E31: =IFERROR(B31/$B$9,"") -> 0.0055244295 | F31: Ocupación de la vía pública con 5 mesas en temporada. Cada ayuntamiento tiene su ordenanza fiscal y este plan no ha leído ninguna: sustituye esta cifra por la de tu ayuntamiento | G31: =IFERROR(IF(B9="","",'0. Supuestos'!$B$41),"") -> 0.21
A32: Gestión de residuos | B32: 350 | C32: =IFERROR(IF(C9="","",B32*(1+'0. Supuestos'!$B$48)),"") -> 350 | D32: =IFERROR(IF(D9="","",C32*(1+'0. Supuestos'!$B$48)),"") -> 350 | E32: =IFERROR(B32/$B$9,"") -> 0.0016112919 | F32: Cartón, envases y orgánico del obrador con gestor autorizado o por el servicio municipal | G32: =IFERROR(IF(B9="","",'0. Supuestos'!$B$41),"") -> 0.21
A33: Desinsectación, desratización y desinfección (DDD) | B33: 450 | C33: =IFERROR(IF(C9="","",B33*(1+'0. Supuestos'!$B$48)),"") -> 450 | D33: =IFERROR(IF(D9="","",C33*(1+'0. Supuestos'!$B$48)),"") -> 450 | E33: =IFERROR(B33/$B$9,"") -> 0.0020716611 | F33: Empresa inscrita en el ROESB; forma parte del plan APPCC | G33: =IFERROR(IF(B9="","",'0. Supuestos'!$B$41),"") -> 0.21
A34: Derechos de autor por música ambiental (SGAE y AGEDI-AIE) | B34: 500 | C34: =IFERROR(IF(C9="","",B34*(1+'0. Supuestos'!$B$48)),"") -> 500 | D34: =IFERROR(IF(D9="","",C34*(1+'0. Supuestos'!$B$48)),"") -> 500 | E34: =IFERROR(B34/$B$9,"") -> 0.0023018456 | F34: SGAE y AGEDI-AIE son dos licencias distintas; el importe depende de los metros y del aforo de tu tienda | G34: =IFERROR(IF(B9="","",'0. Supuestos'!$B$41),"") -> 0.21
A35: Prevención de riesgos laborales y vigilancia de la salud | B35: 450 | C35: =IFERROR(IF(C9="","",B35*(1+'0. Supuestos'!$B$48)),"") -> 450 | D35: =IFERROR(IF(D9="","",C35*(1+'0. Supuestos'!$B$48)),"") -> 450 | E35: =IFERROR(B35/$B$9,"") -> 0.0020716611 | F35: El plan de prevención es obligatorio (Ley 31/1995): trabajo en frío, cargas y cortes, y reconocimientos médicos de la plantilla | G35: =IFERROR(IF(B9="","",'0. Supuestos'!$B$41),"") -> 0.21
A36: Amortización del inmovilizado | B36: =IFERROR(IF(B9="","",'Inversión Inicial'!$B$38),"") -> 10665 | C36: =IFERROR(IF(C9="","",B36),"") -> 10665 | D36: =IFERROR(IF(D9="","",B36),"") -> 10665 | E36: =IFERROR(B36/$B$9,"") -> 0.049098367 | F36: Sale de las bases de amortización de la hoja de Inversión: sólo inmovilizado real. NO sube con el IPC: es una cuota sobre el coste HISTÓRICO del inmovilizado | G36: 0
A37: Gastos financieros (intereses del préstamo) | B37: =IFERROR(IF(B9="","",'Financiación'!$B$44),"") -> 7740 | C37: =IFERROR(IF(C9="","",'Financiación'!$B$46),"") -> 7740 | D37: =IFERROR(IF(D9="","",'Financiación'!$B$48),"") -> 6630.3733 | E37: =IFERROR(B37/$B$9,"") -> 0.03563257 | F37: Sólo los INTERESES son gasto. La devolución del principal va en la hoja de Tesorería | G37: 0
A38: TOTAL COSTES FIJOS | B38: =IFERROR(IF(B9="","",SUM(B22:B37)),"") -> 141162.3 | C38: =IFERROR(IF(C9="","",SUM(C22:C37)),"") -> 147162.3 | D38: =IFERROR(IF(D9="","",SUM(D22:D37)),"") -> 152052.67 | E38: =IFERROR(B38/$B$9,"") -> 0.64986764
A39: IVA soportado de los costes variables | B39: =IFERROR(IF(B9="","",SUMPRODUCT(B13:B18,G13:G18)),"") -> 6896.6398 | C39: =IFERROR(IF(C9="","",SUMPRODUCT(C13:C18,G13:G18)),"") -> 7448.3709 | D39: =IFERROR(IF(D9="","",SUMPRODUCT(D13:D18,G13:G18)),"") -> 7820.7895 | F39: Cada línea a SU tipo, leído de la columna de al lado. Es lo que la hoja de Tesorería paga de más a los proveedores y luego se deduce
A40: IVA soportado de los costes fijos | B40: =IFERROR(IF(B9="","",SUMPRODUCT(B22:B37,G22:G37)),"") -> 8200.5 | C40: =IFERROR(IF(C9="","",SUMPRODUCT(C22:C37,G22:G37)),"") -> 8200.5 | D40: =IFERROR(IF(D9="","",SUMPRODUCT(D22:D37,G22:G37)),"") -> 8200.5
A41: RESULTADO ANTES DE IMPUESTOS | B41: =IFERROR(IF(B9="","",B20-B38),"") -> 14799.506 | C41: =IFERROR(IF(C9="","",C20-C38),"") -> 21276.45 | D41: =IFERROR(IF(D9="","",D20-D38),"") -> 24808.015 | E41: =IFERROR(B41/$B$9,"") -> 0.068132356
...

Sheet Punto Equilibrio
A1: PUNTO DE EQUILIBRIO
A2: Punto de equilibrio — heladería artesanal
A4: Variable | B4: Año 1 | C4: Año 2 | D4: Año 3 | E4: Notas
A5: DATOS BASE POR AÑO
A6: Costes fijos anuales | B6: =IFERROR(IF('PyG 3 Años'!$B$9="","",'PyG 3 Años'!$B$38),"") -> 141162.3 | C6: =IFERROR(IF('PyG 3 Años'!$C$9="","",'PyG 3 Años'!$C$38),"") -> 147162.3 | D6: =IFERROR(IF('PyG 3 Años'!$D$9="","",'PyG 3 Años'!$D$38),"") -> 152052.67 | E6: Los MISMOS costes fijos del P&L. Cada año tiene los suyos: por eso el umbral no puede ser uno solo para los tres
A7: Costes fijos mensuales | B7: =IFERROR(IF('PyG 3 Años'!$B$9="","",B6/12),"") -> 11763.525 | C7: =IFERROR(IF('PyG 3 Años'!$C$9="","",C6/12),"") -> 12263.525 | D7: =IFERROR(IF('PyG 3 Años'!$D$9="","",D6/12),"") -> 12671.056
A8: Ticket medio sin IVA | B8: =IFERROR(IF('PyG 3 Años'!$B$9="","",'PyG 3 Años'!$B$7),"") -> 4.9 | C8: =IFERROR(IF('PyG 3 Años'!$C$9="","",'PyG 3 Años'!$C$7),"") -> 4.9 | D8: =IFERROR(IF('PyG 3 Años'!$D$9="","",'PyG 3 Años'!$D$7),"") -> 4.9
A9: Coste variable por cliente | B9: =IFERROR(IF('PyG 3 Años'!$B$9="","",'PyG 3 Años'!$B$19/('PyG 3 Años'!$B$6*'PyG 3 Años'!$B$8)),"") -> 1.3818 | C9: =IFERROR(IF('PyG 3 Años'!$C$9="","",'PyG 3 Años'!$C$19/('PyG 3 Años'!$C$6*'PyG 3 Años'!$C$8)),"") -> 1.3818 | D9: =IFERROR(IF('PyG 3 Años'!$D$9="","",'PyG 3 Años'!$D$19/('PyG 3 Años'!$D$6*'PyG 3 Años'!$D$8)),"") -> 1.3818 | E9: Sale del total de costes variables del P&L, no de una estimación aparte. Incluye los varios e imprevistos, que son un porcentaje de las ventas
A10: Margen de contribución por cliente | B10: =IFERROR(IF('PyG 3 Años'!$B$9="","",B8-B9),"") -> 3.5182 | C10: =IFERROR(IF('PyG 3 Años'!$C$9="","",C8-C9),"") -> 3.5182 | D10: =IFERROR(IF('PyG 3 Años'!$D$9="","",D8-D9),"") -> 3.5182 | E10: Ticket menos coste variable unitario
A11: Días de apertura al año | B11: =IFERROR(IF('PyG 3 Años'!$B$9="","",'PyG 3 Años'!$B$8),"") -> 310 | C11: =IFERROR(IF('PyG 3 Años'!$C$9="","",'PyG 3 Años'!$C$8),"") -> 310 | D11: =IFERROR(IF('PyG 3 Años'!$D$9="","",'PyG 3 Años'!$D$8),"") -> 310 | E11: El mismo calendario que el P&L y que los escenarios
A12: Devolución de principal del año (cuota) | B12: =IFERROR(IF('PyG 3 Años'!$B$9="","",'Financiación'!$B$45),"") -> 0 | C12: =IFERROR(IF('PyG 3 Años'!$C$9="","",'Financiación'!$B$47),"") -> 18493.779 | D12: =IFERROR(IF('PyG 3 Años'!$D$9="","",'Financiación'!$B$49),"") -> 19603.406 | E12: El principal NO es gasto del P&L, pero sale de la caja. Sin él, el umbral de equilibrio se publica por debajo del real
A13: PUNTO DE EQUILIBRIO CONTABLE (incluye amortización)
A14: Clientes necesarios al año | B14: =IFERROR(IF('PyG 3 Años'!$B$9="","",IF(B10<=0,"",B6/B10)),"") -> 40123.444 | C14: =IFERROR(IF('PyG 3 Años'!$C$9="","",IF(C10<=0,"",C6/C10)),"") -> 41828.861 | D14: =IFERROR(IF('PyG 3 Años'!$D$9="","",IF(D10<=0,"",D6/D10)),"") -> 43218.883
A15: Clientes necesarios al día | B15: =IFERROR(IF('PyG 3 Años'!$B$9="","",B14/B11),"") -> 129.43046 | C15: =IFERROR(IF('PyG 3 Años'!$C$9="","",C14/C11),"") -> 134.93181 | D15: =IFERROR(IF('PyG 3 Años'!$D$9="","",D14/D11),"") -> 139.41575
A16: Ingresos necesarios al año | B16: =IFERROR(IF('PyG 3 Años'!$B$9="","",B14*B8),"") -> 196604.87 | C16: =IFERROR(IF('PyG 3 Años'!$C$9="","",C14*C8),"") -> 204961.42 | D16: =IFERROR(IF('PyG 3 Años'!$D$9="","",D14*D8),"") -> 211772.53
A17: PUNTO DE EQUILIBRIO DE CAJA (incluye la cuota del préstamo)
A18: Costes fijos de caja + principal del año | B18: =IFERROR(IF('PyG 3 Años'!$B$9="","",B6-'PyG 3 Años'!$B$36+B12),"") -> 130497.3 | C18: =IFERROR(IF('PyG 3 Años'!$C$9="","",C6-'PyG 3 Años'!$C$36+C12),"") -> 154991.08 | D18: =IFERROR(IF('PyG 3 Años'!$D$9="","",D6-'PyG 3 Años'!$D$36+D12),"") -> 160991.08 | E18: Los fijos del P&L sin la amortización (que no se paga) y CON la devolución de principal (que sí). Es el umbral que decide si la caja aguanta
A19: Clientes necesarios al año (caja) | B19: =IFERROR(IF('PyG 3 Años'!$B$9="","",IF(B10<=0,"",B18/B10)),"") -> 37092.064 | C19: =IFERROR(IF('PyG 3 Años'!$C$9="","",IF(C10<=0,"",C18/C10)),"") -> 44054.084 | D19: =IFERROR(IF('PyG 3 Años'!$D$9="","",IF(D10<=0,"",D18/D10)),"") -> 45759.502
A20: Clientes necesarios al día (caja) | B20: =IFERROR(IF('PyG 3 Años'!$B$9="","",B19/B11),"") -> 119.65182 | C20: =IFERROR(IF('PyG 3 Años'!$C$9="","",C19/C11),"") -> 142.10995 | D20: =IFERROR(IF('PyG 3 Años'!$D$9="","",D19/D11),"") -> 147.6113
A21: Ingresos necesarios al año (caja) | B21: =IFERROR(IF('PyG 3 Años'!$B$9="","",B19*B8),"") -> 181751.11 | C21: =IFERROR(IF('PyG 3 Años'!$C$9="","",C19*C8),"") -> 215865.01 | D21: =IFERROR(IF('PyG 3 Años'!$D$9="","",D19*D8),"") -> 224221.56
A22: CONTRASTE CON EL PLAN
A23: Clientes/día previstos en el plan | B23: =IFERROR(IF('PyG 3 Años'!$B$9="","",'PyG 3 Años'!$B$6),"") -> 143 | C23: =IFERROR(IF('PyG 3 Años'!$C$9="","",'PyG 3 Años'!$C$6),"") -> 154.44 | D23: =IFERROR(IF('PyG 3 Años'!$D$9="","",'PyG 3 Años'!$D$6),"") -> 162.162
A24: Holgura sobre el equilibrio de CAJA (%) | B24: =IFERROR(IF('PyG 3 Años'!$B$9="","",B23/B20-1),"") -> 0.19513435 | C24: =IFERROR(IF('PyG 3 Años'!$C$9="","",C23/C20-1),"") -> 0.086764164 | D24: =IFERROR(IF('PyG 3 Años'!$D$9="","",D23/D20-1),"") -> 0.098574462 | E24: Cuánto puedes caer antes de no poder pagar los costes fijos y la cuota. El mínimo exigible está en la hoja de Supuestos
A25: INTERPRETACIÓN
A26: =IFERROR("Con el ticket medio sin IVA de la fila de arriba necesitas "&TEXT(ROUNDUP(B15,0),"0")&" clientes al día durante los "&TEXT(B11,"0")&" días que abres para no perder dinero (equilibrio contable, con la amortización dentro), y "&TEXT(ROUNDUP(B20,0),"0")&" para que la caja aguante (equilibrio de caja: sin la amortización, que no se paga, y con la cuota del préstamo del año"&IF(B12=0,"; este año sólo intereses, porque el préstamo está en carencia","")&"). En las filas «Ingresos necesarios al año» tienes esas mismas cifras en euros.","") -> Con el ticket medio sin IVA de la fila de arriba necesitas 130 clientes al día durante los 310 días que abres para no perder dinero (equilibrio contable, con la amortización dentro), y 120 para que la caja aguante (equilibrio de caja: sin la amortización, que no se paga, y con la cuota del préstamo del año; este año sólo intereses, porque el préstamo está en carencia). En las filas «Ingresos necesarios al año» tienes esas mismas cifras en euros.
A28: SENSIBILIDAD DEL PUNTO DE EQUILIBRIO
A29: Clientes/día necesarios para cubrir costes según el ticket medio (columnas) y el coste variable por cliente (filas). En verde, los que están por debajo de los clientes que prevé el plan.
A31: Clientes/día necesarios: ticket medio sin IVA (columnas) × coste variable por cliente (filas) | B31: =IFERROR($B$8-2,"") -> 2.9 | C31: =IFERROR(IF($B$8="","",$B$8),"") -> 4.9 | D31: =IFERROR($B$8+2,"") -> 6.9 | E31: =IFERROR($B$8+4,"") -> 8.9
A32: =IFERROR($B$9*0.85,"") -> 1.17453 | B32: =IFERROR(IF($B$31-$A32<=0,"",$B$6/($B$31-$A32)/$B$11),"") -> 263.90622 | C32: =IFERROR(IF($C$31-$A32<=0,"",$B$6/($C$31-$A32)/$B$11),"") -> 122.22948 | D32: =IFERROR(IF($D$31-$A32<=0,"",$B$6/($D$31-$A32)/$B$11),"") -> 79.53273 | E32: =IFERROR(IF($E$31-$A32<=0,"",$B$6/($E$31-$A32)/$B$11),"") -> 58.942984
A33: =IFERROR($B$9*0.925,"") -> 1.278165 | B33: =IFERROR(IF($B$31-$A33<=0,"",$B$6/($B$31-$A33)/$B$11),"") -> 280.76978 | C33: =IFERROR(IF($C$31-$A33<=0,"",$B$6/($C$31-$A33)/$B$11),"") -> 125.72695 | D33: =IFERROR(IF($D$31-$A33<=0,"",$B$6/($D$31-$A33)/$B$11),"") -> 80.998866 | E33: =IFERROR(IF($E$31-$A33<=0,"",$B$6/($E$31-$A33)/$B$11),"") -> 59.744439
A34: =IFERROR($B$9*1.0,"") -> 1.3818 | B34: =IFERROR(IF($B$31-$A34<=0,"",$B$6/($B$31-$A34)/$B$11),"") -> 299.93562 | C34: =IFERROR(IF($C$31-$A34<=0,"",$B$6/($C$31-$A34)/$B$11),"") -> 129.43046 | D34: =IFERROR(IF($D$31-$A34<=0,"",$B$6/($D$31-$A34)/$B$11),"") -> 82.520071 | E34: =IFERROR(IF($E$31-$A34<=0,"",$B$6/($E$31-$A34)/$B$11),"") -> 60.567989
A35: =IFERROR($B$9*1.075,"") -> 1.485435 | B35: =IFERROR(IF($B$31-$A35<=0,"",$B$6/($B$31-$A35)/$B$11),"") -> 321.90974 | C35: =IFERROR(IF($C$31-$A35<=0,"",$B$6/($C$31-$A35)/$B$11),"") -> 133.35879 | D35: =IFERROR(IF($D$31-$A35<=0,"",$B$6/($D$31-$A35)/$B$11),"") -> 84.099509 | E35: =IFERROR(IF($E$31-$A35<=0,"",$B$6/($E$31-$A35)/$B$11),"") -> 61.414561
A36: =IFERROR($B$9*1.15,"") -> 1.58907 | B36: =IFERROR(IF($B$31-$A36<=0,"",$B$6/($B$31-$A36)/$B$11),"") -> 347.35818 | C36: =IFERROR(IF($C$31-$A36<=0,"",$B$6/($C$31-$A36)/$B$11),"") -> 137.53304 | D36: =IFERROR(IF($D$31-$A36<=0,"",$B$6/($D$31-$A36)/$B$11),"") -> 85.740587 | E36: =IFERROR(IF($E$31-$A36<=0,"",$B$6/($E$31-$A36)/$B$11),"") -> 62.285134

Sheet Escenarios
A1: ESCENARIOS
A4: Métrica | B4: Pesimista | C4: Realista | D4: Optimista | E4: Notas
A5: Clientes/día | B5: 120 | C5: =IFERROR(IF('PyG 3 Años'!$B$6="","",'PyG 3 Años'!$B$6),"") -> 143 | D5: 165
A6: Ticket medio sin IVA | B6: 4.6 | C6: =IFERROR(IF('PyG 3 Años'!$B$7="","",'PyG 3 Años'!$B$7),"") -> 4.9 | D6: 5.2
A7: Días de apertura al año | B7: 300 | C7: =IFERROR(IF('PyG 3 Años'!$B$8="","",'PyG 3 Años'!$B$8),"") -> 310 | D7: 320
A8: INGRESOS ANUALES (sin IVA) | B8: =IFERROR(IF(B5*B6*B7=0,"",B5*B6*B7),"") -> 165600 | C8: =IFERROR(IF(C5*C6*C7=0,"",C5*C6*C7),"") -> 217217 | D8: =IFERROR(IF(D5*D6*D7=0,"",D5*D6*D7),"") -> 274560
A9: Coste de mercancía — comida | B9: =IFERROR(IF(B8="","",B8*'0. Supuestos'!$B$11*'0. Supuestos'!$B$13),"") -> 29808 | C9: =IFERROR(IF(C8="","",C8*'0. Supuestos'!$B$11*'0. Supuestos'!$B$13),"") -> 39099.06 | D9: =IFERROR(IF(D8="","",D8*'0. Supuestos'!$B$11*'0. Supuestos'!$B$13),"") -> 49420.8
A10: Coste de mercancía — bebida | B10: =IFERROR(IF(B8="","",B8*'0. Supuestos'!$B$12*'0. Supuestos'!$B$14),"") -> 4140 | C10: =IFERROR(IF(C8="","",C8*'0. Supuestos'!$B$12*'0. Supuestos'!$B$14),"") -> 5430.425 | D10: =IFERROR(IF(D8="","",D8*'0. Supuestos'!$B$12*'0. Supuestos'!$B$14),"") -> 6864
A11: Consumibles y envases | B11: =IFERROR(IF(B8="","",B8*'0. Supuestos'!$B$15),"") -> 6624 | C11: =IFERROR(IF(C8="","",C8*'0. Supuestos'!$B$15),"") -> 8688.68 | D11: =IFERROR(IF(D8="","",D8*'0. Supuestos'!$B$15),"") -> 10982.4
A12: Comisiones de delivery | B12: =IFERROR(IF(B8="","",B8*'0. Supuestos'!$B$16*'0. Supuestos'!$B$17),"") -> 1490.4 | C12: =IFERROR(IF(C8="","",C8*'0. Supuestos'!$B$16*'0. Supuestos'!$B$17),"") -> 1954.953 | D12: =IFERROR(IF(D8="","",D8*'0. Supuestos'!$B$16*'0. Supuestos'!$B$17),"") -> 2471.04
A13: Comisiones de los medios de pago | B13: =IFERROR(IF(B8="","",B8*'0. Supuestos'!$B$18),"") -> 1324.8 | C13: =IFERROR(IF(C8="","",C8*'0. Supuestos'!$B$18),"") -> 1737.736 | D13: =IFERROR(IF(D8="","",D8*'0. Supuestos'!$B$18),"") -> 2196.48
A14: Varios e imprevistos | B14: =IFERROR(IF(B8="","",B8*'0. Supuestos'!$B$28),"") -> 3312 | C14: =IFERROR(IF(C8="","",C8*'0. Supuestos'!$B$28),"") -> 4344.34 | D14: =IFERROR(IF(D8="","",D8*'0. Supuestos'!$B$28),"") -> 5491.2
A15: TOTAL COSTES VARIABLES | B15: =IFERROR(IF(B8="","",SUM(B9:B14)),"") -> 46699.2 | C15: =IFERROR(IF(C8="","",SUM(C9:C14)),"") -> 61255.194 | D15: =IFERROR(IF(D8="","",SUM(D9:D14)),"") -> 77425.92
A16: MARGEN BRUTO | B16: =IFERROR(IF(B8="","",B8-B15),"") -> 118900.8 | C16: =IFERROR(IF(C8="","",C8-C15),"") -> 155961.81 | D16: =IFERROR(IF(D8="","",D8-D15),"") -> 197134.08
A17: COSTES FIJOS (los del P&L) | B17: =IFERROR(IF(B8="","",'PyG 3 Años'!$B$38),"") -> 141162.3 | C17: =IFERROR(IF(C8="","",'PyG 3 Años'!$B$38),"") -> 141162.3 | D17: =IFERROR(IF(D8="","",'PyG 3 Años'!$B$38),"") -> 141162.3 | E17: Los costes fijos no cambian con el escenario: por eso son fijos
A18: RESULTADO ANTES DE IMPUESTOS | B18: =IFERROR(IF(B8="","",B16-B17),"") -> -22261.5 | C18: =IFERROR(IF(C8="","",C16-C17),"") -> 14799.506 | D18: =IFERROR(IF(D8="","",D16-D17),"") -> 55971.78
A19: Impuesto de Sociedades | B19: =IFERROR(IF(B8="","",MAX(0,B18-'0. Supuestos'!$B$42)*'0. Supuestos'!$B$37),"") -> 0 | C19: =IFERROR(IF(C8="","",MAX(0,C18-'0. Supuestos'!$B$42)*'0. Supuestos'!$B$37),"") -> 2219.9259 | D19: =IFERROR(IF(D8="","",MAX(0,D18-'0. Supuestos'!$B$42)*'0. Supuestos'!$B$37),"") -> 8395.767 | E19: Al tipo de entidad de nueva creación, compensando las bases negativas anteriores
A20: RESULTADO NETO | B20: =IFERROR(IF(B8="","",B18-B19),"") -> -22261.5 | C20: =IFERROR(IF(C8="","",C18-C19),"") -> 12579.58 | D20: =IFERROR(IF(D8="","",D18-D19),"") -> 47576.013
A21: Clientes/día para el equilibrio | B21: =IFERROR(IF(B8="","",IF(B6-B15/(B5*B7)<=0,"",B17/(B6-B15/(B5*B7))/B7)),"") -> 142.4673 | C21: =IFERROR(IF(C8="","",IF(C6-C15/(C5*C7)<=0,"",C17/(C6-C15/(C5*C7))/C7)),"") -> 129.43046 | D21: =IFERROR(IF(D8="","",IF(D6-D15/(D5*D7)<=0,"",D17/(D6-D15/(D5*D7))/D7)),"") -> 118.15197
A22: LO QUE CADA ESCENARIO EXIGE
A23: Coste de personal / Ventas | B23: =IFERROR(IF(B8="","",'PyG 3 Años'!$B$23/B8),"") -> 0.49642089 | C23: =IFERROR(IF(C8="","",'PyG 3 Años'!$B$23/C8),"") -> 0.37845703 | D23: =IFERROR(IF(D8="","",'PyG 3 Años'!$B$23/D8),"") -> 0.2994147 | E23: La MISMA plantilla en los tres escenarios. Si en el pesimista se dispara, el ajuste hay que hacerlo en la hoja de Personal, no aquí
A24: Clientes al año por jornada equivalente | B24: =IFERROR(IF(B8="","",B5*B7/'Personal'!$C$11),"") -> 11803.279 | C24: =IFERROR(IF(C8="","",C5*C7/'Personal'!$C$11),"") -> 14534.426 | D24: =IFERROR(IF(D8="","",D5*D7/'Personal'!$C$11),"") -> 17311.475 | E24: Clientes que tendría que sacar cada jornada completa del cuadro de Personal. En el optimista dice si hace falta contratar
A25: Saldo de caja al cierre del año 1 (estimado, el mismo método en los tres escenarios) | B25: =IFERROR(IF(B8="","",'Inversión Inicial'!$B$30+B20+'PyG 3 Años'!$B$36-'Financiación'!$B$45),"") -> 21027.825 | C25: =IFERROR(IF(C8="","",'Inversión Inicial'!$B$30+C20+'PyG 3 Años'!$B$36-'Financiación'!$B$45),"") -> 55868.905 | D25: =IFERROR(IF(D8="","",'Inversión Inicial'!$B$30+D20+'PyG 3 Años'!$B$36-'Financiación'!$B$45),"") -> 90865.338 | E25: Saldo ESTIMADO: fondo de maniobra más el resultado del año, devolviendo la amortización (que no se paga) y restando el principal del préstamo. No incluye el desfase de cobros y pagos ni la liquidación del IVA, así que las tres columnas se pueden comparar entre sí. En rojo, el escenario se queda sin caja
A26: Saldo real del mes 12 de la hoja de Tesorería (sólo realista) | C26: =IFERROR(IF(C8="","",'Tesorería 12 meses'!$M$22),"") -> 66345.347 | E26: El saldo REAL del caso base, con su desfase de cobros y pagos y su liquidación de IVA. Sólo existe para el escenario realista, que es el único con tesorería mensual propia: por eso no está en la fila de arriba, donde se compararía contra dos estimaciones
A28: La columna «Realista» lee sus tres datos de la hoja de Supuestos, así que reproduce EXACTAMENTE el año 1 del P&L. Los otros dos escenarios usan las mismas tasas de coste: lo único que cambia son los clientes, el ticket y los días. Los COSTES FIJOS sí son los mismos en los tres: los varios e imprevistos, que son un porcentaje de las ventas, van arriba con los variables y cada escenario carga los suyos.

Sheet Personal
A1: PERSONAL Y COSTES
A2: =IFERROR("Convenio Hostelería — "&TEXT('0. Supuestos'!$B$21,"0")&" pagas + SS "&TEXT('0. Supuestos'!$B$20*100,"0")&" %","") -> Convenio Hostelería — 14 pagas + SS 33 %
A4: Puesto | B4: Personas | C4: Jornada | D4: Bruto mes (€, total del puesto) | E4: Seg. Social a cargo de la empresa (€) | F4: Coste mes (€, total del puesto) | G4: Coste año (€) | H4: Horas/semana por persona | I4: Horas/año del puesto | J4: Notas
A5: Titular — maestro heladero, compras y gestión | B5: 1 | C5: 1 | D5: 1750 | E5: =IFERROR(IF(D5="","",D5*'0. Supuestos'!$B$20),"") -> 577.5 | F5: =IFERROR(IF(D5="","",D5+E5),"") -> 2327.5 | G5: =IFERROR(IF(D5="","",F5*MAX(12,'0. Supuestos'!$B$21)),"") -> 32585 | H5: =IFERROR(IF(D5="","",C5*$B$18),"") -> 40 | I5: =IFERROR(IF(D5="","",H5*B5*$B$19),"") -> 1840 | J5: Balancea las mezclas, pasteuriza, manteca y abate, compra y lleva la gestión. Como administrador de la SL cotiza en el régimen de autónomos: confirma con tu gestoría la cuota y si te aplica la reducida de inicio
A6: Dependiente/a y encargado/a de turno (todo el año) | B6: 1 | C6: 1 | D6: 1300 | E6: =IFERROR(IF(D6="","",D6*'0. Supuestos'!$B$20),"") -> 429 | F6: =IFERROR(IF(D6="","",D6+E6),"") -> 1729 | G6: =IFERROR(IF(D6="","",F6*MAX(12,'0. Supuestos'!$B$21)),"") -> 24206 | H6: =IFERROR(IF(D6="","",C6*$B$18),"") -> 40 | I6: =IFERROR(IF(D6="","",H6*B6*$B$19),"") -> 1840 | J6: Mostrador, caja, vitrina y cierre; abre y cierra cuando el titular está en el obrador
A7: Dependiente/a de temporada (fijo discontinuo, abril-septiembre) | B7: 1 | C7: 0.5 | D7: 650 | E7: =IFERROR(IF(D7="","",D7*'0. Supuestos'!$B$20),"") -> 214.5 | F7: =IFERROR(IF(D7="","",D7+E7),"") -> 864.5 | G7: =IFERROR(IF(D7="","",F7*MAX(12,'0. Supuestos'!$B$21)),"") -> 12103 | H7: =IFERROR(IF(D7="","",C7*$B$18),"") -> 20 | I7: =IFERROR(IF(D7="","",H7*B7*$B$19),"") -> 920 | J7: Contrato fijo discontinuo (art. 16 del Estatuto de los Trabajadores) a jornada completa de abril a septiembre: equivale a media jornada en cómputo anual. Llamamiento por escrito
A8: Dependiente/a de verano (fijo discontinuo, junio-septiembre) | B8: 1 | C8: 0.25 | D8: 325 | E8: =IFERROR(IF(D8="","",D8*'0. Supuestos'!$B$20),"") -> 107.25 | F8: =IFERROR(IF(D8="","",D8+E8),"") -> 432.25 | G8: =IFERROR(IF(D8="","",F8*MAX(12,'0. Supuestos'!$B$21)),"") -> 6051.5 | H8: =IFERROR(IF(D8="","",C8*$B$18),"") -> 10 | I8: =IFERROR(IF(D8="","",H8*B8*$B$19),"") -> 460 | J8: Fijo discontinuo de 30 horas a la semana de junio a septiembre: las tardes y noches del pico. Nunca como autónomo que te factura: con tu horario y tu dirección es falso autónomo (art. 1.1 ET)
A9: Ayudante de obrador (fijo discontinuo, mayo-septiembre) | B9: 1 | C9: 0.2 | D9: 260 | E9: =IFERROR(IF(D9="","",D9*'0. Supuestos'!$B$20),"") -> 85.8 | F9: =IFERROR(IF(D9="","",D9+E9),"") -> 345.8 | G9: =IFERROR(IF(D9="","",F9*MAX(12,'0. Supuestos'!$B$21)),"") -> 4841.2 | H9: =IFERROR(IF(D9="","",C9*$B$18),"") -> 8 | I9: =IFERROR(IF(D9="","",H9*B9*$B$19),"") -> 368 | J9: Media jornada de mayo a septiembre: pesaje, limpieza del pasteurizador y de la mantecadora, cubetas y apoyo en las tandas del verano
A10: Suplencias de vacaciones y descansos | B10: 1 | C10: 0.1 | D10: 130 | E10: =IFERROR(IF(D10="","",D10*'0. Supuestos'!$B$20),"") -> 42.9 | F10: =IFERROR(IF(D10="","",D10+E10),"") -> 172.9 | G10: =IFERROR(IF(D10="","",F10*MAX(12,'0. Supuestos'!$B$21)),"") -> 2420.6 | H10: =IFERROR(IF(D10="","",C10*$B$18),"") -> 4 | I10: =IFERROR(IF(D10="","",H10*B10*$B$19),"") -> 184 | J10: Cobertura de los 30 días de vacaciones (art. 38 ET) y del descanso semanal del equipo de todo el año
A11: TOTAL PLANTILLA | B11: =IFERROR(IF(COUNT(D5:D10)=0,"",SUM(B5:B10)),"") -> 6 | C11: =IFERROR(IF(COUNT(D5:D10)=0,"",SUM(C5:C10)),"") -> 3.05 | D11: =IFERROR(IF(COUNT(D5:D10)=0,"",SUM(D5:D10)),"") -> 4415 | E11: =IFERROR(IF(COUNT(D5:D10)=0,"",SUM(E5:E10)),"") -> 1456.95 | F11: =IFERROR(IF(COUNT(D5:D10)=0,"",SUM(F5:F10)),"") -> 5871.95 | G11: =IFERROR(IF(COUNT(D5:D10)=0,"",SUM(G5:G10)),"") -> 82207.3 | I11: =IFERROR(IF(COUNT(D5:D10)=0,"",SUM(I5:I10)),"") -> 5612
A12: CRECIMIENTO DE LA PLANTILLA (coste escalonado)
A13: Coste anual de las incorporaciones del año 2 (€) | B13: 6000 | J13: Coste ANUAL completo (bruto + Seguridad Social × pagas) de lo que se contrate ese año. El P&L lo suma al coste del año anterior: la plantilla no crece con un porcentaje, crece con personas
A14: Coste anual de las incorporaciones del año 3 (€) | B14: 6000 | J14: Coste ANUAL completo (bruto + Seguridad Social × pagas) de lo que se contrate ese año. El P&L lo suma al coste del año anterior: la plantilla no crece con un porcentaje, crece con personas
A15: Coste de personal del año 2 | B15: =IFERROR(IF(G11="","",G11*(1+'0. Supuestos'!$B$48)+B13),"") -> 88207.3
A16: Coste de personal del año 3 | B16: =IFERROR(IF(B15="","",B15*(1+'0. Supuestos'!$B$48)+B14),"") -> 94207.3
A17: COBERTURA POR HORAS DE SERVICIO
A18: Jornada completa del convenio (horas/semana) | B18: 40 | J18: Art. 34.1 del Estatuto de los Trabajadores; tu convenio provincial puede fijar menos
A19: Semanas trabajadas al año por persona | B19: 46 | J19: 46 semanas: 52 menos las vacaciones (30 días naturales, art. 38 ET), los festivos y las ausencias medias
A20: Horas de servicio al día que hay que cubrir | B20: 9.5 | J20: Media del año de la apertura de la TIENDA: 12 h en temporada alta (de mediados de abril a septiembre), 8 h en marzo y octubre y 6 h entre semana en invierno. El obrador va en la fila de abajo
A21: Personas necesarias a la vez en cada franja | B21: 1.6 | J21: Presencia media a la vez en el mostrador: 1,8-2 personas en verano, 1,3 en primavera y otoño y 1 en invierno. En julio y agosto el cuadrante va justo: el titular hace horas o entra un extra de fin de semana
A22: Horas de producción al día ANTES de abrir | B22: 2.75 | J22: Tandas del obrador antes de abrir: pasteurizar, enfriar, madurar, mantecar y abatir. Unas 4 h en julio y 1,5 h en invierno
A23: Personas en el turno de producción | B23: 1 | J23: El maestro heladero; en verano le ayuda el ayudante de obrador
A24: Horas de servicio a cubrir al año | B24: =IFERROR(IF(OR(B20="",B21="",'0. Supuestos'!$B$6=""),"",B20*B21*'0. Supuestos'!$B$6+B22*B23*'0. Supuestos'!$B$6),"") -> 5564.5
A25: Horas contratadas al año | B25: =IFERROR(IF(I11="","",I11),"") -> 5612
A26: Cobertura (contratadas / necesarias) | B26: =IFERROR(B25/B24,"") -> 1.0085363 | J26: Por debajo del 100 % la plantilla no llega a cubrir el horario que declara el plan: o se contrata más o se recorta el horario
A28: Las columnas «Bruto mes», «Seg. Social», «Coste mes» y «Coste año» son TOTALES de la fila: en un puesto con dos personas incluyen a las dos. «Jornada» es el porcentaje sobre la jornada completa del convenio y sirve para comparar el salario con el suelo legal en proporción. El tipo de Seguridad Social y el número de pagas están en la hoja «0. Supuestos».
A29: El suelo salarial es el MAYOR entre el SMI y el salario de convenio, los dos en la hoja «0. Supuestos»; las jornadas parciales lo llevan en proporción. El convenio aplicable es el PROVINCIAL de hostelería: no existe una tabla salarial estatal única, así que la celda del convenio se entrega vacía para que copies la de tu provincia.

Sheet Instrucciones
A1: INSTRUCCIONES DE USO — Plan financiero Heladería Artesanal
A3: CÓMO SE USA ESTE LIBRO
A4: Este plan financiero es un MODELO: sólo se teclea en las celdas VERDES y el resto se recalcula solo.
A5: 1. «0. Supuestos» es la hoja de mando: clientes, ticket sin IVA, días de apertura, mezcla de comida y bebida, coste de mercancía, alquiler, financiación e impuestos.
A6: 2. Las partidas de la inversión, los costes fijos y la plantilla se teclean en su propia hoja, también en verde. Ningún número se escribe dos veces.
A7: 3. Sólo «Punto Equilibrio» se deriva entera de lo anterior. En las otras tres hojas también hay celdas verdes que puedes tocar: el escenario pesimista y el optimista en «Escenarios», la estacionalidad y la rampa de arranque en «Tesorería 12 meses», y las cuatro fuentes alternativas de financiación en «Financiación». Todo lo demás se calcula.
A8: 4. Todas las cifras van SIN IVA. Para pasar un PVP a precio sin IVA, divide por el tipo que le corresponda: entre 1,10 en el local (comida y bebida, alcohol incluido: art. 91.Uno.2.2.º de la Ley 37/1992 del IVA) y, cuando se venden para llevar, los alimentos —helado y tartas heladas incluidos—, que son productos alimenticios al tipo reducido por el art. 91.Uno.1.1.º; y entre 1,21 el tipo general, que en hostelería sólo alcanza a lo que sale del local como entrega de bienes excluida del reducido: el alcohol y los refrescos, zumos y gaseosas con azúcares o edulcorantes añadidos para llevar o a domicilio (la comida para llevar sigue al 10 %); el libro lo aplica al alcohol del canal de delivery. El tipo de cada línea de venta está en la columna «Tipo de IVA de la línea» del P&L y de ahí salen los cobros, el IVA repercutido y el PVP equivalente. El IVA de la inversión se adelanta y se recupera con el modelo 303.
A9: 5. Si cambias la plantilla, el P&L la lee sola: el coste de personal sale de la hoja «Personal», no de una estimación aparte.
A10: 6. La hoja «Tesorería 12 meses» responde la pregunta que decide una operación bancaria: en qué mes se agota la caja. Su Mes 1 es MARZO: el plan abre en temporada para llegar al primer invierno con la caja del verano. El saldo mínimo del año nunca puede salir en rojo.
A11: 7. La hoja «Financiación» cuadra lo que hace falta con lo que se aporta y monta el cuadro de amortización del préstamo. Si la diferencia sale en rojo, el plan no está financiado.
A12: 8. El documento Word de este pack usa las cifras de este Excel: si cambias una celda verde, el Excel manda.
A14: RATIOS QUE AUDITA EL LIBRO
A15: Los umbrales viven en la columna «Umbral» del bloque RATIOS CLAVE del P&L: cámbialos ahí y el semáforo cambia con ellos.
A17: Ratio | B17: Valor del año 1 | C17: Umbral | D17: Estado
A18: Coste de mercancía / Ventas | B18: =IFERROR(IF('PyG 3 Años'!$B$53="","",'PyG 3 Años'!$B$53),"") -> 0.205 | C18: =IFERROR(IF('PyG 3 Años'!$E$53="","",'PyG 3 Años'!$E$53),"") -> 0.25 | D18: =IFERROR(IF(OR(B18="",C18=""),"",IF(B18<=C18,"CUMPLE","REVISAR")),"") -> CUMPLE
A19: Coste de personal / Ventas | B19: =IFERROR(IF('PyG 3 Años'!$B$54="","",'PyG 3 Años'!$B$54),"") -> 0.37845703 | C19: =IFERROR(IF('PyG 3 Años'!$E$54="","",'PyG 3 Años'!$E$54),"") -> 0.4 | D19: =IFERROR(IF(OR(B19="",C19=""),"",IF(B19<=C19,"CUMPLE","REVISAR")),"") -> CUMPLE
A20: Alquiler / Ventas | B20: =IFERROR(IF('PyG 3 Años'!$B$55="","",'PyG 3 Años'!$B$55),"") -> 0.093915301 | C20: =IFERROR(IF('PyG 3 Años'!$E$55="","",'PyG 3 Años'!$E$55),"") -> 0.12 | D20: =IFERROR(IF(OR(B20="",C20=""),"",IF(B20<=C20,"CUMPLE","REVISAR")),"") -> CUMPLE
A21: Resultado neto / Ventas | B21: =IFERROR(IF('PyG 3 Años'!$B$56="","",'PyG 3 Años'!$B$56),"") -> 0.057912503 | C21: =IFERROR(IF('PyG 3 Años'!$E$56="","",'PyG 3 Años'!$E$56),"") -> 0.05 | D21: =IFERROR(IF(OR(B21="",C21=""),"",IF(B21>=C21,"CUMPLE","REVISAR")),"") -> CUMPLE
A22: Margen bruto / Ventas | B22: =IFERROR(IF('PyG 3 Años'!$B$51="","",'PyG 3 Años'!$B$51),"") -> 0.718 | C22: =IFERROR(IF('PyG 3 Años'!$E$51="","",'PyG 3 Años'!$E$51),"") -> 0.7 | D22: =IFERROR(IF(OR(B22="",C22=""),"",IF(B22>=C22,"CUMPLE","REVISAR")),"") -> CUMPLE
A24: CIFRAS DE ESTE PLAN
A25: Inversión total (suma de los bloques) | B25: =IFERROR(IF('Inversión Inicial'!$B$31="","",'Inversión Inicial'!$B$31),"") -> 158274.33
A26: Necesidad total de caja al arranque | B26: =IFERROR(IF('Inversión Inicial'!$B$34="","",'Inversión Inicial'!$B$34),"") -> 183169.83
A27: Fondo de maniobra dotado | B27: =IFERROR(IF('Inversión Inicial'!$B$30="","",'Inversión Inicial'!$B$30),"") -> 32624.325
A28: Facturación prevista del año 1 | B28: =IFERROR(IF('PyG 3 Años'!$B$9="","",'PyG 3 Años'!$B$9),"") -> 217217
A29: Resultado neto del año 1 | B29: =IFERROR(IF('PyG 3 Años'!$B$48="","",'PyG 3 Años'!$B$48),"") -> 12579.58
A30: Clientes/día para el punto de equilibrio CONTABLE (con la amortización dentro) | B30: =IFERROR(IF('Punto Equilibrio'!$B$15="","",'Punto Equilibrio'!$B$15),"") -> 129.43046
