Workbook

Sheet 0. Supuestos
A1: SUPUESTOS — aquí se teclean las TASAS y los DRIVERS del modelo
A2: Cambia las celdas VERDES: el resto del libro se recalcula solo. Las partidas de gasto se teclean en su hoja (también en verde) y no se repiten aquí.
A3: ACTIVIDAD
A4: Cubiertos/día (media del año 1) | B4: 80 | C4: Comensales servidos al día de media del año, contando todos los servicios. La rotación que implica sobre el aforo la calcula la celda «Rotaciones al día implícitas» de esta misma hoja; el documento del plan pide un MÍNIMO de 1,8 covers por mesa y servicio en temporada alta
A5: Ticket medio SIN IVA (€) | B5: 18.2 | C5: SIN IVA. El PVP equivalente lo calcula la celda «PVP equivalente con IVA» de abajo (al 10 % en sala son 20,02 € con los supuestos de partida): dentro del rango 15-22 € que declara este mismo libro y del 18-25 € que fija el documento del plan
A6: Días de apertura al año | B6: 310 | C6: Cierre semanal de un día y vacaciones. El MISMO dato lo usan el P&L, el punto de equilibrio y los escenarios
A7: Crecimiento de volumen del año 2 | B7: 0.1 | C7: Segundo año con la clientela ya asentada
A8: Crecimiento de volumen del año 3 | B8: 0.06 | C8: Tercer año, cerca del techo de rotación del local
A9: PVP equivalente con IVA (calculado) | B9: =IFERROR(IF($B$5="","",$B$5*(1+SUMPRODUCT('2. P&L 3 Años'!$E$11:$E$12,'2. P&L 3 Años'!$G$11:$G$12))),"") -> 20.02 | C9: =IFERROR("Ticket sin IVA más el IVA medio ponderado de tus líneas de venta: "&TEXT(SUMPRODUCT('2. P&L 3 Años'!$E$11:$E$12,'2. P&L 3 Años'!$G$11:$G$12)*100,"0")&" %. En sala todo va al 10 % (art. 91.Uno.2.2.º de la Ley 37/1992, alcohol incluido); el alcohol que sale por delivery y el pan común, si los tienes, mueven la media. Aquí va redondeado. Compáralo con el rango del sector, que va con IVA.","") -> Ticket sin IVA más el IVA medio ponderado de tus líneas de venta: 10 %. En sala todo va al 10 % (art. 91.Uno.2.2.º de la Ley 37/1992, alcohol incluido); el alcohol que sale por delivery y el pan común, si los tienes, mueven la media. Aquí va redondeado. Compáralo con el rango del sector, que va con IVA.
A10: MIX Y COSTE DE MERCANCÍA
A11: Ventas de COMIDA sobre el total | B11: 0.65 | C11: Peso de la COMIDA sobre el total de ventas. Es un INPUT: cámbialo aquí y el P&L, la tesorería y el IVA repercutido se recalculan solos
A12: Ventas de BEBIDA sobre el total | B12: =IFERROR(IF(COUNT(B11)=0,"",1-B11),"") -> 0.35 | C12: Se calcula como el resto: comida + bebida = 100 %
A13: Coste de mercancía sobre las ventas de COMIDA | B13: 0.3 | C13: Food cost objetivo del bar-restaurante casual: 28-32 % según las referencias de este mismo libro. Se aplica SOLO a la comida
A14: Coste de mercancía sobre las ventas de BEBIDA | B14: 0.22 | C14: Coste de la bebida sobre las ventas de bebida, no sobre el total
A15: Consumibles sobre ventas | B15: 0.015 | C15: Servilletas, papel, productos de limpieza y envases de llevar
A16: Ventas por delivery sobre el total | B16: 0 | C16: A CERO por defecto: si no repartes no arrastras un coste inventado. Súbelo al peso REAL del canal y la comisión se aplica sólo sobre esa parte
A17: Comisión de la plataforma de delivery | B17: 0.28 | C17: Comisión típica de las plataformas sobre el pedido servido por ese canal; confírmala en tu contrato antes de proyectar
A18: Comisión de los medios de pago | B18: 0.008 | C18: Tarjeta y bizum sobre el total facturado; pide oferta a dos proveedores de TPV
A19: PERSONAL
A20: Seguridad Social a cargo de la empresa | B20: 0.33 | C20: Contingencias comunes + AT/EP + desempleo + FOGASA + FP; ajusta a tu convenio y bonificaciones
A21: Número de pagas anuales | B21: 14 | C21: Salario bruto anual = bruto mensual × pagas
A22: SMI anual de referencia (€) | B22: 17094 | C22: SMI 2026: 17.094 € al año (1.221 €/mes en 14 pagas), suelo legal por jornada completa. Comprueba el importe vigente si presentas el plan en otro ejercicio
A23: LOCAL Y FIJOS
A24: Alquiler mensual del local (€) | B24: 3000 | C24: Dentro del rango 2.000-4.500 €/mes que declara este libro para un local de 80-120 m² en zona urbana, y respetando el techo del 10 % sobre ventas
A25: Fianza del alquiler (meses) | B25: 3 | C25: Tres meses de renta, como en el contrato tipo de local de negocio
A26: Suministros mensuales de luz, agua y gas (€) | B26: 1800 | C26: Luz, agua y gas de una cocina con horno, cámaras y campana: pide el histórico del local antes de firmar
A27: Seguros (€/año) | B27: 2000 | C27: Responsabilidad civil + multirriesgo del local + convenio
A28: Varios e imprevistos sobre ventas | B28: 0.02 | C28: Colchón de gasto corriente no presupuestado
A29: FINANCIACIÓN
A30: Recursos propios aportados (€) | B30: 75000 | C30: Aportación de los socios. Con menos, el banco no entra: pide un 35-40 % de fondos propios sobre la inversión
A31: Préstamo bancario solicitado (€) | B31: 128000 | C31: Principal solicitado. La hoja de Financiación comprueba que origen y usos cuadran, y trae una celda que calcula el importe exacto que los ajusta
A32: Tipo de interés nominal anual | B32: 0.06 | C32: Tipo nominal anual; pide oferta a dos entidades y a una línea ICO antes de fijarlo
A33: Plazo del préstamo (años) | B33: 7 | C33: Años totales, carencia incluida
A34: Carencia de principal (años) | B34: 1 | C34: Primer año sólo intereses, que es cuando la caja está más tensa
A35: Fondo de maniobra (meses de costes fijos) | B35: 3 | C35: Mínimo que exige este mismo libro: «Fondo de maniobra: mínimo 3 meses de costes fijos antes de abrir»
A36: FISCAL
A37: Impuesto de Sociedades, nueva creación | B37: 0.15 | C37: Art. 29.1 LIS: el PRIMER ejercicio con base imponible positiva y el SIGUIENTE. El libro lo aproxima contando los dos primeros ejercicios con base positiva: coincide con la ley salvo que entre ellos haya un ejercicio en pérdidas
A38: Impuesto de Sociedades, tipo general | B38: 0.25 | C38: A partir del tercer ejercicio con base positiva. Es el tipo general del art. 29.1 LIS: si tu cifra de negocios queda por debajo de 1 M € (microempresa) o de 10 M € (reducida dimensión), desde 2025 hay tipos más bajos que se implantan de forma gradual; confirma el de tu ejercicio con tu asesor y cámbialo aquí
A39: IVA repercutido de restauración | B39: 0.1 | C39: Tipo reducido de hostelería
A40: IVA repercutido/soportado general | B40: 0.21 | C40: Tipo general. En este libro lo usan dos cosas: el IVA que soportas al comprar el alcohol (el proveedor lo factura al 21 %) y el que repercutes por el alcohol que sale por delivery (es una entrega de bienes). El alcohol servido en sala va al reducido: su tipo está en el bloque de desglose del IVA. Suministros, equipamiento y servicios tienen su tipo en la celda de abajo. El libro manda al general sólo el alcohol: si compras refrescos o zumos con azúcares añadidos, su factura también va al 21 % (art. 91.Uno.1.1.º de la Ley 37/1992)
...

Sheet 1. Inversión Inicial
A1: ChefBusiness Consultoría Gastronómica
A2: Inversión Inicial — Bar-Restaurante
A3: Plan de Negocio: Bar-Restaurante / Restaurante Casual — España 2026
A5: Concepto | B5: Importe | C5: % s/inversión | D5: Notas | E5: ¿Lleva IVA?
A6: LOCAL Y ACONDICIONAMIENTO | B6: =IFERROR(IF(COUNT(B7:B13)=0,"",SUM(B7:B13)),"") -> 53650 | C6: =IFERROR(B6/$B$48,"") -> 0.29969589
A7: Honorarios inmobiliaria | B7: 1500 | C7: =IFERROR(B7/$B$48,"") -> 0.0083791955 | D7: Medio mes de alquiler | E7: Sí
A8: Obra civil y reforma local | B8: 25000 | C8: =IFERROR(B8/$B$48,"") -> 0.13965326 | D8: Cocina, extracción, instalaciones, suelo, pintura | E8: Sí
A9: Proyecto técnico + licencia actividad | B9: 3500 | C9: =IFERROR(B9/$B$48,"") -> 0.019551456 | D9: Ingeniero + tasas ayuntamiento | E9: Sí
A10: Decoración e interiorismo | B10: 8000 | C10: =IFERROR(B10/$B$48,"") -> 0.044689042 | D10: Mobiliario sala, iluminación, rotulación | E10: Sí
A11: Fianza del alquiler | B11: =IFERROR(IF('0. Supuestos'!$B$24="","",'0. Supuestos'!$B$24*'0. Supuestos'!$B$25),"") -> 9000 | C11: =IFERROR(B11/$B$48,"") -> 0.050275173 | D11: =IFERROR(""&TEXT('0. Supuestos'!$B$25,"0")&" meses de renta, al tipo de la hoja de Supuestos. Es un activo recuperable al cerrar: ni se amortiza ni lleva IVA","") -> 3 meses de renta, al tipo de la hoja de Supuestos. Es un activo recuperable al cerrar: ni se amortiza ni lleva IVA | E11: No
A12: Alquiler de los meses previos a la apertura | B12: =IFERROR(IF('0. Supuestos'!$B$24="","",'0. Supuestos'!$B$24*'0. Supuestos'!$B$54),"") -> 3000 | C12: =IFERROR(B12/$B$48,"") -> 0.016758391 | D12: =IFERROR("Renta "&IF('0. Supuestos'!$B$54=1,"del mes","de los "&TEXT('0. Supuestos'!$B$54,"0")&" meses")&" de obra y licencias. NO se solapa con el P&L, que arranca el día de la apertura: los doce meses del P&L son los doce de explotación","") -> Renta del mes de obra y licencias. NO se solapa con el P&L, que arranca el día de la apertura: los doce meses del P&L son los doce de explotación | E12: Sí
A13: Imprevistos de obra y acondicionamiento | B13: =IFERROR(IF(COUNT(B8,B9,B10)=0,"",ROUND((B8+B9+B10)*'0. Supuestos'!$B$55,0)),"") -> 3650 | C13: =IFERROR(B13/$B$48,"") -> 0.020389376 | D13: =IFERROR("Al "&TEXT('0. Supuestos'!$B$55,"0%")&" de las partidas de OBRA Y ACONDICIONAMIENTO de este bloque (Obra civil y reforma local, Proyecto técnico + licencia actividad y Decoración e interiorismo), no del bloque entero: el resto de partidas del bloque quedan fuera. Un banco no "&"financia una reforma sin colchón: el porcentaje está en la hoja de Supuestos","") -> Al 10% de las partidas de OBRA Y ACONDICIONAMIENTO de este bloque (Obra civil y reforma local, Proyecto técnico + licencia actividad y Decoración e interiorismo), no del bloque entero: el resto de partidas del bloque quedan fuera. Un banco no financia una reforma sin colchón: el porcentaje está en la hoja de Supuestos | E13: Sí
A14: EQUIPAMIENTO COCINA | B14: =IFERROR(IF(COUNT(B15:B24)=0,"",SUM(B15:B24)),"") -> 25700 | C14: =IFERROR(B14/$B$48,"") -> 0.14356355
A15: Cocina industrial (fuegos + plancha) | B15: 4500 | C15: =IFERROR(B15/$B$48,"") -> 0.025137586 | D15: 4 fuegos + plancha 80cm | E15: Sí
A16: Horno mixto (convección + vapor) | B16: 5500 | C16: =IFERROR(B16/$B$48,"") -> 0.030723717 | D16: 10 bandejas GN 1/1 | E16: Sí
A17: Freidora profesional | B17: 800 | C17: =IFERROR(B17/$B$48,"") -> 0.0044689042 | D17: 2 cubetas x 8L | E17: Sí
A18: Mesa refrigerada bajo mostrador | B18: 2200 | C18: =IFERROR(B18/$B$48,"") -> 0.012289487 | D18: 3 puertas, 400L | E18: Sí
A19: Cámara frigorífica | B19: 3500 | C19: =IFERROR(B19/$B$48,"") -> 0.019551456 | D19: Positiva + negativa | E19: Sí
A20: Campana extractora + motor | B20: 3000 | C20: =IFERROR(B20/$B$48,"") -> 0.016758391 | D20: Instalación incluida | E20: Sí
A21: Lavavajillas industrial | B21: 2800 | C21: =IFERROR(B21/$B$48,"") -> 0.015641165 | D21: Cesta 50x50 | E21: Sí
A22: Menaje y utensilios cocina | B22: 2000 | C22: =IFERROR(B22/$B$48,"") -> 0.011172261 | D22: Sartenes, ollas, GN, cuchillos, tablas | E22: Sí
A23: Fregadero industrial doble seno | B23: 600 | C23: =IFERROR(B23/$B$48,"") -> 0.0033516782 | E23: Sí
A24: Estanterías inox almacén | B24: 800 | C24: =IFERROR(B24/$B$48,"") -> 0.0044689042 | D24: 4 niveles x 3 unidades | E24: Sí
A25: EQUIPAMIENTO SALA Y BARRA | B25: =IFERROR(IF(COUNT(B26:B35)=0,"",SUM(B26:B35)),"") -> 21760 | C25: =IFERROR(B25/$B$48,"") -> 0.1215542
A26: Barra de bar (fabricación + instalación) | B26: 4000 | C26: =IFERROR(B26/$B$48,"") -> 0.022344521 | D26: 5 metros lineales | E26: Sí
A27: Mesas y sillas (12 mesas x 4 sillas) | B27: 3600 | C27: =IFERROR(B27/$B$48,"") -> 0.020110069 | D27: Set 120 €/mesa | E27: Sí
A28: Taburetes barra (8 unidades) | B28: 960 | C28: =IFERROR(B28/$B$48,"") -> 0.0053626851 | D28: 120 €/ud | E28: Sí
A29: Cafetera espresso profesional | B29: 3500 | C29: =IFERROR(B29/$B$48,"") -> 0.019551456 | D29: 2 grupos | E29: Sí
A30: Molinillo café profesional | B30: 500 | C30: =IFERROR(B30/$B$48,"") -> 0.0027930652 | E30: Sí
A31: Grifo cerveza (2 tomas) | B31: 1200 | C31: =IFERROR(B31/$B$48,"") -> 0.0067033564 | D31: Instalación + barril inicial | E31: Sí
A32: Vinoteca / nevera vinos | B32: 800 | C32: =IFERROR(B32/$B$48,"") -> 0.0044689042 | D32: 24 botellas | E32: Sí
A33: Cristalería, vajilla, cubertería | B33: 1500 | C33: =IFERROR(B33/$B$48,"") -> 0.0083791955 | D33: Servicio completo 50 pax | E33: Sí
A34: TPV + software hostelería | B34: 1500 | C34: =IFERROR(B34/$B$48,"") -> 0.0083791955 | D34: Terminal + licencia anual | E34: Sí
A35: Mobiliario y toldo de terraza | B35: 4200 | C35: =IFERROR(B35/$B$48,"") -> 0.023461747 | D35: Mesas, sillas, toldo y estufas para las plazas de terraza que describe el plan. Ponlo a 0 si tu local no tiene terraza o si la licencia no sale | E35: Sí
A36: MARKETING Y LANZAMIENTO | B36: =IFERROR(IF(COUNT(B37:B39)=0,"",SUM(B37:B39)),"") -> 4000 | C36: =IFERROR(B36/$B$48,"") -> 0.022344521
A37: Diseño marca e identidad visual | B37: 1500 | C37: =IFERROR(B37/$B$48,"") -> 0.0083791955 | D37: Logo, carta, señalética | E37: Sí
A38: Web + Google My Business | B38: 1000 | C38: =IFERROR(B38/$B$48,"") -> 0.0055861303 | D38: Página básica + ficha GMB | E38: Sí
A39: Campaña lanzamiento RRSS + inauguración | B39: 1500 | C39: =IFERROR(B39/$B$48,"") -> 0.0083791955 | D39: 3 meses iniciales | E39: Sí
A40: GASTOS LEGALES Y CONSTITUCIÓN | B40: =IFERROR(IF(COUNT(B41:B42)=0,"",SUM(B41:B42)),"") -> 1100 | C40: =IFERROR(B40/$B$48,"") -> 0.0061447433
A41: Constitución SL (notaría + registro) | B41: 600 | C41: =IFERROR(B41/$B$48,"") -> 0.0033516782 | D41: Capital social mín. 1 € (Ley Crea y Crece) | E41: No
...

Sheet 2. P&L 3 Años
A1: ChefBusiness Consultoría Gastronómica
A2: Cuenta de Resultados Previsional — 3 Años
A3: Plan de Negocio: Bar-Restaurante / Restaurante Casual — España 2026
A5: Concepto | B5: Año 1 | C5: Año 2 | D5: Año 3 | E5: % s/ventas (año 1) | F5: Notas | G5: Tipo de IVA de la línea (%)
A6: INGRESOS
A7: Cubiertos/día (media) | B7: =IFERROR(IF('0. Supuestos'!$B$4="","",'0. Supuestos'!$B$4),"") -> 80 | C7: =IFERROR(B7*(1+'0. Supuestos'!$B$7),"") -> 88 | D7: =IFERROR(C7*(1+'0. Supuestos'!$B$8),"") -> 93.28 | F7: El crecimiento de los años 2 y 3 está en la hoja de Supuestos
A8: Ticket medio sin IVA | B8: =IFERROR(IF('0. Supuestos'!$B$5="","",'0. Supuestos'!$B$5),"") -> 18.2 | C8: =IFERROR(IF(B8="","",B8),"") -> 18.2 | D8: =IFERROR(IF(C8="","",C8),"") -> 18.2 | F8: Constante en euros del año 1: una subida de precios es una decisión aparte
A9: Días de apertura al año | B9: =IFERROR(IF('0. Supuestos'!$B$6="","",'0. Supuestos'!$B$6),"") -> 310 | C9: =IFERROR(IF(B9="","",B9),"") -> 310 | D9: =IFERROR(IF(C9="","",C9),"") -> 310
A10: INGRESOS TOTALES (sin IVA) | B10: =IFERROR(IF(B7*B8*B9=0,"",B7*B8*B9),"") -> 451360 | C10: =IFERROR(IF(C7*C8*C9=0,"",C7*C8*C9),"") -> 496496 | D10: =IFERROR(IF(D7*D8*D9=0,"",D7*D8*D9),"") -> 526285.76 | E10: =IFERROR(IF(B10="","",1),"") -> 1
A11: Ventas de comida (cocina y barra) | B11: =IFERROR(IF(B10="","",B10*$E$11),"") -> 293384 | C11: =IFERROR(IF(C10="","",C10*$E$11),"") -> 322722.4 | D11: =IFERROR(IF(D10="","",D10*$E$11),"") -> 342085.74 | E11: =IFERROR(IF('0. Supuestos'!$B$11="","",'0. Supuestos'!$B$11),"") -> 0.65 | F11: Menú del mediodía, carta y raciones | G11: =IFERROR(IF(B10="","",'0. Supuestos'!$B$39),"") -> 0.1
A12: Ventas de bebida (cañas, vinos, cafés y copas) | B12: =IFERROR(IF(B10="","",B10*$E$12),"") -> 157976 | C12: =IFERROR(IF(C10="","",C10*$E$12),"") -> 173773.6 | D12: =IFERROR(IF(D10="","",D10*$E$12),"") -> 184200.02 | E12: =IFERROR(IF('0. Supuestos'!$B$12="","",'0. Supuestos'!$B$12),"") -> 0.35 | F12: Se calcula como el resto: comida + bebida = 100 % | G12: =IFERROR(IF(B10="","",('0. Supuestos'!$B$62*((1-'0. Supuestos'!$B$16)*'0. Supuestos'!$B$63+'0. Supuestos'!$B$16*'0. Supuestos'!$B$40)+(1-'0. Supuestos'!$B$62)*'0. Supuestos'!$B$39)),"") -> 0.1
A13: COSTES VARIABLES
A14: Coste de mercancía — comida | B14: =IFERROR(IF(B10="","",B10*'0. Supuestos'!$B$11*'0. Supuestos'!$B$13),"") -> 88015.2 | C14: =IFERROR(IF(C10="","",C10*'0. Supuestos'!$B$11*'0. Supuestos'!$B$13),"") -> 96816.72 | D14: =IFERROR(IF(D10="","",D10*'0. Supuestos'!$B$11*'0. Supuestos'!$B$13),"") -> 102625.72 | E14: =IFERROR(B14/$B$10,"") -> 0.195 | F14: =IFERROR("Al "&TEXT('0. Supuestos'!$B$13,"0%")&" de las ventas de COMIDA, no del total: la bebida tiene su propia línea","") -> Al 30% de las ventas de COMIDA, no del total: la bebida tiene su propia línea | G14: =IFERROR(IF(B10="","",'0. Supuestos'!$B$39),"") -> 0.1
A15: Coste de mercancía — bebida | B15: =IFERROR(IF(B10="","",B10*'0. Supuestos'!$B$12*'0. Supuestos'!$B$14),"") -> 34754.72 | C15: =IFERROR(IF(C10="","",C10*'0. Supuestos'!$B$12*'0. Supuestos'!$B$14),"") -> 38230.192 | D15: =IFERROR(IF(D10="","",D10*'0. Supuestos'!$B$12*'0. Supuestos'!$B$14),"") -> 40524.004 | E15: =IFERROR(B15/$B$10,"") -> 0.077 | F15: =IFERROR("Al "&TEXT('0. Supuestos'!$B$14,"0%")&" de las ventas de BEBIDA","") -> Al 22% de las ventas de BEBIDA | G15: =IFERROR(IF(B10="","",('0. Supuestos'!$B$62*'0. Supuestos'!$B$40+(1-'0. Supuestos'!$B$62)*'0. Supuestos'!$B$39)),"") -> 0.166
A16: Consumibles y envases | B16: =IFERROR(IF(B10="","",B10*'0. Supuestos'!$B$15),"") -> 6770.4 | C16: =IFERROR(IF(C10="","",C10*'0. Supuestos'!$B$15),"") -> 7447.44 | D16: =IFERROR(IF(D10="","",D10*'0. Supuestos'!$B$15),"") -> 7894.2864 | E16: =IFERROR(B16/$B$10,"") -> 0.015 | G16: =IFERROR(IF(B10="","",'0. Supuestos'!$B$41),"") -> 0.21
A17: Comisiones de delivery | B17: =IFERROR(IF(B10="","",B10*'0. Supuestos'!$B$16*'0. Supuestos'!$B$17),"") -> 0 | C17: =IFERROR(IF(C10="","",C10*'0. Supuestos'!$B$16*'0. Supuestos'!$B$17),"") -> 0 | D17: =IFERROR(IF(D10="","",D10*'0. Supuestos'!$B$16*'0. Supuestos'!$B$17),"") -> 0 | E17: =IFERROR(B17/$B$10,"") -> 0 | F17: Sobre las ventas DEL CANAL. Con 0 % de delivery en Supuestos, esta línea vale cero | G17: =IFERROR(IF(B10="","",'0. Supuestos'!$B$41),"") -> 0.21
A18: Comisiones de los medios de pago | B18: =IFERROR(IF(B10="","",B10*'0. Supuestos'!$B$18),"") -> 3610.88 | C18: =IFERROR(IF(C10="","",C10*'0. Supuestos'!$B$18),"") -> 3971.968 | D18: =IFERROR(IF(D10="","",D10*'0. Supuestos'!$B$18),"") -> 4210.2861 | E18: =IFERROR(B18/$B$10,"") -> 0.008 | F18: Las comisiones de los medios de pago están EXENTAS de IVA (art. 20.Uno.18 LIVA): no se deduce nada por ellas | G18: 0
A19: Varios e imprevistos | B19: =IFERROR(IF(B10="","",B10*'0. Supuestos'!$B$28),"") -> 9027.2 | C19: =IFERROR(IF(C10="","",C10*'0. Supuestos'!$B$28),"") -> 9929.92 | D19: =IFERROR(IF(D10="","",D10*'0. Supuestos'!$B$28),"") -> 10525.715 | E19: =IFERROR(B19/$B$10,"") -> 0.02 | F19: =IFERROR("Al "&TEXT('0. Supuestos'!$B$28,"0%")&" de las ventas. Es un coste VARIABLE: sube y baja con la facturación, así que no puede vivir en los costes fijos","") -> Al 2% de las ventas. Es un coste VARIABLE: sube y baja con la facturación, así que no puede vivir en los costes fijos | G19: =IFERROR(IF(B10="","",'0. Supuestos'!$B$41),"") -> 0.21
A20: TOTAL COSTES VARIABLES | B20: =IFERROR(IF(B10="","",SUM(B14:B19)),"") -> 142178.4 | C20: =IFERROR(IF(C10="","",SUM(C14:C19)),"") -> 156396.24 | D20: =IFERROR(IF(D10="","",SUM(D14:D19)),"") -> 165780.01 | E20: =IFERROR(B20/$B$10,"") -> 0.315
A21: MARGEN BRUTO | B21: =IFERROR(IF(B10="","",B10-B20),"") -> 309181.6 | C21: =IFERROR(IF(C10="","",C10-C20),"") -> 340099.76 | D21: =IFERROR(IF(D10="","",D10-D20),"") -> 360505.75 | E21: =IFERROR(B21/$B$10,"") -> 0.685
A22: COSTES FIJOS
A23: Alquiler del local | B23: =IFERROR(IF(B10="","",'0. Supuestos'!$B$24*12),"") -> 36000 | C23: =IFERROR(IF(C10="","",B23*(1+'0. Supuestos'!$B$48)),"") -> 36000 | D23: =IFERROR(IF(D10="","",C23*(1+'0. Supuestos'!$B$48)),"") -> 36000 | E23: =IFERROR(B23/$B$10,"") -> 0.079758951 | F23: El importe mensual está en la hoja de Supuestos; aquí se multiplica por doce. La renta de los meses de obra, que es anterior a la apertura, está en la hoja de Inversión y NO se cuenta dos veces | G23: =IFERROR(IF(B10="","",'0. Supuestos'!$B$41),"") -> 0.21
A24: Personal (nóminas + Seguridad Social) | B24: =IFERROR(IF(B10="","",'5. Personal'!$G$13),"") -> 151939.2 | C24: =IFERROR(IF(C10="","",'5. Personal'!$B$17),"") -> 157939.2 | D24: =IFERROR(IF(D10="","",'5. Personal'!$B$18),"") -> 163939.2 | E24: =IFERROR(B24/$B$10,"") -> 0.33662531 | F24: Sale de la hoja de Personal: es el MISMO número, no una estimación aparte. Los años 2 y 3 suman las INCORPORACIONES declaradas en esa hoja, no un porcentaje de volumen | G24: 0
A25: Suministros (luz, agua, gas) | B25: =IFERROR(IF(B10="","",'0. Supuestos'!$B$26*12),"") -> 21600 | C25: =IFERROR(IF(C10="","",B25*(1+'0. Supuestos'!$B$48)),"") -> 21600 | D25: =IFERROR(IF(D10="","",C25*(1+'0. Supuestos'!$B$48)),"") -> 21600 | E25: =IFERROR(B25/$B$10,"") -> 0.04785537 | F25: Luz y gas van al 21 %; la factura del agua, al 10 %. El libro aplica a toda esta partida el tipo de la columna de al lado (21 %): si el agua pesa mucho en tu local, sepárala en su línea | G25: =IFERROR(IF(B10="","",'0. Supuestos'!$B$41),"") -> 0.21
A26: Seguros (RC + multirriesgo) | B26: =IFERROR(IF(B10="","",'0. Supuestos'!$B$27),"") -> 2000 | C26: =IFERROR(IF(C10="","",B26*(1+'0. Supuestos'!$B$48)),"") -> 2000 | D26: =IFERROR(IF(D10="","",C26*(1+'0. Supuestos'!$B$48)),"") -> 2000 | E26: =IFERROR(B26/$B$10,"") -> 0.0044310528 | F26: Las operaciones de seguro están EXENTAS de IVA (art. 20.Uno.16 LIVA): la prima no lleva IVA deducible | G26: 0
A27: Gestoría + contabilidad | B27: 1800 | C27: =IFERROR(IF(C10="","",B27*(1+'0. Supuestos'!$B$48)),"") -> 1800 | D27: =IFERROR(IF(D10="","",C27*(1+'0. Supuestos'!$B$48)),"") -> 1800 | E27: =IFERROR(B27/$B$10,"") -> 0.0039879475 | G27: =IFERROR(IF(B10="","",'0. Supuestos'!$B$41),"") -> 0.21
A28: Marketing y publicidad | B28: 6000 | C28: =IFERROR(IF(C10="","",B28*(1+'0. Supuestos'!$B$48)),"") -> 6000 | D28: =IFERROR(IF(D10="","",C28*(1+'0. Supuestos'!$B$48)),"") -> 6000 | E28: =IFERROR(B28/$B$10,"") -> 0.013293158 | G28: =IFERROR(IF(B10="","",'0. Supuestos'!$B$41),"") -> 0.21
A29: Mantenimiento y reparaciones | B29: 2400 | C29: =IFERROR(IF(C10="","",B29*(1+'0. Supuestos'!$B$48)),"") -> 2400 | D29: =IFERROR(IF(D10="","",C29*(1+'0. Supuestos'!$B$48)),"") -> 2400 | E29: =IFERROR(B29/$B$10,"") -> 0.0053172634 | G29: =IFERROR(IF(B10="","",'0. Supuestos'!$B$41),"") -> 0.21
A30: Software (TPV, reservas, RRSS) | B30: 1800 | C30: =IFERROR(IF(C10="","",B30*(1+'0. Supuestos'!$B$48)),"") -> 1800 | D30: =IFERROR(IF(D10="","",C30*(1+'0. Supuestos'!$B$48)),"") -> 1800 | E30: =IFERROR(B30/$B$10,"") -> 0.0039879475 | G30: =IFERROR(IF(B10="","",'0. Supuestos'!$B$41),"") -> 0.21
A31: Limpieza, lavandería y lencería | B31: 3600 | C31: =IFERROR(IF(C10="","",B31*(1+'0. Supuestos'!$B$48)),"") -> 3600 | D31: =IFERROR(IF(D10="","",C31*(1+'0. Supuestos'!$B$48)),"") -> 3600 | E31: =IFERROR(B31/$B$10,"") -> 0.0079758951 | F31: Mantelería, paños y uniformes. Pide presupuesto en tu zona: es un importe orientativo y editable | G31: =IFERROR(IF(B10="","",'0. Supuestos'!$B$41),"") -> 0.21
A32: Gestión de residuos y de aceite vegetal usado | B32: 1200 | C32: =IFERROR(IF(C10="","",B32*(1+'0. Supuestos'!$B$48)),"") -> 1200 | D32: =IFERROR(IF(D10="","",C32*(1+'0. Supuestos'!$B$48)),"") -> 1200 | E32: =IFERROR(B32/$B$10,"") -> 0.0026586317 | F32: Gestor autorizado. Lo pide la inspección y el aceite no puede ir al desagüe | G32: =IFERROR(IF(B10="","",'0. Supuestos'!$B$41),"") -> 0.21
A33: Desinsectación, desratización y desinfección (DDD) | B33: 900 | C33: =IFERROR(IF(C10="","",B33*(1+'0. Supuestos'!$B$48)),"") -> 900 | D33: =IFERROR(IF(D10="","",C33*(1+'0. Supuestos'!$B$48)),"") -> 900 | E33: =IFERROR(B33/$B$10,"") -> 0.0019939738 | F33: Empresa inscrita en el ROESB; forma parte del plan APPCC | G33: =IFERROR(IF(B10="","",'0. Supuestos'!$B$41),"") -> 0.21
A34: Derechos de autor por música ambiental | B34: 900 | C34: =IFERROR(IF(C10="","",B34*(1+'0. Supuestos'!$B$48)),"") -> 900 | D34: =IFERROR(IF(D10="","",C34*(1+'0. Supuestos'!$B$48)),"") -> 900 | E34: =IFERROR(B34/$B$10,"") -> 0.0019939738 | F34: SGAE y AGEDI-AIE son dos licencias distintas; el importe depende de los metros y del aforo | G34: =IFERROR(IF(B10="","",'0. Supuestos'!$B$41),"") -> 0.21
A35: Prevención de riesgos laborales y vigilancia de la salud | B35: 600 | C35: =IFERROR(IF(C10="","",B35*(1+'0. Supuestos'!$B$48)),"") -> 600 | D35: =IFERROR(IF(D10="","",C35*(1+'0. Supuestos'!$B$48)),"") -> 600 | E35: =IFERROR(B35/$B$10,"") -> 0.0013293158 | F35: El plan de prevención es obligatorio; el proveedor externo, no (art. 30.5 de la Ley 31/1995) | G35: =IFERROR(IF(B10="","",'0. Supuestos'!$B$41),"") -> 0.21
A36: Comisiones de reservas online | B36: 2400 | C36: =IFERROR(IF(C10="","",B36*(1+'0. Supuestos'!$B$48)),"") -> 2400 | D36: =IFERROR(IF(D10="","",C36*(1+'0. Supuestos'!$B$48)),"") -> 2400 | E36: =IFERROR(B36/$B$10,"") -> 0.0053172634 | F36: TheFork y similares cobran por comensal sentado: mira la letra pequeña antes de firmar | G36: =IFERROR(IF(B10="","",'0. Supuestos'!$B$41),"") -> 0.21
A37: Reposición de menaje, cristalería y vajilla | B37: 2400 | C37: =IFERROR(IF(C10="","",B37*(1+'0. Supuestos'!$B$48)),"") -> 2400 | D37: =IFERROR(IF(D10="","",C37*(1+'0. Supuestos'!$B$48)),"") -> 2400 | E37: =IFERROR(B37/$B$10,"") -> 0.0053172634 | F37: Roturas del ejercicio. En un casual con barra se rompe más de lo que se presupuesta | G37: =IFERROR(IF(B10="","",'0. Supuestos'!$B$41),"") -> 0.21
A38: Amortización del inmovilizado | B38: =IFERROR(IF(B10="","",'1. Inversión Inicial'!$B$55),"") -> 8761 | C38: =IFERROR(IF(C10="","",B38),"") -> 8761 | D38: =IFERROR(IF(D10="","",B38),"") -> 8761 | E38: =IFERROR(B38/$B$10,"") -> 0.019410227 | F38: Sale de las bases de amortización de la hoja de Inversión: sólo inmovilizado real. NO sube con el IPC: es una cuota sobre el coste HISTÓRICO del inmovilizado | G38: 0
A39: Gastos financieros (intereses del préstamo) | B39: =IFERROR(IF(B10="","",'7. Financiación'!$B$44),"") -> 7680 | C39: =IFERROR(IF(C10="","",'7. Financiación'!$B$46),"") -> 7680 | D39: =IFERROR(IF(D10="","",'7. Financiación'!$B$48),"") -> 6578.975 | E39: =IFERROR(B39/$B$10,"") -> 0.017015243 | F39: Sólo los INTERESES son gasto. La devolución del principal va en la hoja de Tesorería | G39: 0
A40: TOTAL COSTES FIJOS | B40: =IFERROR(IF(B10="","",SUM(B23:B39)),"") -> 251980.2 | C40: =IFERROR(IF(C10="","",SUM(C23:C39)),"") -> 257980.2 | D40: =IFERROR(IF(D10="","",SUM(D23:D39)),"") -> 262879.18 | E40: =IFERROR(B40/$B$10,"") -> 0.55826879
A41: IVA soportado de los costes variables | B41: =IFERROR(IF(B10="","",SUMPRODUCT(B14:B19,G14:G19)),"") -> 17888.3 | C41: =IFERROR(IF(C10="","",SUMPRODUCT(C14:C19,G14:G19)),"") -> 19677.129 | D41: =IFERROR(IF(D10="","",SUMPRODUCT(D14:D19,G14:G19)),"") -> 20857.757 | F41: Cada línea a SU tipo, leído de la columna de al lado. Es lo que la hoja de Tesorería paga de más a los proveedores y luego se deduce
...

Sheet 3. Punto Equilibrio
A1: ChefBusiness Consultoría Gastronómica
A2: Punto de Equilibrio (Break-Even) — Bar-Restaurante
A3: Plan de Negocio: Bar-Restaurante / Restaurante Casual — España 2026
A5: Variable | B5: Año 1 | C5: Año 2 | D5: Año 3 | E5: Notas
A6: DATOS BASE POR AÑO
A7: Costes fijos anuales | B7: =IFERROR(IF('2. P&L 3 Años'!$B$10="","",'2. P&L 3 Años'!$B$40),"") -> 251980.2 | C7: =IFERROR(IF('2. P&L 3 Años'!$C$10="","",'2. P&L 3 Años'!$C$40),"") -> 257980.2 | D7: =IFERROR(IF('2. P&L 3 Años'!$D$10="","",'2. P&L 3 Años'!$D$40),"") -> 262879.18 | E7: Los MISMOS costes fijos del P&L. Cada año tiene los suyos: por eso el umbral no puede ser uno solo para los tres
A8: Costes fijos mensuales | B8: =IFERROR(IF('2. P&L 3 Años'!$B$10="","",B7/12),"") -> 20998.35 | C8: =IFERROR(IF('2. P&L 3 Años'!$C$10="","",C7/12),"") -> 21498.35 | D8: =IFERROR(IF('2. P&L 3 Años'!$D$10="","",D7/12),"") -> 21906.598
A9: Ticket medio sin IVA | B9: =IFERROR(IF('2. P&L 3 Años'!$B$10="","",'2. P&L 3 Años'!$B$8),"") -> 18.2 | C9: =IFERROR(IF('2. P&L 3 Años'!$C$10="","",'2. P&L 3 Años'!$C$8),"") -> 18.2 | D9: =IFERROR(IF('2. P&L 3 Años'!$D$10="","",'2. P&L 3 Años'!$D$8),"") -> 18.2
A10: Coste variable por cubierto | B10: =IFERROR(IF('2. P&L 3 Años'!$B$10="","",'2. P&L 3 Años'!$B$20/('2. P&L 3 Años'!$B$7*'2. P&L 3 Años'!$B$9)),"") -> 5.733 | C10: =IFERROR(IF('2. P&L 3 Años'!$C$10="","",'2. P&L 3 Años'!$C$20/('2. P&L 3 Años'!$C$7*'2. P&L 3 Años'!$C$9)),"") -> 5.733 | D10: =IFERROR(IF('2. P&L 3 Años'!$D$10="","",'2. P&L 3 Años'!$D$20/('2. P&L 3 Años'!$D$7*'2. P&L 3 Años'!$D$9)),"") -> 5.733 | E10: Sale del total de costes variables del P&L, no de una estimación aparte. Incluye los varios e imprevistos, que son un porcentaje de las ventas
A11: Margen de contribución por cubierto | B11: =IFERROR(IF('2. P&L 3 Años'!$B$10="","",B9-B10),"") -> 12.467 | C11: =IFERROR(IF('2. P&L 3 Años'!$C$10="","",C9-C10),"") -> 12.467 | D11: =IFERROR(IF('2. P&L 3 Años'!$D$10="","",D9-D10),"") -> 12.467 | E11: Ticket menos coste variable unitario
A12: Días de apertura al año | B12: =IFERROR(IF('2. P&L 3 Años'!$B$10="","",'2. P&L 3 Años'!$B$9),"") -> 310 | C12: =IFERROR(IF('2. P&L 3 Años'!$C$10="","",'2. P&L 3 Años'!$C$9),"") -> 310 | D12: =IFERROR(IF('2. P&L 3 Años'!$D$10="","",'2. P&L 3 Años'!$D$9),"") -> 310 | E12: El mismo calendario que el P&L y que los escenarios
A13: Devolución de principal del año (cuota) | B13: =IFERROR(IF('2. P&L 3 Años'!$B$10="","",'7. Financiación'!$B$45),"") -> 0 | C13: =IFERROR(IF('2. P&L 3 Años'!$C$10="","",'7. Financiación'!$B$47),"") -> 18350.416 | D13: =IFERROR(IF('2. P&L 3 Años'!$D$10="","",'7. Financiación'!$B$49),"") -> 19451.441 | E13: El principal NO es gasto del P&L, pero sale de la caja. Sin él, el umbral de equilibrio se publica por debajo del real
A14: PUNTO DE EQUILIBRIO CONTABLE (incluye amortización)
A15: Cubiertos necesarios al año | B15: =IFERROR(IF('2. P&L 3 Años'!$B$10="","",IF(B11<=0,"",B7/B11)),"") -> 20211.775 | C15: =IFERROR(IF('2. P&L 3 Años'!$C$10="","",IF(C11<=0,"",C7/C11)),"") -> 20693.046 | D15: =IFERROR(IF('2. P&L 3 Años'!$D$10="","",IF(D11<=0,"",D7/D11)),"") -> 21086.001
A16: Cubiertos necesarios al día | B16: =IFERROR(IF('2. P&L 3 Años'!$B$10="","",B15/B12),"") -> 65.199274 | C16: =IFERROR(IF('2. P&L 3 Años'!$C$10="","",C15/C12),"") -> 66.75176 | D16: =IFERROR(IF('2. P&L 3 Años'!$D$10="","",D15/D12),"") -> 68.019358
A17: Ingresos necesarios al año | B17: =IFERROR(IF('2. P&L 3 Años'!$B$10="","",B15*B9),"") -> 367854.31 | C17: =IFERROR(IF('2. P&L 3 Años'!$C$10="","",C15*C9),"") -> 376613.43 | D17: =IFERROR(IF('2. P&L 3 Años'!$D$10="","",D15*D9),"") -> 383765.22
A18: PUNTO DE EQUILIBRIO DE CAJA (incluye la cuota del préstamo)
A19: Costes fijos de caja + principal del año | B19: =IFERROR(IF('2. P&L 3 Años'!$B$10="","",B7-'2. P&L 3 Años'!$B$38+B13),"") -> 243219.2 | C19: =IFERROR(IF('2. P&L 3 Años'!$C$10="","",C7-'2. P&L 3 Años'!$C$38+C13),"") -> 267569.62 | D19: =IFERROR(IF('2. P&L 3 Años'!$D$10="","",D7-'2. P&L 3 Años'!$D$38+D13),"") -> 273569.62 | E19: Los fijos del P&L sin la amortización (que no se paga) y CON la devolución de principal (que sí). Es el umbral que decide si la caja aguanta
A20: Cubiertos necesarios al año (caja) | B20: =IFERROR(IF('2. P&L 3 Años'!$B$10="","",IF(B11<=0,"",B19/B11)),"") -> 19509.04 | C20: =IFERROR(IF('2. P&L 3 Años'!$C$10="","",IF(C11<=0,"",C19/C11)),"") -> 21462.23 | D20: =IFERROR(IF('2. P&L 3 Años'!$D$10="","",IF(D11<=0,"",D19/D11)),"") -> 21943.5
A21: Cubiertos necesarios al día (caja) | B21: =IFERROR(IF('2. P&L 3 Años'!$B$10="","",B20/B12),"") -> 62.932387 | C21: =IFERROR(IF('2. P&L 3 Años'!$C$10="","",C20/C12),"") -> 69.232999 | D21: =IFERROR(IF('2. P&L 3 Años'!$D$10="","",D20/D12),"") -> 70.785484
A22: Ingresos necesarios al año (caja) | B22: =IFERROR(IF('2. P&L 3 Años'!$B$10="","",B20*B9),"") -> 355064.53 | C22: =IFERROR(IF('2. P&L 3 Años'!$C$10="","",C20*C9),"") -> 390612.58 | D22: =IFERROR(IF('2. P&L 3 Años'!$D$10="","",D20*D9),"") -> 399371.7
A23: CONTRASTE CON EL PLAN
A24: Cubiertos/día previstos en el plan | B24: =IFERROR(IF('2. P&L 3 Años'!$B$10="","",'2. P&L 3 Años'!$B$7),"") -> 80 | C24: =IFERROR(IF('2. P&L 3 Años'!$C$10="","",'2. P&L 3 Años'!$C$7),"") -> 88 | D24: =IFERROR(IF('2. P&L 3 Años'!$D$10="","",'2. P&L 3 Años'!$D$7),"") -> 93.28
A25: Holgura sobre el equilibrio de CAJA (%) | B25: =IFERROR(IF('2. P&L 3 Años'!$B$10="","",B24/B21-1),"") -> 0.27120556 | C25: =IFERROR(IF('2. P&L 3 Años'!$C$10="","",C24/C21-1),"") -> 0.27107018 | D25: =IFERROR(IF('2. P&L 3 Años'!$D$10="","",D24/D21-1),"") -> 0.3177843 | E25: Cuánto superan tus ventas previstas a las del equilibrio de caja. La caída que aguantas antes de no poder pagar los costes fijos y la cuota es algo menor: con un 25 % de holgura, un 20 %. El mínimo exigible está en la hoja de Supuestos
A26: Rotaciones al día que da el local como máximo | B26: 3 | E26: Servicios completos por plaza y día que puedes llegar a hacer con tu horario. Es el techo físico del local, no un objetivo
A27: Rotaciones al día que exige el equilibrio de caja | B27: =IFERROR(IF('2. P&L 3 Años'!$B$10="","",B21/'0. Supuestos'!$B$51),"") -> 1.1237926 | C27: =IFERROR(IF('2. P&L 3 Años'!$C$10="","",C21/'0. Supuestos'!$B$51),"") -> 1.2363035 | D27: =IFERROR(IF('2. P&L 3 Años'!$D$10="","",D21/'0. Supuestos'!$B$51),"") -> 1.2640265 | E27: Cubiertos de equilibrio entre las plazas que declara la hoja de Supuestos. Por encima del techo de arriba, el punto de equilibrio está fuera del alcance del local
A28: INTERPRETACIÓN
A29: =IFERROR("Con el ticket medio sin IVA de la fila de arriba necesitas "&TEXT(ROUNDUP(B16,0),"0")&" cubiertos al día durante los "&TEXT(B12,"0")&" días que abres para no perder dinero (equilibrio contable, con la amortización dentro), y "&TEXT(ROUNDUP(B21,0),"0")&" para que la caja aguante (equilibrio de caja: sin la amortización, que no se paga, y con la cuota del préstamo del año"&IF(B13=0,"; este año sólo intereses, porque el préstamo está en carencia","")&"). En las filas «Ingresos necesarios al año» tienes esas mismas cifras en euros.","") -> Con el ticket medio sin IVA de la fila de arriba necesitas 66 cubiertos al día durante los 310 días que abres para no perder dinero (equilibrio contable, con la amortización dentro), y 63 para que la caja aguante (equilibrio de caja: sin la amortización, que no se paga, y con la cuota del préstamo del año; este año sólo intereses, porque el préstamo está en carencia). En las filas «Ingresos necesarios al año» tienes esas mismas cifras en euros.
A31: SENSIBILIDAD DEL PUNTO DE EQUILIBRIO
A32: Cubiertos/día necesarios para cubrir costes según el ticket medio (columnas) y el coste variable por cubierto (filas). En verde, los que están por debajo de los cubiertos que prevé el plan.
A34: Cubiertos/día necesarios: ticket medio sin IVA (columnas) × coste variable por cubierto (filas) | B34: =IFERROR($B$9-2,"") -> 16.2 | C34: =IFERROR(IF($B$9="","",$B$9),"") -> 18.2 | D34: =IFERROR($B$9+2,"") -> 20.2 | E34: =IFERROR($B$9+4,"") -> 22.2
A35: =IFERROR($B$10*0.85,"") -> 4.87305 | B35: =IFERROR(IF($B$34-$A35<=0,"",$B$7/($B$34-$A35)/$B$12),"") -> 71.761538 | C35: =IFERROR(IF($C$34-$A35<=0,"",$B$7/($C$34-$A35)/$B$12),"") -> 60.992152 | D35: =IFERROR(IF($D$34-$A35<=0,"",$B$7/($D$34-$A35)/$B$12),"") -> 53.03334 | E35: =IFERROR(IF($E$34-$A35<=0,"",$B$7/($E$34-$A35)/$B$12),"") -> 46.911854
A36: =IFERROR($B$10*0.925,"") -> 5.303025 | B36: =IFERROR(IF($B$34-$A36<=0,"",$B$7/($B$34-$A36)/$B$12),"") -> 74.593119 | C36: =IFERROR(IF($C$34-$A36<=0,"",$B$7/($C$34-$A36)/$B$12),"") -> 63.025582 | D36: =IFERROR(IF($D$34-$A36<=0,"",$B$7/($D$34-$A36)/$B$12),"") -> 54.564054 | E36: =IFERROR(IF($E$34-$A36<=0,"",$B$7/($E$34-$A36)/$B$12),"") -> 48.105614
A37: =IFERROR($B$10*1.0,"") -> 5.733 | B37: =IFERROR(IF($B$34-$A37<=0,"",$B$7/($B$34-$A37)/$B$12),"") -> 77.657338 | C37: =IFERROR(IF($C$34-$A37<=0,"",$B$7/($C$34-$A37)/$B$12),"") -> 65.199274 | D37: =IFERROR(IF($D$34-$A37<=0,"",$B$7/($D$34-$A37)/$B$12),"") -> 56.185758 | E37: =IFERROR(IF($E$34-$A37<=0,"",$B$7/($E$34-$A37)/$B$12),"") -> 49.361715
A38: =IFERROR($B$10*1.075,"") -> 6.162975 | B38: =IFERROR(IF($B$34-$A38<=0,"",$B$7/($B$34-$A38)/$B$12),"") -> 80.984092 | C38: =IFERROR(IF($C$34-$A38<=0,"",$B$7/($C$34-$A38)/$B$12),"") -> 67.52826 | D38: =IFERROR(IF($D$34-$A38<=0,"",$B$7/($D$34-$A38)/$B$12),"") -> 57.906811 | E38: =IFERROR(IF($E$34-$A38<=0,"",$B$7/($E$34-$A38)/$B$12),"") -> 50.685171
A39: =IFERROR($B$10*1.15,"") -> 6.59295 | B39: =IFERROR(IF($B$34-$A39<=0,"",$B$7/($B$34-$A39)/$B$12),"") -> 84.608632 | C39: =IFERROR(IF($C$34-$A39<=0,"",$B$7/($C$34-$A39)/$B$12),"") -> 70.029797 | D39: =IFERROR(IF($D$34-$A39<=0,"",$B$7/($D$34-$A39)/$B$12),"") -> 59.736633 | E39: =IFERROR(IF($E$34-$A39<=0,"",$B$7/($E$34-$A39)/$B$12),"") -> 52.08155
A41: ChefBusiness.co — Plan de Negocio: Bar-Restaurante

Sheet 4. Escenarios
A1: ChefBusiness Consultoría Gastronómica
A2: Análisis de Escenarios — Año 1
A3: Plan de Negocio: Bar-Restaurante / Restaurante Casual — España 2026
A5: Métrica | B5: Pesimista | C5: Realista | D5: Optimista | E5: Notas
A6: Cubiertos/día | B6: 58 | C6: =IFERROR(IF('2. P&L 3 Años'!$B$7="","",'2. P&L 3 Años'!$B$7),"") -> 80 | D6: 95
A7: Ticket medio sin IVA | B7: 15.9 | C7: =IFERROR(IF('2. P&L 3 Años'!$B$8="","",'2. P&L 3 Años'!$B$8),"") -> 18.2 | D7: 18.5
A8: Días de apertura al año | B8: 300 | C8: =IFERROR(IF('2. P&L 3 Años'!$B$9="","",'2. P&L 3 Años'!$B$9),"") -> 310 | D8: 320
A9: INGRESOS ANUALES (sin IVA) | B9: =IFERROR(IF(B6*B7*B8=0,"",B6*B7*B8),"") -> 276660 | C9: =IFERROR(IF(C6*C7*C8=0,"",C6*C7*C8),"") -> 451360 | D9: =IFERROR(IF(D6*D7*D8=0,"",D6*D7*D8),"") -> 562400
A10: Coste de mercancía — comida | B10: =IFERROR(IF(B9="","",B9*'0. Supuestos'!$B$11*'0. Supuestos'!$B$13),"") -> 53948.7 | C10: =IFERROR(IF(C9="","",C9*'0. Supuestos'!$B$11*'0. Supuestos'!$B$13),"") -> 88015.2 | D10: =IFERROR(IF(D9="","",D9*'0. Supuestos'!$B$11*'0. Supuestos'!$B$13),"") -> 109668
A11: Coste de mercancía — bebida | B11: =IFERROR(IF(B9="","",B9*'0. Supuestos'!$B$12*'0. Supuestos'!$B$14),"") -> 21302.82 | C11: =IFERROR(IF(C9="","",C9*'0. Supuestos'!$B$12*'0. Supuestos'!$B$14),"") -> 34754.72 | D11: =IFERROR(IF(D9="","",D9*'0. Supuestos'!$B$12*'0. Supuestos'!$B$14),"") -> 43304.8
A12: Consumibles y envases | B12: =IFERROR(IF(B9="","",B9*'0. Supuestos'!$B$15),"") -> 4149.9 | C12: =IFERROR(IF(C9="","",C9*'0. Supuestos'!$B$15),"") -> 6770.4 | D12: =IFERROR(IF(D9="","",D9*'0. Supuestos'!$B$15),"") -> 8436
A13: Comisiones de delivery | B13: =IFERROR(IF(B9="","",B9*'0. Supuestos'!$B$16*'0. Supuestos'!$B$17),"") -> 0 | C13: =IFERROR(IF(C9="","",C9*'0. Supuestos'!$B$16*'0. Supuestos'!$B$17),"") -> 0 | D13: =IFERROR(IF(D9="","",D9*'0. Supuestos'!$B$16*'0. Supuestos'!$B$17),"") -> 0
A14: Comisiones de los medios de pago | B14: =IFERROR(IF(B9="","",B9*'0. Supuestos'!$B$18),"") -> 2213.28 | C14: =IFERROR(IF(C9="","",C9*'0. Supuestos'!$B$18),"") -> 3610.88 | D14: =IFERROR(IF(D9="","",D9*'0. Supuestos'!$B$18),"") -> 4499.2
A15: Varios e imprevistos | B15: =IFERROR(IF(B9="","",B9*'0. Supuestos'!$B$28),"") -> 5533.2 | C15: =IFERROR(IF(C9="","",C9*'0. Supuestos'!$B$28),"") -> 9027.2 | D15: =IFERROR(IF(D9="","",D9*'0. Supuestos'!$B$28),"") -> 11248
A16: TOTAL COSTES VARIABLES | B16: =IFERROR(IF(B9="","",SUM(B10:B15)),"") -> 87147.9 | C16: =IFERROR(IF(C9="","",SUM(C10:C15)),"") -> 142178.4 | D16: =IFERROR(IF(D9="","",SUM(D10:D15)),"") -> 177156
A17: MARGEN BRUTO | B17: =IFERROR(IF(B9="","",B9-B16),"") -> 189512.1 | C17: =IFERROR(IF(C9="","",C9-C16),"") -> 309181.6 | D17: =IFERROR(IF(D9="","",D9-D16),"") -> 385244
A18: COSTES FIJOS (los del P&L) | B18: =IFERROR(IF(B9="","",'2. P&L 3 Años'!$B$40),"") -> 251980.2 | C18: =IFERROR(IF(C9="","",'2. P&L 3 Años'!$B$40),"") -> 251980.2 | D18: =IFERROR(IF(D9="","",'2. P&L 3 Años'!$B$40),"") -> 251980.2 | E18: Los costes fijos no cambian con el escenario: por eso son fijos
A19: RESULTADO ANTES DE IMPUESTOS | B19: =IFERROR(IF(B9="","",B17-B18),"") -> -62468.1 | C19: =IFERROR(IF(C9="","",C17-C18),"") -> 57201.4 | D19: =IFERROR(IF(D9="","",D17-D18),"") -> 133263.8
A20: Impuesto de Sociedades | B20: =IFERROR(IF(B9="","",MAX(0,B19-'0. Supuestos'!$B$42)*'0. Supuestos'!$B$37),"") -> 0 | C20: =IFERROR(IF(C9="","",MAX(0,C19-'0. Supuestos'!$B$42)*'0. Supuestos'!$B$37),"") -> 8580.21 | D20: =IFERROR(IF(D9="","",MAX(0,D19-'0. Supuestos'!$B$42)*'0. Supuestos'!$B$37),"") -> 19989.57 | E20: Al tipo de entidad de nueva creación, compensando las bases negativas anteriores
A21: RESULTADO NETO | B21: =IFERROR(IF(B9="","",B19-B20),"") -> -62468.1 | C21: =IFERROR(IF(C9="","",C19-C20),"") -> 48621.19 | D21: =IFERROR(IF(D9="","",D19-D20),"") -> 113274.23
A22: Cubiertos/día para el equilibrio | B22: =IFERROR(IF(B9="","",IF(B7-B16/(B6*B8)<=0,"",B18/(B7-B16/(B6*B8))/B8)),"") -> 77.118303 | C22: =IFERROR(IF(C9="","",IF(C7-C16/(C6*C8)<=0,"",C18/(C7-C16/(C6*C8))/C8)),"") -> 65.199274 | D22: =IFERROR(IF(D9="","",IF(D7-D16/(D6*D8)<=0,"",D18/(D7-D16/(D6*D8))/D8)),"") -> 62.137552
A23: LO QUE CADA ESCENARIO EXIGE
A24: Coste de personal / Ventas | B24: =IFERROR(IF(B9="","",'2. P&L 3 Años'!$B$24/B9),"") -> 0.54919106 | C24: =IFERROR(IF(C9="","",'2. P&L 3 Años'!$B$24/C9),"") -> 0.33662531 | D24: =IFERROR(IF(D9="","",'2. P&L 3 Años'!$B$24/D9),"") -> 0.27016216 | E24: La MISMA plantilla en los tres escenarios. Si en el pesimista se dispara, el ajuste hay que hacerlo en la hoja de Personal, no aquí
A25: Cubiertos al año por jornada equivalente | B25: =IFERROR(IF(B9="","",B6*B8/'5. Personal'!$C$13),"") -> 3222.2222 | C25: =IFERROR(IF(C9="","",C6*C8/'5. Personal'!$C$13),"") -> 4592.5926 | D25: =IFERROR(IF(D9="","",D6*D8/'5. Personal'!$C$13),"") -> 5629.6296 | E25: Cubiertos que tendría que sacar cada jornada completa del cuadro de Personal. En el optimista dice si hace falta contratar
A26: Saldo de caja al cierre del año 1 (estimado, el mismo método en los tres escenarios) | B26: =IFERROR(IF(B9="","",'1. Inversión Inicial'!$B$47+B21+'2. P&L 3 Años'!$B$38-'7. Financiación'!$B$45),"") -> 7097.7 | C26: =IFERROR(IF(C9="","",'1. Inversión Inicial'!$B$47+C21+'2. P&L 3 Años'!$B$38-'7. Financiación'!$B$45),"") -> 118186.99 | D26: =IFERROR(IF(D9="","",'1. Inversión Inicial'!$B$47+D21+'2. P&L 3 Años'!$B$38-'7. Financiación'!$B$45),"") -> 182840.03 | E26: Saldo ESTIMADO: fondo de maniobra más el resultado del año, devolviendo la amortización (que no se paga) y restando el principal del préstamo. No incluye el desfase de cobros y pagos ni la liquidación del IVA, así que las tres columnas se pueden comparar entre sí. En rojo, el escenario se queda sin caja
A27: Saldo real del mes 12 de la hoja de Tesorería (sólo realista) | C27: =IFERROR(IF(C9="","",'6. Tesorería 12 meses'!$M$22),"") -> 155793.41 | E27: El saldo REAL del caso base, con su desfase de cobros y pagos y su liquidación de IVA. Sólo existe para el escenario realista, que es el único con tesorería mensual propia: por eso no está en la fila de arriba, donde se compararía contra dos estimaciones
A29: La columna «Realista» lee sus tres datos de la hoja de Supuestos, así que reproduce EXACTAMENTE el año 1 del P&L. Los otros dos escenarios usan las mismas tasas de coste: lo único que cambia son los cubiertos, el ticket y los días. Los COSTES FIJOS sí son los mismos en los tres: los varios e imprevistos, que son un porcentaje de las ventas, van arriba con los variables y cada escenario carga los suyos.
A30: NOTA: El escenario pesimista refleja un arranque lento con menor afluencia. El optimista asume alta ocupación y ticket medio superior. Los costes fijos son constantes en los 3 escenarios.
A31: ChefBusiness.co — Plan de Negocio: Bar-Restaurante

Sheet 5. Personal
A1: ChefBusiness Consultoría Gastronómica
A2: Cuadro de Personal y Coste Laboral
A3: Plan de Negocio: Bar-Restaurante / Restaurante Casual — España 2026
A5: Puesto | B5: Personas | C5: Jornada | D5: Bruto mes (€, total del puesto) | E5: Seg. Social a cargo de la empresa (€) | F5: Coste mes (€, total del puesto) | G5: Coste año (€) | H5: Horas/semana por persona | I5: Horas/año del puesto | J5: Notas
A6: Gerente / Propietario | B6: 1 | C6: 1 | D6: 1900 | E6: =IFERROR(IF(D6="","",D6*'0. Supuestos'!$B$20),"") -> 627 | F6: =IFERROR(IF(D6="","",D6+E6),"") -> 2527 | G6: =IFERROR(IF(D6="","",F6*MAX(12,'0. Supuestos'!$B$21)),"") -> 35378 | H6: =IFERROR(IF(D6="","",C6*$B$20),"") -> 40 | I6: =IFERROR(IF(D6="","",H6*B6*$B$21),"") -> 1840 | J6: Trabaja en sala: compras, cierre de caja, proveedores y RRSS
A7: Jefe de cocina | B7: 1 | C7: 1 | D7: 1800 | E7: =IFERROR(IF(D7="","",D7*'0. Supuestos'!$B$20),"") -> 594 | F7: =IFERROR(IF(D7="","",D7+E7),"") -> 2394 | G7: =IFERROR(IF(D7="","",F7*MAX(12,'0. Supuestos'!$B$21)),"") -> 33516 | H7: =IFERROR(IF(D7="","",C7*$B$20),"") -> 40 | I7: =IFERROR(IF(D7="","",H7*B7*$B$21),"") -> 1840 | J7: Escandallos, pedidos y línea caliente
A8: Ayudante de cocina | B8: 1 | C8: 1 | D8: 1250 | E8: =IFERROR(IF(D8="","",D8*'0. Supuestos'!$B$20),"") -> 412.5 | F8: =IFERROR(IF(D8="","",D8+E8),"") -> 1662.5 | G8: =IFERROR(IF(D8="","",F8*MAX(12,'0. Supuestos'!$B$21)),"") -> 23275 | H8: =IFERROR(IF(D8="","",C8*$B$20),"") -> 40 | I8: =IFERROR(IF(D8="","",H8*B8*$B$21),"") -> 1840 | J8: Mise en place, fríos y limpieza de cocina. Por encima del SMI de jornada completa
A9: Camarero/a de barra y sala | B9: 1 | C9: 1 | D9: 1300 | E9: =IFERROR(IF(D9="","",D9*'0. Supuestos'!$B$20),"") -> 429 | F9: =IFERROR(IF(D9="","",D9+E9),"") -> 1729 | G9: =IFERROR(IF(D9="","",F9*MAX(12,'0. Supuestos'!$B$21)),"") -> 24206 | H9: =IFERROR(IF(D9="","",C9*$B$20),"") -> 40 | I9: =IFERROR(IF(D9="","",H9*B9*$B$21),"") -> 1840 | J9: Jornada completa, con el servicio de mediodía y el de noche
A10: Camarero/a a tiempo parcial | B10: 1 | C10: 0.75 | D10: 1000 | E10: =IFERROR(IF(D10="","",D10*'0. Supuestos'!$B$20),"") -> 330 | F10: =IFERROR(IF(D10="","",D10+E10),"") -> 1330 | G10: =IFERROR(IF(D10="","",F10*MAX(12,'0. Supuestos'!$B$21)),"") -> 18620 | H10: =IFERROR(IF(D10="","",C10*$B$20),"") -> 30 | I10: =IFERROR(IF(D10="","",H10*B10*$B$21),"") -> 1380 | J10: Refuerzo de los dos servicios fuertes, 30 horas semanales
A11: Extra de fin de semana | B11: 1 | C11: 0.5 | D11: 650 | E11: =IFERROR(IF(D11="","",D11*'0. Supuestos'!$B$20),"") -> 214.5 | F11: =IFERROR(IF(D11="","",D11+E11),"") -> 864.5 | G11: =IFERROR(IF(D11="","",F11*MAX(12,'0. Supuestos'!$B$21)),"") -> 12103 | H11: =IFERROR(IF(D11="","",C11*$B$20),"") -> 20 | I11: =IFERROR(IF(D11="","",H11*B11*$B$21),"") -> 920 | J11: Viernes, sábado y domingo, 20 horas semanales
A12: Suplencias de vacaciones y descansos | B12: 1 | C12: 0.15 | D12: 260 | E12: =IFERROR(IF(D12="","",D12*'0. Supuestos'!$B$20),"") -> 85.8 | F12: =IFERROR(IF(D12="","",D12+E12),"") -> 345.8 | G12: =IFERROR(IF(D12="","",F12*MAX(12,'0. Supuestos'!$B$21)),"") -> 4841.2 | H12: =IFERROR(IF(D12="","",C12*$B$20),"") -> 6 | I12: =IFERROR(IF(D12="","",H12*B12*$B$21),"") -> 276 | J12: Cobertura de los 30 días de vacaciones (art. 38 ET) y del descanso semanal de los seis puestos. Equivale a una jornada del 15 %
A13: TOTAL PLANTILLA | B13: =IFERROR(IF(COUNT(D6:D12)=0,"",SUM(B6:B12)),"") -> 7 | C13: =IFERROR(IF(COUNT(D6:D12)=0,"",SUM(C6:C12)),"") -> 5.4 | D13: =IFERROR(IF(COUNT(D6:D12)=0,"",SUM(D6:D12)),"") -> 8160 | E13: =IFERROR(IF(COUNT(D6:D12)=0,"",SUM(E6:E12)),"") -> 2692.8 | F13: =IFERROR(IF(COUNT(D6:D12)=0,"",SUM(F6:F12)),"") -> 10852.8 | G13: =IFERROR(IF(COUNT(D6:D12)=0,"",SUM(G6:G12)),"") -> 151939.2 | I13: =IFERROR(IF(COUNT(D6:D12)=0,"",SUM(I6:I12)),"") -> 9936
A14: CRECIMIENTO DE LA PLANTILLA (coste escalonado)
A15: Coste anual de las incorporaciones del año 2 (€) | B15: 6000 | J15: Coste ANUAL completo (bruto + Seguridad Social × pagas) de lo que se contrate ese año. El P&L lo suma al coste del año anterior: la plantilla no crece con un porcentaje, crece con personas
A16: Coste anual de las incorporaciones del año 3 (€) | B16: 6000 | J16: Coste ANUAL completo (bruto + Seguridad Social × pagas) de lo que se contrate ese año. El P&L lo suma al coste del año anterior: la plantilla no crece con un porcentaje, crece con personas
A17: Coste de personal del año 2 | B17: =IFERROR(IF(G13="","",G13*(1+'0. Supuestos'!$B$48)+B15),"") -> 157939.2
A18: Coste de personal del año 3 | B18: =IFERROR(IF(B17="","",B17*(1+'0. Supuestos'!$B$48)+B16),"") -> 163939.2
A19: COBERTURA POR HORAS DE SERVICIO
A20: Jornada completa del convenio (horas/semana) | B20: 40 | J20: Art. 34.1 del Estatuto de los Trabajadores; tu convenio provincial puede fijar menos
A21: Semanas trabajadas al año por persona | B21: 46 | J21: 46 semanas: 52 menos las vacaciones (30 días naturales, art. 38 ET), los festivos y las ausencias medias
A22: Horas de servicio al día que hay que cubrir | B22: 13 | J22: De la apertura al cierre, barra incluida. Cuéntalas sobre tu horario real
A23: Personas necesarias a la vez en cada franja | B23: 2 | J23: Media de presencia simultánea entre cocina, barra y sala. En los dos servicios fuertes hará falta más y a media tarde menos
A24: Horas de servicio a cubrir al año | B24: =IFERROR(IF(OR(B22="",B23="",'0. Supuestos'!$B$6=""),"",B22*B23*'0. Supuestos'!$B$6),"") -> 8060
A25: Horas contratadas al año | B25: =IFERROR(IF(I13="","",I13),"") -> 9936
A26: Cobertura (contratadas / necesarias) | B26: =IFERROR(B25/B24,"") -> 1.2327543 | J26: Por debajo del 100 % la plantilla no llega a cubrir el horario que declara el plan: o se contrata más o se recorta el horario
A28: Las columnas «Bruto mes», «Seg. Social», «Coste mes» y «Coste año» son TOTALES de la fila: en un puesto con dos personas incluyen a las dos. «Jornada» es el porcentaje sobre la jornada completa del convenio y sirve para comparar el salario con el suelo legal en proporción. El tipo de Seguridad Social y el número de pagas están en la hoja «0. Supuestos».
A29: El suelo salarial es el MAYOR entre el SMI y el salario de convenio, los dos en la hoja «0. Supuestos»; las jornadas parciales lo llevan en proporción. El convenio aplicable es el PROVINCIAL de hostelería: no existe una tabla salarial estatal única, así que la celda del convenio se entrega vacía para que copies la de tu provincia.
A30: ChefBusiness.co — Plan de Negocio: Bar-Restaurante

Sheet Instrucciones
A1: INSTRUCCIONES DE USO — Plan financiero Bar-Restaurante / Restaurante Casual
A3: CÓMO SE USA ESTE LIBRO
A4: Este plan financiero es un MODELO: sólo se teclea en las celdas VERDES y el resto se recalcula solo.
A5: 1. «0. Supuestos» es la hoja de mando: cubiertos, ticket sin IVA, días de apertura, mezcla de comida y bebida, coste de mercancía, alquiler, financiación e impuestos.
A6: 2. Las partidas de la inversión, los costes fijos y la plantilla se teclean en su propia hoja, también en verde. Ningún número se escribe dos veces.
A7: 3. En «3. Punto Equilibrio» sólo se teclea el techo de rotaciones que da tu local; todo lo demás se deriva de lo anterior. En las otras tres hojas también hay celdas verdes que puedes tocar: el escenario pesimista y el optimista en «4. Escenarios», la estacionalidad y la rampa de arranque en «6. Tesorería 12 meses», y las cuatro fuentes alternativas de financiación en «7. Financiación». Todo lo demás se calcula.
A8: 4. Todas las cifras van SIN IVA. Para pasar un PVP a precio sin IVA, divide por el tipo que le corresponda: entre 1,10 en sala (comida y bebida, alcohol incluido: art. 91.Uno.2.2.º de la Ley 37/1992 del IVA) y, cuando se venden para llevar, los alimentos —bollería y pastelería incluidas—, que son productos alimenticios al tipo reducido por el art. 91.Uno.1.1.º; y entre 1,21 el tipo general, que en hostelería sólo alcanza a lo que sale del local como entrega de bienes excluida del reducido: el alcohol y los refrescos o zumos con azúcares añadidos para llevar o a domicilio (la comida para llevar sigue al 10 %); el libro lo aplica al alcohol del canal de delivery. El tipo de cada línea de venta está en la columna «Tipo de IVA de la línea» del P&L y de ahí salen los cobros, el IVA repercutido y el PVP equivalente. El IVA de la inversión se adelanta y se recupera con el modelo 303.
A9: 5. Si cambias la plantilla, el P&L la lee sola: el coste de personal sale de la hoja «Personal», no de una estimación aparte.
A10: 6. La hoja «6. Tesorería 12 meses» responde la pregunta que decide una operación bancaria: en qué mes se agota la caja. El saldo mínimo del año nunca puede salir en rojo.
A11: 7. La hoja «7. Financiación» cuadra lo que hace falta con lo que se aporta y monta el cuadro de amortización del préstamo. Si la diferencia sale en rojo, el plan no está financiado.
A13: RATIOS QUE AUDITA EL LIBRO
A14: Los umbrales viven en la columna «Umbral» del bloque RATIOS CLAVE del P&L: cámbialos ahí y el semáforo cambia con ellos.
A16: Ratio | B16: Valor del año 1 | C16: Umbral | D16: Estado
A17: Coste de mercancía / Ventas | B17: =IFERROR(IF('2. P&L 3 Años'!$B$55="","",'2. P&L 3 Años'!$B$55),"") -> 0.272 | C17: =IFERROR(IF('2. P&L 3 Años'!$E$55="","",'2. P&L 3 Años'!$E$55),"") -> 0.32 | D17: =IFERROR(IF(OR(B17="",C17=""),"",IF(B17<=C17,"CUMPLE","REVISAR")),"") -> CUMPLE
A18: Coste de personal / Ventas | B18: =IFERROR(IF('2. P&L 3 Años'!$B$56="","",'2. P&L 3 Años'!$B$56),"") -> 0.33662531 | C18: =IFERROR(IF('2. P&L 3 Años'!$E$56="","",'2. P&L 3 Años'!$E$56),"") -> 0.34 | D18: =IFERROR(IF(OR(B18="",C18=""),"",IF(B18<=C18,"CUMPLE","REVISAR")),"") -> CUMPLE
A19: Alquiler / Ventas | B19: =IFERROR(IF('2. P&L 3 Años'!$B$57="","",'2. P&L 3 Años'!$B$57),"") -> 0.079758951 | C19: =IFERROR(IF('2. P&L 3 Años'!$E$57="","",'2. P&L 3 Años'!$E$57),"") -> 0.1 | D19: =IFERROR(IF(OR(B19="",C19=""),"",IF(B19<=C19,"CUMPLE","REVISAR")),"") -> CUMPLE
A20: Resultado neto / Ventas | B20: =IFERROR(IF('2. P&L 3 Años'!$B$58="","",'2. P&L 3 Años'!$B$58),"") -> 0.10772153 | C20: =IFERROR(IF('2. P&L 3 Años'!$E$58="","",'2. P&L 3 Años'!$E$58),"") -> 0.05 | D20: =IFERROR(IF(OR(B20="",C20=""),"",IF(B20>=C20,"CUMPLE","REVISAR")),"") -> CUMPLE
A21: Margen bruto / Ventas | B21: =IFERROR(IF('2. P&L 3 Años'!$B$53="","",'2. P&L 3 Años'!$B$53),"") -> 0.685 | C21: =IFERROR(IF('2. P&L 3 Años'!$E$53="","",'2. P&L 3 Años'!$E$53),"") -> 0.65 | D21: =IFERROR(IF(OR(B21="",C21=""),"",IF(B21>=C21,"CUMPLE","REVISAR")),"") -> CUMPLE
A23: CIFRAS DE ESTE PLAN
A24: Inversión total (suma de los bloques) | B24: =IFERROR(IF('1. Inversión Inicial'!$B$48="","",'1. Inversión Inicial'!$B$48),"") -> 179014.8
A25: Necesidad total de caja al arranque | B25: =IFERROR(IF('1. Inversión Inicial'!$B$51="","",'1. Inversión Inicial'!$B$51),"") -> 201717.9
A26: Fondo de maniobra dotado | B26: =IFERROR(IF('1. Inversión Inicial'!$B$47="","",'1. Inversión Inicial'!$B$47),"") -> 60804.8
A27: Facturación prevista del año 1 | B27: =IFERROR(IF('2. P&L 3 Años'!$B$10="","",'2. P&L 3 Años'!$B$10),"") -> 451360
A28: Resultado neto del año 1 | B28: =IFERROR(IF('2. P&L 3 Años'!$B$50="","",'2. P&L 3 Años'!$B$50),"") -> 48621.19
A29: Cubiertos/día para el punto de equilibrio CONTABLE (con la amortización dentro) | B29: =IFERROR(IF('3. Punto Equilibrio'!$B$16="","",'3. Punto Equilibrio'!$B$16),"") -> 65.199274
A30: Payback del proyecto (años), antes de la deuda | B30: =IFERROR(IF('6. Tesorería 12 meses'!$B$31="","",'6. Tesorería 12 meses'!$B$31),"") -> 2.3
A32: QUÉ HA CAMBIADO RESPECTO DE LA VERSIÓN 1.1
A33: Concepto | B33: v1.1 | C33: v2.2 | D33: Por qué
A34: Coste de personal imputado al P&L | B34: 115.200 € | C34: Sale de la hoja Personal, por fórmula | D34: El P&L decía «ver hoja Personal» y usaba otra cifra; ahora lee la hoja
A35: Plantilla | B35: 7 personas / 209.171 € | C35: 7 puestos, tres a tiempo parcial (uno de ellos, suplencias) / 151.939 € | D35: Dimensionada por horas de servicio para 56 plazas; con la plantilla anterior el coste laboral era el 66,3 % de las ventas
A36: Cubiertos/día del año 1 | B36: 55 | C36: 80 | D36: 1,43 rotaciones sobre las 56 plazas del propio pack; el documento pide un MÍNIMO de 1,8 en temporada alta, así que el caso base se proyecta por debajo a propósito
A37: Ticket medio | B37: 18,50 € (sin declarar IVA) | C37: 18,20 € SIN IVA | D37: El ticket de la versión 1.1 no decía si llevaba IVA; ahora se declara sin IVA y equivale a 20,02 € de PVP al 10 % en sala, dentro del rango 15-22 € del propio libro
A38: Alquiler | B38: 3.000 €/mes | C38: 3.000 €/mes (sin cambio) | D38: Con el ticket recalibrado son el 8,0 % de las ventas, dentro del techo de 8-10 % del propio libro
A39: Suministros | B39: 1.200 €/mes | C39: 1.800 €/mes | D39: Una cocina con horno, cámaras y campana no consume el 3,2 % de las ventas
A40: Fondo de maniobra | B40: 30.000 € etiquetados «3 meses» | C40: 3 × costes fijos de caja mensuales, por fórmula | D40: Los 30.000 € cubrían 1,8 meses, no 3
A41: Amortización | B41: 5.000 €/año (base implícita 50.000 €) | C41: Base amortizable real / vida útil, por fórmula | D41: El inmovilizado del propio libro suma bastante más, y el fondo de maniobra no se amortiza
A42: Cuota del préstamo en el P&L | B42: 7.200 €/año de cuota completa | C42: sólo los intereses; el principal va a tesorería | D42: Meter la cuota entera antes del resultado convierte el P&L en un flujo de caja
A43: Impuesto de Sociedades | B43: 25 % en los años 2 y 3, sin compensar la BIN | C43: 15 % los dos primeros ejercicios con base positiva y compensación de bases negativas | D43: Artículos 26 y 29.1 de la Ley del Impuesto sobre Sociedades
A44: Comisiones de delivery | B44: 5 % de TODA la facturación, sin interruptor | C44: % del canal × comisión de la plataforma, a 0 por defecto | D44: Si no repartes, no arrastras un coste inventado
A45: Coste de la bebida | B45: food cost del 30 % sobre el total MÁS un 22 % sobre la bebida | C45: cada familia paga su propio coste | D45: 33.119,63 € cobrados dos veces en el año 1
...

Sheet 6. Tesorería 12 meses
A1: PREVISIÓN DE TESORERÍA — AÑO 1
A2: El P&L dice si el negocio gana dinero; esta hoja dice si le queda caja para llegar a fin de mes. Es la primera que mira un banco.
A4: Concepto | B4: Mes 1 (€) | C4: Mes 2 (€) | D4: Mes 3 (€) | E4: Mes 4 (€) | F4: Mes 5 (€) | G4: Mes 6 (€) | H4: Mes 7 (€) | I4: Mes 8 (€) | J4: Mes 9 (€) | K4: Mes 10 (€) | L4: Mes 11 (€) | M4: Mes 12 (€) | N4: Año (€)
A5: Estacionalidad del mes (suma 100 %) | B5: 0.07 | C5: 0.072 | D5: 0.082 | E5: 0.085 | F5: 0.09 | G5: 0.088 | H5: 0.085 | I5: 0.062 | J5: 0.085 | K5: 0.088 | L5: 0.087 | M5: 0.106 | N5: =IFERROR(IF('2. P&L 3 Años'!$B$10="","",SUM(B5:M5)),"") -> 1 | O5: Perfil de tu zona: agosto flojo en ciudad y fuerte en costa. Tiene que sumar 100 %
