Workbook

Sheet Instrucciones
A1: Quejas, Reclamaciones Formales y Reseñas
A2: AI Chef Pro · aichef.pro — Manual del Manager de Restaurante
A4: Instrucciones de uso
A5: 1. Abre «Parámetros» y pon TU SLA: cuántas horas te das para cerrar una queja leve, una media y una grave. Es un compromiso de la casa, no una norma: por eso está en celda verde.
A6: 2. En la misma hoja, busca tu comunidad en la tabla de plazos legales. Sólo vienen sembradas Cataluña y Andalucía, que son las dos verificadas contra la norma. Si la tuya no está, escribe su plazo y su norma en la fila «Otras comunidades»: el libro la usará igual.
A7: 3. Registra cada queja en «Registro de Quejas» según ocurre. Fecha, canal, motivo de la lista, gravedad de 1 a 3, quién la atiende, qué se hizo y la fecha en que quedó cerrada. El libro calcula solo las horas que tardaste, el SLA que le tocaba y si lo cumpliste.
A8: 4. Una hoja OFICIAL de reclamaciones no es una queja: va a «Reclamaciones Formales», con su número, la comunidad y la fecha en que contestaste por escrito. El libro trae el plazo legal de esa comunidad y te dice si llegaste a tiempo.
A9: 5. Vuelca las reseñas en «Reseñas»: plataforma, fecha, estrellas, de qué va y si está respondida. El mes lo calcula el libro.
A10: 6. Lee «Resumen» una vez al mes. Ahí está lo que importa: cuál es el motivo que más se repite, cuánto tardas de media en cerrar, qué porcentaje de SLA cumples, si alguna reclamación se contestó fuera de plazo y cómo se mueve la media de estrellas mes a mes.
A11: 7. Si un motivo concentra las quejas, deja de tratarlo como incidentes sueltos: es un problema de proceso. Llévalo al plan de acción del libro de reuniones y ponle responsable y fecha.
A13: Celdas verdes = campos editables
A15: QUEJA, RECLAMACIÓN Y RESEÑA NO SON LO MISMO, y por eso son tres hojas. La queja se resuelve en sala y se mide contra el SLA que se pone la casa. La hoja oficial de reclamaciones es un procedimiento administrativo con un plazo de respuesta que fija tu comunidad autónoma. La reseña es pública, la lee quien todavía no ha venido, y se responde.
... A31: Versión 1.0 · septiembre 2026 · aichef.pro/manual-manager-restaurante · info@aichef.pro

Sheet Parámetros
A1: Parámetros — el SLA es tuyo; el plazo legal, de tu comunidad
A2: AI Chef Pro · aichef.pro — Manual del Manager de Restaurante
A4: SLA DE LA CASA POR GRAVEDAD DE LA QUEJA
A5: Gravedad (1-3) | B5: Qué significa | C5: SLA de cierre (horas) | F5: Notas y fuente
A6: 1 | B6: Leve: molestia sin impacto en la experiencia | C6: 72 | F6: El SLA es un compromiso de la casa, no una obligación legal. La escala de gravedad es la del capítulo 17 del manual.
A7: 2 | B7: Media: afecta a la experiencia de la mesa | C7: 48
A8: 3 | B8: Grave: riesgo sanitario, legal o reputacional | C8: 24
A10: CONSTANTE DE CÁLCULO
A11: Horas que tiene un día | C11: 24 | F11: Excel resta fechas en DÍAS. Esta celda convierte esa resta en horas para poder compararla con el SLA. No es un parámetro de tu negocio: por eso no está en verde.
A13: PLAZO LEGAL DE RESPUESTA A LA HOJA OFICIAL DE RECLAMACIONES, POR COMUNIDAD
A14: Comunidad | B14: Plazo legal | C14: Días para el aviso | D14: Se cuentan | F14: Norma, verificación y URL
A15: Cataluña | B15: 1 mes | C15: 30 | D15: Naturales | F15: Verificado el 04-09-2026 · Decret 121/2013 y Codi de consum de Cataluña (Llei 22/2010), art. 126-9: hay que contestar en el plazo máximo de 1 mes desde la presentación de la hoja · https://www.boe.es/buscar/act.php?id=BOE-A-2010-13115
A16: Andalucía | B16: 10 días hábiles | C16: 10 | D16: Hábiles | F16: Verificado el 04-09-2026 · Decreto 82/2022, arts. 4, 7 y 12: respuesta por escrito en 10 días hábiles, cartel de tamaño mínimo DIN-A4 con letra de 0,7 cm o más, y hoja electrónica obligatoria desde mayo de 2026 · https://www.juntadeandalucia.es/boja/2022/95/42
A17: Otras comunidades | F17: Consulta tu comunidad: la hoja oficial de reclamaciones es competencia AUTONÓMICA y el plazo cambia de una a otra. Escribe aquí el tuyo, con la norma que lo fija, y el libro lo usará en la hoja «Reclamaciones Formales».
A19: MOTIVOS DE QUEJA (lista cerrada del registro)
A20: Motivo | B20: Qué recoge
A21: Espera excesiva | B21: Tiempo de espera para sentarse, para la comanda o para que salga el plato. | F21: La lista es cerrada A PROPÓSITO: si cada queja se escribe con palabras distintas, el resumen no puede contar cuál se repite, que es justo lo que hay que ver.
A22: Plato frío o mal temperado | B22: Temperatura de servicio fuera del estándar de la ficha.
A23: Error en la comanda | B23: Plato distinto del pedido, modificación perdida o guarnición cambiada.
A24: Trato del personal | B24: Forma, tono o atención de una persona del equipo.
A25: Cobro incorrecto | B25: Precio, cantidad o forma de pago mal aplicados.
A26: Limpieza | B26: Sala, aseos, mantelería, cristalería o cubertería.
A27: Reserva no encontrada | B27: La reserva no consta, o consta con otros datos.
A28: Ruido | B28: Volumen de música, acústica de la sala o ruido de office.
A29: Información de alérgenos | B29: Información incompleta, tardía o incorrecta sobre los 14 alérgenos.
A30: Producto en mal estado | B30: Producto en mal estado o sospecha de incidente alimentario. Siempre gravedad 3.
A32: CANALES DE ENTRADA
A33: Canal
A34: En sala
A35: Teléfono
A36: Correo electrónico
A37: Reseña online
A38: Redes sociales
A39: Hoja de reclamaciones
A41: La hoja oficial de reclamaciones es competencia AUTONÓMICA. Este libro sólo siembra los dos plazos verificados contra la norma el 04-09-2026. Antes de fiarte de cualquier otro dato, compruébalo en el boletín de tu comunidad.

Sheet Registro de Quejas
A1: Registro de quejas — lo que se resuelve en sala
A2: AI Chef Pro · aichef.pro — Manual del Manager de Restaurante
G3: Las horas hasta el cierre, el SLA de esa gravedad y el cumplimiento los calcula el libro.
A4: # | B4: Fecha de la queja | C4: Canal | D4: Motivo | E4: Gravedad (1-3) | F4: Responsable | G4: Acción tomada | H4: Fecha de cierre | I4: Horas hasta el cierre | J4: SLA de esa gravedad (horas) | K4: SLA cumplido | L4: Notas
A5: 1 | B5: 46178 | C5: En sala | D5: Error en la comanda | E5: 1 | F5: P03 · Nuria C. | G5: Se rehace el plato y se invita al postre | H5: 46178 | I5: =IFERROR(IF(OR($B5="",$H5=""),"",($H5-$B5)*Parámetros!$C$11),"") -> 0 | J5: =IFERROR(IF($E5="","",INDEX(Parámetros!$C$6:$C$8,MATCH($E5,Parámetros!$A$6:$A$8,0))),"") -> 72 | K5: =IFERROR(IF(OR($I5="",$J5=""),"",IF($I5<=$J5,"Sí","No")),"") -> Sí
A6: 2 | B6: 46180 | C6: Reseña online | D6: Espera excesiva | E6: 2 | F6: P01 · Marta L. | G6: Respuesta pública y llamada al cliente | H6: 46181 | I6: =IFERROR(IF(OR($B6="",$H6=""),"",($H6-$B6)*Parámetros!$C$11),"") -> 24 | J6: =IFERROR(IF($E6="","",INDEX(Parámetros!$C$6:$C$8,MATCH($E6,Parámetros!$A$6:$A$8,0))),"") -> 48 | K6: =IFERROR(IF(OR($I6="",$J6=""),"",IF($I6<=$J6,"Sí","No")),"") -> Sí
A7: 3 | B7: 46184 | C7: En sala | D7: Plato frío o mal temperado | E7: 2 | F7: P02 · Iván R. | G7: Se repone el plato; revisión de la lámpara del pase | H7: 46184 | I7: =IFERROR(IF(OR($B7="",$H7=""),"",($H7-$B7)*Parámetros!$C$11),"") -> 0 | J7: =IFERROR(IF($E7="","",INDEX(Parámetros!$C$6:$C$8,MATCH($E7,Parámetros!$A$6:$A$8,0))),"") -> 48 | K7: =IFERROR(IF(OR($I7="",$J7=""),"",IF($I7<=$J7,"Sí","No")),"") -> Sí
A8: 4 | B8: 46186 | C8: Teléfono | D8: Reserva no encontrada | E8: 2 | F8: P03 · Nuria C. | G8: Se acomoda en terraza; revisión del cuaderno de reservas | H8: 46187 | I8: =IFERROR(IF(OR($B8="",$H8=""),"",($H8-$B8)*Parámetros!$C$11),"") -> 24 | J8: =IFERROR(IF($E8="","",INDEX(Parámetros!$C$6:$C$8,MATCH($E8,Parámetros!$A$6:$A$8,0))),"") -> 48 | K8: =IFERROR(IF(OR($I8="",$J8=""),"",IF($I8<=$J8,"Sí","No")),"") -> Sí
A9: 5 | B9: 46191 | C9: En sala | D9: Cobro incorrecto | E9: 2 | F9: P01 · Marta L. | G9: Devolución en el acto y revisión del cierre de caja | H9: 46191 | I9: =IFERROR(IF(OR($B9="",$H9=""),"",($H9-$B9)*Parámetros!$C$11),"") -> 0 | J9: =IFERROR(IF($E9="","",INDEX(Parámetros!$C$6:$C$8,MATCH($E9,Parámetros!$A$6:$A$8,0))),"") -> 48 | K9: =IFERROR(IF(OR($I9="",$J9=""),"",IF($I9<=$J9,"Sí","No")),"") -> Sí
A10: 6 | B10: 46193 | C10: En sala | D10: Espera excesiva | E10: 2 | F10: P03 · Nuria C. | G10: Disculpa y aperitivo; se apunta la hora de comanda | H10: 46194 | I10: =IFERROR(IF(OR($B10="",$H10=""),"",($H10-$B10)*Parámetros!$C$11),"") -> 24 | J10: =IFERROR(IF($E10="","",INDEX(Parámetros!$C$6:$C$8,MATCH($E10,Parámetros!$A$6:$A$8,0))),"") -> 48 | K10: =IFERROR(IF(OR($I10="",$J10=""),"",IF($I10<=$J10,"Sí","No")),"") -> Sí
A11: 7 | B11: 46198 | C11: Correo electrónico | D11: Trato del personal | E11: 3 | F11: P01 · Marta L. | G11: Reunión con la persona implicada y respuesta escrita | H11: 46200 | I11: =IFERROR(IF(OR($B11="",$H11=""),"",($H11-$B11)*Parámetros!$C$11),"") -> 48 | J11: =IFERROR(IF($E11="","",INDEX(Parámetros!$C$6:$C$8,MATCH($E11,Parámetros!$A$6:$A$8,0))),"") -> 24 | K11: =IFERROR(IF(OR($I11="",$J11=""),"",IF($I11<=$J11,"Sí","No")),"") -> No
A12: 8 | B12: 46201 | C12: En sala | D12: Limpieza | E12: 1 | F12: P03 · Nuria C. | G12: Refuerzo del repaso de aseos en el turno de tarde | H12: 46203 | I12: =IFERROR(IF(OR($B12="",$H12=""),"",($H12-$B12)*Parámetros!$C$11),"") -> 48 | J12: =IFERROR(IF($E12="","",INDEX(Parámetros!$C$6:$C$8,MATCH($E12,Parámetros!$A$6:$A$8,0))),"") -> 72 | K12: =IFERROR(IF(OR($I12="",$J12=""),"",IF($I12<=$J12,"Sí","No")),"") -> Sí
A13: 9 | B13: 46205 | C13: En sala | D13: Espera excesiva | E13: 2 | F13: P03 · Nuria C. | G13: Se avisa del tiempo real al sentar; aperitivo de cortesía | H13: 46206 | I13: =IFERROR(IF(OR($B13="",$H13=""),"",($H13-$B13)*Parámetros!$C$11),"") -> 24 | J13: =IFERROR(IF($E13="","",INDEX(Parámetros!$C$6:$C$8,MATCH($E13,Parámetros!$A$6:$A$8,0))),"") -> 48 | K13: =IFERROR(IF(OR($I13="",$J13=""),"",IF($I13<=$J13,"Sí","No")),"") -> Sí
A14: 10 | B14: 46206 | C14: Reseña online | D14: Espera excesiva | E14: 2 | F14: P01 · Marta L. | G14: Respuesta pública en 24 h | H14: 46207 | I14: =IFERROR(IF(OR($B14="",$H14=""),"",($H14-$B14)*Parámetros!$C$11),"") -> 24 | J14: =IFERROR(IF($E14="","",INDEX(Parámetros!$C$6:$C$8,MATCH($E14,Parámetros!$A$6:$A$8,0))),"") -> 48 | K14: =IFERROR(IF(OR($I14="",$J14=""),"",IF($I14<=$J14,"Sí","No")),"") -> Sí
A15: 11 | B15: 46207 | C15: En sala | D15: Error en la comanda | E15: 1 | F15: P08 · Carlos V. | G15: Se rehace el plato | H15: 46207 | I15: =IFERROR(IF(OR($B15="",$H15=""),"",($H15-$B15)*Parámetros!$C$11),"") -> 0 | J15: =IFERROR(IF($E15="","",INDEX(Parámetros!$C$6:$C$8,MATCH($E15,Parámetros!$A$6:$A$8,0))),"") -> 72 | K15: =IFERROR(IF(OR($I15="",$J15=""),"",IF($I15<=$J15,"Sí","No")),"") -> Sí
A16: 12 | B16: 46208 | C16: En sala | D16: Espera excesiva | E16: 3 | F16: P01 · Marta L. | G16: Se invita a la mesa; se abre el análisis de tiempos de pase | H16: 46209 | I16: =IFERROR(IF(OR($B16="",$H16=""),"",($H16-$B16)*Parámetros!$C$11),"") -> 24 | J16: =IFERROR(IF($E16="","",INDEX(Parámetros!$C$6:$C$8,MATCH($E16,Parámetros!$A$6:$A$8,0))),"") -> 24 | K16: =IFERROR(IF(OR($I16="",$J16=""),"",IF($I16<=$J16,"Sí","No")),"") -> Sí
... A34: 30 | B34: 46261 | C34: Correo electrónico | D34: Trato del personal | E34: 2 | F34: P01 · Marta L. | G34: Respuesta escrita y seguimiento en el uno-a-uno | H34: 46263 | I34: =IFERROR(IF(OR($B34="",$H34=""),"",($H34-$B34)*Parámetros!$C$11),"") -> 48 | J34: =IFERROR(IF($E34="","",INDEX(Parámetros!$C$6:$C$8,MATCH($E34,Parámetros!$A$6:$A$8,0))),"") -> 48 | K34: =IFERROR(IF(OR($I34="",$J34=""),"",IF($I34<=$J34,"Sí","No")),"") -> Sí
A35: 31 | I35: =IFERROR(IF(OR($B35="",$H35=""),"",($H35-$B35)*Parámetros!$C$11),"") | J35: =IFERROR(IF($E35="","",INDEX(Parámetros!$C$6:$C$8,MATCH($E35,Parámetros!$A$6:$A$8,0))),"") | K35: =IFERROR(IF(OR($I35="",$J35=""),"",IF($I35<=$J35,"Sí","No")),"")
A36: 32 | I36: =IFERROR(IF(OR($B36="",$H36=""),"",($H36-$B36)*Parámetros!$C$11),"") | J36: =IFERROR(IF($E36="","",INDEX(Parámetros!$C$6:$C$8,MATCH($E36,Parámetros!$A$6:$A$8,0))),"") | K36: =IFERROR(IF(OR($I36="",$J36=""),"",IF($I36<=$J36,"Sí","No")),"")
A37: 33 | I37: =IFERROR(IF(OR($B37="",$H37=""),"",($H37-$B37)*Parámetros!$C$11),"") | J37: =IFERROR(IF($E37="","",INDEX(Parámetros!$C$6:$C$8,MATCH($E37,Parámetros!$A$6:$A$8,0))),"") | K37: =IFERROR(IF(OR($I37="",$J37=""),"",IF($I37<=$J37,"Sí","No")),"")
A38: 34 | I38: =IFERROR(IF(OR($B38="",$H38=""),"",($H38-$B38)*Parámetros!$C$11),"") | J38: =IFERROR(IF($E38="","",INDEX(Parámetros!$C$6:$C$8,MATCH($E38,Parámetros!$A$6:$A$8,0))),"") | K38: =IFERROR(IF(OR($I38="",$J38=""),"",IF($I38<=$J38,"Sí","No")),"")
A39: 35 | I39: =IFERROR(IF(OR($B39="",$H39=""),"",($H39-$B39)*Parámetros!$C$11),"") | J39: =IFERROR(IF($E39="","",INDEX(Parámetros!$C$6:$C$8,MATCH($E39,Parámetros!$A$6:$A$8,0))),"") | K39: =IFERROR(IF(OR($I39="",$J39=""),"",IF($I39<=$J39,"Sí","No")),"")
A40: 36 | I40: =IFERROR(IF(OR($B40="",$H40=""),"",($H40-$B40)*Parámetros!$C$11),"") | J40: =IFERROR(IF($E40="","",INDEX(Parámetros!$C$6:$C$8,MATCH($E40,Parámetros!$A$6:$A$8,0))),"") | K40: =IFERROR(IF(OR($I40="",$J40=""),"",IF($I40<=$J40,"Sí","No")),"")
A41: 37 | I41: =IFERROR(IF(OR($B41="",$H41=""),"",($H41-$B41)*Parámetros!$C$11),"") | J41: =IFERROR(IF($E41="","",INDEX(Parámetros!$C$6:$C$8,MATCH($E41,Parámetros!$A$6:$A$8,0))),"") | K41: =IFERROR(IF(OR($I41="",$J41=""),"",IF($I41<=$J41,"Sí","No")),"")
A42: 38 | I42: =IFERROR(IF(OR($B42="",$H42=""),"",($H42-$B42)*Parámetros!$C$11),"") | J42: =IFERROR(IF($E42="","",INDEX(Parámetros!$C$6:$C$8,MATCH($E42,Parámetros!$A$6:$A$8,0))),"") | K42: =IFERROR(IF(OR($I42="",$J42=""),"",IF($I42<=$J42,"Sí","No")),"")
A43: 39 | I43: =IFERROR(IF(OR($B43="",$H43=""),"",($H43-$B43)*Parámetros!$C$11),"") | J43: =IFERROR(IF($E43="","",INDEX(Parámetros!$C$6:$C$8,MATCH($E43,Parámetros!$A$6:$A$8,0))),"") | K43: =IFERROR(IF(OR($I43="",$J43=""),"",IF($I43<=$J43,"Sí","No")),"")
A44: 40 | I44: =IFERROR(IF(OR($B44="",$H44=""),"",($H44-$B44)*Parámetros!$C$11),"") | J44: =IFERROR(IF($E44="","",INDEX(Parámetros!$C$6:$C$8,MATCH($E44,Parámetros!$A$6:$A$8,0))),"") | K44: =IFERROR(IF(OR($I44="",$J44=""),"",IF($I44<=$J44,"Sí","No")),"")
A45: 41 | I45: =IFERROR(IF(OR($B45="",$H45=""),"",($H45-$B45)*Parámetros!$C$11),"") | J45: =IFERROR(IF($E45="","",INDEX(Parámetros!$C$6:$C$8,MATCH($E45,Parámetros!$A$6:$A$8,0))),"") | K45: =IFERROR(IF(OR($I45="",$J45=""),"",IF($I45<=$J45,"Sí","No")),"")
A46: 42 | I46: =IFERROR(IF(OR($B46="",$H46=""),"",($H46-$B46)*Parámetros!$C$11),"") | J46: =IFERROR(IF($E46="","",INDEX(Parámetros!$C$6:$C$8,MATCH($E46,Parámetros!$A$6:$A$8,0))),"") | K46: =IFERROR(IF(OR($I46="",$J46=""),"",IF($I46<=$J46,"Sí","No")),"")
... A54: 50 | I54: =IFERROR(IF(OR($B54="",$H54=""),"",($H54-$B54)*Parámetros!$C$11),"") | J54: =IFERROR(IF($E54="","",INDEX(Parámetros!$C$6:$C$8,MATCH($E54,Parámetros!$A$6:$A$8,0))),"") | K54: =IFERROR(IF(OR($I54="",$J54=""),"",IF($I54<=$J54,"Sí","No")),"")
A56: Una queja sin fecha de cierre no cuenta como incumplida: cuenta como ABIERTA, y por eso su fila se queda vacía. Cierra la fecha cuando la incidencia esté resuelta de verdad.

Sheet Reclamaciones Formales
A1: Reclamaciones formales — la hoja oficial y su plazo legal
A2: AI Chef Pro · aichef.pro — Manual del Manager de Restaurante
F3: El plazo sale de la tabla de tu comunidad en «Parámetros». Los días que cuenta el libro son NATURALES.
A4: # | B4: Fecha de entrega de la hoja | C4: Número de hoja | D4: Comunidad | E4: Fecha de respuesta por escrito | F4: Días naturales transcurridos | G4: Plazo de la comunidad (días) | H4: Se cuentan | I4: Dentro de plazo | J4: Objeto de la reclamación y respuesta
A5: 1 | B5: 46214 | C5: GI-2026-0417 | D5: Cataluña | E5: 46233 | F5: =IFERROR(IF(OR($B5="",$E5=""),"",$E5-$B5),"") -> 19 | G5: =IFERROR(IF($D5="","",IF(INDEX(Parámetros!$C$15:$C$17,MATCH($D5,Parámetros!$A$15:$A$17,0))=0,"",INDEX(Parámetros!$C$15:$C$17,MATCH($D5,Parámetros!$A$15:$A$17,0)))),"") -> 30 | H5: =IFERROR(IF($D5="","",IF(INDEX(Parámetros!$D$15:$D$17,MATCH($D5,Parámetros!$A$15:$A$17,0))=0,"",INDEX(Parámetros!$D$15:$D$17,MATCH($D5,Parámetros!$A$15:$A$17,0)))),"") -> Naturales | I5: =IFERROR(IF(OR($F5="",$G5=""),"",IF($F5<=$G5,"Sí","No")),"") -> Sí
A6: 2 | B6: 46228 | C6: GI-2026-0463 | D6: Cataluña | E6: 46267 | F6: =IFERROR(IF(OR($B6="",$E6=""),"",$E6-$B6),"") -> 39 | G6: =IFERROR(IF($D6="","",IF(INDEX(Parámetros!$C$15:$C$17,MATCH($D6,Parámetros!$A$15:$A$17,0))=0,"",INDEX(Parámetros!$C$15:$C$17,MATCH($D6,Parámetros!$A$15:$A$17,0)))),"") -> 30 | H6: =IFERROR(IF($D6="","",IF(INDEX(Parámetros!$D$15:$D$17,MATCH($D6,Parámetros!$A$15:$A$17,0))=0,"",INDEX(Parámetros!$D$15:$D$17,MATCH($D6,Parámetros!$A$15:$A$17,0)))),"") -> Naturales | I6: =IFERROR(IF(OR($F6="",$G6=""),"",IF($F6<=$G6,"Sí","No")),"") -> No
A7: 3 | B7: 46248 | C7: GI-2026-0521 | D7: Cataluña | E7: 46262 | F7: =IFERROR(IF(OR($B7="",$E7=""),"",$E7-$B7),"") -> 14 | G7: =IFERROR(IF($D7="","",IF(INDEX(Parámetros!$C$15:$C$17,MATCH($D7,Parámetros!$A$15:$A$17,0))=0,"",INDEX(Parámetros!$C$15:$C$17,MATCH($D7,Parámetros!$A$15:$A$17,0)))),"") -> 30 | H7: =IFERROR(IF($D7="","",IF(INDEX(Parámetros!$D$15:$D$17,MATCH($D7,Parámetros!$A$15:$A$17,0))=0,"",INDEX(Parámetros!$D$15:$D$17,MATCH($D7,Parámetros!$A$15:$A$17,0)))),"") -> Naturales | I7: =IFERROR(IF(OR($F7="",$G7=""),"",IF($F7<=$G7,"Sí","No")),"") -> Sí
A8: 4 | F8: =IFERROR(IF(OR($B8="",$E8=""),"",$E8-$B8),"") | G8: =IFERROR(IF($D8="","",IF(INDEX(Parámetros!$C$15:$C$17,MATCH($D8,Parámetros!$A$15:$A$17,0))=0,"",INDEX(Parámetros!$C$15:$C$17,MATCH($D8,Parámetros!$A$15:$A$17,0)))),"") | H8: =IFERROR(IF($D8="","",IF(INDEX(Parámetros!$D$15:$D$17,MATCH($D8,Parámetros!$A$15:$A$17,0))=0,"",INDEX(Parámetros!$D$15:$D$17,MATCH($D8,Parámetros!$A$15:$A$17,0)))),"") | I8: =IFERROR(IF(OR($F8="",$G8=""),"",IF($F8<=$G8,"Sí","No")),"")
A9: 5 | F9: =IFERROR(IF(OR($B9="",$E9=""),"",$E9-$B9),"") | G9: =IFERROR(IF($D9="","",IF(INDEX(Parámetros!$C$15:$C$17,MATCH($D9,Parámetros!$A$15:$A$17,0))=0,"",INDEX(Parámetros!$C$15:$C$17,MATCH($D9,Parámetros!$A$15:$A$17,0)))),"") | H9: =IFERROR(IF($D9="","",IF(INDEX(Parámetros!$D$15:$D$17,MATCH($D9,Parámetros!$A$15:$A$17,0))=0,"",INDEX(Parámetros!$D$15:$D$17,MATCH($D9,Parámetros!$A$15:$A$17,0)))),"") | I9: =IFERROR(IF(OR($F9="",$G9=""),"",IF($F9<=$G9,"Sí","No")),"")
A10: 6 | F10: =IFERROR(IF(OR($B10="",$E10=""),"",$E10-$B10),"") | G10: =IFERROR(IF($D10="","",IF(INDEX(Parámetros!$C$15:$C$17,MATCH($D10,Parámetros!$A$15:$A$17,0))=0,"",INDEX(Parámetros!$C$15:$C$17,MATCH($D10,Parámetros!$A$15:$A$17,0)))),"") | H10: =IFERROR(IF($D10="","",IF(INDEX(Parámetros!$D$15:$D$17,MATCH($D10,Parámetros!$A$15:$A$17,0))=0,"",INDEX(Parámetros!$D$15:$D$17,MATCH($D10,Parámetros!$A$15:$A$17,0)))),"") | I10: =IFERROR(IF(OR($F10="",$G10=""),"",IF($F10<=$G10,"Sí","No")),"")
A11: 7 | F11: =IFERROR(IF(OR($B11="",$E11=""),"",$E11-$B11),"") | G11: =IFERROR(IF($D11="","",IF(INDEX(Parámetros!$C$15:$C$17,MATCH($D11,Parámetros!$A$15:$A$17,0))=0,"",INDEX(Parámetros!$C$15:$C$17,MATCH($D11,Parámetros!$A$15:$A$17,0)))),"") | H11: =IFERROR(IF($D11="","",IF(INDEX(Parámetros!$D$15:$D$17,MATCH($D11,Parámetros!$A$15:$A$17,0))=0,"",INDEX(Parámetros!$D$15:$D$17,MATCH($D11,Parámetros!$A$15:$A$17,0)))),"") | I11: =IFERROR(IF(OR($F11="",$G11=""),"",IF($F11<=$G11,"Sí","No")),"")
A12: 8 | F12: =IFERROR(IF(OR($B12="",$E12=""),"",$E12-$B12),"") | G12: =IFERROR(IF($D12="","",IF(INDEX(Parámetros!$C$15:$C$17,MATCH($D12,Parámetros!$A$15:$A$17,0))=0,"",INDEX(Parámetros!$C$15:$C$17,MATCH($D12,Parámetros!$A$15:$A$17,0)))),"") | H12: =IFERROR(IF($D12="","",IF(INDEX(Parámetros!$D$15:$D$17,MATCH($D12,Parámetros!$A$15:$A$17,0))=0,"",INDEX(Parámetros!$D$15:$D$17,MATCH($D12,Parámetros!$A$15:$A$17,0)))),"") | I12: =IFERROR(IF(OR($F12="",$G12=""),"",IF($F12<=$G12,"Sí","No")),"")
A13: 9 | F13: =IFERROR(IF(OR($B13="",$E13=""),"",$E13-$B13),"") | G13: =IFERROR(IF($D13="","",IF(INDEX(Parámetros!$C$15:$C$17,MATCH($D13,Parámetros!$A$15:$A$17,0))=0,"",INDEX(Parámetros!$C$15:$C$17,MATCH($D13,Parámetros!$A$15:$A$17,0)))),"") | H13: =IFERROR(IF($D13="","",IF(INDEX(Parámetros!$D$15:$D$17,MATCH($D13,Parámetros!$A$15:$A$17,0))=0,"",INDEX(Parámetros!$D$15:$D$17,MATCH($D13,Parámetros!$A$15:$A$17,0)))),"") | I13: =IFERROR(IF(OR($F13="",$G13=""),"",IF($F13<=$G13,"Sí","No")),"")
A14: 10 | F14: =IFERROR(IF(OR($B14="",$E14=""),"",$E14-$B14),"") | G14: =IFERROR(IF($D14="","",IF(INDEX(Parámetros!$C$15:$C$17,MATCH($D14,Parámetros!$A$15:$A$17,0))=0,"",INDEX(Parámetros!$C$15:$C$17,MATCH($D14,Parámetros!$A$15:$A$17,0)))),"") | H14: =IFERROR(IF($D14="","",IF(INDEX(Parámetros!$D$15:$D$17,MATCH($D14,Parámetros!$A$15:$A$17,0))=0,"",INDEX(Parámetros!$D$15:$D$17,MATCH($D14,Parámetros!$A$15:$A$17,0)))),"") | I14: =IFERROR(IF(OR($F14="",$G14=""),"",IF($F14<=$G14,"Sí","No")),"")
A15: 11 | F15: =IFERROR(IF(OR($B15="",$E15=""),"",$E15-$B15),"") | G15: =IFERROR(IF($D15="","",IF(INDEX(Parámetros!$C$15:$C$17,MATCH($D15,Parámetros!$A$15:$A$17,0))=0,"",INDEX(Parámetros!$C$15:$C$17,MATCH($D15,Parámetros!$A$15:$A$17,0)))),"") | H15: =IFERROR(IF($D15="","",IF(INDEX(Parámetros!$D$15:$D$17,MATCH($D15,Parámetros!$A$15:$A$17,0))=0,"",INDEX(Parámetros!$D$15:$D$17,MATCH($D15,Parámetros!$A$15:$A$17,0)))),"") | I15: =IFERROR(IF(OR($F15="",$G15=""),"",IF($F15<=$G15,"Sí","No")),"")
A16: 12 | F16: =IFERROR(IF(OR($B16="",$E16=""),"",$E16-$B16),"") | G16: =IFERROR(IF($D16="","",IF(INDEX(Parámetros!$C$15:$C$17,MATCH($D16,Parámetros!$A$15:$A$17,0))=0,"",INDEX(Parámetros!$C$15:$C$17,MATCH($D16,Parámetros!$A$15:$A$17,0)))),"") | H16: =IFERROR(IF($D16="","",IF(INDEX(Parámetros!$D$15:$D$17,MATCH($D16,Parámetros!$A$15:$A$17,0))=0,"",INDEX(Parámetros!$D$15:$D$17,MATCH($D16,Parámetros!$A$15:$A$17,0)))),"") | I16: =IFERROR(IF(OR($F16="",$G16=""),"",IF($F16<=$G16,"Sí","No")),"")
A17: 13 | F17: =IFERROR(IF(OR($B17="",$E17=""),"",$E17-$B17),"") | G17: =IFERROR(IF($D17="","",IF(INDEX(Parámetros!$C$15:$C$17,MATCH($D17,Parámetros!$A$15:$A$17,0))=0,"",INDEX(Parámetros!$C$15:$C$17,MATCH($D17,Parámetros!$A$15:$A$17,0)))),"") | H17: =IFERROR(IF($D17="","",IF(INDEX(Parámetros!$D$15:$D$17,MATCH($D17,Parámetros!$A$15:$A$17,0))=0,"",INDEX(Parámetros!$D$15:$D$17,MATCH($D17,Parámetros!$A$15:$A$17,0)))),"") | I17: =IFERROR(IF(OR($F17="",$G17=""),"",IF($F17<=$G17,"Sí","No")),"")
A18: 14 | F18: =IFERROR(IF(OR($B18="",$E18=""),"",$E18-$B18),"") | G18: =IFERROR(IF($D18="","",IF(INDEX(Parámetros!$C$15:$C$17,MATCH($D18,Parámetros!$A$15:$A$17,0))=0,"",INDEX(Parámetros!$C$15:$C$17,MATCH($D18,Parámetros!$A$15:$A$17,0)))),"") | H18: =IFERROR(IF($D18="","",IF(INDEX(Parámetros!$D$15:$D$17,MATCH($D18,Parámetros!$A$15:$A$17,0))=0,"",INDEX(Parámetros!$D$15:$D$17,MATCH($D18,Parámetros!$A$15:$A$17,0)))),"") | I18: =IFERROR(IF(OR($F18="",$G18=""),"",IF($F18<=$G18,"Sí","No")),"")
A19: 15 | F19: =IFERROR(IF(OR($B19="",$E19=""),"",$E19-$B19),"") | G19: =IFERROR(IF($D19="","",IF(INDEX(Parámetros!$C$15:$C$17,MATCH($D19,Parámetros!$A$15:$A$17,0))=0,"",INDEX(Parámetros!$C$15:$C$17,MATCH($D19,Parámetros!$A$15:$A$17,0)))),"") | H19: =IFERROR(IF($D19="","",IF(INDEX(Parámetros!$D$15:$D$17,MATCH($D19,Parámetros!$A$15:$A$17,0))=0,"",INDEX(Parámetros!$D$15:$D$17,MATCH($D19,Parámetros!$A$15:$A$17,0)))),"") | I19: =IFERROR(IF(OR($F19="",$G19=""),"",IF($F19<=$G19,"Sí","No")),"")
... A24: 20 | F24: =IFERROR(IF(OR($B24="",$E24=""),"",$E24-$B24),"") | G24: =IFERROR(IF($D24="","",IF(INDEX(Parámetros!$C$15:$C$17,MATCH($D24,Parámetros!$A$15:$A$17,0))=0,"",INDEX(Parámetros!$C$15:$C$17,MATCH($D24,Parámetros!$A$15:$A$17,0)))),"") | H24: =IFERROR(IF($D24="","",IF(INDEX(Parámetros!$D$15:$D$17,MATCH($D24,Parámetros!$A$15:$A$17,0))=0,"",INDEX(Parámetros!$D$15:$D$17,MATCH($D24,Parámetros!$A$15:$A$17,0)))),"") | I24: =IFERROR(IF(OR($F24="",$G24=""),"",IF($F24<=$G24,"Sí","No")),"")
A26: Entregar la hoja es obligatorio y gratuito, y negarse es una infracción de consumo. Lo que decide si llegas a tiempo es la RESPUESTA POR ESCRITO, no la conversación en sala.
A27: Cuando la columna «Se cuentan» dice «Hábiles», el libro sigue comparando días naturales: te avisa antes, nunca después. Para el expediente, cuenta los hábiles de tu calendario.

Sheet Reseñas
A1: Reseñas — lo público, lo que lee quien todavía no ha venido
A2: AI Chef Pro · aichef.pro — Manual del Manager de Restaurante
F3: El mes lo calcula el libro desde la fecha: la hoja «Resumen» agrupa por él.
A4: # | B4: Plataforma | C4: Fecha | D4: Estrellas (1-5) | E4: Tema | F4: Respondida | G4: Mes | H4: Notas
A5: 1 | B5: Google | C5: 46084 | D5: 5 | E5: Comida | F5: Sí | G5: =IFERROR(IF($C5="","",DATE(YEAR($C5),MONTH($C5),1)),"") -> 46082
A6: 2 | B6: TripAdvisor | C6: 46088 | D6: 5 | E6: Servicio | F6: Sí | G6: =IFERROR(IF($C6="","",DATE(YEAR($C6),MONTH($C6),1)),"") -> 46082
A7: 3 | B7: Google | C7: 46093 | D7: 4 | E7: Ambiente | F7: Sí | G7: =IFERROR(IF($C7="","",DATE(YEAR($C7),MONTH($C7),1)),"") -> 46082
A8: 4 | B8: TheFork | C8: 46097 | D8: 4 | E8: Comida | F8: No | G8: =IFERROR(IF($C8="","",DATE(YEAR($C8),MONTH($C8),1)),"") -> 46082
A9: 5 | B9: Google | C9: 46102 | D9: 5 | E9: Comida | F9: Sí | G9: =IFERROR(IF($C9="","",DATE(YEAR($C9),MONTH($C9),1)),"") -> 46082
A10: 6 | B10: TripAdvisor | C10: 46106 | D10: 3 | E10: Espera | F10: Sí | G10: =IFERROR(IF($C10="","",DATE(YEAR($C10),MONTH($C10),1)),"") -> 46082
A11: 7 | B11: Google | C11: 46110 | D11: 4 | E11: Servicio | F11: No | G11: =IFERROR(IF($C11="","",DATE(YEAR($C11),MONTH($C11),1)),"") -> 46082
A12: 8 | B12: Google | C12: 46116 | D12: 5 | E12: Comida | F12: Sí | G12: =IFERROR(IF($C12="","",DATE(YEAR($C12),MONTH($C12),1)),"") -> 46113
A13: 9 | B13: TheFork | C13: 46121 | D13: 4 | E13: Reserva | F13: Sí | G13: =IFERROR(IF($C13="","",DATE(YEAR($C13),MONTH($C13),1)),"") -> 46113
A14: 10 | B14: Google | C14: 46126 | D14: 5 | E14: Servicio | F14: Sí | G14: =IFERROR(IF($C14="","",DATE(YEAR($C14),MONTH($C14),1)),"") -> 46113
A15: 11 | B15: Facebook | C15: 46130 | D15: 4 | E15: Ambiente | F15: No | G15: =IFERROR(IF($C15="","",DATE(YEAR($C15),MONTH($C15),1)),"") -> 46113
A16: 12 | B16: Google | C16: 46135 | D16: 5 | E16: Comida | F16: Sí | G16: =IFERROR(IF($C16="","",DATE(YEAR($C16),MONTH($C16),1)),"") -> 46113
... A44: 40 | B44: Google | C44: 46263 | D44: 5 | E44: Servicio | F44: Sí | G44: =IFERROR(IF($C44="","",DATE(YEAR($C44),MONTH($C44),1)),"") -> 46235
A45: 41 | G45: =IFERROR(IF($C45="","",DATE(YEAR($C45),MONTH($C45),1)),"")
A46: 42 | G46: =IFERROR(IF($C46="","",DATE(YEAR($C46),MONTH($C46),1)),"")
A47: 43 | G47: =IFERROR(IF($C47="","",DATE(YEAR($C47),MONTH($C47),1)),"")
A48: 44 | G48: =IFERROR(IF($C48="","",DATE(YEAR($C48),MONTH($C48),1)),"")
A49: 45 | G49: =IFERROR(IF($C49="","",DATE(YEAR($C49),MONTH($C49),1)),"")
A50: 46 | G50: =IFERROR(IF($C50="","",DATE(YEAR($C50),MONTH($C50),1)),"")
A51: 47 | G51: =IFERROR(IF($C51="","",DATE(YEAR($C51),MONTH($C51),1)),"")
A52: 48 | G52: =IFERROR(IF($C52="","",DATE(YEAR($C52),MONTH($C52),1)),"")
A53: 49 | G53: =IFERROR(IF($C53="","",DATE(YEAR($C53),MONTH($C53),1)),"")
A54: 50 | G54: =IFERROR(IF($C54="","",DATE(YEAR($C54),MONTH($C54),1)),"")
A55: 51 | G55: =IFERROR(IF($C55="","",DATE(YEAR($C55),MONTH($C55),1)),"")
A56: 52 | G56: =IFERROR(IF($C56="","",DATE(YEAR($C56),MONTH($C56),1)),"")
... A64: 60 | G64: =IFERROR(IF($C64="","",DATE(YEAR($C64),MONTH($C64),1)),"")
A66: Responder una reseña mala no es discutir: es dejar escrito, para el que la lee después, qué pasó y qué has cambiado.

Sheet Resumen
A1: Resumen — dónde se repite el problema y si llegas a tiempo
A2: AI Chef Pro · aichef.pro — Manual del Manager de Restaurante
A4: OBJETIVOS DE LA CASA — celdas verdes
A5: Objetivo de SLA cumplido (%) | D5: 0.9 | H5: Por debajo de este porcentaje, la celda de cumplimiento se pone en rojo.
A6: Objetivo de reseñas respondidas (%) | D6: 0.9 | H6: Responder también las buenas: es lo que sostiene la media.
A7: Objetivo de media de estrellas | D7: 4.3 | H7: Objetivo de la casa, no un dato de mercado.
A8: Tolerancia para leer la variación entre meses (estrellas) | D8: 0.05 | H8: Por debajo de esta diferencia, el mes se lee como «Igual»: no toda oscilación es una tendencia.
A10: QUEJAS — lo calcula el libro
A11: Quejas registradas | D11: =COUNTIF('Registro de Quejas'!$B$5:$B$54,"<>") -> 30
A12: Motivo más repetido | D12: =IFERROR(INDEX($A$22:$A$31,MATCH(MAX($C$22:$C$31),$C$22:$C$31,0)),"") -> Espera excesiva
A13: Quejas de ese motivo | D13: =IFERROR(MAX($C$22:$C$31),"") -> 10
A14: Gravedad más repetida | D14: =IFERROR(INDEX($A$35:$A$37,MATCH(MAX($C$35:$C$37),$C$35:$C$37,0)),"") -> 2
A15: Quejas de esa gravedad | D15: =IFERROR(MAX($C$35:$C$37),"") -> 16
A16: Tiempo medio hasta el cierre (horas) | D16: =IFERROR(AVERAGEIFS('Registro de Quejas'!$I$5:$I$54,'Registro de Quejas'!$I$5:$I$54,">=0"),"") -> 27.2
A17: Quejas cerradas dentro del SLA | D17: =COUNTIF('Registro de Quejas'!$K$5:$K$54,"Sí") -> 28
A18: Quejas cerradas fuera del SLA | D18: =COUNTIF('Registro de Quejas'!$K$5:$K$54,"No") -> 2
A19: SLA CUMPLIDO (%) | D19: =IFERROR(IF($D$17+$D$18=0,"",$D$17/($D$17+$D$18)),"") -> 0.93333333
A20: QUEJAS POR MOTIVO — el motivo que se repite es un problema de proceso
A21: Motivo | C21: Quejas | D21: Porcentaje del total | E21: Horas medias hasta el cierre | F21: Fuera del SLA
A22: Espera excesiva | C22: =COUNTIF('Registro de Quejas'!$D$5:$D$54,$A22) -> 10 | D22: =IFERROR(IF($D$11=0,"",$C22/$D$11),"") -> 0.33333333 | E22: =IFERROR(AVERAGEIFS('Registro de Quejas'!$I$5:$I$54,'Registro de Quejas'!$D$5:$D$54,$A22,'Registro de Quejas'!$I$5:$I$54,">=0"),"") -> 26.4 | F22: =COUNTIFS('Registro de Quejas'!$D$5:$D$54,$A22,'Registro de Quejas'!$K$5:$K$54,"No") -> 0
A23: Plato frío o mal temperado | C23: =COUNTIF('Registro de Quejas'!$D$5:$D$54,$A23) -> 2 | D23: =IFERROR(IF($D$11=0,"",$C23/$D$11),"") -> 0.066666667 | E23: =IFERROR(AVERAGEIFS('Registro de Quejas'!$I$5:$I$54,'Registro de Quejas'!$D$5:$D$54,$A23,'Registro de Quejas'!$I$5:$I$54,">=0"),"") -> 12 | F23: =COUNTIFS('Registro de Quejas'!$D$5:$D$54,$A23,'Registro de Quejas'!$K$5:$K$54,"No") -> 0
A24: Error en la comanda | C24: =COUNTIF('Registro de Quejas'!$D$5:$D$54,$A24) -> 4 | D24: =IFERROR(IF($D$11=0,"",$C24/$D$11),"") -> 0.13333333 | E24: =IFERROR(AVERAGEIFS('Registro de Quejas'!$I$5:$I$54,'Registro de Quejas'!$D$5:$D$54,$A24,'Registro de Quejas'!$I$5:$I$54,">=0"),"") -> 0 | F24: =COUNTIFS('Registro de Quejas'!$D$5:$D$54,$A24,'Registro de Quejas'!$K$5:$K$54,"No") -> 0
A25: Trato del personal | C25: =COUNTIF('Registro de Quejas'!$D$5:$D$54,$A25) -> 4 | D25: =IFERROR(IF($D$11=0,"",$C25/$D$11),"") -> 0.13333333 | E25: =IFERROR(AVERAGEIFS('Registro de Quejas'!$I$5:$I$54,'Registro de Quejas'!$D$5:$D$54,$A25,'Registro de Quejas'!$I$5:$I$54,">=0"),"") -> 48 | F25: =COUNTIFS('Registro de Quejas'!$D$5:$D$54,$A25,'Registro de Quejas'!$K$5:$K$54,"No") -> 1
A26: Cobro incorrecto | C26: =COUNTIF('Registro de Quejas'!$D$5:$D$54,$A26) -> 2 | D26: =IFERROR(IF($D$11=0,"",$C26/$D$11),"") -> 0.066666667 | E26: =IFERROR(AVERAGEIFS('Registro de Quejas'!$I$5:$I$54,'Registro de Quejas'!$D$5:$D$54,$A26,'Registro de Quejas'!$I$5:$I$54,">=0"),"") -> 0 | F26: =COUNTIFS('Registro de Quejas'!$D$5:$D$54,$A26,'Registro de Quejas'!$K$5:$K$54,"No") -> 0
A27: Limpieza | C27: =COUNTIF('Registro de Quejas'!$D$5:$D$54,$A27) -> 2 | D27: =IFERROR(IF($D$11=0,"",$C27/$D$11),"") -> 0.066666667 | E27: =IFERROR(AVERAGEIFS('Registro de Quejas'!$I$5:$I$54,'Registro de Quejas'!$D$5:$D$54,$A27,'Registro de Quejas'!$I$5:$I$54,">=0"),"") -> 60 | F27: =COUNTIFS('Registro de Quejas'!$D$5:$D$54,$A27,'Registro de Quejas'!$K$5:$K$54,"No") -> 0
A28: Reserva no encontrada | C28: =COUNTIF('Registro de Quejas'!$D$5:$D$54,$A28) -> 2 | D28: =IFERROR(IF($D$11=0,"",$C28/$D$11),"") -> 0.066666667 | E28: =IFERROR(AVERAGEIFS('Registro de Quejas'!$I$5:$I$54,'Registro de Quejas'!$D$5:$D$54,$A28,'Registro de Quejas'!$I$5:$I$54,">=0"),"") -> 24 | F28: =COUNTIFS('Registro de Quejas'!$D$5:$D$54,$A28,'Registro de Quejas'!$K$5:$K$54,"No") -> 0
A29: Ruido | C29: =COUNTIF('Registro de Quejas'!$D$5:$D$54,$A29) -> 2 | D29: =IFERROR(IF($D$11=0,"",$C29/$D$11),"") -> 0.066666667 | E29: =IFERROR(AVERAGEIFS('Registro de Quejas'!$I$5:$I$54,'Registro de Quejas'!$D$5:$D$54,$A29,'Registro de Quejas'!$I$5:$I$54,">=0"),"") -> 48 | F29: =COUNTIFS('Registro de Quejas'!$D$5:$D$54,$A29,'Registro de Quejas'!$K$5:$K$54,"No") -> 0
A30: Información de alérgenos | C30: =COUNTIF('Registro de Quejas'!$D$5:$D$54,$A30) -> 1 | D30: =IFERROR(IF($D$11=0,"",$C30/$D$11),"") -> 0.033333333 | E30: =IFERROR(AVERAGEIFS('Registro de Quejas'!$I$5:$I$54,'Registro de Quejas'!$D$5:$D$54,$A30,'Registro de Quejas'!$I$5:$I$54,">=0"),"") -> 24 | F30: =COUNTIFS('Registro de Quejas'!$D$5:$D$54,$A30,'Registro de Quejas'!$K$5:$K$54,"No") -> 0
A31: Producto en mal estado | C31: =COUNTIF('Registro de Quejas'!$D$5:$D$54,$A31) -> 1 | D31: =IFERROR(IF($D$11=0,"",$C31/$D$11),"") -> 0.033333333 | E31: =IFERROR(AVERAGEIFS('Registro de Quejas'!$I$5:$I$54,'Registro de Quejas'!$D$5:$D$54,$A31,'Registro de Quejas'!$I$5:$I$54,">=0"),"") -> 48 | F31: =COUNTIFS('Registro de Quejas'!$D$5:$D$54,$A31,'Registro de Quejas'!$K$5:$K$54,"No") -> 1
A33: QUEJAS POR GRAVEDAD
A34: Gravedad | B34: Qué significa | C34: Quejas | D34: SLA (horas) | E34: Horas medias hasta el cierre | F34: Dentro del SLA | G34: Cumplimiento (%)
A35: 1 | B35: Leve: molestia sin impacto en la experiencia | C35: =COUNTIF('Registro de Quejas'!$E$5:$E$54,$A35) -> 9 | D35: =IFERROR(IF($A35="","",INDEX(Parámetros!$C$6:$C$8,MATCH($A35,Parámetros!$A$6:$A$8,0))),"") -> 72 | E35: =IFERROR(AVERAGEIFS('Registro de Quejas'!$I$5:$I$54,'Registro de Quejas'!$E$5:$E$54,$A35,'Registro de Quejas'!$I$5:$I$54,">=0"),"") -> 29.333333 | F35: =COUNTIFS('Registro de Quejas'!$E$5:$E$54,$A35,'Registro de Quejas'!$K$5:$K$54,"Sí") -> 9 | G35: =IFERROR(IF($C35=0,"",$F35/$C35),"") -> 1
A36: 2 | B36: Media: afecta a la experiencia de la mesa | C36: =COUNTIF('Registro de Quejas'!$E$5:$E$54,$A36) -> 16 | D36: =IFERROR(IF($A36="","",INDEX(Parámetros!$C$6:$C$8,MATCH($A36,Parámetros!$A$6:$A$8,0))),"") -> 48 | E36: =IFERROR(AVERAGEIFS('Registro de Quejas'!$I$5:$I$54,'Registro de Quejas'!$E$5:$E$54,$A36,'Registro de Quejas'!$I$5:$I$54,">=0"),"") -> 25.5 | F36: =COUNTIFS('Registro de Quejas'!$E$5:$E$54,$A36,'Registro de Quejas'!$K$5:$K$54,"Sí") -> 16 | G36: =IFERROR(IF($C36=0,"",$F36/$C36),"") -> 1
A37: 3 | B37: Grave: riesgo sanitario, legal o reputacional | C37: =COUNTIF('Registro de Quejas'!$E$5:$E$54,$A37) -> 5 | D37: =IFERROR(IF($A37="","",INDEX(Parámetros!$C$6:$C$8,MATCH($A37,Parámetros!$A$6:$A$8,0))),"") -> 24 | E37: =IFERROR(AVERAGEIFS('Registro de Quejas'!$I$5:$I$54,'Registro de Quejas'!$E$5:$E$54,$A37,'Registro de Quejas'!$I$5:$I$54,">=0"),"") -> 28.8 | F37: =COUNTIFS('Registro de Quejas'!$E$5:$E$54,$A37,'Registro de Quejas'!$K$5:$K$54,"Sí") -> 3 | G37: =IFERROR(IF($C37=0,"",$F37/$C37),"") -> 0.6
A39: RECLAMACIONES FORMALES — el plazo lo fija tu comunidad
A40: Reclamaciones registradas | D40: =COUNTIF('Reclamaciones Formales'!$B$5:$B$24,"<>") -> 3
A41: Contestadas dentro de plazo | D41: =COUNTIF('Reclamaciones Formales'!$I$5:$I$24,"Sí") -> 2
A42: CONTESTADAS FUERA DE PLAZO | D42: =COUNTIF('Reclamaciones Formales'!$I$5:$I$24,"No") -> 1
A43: Contestadas dentro de plazo (%) | D43: =IFERROR(IF($D$41+$D$42=0,"",$D$41/($D$41+$D$42)),"") -> 0.66666667
A44: Una reclamación fuera de plazo no se arregla contestando después: se evita poniendo la fecha límite en el calendario el mismo día en que entregas la hoja.
...
