Workbook

Sheet Escandallo
A1: ESCANDALLO POR BEBIDA — 16 INSUMOS × 10 BEBIDAS, EN GRAMOS, MILILITROS Y UNIDADES
A2: Escribe solo en las celdas VERDES (precios, mermas, cantidades, mezcla y precios de carta). Importes sin IVA salvo el precio de carta. Los precios son estimaciones del kit: pon los de tu proveedor. El coste de una bebida de esta hoja NO es el «coste de bebida» del plan financiero: aquel es la media de la mezcla con la merma, no una receta.
A4: DATOS GENERALES | B4: Valor | E4: Notas
A5: IVA de la bebida servida (%) | B5: 0.1 | E5: Bebida para consumir en el acto o para llevar: 10 % (Ley 37/1992, art. 91). Los extras con precio propio van al 21 %.
A6: Food cost objetivo (% sobre el precio sin IVA) | B6: 0.25 | E6: Estimación del kit: referencia de cafetería de 22 a 30 %. Pon el que te marque tu plan financiero.
A7: Margen de vigilancia sobre el objetivo (puntos) | B7: 0.05 | E7: Hasta este margen por encima del objetivo, el semáforo dice «Vigila el coste»; más allá, «Por encima del objetivo».
A8: Gramos de café por doble (g) | B8: 16 | E8: Estimación del kit: un doble de especialidad lleva 16-18 g. Mueve los gramos de la fila del café de todas las bebidas.
A10: INSUMO (cantidad · precio) | B10: Precio sin IVA | C10: Merma | D10: Precio neto | E10: Espresso | F10: Americano | G10: Cortado | H10: Café con leche | I10: Flat white | J10: Capuchino | K10: Latte | L10: Mocha | M10: Chai latte | N10: Chocolate a la taza | O10: ORIGEN DEL PRECIO DE EJEMPLO
A11: Precio de carta con IVA (€) | E11: 2.2 | F11: 2.7 | G11: 2.4 | H11: 3.3 | I11: 3.8 | J11: 3.8 | K11: 4.2 | L11: 4.6 | M11: 4.4 | N11: 3.8
A12: Mezcla de ventas (% de las bebidas) | E12: 0.14 | F12: 0.14 | G12: 0.1 | H12: 0.16 | I12: 0.08 | J12: 0.14 | K12: 0.12 | L12: 0.04 | M12: 0.04 | N12: 0.04
A13: Dobles de espresso por bebida | E13: 1 | F13: 1 | G13: 1 | H13: 1 | I13: 1 | J13: 1 | K13: 1 | L13: 1 | M13: 0 | N13: 0
A14: Café en grano (g · €/kg) | B14: 22 | C14: 0.1 | D14: =B14/(1-C14) -> 24.444444 | E14: =E$13*$B$8 -> 16 | F14: =F$13*$B$8 -> 16 | G14: =G$13*$B$8 -> 16 | H14: =H$13*$B$8 -> 16 | I14: =I$13*$B$8 -> 16 | J14: =J$13*$B$8 -> 16 | K14: =K$13*$B$8 -> 16 | L14: =L$13*$B$8 -> 16 | ... N14: =N$13*$B$8 -> 0 | O14: Estimación del kit: 18-28 €/kg en hostelería, se toma 22 €/kg; 10 % de merma por purga y calibrado.
A15: Leche entera (ml · €/l) | B15: 1.05 | C15: 0.1 | D15: =B15/(1-C15) -> 1.1666667 | E15: 0 | F15: 0 | G15: 56 | H15: 126 | I15: 105 | J15: 112 | K15: 168 | L15: 140 | M15: 154 | N15: 140 | O15: Estimación del kit: ≈ 1,05 €/l.
A16: Leche sin lactosa (ml · €/l) | B16: 1.35 | C16: 0.1 | D16: =B16/(1-C16) -> 1.5 | E16: 0 | F16: 0 | G16: 8 | H16: 18 | I16: 15 | J16: 16 | K16: 24 | L16: 20 | M16: 22 | N16: 20 | O16: Estimación del kit.
A17: Bebida de avena barista (ml · €/l) | B17: 2.5 | C17: 0.1 | D17: =B17/(1-C17) -> 2.7777778 | E17: 0 | F17: 0 | G17: 12 | H17: 27 | I17: 22 | J17: 24 | K17: 36 | L17: 30 | M17: 33 | N17: 30 | O17: Estimación del kit: ≈ 2,50 €/l.
A18: Bebida de soja barista (ml · €/l) | B18: 1.9 | C18: 0.1 | D18: =B18/(1-C18) -> 2.1111111 | E18: 0 | F18: 0 | G18: 4 | H18: 9 | I18: 8 | J18: 8 | K18: 12 | L18: 10 | M18: 11 | N18: 10 | O18: Estimación del kit.
A19: Cacao en polvo (g · €/kg) | B19: 9 | C19: 0.05 | D19: =B19/(1-C19) -> 9.4736842 | E19: 0 | F19: 0 | G19: 0 | H19: 0 | I19: 0 | J19: 2 | K19: 0 | L19: 15 | M19: 0 | N19: 25 | O19: Estimación del kit.
A20: Concentrado de chai (ml · €/l) | B20: 6 | C20: 0.05 | D20: =B20/(1-C20) -> 6.3157895 | E20: 0 | F20: 0 | G20: 0 | H20: 0 | I20: 0 | J20: 0 | K20: 0 | L20: 0 | M20: 60 | N20: 0 | O20: Estimación del kit.
A21: Sirope de vainilla o caramelo (ml · €/l) | B21: 6 | C21: 0.05 | D21: =B21/(1-C21) -> 6.3157895 | E21: 0 | F21: 0 | G21: 0 | H21: 0 | I21: 0 | J21: 0 | K21: 10 | L21: 0 | M21: 0 | N21: 0 | O21: Estimación del kit.
A22: Té e infusiones (g · €/kg) | B22: 40 | C22: 0.05 | D22: =B22/(1-C22) -> 42.105263 | E22: 0 | F22: 0 | G22: 0 | H22: 0 | I22: 0 | J22: 0 | K22: 0 | L22: 0 | M22: 0 | N22: 0 | O22: Hueco para tu carta de infusiones: vacío en el ejemplo.
A23: Azúcar (g · €/kg) | B23: 1.5 | C23: 0 | D23: =B23/(1-C23) -> 1.5 | E23: 0 | F23: 0 | G23: 0 | H23: 0 | I23: 0 | J23: 0 | K23: 0 | L23: 8 | M23: 0 | N23: 10 | O23: Estimación del kit.
A24: Vaso de 4 oz (ud. · €/ud.) | B24: 0.05 | C24: 0.03 | D24: =B24/(1-C24) -> 0.051546392 | E24: 1 | F24: 0 | G24: 1 | H24: 0 | I24: 0 | J24: 0 | K24: 0 | L24: 0 | M24: 0 | N24: 0 | O24: Estimación del kit: vaso, tapa, servilleta y removedor suman ≈ 0,13 € por bebida.
A25: Vaso de 8 oz (ud. · €/ud.) | B25: 0.07 | C25: 0.03 | D25: =B25/(1-C25) -> 0.072164948 | E25: 0 | F25: 1 | G25: 0 | H25: 1 | I25: 1 | J25: 1 | K25: 0 | L25: 0 | M25: 0 | N25: 1 | O25: Ídem.
A26: Vaso de 12 oz (ud. · €/ud.) | B26: 0.09 | C26: 0.03 | D26: =B26/(1-C26) -> 0.092783505 | E26: 0 | F26: 0 | G26: 0 | H26: 0 | I26: 0 | J26: 0 | K26: 1 | L26: 1 | M26: 1 | N26: 0 | O26: Ídem.
... A29: Servilleta (ud. · €/ud.) | B29: 0.01 | C29: 0.03 | D29: =B29/(1-C29) -> 0.010309278 | E29: 1 | F29: 1 | G29: 1 | H29: 1 | I29: 1 | J29: 1 | K29: 1 | L29: 1 | M29: 1 | N29: 1 | O29: Ídem.
A31: RESULTADO POR BEBIDA | E31: =E10 -> Espresso | F31: =F10 -> Americano | G31: =G10 -> Cortado | H31: =H10 -> Café con leche | I31: =I10 -> Flat white | J31: =J10 -> Capuchino | K31: =K10 -> Latte | L31: =L10 -> Mocha | ... N31: =N10 -> Chocolate a la taza
A32: Leche y bebida vegetal en total (ml) | E32: =SUM(E15:E18) -> 0 | F32: =SUM(F15:F18) -> 0 | G32: =SUM(G15:G18) -> 80 | H32: =SUM(H15:H18) -> 180 | I32: =SUM(I15:I18) -> 150 | J32: =SUM(J15:J18) -> 160 | K32: =SUM(K15:K18) -> 240 | L32: =SUM(L15:L18) -> 200 | ... N32: =SUM(N15:N18) -> 200
A33: Coste de producto (€) | E33: =SUMPRODUCT(E$14:E$23,$D$14:$D$23)/1000 -> 0.39111111 | F33: =SUMPRODUCT(F$14:F$23,$D$14:$D$23)/1000 -> 0.39111111 | G33: =SUMPRODUCT(G$14:G$23,$D$14:$D$23)/1000 -> 0.51022222 | H33: =SUMPRODUCT(H$14:H$23,$D$14:$D$23)/1000 -> 0.65911111 | I33: =SUMPRODUCT(I$14:I$23,$D$14:$D$23)/1000 -> 0.61411111 | J33: =SUMPRODUCT(J$14:J$23,$D$14:$D$23)/1000 -> 0.6482807 | K33: =SUMPRODUCT(K$14:K$23,$D$14:$D$23)/1000 -> 0.81160234 | L33: =SUMPRODUCT(L$14:L$23,$D$14:$D$23)/1000 -> 0.84299415 | ... N33: =SUMPRODUCT(N$14:N$23,$D$14:$D$23)/1000 -> 0.54961988
A34: Coste de envase y mesa (€) | E34: =SUMPRODUCT(E$24:E$29,$D$24:$D$29) -> 0.072164948 | F34: =SUMPRODUCT(F$24:F$29,$D$24:$D$29) -> 0.12371134 | G34: =SUMPRODUCT(G$24:G$29,$D$24:$D$29) -> 0.072164948 | H34: =SUMPRODUCT(H$24:H$29,$D$24:$D$29) -> 0.12371134 | I34: =SUMPRODUCT(I$24:I$29,$D$24:$D$29) -> 0.12371134 | J34: =SUMPRODUCT(J$24:J$29,$D$24:$D$29) -> 0.12371134 | K34: =SUMPRODUCT(K$24:K$29,$D$24:$D$29) -> 0.1443299 | L34: =SUMPRODUCT(L$24:L$29,$D$24:$D$29) -> 0.1443299 | ... N34: =SUMPRODUCT(N$24:N$29,$D$24:$D$29) -> 0.12371134
A35: Coste total con envase (€) | E35: =E33+E34 -> 0.46327606 | F35: =F33+F34 -> 0.51482245 | G35: =G33+G34 -> 0.58238717 | H35: =H33+H34 -> 0.78282245 | I35: =I33+I34 -> 0.73782245 | J35: =J33+J34 -> 0.77199204 | K35: =K33+K34 -> 0.95593224 | L35: =L33+L34 -> 0.98732405 | ... N35: =N33+N34 -> 0.67333122
A36: Precio de carta sin IVA (€) | E36: =E11/(1+$B$5) -> 2 | F36: =F11/(1+$B$5) -> 2.4545455 | G36: =G11/(1+$B$5) -> 2.1818182 | H36: =H11/(1+$B$5) -> 3 | I36: =I11/(1+$B$5) -> 3.4545455 | J36: =J11/(1+$B$5) -> 3.4545455 | K36: =K11/(1+$B$5) -> 3.8181818 | L36: =L11/(1+$B$5) -> 4.1818182 | ... N36: =N11/(1+$B$5) -> 3.4545455
A37: Food cost sin envase | E37: =E33/E36 -> 0.19555556 | F37: =F33/F36 -> 0.15934156 | G37: =G33/G36 -> 0.23385185 | H37: =H33/H36 -> 0.2197037 | I37: =I33/I36 -> 0.17776901 | J37: =J33/J36 -> 0.1876602 | K37: =K33/K36 -> 0.21256252 | L37: =L33/L36 -> 0.20158556 | ... N37: =N33/N36 -> 0.15910049
A38: Food cost con envase | E38: =E35/E36 -> 0.23163803 | F38: =F35/F36 -> 0.20974248 | G38: =G35/G36 -> 0.26692745 | H38: =H35/H36 -> 0.26094082 | I38: =I35/I36 -> 0.21358018 | J38: =J35/J36 -> 0.22347138 | K38: =K35/K36 -> 0.2503632 | L38: =L35/L36 -> 0.23609923 | ... N38: =N35/N36 -> 0.19491167
A39: Semáforo del food cost | E39: =IF(E38<=$B$6,"En objetivo",IF(E38<=$B$6+$B$7,"Vigila el coste","Por encima del objetivo")) -> En objetivo | F39: =IF(F38<=$B$6,"En objetivo",IF(F38<=$B$6+$B$7,"Vigila el coste","Por encima del objetivo")) -> En objetivo | G39: =IF(G38<=$B$6,"En objetivo",IF(G38<=$B$6+$B$7,"Vigila el coste","Por encima del objetivo")) -> Vigila el coste | H39: =IF(H38<=$B$6,"En objetivo",IF(H38<=$B$6+$B$7,"Vigila el coste","Por encima del objetivo")) -> Vigila el coste | I39: =IF(I38<=$B$6,"En objetivo",IF(I38<=$B$6+$B$7,"Vigila el coste","Por encima del objetivo")) -> En objetivo | J39: =IF(J38<=$B$6,"En objetivo",IF(J38<=$B$6+$B$7,"Vigila el coste","Por encima del objetivo")) -> En objetivo | K39: =IF(K38<=$B$6,"En objetivo",IF(K38<=$B$6+$B$7,"Vigila el coste","Por encima del objetivo")) -> Vigila el coste | L39: =IF(L38<=$B$6,"En objetivo",IF(L38<=$B$6+$B$7,"Vigila el coste","Por encima del objetivo")) -> En objetivo | ... N39: =IF(N38<=$B$6,"En objetivo",IF(N38<=$B$6+$B$7,"Vigila el coste","Por encima del objetivo")) -> En objetivo
A40: Margen por bebida (€) | E40: =E36-E35 -> 1.5367239 | F40: =F36-F35 -> 1.939723 | G40: =G36-G35 -> 1.599431 | H40: =H36-H35 -> 2.2171775 | I40: =I36-I35 -> 2.716723 | J40: =J36-J35 -> 2.6825534 | K40: =K36-K35 -> 2.8622496 | L40: =L36-L35 -> 3.1944941 | ... N40: =N36-N35 -> 2.7812142
A41: Precio de carta con IVA para llegar al objetivo (€) | E41: =E35/$B$6*(1+$B$5) -> 2.0384147 | F41: =F35/$B$6*(1+$B$5) -> 2.2652188 | G41: =G35/$B$6*(1+$B$5) -> 2.5625036 | H41: =H35/$B$6*(1+$B$5) -> 3.4444188 | I41: =I35/$B$6*(1+$B$5) -> 3.2464188 | J41: =J35/$B$6*(1+$B$5) -> 3.396765 | K41: =K35/$B$6*(1+$B$5) -> 4.2061018 | L41: =L35/$B$6*(1+$B$5) -> 4.3442258 | ... N41: =N35/$B$6*(1+$B$5) -> 2.9626574
A43: COSTE DE LA MEZCLA (lo lee la hoja «Calculadora») | B43: Valor
A44: Suma de la mezcla de ventas | B44: =SUM($E$12:$N$12) -> 1
A45: Comprobación de la mezcla | B45: =IF(ROUND($B$44,2)=1,"Correcto: la mezcla suma el cien por cien","Revisa la mezcla: no suma el cien por cien") -> Correcto: la mezcla suma el cien por cien
A46: Coste medio por bebida sin envase (€) | B46: =IF($B$44=0,0,VALUE(SUMPRODUCT($E$12:$N$12,$E$33:$N$33))/$B$44) -> 0.58723626
...

Sheet Calculadora
A1: CALCULADORA DE PRECIOS DE CAFETERÍA MÓVIL PARA EVENTOS — DE LA TAZA AL PRESUPUESTO
A2: Escribe sólo en las celdas VERDES: todo lo demás se calcula. Importes sin IVA salvo donde la fila diga lo contrario. Los valores por defecto son estimaciones del kit (ratios de EE. UU. en el consumo): cámbialos por los tuyos.
A4: DATOS DEL EVENTO | B4: Valor | C4: Notas
A5: Cliente | B5: Particular | C5: Particular, Empresa o Feria: cambian el margen objetivo, el canon, el cobro y los tramos de cancelación (tabla del final). En Feria, «invitados» son las tazas que esperas vender.
A6: Invitados previstos (en Feria, tazas previstas) | B6: 120 | C6: Número entero de invitados a los que sirves.
A7: Formato del servicio (fija las bebidas por invitado) | B7: Más de 2 y hasta 4 horas | C7: Bebidas por invitado según las horas de barra: tabla del final (estimación del kit con ratios de EE. UU.). En Feria no se usa.
A8: Horario | B8: Noche (después de la cena) | C8: Mañana +25 %, boda de noche −10 % (estimación del kit con ratios de EE. UU.). Ajusta las bebidas por invitado. En Feria no se usa.
A9: Servicio en | B9: Loza (tazas reutilizables) | C9: Loza: sin coste de vaso ni tapa. Vaso de un solo uso: suma el envase y, en el tique, el precio aparte del vaso de plástico (Ley 7/2022, art. 55). El compostable con forro de PE o PLA también es plástico.
A10: Horas de servicio con la barra abierta | B10: 3 | C10: Se usan para el ritmo de bebidas por hora y para el personal.
A11: Horas por persona fuera del servicio (carga, viaje, montaje y limpieza) | B11: 5 | C11: Estimación del kit: un servicio de dos horas es una jornada de siete a nueve. Pon las reales.
A12: Bollería o dulce por invitado (coste, sin IVA) | B12: 0.4 | C12: Lo que te cuesta el dulce que añades al pack. 0 si no ofreces bollería.
A13: Alquileres repercutidos (carpa, cubierta, mesas, loza extra) | B13: 0 | C13: Lo que te cobra el alquilador para este evento. Si lo facturas aparte sin ser accesorio, ese importe va al 21 % de IVA.
A14: Electricidad en el lugar | B14: Enchufe de 16 A | C14: Un enchufe de 16 A a 230 V da unos 3,7 kW. Tu cafetera de dos grupos gasta de 2,4 a 4,5 kW: con una de 3,5 kW o menos cabe; si no, toma dedicada o generador inverter o baterías.
A15: Generador o baterías: coste por evento (si no hay toma) | B15: 90 | C15: Estimación del kit: combustible o carga y desgaste. Solo se suma si eliges «Sin toma».
A16: Potencia de tu cafetera de dos grupos (kW) | B16: 3.5 | C16: La del caso: 3,5 kW o menos para caber en un enchufe de 16 A. Mira la placa de tu máquina.
A17: Coste bruto por hora de un barista | B17: 13 | C17: Estimación del kit: del titular (13,7 €/h) y del camarero fijo discontinuo (10,7 €/h) con 14 pagas y 1.840 horas (40 h × 46 semanas, como el plan). Copia tu convenio.
A18: Seguridad Social a cargo de la empresa | B18: 0.33 | C18: 30,65 % de contingencias, desempleo, FOGASA, formación y MEI, más AT/EP (fijos discontinuos, art. 16 ET).
A19: Kilómetros de ida (base → lugar) | B19: 35 | C19: Se cobran ida y vuelta, en una línea aparte y sin margen (en Feria son coste tuyo).
A20: Tarifa por kilómetro de desplazamiento | B20: 0.45 | C20: Referencia de escaparate de 2026: 0,45 €/km (La Galería del Café, en Bodas.net). Pon la tuya.
A21: IVA del servicio | B21: 0.1 | C21: Ley 37/1992, art. 91: bebida para consumir en el acto, 10 %. Lo que facturas aparte con precio propio, 21 %.
A22: Feria: precio medio por taza que cobrarás (sin IVA) | B22: 3 | C22: Estimación del kit: ≈ 3,00 € sin IVA por taza. Mira el precio medio por taza de tu carta en la hoja «Escandallo». Solo cuenta si el cliente es Feria.
A23: Feria: canon fijo del organizador (€) | B23: 0 | C23: Cuota fija por emplazamiento, si el organizador la cobra. Solo cuenta en Feria.
A24: Días que faltan para el evento si el cliente cancela | B24: 45 | C24: Elige los días y la hoja te dice el tramo y lo que retienes.
A26: CÁLCULO | B26: Valor | C26: Notas
A27: LOGÍSTICA (tabla de escalado)
A28: Bebidas por invitado del formato | B28: =INDEX('Calculadora'!$B$107:$B$111,MATCH($B$7,'Calculadora'!$A$107:$A$111,0)) -> 1.4 | C28: Busca el formato en la tabla del final.
A29: Ajuste por horario | B29: =INDEX('Calculadora'!$B$114:$B$116,MATCH($B$8,'Calculadora'!$A$114:$A$116,0)) -> -0.1 | C29: Busca el horario en la tabla del final.
A30: Bebidas que se sirven (ud.) | B30: =IF($B$5='Calculadora'!$D$127,$B$6,ROUNDUP(ROUND($B$6*$B$28*(1+$B$29),2),0)) -> 152 | C30: Invitados × bebidas por invitado × (1 + ajuste), hacia arriba. En Feria, las tazas previstas.
A31: Bebidas por hora (media) | B31: =$B$30/$B$10 -> 50.666667
A32: Baristas necesarios | B32: =MAX(1,ROUNDUP(ROUND($B$31*'Calculadora'!$B$93/'Calculadora'!$B$92,2),0)) -> 2 | C32: Bebidas por hora × factor de pico ÷ lo que saca un barista, hacia arriba.
A33: Cafeteras de dos grupos (estaciones) | B33: =ROUNDUP($B$32/'Calculadora'!$B$94,0) -> 1 | C33: Dos baristas por cafetera; una segunda estación entra cuando el pico no cabe en una.
A34: Grupos en total | B34: =$B$33*'Calculadora'!$B$95 -> 2
A35: Molinos | B35: =$B$33+'Calculadora'!$B$96 -> 2 | C35: Uno por estación más uno de reserva (descafeinado o filtro).
A36: Café en grano (kg) | B36: =ROUNDUP($B$30*'Escandallo'!$B$49/1000+'Calculadora'!$B$97,1) -> 2.4 | C36: Bebidas × café medio de tu mezcla (hoja «Escandallo») más la purga y el calibrado.
A37: Leche y bebidas vegetales (l) | B37: =ROUNDUP(ROUND($B$30*'Escandallo'!$B$50/1000,2),0) -> 19 | C37: Bebidas × leche media de tu mezcla.
A38: Vasos desechables o tazas de loza (ud.) | B38: =IF($B$9='Calculadora'!$A$119,ROUNDUP(ROUND($B$6*'Calculadora'!$B$99,2),0),ROUNDUP(ROUND($B$30*(1+'Calculadora'!$B$98),2),0)) -> 150 | C38: Loza: tazas por invitado con reposición para el lavado. Vaso de un solo uso: bebidas más la reserva.
A39: Agua limpia (l) | B39: =ROUNDUP(ROUND($B$30*'Calculadora'!$B$100+'Calculadora'!$B$101,2),0) -> 58 | C39: Lleva un depósito de aguas grises al menos igual: no se vierte en el recinto. El agua de los depósitos es tu responsabilidad hasta el punto de uso.
A40: ELECTRICIDAD (aviso del contrato)
A41: Potencia de las cafeteras (kW) | B41: =$B$33*$B$16 -> 3.5 | C41: Estaciones × kW de tu cafetera.
A42: Intensidad (A) | B42: =$B$41*1000/'Calculadora'!$B$102 -> 15.217391 | C42: kW × 1.000 ÷ tensión.
...

Sheet Ejemplos
A1: 3 PRESUPUESTOS DE EJEMPLO — con las mismas fórmulas de la hoja «Calculadora»
A2: Estimaciones del kit para ilustrar el cálculo, no precios de mercado: cambia los datos en «Calculadora» para presupuestar tus eventos. Las tablas (margen y cobro por cliente, formatos, escalado) están al final de esa hoja y la mezcla de bebidas, en «Escandallo»; también mueven estos ejemplos.
A4: DATOS DEL EVENTO | B4: Boda con barra tras la cena | C4: Congreso con dos pausas de café | D4: Jornada de feria con venta directa
A5: Cliente | B5: Particular | C5: Empresa | D5: Feria
A6: Invitados previstos (en Feria, tazas previstas) | B6: 120 | C6: 300 | D6: 250
A7: Formato del servicio (fija las bebidas por invitado) | B7: Más de 2 y hasta 4 horas | C7: Congreso con pausas de café | D7: Más de 2 y hasta 4 horas
A8: Horario | B8: Noche (después de la cena) | C8: Tarde o jornada mixta | D8: Tarde o jornada mixta
A9: Servicio en | B9: Loza (tazas reutilizables) | C9: Loza (tazas reutilizables) | D9: Vaso de un solo uso
A10: Horas de servicio con la barra abierta | B10: 3 | C10: 8 | D10: 10
A11: Horas por persona fuera del servicio (carga, viaje, montaje y limpieza) | B11: 5 | C11: 2 | D11: 2
A12: Bollería o dulce por invitado (coste, sin IVA) | B12: 0.4 | C12: 0 | D12: 0
A13: Alquileres repercutidos (carpa, cubierta, mesas, loza extra) | B13: 0 | C13: 0 | D13: 0
A14: Electricidad en el lugar | B14: Enchufe de 16 A | C14: Toma dedicada | D14: Sin toma (generador o baterías)
A15: Generador o baterías: coste por evento (si no hay toma) | B15: 90 | C15: 90 | D15: 90
A16: Potencia de tu cafetera de dos grupos (kW) | B16: 3.5 | C16: 3.5 | D16: 3.5
A17: Coste bruto por hora de un barista | B17: 13 | C17: 13 | D17: 13
A18: Seguridad Social a cargo de la empresa | B18: 0.33 | C18: 0.33 | D18: 0.33
A19: Kilómetros de ida (base → lugar) | B19: 35 | C19: 25 | D19: 40
A20: Tarifa por kilómetro de desplazamiento | B20: 0.45 | C20: 0.45 | D20: 0.45
A21: IVA del servicio | B21: 0.1 | C21: 0.1 | D21: 0.1
A22: Feria: precio medio por taza que cobrarás (sin IVA) | B22: 3 | C22: 3 | D22: 3
A23: Feria: canon fijo del organizador (€) | B23: 0 | C23: 0 | D23: 0
A24: Días que faltan para el evento si el cliente cancela | B24: 45 | C24: 20 | D24: 45
A26: RESULTADO | B26: Boda con barra tras la cena | C26: Congreso con dos pausas de café | D26: Jornada de feria con venta directa
A27: LOGÍSTICA (tabla de escalado)
A28: Bebidas por invitado del formato | B28: =INDEX('Calculadora'!$B$107:$B$111,MATCH($B$7,'Calculadora'!$A$107:$A$111,0)) -> 1.4 | C28: =INDEX('Calculadora'!$B$107:$B$111,MATCH($C$7,'Calculadora'!$A$107:$A$111,0)) -> 1.6 | D28: =INDEX('Calculadora'!$B$107:$B$111,MATCH($D$7,'Calculadora'!$A$107:$A$111,0)) -> 1.4
A29: Ajuste por horario | B29: =INDEX('Calculadora'!$B$114:$B$116,MATCH($B$8,'Calculadora'!$A$114:$A$116,0)) -> -0.1 | C29: =INDEX('Calculadora'!$B$114:$B$116,MATCH($C$8,'Calculadora'!$A$114:$A$116,0)) -> 0 | D29: =INDEX('Calculadora'!$B$114:$B$116,MATCH($D$8,'Calculadora'!$A$114:$A$116,0)) -> 0
A30: Bebidas que se sirven (ud.) | B30: =IF($B$5='Calculadora'!$D$127,$B$6,ROUNDUP(ROUND($B$6*$B$28*(1+$B$29),2),0)) -> 152 | C30: =IF($C$5='Calculadora'!$D$127,$C$6,ROUNDUP(ROUND($C$6*$C$28*(1+$C$29),2),0)) -> 480 | D30: =IF($D$5='Calculadora'!$D$127,$D$6,ROUNDUP(ROUND($D$6*$D$28*(1+$D$29),2),0)) -> 250
A31: Bebidas por hora (media) | B31: =$B$30/$B$10 -> 50.666667 | C31: =$C$30/$C$10 -> 60 | D31: =$D$30/$D$10 -> 25
A32: Baristas necesarios | B32: =MAX(1,ROUNDUP(ROUND($B$31*'Calculadora'!$B$93/'Calculadora'!$B$92,2),0)) -> 2 | C32: =MAX(1,ROUNDUP(ROUND($C$31*'Calculadora'!$B$93/'Calculadora'!$B$92,2),0)) -> 2 | D32: =MAX(1,ROUNDUP(ROUND($D$31*'Calculadora'!$B$93/'Calculadora'!$B$92,2),0)) -> 1
A33: Cafeteras de dos grupos (estaciones) | B33: =ROUNDUP($B$32/'Calculadora'!$B$94,0) -> 1 | C33: =ROUNDUP($C$32/'Calculadora'!$B$94,0) -> 1 | D33: =ROUNDUP($D$32/'Calculadora'!$B$94,0) -> 1
A34: Grupos en total | B34: =$B$33*'Calculadora'!$B$95 -> 2 | C34: =$C$33*'Calculadora'!$B$95 -> 2 | D34: =$D$33*'Calculadora'!$B$95 -> 2
A35: Molinos | B35: =$B$33+'Calculadora'!$B$96 -> 2 | C35: =$C$33+'Calculadora'!$B$96 -> 2 | D35: =$D$33+'Calculadora'!$B$96 -> 2
A36: Café en grano (kg) | B36: =ROUNDUP($B$30*'Escandallo'!$B$49/1000+'Calculadora'!$B$97,1) -> 2.4 | C36: =ROUNDUP($C$30*'Escandallo'!$B$49/1000+'Calculadora'!$B$97,1) -> 7.3 | D36: =ROUNDUP($D$30*'Escandallo'!$B$49/1000+'Calculadora'!$B$97,1) -> 3.9
A37: Leche y bebidas vegetales (l) | B37: =ROUNDUP(ROUND($B$30*'Escandallo'!$B$50/1000,2),0) -> 19 | C37: =ROUNDUP(ROUND($C$30*'Escandallo'!$B$50/1000,2),0) -> 60 | D37: =ROUNDUP(ROUND($D$30*'Escandallo'!$B$50/1000,2),0) -> 32
A38: Vasos desechables o tazas de loza (ud.) | B38: =IF($B$9='Calculadora'!$A$119,ROUNDUP(ROUND($B$6*'Calculadora'!$B$99,2),0),ROUNDUP(ROUND($B$30*(1+'Calculadora'!$B$98),2),0)) -> 150 | C38: =IF($C$9='Calculadora'!$A$119,ROUNDUP(ROUND($C$6*'Calculadora'!$B$99,2),0),ROUNDUP(ROUND($C$30*(1+'Calculadora'!$B$98),2),0)) -> 375 | D38: =IF($D$9='Calculadora'!$A$119,ROUNDUP(ROUND($D$6*'Calculadora'!$B$99,2),0),ROUNDUP(ROUND($D$30*(1+'Calculadora'!$B$98),2),0)) -> 275
A39: Agua limpia (l) | B39: =ROUNDUP(ROUND($B$30*'Calculadora'!$B$100+'Calculadora'!$B$101,2),0) -> 58 | C39: =ROUNDUP(ROUND($C$30*'Calculadora'!$B$100+'Calculadora'!$B$101,2),0) -> 140 | D39: =ROUNDUP(ROUND($D$30*'Calculadora'!$B$100+'Calculadora'!$B$101,2),0) -> 83
A40: ELECTRICIDAD (aviso del contrato)
A41: Potencia de las cafeteras (kW) | B41: =$B$33*$B$16 -> 3.5 | C41: =$C$33*$C$16 -> 3.5 | D41: =$D$33*$D$16 -> 3.5
A42: Intensidad (A) | B42: =$B$41*1000/'Calculadora'!$B$102 -> 15.217391 | C42: =$C$41*1000/'Calculadora'!$B$102 -> 15.217391 | D42: =$D$41*1000/'Calculadora'!$B$102 -> 15.217391
...

Sheet Instrucciones
A1: INSTRUCCIONES DE USO — Calculadora de escandallo y presupuesto de cafetería móvil para eventos
A2: Convierte el coste de tus bebidas en un precio por invitado y en un presupuesto completo: baristas, cafeteras, molinos, kilos de café, litros de leche, vasos, potencia eléctrica y agua, subtotal, IVA, total, cobro por pagos y lo que retienes si el cliente cancela. Sólo se escribe en las celdas VERDES; el margen se calcula.
A3: HOJA «ESCANDALLO»
A5: 1. Escribe el precio sin IVA y la merma de cada insumo (café, leches, cacao, chai, sirope, té, azúcar, vasos, tapa, removedor y servilleta) y los gramos, mililitros o unidades de cada bebida. El café se calcula con los dobles por bebida y los gramos por doble.
A6: 2. Para cada bebida ves el coste de producto, el coste con envase, el precio sin IVA, el food cost con semáforo, el margen y el precio de carta que necesitarías para llegar a tu objetivo. La mezcla de ventas tiene que sumar el cien por cien: la hoja lo avisa.
A7: 3. El coste de UNA bebida de esta hoja no es el «coste de bebida» del plan financiero: aquel es la media de la mezcla con la merma (purga, calibrado y leche sobrante), no una receta. No copies uno en el otro.
A8: HOJA «CALCULADORA»
A10: 4. Elige el cliente (Particular, Empresa o Feria), los invitados, el formato (bebidas por invitado según las horas), el horario y el servicio en loza o en vaso de un solo uso. En Feria, los invitados son las tazas que esperas vender.
A11: 5. La tabla de escalado del final da baristas, cafeteras de dos grupos, molinos, kilos de café, litros de leche, vasos o tazas, potencia, toma eléctrica y agua. Es la misma que figura en las Instrucciones del plan financiero y en el plan de negocio.
A12: 6. Escribe las horas de servicio y las horas fuera del servicio (carga, viaje, montaje y limpieza), el coste bruto por hora y la Seguridad Social. Si cobras tú de barista, cuéntate a precio de hora: es tu coste de oportunidad.
A13: 7. El precio por invitado es el coste directo dividido entre (1 − margen − canon), redondeado a los 0,50 € de arriba. Verás también su equivalente por hora de barra y por bebida, para comparar con las tarifas por hora o por consumición que te pidan.
A14: 8. A una empresa se le presupuesta el precio SIN IVA («+ IVA»); a un particular, el precio CON IVA, porque en una oferta a consumidores el precio va con los impuestos incluidos. El desplazamiento va en línea aparte, ida y vuelta y sin margen.
... A37: Versión 1.0 · octubre 2026 · aichef.pro/plan-negocio-cafeteria-movil-eventos · info@aichef.pro
