Workbook

Sheet 0. Supuestos
A1: SUPUESTOS — aquí se teclean las TASAS y los DRIVERS del modelo
A2: Cambia las celdas VERDES: el resto del libro se recalcula solo. Las partidas de gasto se teclean en su hoja (también en verde) y no se repiten aquí.
A3: ACTIVIDAD
A4: Invitados por evento (media del año 1) | B4: 135 | C4: Invitados de media por evento en el año 1; en la venta directa, cada taza vendida cuenta como un invitado. Sale de la mezcla de la tabla de referencias de la hoja de Instrucciones: bodas de 120, empresa de 80, congresos o ferias de 300 asistentes, celebraciones privadas de 50 y unas 250 tazas por jornada de venta directa. Es una media: la capacidad por evento está más abajo
A5: Precio medio por invitado SIN IVA (€) | B5: 6.2 | C5: SIN IVA, por invitado: el precio del servicio de barra (paquete de bebidas ilimitadas durante unas horas) repartido entre los invitados y, en la venta directa, el precio de cada taza. Media ponderada de la mezcla: 9,00 € la boda, 8,00 € el evento de empresa, 4,50 € el asistente a un congreso, 9,50 € la celebración privada y 3,00 € la taza en la feria. Por eso la media baja. El precio con IVA (10 %) está en la fila de abajo
A6: Eventos al año | B6: 130 | C6: Eventos servidos en el año: 30 bodas, 40 de empresa (presentaciones, jornadas, team building, Navidad), 22 jornadas de congreso o feria con stand de marca, 25 celebraciones privadas y rodajes, y 12 jornadas de venta directa en mercados y festivales (la mezcla suma 129; el plan redondea a 130). Es el MISMO dato para la cuenta de resultados, el punto de equilibrio, los escenarios y las horas de personal
A7: Crecimiento de volumen del año 2 | B7: 0.1 | C7: Más actividad el segundo año: empresas y agencias que repiten, bodas que llegan por recomendación y planners que ya te conocen, sobre un primer año con la agenda aún por llenar. El libro lo aplica a los invitados por evento con los mismos eventos; en euros es lo mismo que un 10 % más de eventos del mismo tamaño. El personal no sube con este porcentaje: crece con las incorporaciones de la hoja Personal
A8: Crecimiento de volumen del año 3 | B8: 0.08 | C8: Sobre el año 2. El techo lo ponen los sábados de temporada, el calendario de congresos y una sola barra con su titular: más allá hace falta una segunda estación
A9: PVP equivalente con IVA (calculado) | B9: =IFERROR(IF($B$5="","",$B$5*(1+SUMPRODUCT('PyG 3 Años'!$E$10:$E$11,'PyG 3 Años'!$G$10:$G$11))),"") -> 6.82 | C9: =IFERROR("Precio por invitado sin IVA más el IVA medio ponderado de tus líneas de venta: "&TEXT(SUMPRODUCT('PyG 3 Años'!$E$10:$E$11,'PyG 3 Años'!$G$10:$G$11)*100,"0")&" %. Todo lo que sirve la cafetería, en la barra o en la venta directa, va al 10 % (art. 91.Uno.2.2.º de la Ley 37/1992). Aquí va redondeado. Compáralo con el precio por invitado de las barras de tu zona, que suele ir con IVA.","") -> Precio por invitado sin IVA más el IVA medio ponderado de tus líneas de venta: 10 %. Todo lo que sirve la cafetería, en la barra o en la venta directa, va al 10 % (art. 91.Uno.2.2.º de la Ley 37/1992). Aquí va redondeado. Compáralo con el precio por invitado de las barras de tu zona, que suele ir con IVA.
A10: MIX Y COSTE DE MERCANCÍA
A11: Ventas de COMIDA sobre el total | B11: 0.11 | C11: Peso de la COMIDA sobre el total de ventas. Es un INPUT: cámbialo aquí y el P&L, la tesorería y el IVA repercutido se recalculan solos
A12: Ventas de BEBIDA sobre el total | B12: =IFERROR(IF(COUNT(B11)=0,"",1-B11),"") -> 0.89 | C12: Se calcula como el resto: comida + bebida = 100 %
A13: Coste de mercancía sobre las ventas de COMIDA | B13: 0.46 | C13: Bollería y dulces comprados hechos a un obrador (cruasanes pequeños, galletas, bizcocho) sobre su venta: se sirven tal cual, sin elaborar nada en la base. Pide la ficha de alérgenos de cada pieza
A14: Coste de mercancía sobre las ventas de BEBIDA | B14: 0.16 | C14: Café, leche, bebidas vegetales, cacao, chai y siropes sobre las ventas de bebida, con la merma (purga del molino, leche que sobra en la jarra) y un punto de catas y pruebas: unos 0,59 € por bebida. Es la MEDIA de la mezcla del año, no la receta de una bebida: el coste de un espresso o de un latte concreto está en la calculadora del kit y no se copia aquí. Los vasos y las tapas van en los consumibles
A15: Consumibles sobre ventas | B15: 0.04 | C15: Vasos, tapas, servilletas y palillos de madera (unos 0,12 € por bebida servida en vaso de un solo uso), hielo, filtros de agua, detergente de grupos y gasolina del generador. En bodas y empresa se sirve en loza (se lava en la base); el vaso de un solo uso, con su precio aparte en el tique (Ley 7/2022, art. 55.2), sólo en la venta directa
A16: Ventas directas en ferias y mercados sobre el total | B16: 0.084 | C16: Parte de las ventas que se hace en VENTA DIRECTA al público, en mercados gastronómicos, ferias y festivales: 12 jornadas al año con unas 250 tazas a 3,00 € sin IVA. Va también al 10 %. En la vía pública es venta no sedentaria y necesita autorización municipal (RD 199/2010); en un recinto privado, contrato con el organizador. No es venta diaria en la calle: ese es otro negocio
A17: Canon o comisión del organizador de la feria | B17: 0.15 | C17: Canon del organizador de la feria o del mercado, como porcentaje de lo que vendes allí. Si cobra una cuota fija por jornada o por emplazamiento, divídela entre lo que prevés vender: 110 € por una jornada de 750 € sin IVA son un 15 %
A18: Comisión de los medios de pago | B18: 0.006 | C18: Casi todo se cobra por transferencia (señales de los particulares y facturas de empresa); el datáfono queda para la venta directa
A19: PERSONAL
A20: Seguridad Social a cargo de la empresa | B20: 0.33 | C20: Contingencias comunes + AT/EP + desempleo + FOGASA + FP; ajusta a tu convenio y bonificaciones
A21: Número de pagas anuales | B21: 14 | C21: Salario bruto anual = bruto mensual × pagas
A22: SMI anual de referencia (€) | B22: 17094 | C22: SMI 2026: 17.094 € al año (1.221 €/mes en 14 pagas), suelo legal por jornada completa. Comprueba el importe vigente si presentas el plan en otro ejercicio
A23: ALMACÉN BASE Y FIJOS
A24: Cuota mensual del almacén base (€) | B24: 400 | C24: Cuota del almacén base: una nave o un garaje con fregadero y punto de agua donde se lavan la loza, las jarras y los depósitos, se guardan el café, la leche y los vasos, y duerme la furgoneta. No hay cocina ni se elabora comida: no se prepara nada en casa para un evento (RD 1021/2022, art. 13.5.b), y un trastero sin agua no sirve para lavar loza ni depósitos. Pide dos presupuestos en tu zona
A25: Fianza del almacén base (meses) | B25: 2 | C25: Dos cuotas de fianza, lo habitual en un alquiler de nave o garaje
A26: Suministros mensuales (teléfono, datos y luz del almacén base) (€) | B26: 60 | C26: Teléfono, datos y luz del almacén base fuera de la cuota. La gasolina del generador va en los consumibles y el combustible de la furgoneta en varios, porque suben y bajan con los eventos
A27: Seguros (€/año) | B27: 1300 | C27: Responsabilidad civil de explotación y de producto de 300.000 a 600.000 € (unos 500 €), seguro de la furgoneta de uso comercial (650 €) y de los equipos que salen a cada evento (150 €)
A28: Varios e imprevistos sobre ventas | B28: 0.04 | C28: Combustible de los desplazamientos (2 puntos), imprevistos (1 punto) y escaparates de bodas y planners (1 punto). Es variable: sube y baja con los eventos. El desplazamiento que cobras aparte por kilómetro no está en las ventas del libro: compensa este gasto
A29: FINANCIACIÓN
A30: Recursos propios aportados (€) | B30: 25000 | C30: Aportación del socio. Un banco pide entre el 25 y el 30 % de la necesidad de caja con dinero propio
A31: Préstamo bancario solicitado (€) | B31: 44500 | C31: Principal solicitado. La hoja de Financiación compara lo que aportas con la necesidad de caja de la hoja de inversión y te dice si sobra o falta: ajústalo con ese dato
A32: Tipo de interés nominal anual | B32: 0.065 | C32: Tipo nominal anual de un préstamo de empresa sin garantía inmobiliaria. Pide oferta a dos entidades y a una línea ICO o ENISA antes de fijarlo
A33: Plazo del préstamo (años) | B33: 6 | C33: Años totales, carencia incluida: la vida de la cafetera y del equipo
A34: Carencia de principal (años) | B34: 1 | C34: El primer año sólo intereses: es cuando la caja está más tensa, con la agenda de bodas y empresas aún por llenar. Desde el segundo año se devuelve el principal: mira la holgura de caja de ese año en el Punto de Equilibrio
A35: Fondo de maniobra (meses de costes fijos) | B35: 3 | C35: Tres meses de costes fijos: cubren el valle de agosto y el de enero y febrero, y los 30-60 días que tardan en pagar empresas y agencias
A36: FISCAL
A37: Impuesto de Sociedades, nueva creación | B37: 0.15 | C37: Art. 29.1 LIS: el PRIMER ejercicio con base imponible positiva y el SIGUIENTE. El libro lo aproxima contando los dos primeros ejercicios con base positiva: coincide con la ley salvo que entre ellos haya un ejercicio en pérdidas
A38: Impuesto de Sociedades, tipo general | B38: 0.25 | C38: A partir del tercer ejercicio con base positiva. Es el tipo general del art. 29.1 LIS: si tu cifra de negocios queda por debajo de 1 M € (microempresa) o de 10 M € (reducida dimensión), desde 2025 hay tipos más bajos que se implantan de forma gradual; confirma el de tu ejercicio con tu asesor y cámbialo aquí
A39: IVA repercutido de restauración | B39: 0.1 | C39: Tipo reducido de hostelería
A40: IVA repercutido/soportado general | B40: 0.21 | C40: Tipo general. En este plan es el de los extras con precio propio (personalización de la barra, talleres de latte art o alquiler de la cafetera sin barista), que no están en este libro; suministros, equipamiento y servicios tienen su tipo en la celda de abajo. La cafetería no sirve alcohol: todo lo que vende va al reducido, y el libro carga la compra de café y bebidas al 10 %. La leche se factura al 4 %, así que el IVA que soportas de verdad es algo menor que el del libro (art. 91.Dos.1.1.º de la Ley 37/1992)
...

Sheet Inversión Inicial
A1: PLAN DE NEGOCIO: CAFETERÍA MÓVIL PARA EVENTOS
A2: Inversión inicial estimada — barra de café de especialidad para bodas, empresas y ferias
A3: Ajusta las cifras a tu proyecto.
A5: Concepto | B5: Importe | C5: % s/inversión | D5: Notas | E5: ¿Lleva IVA?
A6: INVERSIÓN | B6: =IFERROR(IF(COUNT(B7:B23)=0,"",SUM(B7:B23)),"") -> 44416 | C6: =IFERROR(B6/$B$26,"") -> 0.73951969
A7: Furgoneta usada con rotulación y anclajes | B7: 15200 | C7: =IFERROR(B7/$B$26,"") -> 0.2530777 | D7: Furgoneta de ocasión tipo Kangoo L2 o Trafic (12.000-16.000 € en el mercado; el caso, 14.000 €) con la rotulación de la marca, estanterías y anclajes para llevar la barra, la cafetera y los depósitos sujetos. Si fijas en ella fregadero, depósitos o mueble, es una reforma de vehículo: informe de conformidad e ITV. Estimación del kit. Si la compras a un particular no hay IVA, sino el impuesto de transmisiones; en un concesionario, en REBU, el IVA no se deduce: pon «No» en la columna de al lado | E7: Sí
A8: Barra-carro a medida con ruedas y depósitos ocultos, carpa e iluminación | B8: 4400 | C8: =IFERROR(B8/$B$26,"") -> 0.073259335 | D8: Barra móvil fabricada a medida, con los depósitos de agua escondidos y ruedas para entrar en salones y pabellones, más una carpa de 3 × 3 m y la iluminación para los servicios de noche. Una mesa de barista básica ronda los 1.800 € sin máquina. Estimación del kit | E8: Sí
A9: Cafetera de dos grupos de gama media (3,5 kW como máximo) | B9: 5500 | C9: =IFERROR(B9/$B$26,"") -> 0.091574169 | D9: Máquina de espresso de dos grupos de gama media (3.000-6.000 €). Que no pase de 3,5 kW: así cabe en un enchufe de 16 A (unos 3,7 kW) y no dependes del generador en cada finca. Estimación del kit | E9: Sí
A10: Molinos: espresso bajo demanda y descafeinado o filtro | B10: 2100 | C10: =IFERROR(B10/$B$26,"") -> 0.034964683 | D10: Un molino de espresso bajo demanda profesional (unos 1.430 € sin IVA) y otro para el descafeinado o el filtro (unos 620 €): el invitado español pide descafeinado de máquina. Fichas de distribuidor | E10: Sí
A11: Energía: generador inverter de 5-7 kVA o primera batería, y cuadro con protecciones | B11: 4500 | C11: =IFERROR(B11/$B$26,"") -> 0.07492432 | D11: Para las fincas sin toma suficiente: un generador inverter de 5 kVA o más (los de 7 kVA, 4.300-5.350 €) o una primera batería de litio con inversor, silenciosa para bodas (un sistema completo, 6.000-10.000 €), con un cuadro con protecciones. Estimación del kit | E11: Sí
A12: Agua e higiene: depósitos alimentarios, bomba, filtro descalcificador y lavamanos | B12: 1000 | C12: =IFERROR(B12/$B$26,"") -> 0.016649849 | D12: Dos depósitos de uso alimentario (agua limpia y gris), bomba, filtro descalcificador para la cafetera y un lavamanos autónomo. El agua se carga en red pública y el operador responde de ella hasta el punto de uso (RD 3/2023, arts. 65.3 y 66.b) | E12: Sí
A13: Frío: nevera bajo barra, neveras portátiles, acumuladores y termómetro | B13: 900 | C13: =IFERROR(B13/$B$26,"") -> 0.014984864 | D13: Leche y bebidas vegetales a la temperatura de su etiqueta desde la base hasta la barra, y un termómetro para el registro del APPCC | E13: Sí
A14: Menaje: jarras por tipo de leche, tampers, básculas, cajón de posos y loza | B14: 1500 | C14: =IFERROR(B14/$B$26,"") -> 0.024974773 | D14: Una jarra por cada tipo de leche (alérgenos), tampers, básculas de extracción, cajón de posos, loza para 150 invitados y cajas para transportarla. En bodas y eventos de empresa se sirve en loza: es la opción segura con la normativa de envases | E14: Sí
A15: TPV, datáfono y software | B15: 600 | C15: =IFERROR(B15/$B$26,"") -> 0.0099899094 | D15: Cobro en la venta directa y facturación conforme a Veri*factu | E15: Sí
A16: Marca, web, fotos y dossier | B16: 2000 | C16: =IFERROR(B16/$B$26,"") -> 0.033299698 | D16: Identidad, web con formulario de presupuesto, sesión de fotos de la barra y dossier para novios, empresas, agencias y planners | E16: Sí
A17: Constitución SL + notaría + registro | B17: 1000 | C17: =IFERROR(B17/$B$26,"") -> 0.016649849 | D17: SL unipersonal. Las tasas y el arancel del Registro no llevan IVA; los honorarios del notario y de la gestoría sí: cambia la columna de al lado a «Sí» si tu presupuesto es sobre todo de honorarios | E17: No
A18: Declaración responsable, APPCC, alérgenos y formación de barista | B18: 1000 | C18: =IFERROR(B18/$B$26,"") -> 0.016649849 | D18: Redacción del plan APPCC itinerante, fichas de alérgenos de cada bebida y de la bollería, formación en higiene alimentaria y curso de barista | E18: Sí
... A20: Lanzamiento: feria nupcial, escaparate de bodas y catas para agencias | B20: 1500 | C20: =IFERROR(B20/$B$26,"") -> 0.024974773 | D20: Stand en una feria nupcial, alta destacada en un portal de bodas y catas para agencias y planners antes del primer evento | E20: Sí
A21: Fianza del almacén base | B21: =IFERROR(IF('0. Supuestos'!$B$24="","",'0. Supuestos'!$B$24*'0. Supuestos'!$B$25),"") -> 800 | C21: =IFERROR(B21/$B$26,"") -> 0.013319879 | D21: =IFERROR(""&TEXT('0. Supuestos'!$B$25,"0")&" cuotas del almacén base, al tipo de la hoja de Supuestos. Es un activo recuperable al cerrar: ni se amortiza ni lleva IVA","") -> 2 cuotas del almacén base, al tipo de la hoja de Supuestos. Es un activo recuperable al cerrar: ni se amortiza ni lleva IVA | E21: No
A22: Cuota del almacén base de los meses previos al arranque | B22: =IFERROR(IF('0. Supuestos'!$B$24="","",'0. Supuestos'!$B$24*'0. Supuestos'!$B$54),"") -> 400 | C22: =IFERROR(B22/$B$26,"") -> 0.0066599396 | D22: =IFERROR("Cuota "&IF('0. Supuestos'!$B$54=1,"del mes","de los "&TEXT('0. Supuestos'!$B$54,"0")&" meses")&" de puesta en marcha (montaje del almacén, calibrado de la cafetera, catas y primeras reservas). NO se solapa con el P&L, que arranca el día de la apertura: los doce meses del P&L son los doce de explotación","") -> Cuota del mes de puesta en marcha (montaje del almacén, calibrado de la cafetera, catas y primeras reservas). NO se solapa con el P&L, que arranca el día de la apertura: los doce meses del P&L son los doce de explotación | E22: Sí
A23: Imprevistos de la compra y preparación de la furgoneta | B23: =IFERROR(IF(COUNT(B7)=0,"",ROUND((B7)*'0. Supuestos'!$B$55,0)),"") -> 1216 | C23: =IFERROR(B23/$B$26,"") -> 0.020246216 | D23: =IFERROR("Al "&TEXT('0. Supuestos'!$B$55,"0%")&" de las partidas de la furgoneta de este bloque (Furgoneta usada con rotulación y anclajes), no del bloque entero: el resto de partidas del bloque quedan fuera. Un banco no financia una compra así sin colchón: el porcentaje está en la hoja de Supuestos","") -> Al 8% de las partidas de la furgoneta de este bloque (Furgoneta usada con rotulación y anclajes), no del bloque entero: el resto de partidas del bloque quedan fuera. Un banco no financia una compra así sin colchón: el porcentaje está en la hoja de Supuestos | E23: Sí
A24: FONDO DE MANIOBRA | B24: =IFERROR(IF(B25="","",B25),"") -> 15644.605 | C24: =IFERROR(B24/$B$26,"") -> 0.26048031
A25: Colchón operativo hasta alcanzar el equilibrio | B25: =IFERROR(IF('0. Supuestos'!$B$35*('PyG 3 Años'!$B$38-'PyG 3 Años'!$B$36)=0,"",'0. Supuestos'!$B$35*('PyG 3 Años'!$B$38-'PyG 3 Años'!$B$36)/12),"") -> 15644.605 | C25: =IFERROR(B25/$B$26,"") -> 0.26048031 | D25: =IFERROR("Cubre "&TEXT('0. Supuestos'!$B$35,"0")&IF('0. Supuestos'!$B$35=1," mes"," meses")&" de costes fijos DE CAJA del año 1 (los del P&L menos la amortización, que no se paga), que es el mínimo que exigen las Instrucciones de este libro","") -> Cubre 3 meses de costes fijos DE CAJA del año 1 (los del P&L menos la amortización, que no se paga), que es el mínimo que exigen las Instrucciones de este libro | E25: No
A26: INVERSIÓN TOTAL (suma de los bloques) | B26: =IFERROR(B6+B24,"") -> 60060.605 | D26: =IFERROR("Los porcentajes de la columna C se leen sobre esta cifra, que incluye el fondo de maniobra ("&TEXT(C24,"0%")&" del total). Para comparar el desglose con otro plan, usa la fila de CAPEX de abajo.","") -> Los porcentajes de la columna C se leen sobre esta cifra, que incluye el fondo de maniobra (26% del total). Para comparar el desglose con otro plan, usa la fila de CAPEX de abajo.
A27: CAPEX (inversión sin el fondo de maniobra) | B27: =IFERROR(B26-B24,"") -> 44416 | D27: Es lo que se compra: furgoneta, equipamiento, lanzamiento y gastos de constitución. El colchón de caja no es inversión, es circulante
A28: IVA soportado sobre la inversión (recuperable) | B28: =IFERROR(IF(B26="","",SUMIF($E$7:$E$23,"Sí",$B$7:$B$23)*'0. Supuestos'!$B$41),"") -> 8949.36 | D28: =IFERROR("Al "&TEXT('0. Supuestos'!$B$41,"0%")&" sobre las partidas marcadas con «Sí» en la columna de IVA. Las tasas y licencias no están sujetas y los seguros están exentos (art. 20.Uno.16 LIVA). Las tasas y aranceles registrales no llevan IVA; los honorarios de notaría y gestoría sí "&"(21 %, deducible). Se recupera con el modelo 303, pero hay que adelantarlo","") -> Al 21% sobre las partidas marcadas con «Sí» en la columna de IVA. Las tasas y licencias no están sujetas y los seguros están exentos (art. 20.Uno.16 LIVA). Las tasas y aranceles registrales no llevan IVA; los honorarios de notaría y gestoría sí (21 %, deducible). Se recupera con el modelo 303, pero hay que adelantarlo
A29: NECESIDAD TOTAL DE CAJA AL ARRANQUE | B29: =IFERROR(B26+B28,"") -> 69009.965 | D29: Es la cifra que tiene que cubrir la hoja de Financiación
A30: BASES DE AMORTIZACIÓN (no suman a la inversión)
A31: Furgoneta, rotulación e imprevistos | B31: =IFERROR(IF(B7="","",B7+B23),"") -> 16416 | D31: =IFERROR("Se amortiza en "&TEXT('0. Supuestos'!$B$44,"0")&" años","") -> Se amortiza en 8 años
A32: Maquinaria, mobiliario y equipos | B32: =IFERROR(IF(B8="","",B8+B9+B10+B11+B12+B13+B14+B15),"") -> 20500 | D32: =IFERROR("Se amortiza en "&TEXT('0. Supuestos'!$B$45,"0")&" años","") -> Se amortiza en 10 años
A33: Amortización anual del inmovilizado | B33: =IFERROR(B31/MAX(1,'0. Supuestos'!$B$44)+B32/MAX(1,'0. Supuestos'!$B$45),"") -> 4102 | D33: =IFERROR("No se amortizan, por no ser inmovilizado, Marca, web, fotos y dossier, Constitución SL + notaría + registro, Declaración responsable, APPCC, alérgenos y formación de barista, Stock inicial: café, leche UHT y vasos, Lanzamiento: feria "&"nupcial, escaparate de bodas y catas para agencias, Fianza del almacén base, Cuota del almacén base de los meses previos al arranque ni Colchón operativo hasta alcanzar el equilibrio. Suman "&TEXT(B26-B31-B32,"0")&" € de los "&TEXT(B26,"0")&" € de inversión.","") -> No se amortizan, por no ser inmovilizado, Marca, web, fotos y dossier, Constitución SL + notaría + registro, Declaración responsable, APPCC, alérgenos y formación de barista, Stock inicial: café, leche UHT y vasos, Lanzamiento: feria nupcial, escaparate de bodas y catas para agencias, Fianza del almacén base, Cuota del almacén base de los meses previos al arranque ni Colchón operativo hasta alcanzar el equilibrio. Suman 23145 € de los 60061 € de inversión.

Sheet PyG 3 Años
A1: CUENTA DE RESULTADOS PREVISIONAL — 3 AÑOS
A2: Escenario realista — cafetería móvil para eventos
A4: Concepto | B4: Año 1 | C4: Año 2 | D4: Año 3 | E4: % s/ventas (año 1) | F4: Notas | G4: Tipo de IVA de la línea (%)
A5: INGRESOS
A6: Invitados por evento (media) | B6: =IFERROR(IF('0. Supuestos'!$B$4="","",'0. Supuestos'!$B$4),"") -> 135 | C6: =IFERROR(B6*(1+'0. Supuestos'!$B$7),"") -> 148.5 | D6: =IFERROR(C6*(1+'0. Supuestos'!$B$8),"") -> 160.38 | F6: El crecimiento de los años 2 y 3 está en la hoja de Supuestos
A7: Precio medio por invitado sin IVA | B7: =IFERROR(IF('0. Supuestos'!$B$5="","",'0. Supuestos'!$B$5),"") -> 6.2 | C7: =IFERROR(IF(B7="","",B7),"") -> 6.2 | D7: =IFERROR(IF(C7="","",C7),"") -> 6.2 | F7: Constante en euros del año 1: una subida de precios es una decisión aparte
A8: Eventos al año | B8: =IFERROR(IF('0. Supuestos'!$B$6="","",'0. Supuestos'!$B$6),"") -> 130 | C8: =IFERROR(IF(B8="","",B8),"") -> 130 | D8: =IFERROR(IF(C8="","",C8),"") -> 130
A9: INGRESOS TOTALES (sin IVA) | B9: =IFERROR(IF(B6*B7*B8=0,"",B6*B7*B8),"") -> 108810 | C9: =IFERROR(IF(C6*C7*C8=0,"",C6*C7*C8),"") -> 119691 | D9: =IFERROR(IF(D6*D7*D8=0,"",D6*D7*D8),"") -> 129266.28 | E9: =IFERROR(IF(B9="","",1),"") -> 1
A10: Dulces y bollería de obrador | B10: =IFERROR(IF(B9="","",B9*$E$10),"") -> 11969.1 | C10: =IFERROR(IF(C9="","",C9*$E$10),"") -> 13166.01 | D10: =IFERROR(IF(D9="","",D9*$E$10),"") -> 14219.291 | E10: =IFERROR(IF('0. Supuestos'!$B$11="","",'0. Supuestos'!$B$11),"") -> 0.11 | F10: Bollería y dulces comprados a un obrador que se añaden al paquete de café o se venden en la feria: se sirven tal cual, sin elaborar. Al 10 % de IVA | G10: =IFERROR(IF(B9="","",'0. Supuestos'!$B$39),"") -> 0.1
A11: Bebidas de café y sin café | B11: =IFERROR(IF(B9="","",B9*$E$11),"") -> 96840.9 | C11: =IFERROR(IF(C9="","",C9*$E$11),"") -> 106524.99 | D11: =IFERROR(IF(D9="","",D9*$E$11),"") -> 115046.99 | E11: =IFERROR(IF('0. Supuestos'!$B$12="","",'0. Supuestos'!$B$12),"") -> 0.89 | F11: Espresso, americano, cortado, café con leche, flat white, capuchino, latte, mocha, chai y chocolate, con leche entera, sin lactosa o bebida vegetal. Sin alcohol. Al 10 % de IVA, en la barra del evento y en la venta directa | G11: =IFERROR(IF(B9="","",('0. Supuestos'!$B$62*((1-'0. Supuestos'!$B$16)*'0. Supuestos'!$B$63+'0. Supuestos'!$B$16*'0. Supuestos'!$B$40)+(1-'0. Supuestos'!$B$62)*'0. Supuestos'!$B$39)),"") -> 0.1
A12: COSTES VARIABLES
A13: Coste de mercancía — comida | B13: =IFERROR(IF(B9="","",B9*'0. Supuestos'!$B$11*'0. Supuestos'!$B$13),"") -> 5505.786 | C13: =IFERROR(IF(C9="","",C9*'0. Supuestos'!$B$11*'0. Supuestos'!$B$13),"") -> 6056.3646 | D13: =IFERROR(IF(D9="","",D9*'0. Supuestos'!$B$11*'0. Supuestos'!$B$13),"") -> 6540.8738 | E13: =IFERROR(B13/$B$9,"") -> 0.0506 | F13: =IFERROR("Al "&TEXT('0. Supuestos'!$B$13,"0%")&" de las ventas de COMIDA, no del total: la bebida tiene su propia línea","") -> Al 46% de las ventas de COMIDA, no del total: la bebida tiene su propia línea | G13: =IFERROR(IF(B9="","",'0. Supuestos'!$B$39),"") -> 0.1
A14: Coste de mercancía — bebida | B14: =IFERROR(IF(B9="","",B9*'0. Supuestos'!$B$12*'0. Supuestos'!$B$14),"") -> 15494.544 | C14: =IFERROR(IF(C9="","",C9*'0. Supuestos'!$B$12*'0. Supuestos'!$B$14),"") -> 17043.998 | D14: =IFERROR(IF(D9="","",D9*'0. Supuestos'!$B$12*'0. Supuestos'!$B$14),"") -> 18407.518 | E14: =IFERROR(B14/$B$9,"") -> 0.1424 | F14: =IFERROR("Al "&TEXT('0. Supuestos'!$B$14,"0%")&" de las ventas de BEBIDA","") -> Al 16% de las ventas de BEBIDA | G14: =IFERROR(IF(B9="","",('0. Supuestos'!$B$62*'0. Supuestos'!$B$40+(1-'0. Supuestos'!$B$62)*'0. Supuestos'!$B$39)),"") -> 0.1
A15: Consumibles y envases | B15: =IFERROR(IF(B9="","",B9*'0. Supuestos'!$B$15),"") -> 4352.4 | C15: =IFERROR(IF(C9="","",C9*'0. Supuestos'!$B$15),"") -> 4787.64 | D15: =IFERROR(IF(D9="","",D9*'0. Supuestos'!$B$15),"") -> 5170.6512 | E15: =IFERROR(B15/$B$9,"") -> 0.04 | G15: =IFERROR(IF(B9="","",'0. Supuestos'!$B$41),"") -> 0.21
A16: Canon de ferias y mercados | B16: =IFERROR(IF(B9="","",B9*'0. Supuestos'!$B$16*'0. Supuestos'!$B$17),"") -> 1371.006 | C16: =IFERROR(IF(C9="","",C9*'0. Supuestos'!$B$16*'0. Supuestos'!$B$17),"") -> 1508.1066 | D16: =IFERROR(IF(D9="","",D9*'0. Supuestos'!$B$16*'0. Supuestos'!$B$17),"") -> 1628.7551 | E16: =IFERROR(B16/$B$9,"") -> 0.0126 | F16: Sobre las ventas DEL CANAL. Con 0 % de ferias y mercados en Supuestos, esta línea vale cero | G16: =IFERROR(IF(B9="","",'0. Supuestos'!$B$41),"") -> 0.21
A17: Comisiones de los medios de pago | B17: =IFERROR(IF(B9="","",B9*'0. Supuestos'!$B$18),"") -> 652.86 | C17: =IFERROR(IF(C9="","",C9*'0. Supuestos'!$B$18),"") -> 718.146 | D17: =IFERROR(IF(D9="","",D9*'0. Supuestos'!$B$18),"") -> 775.59768 | E17: =IFERROR(B17/$B$9,"") -> 0.006 | F17: Las comisiones de los medios de pago están EXENTAS de IVA (art. 20.Uno.18 LIVA): no se deduce nada por ellas | G17: 0
A18: Varios e imprevistos | B18: =IFERROR(IF(B9="","",B9*'0. Supuestos'!$B$28),"") -> 4352.4 | C18: =IFERROR(IF(C9="","",C9*'0. Supuestos'!$B$28),"") -> 4787.64 | D18: =IFERROR(IF(D9="","",D9*'0. Supuestos'!$B$28),"") -> 5170.6512 | E18: =IFERROR(B18/$B$9,"") -> 0.04 | F18: =IFERROR("Al "&TEXT('0. Supuestos'!$B$28,"0%")&" de las ventas. Es un coste VARIABLE: sube y baja con la facturación, así que no puede vivir en los costes fijos","") -> Al 4% de las ventas. Es un coste VARIABLE: sube y baja con la facturación, así que no puede vivir en los costes fijos | G18: =IFERROR(IF(B9="","",'0. Supuestos'!$B$41),"") -> 0.21
A19: TOTAL COSTES VARIABLES | B19: =IFERROR(IF(B9="","",SUM(B13:B18)),"") -> 31728.996 | C19: =IFERROR(IF(C9="","",SUM(C13:C18)),"") -> 34901.896 | D19: =IFERROR(IF(D9="","",SUM(D13:D18)),"") -> 37694.047 | E19: =IFERROR(B19/$B$9,"") -> 0.2916
A20: MARGEN BRUTO | B20: =IFERROR(IF(B9="","",B9-B19),"") -> 77081.004 | C20: =IFERROR(IF(C9="","",C9-C19),"") -> 84789.104 | D20: =IFERROR(IF(D9="","",D9-D19),"") -> 91572.233 | E20: =IFERROR(B20/$B$9,"") -> 0.7084
A21: COSTES FIJOS
A22: Cuota del almacén base | B22: =IFERROR(IF(B9="","",'0. Supuestos'!$B$24*12),"") -> 4800 | C22: =IFERROR(IF(C9="","",B22*(1+'0. Supuestos'!$B$48)),"") -> 4800 | D22: =IFERROR(IF(D9="","",C22*(1+'0. Supuestos'!$B$48)),"") -> 4800 | E22: =IFERROR(B22/$B$9,"") -> 0.044113593 | F22: El importe mensual está en la hoja de Supuestos; aquí se multiplica por doce. Es la cuota de una nave o un garaje con fregadero y punto de agua (lavado de loza, jarras y depósitos, almacén de café, leche y vasos, y plaza para la furgoneta). El mes previo al primer evento está en la hoja de Inversión y NO se cuenta dos veces | G22: =IFERROR(IF(B9="","",'0. Supuestos'!$B$41),"") -> 0.21
A23: Personal (nóminas + Seguridad Social) | B23: =IFERROR(IF(B9="","",'Personal'!$G$9),"") -> 44985.92 | C23: =IFERROR(IF(C9="","",'Personal'!$B$13),"") -> 50985.92 | D23: =IFERROR(IF(D9="","",'Personal'!$B$14),"") -> 56985.92 | E23: =IFERROR(B23/$B$9,"") -> 0.41343553 | F23: Sale de la hoja de Personal: es el MISMO número, no una estimación aparte. Los años 2 y 3 suman las INCORPORACIONES declaradas en esa hoja, no un porcentaje de volumen | G23: 0
A24: Suministros (teléfono, datos y luz del almacén base) | B24: =IFERROR(IF(B9="","",'0. Supuestos'!$B$26*12),"") -> 720 | C24: =IFERROR(IF(C9="","",B24*(1+'0. Supuestos'!$B$48)),"") -> 720 | D24: =IFERROR(IF(D9="","",C24*(1+'0. Supuestos'!$B$48)),"") -> 720 | E24: =IFERROR(B24/$B$9,"") -> 0.0066170389 | F24: Teléfono, datos y luz del almacén base. La gasolina del generador va en los consumibles. Va al 21 % de IVA | G24: =IFERROR(IF(B9="","",'0. Supuestos'!$B$41),"") -> 0.21
A25: Seguros (RC + multirriesgo) | B25: =IFERROR(IF(B9="","",'0. Supuestos'!$B$27),"") -> 1300 | C25: =IFERROR(IF(C9="","",B25*(1+'0. Supuestos'!$B$48)),"") -> 1300 | D25: =IFERROR(IF(D9="","",C25*(1+'0. Supuestos'!$B$48)),"") -> 1300 | E25: =IFERROR(B25/$B$9,"") -> 0.011947431 | F25: Las operaciones de seguro están EXENTAS de IVA (art. 20.Uno.16 LIVA): la prima no lleva IVA deducible | G25: 0
A26: Asesoría fiscal y laboral (nóminas de fijos discontinuos) | B26: 1680 | C26: =IFERROR(IF(C9="","",B26*(1+'0. Supuestos'!$B$48)),"") -> 1680 | D26: =IFERROR(IF(D9="","",C26*(1+'0. Supuestos'!$B$48)),"") -> 1680 | E26: =IFERROR(B26/$B$9,"") -> 0.015439757 | F26: Contabilidad, impuestos de la SL y nóminas de los fijos discontinuos de cada mes con llamamientos | G26: =IFERROR(IF(B9="","",'0. Supuestos'!$B$41),"") -> 0.21
A27: Furgoneta: mantenimiento, neumáticos e ITV | B27: 800 | C27: =IFERROR(IF(C9="","",B27*(1+'0. Supuestos'!$B$48)),"") -> 800 | D27: =IFERROR(IF(D9="","",C27*(1+'0. Supuestos'!$B$48)),"") -> 800 | E27: =IFERROR(B27/$B$9,"") -> 0.0073522654 | F27: Taller, neumáticos e ITV de la furgoneta (y del remolque, si lo usas) | G27: =IFERROR(IF(B9="","",'0. Supuestos'!$B$41),"") -> 0.21
A28: Marketing: escaparate de bodas, Google Ads local, redes y feria nupcial | B28: 3000 | C28: =IFERROR(IF(C9="","",B28*(1+'0. Supuestos'!$B$48)),"") -> 3000 | D28: =IFERROR(IF(D9="","",C28*(1+'0. Supuestos'!$B$48)),"") -> 3000 | E28: =IFERROR(B28/$B$9,"") -> 0.027570995 | F28: Ficha en los portales de bodas, Google Ads local, redes sociales y una feria nupcial al año | G28: =IFERROR(IF(B9="","",'0. Supuestos'!$B$41),"") -> 0.21
A29: Software de gestión comercial, CRM y teléfono | B29: 500 | C29: =IFERROR(IF(C9="","",B29*(1+'0. Supuestos'!$B$48)),"") -> 500 | D29: =IFERROR(IF(D9="","",C29*(1+'0. Supuestos'!$B$48)),"") -> 500 | E29: =IFERROR(B29/$B$9,"") -> 0.0045951659 | F29: Presupuestos, agenda de eventos, CRM de clientes y línea de teléfono | G29: =IFERROR(IF(B9="","",'0. Supuestos'!$B$41),"") -> 0.21
A30: Mantenimiento de la cafetera y los molinos (técnico, juntas y filtros) | B30: 600 | C30: =IFERROR(IF(C9="","",B30*(1+'0. Supuestos'!$B$48)),"") -> 600 | D30: =IFERROR(IF(D9="","",C30*(1+'0. Supuestos'!$B$48)),"") -> 600 | E30: =IFERROR(B30/$B$9,"") -> 0.0055141991 | F30: Revisión anual del técnico, juntas y duchas de los grupos, fresas del molino y cartuchos del filtro descalcificador | G30: =IFERROR(IF(B9="","",'0. Supuestos'!$B$41),"") -> 0.21
A31: Uniformes y lavandería | B31: 300 | C31: =IFERROR(IF(C9="","",B31*(1+'0. Supuestos'!$B$48)),"") -> 300 | D31: =IFERROR(IF(D9="","",C31*(1+'0. Supuestos'!$B$48)),"") -> 300 | E31: =IFERROR(B31/$B$9,"") -> 0.0027570995 | F31: Delantales, camisas y paños: lavado y reposición | G31: =IFERROR(IF(B9="","",'0. Supuestos'!$B$41),"") -> 0.21
A32: Gestión de residuos (posos de café y envases) | B32: 100 | C32: =IFERROR(IF(C9="","",B32*(1+'0. Supuestos'!$B$48)),"") -> 100 | D32: =IFERROR(IF(D9="","",C32*(1+'0. Supuestos'!$B$48)),"") -> 100 | E32: =IFERROR(B32/$B$9,"") -> 0.00091903318 | F32: Retirada de posos y envases al punto autorizado; el agua gris de los depósitos, nunca al terreno de la finca | G32: =IFERROR(IF(B9="","",'0. Supuestos'!$B$41),"") -> 0.21
A33: Prevención de riesgos laborales y vigilancia de la salud | B33: 300 | C33: =IFERROR(IF(C9="","",B33*(1+'0. Supuestos'!$B$48)),"") -> 300 | D33: =IFERROR(IF(D9="","",C33*(1+'0. Supuestos'!$B$48)),"") -> 300 | E33: =IFERROR(B33/$B$9,"") -> 0.0027570995 | F33: Plan de prevención obligatorio (Ley 31/1995): quemaduras de vapor, cargas, conducción y posturas, y reconocimientos médicos | G33: =IFERROR(IF(B9="","",'0. Supuestos'!$B$41),"") -> 0.21
A34: Catas y degustaciones comerciales | B34: 300 | C34: =IFERROR(IF(C9="","",B34*(1+'0. Supuestos'!$B$48)),"") -> 300 | D34: =IFERROR(IF(D9="","",C34*(1+'0. Supuestos'!$B$48)),"") -> 300 | E34: =IFERROR(B34/$B$9,"") -> 0.0027570995 | F34: Café, leche y horas de las catas para novios, agencias y planners que no se cobran | G34: =IFERROR(IF(B9="","",'0. Supuestos'!$B$41),"") -> 0.21
A35: Licencias y tasas de venta en ferias y mercados | B35: 300 | C35: =IFERROR(IF(C9="","",B35*(1+'0. Supuestos'!$B$48)),"") -> 300 | D35: =IFERROR(IF(D9="","",C35*(1+'0. Supuestos'!$B$48)),"") -> 300 | E35: =IFERROR(B35/$B$9,"") -> 0.0027570995 | F35: Autorizaciones municipales de venta no sedentaria y tasas de ocupación de las jornadas de venta directa (RD 199/2010). Pon las de tu ayuntamiento. Las tasas municipales no llevan IVA, pero el libro aplica a todos los costes fijos el tipo general de la columna de al lado: aquí suma unos 63 € al año de IVA que pagas y te deduces en el mismo trimestre, sin efecto en el resultado | G35: =IFERROR(IF(B9="","",'0. Supuestos'!$B$41),"") -> 0.21
A36: Amortización del inmovilizado | B36: =IFERROR(IF(B9="","",'Inversión Inicial'!$B$33),"") -> 4102 | C36: =IFERROR(IF(C9="","",B36),"") -> 4102 | D36: =IFERROR(IF(D9="","",B36),"") -> 4102 | E36: =IFERROR(B36/$B$9,"") -> 0.037698741 | F36: Sale de las bases de amortización de la hoja de Inversión: sólo inmovilizado real. NO sube con el IPC: es una cuota sobre el coste HISTÓRICO del inmovilizado | G36: 0
A37: Gastos financieros (intereses del préstamo) | B37: =IFERROR(IF(B9="","",'Financiación'!$B$44),"") -> 2892.5 | C37: =IFERROR(IF(C9="","",'Financiación'!$B$46),"") -> 2892.5 | D37: =IFERROR(IF(D9="","",'Financiación'!$B$48),"") -> 2384.4771 | E37: =IFERROR(B37/$B$9,"") -> 0.026583035 | F37: Sólo los INTERESES son gasto. La devolución del principal va en la hoja de Tesorería | G37: 0
A38: TOTAL COSTES FIJOS | B38: =IFERROR(IF(B9="","",SUM(B22:B37)),"") -> 66680.42 | C38: =IFERROR(IF(C9="","",SUM(C22:C37)),"") -> 72680.42 | D38: =IFERROR(IF(D9="","",SUM(D22:D37)),"") -> 78172.397 | E38: =IFERROR(B38/$B$9,"") -> 0.61281518
A39: IVA soportado de los costes variables | B39: =IFERROR(IF(B9="","",SUMPRODUCT(B13:B18,G13:G18)),"") -> 4215.9523 | C39: =IFERROR(IF(C9="","",SUMPRODUCT(C13:C18,G13:G18)),"") -> 4637.5475 | D39: =IFERROR(IF(D9="","",SUMPRODUCT(D13:D18,G13:G18)),"") -> 5008.5513 | F39: Cada línea a SU tipo, leído de la columna de al lado. Es lo que la hoja de Tesorería paga de más a los proveedores y luego se deduce
A40: IVA soportado de los costes fijos | B40: =IFERROR(IF(B9="","",SUMPRODUCT(B22:B37,G22:G37)),"") -> 2814 | C40: =IFERROR(IF(C9="","",SUMPRODUCT(C22:C37,G22:G37)),"") -> 2814 | D40: =IFERROR(IF(D9="","",SUMPRODUCT(D22:D37,G22:G37)),"") -> 2814
A41: RESULTADO ANTES DE IMPUESTOS | B41: =IFERROR(IF(B9="","",B20-B38),"") -> 10400.584 | C41: =IFERROR(IF(C9="","",C20-C38),"") -> 12108.684 | D41: =IFERROR(IF(D9="","",D20-D38),"") -> 13399.836 | E41: =IFERROR(B41/$B$9,"") -> 0.095584818
...

Sheet Punto Equilibrio
A1: ANÁLISIS DE PUNTO DE EQUILIBRIO
A2: Punto de equilibrio — cafetería móvil para eventos
A4: Variable | B4: Año 1 | C4: Año 2 | D4: Año 3 | E4: Notas
A5: DATOS BASE POR AÑO
A6: Costes fijos anuales | B6: =IFERROR(IF('PyG 3 Años'!$B$9="","",'PyG 3 Años'!$B$38),"") -> 66680.42 | C6: =IFERROR(IF('PyG 3 Años'!$C$9="","",'PyG 3 Años'!$C$38),"") -> 72680.42 | D6: =IFERROR(IF('PyG 3 Años'!$D$9="","",'PyG 3 Años'!$D$38),"") -> 78172.397 | E6: Los MISMOS costes fijos del P&L. Cada año tiene los suyos: por eso el umbral no puede ser uno solo para los tres
A7: Costes fijos mensuales | B7: =IFERROR(IF('PyG 3 Años'!$B$9="","",B6/12),"") -> 5556.7017 | C7: =IFERROR(IF('PyG 3 Años'!$C$9="","",C6/12),"") -> 6056.7017 | D7: =IFERROR(IF('PyG 3 Años'!$D$9="","",D6/12),"") -> 6514.3664
A8: Precio medio por invitado sin IVA | B8: =IFERROR(IF('PyG 3 Años'!$B$9="","",'PyG 3 Años'!$B$7),"") -> 6.2 | C8: =IFERROR(IF('PyG 3 Años'!$C$9="","",'PyG 3 Años'!$C$7),"") -> 6.2 | D8: =IFERROR(IF('PyG 3 Años'!$D$9="","",'PyG 3 Años'!$D$7),"") -> 6.2
A9: Coste variable por invitado | B9: =IFERROR(IF('PyG 3 Años'!$B$9="","",'PyG 3 Años'!$B$19/('PyG 3 Años'!$B$6*'PyG 3 Años'!$B$8)),"") -> 1.80792 | C9: =IFERROR(IF('PyG 3 Años'!$C$9="","",'PyG 3 Años'!$C$19/('PyG 3 Años'!$C$6*'PyG 3 Años'!$C$8)),"") -> 1.80792 | D9: =IFERROR(IF('PyG 3 Años'!$D$9="","",'PyG 3 Años'!$D$19/('PyG 3 Años'!$D$6*'PyG 3 Años'!$D$8)),"") -> 1.80792 | E9: Sale del total de costes variables del P&L, no de una estimación aparte. Incluye los varios e imprevistos, que son un porcentaje de las ventas
A10: Margen de contribución por invitado | B10: =IFERROR(IF('PyG 3 Años'!$B$9="","",B8-B9),"") -> 4.39208 | C10: =IFERROR(IF('PyG 3 Años'!$C$9="","",C8-C9),"") -> 4.39208 | D10: =IFERROR(IF('PyG 3 Años'!$D$9="","",D8-D9),"") -> 4.39208 | E10: Precio por invitado menos coste variable unitario
A11: Eventos al año | B11: =IFERROR(IF('PyG 3 Años'!$B$9="","",'PyG 3 Años'!$B$8),"") -> 130 | C11: =IFERROR(IF('PyG 3 Años'!$C$9="","",'PyG 3 Años'!$C$8),"") -> 130 | D11: =IFERROR(IF('PyG 3 Años'!$D$9="","",'PyG 3 Años'!$D$8),"") -> 130 | E11: El mismo calendario que el P&L y que los escenarios
A12: Devolución de principal del año (cuota) | B12: =IFERROR(IF('PyG 3 Años'!$B$9="","",'Financiación'!$B$45),"") -> 0 | C12: =IFERROR(IF('PyG 3 Años'!$C$9="","",'Financiación'!$B$47),"") -> 7815.7369 | D12: =IFERROR(IF('PyG 3 Años'!$D$9="","",'Financiación'!$B$49),"") -> 8323.7598 | E12: El principal NO es gasto del P&L, pero sale de la caja. Sin él, el umbral de equilibrio se publica por debajo del real
A13: PUNTO DE EQUILIBRIO CONTABLE (incluye amortización)
A14: Invitados necesarios al año | B14: =IFERROR(IF('PyG 3 Años'!$B$9="","",IF(B10<=0,"",B6/B10)),"") -> 15181.968 | C14: =IFERROR(IF('PyG 3 Años'!$C$9="","",IF(C10<=0,"",C6/C10)),"") -> 16548.064 | D14: =IFERROR(IF('PyG 3 Años'!$D$9="","",IF(D10<=0,"",D6/D10)),"") -> 17798.491
A15: Invitados necesarios por evento | B15: =IFERROR(IF('PyG 3 Años'!$B$9="","",B14/B11),"") -> 116.78437 | C15: =IFERROR(IF('PyG 3 Años'!$C$9="","",C14/C11),"") -> 127.2928 | D15: =IFERROR(IF('PyG 3 Años'!$D$9="","",D14/D11),"") -> 136.91147
A16: Ingresos necesarios al año | B16: =IFERROR(IF('PyG 3 Años'!$B$9="","",B14*B8),"") -> 94128.204 | C16: =IFERROR(IF('PyG 3 Años'!$C$9="","",C14*C8),"") -> 102598 | D16: =IFERROR(IF('PyG 3 Años'!$D$9="","",D14*D8),"") -> 110350.65
A17: PUNTO DE EQUILIBRIO DE CAJA (incluye la cuota del préstamo)
A18: Costes fijos de caja + principal del año | B18: =IFERROR(IF('PyG 3 Años'!$B$9="","",B6-'PyG 3 Años'!$B$36+B12),"") -> 62578.42 | C18: =IFERROR(IF('PyG 3 Años'!$C$9="","",C6-'PyG 3 Años'!$C$36+C12),"") -> 76394.157 | D18: =IFERROR(IF('PyG 3 Años'!$D$9="","",D6-'PyG 3 Años'!$D$36+D12),"") -> 82394.157 | E18: Los fijos del P&L sin la amortización (que no se paga) y CON la devolución de principal (que sí). Es el umbral que decide si la caja aguanta
A19: Invitados necesarios al año (caja) | B19: =IFERROR(IF('PyG 3 Años'!$B$9="","",IF(B10<=0,"",B18/B10)),"") -> 14248.015 | C19: =IFERROR(IF('PyG 3 Años'!$C$9="","",IF(C10<=0,"",C18/C10)),"") -> 17393.617 | D19: =IFERROR(IF('PyG 3 Años'!$D$9="","",IF(D10<=0,"",D18/D10)),"") -> 18759.712
A20: Invitados necesarios por evento (caja) | B20: =IFERROR(IF('PyG 3 Años'!$B$9="","",B19/B11),"") -> 109.60011 | C20: =IFERROR(IF('PyG 3 Años'!$C$9="","",C19/C11),"") -> 133.79705 | D20: =IFERROR(IF('PyG 3 Años'!$D$9="","",D19/D11),"") -> 144.30548
A21: Ingresos necesarios al año (caja) | B21: =IFERROR(IF('PyG 3 Años'!$B$9="","",B19*B8),"") -> 88337.691 | C21: =IFERROR(IF('PyG 3 Años'!$C$9="","",C19*C8),"") -> 107840.42 | D21: =IFERROR(IF('PyG 3 Años'!$D$9="","",D19*D8),"") -> 116310.22
A22: CONTRASTE CON EL PLAN
A23: Invitados por evento previstos en el plan | B23: =IFERROR(IF('PyG 3 Años'!$B$9="","",'PyG 3 Años'!$B$6),"") -> 135 | C23: =IFERROR(IF('PyG 3 Años'!$C$9="","",'PyG 3 Años'!$C$6),"") -> 148.5 | D23: =IFERROR(IF('PyG 3 Años'!$D$9="","",'PyG 3 Años'!$D$6),"") -> 160.38
A24: Holgura sobre el equilibrio de CAJA (%) | B24: =IFERROR(IF('PyG 3 Años'!$B$9="","",B23/B20-1),"") -> 0.23175056 | C24: =IFERROR(IF('PyG 3 Años'!$C$9="","",C23/C20-1),"") -> 0.10988992 | D24: =IFERROR(IF('PyG 3 Años'!$D$9="","",D23/D20-1),"") -> 0.11139231 | E24: Cuánto superan tus ventas previstas a las del equilibrio de caja. La caída que aguantas antes de no poder pagar los costes fijos y la cuota es algo menor: con un 25 % de holgura, un 20 %. El mínimo exigible está en la hoja de Supuestos
A25: INTERPRETACIÓN
A26: =IFERROR("Con el precio medio por invitado sin IVA de la fila de arriba necesitas "&TEXT(ROUNDUP(B15,0),"0")&" invitados por evento durante los "&TEXT(B11,"0")&" eventos del año para no perder dinero (equilibrio contable, con la amortización dentro), y "&TEXT(ROUNDUP(B20,0),"0")&" para que la caja aguante (equilibrio de caja: sin la amortización, que no se paga, y con la cuota del préstamo del año"&IF(B12=0,"; este año sólo intereses, porque el préstamo está en carencia","")&"). En las filas «Ingresos necesarios al año» tienes esas mismas cifras en euros.","") -> Con el precio medio por invitado sin IVA de la fila de arriba necesitas 117 invitados por evento durante los 130 eventos del año para no perder dinero (equilibrio contable, con la amortización dentro), y 110 para que la caja aguante (equilibrio de caja: sin la amortización, que no se paga, y con la cuota del préstamo del año; este año sólo intereses, porque el préstamo está en carencia). En las filas «Ingresos necesarios al año» tienes esas mismas cifras en euros.
A28: SENSIBILIDAD DEL PUNTO DE EQUILIBRIO
A29: Invitados por evento necesarios para cubrir costes según el precio medio por invitado (columnas) y el coste variable por invitado (filas). En verde, los que están por debajo de los invitados que prevé el plan.
A31: Invitados por evento necesarios: precio medio por invitado sin IVA (columnas) × coste variable por invitado (filas) | B31: =IFERROR($B$8-2,"") -> 4.2 | C31: =IFERROR(IF($B$8="","",$B$8),"") -> 6.2 | D31: =IFERROR($B$8+2,"") -> 8.2 | E31: =IFERROR($B$8+4,"") -> 10.2
A32: =IFERROR($B$9*0.85,"") -> 1.536732 | B32: =IFERROR(IF($B$31-$A32<=0,"",$B$6/($B$31-$A32)/$B$11),"") -> 192.59282 | C32: =IFERROR(IF($C$31-$A32<=0,"",$B$6/($C$31-$A32)/$B$11),"") -> 109.99289 | D32: =IFERROR(IF($D$31-$A32<=0,"",$B$6/($D$31-$A32)/$B$11),"") -> 76.97819 | E32: =IFERROR(IF($E$31-$A32<=0,"",$B$6/($E$31-$A32)/$B$11),"") -> 59.207023
A33: =IFERROR($B$9*0.925,"") -> 1.672326 | B33: =IFERROR(IF($B$31-$A33<=0,"",$B$6/($B$31-$A33)/$B$11),"") -> 202.92423 | C33: =IFERROR(IF($C$31-$A33<=0,"",$B$6/($C$31-$A33)/$B$11),"") -> 113.28693 | D33: =IFERROR(IF($D$31-$A33<=0,"",$B$6/($D$31-$A33)/$B$11),"") -> 78.577194 | E33: =IFERROR(IF($E$31-$A33<=0,"",$B$6/($E$31-$A33)/$B$11),"") -> 60.148442
A34: =IFERROR($B$9*1.0,"") -> 1.80792 | B34: =IFERROR(IF($B$31-$A34<=0,"",$B$6/($B$31-$A34)/$B$11),"") -> 214.4269 | C34: =IFERROR(IF($C$31-$A34<=0,"",$B$6/($C$31-$A34)/$B$11),"") -> 116.78437 | D34: =IFERROR(IF($D$31-$A34<=0,"",$B$6/($D$31-$A34)/$B$11),"") -> 80.244038 | E34: =IFERROR(IF($E$31-$A34<=0,"",$B$6/($E$31-$A34)/$B$11),"") -> 61.120283
A35: =IFERROR($B$9*1.075,"") -> 1.943514 | B35: =IFERROR(IF($B$31-$A35<=0,"",$B$6/($B$31-$A35)/$B$11),"") -> 227.31198 | C35: =IFERROR(IF($C$31-$A35<=0,"",$B$6/($C$31-$A35)/$B$11),"") -> 120.50464 | D35: =IFERROR(IF($D$31-$A35<=0,"",$B$6/($D$31-$A35)/$B$11),"") -> 81.98313 | E35: =IFERROR(IF($E$31-$A35<=0,"",$B$6/($E$31-$A35)/$B$11),"") -> 62.124045
A36: =IFERROR($B$9*1.15,"") -> 2.079108 | B36: =IFERROR(IF($B$31-$A36<=0,"",$B$6/($B$31-$A36)/$B$11),"") -> 241.84461 | C36: =IFERROR(IF($C$31-$A36<=0,"",$B$6/($C$31-$A36)/$B$11),"") -> 124.46973 | D36: =IFERROR(IF($D$31-$A36<=0,"",$B$6/($D$31-$A36)/$B$11),"") -> 83.799274 | E36: =IFERROR(IF($E$31-$A36<=0,"",$B$6/($E$31-$A36)/$B$11),"") -> 63.161326

Sheet Escenarios
A1: ANÁLISIS DE ESCENARIOS
A4: Métrica | B4: Pesimista | C4: Realista | D4: Optimista | E4: Notas
A5: Invitados por evento | B5: 130 | C5: =IFERROR(IF('PyG 3 Años'!$B$6="","",'PyG 3 Años'!$B$6),"") -> 135 | D5: 140
A6: Precio medio por invitado sin IVA | B6: 5.7 | C6: =IFERROR(IF('PyG 3 Años'!$B$7="","",'PyG 3 Años'!$B$7),"") -> 6.2 | D6: 6.3
A7: Eventos al año | B7: 110 | C7: =IFERROR(IF('PyG 3 Años'!$B$8="","",'PyG 3 Años'!$B$8),"") -> 130 | D7: 145
A8: INGRESOS ANUALES (sin IVA) | B8: =IFERROR(IF(B5*B6*B7=0,"",B5*B6*B7),"") -> 81510 | C8: =IFERROR(IF(C5*C6*C7=0,"",C5*C6*C7),"") -> 108810 | D8: =IFERROR(IF(D5*D6*D7=0,"",D5*D6*D7),"") -> 127890
A9: Coste de mercancía — comida | B9: =IFERROR(IF(B8="","",B8*'0. Supuestos'!$B$11*'0. Supuestos'!$B$13),"") -> 4124.406 | C9: =IFERROR(IF(C8="","",C8*'0. Supuestos'!$B$11*'0. Supuestos'!$B$13),"") -> 5505.786 | D9: =IFERROR(IF(D8="","",D8*'0. Supuestos'!$B$11*'0. Supuestos'!$B$13),"") -> 6471.234
A10: Coste de mercancía — bebida | B10: =IFERROR(IF(B8="","",B8*'0. Supuestos'!$B$12*'0. Supuestos'!$B$14),"") -> 11607.024 | C10: =IFERROR(IF(C8="","",C8*'0. Supuestos'!$B$12*'0. Supuestos'!$B$14),"") -> 15494.544 | D10: =IFERROR(IF(D8="","",D8*'0. Supuestos'!$B$12*'0. Supuestos'!$B$14),"") -> 18211.536
A11: Consumibles y envases | B11: =IFERROR(IF(B8="","",B8*'0. Supuestos'!$B$15),"") -> 3260.4 | C11: =IFERROR(IF(C8="","",C8*'0. Supuestos'!$B$15),"") -> 4352.4 | D11: =IFERROR(IF(D8="","",D8*'0. Supuestos'!$B$15),"") -> 5115.6
A12: Canon de ferias y mercados | B12: =IFERROR(IF(B8="","",B8*'0. Supuestos'!$B$16*'0. Supuestos'!$B$17),"") -> 1027.026 | C12: =IFERROR(IF(C8="","",C8*'0. Supuestos'!$B$16*'0. Supuestos'!$B$17),"") -> 1371.006 | D12: =IFERROR(IF(D8="","",D8*'0. Supuestos'!$B$16*'0. Supuestos'!$B$17),"") -> 1611.414
A13: Comisiones de los medios de pago | B13: =IFERROR(IF(B8="","",B8*'0. Supuestos'!$B$18),"") -> 489.06 | C13: =IFERROR(IF(C8="","",C8*'0. Supuestos'!$B$18),"") -> 652.86 | D13: =IFERROR(IF(D8="","",D8*'0. Supuestos'!$B$18),"") -> 767.34
A14: Varios e imprevistos | B14: =IFERROR(IF(B8="","",B8*'0. Supuestos'!$B$28),"") -> 3260.4 | C14: =IFERROR(IF(C8="","",C8*'0. Supuestos'!$B$28),"") -> 4352.4 | D14: =IFERROR(IF(D8="","",D8*'0. Supuestos'!$B$28),"") -> 5115.6
A15: TOTAL COSTES VARIABLES | B15: =IFERROR(IF(B8="","",SUM(B9:B14)),"") -> 23768.316 | C15: =IFERROR(IF(C8="","",SUM(C9:C14)),"") -> 31728.996 | D15: =IFERROR(IF(D8="","",SUM(D9:D14)),"") -> 37292.724
A16: MARGEN BRUTO | B16: =IFERROR(IF(B8="","",B8-B15),"") -> 57741.684 | C16: =IFERROR(IF(C8="","",C8-C15),"") -> 77081.004 | D16: =IFERROR(IF(D8="","",D8-D15),"") -> 90597.276
A17: COSTES FIJOS (los del P&L) | B17: =IFERROR(IF(B8="","",'PyG 3 Años'!$B$38),"") -> 66680.42 | C17: =IFERROR(IF(C8="","",'PyG 3 Años'!$B$38),"") -> 66680.42 | D17: =IFERROR(IF(D8="","",'PyG 3 Años'!$B$38),"") -> 66680.42 | E17: Los costes fijos no cambian con el escenario: por eso son fijos
A18: RESULTADO ANTES DE IMPUESTOS | B18: =IFERROR(IF(B8="","",B16-B17),"") -> -8938.736 | C18: =IFERROR(IF(C8="","",C16-C17),"") -> 10400.584 | D18: =IFERROR(IF(D8="","",D16-D17),"") -> 23916.856
A19: Impuesto de Sociedades | B19: =IFERROR(IF(B8="","",MAX(0,B18-'0. Supuestos'!$B$42)*'0. Supuestos'!$B$37),"") -> 0 | C19: =IFERROR(IF(C8="","",MAX(0,C18-'0. Supuestos'!$B$42)*'0. Supuestos'!$B$37),"") -> 1560.0876 | D19: =IFERROR(IF(D8="","",MAX(0,D18-'0. Supuestos'!$B$42)*'0. Supuestos'!$B$37),"") -> 3587.5284 | E19: Al tipo de entidad de nueva creación, compensando las bases negativas anteriores
A20: RESULTADO NETO | B20: =IFERROR(IF(B8="","",B18-B19),"") -> -8938.736 | C20: =IFERROR(IF(C8="","",C18-C19),"") -> 8840.4964 | D20: =IFERROR(IF(D8="","",D18-D19),"") -> 20329.328
A21: Invitados por evento para el equilibrio | B21: =IFERROR(IF(B8="","",IF(B6-B15/(B5*B7)<=0,"",B17/(B6-B15/(B5*B7))/B7)),"") -> 150.12473 | C21: =IFERROR(IF(C8="","",IF(C6-C15/(C5*C7)<=0,"",C17/(C6-C15/(C5*C7))/C7)),"") -> 116.78437 | D21: =IFERROR(IF(D8="","",IF(D6-D15/(D5*D7)<=0,"",D17/(D6-D15/(D5*D7))/D7)),"") -> 103.04127
A22: LO QUE CADA ESCENARIO EXIGE
A23: Coste de personal / Ventas | B23: =IFERROR(IF(B8="","",'PyG 3 Años'!$B$23/B8),"") -> 0.55190676 | C23: =IFERROR(IF(C8="","",'PyG 3 Años'!$B$23/C8),"") -> 0.41343553 | D23: =IFERROR(IF(D8="","",'PyG 3 Años'!$B$23/D8),"") -> 0.35175479 | E23: La MISMA plantilla en los tres escenarios. Si en el pesimista se dispara, el ajuste hay que hacerlo en la hoja de Personal, no aquí
A24: Invitados al año por jornada equivalente | B24: =IFERROR(IF(B8="","",B5*B7/'Personal'!$C$9),"") -> 9930.5556 | C24: =IFERROR(IF(C8="","",C5*C7/'Personal'!$C$9),"") -> 12187.5 | D24: =IFERROR(IF(D8="","",D5*D7/'Personal'!$C$9),"") -> 14097.222 | E24: Invitados que tendría que servir cada jornada completa del cuadro de Personal. En el optimista dice si hace falta contratar
A25: Saldo de caja al cierre del año 1 (estimado, el mismo método en los tres escenarios) | B25: =IFERROR(IF(B8="","",'Inversión Inicial'!$B$25+B20+'PyG 3 Años'!$B$36-'Financiación'!$B$45),"") -> 10807.869 | C25: =IFERROR(IF(C8="","",'Inversión Inicial'!$B$25+C20+'PyG 3 Años'!$B$36-'Financiación'!$B$45),"") -> 28587.101 | D25: =IFERROR(IF(D8="","",'Inversión Inicial'!$B$25+D20+'PyG 3 Años'!$B$36-'Financiación'!$B$45),"") -> 40075.933 | E25: Saldo ESTIMADO: fondo de maniobra más el resultado del año, devolviendo la amortización (que no se paga) y restando el principal del préstamo. No incluye el desfase de cobros y pagos ni la liquidación del IVA, así que las tres columnas se pueden comparar entre sí. En rojo, el escenario se queda sin caja
A26: Saldo real del mes 12 de la hoja de Tesorería (sólo realista) | C26: =IFERROR(IF(C8="","",'Tesorería 12 meses'!$M$22),"") -> 30156.196 | E26: El saldo REAL del caso base, con su desfase de cobros y pagos y su liquidación de IVA. Sólo existe para el escenario realista, que es el único con tesorería mensual propia: por eso no está en la fila de arriba, donde se compararía contra dos estimaciones
A28: La columna «Realista» lee sus tres datos de la hoja de Supuestos, así que reproduce EXACTAMENTE el año 1 del P&L. Los otros dos escenarios usan las mismas tasas de coste: lo único que cambia son los invitados, el precio por invitado y los eventos. Los COSTES FIJOS sí son los mismos en los tres: los varios e imprevistos, que son un porcentaje de las ventas, van arriba con los variables y cada escenario carga los suyos.

Sheet Personal
A1: ESTRUCTURA DE PERSONAL Y COSTES
A2: =IFERROR("Convenio Hostelería — "&TEXT('0. Supuestos'!$B$21,"0")&" pagas + SS "&TEXT('0. Supuestos'!$B$20*100,"0")&" %","") -> Convenio Hostelería — 14 pagas + SS 33 %
A4: Puesto | B4: Personas | C4: Jornada | D4: Bruto mes (€, total del puesto) | E4: Seg. Social a cargo de la empresa (€) | F4: Coste mes (€, total del puesto) | G4: Coste año (€) | H4: Horas/semana por persona | I4: Horas/año del puesto | J4: Notas
A5: Propietario/a — titular-barista, ventas y compras | B5: 1 | C5: 1 | D5: 1800 | E5: =IFERROR(IF(D5="","",D5*'0. Supuestos'!$B$20),"") -> 594 | F5: =IFERROR(IF(D5="","",D5+E5),"") -> 2394 | G5: =IFERROR(IF(D5="","",F5*MAX(12,'0. Supuestos'!$B$21)),"") -> 33516 | H5: =IFERROR(IF(D5="","",C5*$B$16),"") -> 40 | I5: =IFERROR(IF(D5="","",H5*B5*$B$17),"") -> 1840 | J5: Sirve en cada evento, conduce, vende a novios, empresas y agencias, compra el café y lleva la agenda. Como administrador de la SL cotiza en el régimen de autónomos: confirma con tu gestoría la cuota y si te aplica la reducida de inicio
A6: Camarero/a de barra (barista), fijo discontinuo | B6: 1 | C6: 0.36 | D6: 504 | E6: =IFERROR(IF(D6="","",D6*'0. Supuestos'!$B$20),"") -> 166.32 | F6: =IFERROR(IF(D6="","",D6+E6),"") -> 670.32 | G6: =IFERROR(IF(D6="","",F6*MAX(12,'0. Supuestos'!$B$21)),"") -> 9384.48 | H6: =IFERROR(IF(D6="","",C6*$B$16),"") -> 14.4 | I6: =IFERROR(IF(D6="","",H6*B6*$B$17),"") -> 662.4 | J6: Contrato fijo discontinuo (art. 16 del Estatuto de los Trabajadores) al 36 % de jornada en cómputo anual: segundo barista en bodas, congresos, la mitad de los eventos de empresa y la venta directa (unas 650 horas). «Barista» no es categoría del convenio: se contrata como camarero/a. Bruto a jornada completa: 1.400 € en 14 pagas
A7: Suplencias y refuerzo de temporada (fijo discontinuo) | B7: 1 | C7: 0.04 | D7: 56 | E7: =IFERROR(IF(D7="","",D7*'0. Supuestos'!$B$20),"") -> 18.48 | F7: =IFERROR(IF(D7="","",D7+E7),"") -> 74.48 | G7: =IFERROR(IF(D7="","",F7*MAX(12,'0. Supuestos'!$B$21)),"") -> 1042.72 | H7: =IFERROR(IF(D7="","",C7*$B$16),"") -> 1.6 | I7: =IFERROR(IF(D7="","",H7*B7*$B$17),"") -> 73.6 | J7: Bolsa para cubrir las vacaciones del camarero/a y los picos de temporada: unas 75 horas al año, mismo contrato y misma categoría. Para cubrir una baja concreta, el contrato es de sustitución (art. 15.3 del Estatuto de los Trabajadores). Nunca como autónomo que te factura: con tu horario y tu dirección es falso autónomo (art. 1.1)
A8: Refuerzo para eventos grandes (fijo discontinuo) | B8: 1 | C8: 0.04 | D8: 56 | E8: =IFERROR(IF(D8="","",D8*'0. Supuestos'!$B$20),"") -> 18.48 | F8: =IFERROR(IF(D8="","",D8+E8),"") -> 74.48 | G8: =IFERROR(IF(D8="","",F8*MAX(12,'0. Supuestos'!$B$21)),"") -> 1042.72 | H8: =IFERROR(IF(D8="","",C8*$B$16),"") -> 1.6 | I8: =IFERROR(IF(D8="","",H8*B8*$B$17),"") -> 73.6 | J8: Tercer barista para los congresos y las bodas de más de 200 invitados que pidan una segunda estación (tabla de escalado de la hoja Instrucciones): unas 75 horas al año. Por encima del SMI en proporción a su jornada
A9: TOTAL PLANTILLA | B9: =IFERROR(IF(COUNT(D5:D8)=0,"",SUM(B5:B8)),"") -> 4 | C9: =IFERROR(IF(COUNT(D5:D8)=0,"",SUM(C5:C8)),"") -> 1.44 | D9: =IFERROR(IF(COUNT(D5:D8)=0,"",SUM(D5:D8)),"") -> 2416 | E9: =IFERROR(IF(COUNT(D5:D8)=0,"",SUM(E5:E8)),"") -> 797.28 | F9: =IFERROR(IF(COUNT(D5:D8)=0,"",SUM(F5:F8)),"") -> 3213.28 | G9: =IFERROR(IF(COUNT(D5:D8)=0,"",SUM(G5:G8)),"") -> 44985.92 | I9: =IFERROR(IF(COUNT(D5:D8)=0,"",SUM(I5:I8)),"") -> 2649.6
A10: CRECIMIENTO DE LA PLANTILLA (coste escalonado)
A11: Coste anual de las incorporaciones del año 2 (€) | B11: 6000 | J11: Coste ANUAL completo (bruto + Seguridad Social × pagas) de lo que se contrate ese año. El P&L lo suma al coste del año anterior: la plantilla no crece con un porcentaje, crece con personas
A12: Coste anual de las incorporaciones del año 3 (€) | B12: 6000 | J12: Coste ANUAL completo (bruto + Seguridad Social × pagas) de lo que se contrate ese año. El P&L lo suma al coste del año anterior: la plantilla no crece con un porcentaje, crece con personas
A13: Coste de personal del año 2 | B13: =IFERROR(IF(G9="","",G9*(1+'0. Supuestos'!$B$48)+B11),"") -> 50985.92
A14: Coste de personal del año 3 | B14: =IFERROR(IF(B13="","",B13*(1+'0. Supuestos'!$B$48)+B12),"") -> 56985.92
A15: COBERTURA POR HORAS DE SERVICIO
A16: Jornada completa del convenio (horas/semana) | B16: 40 | J16: Art. 34.1 del Estatuto de los Trabajadores; tu convenio provincial puede fijar menos
A17: Semanas trabajadas al año por persona | B17: 46 | J17: 46 semanas: 52 menos las vacaciones (30 días naturales, art. 38 ET), los festivos y las ausencias medias
A18: Horas de trabajo por evento que hay que cubrir | B18: 7.5 | J18: Horas por evento y persona: carga en la base, viaje, llegada una hora antes, montaje, servicio, desmontaje, limpieza y descarga. Un servicio «de 2 horas» es una jornada de 7 a 9 horas. La oficina y la limpieza de la base van aparte
A19: Personas necesarias a la vez en cada evento | B19: 1.6 | J19: Personas trabajando a la vez en un evento medio: dos baristas en bodas, congresos, ferias y la mitad de los eventos de empresa, y el titular solo en los pequeños. Ajústalo y la hoja te dice si llega la plantilla
A20: Horas de servicio a cubrir al año | B20: =IFERROR(IF(OR(B18="",B19="",'0. Supuestos'!$B$6=""),"",B18*B19*'0. Supuestos'!$B$6),"") -> 1560
A21: Horas contratadas al año | B21: =IFERROR(IF(I9="","",I9),"") -> 2649.6
A22: Cobertura (contratadas / necesarias) | B22: =IFERROR(B21/B20,"") -> 1.6984615 | J22: Por debajo del 100 % la plantilla no llega a cubrir el horario que declara el plan: o se contrata más o se recorta el horario
A24: Las columnas «Bruto mes», «Seg. Social», «Coste mes» y «Coste año» son TOTALES de la fila: en un puesto con dos personas incluyen a las dos. «Jornada» es el porcentaje sobre la jornada completa del convenio y sirve para comparar el salario con el suelo legal en proporción. El tipo de Seguridad Social y el número de pagas están en la hoja «0. Supuestos».
A25: El suelo salarial es el MAYOR entre el SMI y el salario de convenio, los dos en la hoja «0. Supuestos»; las jornadas parciales lo llevan en proporción. El convenio aplicable es el PROVINCIAL de hostelería: no existe una tabla salarial estatal única, así que la celda del convenio se entrega vacía para que copies la de tu provincia.

Sheet Instrucciones
A1: INSTRUCCIONES DE USO — Plan financiero Cafetería Móvil para Eventos
A3: CÓMO SE USA ESTE LIBRO
A4: Este plan financiero es un MODELO: sólo se teclea en las celdas VERDES y el resto se recalcula solo.
A5: 1. «0. Supuestos» es la hoja de mando: invitados, precio por invitado sin IVA, eventos, mezcla de comida y bebida, coste de mercancía, alquiler, financiación e impuestos.
A6: 2. Las partidas de la inversión, los costes fijos y la plantilla se teclean en su propia hoja, también en verde. Ningún número se escribe dos veces.
A7: 3. Sólo «Punto Equilibrio» se deriva entera de lo anterior. En las otras tres hojas también hay celdas verdes que puedes tocar: el escenario pesimista y el optimista en «Escenarios», la estacionalidad y la rampa de arranque en «Tesorería 12 meses», y las cuatro fuentes alternativas de financiación en «Financiación». Todo lo demás se calcula.
A8: 4. Todas las cifras van SIN IVA. Para pasar un PVP a precio sin IVA, divide entre 1,10: todo lo que sirve la cafetería móvil, en la barra del evento o en la venta directa de ferias y mercados, va al 10 % (art. 91.Uno.2.2.º de la Ley 37/1992 del IVA; la bollería y el café que se llevan, al mismo tipo por el art. 91.Uno.1.1.º). Entre 1,21 sólo van los extras con precio propio (personalización de la barra, talleres de latte art, alquiler de la cafetera sin barista) y un refresco envasado con azúcares o edulcorantes añadidos que se venda para llevar: ninguno de los dos está en este libro. El tipo de cada línea de venta está en la columna «Tipo de IVA de la línea» del P&L y de ahí salen los cobros, el IVA repercutido y el PVP equivalente. El IVA de la inversión se adelanta y se recupera con el modelo 303.
A9: 5. Si cambias la plantilla, el P&L la lee sola: el coste de personal sale de la hoja «Personal», no de una estimación aparte.
A10: 6. La hoja «Tesorería 12 meses» responde la pregunta que decide una operación bancaria: en qué mes se agota la caja. Su Mes 1 es MARZO: la cafetería arranca en primavera y llega al primer invierno con la caja de la temporada. El saldo mínimo del año nunca puede salir en rojo. Las señales de los particulares no se modelan: tu caja real será algo mejor.
A11: 7. La hoja «Financiación» cuadra lo que hace falta con lo que se aporta y monta el cuadro de amortización del préstamo. Si la diferencia sale en rojo, el plan no está financiado.
A12: 8. El documento Word de este pack usa las cifras de este Excel; la calculadora de presupuestos y el modelo de contrato usan los mismos porcentajes de cobro y de cancelación, y la misma tabla de escalado. Si cambias una celda verde, el Excel manda. El coste de mercancía de Supuestos es la media de la mezcla con la merma: el de una bebida concreta está en la calculadora y no se copia aquí.
A14: RATIOS QUE AUDITA EL LIBRO
A15: Los umbrales viven en la columna «Umbral» del bloque RATIOS CLAVE del P&L: cámbialos ahí y el semáforo cambia con ellos.
A17: Ratio | B17: Valor del año 1 | C17: Umbral | D17: Estado
