Workbook

Sheet Dough
A1: PIZZA DOUGH CALCULATOR: TRADITIONAL NEAPOLITAN RATIOS AND BAKER'S %
A2: Type only in the GREEN cells: everything else is calculated. Dough in grams (how bakers work), with a gray echo in ounces and pounds. Prices in $/lb. The ingredient prices are examples (Kit estimate, Oct 2026): replace them with your distributor's.
A3: FIXED NOTICE. The traffic light on this sheet only tells you whether your flour, salt, yeast and dough ball weight fall inside the traditional Neapolitan ratios. It does NOT make your pizza "VPN-certified". In the United States no federal rule governs the term "Neapolitan-style", so you may write it on your menu; but "VPN-certified" is a private certification awarded by the AVPN after an inspection of your wood-fired dome oven, ingredients and method, and only a certified shop may use that seal. Meeting these ratios is not that certificate. Until you hold it, write "Neapolitan-style" and the name of the pizza (Margherita, Marinara...).
A5: A. TRADITIONAL NEAPOLITAN RATIOS (EU TSG spec, also used by the AVPN), PER LITER OF WATER | B5: Value | C5: Trad. min. | D5: Trad. max. | E5: Notes
A6: Number of dough balls you want to make | B6: 60 | E6: Whole number greater than 0. One dough ball, one pizza.
A7: Dough ball weight (g) | B7: 250 | C7: 180 | D7: 250 | E7: The traditional Neapolitan ratios call for hand-shaped dough balls of 180 to 250 g. Gray cells show the traditional range.
A8: Mixing and balling loss (%) | B8: 0.03 | E8: Kit estimate: dough left in the mixer, on the bench and on your hands. It is added to the dough you need.
A9: Flour per liter of water (g) | B9: 1800 | C9: 1600 | D9: 1800 | E9: Traditional ratios: up to 1,800 g of flour per liter of water (the "kneading point"). The 1,600 g minimum gives a 62 % absorption (kit calculation over the traditional 55-62 % range).
A10: Salt per liter of water (g) | B10: 52.5 | C10: 50 | D10: 55 | E10: Traditional ratios: 50 to 55 g of salt per liter of water.
A11: Fresh brewer's yeast per liter of water (g) | B11: 3 | C11: 3 | D11: 3 | E11: Traditional ratios: 3 g per liter of water.
A12: Water per liter (g) | B12: 1000 | E12: Constant: one liter of water weighs 1,000 g. Not editable.
A13: Grams per lb (constant: 453.6 g per lb) | B13: 453.6 | E13: Constant: 1 lb = 453.6 g. Not editable. It converts the $/lb prices to grams.
A14: Ounces per lb (constant: 16 oz per lb) | B14: 16 | E14: Constant: 1 lb = 16 oz. Not editable. The "Food Cost" sheet uses it for the pizza portions.
A15: 00 flour price ($/lb) | B15: 1.1 | E15: Kit estimate (Oct 2026): 00 pizza flour in 50 lb bags. Replace with your distributor's price.
A16: Salt price ($/lb) | B16: 0.6 | E16: Kit estimate (Oct 2026): replace with your distributor's price.
A17: Fresh yeast price ($/lb) | B17: 4.5 | E17: Kit estimate (Oct 2026): replace with your distributor's price.
A19: RESULT OF BLOCK A | B19: Value | E19: Notes
A20: Dough ball weight (oz, echo of the ball weight above) | B20: =$B$7*$B$14/$B$13 -> 8.8183422 | E20: Gray echo of the green cell in ounces: grams × 16 ÷ 453.6.
A21: Total dough to prepare (g) | B21: =$B$6*$B$7*(1+$B$8) -> 15450 | E21: Dough balls × weight × (1 + loss).
A22: Total dough to prepare (lb, echo) | B22: =$B$21/$B$13 -> 34.060847 | E22: Gray echo in pounds.
A23: Dough that comes out of each liter of water (g) | B23: =$B$12+$B$9+$B$10+$B$11 -> 2855.5 | E23: Water + flour + salt + yeast per liter.
A24: Liters of water you need | B24: =$B$21/$B$23 -> 5.4106111 | E24: Total dough ÷ dough per liter.
A25: Water (g) | B25: =$B$24*$B$12 -> 5410.6111
A26: Flour (g) | B26: =$B$24*$B$9 -> 9739.1
A27: Flour (lb, echo) | B27: =$B$26/$B$13 -> 21.470679 | E27: Gray echo in pounds: compare it with your 50 lb bags.
A28: Salt (g) | B28: =$B$24*$B$10 -> 284.05708
A29: Fresh yeast (g) | B29: =$B$24*$B$11 -> 16.231833
A30: Baker's %: hydration (water ÷ flour) | B30: =$B$25/$B$26 -> 0.55555556 | E30: To carry it over to block B.
A31: Baker's %: salt (salt ÷ flour) | B31: =$B$28/$B$26 -> 0.029166667
A32: Baker's %: yeast (yeast ÷ flour) | B32: =$B$29/$B$26 -> 0.0016666667
A33: Flour per dough ball (g) | B33: =$B$26/$B$6 -> 162.31833
A34: Dough balls that come out of 1 lb of flour | B34: =$B$6*$B$13/$B$26 -> 2.7945087 | E34: With the traditional ratios, about 2.8 balls of 250 g per lb of flour.
A35: Dough cost ($) | B35: =($B$26*$B$15+$B$28*$B$16+$B$29*$B$17)/$B$13 -> 24.154514 | E35: Sum of grams × $/lb ÷ 453.6, loss included.
A36: Dough cost per ball ($) | B36: =$B$35/$B$6 -> 0.40257523
A37: Traditional ratios traffic light | B37: =IF(AND($B$9>=$C$9,$B$9<=$D$9,$B$10>=$C$10,$B$10<=$D$10,$B$7>=$C$7,$B$7<=$D$7),"Within the traditional ratios","Outside the traditional ratios") -> Within the traditional ratios | E37: It looks at flour and salt per liter and at the ball weight. Mind the fixed notice above: it is not a seal.
A39: B. BY BAKER'S % (over the flour) | B39: Value | E39: Notes
A40: Hydration (water over flour, %) | B40: 0.6 | E40: The traditional ratios leave 55 to 62 % depending on the flour absorption. 60 % is a kit example.
A41: Salt (over flour, %) | B41: 0.028 | E41: Traditional ratios: 2.8 to 3.1 % over the flour (50-55 g per liter of water).
A42: Fresh yeast (over flour, %) | B42: 0.002 | E42: Traditional ratios: about 0.17 % over the flour (3 g per liter of water). 0.2 % is a kit example.
A44: RESULT OF BLOCK B (same total dough as block A) | B44: Value | E44: Notes
...

Sheet Food Cost
A1: FOOD COST PER PIZZA: 8 EXAMPLE PIZZAS, PORTIONS IN OUNCES
A2: Type only in the GREEN cells (ingredients, prices, waste, ounces, names and menu prices). Prices are $/lb before sales tax; portions are in ounces. The prices are examples (Kit estimate, Oct 2026): use your distributor's. The sample menu says "Neapolitan-style" and uses the recipe names, not a "VPN-certified" claim (see the notice on the "Dough" sheet).
A4: GENERAL DATA | B4: Value | E4: Notes
A5: Sales tax included in your menu prices (%) | B5: 0 | E5: Leave 0 % if your menu prices are quoted before sales tax (the usual way in the US: the guest pays tax on top). If your prices already include tax, enter the rate so the food cost is calculated on the price net of tax.
A6: Target food cost (% of the pre-tax menu price) | B6: 0.26 | E6: Industry reference for pizza shops: 25-30 %. The kit's business plan uses 26 %. Use the one in your financial plan.
A7: Watch margin above the target (points) | B7: 0.05 | E7: Up to this margin above the target, the traffic light says "Watch the cost"; beyond it, "Above target".
A8: Cost of the take-out box ($) | B8: 0.75 | E8: Kit estimate (Oct 2026): replace with your distributor's price.
A9: Ounces per lb (constant: 16 oz per lb) | B9: ='Dough'!$B$14 -> 16 | E9: Constant, linked to the "Dough" sheet. Not editable. It converts the $/lb prices to the ounce portions.
A10: Dough cost per ball (from the "Dough" sheet) ($) | B10: ='Dough'!$B$56 -> 0.40257523 | E10: Calculated on the "Dough" sheet (block A or B, as you choose there).
A12: INGREDIENT (portions in oz) | B12: $/lb before tax | C12: Waste | D12: Net $/lb | E12: Margherita | F12: Marinara | G12: Diavola | H12: Capricciosa | I12: Quattro Formaggi | J12: Ham & Mushroom | K12: Bufalina | L12: Sausage & Broccoli Rabe | M12: ORIGIN OF THE EXAMPLE PRICE
A13: Menu price ($) | E13: 18 | F13: 15 | G13: 20 | H13: 21 | I13: 21 | J13: 20 | K13: 23 | L13: 22
A14: San Marzano-style crushed tomatoes | B14: 2.5 | C14: 0 | D14: =B14/(1-C14) -> 2.5 | E14: 3 | F14: 4 | G14: 3 | H14: 3 | I14: 0 | J14: 3 | K14: 2 | L14: 0 | M14: Kit estimate (Oct 2026): replace with your distributor's price
A15: Fior di latte (fresh mozzarella) | B15: 7 | C15: 0.03 | D15: =B15/(1-C15) -> 7.2164948 | E15: 4 | F15: 0 | G15: 3.5 | H15: 3 | I15: 2.25 | J15: 3.5 | K15: 0 | L15: 0 | M15: Kit estimate (Oct 2026): replace with your distributor's price
A16: Mozzarella di bufala | B16: 14 | C16: 0.03 | D16: =B16/(1-C16) -> 14.43299 | E16: 0 | F16: 0 | G16: 0 | H16: 0 | I16: 0 | J16: 0 | K16: 4.5 | L16: 0 | M16: Kit estimate (Oct 2026): replace with your distributor's price
A17: Extra virgin olive oil | B17: 6 | C17: 0 | D17: =B17/(1-C17) -> 6 | E17: 0.25 | F17: 0.25 | G17: 0.25 | H17: 0.25 | I17: 0.15 | J17: 0.25 | K17: 0.25 | L17: 0.25 | M17: Kit estimate (Oct 2026): replace with your distributor's price
A18: Fresh basil | B18: 16 | C18: 0.3 | D18: =B18/(1-C18) -> 22.857143 | E18: 0.1 | F18: 0 | G18: 0.1 | H18: 0 | I18: 0 | J18: 0 | K18: 0.1 | L18: 0 | M18: Kit estimate (Oct 2026): replace with your distributor's price
A19: Dried oregano | B19: 12 | C19: 0 | D19: =B19/(1-C19) -> 12 | E19: 0 | F19: 0.02 | G19: 0 | H19: 0 | I19: 0 | J19: 0 | K19: 0 | L19: 0 | M19: Kit estimate (Oct 2026): replace with your distributor's price
A20: Garlic | B20: 3.5 | C20: 0.2 | D20: =B20/(1-C20) -> 4.375 | E20: 0 | F20: 0.1 | G20: 0 | H20: 0 | I20: 0 | J20: 0 | K20: 0 | L20: 0.1 | M20: Kit estimate (Oct 2026): replace with your distributor's price
A21: Spicy salami | B21: 12 | C21: 0.03 | D21: =B21/(1-C21) -> 12.371134 | E21: 0 | F21: 0 | G21: 2 | H21: 0 | I21: 0 | J21: 0 | K21: 0 | L21: 0 | M21: Kit estimate (Oct 2026): replace with your distributor's price
A22: Cooked ham | B22: 7.5 | C22: 0.03 | D22: =B22/(1-C22) -> 7.7319588 | E22: 0 | F22: 0 | G22: 0 | H22: 1.5 | I22: 0 | J22: 1.75 | K22: 0 | L22: 0 | M22: Kit estimate (Oct 2026): replace with your distributor's price
A23: Sliced mushrooms | B23: 3.5 | C23: 0.1 | D23: =B23/(1-C23) -> 3.8888889 | E23: 0 | F23: 0 | G23: 0 | H23: 1.5 | I23: 0 | J23: 1.75 | K23: 0 | L23: 0 | M23: Kit estimate (Oct 2026): replace with your distributor's price
A24: Artichoke hearts in oil | B24: 7 | C24: 0.1 | D24: =B24/(1-C24) -> 7.7777778 | E24: 0 | F24: 0 | G24: 0 | H24: 1 | I24: 0 | J24: 0 | K24: 0 | L24: 0 | M24: Kit estimate (Oct 2026): replace with your distributor's price
A25: Black olives | B25: 5.5 | C25: 0.05 | D25: =B25/(1-C25) -> 5.7894737 | E25: 0 | F25: 0 | G25: 0 | H25: 0.5 | I25: 0 | J25: 0 | K25: 0 | L25: 0 | M25: Kit estimate (Oct 2026): replace with your distributor's price
... A35: Ricotta | B35: 4.5 | C35: 0.02 | D35: =B35/(1-C35) -> 4.5918367 | E35: 0 | F35: 0 | G35: 0 | H35: 0 | I35: 0 | J35: 0 | K35: 0 | L35: 0 | M35: Kit estimate (Oct 2026): free slot for your own pizzas; replace with your distributor's price
A37: RESULT PER PIZZA (ounces in the columns above) | E37: =E12 -> Margherita | F37: =F12 -> Marinara | G37: =G12 -> Diavola | H37: =H12 -> Capricciosa | I37: =I12 -> Quattro Formaggi | J37: =J12 -> Ham & Mushroom | K37: =K12 -> Bufalina | L37: =L12 -> Sausage & Broccoli Rabe
A38: Raw weight of the pizza (oz) | E38: ='Dough'!$B$20+SUM(E$14:E$35) -> 16.168342 | F38: ='Dough'!$B$20+SUM(F$14:F$35) -> 13.188342 | G38: ='Dough'!$B$20+SUM(G$14:G$35) -> 17.668342 | H38: ='Dough'!$B$20+SUM(H$14:H$35) -> 19.568342 | I38: ='Dough'!$B$20+SUM(I$14:I$35) -> 14.968342 | J38: ='Dough'!$B$20+SUM(J$14:J$35) -> 19.068342 | K38: ='Dough'!$B$20+SUM(K$14:K$35) -> 16.668342 | L38: ='Dough'!$B$20+SUM(L$14:L$35) -> 17.168342
A39: Dough cost ($) | E39: =$B$10 -> 0.40257523 | F39: =$B$10 -> 0.40257523 | G39: =$B$10 -> 0.40257523 | H39: =$B$10 -> 0.40257523 | I39: =$B$10 -> 0.40257523 | J39: =$B$10 -> 0.40257523 | K39: =$B$10 -> 0.40257523 | L39: =$B$10 -> 0.40257523
A40: Ingredient cost ($) | E40: =SUMPRODUCT(E$14:E$35,$D$14:$D$35)/$B$9 -> 2.5094809 | F40: =SUMPRODUCT(F$14:F$35,$D$14:$D$35)/$B$9 -> 0.76109375 | G40: =SUMPRODUCT(G$14:G$35,$D$14:$D$35)/$B$9 -> 3.8303571 | H40: =SUMPRODUCT(H$14:H$35,$D$14:$D$35)/$B$9 -> 3.6720794 | I40: =SUMPRODUCT(I$14:I$35,$D$14:$D$35)/$B$9 -> 3.4018482 | J40: =SUMPRODUCT(J$14:J$35,$D$14:$D$35)/$B$9 -> 3.4121385 | K40: =SUMPRODUCT(K$14:K$35,$D$14:$D$35)/$B$9 -> 4.9044381 | L40: =SUMPRODUCT(L$14:L$35,$D$14:$D$35)/$B$9 -> 3.5702369
A41: COST OF THE PIZZA ($) | E41: =E39+E40 -> 2.9120561 | F41: =F39+F40 -> 1.163669 | G41: =G39+G40 -> 4.2329324 | H41: =H39+H40 -> 4.0746546 | I41: =I39+I40 -> 3.8044234 | J41: =J39+J40 -> 3.8147137 | K41: =K39+K40 -> 5.3070134 | L41: =L39+L40 -> 3.9728121
A42: Menu price before sales tax ($) | E42: =E13/(1+$B$5) -> 18 | F42: =F13/(1+$B$5) -> 15 | G42: =G13/(1+$B$5) -> 20 | H42: =H13/(1+$B$5) -> 21 | I42: =I13/(1+$B$5) -> 21 | J42: =J13/(1+$B$5) -> 20 | K42: =K13/(1+$B$5) -> 23 | L42: =L13/(1+$B$5) -> 22
A43: FOOD COST (%) | E43: =E41/E42 -> 0.16178089 | F43: =F41/F42 -> 0.077577932 | G43: =G41/G42 -> 0.21164662 | H43: =H41/H42 -> 0.19403117 | I43: =I41/I42 -> 0.18116302 | J43: =J41/J42 -> 0.19073568 | K43: =K41/K42 -> 0.23073971 | L43: =L41/L42 -> 0.18058237
A44: Traffic light against the target | E44: =IF(E43<=$B$6,"On target",IF(E43<=$B$6+$B$7,"Watch the cost","Above target")) -> On target | F44: =IF(F43<=$B$6,"On target",IF(F43<=$B$6+$B$7,"Watch the cost","Above target")) -> On target | G44: =IF(G43<=$B$6,"On target",IF(G43<=$B$6+$B$7,"Watch the cost","Above target")) -> On target | H44: =IF(H43<=$B$6,"On target",IF(H43<=$B$6+$B$7,"Watch the cost","Above target")) -> On target | I44: =IF(I43<=$B$6,"On target",IF(I43<=$B$6+$B$7,"Watch the cost","Above target")) -> On target | J44: =IF(J43<=$B$6,"On target",IF(J43<=$B$6+$B$7,"Watch the cost","Above target")) -> On target | K44: =IF(K43<=$B$6,"On target",IF(K43<=$B$6+$B$7,"Watch the cost","Above target")) -> On target | L44: =IF(L43<=$B$6,"On target",IF(L43<=$B$6+$B$7,"Watch the cost","Above target")) -> On target
A45: Margin per pizza ($, price before tax − cost) | E45: =E42-E41 -> 15.087944 | F45: =F42-F41 -> 13.836331 | G45: =G42-G41 -> 15.767068 | H45: =H42-H41 -> 16.925345 | I45: =I42-I41 -> 17.195577 | J45: =J42-J41 -> 16.185286 | K45: =K42-K41 -> 17.692987 | L45: =L42-L41 -> 18.027188
A46: Menu price needed to reach the target ($) | E46: =E41/$B$6*(1+$B$5) -> 11.200216 | F46: =F41/$B$6*(1+$B$5) -> 4.4756499 | G46: =G41/$B$6*(1+$B$5) -> 16.280509 | H46: =H41/$B$6*(1+$B$5) -> 15.671749 | I46: =I41/$B$6*(1+$B$5) -> 14.632398 | J46: =J41/$B$6*(1+$B$5) -> 14.671976 | K46: =K41/$B$6*(1+$B$5) -> 20.41159 | L46: =L41/$B$6*(1+$B$5) -> 15.280047
A47: Take-out cost: pizza + box ($) | E47: =E41+$B$8 -> 3.6620561 | F47: =F41+$B$8 -> 1.913669 | G47: =G41+$B$8 -> 4.9829324 | H47: =H41+$B$8 -> 4.8246546 | I47: =I41+$B$8 -> 4.5544234 | J47: =J41+$B$8 -> 4.5647137 | K47: =K41+$B$8 -> 6.0570134 | L47: =L41+$B$8 -> 4.7228121
A48: Take-out food cost with the box (%) | E48: =E47/E42 -> 0.20344756 | F48: =F47/F42 -> 0.12757793 | G48: =G47/G42 -> 0.24914662 | H48: =H47/H42 -> 0.22974546 | I48: =I47/I42 -> 0.21687731 | J48: =J47/J42 -> 0.22823568 | K48: =K47/K42 -> 0.26334841 | L48: =L47/L42 -> 0.21467328
A49: The food cost in the table is for the pizza served in the dining room. For take-out the box is added to the cost and the menu price is the same; if you charge more for take-out or delivery, change the pizza price to see the effect. It does not include the commission of the third-party delivery marketplace, which comes out of the price, not out of the cost of the pizza.

Sheet Instructions
A1: INSTRUCTIONS: Pizza Dough & Food Cost Calculator
A2: Two tools in one workbook: the "Dough" sheet tells you how much flour, water, salt and yeast you need for the number of dough balls you are going to make, and what each ball costs; the "Food Cost" sheet calculates the cost of 8 example pizzas, their food cost, their margin and the menu price you need. Type only in the GREEN cells; everything else is calculated. Dough is in grams (how bakers work) with a gray echo in ounces and pounds; ingredient prices are in $/lb and the pizza portions are in ounces.
A3: NOTICE ABOUT THE NAME
A5: FIXED NOTICE. The traffic light on this sheet only tells you whether your flour, salt, yeast and dough ball weight fall inside the traditional Neapolitan ratios. It does NOT make your pizza "VPN-certified". In the United States no federal rule governs the term "Neapolitan-style", so you may write it on your menu; but "VPN-certified" is a private certification awarded by the AVPN after an inspection of your wood-fired dome oven, ingredients and method, and only a certified shop may use that seal. Meeting these ratios is not that certificate. Until you hold it, write "Neapolitan-style" and the name of the pizza (Margherita, Marinara...).
A6: "DOUGH" SHEET
A8: 1. Block A (per liter of water): type how many dough balls you want, their weight and the mixing loss. The amounts per liter are the traditional Neapolitan ratios (the EU Traditional Specialty Guaranteed spec, also used by the AVPN): up to 1,800 g of flour, 50 to 55 g of salt and 3 g of fresh brewer's yeast per liter of water, with dough balls of 180 to 250 g. The traditional range appears in gray next to each cell.
A9: 2. The block A traffic light says whether the flour, the salt and the ball weight fit those ranges. Green does not mean "VPN-certified": that certificate comes from the AVPN after an inspection of the shop, the oven and the method.
A10: 3. Block B (baker's %): type the hydration, the salt and the yeast as a percentage of the flour weight, which is how the trade works. It uses the same total dough as block A. If you type the percentages that block A calculates, you get the same result.
A11: 4. At the bottom you choose which dough cost per ball feeds the food cost: the one from the traditional ratios (A) or the one from your own percentages (B).
A12: "FOOD COST" SHEET
A14: 1. Type the sales tax included in your menu prices (0 % if your menu is quoted before tax, which is the usual US way), the target food cost, the watch margin and the cost of the take-out box.
A15: 2. In the table, each row is an ingredient with its price per lb before tax and its waste (the part lost when trimming or cleaning). The net price per lb divides the price by (1 − waste). The ounces of each pizza go in its column; you can change the names, the ounces and the menu prices, and use the free rows for your own ingredients. The conversion from ounces to pounds uses the gray constant (16 oz per lb).
... A28: Planning tool, not financial, tax or legal advice. Requirements vary by state, county and city — check with your accountant and local authorities.
