Workbook

Sheet Instrucciones
A1: Carta de bebidas y beverage cost
A2: AI Chef Pro · aichef.pro — Guía Food Cost + Ingeniería de Menú
A4: Instrucciones de uso
A5: 1. Hoja «Parámetros»: revisa la matriz de IVA repercutido y pon tu objetivo de beverage cost para cada categoría. Los tres objetivos vienen sembrados con las referencias del sector y su fuente.
A6: 2. Hoja «Vinos»: por cada referencia, el precio de compra de la botella sin IVA, el formato, los centilitros que sirves por copa y los PVP de botella y de copa. El libro calcula las copas por botella, el coste por copa y el beverage cost de las dos formas de venderlo. Hay 30 filas (8 de ejemplo, 22 libres): una carta de vinos real tiene 30-60 referencias.
A7: 3. Hoja «Cervezas y Refrescos»: el coste por servicio sale del precio de la unidad de compra por la parte que sirves (barril de 30 L → caña de 25 cl). La «unidad de medida» dice si el contenido y el servicio van en cl o en ml. Hay 15 filas (7 de ejemplo, 8 libres).
A8: 4. Hoja «Destilados y Cócteles»: arriba, el combinado sencillo (destilado + mezcla, 12 filas: 5 de ejemplo y 7 libres); abajo, los cócteles desglosados ingrediente a ingrediente (8 cócteles con hasta 4 líneas cada uno: 4 de ejemplo y 4 libres), con el precio de cada uno en euros por litro.
A9: 5. Escribe las unidades vendidas al mes de cada referencia: sin ellas hay coste por copa, pero no hay beverage cost ponderado ni margen del mes.
A10: 6. Hoja «Resumen Bodega»: ventas, coste, beverage cost ponderado y margen de contribución por categoría, con semáforo contra tu objetivo y el total de la bodega.
A11: 7. Los precios con IVA se calculan solos por canal: en sala todo va al 10 %; para llevar, el alcohol y los refrescos azucarados al 21 %.
A13: Celdas verdes = campos editables
A15: Todos los precios de compra y de venta van SIN IVA salvo las columnas que dicen «con IVA»: son las que van en la carta.
... A22: Versión 1.0 · septiembre 2026 · aichef.pro/guia-food-cost-ingenieria-menu · info@aichef.pro

Sheet Parámetros
A1: Parámetros de la bodega
A2: AI Chef Pro · aichef.pro — Guía Food Cost + Ingeniería de Menú
A4: MATRIZ DE IVA REPERCUTIDO POR CANAL Y TIPO DE PRODUCTO
A5: Canal | B5: Comida | C5: Refresco/azucarada | D5: Bebida alcohólica
A6: Sala | B6: 0.1 | C6: 0.1 | D6: 0.1
A7: Take away | B7: 0.1 | C7: 0.21 | D7: 0.21
A8: Delivery | B8: 0.1 | C8: 0.21 | D8: 0.21
A9: Sala — 10 % para todo el consumo en el local, alcohol incluido: art. 91.Uno.2.2.º de la Ley del IVA (servicios de hostelería y suministro de comidas y bebidas para consumir en el acto).
A10: Take away — Sin servicio es entrega de bienes y manda el tipo del producto: comida elaborada 10 % (art. 91.Uno.1.1.º); bebidas alcohólicas y refrescos, zumos y gaseosas con azúcares o edulcorantes añadidos, 21 % (excluidos del tipo reducido desde el 1-ene-2021).
A11: Delivery — Misma regla que el take away: es entrega de bienes, no servicio de hostelería.
A12: Fuente: Ley 37/1992 del IVA, texto consolidado: https://www.boe.es/buscar/act.php?id=BOE-A-1992-28740
A13: El agua, los zumos naturales sin azúcares añadidos y la cerveza sin alcohol no son bebidas alcohólicas ni llevan edulcorantes añadidos: para llevar van al tipo reducido, es decir, a la columna «Comida» de esta matriz.
A15: OBJETIVO DE BEVERAGE COST POR CATEGORÍA
A16: Categoría | B16: Objetivo (%)
A17: Vinos | B17: 0.3
A18: Cervezas y refrescos | B18: 0.22
A19: Destilados y cócteles | B19: 0.2
A20: Vinos — Media española de bebida 34,5 % sobre ingresos de bebida (CaixaBankLab × elBulliFoundation); objetivo de la casa 30 %
A21: Cervezas y refrescos — Referencia España 15-25 % en bebidas estándar (qamarero.com); barril 20-26 % y botella 24-28 % (referencias EE. UU., purimax.com)
A22: Destilados y cócteles — Referencia EE. UU. 15-22 % (purimax.com); pour cost objetivo del sector 18-24 %
A23: Fuente: CaixaBankLab × elBulliFoundation (https://www.caixabanklab.com/elbullifoundation/es/consumos-beneficios-restaurante/), qamarero.com y purimax.com, consultados el 2026-09-03.
A24: Son objetivos de la casa, no una norma: súbelos o bájalos según tu carta y tu clientela. Todo el libro los lee de estas tres celdas.

Sheet Vinos
A1: Vinos: botella y copa
A2: AI Chef Pro · aichef.pro — Guía Food Cost + Ingeniería de Menú
A3: La misma botella deja un margen distinto según la vendas entera o por copas. Aquí se ven las dos.
A4: # | B4: Vino | C4: Tipo a efectos de IVA | D4: Precio de compra de la botella, sin IVA (€) | E4: Formato de la botella (cl) | F4: Servicio de copa (cl) | G4: Copas por botella (n.º) | H4: PVP de la botella en sala, sin IVA (€) | I4: PVP de la copa en sala, sin IVA (€) | J4: Botellas vendidas al mes (n.º) | K4: Copas vendidas al mes (n.º) | L4: Coste por copa (€) | M4: Margen por botella (€) | N4: Margen por copa (€) | O4: Beverage cost de la botella (%) | P4: Beverage cost de la copa (%) | Q4: Ventas del mes, sin IVA (€) | R4: Coste del mes (€) | S4: Margen de contribución del mes (€) | T4: Beverage cost del mes (%) | U4: IVA repercutido en sala (%) | V4: PVP de la botella con IVA en sala (€) | W4: PVP de la copa con IVA en sala (€) | X4: IVA repercutido para llevar (%) | Y4: PVP de la botella con IVA para llevar (€)
A5: 1 | B5: Tinto de la casa (Tempranillo joven) | C5: Bebida alcohólica | D5: 3.9 | E5: 75 | F5: 15 | G5: =IFERROR(IF(OR($E5="",$F5="",$F5=0),"",$E5/$F5),"") -> 5 | H5: 13.6 | I5: 3 | J5: 120 | K5: 780 | L5: =IFERROR(IF(OR($D5="",$G5="",$G5=0),"",$D5/$G5),"") -> 0.78 | M5: =IFERROR(IF(OR($H5="",$D5=""),"",$H5-$D5),"") -> 9.7 | N5: =IFERROR(IF(OR($I5="",$L5=""),"",$I5-$L5),"") -> 2.22 | O5: =IFERROR(IF(OR($D5="",$H5="",$H5=0),"",$D5/$H5),"") -> 0.28676471 | P5: =IFERROR(IF(OR($L5="",$I5="",$I5=0),"",$L5/$I5),"") -> 0.26 | Q5: =IFERROR(IF(OR($H5="",$I5="",$J5="",$K5=""),"",$H5*$J5+$I5*$K5),"") -> 3972 | R5: =IFERROR(IF(OR($D5="",$L5="",$J5="",$K5=""),"",$D5*$J5+$L5*$K5),"") -> 1076.4 | S5: =IFERROR(IF(OR($Q5="",$R5=""),"",$Q5-$R5),"") -> 2895.6 | T5: =IFERROR(IF(OR($Q5="",$Q5=0,$R5=""),"",$R5/$Q5),"") -> 0.27099698 | U5: =IFERROR(IF($C5="","",INDEX(Parámetros!$B$6:$D$8,MATCH(Parámetros!$A$6,Parámetros!$A$6:$A$8,0),MATCH($C5,Parámetros!$B$5:$D$5,0))),"") -> 0.1 | V5: =IFERROR(IF(OR($H5="",$U5=""),"",$H5*(1+$U5)),"") -> 14.96 | W5: =IFERROR(IF(OR($I5="",$U5=""),"",$I5*(1+$U5)),"") -> 3.3 | X5: =IFERROR(IF($C5="","",INDEX(Parámetros!$B$6:$D$8,MATCH(Parámetros!$A$7,Parámetros!$A$6:$A$8,0),MATCH($C5,Parámetros!$B$5:$D$5,0))),"") -> 0.21 | Y5: =IFERROR(IF(OR($H5="",$X5=""),"",$H5*(1+$X5)),"") -> 16.456
A6: 2 | B6: Crianza Rioja | C6: Bebida alcohólica | D6: 6.1 | E6: 75 | F6: 15 | G6: =IFERROR(IF(OR($E6="",$F6="",$F6=0),"",$E6/$F6),"") -> 5 | H6: 19.1 | I6: 4.1 | J6: 95 | K6: 320 | L6: =IFERROR(IF(OR($D6="",$G6="",$G6=0),"",$D6/$G6),"") -> 1.22 | M6: =IFERROR(IF(OR($H6="",$D6=""),"",$H6-$D6),"") -> 13 | N6: =IFERROR(IF(OR($I6="",$L6=""),"",$I6-$L6),"") -> 2.88 | O6: =IFERROR(IF(OR($D6="",$H6="",$H6=0),"",$D6/$H6),"") -> 0.31937173 | P6: =IFERROR(IF(OR($L6="",$I6="",$I6=0),"",$L6/$I6),"") -> 0.29756098 | Q6: =IFERROR(IF(OR($H6="",$I6="",$J6="",$K6=""),"",$H6*$J6+$I6*$K6),"") -> 3126.5 | R6: =IFERROR(IF(OR($D6="",$L6="",$J6="",$K6=""),"",$D6*$J6+$L6*$K6),"") -> 969.9 | S6: =IFERROR(IF(OR($Q6="",$R6=""),"",$Q6-$R6),"") -> 2156.6 | T6: =IFERROR(IF(OR($Q6="",$Q6=0,$R6=""),"",$R6/$Q6),"") -> 0.31021909 | U6: =IFERROR(IF($C6="","",INDEX(Parámetros!$B$6:$D$8,MATCH(Parámetros!$A$6,Parámetros!$A$6:$A$8,0),MATCH($C6,Parámetros!$B$5:$D$5,0))),"") -> 0.1 | V6: =IFERROR(IF(OR($H6="",$U6=""),"",$H6*(1+$U6)),"") -> 21.01 | W6: =IFERROR(IF(OR($I6="",$U6=""),"",$I6*(1+$U6)),"") -> 4.51 | X6: =IFERROR(IF($C6="","",INDEX(Parámetros!$B$6:$D$8,MATCH(Parámetros!$A$7,Parámetros!$A$6:$A$8,0),MATCH($C6,Parámetros!$B$5:$D$5,0))),"") -> 0.21 | Y6: =IFERROR(IF(OR($H6="",$X6=""),"",$H6*(1+$X6)),"") -> 23.111
A7: 3 | B7: Ribera del Duero roble | C7: Bebida alcohólica | D7: 7.4 | E7: 75 | F7: 15 | G7: =IFERROR(IF(OR($E7="",$F7="",$F7=0),"",$E7/$F7),"") -> 5 | H7: 21.8 | I7: 4.5 | J7: 70 | K7: 210 | L7: =IFERROR(IF(OR($D7="",$G7="",$G7=0),"",$D7/$G7),"") -> 1.48 | M7: =IFERROR(IF(OR($H7="",$D7=""),"",$H7-$D7),"") -> 14.4 | N7: =IFERROR(IF(OR($I7="",$L7=""),"",$I7-$L7),"") -> 3.02 | O7: =IFERROR(IF(OR($D7="",$H7="",$H7=0),"",$D7/$H7),"") -> 0.33944954 | P7: =IFERROR(IF(OR($L7="",$I7="",$I7=0),"",$L7/$I7),"") -> 0.32888889 | Q7: =IFERROR(IF(OR($H7="",$I7="",$J7="",$K7=""),"",$H7*$J7+$I7*$K7),"") -> 2471 | R7: =IFERROR(IF(OR($D7="",$L7="",$J7="",$K7=""),"",$D7*$J7+$L7*$K7),"") -> 828.8 | S7: =IFERROR(IF(OR($Q7="",$R7=""),"",$Q7-$R7),"") -> 1642.2 | T7: =IFERROR(IF(OR($Q7="",$Q7=0,$R7=""),"",$R7/$Q7),"") -> 0.33541076 | U7: =IFERROR(IF($C7="","",INDEX(Parámetros!$B$6:$D$8,MATCH(Parámetros!$A$6,Parámetros!$A$6:$A$8,0),MATCH($C7,Parámetros!$B$5:$D$5,0))),"") -> 0.1 | V7: =IFERROR(IF(OR($H7="",$U7=""),"",$H7*(1+$U7)),"") -> 23.98 | W7: =IFERROR(IF(OR($I7="",$U7=""),"",$I7*(1+$U7)),"") -> 4.95 | X7: =IFERROR(IF($C7="","",INDEX(Parámetros!$B$6:$D$8,MATCH(Parámetros!$A$7,Parámetros!$A$6:$A$8,0),MATCH($C7,Parámetros!$B$5:$D$5,0))),"") -> 0.21 | Y7: =IFERROR(IF(OR($H7="",$X7=""),"",$H7*(1+$X7)),"") -> 26.378
A8: 4 | B8: Verdejo Rueda | C8: Bebida alcohólica | D8: 4.2 | E8: 75 | F8: 15 | G8: =IFERROR(IF(OR($E8="",$F8="",$F8=0),"",$E8/$F8),"") -> 5 | H8: 14.5 | I8: 3.2 | J8: 110 | K8: 640 | L8: =IFERROR(IF(OR($D8="",$G8="",$G8=0),"",$D8/$G8),"") -> 0.84 | M8: =IFERROR(IF(OR($H8="",$D8=""),"",$H8-$D8),"") -> 10.3 | N8: =IFERROR(IF(OR($I8="",$L8=""),"",$I8-$L8),"") -> 2.36 | O8: =IFERROR(IF(OR($D8="",$H8="",$H8=0),"",$D8/$H8),"") -> 0.28965517 | P8: =IFERROR(IF(OR($L8="",$I8="",$I8=0),"",$L8/$I8),"") -> 0.2625 | Q8: =IFERROR(IF(OR($H8="",$I8="",$J8="",$K8=""),"",$H8*$J8+$I8*$K8),"") -> 3643 | R8: =IFERROR(IF(OR($D8="",$L8="",$J8="",$K8=""),"",$D8*$J8+$L8*$K8),"") -> 999.6 | S8: =IFERROR(IF(OR($Q8="",$R8=""),"",$Q8-$R8),"") -> 2643.4 | T8: =IFERROR(IF(OR($Q8="",$Q8=0,$R8=""),"",$R8/$Q8),"") -> 0.27438924 | U8: =IFERROR(IF($C8="","",INDEX(Parámetros!$B$6:$D$8,MATCH(Parámetros!$A$6,Parámetros!$A$6:$A$8,0),MATCH($C8,Parámetros!$B$5:$D$5,0))),"") -> 0.1 | V8: =IFERROR(IF(OR($H8="",$U8=""),"",$H8*(1+$U8)),"") -> 15.95 | W8: =IFERROR(IF(OR($I8="",$U8=""),"",$I8*(1+$U8)),"") -> 3.52 | X8: =IFERROR(IF($C8="","",INDEX(Parámetros!$B$6:$D$8,MATCH(Parámetros!$A$7,Parámetros!$A$6:$A$8,0),MATCH($C8,Parámetros!$B$5:$D$5,0))),"") -> 0.21 | Y8: =IFERROR(IF(OR($H8="",$X8=""),"",$H8*(1+$X8)),"") -> 17.545
A9: 5 | B9: Albariño Rías Baixas | C9: Bebida alcohólica | D9: 7.9 | E9: 75 | F9: 15 | G9: =IFERROR(IF(OR($E9="",$F9="",$F9=0),"",$E9/$F9),"") -> 5 | H9: 22.7 | I9: 4.8 | J9: 55 | K9: 150 | L9: =IFERROR(IF(OR($D9="",$G9="",$G9=0),"",$D9/$G9),"") -> 1.58 | M9: =IFERROR(IF(OR($H9="",$D9=""),"",$H9-$D9),"") -> 14.8 | N9: =IFERROR(IF(OR($I9="",$L9=""),"",$I9-$L9),"") -> 3.22 | O9: =IFERROR(IF(OR($D9="",$H9="",$H9=0),"",$D9/$H9),"") -> 0.34801762 | P9: =IFERROR(IF(OR($L9="",$I9="",$I9=0),"",$L9/$I9),"") -> 0.32916667 | Q9: =IFERROR(IF(OR($H9="",$I9="",$J9="",$K9=""),"",$H9*$J9+$I9*$K9),"") -> 1968.5 | R9: =IFERROR(IF(OR($D9="",$L9="",$J9="",$K9=""),"",$D9*$J9+$L9*$K9),"") -> 671.5 | S9: =IFERROR(IF(OR($Q9="",$R9=""),"",$Q9-$R9),"") -> 1297 | T9: =IFERROR(IF(OR($Q9="",$Q9=0,$R9=""),"",$R9/$Q9),"") -> 0.34112268 | U9: =IFERROR(IF($C9="","",INDEX(Parámetros!$B$6:$D$8,MATCH(Parámetros!$A$6,Parámetros!$A$6:$A$8,0),MATCH($C9,Parámetros!$B$5:$D$5,0))),"") -> 0.1 | V9: =IFERROR(IF(OR($H9="",$U9=""),"",$H9*(1+$U9)),"") -> 24.97 | W9: =IFERROR(IF(OR($I9="",$U9=""),"",$I9*(1+$U9)),"") -> 5.28 | X9: =IFERROR(IF($C9="","",INDEX(Parámetros!$B$6:$D$8,MATCH(Parámetros!$A$7,Parámetros!$A$6:$A$8,0),MATCH($C9,Parámetros!$B$5:$D$5,0))),"") -> 0.21 | Y9: =IFERROR(IF(OR($H9="",$X9=""),"",$H9*(1+$X9)),"") -> 27.467
A10: 6 | B10: Cava brut nature | C10: Bebida alcohólica | D10: 5.6 | E10: 75 | F10: 15 | G10: =IFERROR(IF(OR($E10="",$F10="",$F10=0),"",$E10/$F10),"") -> 5 | H10: 18.2 | I10: 3.9 | J10: 40 | K10: 180 | L10: =IFERROR(IF(OR($D10="",$G10="",$G10=0),"",$D10/$G10),"") -> 1.12 | M10: =IFERROR(IF(OR($H10="",$D10=""),"",$H10-$D10),"") -> 12.6 | N10: =IFERROR(IF(OR($I10="",$L10=""),"",$I10-$L10),"") -> 2.78 | O10: =IFERROR(IF(OR($D10="",$H10="",$H10=0),"",$D10/$H10),"") -> 0.30769231 | P10: =IFERROR(IF(OR($L10="",$I10="",$I10=0),"",$L10/$I10),"") -> 0.28717949 | Q10: =IFERROR(IF(OR($H10="",$I10="",$J10="",$K10=""),"",$H10*$J10+$I10*$K10),"") -> 1430 | R10: =IFERROR(IF(OR($D10="",$L10="",$J10="",$K10=""),"",$D10*$J10+$L10*$K10),"") -> 425.6 | S10: =IFERROR(IF(OR($Q10="",$R10=""),"",$Q10-$R10),"") -> 1004.4 | T10: =IFERROR(IF(OR($Q10="",$Q10=0,$R10=""),"",$R10/$Q10),"") -> 0.29762238 | U10: =IFERROR(IF($C10="","",INDEX(Parámetros!$B$6:$D$8,MATCH(Parámetros!$A$6,Parámetros!$A$6:$A$8,0),MATCH($C10,Parámetros!$B$5:$D$5,0))),"") -> 0.1 | V10: =IFERROR(IF(OR($H10="",$U10=""),"",$H10*(1+$U10)),"") -> 20.02 | W10: =IFERROR(IF(OR($I10="",$U10=""),"",$I10*(1+$U10)),"") -> 4.29 | X10: =IFERROR(IF($C10="","",INDEX(Parámetros!$B$6:$D$8,MATCH(Parámetros!$A$7,Parámetros!$A$6:$A$8,0),MATCH($C10,Parámetros!$B$5:$D$5,0))),"") -> 0.21 | Y10: =IFERROR(IF(OR($H10="",$X10=""),"",$H10*(1+$X10)),"") -> 22.022
A11: 7 | B11: Rosado Navarra | C11: Bebida alcohólica | D11: 3.7 | E11: 75 | F11: 15 | G11: =IFERROR(IF(OR($E11="",$F11="",$F11=0),"",$E11/$F11),"") -> 5 | H11: 12.7 | I11: 2.9 | J11: 30 | K11: 140 | L11: =IFERROR(IF(OR($D11="",$G11="",$G11=0),"",$D11/$G11),"") -> 0.74 | M11: =IFERROR(IF(OR($H11="",$D11=""),"",$H11-$D11),"") -> 9 | N11: =IFERROR(IF(OR($I11="",$L11=""),"",$I11-$L11),"") -> 2.16 | O11: =IFERROR(IF(OR($D11="",$H11="",$H11=0),"",$D11/$H11),"") -> 0.29133858 | P11: =IFERROR(IF(OR($L11="",$I11="",$I11=0),"",$L11/$I11),"") -> 0.25517241 | Q11: =IFERROR(IF(OR($H11="",$I11="",$J11="",$K11=""),"",$H11*$J11+$I11*$K11),"") -> 787 | R11: =IFERROR(IF(OR($D11="",$L11="",$J11="",$K11=""),"",$D11*$J11+$L11*$K11),"") -> 214.6 | S11: =IFERROR(IF(OR($Q11="",$R11=""),"",$Q11-$R11),"") -> 572.4 | T11: =IFERROR(IF(OR($Q11="",$Q11=0,$R11=""),"",$R11/$Q11),"") -> 0.27268107 | U11: =IFERROR(IF($C11="","",INDEX(Parámetros!$B$6:$D$8,MATCH(Parámetros!$A$6,Parámetros!$A$6:$A$8,0),MATCH($C11,Parámetros!$B$5:$D$5,0))),"") -> 0.1 | V11: =IFERROR(IF(OR($H11="",$U11=""),"",$H11*(1+$U11)),"") -> 13.97 | W11: =IFERROR(IF(OR($I11="",$U11=""),"",$I11*(1+$U11)),"") -> 3.19 | X11: =IFERROR(IF($C11="","",INDEX(Parámetros!$B$6:$D$8,MATCH(Parámetros!$A$7,Parámetros!$A$6:$A$8,0),MATCH($C11,Parámetros!$B$5:$D$5,0))),"") -> 0.21 | Y11: =IFERROR(IF(OR($H11="",$X11=""),"",$H11*(1+$X11)),"") -> 15.367
A12: 8 | B12: Vino dulce Pedro Ximénez | C12: Bebida alcohólica | D12: 11.5 | E12: 50 | F12: 6.25 | G12: =IFERROR(IF(OR($E12="",$F12="",$F12=0),"",$E12/$F12),"") -> 8 | H12: 27.3 | I12: 4 | J12: 10 | K12: 120 | L12: =IFERROR(IF(OR($D12="",$G12="",$G12=0),"",$D12/$G12),"") -> 1.4375 | M12: =IFERROR(IF(OR($H12="",$D12=""),"",$H12-$D12),"") -> 15.8 | N12: =IFERROR(IF(OR($I12="",$L12=""),"",$I12-$L12),"") -> 2.5625 | O12: =IFERROR(IF(OR($D12="",$H12="",$H12=0),"",$D12/$H12),"") -> 0.42124542 | P12: =IFERROR(IF(OR($L12="",$I12="",$I12=0),"",$L12/$I12),"") -> 0.359375 | Q12: =IFERROR(IF(OR($H12="",$I12="",$J12="",$K12=""),"",$H12*$J12+$I12*$K12),"") -> 753 | R12: =IFERROR(IF(OR($D12="",$L12="",$J12="",$K12=""),"",$D12*$J12+$L12*$K12),"") -> 287.5 | S12: =IFERROR(IF(OR($Q12="",$R12=""),"",$Q12-$R12),"") -> 465.5 | T12: =IFERROR(IF(OR($Q12="",$Q12=0,$R12=""),"",$R12/$Q12),"") -> 0.38180611 | U12: =IFERROR(IF($C12="","",INDEX(Parámetros!$B$6:$D$8,MATCH(Parámetros!$A$6,Parámetros!$A$6:$A$8,0),MATCH($C12,Parámetros!$B$5:$D$5,0))),"") -> 0.1 | V12: =IFERROR(IF(OR($H12="",$U12=""),"",$H12*(1+$U12)),"") -> 30.03 | W12: =IFERROR(IF(OR($I12="",$U12=""),"",$I12*(1+$U12)),"") -> 4.4 | X12: =IFERROR(IF($C12="","",INDEX(Parámetros!$B$6:$D$8,MATCH(Parámetros!$A$7,Parámetros!$A$6:$A$8,0),MATCH($C12,Parámetros!$B$5:$D$5,0))),"") -> 0.21 | Y12: =IFERROR(IF(OR($H12="",$X12=""),"",$H12*(1+$X12)),"") -> 33.033
A13: 9 | G13: =IFERROR(IF(OR($E13="",$F13="",$F13=0),"",$E13/$F13),"") | L13: =IFERROR(IF(OR($D13="",$G13="",$G13=0),"",$D13/$G13),"") | M13: =IFERROR(IF(OR($H13="",$D13=""),"",$H13-$D13),"") | N13: =IFERROR(IF(OR($I13="",$L13=""),"",$I13-$L13),"") | O13: =IFERROR(IF(OR($D13="",$H13="",$H13=0),"",$D13/$H13),"") | P13: =IFERROR(IF(OR($L13="",$I13="",$I13=0),"",$L13/$I13),"") | Q13: =IFERROR(IF(OR($H13="",$I13="",$J13="",$K13=""),"",$H13*$J13+$I13*$K13),"") | R13: =IFERROR(IF(OR($D13="",$L13="",$J13="",$K13=""),"",$D13*$J13+$L13*$K13),"") | S13: =IFERROR(IF(OR($Q13="",$R13=""),"",$Q13-$R13),"") | T13: =IFERROR(IF(OR($Q13="",$Q13=0,$R13=""),"",$R13/$Q13),"") | U13: =IFERROR(IF($C13="","",INDEX(Parámetros!$B$6:$D$8,MATCH(Parámetros!$A$6,Parámetros!$A$6:$A$8,0),MATCH($C13,Parámetros!$B$5:$D$5,0))),"") | V13: =IFERROR(IF(OR($H13="",$U13=""),"",$H13*(1+$U13)),"") | W13: =IFERROR(IF(OR($I13="",$U13=""),"",$I13*(1+$U13)),"") | X13: =IFERROR(IF($C13="","",INDEX(Parámetros!$B$6:$D$8,MATCH(Parámetros!$A$7,Parámetros!$A$6:$A$8,0),MATCH($C13,Parámetros!$B$5:$D$5,0))),"") | Y13: =IFERROR(IF(OR($H13="",$X13=""),"",$H13*(1+$X13)),"")
A14: 10 | G14: =IFERROR(IF(OR($E14="",$F14="",$F14=0),"",$E14/$F14),"") | L14: =IFERROR(IF(OR($D14="",$G14="",$G14=0),"",$D14/$G14),"") | M14: =IFERROR(IF(OR($H14="",$D14=""),"",$H14-$D14),"") | N14: =IFERROR(IF(OR($I14="",$L14=""),"",$I14-$L14),"") | O14: =IFERROR(IF(OR($D14="",$H14="",$H14=0),"",$D14/$H14),"") | P14: =IFERROR(IF(OR($L14="",$I14="",$I14=0),"",$L14/$I14),"") | Q14: =IFERROR(IF(OR($H14="",$I14="",$J14="",$K14=""),"",$H14*$J14+$I14*$K14),"") | R14: =IFERROR(IF(OR($D14="",$L14="",$J14="",$K14=""),"",$D14*$J14+$L14*$K14),"") | S14: =IFERROR(IF(OR($Q14="",$R14=""),"",$Q14-$R14),"") | T14: =IFERROR(IF(OR($Q14="",$Q14=0,$R14=""),"",$R14/$Q14),"") | U14: =IFERROR(IF($C14="","",INDEX(Parámetros!$B$6:$D$8,MATCH(Parámetros!$A$6,Parámetros!$A$6:$A$8,0),MATCH($C14,Parámetros!$B$5:$D$5,0))),"") | V14: =IFERROR(IF(OR($H14="",$U14=""),"",$H14*(1+$U14)),"") | W14: =IFERROR(IF(OR($I14="",$U14=""),"",$I14*(1+$U14)),"") | X14: =IFERROR(IF($C14="","",INDEX(Parámetros!$B$6:$D$8,MATCH(Parámetros!$A$7,Parámetros!$A$6:$A$8,0),MATCH($C14,Parámetros!$B$5:$D$5,0))),"") | Y14: =IFERROR(IF(OR($H14="",$X14=""),"",$H14*(1+$X14)),"")
A15: 11 | G15: =IFERROR(IF(OR($E15="",$F15="",$F15=0),"",$E15/$F15),"") | L15: =IFERROR(IF(OR($D15="",$G15="",$G15=0),"",$D15/$G15),"") | M15: =IFERROR(IF(OR($H15="",$D15=""),"",$H15-$D15),"") | N15: =IFERROR(IF(OR($I15="",$L15=""),"",$I15-$L15),"") | O15: =IFERROR(IF(OR($D15="",$H15="",$H15=0),"",$D15/$H15),"") | P15: =IFERROR(IF(OR($L15="",$I15="",$I15=0),"",$L15/$I15),"") | Q15: =IFERROR(IF(OR($H15="",$I15="",$J15="",$K15=""),"",$H15*$J15+$I15*$K15),"") | R15: =IFERROR(IF(OR($D15="",$L15="",$J15="",$K15=""),"",$D15*$J15+$L15*$K15),"") | S15: =IFERROR(IF(OR($Q15="",$R15=""),"",$Q15-$R15),"") | T15: =IFERROR(IF(OR($Q15="",$Q15=0,$R15=""),"",$R15/$Q15),"") | U15: =IFERROR(IF($C15="","",INDEX(Parámetros!$B$6:$D$8,MATCH(Parámetros!$A$6,Parámetros!$A$6:$A$8,0),MATCH($C15,Parámetros!$B$5:$D$5,0))),"") | V15: =IFERROR(IF(OR($H15="",$U15=""),"",$H15*(1+$U15)),"") | W15: =IFERROR(IF(OR($I15="",$U15=""),"",$I15*(1+$U15)),"") | X15: =IFERROR(IF($C15="","",INDEX(Parámetros!$B$6:$D$8,MATCH(Parámetros!$A$7,Parámetros!$A$6:$A$8,0),MATCH($C15,Parámetros!$B$5:$D$5,0))),"") | Y15: =IFERROR(IF(OR($H15="",$X15=""),"",$H15*(1+$X15)),"")
A16: 12 | G16: =IFERROR(IF(OR($E16="",$F16="",$F16=0),"",$E16/$F16),"") | L16: =IFERROR(IF(OR($D16="",$G16="",$G16=0),"",$D16/$G16),"") | M16: =IFERROR(IF(OR($H16="",$D16=""),"",$H16-$D16),"") | N16: =IFERROR(IF(OR($I16="",$L16=""),"",$I16-$L16),"") | O16: =IFERROR(IF(OR($D16="",$H16="",$H16=0),"",$D16/$H16),"") | P16: =IFERROR(IF(OR($L16="",$I16="",$I16=0),"",$L16/$I16),"") | Q16: =IFERROR(IF(OR($H16="",$I16="",$J16="",$K16=""),"",$H16*$J16+$I16*$K16),"") | R16: =IFERROR(IF(OR($D16="",$L16="",$J16="",$K16=""),"",$D16*$J16+$L16*$K16),"") | S16: =IFERROR(IF(OR($Q16="",$R16=""),"",$Q16-$R16),"") | T16: =IFERROR(IF(OR($Q16="",$Q16=0,$R16=""),"",$R16/$Q16),"") | U16: =IFERROR(IF($C16="","",INDEX(Parámetros!$B$6:$D$8,MATCH(Parámetros!$A$6,Parámetros!$A$6:$A$8,0),MATCH($C16,Parámetros!$B$5:$D$5,0))),"") | V16: =IFERROR(IF(OR($H16="",$U16=""),"",$H16*(1+$U16)),"") | W16: =IFERROR(IF(OR($I16="",$U16=""),"",$I16*(1+$U16)),"") | X16: =IFERROR(IF($C16="","",INDEX(Parámetros!$B$6:$D$8,MATCH(Parámetros!$A$7,Parámetros!$A$6:$A$8,0),MATCH($C16,Parámetros!$B$5:$D$5,0))),"") | Y16: =IFERROR(IF(OR($H16="",$X16=""),"",$H16*(1+$X16)),"")
A17: 13 | G17: =IFERROR(IF(OR($E17="",$F17="",$F17=0),"",$E17/$F17),"") | L17: =IFERROR(IF(OR($D17="",$G17="",$G17=0),"",$D17/$G17),"") | M17: =IFERROR(IF(OR($H17="",$D17=""),"",$H17-$D17),"") | N17: =IFERROR(IF(OR($I17="",$L17=""),"",$I17-$L17),"") | O17: =IFERROR(IF(OR($D17="",$H17="",$H17=0),"",$D17/$H17),"") | P17: =IFERROR(IF(OR($L17="",$I17="",$I17=0),"",$L17/$I17),"") | Q17: =IFERROR(IF(OR($H17="",$I17="",$J17="",$K17=""),"",$H17*$J17+$I17*$K17),"") | R17: =IFERROR(IF(OR($D17="",$L17="",$J17="",$K17=""),"",$D17*$J17+$L17*$K17),"") | S17: =IFERROR(IF(OR($Q17="",$R17=""),"",$Q17-$R17),"") | T17: =IFERROR(IF(OR($Q17="",$Q17=0,$R17=""),"",$R17/$Q17),"") | U17: =IFERROR(IF($C17="","",INDEX(Parámetros!$B$6:$D$8,MATCH(Parámetros!$A$6,Parámetros!$A$6:$A$8,0),MATCH($C17,Parámetros!$B$5:$D$5,0))),"") | V17: =IFERROR(IF(OR($H17="",$U17=""),"",$H17*(1+$U17)),"") | W17: =IFERROR(IF(OR($I17="",$U17=""),"",$I17*(1+$U17)),"") | X17: =IFERROR(IF($C17="","",INDEX(Parámetros!$B$6:$D$8,MATCH(Parámetros!$A$7,Parámetros!$A$6:$A$8,0),MATCH($C17,Parámetros!$B$5:$D$5,0))),"") | Y17: =IFERROR(IF(OR($H17="",$X17=""),"",$H17*(1+$X17)),"")
A18: 14 | G18: =IFERROR(IF(OR($E18="",$F18="",$F18=0),"",$E18/$F18),"") | L18: =IFERROR(IF(OR($D18="",$G18="",$G18=0),"",$D18/$G18),"") | M18: =IFERROR(IF(OR($H18="",$D18=""),"",$H18-$D18),"") | N18: =IFERROR(IF(OR($I18="",$L18=""),"",$I18-$L18),"") | O18: =IFERROR(IF(OR($D18="",$H18="",$H18=0),"",$D18/$H18),"") | P18: =IFERROR(IF(OR($L18="",$I18="",$I18=0),"",$L18/$I18),"") | Q18: =IFERROR(IF(OR($H18="",$I18="",$J18="",$K18=""),"",$H18*$J18+$I18*$K18),"") | R18: =IFERROR(IF(OR($D18="",$L18="",$J18="",$K18=""),"",$D18*$J18+$L18*$K18),"") | S18: =IFERROR(IF(OR($Q18="",$R18=""),"",$Q18-$R18),"") | T18: =IFERROR(IF(OR($Q18="",$Q18=0,$R18=""),"",$R18/$Q18),"") | U18: =IFERROR(IF($C18="","",INDEX(Parámetros!$B$6:$D$8,MATCH(Parámetros!$A$6,Parámetros!$A$6:$A$8,0),MATCH($C18,Parámetros!$B$5:$D$5,0))),"") | V18: =IFERROR(IF(OR($H18="",$U18=""),"",$H18*(1+$U18)),"") | W18: =IFERROR(IF(OR($I18="",$U18=""),"",$I18*(1+$U18)),"") | X18: =IFERROR(IF($C18="","",INDEX(Parámetros!$B$6:$D$8,MATCH(Parámetros!$A$7,Parámetros!$A$6:$A$8,0),MATCH($C18,Parámetros!$B$5:$D$5,0))),"") | Y18: =IFERROR(IF(OR($H18="",$X18=""),"",$H18*(1+$X18)),"")
A19: 15 | G19: =IFERROR(IF(OR($E19="",$F19="",$F19=0),"",$E19/$F19),"") | L19: =IFERROR(IF(OR($D19="",$G19="",$G19=0),"",$D19/$G19),"") | M19: =IFERROR(IF(OR($H19="",$D19=""),"",$H19-$D19),"") | N19: =IFERROR(IF(OR($I19="",$L19=""),"",$I19-$L19),"") | O19: =IFERROR(IF(OR($D19="",$H19="",$H19=0),"",$D19/$H19),"") | P19: =IFERROR(IF(OR($L19="",$I19="",$I19=0),"",$L19/$I19),"") | Q19: =IFERROR(IF(OR($H19="",$I19="",$J19="",$K19=""),"",$H19*$J19+$I19*$K19),"") | R19: =IFERROR(IF(OR($D19="",$L19="",$J19="",$K19=""),"",$D19*$J19+$L19*$K19),"") | S19: =IFERROR(IF(OR($Q19="",$R19=""),"",$Q19-$R19),"") | T19: =IFERROR(IF(OR($Q19="",$Q19=0,$R19=""),"",$R19/$Q19),"") | U19: =IFERROR(IF($C19="","",INDEX(Parámetros!$B$6:$D$8,MATCH(Parámetros!$A$6,Parámetros!$A$6:$A$8,0),MATCH($C19,Parámetros!$B$5:$D$5,0))),"") | V19: =IFERROR(IF(OR($H19="",$U19=""),"",$H19*(1+$U19)),"") | W19: =IFERROR(IF(OR($I19="",$U19=""),"",$I19*(1+$U19)),"") | X19: =IFERROR(IF($C19="","",INDEX(Parámetros!$B$6:$D$8,MATCH(Parámetros!$A$7,Parámetros!$A$6:$A$8,0),MATCH($C19,Parámetros!$B$5:$D$5,0))),"") | Y19: =IFERROR(IF(OR($H19="",$X19=""),"",$H19*(1+$X19)),"")
A20: 16 | G20: =IFERROR(IF(OR($E20="",$F20="",$F20=0),"",$E20/$F20),"") | L20: =IFERROR(IF(OR($D20="",$G20="",$G20=0),"",$D20/$G20),"") | M20: =IFERROR(IF(OR($H20="",$D20=""),"",$H20-$D20),"") | N20: =IFERROR(IF(OR($I20="",$L20=""),"",$I20-$L20),"") | O20: =IFERROR(IF(OR($D20="",$H20="",$H20=0),"",$D20/$H20),"") | P20: =IFERROR(IF(OR($L20="",$I20="",$I20=0),"",$L20/$I20),"") | Q20: =IFERROR(IF(OR($H20="",$I20="",$J20="",$K20=""),"",$H20*$J20+$I20*$K20),"") | R20: =IFERROR(IF(OR($D20="",$L20="",$J20="",$K20=""),"",$D20*$J20+$L20*$K20),"") | S20: =IFERROR(IF(OR($Q20="",$R20=""),"",$Q20-$R20),"") | T20: =IFERROR(IF(OR($Q20="",$Q20=0,$R20=""),"",$R20/$Q20),"") | U20: =IFERROR(IF($C20="","",INDEX(Parámetros!$B$6:$D$8,MATCH(Parámetros!$A$6,Parámetros!$A$6:$A$8,0),MATCH($C20,Parámetros!$B$5:$D$5,0))),"") | V20: =IFERROR(IF(OR($H20="",$U20=""),"",$H20*(1+$U20)),"") | W20: =IFERROR(IF(OR($I20="",$U20=""),"",$I20*(1+$U20)),"") | X20: =IFERROR(IF($C20="","",INDEX(Parámetros!$B$6:$D$8,MATCH(Parámetros!$A$7,Parámetros!$A$6:$A$8,0),MATCH($C20,Parámetros!$B$5:$D$5,0))),"") | Y20: =IFERROR(IF(OR($H20="",$X20=""),"",$H20*(1+$X20)),"")
A21: 17 | G21: =IFERROR(IF(OR($E21="",$F21="",$F21=0),"",$E21/$F21),"") | L21: =IFERROR(IF(OR($D21="",$G21="",$G21=0),"",$D21/$G21),"") | M21: =IFERROR(IF(OR($H21="",$D21=""),"",$H21-$D21),"") | N21: =IFERROR(IF(OR($I21="",$L21=""),"",$I21-$L21),"") | O21: =IFERROR(IF(OR($D21="",$H21="",$H21=0),"",$D21/$H21),"") | P21: =IFERROR(IF(OR($L21="",$I21="",$I21=0),"",$L21/$I21),"") | Q21: =IFERROR(IF(OR($H21="",$I21="",$J21="",$K21=""),"",$H21*$J21+$I21*$K21),"") | R21: =IFERROR(IF(OR($D21="",$L21="",$J21="",$K21=""),"",$D21*$J21+$L21*$K21),"") | S21: =IFERROR(IF(OR($Q21="",$R21=""),"",$Q21-$R21),"") | T21: =IFERROR(IF(OR($Q21="",$Q21=0,$R21=""),"",$R21/$Q21),"") | U21: =IFERROR(IF($C21="","",INDEX(Parámetros!$B$6:$D$8,MATCH(Parámetros!$A$6,Parámetros!$A$6:$A$8,0),MATCH($C21,Parámetros!$B$5:$D$5,0))),"") | V21: =IFERROR(IF(OR($H21="",$U21=""),"",$H21*(1+$U21)),"") | W21: =IFERROR(IF(OR($I21="",$U21=""),"",$I21*(1+$U21)),"") | X21: =IFERROR(IF($C21="","",INDEX(Parámetros!$B$6:$D$8,MATCH(Parámetros!$A$7,Parámetros!$A$6:$A$8,0),MATCH($C21,Parámetros!$B$5:$D$5,0))),"") | Y21: =IFERROR(IF(OR($H21="",$X21=""),"",$H21*(1+$X21)),"")
A22: 18 | G22: =IFERROR(IF(OR($E22="",$F22="",$F22=0),"",$E22/$F22),"") | L22: =IFERROR(IF(OR($D22="",$G22="",$G22=0),"",$D22/$G22),"") | M22: =IFERROR(IF(OR($H22="",$D22=""),"",$H22-$D22),"") | N22: =IFERROR(IF(OR($I22="",$L22=""),"",$I22-$L22),"") | O22: =IFERROR(IF(OR($D22="",$H22="",$H22=0),"",$D22/$H22),"") | P22: =IFERROR(IF(OR($L22="",$I22="",$I22=0),"",$L22/$I22),"") | Q22: =IFERROR(IF(OR($H22="",$I22="",$J22="",$K22=""),"",$H22*$J22+$I22*$K22),"") | R22: =IFERROR(IF(OR($D22="",$L22="",$J22="",$K22=""),"",$D22*$J22+$L22*$K22),"") | S22: =IFERROR(IF(OR($Q22="",$R22=""),"",$Q22-$R22),"") | T22: =IFERROR(IF(OR($Q22="",$Q22=0,$R22=""),"",$R22/$Q22),"") | U22: =IFERROR(IF($C22="","",INDEX(Parámetros!$B$6:$D$8,MATCH(Parámetros!$A$6,Parámetros!$A$6:$A$8,0),MATCH($C22,Parámetros!$B$5:$D$5,0))),"") | V22: =IFERROR(IF(OR($H22="",$U22=""),"",$H22*(1+$U22)),"") | W22: =IFERROR(IF(OR($I22="",$U22=""),"",$I22*(1+$U22)),"") | X22: =IFERROR(IF($C22="","",INDEX(Parámetros!$B$6:$D$8,MATCH(Parámetros!$A$7,Parámetros!$A$6:$A$8,0),MATCH($C22,Parámetros!$B$5:$D$5,0))),"") | Y22: =IFERROR(IF(OR($H22="",$X22=""),"",$H22*(1+$X22)),"")
A23: 19 | G23: =IFERROR(IF(OR($E23="",$F23="",$F23=0),"",$E23/$F23),"") | L23: =IFERROR(IF(OR($D23="",$G23="",$G23=0),"",$D23/$G23),"") | M23: =IFERROR(IF(OR($H23="",$D23=""),"",$H23-$D23),"") | N23: =IFERROR(IF(OR($I23="",$L23=""),"",$I23-$L23),"") | O23: =IFERROR(IF(OR($D23="",$H23="",$H23=0),"",$D23/$H23),"") | P23: =IFERROR(IF(OR($L23="",$I23="",$I23=0),"",$L23/$I23),"") | Q23: =IFERROR(IF(OR($H23="",$I23="",$J23="",$K23=""),"",$H23*$J23+$I23*$K23),"") | R23: =IFERROR(IF(OR($D23="",$L23="",$J23="",$K23=""),"",$D23*$J23+$L23*$K23),"") | S23: =IFERROR(IF(OR($Q23="",$R23=""),"",$Q23-$R23),"") | T23: =IFERROR(IF(OR($Q23="",$Q23=0,$R23=""),"",$R23/$Q23),"") | U23: =IFERROR(IF($C23="","",INDEX(Parámetros!$B$6:$D$8,MATCH(Parámetros!$A$6,Parámetros!$A$6:$A$8,0),MATCH($C23,Parámetros!$B$5:$D$5,0))),"") | V23: =IFERROR(IF(OR($H23="",$U23=""),"",$H23*(1+$U23)),"") | W23: =IFERROR(IF(OR($I23="",$U23=""),"",$I23*(1+$U23)),"") | X23: =IFERROR(IF($C23="","",INDEX(Parámetros!$B$6:$D$8,MATCH(Parámetros!$A$7,Parámetros!$A$6:$A$8,0),MATCH($C23,Parámetros!$B$5:$D$5,0))),"") | Y23: =IFERROR(IF(OR($H23="",$X23=""),"",$H23*(1+$X23)),"")
A24: 20 | G24: =IFERROR(IF(OR($E24="",$F24="",$F24=0),"",$E24/$F24),"") | L24: =IFERROR(IF(OR($D24="",$G24="",$G24=0),"",$D24/$G24),"") | M24: =IFERROR(IF(OR($H24="",$D24=""),"",$H24-$D24),"") | N24: =IFERROR(IF(OR($I24="",$L24=""),"",$I24-$L24),"") | O24: =IFERROR(IF(OR($D24="",$H24="",$H24=0),"",$D24/$H24),"") | P24: =IFERROR(IF(OR($L24="",$I24="",$I24=0),"",$L24/$I24),"") | Q24: =IFERROR(IF(OR($H24="",$I24="",$J24="",$K24=""),"",$H24*$J24+$I24*$K24),"") | R24: =IFERROR(IF(OR($D24="",$L24="",$J24="",$K24=""),"",$D24*$J24+$L24*$K24),"") | S24: =IFERROR(IF(OR($Q24="",$R24=""),"",$Q24-$R24),"") | T24: =IFERROR(IF(OR($Q24="",$Q24=0,$R24=""),"",$R24/$Q24),"") | U24: =IFERROR(IF($C24="","",INDEX(Parámetros!$B$6:$D$8,MATCH(Parámetros!$A$6,Parámetros!$A$6:$A$8,0),MATCH($C24,Parámetros!$B$5:$D$5,0))),"") | V24: =IFERROR(IF(OR($H24="",$U24=""),"",$H24*(1+$U24)),"") | W24: =IFERROR(IF(OR($I24="",$U24=""),"",$I24*(1+$U24)),"") | X24: =IFERROR(IF($C24="","",INDEX(Parámetros!$B$6:$D$8,MATCH(Parámetros!$A$7,Parámetros!$A$6:$A$8,0),MATCH($C24,Parámetros!$B$5:$D$5,0))),"") | Y24: =IFERROR(IF(OR($H24="",$X24=""),"",$H24*(1+$X24)),"")
... A34: 30 | G34: =IFERROR(IF(OR($E34="",$F34="",$F34=0),"",$E34/$F34),"") | L34: =IFERROR(IF(OR($D34="",$G34="",$G34=0),"",$D34/$G34),"") | M34: =IFERROR(IF(OR($H34="",$D34=""),"",$H34-$D34),"") | N34: =IFERROR(IF(OR($I34="",$L34=""),"",$I34-$L34),"") | O34: =IFERROR(IF(OR($D34="",$H34="",$H34=0),"",$D34/$H34),"") | P34: =IFERROR(IF(OR($L34="",$I34="",$I34=0),"",$L34/$I34),"") | Q34: =IFERROR(IF(OR($H34="",$I34="",$J34="",$K34=""),"",$H34*$J34+$I34*$K34),"") | R34: =IFERROR(IF(OR($D34="",$L34="",$J34="",$K34=""),"",$D34*$J34+$L34*$K34),"") | S34: =IFERROR(IF(OR($Q34="",$R34=""),"",$Q34-$R34),"") | T34: =IFERROR(IF(OR($Q34="",$Q34=0,$R34=""),"",$R34/$Q34),"") | U34: =IFERROR(IF($C34="","",INDEX(Parámetros!$B$6:$D$8,MATCH(Parámetros!$A$6,Parámetros!$A$6:$A$8,0),MATCH($C34,Parámetros!$B$5:$D$5,0))),"") | V34: =IFERROR(IF(OR($H34="",$U34=""),"",$H34*(1+$U34)),"") | W34: =IFERROR(IF(OR($I34="",$U34=""),"",$I34*(1+$U34)),"") | X34: =IFERROR(IF($C34="","",INDEX(Parámetros!$B$6:$D$8,MATCH(Parámetros!$A$7,Parámetros!$A$6:$A$8,0),MATCH($C34,Parámetros!$B$5:$D$5,0))),"") | Y34: =IFERROR(IF(OR($H34="",$X34=""),"",$H34*(1+$X34)),"")
B35: TOTAL VINOS | J35: =IF(COUNT(J5:J34)=0,"",SUM(J5:J34)) -> 530 | K35: =IF(COUNT(K5:K34)=0,"",SUM(K5:K34)) -> 2540 | Q35: =IF(COUNT(Q5:Q34)=0,"",SUM(Q5:Q34)) -> 18151 | R35: =IF(COUNT(R5:R34)=0,"",SUM(R5:R34)) -> 5473.9 | S35: =IF(COUNT(S5:S34)=0,"",SUM(S5:S34)) -> 12677.1 | T35: =IFERROR(IF(OR($Q$35="",$Q$35=0,$R$35=""),"",$R$35/$Q$35),"") -> 0.30157567
B37: Objetivo de beverage cost de los vinos (%) | E37: =IF(Parámetros!$B$17="","",Parámetros!$B$17) -> 0.3
B39: El servicio de copa es lo que sirves de verdad: cámbialo y cambian las copas por botella, el coste por copa y el beverage cost. Es la palanca más barata de toda la bodega.

Sheet Cervezas y Refrescos
A1: Cervezas y refrescos
A2: AI Chef Pro · aichef.pro — Guía Food Cost + Ingeniería de Menú
A3: El coste por servicio sale del precio de la unidad de compra por la parte que sirves: un barril de 30 L da 120 cañas de 25 cl.
A4: # | B4: Referencia | C4: Formato de compra | D4: Tipo a efectos de IVA | E4: Unidad de medida | F4: Precio de compra de la unidad, sin IVA (€) | G4: Contenido de la unidad de compra | H4: Servicio | I4: PVP del servicio en sala, sin IVA (€) | J4: Servicios vendidos al mes (n.º) | K4: Servicios por unidad de compra (n.º) | L4: Coste por servicio (€) | M4: Margen por servicio (€) | N4: Beverage cost (%) | O4: Ventas del mes, sin IVA (€) | P4: Coste del mes (€) | Q4: Margen de contribución del mes (€) | R4: IVA repercutido en sala (%) | S4: PVP del servicio con IVA en sala (€) | T4: IVA repercutido para llevar (%) | U4: PVP del servicio con IVA para llevar (€)
A5: 1 | B5: Cerveza de barril (30 L) | C5: barril | D5: Bebida alcohólica | E5: cl | F5: 78 | G5: 3000 | H5: 25 | I5: 2.3 | J5: 2900 | K5: =IFERROR(IF(OR($G5="",$H5="",$H5=0),"",$G5/$H5),"") -> 120 | L5: =IFERROR(IF(OR($F5="",$G5="",$G5=0,$H5=""),"",$F5*$H5/$G5),"") -> 0.65 | M5: =IFERROR(IF(OR($I5="",$L5=""),"",$I5-$L5),"") -> 1.65 | N5: =IFERROR(IF(OR($L5="",$I5="",$I5=0),"",$L5/$I5),"") -> 0.2826087 | O5: =IFERROR(IF(OR($I5="",$J5=""),"",$I5*$J5),"") -> 6670 | P5: =IFERROR(IF(OR($L5="",$J5=""),"",$L5*$J5),"") -> 1885 | Q5: =IFERROR(IF(OR($O5="",$P5=""),"",$O5-$P5),"") -> 4785 | R5: =IFERROR(IF($D5="","",INDEX(Parámetros!$B$6:$D$8,MATCH(Parámetros!$A$6,Parámetros!$A$6:$A$8,0),MATCH($D5,Parámetros!$B$5:$D$5,0))),"") -> 0.1 | S5: =IFERROR(IF(OR($I5="",$R5=""),"",$I5*(1+$R5)),"") -> 2.53 | T5: =IFERROR(IF($D5="","",INDEX(Parámetros!$B$6:$D$8,MATCH(Parámetros!$A$7,Parámetros!$A$6:$A$8,0),MATCH($D5,Parámetros!$B$5:$D$5,0))),"") -> 0.21 | U5: =IFERROR(IF(OR($I5="",$T5=""),"",$I5*(1+$T5)),"") -> 2.783
A6: 2 | B6: Cerveza de barril (30 L) | C6: barril | D6: Bebida alcohólica | E6: cl | F6: 78 | G6: 3000 | H6: 50 | I6: 4.1 | J6: 620 | K6: =IFERROR(IF(OR($G6="",$H6="",$H6=0),"",$G6/$H6),"") -> 60 | L6: =IFERROR(IF(OR($F6="",$G6="",$G6=0,$H6=""),"",$F6*$H6/$G6),"") -> 1.3 | M6: =IFERROR(IF(OR($I6="",$L6=""),"",$I6-$L6),"") -> 2.8 | N6: =IFERROR(IF(OR($L6="",$I6="",$I6=0),"",$L6/$I6),"") -> 0.31707317 | O6: =IFERROR(IF(OR($I6="",$J6=""),"",$I6*$J6),"") -> 2542 | P6: =IFERROR(IF(OR($L6="",$J6=""),"",$L6*$J6),"") -> 806 | Q6: =IFERROR(IF(OR($O6="",$P6=""),"",$O6-$P6),"") -> 1736 | R6: =IFERROR(IF($D6="","",INDEX(Parámetros!$B$6:$D$8,MATCH(Parámetros!$A$6,Parámetros!$A$6:$A$8,0),MATCH($D6,Parámetros!$B$5:$D$5,0))),"") -> 0.1 | S6: =IFERROR(IF(OR($I6="",$R6=""),"",$I6*(1+$R6)),"") -> 4.51 | T6: =IFERROR(IF($D6="","",INDEX(Parámetros!$B$6:$D$8,MATCH(Parámetros!$A$7,Parámetros!$A$6:$A$8,0),MATCH($D6,Parámetros!$B$5:$D$5,0))),"") -> 0.21 | U6: =IFERROR(IF(OR($I6="",$T6=""),"",$I6*(1+$T6)),"") -> 4.961
A7: 3 | B7: Cerveza tercio (33 cl) | C7: botella | D7: Bebida alcohólica | E7: cl | F7: 0.62 | G7: 33 | H7: 33 | I7: 2.5 | J7: 540 | K7: =IFERROR(IF(OR($G7="",$H7="",$H7=0),"",$G7/$H7),"") -> 1 | L7: =IFERROR(IF(OR($F7="",$G7="",$G7=0,$H7=""),"",$F7*$H7/$G7),"") -> 0.62 | M7: =IFERROR(IF(OR($I7="",$L7=""),"",$I7-$L7),"") -> 1.88 | N7: =IFERROR(IF(OR($L7="",$I7="",$I7=0),"",$L7/$I7),"") -> 0.248 | O7: =IFERROR(IF(OR($I7="",$J7=""),"",$I7*$J7),"") -> 1350 | P7: =IFERROR(IF(OR($L7="",$J7=""),"",$L7*$J7),"") -> 334.8 | Q7: =IFERROR(IF(OR($O7="",$P7=""),"",$O7-$P7),"") -> 1015.2 | R7: =IFERROR(IF($D7="","",INDEX(Parámetros!$B$6:$D$8,MATCH(Parámetros!$A$6,Parámetros!$A$6:$A$8,0),MATCH($D7,Parámetros!$B$5:$D$5,0))),"") -> 0.1 | S7: =IFERROR(IF(OR($I7="",$R7=""),"",$I7*(1+$R7)),"") -> 2.75 | T7: =IFERROR(IF($D7="","",INDEX(Parámetros!$B$6:$D$8,MATCH(Parámetros!$A$7,Parámetros!$A$6:$A$8,0),MATCH($D7,Parámetros!$B$5:$D$5,0))),"") -> 0.21 | U7: =IFERROR(IF(OR($I7="",$T7=""),"",$I7*(1+$T7)),"") -> 3.025
A8: 4 | B8: Cerveza sin alcohol (33 cl) | C8: botella | D8: Comida | E8: cl | F8: 0.58 | G8: 33 | H8: 33 | I8: 2.4 | J8: 180 | K8: =IFERROR(IF(OR($G8="",$H8="",$H8=0),"",$G8/$H8),"") -> 1 | L8: =IFERROR(IF(OR($F8="",$G8="",$G8=0,$H8=""),"",$F8*$H8/$G8),"") -> 0.58 | M8: =IFERROR(IF(OR($I8="",$L8=""),"",$I8-$L8),"") -> 1.82 | N8: =IFERROR(IF(OR($L8="",$I8="",$I8=0),"",$L8/$I8),"") -> 0.24166667 | O8: =IFERROR(IF(OR($I8="",$J8=""),"",$I8*$J8),"") -> 432 | P8: =IFERROR(IF(OR($L8="",$J8=""),"",$L8*$J8),"") -> 104.4 | Q8: =IFERROR(IF(OR($O8="",$P8=""),"",$O8-$P8),"") -> 327.6 | R8: =IFERROR(IF($D8="","",INDEX(Parámetros!$B$6:$D$8,MATCH(Parámetros!$A$6,Parámetros!$A$6:$A$8,0),MATCH($D8,Parámetros!$B$5:$D$5,0))),"") -> 0.1 | S8: =IFERROR(IF(OR($I8="",$R8=""),"",$I8*(1+$R8)),"") -> 2.64 | T8: =IFERROR(IF($D8="","",INDEX(Parámetros!$B$6:$D$8,MATCH(Parámetros!$A$7,Parámetros!$A$6:$A$8,0),MATCH($D8,Parámetros!$B$5:$D$5,0))),"") -> 0.1 | U8: =IFERROR(IF(OR($I8="",$T8=""),"",$I8*(1+$T8)),"") -> 2.64
A9: 5 | B9: Refresco de cola (lata 33 cl) | C9: lata | D9: Refresco/azucarada | E9: cl | F9: 0.55 | G9: 33 | H9: 33 | I9: 2.3 | J9: 760 | K9: =IFERROR(IF(OR($G9="",$H9="",$H9=0),"",$G9/$H9),"") -> 1 | L9: =IFERROR(IF(OR($F9="",$G9="",$G9=0,$H9=""),"",$F9*$H9/$G9),"") -> 0.55 | M9: =IFERROR(IF(OR($I9="",$L9=""),"",$I9-$L9),"") -> 1.75 | N9: =IFERROR(IF(OR($L9="",$I9="",$I9=0),"",$L9/$I9),"") -> 0.23913043 | O9: =IFERROR(IF(OR($I9="",$J9=""),"",$I9*$J9),"") -> 1748 | P9: =IFERROR(IF(OR($L9="",$J9=""),"",$L9*$J9),"") -> 418 | Q9: =IFERROR(IF(OR($O9="",$P9=""),"",$O9-$P9),"") -> 1330 | R9: =IFERROR(IF($D9="","",INDEX(Parámetros!$B$6:$D$8,MATCH(Parámetros!$A$6,Parámetros!$A$6:$A$8,0),MATCH($D9,Parámetros!$B$5:$D$5,0))),"") -> 0.1 | S9: =IFERROR(IF(OR($I9="",$R9=""),"",$I9*(1+$R9)),"") -> 2.53 | T9: =IFERROR(IF($D9="","",INDEX(Parámetros!$B$6:$D$8,MATCH(Parámetros!$A$7,Parámetros!$A$6:$A$8,0),MATCH($D9,Parámetros!$B$5:$D$5,0))),"") -> 0.21 | U9: =IFERROR(IF(OR($I9="",$T9=""),"",$I9*(1+$T9)),"") -> 2.783
A10: 6 | B10: Agua mineral (50 cl) | C10: botella | D10: Comida | E10: cl | F10: 0.28 | G10: 50 | H10: 50 | I10: 1.8 | J10: 1100 | K10: =IFERROR(IF(OR($G10="",$H10="",$H10=0),"",$G10/$H10),"") -> 1 | L10: =IFERROR(IF(OR($F10="",$G10="",$G10=0,$H10=""),"",$F10*$H10/$G10),"") -> 0.28 | M10: =IFERROR(IF(OR($I10="",$L10=""),"",$I10-$L10),"") -> 1.52 | N10: =IFERROR(IF(OR($L10="",$I10="",$I10=0),"",$L10/$I10),"") -> 0.15555556 | O10: =IFERROR(IF(OR($I10="",$J10=""),"",$I10*$J10),"") -> 1980 | P10: =IFERROR(IF(OR($L10="",$J10=""),"",$L10*$J10),"") -> 308 | Q10: =IFERROR(IF(OR($O10="",$P10=""),"",$O10-$P10),"") -> 1672 | R10: =IFERROR(IF($D10="","",INDEX(Parámetros!$B$6:$D$8,MATCH(Parámetros!$A$6,Parámetros!$A$6:$A$8,0),MATCH($D10,Parámetros!$B$5:$D$5,0))),"") -> 0.1 | S10: =IFERROR(IF(OR($I10="",$R10=""),"",$I10*(1+$R10)),"") -> 1.98 | T10: =IFERROR(IF($D10="","",INDEX(Parámetros!$B$6:$D$8,MATCH(Parámetros!$A$7,Parámetros!$A$6:$A$8,0),MATCH($D10,Parámetros!$B$5:$D$5,0))),"") -> 0.1 | U10: =IFERROR(IF(OR($I10="",$T10=""),"",$I10*(1+$T10)),"") -> 1.98
A11: 7 | B11: Zumo de naranja natural | C11: kg naranjas | D11: Comida | E11: ml | F11: 1.4 | G11: 1000 | H11: 250 | I11: 3.2 | J11: 260 | K11: =IFERROR(IF(OR($G11="",$H11="",$H11=0),"",$G11/$H11),"") -> 4 | L11: =IFERROR(IF(OR($F11="",$G11="",$G11=0,$H11=""),"",$F11*$H11/$G11),"") -> 0.35 | M11: =IFERROR(IF(OR($I11="",$L11=""),"",$I11-$L11),"") -> 2.85 | N11: =IFERROR(IF(OR($L11="",$I11="",$I11=0),"",$L11/$I11),"") -> 0.109375 | O11: =IFERROR(IF(OR($I11="",$J11=""),"",$I11*$J11),"") -> 832 | P11: =IFERROR(IF(OR($L11="",$J11=""),"",$L11*$J11),"") -> 91 | Q11: =IFERROR(IF(OR($O11="",$P11=""),"",$O11-$P11),"") -> 741 | R11: =IFERROR(IF($D11="","",INDEX(Parámetros!$B$6:$D$8,MATCH(Parámetros!$A$6,Parámetros!$A$6:$A$8,0),MATCH($D11,Parámetros!$B$5:$D$5,0))),"") -> 0.1 | S11: =IFERROR(IF(OR($I11="",$R11=""),"",$I11*(1+$R11)),"") -> 3.52 | T11: =IFERROR(IF($D11="","",INDEX(Parámetros!$B$6:$D$8,MATCH(Parámetros!$A$7,Parámetros!$A$6:$A$8,0),MATCH($D11,Parámetros!$B$5:$D$5,0))),"") -> 0.1 | U11: =IFERROR(IF(OR($I11="",$T11=""),"",$I11*(1+$T11)),"") -> 3.52
A12: 8 | K12: =IFERROR(IF(OR($G12="",$H12="",$H12=0),"",$G12/$H12),"") | L12: =IFERROR(IF(OR($F12="",$G12="",$G12=0,$H12=""),"",$F12*$H12/$G12),"") | M12: =IFERROR(IF(OR($I12="",$L12=""),"",$I12-$L12),"") | N12: =IFERROR(IF(OR($L12="",$I12="",$I12=0),"",$L12/$I12),"") | O12: =IFERROR(IF(OR($I12="",$J12=""),"",$I12*$J12),"") | P12: =IFERROR(IF(OR($L12="",$J12=""),"",$L12*$J12),"") | Q12: =IFERROR(IF(OR($O12="",$P12=""),"",$O12-$P12),"") | R12: =IFERROR(IF($D12="","",INDEX(Parámetros!$B$6:$D$8,MATCH(Parámetros!$A$6,Parámetros!$A$6:$A$8,0),MATCH($D12,Parámetros!$B$5:$D$5,0))),"") | S12: =IFERROR(IF(OR($I12="",$R12=""),"",$I12*(1+$R12)),"") | T12: =IFERROR(IF($D12="","",INDEX(Parámetros!$B$6:$D$8,MATCH(Parámetros!$A$7,Parámetros!$A$6:$A$8,0),MATCH($D12,Parámetros!$B$5:$D$5,0))),"") | U12: =IFERROR(IF(OR($I12="",$T12=""),"",$I12*(1+$T12)),"")
A13: 9 | K13: =IFERROR(IF(OR($G13="",$H13="",$H13=0),"",$G13/$H13),"") | L13: =IFERROR(IF(OR($F13="",$G13="",$G13=0,$H13=""),"",$F13*$H13/$G13),"") | M13: =IFERROR(IF(OR($I13="",$L13=""),"",$I13-$L13),"") | N13: =IFERROR(IF(OR($L13="",$I13="",$I13=0),"",$L13/$I13),"") | O13: =IFERROR(IF(OR($I13="",$J13=""),"",$I13*$J13),"") | P13: =IFERROR(IF(OR($L13="",$J13=""),"",$L13*$J13),"") | Q13: =IFERROR(IF(OR($O13="",$P13=""),"",$O13-$P13),"") | R13: =IFERROR(IF($D13="","",INDEX(Parámetros!$B$6:$D$8,MATCH(Parámetros!$A$6,Parámetros!$A$6:$A$8,0),MATCH($D13,Parámetros!$B$5:$D$5,0))),"") | S13: =IFERROR(IF(OR($I13="",$R13=""),"",$I13*(1+$R13)),"") | T13: =IFERROR(IF($D13="","",INDEX(Parámetros!$B$6:$D$8,MATCH(Parámetros!$A$7,Parámetros!$A$6:$A$8,0),MATCH($D13,Parámetros!$B$5:$D$5,0))),"") | U13: =IFERROR(IF(OR($I13="",$T13=""),"",$I13*(1+$T13)),"")
A14: 10 | K14: =IFERROR(IF(OR($G14="",$H14="",$H14=0),"",$G14/$H14),"") | L14: =IFERROR(IF(OR($F14="",$G14="",$G14=0,$H14=""),"",$F14*$H14/$G14),"") | M14: =IFERROR(IF(OR($I14="",$L14=""),"",$I14-$L14),"") | N14: =IFERROR(IF(OR($L14="",$I14="",$I14=0),"",$L14/$I14),"") | O14: =IFERROR(IF(OR($I14="",$J14=""),"",$I14*$J14),"") | P14: =IFERROR(IF(OR($L14="",$J14=""),"",$L14*$J14),"") | Q14: =IFERROR(IF(OR($O14="",$P14=""),"",$O14-$P14),"") | R14: =IFERROR(IF($D14="","",INDEX(Parámetros!$B$6:$D$8,MATCH(Parámetros!$A$6,Parámetros!$A$6:$A$8,0),MATCH($D14,Parámetros!$B$5:$D$5,0))),"") | S14: =IFERROR(IF(OR($I14="",$R14=""),"",$I14*(1+$R14)),"") | T14: =IFERROR(IF($D14="","",INDEX(Parámetros!$B$6:$D$8,MATCH(Parámetros!$A$7,Parámetros!$A$6:$A$8,0),MATCH($D14,Parámetros!$B$5:$D$5,0))),"") | U14: =IFERROR(IF(OR($I14="",$T14=""),"",$I14*(1+$T14)),"")
A15: 11 | K15: =IFERROR(IF(OR($G15="",$H15="",$H15=0),"",$G15/$H15),"") | L15: =IFERROR(IF(OR($F15="",$G15="",$G15=0,$H15=""),"",$F15*$H15/$G15),"") | M15: =IFERROR(IF(OR($I15="",$L15=""),"",$I15-$L15),"") | N15: =IFERROR(IF(OR($L15="",$I15="",$I15=0),"",$L15/$I15),"") | O15: =IFERROR(IF(OR($I15="",$J15=""),"",$I15*$J15),"") | P15: =IFERROR(IF(OR($L15="",$J15=""),"",$L15*$J15),"") | Q15: =IFERROR(IF(OR($O15="",$P15=""),"",$O15-$P15),"") | R15: =IFERROR(IF($D15="","",INDEX(Parámetros!$B$6:$D$8,MATCH(Parámetros!$A$6,Parámetros!$A$6:$A$8,0),MATCH($D15,Parámetros!$B$5:$D$5,0))),"") | S15: =IFERROR(IF(OR($I15="",$R15=""),"",$I15*(1+$R15)),"") | T15: =IFERROR(IF($D15="","",INDEX(Parámetros!$B$6:$D$8,MATCH(Parámetros!$A$7,Parámetros!$A$6:$A$8,0),MATCH($D15,Parámetros!$B$5:$D$5,0))),"") | U15: =IFERROR(IF(OR($I15="",$T15=""),"",$I15*(1+$T15)),"")
A16: 12 | K16: =IFERROR(IF(OR($G16="",$H16="",$H16=0),"",$G16/$H16),"") | L16: =IFERROR(IF(OR($F16="",$G16="",$G16=0,$H16=""),"",$F16*$H16/$G16),"") | M16: =IFERROR(IF(OR($I16="",$L16=""),"",$I16-$L16),"") | N16: =IFERROR(IF(OR($L16="",$I16="",$I16=0),"",$L16/$I16),"") | O16: =IFERROR(IF(OR($I16="",$J16=""),"",$I16*$J16),"") | P16: =IFERROR(IF(OR($L16="",$J16=""),"",$L16*$J16),"") | Q16: =IFERROR(IF(OR($O16="",$P16=""),"",$O16-$P16),"") | R16: =IFERROR(IF($D16="","",INDEX(Parámetros!$B$6:$D$8,MATCH(Parámetros!$A$6,Parámetros!$A$6:$A$8,0),MATCH($D16,Parámetros!$B$5:$D$5,0))),"") | S16: =IFERROR(IF(OR($I16="",$R16=""),"",$I16*(1+$R16)),"") | T16: =IFERROR(IF($D16="","",INDEX(Parámetros!$B$6:$D$8,MATCH(Parámetros!$A$7,Parámetros!$A$6:$A$8,0),MATCH($D16,Parámetros!$B$5:$D$5,0))),"") | U16: =IFERROR(IF(OR($I16="",$T16=""),"",$I16*(1+$T16)),"")
A17: 13 | K17: =IFERROR(IF(OR($G17="",$H17="",$H17=0),"",$G17/$H17),"") | L17: =IFERROR(IF(OR($F17="",$G17="",$G17=0,$H17=""),"",$F17*$H17/$G17),"") | M17: =IFERROR(IF(OR($I17="",$L17=""),"",$I17-$L17),"") | N17: =IFERROR(IF(OR($L17="",$I17="",$I17=0),"",$L17/$I17),"") | O17: =IFERROR(IF(OR($I17="",$J17=""),"",$I17*$J17),"") | P17: =IFERROR(IF(OR($L17="",$J17=""),"",$L17*$J17),"") | Q17: =IFERROR(IF(OR($O17="",$P17=""),"",$O17-$P17),"") | R17: =IFERROR(IF($D17="","",INDEX(Parámetros!$B$6:$D$8,MATCH(Parámetros!$A$6,Parámetros!$A$6:$A$8,0),MATCH($D17,Parámetros!$B$5:$D$5,0))),"") | S17: =IFERROR(IF(OR($I17="",$R17=""),"",$I17*(1+$R17)),"") | T17: =IFERROR(IF($D17="","",INDEX(Parámetros!$B$6:$D$8,MATCH(Parámetros!$A$7,Parámetros!$A$6:$A$8,0),MATCH($D17,Parámetros!$B$5:$D$5,0))),"") | U17: =IFERROR(IF(OR($I17="",$T17=""),"",$I17*(1+$T17)),"")
A18: 14 | K18: =IFERROR(IF(OR($G18="",$H18="",$H18=0),"",$G18/$H18),"") | L18: =IFERROR(IF(OR($F18="",$G18="",$G18=0,$H18=""),"",$F18*$H18/$G18),"") | M18: =IFERROR(IF(OR($I18="",$L18=""),"",$I18-$L18),"") | N18: =IFERROR(IF(OR($L18="",$I18="",$I18=0),"",$L18/$I18),"") | O18: =IFERROR(IF(OR($I18="",$J18=""),"",$I18*$J18),"") | P18: =IFERROR(IF(OR($L18="",$J18=""),"",$L18*$J18),"") | Q18: =IFERROR(IF(OR($O18="",$P18=""),"",$O18-$P18),"") | R18: =IFERROR(IF($D18="","",INDEX(Parámetros!$B$6:$D$8,MATCH(Parámetros!$A$6,Parámetros!$A$6:$A$8,0),MATCH($D18,Parámetros!$B$5:$D$5,0))),"") | S18: =IFERROR(IF(OR($I18="",$R18=""),"",$I18*(1+$R18)),"") | T18: =IFERROR(IF($D18="","",INDEX(Parámetros!$B$6:$D$8,MATCH(Parámetros!$A$7,Parámetros!$A$6:$A$8,0),MATCH($D18,Parámetros!$B$5:$D$5,0))),"") | U18: =IFERROR(IF(OR($I18="",$T18=""),"",$I18*(1+$T18)),"")
A19: 15 | K19: =IFERROR(IF(OR($G19="",$H19="",$H19=0),"",$G19/$H19),"") | L19: =IFERROR(IF(OR($F19="",$G19="",$G19=0,$H19=""),"",$F19*$H19/$G19),"") | M19: =IFERROR(IF(OR($I19="",$L19=""),"",$I19-$L19),"") | N19: =IFERROR(IF(OR($L19="",$I19="",$I19=0),"",$L19/$I19),"") | O19: =IFERROR(IF(OR($I19="",$J19=""),"",$I19*$J19),"") | P19: =IFERROR(IF(OR($L19="",$J19=""),"",$L19*$J19),"") | Q19: =IFERROR(IF(OR($O19="",$P19=""),"",$O19-$P19),"") | R19: =IFERROR(IF($D19="","",INDEX(Parámetros!$B$6:$D$8,MATCH(Parámetros!$A$6,Parámetros!$A$6:$A$8,0),MATCH($D19,Parámetros!$B$5:$D$5,0))),"") | S19: =IFERROR(IF(OR($I19="",$R19=""),"",$I19*(1+$R19)),"") | T19: =IFERROR(IF($D19="","",INDEX(Parámetros!$B$6:$D$8,MATCH(Parámetros!$A$7,Parámetros!$A$6:$A$8,0),MATCH($D19,Parámetros!$B$5:$D$5,0))),"") | U19: =IFERROR(IF(OR($I19="",$T19=""),"",$I19*(1+$T19)),"")
B20: TOTAL CERVEZAS Y REFRESCOS | J20: =IF(COUNT(J5:J19)=0,"",SUM(J5:J19)) -> 6360 | N20: =IFERROR(IF(OR($O$20="",$O$20=0,$P$20=""),"",$P$20/$O$20),"") -> 0.25377395 | O20: =IF(COUNT(O5:O19)=0,"",SUM(O5:O19)) -> 15554 | P20: =IF(COUNT(P5:P19)=0,"",SUM(P5:P19)) -> 3947.2 | Q20: =IF(COUNT(Q5:Q19)=0,"",SUM(Q5:Q19)) -> 11606.8
B22: Objetivo de beverage cost de cervezas y refrescos (%) | E22: =IF(Parámetros!$B$18="","",Parámetros!$B$18) -> 0.22
B24: Las dos primeras filas son el MISMO barril servido en caña de 25 cl y en jarra de 50 cl: el coste por servicio se dobla, el precio no siempre. Míralo antes de poner la jarra en la carta.
B25: El zumo natural se mide en mililitros porque su unidad de compra son kilos de naranja: 1 kg da unos 1.000 ml de zumo y el servicio es de 250 ml. Ajusta el rendimiento con tu exprimidor.

Sheet Destilados y Cócteles
A1: Destilados y cócteles
A2: AI Chef Pro · aichef.pro — Guía Food Cost + Ingeniería de Menú
A3: COMBINADOS: DESTILADO + MEZCLA
A4: # | B4: Destilado | C4: Tipo a efectos de IVA | D4: Precio de compra de la botella, sin IVA (€) | E4: Formato de la botella (cl) | F4: Servicio de copa (cl) | G4: Coste de la mezcla por copa (€) | H4: PVP del combinado en sala, sin IVA (€) | I4: Copas vendidas al mes (n.º) | J4: Copas por botella (n.º) | K4: Coste del destilado por copa (€) | L4: Coste total por copa (€) | M4: Margen por copa (€) | N4: Beverage cost (%) | O4: Ventas del mes, sin IVA (€) | P4: Coste del mes (€) | Q4: Margen de contribución del mes (€) | R4: IVA repercutido en sala (%) | S4: PVP del combinado con IVA en sala (€)
A5: 1 | B5: Ginebra premium | C5: Bebida alcohólica | D5: 16.9 | E5: 70 | F5: 5 | G5: 0.6 | H5: 8.2 | I5: 310 | J5: =IFERROR(IF(OR($E5="",$F5="",$F5=0),"",$E5/$F5),"") -> 14 | K5: =IFERROR(IF(OR($D5="",$E5="",$E5=0,$F5=""),"",$D5*$F5/$E5),"") -> 1.2071429 | L5: =IFERROR(IF($K5="","",$K5+IF($G5="",0,$G5)),"") -> 1.8071429 | M5: =IFERROR(IF(OR($H5="",$L5=""),"",$H5-$L5),"") -> 6.3928571 | N5: =IFERROR(IF(OR($L5="",$H5="",$H5=0),"",$L5/$H5),"") -> 0.22038328 | O5: =IFERROR(IF(OR($H5="",$I5=""),"",$H5*$I5),"") -> 2542 | P5: =IFERROR(IF(OR($L5="",$I5=""),"",$L5*$I5),"") -> 560.21429 | Q5: =IFERROR(IF(OR($O5="",$P5=""),"",$O5-$P5),"") -> 1981.7857 | R5: =IFERROR(IF($C5="","",INDEX(Parámetros!$B$6:$D$8,MATCH(Parámetros!$A$6,Parámetros!$A$6:$A$8,0),MATCH($C5,Parámetros!$B$5:$D$5,0))),"") -> 0.1 | S5: =IFERROR(IF(OR($H5="",$R5=""),"",$H5*(1+$R5)),"") -> 9.02
A6: 2 | B6: Ron añejo | C6: Bebida alcohólica | D6: 14.2 | E6: 70 | F6: 5 | G6: 0.55 | H6: 7.5 | I6: 140 | J6: =IFERROR(IF(OR($E6="",$F6="",$F6=0),"",$E6/$F6),"") -> 14 | K6: =IFERROR(IF(OR($D6="",$E6="",$E6=0,$F6=""),"",$D6*$F6/$E6),"") -> 1.0142857 | L6: =IFERROR(IF($K6="","",$K6+IF($G6="",0,$G6)),"") -> 1.5642857 | M6: =IFERROR(IF(OR($H6="",$L6=""),"",$H6-$L6),"") -> 5.9357143 | N6: =IFERROR(IF(OR($L6="",$H6="",$H6=0),"",$L6/$H6),"") -> 0.20857143 | O6: =IFERROR(IF(OR($H6="",$I6=""),"",$H6*$I6),"") -> 1050 | P6: =IFERROR(IF(OR($L6="",$I6=""),"",$L6*$I6),"") -> 219 | Q6: =IFERROR(IF(OR($O6="",$P6=""),"",$O6-$P6),"") -> 831 | R6: =IFERROR(IF($C6="","",INDEX(Parámetros!$B$6:$D$8,MATCH(Parámetros!$A$6,Parámetros!$A$6:$A$8,0),MATCH($C6,Parámetros!$B$5:$D$5,0))),"") -> 0.1 | S6: =IFERROR(IF(OR($H6="",$R6=""),"",$H6*(1+$R6)),"") -> 8.25
A7: 3 | B7: Whisky escocés 12 años | C7: Bebida alcohólica | D7: 22.4 | E7: 70 | F7: 5 | G7: 0.55 | H7: 8.6 | I7: 95 | J7: =IFERROR(IF(OR($E7="",$F7="",$F7=0),"",$E7/$F7),"") -> 14 | K7: =IFERROR(IF(OR($D7="",$E7="",$E7=0,$F7=""),"",$D7*$F7/$E7),"") -> 1.6 | L7: =IFERROR(IF($K7="","",$K7+IF($G7="",0,$G7)),"") -> 2.15 | M7: =IFERROR(IF(OR($H7="",$L7=""),"",$H7-$L7),"") -> 6.45 | N7: =IFERROR(IF(OR($L7="",$H7="",$H7=0),"",$L7/$H7),"") -> 0.25 | O7: =IFERROR(IF(OR($H7="",$I7=""),"",$H7*$I7),"") -> 817 | P7: =IFERROR(IF(OR($L7="",$I7=""),"",$L7*$I7),"") -> 204.25 | Q7: =IFERROR(IF(OR($O7="",$P7=""),"",$O7-$P7),"") -> 612.75 | R7: =IFERROR(IF($C7="","",INDEX(Parámetros!$B$6:$D$8,MATCH(Parámetros!$A$6,Parámetros!$A$6:$A$8,0),MATCH($C7,Parámetros!$B$5:$D$5,0))),"") -> 0.1 | S7: =IFERROR(IF(OR($H7="",$R7=""),"",$H7*(1+$R7)),"") -> 9.46
A8: 4 | B8: Vodka | C8: Bebida alcohólica | D8: 11.8 | E8: 70 | F8: 5 | G8: 0.55 | H8: 7.2 | I8: 80 | J8: =IFERROR(IF(OR($E8="",$F8="",$F8=0),"",$E8/$F8),"") -> 14 | K8: =IFERROR(IF(OR($D8="",$E8="",$E8=0,$F8=""),"",$D8*$F8/$E8),"") -> 0.84285714 | L8: =IFERROR(IF($K8="","",$K8+IF($G8="",0,$G8)),"") -> 1.3928571 | M8: =IFERROR(IF(OR($H8="",$L8=""),"",$H8-$L8),"") -> 5.8071429 | N8: =IFERROR(IF(OR($L8="",$H8="",$H8=0),"",$L8/$H8),"") -> 0.19345238 | O8: =IFERROR(IF(OR($H8="",$I8=""),"",$H8*$I8),"") -> 576 | P8: =IFERROR(IF(OR($L8="",$I8=""),"",$L8*$I8),"") -> 111.42857 | Q8: =IFERROR(IF(OR($O8="",$P8=""),"",$O8-$P8),"") -> 464.57143 | R8: =IFERROR(IF($C8="","",INDEX(Parámetros!$B$6:$D$8,MATCH(Parámetros!$A$6,Parámetros!$A$6:$A$8,0),MATCH($C8,Parámetros!$B$5:$D$5,0))),"") -> 0.1 | S8: =IFERROR(IF(OR($H8="",$R8=""),"",$H8*(1+$R8)),"") -> 7.92
A9: 5 | B9: Vermut de grifo (1 L) | C9: Bebida alcohólica | D9: 7.9 | E9: 100 | F9: 8 | G9: 0.1 | H9: 3.6 | I9: 420 | J9: =IFERROR(IF(OR($E9="",$F9="",$F9=0),"",$E9/$F9),"") -> 12.5 | K9: =IFERROR(IF(OR($D9="",$E9="",$E9=0,$F9=""),"",$D9*$F9/$E9),"") -> 0.632 | L9: =IFERROR(IF($K9="","",$K9+IF($G9="",0,$G9)),"") -> 0.732 | M9: =IFERROR(IF(OR($H9="",$L9=""),"",$H9-$L9),"") -> 2.868 | N9: =IFERROR(IF(OR($L9="",$H9="",$H9=0),"",$L9/$H9),"") -> 0.20333333 | O9: =IFERROR(IF(OR($H9="",$I9=""),"",$H9*$I9),"") -> 1512 | P9: =IFERROR(IF(OR($L9="",$I9=""),"",$L9*$I9),"") -> 307.44 | Q9: =IFERROR(IF(OR($O9="",$P9=""),"",$O9-$P9),"") -> 1204.56 | R9: =IFERROR(IF($C9="","",INDEX(Parámetros!$B$6:$D$8,MATCH(Parámetros!$A$6,Parámetros!$A$6:$A$8,0),MATCH($C9,Parámetros!$B$5:$D$5,0))),"") -> 0.1 | S9: =IFERROR(IF(OR($H9="",$R9=""),"",$H9*(1+$R9)),"") -> 3.96
A10: 6 | J10: =IFERROR(IF(OR($E10="",$F10="",$F10=0),"",$E10/$F10),"") | K10: =IFERROR(IF(OR($D10="",$E10="",$E10=0,$F10=""),"",$D10*$F10/$E10),"") | L10: =IFERROR(IF($K10="","",$K10+IF($G10="",0,$G10)),"") | M10: =IFERROR(IF(OR($H10="",$L10=""),"",$H10-$L10),"") | N10: =IFERROR(IF(OR($L10="",$H10="",$H10=0),"",$L10/$H10),"") | O10: =IFERROR(IF(OR($H10="",$I10=""),"",$H10*$I10),"") | P10: =IFERROR(IF(OR($L10="",$I10=""),"",$L10*$I10),"") | Q10: =IFERROR(IF(OR($O10="",$P10=""),"",$O10-$P10),"") | R10: =IFERROR(IF($C10="","",INDEX(Parámetros!$B$6:$D$8,MATCH(Parámetros!$A$6,Parámetros!$A$6:$A$8,0),MATCH($C10,Parámetros!$B$5:$D$5,0))),"") | S10: =IFERROR(IF(OR($H10="",$R10=""),"",$H10*(1+$R10)),"")
A11: 7 | J11: =IFERROR(IF(OR($E11="",$F11="",$F11=0),"",$E11/$F11),"") | K11: =IFERROR(IF(OR($D11="",$E11="",$E11=0,$F11=""),"",$D11*$F11/$E11),"") | L11: =IFERROR(IF($K11="","",$K11+IF($G11="",0,$G11)),"") | M11: =IFERROR(IF(OR($H11="",$L11=""),"",$H11-$L11),"") | N11: =IFERROR(IF(OR($L11="",$H11="",$H11=0),"",$L11/$H11),"") | O11: =IFERROR(IF(OR($H11="",$I11=""),"",$H11*$I11),"") | P11: =IFERROR(IF(OR($L11="",$I11=""),"",$L11*$I11),"") | Q11: =IFERROR(IF(OR($O11="",$P11=""),"",$O11-$P11),"") | R11: =IFERROR(IF($C11="","",INDEX(Parámetros!$B$6:$D$8,MATCH(Parámetros!$A$6,Parámetros!$A$6:$A$8,0),MATCH($C11,Parámetros!$B$5:$D$5,0))),"") | S11: =IFERROR(IF(OR($H11="",$R11=""),"",$H11*(1+$R11)),"")
A12: 8 | J12: =IFERROR(IF(OR($E12="",$F12="",$F12=0),"",$E12/$F12),"") | K12: =IFERROR(IF(OR($D12="",$E12="",$E12=0,$F12=""),"",$D12*$F12/$E12),"") | L12: =IFERROR(IF($K12="","",$K12+IF($G12="",0,$G12)),"") | M12: =IFERROR(IF(OR($H12="",$L12=""),"",$H12-$L12),"") | N12: =IFERROR(IF(OR($L12="",$H12="",$H12=0),"",$L12/$H12),"") | O12: =IFERROR(IF(OR($H12="",$I12=""),"",$H12*$I12),"") | P12: =IFERROR(IF(OR($L12="",$I12=""),"",$L12*$I12),"") | Q12: =IFERROR(IF(OR($O12="",$P12=""),"",$O12-$P12),"") | R12: =IFERROR(IF($C12="","",INDEX(Parámetros!$B$6:$D$8,MATCH(Parámetros!$A$6,Parámetros!$A$6:$A$8,0),MATCH($C12,Parámetros!$B$5:$D$5,0))),"") | S12: =IFERROR(IF(OR($H12="",$R12=""),"",$H12*(1+$R12)),"")
A13: 9 | J13: =IFERROR(IF(OR($E13="",$F13="",$F13=0),"",$E13/$F13),"") | K13: =IFERROR(IF(OR($D13="",$E13="",$E13=0,$F13=""),"",$D13*$F13/$E13),"") | L13: =IFERROR(IF($K13="","",$K13+IF($G13="",0,$G13)),"") | M13: =IFERROR(IF(OR($H13="",$L13=""),"",$H13-$L13),"") | N13: =IFERROR(IF(OR($L13="",$H13="",$H13=0),"",$L13/$H13),"") | O13: =IFERROR(IF(OR($H13="",$I13=""),"",$H13*$I13),"") | P13: =IFERROR(IF(OR($L13="",$I13=""),"",$L13*$I13),"") | Q13: =IFERROR(IF(OR($O13="",$P13=""),"",$O13-$P13),"") | R13: =IFERROR(IF($C13="","",INDEX(Parámetros!$B$6:$D$8,MATCH(Parámetros!$A$6,Parámetros!$A$6:$A$8,0),MATCH($C13,Parámetros!$B$5:$D$5,0))),"") | S13: =IFERROR(IF(OR($H13="",$R13=""),"",$H13*(1+$R13)),"")
A14: 10 | J14: =IFERROR(IF(OR($E14="",$F14="",$F14=0),"",$E14/$F14),"") | K14: =IFERROR(IF(OR($D14="",$E14="",$E14=0,$F14=""),"",$D14*$F14/$E14),"") | L14: =IFERROR(IF($K14="","",$K14+IF($G14="",0,$G14)),"") | M14: =IFERROR(IF(OR($H14="",$L14=""),"",$H14-$L14),"") | N14: =IFERROR(IF(OR($L14="",$H14="",$H14=0),"",$L14/$H14),"") | O14: =IFERROR(IF(OR($H14="",$I14=""),"",$H14*$I14),"") | P14: =IFERROR(IF(OR($L14="",$I14=""),"",$L14*$I14),"") | Q14: =IFERROR(IF(OR($O14="",$P14=""),"",$O14-$P14),"") | R14: =IFERROR(IF($C14="","",INDEX(Parámetros!$B$6:$D$8,MATCH(Parámetros!$A$6,Parámetros!$A$6:$A$8,0),MATCH($C14,Parámetros!$B$5:$D$5,0))),"") | S14: =IFERROR(IF(OR($H14="",$R14=""),"",$H14*(1+$R14)),"")
A15: 11 | J15: =IFERROR(IF(OR($E15="",$F15="",$F15=0),"",$E15/$F15),"") | K15: =IFERROR(IF(OR($D15="",$E15="",$E15=0,$F15=""),"",$D15*$F15/$E15),"") | L15: =IFERROR(IF($K15="","",$K15+IF($G15="",0,$G15)),"") | M15: =IFERROR(IF(OR($H15="",$L15=""),"",$H15-$L15),"") | N15: =IFERROR(IF(OR($L15="",$H15="",$H15=0),"",$L15/$H15),"") | O15: =IFERROR(IF(OR($H15="",$I15=""),"",$H15*$I15),"") | P15: =IFERROR(IF(OR($L15="",$I15=""),"",$L15*$I15),"") | Q15: =IFERROR(IF(OR($O15="",$P15=""),"",$O15-$P15),"") | R15: =IFERROR(IF($C15="","",INDEX(Parámetros!$B$6:$D$8,MATCH(Parámetros!$A$6,Parámetros!$A$6:$A$8,0),MATCH($C15,Parámetros!$B$5:$D$5,0))),"") | S15: =IFERROR(IF(OR($H15="",$R15=""),"",$H15*(1+$R15)),"")
A16: 12 | J16: =IFERROR(IF(OR($E16="",$F16="",$F16=0),"",$E16/$F16),"") | K16: =IFERROR(IF(OR($D16="",$E16="",$E16=0,$F16=""),"",$D16*$F16/$E16),"") | L16: =IFERROR(IF($K16="","",$K16+IF($G16="",0,$G16)),"") | M16: =IFERROR(IF(OR($H16="",$L16=""),"",$H16-$L16),"") | N16: =IFERROR(IF(OR($L16="",$H16="",$H16=0),"",$L16/$H16),"") | O16: =IFERROR(IF(OR($H16="",$I16=""),"",$H16*$I16),"") | P16: =IFERROR(IF(OR($L16="",$I16=""),"",$L16*$I16),"") | Q16: =IFERROR(IF(OR($O16="",$P16=""),"",$O16-$P16),"") | R16: =IFERROR(IF($C16="","",INDEX(Parámetros!$B$6:$D$8,MATCH(Parámetros!$A$6,Parámetros!$A$6:$A$8,0),MATCH($C16,Parámetros!$B$5:$D$5,0))),"") | S16: =IFERROR(IF(OR($H16="",$R16=""),"",$H16*(1+$R16)),"")
B17: TOTAL COMBINADOS | I17: =IF(COUNT(I5:I16)=0,"",SUM(I5:I16)) -> 1045 | N17: =IFERROR(IF(OR($O$17="",$O$17=0,$P$17=""),"",$P$17/$O$17),"") -> 0.21584314 | O17: =IF(COUNT(O5:O16)=0,"",SUM(O5:O16)) -> 6497 | P17: =IF(COUNT(P5:P16)=0,"",SUM(P5:P16)) -> 1402.3329 | Q17: =IF(COUNT(Q5:Q16)=0,"",SUM(Q5:Q16)) -> 5094.6671
A19: CÓCTELES: COSTE INGREDIENTE A INGREDIENTE
A20: # | B20: Cóctel | C20: Ingrediente | D20: Cantidad (cl) | E20: Precio del ingrediente (€/L) | F20: Coste de la línea (€)
A21: 1 | B21: Gin tonic de la casa | C21: Ginebra premium | D21: 5 | E21: 24.14 | F21: =IFERROR(IF(OR($D21="",$E21=""),"",$D21*$E21/100),"") -> 1.207
A22: 2 | B22: Gin tonic de la casa | C22: Tónica premium | D22: 20 | E22: 3 | F22: =IFERROR(IF(OR($D22="",$E22=""),"",$D22*$E22/100),"") -> 0.6
A23: 3 | B23: Gin tonic de la casa | C23: Lima y botánicos | D23: 1 | E23: 12 | F23: =IFERROR(IF(OR($D23="",$E23=""),"",$D23*$E23/100),"") -> 0.12
A24: 4 | B24: Gin tonic de la casa | F24: =IFERROR(IF(OR($D24="",$E24=""),"",$D24*$E24/100),"")
A25: 1 | B25: Mojito | C25: Ron blanco | D25: 5 | E25: 17 | F25: =IFERROR(IF(OR($D25="",$E25=""),"",$D25*$E25/100),"") -> 0.85
A26: 2 | B26: Mojito | C26: Lima | D26: 3 | E26: 4 | F26: =IFERROR(IF(OR($D26="",$E26=""),"",$D26*$E26/100),"") -> 0.12
A27: 3 | B27: Mojito | C27: Azúcar y hierbabuena | D27: 2 | E27: 6 | F27: =IFERROR(IF(OR($D27="",$E27=""),"",$D27*$E27/100),"") -> 0.12
A28: 4 | B28: Mojito | C28: Soda | D28: 10 | E28: 1.2 | F28: =IFERROR(IF(OR($D28="",$E28=""),"",$D28*$E28/100),"") -> 0.12
A29: 1 | B29: Aperol spritz | C29: Aperol | D29: 6 | E29: 18.5 | F29: =IFERROR(IF(OR($D29="",$E29=""),"",$D29*$E29/100),"") -> 1.11
A30: 2 | B30: Aperol spritz | C30: Cava brut | D30: 9 | E30: 7.47 | F30: =IFERROR(IF(OR($D30="",$E30=""),"",$D30*$E30/100),"") -> 0.6723
A31: 3 | B31: Aperol spritz | C31: Soda | D31: 3 | E31: 1.2 | F31: =IFERROR(IF(OR($D31="",$E31=""),"",$D31*$E31/100),"") -> 0.036
A32: 4 | B32: Aperol spritz | F32: =IFERROR(IF(OR($D32="",$E32=""),"",$D32*$E32/100),"")
A33: 1 | B33: Negroni | C33: Ginebra | D33: 3 | E33: 24.14 | F33: =IFERROR(IF(OR($D33="",$E33=""),"",$D33*$E33/100),"") -> 0.7242
A34: 2 | B34: Negroni | C34: Vermut rojo | D34: 3 | E34: 7.9 | F34: =IFERROR(IF(OR($D34="",$E34=""),"",$D34*$E34/100),"") -> 0.237
A35: 3 | B35: Negroni | C35: Bitter | D35: 3 | E35: 18 | F35: =IFERROR(IF(OR($D35="",$E35=""),"",$D35*$E35/100),"") -> 0.54
A36: 4 | B36: Negroni | F36: =IFERROR(IF(OR($D36="",$E36=""),"",$D36*$E36/100),"")
A37: 1 | F37: =IFERROR(IF(OR($D37="",$E37=""),"",$D37*$E37/100),"")
A38: 2 | F38: =IFERROR(IF(OR($D38="",$E38=""),"",$D38*$E38/100),"")
A39: 3 | F39: =IFERROR(IF(OR($D39="",$E39=""),"",$D39*$E39/100),"")
A40: 4 | F40: =IFERROR(IF(OR($D40="",$E40=""),"",$D40*$E40/100),"")
A41: 1 | F41: =IFERROR(IF(OR($D41="",$E41=""),"",$D41*$E41/100),"")
...

Sheet Resumen Bodega
A1: Resumen de la bodega
A2: AI Chef Pro · aichef.pro — Guía Food Cost + Ingeniería de Menú
