Workbook

Sheet Instrucciones
A1: Matriz Multi-Método de la Carta
A2: AI Chef Pro · aichef.pro — Guía Food Cost + Ingeniería de Menú
A4: Instrucciones de uso
A5: 1. Vuelca tu carta en la hoja «Datos»: plato, familia, unidades vendidas del último mes, coste por ración y precio de venta SIN IVA.
A6: 2. El coste por ración sale de tu ficha de escandallo (libro «ficha-escandallo-base» de este mismo pack). El PVP con IVA de sala lo calcula el libro.
A7: 3. Las hojas Kasavana-Smith, Miller, Pavesic y Goal Value leen esos datos y clasifican cada plato con su método. En ellas no se teclea nada.
A8: 4. Cada método se aplica DENTRO de su familia: un postre se compara con los postres, no con los chuletones.
A9: 5. Abre «Comparativa»: ahí tienes las cuatro lecturas del mismo plato, cuántas se salen de la mejor categoría y un diagnóstico de qué hacer.
A10: 6. Lleva las decisiones al libro «plan-accion-90-dias» con responsable y fecha. Un análisis sin fecha no cambia nada.
A11: 7. La hoja «Menú Precio Fijo» va aparte: en un menú cerrado el margen no lo decide el precio, lo decide el mix de elecciones de tus comensales.
A12: 8. Ajusta el factor del umbral de popularidad y los porcentajes de personal y de otros costes variables si tu casa no se parece al ejemplo.
A14: Celdas verdes = campos editables
... A30: Versión 1.0 · septiembre 2026 · aichef.pro/guia-food-cost-ingenieria-menu · info@aichef.pro

Sheet Datos
A1: Datos de la carta
A2: AI Chef Pro · aichef.pro — Guía Food Cost + Ingeniería de Menú
E3: El coste por ración sale de tu ficha de escandallo; el PVP va SIN IVA.
A4: # | B4: Plato | C4: Familia | D4: Uds vendidas (mes) | E4: Coste por ración (€) | F4: PVP sin IVA (€) | G4: Margen de contribución (€) | H4: Food cost (%) | I4: PVP con IVA en sala (€) | J4: Uds de su familia | K4: Platos de su familia con ventas | L4: Mix dentro de su familia (%) | M4: Umbral de popularidad de su familia (%) | N4: MC medio ponderado de su familia (€) | O4: Food cost medio ponderado de su familia (%) | P4: MC ponderado del plato: MC × uds (€) | Q4: Media del MC ponderado de su familia (€)
A5: 1 | B5: Croquetas de jamón ibérico (6 ud) | C5: Entrantes | D5: 420 | E5: 2.1 | F5: 8.6 | G5: =IFERROR(IF(OR($E5="",$F5=""),"",$F5-$E5),"") -> 6.5 | H5: =IFERROR(IF(OR($E5="",$F5="",$F5=0),"",$E5/$F5),"") -> 0.24418605 | I5: =IFERROR(IF(OR($F5="",$D$34=""),"",$F5*(1+$D$34)),"") -> 9.46 | J5: =IFERROR(IF($C5="","",SUMPRODUCT(--($C$5:$C$29=$C5),$D$5:$D$29)),"") -> 1730 | K5: =IFERROR(IF($C5="","",SUMPRODUCT(--($C$5:$C$29=$C5),--($D$5:$D$29>0))),"") -> 7 | L5: =IFERROR(IF(OR($D5="",$J5="",$J5=0),"",$D5/$J5),"") -> 0.24277457 | M5: =IFERROR(IF(OR($K5="",$K5=0,$D$33=""),"",$D$33/$K5),"") -> 0.1 | N5: =IFERROR(IF(OR($J5="",$J5=0),"",SUMPRODUCT(--($C$5:$C$29=$C5),$D$5:$D$29,$G$5:$G$29)/$J5),"") -> 7.4635838 | O5: =IFERROR(IF(SUMPRODUCT(--($C$5:$C$29=$C5),$D$5:$D$29,$F$5:$F$29)=0,"",SUMPRODUCT(--($C$5:$C$29=$C5),$D$5:$D$29,$E$5:$E$29)/SUMPRODUCT(--($C$5:$C$29=$C5),$D$5:$D$29,$F$5:$F$29)),"") -> 0.30714746 | P5: =IFERROR(IF(OR($G5="",$D5=""),"",$G5*$D5),"") -> 2730 | Q5: =IFERROR(IF(OR($K5="",$K5=0),"",SUMPRODUCT(--($C$5:$C$29=$C5),$D$5:$D$29,$G$5:$G$29)/$K5),"") -> 1844.5714
A6: 2 | B6: Ensalada de tomate rosa, ventresca y cebolleta | C6: Entrantes | D6: 310 | E6: 3.6 | F6: 11.8 | G6: =IFERROR(IF(OR($E6="",$F6=""),"",$F6-$E6),"") -> 8.2 | H6: =IFERROR(IF(OR($E6="",$F6="",$F6=0),"",$E6/$F6),"") -> 0.30508475 | I6: =IFERROR(IF(OR($F6="",$D$34=""),"",$F6*(1+$D$34)),"") -> 12.98 | J6: =IFERROR(IF($C6="","",SUMPRODUCT(--($C$5:$C$29=$C6),$D$5:$D$29)),"") -> 1730 | K6: =IFERROR(IF($C6="","",SUMPRODUCT(--($C$5:$C$29=$C6),--($D$5:$D$29>0))),"") -> 7 | L6: =IFERROR(IF(OR($D6="",$J6="",$J6=0),"",$D6/$J6),"") -> 0.17919075 | M6: =IFERROR(IF(OR($K6="",$K6=0,$D$33=""),"",$D$33/$K6),"") -> 0.1 | N6: =IFERROR(IF(OR($J6="",$J6=0),"",SUMPRODUCT(--($C$5:$C$29=$C6),$D$5:$D$29,$G$5:$G$29)/$J6),"") -> 7.4635838 | O6: =IFERROR(IF(SUMPRODUCT(--($C$5:$C$29=$C6),$D$5:$D$29,$F$5:$F$29)=0,"",SUMPRODUCT(--($C$5:$C$29=$C6),$D$5:$D$29,$E$5:$E$29)/SUMPRODUCT(--($C$5:$C$29=$C6),$D$5:$D$29,$F$5:$F$29)),"") -> 0.30714746 | P6: =IFERROR(IF(OR($G6="",$D6=""),"",$G6*$D6),"") -> 2542 | Q6: =IFERROR(IF(OR($K6="",$K6=0),"",SUMPRODUCT(--($C$5:$C$29=$C6),$D$5:$D$29,$G$5:$G$29)/$K6),"") -> 1844.5714
A7: 3 | B7: Gambas al ajillo | C7: Entrantes | D7: 260 | E7: 6.9 | F7: 15.5 | G7: =IFERROR(IF(OR($E7="",$F7=""),"",$F7-$E7),"") -> 8.6 | H7: =IFERROR(IF(OR($E7="",$F7="",$F7=0),"",$E7/$F7),"") -> 0.44516129 | I7: =IFERROR(IF(OR($F7="",$D$34=""),"",$F7*(1+$D$34)),"") -> 17.05 | J7: =IFERROR(IF($C7="","",SUMPRODUCT(--($C$5:$C$29=$C7),$D$5:$D$29)),"") -> 1730 | K7: =IFERROR(IF($C7="","",SUMPRODUCT(--($C$5:$C$29=$C7),--($D$5:$D$29>0))),"") -> 7 | L7: =IFERROR(IF(OR($D7="",$J7="",$J7=0),"",$D7/$J7),"") -> 0.15028902 | M7: =IFERROR(IF(OR($K7="",$K7=0,$D$33=""),"",$D$33/$K7),"") -> 0.1 | N7: =IFERROR(IF(OR($J7="",$J7=0),"",SUMPRODUCT(--($C$5:$C$29=$C7),$D$5:$D$29,$G$5:$G$29)/$J7),"") -> 7.4635838 | O7: =IFERROR(IF(SUMPRODUCT(--($C$5:$C$29=$C7),$D$5:$D$29,$F$5:$F$29)=0,"",SUMPRODUCT(--($C$5:$C$29=$C7),$D$5:$D$29,$E$5:$E$29)/SUMPRODUCT(--($C$5:$C$29=$C7),$D$5:$D$29,$F$5:$F$29)),"") -> 0.30714746 | P7: =IFERROR(IF(OR($G7="",$D7=""),"",$G7*$D7),"") -> 2236 | Q7: =IFERROR(IF(OR($K7="",$K7=0),"",SUMPRODUCT(--($C$5:$C$29=$C7),$D$5:$D$29,$G$5:$G$29)/$K7),"") -> 1844.5714
A8: 4 | B8: Huevos rotos con patatas y chistorra | C8: Entrantes | D8: 380 | E8: 2.4 | F8: 9.8 | G8: =IFERROR(IF(OR($E8="",$F8=""),"",$F8-$E8),"") -> 7.4 | H8: =IFERROR(IF(OR($E8="",$F8="",$F8=0),"",$E8/$F8),"") -> 0.24489796 | I8: =IFERROR(IF(OR($F8="",$D$34=""),"",$F8*(1+$D$34)),"") -> 10.78 | J8: =IFERROR(IF($C8="","",SUMPRODUCT(--($C$5:$C$29=$C8),$D$5:$D$29)),"") -> 1730 | K8: =IFERROR(IF($C8="","",SUMPRODUCT(--($C$5:$C$29=$C8),--($D$5:$D$29>0))),"") -> 7 | L8: =IFERROR(IF(OR($D8="",$J8="",$J8=0),"",$D8/$J8),"") -> 0.21965318 | M8: =IFERROR(IF(OR($K8="",$K8=0,$D$33=""),"",$D$33/$K8),"") -> 0.1 | N8: =IFERROR(IF(OR($J8="",$J8=0),"",SUMPRODUCT(--($C$5:$C$29=$C8),$D$5:$D$29,$G$5:$G$29)/$J8),"") -> 7.4635838 | O8: =IFERROR(IF(SUMPRODUCT(--($C$5:$C$29=$C8),$D$5:$D$29,$F$5:$F$29)=0,"",SUMPRODUCT(--($C$5:$C$29=$C8),$D$5:$D$29,$E$5:$E$29)/SUMPRODUCT(--($C$5:$C$29=$C8),$D$5:$D$29,$F$5:$F$29)),"") -> 0.30714746 | P8: =IFERROR(IF(OR($G8="",$D8=""),"",$G8*$D8),"") -> 2812 | Q8: =IFERROR(IF(OR($K8="",$K8=0),"",SUMPRODUCT(--($C$5:$C$29=$C8),$D$5:$D$29,$G$5:$G$29)/$K8),"") -> 1844.5714
A9: 5 | B9: Tabla de quesos de la zona | C9: Entrantes | D9: 90 | E9: 5.2 | F9: 13.6 | G9: =IFERROR(IF(OR($E9="",$F9=""),"",$F9-$E9),"") -> 8.4 | H9: =IFERROR(IF(OR($E9="",$F9="",$F9=0),"",$E9/$F9),"") -> 0.38235294 | I9: =IFERROR(IF(OR($F9="",$D$34=""),"",$F9*(1+$D$34)),"") -> 14.96 | J9: =IFERROR(IF($C9="","",SUMPRODUCT(--($C$5:$C$29=$C9),$D$5:$D$29)),"") -> 1730 | K9: =IFERROR(IF($C9="","",SUMPRODUCT(--($C$5:$C$29=$C9),--($D$5:$D$29>0))),"") -> 7 | L9: =IFERROR(IF(OR($D9="",$J9="",$J9=0),"",$D9/$J9),"") -> 0.052023121 | M9: =IFERROR(IF(OR($K9="",$K9=0,$D$33=""),"",$D$33/$K9),"") -> 0.1 | N9: =IFERROR(IF(OR($J9="",$J9=0),"",SUMPRODUCT(--($C$5:$C$29=$C9),$D$5:$D$29,$G$5:$G$29)/$J9),"") -> 7.4635838 | O9: =IFERROR(IF(SUMPRODUCT(--($C$5:$C$29=$C9),$D$5:$D$29,$F$5:$F$29)=0,"",SUMPRODUCT(--($C$5:$C$29=$C9),$D$5:$D$29,$E$5:$E$29)/SUMPRODUCT(--($C$5:$C$29=$C9),$D$5:$D$29,$F$5:$F$29)),"") -> 0.30714746 | P9: =IFERROR(IF(OR($G9="",$D9=""),"",$G9*$D9),"") -> 756 | Q9: =IFERROR(IF(OR($K9="",$K9=0),"",SUMPRODUCT(--($C$5:$C$29=$C9),$D$5:$D$29,$G$5:$G$29)/$K9),"") -> 1844.5714
A10: 6 | B10: Alcachofas confitadas con jamón | C10: Entrantes | D10: 120 | E10: 3.1 | F10: 10.9 | G10: =IFERROR(IF(OR($E10="",$F10=""),"",$F10-$E10),"") -> 7.8 | H10: =IFERROR(IF(OR($E10="",$F10="",$F10=0),"",$E10/$F10),"") -> 0.28440367 | I10: =IFERROR(IF(OR($F10="",$D$34=""),"",$F10*(1+$D$34)),"") -> 11.99 | J10: =IFERROR(IF($C10="","",SUMPRODUCT(--($C$5:$C$29=$C10),$D$5:$D$29)),"") -> 1730 | K10: =IFERROR(IF($C10="","",SUMPRODUCT(--($C$5:$C$29=$C10),--($D$5:$D$29>0))),"") -> 7 | L10: =IFERROR(IF(OR($D10="",$J10="",$J10=0),"",$D10/$J10),"") -> 0.069364162 | M10: =IFERROR(IF(OR($K10="",$K10=0,$D$33=""),"",$D$33/$K10),"") -> 0.1 | N10: =IFERROR(IF(OR($J10="",$J10=0),"",SUMPRODUCT(--($C$5:$C$29=$C10),$D$5:$D$29,$G$5:$G$29)/$J10),"") -> 7.4635838 | O10: =IFERROR(IF(SUMPRODUCT(--($C$5:$C$29=$C10),$D$5:$D$29,$F$5:$F$29)=0,"",SUMPRODUCT(--($C$5:$C$29=$C10),$D$5:$D$29,$E$5:$E$29)/SUMPRODUCT(--($C$5:$C$29=$C10),$D$5:$D$29,$F$5:$F$29)),"") -> 0.30714746 | P10: =IFERROR(IF(OR($G10="",$D10=""),"",$G10*$D10),"") -> 936 | Q10: =IFERROR(IF(OR($K10="",$K10=0),"",SUMPRODUCT(--($C$5:$C$29=$C10),$D$5:$D$29,$G$5:$G$29)/$K10),"") -> 1844.5714
A11: 7 | B11: Sopa de tomate asado con albahaca | C11: Entrantes | D11: 150 | E11: 1.2 | F11: 7.2 | G11: =IFERROR(IF(OR($E11="",$F11=""),"",$F11-$E11),"") -> 6 | H11: =IFERROR(IF(OR($E11="",$F11="",$F11=0),"",$E11/$F11),"") -> 0.16666667 | I11: =IFERROR(IF(OR($F11="",$D$34=""),"",$F11*(1+$D$34)),"") -> 7.92 | J11: =IFERROR(IF($C11="","",SUMPRODUCT(--($C$5:$C$29=$C11),$D$5:$D$29)),"") -> 1730 | K11: =IFERROR(IF($C11="","",SUMPRODUCT(--($C$5:$C$29=$C11),--($D$5:$D$29>0))),"") -> 7 | L11: =IFERROR(IF(OR($D11="",$J11="",$J11=0),"",$D11/$J11),"") -> 0.086705202 | M11: =IFERROR(IF(OR($K11="",$K11=0,$D$33=""),"",$D$33/$K11),"") -> 0.1 | N11: =IFERROR(IF(OR($J11="",$J11=0),"",SUMPRODUCT(--($C$5:$C$29=$C11),$D$5:$D$29,$G$5:$G$29)/$J11),"") -> 7.4635838 | O11: =IFERROR(IF(SUMPRODUCT(--($C$5:$C$29=$C11),$D$5:$D$29,$F$5:$F$29)=0,"",SUMPRODUCT(--($C$5:$C$29=$C11),$D$5:$D$29,$E$5:$E$29)/SUMPRODUCT(--($C$5:$C$29=$C11),$D$5:$D$29,$F$5:$F$29)),"") -> 0.30714746 | P11: =IFERROR(IF(OR($G11="",$D11=""),"",$G11*$D11),"") -> 900 | Q11: =IFERROR(IF(OR($K11="",$K11=0),"",SUMPRODUCT(--($C$5:$C$29=$C11),$D$5:$D$29,$G$5:$G$29)/$K11),"") -> 1844.5714
A12: 8 | B12: Solomillo de cerdo ibérico con puré de boniato | C12: Principales | D12: 340 | E12: 5.67 | F12: 17.3 | G12: =IFERROR(IF(OR($E12="",$F12=""),"",$F12-$E12),"") -> 11.63 | H12: =IFERROR(IF(OR($E12="",$F12="",$F12=0),"",$E12/$F12),"") -> 0.32774566 | I12: =IFERROR(IF(OR($F12="",$D$34=""),"",$F12*(1+$D$34)),"") -> 19.03 | J12: =IFERROR(IF($C12="","",SUMPRODUCT(--($C$5:$C$29=$C12),$D$5:$D$29)),"") -> 2020 | K12: =IFERROR(IF($C12="","",SUMPRODUCT(--($C$5:$C$29=$C12),--($D$5:$D$29>0))),"") -> 9 | L12: =IFERROR(IF(OR($D12="",$J12="",$J12=0),"",$D12/$J12),"") -> 0.16831683 | M12: =IFERROR(IF(OR($K12="",$K12=0,$D$33=""),"",$D$33/$K12),"") -> 0.077777778 | N12: =IFERROR(IF(OR($J12="",$J12=0),"",SUMPRODUCT(--($C$5:$C$29=$C12),$D$5:$D$29,$G$5:$G$29)/$J12),"") -> 10.795149 | O12: =IFERROR(IF(SUMPRODUCT(--($C$5:$C$29=$C12),$D$5:$D$29,$F$5:$F$29)=0,"",SUMPRODUCT(--($C$5:$C$29=$C12),$D$5:$D$29,$E$5:$E$29)/SUMPRODUCT(--($C$5:$C$29=$C12),$D$5:$D$29,$F$5:$F$29)),"") -> 0.35587523 | P12: =IFERROR(IF(OR($G12="",$D12=""),"",$G12*$D12),"") -> 3954.2 | Q12: =IFERROR(IF(OR($K12="",$K12=0),"",SUMPRODUCT(--($C$5:$C$29=$C12),$D$5:$D$29,$G$5:$G$29)/$K12),"") -> 2422.9111
A13: 9 | B13: Bacalao confitado al pil-pil | C13: Principales | D13: 190 | E13: 7.4 | F13: 19.1 | G13: =IFERROR(IF(OR($E13="",$F13=""),"",$F13-$E13),"") -> 11.7 | H13: =IFERROR(IF(OR($E13="",$F13="",$F13=0),"",$E13/$F13),"") -> 0.38743455 | I13: =IFERROR(IF(OR($F13="",$D$34=""),"",$F13*(1+$D$34)),"") -> 21.01 | J13: =IFERROR(IF($C13="","",SUMPRODUCT(--($C$5:$C$29=$C13),$D$5:$D$29)),"") -> 2020 | K13: =IFERROR(IF($C13="","",SUMPRODUCT(--($C$5:$C$29=$C13),--($D$5:$D$29>0))),"") -> 9 | L13: =IFERROR(IF(OR($D13="",$J13="",$J13=0),"",$D13/$J13),"") -> 0.094059406 | M13: =IFERROR(IF(OR($K13="",$K13=0,$D$33=""),"",$D$33/$K13),"") -> 0.077777778 | N13: =IFERROR(IF(OR($J13="",$J13=0),"",SUMPRODUCT(--($C$5:$C$29=$C13),$D$5:$D$29,$G$5:$G$29)/$J13),"") -> 10.795149 | O13: =IFERROR(IF(SUMPRODUCT(--($C$5:$C$29=$C13),$D$5:$D$29,$F$5:$F$29)=0,"",SUMPRODUCT(--($C$5:$C$29=$C13),$D$5:$D$29,$E$5:$E$29)/SUMPRODUCT(--($C$5:$C$29=$C13),$D$5:$D$29,$F$5:$F$29)),"") -> 0.35587523 | P13: =IFERROR(IF(OR($G13="",$D13=""),"",$G13*$D13),"") -> 2223 | Q13: =IFERROR(IF(OR($K13="",$K13=0),"",SUMPRODUCT(--($C$5:$C$29=$C13),$D$5:$D$29,$G$5:$G$29)/$K13),"") -> 2422.9111
A14: 10 | B14: Hamburguesa de vaca madurada con patatas | C14: Principales | D14: 460 | E14: 4.3 | F14: 13.6 | G14: =IFERROR(IF(OR($E14="",$F14=""),"",$F14-$E14),"") -> 9.3 | H14: =IFERROR(IF(OR($E14="",$F14="",$F14=0),"",$E14/$F14),"") -> 0.31617647 | I14: =IFERROR(IF(OR($F14="",$D$34=""),"",$F14*(1+$D$34)),"") -> 14.96 | J14: =IFERROR(IF($C14="","",SUMPRODUCT(--($C$5:$C$29=$C14),$D$5:$D$29)),"") -> 2020 | K14: =IFERROR(IF($C14="","",SUMPRODUCT(--($C$5:$C$29=$C14),--($D$5:$D$29>0))),"") -> 9 | L14: =IFERROR(IF(OR($D14="",$J14="",$J14=0),"",$D14/$J14),"") -> 0.22772277 | M14: =IFERROR(IF(OR($K14="",$K14=0,$D$33=""),"",$D$33/$K14),"") -> 0.077777778 | N14: =IFERROR(IF(OR($J14="",$J14=0),"",SUMPRODUCT(--($C$5:$C$29=$C14),$D$5:$D$29,$G$5:$G$29)/$J14),"") -> 10.795149 | O14: =IFERROR(IF(SUMPRODUCT(--($C$5:$C$29=$C14),$D$5:$D$29,$F$5:$F$29)=0,"",SUMPRODUCT(--($C$5:$C$29=$C14),$D$5:$D$29,$E$5:$E$29)/SUMPRODUCT(--($C$5:$C$29=$C14),$D$5:$D$29,$F$5:$F$29)),"") -> 0.35587523 | P14: =IFERROR(IF(OR($G14="",$D14=""),"",$G14*$D14),"") -> 4278 | Q14: =IFERROR(IF(OR($K14="",$K14=0),"",SUMPRODUCT(--($C$5:$C$29=$C14),$D$5:$D$29,$G$5:$G$29)/$K14),"") -> 2422.9111
A15: 11 | B15: Arroz meloso de secreto ibérico y setas | C15: Principales | D15: 270 | E15: 6.2 | F15: 16.4 | G15: =IFERROR(IF(OR($E15="",$F15=""),"",$F15-$E15),"") -> 10.2 | H15: =IFERROR(IF(OR($E15="",$F15="",$F15=0),"",$E15/$F15),"") -> 0.37804878 | I15: =IFERROR(IF(OR($F15="",$D$34=""),"",$F15*(1+$D$34)),"") -> 18.04 | J15: =IFERROR(IF($C15="","",SUMPRODUCT(--($C$5:$C$29=$C15),$D$5:$D$29)),"") -> 2020 | K15: =IFERROR(IF($C15="","",SUMPRODUCT(--($C$5:$C$29=$C15),--($D$5:$D$29>0))),"") -> 9 | L15: =IFERROR(IF(OR($D15="",$J15="",$J15=0),"",$D15/$J15),"") -> 0.13366337 | M15: =IFERROR(IF(OR($K15="",$K15=0,$D$33=""),"",$D$33/$K15),"") -> 0.077777778 | N15: =IFERROR(IF(OR($J15="",$J15=0),"",SUMPRODUCT(--($C$5:$C$29=$C15),$D$5:$D$29,$G$5:$G$29)/$J15),"") -> 10.795149 | O15: =IFERROR(IF(SUMPRODUCT(--($C$5:$C$29=$C15),$D$5:$D$29,$F$5:$F$29)=0,"",SUMPRODUCT(--($C$5:$C$29=$C15),$D$5:$D$29,$E$5:$E$29)/SUMPRODUCT(--($C$5:$C$29=$C15),$D$5:$D$29,$F$5:$F$29)),"") -> 0.35587523 | P15: =IFERROR(IF(OR($G15="",$D15=""),"",$G15*$D15),"") -> 2754 | Q15: =IFERROR(IF(OR($K15="",$K15=0),"",SUMPRODUCT(--($C$5:$C$29=$C15),$D$5:$D$29,$G$5:$G$29)/$K15),"") -> 2422.9111
A16: 12 | B16: Chuletón de vaca madurada (500 g) | C16: Principales | D16: 110 | E16: 14.8 | F16: 32.7 | G16: =IFERROR(IF(OR($E16="",$F16=""),"",$F16-$E16),"") -> 17.9 | H16: =IFERROR(IF(OR($E16="",$F16="",$F16=0),"",$E16/$F16),"") -> 0.45259939 | I16: =IFERROR(IF(OR($F16="",$D$34=""),"",$F16*(1+$D$34)),"") -> 35.97 | J16: =IFERROR(IF($C16="","",SUMPRODUCT(--($C$5:$C$29=$C16),$D$5:$D$29)),"") -> 2020 | K16: =IFERROR(IF($C16="","",SUMPRODUCT(--($C$5:$C$29=$C16),--($D$5:$D$29>0))),"") -> 9 | L16: =IFERROR(IF(OR($D16="",$J16="",$J16=0),"",$D16/$J16),"") -> 0.054455446 | M16: =IFERROR(IF(OR($K16="",$K16=0,$D$33=""),"",$D$33/$K16),"") -> 0.077777778 | N16: =IFERROR(IF(OR($J16="",$J16=0),"",SUMPRODUCT(--($C$5:$C$29=$C16),$D$5:$D$29,$G$5:$G$29)/$J16),"") -> 10.795149 | O16: =IFERROR(IF(SUMPRODUCT(--($C$5:$C$29=$C16),$D$5:$D$29,$F$5:$F$29)=0,"",SUMPRODUCT(--($C$5:$C$29=$C16),$D$5:$D$29,$E$5:$E$29)/SUMPRODUCT(--($C$5:$C$29=$C16),$D$5:$D$29,$F$5:$F$29)),"") -> 0.35587523 | P16: =IFERROR(IF(OR($G16="",$D16=""),"",$G16*$D16),"") -> 1969 | Q16: =IFERROR(IF(OR($K16="",$K16=0),"",SUMPRODUCT(--($C$5:$C$29=$C16),$D$5:$D$29,$G$5:$G$29)/$K16),"") -> 2422.9111
... A24: 20 | B24: Fruta de temporada preparada | C24: Postres | D24: 60 | E24: 1.4 | F24: 4.5 | G24: =IFERROR(IF(OR($E24="",$F24=""),"",$F24-$E24),"") -> 3.1 | H24: =IFERROR(IF(OR($E24="",$F24="",$F24=0),"",$E24/$F24),"") -> 0.31111111 | I24: =IFERROR(IF(OR($F24="",$D$34=""),"",$F24*(1+$D$34)),"") -> 4.95 | J24: =IFERROR(IF($C24="","",SUMPRODUCT(--($C$5:$C$29=$C24),$D$5:$D$29)),"") -> 1120 | K24: =IFERROR(IF($C24="","",SUMPRODUCT(--($C$5:$C$29=$C24),--($D$5:$D$29>0))),"") -> 4 | L24: =IFERROR(IF(OR($D24="",$J24="",$J24=0),"",$D24/$J24),"") -> 0.053571429 | M24: =IFERROR(IF(OR($K24="",$K24=0,$D$33=""),"",$D$33/$K24),"") -> 0.175 | N24: =IFERROR(IF(OR($J24="",$J24=0),"",SUMPRODUCT(--($C$5:$C$29=$C24),$D$5:$D$29,$G$5:$G$29)/$J24),"") -> 4.4821429 | O24: =IFERROR(IF(SUMPRODUCT(--($C$5:$C$29=$C24),$D$5:$D$29,$F$5:$F$29)=0,"",SUMPRODUCT(--($C$5:$C$29=$C24),$D$5:$D$29,$E$5:$E$29)/SUMPRODUCT(--($C$5:$C$29=$C24),$D$5:$D$29,$F$5:$F$29)),"") -> 0.23229852 | P24: =IFERROR(IF(OR($G24="",$D24=""),"",$G24*$D24),"") -> 186 | Q24: =IFERROR(IF(OR($K24="",$K24=0),"",SUMPRODUCT(--($C$5:$C$29=$C24),$D$5:$D$29,$G$5:$G$29)/$K24),"") -> 1255
A25: 21 | G25: =IFERROR(IF(OR($E25="",$F25=""),"",$F25-$E25),"") | H25: =IFERROR(IF(OR($E25="",$F25="",$F25=0),"",$E25/$F25),"") | I25: =IFERROR(IF(OR($F25="",$D$34=""),"",$F25*(1+$D$34)),"") | J25: =IFERROR(IF($C25="","",SUMPRODUCT(--($C$5:$C$29=$C25),$D$5:$D$29)),"") | K25: =IFERROR(IF($C25="","",SUMPRODUCT(--($C$5:$C$29=$C25),--($D$5:$D$29>0))),"") | L25: =IFERROR(IF(OR($D25="",$J25="",$J25=0),"",$D25/$J25),"") | M25: =IFERROR(IF(OR($K25="",$K25=0,$D$33=""),"",$D$33/$K25),"") | N25: =IFERROR(IF(OR($J25="",$J25=0),"",SUMPRODUCT(--($C$5:$C$29=$C25),$D$5:$D$29,$G$5:$G$29)/$J25),"") | O25: =IFERROR(IF(SUMPRODUCT(--($C$5:$C$29=$C25),$D$5:$D$29,$F$5:$F$29)=0,"",SUMPRODUCT(--($C$5:$C$29=$C25),$D$5:$D$29,$E$5:$E$29)/SUMPRODUCT(--($C$5:$C$29=$C25),$D$5:$D$29,$F$5:$F$29)),"") | P25: =IFERROR(IF(OR($G25="",$D25=""),"",$G25*$D25),"") | Q25: =IFERROR(IF(OR($K25="",$K25=0),"",SUMPRODUCT(--($C$5:$C$29=$C25),$D$5:$D$29,$G$5:$G$29)/$K25),"")
A26: 22 | G26: =IFERROR(IF(OR($E26="",$F26=""),"",$F26-$E26),"") | H26: =IFERROR(IF(OR($E26="",$F26="",$F26=0),"",$E26/$F26),"") | I26: =IFERROR(IF(OR($F26="",$D$34=""),"",$F26*(1+$D$34)),"") | J26: =IFERROR(IF($C26="","",SUMPRODUCT(--($C$5:$C$29=$C26),$D$5:$D$29)),"") | K26: =IFERROR(IF($C26="","",SUMPRODUCT(--($C$5:$C$29=$C26),--($D$5:$D$29>0))),"") | L26: =IFERROR(IF(OR($D26="",$J26="",$J26=0),"",$D26/$J26),"") | M26: =IFERROR(IF(OR($K26="",$K26=0,$D$33=""),"",$D$33/$K26),"") | N26: =IFERROR(IF(OR($J26="",$J26=0),"",SUMPRODUCT(--($C$5:$C$29=$C26),$D$5:$D$29,$G$5:$G$29)/$J26),"") | O26: =IFERROR(IF(SUMPRODUCT(--($C$5:$C$29=$C26),$D$5:$D$29,$F$5:$F$29)=0,"",SUMPRODUCT(--($C$5:$C$29=$C26),$D$5:$D$29,$E$5:$E$29)/SUMPRODUCT(--($C$5:$C$29=$C26),$D$5:$D$29,$F$5:$F$29)),"") | P26: =IFERROR(IF(OR($G26="",$D26=""),"",$G26*$D26),"") | Q26: =IFERROR(IF(OR($K26="",$K26=0),"",SUMPRODUCT(--($C$5:$C$29=$C26),$D$5:$D$29,$G$5:$G$29)/$K26),"")
A27: 23 | G27: =IFERROR(IF(OR($E27="",$F27=""),"",$F27-$E27),"") | H27: =IFERROR(IF(OR($E27="",$F27="",$F27=0),"",$E27/$F27),"") | I27: =IFERROR(IF(OR($F27="",$D$34=""),"",$F27*(1+$D$34)),"") | J27: =IFERROR(IF($C27="","",SUMPRODUCT(--($C$5:$C$29=$C27),$D$5:$D$29)),"") | K27: =IFERROR(IF($C27="","",SUMPRODUCT(--($C$5:$C$29=$C27),--($D$5:$D$29>0))),"") | L27: =IFERROR(IF(OR($D27="",$J27="",$J27=0),"",$D27/$J27),"") | M27: =IFERROR(IF(OR($K27="",$K27=0,$D$33=""),"",$D$33/$K27),"") | N27: =IFERROR(IF(OR($J27="",$J27=0),"",SUMPRODUCT(--($C$5:$C$29=$C27),$D$5:$D$29,$G$5:$G$29)/$J27),"") | O27: =IFERROR(IF(SUMPRODUCT(--($C$5:$C$29=$C27),$D$5:$D$29,$F$5:$F$29)=0,"",SUMPRODUCT(--($C$5:$C$29=$C27),$D$5:$D$29,$E$5:$E$29)/SUMPRODUCT(--($C$5:$C$29=$C27),$D$5:$D$29,$F$5:$F$29)),"") | P27: =IFERROR(IF(OR($G27="",$D27=""),"",$G27*$D27),"") | Q27: =IFERROR(IF(OR($K27="",$K27=0),"",SUMPRODUCT(--($C$5:$C$29=$C27),$D$5:$D$29,$G$5:$G$29)/$K27),"")
A28: 24 | G28: =IFERROR(IF(OR($E28="",$F28=""),"",$F28-$E28),"") | H28: =IFERROR(IF(OR($E28="",$F28="",$F28=0),"",$E28/$F28),"") | I28: =IFERROR(IF(OR($F28="",$D$34=""),"",$F28*(1+$D$34)),"") | J28: =IFERROR(IF($C28="","",SUMPRODUCT(--($C$5:$C$29=$C28),$D$5:$D$29)),"") | K28: =IFERROR(IF($C28="","",SUMPRODUCT(--($C$5:$C$29=$C28),--($D$5:$D$29>0))),"") | L28: =IFERROR(IF(OR($D28="",$J28="",$J28=0),"",$D28/$J28),"") | M28: =IFERROR(IF(OR($K28="",$K28=0,$D$33=""),"",$D$33/$K28),"") | N28: =IFERROR(IF(OR($J28="",$J28=0),"",SUMPRODUCT(--($C$5:$C$29=$C28),$D$5:$D$29,$G$5:$G$29)/$J28),"") | O28: =IFERROR(IF(SUMPRODUCT(--($C$5:$C$29=$C28),$D$5:$D$29,$F$5:$F$29)=0,"",SUMPRODUCT(--($C$5:$C$29=$C28),$D$5:$D$29,$E$5:$E$29)/SUMPRODUCT(--($C$5:$C$29=$C28),$D$5:$D$29,$F$5:$F$29)),"") | P28: =IFERROR(IF(OR($G28="",$D28=""),"",$G28*$D28),"") | Q28: =IFERROR(IF(OR($K28="",$K28=0),"",SUMPRODUCT(--($C$5:$C$29=$C28),$D$5:$D$29,$G$5:$G$29)/$K28),"")
A29: 25 | G29: =IFERROR(IF(OR($E29="",$F29=""),"",$F29-$E29),"") | H29: =IFERROR(IF(OR($E29="",$F29="",$F29=0),"",$E29/$F29),"") | I29: =IFERROR(IF(OR($F29="",$D$34=""),"",$F29*(1+$D$34)),"") | J29: =IFERROR(IF($C29="","",SUMPRODUCT(--($C$5:$C$29=$C29),$D$5:$D$29)),"") | K29: =IFERROR(IF($C29="","",SUMPRODUCT(--($C$5:$C$29=$C29),--($D$5:$D$29>0))),"") | L29: =IFERROR(IF(OR($D29="",$J29="",$J29=0),"",$D29/$J29),"") | M29: =IFERROR(IF(OR($K29="",$K29=0,$D$33=""),"",$D$33/$K29),"") | N29: =IFERROR(IF(OR($J29="",$J29=0),"",SUMPRODUCT(--($C$5:$C$29=$C29),$D$5:$D$29,$G$5:$G$29)/$J29),"") | O29: =IFERROR(IF(SUMPRODUCT(--($C$5:$C$29=$C29),$D$5:$D$29,$F$5:$F$29)=0,"",SUMPRODUCT(--($C$5:$C$29=$C29),$D$5:$D$29,$E$5:$E$29)/SUMPRODUCT(--($C$5:$C$29=$C29),$D$5:$D$29,$F$5:$F$29)),"") | P29: =IFERROR(IF(OR($G29="",$D29=""),"",$G29*$D29),"") | Q29: =IFERROR(IF(OR($K29="",$K29=0),"",SUMPRODUCT(--($C$5:$C$29=$C29),$D$5:$D$29,$G$5:$G$29)/$K29),"")
A31: RESUMEN Y PARÁMETROS — lo calcula el libro
B32: TOTAL DE LA CARTA | D32: =IFERROR(SUM($D$5:$D$29),"") -> 4870 | G32: =IFERROR(IF($D$32=0,"",SUMPRODUCT($D$5:$D$29,$G$5:$G$29)/$D$32),"") -> 8.1597947 | H32: =IFERROR(IF(SUMPRODUCT($D$5:$D$29,$F$5:$F$29)=0,"",SUMPRODUCT($D$5:$D$29,$E$5:$E$29)/SUMPRODUCT($D$5:$D$29,$F$5:$F$29)),"") -> 0.32680208 | I32: =IFERROR(SUMPRODUCT($D$5:$D$29,$F$5:$F$29),"") -> 59029 | J32: Uds · MC medio ponderado · food cost medio ponderado · ventas netas del mes
B33: Factor del umbral de popularidad (%) | D33: 0.7 | F33: El clásico es el 70 % del mix medio: el umbral de cada familia = este factor ÷ número de platos de la familia con ventas. Súbelo si la familia es muy corta.
B34: Tipo de IVA de restauración (%) | D34: 0.1 | F34: 10 % en restauración, INCLUIDA la bebida alcohólica servida en sala: el art. 91.Uno.2.2 de la Ley del IVA grava a ese tipo los servicios de hostelería y «el suministro de comidas y bebidas para consumir en el acto», y no excluye el alcohol. Cámbialo aquí y se recalcula todo el libro.
B35: Platos con ventas en la carta | D35: =COUNTIF($D$5:$D$29,">0") -> 20
B36: Platos dados de alta en la carta | D36: =COUNTIF($B$5:$B$29,"<>") -> 20
A38: RESUMEN POR FAMILIA — lo calcula el libro
B39: Familia | C39: Platos en carta | D39: Platos con ventas | E39: Uds vendidas | F39: Mix sobre la carta (%) | G39: MC medio ponderado (€) | H39: Food cost medio ponderado (%) | I39: Ventas netas del mes (€)
B40: Entrantes | C40: =COUNTIF($C$5:$C$29,$B40) -> 7 | D40: =IFERROR(IF($C40=0,"",SUMPRODUCT(--($C$5:$C$29=$B40),--($D$5:$D$29>0))),"") -> 7 | E40: =IFERROR(IF($C40=0,"",SUMIF($C$5:$C$29,$B40,$D$5:$D$29)),"") -> 1730 | F40: =IFERROR(IF(OR($D$32=0,$C40=0),"",$E40/$D$32),"") -> 0.35523614 | G40: =IFERROR(IF($E40=0,"",SUMPRODUCT(--($C$5:$C$29=$B40),$D$5:$D$29,$G$5:$G$29)/$E40),"") -> 7.4635838 | H40: =IFERROR(IF(SUMPRODUCT(--($C$5:$C$29=$B40),$D$5:$D$29,$F$5:$F$29)=0,"",SUMPRODUCT(--($C$5:$C$29=$B40),$D$5:$D$29,$E$5:$E$29)/SUMPRODUCT(--($C$5:$C$29=$B40),$D$5:$D$29,$F$5:$F$29)),"") -> 0.30714746 | I40: =IFERROR(SUMPRODUCT(--($C$5:$C$29=$B40),$D$5:$D$29,$F$5:$F$29),"") -> 18636
B41: Principales | C41: =COUNTIF($C$5:$C$29,$B41) -> 9 | D41: =IFERROR(IF($C41=0,"",SUMPRODUCT(--($C$5:$C$29=$B41),--($D$5:$D$29>0))),"") -> 9 | E41: =IFERROR(IF($C41=0,"",SUMIF($C$5:$C$29,$B41,$D$5:$D$29)),"") -> 2020 | F41: =IFERROR(IF(OR($D$32=0,$C41=0),"",$E41/$D$32),"") -> 0.41478439 | G41: =IFERROR(IF($E41=0,"",SUMPRODUCT(--($C$5:$C$29=$B41),$D$5:$D$29,$G$5:$G$29)/$E41),"") -> 10.795149 | H41: =IFERROR(IF(SUMPRODUCT(--($C$5:$C$29=$B41),$D$5:$D$29,$F$5:$F$29)=0,"",SUMPRODUCT(--($C$5:$C$29=$B41),$D$5:$D$29,$E$5:$E$29)/SUMPRODUCT(--($C$5:$C$29=$B41),$D$5:$D$29,$F$5:$F$29)),"") -> 0.35587523 | I41: =IFERROR(SUMPRODUCT(--($C$5:$C$29=$B41),$D$5:$D$29,$F$5:$F$29),"") -> 33854
B42: Postres | C42: =COUNTIF($C$5:$C$29,$B42) -> 4 | D42: =IFERROR(IF($C42=0,"",SUMPRODUCT(--($C$5:$C$29=$B42),--($D$5:$D$29>0))),"") -> 4 | E42: =IFERROR(IF($C42=0,"",SUMIF($C$5:$C$29,$B42,$D$5:$D$29)),"") -> 1120 | F42: =IFERROR(IF(OR($D$32=0,$C42=0),"",$E42/$D$32),"") -> 0.22997947 | G42: =IFERROR(IF($E42=0,"",SUMPRODUCT(--($C$5:$C$29=$B42),$D$5:$D$29,$G$5:$G$29)/$E42),"") -> 4.4821429 | H42: =IFERROR(IF(SUMPRODUCT(--($C$5:$C$29=$B42),$D$5:$D$29,$F$5:$F$29)=0,"",SUMPRODUCT(--($C$5:$C$29=$B42),$D$5:$D$29,$E$5:$E$29)/SUMPRODUCT(--($C$5:$C$29=$B42),$D$5:$D$29,$F$5:$F$29)),"") -> 0.23229852 | I42: =IFERROR(SUMPRODUCT(--($C$5:$C$29=$B42),$D$5:$D$29,$F$5:$F$29),"") -> 6539
B43: Menú | C43: =COUNTIF($C$5:$C$29,$B43) -> 0 | D43: =IFERROR(IF($C43=0,"",SUMPRODUCT(--($C$5:$C$29=$B43),--($D$5:$D$29>0))),"") | E43: =IFERROR(IF($C43=0,"",SUMIF($C$5:$C$29,$B43,$D$5:$D$29)),"") | F43: =IFERROR(IF(OR($D$32=0,$C43=0),"",$E43/$D$32),"") | G43: =IFERROR(IF($E43=0,"",SUMPRODUCT(--($C$5:$C$29=$B43),$D$5:$D$29,$G$5:$G$29)/$E43),"") | H43: =IFERROR(IF(SUMPRODUCT(--($C$5:$C$29=$B43),$D$5:$D$29,$F$5:$F$29)=0,"",SUMPRODUCT(--($C$5:$C$29=$B43),$D$5:$D$29,$E$5:$E$29)/SUMPRODUCT(--($C$5:$C$29=$B43),$D$5:$D$29,$F$5:$F$29)),"") | I43: =IFERROR(SUMPRODUCT(--($C$5:$C$29=$B43),$D$5:$D$29,$F$5:$F$29),"") -> 0

Sheet Kasavana-Smith
A1: Kasavana & Smith — popularidad × margen de contribución
A2: AI Chef Pro · aichef.pro — Guía Food Cost + Ingeniería de Menú
E3: Todo se calcula desde la hoja «Datos». Aquí no se teclea nada.
A4: # | B4: Plato | C4: Familia | D4: Uds vendidas | E4: Mix dentro de su familia (%) | F4: Umbral de popularidad de su familia (%) | G4: Popularidad | H4: MC del plato (€) | I4: MC medio ponderado de su familia (€) | J4: Nivel de margen | K4: Clasificación | L4: Qué significa | M4: Acción recomendada
A5: 1 | B5: =IFERROR(IF('Datos'!$B5="","",'Datos'!$B5),"") -> Croquetas de jamón ibérico (6 ud) | C5: =IFERROR(IF('Datos'!$C5="","",'Datos'!$C5),"") -> Entrantes | D5: =IFERROR(IF('Datos'!$D5="","",'Datos'!$D5),"") -> 420 | E5: =IFERROR(IF('Datos'!$L5="","",'Datos'!$L5),"") -> 0.24277457 | F5: =IFERROR(IF('Datos'!$M5="","",'Datos'!$M5),"") -> 0.1 | G5: =IFERROR(IF(OR($E5="",$F5=""),"",IF($E5>=$F5,"Alta","Baja")),"") -> Alta | H5: =IFERROR(IF('Datos'!$G5="","",'Datos'!$G5),"") -> 6.5 | I5: =IFERROR(IF('Datos'!$N5="","",'Datos'!$N5),"") -> 7.4635838 | J5: =IFERROR(IF(OR($H5="",$I5=""),"",IF($H5>=$I5,"Alto","Bajo")),"") -> Bajo | K5: =IFERROR(IF(OR($G5="",$J5=""),"",IF(AND($G5="Alta",$J5="Alto"),"Star",IF(AND($G5="Alta",$J5="Bajo"),"Plowhorse",IF(AND($G5="Baja",$J5="Alto"),"Puzzle","Dog")))),"") -> Plowhorse | L5: =IFERROR(IF($K5="","",IF($K5="Star","Se vende y deja margen: es el plato que sostiene a su familia.",IF($K5="Plowhorse","Se vende mucho, pero deja poco margen en euros por unidad.",IF($K5="Puzzle","Deja buen margen en euros, pero se pide poco.","Ni se vende ni deja margen.")))),"") -> Se vende mucho, pero deja poco margen en euros por unidad. | M5: =IFERROR(IF($K5="","",IF($K5="Star","Mantener receta y proveedor, y darle sitio destacado en la carta.",IF($K5="Plowhorse","Subir precio con cuidado o bajar coste sin tocar la ración.",IF($K5="Puzzle","Reubicar en la carta, renombrar y que la sala lo sugiera.","Retirar o reformular: ocupa sitio en la carta y en la cocina.")))),"") -> Subir precio con cuidado o bajar coste sin tocar la ración.
A6: 2 | B6: =IFERROR(IF('Datos'!$B6="","",'Datos'!$B6),"") -> Ensalada de tomate rosa, ventresca y cebolleta | C6: =IFERROR(IF('Datos'!$C6="","",'Datos'!$C6),"") -> Entrantes | D6: =IFERROR(IF('Datos'!$D6="","",'Datos'!$D6),"") -> 310 | E6: =IFERROR(IF('Datos'!$L6="","",'Datos'!$L6),"") -> 0.17919075 | F6: =IFERROR(IF('Datos'!$M6="","",'Datos'!$M6),"") -> 0.1 | G6: =IFERROR(IF(OR($E6="",$F6=""),"",IF($E6>=$F6,"Alta","Baja")),"") -> Alta | H6: =IFERROR(IF('Datos'!$G6="","",'Datos'!$G6),"") -> 8.2 | I6: =IFERROR(IF('Datos'!$N6="","",'Datos'!$N6),"") -> 7.4635838 | J6: =IFERROR(IF(OR($H6="",$I6=""),"",IF($H6>=$I6,"Alto","Bajo")),"") -> Alto | K6: =IFERROR(IF(OR($G6="",$J6=""),"",IF(AND($G6="Alta",$J6="Alto"),"Star",IF(AND($G6="Alta",$J6="Bajo"),"Plowhorse",IF(AND($G6="Baja",$J6="Alto"),"Puzzle","Dog")))),"") -> Star | L6: =IFERROR(IF($K6="","",IF($K6="Star","Se vende y deja margen: es el plato que sostiene a su familia.",IF($K6="Plowhorse","Se vende mucho, pero deja poco margen en euros por unidad.",IF($K6="Puzzle","Deja buen margen en euros, pero se pide poco.","Ni se vende ni deja margen.")))),"") -> Se vende y deja margen: es el plato que sostiene a su familia. | M6: =IFERROR(IF($K6="","",IF($K6="Star","Mantener receta y proveedor, y darle sitio destacado en la carta.",IF($K6="Plowhorse","Subir precio con cuidado o bajar coste sin tocar la ración.",IF($K6="Puzzle","Reubicar en la carta, renombrar y que la sala lo sugiera.","Retirar o reformular: ocupa sitio en la carta y en la cocina.")))),"") -> Mantener receta y proveedor, y darle sitio destacado en la carta.
A7: 3 | B7: =IFERROR(IF('Datos'!$B7="","",'Datos'!$B7),"") -> Gambas al ajillo | C7: =IFERROR(IF('Datos'!$C7="","",'Datos'!$C7),"") -> Entrantes | D7: =IFERROR(IF('Datos'!$D7="","",'Datos'!$D7),"") -> 260 | E7: =IFERROR(IF('Datos'!$L7="","",'Datos'!$L7),"") -> 0.15028902 | F7: =IFERROR(IF('Datos'!$M7="","",'Datos'!$M7),"") -> 0.1 | G7: =IFERROR(IF(OR($E7="",$F7=""),"",IF($E7>=$F7,"Alta","Baja")),"") -> Alta | H7: =IFERROR(IF('Datos'!$G7="","",'Datos'!$G7),"") -> 8.6 | I7: =IFERROR(IF('Datos'!$N7="","",'Datos'!$N7),"") -> 7.4635838 | J7: =IFERROR(IF(OR($H7="",$I7=""),"",IF($H7>=$I7,"Alto","Bajo")),"") -> Alto | K7: =IFERROR(IF(OR($G7="",$J7=""),"",IF(AND($G7="Alta",$J7="Alto"),"Star",IF(AND($G7="Alta",$J7="Bajo"),"Plowhorse",IF(AND($G7="Baja",$J7="Alto"),"Puzzle","Dog")))),"") -> Star | L7: =IFERROR(IF($K7="","",IF($K7="Star","Se vende y deja margen: es el plato que sostiene a su familia.",IF($K7="Plowhorse","Se vende mucho, pero deja poco margen en euros por unidad.",IF($K7="Puzzle","Deja buen margen en euros, pero se pide poco.","Ni se vende ni deja margen.")))),"") -> Se vende y deja margen: es el plato que sostiene a su familia. | M7: =IFERROR(IF($K7="","",IF($K7="Star","Mantener receta y proveedor, y darle sitio destacado en la carta.",IF($K7="Plowhorse","Subir precio con cuidado o bajar coste sin tocar la ración.",IF($K7="Puzzle","Reubicar en la carta, renombrar y que la sala lo sugiera.","Retirar o reformular: ocupa sitio en la carta y en la cocina.")))),"") -> Mantener receta y proveedor, y darle sitio destacado en la carta.
A8: 4 | B8: =IFERROR(IF('Datos'!$B8="","",'Datos'!$B8),"") -> Huevos rotos con patatas y chistorra | C8: =IFERROR(IF('Datos'!$C8="","",'Datos'!$C8),"") -> Entrantes | D8: =IFERROR(IF('Datos'!$D8="","",'Datos'!$D8),"") -> 380 | E8: =IFERROR(IF('Datos'!$L8="","",'Datos'!$L8),"") -> 0.21965318 | F8: =IFERROR(IF('Datos'!$M8="","",'Datos'!$M8),"") -> 0.1 | G8: =IFERROR(IF(OR($E8="",$F8=""),"",IF($E8>=$F8,"Alta","Baja")),"") -> Alta | H8: =IFERROR(IF('Datos'!$G8="","",'Datos'!$G8),"") -> 7.4 | I8: =IFERROR(IF('Datos'!$N8="","",'Datos'!$N8),"") -> 7.4635838 | J8: =IFERROR(IF(OR($H8="",$I8=""),"",IF($H8>=$I8,"Alto","Bajo")),"") -> Bajo | K8: =IFERROR(IF(OR($G8="",$J8=""),"",IF(AND($G8="Alta",$J8="Alto"),"Star",IF(AND($G8="Alta",$J8="Bajo"),"Plowhorse",IF(AND($G8="Baja",$J8="Alto"),"Puzzle","Dog")))),"") -> Plowhorse | L8: =IFERROR(IF($K8="","",IF($K8="Star","Se vende y deja margen: es el plato que sostiene a su familia.",IF($K8="Plowhorse","Se vende mucho, pero deja poco margen en euros por unidad.",IF($K8="Puzzle","Deja buen margen en euros, pero se pide poco.","Ni se vende ni deja margen.")))),"") -> Se vende mucho, pero deja poco margen en euros por unidad. | M8: =IFERROR(IF($K8="","",IF($K8="Star","Mantener receta y proveedor, y darle sitio destacado en la carta.",IF($K8="Plowhorse","Subir precio con cuidado o bajar coste sin tocar la ración.",IF($K8="Puzzle","Reubicar en la carta, renombrar y que la sala lo sugiera.","Retirar o reformular: ocupa sitio en la carta y en la cocina.")))),"") -> Subir precio con cuidado o bajar coste sin tocar la ración.
A9: 5 | B9: =IFERROR(IF('Datos'!$B9="","",'Datos'!$B9),"") -> Tabla de quesos de la zona | C9: =IFERROR(IF('Datos'!$C9="","",'Datos'!$C9),"") -> Entrantes | D9: =IFERROR(IF('Datos'!$D9="","",'Datos'!$D9),"") -> 90 | E9: =IFERROR(IF('Datos'!$L9="","",'Datos'!$L9),"") -> 0.052023121 | F9: =IFERROR(IF('Datos'!$M9="","",'Datos'!$M9),"") -> 0.1 | G9: =IFERROR(IF(OR($E9="",$F9=""),"",IF($E9>=$F9,"Alta","Baja")),"") -> Baja | H9: =IFERROR(IF('Datos'!$G9="","",'Datos'!$G9),"") -> 8.4 | I9: =IFERROR(IF('Datos'!$N9="","",'Datos'!$N9),"") -> 7.4635838 | J9: =IFERROR(IF(OR($H9="",$I9=""),"",IF($H9>=$I9,"Alto","Bajo")),"") -> Alto | K9: =IFERROR(IF(OR($G9="",$J9=""),"",IF(AND($G9="Alta",$J9="Alto"),"Star",IF(AND($G9="Alta",$J9="Bajo"),"Plowhorse",IF(AND($G9="Baja",$J9="Alto"),"Puzzle","Dog")))),"") -> Puzzle | L9: =IFERROR(IF($K9="","",IF($K9="Star","Se vende y deja margen: es el plato que sostiene a su familia.",IF($K9="Plowhorse","Se vende mucho, pero deja poco margen en euros por unidad.",IF($K9="Puzzle","Deja buen margen en euros, pero se pide poco.","Ni se vende ni deja margen.")))),"") -> Deja buen margen en euros, pero se pide poco. | M9: =IFERROR(IF($K9="","",IF($K9="Star","Mantener receta y proveedor, y darle sitio destacado en la carta.",IF($K9="Plowhorse","Subir precio con cuidado o bajar coste sin tocar la ración.",IF($K9="Puzzle","Reubicar en la carta, renombrar y que la sala lo sugiera.","Retirar o reformular: ocupa sitio en la carta y en la cocina.")))),"") -> Reubicar en la carta, renombrar y que la sala lo sugiera.
A10: 6 | B10: =IFERROR(IF('Datos'!$B10="","",'Datos'!$B10),"") -> Alcachofas confitadas con jamón | C10: =IFERROR(IF('Datos'!$C10="","",'Datos'!$C10),"") -> Entrantes | D10: =IFERROR(IF('Datos'!$D10="","",'Datos'!$D10),"") -> 120 | E10: =IFERROR(IF('Datos'!$L10="","",'Datos'!$L10),"") -> 0.069364162 | F10: =IFERROR(IF('Datos'!$M10="","",'Datos'!$M10),"") -> 0.1 | G10: =IFERROR(IF(OR($E10="",$F10=""),"",IF($E10>=$F10,"Alta","Baja")),"") -> Baja | H10: =IFERROR(IF('Datos'!$G10="","",'Datos'!$G10),"") -> 7.8 | I10: =IFERROR(IF('Datos'!$N10="","",'Datos'!$N10),"") -> 7.4635838 | J10: =IFERROR(IF(OR($H10="",$I10=""),"",IF($H10>=$I10,"Alto","Bajo")),"") -> Alto | K10: =IFERROR(IF(OR($G10="",$J10=""),"",IF(AND($G10="Alta",$J10="Alto"),"Star",IF(AND($G10="Alta",$J10="Bajo"),"Plowhorse",IF(AND($G10="Baja",$J10="Alto"),"Puzzle","Dog")))),"") -> Puzzle | L10: =IFERROR(IF($K10="","",IF($K10="Star","Se vende y deja margen: es el plato que sostiene a su familia.",IF($K10="Plowhorse","Se vende mucho, pero deja poco margen en euros por unidad.",IF($K10="Puzzle","Deja buen margen en euros, pero se pide poco.","Ni se vende ni deja margen.")))),"") -> Deja buen margen en euros, pero se pide poco. | M10: =IFERROR(IF($K10="","",IF($K10="Star","Mantener receta y proveedor, y darle sitio destacado en la carta.",IF($K10="Plowhorse","Subir precio con cuidado o bajar coste sin tocar la ración.",IF($K10="Puzzle","Reubicar en la carta, renombrar y que la sala lo sugiera.","Retirar o reformular: ocupa sitio en la carta y en la cocina.")))),"") -> Reubicar en la carta, renombrar y que la sala lo sugiera.
A11: 7 | B11: =IFERROR(IF('Datos'!$B11="","",'Datos'!$B11),"") -> Sopa de tomate asado con albahaca | C11: =IFERROR(IF('Datos'!$C11="","",'Datos'!$C11),"") -> Entrantes | D11: =IFERROR(IF('Datos'!$D11="","",'Datos'!$D11),"") -> 150 | E11: =IFERROR(IF('Datos'!$L11="","",'Datos'!$L11),"") -> 0.086705202 | F11: =IFERROR(IF('Datos'!$M11="","",'Datos'!$M11),"") -> 0.1 | G11: =IFERROR(IF(OR($E11="",$F11=""),"",IF($E11>=$F11,"Alta","Baja")),"") -> Baja | H11: =IFERROR(IF('Datos'!$G11="","",'Datos'!$G11),"") -> 6 | I11: =IFERROR(IF('Datos'!$N11="","",'Datos'!$N11),"") -> 7.4635838 | J11: =IFERROR(IF(OR($H11="",$I11=""),"",IF($H11>=$I11,"Alto","Bajo")),"") -> Bajo | K11: =IFERROR(IF(OR($G11="",$J11=""),"",IF(AND($G11="Alta",$J11="Alto"),"Star",IF(AND($G11="Alta",$J11="Bajo"),"Plowhorse",IF(AND($G11="Baja",$J11="Alto"),"Puzzle","Dog")))),"") -> Dog | L11: =IFERROR(IF($K11="","",IF($K11="Star","Se vende y deja margen: es el plato que sostiene a su familia.",IF($K11="Plowhorse","Se vende mucho, pero deja poco margen en euros por unidad.",IF($K11="Puzzle","Deja buen margen en euros, pero se pide poco.","Ni se vende ni deja margen.")))),"") -> Ni se vende ni deja margen. | M11: =IFERROR(IF($K11="","",IF($K11="Star","Mantener receta y proveedor, y darle sitio destacado en la carta.",IF($K11="Plowhorse","Subir precio con cuidado o bajar coste sin tocar la ración.",IF($K11="Puzzle","Reubicar en la carta, renombrar y que la sala lo sugiera.","Retirar o reformular: ocupa sitio en la carta y en la cocina.")))),"") -> Retirar o reformular: ocupa sitio en la carta y en la cocina.
A12: 8 | B12: =IFERROR(IF('Datos'!$B12="","",'Datos'!$B12),"") -> Solomillo de cerdo ibérico con puré de boniato | C12: =IFERROR(IF('Datos'!$C12="","",'Datos'!$C12),"") -> Principales | D12: =IFERROR(IF('Datos'!$D12="","",'Datos'!$D12),"") -> 340 | E12: =IFERROR(IF('Datos'!$L12="","",'Datos'!$L12),"") -> 0.16831683 | F12: =IFERROR(IF('Datos'!$M12="","",'Datos'!$M12),"") -> 0.077777778 | G12: =IFERROR(IF(OR($E12="",$F12=""),"",IF($E12>=$F12,"Alta","Baja")),"") -> Alta | H12: =IFERROR(IF('Datos'!$G12="","",'Datos'!$G12),"") -> 11.63 | I12: =IFERROR(IF('Datos'!$N12="","",'Datos'!$N12),"") -> 10.795149 | J12: =IFERROR(IF(OR($H12="",$I12=""),"",IF($H12>=$I12,"Alto","Bajo")),"") -> Alto | K12: =IFERROR(IF(OR($G12="",$J12=""),"",IF(AND($G12="Alta",$J12="Alto"),"Star",IF(AND($G12="Alta",$J12="Bajo"),"Plowhorse",IF(AND($G12="Baja",$J12="Alto"),"Puzzle","Dog")))),"") -> Star | L12: =IFERROR(IF($K12="","",IF($K12="Star","Se vende y deja margen: es el plato que sostiene a su familia.",IF($K12="Plowhorse","Se vende mucho, pero deja poco margen en euros por unidad.",IF($K12="Puzzle","Deja buen margen en euros, pero se pide poco.","Ni se vende ni deja margen.")))),"") -> Se vende y deja margen: es el plato que sostiene a su familia. | M12: =IFERROR(IF($K12="","",IF($K12="Star","Mantener receta y proveedor, y darle sitio destacado en la carta.",IF($K12="Plowhorse","Subir precio con cuidado o bajar coste sin tocar la ración.",IF($K12="Puzzle","Reubicar en la carta, renombrar y que la sala lo sugiera.","Retirar o reformular: ocupa sitio en la carta y en la cocina.")))),"") -> Mantener receta y proveedor, y darle sitio destacado en la carta.
A13: 9 | B13: =IFERROR(IF('Datos'!$B13="","",'Datos'!$B13),"") -> Bacalao confitado al pil-pil | C13: =IFERROR(IF('Datos'!$C13="","",'Datos'!$C13),"") -> Principales | D13: =IFERROR(IF('Datos'!$D13="","",'Datos'!$D13),"") -> 190 | E13: =IFERROR(IF('Datos'!$L13="","",'Datos'!$L13),"") -> 0.094059406 | F13: =IFERROR(IF('Datos'!$M13="","",'Datos'!$M13),"") -> 0.077777778 | G13: =IFERROR(IF(OR($E13="",$F13=""),"",IF($E13>=$F13,"Alta","Baja")),"") -> Alta | H13: =IFERROR(IF('Datos'!$G13="","",'Datos'!$G13),"") -> 11.7 | I13: =IFERROR(IF('Datos'!$N13="","",'Datos'!$N13),"") -> 10.795149 | J13: =IFERROR(IF(OR($H13="",$I13=""),"",IF($H13>=$I13,"Alto","Bajo")),"") -> Alto | K13: =IFERROR(IF(OR($G13="",$J13=""),"",IF(AND($G13="Alta",$J13="Alto"),"Star",IF(AND($G13="Alta",$J13="Bajo"),"Plowhorse",IF(AND($G13="Baja",$J13="Alto"),"Puzzle","Dog")))),"") -> Star | L13: =IFERROR(IF($K13="","",IF($K13="Star","Se vende y deja margen: es el plato que sostiene a su familia.",IF($K13="Plowhorse","Se vende mucho, pero deja poco margen en euros por unidad.",IF($K13="Puzzle","Deja buen margen en euros, pero se pide poco.","Ni se vende ni deja margen.")))),"") -> Se vende y deja margen: es el plato que sostiene a su familia. | M13: =IFERROR(IF($K13="","",IF($K13="Star","Mantener receta y proveedor, y darle sitio destacado en la carta.",IF($K13="Plowhorse","Subir precio con cuidado o bajar coste sin tocar la ración.",IF($K13="Puzzle","Reubicar en la carta, renombrar y que la sala lo sugiera.","Retirar o reformular: ocupa sitio en la carta y en la cocina.")))),"") -> Mantener receta y proveedor, y darle sitio destacado en la carta.
A14: 10 | B14: =IFERROR(IF('Datos'!$B14="","",'Datos'!$B14),"") -> Hamburguesa de vaca madurada con patatas | C14: =IFERROR(IF('Datos'!$C14="","",'Datos'!$C14),"") -> Principales | D14: =IFERROR(IF('Datos'!$D14="","",'Datos'!$D14),"") -> 460 | E14: =IFERROR(IF('Datos'!$L14="","",'Datos'!$L14),"") -> 0.22772277 | F14: =IFERROR(IF('Datos'!$M14="","",'Datos'!$M14),"") -> 0.077777778 | G14: =IFERROR(IF(OR($E14="",$F14=""),"",IF($E14>=$F14,"Alta","Baja")),"") -> Alta | H14: =IFERROR(IF('Datos'!$G14="","",'Datos'!$G14),"") -> 9.3 | I14: =IFERROR(IF('Datos'!$N14="","",'Datos'!$N14),"") -> 10.795149 | J14: =IFERROR(IF(OR($H14="",$I14=""),"",IF($H14>=$I14,"Alto","Bajo")),"") -> Bajo | K14: =IFERROR(IF(OR($G14="",$J14=""),"",IF(AND($G14="Alta",$J14="Alto"),"Star",IF(AND($G14="Alta",$J14="Bajo"),"Plowhorse",IF(AND($G14="Baja",$J14="Alto"),"Puzzle","Dog")))),"") -> Plowhorse | L14: =IFERROR(IF($K14="","",IF($K14="Star","Se vende y deja margen: es el plato que sostiene a su familia.",IF($K14="Plowhorse","Se vende mucho, pero deja poco margen en euros por unidad.",IF($K14="Puzzle","Deja buen margen en euros, pero se pide poco.","Ni se vende ni deja margen.")))),"") -> Se vende mucho, pero deja poco margen en euros por unidad. | M14: =IFERROR(IF($K14="","",IF($K14="Star","Mantener receta y proveedor, y darle sitio destacado en la carta.",IF($K14="Plowhorse","Subir precio con cuidado o bajar coste sin tocar la ración.",IF($K14="Puzzle","Reubicar en la carta, renombrar y que la sala lo sugiera.","Retirar o reformular: ocupa sitio en la carta y en la cocina.")))),"") -> Subir precio con cuidado o bajar coste sin tocar la ración.
A15: 11 | B15: =IFERROR(IF('Datos'!$B15="","",'Datos'!$B15),"") -> Arroz meloso de secreto ibérico y setas | C15: =IFERROR(IF('Datos'!$C15="","",'Datos'!$C15),"") -> Principales | D15: =IFERROR(IF('Datos'!$D15="","",'Datos'!$D15),"") -> 270 | E15: =IFERROR(IF('Datos'!$L15="","",'Datos'!$L15),"") -> 0.13366337 | F15: =IFERROR(IF('Datos'!$M15="","",'Datos'!$M15),"") -> 0.077777778 | G15: =IFERROR(IF(OR($E15="",$F15=""),"",IF($E15>=$F15,"Alta","Baja")),"") -> Alta | H15: =IFERROR(IF('Datos'!$G15="","",'Datos'!$G15),"") -> 10.2 | I15: =IFERROR(IF('Datos'!$N15="","",'Datos'!$N15),"") -> 10.795149 | J15: =IFERROR(IF(OR($H15="",$I15=""),"",IF($H15>=$I15,"Alto","Bajo")),"") -> Bajo | K15: =IFERROR(IF(OR($G15="",$J15=""),"",IF(AND($G15="Alta",$J15="Alto"),"Star",IF(AND($G15="Alta",$J15="Bajo"),"Plowhorse",IF(AND($G15="Baja",$J15="Alto"),"Puzzle","Dog")))),"") -> Plowhorse | L15: =IFERROR(IF($K15="","",IF($K15="Star","Se vende y deja margen: es el plato que sostiene a su familia.",IF($K15="Plowhorse","Se vende mucho, pero deja poco margen en euros por unidad.",IF($K15="Puzzle","Deja buen margen en euros, pero se pide poco.","Ni se vende ni deja margen.")))),"") -> Se vende mucho, pero deja poco margen en euros por unidad. | M15: =IFERROR(IF($K15="","",IF($K15="Star","Mantener receta y proveedor, y darle sitio destacado en la carta.",IF($K15="Plowhorse","Subir precio con cuidado o bajar coste sin tocar la ración.",IF($K15="Puzzle","Reubicar en la carta, renombrar y que la sala lo sugiera.","Retirar o reformular: ocupa sitio en la carta y en la cocina.")))),"") -> Subir precio con cuidado o bajar coste sin tocar la ración.
A16: 12 | B16: =IFERROR(IF('Datos'!$B16="","",'Datos'!$B16),"") -> Chuletón de vaca madurada (500 g) | C16: =IFERROR(IF('Datos'!$C16="","",'Datos'!$C16),"") -> Principales | D16: =IFERROR(IF('Datos'!$D16="","",'Datos'!$D16),"") -> 110 | E16: =IFERROR(IF('Datos'!$L16="","",'Datos'!$L16),"") -> 0.054455446 | F16: =IFERROR(IF('Datos'!$M16="","",'Datos'!$M16),"") -> 0.077777778 | G16: =IFERROR(IF(OR($E16="",$F16=""),"",IF($E16>=$F16,"Alta","Baja")),"") -> Baja | H16: =IFERROR(IF('Datos'!$G16="","",'Datos'!$G16),"") -> 17.9 | I16: =IFERROR(IF('Datos'!$N16="","",'Datos'!$N16),"") -> 10.795149 | J16: =IFERROR(IF(OR($H16="",$I16=""),"",IF($H16>=$I16,"Alto","Bajo")),"") -> Alto | K16: =IFERROR(IF(OR($G16="",$J16=""),"",IF(AND($G16="Alta",$J16="Alto"),"Star",IF(AND($G16="Alta",$J16="Bajo"),"Plowhorse",IF(AND($G16="Baja",$J16="Alto"),"Puzzle","Dog")))),"") -> Puzzle | L16: =IFERROR(IF($K16="","",IF($K16="Star","Se vende y deja margen: es el plato que sostiene a su familia.",IF($K16="Plowhorse","Se vende mucho, pero deja poco margen en euros por unidad.",IF($K16="Puzzle","Deja buen margen en euros, pero se pide poco.","Ni se vende ni deja margen.")))),"") -> Deja buen margen en euros, pero se pide poco. | M16: =IFERROR(IF($K16="","",IF($K16="Star","Mantener receta y proveedor, y darle sitio destacado en la carta.",IF($K16="Plowhorse","Subir precio con cuidado o bajar coste sin tocar la ración.",IF($K16="Puzzle","Reubicar en la carta, renombrar y que la sala lo sugiera.","Retirar o reformular: ocupa sitio en la carta y en la cocina.")))),"") -> Reubicar en la carta, renombrar y que la sala lo sugiera.
... A29: 25 | B29: =IFERROR(IF('Datos'!$B29="","",'Datos'!$B29),"") | C29: =IFERROR(IF('Datos'!$C29="","",'Datos'!$C29),"") | D29: =IFERROR(IF('Datos'!$D29="","",'Datos'!$D29),"") | E29: =IFERROR(IF('Datos'!$L29="","",'Datos'!$L29),"") | F29: =IFERROR(IF('Datos'!$M29="","",'Datos'!$M29),"") | G29: =IFERROR(IF(OR($E29="",$F29=""),"",IF($E29>=$F29,"Alta","Baja")),"") | H29: =IFERROR(IF('Datos'!$G29="","",'Datos'!$G29),"") | I29: =IFERROR(IF('Datos'!$N29="","",'Datos'!$N29),"") | J29: =IFERROR(IF(OR($H29="",$I29=""),"",IF($H29>=$I29,"Alto","Bajo")),"") | K29: =IFERROR(IF(OR($G29="",$J29=""),"",IF(AND($G29="Alta",$J29="Alto"),"Star",IF(AND($G29="Alta",$J29="Bajo"),"Plowhorse",IF(AND($G29="Baja",$J29="Alto"),"Puzzle","Dog")))),"") | L29: =IFERROR(IF($K29="","",IF($K29="Star","Se vende y deja margen: es el plato que sostiene a su familia.",IF($K29="Plowhorse","Se vende mucho, pero deja poco margen en euros por unidad.",IF($K29="Puzzle","Deja buen margen en euros, pero se pide poco.","Ni se vende ni deja margen.")))),"") | M29: =IFERROR(IF($K29="","",IF($K29="Star","Mantener receta y proveedor, y darle sitio destacado en la carta.",IF($K29="Plowhorse","Subir precio con cuidado o bajar coste sin tocar la ración.",IF($K29="Puzzle","Reubicar en la carta, renombrar y que la sala lo sugiera.","Retirar o reformular: ocupa sitio en la carta y en la cocina.")))),"")
A31: RESUMEN — lo calcula el libro
B32: Clasificación | C32: Platos | D32: Uds vendidas | E32: % de las uds de la carta | F32: MC total aportado (€)
B33: Star | C33: =COUNTIF($K$5:$K$29,$B33) -> 6 | D33: =IFERROR(SUMIF($K$5:$K$29,$B33,$D$5:$D$29),"") -> 1950 | E33: =IFERROR(IF(SUM($D$5:$D$29)=0,"",$D33/SUM($D$5:$D$29)),"") -> 0.40041068 | F33: =IFERROR(SUMPRODUCT(--($K$5:$K$29=$B33),$D$5:$D$29,$H$5:$H$29),"") -> 14865.2
B34: Plowhorse | C34: =COUNTIF($K$5:$K$29,$B34) -> 6 | D34: =IFERROR(SUMIF($K$5:$K$29,$B34,$D$5:$D$29),"") -> 2040 | E34: =IFERROR(IF(SUM($D$5:$D$29)=0,"",$D34/SUM($D$5:$D$29)),"") -> 0.41889117 | F34: =IFERROR(SUMPRODUCT(--($K$5:$K$29=$B34),$D$5:$D$29,$H$5:$H$29),"") -> 16198
B35: Puzzle | C35: =COUNTIF($K$5:$K$29,$B35) -> 5 | D35: =IFERROR(SUMIF($K$5:$K$29,$B35,$D$5:$D$29),"") -> 530 | E35: =IFERROR(IF(SUM($D$5:$D$29)=0,"",$D35/SUM($D$5:$D$29)),"") -> 0.10882957 | F35: =IFERROR(SUMPRODUCT(--($K$5:$K$29=$B35),$D$5:$D$29,$H$5:$H$29),"") -> 6357
B36: Dog | C36: =COUNTIF($K$5:$K$29,$B36) -> 3 | D36: =IFERROR(SUMIF($K$5:$K$29,$B36,$D$5:$D$29),"") -> 350 | E36: =IFERROR(IF(SUM($D$5:$D$29)=0,"",$D36/SUM($D$5:$D$29)),"") -> 0.071868583 | F36: =IFERROR(SUMPRODUCT(--($K$5:$K$29=$B36),$D$5:$D$29,$H$5:$H$29),"") -> 2318

Sheet Miller
A1: Miller — popularidad × food cost %
A2: AI Chef Pro · aichef.pro — Guía Food Cost + Ingeniería de Menú
E3: Miller premia el food cost bajo; Kasavana & Smith premia el margen en euros. No siempre coinciden.
A4: # | B4: Plato | C4: Familia | D4: Uds vendidas | E4: Mix dentro de su familia (%) | F4: Umbral de popularidad de su familia (%) | G4: Popularidad | H4: Food cost del plato (%) | I4: Food cost medio ponderado de su familia (%) | J4: Nivel de food cost | K4: Clasificación | L4: Qué significa | M4: Acción recomendada
A5: 1 | B5: =IFERROR(IF('Datos'!$B5="","",'Datos'!$B5),"") -> Croquetas de jamón ibérico (6 ud) | C5: =IFERROR(IF('Datos'!$C5="","",'Datos'!$C5),"") -> Entrantes | D5: =IFERROR(IF('Datos'!$D5="","",'Datos'!$D5),"") -> 420 | E5: =IFERROR(IF('Datos'!$L5="","",'Datos'!$L5),"") -> 0.24277457 | F5: =IFERROR(IF('Datos'!$M5="","",'Datos'!$M5),"") -> 0.1 | G5: =IFERROR(IF(OR($E5="",$F5=""),"",IF($E5>=$F5,"Alta","Baja")),"") -> Alta | H5: =IFERROR(IF('Datos'!$H5="","",'Datos'!$H5),"") -> 0.24418605 | I5: =IFERROR(IF('Datos'!$O5="","",'Datos'!$O5),"") -> 0.30714746 | J5: =IFERROR(IF(OR($H5="",$I5=""),"",IF($H5<=$I5,"Bajo","Alto")),"") -> Bajo | K5: =IFERROR(IF(OR($G5="",$J5=""),"",IF(AND($G5="Alta",$J5="Bajo"),"Winner",IF(AND($G5="Baja",$J5="Alto"),"Loser","Marginal"))),"") -> Winner | L5: =IFERROR(IF($K5="","",IF($K5="Winner","Popular y con el food cost por debajo de la media de su familia.",IF($K5="Marginal","Cumple en una sola de las dos: o vende, o tiene el food cost sano.","Poco pedido y con el food cost por encima de su familia."))),"") -> Popular y con el food cost por debajo de la media de su familia. | M5: =IFERROR(IF($K5="","",IF($K5="Winner","Mantener y proteger el escandallo: es el que aguanta una subida del proveedor.",IF($K5="Marginal","Mirar las otras lecturas antes de tocarlo: el problema es de precio o es de carta.","Reformular la receta o retirarlo de la carta."))),"") -> Mantener y proteger el escandallo: es el que aguanta una subida del proveedor.
A6: 2 | B6: =IFERROR(IF('Datos'!$B6="","",'Datos'!$B6),"") -> Ensalada de tomate rosa, ventresca y cebolleta | C6: =IFERROR(IF('Datos'!$C6="","",'Datos'!$C6),"") -> Entrantes | D6: =IFERROR(IF('Datos'!$D6="","",'Datos'!$D6),"") -> 310 | E6: =IFERROR(IF('Datos'!$L6="","",'Datos'!$L6),"") -> 0.17919075 | F6: =IFERROR(IF('Datos'!$M6="","",'Datos'!$M6),"") -> 0.1 | G6: =IFERROR(IF(OR($E6="",$F6=""),"",IF($E6>=$F6,"Alta","Baja")),"") -> Alta | H6: =IFERROR(IF('Datos'!$H6="","",'Datos'!$H6),"") -> 0.30508475 | I6: =IFERROR(IF('Datos'!$O6="","",'Datos'!$O6),"") -> 0.30714746 | J6: =IFERROR(IF(OR($H6="",$I6=""),"",IF($H6<=$I6,"Bajo","Alto")),"") -> Bajo | K6: =IFERROR(IF(OR($G6="",$J6=""),"",IF(AND($G6="Alta",$J6="Bajo"),"Winner",IF(AND($G6="Baja",$J6="Alto"),"Loser","Marginal"))),"") -> Winner | L6: =IFERROR(IF($K6="","",IF($K6="Winner","Popular y con el food cost por debajo de la media de su familia.",IF($K6="Marginal","Cumple en una sola de las dos: o vende, o tiene el food cost sano.","Poco pedido y con el food cost por encima de su familia."))),"") -> Popular y con el food cost por debajo de la media de su familia. | M6: =IFERROR(IF($K6="","",IF($K6="Winner","Mantener y proteger el escandallo: es el que aguanta una subida del proveedor.",IF($K6="Marginal","Mirar las otras lecturas antes de tocarlo: el problema es de precio o es de carta.","Reformular la receta o retirarlo de la carta."))),"") -> Mantener y proteger el escandallo: es el que aguanta una subida del proveedor.
A7: 3 | B7: =IFERROR(IF('Datos'!$B7="","",'Datos'!$B7),"") -> Gambas al ajillo | C7: =IFERROR(IF('Datos'!$C7="","",'Datos'!$C7),"") -> Entrantes | D7: =IFERROR(IF('Datos'!$D7="","",'Datos'!$D7),"") -> 260 | E7: =IFERROR(IF('Datos'!$L7="","",'Datos'!$L7),"") -> 0.15028902 | F7: =IFERROR(IF('Datos'!$M7="","",'Datos'!$M7),"") -> 0.1 | G7: =IFERROR(IF(OR($E7="",$F7=""),"",IF($E7>=$F7,"Alta","Baja")),"") -> Alta | H7: =IFERROR(IF('Datos'!$H7="","",'Datos'!$H7),"") -> 0.44516129 | I7: =IFERROR(IF('Datos'!$O7="","",'Datos'!$O7),"") -> 0.30714746 | J7: =IFERROR(IF(OR($H7="",$I7=""),"",IF($H7<=$I7,"Bajo","Alto")),"") -> Alto | K7: =IFERROR(IF(OR($G7="",$J7=""),"",IF(AND($G7="Alta",$J7="Bajo"),"Winner",IF(AND($G7="Baja",$J7="Alto"),"Loser","Marginal"))),"") -> Marginal | L7: =IFERROR(IF($K7="","",IF($K7="Winner","Popular y con el food cost por debajo de la media de su familia.",IF($K7="Marginal","Cumple en una sola de las dos: o vende, o tiene el food cost sano.","Poco pedido y con el food cost por encima de su familia."))),"") -> Cumple en una sola de las dos: o vende, o tiene el food cost sano. | M7: =IFERROR(IF($K7="","",IF($K7="Winner","Mantener y proteger el escandallo: es el que aguanta una subida del proveedor.",IF($K7="Marginal","Mirar las otras lecturas antes de tocarlo: el problema es de precio o es de carta.","Reformular la receta o retirarlo de la carta."))),"") -> Mirar las otras lecturas antes de tocarlo: el problema es de precio o es de carta.
A8: 4 | B8: =IFERROR(IF('Datos'!$B8="","",'Datos'!$B8),"") -> Huevos rotos con patatas y chistorra | C8: =IFERROR(IF('Datos'!$C8="","",'Datos'!$C8),"") -> Entrantes | D8: =IFERROR(IF('Datos'!$D8="","",'Datos'!$D8),"") -> 380 | E8: =IFERROR(IF('Datos'!$L8="","",'Datos'!$L8),"") -> 0.21965318 | F8: =IFERROR(IF('Datos'!$M8="","",'Datos'!$M8),"") -> 0.1 | G8: =IFERROR(IF(OR($E8="",$F8=""),"",IF($E8>=$F8,"Alta","Baja")),"") -> Alta | H8: =IFERROR(IF('Datos'!$H8="","",'Datos'!$H8),"") -> 0.24489796 | I8: =IFERROR(IF('Datos'!$O8="","",'Datos'!$O8),"") -> 0.30714746 | J8: =IFERROR(IF(OR($H8="",$I8=""),"",IF($H8<=$I8,"Bajo","Alto")),"") -> Bajo | K8: =IFERROR(IF(OR($G8="",$J8=""),"",IF(AND($G8="Alta",$J8="Bajo"),"Winner",IF(AND($G8="Baja",$J8="Alto"),"Loser","Marginal"))),"") -> Winner | L8: =IFERROR(IF($K8="","",IF($K8="Winner","Popular y con el food cost por debajo de la media de su familia.",IF($K8="Marginal","Cumple en una sola de las dos: o vende, o tiene el food cost sano.","Poco pedido y con el food cost por encima de su familia."))),"") -> Popular y con el food cost por debajo de la media de su familia. | M8: =IFERROR(IF($K8="","",IF($K8="Winner","Mantener y proteger el escandallo: es el que aguanta una subida del proveedor.",IF($K8="Marginal","Mirar las otras lecturas antes de tocarlo: el problema es de precio o es de carta.","Reformular la receta o retirarlo de la carta."))),"") -> Mantener y proteger el escandallo: es el que aguanta una subida del proveedor.
A9: 5 | B9: =IFERROR(IF('Datos'!$B9="","",'Datos'!$B9),"") -> Tabla de quesos de la zona | C9: =IFERROR(IF('Datos'!$C9="","",'Datos'!$C9),"") -> Entrantes | D9: =IFERROR(IF('Datos'!$D9="","",'Datos'!$D9),"") -> 90 | E9: =IFERROR(IF('Datos'!$L9="","",'Datos'!$L9),"") -> 0.052023121 | F9: =IFERROR(IF('Datos'!$M9="","",'Datos'!$M9),"") -> 0.1 | G9: =IFERROR(IF(OR($E9="",$F9=""),"",IF($E9>=$F9,"Alta","Baja")),"") -> Baja | H9: =IFERROR(IF('Datos'!$H9="","",'Datos'!$H9),"") -> 0.38235294 | I9: =IFERROR(IF('Datos'!$O9="","",'Datos'!$O9),"") -> 0.30714746 | J9: =IFERROR(IF(OR($H9="",$I9=""),"",IF($H9<=$I9,"Bajo","Alto")),"") -> Alto | K9: =IFERROR(IF(OR($G9="",$J9=""),"",IF(AND($G9="Alta",$J9="Bajo"),"Winner",IF(AND($G9="Baja",$J9="Alto"),"Loser","Marginal"))),"") -> Loser | L9: =IFERROR(IF($K9="","",IF($K9="Winner","Popular y con el food cost por debajo de la media de su familia.",IF($K9="Marginal","Cumple en una sola de las dos: o vende, o tiene el food cost sano.","Poco pedido y con el food cost por encima de su familia."))),"") -> Poco pedido y con el food cost por encima de su familia. | M9: =IFERROR(IF($K9="","",IF($K9="Winner","Mantener y proteger el escandallo: es el que aguanta una subida del proveedor.",IF($K9="Marginal","Mirar las otras lecturas antes de tocarlo: el problema es de precio o es de carta.","Reformular la receta o retirarlo de la carta."))),"") -> Reformular la receta o retirarlo de la carta.
A10: 6 | B10: =IFERROR(IF('Datos'!$B10="","",'Datos'!$B10),"") -> Alcachofas confitadas con jamón | C10: =IFERROR(IF('Datos'!$C10="","",'Datos'!$C10),"") -> Entrantes | D10: =IFERROR(IF('Datos'!$D10="","",'Datos'!$D10),"") -> 120 | E10: =IFERROR(IF('Datos'!$L10="","",'Datos'!$L10),"") -> 0.069364162 | F10: =IFERROR(IF('Datos'!$M10="","",'Datos'!$M10),"") -> 0.1 | G10: =IFERROR(IF(OR($E10="",$F10=""),"",IF($E10>=$F10,"Alta","Baja")),"") -> Baja | H10: =IFERROR(IF('Datos'!$H10="","",'Datos'!$H10),"") -> 0.28440367 | I10: =IFERROR(IF('Datos'!$O10="","",'Datos'!$O10),"") -> 0.30714746 | J10: =IFERROR(IF(OR($H10="",$I10=""),"",IF($H10<=$I10,"Bajo","Alto")),"") -> Bajo | K10: =IFERROR(IF(OR($G10="",$J10=""),"",IF(AND($G10="Alta",$J10="Bajo"),"Winner",IF(AND($G10="Baja",$J10="Alto"),"Loser","Marginal"))),"") -> Marginal | L10: =IFERROR(IF($K10="","",IF($K10="Winner","Popular y con el food cost por debajo de la media de su familia.",IF($K10="Marginal","Cumple en una sola de las dos: o vende, o tiene el food cost sano.","Poco pedido y con el food cost por encima de su familia."))),"") -> Cumple en una sola de las dos: o vende, o tiene el food cost sano. | M10: =IFERROR(IF($K10="","",IF($K10="Winner","Mantener y proteger el escandallo: es el que aguanta una subida del proveedor.",IF($K10="Marginal","Mirar las otras lecturas antes de tocarlo: el problema es de precio o es de carta.","Reformular la receta o retirarlo de la carta."))),"") -> Mirar las otras lecturas antes de tocarlo: el problema es de precio o es de carta.
A11: 7 | B11: =IFERROR(IF('Datos'!$B11="","",'Datos'!$B11),"") -> Sopa de tomate asado con albahaca | C11: =IFERROR(IF('Datos'!$C11="","",'Datos'!$C11),"") -> Entrantes | D11: =IFERROR(IF('Datos'!$D11="","",'Datos'!$D11),"") -> 150 | E11: =IFERROR(IF('Datos'!$L11="","",'Datos'!$L11),"") -> 0.086705202 | F11: =IFERROR(IF('Datos'!$M11="","",'Datos'!$M11),"") -> 0.1 | G11: =IFERROR(IF(OR($E11="",$F11=""),"",IF($E11>=$F11,"Alta","Baja")),"") -> Baja | H11: =IFERROR(IF('Datos'!$H11="","",'Datos'!$H11),"") -> 0.16666667 | I11: =IFERROR(IF('Datos'!$O11="","",'Datos'!$O11),"") -> 0.30714746 | J11: =IFERROR(IF(OR($H11="",$I11=""),"",IF($H11<=$I11,"Bajo","Alto")),"") -> Bajo | K11: =IFERROR(IF(OR($G11="",$J11=""),"",IF(AND($G11="Alta",$J11="Bajo"),"Winner",IF(AND($G11="Baja",$J11="Alto"),"Loser","Marginal"))),"") -> Marginal | L11: =IFERROR(IF($K11="","",IF($K11="Winner","Popular y con el food cost por debajo de la media de su familia.",IF($K11="Marginal","Cumple en una sola de las dos: o vende, o tiene el food cost sano.","Poco pedido y con el food cost por encima de su familia."))),"") -> Cumple en una sola de las dos: o vende, o tiene el food cost sano. | M11: =IFERROR(IF($K11="","",IF($K11="Winner","Mantener y proteger el escandallo: es el que aguanta una subida del proveedor.",IF($K11="Marginal","Mirar las otras lecturas antes de tocarlo: el problema es de precio o es de carta.","Reformular la receta o retirarlo de la carta."))),"") -> Mirar las otras lecturas antes de tocarlo: el problema es de precio o es de carta.
