Workbook

Sheet Instrucciones
A1: Plan de Acción a 90 Días
A2: AI Chef Pro · aichef.pro — Guía Food Cost + Ingeniería de Menú
A4: Instrucciones de uso
A5: 1. Abre «Decisiones» y vuelca ahí lo que han dicho las otras herramientas del pack: qué plato, de qué hoja sale y qué se decide hacer con él.
A6: 2. Ponle a cada decisión un responsable con nombre y apellido y una semana del plan (1-13). La «Fecha objetivo» la calcula el libro solo desde la «Fecha de inicio del plan» de la celda verde D36: una decisión sin dueño y sin fecha no se ejecuta.
A7: 3. Estima el impacto en euros al mes. No hace falta precisión: hace falta orden de magnitud para saber por dónde empezar.
A8: 4. Cambia el «Estado» según avances. El libro cuenta cuántas has cerrado, cuánto impacto llevas conseguido y cuánto queda pendiente.
A9: 5. En «Calendario 90 Días» tienes 13 semanas con dos hitos cada una. Son una propuesta: reescríbelos con lo que toque en tu casa.
A10: 6. Marca «Hecho» = Sí a medida que cierras hitos; el avance del plan y el de cada bloque se calculan solos.
A11: 7. En «KPI de Seguimiento» anota la foto del mes 0 y luego los meses 1, 2 y 3. La lectura te dice si cada KPI mejora o empeora.
A12: 8. A los 90 días, vuelve a la matriz con las ventas nuevas: los platos habrán cambiado de casilla y el ciclo empieza otra vez.
A14: Celdas verdes = campos editables
... A32: Versión 1.0 · septiembre 2026 · aichef.pro/guia-food-cost-ingenieria-menu · info@aichef.pro

Sheet Decisiones
A1: Decisiones — qué se hace, quién y cuándo
A2: AI Chef Pro · aichef.pro — Guía Food Cost + Ingeniería de Menú
E3: Cada fila sale de una hoja del pack. Sin responsable y sin fecha, no es una decisión: es una opinión.
A4: # | B4: Plato o área | C4: Herramienta de origen | D4: Decisión | E4: Responsable | F4: Semana del plan | G4: Fecha objetivo | H4: Estado | I4: Impacto estimado (€/mes) | J4: Impacto ya conseguido (€/mes) | K4: Notas
A5: 1 | B5: Gambas al ajillo (E3) | C5: Matriz multi-método | D5: Revisar | E5: Gerente | F5: 2 | G5: =IFERROR(IF(OR($F5="",$D$36=""),"",$D$36+7*($F5-1)),"") -> 46273 | H5: Pendiente | I5: 180 | J5: =IFERROR(IF(OR($B5="",$I5=""),"",IF($H5="Hecha",$I5,0)),"") -> 0
A6: 2 | B6: Chuletón de vaca madurada (P5) | C6: Matriz multi-método | D6: Rediseñar | E6: Jefe de cocina | F6: 1 | G6: =IFERROR(IF(OR($F6="",$D$36=""),"",$D$36+7*($F6-1)),"") -> 46266 | H6: Pendiente | I6: 260 | J6: =IFERROR(IF(OR($B6="",$I6=""),"",IF($H6="Hecha",$I6,0)),"") -> 0
A7: 3 | B7: Tabla de quesos (E5) | C7: Matriz multi-método | D7: Rediseñar | E7: Gerente | F7: 4 | G7: =IFERROR(IF(OR($F7="",$D$36=""),"",$D$36+7*($F7-1)),"") -> 46287 | H7: Pendiente | I7: 140 | J7: =IFERROR(IF(OR($B7="",$I7=""),"",IF($H7="Hecha",$I7,0)),"") -> 0
A8: 4 | B8: Lasaña de verduras (P8) | C8: Matriz multi-método | D8: Revisar | E8: Jefe de cocina | F8: 3 | G8: =IFERROR(IF(OR($F8="",$D$36=""),"",$D$36+7*($F8-1)),"") -> 46280 | H8: Pendiente | I8: 120 | J8: =IFERROR(IF(OR($B8="",$I8=""),"",IF($H8="Hecha",$I8,0)),"") -> 0
A9: 5 | B9: Fruta de temporada (D4) | C9: Matriz multi-método | D9: Retirar | E9: Jefe de cocina | F9: 3 | G9: =IFERROR(IF(OR($F9="",$D$36=""),"",$D$36+7*($F9-1)),"") -> 46280 | H9: Pendiente | I9: 60 | J9: =IFERROR(IF(OR($B9="",$I9=""),"",IF($H9="Hecha",$I9,0)),"") -> 0
A10: 6 | B10: Lubina a la sal (P6) en delivery | C10: Simulador multicanal | D10: Retirar | E10: Gerente | F10: 2 | G10: =IFERROR(IF(OR($F10="",$D$36=""),"",$D$36+7*($F10-1)),"") -> 46273 | H10: Pendiente | I10: 90 | J10: =IFERROR(IF(OR($B10="",$I10=""),"",IF($H10="Hecha",$I10,0)),"") -> 0
A11: 7 | B11: Chuletón (P5) en delivery | C11: Simulador multicanal | D11: Retirar | E11: Gerente | F11: 2 | G11: =IFERROR(IF(OR($F11="",$D$36=""),"",$D$36+7*($F11-1)),"") -> 46273 | H11: Pendiente | I11: 140 | J11: =IFERROR(IF(OR($B11="",$I11=""),"",IF($H11="Hecha",$I11,0)),"") -> 0
A12: 8 | B12: Pescado entero: cambiar a lomos | C12: Test de rendimiento | D12: Negociar | E12: Jefe de compras | F12: 5 | G12: =IFERROR(IF(OR($F12="",$D$36=""),"",$D$36+7*($F12-1)),"") -> 46294 | H12: Pendiente | I12: 260 | J12: =IFERROR(IF(OR($B12="",$I12=""),"",IF($H12="Hecha",$I12,0)),"") -> 0
A13: 9 | B13: Copa de crianza: PVP | C13: Carta de bebidas | D13: Resubir | E13: Jefe de sala | F13: 2 | G13: =IFERROR(IF(OR($F13="",$D$36=""),"",$D$36+7*($F13-1)),"") -> 46273 | H13: Pendiente | I13: 210 | J13: =IFERROR(IF(OR($B13="",$I13=""),"",IF($H13="Hecha",$I13,0)),"") -> 0
A14: 10 | B14: Cuadrante de sala en meses bajos | C14: Cuadro de mando prime cost | D14: Reformular | E14: Gerente | F14: 6 | G14: =IFERROR(IF(OR($F14="",$D$36=""),"",$D$36+7*($F14-1)),"") -> 46301 | H14: Pendiente | I14: 900 | J14: =IFERROR(IF(OR($B14="",$I14=""),"",IF($H14="Hecha",$I14,0)),"") -> 0
A15: 11 | G15: =IFERROR(IF(OR($F15="",$D$36=""),"",$D$36+7*($F15-1)),"") | J15: =IFERROR(IF(OR($B15="",$I15=""),"",IF($H15="Hecha",$I15,0)),"")
A16: 12 | G16: =IFERROR(IF(OR($F16="",$D$36=""),"",$D$36+7*($F16-1)),"") | J16: =IFERROR(IF(OR($B16="",$I16=""),"",IF($H16="Hecha",$I16,0)),"")
A17: 13 | G17: =IFERROR(IF(OR($F17="",$D$36=""),"",$D$36+7*($F17-1)),"") | J17: =IFERROR(IF(OR($B17="",$I17=""),"",IF($H17="Hecha",$I17,0)),"")
A18: 14 | G18: =IFERROR(IF(OR($F18="",$D$36=""),"",$D$36+7*($F18-1)),"") | J18: =IFERROR(IF(OR($B18="",$I18=""),"",IF($H18="Hecha",$I18,0)),"")
A19: 15 | G19: =IFERROR(IF(OR($F19="",$D$36=""),"",$D$36+7*($F19-1)),"") | J19: =IFERROR(IF(OR($B19="",$I19=""),"",IF($H19="Hecha",$I19,0)),"")
A20: 16 | G20: =IFERROR(IF(OR($F20="",$D$36=""),"",$D$36+7*($F20-1)),"") | J20: =IFERROR(IF(OR($B20="",$I20=""),"",IF($H20="Hecha",$I20,0)),"")
A21: 17 | G21: =IFERROR(IF(OR($F21="",$D$36=""),"",$D$36+7*($F21-1)),"") | J21: =IFERROR(IF(OR($B21="",$I21=""),"",IF($H21="Hecha",$I21,0)),"")
A22: 18 | G22: =IFERROR(IF(OR($F22="",$D$36=""),"",$D$36+7*($F22-1)),"") | J22: =IFERROR(IF(OR($B22="",$I22=""),"",IF($H22="Hecha",$I22,0)),"")
A23: 19 | G23: =IFERROR(IF(OR($F23="",$D$36=""),"",$D$36+7*($F23-1)),"") | J23: =IFERROR(IF(OR($B23="",$I23=""),"",IF($H23="Hecha",$I23,0)),"")
A24: 20 | G24: =IFERROR(IF(OR($F24="",$D$36=""),"",$D$36+7*($F24-1)),"") | J24: =IFERROR(IF(OR($B24="",$I24=""),"",IF($H24="Hecha",$I24,0)),"")
A26: RESUMEN Y PARÁMETROS — lo calcula el libro
B27: Decisiones registradas | D27: =COUNTIF($B$5:$B$24,"<>") -> 10
B28: Decisiones cerradas (estado «Hecha») | D28: =COUNTIF($H$5:$H$24,"Hecha") -> 0
B29: Decisiones descartadas | D29: =COUNTIF($H$5:$H$24,"Descartada") -> 0
B30: Decisiones cerradas (%) | D30: =IFERROR(IF($D$27=0,"",$D$28/$D$27),"") -> 0
B31: IMPACTO TOTAL ESTIMADO (€/mes) | D31: =IFERROR(SUM($I$5:$I$24),"") -> 2360
B32: Impacto ya conseguido (€/mes) | D32: =IFERROR(SUMIF($H$5:$H$24,"Hecha",$I$5:$I$24),"") -> 0
B33: Impacto pendiente (€/mes) | D33: =IFERROR(IF(OR($D$31="",$D$32=""),"",$D$31-$D$32),"") -> 2360
B34: Impacto total estimado a 12 meses (€) | D34: =IFERROR(IF($D$31="","",$D$31*12),"") -> 28320
B35: Objetivo de cierre a 90 días (%) | D35: 0.8 | F35: Qué parte de las decisiones te comprometes a cerrar en el trimestre. Si el porcentaje cerrado se queda por debajo, la celda se pone en rojo.
B36: Fecha de inicio del plan | D36: 46266 | F36: La semana 1 empieza este día; de aquí salen las fechas objetivo de las decisiones y del calendario. Cámbiala por tu fecha real.
A37: RESUMEN POR TIPO DE DECISIÓN — lo calcula el libro
B38: Decisión | C38: Decisiones | D38: Impacto estimado (€/mes) | E38: Impacto conseguido (€/mes)
B39: Reformular | C39: =COUNTIF($D$5:$D$24,$B39) -> 1 | D39: =IFERROR(SUMIF($D$5:$D$24,$B39,$I$5:$I$24),"") -> 900 | E39: =IFERROR(SUMPRODUCT(--($D$5:$D$24=$B39),--($H$5:$H$24="Hecha"),$I$5:$I$24),"") -> 0
B40: Resubir | C40: =COUNTIF($D$5:$D$24,$B40) -> 1 | D40: =IFERROR(SUMIF($D$5:$D$24,$B40,$I$5:$I$24),"") -> 210 | E40: =IFERROR(SUMPRODUCT(--($D$5:$D$24=$B40),--($H$5:$H$24="Hecha"),$I$5:$I$24),"") -> 0
B41: Rediseñar | C41: =COUNTIF($D$5:$D$24,$B41) -> 2 | D41: =IFERROR(SUMIF($D$5:$D$24,$B41,$I$5:$I$24),"") -> 400 | E41: =IFERROR(SUMPRODUCT(--($D$5:$D$24=$B41),--($H$5:$H$24="Hecha"),$I$5:$I$24),"") -> 0
...

Sheet Calendario 90 Días
A1: Calendario a 90 días — 13 semanas, dos hitos por semana
A2: AI Chef Pro · aichef.pro — Guía Food Cost + Ingeniería de Menú
C3: Medir · escandallar y clasificar · aplicar · medir el efecto · revisar. Los hitos son una propuesta: reescríbelos con lo que toque en tu casa.
A4: Semana | B4: Bloque | C4: Hito | D4: Responsable | E4: Fecha objetivo | F4: Hecho | G4: Nota
A5: 1 | B5: Medir | C5: Sacar el informe de ventas por plato del último mes y volcarlo en la hoja «Datos» de la matriz. | D5: Gerente | E5: =IFERROR(IF(OR($A5="",'Decisiones'!$D$36=""),"",'Decisiones'!$D$36+7*($A5-1)),"") -> 46266 | F5: No
A6: 1 | B6: Medir | C6: Hacer inventario de cierre y anotar stock inicial, compras y stock final del mes. | D6: Jefe de cocina | E6: =IFERROR(IF(OR($A6="",'Decisiones'!$D$36=""),"",'Decisiones'!$D$36+7*($A6-1)),"") -> 46266 | F6: No
A7: 2 | B7: Medir | C7: Test de rendimiento de los 10 productos que más pesan en la compra, con báscula y hoja de rendimiento. | D7: Jefe de cocina | E7: =IFERROR(IF(OR($A7="",'Decisiones'!$D$36=""),"",'Decisiones'!$D$36+7*($A7-1)),"") -> 46273 | F7: No
A8: 2 | B8: Medir | C8: Medir la merma de cocción de las cinco elaboraciones que más se venden. | D8: Jefe de cocina | E8: =IFERROR(IF(OR($A8="",'Decisiones'!$D$36=""),"",'Decisiones'!$D$36+7*($A8-1)),"") -> 46273 | F8: No
A9: 3 | B9: Escandallar y clasificar | C9: Escandallar los platos de más venta con las mermas MEDIDAS, no con las de referencia. | D9: Jefe de cocina | E9: =IFERROR(IF(OR($A9="",'Decisiones'!$D$36=""),"",'Decisiones'!$D$36+7*($A9-1)),"") -> 46280 | F9: No
A10: 3 | B10: Escandallar y clasificar | C10: Rellenar coste por ración y PVP sin IVA de toda la carta en la matriz multi-método. | D10: Gerente | E10: =IFERROR(IF(OR($A10="",'Decisiones'!$D$36=""),"",'Decisiones'!$D$36+7*($A10-1)),"") -> 46280 | F10: No
A11: 4 | B11: Escandallar y clasificar | C11: Leer las cuatro clasificaciones y la hoja «Comparativa» plato a plato. | D11: Gerente | E11: =IFERROR(IF(OR($A11="",'Decisiones'!$D$36=""),"",'Decisiones'!$D$36+7*($A11-1)),"") -> 46287 | F11: No
A12: 4 | B12: Escandallar y clasificar | C12: Pasar a la hoja «Decisiones» los platos con tres o cuatro lecturas fuera de la mejor categoría. | D12: Gerente | E12: =IFERROR(IF(OR($A12="",'Decisiones'!$D$36=""),"",'Decisiones'!$D$36+7*($A12-1)),"") -> 46287 | F12: No
A13: 5 | B13: Aplicar decisiones | C13: Aplicar las subidas de precio decididas y reimprimir la carta. | D13: Gerente | E13: =IFERROR(IF(OR($A13="",'Decisiones'!$D$36=""),"",'Decisiones'!$D$36+7*($A13-1)),"") -> 46294 | F13: No
A14: 5 | B14: Aplicar decisiones | C14: Explicar a sala los cambios de precio y qué platos hay que sugerir. | D14: Jefe de sala | E14: =IFERROR(IF(OR($A14="",'Decisiones'!$D$36=""),"",'Decisiones'!$D$36+7*($A14-1)),"") -> 46294 | F14: No
A15: 6 | B15: Aplicar decisiones | C15: Reformular las recetas marcadas: ficha de escandallo nueva y prueba en cocina. | D15: Jefe de cocina | E15: =IFERROR(IF(OR($A15="",'Decisiones'!$D$36=""),"",'Decisiones'!$D$36+7*($A15-1)),"") -> 46301 | F15: No
A16: 6 | B16: Aplicar decisiones | C16: Negociar con los proveedores de las tres partidas que más pesan en la compra. | D16: Jefe de compras | E16: =IFERROR(IF(OR($A16="",'Decisiones'!$D$36=""),"",'Decisiones'!$D$36+7*($A16-1)),"") -> 46301 | F16: No
... A30: 13 | B30: Revisión | C30: Decidir el trimestre siguiente: qué se mantiene, qué se repite y qué entra nuevo. | D30: Gerente | E30: =IFERROR(IF(OR($A30="",'Decisiones'!$D$36=""),"",'Decisiones'!$D$36+7*($A30-1)),"") -> 46350 | F30: No
A32: RESUMEN — lo calcula el libro
C33: Hitos registrados | D33: =COUNTIF($C$5:$C$30,"<>") -> 26
C34: Hitos hechos | D34: =COUNTIF($F$5:$F$30,"Sí") -> 0
C35: Hitos pendientes | D35: =IFERROR(IF(OR($D$33="",$D$34=""),"",$D$33-$D$34),"") -> 26
C36: AVANCE DEL CALENDARIO (%) | D36: =IFERROR(IF($D$33=0,"",$D$34/$D$33),"") -> 0
A38: AVANCE POR BLOQUE — lo calcula el libro
C39: Bloque | D39: Hitos | E39: Hechos | F39: Avance (%)
C40: Medir | D40: =COUNTIF($B$5:$B$30,$C40) -> 4 | E40: =IFERROR(SUMPRODUCT(--($B$5:$B$30=$C40),--($F$5:$F$30="Sí")),"") -> 0 | F40: =IFERROR(IF($D40=0,"",$E40/$D40),"") -> 0
C41: Escandallar y clasificar | D41: =COUNTIF($B$5:$B$30,$C41) -> 4 | E41: =IFERROR(SUMPRODUCT(--($B$5:$B$30=$C41),--($F$5:$F$30="Sí")),"") -> 0 | F41: =IFERROR(IF($D41=0,"",$E41/$D41),"") -> 0
C42: Aplicar decisiones | D42: =COUNTIF($B$5:$B$30,$C42) -> 8 | E42: =IFERROR(SUMPRODUCT(--($B$5:$B$30=$C42),--($F$5:$F$30="Sí")),"") -> 0 | F42: =IFERROR(IF($D42=0,"",$E42/$D42),"") -> 0
C43: Medir el efecto | D43: =COUNTIF($B$5:$B$30,$C43) -> 8 | E43: =IFERROR(SUMPRODUCT(--($B$5:$B$30=$C43),--($F$5:$F$30="Sí")),"") -> 0 | F43: =IFERROR(IF($D43=0,"",$E43/$D43),"") -> 0
C44: Revisión | D44: =COUNTIF($B$5:$B$30,$C44) -> 2 | E44: =IFERROR(SUMPRODUCT(--($B$5:$B$30=$C44),--($F$5:$F$30="Sí")),"") -> 0 | F44: =IFERROR(IF($D44=0,"",$E44/$D44),"") -> 0
C46: Un plan recién abierto marca 0 % de avance: es lo correcto. El avance se gana marcando «Hecho» = Sí.

Sheet KPI de Seguimiento
A1: KPI de seguimiento — mes 0 contra mes 3
A2: AI Chef Pro · aichef.pro — Guía Food Cost + Ingeniería de Menú
C3: El mes 0 es la foto de salida. En los KPI en porcentaje la variación son PUNTOS porcentuales.
A4: KPI | B4: Mes 0 | C4: Mes 1 | D4: Mes 2 | E4: Mes 3 | F4: Variación mes 1 vs mes 0 | G4: Variación mes 2 vs mes 0 | H4: Variación mes 3 vs mes 0 | I4: ¿Bajar es bueno? | J4: Lectura mes 3 vs mes 0 | K4: Nota
A5: Food cost (%) | B5: 0.331 | C5: 0.322 | D5: 0.311 | E5: 0.298 | F5: =IFERROR(IF(OR($B5="",$C5=""),"",$C5-$B5),"") -> -0.009 | G5: =IFERROR(IF(OR($B5="",$D5=""),"",$D5-$B5),"") -> -0.02 | H5: =IFERROR(IF(OR($B5="",$E5=""),"",$E5-$B5),"") -> -0.033 | I5: Sí | J5: =IFERROR(IF(OR($B5="",$E5="",$I5=""),"",IF($H5=0,"Sin cambio",IF(OR(AND($I5="Sí",$H5<0),AND($I5="No",$H5>0)),"Mejora","Empeora"))),"") -> Mejora | K5: Coste de producto sobre ventas netas de comida. Objetivo de la casa en el cuadro de mando.
A6: Prime cost (%) | B6: 0.668 | C6: 0.661 | D6: 0.652 | E6: 0.638 | F6: =IFERROR(IF(OR($B6="",$C6=""),"",$C6-$B6),"") -> -0.007 | G6: =IFERROR(IF(OR($B6="",$D6=""),"",$D6-$B6),"") -> -0.016 | H6: =IFERROR(IF(OR($B6="",$E6=""),"",$E6-$B6),"") -> -0.03 | I6: Sí | J6: =IFERROR(IF(OR($B6="",$E6="",$I6=""),"",IF($H6=0,"Sin cambio",IF(OR(AND($I6="Sí",$H6<0),AND($I6="No",$H6>0)),"Mejora","Empeora"))),"") -> Mejora | K6: Producto + personal con Seguridad Social, sobre ventas netas.
A7: Ticket medio sin IVA (€) | B7: 27.4 | C7: 27.9 | D7: 28.6 | E7: 29.1 | F7: =IFERROR(IF(OR($B7="",$C7=""),"",$C7-$B7),"") -> 0.5 | G7: =IFERROR(IF(OR($B7="",$D7=""),"",$D7-$B7),"") -> 1.2 | H7: =IFERROR(IF(OR($B7="",$E7=""),"",$E7-$B7),"") -> 1.7 | I7: No | J7: =IFERROR(IF(OR($B7="",$E7="",$I7=""),"",IF($H7=0,"Sin cambio",IF(OR(AND($I7="Sí",$H7<0),AND($I7="No",$H7>0)),"Mejora","Empeora"))),"") -> Mejora | K7: Ventas netas ÷ cubiertos. Sube si la carta empuja bien.
A8: Margen de contribución por cubierto (€) | B8: 18.1 | C8: 18.6 | D8: 19.4 | E8: 20.2 | F8: =IFERROR(IF(OR($B8="",$C8=""),"",$C8-$B8),"") -> 0.5 | G8: =IFERROR(IF(OR($B8="",$D8=""),"",$D8-$B8),"") -> 1.3 | H8: =IFERROR(IF(OR($B8="",$E8=""),"",$E8-$B8),"") -> 2.1 | I8: No | J8: =IFERROR(IF(OR($B8="",$E8="",$I8=""),"",IF($H8=0,"Sin cambio",IF(OR(AND($I8="Sí",$H8<0),AND($I8="No",$H8>0)),"Mejora","Empeora"))),"") -> Mejora | K8: El euro que deja cada comensal para pagar personal, alquiler y luz.
A9: Platos en carta (n.º) | B9: 20 | C9: 20 | D9: 19 | E9: 18 | F9: =IFERROR(IF(OR($B9="",$C9=""),"",$C9-$B9),"") -> 0 | G9: =IFERROR(IF(OR($B9="",$D9=""),"",$D9-$B9),"") -> -1 | H9: =IFERROR(IF(OR($B9="",$E9=""),"",$E9-$B9),"") -> -2 | I9: Sí | J9: =IFERROR(IF(OR($B9="",$E9="",$I9=""),"",IF($H9=0,"Sin cambio",IF(OR(AND($I9="Sí",$H9<0),AND($I9="No",$H9>0)),"Mejora","Empeora"))),"") -> Mejora | K9: La poda es un objetivo, no un accidente. Cámbialo a «No» si tu plan es ampliar carta.
F10: =IFERROR(IF(OR($B10="",$C10=""),"",$C10-$B10),"") | G10: =IFERROR(IF(OR($B10="",$D10=""),"",$D10-$B10),"") | H10: =IFERROR(IF(OR($B10="",$E10=""),"",$E10-$B10),"") | J10: =IFERROR(IF(OR($B10="",$E10="",$I10=""),"",IF($H10=0,"Sin cambio",IF(OR(AND($I10="Sí",$H10<0),AND($I10="No",$H10>0)),"Mejora","Empeora"))),"")
F11: =IFERROR(IF(OR($B11="",$C11=""),"",$C11-$B11),"") | G11: =IFERROR(IF(OR($B11="",$D11=""),"",$D11-$B11),"") | H11: =IFERROR(IF(OR($B11="",$E11=""),"",$E11-$B11),"") | J11: =IFERROR(IF(OR($B11="",$E11="",$I11=""),"",IF($H11=0,"Sin cambio",IF(OR(AND($I11="Sí",$H11<0),AND($I11="No",$H11>0)),"Mejora","Empeora"))),"")
F12: =IFERROR(IF(OR($B12="",$C12=""),"",$C12-$B12),"") | G12: =IFERROR(IF(OR($B12="",$D12=""),"",$D12-$B12),"") | H12: =IFERROR(IF(OR($B12="",$E12=""),"",$E12-$B12),"") | J12: =IFERROR(IF(OR($B12="",$E12="",$I12=""),"",IF($H12=0,"Sin cambio",IF(OR(AND($I12="Sí",$H12<0),AND($I12="No",$H12>0)),"Mejora","Empeora"))),"")
A14: RESUMEN — lo calcula el libro
A15: KPI registrados | C15: =COUNTIF($A$5:$A$12,"<>") -> 5
A16: KPI QUE MEJORAN | C16: =COUNTIF($J$5:$J$12,"Mejora") -> 5
A17: KPI que empeoran | C17: =COUNTIF($J$5:$J$12,"Empeora") -> 0
A18: KPI sin cambio | C18: =COUNTIF($J$5:$J$12,"Sin cambio") -> 0
A19: KPI que mejoran (%) | C19: =IFERROR(IF($C$15=0,"",$C$16/$C$15),"") -> 1
A21: Los cuatro primeros KPI se leen juntos: un food cost que baja mientras el margen por cubierto también baja significa que has abaratado el plato, no que hayas ganado dinero.
A22: Las tres últimas filas están libres para los KPI de tu casa (rotación de mesas, ratio de bebida sobre comida, mermas en euros…). Marca en «¿Bajar es bueno?» el sentido de cada uno.
