Workbook

Sheet 0. Assumptions
A1: ASSUMPTIONS — the RATES and DRIVERS of the model are typed here
A2: Change the GREEN cells: the rest of the workbook recalculates on its own. Expense items are typed on their own tab (also in green) and are not repeated here. Amounts are in US dollars (or your own currency).
A3: BUSINESS ACTIVITY
A4: Events per year (year-1 average) | B4: 160 | C4: Average number of events you work per year, counting every wedding, corporate event and private party. It is the main volume driver of the whole workbook: the P&L, break-even and scenarios all read it, and years 2 and 3 grow in events. Compare it with the capacity row further down (max events a year your bars and crews can handle).
A5: Average price per guest (excl. sales tax and alcohol; bar package + add-ons) | B5: 14 | C5: Price per guest for a dry hire event (your client buys the alcohol; you bring the bar, the bartenders and everything else), EXCL. sales tax and excl. alcohol: the bar package plus add-ons, with bartenders, mixers, garnishes, ice and cups included, the service charge in and the voluntary gratuity out. Price per guest incl. sales tax = this value × (1 + your sales tax rate). At 95 guests, 14 per guest gives 1,330 per event: above Check Cherry's $750 median and in the upper quarter (the middle half runs $450-$1,275; see the benchmarks table on the "Instructions" tab). the Pricing Calculator builds your quote from your own costs and hours: divide its subtotal by the billable guests to bring it here.
A6: Average guests per event | B6: 95 | C6: Average number of guests per event across your whole mix, from private parties of about 60 to weddings of 120. Check Cherry booking data puts the typical event near 80 guests (see the benchmarks table on the "Instructions" tab). Sales per event = guests × price per guest. One cell for the whole workbook: the P&L, break-even and scenarios all read it, so they always agree.
A7: Volume growth in year 2 | B7: 0.1 | C7: Growth in events in year 2 over year 1 (enter 0.1 for 10%). Kept modest on purpose: two crews and a Saturday calendar cap how many events you can work, and weddings are booked about two months ahead, so referrals from venues and planners take a season to show up.
A8: Volume growth in year 3 | B8: 0.08 | C8: Growth in events in year 3 over year 2, kept conservative for the same reason: repeat corporate clients and planner referrals build up slowly.
A9: Price per guest incl. sales tax (calculated) | B9: =IFERROR(IF($B$5="","",$B$5*(1+SUMPRODUCT('3-Year P&L'!$E$10:$E$11,'3-Year P&L'!$G$10:$G$11))),"") -> 15.12 | C9: =IFERROR("Price per guest excl. sales tax plus the weighted sales tax of your sales lines ("&TEXT(SUMPRODUCT('3-Year P&L'!$E$10:$E$11,'3-Year P&L'!$G$10:$G$11)*100,"0")&"%), rounded. In the US the quote adds sales tax on top, and whether the bartending service and the service charge are taxable depends on the state (California taxes them); in the UK, VAT is included in the price.","") -> Price per guest excl. sales tax plus the weighted sales tax of your sales lines (8%), rounded. In the US the quote adds sales tax on top, and whether the bartending service and the service charge are taxable depends on the state (California taxes them); in the UK, VAT is included in the price.
A10: SALES MIX AND COST OF GOODS SOLD
A11: BAR PACKAGES share of sales (bartending service, bar, mixers, garnishes, ice) | B11: 0.85 | C11: Share of BAR PACKAGES in total sales: bartending service, bar, mixers, garnishes, ice and cups. It is an INPUT: change it here and the P&L, the cash flow and the sales tax collected recalculate on their own.
A12: ADD-ONS share of sales (travel fees, extra hours, glassware, specialty bars) | B12: =IFERROR(IF(COUNT(B11)=0,"",1-B11),"") -> 0.15 | C12: Calculated as the remainder: bar packages + add-ons = 100%. Add-ons are travel fees, extra hours of service, glassware, champagne service and specialty bars.
A13: Cost of goods on BAR PACKAGE sales (mixers, garnishes, ice, N/A drinks) | B13: 0.19 | C13: Cost of goods sold on bar package sales: mixers, garnishes, ice and non-alcoholic drinks (Kit estimate; see the ice and mixers row in the benchmarks table on the "Instructions" tab). There is no alcohol in it: in dry hire the host buys it. Test it at a higher rate (more fresh juice, more garnish) before you trust the result.
A14: Cost of goods on ADD-ON sales | B14: 0.2 | C14: Cost of goods sold on add-on sales: specialty bars, champagne service and rented extra glassware (Kit estimate). Set above the bar package rate because these items bring their own ingredients or rental fees. No alcohol: the host buys it.
A15: Cups, straws, napkins and bar disposables as % of sales | B15: 0.04 | C15: Cups, straws, napkins, coasters and the printed drink menu sign, as a % of sales (Kit estimate). It sits next to cost of goods sold instead of hiding in miscellaneous. Some cities and venues restrict single-use plastics, so check the rules and price compostable cups if you need them.
A16: Share of sales booked through gig marketplaces (GigSalad, The Bash, Thumbtack) | B16: 0.2 | C16: Share of your sales booked through gig marketplaces such as GigSalad, The Bash and Thumbtack, rather than by hosts and planners who book you directly. Set it to 0 if you only sell direct. The marketplace sends you the booking and keeps a fee (next row).
A17: Marketplace fee on those bookings | B17: 0.05 | C17: Fee the marketplace keeps on those bookings. GigSalad charges 5% of the confirmed booking on its free plan and 2.5% on the paid plan, and nothing per lead (gigsalad.com); Thumbtack charges per lead instead, so convert that cost to a % of booked sales. Fees change: check the current schedule when you sign up. Not used while the marketplace share is 0%.
A18: Card processing fee | B18: 0.03 | C18: Card fees on total sales. Hosts and planners mostly pay by card, with some ACH or check from companies, which lowers the cost. The example (3%) is a blended rate: a percentage plus a per-transaction fee, which weighs more on small deposits. Check your processor's statement and enter your effective rate (Kit estimate).
A19: LABOR
A20: Employer payroll taxes | B20: 0.1 | C20: FICA (Social Security 6.2% + Medicare 1.45%) + federal and state unemployment taxes (FUTA / SUTA). Workers' comp is in the insurance line. The example uses a lean 10% with no benefits; ask your payroll provider for your rate.
A21: Monthly pay periods per year (keep 12) | B21: 12 | C21: Annual gross pay = monthly gross pay × this number. Keep 12 in the US: it counts the monthly salaries the model pays in a year, not how often you run payroll (weekly or biweekly payroll pays the same annual amount)
A22: Federal minimum wage, annual full-time | B22: 15080 | C22: US federal minimum wage: 7.25 per hour × 2,080 hours = 15,080 per year for a full-time job. Your state or city may set a higher floor: enter it in the state / local minimum wage cell below. Check the current rates at dol.gov
A23: STORAGE, TRAILER PARKING AND FIXED COSTS
A24: Storage unit & trailer parking, per month | B24: 600 | C24: Monthly cost of the storage unit (or garage) where the bar, glassware and supplies live, plus the parking spot for the trailer. It is not storefront rent: you work at the host's venue. The deposit and the months before opening are calculated from this cell. If your county requires a commissary for ice or garnish, add it here (Kit estimate: +300-800 per month).
A25: Storage unit deposit (months) | B25: 1 | C25: Months of deposit on the storage unit. Many facilities ask for about one month up front: far less than the deposit on a commercial lease. Agree it in writing.
A26: Monthly utilities (storage unit power and water) | B26: 100 | C26: Electricity and water for the storage unit (lights, the wash area, charging), plus any utilities the storage rent does not cover. Fuel for the tow vehicle and the generator is not here: it is in the "Vehicle and trailer fuel, maintenance and registration" line of the "3-Year P&L". It is the one cell for this cost, so you change it in one place and the rest of the workbook follows.
A27: Insurance (per year) | B27: 4000 | C27: Yearly insurance: general liability plus liquor liability (Kit estimate 600-1,000), commercial auto covering the trailer (about 1,800), workers' comp for your W-2 bartenders (about 1,000) and equipment coverage (about 300). Venues ask for a COI naming them as additional insured, and general liability plus liquor liability start around $550 a year, bundled (insurancecanopy.com). The total is a Kit estimate: get quotes before you fix it.
A28: Miscellaneous and contingency as % of sales | B28: 0.03 | C28: Last-minute costs of each event: extra ice, mixers bought on the way, parking at the venue. It is a VARIABLE cost: it rises and falls with the number of events, so it cannot sit among the fixed costs or it would move the break-even without anyone noticing. Fuel, maintenance and registration of the tow vehicle and trailer have their own line in the P&L.
A29: FINANCING
A30: Owner's equity contributed | B30: 28000 | C30: Your own money. Lenders usually expect an owner equity injection (often around 10% for SBA start-ups; many want 20-30%) on the total cash needed in this plan.
A31: Loan requested | B31: 49000 | C31: Principal requested from your lender: an SBA 7(a) loan through your bank, or a small SBA Microloan (up to 50,000). This is the cell. It is the only loan that the amortization schedule, the P&L interest and the DSCR use. The "Financing" tab checks that the sources of funds match the total cash needed on the "Startup Costs" tab (which includes working capital and the trailer and fit-out contingency): copy the loan suggested there into this cell until the difference reaches zero.
A32: Nominal annual interest rate (not APR) | B32: 0.1 | C32: Nominal annual rate (not APR). The example (10%) is the kit's assumption for a small SBA loan. A smaller loan secured by a used trailer and bar equipment often prices above a storefront loan: ask two lenders for quotes, and ask about SBA-guaranteed loans, before you set it.
A33: Loan term (years) | B33: 7 | C33: Total years, interest-only period included. A trailer and bar equipment lose value faster than a storefront build-out, so the term is shorter. SBA 7(a) allows up to 10 years for equipment and working capital.
A34: Interest-only period (years) | B34: 0 | C34: ZERO by default: repayment starts in year 1, so the year-1 DSCR already measures the full loan payment. If you negotiate an interest-only first year, enter it here and read the year-1 DSCR with care.
A35: Working capital (months of fixed costs) | B35: 3 | C35: The minimum this workbook asks for (see "Instructions"): a cushion below 3 months does not cover a slow stretch, such as the off-season for weddings or a corporate client who pays late.
A36: TAXES
A37: Effective income tax rate (years 1-2) | B37: 0.25 | C37: Example: 21% federal rate for a C corporation plus state tax, rounded to 25%. If you operate as a sole proprietorship, LLC taxed as a pass-through or S corporation, the business itself pays 0% here and you pay tax on the profit personally: set this to 0 and budget for your personal tax separately. The model applies this rate to the first two years with positive taxable income
A38: Effective income tax rate (from year 3) | B38: 0.25 | C38: From the third year with positive taxable income. Same example rate (21% federal C corporation + state). Confirm the rate that applies to you with your accountant and change it here
A39: Sales tax rate on sales | B39: 0.08 | C39: Example rate: state + local sales tax combined, applied to the whole invoice (bar service, add-ons and service charge). Whether bartending services are taxable varies by state: California taxes them (cdtfa.ca.gov). UK: 20% VAT on the service.
A40: Sales tax rate on alcohol sold (licensed only) | B40: 0.08 | C40: Same example rate as above. Some states add separate liquor taxes: include them here if they apply to you. Alcohol served on site has its own rate in the sales tax breakdown block, further down. Utilities, equipment and services are handled in the cell below
...

Sheet Startup Costs
A1: BUSINESS PLAN: MOBILE BAR & EVENT BARTENDING
A2: Estimated Startup Costs
A3: US kit example (2026) — replace with your own quotes.
A5: Item | B5: Amount | C5: % of startup costs | D5: Notes | E5: Taxable / recoverable tax?
A6: STARTUP COSTS | B6: =IFERROR(IF(COUNT(B7:B23)=0,"",SUM(B7:B23)),"") -> 47530 | C6: =IFERROR(B6/$B$26,"") -> 0.61749647
A7: Bar trailer, used (6 x 12 ft (1.8 x 3.7 m) cargo / concession or horse trailer) | B7: 9000 | C7: =IFERROR(B7/$B$26,"") -> 0.11692548 | D7: A used bar trailer (6 x 12 ft (1.8 x 3.7 m) cargo, concession or horse trailer) that you convert. The tow vehicle is yours, so it costs 0 in the plan: if you do not have one, a used pickup is an extra purchase starting around $10,000 (checkcherry.com). Prices vary a lot with size and condition, so get several quotes. | E7: Yes
A8: Trailer conversion (bar top, cabinetry, hand sink, water tanks, LED, electrical) | B8: 12000 | C8: =IFERROR(B8/$B$26,"") -> 0.15590064 | D8: Bar top, cabinets, hand sink and fresh and gray water tanks, LED lighting and the electrical work. A basic conversion typically starts around 5,000 and a custom build costs several times more (Kit estimate). | E8: Yes
A9: Wrap, signage and bar facade | B9: 2500 | C9: =IFERROR(B9/$B$26,"") -> 0.032479301 | D9: Trailer wrap, signage and the bar facade: your rolling billboard at every venue and the first thing guests photograph. | E9: Yes
A10: Portable bar for the second crew and indoor venues | B10: 2000 | C10: =IFERROR(B10/$B$26,"") -> 0.025983441 | D10: A portable bar for the second crew and for indoor venues where the trailer does not fit. Basic units start around 1,000 (checkcherry.com); a nicer one with a lit back bar costs more. | E10: Yes
A11: Inverter generator and power | B11: 1800 | C11: =IFERROR(B11/$B$26,"") -> 0.023385097 | D11: A quiet inverter generator and the cabling, for venues without power. Typical range 800-3,000 (Kit estimate). | E11: Yes
A12: Storage unit fit-out (shelving, glass racks, wash station) | B12: 1000 | C12: =IFERROR(B12/$B$26,"") -> 0.01299172 | D12: Shelving, glassware racks and a wash area inside the storage unit. Ask the facility what it already provides before you budget this line. | E12: Yes
A13: LLC formation, contracts and legal | B13: 1500 | C13: =IFERROR(B13/$B$26,"") -> 0.019487581 | D13: State filing fees for the articles of organization (Secretary of State) plus any attorney or filing-service fees; a registered agent is also needed. Fees vary a lot by state. The "Taxable / recoverable tax?" column is set to No: it only matters if you enter a recoverable input tax rate (for example UK VAT). | E13: No
A14: First-year permits and certifications (business license, sales tax permit, TABC / RBS / TIPS) | B14: 1000 | C14: =IFERROR(B14/$B$26,"") -> 0.01299172 | D14: Business license, sales tax permit and responsible-service certifications (TABC in Texas, RBS in California, TIPS or ServSafe Alcohol) for year 1. It varies a lot by state and city: get the amounts for yours before you close the budget. | E14: No
A15: Health permit / unit inspection (only if your county requires it) | B15: 500 | C15: =IFERROR(B15/$B$26,"") -> 0.0064958602 | D15: Only if your county requires it: ask your county health department whether ice, cut garnish or the hand sink trigger a unit inspection. If not, enter 0. | E15: Yes
A16: Booking software, card reader and tablet | B16: 800 | C16: =IFERROR(B16/$B$26,"") -> 0.010393376 | D16: Booking software and CRM for proposals, contracts and deposits, plus a card reader and a tablet. | E16: Yes
A17: Bar tools and smallwares (4 stations) | B17: 1200 | C17: =IFERROR(B17/$B$26,"") -> 0.015590064 | D17: Shakers, jiggers, speed rails, strainers, ice scoops and bar mats for 4 stations: the equipment that gets depreciated. Daily disposables are NOT depreciated: they go in the disposables line of the P&L, at the % of sales set in "0. Assumptions". | E17: Yes
A18: Opening inventory (mixers, syrups, garnishes, cups, napkins) | B18: 1500 | C18: =IFERROR(B18/$B$26,"") -> 0.019487581 | D18: Mixers, syrups, garnishes, cups and napkins for your first events. No alcohol: in dry hire the host buys it. With 0% recoverable input tax (the US default), any sales tax you pay on this purchase is treated as a cost. | E18: Yes
... A20: Glassware (300 pieces + racks), coolers, ice bins and dispensers | B20: 3500 | C20: =IFERROR(B20/$B$26,"") -> 0.045471021 | D20: Glassware (300 pieces plus racks), coolers, ice bins and dispensers for events where the host does not rent glass. | E20: Yes
A21: Storage unit deposit | B21: =IFERROR(IF('0. Assumptions'!$B$24="","",'0. Assumptions'!$B$24*'0. Assumptions'!$B$25),"") -> 600 | C21: =IFERROR(B21/$B$26,"") -> 0.0077950322 | D21: =IFERROR(""&TEXT('0. Assumptions'!$B$25,"0")&IF('0. Assumptions'!$B$25=1," month"," months")&" of rent, from ""0. Assumptions"". Refundable when the storage unit lease ends: it is not depreciated and carries no tax","") -> 1 month of rent, from "0. Assumptions". Refundable when the storage unit lease ends: it is not depreciated and carries no tax | E21: No
A22: Storage rent before opening | B22: =IFERROR(IF('0. Assumptions'!$B$24="","",'0. Assumptions'!$B$24*'0. Assumptions'!$B$54),"") -> 1200 | C22: =IFERROR(B22/$B$26,"") -> 0.015590064 | D22: =IFERROR("Rent "&IF('0. Assumptions'!$B$54=1,"for the month","for the "&TEXT('0. Assumptions'!$B$54,"0")&" months")&" of trailer build, permits and pre-sales before opening. It does not overlap the P&L, which starts on opening day: its twelve months are twelve trading months","") -> Rent for the 2 months of trailer build, permits and pre-sales before opening. It does not overlap the P&L, which starts on opening day: its twelve months are twelve trading months | E22: Yes
A23: Trailer and fit-out contingency | B23: =IFERROR(IF(COUNT(B7,B8,B11,B12,B15)=0,"",ROUND((B7+B8+B11+B12+B15)*'0. Assumptions'!$B$55,0)),"") -> 2430 | C23: =IFERROR(B23/$B$26,"") -> 0.031569881 | D23: =IFERROR("At "&TEXT('0. Assumptions'!$B$55,"0%")&" of the BUILD-OUT items of this block (used bar trailer, trailer conversion, inverter generator, storage unit fit-out and the health permit / unit inspection), not of the whole block: the other items are left out. No lender funds a "&"build-out without a cushion: the percentage is in ""0. Assumptions""","") -> At 10% of the BUILD-OUT items of this block (used bar trailer, trailer conversion, inverter generator, storage unit fit-out and the health permit / unit inspection), not of the whole block: the other items are left out. No lender funds a build-out without a cushion: the percentage is in "0. Assumptions" | E23: Yes
A24: WORKING CAPITAL | B24: =IFERROR(IF(B25="","",B25),"") -> 29442.1 | C24: =IFERROR(B24/$B$26,"") -> 0.38250353
A25: Operating cushion until break-even | B25: =IFERROR(IF('0. Assumptions'!$B$35*('3-Year P&L'!$B$38-'3-Year P&L'!$B$36)=0,"",'0. Assumptions'!$B$35*('3-Year P&L'!$B$38-'3-Year P&L'!$B$36)/12),"") -> 29442.1 | C25: =IFERROR(B25/$B$26,"") -> 0.38250353 | D25: =IFERROR("Covers "&TEXT('0. Assumptions'!$B$35,"0")&IF('0. Assumptions'!$B$35=1," month"," months")&" of year-1 CASH fixed costs (the P&L fixed costs minus depreciation, which is not paid out), the minimum the Instructions of this workbook ask for","") -> Covers 3 months of year-1 CASH fixed costs (the P&L fixed costs minus depreciation, which is not paid out), the minimum the Instructions of this workbook ask for | E25: No
A26: TOTAL STARTUP COSTS (sum of the blocks) | B26: =IFERROR(B6+B24,"") -> 76972.1 | D26: =IFERROR("The percentages in column C are read on this figure, which includes the working capital ("&TEXT(C24,"0%")&" of the total). To compare the breakdown with another plan, use the CAPEX row below.","") -> The percentages in column C are read on this figure, which includes the working capital (38% of the total). To compare the breakdown with another plan, use the CAPEX row below.
A27: CAPEX (startup costs excluding working capital) | B27: =IFERROR(B26-B24,"") -> 47530 | D27: What you buy: trailer, conversion, equipment, launch and formation costs. The cash cushion is not an investment: it is working capital.
A28: Recoverable input tax on capex | B28: =IFERROR(IF(B26="","",SUMIF($E$7:$E$23,"Yes",$B$7:$B$23)*'0. Assumptions'!$B$41),"") -> 0 | D28: =IFERROR("At "&TEXT('0. Assumptions'!$B$41,"0%")&" on the items marked ""Yes"" in the tax column. US: the sales tax you pay on equipment is part of its cost and is not recovered, so this rate is 0. UK (VAT-registered): 20%, reclaimed on your VAT return, but you pay it first, so the loan has to cover it","") -> At 0% on the items marked "Yes" in the tax column. US: the sales tax you pay on equipment is part of its cost and is not recovered, so this rate is 0. UK (VAT-registered): 20%, reclaimed on your VAT return, but you pay it first, so the loan has to cover it
A29: TOTAL CASH NEEDED AT LAUNCH | B29: =IFERROR(B26+B28,"") -> 76972.1 | D29: This is the figure the Financing tab has to cover
A30: DEPRECIATION BASES (not added to startup costs)
A31: Trailer, conversion and fit-out (depreciated over the trailer life) | B31: =IFERROR(IF(B7="","",B7+B8+B11+B12+B15+B23),"") -> 26730 | D31: =IFERROR("Depreciated over "&TEXT('0. Assumptions'!$B$44,"0")&" years","") -> Depreciated over 7 years
A32: Machinery, furniture and equipment | B32: =IFERROR(IF(B9="","",B9+B10+B16+B17+B20),"") -> 10000 | D32: =IFERROR("Depreciated over "&TEXT('0. Assumptions'!$B$45,"0")&" years","") -> Depreciated over 5 years
A33: Annual depreciation of fixed assets | B33: =IFERROR(B31/MAX(1,'0. Assumptions'!$B$44)+B32/MAX(1,'0. Assumptions'!$B$45),"") -> 5818.5714 | D33: =IFERROR("Not depreciated, because they are not fixed assets: LLC formation and legal, first-year permits and certifications, opening inventory, website, photos and launch, the storage unit deposit, pre-opening storage rent and the working capital "&"reserve. They add up to "&TEXT(B26-B31-B32,"#,##0")&" of the "&TEXT(B26,"#,##0")&" total investment.","") -> Not depreciated, because they are not fixed assets: LLC formation and legal, first-year permits and certifications, opening inventory, website, photos and launch, the storage unit deposit, pre-opening storage rent and the working capital reserve. They add up to 40242 of the 76972 total investment.

Sheet 3-Year P&L
A1: PRO FORMA P&L — 3 YEARS
A2: Base case — mobile bar (dry hire)
A4: Item | B4: Year 1 | C4: Year 2 | D4: Year 3 | E4: % of sales (year 1) | F4: Notes | G4: Sales tax rate on the line (%)
A5: REVENUE
A6: Events per year (average) | B6: =IFERROR(IF('0. Assumptions'!$B$4="","",'0. Assumptions'!$B$4),"") -> 160 | C6: =IFERROR(B6*(1+'0. Assumptions'!$B$7),"") -> 176 | D6: =IFERROR(C6*(1+'0. Assumptions'!$B$8),"") -> 190.08 | F6: Growth for years 2 and 3 is set in "0. Assumptions"
A7: Average price per guest (excl. sales tax) | B7: =IFERROR(IF('0. Assumptions'!$B$5="","",'0. Assumptions'!$B$5),"") -> 14 | C7: =IFERROR(IF(B7="","",B7),"") -> 14 | D7: =IFERROR(IF(C7="","",C7),"") -> 14 | F7: Held constant at year-1 prices: a price increase is a separate decision
A8: Average guests per event | B8: =IFERROR(IF('0. Assumptions'!$B$6="","",'0. Assumptions'!$B$6),"") -> 95 | C8: =IFERROR(IF(B8="","",B8),"") -> 95 | D8: =IFERROR(IF(C8="","",C8),"") -> 95
A9: TOTAL REVENUE (excl. sales tax) | B9: =IFERROR(IF(B6*B7*B8=0,"",B6*B7*B8),"") -> 212800 | C9: =IFERROR(IF(C6*C7*C8=0,"",C6*C7*C8),"") -> 234080 | D9: =IFERROR(IF(D6*D7*D8=0,"",D6*D7*D8),"") -> 252806.4 | E9: =IFERROR(IF(B9="","",1),"") -> 1
A10: Bar package sales (bartending service, bar, mixers, garnishes, ice) | B10: =IFERROR(IF(B9="","",B9*$E$10),"") -> 180880 | C10: =IFERROR(IF(C9="","",C9*$E$10),"") -> 198968 | D10: =IFERROR(IF(D9="","",D9*$E$10),"") -> 214885.44 | E10: =IFERROR(IF('0. Assumptions'!$B$11="","",'0. Assumptions'!$B$11),"") -> 0.85 | F10: Bar package sales: bartending service, bar, mixers, garnishes, ice and cups per guest, for weddings, corporate events and private parties. No alcohol: the host buys it. All of it carries cost of goods sold at the bar package rate. | G10: =IFERROR(IF(B9="","",'0. Assumptions'!$B$39),"") -> 0.08
A11: Add-on sales (travel fees, extra hours, glassware, specialty bars) | B11: =IFERROR(IF(B9="","",B9*$E$11),"") -> 31920 | C11: =IFERROR(IF(C9="","",C9*$E$11),"") -> 35112 | D11: =IFERROR(IF(D9="","",D9*$E$11),"") -> 37920.96 | E11: =IFERROR(IF('0. Assumptions'!$B$12="","",'0. Assumptions'!$B$12),"") -> 0.15 | F11: Add-on sales: travel fees, extra hours of service, glassware, champagne service and specialty bars. They carry cost of goods sold at the add-on rate. | G11: =IFERROR(IF(B9="","",('0. Assumptions'!$B$62*((1-'0. Assumptions'!$B$16)*'0. Assumptions'!$B$63+'0. Assumptions'!$B$16*'0. Assumptions'!$B$40)+(1-'0. Assumptions'!$B$62)*'0. Assumptions'!$B$39)),"") -> 0.08
A12: VARIABLE COSTS
A13: Cost of goods — bar packages (mixers, garnishes, ice) | B13: =IFERROR(IF(B9="","",B9*'0. Assumptions'!$B$11*'0. Assumptions'!$B$13),"") -> 34367.2 | C13: =IFERROR(IF(C9="","",C9*'0. Assumptions'!$B$11*'0. Assumptions'!$B$13),"") -> 37803.92 | D13: =IFERROR(IF(D9="","",D9*'0. Assumptions'!$B$11*'0. Assumptions'!$B$13),"") -> 40828.234 | E13: =IFERROR(B13/$B$9,"") -> 0.1615 | F13: =IFERROR("At "&TEXT('0. Assumptions'!$B$13,"0%")&" of BAR PACKAGE sales (mixers, garnishes, ice), not of total sales: add-ons have their own line","") -> At 19% of BAR PACKAGE sales (mixers, garnishes, ice), not of total sales: add-ons have their own line | G13: =IFERROR(IF(B9="","",'0. Assumptions'!$B$41),"") -> 0
A14: Cost of goods — add-ons | B14: =IFERROR(IF(B9="","",B9*'0. Assumptions'!$B$12*'0. Assumptions'!$B$14),"") -> 6384 | C14: =IFERROR(IF(C9="","",C9*'0. Assumptions'!$B$12*'0. Assumptions'!$B$14),"") -> 7022.4 | D14: =IFERROR(IF(D9="","",D9*'0. Assumptions'!$B$12*'0. Assumptions'!$B$14),"") -> 7584.192 | E14: =IFERROR(B14/$B$9,"") -> 0.03 | F14: =IFERROR("At "&TEXT('0. Assumptions'!$B$14,"0%")&" of ADD-ON sales","") -> At 20% of ADD-ON sales | G14: =IFERROR(IF(B9="","",'0. Assumptions'!$B$41),"") -> 0
A15: Cups, straws, napkins and bar disposables | B15: =IFERROR(IF(B9="","",B9*'0. Assumptions'!$B$15),"") -> 8512 | C15: =IFERROR(IF(C9="","",C9*'0. Assumptions'!$B$15),"") -> 9363.2 | D15: =IFERROR(IF(D9="","",D9*'0. Assumptions'!$B$15),"") -> 10112.256 | E15: =IFERROR(B15/$B$9,"") -> 0.04 | G15: =IFERROR(IF(B9="","",'0. Assumptions'!$B$41),"") -> 0
A16: Gig marketplace fees | B16: =IFERROR(IF(B9="","",B9*'0. Assumptions'!$B$16*'0. Assumptions'!$B$17),"") -> 2128 | C16: =IFERROR(IF(C9="","",C9*'0. Assumptions'!$B$16*'0. Assumptions'!$B$17),"") -> 2340.8 | D16: =IFERROR(IF(D9="","",D9*'0. Assumptions'!$B$16*'0. Assumptions'!$B$17),"") -> 2528.064 | E16: =IFERROR(B16/$B$9,"") -> 0.01 | F16: Applied to the sales of THAT CHANNEL. With 0% marketplace sales in "0. Assumptions", this line is zero. | G16: =IFERROR(IF(B9="","",'0. Assumptions'!$B$41),"") -> 0
A17: Card processing fees | B17: =IFERROR(IF(B9="","",B9*'0. Assumptions'!$B$18),"") -> 6384 | C17: =IFERROR(IF(C9="","",C9*'0. Assumptions'!$B$18),"") -> 7022.4 | D17: =IFERROR(IF(D9="","",D9*'0. Assumptions'!$B$18),"") -> 7584.192 | E17: =IFERROR(B17/$B$9,"") -> 0.03 | F17: Card processing fees are not subject to sales tax: no tax is recovered or deducted for them | G17: 0
A18: Miscellaneous and contingency | B18: =IFERROR(IF(B9="","",B9*'0. Assumptions'!$B$28),"") -> 6384 | C18: =IFERROR(IF(C9="","",C9*'0. Assumptions'!$B$28),"") -> 7022.4 | D18: =IFERROR(IF(D9="","",D9*'0. Assumptions'!$B$28),"") -> 7584.192 | E18: =IFERROR(B18/$B$9,"") -> 0.03 | F18: =IFERROR("At "&TEXT('0. Assumptions'!$B$28,"0%")&" of sales: a cushion for unbudgeted event costs (extra ice, last-minute mixers, venue parking). It is a VARIABLE cost: it moves with the number of events, so it cannot sit in fixed costs (fuel, maintenance and registration of the tow "&"vehicle and the trailer are in row 27)","") -> At 3% of sales: a cushion for unbudgeted event costs (extra ice, last-minute mixers, venue parking). It is a VARIABLE cost: it moves with the number of events, so it cannot sit in fixed costs (fuel, maintenance and registration of the tow vehicle and the trailer are in row 27) | G18: =IFERROR(IF(B9="","",'0. Assumptions'!$B$41),"") -> 0
A19: TOTAL VARIABLE COSTS | B19: =IFERROR(IF(B9="","",SUM(B13:B18)),"") -> 64159.2 | C19: =IFERROR(IF(C9="","",SUM(C13:C18)),"") -> 70575.12 | D19: =IFERROR(IF(D9="","",SUM(D13:D18)),"") -> 76221.13 | E19: =IFERROR(B19/$B$9,"") -> 0.3015
A20: GROSS MARGIN | B20: =IFERROR(IF(B9="","",B9-B19),"") -> 148640.8 | C20: =IFERROR(IF(C9="","",C9-C19),"") -> 163504.88 | D20: =IFERROR(IF(D9="","",D9-D19),"") -> 176585.27 | E20: =IFERROR(B20/$B$9,"") -> 0.6985
A21: FIXED COSTS
A22: Storage unit & trailer parking | B22: =IFERROR(IF(B9="","",'0. Assumptions'!$B$24*12),"") -> 7200 | C22: =IFERROR(IF(C9="","",B22*(1+'0. Assumptions'!$B$48)),"") -> 7200 | D22: =IFERROR(IF(D9="","",C22*(1+'0. Assumptions'!$B$48)),"") -> 7200 | E22: =IFERROR(B22/$B$9,"") -> 0.033834586 | F22: The monthly amount is typed in "0. Assumptions"; here it is multiplied by twelve. It covers your storage unit and the parking spot for the trailer, not storefront rent. The months before opening are on the "Startup Costs" tab and are NOT counted twice. | G22: =IFERROR(IF(B9="","",'0. Assumptions'!$B$41),"") -> 0
A23: Labor (wages + employer payroll taxes) | B23: =IFERROR(IF(B9="","",Staffing!$G$9),"") -> 78368.4 | C23: =IFERROR(IF(C9="","",Staffing!$B$13),"") -> 81368.4 | D23: =IFERROR(IF(D9="","",Staffing!$B$14),"") -> 84368.4 | E23: =IFERROR(B23/$B$9,"") -> 0.36827256 | F23: Comes from the Staffing tab: it is the SAME number, not a separate estimate. Years 2 and 3 add the new hires declared on that tab, not a percentage of volume | G23: 0
A24: Utilities (storage unit power and water) | B24: =IFERROR(IF(B9="","",'0. Assumptions'!$B$26*12),"") -> 1200 | C24: =IFERROR(IF(C9="","",B24*(1+'0. Assumptions'!$B$48)),"") -> 1200 | D24: =IFERROR(IF(D9="","",C24*(1+'0. Assumptions'!$B$48)),"") -> 1200 | E24: =IFERROR(B24/$B$9,"") -> 0.0056390977 | F24: Electricity and water for the storage unit, plus any utilities the storage rent does not cover. Fuel for the tow vehicle and the generator is in the vehicle and trailer line. | G24: =IFERROR(IF(B9="","",'0. Assumptions'!$B$41),"") -> 0
A25: Insurance (general and liquor liability, auto, workers' comp) | B25: =IFERROR(IF(B9="","",'0. Assumptions'!$B$27),"") -> 4000 | C25: =IFERROR(IF(C9="","",B25*(1+'0. Assumptions'!$B$48)),"") -> 4000 | D25: =IFERROR(IF(D9="","",C25*(1+'0. Assumptions'!$B$48)),"") -> 4000 | E25: =IFERROR(B25/$B$9,"") -> 0.018796992 | F25: Insurance premiums are not subject to sales tax: there is no recoverable tax on them | G25: 0
A26: Permits and certifications renewal | B26: 500 | C26: =IFERROR(IF(C9="","",B26*(1+'0. Assumptions'!$B$48)),"") -> 500 | D26: =IFERROR(IF(D9="","",C26*(1+'0. Assumptions'!$B$48)),"") -> 500 | E26: =IFERROR(B26/$B$9,"") -> 0.0023496241 | G26: =IFERROR(IF(B9="","",'0. Assumptions'!$B$41),"") -> 0
A27: Vehicle and trailer fuel, maintenance and registration | B27: 4000 | C27: =IFERROR(IF(C9="","",B27*(1+'0. Assumptions'!$B$48)),"") -> 4000 | D27: =IFERROR(IF(D9="","",C27*(1+'0. Assumptions'!$B$48)),"") -> 4000 | E27: =IFERROR(B27/$B$9,"") -> 0.018796992 | G27: =IFERROR(IF(B9="","",'0. Assumptions'!$B$41),"") -> 0
A28: Marketing and advertising | B28: 9000 | C28: =IFERROR(IF(C9="","",B28*(1+'0. Assumptions'!$B$48)),"") -> 9000 | D28: =IFERROR(IF(D9="","",C28*(1+'0. Assumptions'!$B$48)),"") -> 9000 | E28: =IFERROR(B28/$B$9,"") -> 0.042293233 | G28: =IFERROR(IF(B9="","",'0. Assumptions'!$B$41),"") -> 0
A29: Accounting / bookkeeping | B29: 2400 | C29: =IFERROR(IF(C9="","",B29*(1+'0. Assumptions'!$B$48)),"") -> 2400 | D29: =IFERROR(IF(D9="","",C29*(1+'0. Assumptions'!$B$48)),"") -> 2400 | E29: =IFERROR(B29/$B$9,"") -> 0.011278195 | G29: =IFERROR(IF(B9="","",'0. Assumptions'!$B$41),"") -> 0
A30: Software (booking / CRM, e-signature, POS) | B30: 1500 | C30: =IFERROR(IF(C9="","",B30*(1+'0. Assumptions'!$B$48)),"") -> 1500 | D30: =IFERROR(IF(D9="","",C30*(1+'0. Assumptions'!$B$48)),"") -> 1500 | E30: =IFERROR(B30/$B$9,"") -> 0.0070488722 | G30: =IFERROR(IF(B9="","",'0. Assumptions'!$B$41),"") -> 0
A31: Glass washing, linens and bar towels | B31: 1200 | C31: =IFERROR(IF(C9="","",B31*(1+'0. Assumptions'!$B$48)),"") -> 1200 | D31: =IFERROR(IF(D9="","",C31*(1+'0. Assumptions'!$B$48)),"") -> 1200 | E31: =IFERROR(B31/$B$9,"") -> 0.0056390977 | G31: =IFERROR(IF(B9="","",'0. Assumptions'!$B$41),"") -> 0
A32: Phone and internet | B32: 900 | C32: =IFERROR(IF(C9="","",B32*(1+'0. Assumptions'!$B$48)),"") -> 900 | D32: =IFERROR(IF(D9="","",C32*(1+'0. Assumptions'!$B$48)),"") -> 900 | E32: =IFERROR(B32/$B$9,"") -> 0.0042293233 | F32: Business mobile plan and data for the card reader at venues with weak signal. Get a quote from your carrier. | G32: =IFERROR(IF(B9="","",'0. Assumptions'!$B$41),"") -> 0
A33: Equipment repair and breakage | B33: 1200 | C33: =IFERROR(IF(C9="","",B33*(1+'0. Assumptions'!$B$48)),"") -> 1200 | D33: =IFERROR(IF(D9="","",C33*(1+'0. Assumptions'!$B$48)),"") -> 1200 | E33: =IFERROR(B33/$B$9,"") -> 0.0056390977 | F33: Replacing broken or lost glassware and repairing equipment. Glass breaks at events, so restock every season. | G33: =IFERROR(IF(B9="","",'0. Assumptions'!$B$41),"") -> 0
A34: Staff training and server certifications (TIPS / TABC / RBS) | B34: 400 | C34: =IFERROR(IF(C9="","",B34*(1+'0. Assumptions'!$B$48)),"") -> 400 | D34: =IFERROR(IF(D9="","",C34*(1+'0. Assumptions'!$B$48)),"") -> 400 | E34: =IFERROR(B34/$B$9,"") -> 0.0018796992 | F34: Responsible-service certifications for you and your bartenders (TIPS, TABC, RBS or ServSafe Alcohol) and their renewals. The certificate you need varies by state, and many venues ask for it anyway. | G34: =IFERROR(IF(B9="","",'0. Assumptions'!$B$41),"") -> 0
A35: Tastings and cocktail menu consultations for prospects | B35: 1000 | C35: =IFERROR(IF(C9="","",B35*(1+'0. Assumptions'!$B$48)),"") -> 1000 | D35: =IFERROR(IF(D9="","",C35*(1+'0. Assumptions'!$B$48)),"") -> 1000 | E35: =IFERROR(B35/$B$9,"") -> 0.0046992481 | F35: Tastings and drink menu consultations for couples and planners: mixers, garnish and your time. Many operators credit the tasting toward the booking: if you do, lower this line. | G35: =IFERROR(IF(B9="","",'0. Assumptions'!$B$41),"") -> 0
A36: Depreciation of fixed assets | B36: =IFERROR(IF(B9="","",'Startup Costs'!$B$33),"") -> 5818.5714 | C36: =IFERROR(IF(C9="","",B36),"") -> 5818.5714 | D36: =IFERROR(IF(D9="","",B36),"") -> 5818.5714 | E36: =IFERROR(B36/$B$9,"") -> 0.027342911 | F36: Comes from the depreciation bases on the Startup Costs tab: real fixed assets only. It does NOT rise with inflation: it is a charge on the HISTORICAL cost of the assets | G36: 0
A37: Interest expense (loan interest) | B37: =IFERROR(IF(B9="","",Financing!$B$44),"") -> 4900 | C37: =IFERROR(IF(C9="","",Financing!$B$46),"") -> 4383.5131 | D37: =IFERROR(IF(D9="","",Financing!$B$48),"") -> 3815.3774 | E37: =IFERROR(B37/$B$9,"") -> 0.023026316 | F37: Only INTEREST is an expense. Principal repaid appears on the cash flow tab | G37: 0
A38: TOTAL FIXED COSTS | B38: =IFERROR(IF(B9="","",SUM(B22:B37)),"") -> 123586.97 | C38: =IFERROR(IF(C9="","",SUM(C22:C37)),"") -> 126070.48 | D38: =IFERROR(IF(D9="","",SUM(D22:D37)),"") -> 128502.35 | E38: =IFERROR(B38/$B$9,"") -> 0.58076584
A39: Recoverable input tax on variable costs | B39: =IFERROR(IF(B9="","",SUMPRODUCT(B13:B18,G13:G18)),"") -> 0 | C39: =IFERROR(IF(C9="","",SUMPRODUCT(C13:C18,G13:G18)),"") -> 0 | D39: =IFERROR(IF(D9="","",SUMPRODUCT(D13:D18,G13:G18)),"") -> 0 | F39: Each line at ITS OWN rate, read from the column next to it. It is what the cash flow tab overpays to suppliers and later deducts (zero wherever no tax is recoverable)
A40: Recoverable input tax on fixed costs | B40: =IFERROR(IF(B9="","",SUMPRODUCT(B22:B37,G22:G37)),"") -> 0 | C40: =IFERROR(IF(C9="","",SUMPRODUCT(C22:C37,G22:G37)),"") -> 0 | D40: =IFERROR(IF(D9="","",SUMPRODUCT(D22:D37,G22:G37)),"") -> 0
A41: PRE-TAX INCOME (EBT) | B41: =IFERROR(IF(B9="","",B20-B38),"") -> 25053.829 | C41: =IFERROR(IF(C9="","",C20-C38),"") -> 37434.396 | D41: =IFERROR(IF(D9="","",D20-D38),"") -> 48082.922 | E41: =IFERROR(B41/$B$9,"") -> 0.11773416
...

Sheet Break-Even
A1: BREAK-EVEN ANALYSIS
A2: Break-even — Mobile Bar
A4: Variable | B4: Year 1 | C4: Year 2 | D4: Year 3 | E4: Notes
A5: BASE DATA BY YEAR
A6: Annual fixed costs | B6: =IFERROR(IF('3-Year P&L'!$B$9="","",'3-Year P&L'!$B$38),"") -> 123586.97 | C6: =IFERROR(IF('3-Year P&L'!$C$9="","",'3-Year P&L'!$C$38),"") -> 126070.48 | D6: =IFERROR(IF('3-Year P&L'!$D$9="","",'3-Year P&L'!$D$38),"") -> 128502.35 | E6: The SAME fixed costs as the P&L. Each year has its own, which is why the threshold cannot be a single one for all three years
A7: Monthly fixed costs | B7: =IFERROR(IF('3-Year P&L'!$B$9="","",B6/12),"") -> 10298.914 | C7: =IFERROR(IF('3-Year P&L'!$C$9="","",C6/12),"") -> 10505.874 | D7: =IFERROR(IF('3-Year P&L'!$D$9="","",D6/12),"") -> 10708.529
A8: Average price per guest (excl. sales tax) | B8: =IFERROR(IF('3-Year P&L'!$B$9="","",'3-Year P&L'!$B$7),"") -> 14 | C8: =IFERROR(IF('3-Year P&L'!$C$9="","",'3-Year P&L'!$C$7),"") -> 14 | D8: =IFERROR(IF('3-Year P&L'!$D$9="","",'3-Year P&L'!$D$7),"") -> 14
A9: Variable cost per guest | B9: =IFERROR(IF('3-Year P&L'!$B$9="","",'3-Year P&L'!$B$19/('3-Year P&L'!$B$6*'3-Year P&L'!$B$8)),"") -> 4.221 | C9: =IFERROR(IF('3-Year P&L'!$C$9="","",'3-Year P&L'!$C$19/('3-Year P&L'!$C$6*'3-Year P&L'!$C$8)),"") -> 4.221 | D9: =IFERROR(IF('3-Year P&L'!$D$9="","",'3-Year P&L'!$D$19/('3-Year P&L'!$D$6*'3-Year P&L'!$D$8)),"") -> 4.221 | E9: Comes from the P&L total variable costs, not from a separate estimate. It includes miscellaneous and contingency, which is a percentage of sales
A10: Contribution margin per guest | B10: =IFERROR(IF('3-Year P&L'!$B$9="","",B8-B9),"") -> 9.779 | C10: =IFERROR(IF('3-Year P&L'!$C$9="","",C8-C9),"") -> 9.779 | D10: =IFERROR(IF('3-Year P&L'!$D$9="","",D8-D9),"") -> 9.779 | E10: Price per guest minus variable cost per guest
A11: Average guests per event | B11: =IFERROR(IF('3-Year P&L'!$B$9="","",'3-Year P&L'!$B$8),"") -> 95 | C11: =IFERROR(IF('3-Year P&L'!$C$9="","",'3-Year P&L'!$C$8),"") -> 95 | D11: =IFERROR(IF('3-Year P&L'!$D$9="","",'3-Year P&L'!$D$8),"") -> 95 | E11: The same calendar as the P&L and the scenarios
A12: Principal repaid in the year | B12: =IFERROR(IF('3-Year P&L'!$B$9="","",Financing!$B$45),"") -> 5164.8695 | C12: =IFERROR(IF('3-Year P&L'!$C$9="","",Financing!$B$47),"") -> 5681.3564 | D12: =IFERROR(IF('3-Year P&L'!$D$9="","",Financing!$B$49),"") -> 6249.4921 | E12: Principal is NOT a P&L expense, but it leaves the cash account. Without it, the published break-even threshold would sit below the real one
A13: ACCOUNTING BREAK-EVEN (includes depreciation)
A14: Guests needed per year | B14: =IFERROR(IF('3-Year P&L'!$B$9="","",IF(B10<=0,"",B6/B10)),"") -> 12637.997 | C14: =IFERROR(IF('3-Year P&L'!$C$9="","",IF(C10<=0,"",C6/C10)),"") -> 12891.961 | D14: =IFERROR(IF('3-Year P&L'!$D$9="","",IF(D10<=0,"",D6/D10)),"") -> 13140.643
A15: Events needed per year | B15: =IFERROR(IF('3-Year P&L'!$B$9="","",B14/B11),"") -> 133.03155 | C15: =IFERROR(IF('3-Year P&L'!$C$9="","",C14/C11),"") -> 135.70485 | D15: =IFERROR(IF('3-Year P&L'!$D$9="","",D14/D11),"") -> 138.32256
A16: Revenue needed per year | B16: =IFERROR(IF('3-Year P&L'!$B$9="","",B14*B8),"") -> 176931.96 | C16: =IFERROR(IF('3-Year P&L'!$C$9="","",C14*C8),"") -> 180487.45 | D16: =IFERROR(IF('3-Year P&L'!$D$9="","",D14*D8),"") -> 183969
A17: CASH BREAK-EVEN (loan payments in, depreciation out)
A18: Cash fixed costs + principal repaid for the year | B18: =IFERROR(IF('3-Year P&L'!$B$9="","",B6-'3-Year P&L'!$B$36+B12),"") -> 122933.27 | C18: =IFERROR(IF('3-Year P&L'!$C$9="","",C6-'3-Year P&L'!$C$36+C12),"") -> 125933.27 | D18: =IFERROR(IF('3-Year P&L'!$D$9="","",D6-'3-Year P&L'!$D$36+D12),"") -> 128933.27 | E18: The P&L fixed costs without depreciation (which is not paid in cash) and WITH principal repaid (which is). This is the threshold that decides whether cash holds up
A19: Guests needed per year (cash) | B19: =IFERROR(IF('3-Year P&L'!$B$9="","",IF(B10<=0,"",B18/B10)),"") -> 12571.149 | C19: =IFERROR(IF('3-Year P&L'!$C$9="","",IF(C10<=0,"",C18/C10)),"") -> 12877.929 | D19: =IFERROR(IF('3-Year P&L'!$D$9="","",IF(D10<=0,"",D18/D10)),"") -> 13184.709
A20: Events needed per year (cash) | B20: =IFERROR(IF('3-Year P&L'!$B$9="","",B19/B11),"") -> 132.32789 | C20: =IFERROR(IF('3-Year P&L'!$C$9="","",C19/C11),"") -> 135.55715 | D20: =IFERROR(IF('3-Year P&L'!$D$9="","",D19/D11),"") -> 138.78641
A21: Revenue needed per year (cash) | B21: =IFERROR(IF('3-Year P&L'!$B$9="","",B19*B8),"") -> 175996.09 | C21: =IFERROR(IF('3-Year P&L'!$C$9="","",C19*C8),"") -> 180291.01 | D21: =IFERROR(IF('3-Year P&L'!$D$9="","",D19*D8),"") -> 184585.93
A22: COMPARISON WITH THE PLAN
A23: Events per year in the plan | B23: =IFERROR(IF('3-Year P&L'!$B$9="","",'3-Year P&L'!$B$6),"") -> 160 | C23: =IFERROR(IF('3-Year P&L'!$C$9="","",'3-Year P&L'!$C$6),"") -> 176 | D23: =IFERROR(IF('3-Year P&L'!$D$9="","",'3-Year P&L'!$D$6),"") -> 190.08
A24: Cushion above CASH break-even (%) | B24: =IFERROR(IF('3-Year P&L'!$B$9="","",B23/B20-1),"") -> 0.20911776 | C24: =IFERROR(IF('3-Year P&L'!$C$9="","",C23/C20-1),"") -> 0.29834539 | D24: =IFERROR(IF('3-Year P&L'!$D$9="","",D23/D20-1),"") -> 0.36958654 | E24: How far the plan sits above the cash break-even (plan ÷ break-even − 1); the drop you can absorb is 1 − break-even ÷ plan. The required minimum is set in the "0. Assumptions" tab
A25: INTERPRETATION
A26: =IFERROR("With the average price per guest excl. sales tax above, you need "&TEXT(ROUNDUP(B15,0),"0")&" events a year at your average of "&TEXT(B11,"0")&" guests per event to avoid losing money (accounting break-even, depreciation included), and "&TEXT(ROUNDUP(B20,0),"0")&" for cash to hold (cash break-even: depreciation out, because it is not paid, and the year's loan payment in"&IF(B12=0,"; no principal is repaid this year (interest-only period or no loan)","")&"). The ""Revenue needed per year"" rows show the same figures in your currency.","") -> With the average price per guest excl. sales tax above, you need 134 events a year at your average of 95 guests per event to avoid losing money (accounting break-even, depreciation included), and 133 for cash to hold (cash break-even: depreciation out, because it is not paid, and the year's loan payment in). The "Revenue needed per year" rows show the same figures in your currency.
A28: BREAK-EVEN SENSITIVITY
A29: Events per year needed to cover costs for each price per guest (columns, in steps around the plan's price) and each variable cost per guest (rows). Green cells are below the events per year the plan forecasts.
A31: Events per year needed: price per guest excl. sales tax (columns) × variable cost per guest (rows) | B31: =IFERROR($B$8-1,"") -> 13 | C31: =IFERROR(IF($B$8="","",$B$8),"") -> 14 | D31: =IFERROR($B$8+1,"") -> 15 | E31: =IFERROR($B$8+2,"") -> 16
A32: =IFERROR($B$9*0.85,"") -> 3.58785 | B32: =IFERROR(IF($B$31-$A32<=0,"",$B$6/($B$31-$A32)/$B$11),"") -> 138.21661 | C32: =IFERROR(IF($C$31-$A32<=0,"",$B$6/($C$31-$A32)/$B$11),"") -> 124.94206 | D32: =IFERROR(IF($D$31-$A32<=0,"",$B$6/($D$31-$A32)/$B$11),"") -> 113.9939 | E32: =IFERROR(IF($E$31-$A32<=0,"",$B$6/($E$31-$A32)/$B$11),"") -> 104.80984
A33: =IFERROR($B$9*0.925,"") -> 3.904425 | B33: =IFERROR(IF($B$31-$A33<=0,"",$B$6/($B$31-$A33)/$B$11),"") -> 143.0273 | C33: =IFERROR(IF($C$31-$A33<=0,"",$B$6/($C$31-$A33)/$B$11),"") -> 128.85997 | D33: =IFERROR(IF($D$31-$A33<=0,"",$B$6/($D$31-$A33)/$B$11),"") -> 117.24633 | E33: =IFERROR(IF($E$31-$A33<=0,"",$B$6/($E$31-$A33)/$B$11),"") -> 107.55301
A34: =IFERROR($B$9*1.0,"") -> 4.221 | B34: =IFERROR(IF($B$31-$A34<=0,"",$B$6/($B$31-$A34)/$B$11),"") -> 148.18493 | C34: =IFERROR(IF($C$31-$A34<=0,"",$B$6/($C$31-$A34)/$B$11),"") -> 133.03155 | D34: =IFERROR(IF($D$31-$A34<=0,"",$B$6/($D$31-$A34)/$B$11),"") -> 120.68981 | E34: =IFERROR(IF($E$31-$A34<=0,"",$B$6/($E$31-$A34)/$B$11),"") -> 110.44363
A35: =IFERROR($B$9*1.075,"") -> 4.537575 | B35: =IFERROR(IF($B$31-$A35<=0,"",$B$6/($B$31-$A35)/$B$11),"") -> 153.72845 | C35: =IFERROR(IF($C$31-$A35<=0,"",$B$6/($C$31-$A35)/$B$11),"") -> 137.48225 | D35: =IFERROR(IF($D$31-$A35<=0,"",$B$6/($D$31-$A35)/$B$11),"") -> 124.34168 | E35: =IFERROR(IF($E$31-$A35<=0,"",$B$6/($E$31-$A35)/$B$11),"") -> 113.49392
A36: =IFERROR($B$9*1.15,"") -> 4.85415 | B36: =IFERROR(IF($B$31-$A36<=0,"",$B$6/($B$31-$A36)/$B$11),"") -> 159.70285 | C36: =IFERROR(IF($C$31-$A36<=0,"",$B$6/($C$31-$A36)/$B$11),"") -> 142.24107 | D36: =IFERROR(IF($D$31-$A36<=0,"",$B$6/($D$31-$A36)/$B$11),"") -> 128.22144 | E36: =IFERROR(IF($E$31-$A36<=0,"",$B$6/($E$31-$A36)/$B$11),"") -> 116.71748

Sheet Scenarios
A1: SCENARIO ANALYSIS
A4: Metric | B4: Pessimistic | C4: Base | D4: Optimistic | E4: Notes
A5: Events per year | B5: 120 | C5: =IFERROR(IF('3-Year P&L'!$B$6="","",'3-Year P&L'!$B$6),"") -> 160 | D5: 200
A6: Average price per guest (excl. sales tax) | B6: 12.6 | C6: =IFERROR(IF('3-Year P&L'!$B$7="","",'3-Year P&L'!$B$7),"") -> 14 | D6: 15.4
A7: Average guests per event | B7: 86 | C7: =IFERROR(IF('3-Year P&L'!$B$8="","",'3-Year P&L'!$B$8),"") -> 95 | D7: 105
A8: ANNUAL REVENUE (excl. sales tax) | B8: =IFERROR(IF(B5*B6*B7=0,"",B5*B6*B7),"") -> 130032 | C8: =IFERROR(IF(C5*C6*C7=0,"",C5*C6*C7),"") -> 212800 | D8: =IFERROR(IF(D5*D6*D7=0,"",D5*D6*D7),"") -> 323400
A9: Cost of goods — bar packages (mixers, garnishes, ice) | B9: =IFERROR(IF(B8="","",B8*'0. Assumptions'!$B$11*'0. Assumptions'!$B$13),"") -> 21000.168 | C9: =IFERROR(IF(C8="","",C8*'0. Assumptions'!$B$11*'0. Assumptions'!$B$13),"") -> 34367.2 | D9: =IFERROR(IF(D8="","",D8*'0. Assumptions'!$B$11*'0. Assumptions'!$B$13),"") -> 52229.1
A10: Cost of goods — add-ons | B10: =IFERROR(IF(B8="","",B8*'0. Assumptions'!$B$12*'0. Assumptions'!$B$14),"") -> 3900.96 | C10: =IFERROR(IF(C8="","",C8*'0. Assumptions'!$B$12*'0. Assumptions'!$B$14),"") -> 6384 | D10: =IFERROR(IF(D8="","",D8*'0. Assumptions'!$B$12*'0. Assumptions'!$B$14),"") -> 9702
A11: Cups, straws, napkins and bar disposables | B11: =IFERROR(IF(B8="","",B8*'0. Assumptions'!$B$15),"") -> 5201.28 | C11: =IFERROR(IF(C8="","",C8*'0. Assumptions'!$B$15),"") -> 8512 | D11: =IFERROR(IF(D8="","",D8*'0. Assumptions'!$B$15),"") -> 12936
A12: Gig marketplace fees | B12: =IFERROR(IF(B8="","",B8*'0. Assumptions'!$B$16*'0. Assumptions'!$B$17),"") -> 1300.32 | C12: =IFERROR(IF(C8="","",C8*'0. Assumptions'!$B$16*'0. Assumptions'!$B$17),"") -> 2128 | D12: =IFERROR(IF(D8="","",D8*'0. Assumptions'!$B$16*'0. Assumptions'!$B$17),"") -> 3234
A13: Card processing fees | B13: =IFERROR(IF(B8="","",B8*'0. Assumptions'!$B$18),"") -> 3900.96 | C13: =IFERROR(IF(C8="","",C8*'0. Assumptions'!$B$18),"") -> 6384 | D13: =IFERROR(IF(D8="","",D8*'0. Assumptions'!$B$18),"") -> 9702
A14: Miscellaneous and contingency | B14: =IFERROR(IF(B8="","",B8*'0. Assumptions'!$B$28),"") -> 3900.96 | C14: =IFERROR(IF(C8="","",C8*'0. Assumptions'!$B$28),"") -> 6384 | D14: =IFERROR(IF(D8="","",D8*'0. Assumptions'!$B$28),"") -> 9702
A15: TOTAL VARIABLE COSTS | B15: =IFERROR(IF(B8="","",SUM(B9:B14)),"") -> 39204.648 | C15: =IFERROR(IF(C8="","",SUM(C9:C14)),"") -> 64159.2 | D15: =IFERROR(IF(D8="","",SUM(D9:D14)),"") -> 97505.1
A16: GROSS MARGIN | B16: =IFERROR(IF(B8="","",B8-B15),"") -> 90827.352 | C16: =IFERROR(IF(C8="","",C8-C15),"") -> 148640.8 | D16: =IFERROR(IF(D8="","",D8-D15),"") -> 225894.9
A17: FIXED COSTS (the P&L's) | B17: =IFERROR(IF(B8="","",'3-Year P&L'!$B$38),"") -> 123586.97 | C17: =IFERROR(IF(C8="","",'3-Year P&L'!$B$38),"") -> 123586.97 | D17: =IFERROR(IF(D8="","",'3-Year P&L'!$B$38),"") -> 123586.97 | E17: Fixed costs do not change with the scenario: that is why they are fixed
A18: PRE-TAX INCOME (EBT) | B18: =IFERROR(IF(B8="","",B16-B17),"") -> -32759.619 | C18: =IFERROR(IF(C8="","",C16-C17),"") -> 25053.829 | D18: =IFERROR(IF(D8="","",D16-D17),"") -> 102307.93
A19: Income tax | B19: =IFERROR(IF(B8="","",MAX(0,B18-'0. Assumptions'!$B$42)*'0. Assumptions'!$B$37),"") -> 0 | C19: =IFERROR(IF(C8="","",MAX(0,C18-'0. Assumptions'!$B$42)*'0. Assumptions'!$B$37),"") -> 6263.4571 | D19: =IFERROR(IF(D8="","",MAX(0,D18-'0. Assumptions'!$B$42)*'0. Assumptions'!$B$37),"") -> 25576.982 | E19: At the "years 1-2" effective income tax rate, offsetting prior net operating losses
A20: NET INCOME | B20: =IFERROR(IF(B8="","",B18-B19),"") -> -32759.619 | C20: =IFERROR(IF(C8="","",C18-C19),"") -> 18790.371 | D20: =IFERROR(IF(D8="","",D18-D19),"") -> 76730.946
A21: Events per year to break even | B21: =IFERROR(IF(B8="","",IF(B6-B15/(B5*B7)<=0,"",B17/(B6-B15/(B5*B7))/B7)),"") -> 163.28161 | C21: =IFERROR(IF(C8="","",IF(C6-C15/(C5*C7)<=0,"",C17/(C6-C15/(C5*C7))/C7)),"") -> 133.03155 | D21: =IFERROR(IF(D8="","",IF(D6-D15/(D5*D7)<=0,"",D17/(D6-D15/(D5*D7))/D7)),"") -> 109.41989
A22: WHAT EACH SCENARIO DEMANDS
A23: Labor cost / Sales | B23: =IFERROR(IF(B8="","",'3-Year P&L'!$B$23/B8),"") -> 0.60268549 | C23: =IFERROR(IF(C8="","",'3-Year P&L'!$B$23/C8),"") -> 0.36827256 | D23: =IFERROR(IF(D8="","",'3-Year P&L'!$B$23/D8),"") -> 0.24232653 | E23: The SAME staffing in all three scenarios. In the pessimistic case your real cost of event bartenders and barbacks falls with the number of events (you pay hours per event), so the real result would be somewhat better than shown. If labor cost still blows up, adjust it in the "Staffing" tab, not here.
A24: Guests per year per full-time equivalent | B24: =IFERROR(IF(B8="","",B5*B7/Staffing!$C$9),"") -> 5578.3784 | C24: =IFERROR(IF(C8="","",C5*C7/Staffing!$C$9),"") -> 8216.2162 | D24: =IFERROR(IF(D8="","",D5*D7/Staffing!$C$9),"") -> 11351.351 | E24: Guests each full-time equivalent in the "Staffing" table would have to serve in a year. In the optimistic scenario it tells you whether you need to hire
A25: Year-1 closing cash balance (estimate, same method in all three scenarios) | B25: =IFERROR(IF(B8="","",'Startup Costs'!$B$25+B20+'3-Year P&L'!$B$36-Financing!$B$45),"") -> -2663.8175 | C25: =IFERROR(IF(C8="","",'Startup Costs'!$B$25+C20+'3-Year P&L'!$B$36-Financing!$B$45),"") -> 48886.173 | D25: =IFERROR(IF(D8="","",'Startup Costs'!$B$25+D20+'3-Year P&L'!$B$36-Financing!$B$45),"") -> 106826.75 | E25: ESTIMATED balance: working capital plus the year's result, adding back depreciation (which is not paid) and subtracting loan principal. It does not include the timing gap between receipts and payments or the sales tax settlement, so the three columns can be compared with each other. In red, the scenario runs out of cash
A26: Actual month-12 balance from the 12-Month Cash Flow tab (Base case only) | C26: =IFERROR(IF(C8="","",'12-Month Cash Flow'!$M$22),"") -> 58962.499 | E26: The ACTUAL base-case balance, with its timing of receipts and payments and its sales tax settlement. It exists only for the Base scenario, the only one with its own monthly cash flow: that is why it is not in the row above, where it would be compared against two estimates
A28: The "Base" column reads its three inputs (events per year, price per guest and guests per event) from the "0. Assumptions" tab, so it reproduces EXACTLY year 1 of the P&L. The other two scenarios use the same cost rates: only events, price and guests change. FIXED COSTS are the same in all three, while variable costs follow the sales of each scenario.

Sheet Staffing
A1: STAFFING STRUCTURE AND COSTS
A2: =IFERROR("Payroll — "&TEXT('0. Assumptions'!$B$21,"0")&" pay periods + employer taxes "&TEXT('0. Assumptions'!$B$20*100,"0")&"%","") -> Payroll — 12 pay periods + employer taxes 10%
A4: Position | B4: People | C4: FTE | D4: Gross pay per month (total for the position) | E4: Employer payroll taxes (total for the position) | F4: Cost per month (total for the position) | G4: Cost per year | H4: Hours per week per person | I4: Hours per year for the position | J4: Notes
A5: Owner & Lead Bartender (sales and operations) | B5: 1 | C5: 1 | D5: 3250 | E5: =IFERROR(IF(D5="","",D5*'0. Assumptions'!$B$20),"") -> 325 | F5: =IFERROR(IF(D5="","",D5+E5),"") -> 3575 | G5: =IFERROR(IF(D5="","",F5*MAX(12,'0. Assumptions'!$B$21)),"") -> 42900 | H5: =IFERROR(IF(D5="","",C5*$B$16),"") -> 40 | I5: =IFERROR(IF(D5="","",H5*B5*$B$17),"") -> 2000 | J5: Sells, runs the tastings, designs the drink menus and leads the bar for crew 1. Covers the main shift at every event.
A6: Second-crew lead bartender (part-time W-2) | B6: 1 | C6: 0.25 | D6: 867 | E6: =IFERROR(IF(D6="","",D6*'0. Assumptions'!$B$20),"") -> 86.7 | F6: =IFERROR(IF(D6="","",D6+E6),"") -> 953.7 | G6: =IFERROR(IF(D6="","",F6*MAX(12,'0. Assumptions'!$B$21)),"") -> 11444.4 | H6: =IFERROR(IF(D6="","",C6*$B$16),"") -> 10 | I6: =IFERROR(IF(D6="","",H6*B6*$B$17),"") -> 500 | J6: Leads the second crew on peak-season Saturdays: setup, service and breakdown. Part-time W-2, paid at or above the pay floor in proportion to FTE.
A7: Event bartenders (hourly W-2) | B7: 5 | C7: 0.1 | D7: 1560 | E7: =IFERROR(IF(D7="","",D7*'0. Assumptions'!$B$20),"") -> 156 | F7: =IFERROR(IF(D7="","",D7+E7),"") -> 1716 | G7: =IFERROR(IF(D7="","",F7*MAX(12,'0. Assumptions'!$B$21)),"") -> 20592 | H7: =IFERROR(IF(D7="","",C7*$B$16),"") -> 4 | I7: =IFERROR(IF(D7="","",H7*B7*$B$17),"") -> 1000 | J7: Bartenders hired per event and paid hourly as W-2 employees. Their FTE is a fraction because they only work event hours. Voluntary tips are theirs (FLSA). Treating them as 1099 contractors is a misclassification risk (FLSA; California AB5). Paid at or above the pay floor in proportion to FTE.
A8: Barbacks / setup crew (hourly W-2) | B8: 2 | C8: 0.05 | D8: 260 | E8: =IFERROR(IF(D8="","",D8*'0. Assumptions'!$B$20),"") -> 26 | F8: =IFERROR(IF(D8="","",D8+E8),"") -> 286 | G8: =IFERROR(IF(D8="","",F8*MAX(12,'0. Assumptions'!$B$21)),"") -> 3432 | H8: =IFERROR(IF(D8="","",C8*$B$16),"") -> 2 | I8: =IFERROR(IF(D8="","",H8*B8*$B$17),"") -> 200 | J8: Barbacks hired by the hour as W-2 employees: loading, ice, setup and breakdown at larger events. Paid at or above the pay floor in proportion to FTE.
A9: TOTAL STAFF | B9: =IFERROR(IF(COUNT(D5:D8)=0,"",SUM(B5:B8)),"") -> 9 | C9: =IFERROR(IF(COUNT(D5:D8)=0,"",SUMPRODUCT(B5:B8,C5:C8)),"") -> 1.85 | D9: =IFERROR(IF(COUNT(D5:D8)=0,"",SUM(D5:D8)),"") -> 5937 | E9: =IFERROR(IF(COUNT(D5:D8)=0,"",SUM(E5:E8)),"") -> 593.7 | F9: =IFERROR(IF(COUNT(D5:D8)=0,"",SUM(F5:F8)),"") -> 6530.7 | G9: =IFERROR(IF(COUNT(D5:D8)=0,"",SUM(G5:G8)),"") -> 78368.4 | I9: =IFERROR(IF(COUNT(D5:D8)=0,"",SUM(I5:I8)),"") -> 3700
A10: STAFF GROWTH (stepped cost)
A11: Annual cost of year-2 hires | B11: 3000 | J11: FULL ANNUAL cost (gross pay + employer payroll taxes, over all pay periods) of whoever you hire that year. The P&L adds it to the previous year's cost: staffing grows by people, not by a percentage
A12: Annual cost of year-3 hires | B12: 3000 | J12: FULL ANNUAL cost (gross pay + employer payroll taxes, over all pay periods) of whoever you hire that year. The P&L adds it to the previous year's cost: staffing grows by people, not by a percentage
A13: Labor cost, year 2 | B13: =IFERROR(IF(G9="","",G9*(1+'0. Assumptions'!$B$48)+B11),"") -> 81368.4
A14: Labor cost, year 3 | B14: =IFERROR(IF(B13="","",B13*(1+'0. Assumptions'!$B$48)+B12),"") -> 84368.4
A15: COVERAGE OF EVENT HOURS
A16: Full-time week (hours per week) | B16: 40 | J16: 40 hours a week is the FLSA overtime threshold for non-exempt employees; some states add daily overtime rules. Change it if your own full-time week is different
A17: Weeks worked per year per person | B17: 50 | J17: 50 weeks: 52 minus about two weeks of vacation, holidays and average absences. There is no federal vacation requirement in the US: adjust it to your own policy
A18: Hours per person per event (prep, loading, travel, setup, service, breakdown) | B18: 8 | J18: Hours of work that one event needs: shopping, packing, loading, transport, setup, service, breakdown and cleanup. Serving is only part of it. Hours × people × events per year sets the event staff cost.
A19: People per event (bartenders and barbacks, average) | B19: 2.2 | J19: Average number of people working each event. A large wedding needs more hands: raise it here and the staffing sizes itself.
A20: Event hours to cover per year | B20: =IFERROR(IF(OR(B18="",B19="",'0. Assumptions'!$B$4=""),"",B18*B19*'0. Assumptions'!$B$4),"") -> 2816
A21: Hours hired per year | B21: =IFERROR(IF(I9="","",I9),"") -> 3700
A22: Coverage (hired / needed) | B22: =IFERROR(B21/B20,"") -> 1.3139205 | J22: Below 100% the staff cannot cover the hours the plan declares: either hire more or cut the hours
A24: Columns D-G are TOTALS for the row. Event bartenders and barbacks are hourly W-2 employees with payroll taxes and workers' comp: paying them as 1099 contractors is a misclassification risk (FLSA; California AB5). Tips belong to the staff: the employer keeps none of them (FLSA).
A25: The pay floor is the HIGHER of the federal minimum wage and your state / local minimum wage, both in the "0. Assumptions" tab; part-time positions get it in proportion. There is no single national table above the federal floor: the state / local cell is delivered empty so you can enter the rate for your state and city.

Sheet Instructions
A1: HOW TO USE THIS WORKBOOK — Mobile Bar Financial Projections
A3: HOW TO USE THIS WORKBOOK
A4: This financial plan is a MODEL: you type only in the GREEN cells and everything else recalculates on its own.
A5: 1. "0. Assumptions" is the control sheet: events per year, price per guest excl. sales tax, guests per event, the bar package and add-on mix, cost of goods sold, storage and trailer parking, financing and taxes.
A6: 2. Startup cost items, fixed costs and staffing are typed in their own tab, also in green. No number is typed twice.
A7: 3. Only "Break-Even" is derived entirely from the rest. The other three tabs also have green cells you can edit: the pessimistic and optimistic scenarios in "Scenarios", seasonality and the launch ramp-up in "12-Month Cash Flow", and the other funding sources in "Financing" (rows 8-11 count as sources but are not amortized: your bank or SBA 7(a) loan goes in "Loan requested" on "0. Assumptions"). Everything else is calculated.
A8: 4. All figures are EXCL. SALES TAX. To turn a quoted price into a price excl. sales tax, divide it by 1 + your sales tax rate (with an 8% rate, divide by 1.08); if an item is taxed at a different rate in your state, use that rate. Sales tax on services varies by state: in some, the whole bar package invoice is taxable, including bartender labor and rentals; check yours. The rate of each sales line is in the "Sales tax rate on the line (%)" column of the P&L, and from it come the receipts, the sales tax collected and the equivalent price per guest incl. sales tax. With the default 0% recoverable input tax, the sales tax you pay on purchases and startup costs is treated as a cost; in the UK, enter 20% if you are VAT-registered.
A9: 5. If you change the staffing, the P&L reads it on its own: labor cost comes from the "Staffing" tab, not from a separate estimate.
A10: 6. The "12-Month Cash Flow" tab answers the question that decides a bank deal: in which month the cash runs out. The minimum balance of the year can never be in red.
A11: 7. The "Financing" tab matches what you need with what you put in and builds the amortization schedule of the loan. If the difference is red, the plan is not funded.
