Workbook

Sheet Pricing Calculator
A1: MOBILE BAR PRICING CALCULATOR — COST PER GUEST TO QUOTE
A2: Type in the GREEN cells; everything else is calculated. The default model is dry hire (you supply the alcohol; we bring the bar, the bartenders and everything else): the host buys and owns the alcohol, so it is never in your cost or your price. Amounts are in your currency and exclude sales tax unless the row says otherwise. Every default value is a kit estimate: replace it with your own numbers.
A4: INPUTS | B4: Value | C4: Notes
A5: Bar package | B5: Full bar – dry hire | C5: Choose from the list. The licensed package is ONLY for a business that holds a liquor license or caterer's permit: see section 9 of the business plan. In dry hire the host buys and owns the alcohol.
A6: Guests expected | B6: 95 | C6: Whole number of adult guests at the event.
A7: Hours of bar service | B7: 4 | C7: Service time only; setup, travel and breakdown go two rows below.
A8: Drinks per guest in the first hour | B8: 2 | C8: Planning rule: 2 drinks per guest in the first hour (eventplanning.com).
A9: Drinks per guest in each following hour | B9: 1 | C9: Planning rule: 1 drink per guest per hour after the first (eventplanning.com).
A10: Bartenders working the event | B10: 2 | C10: Compare with the suggested number in the results (table at the bottom).
A11: Barbacks / setup crew working the event | B11: 0 | C11: Usually needed at large weddings.
A12: Setup, travel and breakdown hours per person | B12: 3 | C12: Paid hours on top of service: loading, travel, setup, breakdown. Kit estimate.
A13: Bartender hourly wage | B13: 20 | C13: Kit estimate. BLS (May 2025): mean 19.61 an hour, median 16.51, tips included. Bartenders are W-2 employees.
A14: Barback hourly wage | B14: 16 | C14: Kit estimate. At or above your state minimum wage.
A15: Employer payroll taxes and workers' comp (% of wages) | B15: 0.1 | C15: Kit estimate.
A16: Mixers, garnishes and N/A drinks per drink served | B16: 0.38 | C16: Kit estimate. Juices, syrups, sodas, fruit and mocktail ingredients: what the bar supplies.
A17: Alcohol cost per drink (licensed package only) | B17: 3 | C17: Used ONLY with the licensed package. In dry hire the host buys the alcohol: it is never in your cost or your price.
... A28: Sales tax rate (state + local) | B28: 0.08 | C28: Kit estimate: use your own state + local rate.
A29: Does your state tax the bar service and the service charge? | B29: Yes | C29: California taxes a caterer's service even when the client supplies the drinks (cdtfa.ca.gov). Rules vary by state: check yours.
A30: Deposit to book the date (% of total) | B30: 0.3 | C30: A 30% deposit is typical (checkcherry.com); the balance is due before the event.
A31: Minimum charge for the bar service (subtotal floor) | B31: 400 | C31: Below it you bill the minimum. Kit estimate. 0 = no minimum.
A32: Price of an extra hour of service (quoted separately) | B32: 150 | C32: Kit estimate. It is listed in the quote, not added to the total.
A34: CALCULATION | B34: Value | C34: Notes
A35: Drinks to plan for | B35: =$B$6*($B$8+MAX(0,$B$7-1)*$B$9) -> 475 | C35: Guests × (first-hour drinks + following hours × drinks per hour).
A36: Ice to bring (lb) | B36: =$B$6*$B$19 -> 142.5
A37: Suggested bartenders for this package (Kit estimate) | B37: =IFERROR(ROUNDUP($B$6/INDEX('Pricing Calculator'!$B$60:$B$62,MATCH($B$5,'Pricing Calculator'!$A$60:$A$62,0)),0),"—") -> 2 | C37: Guests ÷ guests per bartender in the table below, rounded up.
A38: Staff cost (wages + payroll taxes) | B38: =($B$10*$B$13+$B$11*$B$14)*($B$7+$B$12)*(1+$B$15) -> 308
A39: Mixers, garnishes and N/A drinks | B39: =$B$35*$B$16 -> 180.5
A40: Alcohol (licensed package only) | B40: =IF($B$5='Pricing Calculator'!$A$62,$B$35*$B$17,0) -> 0 | C40: Zero in dry hire: the host buys the alcohol.
A41: Cups, straws, napkins and menu signs | B41: =$B$6*$B$18 -> 52.25
A42: Ice | B42: =$B$36*$B$20 -> 35.625
A43: Mileage | B43: =$B$21*$B$22 -> 28
A44: Total direct cost | B44: =$B$38+$B$39+$B$40+$B$41+$B$42+$B$43 -> 604.375
A45: Direct cost per guest | B45: =$B$44/$B$6 -> 6.3618421
A46: PRICE PER GUEST before service charge and tax | B46: =ROUNDUP(MAX(0,$B$44/(1-$B$26-$B$25)-$B$23)/$B$6*(1+$B$24)*2,0)/2 -> 14.5 | C46: Rounded up to the next 0.50. Staff, mixers, ice and cups are inside it; the host's alcohol is not.
A47: Bar service subtotal | B47: =MAX($B$46*$B$6+$B$23,$B$31) -> 1377.5 | C47: Price per guest × guests + flat bar fee, never below the minimum.
A48: Equivalent price per hour of service | B48: =$B$47/$B$7 -> 344.375 | C48: The same quote expressed per hour, for clients who compare hourly rates.
A49: Service charge | B49: =$B$47*$B$27 -> 0
A50: Sales tax | B50: =($B$47+IF($B$29="Yes",$B$49,0))*$B$28 -> 110.2 | C50: On the subtotal, plus the service charge if your state taxes it.
A51: TOTAL TO QUOTE | B51: =$B$47+$B$49+$B$50 -> 1487.7
A52: Deposit to book the date | B52: =$B$51*$B$30 -> 446.31
...

Sheet Drinks & Shopping List
A1: DRINKS & SHOPPING LIST — WHAT THE HOST BUYS AND WHAT THE BAR BRINGS
A2: It reads the package, guests, hours and drinks from the "Pricing Calculator" tab. In dry hire this is the shopping list you hand the host about two weeks before the event: the host buys and owns the alcohol, and unopened bottles stay with the host. With the licensed package, you buy it. Green cells are kit estimates: edit them.
A4: THE EVENT (from the "Pricing Calculator" tab)
A5: Bar package | B5: ='Pricing Calculator'!$B$5 -> Full bar – dry hire
A6: Guests | B6: ='Pricing Calculator'!$B$6 -> 95
A7: Hours of bar service | B7: ='Pricing Calculator'!$B$7 -> 4
A8: Drinks to plan for | B8: ='Pricing Calculator'!$B$35 -> 475
A10: DRINK MIX BY PACKAGE (share of drinks; Kit estimate — edit) | B10: Cocktails & spirits | C10: Wine | D10: Beer | E10: Check (must be 100%)
A11: Full bar – dry hire | B11: 0.5 | C11: 0.25 | D11: 0.25 | E11: =IF(ROUND(SUM(B11:D11),4)=1,"OK","Adjust: the three shares must add up to 100%") -> OK
A12: Limited bar (beer, wine + 1 signature) – dry hire | B12: 0.2 | C12: 0.4 | D12: 0.4 | E12: =IF(ROUND(SUM(B12:D12),4)=1,"OK","Adjust: the three shares must add up to 100%") -> OK
A13: Full bar – licensed (alcohol included) | B13: 0.5 | C13: 0.25 | D13: 0.25 | E13: =IF(ROUND(SUM(B13:D13),4)=1,"OK","Adjust: the three shares must add up to 100%") -> OK
A15: ASSUMPTIONS (Kit estimate — edit) | B15: Value | E15: Notes
A16: Drinks per 750 ml bottle of spirits (1.5 oz pours) | B16: 16 | E16: A 750 ml bottle holds about 25 oz: about 16 pours of 1.5 oz.
A17: Glasses per 750 ml bottle of wine | B17: 5 | E17: About 5 glasses of 5 oz.
A18: Beers (12 oz cans or bottles) per beer drink | B18: 1
A19: Safety buffer on every quantity | B19: 0.1 | E19: Kit estimate: unopened bottles stay with the host.
A20: Champagne toast? | B20: No | E20: Yes or No.
A21: Toast pours per 750 ml bottle of sparkling wine | B21: 8 | E21: Kit estimate.
A22: Bag of ice (lb) | B22: 10 | E22: Use the bag size your supplier sells.
A23: Cups per drink | B23: 1
A24: Napkins per drink | B24: 1
A26: SPIRITS SPLIT (share of the cocktails & spirits; Kit estimate — edit) | B26: Share
A27: Vodka | B27: 0.3
A28: Tequila | B28: 0.2
A29: Whiskey / bourbon | B29: 0.2
A30: Rum | B30: 0.15
A31: Gin | B31: 0.15
A32: Check (must be 100%) | B32: =IF(ROUND(SUM(B27:B31),4)=1,"OK","Adjust to 100%") -> OK
A34: DRINKS BY CATEGORY | B34: Drinks
A35: Cocktails & spirits | B35: =IFERROR($B$8*INDEX($B$11:$B$13,MATCH($B$5,$A$11:$A$13,0)),0) -> 237.5
A36: Wine | B36: =IFERROR($B$8*INDEX($C$11:$C$13,MATCH($B$5,$A$11:$A$13,0)),0) -> 118.75
A37: Beer | B37: =IFERROR($B$8*INDEX($D$11:$D$13,MATCH($B$5,$A$11:$A$13,0)),0) -> 118.75
A39: SHOPPING LIST — ALCOHOL | B39: Quantity | C39: Unit | D39: =IF($B$5='Pricing Calculator'!$A$62,"You (licensed package)","The host (dry hire)") -> The host (dry hire) | E39: Notes
A40: Spirits, total (750 ml bottles) | B40: =ROUNDUP($B$35*(1+$B$19)/$B$16,0) -> 17 | C40: bottles | E40: Cocktails & spirits ÷ drinks per bottle, with the buffer.
A41: Vodka | B41: =ROUNDUP($B$35*$B$27*(1+$B$19)/$B$16,0) -> 5 | C41: bottles | E41: Rounded up type by type, so the split can add up to a little more than the total.
A42: Tequila | B42: =ROUNDUP($B$35*$B$28*(1+$B$19)/$B$16,0) -> 4 | C42: bottles
A43: Whiskey / bourbon | B43: =ROUNDUP($B$35*$B$29*(1+$B$19)/$B$16,0) -> 4 | C43: bottles
A44: Rum | B44: =ROUNDUP($B$35*$B$30*(1+$B$19)/$B$16,0) -> 3 | C44: bottles
A45: Gin | B45: =ROUNDUP($B$35*$B$31*(1+$B$19)/$B$16,0) -> 3 | C45: bottles
A46: Wine (750 ml bottles) | B46: =ROUNDUP($B$36*(1+$B$19)/$B$17,0) -> 27 | C46: bottles | E46: Split between red, white and sparkling to taste.
...

Sheet Signature Cocktail Specs
A1: SIGNATURE COCKTAIL SPECS — 10 RECIPES, SCALED AND COSTED
A2: Ten signature cocktails, including one zero-proof mocktail, in US ounces. Type your local price for each bottle or pack in the green cells: the cost per drink and the batch quantities for 50, 100 and 200 drinks are calculated. In dry hire, everything that contains alcohol (bitters included) goes on the host's shopping list; you supply mixers, juices, syrups, garnishes and ice. Pack prices are kit estimates.
A4: Ingredient | B4: Per drink | C4: Unit | D4: Who buys (dry hire) | E4: Pack size | F4: Pack unit | G4: Pack price | H4: Cost per drink | I4: 50 drinks | J4: 100 drinks | K4: 200 drinks | L4: Packs for 100 drinks
A6: OLD FASHIONED | B6: Rocks glass, one large cube
A7: Bourbon | B7: 2 | C7: oz | D7: Host | E7: 25.4 | F7: oz | G7: 25 | H7: =IF(E7=0,0,B7/E7*G7) -> 1.9685039 | I7: =B7*50 -> 100 | J7: =B7*100 -> 200 | K7: =B7*200 -> 400 | L7: =IF(E7=0,0,ROUNDUP(B7*100/E7,0)) -> 8
A8: Angostura bitters | B8: 2 | C8: dash | D8: Host | E8: 120 | F8: dash | G8: 10 | H8: =IF(E8=0,0,B8/E8*G8) -> 0.16666667 | I8: =B8*50 -> 100 | J8: =B8*100 -> 200 | K8: =B8*200 -> 400 | L8: =IF(E8=0,0,ROUNDUP(B8*100/E8,0)) -> 2
A9: Sugar cube | B9: 1 | C9: each | D9: Bar | E9: 126 | F9: each | G9: 4 | H9: =IF(E9=0,0,B9/E9*G9) -> 0.031746032 | I9: =B9*50 -> 50 | J9: =B9*100 -> 100 | K9: =B9*200 -> 200 | L9: =IF(E9=0,0,ROUNDUP(B9*100/E9,0)) -> 1
A10: Orange peel | B10: 1 | C10: each | D10: Bar | E10: 4 | F10: each | G10: 1 | H10: =IF(E10=0,0,B10/E10*G10) -> 0.25 | I10: =B10*50 -> 50 | J10: =B10*100 -> 100 | K10: =B10*200 -> 200 | L10: =IF(E10=0,0,ROUNDUP(B10*100/E10,0)) -> 25
A11: Cost per drink, all ingredients | H11: =SUM(H7:H10) -> 2.4169166
A12: Your cost per drink in dry hire (bar-supplied items) | H12: =SUMIF(D7:D10,"Bar",H7:H10) -> 0.28174603
A14: NEGRONI | B14: Rocks glass, one large cube
A15: Gin | B15: 1 | C15: oz | D15: Host | E15: 25.4 | F15: oz | G15: 25 | H15: =IF(E15=0,0,B15/E15*G15) -> 0.98425197 | I15: =B15*50 -> 50 | J15: =B15*100 -> 100 | K15: =B15*200 -> 200 | L15: =IF(E15=0,0,ROUNDUP(B15*100/E15,0)) -> 4
A16: Sweet vermouth | B16: 1 | C16: oz | D16: Host | E16: 25.4 | F16: oz | G16: 18 | H16: =IF(E16=0,0,B16/E16*G16) -> 0.70866142 | I16: =B16*50 -> 50 | J16: =B16*100 -> 100 | K16: =B16*200 -> 200 | L16: =IF(E16=0,0,ROUNDUP(B16*100/E16,0)) -> 4
A17: Campari | B17: 1 | C17: oz | D17: Host | E17: 25.4 | F17: oz | G17: 28 | H17: =IF(E17=0,0,B17/E17*G17) -> 1.1023622 | I17: =B17*50 -> 50 | J17: =B17*100 -> 100 | K17: =B17*200 -> 200 | L17: =IF(E17=0,0,ROUNDUP(B17*100/E17,0)) -> 4
A18: Orange peel | B18: 1 | C18: each | D18: Bar | E18: 4 | F18: each | G18: 1 | H18: =IF(E18=0,0,B18/E18*G18) -> 0.25 | I18: =B18*50 -> 50 | J18: =B18*100 -> 100 | K18: =B18*200 -> 200 | L18: =IF(E18=0,0,ROUNDUP(B18*100/E18,0)) -> 25
A19: Cost per drink, all ingredients | H19: =SUM(H15:H18) -> 3.0452756
A20: Your cost per drink in dry hire (bar-supplied items) | H20: =SUMIF(D15:D18,"Bar",H15:H18) -> 0.25
A22: FRENCH 75 | B22: Flute or coupe
A23: Gin | B23: 1 | C23: oz | D23: Host | E23: 25.4 | F23: oz | G23: 25 | H23: =IF(E23=0,0,B23/E23*G23) -> 0.98425197 | I23: =B23*50 -> 50 | J23: =B23*100 -> 100 | K23: =B23*200 -> 200 | L23: =IF(E23=0,0,ROUNDUP(B23*100/E23,0)) -> 4
A24: Fresh lemon juice | B24: 0.5 | C24: oz | D24: Bar | E24: 32 | F24: oz | G24: 10 | H24: =IF(E24=0,0,B24/E24*G24) -> 0.15625 | I24: =B24*50 -> 25 | J24: =B24*100 -> 50 | K24: =B24*200 -> 100 | L24: =IF(E24=0,0,ROUNDUP(B24*100/E24,0)) -> 2
A25: Simple syrup | B25: 0.5 | C25: oz | D25: Bar | E25: 33.8 | F25: oz | G25: 8 | H25: =IF(E25=0,0,B25/E25*G25) -> 0.1183432 | I25: =B25*50 -> 25 | J25: =B25*100 -> 50 | K25: =B25*200 -> 100 | L25: =IF(E25=0,0,ROUNDUP(B25*100/E25,0)) -> 2
A26: Sparkling wine (brut) | B26: 2 | C26: oz | D26: Host | E26: 25.4 | F26: oz | G26: 14 | H26: =IF(E26=0,0,B26/E26*G26) -> 1.1023622 | I26: =B26*50 -> 100 | J26: =B26*100 -> 200 | K26: =B26*200 -> 400 | L26: =IF(E26=0,0,ROUNDUP(B26*100/E26,0)) -> 8
A27: Lemon twist | B27: 1 | C27: each | D27: Bar | E27: 6 | F27: each | G27: 0.75 | H27: =IF(E27=0,0,B27/E27*G27) -> 0.125 | I27: =B27*50 -> 50 | J27: =B27*100 -> 100 | K27: =B27*200 -> 200 | L27: =IF(E27=0,0,ROUNDUP(B27*100/E27,0)) -> 17
A28: Cost per drink, all ingredients | H28: =SUM(H23:H27) -> 2.4862074
A29: Your cost per drink in dry hire (bar-supplied items) | H29: =SUMIF(D23:D27,"Bar",H23:H27) -> 0.3995932
A31: MAI TAI | B31: Rocks glass or tiki mug, crushed ice. Allergen: orgeat is made from almonds (tree nuts)
A32: Aged dark rum | B32: 1 | C32: oz | D32: Host | E32: 25.4 | F32: oz | G32: 25 | H32: =IF(E32=0,0,B32/E32*G32) -> 0.98425197 | I32: =B32*50 -> 50 | J32: =B32*100 -> 100 | K32: =B32*200 -> 200 | L32: =IF(E32=0,0,ROUNDUP(B32*100/E32,0)) -> 4
A33: White rum | B33: 1 | C33: oz | D33: Host | E33: 25.4 | F33: oz | G33: 20 | H33: =IF(E33=0,0,B33/E33*G33) -> 0.78740157 | I33: =B33*50 -> 50 | J33: =B33*100 -> 100 | K33: =B33*200 -> 200 | L33: =IF(E33=0,0,ROUNDUP(B33*100/E33,0)) -> 4
A34: Orange curacao | B34: 0.5 | C34: oz | D34: Host | E34: 25.4 | F34: oz | G34: 22 | H34: =IF(E34=0,0,B34/E34*G34) -> 0.43307087 | I34: =B34*50 -> 25 | J34: =B34*100 -> 50 | K34: =B34*200 -> 100 | L34: =IF(E34=0,0,ROUNDUP(B34*100/E34,0)) -> 2
A35: Orgeat (almond) syrup | B35: 0.5 | C35: oz | D35: Bar | E35: 25.4 | F35: oz | G35: 12 | H35: =IF(E35=0,0,B35/E35*G35) -> 0.23622047 | I35: =B35*50 -> 25 | J35: =B35*100 -> 50 | K35: =B35*200 -> 100 | L35: =IF(E35=0,0,ROUNDUP(B35*100/E35,0)) -> 2
A36: Fresh lime juice | B36: 0.75 | C36: oz | D36: Bar | E36: 32 | F36: oz | G36: 10 | H36: =IF(E36=0,0,B36/E36*G36) -> 0.234375 | I36: =B36*50 -> 37.5 | J36: =B36*100 -> 75 | K36: =B36*200 -> 150 | L36: =IF(E36=0,0,ROUNDUP(B36*100/E36,0)) -> 3
A37: Mint sprig | B37: 1 | C37: each | D37: Bar | E37: 20 | F37: each | G37: 2 | H37: =IF(E37=0,0,B37/E37*G37) -> 0.1 | I37: =B37*50 -> 50 | J37: =B37*100 -> 100 | K37: =B37*200 -> 200 | L37: =IF(E37=0,0,ROUNDUP(B37*100/E37,0)) -> 5
A38: Cost per drink, all ingredients | H38: =SUM(H32:H37) -> 2.7753199
A39: Your cost per drink in dry hire (bar-supplied items) | H39: =SUMIF(D32:D37,"Bar",H32:H37) -> 0.57059547
A41: PINA COLADA | B41: Hurricane glass. Allergen: coconut (cream of coconut)
A42: White rum | B42: 2 | C42: oz | D42: Host | E42: 25.4 | F42: oz | G42: 20 | H42: =IF(E42=0,0,B42/E42*G42) -> 1.5748031 | I42: =B42*50 -> 100 | J42: =B42*100 -> 200 | K42: =B42*200 -> 400 | L42: =IF(E42=0,0,ROUNDUP(B42*100/E42,0)) -> 8
A43: Aged rum float | B43: 0.5 | C43: oz | D43: Host | E43: 25.4 | F43: oz | G43: 25 | H43: =IF(E43=0,0,B43/E43*G43) -> 0.49212598 | I43: =B43*50 -> 25 | J43: =B43*100 -> 50 | K43: =B43*200 -> 100 | L43: =IF(E43=0,0,ROUNDUP(B43*100/E43,0)) -> 2
A44: Cream of coconut | B44: 2 | C44: oz | D44: Bar | E44: 15 | F44: oz | G44: 4 | H44: =IF(E44=0,0,B44/E44*G44) -> 0.53333333 | I44: =B44*50 -> 100 | J44: =B44*100 -> 200 | K44: =B44*200 -> 400 | L44: =IF(E44=0,0,ROUNDUP(B44*100/E44,0)) -> 14
A45: Pineapple juice | B45: 4 | C45: oz | D45: Bar | E45: 46 | F45: oz | G45: 4 | H45: =IF(E45=0,0,B45/E45*G45) -> 0.34782609 | I45: =B45*50 -> 200 | J45: =B45*100 -> 400 | K45: =B45*200 -> 800 | L45: =IF(E45=0,0,ROUNDUP(B45*100/E45,0)) -> 9
A46: Pineapple wedge | B46: 1 | C46: each | D46: Bar | E46: 16 | F46: each | G46: 4 | H46: =IF(E46=0,0,B46/E46*G46) -> 0.25 | I46: =B46*50 -> 50 | J46: =B46*100 -> 100 | K46: =B46*200 -> 200 | L46: =IF(E46=0,0,ROUNDUP(B46*100/E46,0)) -> 7
...

Sheet 3 Example Quotes
A1: 3 EXAMPLE QUOTES — calculated with the same formulas as the "Pricing Calculator" tab
A2: Kit estimates for illustration only, not market prices: change the inputs in "Pricing Calculator" to price your own events. All three are dry hire: the host buys the alcohol.
A4: INPUTS | B4: Wedding, 120 guests, 5 hours | C4: Corporate holiday party, 100 guests, 4 hours | D4: Private birthday, 60 guests, 4 hours
A5: Bar package | B5: Full bar – dry hire | C5: Full bar – dry hire | D5: Limited bar (beer, wine + 1 signature) – dry hire
A6: Guests expected | B6: 120 | C6: 100 | D6: 60
A7: Hours of bar service | B7: 5 | C7: 4 | D7: 4
A8: Drinks per guest in the first hour | B8: 2 | C8: 2 | D8: 2
A9: Drinks per guest in each following hour | B9: 1 | C9: 1 | D9: 1
A10: Bartenders working the event | B10: 3 | C10: 2 | D10: 1
A11: Barbacks / setup crew working the event | B11: 1 | C11: 1 | D11: 0
A12: Setup, travel and breakdown hours per person | B12: 3.5 | C12: 3 | D12: 2.5
A13: Bartender hourly wage | B13: 20 | C13: 20 | D13: 20
A14: Barback hourly wage | B14: 16 | C14: 16 | D14: 16
A15: Employer payroll taxes and workers' comp (% of wages) | B15: 0.1 | C15: 0.1 | D15: 0.1
A16: Mixers, garnishes and N/A drinks per drink served | B16: 0.38 | C16: 0.38 | D16: 0.38
A17: Alcohol cost per drink (licensed package only) | B17: 3 | C17: 3 | D17: 3
... A28: Sales tax rate (state + local) | B28: 0.08 | C28: 0.08 | D28: 0.08
A29: Does your state tax the bar service and the service charge? | B29: Yes | C29: Yes | D29: No
A30: Deposit to book the date (% of total) | B30: 0.3 | C30: 0.3 | D30: 0.3
A31: Minimum charge for the bar service (subtotal floor) | B31: 400 | C31: 400 | D31: 400
A32: Price of an extra hour of service (quoted separately) | B32: 150 | C32: 150 | D32: 150
A34: RESULT | B34: Wedding, 120 guests, 5 hours | C34: Corporate holiday party, 100 guests, 4 hours | D34: Private birthday, 60 guests, 4 hours
A35: Drinks to plan for | B35: =$B$6*($B$8+MAX(0,$B$7-1)*$B$9) -> 720 | C35: =$C$6*($C$8+MAX(0,$C$7-1)*$C$9) -> 500 | D35: =$D$6*($D$8+MAX(0,$D$7-1)*$D$9) -> 300
A36: Ice to bring (lb) | B36: =$B$6*$B$19 -> 180 | C36: =$C$6*$C$19 -> 150 | D36: =$D$6*$D$19 -> 90
A37: Suggested bartenders for this package (Kit estimate) | B37: =IFERROR(ROUNDUP($B$6/INDEX('Pricing Calculator'!$B$60:$B$62,MATCH($B$5,'Pricing Calculator'!$A$60:$A$62,0)),0),"—") -> 3 | C37: =IFERROR(ROUNDUP($C$6/INDEX('Pricing Calculator'!$B$60:$B$62,MATCH($C$5,'Pricing Calculator'!$A$60:$A$62,0)),0),"—") -> 2 | D37: =IFERROR(ROUNDUP($D$6/INDEX('Pricing Calculator'!$B$60:$B$62,MATCH($D$5,'Pricing Calculator'!$A$60:$A$62,0)),0),"—") -> 1
A38: Staff cost (wages + payroll taxes) | B38: =($B$10*$B$13+$B$11*$B$14)*($B$7+$B$12)*(1+$B$15) -> 710.6 | C38: =($C$10*$C$13+$C$11*$C$14)*($C$7+$C$12)*(1+$C$15) -> 431.2 | D38: =($D$10*$D$13+$D$11*$D$14)*($D$7+$D$12)*(1+$D$15) -> 143
A39: Mixers, garnishes and N/A drinks | B39: =$B$35*$B$16 -> 273.6 | C39: =$C$35*$C$16 -> 190 | D39: =$D$35*$D$16 -> 114
A40: Alcohol (licensed package only) | B40: =IF($B$5='Pricing Calculator'!$A$62,$B$35*$B$17,0) -> 0 | C40: =IF($C$5='Pricing Calculator'!$A$62,$C$35*$C$17,0) -> 0 | D40: =IF($D$5='Pricing Calculator'!$A$62,$D$35*$D$17,0) -> 0
A41: Cups, straws, napkins and menu signs | B41: =$B$6*$B$18 -> 66 | C41: =$C$6*$C$18 -> 55 | D41: =$D$6*$D$18 -> 33
A42: Ice | B42: =$B$36*$B$20 -> 45 | C42: =$C$36*$C$20 -> 37.5 | D42: =$D$36*$D$20 -> 22.5
A43: Mileage | B43: =$B$21*$B$22 -> 42 | C43: =$C$21*$C$22 -> 21 | D43: =$D$21*$D$22 -> 14
A44: Total direct cost | B44: =$B$38+$B$39+$B$40+$B$41+$B$42+$B$43 -> 1137.2 | C44: =$C$38+$C$39+$C$40+$C$41+$C$42+$C$43 -> 734.7 | D44: =$D$38+$D$39+$D$40+$D$41+$D$42+$D$43 -> 326.5
A45: Direct cost per guest | B45: =$B$44/$B$6 -> 9.4766667 | C45: =$C$44/$C$6 -> 7.347 | D45: =$D$44/$D$6 -> 5.4416667
A46: PRICE PER GUEST before service charge and tax | B46: =ROUNDUP(MAX(0,$B$44/(1-$B$26-$B$25)-$B$23)/$B$6*(1+$B$24)*2,0)/2 -> 19 | C46: =ROUNDUP(MAX(0,$C$44/(1-$C$26-$C$25)-$C$23)/$C$6*(1+$C$24)*2,0)/2 -> 16.5 | D46: =ROUNDUP(MAX(0,$D$44/(1-$D$26-$D$25)-$D$23)/$D$6*(1+$D$24)*2,0)/2 -> 16
A47: Bar service subtotal | B47: =MAX($B$46*$B$6+$B$23,$B$31) -> 2530 | C47: =MAX($C$46*$C$6+$C$23,$C$31) -> 1650 | D47: =MAX($D$46*$D$6+$D$23,$D$31) -> 960
A48: Equivalent price per hour of service | B48: =$B$47/$B$7 -> 506 | C48: =$C$47/$C$7 -> 412.5 | D48: =$D$47/$D$7 -> 240
A49: Service charge | B49: =$B$47*$B$27 -> 379.5 | C49: =$C$47*$C$27 -> 0 | D49: =$D$47*$D$27 -> 0
A50: Sales tax | B50: =($B$47+IF($B$29="Yes",$B$49,0))*$B$28 -> 232.76 | C50: =($C$47+IF($C$29="Yes",$C$49,0))*$C$28 -> 132 | D50: =($D$47+IF($D$29="Yes",$D$49,0))*$D$28 -> 76.8
A51: TOTAL TO QUOTE | B51: =$B$47+$B$49+$B$50 -> 3142.26 | C51: =$C$47+$C$49+$C$50 -> 1782 | D51: =$D$47+$D$49+$D$50 -> 1036.8
A52: Deposit to book the date | B52: =$B$51*$B$30 -> 942.678 | C52: =$C$51*$C$30 -> 534.6 | D52: =$D$51*$D$30 -> 311.04
...

Sheet Instructions
A1: HOW TO USE THE MOBILE BAR PRICING CALCULATOR
A2: This workbook turns your costs into a price per guest and a full quote, and builds the shopping list for the event. You type only in the GREEN cells; the gross margin is calculated, never typed. The default model is dry hire (you supply the alcohol; we bring the bar, the bartenders and everything else).
A3: 1. "Pricing Calculator": choose the bar package, then enter guests, hours of service and the drinks rule (2 drinks per guest in the first hour and 1 per hour after: eventplanning.com). The suggested number of bartenders comes from the table at the bottom of the tab (guests per bartender by package: edit it to your own standard).
A4: 2. Enter the staff (bartenders, barbacks, paid hours, wages, payroll taxes) and the costs you supply: mixers and garnishes per drink, cups and napkins per guest, ice and mileage. The alcohol cost only counts with the licensed package.
A5: 3. Set a flat bar fee if you charge one, the specialty bar upcharge, the marketplace fee, your target margin, the service charge, your sales tax rate and the switch "Does your state tax the bar service and the service charge?". The price per guest is the direct cost divided by (1 - target margin - marketplace fee), minus the flat fee, rounded up to the next 0.50; the subtotal never goes below your minimum.
A6: 4. "Drinks & Shopping List": the drink mix of each package and the bottle math give the host's shopping list (spirits split by type, wine, beer, sparkling wine for the toast) and what the bar brings (ice in bags, cups, napkins, mixer servings). Send it to the host about two weeks before the event.
A7: 5. "Signature Cocktail Specs": ten recipes with the amount per drink, who buys each ingredient in dry hire, the cost per drink from the pack prices you type, and the quantities for 50, 100 and 200 drinks.
A8: 6. "3 Example Quotes": three complete quotes calculated with the same formulas.
A9: DRY HIRE: WHAT YOU CAN AND CANNOT CHARGE
A11: In dry hire the host buys and owns the alcohol and keeps what is left. Do not sell drinks, drink tickets or admission that includes drinks, do not add a markup on the alcohol, and keep any tip jar only where your state allows it: Missouri treats admission fees, tips and alcohol surcharges as possible sales (Missouri Division of Alcohol and Tobacco Control, Industry Circular 24-01). Rules vary by state: check yours before you quote.
A12: SERVICE CHARGE, GRATUITY AND SALES TAX (US)
A14: A mandatory service charge is not a tip: the part you pay out to the staff is wages, with payroll taxes (IRS Rev. Rul. 2012-18), and the part you keep is revenue. A voluntary gratuity is the client's decision and belongs to the staff: this calculator keeps it out of the price and the total.
... A25: Planning tool, not financial, tax or legal advice. Requirements vary by state, county and city — check with your accountant and local authorities.
