Workbook

Sheet Pollo
A1: CALCULADORA DEL POLLO — CUÁNTO PESA ASADO, CUÁNTO CUESTA Y CUÁNTOS POLLOS NECESITAS
A2: Escribe solo en las celdas VERDES: todo lo demás se calcula. Importes sin IVA. Todos los valores por defecto son una estimación del kit, editable: cámbialos por los de tu proveedor y, sobre todo, por lo que midas en tus propios pollos.
A3: AVISO FIJO. El rendimiento del asado (76 %) es una estimación del kit; la referencia del USDA es 78 %, con un rango de 68 a 84 %. Pesa 5 pollos crudos y asados de la misma carga, y ajusta el rendimiento hasta que coincida con lo que mides.
A5: A. EL POLLO | B5: Valor | C5: Notas
A6: Peso medio del pollo en canal (kg) | B6: 1.45 | C6: Pollo limpio de 1,4 a 1,5 kg: el calibre que pide el asador. Pésalo en la recepción. Estimación del kit, editable.
A7: Precio del pollo en canal (€/kg, sin IVA) | B7: 3.05 | C7: Unos 2,96 € el kilo en origen y 3,25 € en Makro (octubre de 2026): el kit pone 3,05 €. Pon el de tu proveedor. Estimación del kit, editable.
A8: Sazón, aceite y sal por pollo (€, sin IVA) | B8: 0.13 | C8: Adobo, aceite y sal de un pollo. Estimación del kit, editable.
A9: Rendimiento del asado (peso asado ÷ peso en canal) | B9: 0.76 | C9: Lo que queda del pollo tras el asado, con hueso. Mídelo con 5 pollos de la misma carga (hoja «Instrucciones»). Estimación del kit, editable.
A10: Referencia: rendimiento del pollo entero asado (USDA) | B10: 0.78 | C10: Referencia fija: el USDA da 78 % con un rango de 68 a 84 %. No se edita.
A11: Personas que comen de un pollo | B11: 3 | C11: Número entero mayor que 0. Para un plato principal con guarnición suelen ser 3. Estimación del kit, editable.
A12: Personas que quieres atender (encargo o evento) | B12: 40 | C12: Número entero mayor que 0. Te dice cuántos pollos pedir.
A13: Pollos sobrantes al cierre | B13: 2 | C13: Pollos enteros que quedan sin vender al cerrar. Cuéntalos; por defecto 2. Estimación del kit, editable.
A14: Parte del sobrante que se reaprovecha (%) | B14: 0.5 | C14: Croquetas, ensalada de pollo o relleno del día siguiente, tras el enfriado correcto. La parte que se tira cuesta dinero. Estimación del kit, editable.
A15: Gramos por kilo (constante) | B15: 1000 | C15: Constante: un kilo son 1.000 gramos. No se edita.
A16: Medios pollos que salen de un pollo (constante) | B16: 2 | C16: Constante: un pollo se parte en 2 mitades. No se edita.
A17: Cuartos de pollo que salen de un pollo (constante) | B17: 4 | C17: Constante: un pollo se parte en 4 cuartos. No se edita.
A19: RESULTADOS | B19: Valor | C19: Notas
A20: PESO ASADO DE UN POLLO (kg) | B20: =$B$6*$B$9 -> 1.102 | C20: Peso en canal × rendimiento.
A21: Merma del asado (kg) | B21: =$B$6-$B$20 -> 0.348 | C21: Agua, grasa y piel que se pierden en el asador.
A22: Merma del asado (%) | B22: =$B$21/$B$6 -> 0.24 | C22: Merma ÷ peso en canal.
A23: RENDIMIENTO DEL POLLO (%) | B23: =$B$20/$B$6 -> 0.76 | C23: Peso asado ÷ peso en canal.
A24: Tu rendimiento frente a la referencia USDA (%) | B24: =$B$23/$B$10 -> 0.97435897 | C24: Por debajo de 100 %: pierdes más que la referencia; mídelo otra vez.
A25: COSTE POR POLLO ENTERO (€) | B25: =$B$6*$B$7+$B$8 -> 4.5525 | C25: Peso en canal × precio por kilo + sazón. Alimenta el escandallo.
A26: COSTE POR KG ASADO (€) | B26: =$B$25/$B$20 -> 4.1311252 | C26: Coste del pollo ÷ kilos asados.
A27: Gramos asados del pollo entero (g) | B27: =$B$20*$B$15 -> 1102 | C27: Peso asado × 1.000.
A28: Gramos asados de medio pollo (g) | B28: =$B$27/$B$16 -> 551 | C28: Pollo entero asado ÷ 2.
A29: Gramos asados de un cuarto (g) | B29: =$B$27/$B$17 -> 275.5 | C29: Pollo entero asado ÷ 4.
A30: Coste de medio pollo (€) | B30: =$B$25/$B$16 -> 2.27625 | C30: Coste del pollo ÷ 2.
A31: Coste de un cuarto de pollo (€) | B31: =$B$25/$B$17 -> 1.138125 | C31: Coste del pollo ÷ 4.
A32: POLLOS PARA LAS N PERSONAS (pollos) | B32: =ROUNDUP($B$12/$B$11,0) -> 14 | C32: Personas ÷ personas por pollo, redondeado hacia arriba.
A33: Kilos en canal que tienes que comprar (kg) | B33: =$B$32*$B$6 -> 20.3 | C33: Pollos × peso en canal.
A34: Coste de los sobrantes que se tiran al cierre (€) | B34: =$B$13*(1-$B$14)*$B$25 -> 4.5525 | C34: Sobrantes × parte que no se reaprovecha × coste del pollo.

Sheet Asador
A1: CALCULADORA DEL ASADOR — SI TUS ESPADAS LLEGAN A LA PUNTA DEL DOMINGO
A2: Escribe solo en las celdas VERDES: todo lo demás se calcula. Todos los valores por defecto son una estimación del kit, editable. La capacidad cuenta las tandas completas que caben entre el primer encendido y la hora límite.
A3: AVISO FIJO. El tiempo de asado (75 minutos) no tiene fuente publicada: ninguna ficha da el de un pollo de 1,5 kg. Cronométralo con tu asador y tu calibre antes de fiarte de la capacidad.
A5: A. EL ASADOR Y EL DOMINGO | B5: Valor | C5: Notas
A6: Espadas del asador | B6: 12 | C6: Número entero mayor que 0. Pon las de tu modelo (los hay de 6, 8 y 12).
A7: Pollos por espada | B7: 5 | C7: Las fichas dan de 4 a 6 según el calibre. Número entero mayor que 0.
A8: Minutos de asado de una tanda | B8: 75 | C8: SIN FUENTE PUBLICADA: ninguna ficha da el tiempo de un pollo de 1,5 kg. Mídelo con tu asador (hoja «Instrucciones»). Estimación del kit, editable.
A9: Minutos de carga, descarga y limpieza entre tandas | B9: 15 | C9: Espetar la tanda siguiente mientras sale la anterior. Estimación del kit, editable.
A10: Primer encendido: hora | B10: 10 | C10: Hora entera (0 a 23). Con 10 y 30 minutos, el asador se enciende a las 10:30. Estimación del kit, editable.
A11: Primer encendido: minutos | B11: 30 | C11: Minutos (0 a 59).
A12: Hora límite para tener los pollos asados: hora | B12: 15 | C12: La punta del domingo termina hacia las 15:00. Hora entera (0 a 23). Estimación del kit, editable.
A13: Hora límite para tener los pollos asados: minutos | B13: 0 | C13: Minutos (0 a 59).
A14: Pollos que vendes un domingo normal | B14: 106 | C14: El del caso del plan de negocio. Cámbialo por el tuyo. Estimación del kit, editable.
A15: Parte del domingo que se vende en la punta (%) | B15: 0.8 | C15: Entre las 12:30 y las 15:00. Estimación del kit, editable.
A16: Subida del domingo de agosto o de un festivo (%) | B16: 0.15 | C16: Sobre un domingo normal. En la costa puede ser mayor. Estimación del kit, editable.
A17: Potencia media de gas que consume el asador (kW) | B17: 60 | C17: La ficha de un asador de 8 espadas da 56 kW a pleno rendimiento; el de 12 espadas gasta más y su media real queda por debajo del máximo de su ficha. Pon la de la tuya. Estimación del kit, editable.
... A19: Minutos por hora (constante) | B19: 60 | C19: Constante: una hora son 60 minutos. No se edita.
A21: RESULTADOS | B21: Valor | C21: Notas
A22: POLLOS POR TANDA | B22: =$B$6*$B$7 -> 60 | C22: Espadas × pollos por espada.
A23: Minutos de un ciclo completo | B23: =$B$8+$B$9 -> 90 | C23: Asado + carga y descarga.
A24: Tandas por hora | B24: =$B$19/$B$23 -> 0.66666667 | C24: 60 minutos ÷ minutos del ciclo.
A25: Capacidad por hora (pollos) | B25: =$B$22*$B$24 -> 40 | C25: Pollos por tanda × tandas por hora.
A26: Minutos entre el primer encendido y la hora límite | B26: =($B$12-$B$10)*$B$19+($B$13-$B$11) -> 270 | C26: Si sale negativo, la hora límite es anterior al encendido.
A27: TANDAS ANTES DE LA HORA LÍMITE | B27: =INT(MAX(0,$B$26)/$B$23) -> 3 | C27: Ciclos completos que caben en ese tiempo.
A28: CAPACIDAD DEL DOMINGO ANTES DE LA HORA LÍMITE (pollos) | B28: =$B$22*$B$27 -> 180 | C28: Pollos por tanda × tandas.
A29: Pollos que se venden en la punta de un domingo normal | B29: =$B$14*$B$15 -> 84.8 | C29: Pollos del domingo × parte que se vende en la punta.
A30: Tandas que necesita un domingo normal (en todo el día) | B30: =ROUNDUP($B$14/$B$22,0) -> 2 | C30: Pollos del domingo ÷ pollos por tanda, hacia arriba.
A31: Tandas que necesita la punta de un domingo normal | B31: =ROUNDUP($B$29/$B$22,0) -> 2 | C31: Pollos de la punta ÷ pollos por tanda, hacia arriba.
A32: Sobrante (+) o déficit (−) en la punta (pollos) | B32: =$B$28-$B$29 -> 95.2 | C32: Capacidad antes de la hora límite menos pollos de la punta.
A33: Semáforo de la punta (domingo normal) | B33: =IF($B$32>=0,"Cubierto","No llegas a la punta") -> Cubierto | C33: Cubierto si la capacidad llega a los pollos de la punta.
A34: Pollos de un domingo de agosto o festivo | B34: =ROUNDUP($B$14*(1+$B$16),0) -> 122 | C34: Domingo normal más la subida, hacia arriba.
A35: Tandas que necesita un domingo de agosto o festivo | B35: =ROUNDUP($B$34/$B$22,0) -> 3 | C35: Pollos de agosto ÷ pollos por tanda, hacia arriba.
A36: Sobrante (+) o déficit (−) en la punta de agosto (pollos) | B36: =$B$28-$B$34*$B$15 -> 82.4 | C36: Capacidad menos la punta de agosto.
A37: Semáforo de la punta de agosto | B37: =IF($B$36>=0,"Cubierto","No llegas a la punta") -> Cubierto | C37: Cubierto si la capacidad llega a la punta de agosto.
A38: Encendido más tardío (minutos desde las 00:00) | B38: =$B$12*$B$19+$B$13-$B$31*$B$23 -> 720 | C38: Hora límite menos las tandas de la punta por su ciclo.
A39: Encendido más tardío: hora | B39: =INT($B$38/$B$19) -> 12 | C39: Si enciendes después, no llegas a la punta.
A40: Encendido más tardío: minutos | B40: =MOD($B$38,$B$19) -> 0
A41: Horas de asador encendido en un domingo normal | B41: =$B$30*$B$23/$B$19 -> 3 | C41: Tandas × ciclo ÷ 60.
A42: Gas de un domingo normal (€) | B42: =$B$17*$B$41*$B$18 -> 18 | C42: Potencia × horas × precio por kWh.
A43: GAS POR POLLO ASADO (€) | B43: =$B$42/($B$30*$B$22) -> 0.15 | C43: Gas del día ÷ pollos que caben en las tandas del día.

Sheet Escandallo
A1: ESCANDALLO DEL POLLO Y DE LOS COMBOS — ENTERO, MEDIO, CUARTO Y 6 COMBOS, EN GRAMOS
A2: Escribe solo en las celdas VERDES (precios, gramos, nombres, fracciones de pollo y precios de carta). Importes sin IVA salvo el precio de carta. Los precios son una estimación del kit, editable: pon los de tu proveedor. El coste del pollo viene de la hoja «Pollo».
A4: DATOS GENERALES | B4: Valor | D4: Notas
A5: IVA de la comida (%) | B5: 0.1 | D5: Comida preparada, en sala, para llevar y a domicilio: 10 % (Ley 37/1992, art. 91).
A6: IVA de la bebida que sale del local (%) | B6: 0.21 | D6: Cerveza, vino y refrescos con azúcares o edulcorantes añadidos para llevar: 21 % (Ley 37/1992, art. 91).
A7: IVA del pan vendido suelto (%) | B7: 0.04 | D7: Pan común: 4 % (Ley 37/1992, art. 91).
A8: Food cost objetivo (% sobre el precio sin IVA) | B8: 0.33 | D8: Referencia del pedido tipo para llevar: 33 %. Estimación del kit, editable.
A9: Margen de vigilancia sobre el objetivo (puntos) | B9: 0.06 | D9: Hasta este margen por encima del objetivo, el semáforo dice «Vigila el coste». El pollo entero suele caer aquí.
A10: Merma de producción de las guarniciones (%) | B10: 0.03 | D10: Patata frita que se tira, ensalada que no se aprovecha. El pollo no la lleva: su merma está en el rendimiento. Estimación del kit, editable.
A11: Envase por pedido para llevar (€, sin IVA) | B11: 0.6 | D11: Bolsa térmica, bandeja y tarrinas de salsa de un pedido. El envase de plástico se cobra aparte en el tique. Estimación del kit, editable.
A12: Comisión de la plataforma de reparto (%) | B12: 0.3 | D12: Sobre el precio sin IVA del pedido. Revisa tu contrato. Estimación del kit, editable.
A13: Recargo de precio en la plataforma (%) | B13: 0.15 | D13: Lo que subes el precio en la plataforma para compensar (unos 2 € por pieza). Estimación del kit, editable.
A15: INGREDIENTE (en gramos) | B15: €/kg sin IVA | C15: Unidad | D15: Pollo entero | E15: Medio pollo | F15: Cuarto de pollo | G15: Pollo con patatas | H15: Medio pollo con croquetas y ensalada | I15: Menú de cuarto de sala | J15: Medio a la brasa con papas, ensalada y cremas | K15: Familiar de domingo | L15: Combo de plataforma | M15: ORIGEN DEL PRECIO
A16: Precio de carta con IVA (€) | D16: 12.9 | E16: 7 | F16: 4 | G16: 16.4 | H16: 12.5 | I16: 9.5 | J16: 14.5 | K16: 29.9 | L16: 21.9
A17: De ese precio, bebida que sale del local, con IVA (€) | D17: 0 | E17: 0 | F17: 0 | G17: 0 | H17: 0 | I17: 0 | J17: 0 | K17: 0 | L17: 1.8
A18: De ese precio, pan vendido suelto, con IVA (€) | D18: 0 | E18: 0 | F18: 0 | G18: 0 | H18: 0 | I18: 0 | J18: 0 | K18: 0 | L18: 0
A19: Patatas fritas (congeladas, con aceite) | B19: 2.55 | C19: g | D19: 0 | E19: 0 | F19: 0 | G19: 350 | H19: 0 | I19: 250 | J19: 0 | K19: 500 | L19: 0 | M19: estimación del kit
A20: Patatas asadas (frescas) | B20: 1.1 | C20: g | D20: 0 | E20: 0 | F20: 0 | G20: 0 | H20: 0 | I20: 0 | J20: 300 | K20: 0 | L20: 400 | M20: estimación del kit
A21: Croquetas de pollo (con el sobrante) | B21: 8.5 | C21: g | D21: 0 | E21: 0 | F21: 0 | G21: 0 | H21: 150 | I21: 0 | J21: 0 | K21: 160 | L21: 0 | M21: estimación del kit (croquetas de 25 g hechas con el pollo del día anterior)
A22: Ensaladilla (con ovoproducto) | B22: 6.25 | C22: g | D22: 0 | E22: 0 | F22: 0 | G22: 0 | H22: 0 | I22: 0 | J22: 0 | K22: 200 | L22: 0 | M22: estimación del kit
A23: Ensalada mixta | B23: 4 | C23: g | D23: 0 | E23: 0 | F23: 0 | G23: 0 | H23: 100 | I23: 70 | J23: 120 | K23: 150 | L23: 100 | M23: estimación del kit
A24: Alioli (con ovoproducto pasteurizado) | B24: 7 | C24: g | D24: 0 | E24: 0 | F24: 0 | G24: 25 | H24: 0 | I24: 0 | J24: 25 | K24: 40 | L24: 0 | M24: estimación del kit
A25: Salsa de yogur y hierbas (sin huevo) | B25: 4.5 | C25: g | D25: 0 | E25: 0 | F25: 0 | G25: 0 | H25: 0 | I25: 0 | J25: 30 | K25: 40 | L25: 40 | M25: estimación del kit
A26: INGREDIENTE (en unidades) | B26: €/ud sin IVA | C26: Unidad
A27: Pollo asado (fracción de pollo entero) | B27: ='Pollo'!$B$25 -> 4.5525 | C27: pollo | D27: 1 | E27: 0.5 | F27: 0.25 | G27: 1 | H27: 0.5 | I27: 0.25 | J27: 0.5 | K27: 1 | L27: 1 | M27: enlazado desde la hoja Pollo (coste por pollo entero)
A28: Pan (ud) | B28: 0.18 | C28: ud | D28: 0 | E28: 0 | F28: 0 | G28: 0 | H28: 0 | I28: 1 | J28: 0 | K28: 2 | L28: 1 | M28: estimación del kit
A29: Bebida (lata o botellín, ud) | B29: 0.55 | C29: ud | D29: 0 | E29: 0 | F29: 0 | G29: 0 | H29: 0 | I29: 0 | J29: 0 | K29: 0 | L29: 1 | M29: estimación del kit
A31: RESULTADO POR PLATO (gramos y unidades en las columnas de arriba) | D31: =D15 -> Pollo entero | E31: =E15 -> Medio pollo | F31: =F15 -> Cuarto de pollo | G31: =G15 -> Pollo con patatas | H31: =H15 -> Medio pollo con croquetas y ensalada | I31: =I15 -> Menú de cuarto de sala | J31: =J15 -> Medio a la brasa con papas, ensalada y cremas | K31: =K15 -> Familiar de domingo | L31: =L15 -> Combo de plataforma
A32: Peso servido en el plato (g) | D32: =SUM(D$19:D$25)+D$27*'Pollo'!$B$27 -> 1102 | E32: =SUM(E$19:E$25)+E$27*'Pollo'!$B$27 -> 551 | F32: =SUM(F$19:F$25)+F$27*'Pollo'!$B$27 -> 275.5 | G32: =SUM(G$19:G$25)+G$27*'Pollo'!$B$27 -> 1477 | H32: =SUM(H$19:H$25)+H$27*'Pollo'!$B$27 -> 801 | I32: =SUM(I$19:I$25)+I$27*'Pollo'!$B$27 -> 595.5 | J32: =SUM(J$19:J$25)+J$27*'Pollo'!$B$27 -> 1026 | K32: =SUM(K$19:K$25)+K$27*'Pollo'!$B$27 -> 2192 | L32: =SUM(L$19:L$25)+L$27*'Pollo'!$B$27 -> 1642
A33: Coste del pollo (€) | D33: =D$27*$B$27 -> 4.5525 | E33: =E$27*$B$27 -> 2.27625 | F33: =F$27*$B$27 -> 1.138125 | G33: =G$27*$B$27 -> 4.5525 | H33: =H$27*$B$27 -> 2.27625 | I33: =I$27*$B$27 -> 1.138125 | J33: =J$27*$B$27 -> 2.27625 | K33: =K$27*$B$27 -> 4.5525 | L33: =L$27*$B$27 -> 4.5525
A34: Coste de guarniciones, pan y bebida, sin merma (€) | D34: =SUMPRODUCT(D$19:D$25,$B$19:$B$25)/'Pollo'!$B$15+SUMPRODUCT(D$28:D$29,$B$28:$B$29) -> 0 | E34: =SUMPRODUCT(E$19:E$25,$B$19:$B$25)/'Pollo'!$B$15+SUMPRODUCT(E$28:E$29,$B$28:$B$29) -> 0 | F34: =SUMPRODUCT(F$19:F$25,$B$19:$B$25)/'Pollo'!$B$15+SUMPRODUCT(F$28:F$29,$B$28:$B$29) -> 0 | G34: =SUMPRODUCT(G$19:G$25,$B$19:$B$25)/'Pollo'!$B$15+SUMPRODUCT(G$28:G$29,$B$28:$B$29) -> 1.0675 | H34: =SUMPRODUCT(H$19:H$25,$B$19:$B$25)/'Pollo'!$B$15+SUMPRODUCT(H$28:H$29,$B$28:$B$29) -> 1.675 | I34: =SUMPRODUCT(I$19:I$25,$B$19:$B$25)/'Pollo'!$B$15+SUMPRODUCT(I$28:I$29,$B$28:$B$29) -> 1.0975 | J34: =SUMPRODUCT(J$19:J$25,$B$19:$B$25)/'Pollo'!$B$15+SUMPRODUCT(J$28:J$29,$B$28:$B$29) -> 1.12 | K34: =SUMPRODUCT(K$19:K$25,$B$19:$B$25)/'Pollo'!$B$15+SUMPRODUCT(K$28:K$29,$B$28:$B$29) -> 5.305 | L34: =SUMPRODUCT(L$19:L$25,$B$19:$B$25)/'Pollo'!$B$15+SUMPRODUCT(L$28:L$29,$B$28:$B$29) -> 1.75
A35: COSTE CON MERMA DE GUARNICIONES (€) | D35: =D33+D34*(1+$B$10) -> 4.5525 | E35: =E33+E34*(1+$B$10) -> 2.27625 | F35: =F33+F34*(1+$B$10) -> 1.138125 | G35: =G33+G34*(1+$B$10) -> 5.652025 | H35: =H33+H34*(1+$B$10) -> 4.0015 | I35: =I33+I34*(1+$B$10) -> 2.26855 | J35: =J33+J34*(1+$B$10) -> 3.42985 | K35: =K33+K34*(1+$B$10) -> 10.01665 | L35: =L33+L34*(1+$B$10) -> 6.355
A36: Precio de venta sin IVA (€) | D36: =(D16-D17-D18)/(1+$B$5)+D17/(1+$B$6)+D18/(1+$B$7) -> 11.727273 | E36: =(E16-E17-E18)/(1+$B$5)+E17/(1+$B$6)+E18/(1+$B$7) -> 6.3636364 | F36: =(F16-F17-F18)/(1+$B$5)+F17/(1+$B$6)+F18/(1+$B$7) -> 3.6363636 | G36: =(G16-G17-G18)/(1+$B$5)+G17/(1+$B$6)+G18/(1+$B$7) -> 14.909091 | H36: =(H16-H17-H18)/(1+$B$5)+H17/(1+$B$6)+H18/(1+$B$7) -> 11.363636 | I36: =(I16-I17-I18)/(1+$B$5)+I17/(1+$B$6)+I18/(1+$B$7) -> 8.6363636 | J36: =(J16-J17-J18)/(1+$B$5)+J17/(1+$B$6)+J18/(1+$B$7) -> 13.181818 | K36: =(K16-K17-K18)/(1+$B$5)+K17/(1+$B$6)+K18/(1+$B$7) -> 27.181818 | L36: =(L16-L17-L18)/(1+$B$5)+L17/(1+$B$6)+L18/(1+$B$7) -> 19.760331
A37: FOOD COST (%) | D37: =D35/D36 -> 0.38819767 | E37: =E35/E36 -> 0.35769643 | F37: =F35/F36 -> 0.31298437 | G37: =G35/G36 -> 0.37909924 | H37: =H35/H36 -> 0.352132 | I37: =I35/I36 -> 0.26267421 | J37: =J35/J36 -> 0.26019552 | K37: =K35/K36 -> 0.36850552 | L37: =L35/L36 -> 0.32160393
A38: Semáforo contra el objetivo | D38: =IF(D37<=$B$8,"En objetivo",IF(D37<=$B$8+$B$9,"Vigila el coste","Por encima del objetivo")) -> Vigila el coste | E38: =IF(E37<=$B$8,"En objetivo",IF(E37<=$B$8+$B$9,"Vigila el coste","Por encima del objetivo")) -> Vigila el coste | F38: =IF(F37<=$B$8,"En objetivo",IF(F37<=$B$8+$B$9,"Vigila el coste","Por encima del objetivo")) -> En objetivo | G38: =IF(G37<=$B$8,"En objetivo",IF(G37<=$B$8+$B$9,"Vigila el coste","Por encima del objetivo")) -> Vigila el coste | H38: =IF(H37<=$B$8,"En objetivo",IF(H37<=$B$8+$B$9,"Vigila el coste","Por encima del objetivo")) -> Vigila el coste | I38: =IF(I37<=$B$8,"En objetivo",IF(I37<=$B$8+$B$9,"Vigila el coste","Por encima del objetivo")) -> En objetivo | J38: =IF(J37<=$B$8,"En objetivo",IF(J37<=$B$8+$B$9,"Vigila el coste","Por encima del objetivo")) -> En objetivo | K38: =IF(K37<=$B$8,"En objetivo",IF(K37<=$B$8+$B$9,"Vigila el coste","Por encima del objetivo")) -> Vigila el coste | L38: =IF(L37<=$B$8,"En objetivo",IF(L37<=$B$8+$B$9,"Vigila el coste","Por encima del objetivo")) -> En objetivo
A39: Margen bruto (€, precio sin IVA − coste) | D39: =D36-D35 -> 7.1747727 | E39: =E36-E35 -> 4.0873864 | F39: =F36-F35 -> 2.4982386 | G39: =G36-G35 -> 9.2570659 | H39: =H36-H35 -> 7.3621364 | I39: =I36-I35 -> 6.3678136 | J39: =J36-J35 -> 9.7519682 | K39: =K36-K35 -> 17.165168 | L39: =L36-L35 -> 13.405331
A40: PVP con IVA sugerido para llegar al objetivo (€) | D40: =D35/$B$8*(1+$B$5) -> 15.175 | E40: =E35/$B$8*(1+$B$5) -> 7.5875 | F40: =F35/$B$8*(1+$B$5) -> 3.79375 | G40: =G35/$B$8*(1+$B$5) -> 18.840083 | H40: =H35/$B$8*(1+$B$5) -> 13.338333 | I40: =I35/$B$8*(1+$B$5) -> 7.5618333 | J40: =J35/$B$8*(1+$B$5) -> 11.432833 | K40: =K35/$B$8*(1+$B$5) -> 33.388833 | L40: =L35/$B$8*(1+$B$5) -> 21.183333
A42: MARGEN POR CANAL (todos los platos) | D42: =D15 -> Pollo entero | E42: =E15 -> Medio pollo | F42: =F15 -> Cuarto de pollo | G42: =G15 -> Pollo con patatas | H42: =H15 -> Medio pollo con croquetas y ensalada | I42: =I15 -> Menú de cuarto de sala | J42: =J15 -> Medio a la brasa con papas, ensalada y cremas | K42: =K15 -> Familiar de domingo | L42: =L15 -> Combo de plataforma
A43: Sala: margen (€) | D43: =D39 -> 7.1747727 | E43: =E39 -> 4.0873864 | F43: =F39 -> 2.4982386 | G43: =G39 -> 9.2570659 | H43: =H39 -> 7.3621364 | I43: =I39 -> 6.3678136 | J43: =J39 -> 9.7519682 | K43: =K39 -> 17.165168 | L43: =L39 -> 13.405331
A44: Sala: margen (%) | D44: =D43/D36 -> 0.61180233 | E44: =E43/E36 -> 0.64230357 | F44: =F43/F36 -> 0.68701563 | G44: =G43/G36 -> 0.62090076 | H44: =H43/H36 -> 0.647868 | I44: =I43/I36 -> 0.73732579 | J44: =J43/J36 -> 0.73980448 | K44: =K43/K36 -> 0.63149448 | L44: =L43/L36 -> 0.67839607
...

Sheet Instrucciones
A1: INSTRUCCIONES DE USO — Calculadora del pollo, el asador y el escandallo
A2: Tres herramientas en un libro: la hoja «Pollo» te dice cuánto pesa un pollo asado, cuánto cuesta cada kilo y cada ración y cuántos pollos necesitas para un número de personas; la hoja «Asador» compara la capacidad de tus espadas con la punta del domingo y la de agosto; la hoja «Escandallo» calcula el coste, el food cost, el margen y el precio de carta del pollo entero, el medio, el cuarto y 6 combos, con el margen en sala, en el mostrador y en la plataforma. Solo se escribe en las celdas VERDES; lo demás se calcula.
A3: Todos los valores por defecto son una estimación del kit, editable: son ejemplos coherentes con el caso del plan de negocio, no precios de nadie. Cámbialos por los de tu proveedor y por lo que midas en tu cocina antes de decidir precios.
A4: HOJA «POLLO»
A6: 1. Cómo medir el rendimiento. Pesa 5 pollos crudos de la misma tanda, asa los 5 juntos y pésalos otra vez al sacarlos, ya escurridos. Divide el peso asado entre el peso en canal y usa la media: es tu rendimiento real. La referencia del USDA es 78 %, con un rango de 68 a 84 %.
A7: 2. El resultado más útil es el coste por pollo entero y por kilo asado, que alimentan el escandallo, y los pollos que tienes que pedir para un encargo o un evento. Fíjate también en el coste de los sobrantes que se tiran: los pollos que quedan al cerrar y no se reaprovechan son dinero perdido.
A8: 3. Seguridad alimentaria. Mide la temperatura en el muslo con sonda: 74 °C o más es el criterio de este kit para dar un pollo por hecho, no una temperatura fijada por una norma. En la vitrina caliente, mantén 63 °C o más y fija en tu APPCC una hora límite propia. El sobrante que vayas a reaprovechar se enfría de 60 a 10 °C en menos de 2 horas (RD 1086/2020, art. 30) y se recalienta a 74 °C o más.
A9: HOJA «ASADOR»
A11: 1. Escribe tus espadas, los pollos por espada y los minutos de asado. El tiempo de asado no tiene fuente publicada: cronometra una tanda desde que enciendes hasta que el muslo llega a 74 °C, con el calibre que compras. Suma los minutos de carga y descarga.
A12: 2. Escribe la hora del primer encendido y la hora límite en que quieres tener los pollos asados (la punta del domingo termina hacia las 15:00). La hoja cuenta las tandas completas que caben, la capacidad y si cubres la punta de un domingo normal y la de agosto.
A13: 3. El encendido más tardío es la hora a la que tienes que encender el asador para no quedarte corto en la punta. El gas por pollo usa la potencia media y el precio del gas que pongas: es una estimación, compruébala con tu factura o tu bombona.
A14: HOJA «ESCANDALLO»
... A27: Versión 1.0 · noviembre 2026 · aichef.pro/plan-negocio-polleria · info@aichef.pro
