Workbook

Sheet 0. Supuestos
A1: SUPUESTOS — aquí se teclean las TASAS y los DRIVERS del modelo
A2: Cambia las celdas VERDES: el resto del libro se recalcula solo. Las partidas de gasto se teclean en su hoja (también en verde) y no se repiten aquí.
A3: ACTIVIDAD
A4: Pedidos/día (media del año 1) | B4: 77 | C4: Pedidos al día, media del año: 1 pedido es un pedido de mostrador o un encargo, uno de plataforma o un cliente sentado en la sala. A la semana, unos 278 para llevar, 45 de plataforma y 140 de sala en 6 días. El domingo llega a unos 150 (un tercio de los pollos de la semana) y un martes se queda en unos 40. Contrástalo con el paso de gente de tu calle un domingo a mediodía y un martes
A5: Ticket medio SIN IVA (€) | B5: 15.8 | C5: SIN IVA, por pedido: el de mostrador (0,8 pollos, patatas, algún extra, pan, salsas y bebida) suma unos 17,70 € con IVA; el de plataforma, unos 20,50 € con su precio más alto; el cliente de sala (menú de cuarto de pollo o medio pollo a la brasa, algo para compartir, bebida y postre), unos 16,10 €. La media sin IVA sale en 15,80 €. El pollo entero del caso cuesta 12,90 € con IVA, dentro de los 11-14 € del asador de barrio (cartas leídas en 2026). El precio con IVA está en la fila «PVP equivalente con IVA» de abajo
A6: Días de apertura al año | B6: 300 | C6: 365 días menos los 52 lunes de cierre, 10 días de cierre en enero (mantenimiento del asador y vacaciones) y 3 días sueltos; los festivos abren como un domingo. Es el MISMO dato para la cuenta de resultados, el punto de equilibrio, los escenarios y las horas de personal
A7: Crecimiento de volumen del año 2 | B7: 0.06 | C7: Clientela que repite y encargos del domingo que se hacen costumbre el segundo año. Se aplica a los pedidos con el mismo ticket; el personal NO sube con este porcentaje: sale de la hoja Personal
A8: Crecimiento de volumen del año 3 | B8: 0.04 | C8: Sobre el año 2. Conservador: el techo lo pone el asador el domingo antes de las tres (60 pollos por carga con doce espadas) y el mostrador en la hora punta
A9: PVP equivalente con IVA (calculado) | B9: =IFERROR(IF($B$5="","",$B$5*(1+SUMPRODUCT('PyG 3 Años'!$E$10:$E$11,'PyG 3 Años'!$G$10:$G$11))),"") -> 17.433878 | C9: =IFERROR("Ticket sin IVA más el IVA medio ponderado de tus líneas de venta: "&TEXT(SUMPRODUCT('PyG 3 Años'!$E$10:$E$11,'PyG 3 Años'!$G$10:$G$11)*100,"0")&" %. En sala todo va al 10 % (art. 91.Uno.2.2.º de la Ley 37/1992, alcohol incluido); la bebida que sale para llevar o por plataforma (columna H de su línea en el P&L) mueve la media. Aquí va redondeado. Compáralo con el rango del sector, que va con IVA.","") -> Ticket sin IVA más el IVA medio ponderado de tus líneas de venta: 10 %. En sala todo va al 10 % (art. 91.Uno.2.2.º de la Ley 37/1992, alcohol incluido); la bebida que sale para llevar o por plataforma (columna H de su línea en el P&L) mueve la media. Aquí va redondeado. Compáralo con el rango del sector, que va con IVA.
A10: MIX Y COSTE DE MERCANCÍA
A11: Ventas de COMIDA sobre el total | B11: 0.9 | C11: Peso de la COMIDA sobre el total de ventas. Es un INPUT: cámbialo aquí y el P&L, la tesorería y el IVA repercutido se recalculan solos
A12: Ventas de BEBIDA sobre el total | B12: =IFERROR(IF(COUNT(B11)=0,"",1-B11),"") -> 0.1 | C12: Se calcula como el resto: comida + bebida = 100 %
A13: Coste de mercancía sobre las ventas de COMIDA | B13: 0.32 | C13: Materia prima de la comida sobre sus ventas: el pollo entero sale a un 38,8 % (el pollo es caro y se vende barato), el medio a un 35,8 %, las patatas a un 28 %, la ensaladilla a un 25 %, el menú de sala a un 26 % y las croquetas, hechas con el pollo del día anterior, a un 22 %: el pedido tipo para llevar queda en un 33 % y la sala en un 25 %. Un 31 % de media, más 1,5 puntos de merma (pollos que sobran y no llegan a croqueta, patata frita que se tira) y menos medio de redondeo. Cada 10 % que suba el pollo resta unos 6.700 € al resultado: el pollo es un precio estimado por el kit, pon el de tu proveedor y escandalla con la calculadora del pack
A14: Coste de mercancía sobre las ventas de BEBIDA | B14: 0.3 | C14: Lata o botella para llevar a unos 2,00 € y la caña, el refresco y el vino en la sala: un 30 % de media de su precio de venta. Si la cervecera te cede la nevera o el equipo de tiraje, pide el precio por escrito
A15: Consumibles sobre ventas | B15: 0.03 | C15: Bolsas térmicas de pollo, bandejas, envases de salsa, bolsas de asa, etiquetas, servilletas y guantes: unos 0,45 € por pedido (ningún proveedor publica tarifa: estimación del kit), y los envases para que el cliente de sala se lleve lo que no consuma (Ley 1/2025, art. 8). El envase de plástico de un solo uso se cobra aparte en el tique (Ley 7/2022, art. 55)
A16: Ventas por delivery sobre el total | B16: 0.11 | C16: Ventas por PLATAFORMA con su reparto (Glovo, Just Eat, Uber Eats) sobre el total. Lo que se recoge en el mostrador o por encargo NO paga comisión y no va aquí. El pollo entero aguanta bien el viaje; las patatas fritas llegan blandas: no subas del 12-15 % sin probarlo
A17: Comisión de la plataforma de delivery | B17: 0.3 | C17: Comisión de la plataforma con su reparto sobre lo que vende ese canal: el plan básico de Uber Eats ronda el 30 % más IVA, Glovo va del 15 al 35 % según la zona y Just Eat, del 13 al 35 %. Compruébala en tu contrato. Si repartes tú, pon 0 y suma el repartidor, con contrato laboral, a la hoja Personal
A18: Comisión de los medios de pago | B18: 0.008 | C18: Tarjeta y bizum sobre el total facturado
A19: PERSONAL
A20: Seguridad Social a cargo de la empresa | B20: 0.33 | C20: Contingencias comunes + AT/EP + desempleo + FOGASA + FP; ajusta a tu convenio y bonificaciones
A21: Número de pagas anuales | B21: 14 | C21: Salario bruto anual = bruto mensual × pagas
A22: SMI anual de referencia (€) | B22: 17094 | C22: SMI 2026: 17.094 € al año (1.221 €/mes en 14 pagas), suelo legal por jornada completa. Comprueba el importe vigente si presentas el plan en otro ejercicio
A23: LOCAL Y FIJOS
A24: Alquiler mensual del local (€) | B24: 1200 | C24: Local de 80 m² con salida de humos a cubierta posible (es el filtro del local): obrador y zona de asado de 25 m² a la vista, mostrador con vitrina caliente, sala de 20 plazas (16 en mesa y 4 en barra), aseos (uno adaptado) y almacén, en un barrio residencial de una ciudad media, cómodo para parar el coche y recoger el encargo, sin traspaso: unos 15 € el m². El peso sobre las ventas lo calcula el propio libro en la fila «Alquiler / Ventas» del P&L
A25: Fianza del alquiler (meses) | B25: 2 | C25: Dos meses de renta, lo habitual en un contrato de local de negocio: compruébalo con tu abogado
A26: Suministros mensuales de luz, agua y gas (€) | B26: 1000 | C26: El gas del asador de pollos (uno de ocho espadas declara 56 kW en su ficha), la luz de la freidora, el frío, la extracción y la climatización, y el agua. Estimación del kit: pide el histórico del local y mide el consumo del asador con la calculadora del pack
A27: Seguros (€/año) | B27: 1400 | C27: Responsabilidad civil de al menos 300.000 € y multirriesgo con incendio y avería del frío. Dile a la aseguradora que trabajas con asador de pollos y freidora a gas: cambia la prima y las condiciones
A28: Varios e imprevistos sobre ventas | B28: 0.02 | C28: Colchón de gasto corriente no presupuestado (pequeñas reparaciones, espadas o utillaje que se rompen, pruebas de carta)
A29: FINANCIACIÓN
A30: Recursos propios aportados (€) | B30: 50000 | C30: Aportación de los socios. Un banco pide entre el 25 y el 30 % de la necesidad de caja con dinero propio
A31: Préstamo bancario solicitado (€) | B31: 112000 | C31: Principal solicitado. La hoja de Financiación compara lo que aportas con la necesidad de caja de la hoja de inversión y te dice si sobra o falta: ajústalo con ese dato
A32: Tipo de interés nominal anual | B32: 0.06 | C32: Tipo nominal anual. Pide oferta a dos entidades y a una línea ICO antes de fijarlo; el asador, el frío y la freidora se pueden pagar con leasing o renting: compáralo
A33: Plazo del préstamo (años) | B33: 7 | C33: Años totales, carencia incluida
A34: Carencia de principal (años) | B34: 1 | C34: El primer año sólo intereses: obra, conducto de humos, gas y asador antes de facturar. Desde el segundo año se devuelve el principal: mira la holgura de caja de ese año en el Punto de Equilibrio
A35: Fondo de maniobra (meses de costes fijos) | B35: 3 | C35: Tres meses de costes fijos: el colchón para la rampa del arranque, que con el Mes 1 en enero cae sobre los meses más flojos del año (enero y febrero)
A36: FISCAL
A37: Impuesto de Sociedades, nueva creación | B37: 0.15 | C37: Art. 29.1 LIS: el PRIMER ejercicio con base imponible positiva y el SIGUIENTE. El libro lo aproxima contando los dos primeros ejercicios con base positiva: coincide con la ley salvo que entre ellos haya un ejercicio en pérdidas
A38: Impuesto de Sociedades, tipo general | B38: 0.25 | C38: A partir del tercer ejercicio con base positiva. Es el tipo general del art. 29.1 LIS: si tu cifra de negocios queda por debajo de 1 M € (microempresa) o de 10 M € (reducida dimensión), desde 2025 hay tipos más bajos que se implantan de forma gradual; confirma el de tu ejercicio con tu asesor y cámbialo aquí
A39: IVA repercutido de restauración | B39: 0.1 | C39: Tipo reducido de hostelería
A40: IVA repercutido/soportado general | B40: 0.21 | C40: Tipo general. En este libro lo usan dos cosas: el IVA que soportas al comprar el alcohol (el proveedor lo factura al 21 %) y el que repercutes por la bebida que sale para llevar o por plataforma (es una entrega de bienes). El alcohol servido en sala va al reducido, como fija la línea de bebida del P&L. Suministros, equipamiento y servicios tienen su tipo en la celda de abajo. En las compras, el libro manda al general la parte de la bebida que declara la celda «Bebida que compras al 21 %» de esta hoja: la cerveza, el vino y los refrescos con azúcares o edulcorantes añadidos, cuya factura va al 21 % (art. 91.Uno.1.1.º de la Ley 37/1992)
...

Sheet Inversión Inicial
A1: PLAN DE NEGOCIO: POLLERÍA Y ASADOR DE POLLOS
A2: Inversión inicial estimada — pollería-asador de barrio con asador de gas, mostrador y 20 plazas
A3: Ajusta las cifras a tu proyecto: son las de un caso tipo en una ciudad media, sin traspaso. Pon tus presupuestos reales en las celdas de importe.
A5: Concepto | B5: Importe | C5: % s/inversión | D5: Notas | E5: ¿Lleva IVA?
A6: INVERSIÓN | B6: =IFERROR(IF(COUNT(B7:B27)=0,"",SUM(B7:B27)),"") -> 97900 | C6: =IFERROR(B6/$B$30,"") -> 0.68858459
A7: Proyecto técnico de actividad y de salida de humos, y dirección de obra | B7: 3500 | C7: =IFERROR(B7/$B$30,"") -> 0.024617427 | D7: Proyecto de la actividad, del conducto de humos y de la instalación de gas, memoria para la licencia o la declaración responsable y certificado final de obra | E7: Sí
A8: Obra y acondicionamiento del local, rótulo y fachada | B8: 24000 | C8: =IFERROR(B8/$B$30,"") -> 0.16880521 | D8: Obrador alicatado, suelo antideslizante (también en los 2 m alrededor del asador), aseos (uno adaptado), mostrador de obra, falsos techos y aislamiento acústico, más el rótulo y la fachada. Estimación del kit: pide dos presupuestos | E8: Sí
A9: Conducto de extracción exclusivo hasta cubierta | B9: 6000 | C9: =IFERROR(B9/$B$30,"") -> 0.042201303 | D9: Conducto exclusivo hasta la cubierta para el asador, la freidora y el fogón: Madrid pide superar en 1 m lo que haya en 15 m (Ordenanza 4/2021). Con brasa de leña o carbón, además, filtro de partículas. Ningún fabricante da precio por metro: pide oferta con tu proyecto | E9: Sí
A10: Instalación eléctrica trifásica, cuadro y boletín | B10: 4500 | C10: =IFERROR(B10/$B$30,"") -> 0.031650977 | D10: Freidora, frío, extracción, climatización, lavavajillas y el motor del asador. Pregunta la potencia disponible ANTES de firmar: con un asador eléctrico hace falta trifásica, y ampliar la potencia tarda de 4 a 8 semanas | E10: Sí
A11: Fontanería, separador de grasas, climatización e instalación de gas | B11: 8000 | C11: =IFERROR(B11/$B$30,"") -> 0.056268404 | D11: Agua fría y caliente en el obrador, desagües con separador de grasas, climatización de la sala y la instalación de gas del asador, la freidora y el fogón por empresa instaladora habilitada, con su certificado (RD 919/2006) | E11: Sí
A12: Asador de pollos de gas de doce espadas y juego de espadas | B12: 5000 | C12: =IFERROR(B12/$B$30,"") -> 0.035167752 | D12: Asador vertical de gas de doce espadas, de 4 a 6 pollos por espada (60 por carga con 5). En el catálogo de un distribuidor de hostelería, de 4.373 a 5.967 € sin IVA, con las espadas aparte (2026). Con ocho espadas, de 2.493 a 4.126 €: mira la hoja del asador de la calculadora antes de elegir | E12: Sí
A13: Vitrina caliente de mostrador y mantenedor de patatas | B13: 2000 | C13: =IFERROR(B13/$B$30,"") -> 0.014067101 | D13: Vitrina expositora caliente que mantenga el pollo a 63 °C o más (las genéricas de 85-146 l rondan los 850-1.250 €) y un mantenedor de patatas fritas | E13: Sí
A14: Freidora doble y fogón | B14: 3000 | C14: =IFERROR(B14/$B$30,"") -> 0.021100651 | D14: Freidora de 2 × 10 l para las patatas y las croquetas (unos 1.900 € sin IVA la eléctrica de 15 kW) y un fogón para las guarniciones y las salsas. Estimación del kit | E14: Sí
A15: Campana extractora con motor y filtros | B15: 2000 | C15: =IFERROR(B15/$B$30,"") -> 0.014067101 | D15: Campana extractora de unos 3 m con motor y filtros de grasa sobre el asador, la freidora y el fogón, con un caudal de 1.800-2.200 m³/h para doce espadas. Sin precio de referencia para 3 m: estimación del kit | E15: Sí
A16: Frío: armarios de pollo crudo y adobado, congelador y vitrina refrigerada | B16: 5500 | C16: =IFERROR(B16/$B$30,"") -> 0.038684528 | D16: Armarios para el pollo crudo y el adobado a 4 °C o menos (las mollejas, a 3 °C o menos), congelador y la vitrina refrigerada de las guarniciones del mostrador | E16: Sí
A17: Lavavajillas de capota, fregaderos, lavamanos y mesas inox de espetar | B17: 5500 | C17: =IFERROR(B17/$B$30,"") -> 0.038684528 | D17: Lavavajillas de capota (las espadas caben), fregaderos, lavamanos de accionamiento no manual y una mesa de acero inoxidable para espetar el pollo crudo, SEPARADA de la de servir | E17: Sí
A18: Utillaje: sondas, básculas, GN, tijeras de trinchar, etiquetadora y vajilla | B18: 2500 | C18: =IFERROR(B18/$B$30,"") -> 0.017583876 | D18: Termómetros sonda, básculas, recipientes GN, tijeras de trinchar, vajilla de la sala y una etiquetadora para lo que envases antes de que el cliente lo pida (RD 126/2015, art. 5) | E18: Sí
... A24: Stock inicial: pollo, patata, aceite, envases y bebida | B24: 2500 | C24: =IFERROR(B24/$B$30,"") -> 0.017583876 | D24: Pollo, patata, aceite de girasol, especias de los adobos, bolsas térmicas y envases para llevar, y la bebida | E24: Sí
A25: Fianza del alquiler | B25: =IFERROR(IF('0. Supuestos'!$B$24="","",'0. Supuestos'!$B$24*'0. Supuestos'!$B$25),"") -> 2400 | C25: =IFERROR(B25/$B$30,"") -> 0.016880521 | D25: =IFERROR(""&TEXT('0. Supuestos'!$B$25,"0")&" meses de renta, al tipo de la hoja de Supuestos. Es un activo recuperable al cerrar: ni se amortiza ni lleva IVA","") -> 2 meses de renta, al tipo de la hoja de Supuestos. Es un activo recuperable al cerrar: ni se amortiza ni lleva IVA | E25: No
A26: Alquiler de los meses previos a la apertura | B26: =IFERROR(IF('0. Supuestos'!$B$24="","",'0. Supuestos'!$B$24*'0. Supuestos'!$B$54),"") -> 2400 | C26: =IFERROR(B26/$B$30,"") -> 0.016880521 | D26: =IFERROR("Renta "&IF('0. Supuestos'!$B$54=1,"del mes","de los "&TEXT('0. Supuestos'!$B$54,"0")&" meses")&" de obra y licencias. NO se solapa con el P&L, que arranca el día de la apertura: los doce meses del P&L son los doce de explotación","") -> Renta de los 2 meses de obra y licencias. NO se solapa con el P&L, que arranca el día de la apertura: los doce meses del P&L son los doce de explotación | E26: Sí
A27: Imprevistos de obra y acondicionamiento | B27: =IFERROR(IF(COUNT(B7,B8,B9,B10,B11)=0,"",ROUND((B7+B8+B9+B10+B11)*'0. Supuestos'!$B$55,0)),"") -> 4600 | C27: =IFERROR(B27/$B$30,"") -> 0.032354332 | D27: =IFERROR("Al "&TEXT('0. Supuestos'!$B$55,"0%")&" de las partidas de OBRA Y ACONDICIONAMIENTO de este bloque (Proyecto técnico de actividad y de salida de humos, y dirección de obra, Obra y acondicionamiento del local, rótulo y fachada, Conducto de extracción exclusivo hasta cubierta, "&"Instalación eléctrica trifásica, cuadro y boletín y Fontanería, separador de grasas, climatización e instalación de gas), no del bloque entero: el resto de partidas del bloque quedan fuera. Un banco no financia una reforma sin colchón: el "&"porcentaje está en la hoja de Supuestos","") -> Al 10% de las partidas de OBRA Y ACONDICIONAMIENTO de este bloque (Proyecto técnico de actividad y de salida de humos, y dirección de obra, Obra y acondicionamiento del local, rótulo y fachada, Conducto de extracción exclusivo hasta cubierta, Instalación eléctrica trifásica, cuadro y boletín y Fontanería, separador de grasas, climatización e instalación de gas), no del bloque entero: el resto de partidas del bloque quedan fuera. Un banco no financia una reforma sin colchón: el porcentaje está en la hoja de Supuestos | E27: Sí
A28: FONDO DE MANIOBRA | B28: =IFERROR(IF(B29="","",B29),"") -> 44275.705 | C28: =IFERROR(B28/$B$30,"") -> 0.31141541
A29: Colchón operativo hasta alcanzar el equilibrio | B29: =IFERROR(IF('0. Supuestos'!$B$35*('PyG 3 Años'!$B$37-'PyG 3 Años'!$B$35)=0,"",'0. Supuestos'!$B$35*('PyG 3 Años'!$B$37-'PyG 3 Años'!$B$35)/12),"") -> 44275.705 | C29: =IFERROR(B29/$B$30,"") -> 0.31141541 | D29: =IFERROR("Cubre "&TEXT('0. Supuestos'!$B$35,"0")&IF('0. Supuestos'!$B$35=1," mes"," meses")&" de costes fijos DE CAJA del año 1 (los del P&L menos la amortización, que no se paga), que es el mínimo que exigen las Instrucciones de este libro","") -> Cubre 3 meses de costes fijos DE CAJA del año 1 (los del P&L menos la amortización, que no se paga), que es el mínimo que exigen las Instrucciones de este libro | E29: No
A30: INVERSIÓN TOTAL (suma de los bloques) | B30: =IFERROR(B6+B28,"") -> 142175.7 | D30: =IFERROR("Los porcentajes de la columna C se leen sobre esta cifra, que incluye el fondo de maniobra ("&TEXT(C28,"0%")&" del total). Para comparar el desglose con otro plan, usa la fila de CAPEX de abajo.","") -> Los porcentajes de la columna C se leen sobre esta cifra, que incluye el fondo de maniobra (31% del total). Para comparar el desglose con otro plan, usa la fila de CAPEX de abajo.
A31: CAPEX (inversión sin el fondo de maniobra) | B31: =IFERROR(B30-B28,"") -> 97900 | D31: Es lo que se compra: obra, equipamiento, lanzamiento y gastos de constitución. El colchón de caja no es inversión, es circulante
A32: IVA soportado sobre la inversión (recuperable) | B32: =IFERROR(IF(B30="","",SUMIF($E$7:$E$27,"Sí",$B$7:$B$27)*'0. Supuestos'!$B$41),"") -> 19425 | D32: =IFERROR("Al "&TEXT('0. Supuestos'!$B$41,"0%")&" sobre las partidas marcadas con «Sí» en la columna de IVA. Las tasas y licencias no están sujetas y los seguros están exentos (art. 20.Uno.16 LIVA). Las tasas y aranceles registrales no llevan IVA; los honorarios de notaría y gestoría sí "&"(21 %, deducible). Se recupera con el modelo 303, pero hay que adelantarlo","") -> Al 21% sobre las partidas marcadas con «Sí» en la columna de IVA. Las tasas y licencias no están sujetas y los seguros están exentos (art. 20.Uno.16 LIVA). Las tasas y aranceles registrales no llevan IVA; los honorarios de notaría y gestoría sí (21 %, deducible). Se recupera con el modelo 303, pero hay que adelantarlo
A33: NECESIDAD TOTAL DE CAJA AL ARRANQUE | B33: =IFERROR(B30+B32,"") -> 161600.7 | D33: Es la cifra que tiene que cubrir la hoja de Financiación
A34: BASES DE AMORTIZACIÓN (no suman a la inversión)
A35: Obra, instalaciones y acondicionamiento | B35: =IFERROR(IF(B7="","",B7+B8+B9+B10+B11+B27),"") -> 50600 | D35: =IFERROR("Se amortiza en "&TEXT('0. Supuestos'!$B$44,"0")&" años","") -> Se amortiza en 10 años
A36: Maquinaria, mobiliario y equipos | B36: =IFERROR(IF(B12="","",B12+B13+B14+B15+B16+B17+B18+B19+B20+B21),"") -> 33000 | D36: =IFERROR("Se amortiza en "&TEXT('0. Supuestos'!$B$45,"0")&" años","") -> Se amortiza en 10 años
A37: Amortización anual del inmovilizado | B37: =IFERROR(B35/MAX(1,'0. Supuestos'!$B$44)+B36/MAX(1,'0. Supuestos'!$B$45),"") -> 8360 | D37: =IFERROR("No se amortizan, por no ser inmovilizado, Constitución de la SL, licencia, tasas, registro sanitario y APPCC, Marca, web, fotos y lanzamiento, Stock inicial: pollo, patata, aceite, envases y bebida, Fianza del alquiler, Alquiler de los "&"meses previos a la apertura ni Colchón operativo hasta alcanzar el equilibrio. Suman "&TEXT(B30-B35-B36,"0")&" € de los "&TEXT(B30,"0")&" € de inversión.","") -> No se amortizan, por no ser inmovilizado, Constitución de la SL, licencia, tasas, registro sanitario y APPCC, Marca, web, fotos y lanzamiento, Stock inicial: pollo, patata, aceite, envases y bebida, Fianza del alquiler, Alquiler de los meses previos a la apertura ni Colchón operativo hasta alcanzar el equilibrio. Suman 58576 € de los 142176 € de inversión.

Sheet PyG 3 Años
A1: CUENTA DE RESULTADOS PREVISIONAL — 3 AÑOS
A2: Escenario realista — pollería-asador con mostrador, encargos, plataforma y sala
A4: Concepto | B4: Año 1 | C4: Año 2 | D4: Año 3 | E4: % s/ventas (año 1) | F4: Notas | G4: Tipo de IVA de la línea (%) | H4: Bebida para llevar o por plataforma al 21 % (%)
A5: INGRESOS
A6: Pedidos/día (media) | B6: =IFERROR(IF('0. Supuestos'!$B$4="","",'0. Supuestos'!$B$4),"") -> 77 | C6: =IFERROR(B6*(1+'0. Supuestos'!$B$7),"") -> 81.62 | D6: =IFERROR(C6*(1+'0. Supuestos'!$B$8),"") -> 84.8848 | F6: El crecimiento de los años 2 y 3 está en la hoja de Supuestos
A7: Ticket medio sin IVA | B7: =IFERROR(IF('0. Supuestos'!$B$5="","",'0. Supuestos'!$B$5),"") -> 15.8 | C7: =IFERROR(IF(B7="","",B7),"") -> 15.8 | D7: =IFERROR(IF(C7="","",C7),"") -> 15.8 | F7: Constante en euros del año 1: una subida de precios es una decisión aparte
A8: Días de apertura al año | B8: =IFERROR(IF('0. Supuestos'!$B$6="","",'0. Supuestos'!$B$6),"") -> 300 | C8: =IFERROR(IF(B8="","",B8),"") -> 300 | D8: =IFERROR(IF(C8="","",C8),"") -> 300
A9: INGRESOS TOTALES (sin IVA) | B9: =IFERROR(IF(B6*B7*B8=0,"",B6*B7*B8),"") -> 364980 | C9: =IFERROR(IF(C6*C7*C8=0,"",C6*C7*C8),"") -> 386878.8 | D9: =IFERROR(IF(D6*D7*D8=0,"",D6*D7*D8),"") -> 402353.95 | E9: =IFERROR(IF(B9="","",1),"") -> 1
A10: Ventas de pollo asado y cocina (mostrador, encargos, plataforma y sala) | B10: =IFERROR(IF(B9="","",B9*$E$10),"") -> 328482 | C10: =IFERROR(IF(C9="","",C9*$E$10),"") -> 348190.92 | D10: =IFERROR(IF(D9="","",D9*$E$10),"") -> 362118.56 | E10: =IFERROR(IF('0. Supuestos'!$B$11="","",'0. Supuestos'!$B$11),"") -> 0.9 | F10: Pollo asado entero, medio y en cuartos, patatas, croquetas, ensaladilla, ensaladas, salsas y pan: para llevar (mostrador y encargos) unos 61 % de las ventas, por plataforma un 11 % y en sala un 28 %. Todo al 10 % de IVA, se coma en la mesa o salga del local (art. 91.Uno.1.1.º y 2.2.º de la Ley 37/1992); el pan común que vendas suelto va al 4 %, pero es una parte mínima y el libro lo deja aquí | G10: =IFERROR(IF(B9="","",'0. Supuestos'!$B$39),"") -> 0.1
A11: Ventas de bebida (refrescos, agua, cerveza y vino) | B11: =IFERROR(IF(B9="","",B9*$E$11),"") -> 36498 | C11: =IFERROR(IF(C9="","",C9*$E$11),"") -> 38687.88 | D11: =IFERROR(IF(D9="","",D9*$E$11),"") -> 40235.395 | E11: =IFERROR(IF('0. Supuestos'!$B$12="","",'0. Supuestos'!$B$12),"") -> 0.1 | F11: Bebida de sala y la que sale con los pedidos · La columna H es la parte de la bebida que sale del local y va al 21 %: la cerveza, el vino y los refrescos con azúcares o edulcorantes añadidos (art. 91.Uno.1.1.º a y b de la Ley 37/1992); el agua y lo que no lleve azúcares ni edulcorantes añadidos, y toda la bebida en sala, al 10 %. Un 31 % = un 3,1 % de las ventas | G11: =IFERROR(IF(B9="","",H11*0.21+(1-H11)*'0. Supuestos'!$B$39),"") -> 0.1341 | H11: 0.31
A12: COSTES VARIABLES
A13: Coste de mercancía — comida | B13: =IFERROR(IF(B9="","",B9*'0. Supuestos'!$B$11*'0. Supuestos'!$B$13),"") -> 105114.24 | C13: =IFERROR(IF(C9="","",C9*'0. Supuestos'!$B$11*'0. Supuestos'!$B$13),"") -> 111421.09 | D13: =IFERROR(IF(D9="","",D9*'0. Supuestos'!$B$11*'0. Supuestos'!$B$13),"") -> 115877.94 | E13: =IFERROR(B13/$B$9,"") -> 0.288 | F13: =IFERROR("Al "&TEXT('0. Supuestos'!$B$13,"0%")&" de las ventas de COMIDA, no del total: la bebida tiene su propia línea · Pollo, aceite, patata congelada y salsas compradas al 10 %; patata fresca, verdura, pan y huevos al 4 % (art. 91.Dos.1.1.º de la Ley 37/1992). Ajústalo a tus facturas","") -> Al 32% de las ventas de COMIDA, no del total: la bebida tiene su propia línea · Pollo, aceite, patata congelada y salsas compradas al 10 %; patata fresca, verdura, pan y huevos al 4 % (art. 91.Dos.1.1.º de la Ley 37/1992). Ajústalo a tus facturas | G13: 0.091
A14: Coste de mercancía — bebida | B14: =IFERROR(IF(B9="","",B9*'0. Supuestos'!$B$12*'0. Supuestos'!$B$14),"") -> 10949.4 | C14: =IFERROR(IF(C9="","",C9*'0. Supuestos'!$B$12*'0. Supuestos'!$B$14),"") -> 11606.364 | D14: =IFERROR(IF(D9="","",D9*'0. Supuestos'!$B$12*'0. Supuestos'!$B$14),"") -> 12070.619 | E14: =IFERROR(B14/$B$9,"") -> 0.03 | F14: =IFERROR("Al "&TEXT('0. Supuestos'!$B$14,"0%")&" de las ventas de BEBIDA","") -> Al 30% de las ventas de BEBIDA | G14: =IFERROR(IF(B9="","",('0. Supuestos'!$B$62*'0. Supuestos'!$B$40+(1-'0. Supuestos'!$B$62)*'0. Supuestos'!$B$39)),"") -> 0.177
A15: Consumibles y envases | B15: =IFERROR(IF(B9="","",B9*'0. Supuestos'!$B$15),"") -> 10949.4 | C15: =IFERROR(IF(C9="","",C9*'0. Supuestos'!$B$15),"") -> 11606.364 | D15: =IFERROR(IF(D9="","",D9*'0. Supuestos'!$B$15),"") -> 12070.619 | E15: =IFERROR(B15/$B$9,"") -> 0.03 | G15: =IFERROR(IF(B9="","",'0. Supuestos'!$B$41),"") -> 0.21
A16: Comisiones de delivery | B16: =IFERROR(IF(B9="","",B9*'0. Supuestos'!$B$16*'0. Supuestos'!$B$17),"") -> 12044.34 | C16: =IFERROR(IF(C9="","",C9*'0. Supuestos'!$B$16*'0. Supuestos'!$B$17),"") -> 12767 | D16: =IFERROR(IF(D9="","",D9*'0. Supuestos'!$B$16*'0. Supuestos'!$B$17),"") -> 13277.68 | E16: =IFERROR(B16/$B$9,"") -> 0.033 | F16: Sobre las ventas DEL CANAL. Con 0 % de delivery en Supuestos, esta línea vale cero | G16: =IFERROR(IF(B9="","",'0. Supuestos'!$B$41),"") -> 0.21
A17: Comisiones de los medios de pago | B17: =IFERROR(IF(B9="","",B9*'0. Supuestos'!$B$18),"") -> 2919.84 | C17: =IFERROR(IF(C9="","",C9*'0. Supuestos'!$B$18),"") -> 3095.0304 | D17: =IFERROR(IF(D9="","",D9*'0. Supuestos'!$B$18),"") -> 3218.8316 | E17: =IFERROR(B17/$B$9,"") -> 0.008 | F17: Las comisiones de los medios de pago están EXENTAS de IVA (art. 20.Uno.18 LIVA): no se deduce nada por ellas | G17: 0
A18: Varios e imprevistos | B18: =IFERROR(IF(B9="","",B9*'0. Supuestos'!$B$28),"") -> 7299.6 | C18: =IFERROR(IF(C9="","",C9*'0. Supuestos'!$B$28),"") -> 7737.576 | D18: =IFERROR(IF(D9="","",D9*'0. Supuestos'!$B$28),"") -> 8047.079 | E18: =IFERROR(B18/$B$9,"") -> 0.02 | F18: =IFERROR("Al "&TEXT('0. Supuestos'!$B$28,"0%")&" de las ventas. Es un coste VARIABLE: sube y baja con la facturación, así que no puede vivir en los costes fijos","") -> Al 2% de las ventas. Es un coste VARIABLE: sube y baja con la facturación, así que no puede vivir en los costes fijos | G18: =IFERROR(IF(B9="","",'0. Supuestos'!$B$41),"") -> 0.21
A19: TOTAL COSTES VARIABLES | B19: =IFERROR(IF(B9="","",SUM(B13:B18)),"") -> 149276.82 | C19: =IFERROR(IF(C9="","",SUM(C13:C18)),"") -> 158233.43 | D19: =IFERROR(IF(D9="","",SUM(D13:D18)),"") -> 164562.77 | E19: =IFERROR(B19/$B$9,"") -> 0.409
A20: MARGEN BRUTO | B20: =IFERROR(IF(B9="","",B9-B19),"") -> 215703.18 | C20: =IFERROR(IF(C9="","",C9-C19),"") -> 228645.37 | D20: =IFERROR(IF(D9="","",D9-D19),"") -> 237791.19 | E20: =IFERROR(B20/$B$9,"") -> 0.591
A21: COSTES FIJOS
A22: Alquiler del local | B22: =IFERROR(IF(B9="","",'0. Supuestos'!$B$24*12),"") -> 14400 | C22: =IFERROR(IF(C9="","",B22*(1+'0. Supuestos'!$B$48)),"") -> 14400 | D22: =IFERROR(IF(D9="","",C22*(1+'0. Supuestos'!$B$48)),"") -> 14400 | E22: =IFERROR(B22/$B$9,"") -> 0.039454217 | F22: El importe mensual está en la hoja de Supuestos; aquí se multiplica por doce. Los dos meses de renta previos a la apertura están en la hoja de Inversión y NO se cuentan dos veces | G22: =IFERROR(IF(B9="","",'0. Supuestos'!$B$41),"") -> 0.21
A23: Personal (nóminas + Seguridad Social) | B23: =IFERROR(IF(B9="","",'Personal'!$G$12),"") -> 128682.82 | C23: =IFERROR(IF(C9="","",'Personal'!$B$16),"") -> 134682.82 | D23: =IFERROR(IF(D9="","",'Personal'!$B$17),"") -> 140682.82 | E23: =IFERROR(B23/$B$9,"") -> 0.35257499 | F23: Sale de la hoja de Personal: es el MISMO número, no una estimación aparte. Los años 2 y 3 suman las INCORPORACIONES declaradas en esa hoja, no un porcentaje de volumen | G23: 0
A24: Suministros (luz, agua, gas) | B24: =IFERROR(IF(B9="","",'0. Supuestos'!$B$26*12),"") -> 12000 | C24: =IFERROR(IF(C9="","",B24*(1+'0. Supuestos'!$B$48)),"") -> 12000 | D24: =IFERROR(IF(D9="","",C24*(1+'0. Supuestos'!$B$48)),"") -> 12000 | E24: =IFERROR(B24/$B$9,"") -> 0.032878514 | F24: Luz y gas van al 21 %; la factura del agua, al 10 %. El libro aplica a toda esta partida el tipo de la columna de al lado (21 %): si el agua pesa mucho en tu local, sepárala en su línea | G24: =IFERROR(IF(B9="","",'0. Supuestos'!$B$41),"") -> 0.21
A25: Seguros (RC + multirriesgo) | B25: =IFERROR(IF(B9="","",'0. Supuestos'!$B$27),"") -> 1400 | C25: =IFERROR(IF(C9="","",B25*(1+'0. Supuestos'!$B$48)),"") -> 1400 | D25: =IFERROR(IF(D9="","",C25*(1+'0. Supuestos'!$B$48)),"") -> 1400 | E25: =IFERROR(B25/$B$9,"") -> 0.0038358266 | F25: Las operaciones de seguro están EXENTAS de IVA (art. 20.Uno.16 LIVA): la prima no lleva IVA deducible | G25: 0
A26: Gestoría laboral, fiscal y contable | B26: 2400 | C26: =IFERROR(IF(C9="","",B26*(1+'0. Supuestos'!$B$48)),"") -> 2400 | D26: =IFERROR(IF(D9="","",C26*(1+'0. Supuestos'!$B$48)),"") -> 2400 | E26: =IFERROR(B26/$B$9,"") -> 0.0065757028 | F26: Contabilidad, impuestos de la SL, nóminas y contratos de la plantilla | G26: =IFERROR(IF(B9="","",'0. Supuestos'!$B$41),"") -> 0.21
A27: Mantenimiento de la campana extractora, el gas, el asador y el frío | B27: 2800 | C27: =IFERROR(IF(C9="","",B27*(1+'0. Supuestos'!$B$48)),"") -> 2800 | D27: =IFERROR(IF(D9="","",C27*(1+'0. Supuestos'!$B$48)),"") -> 2800 | E27: =IFERROR(B27/$B$9,"") -> 0.0076716532 | F27: Dos limpiezas al año de la campana extractora y del conducto (la grasa del asador de pollos y de la freidora las pide; Madrid exige al menos una en su Ordenanza 4/2021, art. 23: mira la de tu ayuntamiento), la revisión del gas y del asador (quemadores, motor y espadas) y el frigorista | G27: =IFERROR(IF(B9="","",'0. Supuestos'!$B$41),"") -> 0.21
A28: Marketing y publicidad | B28: 3500 | C28: =IFERROR(IF(C9="","",B28*(1+'0. Supuestos'!$B$48)),"") -> 3500 | D28: =IFERROR(IF(D9="","",C28*(1+'0. Supuestos'!$B$48)),"") -> 3500 | E28: =IFERROR(B28/$B$9,"") -> 0.0095895666 | F28: Ficha de Google Business, redes sociales, fotos, buzoneo y tarjetas con el teléfono de encargos, y las fechas fuertes: el verano, la Navidad y, si haces el pollo a la brasa al estilo peruano, el Día del Pollo a la Brasa (tercer domingo de julio). La campaña de apertura va en la inversión | G28: =IFERROR(IF(B9="","",'0. Supuestos'!$B$41),"") -> 0.21
A29: Software, TPV, teléfono e internet | B29: 1500 | C29: =IFERROR(IF(C9="","",B29*(1+'0. Supuestos'!$B$48)),"") -> 1500 | D29: =IFERROR(IF(D9="","",C29*(1+'0. Supuestos'!$B$48)),"") -> 1500 | E29: =IFERROR(B29/$B$9,"") -> 0.0041098142 | F29: Cuota del TPV con Veri*factu, la tablet de las plataformas, el teléfono de encargos e internet | G29: =IFERROR(IF(B9="","",'0. Supuestos'!$B$41),"") -> 0.21
A30: Limpieza, lavandería, EPI y análisis de autocontrol | B30: 1200 | C30: =IFERROR(IF(C9="","",B30*(1+'0. Supuestos'!$B$48)),"") -> 1200 | D30: =IFERROR(IF(D9="","",C30*(1+'0. Supuestos'!$B$48)),"") -> 1200 | E30: =IFERROR(B30/$B$9,"") -> 0.0032878514 | F30: Productos de limpieza y desengrasantes, lavado de uniformes y paños, guantes y los análisis de autocontrol que fije tu APPCC | G30: =IFERROR(IF(B9="","",'0. Supuestos'!$B$41),"") -> 0.21
A31: Gestión de residuos y del aceite y la grasa usados | B31: 900 | C31: =IFERROR(IF(C9="","",B31*(1+'0. Supuestos'!$B$48)),"") -> 900 | D31: =IFERROR(IF(D9="","",C31*(1+'0. Supuestos'!$B$48)),"") -> 900 | E31: =IFERROR(B31/$B$9,"") -> 0.0024658885 | F31: La tasa de basuras y el cartón, y el aceite de la freidora y la grasa de la bandeja de goteo del asador con gestor autorizado y certificado de cada recogida (unos 30-60 € por recogida). Pon la tasa de tu ayuntamiento | G31: =IFERROR(IF(B9="","",'0. Supuestos'!$B$41),"") -> 0.21
A32: Desinsectación, desratización y desinfección (DDD) | B32: 450 | C32: =IFERROR(IF(C9="","",B32*(1+'0. Supuestos'!$B$48)),"") -> 450 | D32: =IFERROR(IF(D9="","",C32*(1+'0. Supuestos'!$B$48)),"") -> 450 | E32: =IFERROR(B32/$B$9,"") -> 0.0012329443 | F32: Contrato con una empresa inscrita en el ROESB: forma parte de los prerrequisitos del APPCC | G32: =IFERROR(IF(B9="","",'0. Supuestos'!$B$41),"") -> 0.21
A33: Derechos de autor por música ambiental (SGAE y AGEDI-AIE) | B33: 400 | C33: =IFERROR(IF(C9="","",B33*(1+'0. Supuestos'!$B$48)),"") -> 400 | D33: =IFERROR(IF(D9="","",C33*(1+'0. Supuestos'!$B$48)),"") -> 400 | E33: =IFERROR(B33/$B$9,"") -> 0.0010959505 | F33: SGAE y AGEDI-AIE son dos licencias distintas; el importe depende de los metros y del aforo de tu sala | G33: =IFERROR(IF(B9="","",'0. Supuestos'!$B$41),"") -> 0.21
A34: Prevención de riesgos laborales, vigilancia de la salud y formación | B34: 750 | C34: =IFERROR(IF(C9="","",B34*(1+'0. Supuestos'!$B$48)),"") -> 750 | D34: =IFERROR(IF(D9="","",C34*(1+'0. Supuestos'!$B$48)),"") -> 750 | E34: =IFERROR(B34/$B$9,"") -> 0.0020549071 | F34: El plan de prevención es obligatorio (Ley 31/1995): quemaduras del asador y de la freidora, cortes al trinchar y al espetar, gas y calor; los reconocimientos médicos de la plantilla y la formación en higiene y alérgenos | G34: =IFERROR(IF(B9="","",'0. Supuestos'!$B$41),"") -> 0.21
A35: Amortización del inmovilizado | B35: =IFERROR(IF(B9="","",'Inversión Inicial'!$B$37),"") -> 8360 | C35: =IFERROR(IF(C9="","",B35),"") -> 8360 | D35: =IFERROR(IF(D9="","",B35),"") -> 8360 | E35: =IFERROR(B35/$B$9,"") -> 0.022905365 | F35: Sale de las bases de amortización de la hoja de Inversión: sólo inmovilizado real. NO sube con el IPC: es una cuota sobre el coste HISTÓRICO del inmovilizado | G35: 0
A36: Gastos financieros (intereses del préstamo) | B36: =IFERROR(IF(B9="","",'Financiación'!$B$44),"") -> 6720 | C36: =IFERROR(IF(C9="","",'Financiación'!$B$46),"") -> 6720 | D36: =IFERROR(IF(D9="","",'Financiación'!$B$48),"") -> 5756.6031 | E36: =IFERROR(B36/$B$9,"") -> 0.018411968 | F36: Sólo los INTERESES son gasto. La devolución del principal va en la hoja de Tesorería | G36: 0
A37: TOTAL COSTES FIJOS | B37: =IFERROR(IF(B9="","",SUM(B22:B36)),"") -> 185462.82 | C37: =IFERROR(IF(C9="","",SUM(C22:C36)),"") -> 191462.82 | D37: =IFERROR(IF(D9="","",SUM(D22:D36)),"") -> 196499.42 | E37: =IFERROR(B37/$B$9,"") -> 0.50814516
A38: IVA soportado de los costes variables | B38: =IFERROR(IF(B9="","",SUMPRODUCT(B13:B18,G13:G18)),"") -> 17865.041 | C38: =IFERROR(IF(C9="","",SUMPRODUCT(C13:C18,G13:G18)),"") -> 18936.944 | D38: =IFERROR(IF(D9="","",SUMPRODUCT(D13:D18,G13:G18)),"") -> 19694.421 | F38: Cada línea a SU tipo, leído de la columna de al lado. Es lo que la hoja de Tesorería paga de más a los proveedores y luego se deduce
A39: IVA soportado de los costes fijos | B39: =IFERROR(IF(B9="","",SUMPRODUCT(B22:B36,G22:G36)),"") -> 8463 | C39: =IFERROR(IF(C9="","",SUMPRODUCT(C22:C36,G22:G36)),"") -> 8463 | D39: =IFERROR(IF(D9="","",SUMPRODUCT(D22:D36,G22:G36)),"") -> 8463
A40: RESULTADO ANTES DE IMPUESTOS | B40: =IFERROR(IF(B9="","",B20-B37),"") -> 30240.36 | C40: =IFERROR(IF(C9="","",C20-C37),"") -> 37182.551 | D40: =IFERROR(IF(D9="","",D20-D37),"") -> 41291.762 | E40: =IFERROR(B40/$B$9,"") -> 0.082854841
A41: Bases negativas pendientes al inicio | B41: =IFERROR(IF(B9="","",'0. Supuestos'!$B$42),"") -> 0 | C41: =IFERROR(IF(C9="","",B46),"") -> 0 | D41: =IFERROR(IF(D9="","",C46),"") -> 0 | F41: Art. 26 LIS: las pérdidas de un ejercicio se compensan con los beneficios de los siguientes
...

Sheet Punto Equilibrio
A1: ANÁLISIS DE PUNTO DE EQUILIBRIO
A2: Punto de equilibrio mensual y diario — pollería-asador de barrio
A4: Variable | B4: Año 1 | C4: Año 2 | D4: Año 3 | E4: Notas
A5: DATOS BASE POR AÑO
A6: Costes fijos anuales | B6: =IFERROR(IF('PyG 3 Años'!$B$9="","",'PyG 3 Años'!$B$37),"") -> 185462.82 | C6: =IFERROR(IF('PyG 3 Años'!$C$9="","",'PyG 3 Años'!$C$37),"") -> 191462.82 | D6: =IFERROR(IF('PyG 3 Años'!$D$9="","",'PyG 3 Años'!$D$37),"") -> 196499.42 | E6: Los MISMOS costes fijos del P&L. Cada año tiene los suyos: por eso el umbral no puede ser uno solo para los tres
A7: Costes fijos mensuales | B7: =IFERROR(IF('PyG 3 Años'!$B$9="","",B6/12),"") -> 15455.235 | C7: =IFERROR(IF('PyG 3 Años'!$C$9="","",C6/12),"") -> 15955.235 | D7: =IFERROR(IF('PyG 3 Años'!$D$9="","",D6/12),"") -> 16374.952
A8: Ticket medio sin IVA | B8: =IFERROR(IF('PyG 3 Años'!$B$9="","",'PyG 3 Años'!$B$7),"") -> 15.8 | C8: =IFERROR(IF('PyG 3 Años'!$C$9="","",'PyG 3 Años'!$C$7),"") -> 15.8 | D8: =IFERROR(IF('PyG 3 Años'!$D$9="","",'PyG 3 Años'!$D$7),"") -> 15.8
A9: Coste variable por pedido | B9: =IFERROR(IF('PyG 3 Años'!$B$9="","",'PyG 3 Años'!$B$19/('PyG 3 Años'!$B$6*'PyG 3 Años'!$B$8)),"") -> 6.4622 | C9: =IFERROR(IF('PyG 3 Años'!$C$9="","",'PyG 3 Años'!$C$19/('PyG 3 Años'!$C$6*'PyG 3 Años'!$C$8)),"") -> 6.4622 | D9: =IFERROR(IF('PyG 3 Años'!$D$9="","",'PyG 3 Años'!$D$19/('PyG 3 Años'!$D$6*'PyG 3 Años'!$D$8)),"") -> 6.4622 | E9: Sale del total de costes variables del P&L, no de una estimación aparte. Incluye los varios e imprevistos, que son un porcentaje de las ventas
A10: Margen de contribución por pedido | B10: =IFERROR(IF('PyG 3 Años'!$B$9="","",B8-B9),"") -> 9.3378 | C10: =IFERROR(IF('PyG 3 Años'!$C$9="","",C8-C9),"") -> 9.3378 | D10: =IFERROR(IF('PyG 3 Años'!$D$9="","",D8-D9),"") -> 9.3378 | E10: Ticket menos coste variable unitario
A11: Días de apertura al año | B11: =IFERROR(IF('PyG 3 Años'!$B$9="","",'PyG 3 Años'!$B$8),"") -> 300 | C11: =IFERROR(IF('PyG 3 Años'!$C$9="","",'PyG 3 Años'!$C$8),"") -> 300 | D11: =IFERROR(IF('PyG 3 Años'!$D$9="","",'PyG 3 Años'!$D$8),"") -> 300 | E11: El mismo calendario que el P&L y que los escenarios
A12: Devolución de principal del año (cuota) | B12: =IFERROR(IF('PyG 3 Años'!$B$9="","",'Financiación'!$B$45),"") -> 0 | C12: =IFERROR(IF('PyG 3 Años'!$C$9="","",'Financiación'!$B$47),"") -> 16056.614 | D12: =IFERROR(IF('PyG 3 Años'!$D$9="","",'Financiación'!$B$49),"") -> 17020.011 | E12: El principal NO es gasto del P&L, pero sale de la caja. Sin él, el umbral de equilibrio se publica por debajo del real
A13: PUNTO DE EQUILIBRIO CONTABLE (incluye amortización)
A14: Pedidos necesarios al año | B14: =IFERROR(IF('PyG 3 Años'!$B$9="","",IF(B10<=0,"",B6/B10)),"") -> 19861.511 | C14: =IFERROR(IF('PyG 3 Años'!$C$9="","",IF(C10<=0,"",C6/C10)),"") -> 20504.061 | D14: =IFERROR(IF('PyG 3 Años'!$D$9="","",IF(D10<=0,"",D6/D10)),"") -> 21043.439
A15: Pedidos necesarios al día | B15: =IFERROR(IF('PyG 3 Años'!$B$9="","",B14/B11),"") -> 66.205038 | C15: =IFERROR(IF('PyG 3 Años'!$C$9="","",C14/C11),"") -> 68.34687 | D15: =IFERROR(IF('PyG 3 Años'!$D$9="","",D14/D11),"") -> 70.144796
A16: Ingresos necesarios al año | B16: =IFERROR(IF('PyG 3 Años'!$B$9="","",B14*B8),"") -> 313811.88 | C16: =IFERROR(IF('PyG 3 Años'!$C$9="","",C14*C8),"") -> 323964.16 | D16: =IFERROR(IF('PyG 3 Años'!$D$9="","",D14*D8),"") -> 332486.33
A17: PUNTO DE EQUILIBRIO DE CAJA (incluye la cuota del préstamo)
A18: Costes fijos de caja + principal del año | B18: =IFERROR(IF('PyG 3 Años'!$B$9="","",B6-'PyG 3 Años'!$B$35+B12),"") -> 177102.82 | C18: =IFERROR(IF('PyG 3 Años'!$C$9="","",C6-'PyG 3 Años'!$C$35+C12),"") -> 199159.43 | D18: =IFERROR(IF('PyG 3 Años'!$D$9="","",D6-'PyG 3 Años'!$D$35+D12),"") -> 205159.43 | E18: Los fijos del P&L sin la amortización (que no se paga) y CON la devolución de principal (que sí). Es el umbral que decide si la caja aguanta
A19: Pedidos necesarios al año (caja) | B19: =IFERROR(IF('PyG 3 Años'!$B$9="","",IF(B10<=0,"",B18/B10)),"") -> 18966.225 | C19: =IFERROR(IF('PyG 3 Años'!$C$9="","",IF(C10<=0,"",C18/C10)),"") -> 21328.304 | D19: =IFERROR(IF('PyG 3 Años'!$D$9="","",IF(D10<=0,"",D18/D10)),"") -> 21970.853
A20: Pedidos necesarios al día (caja) | B20: =IFERROR(IF('PyG 3 Años'!$B$9="","",B19/B11),"") -> 63.220751 | C20: =IFERROR(IF('PyG 3 Años'!$C$9="","",C19/C11),"") -> 71.094346 | D20: =IFERROR(IF('PyG 3 Años'!$D$9="","",D19/D11),"") -> 73.236178
A21: Ingresos necesarios al año (caja) | B21: =IFERROR(IF('PyG 3 Años'!$B$9="","",B19*B8),"") -> 299666.36 | C21: =IFERROR(IF('PyG 3 Años'!$C$9="","",C19*C8),"") -> 336987.2 | D21: =IFERROR(IF('PyG 3 Años'!$D$9="","",D19*D8),"") -> 347139.48
A22: CONTRASTE CON EL PLAN
A23: Pedidos/día previstos en el plan | B23: =IFERROR(IF('PyG 3 Años'!$B$9="","",'PyG 3 Años'!$B$6),"") -> 77 | C23: =IFERROR(IF('PyG 3 Años'!$C$9="","",'PyG 3 Años'!$C$6),"") -> 81.62 | D23: =IFERROR(IF('PyG 3 Años'!$D$9="","",'PyG 3 Años'!$D$6),"") -> 84.8848
A24: Holgura sobre el equilibrio de CAJA (%) | B24: =IFERROR(IF('PyG 3 Años'!$B$9="","",B23/B20-1),"") -> 0.21795452 | C24: =IFERROR(IF('PyG 3 Años'!$C$9="","",C23/C20-1),"") -> 0.14805192 | D24: =IFERROR(IF('PyG 3 Años'!$D$9="","",D23/D20-1),"") -> 0.15905557 | E24: Cuánto superan tus ventas previstas a las del equilibrio de caja. La caída que aguantas antes de no poder pagar los costes fijos y la cuota es algo menor: con un 25 % de holgura, un 20 %. El mínimo exigible está en la hoja de Supuestos
A25: INTERPRETACIÓN
A26: =IFERROR("Con el ticket medio sin IVA de la fila de arriba necesitas "&TEXT(ROUNDUP(B15,0),"0")&" pedidos al día durante los "&TEXT(B11,"0")&" días que abres para no perder dinero (equilibrio contable, con la amortización dentro), y "&TEXT(ROUNDUP(B20,0),"0")&" para que la caja aguante (equilibrio de caja: sin la amortización, que no se paga, y con la cuota del préstamo del año"&IF(B12=0,"; este año sólo intereses, porque el préstamo está en carencia","")&"). En las filas «Ingresos necesarios al año» tienes esas mismas cifras en euros.","") -> Con el ticket medio sin IVA de la fila de arriba necesitas 67 pedidos al día durante los 300 días que abres para no perder dinero (equilibrio contable, con la amortización dentro), y 64 para que la caja aguante (equilibrio de caja: sin la amortización, que no se paga, y con la cuota del préstamo del año; este año sólo intereses, porque el préstamo está en carencia). En las filas «Ingresos necesarios al año» tienes esas mismas cifras en euros.
A28: SENSIBILIDAD DEL PUNTO DE EQUILIBRIO
A29: Pedidos/día necesarios para cubrir costes según el ticket medio (columnas) y el coste variable por pedido (filas). En verde, los que están por debajo de los pedidos que prevé el plan.
A31: Pedidos/día necesarios: ticket medio sin IVA (columnas) × coste variable por pedido (filas) | B31: =IFERROR($B$8-2,"") -> 13.8 | C31: =IFERROR(IF($B$8="","",$B$8),"") -> 15.8 | D31: =IFERROR($B$8+2,"") -> 17.8 | E31: =IFERROR($B$8+4,"") -> 19.8
A32: =IFERROR($B$9*0.85,"") -> 5.49287 | B32: =IFERROR(IF($B$31-$A32<=0,"",$B$6/($B$31-$A32)/$B$11),"") -> 74.419132 | C32: =IFERROR(IF($C$31-$A32<=0,"",$B$6/($C$31-$A32)/$B$11),"") -> 59.978811 | D32: =IFERROR(IF($D$31-$A32<=0,"",$B$6/($D$31-$A32)/$B$11),"") -> 50.231809 | E32: =IFERROR(IF($E$31-$A32<=0,"",$B$6/($E$31-$A32)/$B$11),"") -> 43.209882
A33: =IFERROR($B$9*0.925,"") -> 5.977535 | B33: =IFERROR(IF($B$31-$A33<=0,"",$B$6/($B$31-$A33)/$B$11),"") -> 79.029999 | C33: =IFERROR(IF($C$31-$A33<=0,"",$B$6/($C$31-$A33)/$B$11),"") -> 62.938315 | D33: =IFERROR(IF($D$31-$A33<=0,"",$B$6/($D$31-$A33)/$B$11),"") -> 52.291075 | E33: =IFERROR(IF($E$31-$A33<=0,"",$B$6/($E$31-$A33)/$B$11),"") -> 44.724975
A34: =IFERROR($B$9*1.0,"") -> 6.4622 | B34: =IFERROR(IF($B$31-$A34<=0,"",$B$6/($B$31-$A34)/$B$11),"") -> 84.249966 | C34: =IFERROR(IF($C$31-$A34<=0,"",$B$6/($C$31-$A34)/$B$11),"") -> 66.205038 | D34: =IFERROR(IF($D$31-$A34<=0,"",$B$6/($D$31-$A34)/$B$11),"") -> 54.526398 | E34: =IFERROR(IF($E$31-$A34<=0,"",$B$6/($E$31-$A34)/$B$11),"") -> 46.350178
A35: =IFERROR($B$9*1.075,"") -> 6.946865 | B35: =IFERROR(IF($B$31-$A35<=0,"",$B$6/($B$31-$A35)/$B$11),"") -> 90.208262 | C35: =IFERROR(IF($C$31-$A35<=0,"",$B$6/($C$31-$A35)/$B$11),"") -> 69.829433 | D35: =IFERROR(IF($D$31-$A35<=0,"",$B$6/($D$31-$A35)/$B$11),"") -> 56.961366 | E35: =IFERROR(IF($E$31-$A35<=0,"",$B$6/($E$31-$A35)/$B$11),"") -> 48.097947
A36: =IFERROR($B$9*1.15,"") -> 7.43153 | B36: =IFERROR(IF($B$31-$A36<=0,"",$B$6/($B$31-$A36)/$B$11),"") -> 97.073457 | C36: =IFERROR(IF($C$31-$A36<=0,"",$B$6/($C$31-$A36)/$B$11),"") -> 73.873647 | D36: =IFERROR(IF($D$31-$A36<=0,"",$B$6/($D$31-$A36)/$B$11),"") -> 59.623975 | E36: =IFERROR(IF($E$31-$A36<=0,"",$B$6/($E$31-$A36)/$B$11),"") -> 49.98269

Sheet Escenarios
A1: ANÁLISIS DE ESCENARIOS
A2: Pesimista / Realista / Optimista — Año 1
A4: Métrica | B4: Pesimista | C4: Realista | D4: Optimista | E4: Notas
A5: Pedidos/día | B5: 66 | C5: =IFERROR(IF('PyG 3 Años'!$B$6="","",'PyG 3 Años'!$B$6),"") -> 77 | D5: 88
A6: Ticket medio sin IVA | B6: 15 | C6: =IFERROR(IF('PyG 3 Años'!$B$7="","",'PyG 3 Años'!$B$7),"") -> 15.8 | D6: 16.5
A7: Días de apertura al año | B7: 295 | C7: =IFERROR(IF('PyG 3 Años'!$B$8="","",'PyG 3 Años'!$B$8),"") -> 300 | D7: 305
A8: INGRESOS ANUALES (sin IVA) | B8: =IFERROR(IF(B5*B6*B7=0,"",B5*B6*B7),"") -> 292050 | C8: =IFERROR(IF(C5*C6*C7=0,"",C5*C6*C7),"") -> 364980 | D8: =IFERROR(IF(D5*D6*D7=0,"",D5*D6*D7),"") -> 442860
A9: Coste de mercancía — comida | B9: =IFERROR(IF(B8="","",B8*'0. Supuestos'!$B$11*'0. Supuestos'!$B$13),"") -> 84110.4 | C9: =IFERROR(IF(C8="","",C8*'0. Supuestos'!$B$11*'0. Supuestos'!$B$13),"") -> 105114.24 | D9: =IFERROR(IF(D8="","",D8*'0. Supuestos'!$B$11*'0. Supuestos'!$B$13),"") -> 127543.68
A10: Coste de mercancía — bebida | B10: =IFERROR(IF(B8="","",B8*'0. Supuestos'!$B$12*'0. Supuestos'!$B$14),"") -> 8761.5 | C10: =IFERROR(IF(C8="","",C8*'0. Supuestos'!$B$12*'0. Supuestos'!$B$14),"") -> 10949.4 | D10: =IFERROR(IF(D8="","",D8*'0. Supuestos'!$B$12*'0. Supuestos'!$B$14),"") -> 13285.8
A11: Consumibles y envases | B11: =IFERROR(IF(B8="","",B8*'0. Supuestos'!$B$15),"") -> 8761.5 | C11: =IFERROR(IF(C8="","",C8*'0. Supuestos'!$B$15),"") -> 10949.4 | D11: =IFERROR(IF(D8="","",D8*'0. Supuestos'!$B$15),"") -> 13285.8
A12: Comisiones de delivery | B12: =IFERROR(IF(B8="","",B8*'0. Supuestos'!$B$16*'0. Supuestos'!$B$17),"") -> 9637.65 | C12: =IFERROR(IF(C8="","",C8*'0. Supuestos'!$B$16*'0. Supuestos'!$B$17),"") -> 12044.34 | D12: =IFERROR(IF(D8="","",D8*'0. Supuestos'!$B$16*'0. Supuestos'!$B$17),"") -> 14614.38
A13: Comisiones de los medios de pago | B13: =IFERROR(IF(B8="","",B8*'0. Supuestos'!$B$18),"") -> 2336.4 | C13: =IFERROR(IF(C8="","",C8*'0. Supuestos'!$B$18),"") -> 2919.84 | D13: =IFERROR(IF(D8="","",D8*'0. Supuestos'!$B$18),"") -> 3542.88
A14: Varios e imprevistos | B14: =IFERROR(IF(B8="","",B8*'0. Supuestos'!$B$28),"") -> 5841 | C14: =IFERROR(IF(C8="","",C8*'0. Supuestos'!$B$28),"") -> 7299.6 | D14: =IFERROR(IF(D8="","",D8*'0. Supuestos'!$B$28),"") -> 8857.2
A15: TOTAL COSTES VARIABLES | B15: =IFERROR(IF(B8="","",SUM(B9:B14)),"") -> 119448.45 | C15: =IFERROR(IF(C8="","",SUM(C9:C14)),"") -> 149276.82 | D15: =IFERROR(IF(D8="","",SUM(D9:D14)),"") -> 181129.74
A16: MARGEN BRUTO | B16: =IFERROR(IF(B8="","",B8-B15),"") -> 172601.55 | C16: =IFERROR(IF(C8="","",C8-C15),"") -> 215703.18 | D16: =IFERROR(IF(D8="","",D8-D15),"") -> 261730.26
A17: COSTES FIJOS (los del P&L) | B17: =IFERROR(IF(B8="","",'PyG 3 Años'!$B$37),"") -> 185462.82 | C17: =IFERROR(IF(C8="","",'PyG 3 Años'!$B$37),"") -> 185462.82 | D17: =IFERROR(IF(D8="","",'PyG 3 Años'!$B$37),"") -> 185462.82 | E17: Los costes fijos no cambian con el escenario: por eso son fijos
A18: RESULTADO ANTES DE IMPUESTOS | B18: =IFERROR(IF(B8="","",B16-B17),"") -> -12861.27 | C18: =IFERROR(IF(C8="","",C16-C17),"") -> 30240.36 | D18: =IFERROR(IF(D8="","",D16-D17),"") -> 76267.44
A19: Impuesto de Sociedades | B19: =IFERROR(IF(B8="","",MAX(0,B18-'0. Supuestos'!$B$42)*'0. Supuestos'!$B$37),"") -> 0 | C19: =IFERROR(IF(C8="","",MAX(0,C18-'0. Supuestos'!$B$42)*'0. Supuestos'!$B$37),"") -> 4536.054 | D19: =IFERROR(IF(D8="","",MAX(0,D18-'0. Supuestos'!$B$42)*'0. Supuestos'!$B$37),"") -> 11440.116 | E19: Al tipo de entidad de nueva creación, compensando las bases negativas anteriores
A20: RESULTADO NETO | B20: =IFERROR(IF(B8="","",B18-B19),"") -> -12861.27 | C20: =IFERROR(IF(C8="","",C18-C19),"") -> 25704.306 | D20: =IFERROR(IF(D8="","",D18-D19),"") -> 64827.324
A21: Pedidos/día para el equilibrio | B21: =IFERROR(IF(B8="","",IF(B6-B15/(B5*B7)<=0,"",B17/(B6-B15/(B5*B7))/B7)),"") -> 70.917939 | C21: =IFERROR(IF(C8="","",IF(C6-C15/(C5*C7)<=0,"",C17/(C6-C15/(C5*C7))/C7)),"") -> 66.205038 | D21: =IFERROR(IF(D8="","",IF(D6-D15/(D5*D7)<=0,"",D17/(D6-D15/(D5*D7))/D7)),"") -> 62.357055
A22: LO QUE CADA ESCENARIO EXIGE
A23: Coste de personal / Ventas | B23: =IFERROR(IF(B8="","",'PyG 3 Años'!$B$23/B8),"") -> 0.44061914 | C23: =IFERROR(IF(C8="","",'PyG 3 Años'!$B$23/C8),"") -> 0.35257499 | D23: =IFERROR(IF(D8="","",'PyG 3 Años'!$B$23/D8),"") -> 0.29057224 | E23: La MISMA plantilla en los tres escenarios. Si en el pesimista se dispara, el ajuste hay que hacerlo en la hoja de Personal, no aquí
A24: Pedidos al año por jornada equivalente | B24: =IFERROR(IF(B8="","",B5*B7/'Personal'!$C$12),"") -> 4232.6087 | C24: =IFERROR(IF(C8="","",C5*C7/'Personal'!$C$12),"") -> 5021.7391 | D24: =IFERROR(IF(D8="","",D5*D7/'Personal'!$C$12),"") -> 5834.7826 | E24: Pedidos que tendría que sacar cada jornada completa del cuadro de Personal. En el optimista dice si hace falta contratar
A25: Saldo de caja al cierre del año 1 (estimado, el mismo método en los tres escenarios) | B25: =IFERROR(IF(B8="","",'Inversión Inicial'!$B$29+B20+'PyG 3 Años'!$B$35-'Financiación'!$B$45),"") -> 39774.435 | C25: =IFERROR(IF(C8="","",'Inversión Inicial'!$B$29+C20+'PyG 3 Años'!$B$35-'Financiación'!$B$45),"") -> 78340.011 | D25: =IFERROR(IF(D8="","",'Inversión Inicial'!$B$29+D20+'PyG 3 Años'!$B$35-'Financiación'!$B$45),"") -> 117463.03 | E25: Saldo ESTIMADO: fondo de maniobra más el resultado del año, devolviendo la amortización (que no se paga) y restando el principal del préstamo. No incluye el desfase de cobros y pagos ni la liquidación del IVA, así que las tres columnas se pueden comparar entre sí. En rojo, el escenario se queda sin caja
A26: Saldo real del mes 12 de la hoja de Tesorería (sólo realista) | C26: =IFERROR(IF(C8="","",'Tesorería 12 meses'!$M$22),"") -> 106517.48 | E26: El saldo REAL del caso base, con su desfase de cobros y pagos y su liquidación de IVA. Sólo existe para el escenario realista, que es el único con tesorería mensual propia: por eso no está en la fila de arriba, donde se compararía contra dos estimaciones
A28: La columna «Realista» lee sus tres datos de la hoja de Supuestos, así que reproduce EXACTAMENTE el año 1 del P&L. Los otros dos escenarios usan las mismas tasas de coste: lo único que cambia son los pedidos, el ticket y los días. Los COSTES FIJOS sí son los mismos en los tres: los varios e imprevistos, que son un porcentaje de las ventas, van arriba con los variables y cada escenario carga los suyos.

Sheet Personal
A1: ESTRUCTURA DE PERSONAL Y COSTES
A2: =IFERROR("Convenio Hostelería — "&TEXT('0. Supuestos'!$B$21,"0")&" pagas + SS "&TEXT('0. Supuestos'!$B$20*100,"0")&" %","") -> Convenio Hostelería — 14 pagas + SS 33 %
A4: Puesto | B4: Personas | C4: Jornada | D4: Bruto mes (€, total del puesto) | E4: Seg. Social a cargo de la empresa (€) | F4: Coste mes (€, total del puesto) | G4: Coste año (€) | H4: Horas/semana por persona | I4: Horas/año del puesto | J4: Notas
A5: Titular — maestro/a asador: compra del pollo, adobos, asador, encargos y gestión | B5: 1 | C5: 1 | D5: 1900 | E5: =IFERROR(IF(D5="","",D5*'0. Supuestos'!$B$20),"") -> 627 | F5: =IFERROR(IF(D5="","",D5+E5),"") -> 2527 | G5: =IFERROR(IF(D5="","",F5*MAX(12,'0. Supuestos'!$B$21)),"") -> 35378 | H5: =IFERROR(IF(D5="","",C5*$B$19),"") -> 40 | I5: =IFERROR(IF(D5="","",H5*B5*$B$20),"") -> 1840 | J5: Compra el pollo y fija el calibre, prepara los adobos, lleva el asador y las cargas del domingo, organiza los encargos y gestiona. Como administrador de la SL cotiza en el régimen de autónomos: el libro le imputa el 33 % de Seguridad Social sobre 14 pagas como si fuera nómina, que es el lado prudente. Confirma con tu gestoría la cuota real y si te aplica la reducida de inicio
A6: Asador/a-cocinero/a: espetar, freidora, guarniciones y croquetas | B6: 1 | C6: 1 | D6: 1450 | E6: =IFERROR(IF(D6="","",D6*'0. Supuestos'!$B$20),"") -> 478.5 | F6: =IFERROR(IF(D6="","",D6+E6),"") -> 1928.5 | G6: =IFERROR(IF(D6="","",F6*MAX(12,'0. Supuestos'!$B$21)),"") -> 26999 | H6: =IFERROR(IF(D6="","",C6*$B$19),"") -> 40 | I6: =IFERROR(IF(D6="","",H6*B6*$B$20),"") -> 1840 | J6: Espeta y carga el asador, lleva la freidora, las guarniciones y las croquetas y sabe sondear y trinchar. Es inversión, no gasto: si sólo el titular sabe llevar el asador, una baja cierra el domingo, que es un tercio de la semana
A7: Dependiente/a de mostrador y caja | B7: 1 | C7: 1 | D7: 1400 | E7: =IFERROR(IF(D7="","",D7*'0. Supuestos'!$B$20),"") -> 462 | F7: =IFERROR(IF(D7="","",D7+E7),"") -> 1862 | G7: =IFERROR(IF(D7="","",F7*MAX(12,'0. Supuestos'!$B$21)),"") -> 26068 | H7: =IFERROR(IF(D7="","",C7*$B$19),"") -> 40 | I7: =IFERROR(IF(D7="","",H7*B7*$B$20),"") -> 1840 | J7: Mostrador, caja, teléfono y encargos, la tablet de las plataformas y la información de alérgenos
A8: Camarero/a de sala | B8: 1 | C8: 0.75 | D8: 1013 | E8: =IFERROR(IF(D8="","",D8*'0. Supuestos'!$B$20),"") -> 334.29 | F8: =IFERROR(IF(D8="","",D8+E8),"") -> 1347.29 | G8: =IFERROR(IF(D8="","",F8*MAX(12,'0. Supuestos'!$B$21)),"") -> 18862.06 | H8: =IFERROR(IF(D8="","",C8*$B$19),"") -> 30 | I8: =IFERROR(IF(D8="","",H8*B8*$B$20),"") -> 1380 | J8: 30 horas a la semana: los mediodías y las cenas de jueves a sábado
A9: Ayudante de cocina y friegue de fin de semana | B9: 1 | C9: 0.35 | D9: 473 | E9: =IFERROR(IF(D9="","",D9*'0. Supuestos'!$B$20),"") -> 156.09 | F9: =IFERROR(IF(D9="","",D9+E9),"") -> 629.09 | G9: =IFERROR(IF(D9="","",F9*MAX(12,'0. Supuestos'!$B$21)),"") -> 8807.26 | H9: =IFERROR(IF(D9="","",C9*$B$19),"") -> 14 | I9: =IFERROR(IF(D9="","",H9*B9*$B$20),"") -> 644 | J9: Sábado y domingo por la mañana: patatas, ensaladilla y las espadas al lavavajillas
A10: Refuerzo de sábado, domingo y festivos | B10: 1 | C10: 0.4 | D10: 540 | E10: =IFERROR(IF(D10="","",D10*'0. Supuestos'!$B$20),"") -> 178.2 | F10: =IFERROR(IF(D10="","",D10+E10),"") -> 718.2 | G10: =IFERROR(IF(D10="","",F10*MAX(12,'0. Supuestos'!$B$21)),"") -> 10054.8 | H10: =IFERROR(IF(D10="","",C10*$B$19),"") -> 16 | I10: =IFERROR(IF(D10="","",H10*B10*$B$20),"") -> 736 | J10: Mostrador y despacho de encargos en la punta del fin de semana. Este plan NO tiene reparto propio: si lo pones, el repartidor va con contrato laboral del convenio de hostelería, nunca como autónomo
A11: Suplencias de vacaciones y descansos | B11: 1 | C11: 0.1 | D11: 135 | E11: =IFERROR(IF(D11="","",D11*'0. Supuestos'!$B$20),"") -> 44.55 | F11: =IFERROR(IF(D11="","",D11+E11),"") -> 179.55 | G11: =IFERROR(IF(D11="","",F11*MAX(12,'0. Supuestos'!$B$21)),"") -> 2513.7 | H11: =IFERROR(IF(D11="","",C11*$B$19),"") -> 4 | I11: =IFERROR(IF(D11="","",H11*B11*$B$20),"") -> 184 | J11: Cobertura de los 30 días de vacaciones (art. 38 ET) y del descanso semanal del equipo de todo el año
A12: TOTAL PLANTILLA | B12: =IFERROR(IF(COUNT(D5:D11)=0,"",SUM(B5:B11)),"") -> 7 | C12: =IFERROR(IF(COUNT(D5:D11)=0,"",SUM(C5:C11)),"") -> 4.6 | D12: =IFERROR(IF(COUNT(D5:D11)=0,"",SUM(D5:D11)),"") -> 6911 | E12: =IFERROR(IF(COUNT(D5:D11)=0,"",SUM(E5:E11)),"") -> 2280.63 | F12: =IFERROR(IF(COUNT(D5:D11)=0,"",SUM(F5:F11)),"") -> 9191.63 | G12: =IFERROR(IF(COUNT(D5:D11)=0,"",SUM(G5:G11)),"") -> 128682.82 | I12: =IFERROR(IF(COUNT(D5:D11)=0,"",SUM(I5:I11)),"") -> 8464
A13: CRECIMIENTO DE LA PLANTILLA (coste escalonado)
A14: Coste anual de las incorporaciones del año 2 (€) | B14: 6000 | J14: Coste ANUAL completo (bruto + Seguridad Social × pagas) de lo que se contrate ese año. El P&L lo suma al coste del año anterior: la plantilla no crece con un porcentaje, crece con personas
A15: Coste anual de las incorporaciones del año 3 (€) | B15: 6000 | J15: Coste ANUAL completo (bruto + Seguridad Social × pagas) de lo que se contrate ese año. El P&L lo suma al coste del año anterior: la plantilla no crece con un porcentaje, crece con personas
A16: Coste de personal del año 2 | B16: =IFERROR(IF(G12="","",G12*(1+'0. Supuestos'!$B$48)+B14),"") -> 134682.82
A17: Coste de personal del año 3 | B17: =IFERROR(IF(B16="","",B16*(1+'0. Supuestos'!$B$48)+B15),"") -> 140682.82
A18: COBERTURA POR HORAS DE SERVICIO
A19: Jornada completa del convenio (horas/semana) | B19: 40 | J19: Art. 34.1 del Estatuto de los Trabajadores; tu convenio provincial puede fijar menos
A20: Semanas trabajadas al año por persona | B20: 46 | J20: 46 semanas: 52 menos las vacaciones (30 días naturales, art. 38 ET), los festivos y las ausencias medias
A21: Horas de servicio al día que hay que cubrir | B21: 7 | J21: Horas con el local abierto al público de media: de 12:00 a 16:30 de martes a domingo y de 20:00 a 23:00 de jueves a sábado, con la preparación de cada servicio
A22: Personas necesarias a la vez en cada franja | B22: 3 | J22: Presencia media a la vez entre el asador, la freidora, el mostrador y la sala. El domingo de 11:00 a 15:30 hacen falta seis: entran el refuerzo y el ayudante (el cuadrante anual no lo ve: ponlo en el turno)
A23: Horas de producción al día ANTES de abrir | B23: 3 | J23: Espetar y adobar los pollos de la primera carga, encender el asador, croquetas, ensaladilla y patatas antes de abrir
A24: Personas en el turno de producción | B24: 1.5 | J24: El maestro asador con el asador-cocinero. La limpieza del asador y de la campana extractora, el cierre y las compras quedan fuera de este cuadrante: son el margen entre las horas contratadas y las necesarias
A25: Horas de servicio a cubrir al año | B25: =IFERROR(IF(OR(B21="",B22="",'0. Supuestos'!$B$6=""),"",B21*B22*'0. Supuestos'!$B$6+B23*B24*'0. Supuestos'!$B$6),"") -> 7650
A26: Horas contratadas al año | B26: =IFERROR(IF(I12="","",I12),"") -> 8464
A27: Cobertura (contratadas / necesarias) | B27: =IFERROR(B26/B25,"") -> 1.1064052 | J27: Por debajo del 100 % la plantilla no llega a cubrir el horario que declara el plan: o se contrata más o se recorta el horario
A29: Las columnas «Bruto mes», «Seg. Social», «Coste mes» y «Coste año» son TOTALES de la fila: en un puesto con dos personas incluyen a las dos. «Jornada» es el porcentaje sobre la jornada completa del convenio y sirve para comparar el salario con el suelo legal en proporción. El tipo de Seguridad Social y el número de pagas están en la hoja «0. Supuestos».
A30: El suelo salarial es el MAYOR entre el SMI y el salario de convenio, los dos en la hoja «0. Supuestos»; las jornadas parciales lo llevan en proporción. El convenio aplicable es el PROVINCIAL de hostelería: no existe una tabla salarial estatal única, así que la celda del convenio se entrega vacía para que copies la de tu provincia.

Sheet Instrucciones
A1: INSTRUCCIONES DE USO — Plan financiero Pollería y Asador de Pollos
A3: CÓMO SE USA ESTE LIBRO
A4: Este plan financiero es un MODELO: sólo se teclea en las celdas VERDES y el resto se recalcula solo.
A5: 1. «0. Supuestos» es la hoja de mando: pedidos, ticket sin IVA, días de apertura, mezcla de comida y bebida, coste de mercancía, alquiler, financiación e impuestos.
