Workbook

Sheet Instrucciones
A1: Calculadora de inversión inicial (CAPEX)
A2: AI Chef Pro · aichef.pro — Cómo Montar una Pastelería
A3: Para qué sirve: saber cuánto dinero necesitas de verdad para abrir, y si sale mejor un traspaso o una obra nueva.
A5: Instrucciones de uso
A6: 1. Hoja «Parámetros»: los metros del local, los tres precios por m2 de obra, el escenario que eliges, los meses de colchón y los tipos de IVA. Todo lo que calcula el libro sale de aquí.
A7: 2. Hoja «CAPEX por Bloque»: una fila por partida. Escribe el mínimo y el máximo que te hayan presupuestado y el importe con el que trabajas, di si ESE importe lleva IVA y a qué tipo, y marca «No» en lo que no vayas a comprar. La hoja lleva todo a base imponible antes de sumar, que es la única forma de que el total signifique algo.
A8: 3. Hoja «Variante del Formato»: tu pastelería puede no ser la del ejemplo. Diez formatos con un coeficiente editable por bloque sobre el caso central, y al lado el rango de inversión que publica el sector, para que veas si tu cuenta y la suya se parecen.
A9: 4. Hoja «Traspaso vs Obra Nueva»: el precio del traspaso no es lo que cuesta el traspaso. Mete la renta de los dos casos, los meses que estarás parado en cada uno y los años del contrato, y compara el coste completo. Abajo, quince traspasos reales para que veas la horquilla.
A10: 5. Hoja «IVA y Tesorería»: cuánto IVA adelantas, cuándo vuelve y cuánta caja tienes que tener el día que abres. Es la hoja que más sorprende: el IVA de la inversión es dinero que sale de tu bolsillo meses antes de volver.
A11: 6. Hoja «Resumen»: las quince cifras que hay que llevar al banco, todas calculadas desde las hojas anteriores.
A13: Celdas verdes = campos editables
A15: Lo que conviene saber antes de empezar
... A22: Dónde acaba este libro y dónde sigue otro
A23: Lo que necesitas | B23: Dónde está | C23: Por qué no está aquí
A24: A quién compras cada máquina, a qué precio negociado y con qué plazo de entrega | B24: Libro 7: checklist-equipamiento-y-proveedores.xlsx | C24: Aquí la máquina entra sólo por su importe. El plazo de entrega no cambia el CAPEX; cambia la fecha de apertura, y eso es el libro 6.
A25: El P&L a tres años, la tesorería mes a mes y el cuadro de la deuda | B25: Libro 5: plan-financiero-3-anos-pasteleria.xlsx | C25: De ese libro sale el gasto fijo mensual de verdad. Aquí entra como un parámetro con valor por defecto, sólo para calcular el fondo de maniobra.
A26: Si ese local sirve y cuántas piezas al día aguanta el equipo | B26: Libro 1: capacidad-obrador-y-local.xlsx | C26: Comprar bien empieza por saber qué necesitas, no cuánto cuesta. Los dos libros comparten los mismos 90 m2 y la misma columna de IVA.
A27: Qué papeles te tocan, en qué orden y cuándo abres | B27: Libro 6: checklist-legal-y-licencias.xlsx | C27: Las tasas y el proyecto técnico están aquí como importe; el procedimiento y el calendario, allí.
A28: Es COPIA declarada, no vínculo: en toda la guía no hay ni una fórmula que apunte a otro fichero. Donde una celda verde traería un dato de otro libro o del Kit de Tareas Pastelería, viene con un valor por defecto propio, declarado como supuesto, y su nota te dice qué lo sustituye.
A30: Cada cuánto se usa este libro
A31: Cadencia: se rellena UNA VEZ al preparar el plan y se revisa cada vez que entra un presupuesto nuevo, hasta la firma. Después de abrir sólo se vuelve a él para comparar lo presupuestado con lo gastado de verdad, que es lo que enseña a presupuestar el siguiente.
A33: Para editar la estructura o una celda que no esté en verde: Revisar > Desproteger hoja (no tiene contraseña).
A35: Diseñado por John Guerrero — chef y consultor gastronómico desde 2010, en cocina desde los 17 años.
A36: Versión 1.0 · septiembre 2026 · aichef.pro/guia-pasteleria-obrador · info@aichef.pro

Sheet Parámetros
A1: Parámetros
A2: AI Chef Pro · aichef.pro — Cómo Montar una Pastelería
A3: Cambia el escenario de obra y se recalcula el libro entero.
A5: Parámetro | B5: Valor | C5: Unidad | D5: Procedencia | E5: Qué es y de dónde sale
A6: Superficie total del local | B6: 90 | C6: m2 | D6: D22 + PS-85a + PS-85b + PS-85c | E6: Los mismos 90 m2 del libro 1. Es la superficie del caso publicado sobre la que casan los tres escenarios de obra: con 110 m2 el escenario medio se iría a 99.000 € y toda la comparación cambiaría.
A7: Obra civil, escenario bajo | B7: 600 | C7: €/m2 | D7: PS-85a | E7: Local que ya venía de un uso alimentario y sólo hay que adecuar.
A8: Obra civil, escenario medio | B8: 900 | C8: €/m2 | D8: PS-85b | E8: Local diáfano en bruto: instalaciones nuevas, sin sorpresas estructurales. Es el escenario de referencia.
A9: Obra civil, escenario alto | B9: 1200 | C9: €/m2 | D9: PS-85c | E9: Local con refuerzos, acometidas nuevas, patinillo de humos que hay que abrir o protección del edificio.
A10: Escenario de obra elegido | B10: Medio | C10: Bajo, Medio o Alto | D10: supuesto | E10: Cámbialo y se recalculan la obra civil, el CAPEX, la comparación con el traspaso y el IVA soportado.
A11: Precio por m2 aplicado | B11: =IF(B10="","",IF(B10="Bajo",B7,IF(B10="Alto",B9,IF(B10="Medio",B8,"")))) -> 900 | C11: €/m2 | D11: Se calcula | E11: El del escenario que hayas elegido arriba.
A12: Obra civil calculada | B12: =IFERROR(B6*B11,"") -> 81000 | C12: € | D12: Se calcula | E12: Superficie × precio por m2. Es la única partida del CAPEX que no se teclea: sale del escenario.
A13: IVA general | B13: 0.21 | C13: % | D13: art. 90.Uno de la Ley 37/1992 | E13: Tipo general: obra, equipamiento, mobiliario, proyecto y marketing. Es el valor por defecto de la columna «tipo de IVA» de cada línea, pero cada línea tiene el suyo.
A14: IVA de la pastelería que vas a vender | B14: 0.1 | C14: % | D14: PA-36 | E14: No entra en el CAPEX: está aquí porque es el IVA que repercutirás y contra el que se compensa el que adelantas ahora. Bollería, pastelería, confitería y repostería van al 10 % por la regla general de alimentos.
A15: IVA de tasas y trámites | B15: 0 | C15: % | D15: supuesto | E15: Las tasas municipales y la comunicación al registro autonómico no llevan IVA. Se declara como parámetro para que la columna de la hoja de CAPEX no tenga que hacer una excepción escondida.
A16: Meses de colchón de tesorería | B16: 4 | C16: meses | D16: supuesto | E16: Meses de gastos fijos que tienes que tener en caja el día que abres. Es una partida del CAPEX, no una propina: sin ella, el negocio depende de facturar desde el primer día, que es justo lo que no pasa.
A17: Colchón mínimo aceptable antes de avisar (meses) | B17: 3 | C17: meses | D17: supuesto | E17: Umbral del veredicto de caja de más abajo. Si tu banco exige más, súbelo aquí; no lo cambies confundiéndolo con los meses que de verdad dotas arriba.
A18: Gastos fijos mensuales estimados | B18: 15562.21 | C18: €/mes | D18: supuesto | E18: Personal con Seguridad Social, retribución del propietario, alquiler, suministros, seguros, gestoría, amortización e intereses DEL AÑO 1 (la carga máxima, antes de que corra la carencia). Es un valor por defecto para que el fondo de maniobra tenga un número: el cálculo bueno, mes a mes -con el interés del año de crucero, más bajo-, es el libro 5 (plan-financiero-3-anos-pasteleria.xlsx). Por eso el CAPEX y el fondo de maniobra de este libro difieren en unos 134 € de los del libro 5: para citar la INVERSIÓN TOTAL, usa siempre el libro 5, no éste.
A19: Fondo de maniobra calculado | B19: =IFERROR(B16*B18,"") -> 62248.84 | C19: € | D19: Se calcula | E19: Meses de colchón × gastos fijos mensuales.
A20: Renta mensual del local | B20: 1200 | C20: €/mes | D20: supuesto | E20: Supuesto para una ciudad media. Los cinco traspasos de Barcelona de PS-69 se mueven entre 850 y 1.300 €/mes para 63-85 m²; aquí se toma la parte baja porque Barcelona no es una ciudad media.
A21: Meses de fianza | B21: 2 | C21: meses | D21: supuesto | E21: La fianza no es un gasto: es un depósito que se recupera. Va en el CAPEX porque hay que tenerla el día de la firma.
A22: Horizonte de comparación | B22: 5 | C22: años | D22: supuesto | E22: Años sobre los que se compara el traspaso con la obra nueva. Cinco es lo habitual de un contrato con obligado cumplimiento; ponle los del tuyo.
A23: Periodicidad de la declaración de IVA | B23: 3 | C23: meses | D23: supuesto | E23: Trimestral en el régimen general de una pastelería que arranca. Si te inscribes en el registro de devolución mensual, esto es 1 y el IVA de la inversión vuelve mucho antes.
A24: Meses hasta recuperar el IVA de la inversión | B24: 4 | C24: meses | D24: supuesto | E24: El trimestre en el que compras más el plazo de presentación. Y ojo: en régimen general lo normal no es que te lo devuelvan, es que lo compenses contra el IVA que repercutes, así que tarda lo que tardes en facturar.
A25: Financiación bancaria disponible | B25: 60000 | C25: € | D25: supuesto | E25: Todo supuesto: las condiciones las pone tu banco y dependen de la garantía. La carencia de 6 meses es la que hace que el préstamo no se coma la caja justo en la rampa de arranque, y es lo primero que hay que negociar. Durante la carencia sólo se pagan intereses.
A27: Listas de validación (no las borres: las usan los desplegables)
A28: Escenario de obra
A29: Bajo
A30: Medio
A31: Alto
A33: Los tres precios por m2 son los del caso publicado de un escenario de 90 m2, así que casan con esta superficie sin retoques. Si cambias los metros, cambia la obra pero NO cambian los €/m2: pídelos otra vez, porque un local pequeño sale más caro por metro que uno grande.

Sheet CAPEX por Bloque
A1: CAPEX Por Bloque
A2: AI Chef Pro · aichef.pro — Cómo Montar una Pastelería
A3: Todas las líneas se llevan a base imponible antes de sumar. Sin la columna de IVA, el total se desvía un 21 %.
A5: Nº | B5: Bloque | C5: Partida | D5: ¿La compras? | E5: Procedencia | F5: ¿El precio lleva IVA? | G5: Tipo de IVA | H5: Mínimo | I5: Máximo | J5: Tu importe | K5: Base sin IVA | L5: IVA soportado | M5: Total con IVA | N5: Horquilla publicada | O5: Nota
A6: 1 | B6: Obra civil e instalaciones | C6: Obra civil del escenario elegido | D6: Sí | E6: PS-85a/b/c | F6: No | G6: ='Parámetros'!$B$13 -> 0.21 | H6: ='Parámetros'!B12 -> 81000 | I6: ='Parámetros'!B12 -> 81000 | J6: ='Parámetros'!B12 -> 81000 | K6: =IF(D6="No","",IFERROR(IF(F6="Sí",J6/(1+G6),J6),"")) -> 81000 | L6: =IF(K6="","",IFERROR(K6*G6,"")) -> 17010 | M6: =IF(K6="","",IFERROR(K6+L6,"")) -> 98010 | N6: 600, 900 o 1.200 €/m2 sobre 90 m2 (PS-85a/b/c) | O6: La calcula la hoja «Parámetros» con los metros y el escenario. Es la partida que más se desvía en la ejecución: lo que no está en el proyecto se paga aparte.
A7: 2 | B7: Equipamiento de obrador | C7: Horno de convección, 6 bandejas — UNOX XB693 Bakerlux | D7: Sí | E7: PS-72 | F7: Sí | G7: ='Parámetros'!$B$13 -> 0.21 | H7: 3354.12 | I7: 3354.12 | J7: 3354.12 | K7: =IF(D7="No","",IFERROR(IF(F7="Sí",J7/(1+G7),J7),"")) -> 2772 | L7: =IF(K7="","",IFERROR(K7*G7,"")) -> 582.12 | M7: =IF(K7="","",IFERROR(K7+L7,"")) -> 3354.12 | N7: Precio de ficha de distribuidor (PS-72) | O7: Precio publicado CON IVA en la ficha del distribuidor.
A8: 3 | B8: Equipamiento de obrador | C8: Horno de convección, 4 bandejas — SMEG ALFA420E1HDS | D8: Sí | E8: PS-72 | F8: Sí | G8: ='Parámetros'!$B$13 -> 0.21 | H8: 2513.41 | I8: 2513.41 | J8: 2513.41 | K8: =IF(D8="No","",IFERROR(IF(F8="Sí",J8/(1+G8),J8),"")) -> 2077.1983 | L8: =IF(K8="","",IFERROR(K8*G8,"")) -> 436.21165 | M8: =IF(K8="","",IFERROR(K8+L8,"")) -> 2513.41 | N8: Precio de ficha de distribuidor (PS-72) | O8: Segundo horno: sin él no hay dos cocciones a distinta temperatura a la vez.
A9: 4 | B9: Tienda y vitrina | C9: Vitrina expositora pastelera refrigerada curva — Docriluc VEPD-9-15-C | D9: Sí | E9: PS-76 | F9: No | G9: ='Parámetros'!$B$13 -> 0.21 | H9: 2284.1 | I9: 2284.1 | J9: 2284.1 | K9: =IF(D9="No","",IFERROR(IF(F9="Sí",J9/(1+G9),J9),"")) -> 2284.1 | L9: =IF(K9="","",IFERROR(K9*G9,"")) -> 479.661 | M9: =IF(K9="","",IFERROR(K9+L9,"")) -> 2763.761 | N9: Precio de ficha de distribuidor (PS-76) | O9: 1505x900x1305 mm, 452 L, 0,93 m² de exposición, R-290. El precio lleva un descuento de campaña del 30 % sobre un PVP de 3.263,00 €: es un precio FECHADO el 10-09-2026 y puede caducar. Si lo reutilizas, vuelve a mirarlo (D17). Una sola vitrina, contada una sola vez.
A10: 5 | B10: Tienda y vitrina | C10: Puertas correderas traseras para la vitrina — Docriluc accesorio VEPD-9-15 | D10: No | E10: PS-77 | F10: No | G10: ='Parámetros'!$B$13 -> 0.21 | H10: 120.4 | I10: 120.4 | J10: 120.4 | K10: =IF(D10="No","",IFERROR(IF(F10="Sí",J10/(1+G10),J10),"")) | L10: =IF(K10="","",IFERROR(K10*G10,"")) | M10: =IF(K10="","",IFERROR(K10+L10,"")) | N10: Precio de ficha de distribuidor (PS-77) | O10: OPCIONAL: viene con «¿la compras?» en No. Accesorio: no entra en el subtotal comparable de la dotación tipo.
A11: 6 | B11: Equipamiento de obrador | C11: Abatidor de temperatura, 4 bandejas — Irinox gama Multifresh | D11: Sí | E11: PS-78 | F11: No | G11: ='Parámetros'!$B$13 -> 0.21 | H11: 10037 | I11: 10037 | J11: 10037 | K11: =IF(D11="No","",IFERROR(IF(F11="Sí",J11/(1+G11),J11),"")) -> 10037 | L11: =IF(K11="","",IFERROR(K11*G11,"")) -> 2107.77 | M11: =IF(K11="","",IFERROR(K11+L11,"")) -> 12144.77 | N11: Precio de ficha de distribuidor (PS-78) | O11: La compra más cara y la que más se discute (decisión 2 del bonus 2). Ciclos de +85 °C a -40 °C. Un arcón doméstico NO vale como abatidor: el art. 5 del RD 1021/2022 exige potencia suficiente para llegar a -18 °C en el centro con un descenso ininterrumpido (PA-13).
A12: 7 | B12: Equipamiento de obrador | C12: Laminadora automática de masa, hasta 40 cm — Sammic DF-40 | D12: Sí | E12: PS-79 | F12: No | G12: ='Parámetros'!$B$13 -> 0.21 | H12: 1215 | I12: 1215 | J12: 1215 | K12: =IF(D12="No","",IFERROR(IF(F12="Sí",J12/(1+G12),J12),"")) -> 1215 | L12: =IF(K12="","",IFERROR(K12*G12,"")) -> 255.15 | M12: =IF(K12="","",IFERROR(K12+L12,"")) -> 1470.15 | N12: Precio de ficha de distribuidor (PS-79) | O12: 1.215,00 € sin IVA / 1.470,15 € con IVA, según la propia ficha.
A13: 8 | B13: Equipamiento de obrador | C13: Batidora planetaria, 20 L — Sammic BP-20 | D13: Sí | E13: PS-81 | F13: No | G13: ='Parámetros'!$B$13 -> 0.21 | H13: 595.04 | I13: 595.04 | J13: 595.04 | K13: =IF(D13="No","",IFERROR(IF(F13="Sí",J13/(1+G13),J13),"")) -> 595.04 | L13: =IF(K13="","",IFERROR(K13*G13,"")) -> 124.9584 | M13: =IF(K13="","",IFERROR(K13+L13,"")) -> 719.9984 | N13: Precio de ficha de distribuidor (PS-81) | O13: La ficha NO declara si el precio lleva IVA: se trata como base imponible y se marca. 900 W, 95-392 rpm, temporizador 0-99 min. La ficha NO declara si el precio lleva IVA: se trata como base imponible y se marca. Es exactamente el caso que obliga a tener la columna.
A14: 9 | B14: Equipamiento de obrador | C14: Atemperadora de chocolate, 12 kg — Selmi One | D14: No | E14: PS-82 | F14: No | G14: ='Parámetros'!$B$13 -> 0.21 | H14: 7400 | I14: 7400 | J14: 7400 | K14: =IF(D14="No","",IFERROR(IF(F14="Sí",J14/(1+G14),J14),"")) | L14: =IF(K14="","",IFERROR(K14*G14,"")) | M14: =IF(K14="","",IFERROR(K14+L14,"")) | N14: Precio de ficha de distribuidor (PS-82) | O14: OPCIONAL: viene con «¿la compras?» en No. OPCIONAL según el concepto: sólo si abres línea de bombonería o chocolatería. Por eso queda FUERA del subtotal comparable de la dotación tipo (D17): con ella dentro, un solo equipo era el 25 % del subtotal.
A15: 10 | B15: Equipamiento de obrador | C15: Horno de pisos modular (deck) — Salva gama modular de 1 a 5 módulos | D15: No | E15: PS-73 + supuesto | F15: No | G15: ='Parámetros'!$B$13 -> 0.21 | H15: 12000 | I15: 12000 | J15: 12000 | K15: =IF(D15="No","",IFERROR(IF(F15="Sí",J15/(1+G15),J15),"")) | L15: =IF(K15="","",IFERROR(K15*G15,"")) | M15: =IF(K15="","",IFERROR(K15+L15,"")) | N15: Sin precio publicado: Salva vende por presupuesto (PS-73) | O15: OPCIONAL: viene con «¿la compras?» en No. SUPUESTO, no precio de ficha. Salva vende por distribuidor y presupuesto: no hay precio publicado. Bongard, Wiesheu, Miwe y Sveba Dahlen, igual. El valor por defecto es un SUPUESTO para que la celda no quede vacía: pide tres presupuestos.
A16: 11 | B16: Equipamiento de obrador | C16: Cámara de fermentación controlada (roll-in) | D16: Sí | E16: PS-83 + supuesto | F16: No | G16: ='Parámetros'!$B$13 -> 0.21 | H16: 8500 | I16: 8500 | J16: 8500 | K16: =IF(D16="No","",IFERROR(IF(F16="Sí",J16/(1+G16),J16),"")) -> 8500 | L16: =IF(K16="","",IFERROR(K16*G16,"")) -> 1785 | M16: =IF(K16="","",IFERROR(K16+L16,"")) -> 10285 | N16: Hasta 19.438 € en la gama alta de la categoría (PS-83) | O16: SUPUESTO, no precio de ficha. PS-83 da un RANGO de categoría (hasta 19.438 € en la gama alta), no una ficha de producto: no es un precio. El valor por defecto es supuesto. Es lo que permite que la bollería esté horneada a las 7:00 sin entrar a las 3.
A17: 12 | B17: Equipamiento de obrador | C17: Conducto de extracción de humos en acero inoxidable | D17: Sí | E17: PS-84 + supuesto | F17: No | G17: ='Parámetros'!$B$13 -> 0.21 | H17: 6500 | I17: 6500 | J17: 6500 | K17: =IF(D17="No","",IFERROR(IF(F17="Sí",J17/(1+G17),J17),"")) -> 6500 | L17: =IF(K17="","",IFERROR(K17*G17,"")) -> 1365 | M17: =IF(K17="","",IFERROR(K17+L17,"")) -> 7865 | N17: «Puede superar los 6.000 €» (PS-84) | O17: SUPUESTO, no precio de ficha. PS-84 dice «puede superar los 6.000 €»: es una frase, no un presupuesto. La partida que más locales tumba, y la que hay que resolver ANTES de firmar (cap. 06). El aire de la campana es categoría AE4 del RITE y no puede compartir conducto con el del despacho (PA-07b).
A18: 13 | B18: Equipamiento de obrador | C18: Amasadora de espiral, 25 kg | D18: Sí | E18: supuesto | F18: No | G18: ='Parámetros'!$B$13 -> 0.21 | H18: 5200 | I18: 5200 | J18: 5200 | K18: =IF(D18="No","",IFERROR(IF(F18="Sí",J18/(1+G18),J18),"")) -> 5200 | L18: =IF(K18="","",IFERROR(K18*G18,"")) -> 1092 | M18: =IF(K18="","",IFERROR(K18+L18,"")) -> 6292 | N18: 4.000-8.000 € para «amasadora industrial», sin marca (PS-75) | O18: SUPUESTO, no precio de ficha. PS-75 da 4.000-8.000 € para «amasadora industrial», pero es un rango sin marca ni modelo: se usa como orden de magnitud, no como precio.
... A28: 23 | B28: Equipamiento de obrador | C28: Termómetros sonda, básculas y registradores de temperatura | D28: Sí | E28: supuesto | F28: No | G28: ='Parámetros'!$B$13 -> 0.21 | H28: 900 | I28: 900 | J28: 900 | K28: =IF(D28="No","",IFERROR(IF(F28="Sí",J28/(1+G28),J28),"")) -> 900 | L28: =IF(K28="","",IFERROR(K28*G28,"")) -> 189 | M28: =IF(K28="","",IFERROR(K28+L28,"")) -> 1089 | N28: Sin precio publicado: valor por defecto SUPUESTO | O28: SUPUESTO, no precio de ficha. Sin sonda no puedes demostrar los 70 °C/2 s del art. 9.1.a) y la vía se te cae al ovoproducto. Es la compra más barata con más consecuencias.
A29: 24 | B29: Licencias y proyecto técnico | C29: Proyecto técnico visado | D29: Sí | E29: PS-85e | F29: No | G29: ='Parámetros'!$B$13 -> 0.21 | H29: 5000 | I29: 5000 | J29: 5000 | K29: =IF(D29="No","",IFERROR(IF(F29="Sí",J29/(1+G29),J29),"")) -> 5000 | L29: =IF(K29="","",IFERROR(K29*G29,"")) -> 1050 | M29: =IF(K29="","",IFERROR(K29+L29,"")) -> 6050 | N29: Importe publicado (PS-85e)
A30: 25 | B30: Licencias y proyecto técnico | C30: Asesoramiento profesional | D30: Sí | E30: PS-85f | F30: No | G30: ='Parámetros'!$B$13 -> 0.21 | H30: 1000 | I30: 1000 | J30: 1000 | K30: =IF(D30="No","",IFERROR(IF(F30="Sí",J30/(1+G30),J30),"")) -> 1000 | L30: =IF(K30="","",IFERROR(K30*G30,"")) -> 210 | M30: =IF(K30="","",IFERROR(K30+L30,"")) -> 1210 | N30: Importe publicado (PS-85f)
A31: 26 | B31: Licencias y proyecto técnico | C31: Tasas municipales de licencia de actividad | D31: Sí | E31: supuesto | F31: No | G31: ='Parámetros'!$B$15 -> 0 | H31: 1800 | I31: 1800 | J31: 1800 | K31: =IF(D31="No","",IFERROR(IF(F31="Sí",J31/(1+G31),J31),"")) -> 1800 | L31: =IF(K31="","",IFERROR(K31*G31,"")) -> 0 | M31: =IF(K31="","",IFERROR(K31+L31,"")) -> 1800 | N31: SUPUESTO: el importe cambia en cada ayuntamiento | O31: Las tasas municipales no llevan IVA, y su importe cambia en cada ayuntamiento: es el número que hay que ir a buscar, no copiar (PA-05).
A32: 27 | B32: Licencias y proyecto técnico | C32: Comunicación o declaración responsable al registro autonómico | D32: Sí | E32: PA-04 + supuesto | F32: No | G32: ='Parámetros'!$B$15 -> 0 | H32: 120 | I32: 120 | J32: 120 | K32: =IF(D32="No","",IFERROR(IF(F32="Sí",J32/(1+G32),J32),"")) -> 120 | L32: =IF(K32="","",IFERROR(K32*G32,"")) -> 0 | M32: =IF(K32="","",IFERROR(K32+L32,"")) -> 120 | N32: SUPUESTO: el importe cambia en cada ayuntamiento | O32: No es una licencia y NO habilita para abrir: es un trámite de información que se presenta al iniciar la actividad (PA-04). El importe es supuesto y en varias CCAA es gratuito.
A33: 28 | B33: Fianza y garantías | C33: Fianza de arrendamiento (2 meses) | D33: Sí | E33: supuesto | F33: No | G33: ='Parámetros'!$B$15 -> 0 | H33: =IFERROR('Parámetros'!B20*'Parámetros'!B21,"") -> 2400 | I33: =IFERROR('Parámetros'!B20*'Parámetros'!B21,"") -> 2400 | J33: =IFERROR('Parámetros'!B20*'Parámetros'!B21,"") -> 2400 | K33: =IF(D33="No","",IFERROR(IF(F33="Sí",J33/(1+G33),J33),"")) -> 2400 | L33: =IF(K33="","",IFERROR(K33*G33,"")) -> 0 | M33: =IF(K33="","",IFERROR(K33+L33,"")) -> 2400 | N33: Renta mensual × meses de fianza | O33: La fianza no es un gasto: es un depósito que se recupera. Va en el CAPEX porque hay que tenerla el día de la firma.
A34: 29 | B34: Packaging inicial | C34: Primer pedido de packaging, bolsas, cajas y etiquetas | D34: Sí | E34: supuesto | F34: No | G34: ='Parámetros'!$B$13 -> 0.21 | H34: 2500 | I34: 2500 | J34: 2500 | K34: =IF(D34="No","",IFERROR(IF(F34="Sí",J34/(1+G34),J34),"")) -> 2500 | L34: =IF(K34="","",IFERROR(K34*G34,"")) -> 525 | M34: =IF(K34="","",IFERROR(K34+L34,"")) -> 3025 | N34: SUPUESTO: el importe cambia en cada ayuntamiento | O34: Empieza con el mínimo del proveedor: el packaging personalizado obliga a pedidos grandes y es dinero parado en el almacén.
A35: 30 | B35: Marketing de apertura | C35: Marketing de apertura | D35: Sí | E35: PS-85g | F35: No | G35: ='Parámetros'!$B$13 -> 0.21 | H35: 5000 | I35: 5000 | J35: 5000 | K35: =IF(D35="No","",IFERROR(IF(F35="Sí",J35/(1+G35),J35),"")) -> 5000 | L35: =IF(K35="","",IFERROR(K35*G35,"")) -> 1050 | M35: =IF(K35="","",IFERROR(K35+L35,"")) -> 6050 | N35: Importe publicado (PS-85g)
A36: 31 | B36: Fondo de maniobra | C36: Colchón de tesorería (meses de gastos fijos) | D36: Sí | E36: supuesto | F36: No | G36: ='Parámetros'!$B$15 -> 0 | H36: ='Parámetros'!B19 -> 62248.84 | I36: ='Parámetros'!B19 -> 62248.84 | J36: ='Parámetros'!B19 -> 62248.84 | K36: =IF(D36="No","",IFERROR(IF(F36="Sí",J36/(1+G36),J36),"")) -> 62248.84 | L36: =IF(K36="","",IFERROR(K36*G36,"")) -> 0 | M36: =IF(K36="","",IFERROR(K36+L36,"")) -> 62248.84 | N36: Meses de colchón × gastos fijos mensuales | O36: Se calcula: `meses_colchon_fondo_maniobra` × gastos fijos mensuales.
B38: Resumen por bloque
C39: Obra civil e instalaciones | K39: =SUMIF($B$6:$B$36,C39,K$6:K$36) -> 81000 | L39: =SUMIF($B$6:$B$36,C39,L$6:L$36) -> 17010 | M39: =SUMIF($B$6:$B$36,C39,M$6:M$36) -> 98010 | N39: =IFERROR(K39/$K$47,"") -> 0.35518655
C40: Equipamiento de obrador | K40: =SUMIF($B$6:$B$36,C40,K$6:K$36) -> 54296.238 | L40: =SUMIF($B$6:$B$36,C40,L$6:L$36) -> 11402.21 | M40: =SUMIF($B$6:$B$36,C40,M$6:M$36) -> 65698.448 | N40: =IFERROR(K40/$K$47,"") -> 0.23809004
C41: Tienda y vitrina | K41: =SUMIF($B$6:$B$36,C41,K$6:K$36) -> 12684.1 | L41: =SUMIF($B$6:$B$36,C41,L$6:L$36) -> 2663.661 | M41: =SUMIF($B$6:$B$36,C41,M$6:M$36) -> 15347.761 | N41: =IFERROR(K41/$K$47,"") -> 0.055620021
C42: Licencias y proyecto técnico | K42: =SUMIF($B$6:$B$36,C42,K$6:K$36) -> 7920 | L42: =SUMIF($B$6:$B$36,C42,L$6:L$36) -> 1260 | M42: =SUMIF($B$6:$B$36,C42,M$6:M$36) -> 9180 | N42: =IFERROR(K42/$K$47,"") -> 0.034729351
C43: Fianza y garantías | K43: =SUMIF($B$6:$B$36,C43,K$6:K$36) -> 2400 | L43: =SUMIF($B$6:$B$36,C43,L$6:L$36) -> 0 | M43: =SUMIF($B$6:$B$36,C43,M$6:M$36) -> 2400 | N43: =IFERROR(K43/$K$47,"") -> 0.010524046
C44: Packaging inicial | K44: =SUMIF($B$6:$B$36,C44,K$6:K$36) -> 2500 | L44: =SUMIF($B$6:$B$36,C44,L$6:L$36) -> 525 | M44: =SUMIF($B$6:$B$36,C44,M$6:M$36) -> 3025 | N44: =IFERROR(K44/$K$47,"") -> 0.010962548
C45: Marketing de apertura | K45: =SUMIF($B$6:$B$36,C45,K$6:K$36) -> 5000 | L45: =SUMIF($B$6:$B$36,C45,L$6:L$36) -> 1050 | M45: =SUMIF($B$6:$B$36,C45,M$6:M$36) -> 6050 | N45: =IFERROR(K45/$K$47,"") -> 0.021925095
C46: Fondo de maniobra | K46: =SUMIF($B$6:$B$36,C46,K$6:K$36) -> 62248.84 | L46: =SUMIF($B$6:$B$36,C46,L$6:L$36) -> 0 | M46: =SUMIF($B$6:$B$36,C46,M$6:M$36) -> 62248.84 | N46: =IFERROR(K46/$K$47,"") -> 0.27296235
C47: CAPEX TOTAL | K47: =SUM(K39:K46) -> 228049.18 | L47: =SUM(L39:L46) -> 33910.871 | M47: =SUM(M39:M46) -> 261960.05
C48: Del cual, IVA que hay que adelantar | K48: =L47 -> 33910.871
C49: Desembolso total con IVA | K49: =M47 -> 261960.05
C51: Subtotal comparable (obra, equipamiento, tienda, licencias y marketing) | K51: =K39+K40+K41+K42+K45 -> 160900.34
C52: Escenario publicado del sector para 90 m2 (PS-85h) | K52: 137000
...

Sheet Variante del Formato
A1: Variante del Formato
A2: AI Chef Pro · aichef.pro — Cómo Montar una Pastelería
A3: Tu pastelería puede no ser la del ejemplo. Los coeficientes son supuestos editables sobre el caso central; los rangos de la derecha son cifras publicadas. «Inversión de apertura» es el CAPEX sin el fondo de maniobra, que es como publica sus cifras el sector.
B5: Bases del caso central (vienen de «CAPEX por Bloque»)
B6: Obra civil e instalaciones | C6: ='CAPEX por Bloque'!K39 -> 81000
B7: Equipamiento de obrador | C7: ='CAPEX por Bloque'!K40 -> 54296.238
B8: Tienda y vitrina | C8: ='CAPEX por Bloque'!K41 -> 12684.1
B9: Licencias y proyecto técnico | C9: ='CAPEX por Bloque'!K42 -> 7920
B10: Otros de apertura (fianza, packaging y marketing) | C10: ='CAPEX por Bloque'!K43+'CAPEX por Bloque'!K44+'CAPEX por Bloque'!K45 -> 9900
B11: Fondo de maniobra | C11: ='CAPEX por Bloque'!K46 -> 62248.84
A14: Nº | B14: Variante | C14: Id del research | D14: Coef. obra | E14: Coef. equipamiento | F14: Coef. tienda | G14: Coef. licencias | H14: Coef. otros | I14: Inversión de apertura | J14: Con fondo de maniobra | K14: Publicado mínimo | L14: Publicado máximo | M14: Desviación sobre el punto medio | N14: Qué cambia además | O14: ¿Cuadra con el rango publicado?
A15: 1 | B15: Pastelería mediana: obrador propio y despacho a calle (el caso de este libro) | C15: PS-05 | D15: 1 | E15: 1 | F15: 1 | G15: 1 | H15: 1 | I15: =IFERROR($C$6*D15+$C$7*E15+$C$8*F15+$C$9*G15+$C$10*H15,"") -> 165800.34 | J15: =IFERROR(I15+$C$11*H15,"") -> 228049.18 | K15: 100000 | L15: 150000 | M15: =IF(OR(K15="",L15=""),"",IFERROR(I15/((K15+L15)/2)-1,"")) -> 0.32640271 | N15: Es el caso central: todos los coeficientes valen 1,00, así que la inversión de apertura es exactamente el CAPEX total de la hoja anterior menos el fondo de maniobra, y la columna de la derecha se lo suma otra vez para devolver el total. | O15: =IF(M15="","",IF(ABS(M15)>1,"Se van a más del doble: mira el rango antes que la cuenta","En el mismo orden de magnitud")) -> En el mismo orden de magnitud
A16: 2 | B16: Obrador en casa, venta directa al consumidor final | C16: PS-01 | D16: 0.05 | E16: 0.15 | F16: 0 | G16: 0.1 | H16: 0.2 | I16: =IFERROR($C$6*D16+$C$7*E16+$C$8*F16+$C$9*G16+$C$10*H16,"") -> 14966.436 | J16: =IFERROR(I16+$C$11*H16,"") -> 27416.204 | K16: 3000 | L16: 30000 | M16: =IF(OR(K16="",L16=""),"",IFERROR(I16/((K16+L16)/2)-1,"")) -> -0.092943288 | N16: No es un local: es tu vivienda, con la lista cerrada del art. 13.8 del RD 1021/2022 y el matiz autonómico de la letra e). Comunicación al registro autonómico, NO inscripción en el RGSEAA. Sin obra, sin tienda y sin fianza; la hoja «Ruta Doméstica» del libro 6 es la que manda. | O16: =IF(M16="","",IF(ABS(M16)>1,"Se van a más del doble: mira el rango antes que la cuenta","En el mismo orden de magnitud")) -> En el mismo orden de magnitud
A17: 3 | B17: Obrador a puerta cerrada, sólo producción | C17: PS-02 | D17: 0.45 | E17: 0.45 | F17: 0 | G17: 0.6 | H17: 0.5 | I17: =IFERROR($C$6*D17+$C$7*E17+$C$8*F17+$C$9*G17+$C$10*H17,"") -> 70585.307 | J17: =IFERROR(I17+$C$11*H17,"") -> 101709.73 | K17: 8000 | L17: 20000 | M17: =IF(OR(K17="",L17=""),"",IFERROR(I17/((K17+L17)/2)-1,"")) -> 4.0418077 | N17: Sin escaparate ni mobiliario de venta, pero con el umbral del art. 3 encima en cuanto suministres a otros minoristas de distinta titularidad. El árbol del art. 3 está en el libro 6. | O17: =IF(M17="","",IF(ABS(M17)>1,"Se van a más del doble: mira el rango antes que la cuenta","En el mismo orden de magnitud")) -> Se van a más del doble: mira el rango antes que la cuenta
A18: 4 | B18: Local con venta o despacho, sin obrador propio | C18: PS-03 | D18: 0.35 | E18: 0.1 | F18: 1 | G18: 0.7 | H18: 0.6 | I18: =IFERROR($C$6*D18+$C$7*E18+$C$8*F18+$C$9*G18+$C$10*H18,"") -> 57947.724 | J18: =IFERROR(I18+$C$11*H18,"") -> 95297.028 | K18: 15000 | L18: 50000 | M18: =IF(OR(K18="",L18=""),"",IFERROR(I18/((K18+L18)/2)-1,"")) -> 0.78300689 | N18: Compras elaborado o semielaborado: casi todo el equipamiento de obrador desaparece y la vitrina se queda entera. Si no fabricas, no puedes usar la mención «elaboración propia» (art. 11 del RD 1021/2022). | O18: =IF(M18="","",IF(ABS(M18)>1,"Se van a más del doble: mira el rango antes que la cuenta","En el mismo orden de magnitud")) -> En el mismo orden de magnitud
A19: 5 | B19: Cafetería-pastelería con obrador | C19: PS-04 | D19: 1.25 | E19: 1.05 | F19: 1.6 | G19: 1.3 | H19: 1.2 | I19: =IFERROR($C$6*D19+$C$7*E19+$C$8*F19+$C$9*G19+$C$10*H19,"") -> 200731.61 | J19: =IFERROR(I19+$C$11*H19,"") -> 275430.22 | K19: 60000 | L19: 100000 | M19: =IF(OR(K19="",L19=""),"",IFERROR(I19/((K19+L19)/2)-1,"")) -> 1.5091451 | N19: Suma sala, barra, máquina de café y aseos de público. En cuanto hay comidas preparadas cambian el marco sanitario, probablemente el convenio y el IVA aplicable en la zona de degustación, que es del 10 % por ser servicio de hostelería. | O19: =IF(M19="","",IF(ABS(M19)>1,"Se van a más del doble: mira el rango antes que la cuenta","En el mismo orden de magnitud")) -> Se van a más del doble: mira el rango antes que la cuenta
A20: 6 | B20: Punto caliente pequeño | C20: PS-06 | D20: 0.55 | E20: 0.3 | F20: 1 | G20: 0.7 | H20: 0.7 | I20: =IFERROR($C$6*D20+$C$7*E20+$C$8*F20+$C$9*G20+$C$10*H20,"") -> 85996.972 | J20: =IFERROR(I20+$C$11*H20,"") -> 129571.16 | K20: 60000 | L20: 100000 | M20: =IF(OR(K20="",L20=""),"",IFERROR(I20/((K20+L20)/2)-1,"")) -> 0.074962144 | N20: Regenera producto congelado: hornos y vitrina sí, obrador de verdad no. No fabrica, así que tampoco puede decir «elaboración propia». | O20: =IF(M20="","",IF(ABS(M20)>1,"Se van a más del doble: mira el rango antes que la cuenta","En el mismo orden de magnitud")) -> En el mismo orden de magnitud
A21: 7 | B21: Local céntrico o grande | C21: PS-07 | D21: 1.8 | E21: 1.3 | F21: 1.8 | G21: 1.4 | H21: 1.5 | I21: =IFERROR($C$6*D21+$C$7*E21+$C$8*F21+$C$9*G21+$C$10*H21,"") -> 265154.49 | J21: =IFERROR(I21+$C$11*H21,"") -> 358527.75 | K21: 150000 | L21: 250000 | M21: =IF(OR(K21="",L21=""),"",IFERROR(I21/((K21+L21)/2)-1,"")) -> 0.32577245 | N21: La obra y el alquiler dominan la inversión, y la renta que no aparece aquí se come el margen todos los meses. Mira la hoja «Traspaso vs Obra Nueva» con la renta real antes de enamorarte de la calle. | O21: =IF(M21="","",IF(ABS(M21)>1,"Se van a más del doble: mira el rango antes que la cuenta","En el mismo orden de magnitud")) -> En el mismo orden de magnitud
A22: 8 | B22: Franquicia de panadería-pastelería | C22: PS-08 | D22: 1.1 | E22: 1 | F22: 1.2 | G22: 1 | H22: 1.1 | I22: =IFERROR($C$6*D22+$C$7*E22+$C$8*F22+$C$9*G22+$C$10*H22,"") -> 177427.16 | J22: =IFERROR(I22+$C$11*H22,"") -> 245900.88 | K22: 83000 | L22: 180000 | M22: =IF(OR(K22="",L22=""),"",IFERROR(I22/((K22+L22)/2)-1,"")) -> 0.34925596 | N22: Las cifras publicadas de una misma marca varían del doble según la fuente. Y falta lo que este libro no calcula: canon de entrada y royalty mensual, que son gasto recurrente, no inversión. | O22: =IF(M22="","",IF(ABS(M22)>1,"Se van a más del doble: mira el rango antes que la cuenta","En el mismo orden de magnitud")) -> En el mismo orden de magnitud
A23: 9 | B23: Obrador B2B para hostelería | C23: PS-09 | D23: 1.4 | E23: 1.6 | F23: 0.2 | G23: 1.1 | H23: 1.3 | I23: =IFERROR($C$6*D23+$C$7*E23+$C$8*F23+$C$9*G23+$C$10*H23,"") -> 224392.8 | J23: =IFERROR(I23+$C$11*H23,"") -> 305316.29 | M23: =IF(OR(K23="",L23=""),"",IFERROR(I23/((K23+L23)/2)-1,"")) | N23: Sin cifra de inversión publicada: el caso conocido son 320 m2 entre dos locales con el 30 % de la venta a restauración. Producción a volumen, venta a crédito y casi nada de escaparate. Es donde se rompe el requisito de «restringido» del art. 3. | O23: =IF(M23="","",IF(ABS(M23)>1,"Se van a más del doble: mira el rango antes que la cuenta","En el mismo orden de magnitud"))
A24: 10 | B24: Pastelería sin salida de humos | C24: PS-11 | D24: 0.95 | E24: 1.1 | F24: 1 | G24: 1 | H24: 1 | I24: =IFERROR($C$6*D24+$C$7*E24+$C$8*F24+$C$9*G24+$C$10*H24,"") -> 167179.96 | J24: =IFERROR(I24+$C$11*H24,"") -> 229428.8 | M24: =IF(OR(K24="",L24=""),"",IFERROR(I24/((K24+L24)/2)-1,"")) | N24: No tiene rango publicado porque no es un formato de negocio, es una restricción del local: te ahorras el conducto de acero inoxidable (que «puede superar los 6.000 €») a cambio de hornos 100 % eléctricos, campana de condensación, desagüe en el punto del horno y un surtido sin fritos. Compruébalo antes en la ficha de visita del libro 1. | O24: =IF(M24="","",IF(ABS(M24)>1,"Se van a más del doble: mira el rango antes que la cuenta","En el mismo orden de magnitud"))
B26: Variantes con rango de inversión publicado | I26: =COUNT(K15:K24) -> 8
B27: Variantes que se van más de un 50 % del punto medio publicado | I27: =COUNTIF(M15:M24,">0.5")+COUNTIF(M15:M24,"<-0.5") -> 3
B29: LOS COEFICIENTES SON SUPUESTOS, Y EDITABLES A PROPÓSITO. No salen de ninguna estadística: son la desviación razonable de cada formato sobre el caso central, puesta para que puedas moverla. Lo que sí es dato publicado son las dos columnas de la derecha, con su id. Si tu cuenta y el rango publicado se van a más del doble, uno de los dos está mal, y suele ser el rango: casi ninguna de esas cifras dice si lleva IVA, si incluye la obra o si cuenta el fondo de maniobra.
B31: Dos variantes no traen rango: el obrador B2B, del que sólo hay un caso con metros pero sin inversión publicada, y la pastelería sin salida de humos, que no es un formato de negocio sino una restricción del local. En las dos, la columna de desviación se queda vacía a propósito: un cero ahí sería decir que la cuenta cuadra, y lo que pasa es que no hay con qué compararla.

Sheet Traspaso vs Obra Nueva
A1: Traspaso Contra Obra Nueva
A2: AI Chef Pro · aichef.pro — Cómo Montar una Pastelería
A3: El precio de un traspaso no es lo que cuesta un traspaso: la renta de los años del contrato pesa más que el precio.
A5: El local que estás mirando (traspaso)
A6: Precio de traspaso que te piden | B6: PS-69 | C6: 43000 | J6: Sembrado con el traspaso de Gràcia (85 m2, 43.000 €), que es el más parecido en metros a los 90 m2 del caso. Es un precio PEDIDO.
A7: Inversión de adecuación que aún tendrías que hacer | B7: supuesto | C7: 25000 | J7: Un traspaso casi nunca se abre tal cual: pintura, vitrina, rótulo y la máquina que falta. Míralo con la ficha de visita del libro 1 en la mano.
A8: Renta mensual del local traspasado | B8: PS-69 | C8: 1250 | J8: La renta sólo consta en los cinco traspasos de Barcelona. En los otros diez, el anuncio no la dice, que ya es un dato.
A9: Meses parado hasta abrir con el traspaso | B9: supuesto | C9: 1 | J9: Pagas renta desde la firma y no facturas hasta que abres.
A10: CAPEX comparable de la obra nueva (de «CAPEX por Bloque») | C10: ='CAPEX por Bloque'!K51 -> 160900.34 | J10: Sin fianza, packaging ni fondo de maniobra: los dos lados de la comparación los necesitan igual, así que sumarlos a uno solo falsearía el resultado.
A11: Renta mensual del local en obra nueva | C11: ='Parámetros'!B20 -> 1200
A12: Meses de obra sin facturar | B12: supuesto | C12: 4 | J12: Renta que pagas mientras el local está en obras. Es la partida que casi nadie mete y la que más se parece a una sorpresa.
A13: Horizonte de comparación (años) | C13: ='Parámetros'!B22 -> 5
A14: La comparación
A15: Coste del traspaso a lo largo del horizonte | C15: =IFERROR(C6+C7+C8*12*C13,"") -> 143000
A16: Coste de la obra nueva a lo largo del horizonte | C16: =IFERROR(C10+C11*12*C13,"") -> 232900.34
A17: Renta pagada sin facturar, traspaso | C17: =IFERROR(C8*C9,"") -> 1250
A18: Renta pagada sin facturar, obra nueva | C18: =IFERROR(C11*C12,"") -> 4800
A19: TOTAL del traspaso | C19: =IFERROR(C15+C17,"") -> 144250
A20: TOTAL de la obra nueva | C20: =IFERROR(C16+C18,"") -> 237700.34
A21: Diferencia (traspaso menos obra nueva) | C21: =IFERROR(C19-C20,"") -> -93450.338
A22: VEREDICTO | C22: =IF(C21="","",IF(C21<0,"Sale mejor el TRASPASO","Sale mejor la OBRA NUEVA")) -> Sale mejor el TRASPASO | J22: El veredicto compara dinero, y el dinero no lo es todo: un traspaso te da una clientela y un local que ya funcionó, y te ata a una distribución de zonas que igual no admite marcha adelante. Pasa el local traspasado por la ficha de visita del libro 1 antes de hacerle caso a esta celda.
A24: Quince traspasos reales, para ver la horquilla
A25: Ciudad o zona | B25: Tipo de negocio | C25: m2 | D25: Precio pedido | E25: Renta mensual | F25: € por m2 | G25: Coste en el horizonte | H25: Fuente
A26: Barcelona - Gràcia | B26: Pastelería-repostería | C26: 85 | D26: 43000 | E26: 1250 | F26: =IF(ISNUMBER(C26),IFERROR(D26/C26,""),"") -> 505.88235 | G26: =IF(ISNUMBER(E26),IFERROR(D26+E26*12*$C$13,""),"") -> 118000 | H26: PS-69
A27: Barcelona - Poblenou | B27: Pastelería take away | C27: 69 | D27: 80000 | E27: 850 | F27: =IF(ISNUMBER(C27),IFERROR(D27/C27,""),"") -> 1159.4203 | G27: =IF(ISNUMBER(E27),IFERROR(D27+E27*12*$C$13,""),"") -> 131000 | H27: PS-69
A28: Barcelona - Sant Antoni | B28: Obrador sin venta al público | C28: 80 | D28: 25000 | E28: 1050 | F28: =IF(ISNUMBER(C28),IFERROR(D28/C28,""),"") -> 312.5 | G28: =IF(ISNUMBER(E28),IFERROR(D28+E28*12*$C$13,""),"") -> 88000 | H28: PS-69
A29: Barcelona - Pg. Maragall | B29: Panadería-pastelería | C29: 63 | D29: 18000 | E29: 1300 | F29: =IF(ISNUMBER(C29),IFERROR(D29/C29,""),"") -> 285.71429 | G29: =IF(ISNUMBER(E29),IFERROR(D29+E29*12*$C$13,""),"") -> 96000 | H29: PS-69
A30: Barcelona - Sant Andreu | B30: Pastelería artesanal | C30: 63 | D30: 19000 | E30: 1300 | F30: =IF(ISNUMBER(C30),IFERROR(D30/C30,""),"") -> 301.5873 | G30: =IF(ISNUMBER(E30),IFERROR(D30+E30*12*$C$13,""),"") -> 97000 | H30: PS-69
A31: Sevilla | B31: Pastelería | D31: 6000 | F31: =IF(ISNUMBER(C31),IFERROR(D31/C31,""),"") | G31: =IF(ISNUMBER(E31),IFERROR(D31+E31*12*$C$13,""),"") | H31: PS-70
A32: Valencia | B32: Despacho de pan | D32: 15500 | F32: =IF(ISNUMBER(C32),IFERROR(D32/C32,""),"") | G32: =IF(ISNUMBER(E32),IFERROR(D32+E32*12*$C$13,""),"") | H32: PS-70
A33: Valencia - Benimaclet | B33: Pastelería | D33: 18000 | F33: =IF(ISNUMBER(C33),IFERROR(D33/C33,""),"") | G33: =IF(ISNUMBER(E33),IFERROR(D33+E33*12*$C$13,""),"") | H33: PS-70
A34: Madrid | B34: Obrador pequeño | D34: 20000 | F34: =IF(ISNUMBER(C34),IFERROR(D34/C34,""),"") | G34: =IF(ISNUMBER(E34),IFERROR(D34+E34*12*$C$13,""),"") | H34: PS-70
A35: Madrid | B35: Pastelería sin obrador, más de 25 años | D35: 19500 | F35: =IF(ISNUMBER(C35),IFERROR(D35/C35,""),"") | G35: =IF(ISNUMBER(E35),IFERROR(D35+E35*12*$C$13,""),"") | H35: PS-70
A36: Almería | B36: Repostería creativa | D36: 25000 | F36: =IF(ISNUMBER(C36),IFERROR(D36/C36,""),"") | G36: =IF(ISNUMBER(E36),IFERROR(D36+E36*12*$C$13,""),"") | H36: PS-70
A37: Barcelona | B37: Pastelería | D37: 50000 | F37: =IF(ISNUMBER(C37),IFERROR(D37/C37,""),"") | G37: =IF(ISNUMBER(E37),IFERROR(D37+E37*12*$C$13,""),"") | H37: PS-70
A38: Barcelona | B38: Pastelería por jubilación | D38: 75000 | F38: =IF(ISNUMBER(C38),IFERROR(D38/C38,""),"") | G38: =IF(ISNUMBER(E38),IFERROR(D38+E38*12*$C$13,""),"") | H38: PS-70
A39: Gran Canaria | B39: Pastelería | D39: 65000 | F39: =IF(ISNUMBER(C39),IFERROR(D39/C39,""),"") | G39: =IF(ISNUMBER(E39),IFERROR(D39+E39*12*$C$13,""),"") | H39: PS-70
A40: Lleida | B40: Pastelería-cafetería, más de 36 años | D40: 100000 | F40: =IF(ISNUMBER(C40),IFERROR(D40/C40,""),"") | G40: =IF(ISNUMBER(E40),IFERROR(D40+E40*12*$C$13,""),"") | H40: PS-70
A41: Traspasos con renta publicada | D41: =COUNT(E26:E40) -> 5
A42: Precio pedido más bajo | D42: =IFERROR(MIN(D26:D40),"") -> 6000
...

Sheet IVA y Tesorería
A1: IVA y Tesorería del Arranque
A2: AI Chef Pro · aichef.pro — Cómo Montar una Pastelería
A3: El IVA de la inversión sale de tu bolsillo meses antes de volver. Es la sorpresa más cara del primer trimestre.
A5: Bloque | B5: Base sin IVA | C5: IVA soportado | D5: Total con IVA
A6: Obra civil e instalaciones | B6: ='CAPEX por Bloque'!K39 -> 81000 | C6: ='CAPEX por Bloque'!L39 -> 17010 | D6: ='CAPEX por Bloque'!M39 -> 98010
A7: Equipamiento de obrador | B7: ='CAPEX por Bloque'!K40 -> 54296.238 | C7: ='CAPEX por Bloque'!L40 -> 11402.21 | D7: ='CAPEX por Bloque'!M40 -> 65698.448
A8: Tienda y vitrina | B8: ='CAPEX por Bloque'!K41 -> 12684.1 | C8: ='CAPEX por Bloque'!L41 -> 2663.661 | D8: ='CAPEX por Bloque'!M41 -> 15347.761
A9: Licencias y proyecto técnico | B9: ='CAPEX por Bloque'!K42 -> 7920 | C9: ='CAPEX por Bloque'!L42 -> 1260 | D9: ='CAPEX por Bloque'!M42 -> 9180
A10: Fianza y garantías | B10: ='CAPEX por Bloque'!K43 -> 2400 | C10: ='CAPEX por Bloque'!L43 -> 0 | D10: ='CAPEX por Bloque'!M43 -> 2400
A11: Packaging inicial | B11: ='CAPEX por Bloque'!K44 -> 2500 | C11: ='CAPEX por Bloque'!L44 -> 525 | D11: ='CAPEX por Bloque'!M44 -> 3025
A12: Marketing de apertura | B12: ='CAPEX por Bloque'!K45 -> 5000 | C12: ='CAPEX por Bloque'!L45 -> 1050 | D12: ='CAPEX por Bloque'!M45 -> 6050
A13: Fondo de maniobra | B13: ='CAPEX por Bloque'!K46 -> 62248.84 | C13: ='CAPEX por Bloque'!L46 -> 0 | D13: ='CAPEX por Bloque'!M46 -> 62248.84
A14: TOTAL | B14: =SUM(B6:B13) -> 228049.18 | C14: =SUM(C6:C13) -> 33910.871 | D14: =SUM(D6:D13) -> 261960.05
A15: Cuándo vuelve ese IVA
A16: Periodicidad de tu declaración (meses) | B16: ='Parámetros'!B23 -> 3
A17: Meses hasta recuperarlo | B17: ='Parámetros'!B24 -> 4
A18: IVA que tienes que adelantar | B18: =C14 -> 33910.871 | E18: En régimen general lo normal NO es que Hacienda te lo devuelva: es que lo compenses contra el IVA que repercutes. O sea, que vuelve al ritmo al que factures, no en una fecha. Si te inscribes en el registro de devolución mensual, la periodicidad pasa a 1 y la espera se acorta mucho: pregúntale a tu asesor antes de firmar la primera factura, no después.
A20: La caja del día que abres
A21: CAPEX sin IVA | B21: =B14 -> 228049.18
A22: IVA soportado | B22: =C14 -> 33910.871
A23: Desembolso total con IVA | B23: =D14 -> 261960.05
A24: Del cual, fondo de maniobra (es caja, no inversión) | B24: ='CAPEX por Bloque'!K46 -> 62248.84
A25: Financiación bancaria disponible | B25: ='Parámetros'!B25 -> 60000
A26: Aportación propia necesaria | B26: =IFERROR(B23-B25,"") -> 201960.05
A27: Meses de gastos fijos que cubre el fondo de maniobra | B27: =IFERROR(B24/'Parámetros'!B18,"") -> 4 | E27: Por debajo del colchón mínimo de «Parámetros», el negocio depende de facturar desde la primera semana. Es la causa de cierre más frecuente de un local que por lo demás funcionaba.
A28: VEREDICTO DE LA CAJA | B28: =IF(B26="","",IF(B26<=0,"La financiación cubre el desembolso",IF(B27<'Parámetros'!$B$17,"Te falta colchón: revisa el fondo de maniobra","Necesitas aportación propia"))) -> Necesitas aportación propia
A30: Que necesites aportación propia no es una mala noticia: ningún banco financia el 100 % de una apertura, y el que lo hiciera te estaría dejando sin margen de maniobra. Lo que sí es mala noticia es descubrirlo el mes de la firma.

Sheet Resumen
A1: Resumen
A2: AI Chef Pro · aichef.pro — Cómo Montar una Pastelería
A3: Las cifras que hay que llevar al banco. Todas calculadas desde las hojas anteriores; aquí no se teclea nada.
A5: Cifra | B5: Valor | C5: De dónde sale | D5: Qué dice
A6: Escenario de obra elegido | B6: ='Parámetros'!B10 -> Medio | C6: Parámetros | D6: Bajo, medio o alto. Cambiarlo recalcula todo el libro.
A7: Obra civil | B7: ='Parámetros'!B12 -> 81000 | C7: Parámetros | D7: Metros por el precio del escenario. La partida más grande y la que más se desvía en la ejecución.
A8: CAPEX total sin IVA | B8: ='CAPEX por Bloque'!K47 -> 228049.18 | C8: CAPEX por Bloque | D8: Todo llevado a base imponible: es la cifra que se compara con cualquier otro presupuesto.
A9: IVA soportado | B9: ='CAPEX por Bloque'!L47 -> 33910.871 | C9: CAPEX por Bloque | D9: Dinero tuyo que adelantas y que vuelve al ritmo al que factures.
A10: Desembolso total con IVA | B10: ='CAPEX por Bloque'!M47 -> 261960.05 | C10: CAPEX por Bloque | D10: Lo que sale de la cuenta. Es el número de la conversación con el banco.
A11: Subtotal comparable con el sector | B11: ='CAPEX por Bloque'!K51 -> 160900.34 | C11: CAPEX por Bloque | D11: Obra, equipamiento, tienda, licencias y marketing: lo que incluyen los presupuestos publicados.
A12: Desviación sobre el escenario publicado | B12: ='CAPEX por Bloque'!K53 -> 0.17445502 | C12: CAPEX por Bloque | D12: Dos fuentes independientes en el mismo orden de magnitud. La desviación se explica, no se maquilla.
A13: Equipamiento de obrador | B13: ='CAPEX por Bloque'!K40 -> 54296.238 | C13: CAPEX por Bloque | D13: Sin los opcionales, que vienen marcados «No».
A14: Tienda y vitrina | B14: ='CAPEX por Bloque'!K41 -> 12684.1 | C14: CAPEX por Bloque | D14: Vitrina, mobiliario de despacho y TPV.
A15: Fondo de maniobra | B15: ='CAPEX por Bloque'!K46 -> 62248.84 | C15: CAPEX por Bloque | D15: Meses de colchón por gastos fijos. Es inversión, no prudencia.
A16: Aportación propia necesaria | B16: ='IVA y Tesorería'!B26 -> 201960.05 | C16: IVA y Tesorería | D16: Desembolso menos financiación bancaria.
A17: Meses de gastos fijos cubiertos | B17: ='IVA y Tesorería'!B27 -> 4 | C17: IVA y Tesorería | D17: Por debajo de tres, el negocio depende de facturar desde la primera semana.
A18: Veredicto de la caja | B18: ='IVA y Tesorería'!B28 -> Necesitas aportación propia | C18: IVA y Tesorería | D18: Si la financiación cubre el desembolso o hace falta poner dinero.
A19: Coste del traspaso en el horizonte | B19: ='Traspaso vs Obra Nueva'!C19 -> 144250 | C19: Traspaso vs Obra Nueva | D19: Precio pedido, adecuación y renta de todos los años, más la parada.
A20: Coste de la obra nueva en el horizonte | B20: ='Traspaso vs Obra Nueva'!C20 -> 237700.34 | C20: Traspaso vs Obra Nueva | D20: CAPEX comparable y renta de todos los años, más los meses de obra.
A21: Traspaso o obra nueva | B21: ='Traspaso vs Obra Nueva'!C22 -> Sale mejor el TRASPASO | C21: Traspaso vs Obra Nueva | D21: Compara dinero. La distribución del local y la clientela no salen en esta celda.
A23: Si alguna de estas cifras no te cuadra, no la cambies aquí: esta hoja no tiene ni una celda editable. Vuelve a la hoja donde nace y cambia el parámetro o el importe. Es lo que evita que un resumen y su origen digan cosas distintas.
