Workbook

Sheet Instrucciones
A1: Checklist de equipamiento y proveedores
A2: AI Chef Pro · aichef.pro — Cómo Montar una Pastelería
A3: Para qué sirve: decidir qué equipo compras, a quién, a qué precio real y con qué plazo de entrega.
A5: Instrucciones de uso
A6: 1. Hoja «Equipamiento»: la dotación completa de una pastelería con obrador, línea a línea. Empieza por el bloque verde de arriba: el tipo de IVA, la horquilla con la que quieres ver el precio de referencia, el CAPEX de equipamiento que te dio el libro 2, el umbral de desviación que te permites y las semanas que faltan hasta la apertura que tienes en la cabeza. Todo lo demás de la hoja se recalcula con eso.
A7: 2. En cada línea escribe tres cosas: el precio real que te han presupuestado (SIN IVA), quién te lo vende y en cuántas semanas te lo entrega. Las tres vienen rellenas con un valor por defecto para que veas la hoja funcionando; los tres son supuestos y hay que sustituirlos.
A8: 3. Marca el estado de cada línea (Pendiente, Presupuestado, Pedido, Recibido, Instalado o N/A). «N/A» es lo que tu formato no necesita, y no cuenta ni a favor ni en contra del avance.
A9: 4. Hoja «Variante del Formato»: elige arriba qué vas a montar y la hoja te dice qué líneas de la dotación te sobran, cuáles te faltan y cuánto cuesta esa variante frente al caso base. Es la hoja que evita comprar el equipo de otro negocio.
A10: 5. Hoja «Proveedores»: los nueve proveedores con URL comprobada el 10-09-2026, con columnas verdes para tu contacto, tu pedido mínimo, tu plazo y tus condiciones de pago. Los 22 que el research recogió sin verificar no se publican: un directorio con un enlace roto vale menos que uno corto.
A11: 6. Hoja «Contador»: el avance del checklist, el avance de lo CRÍTICO (que es el que decide si puedes abrir), el reparto por bloque de CAPEX y por categoría, y lo negociado contra lo de referencia.
A13: Celdas verdes = campos editables
A15: Lo que conviene saber antes de empezar
... A31: Versión 1.0 · septiembre 2026 · aichef.pro/guia-pasteleria-obrador · info@aichef.pro

Sheet Equipamiento
A1: Equipamiento, Línea a Línea
A2: AI Chef Pro · aichef.pro — Cómo Montar una Pastelería
A3: Los precios de referencia salen de fichas de distribuidor leídas el 10-09-2026 (nueve líneas) o son supuestos declarados (trece). Cada uno con SU base fiscal: mezclarlas desvía la inversión un 21 %.
A5: Parámetros de esta hoja
A6: Parámetro | C6: Valor | D6: Nota
A7: Tipo de IVA general (%) | C7: 0.21 | D7: Tipo general del art. 90.Uno de la Ley 37/1992. La maquinaria y el mobiliario van al 21 %: no hay tipo reducido para el equipamiento de un obrador. Cámbialo aquí y se recalcula toda la columna.
A8: Horquilla del precio de referencia (±%) | C8: 0.25 | D8: SUPUESTO. Con cuánta amplitud quieres ver el mínimo y el máximo alrededor del precio de referencia. El 25 % es la banda que se mueve entre lo que pide una ficha web y lo que se cierra con tres presupuestos; súbela si compras a un solo distribuidor.
A9: Total de CAPEX de equipamiento del libro 2 (€, sin IVA) | C9: 66980.34 | D9: CÓPIALO DE «calculadora-capex-pasteleria.xlsx» (libro 2), bloques «Equipamiento de obrador» y «Tienda y vitrina». Viene relleno con el valor del caso «La Clara» como SUPUESTO, para que la hoja funcione antes de que abras el libro 2. No hay ninguna fórmula entre libros: esto es una copia declarada, no un vínculo.
A10: Umbral de desviación admitida (%) | C10: 0.1 | D10: SUPUESTO. Por encima de esta desviación contra el CAPEX del libro 2, la hoja lo marca en rojo: o has comprado de más, o el plan financiero del libro 5 está calculado con una inversión que ya no es la tuya.
A11: Semanas que faltan hasta la apertura prevista | C11: 20 | D11: SUPUESTO. Cuenta desde hoy hasta la fecha que tienes en la cabeza. El cronograma completo, con la ruta crítica de licencias y obra, lo calcula la hoja «Cronograma y Ruta Crítica» del libro 6.
A12: Margen de seguridad entre la entrega y la apertura (semanas) | C12: 2 | D12: SUPUESTO. Lo que necesitas entre que llega la máquina y que abres: montaje, conexión, puesta en marcha y las pruebas de producción. Con menos de dos semanas, la primera avería te pilla con la tienda abierta.
A14: La dotación completa, línea a línea
A15: Estado | B15: Nº | C15: Partida | D15: Marca | E15: Modelo | F15: Categoría | G15: Bloque de CAPEX | H15: Prioridad | I15: Precio de referencia (€) | J15: ¿Lleva IVA? | K15: Tipo de IVA (%) | L15: Precio de referencia SIN IVA (€) | M15: Mínimo estimado (€) | N15: Máximo estimado (€) | O15: Precio real negociado (€, sin IVA) | P15: Desviación sobre la referencia (%) | Q15: Proveedor | R15: Plazo de entrega (semanas) | S15: Margen hasta la apertura (semanas) | T15: Aux · plazo de las líneas críticas | U15: Aux · ¿el plazo se pasa? (1 = sí) | V15: Fuente del precio | W15: Nota
A16: Pendiente | B16: 1 | C16: Horno de convección, 6 bandejas | D16: UNOX | E16: XB693 Bakerlux | F16: Calor | G16: Equipamiento de obrador | H16: Crítico | I16: 3354.12 | J16: con IVA | K16: =$C$7 -> 0.21 | L16: =IFERROR(IF($I16="","",IF($J16=$E$62,$I16/(1+$K16),$I16)),"") -> 2772 | M16: =IF($L16="","",$L16*(1-$C$8)) -> 2079 | N16: =IF($L16="","",$L16*(1+$C$8)) -> 3465 | O16: 2772 | P16: =IFERROR(IF(OR($O16="",$L16=""),"",$O16/$L16-1),"") -> 0 | Q16: UNOX | R16: 5 | S16: =IFERROR(IF(OR($R16="",$C$11="",$C$12=""),"",$C$11-$R16-$C$12),"") -> 13 | T16: =IF($H16=$C$61,$R16,"") -> 5 | U16: =IF($S16="","",IF($S16<0,1,0)) -> 0 | V16: PS-72 | W16: Precio publicado CON IVA en la ficha del distribuidor.
A17: Pendiente | B17: 2 | C17: Horno de convección, 4 bandejas | D17: SMEG | E17: ALFA420E1HDS | F17: Calor | G17: Equipamiento de obrador | H17: Crítico | I17: 2513.41 | J17: con IVA | K17: =$C$7 -> 0.21 | L17: =IFERROR(IF($I17="","",IF($J17=$E$62,$I17/(1+$K17),$I17)),"") -> 2077.1983 | M17: =IF($L17="","",$L17*(1-$C$8)) -> 1557.8988 | N17: =IF($L17="","",$L17*(1+$C$8)) -> 2596.4979 | O17: 2077.2 | P17: =IFERROR(IF(OR($O17="",$L17=""),"",$O17/$L17-1),"") -> 7.9573169e-07 | Q17: SMEG | R17: 5 | S17: =IFERROR(IF(OR($R17="",$C$11="",$C$12=""),"",$C$11-$R17-$C$12),"") -> 13 | T17: =IF($H17=$C$61,$R17,"") -> 5 | U17: =IF($S17="","",IF($S17<0,1,0)) -> 0 | V17: PS-72 | W17: Segundo horno: sin él no hay dos cocciones a distinta temperatura a la vez.
A18: Pendiente | B18: 3 | C18: Vitrina expositora pastelera refrigerada curva | D18: Docriluc | E18: VEPD-9-15-C | F18: Tienda y vitrina | G18: Tienda y vitrina | H18: Crítico | I18: 2284.1 | J18: sin IVA | K18: =$C$7 -> 0.21 | L18: =IFERROR(IF($I18="","",IF($J18=$E$62,$I18/(1+$K18),$I18)),"") -> 2284.1 | M18: =IF($L18="","",$L18*(1-$C$8)) -> 1713.075 | N18: =IF($L18="","",$L18*(1+$C$8)) -> 2855.125 | O18: 2284.1 | P18: =IFERROR(IF(OR($O18="",$L18=""),"",$O18/$L18-1),"") -> 0 | Q18: Docriluc | R18: 6 | S18: =IFERROR(IF(OR($R18="",$C$11="",$C$12=""),"",$C$11-$R18-$C$12),"") -> 12 | T18: =IF($H18=$C$61,$R18,"") -> 6 | U18: =IF($S18="","",IF($S18<0,1,0)) -> 0 | V18: PS-76 | W18: 1505x900x1305 mm, 452 L, 0,93 m² de exposición, R-290. El precio lleva un descuento de campaña del 30 % sobre un PVP de 3.263,00 €: es un precio FECHADO el 10-09-2026 y puede caducar. Si lo reutilizas, vuelve a mirarlo (D17). Una sola vitrina, contada una sola vez.
A19: Pendiente | B19: 4 | C19: Puertas correderas traseras para la vitrina | D19: Docriluc | E19: accesorio VEPD-9-15 | F19: Tienda y vitrina | G19: Tienda y vitrina | H19: Opcional | I19: 120.4 | J19: sin IVA | K19: =$C$7 -> 0.21 | L19: =IFERROR(IF($I19="","",IF($J19=$E$62,$I19/(1+$K19),$I19)),"") -> 120.4 | M19: =IF($L19="","",$L19*(1-$C$8)) -> 90.3 | N19: =IF($L19="","",$L19*(1+$C$8)) -> 150.5 | O19: 120.4 | P19: =IFERROR(IF(OR($O19="",$L19=""),"",$O19/$L19-1),"") -> 0 | Q19: Docriluc | R19: 6 | S19: =IFERROR(IF(OR($R19="",$C$11="",$C$12=""),"",$C$11-$R19-$C$12),"") -> 12 | T19: =IF($H19=$C$61,$R19,"") | U19: =IF($S19="","",IF($S19<0,1,0)) -> 0 | V19: PS-77 | W19: Accesorio: no entra en el subtotal comparable de la dotación tipo.
A20: Pendiente | B20: 5 | C20: Abatidor de temperatura, 4 bandejas | D20: Irinox | E20: gama Multifresh | F20: Frío negativo | G20: Equipamiento de obrador | H20: Crítico | I20: 10037 | J20: sin IVA | K20: =$C$7 -> 0.21 | L20: =IFERROR(IF($I20="","",IF($J20=$E$62,$I20/(1+$K20),$I20)),"") -> 10037 | M20: =IF($L20="","",$L20*(1-$C$8)) -> 7527.75 | N20: =IF($L20="","",$L20*(1+$C$8)) -> 12546.25 | O20: 10037 | P20: =IFERROR(IF(OR($O20="",$L20=""),"",$O20/$L20-1),"") -> 0 | Q20: Irinox | R20: 8 | S20: =IFERROR(IF(OR($R20="",$C$11="",$C$12=""),"",$C$11-$R20-$C$12),"") -> 10 | T20: =IF($H20=$C$61,$R20,"") -> 8 | U20: =IF($S20="","",IF($S20<0,1,0)) -> 0 | V20: PS-78 | W20: La compra más cara y la que más se discute (decisión 2 del bonus 2). Ciclos de +85 °C a -40 °C. Un arcón doméstico NO vale como abatidor: el art. 5 del RD 1021/2022 exige potencia suficiente para llegar a -18 °C en el centro con un descenso ininterrumpido (PA-13).
A21: Pendiente | B21: 6 | C21: Laminadora automática de masa, hasta 40 cm | D21: Sammic | E21: DF-40 | F21: Laminación | G21: Equipamiento de obrador | H21: Crítico | I21: 1215 | J21: sin IVA | K21: =$C$7 -> 0.21 | L21: =IFERROR(IF($I21="","",IF($J21=$E$62,$I21/(1+$K21),$I21)),"") -> 1215 | M21: =IF($L21="","",$L21*(1-$C$8)) -> 911.25 | N21: =IF($L21="","",$L21*(1+$C$8)) -> 1518.75 | O21: 1215 | P21: =IFERROR(IF(OR($O21="",$L21=""),"",$O21/$L21-1),"") -> 0 | Q21: Sammic | R21: 4 | S21: =IFERROR(IF(OR($R21="",$C$11="",$C$12=""),"",$C$11-$R21-$C$12),"") -> 14 | T21: =IF($H21=$C$61,$R21,"") -> 4 | U21: =IF($S21="","",IF($S21<0,1,0)) -> 0 | V21: PS-79 | W21: 1.215,00 € sin IVA / 1.470,15 € con IVA, según la propia ficha.
A22: Pendiente | B22: 7 | C22: Batidora planetaria, 20 L | D22: Sammic | E22: BE-20 | F22: Amasado y batido | G22: Equipamiento de obrador | H22: Crítico | I22: 595.04 | J22: no declarada | K22: =$C$7 -> 0.21 | L22: =IFERROR(IF($I22="","",IF($J22=$E$62,$I22/(1+$K22),$I22)),"") -> 595.04 | M22: =IF($L22="","",$L22*(1-$C$8)) -> 446.28 | N22: =IF($L22="","",$L22*(1+$C$8)) -> 743.8 | O22: 595.04 | P22: =IFERROR(IF(OR($O22="",$L22=""),"",$O22/$L22-1),"") -> 0 | Q22: Sammic | R22: 3 | S22: =IFERROR(IF(OR($R22="",$C$11="",$C$12=""),"",$C$11-$R22-$C$12),"") -> 15 | T22: =IF($H22=$C$61,$R22,"") -> 3 | U22: =IF($S22="","",IF($S22<0,1,0)) -> 0 | V22: PS-81 | W22: 900 W, 95-392 rpm, temporizador 0-99 min. La ficha NO declara si el precio lleva IVA: se trata como base imponible y se marca. Es exactamente el caso que obliga a tener la columna.
A23: Pendiente | B23: 8 | C23: Atemperadora de chocolate, 12 kg | D23: Selmi | E23: One | F23: Chocolate | G23: Equipamiento de obrador | H23: Opcional | I23: 7400 | J23: sin IVA | K23: =$C$7 -> 0.21 | L23: =IFERROR(IF($I23="","",IF($J23=$E$62,$I23/(1+$K23),$I23)),"") -> 7400 | M23: =IF($L23="","",$L23*(1-$C$8)) -> 5550 | N23: =IF($L23="","",$L23*(1+$C$8)) -> 9250 | O23: 7400 | P23: =IFERROR(IF(OR($O23="",$L23=""),"",$O23/$L23-1),"") -> 0 | Q23: Selmi | R23: 7 | S23: =IFERROR(IF(OR($R23="",$C$11="",$C$12=""),"",$C$11-$R23-$C$12),"") -> 11 | T23: =IF($H23=$C$61,$R23,"") | U23: =IF($S23="","",IF($S23<0,1,0)) -> 0 | V23: PS-82 | W23: OPCIONAL según el concepto: sólo si abres línea de bombonería o chocolatería. Por eso queda FUERA del subtotal comparable de la dotación tipo (D17): con ella dentro, un solo equipo era el 25 % del subtotal.
A24: Pendiente | B24: 9 | C24: Horno de pisos modular (deck) | D24: Salva | E24: gama modular de 1 a 5 módulos | F24: Calor | G24: Equipamiento de obrador | H24: Opcional | I24: 12000 | J24: sin IVA | K24: =$C$7 -> 0.21 | L24: =IFERROR(IF($I24="","",IF($J24=$E$62,$I24/(1+$K24),$I24)),"") -> 12000 | M24: =IF($L24="","",$L24*(1-$C$8)) -> 9000 | N24: =IF($L24="","",$L24*(1+$C$8)) -> 15000 | O24: 12000 | P24: =IFERROR(IF(OR($O24="",$L24=""),"",$O24/$L24-1),"") -> 0 | Q24: Salva | R24: 12 | S24: =IFERROR(IF(OR($R24="",$C$11="",$C$12=""),"",$C$11-$R24-$C$12),"") -> 6 | T24: =IF($H24=$C$61,$R24,"") | U24: =IF($S24="","",IF($S24<0,1,0)) -> 0 | V24: PS-73 + supuesto | W24: Salva vende por distribuidor y presupuesto: no hay precio publicado. Bongard, Wiesheu, Miwe y Sveba Dahlen, igual. El valor por defecto es un SUPUESTO para que la celda no quede vacía: pide tres presupuestos.
A25: Pendiente | B25: 10 | C25: Cámara de fermentación controlada (roll-in) | F25: Frío positivo | G25: Equipamiento de obrador | H25: Crítico | I25: 8500 | J25: sin IVA | K25: =$C$7 -> 0.21 | L25: =IFERROR(IF($I25="","",IF($J25=$E$62,$I25/(1+$K25),$I25)),"") -> 8500 | M25: =IF($L25="","",$L25*(1-$C$8)) -> 6375 | N25: =IF($L25="","",$L25*(1+$C$8)) -> 10625 | O25: 8500 | P25: =IFERROR(IF(OR($O25="",$L25=""),"",$O25/$L25-1),"") -> 0 | Q25: Pendiente: pide tres presupuestos | R25: 9 | S25: =IFERROR(IF(OR($R25="",$C$11="",$C$12=""),"",$C$11-$R25-$C$12),"") -> 9 | T25: =IF($H25=$C$61,$R25,"") -> 9 | U25: =IF($S25="","",IF($S25<0,1,0)) -> 0 | V25: PS-83 + supuesto | W25: PS-83 da un RANGO de categoría (hasta 19.438 € en la gama alta), no una ficha de producto: no es un precio. El valor por defecto es supuesto. Es lo que permite que la bollería esté horneada a las 7:00 sin entrar a las 3.
A26: Pendiente | B26: 11 | C26: Conducto de extracción de humos en acero inoxidable | F26: Instalaciones | G26: Equipamiento de obrador | H26: Crítico | I26: 6500 | J26: sin IVA | K26: =$C$7 -> 0.21 | L26: =IFERROR(IF($I26="","",IF($J26=$E$62,$I26/(1+$K26),$I26)),"") -> 6500 | M26: =IF($L26="","",$L26*(1-$C$8)) -> 4875 | N26: =IF($L26="","",$L26*(1+$C$8)) -> 8125 | O26: 6500 | P26: =IFERROR(IF(OR($O26="",$L26=""),"",$O26/$L26-1),"") -> 0 | Q26: Pendiente: pide tres presupuestos | R26: 6 | S26: =IFERROR(IF(OR($R26="",$C$11="",$C$12=""),"",$C$11-$R26-$C$12),"") -> 12 | T26: =IF($H26=$C$61,$R26,"") -> 6 | U26: =IF($S26="","",IF($S26<0,1,0)) -> 0 | V26: PS-84 + supuesto | W26: PS-84 dice «puede superar los 6.000 €»: es una frase, no un presupuesto. La partida que más locales tumba, y la que hay que resolver ANTES de firmar (cap. 06). El aire de la campana es categoría AE4 del RITE y no puede compartir conducto con el del despacho (PA-07b).
A27: Pendiente | B27: 12 | C27: Amasadora de espiral, 25 kg | F27: Amasado y batido | G27: Equipamiento de obrador | H27: Crítico | I27: 5200 | J27: sin IVA | K27: =$C$7 -> 0.21 | L27: =IFERROR(IF($I27="","",IF($J27=$E$62,$I27/(1+$K27),$I27)),"") -> 5200 | M27: =IF($L27="","",$L27*(1-$C$8)) -> 3900 | N27: =IF($L27="","",$L27*(1+$C$8)) -> 6500 | O27: 5200 | P27: =IFERROR(IF(OR($O27="",$L27=""),"",$O27/$L27-1),"") -> 0 | Q27: Pendiente: pide tres presupuestos | R27: 6 | S27: =IFERROR(IF(OR($R27="",$C$11="",$C$12=""),"",$C$11-$R27-$C$12),"") -> 12 | T27: =IF($H27=$C$61,$R27,"") -> 6 | U27: =IF($S27="","",IF($S27<0,1,0)) -> 0 | V27: supuesto | W27: PS-75 da 4.000-8.000 € para «amasadora industrial», pero es un rango sin marca ni modelo: se usa como orden de magnitud, no como precio.
A28: Pendiente | B28: 13 | C28: Cámara frigorífica modular de conservación (8 m³) | F28: Frío positivo | G28: Equipamiento de obrador | H28: Crítico | I28: 4800 | J28: sin IVA | K28: =$C$7 -> 0.21 | L28: =IFERROR(IF($I28="","",IF($J28=$E$62,$I28/(1+$K28),$I28)),"") -> 4800 | M28: =IF($L28="","",$L28*(1-$C$8)) -> 3600 | N28: =IF($L28="","",$L28*(1+$C$8)) -> 6000 | O28: 4800 | P28: =IFERROR(IF(OR($O28="",$L28=""),"",$O28/$L28-1),"") -> 0 | Q28: Pendiente: pide tres presupuestos | R28: 7 | S28: =IFERROR(IF(OR($R28="",$C$11="",$C$12=""),"",$C$11-$R28-$C$12),"") -> 11 | T28: =IF($H28=$C$61,$R28,"") -> 7 | U28: =IF($S28="","",IF($S28<0,1,0)) -> 0 | V28: supuesto | W28: Es la que sostiene los 4 °C de la fila 9 del art. 4.1 (PA-12).
A29: Pendiente | B29: 14 | C29: Armario de congelación -18 °C | F29: Frío negativo | G29: Equipamiento de obrador | H29: Crítico | I29: 1900 | J29: sin IVA | K29: =$C$7 -> 0.21 | L29: =IFERROR(IF($I29="","",IF($J29=$E$62,$I29/(1+$K29),$I29)),"") -> 1900 | M29: =IF($L29="","",$L29*(1-$C$8)) -> 1425 | N29: =IF($L29="","",$L29*(1+$C$8)) -> 2375 | O29: 1900 | P29: =IFERROR(IF(OR($O29="",$L29=""),"",$O29/$L29-1),"") -> 0 | Q29: Pendiente: pide tres presupuestos | R29: 4 | S29: =IFERROR(IF(OR($R29="",$C$11="",$C$12=""),"",$C$11-$R29-$C$12),"") -> 14 | T29: =IF($H29=$C$61,$R29,"") -> 4 | U29: =IF($S29="","",IF($S29<0,1,0)) -> 0 | V29: supuesto | W29: CONSERVA congelado; no congela. No sustituye al abatidor (art. 5 del RD 1021/2022, PA-13).
A30: Pendiente | B30: 15 | C30: Mesa de trabajo refrigerada con cajones (2 m) | F30: Frío positivo | G30: Equipamiento de obrador | H30: Crítico | I30: 2400 | J30: sin IVA | K30: =$C$7 -> 0.21 | L30: =IFERROR(IF($I30="","",IF($J30=$E$62,$I30/(1+$K30),$I30)),"") -> 2400 | M30: =IF($L30="","",$L30*(1-$C$8)) -> 1800 | N30: =IF($L30="","",$L30*(1+$C$8)) -> 3000 | O30: 2400 | P30: =IFERROR(IF(OR($O30="",$L30=""),"",$O30/$L30-1),"") -> 0 | Q30: Pendiente: pide tres presupuestos | R30: 5 | S30: =IFERROR(IF(OR($R30="",$C$11="",$C$12=""),"",$C$11-$R30-$C$12),"") -> 13 | T30: =IF($H30=$C$61,$R30,"") -> 5 | U30: =IF($S30="","",IF($S30<0,1,0)) -> 0 | V30: supuesto
A31: Pendiente | B31: 16 | C31: Mesas de acero inoxidable y estanterías (lote) | F31: Mobiliario de obrador | G31: Equipamiento de obrador | H31: Crítico | I31: 2800 | J31: sin IVA | K31: =$C$7 -> 0.21 | L31: =IFERROR(IF($I31="","",IF($J31=$E$62,$I31/(1+$K31),$I31)),"") -> 2800 | M31: =IF($L31="","",$L31*(1-$C$8)) -> 2100 | N31: =IF($L31="","",$L31*(1+$C$8)) -> 3500 | O31: 2800 | P31: =IFERROR(IF(OR($O31="",$L31=""),"",$O31/$L31-1),"") -> 0 | Q31: Pendiente: pide tres presupuestos | R31: 4 | S31: =IFERROR(IF(OR($R31="",$C$11="",$C$12=""),"",$C$11-$R31-$C$12),"") -> 14 | T31: =IF($H31=$C$61,$R31,"") -> 4 | U31: =IF($S31="","",IF($S31<0,1,0)) -> 0 | V31: supuesto
A32: Pendiente | B32: 17 | C32: Fregadero doble y lavamanos no manual de pedal | F32: Instalaciones | G32: Equipamiento de obrador | H32: Crítico | I32: 1400 | J32: sin IVA | K32: =$C$7 -> 0.21 | L32: =IFERROR(IF($I32="","",IF($J32=$E$62,$I32/(1+$K32),$I32)),"") -> 1400 | M32: =IF($L32="","",$L32*(1-$C$8)) -> 1050 | N32: =IF($L32="","",$L32*(1+$C$8)) -> 1750 | O32: 1400 | P32: =IFERROR(IF(OR($O32="",$L32=""),"",$O32/$L32-1),"") -> 0 | Q32: Pendiente: pide tres presupuestos | R32: 3 | S32: =IFERROR(IF(OR($R32="",$C$11="",$C$12=""),"",$C$11-$R32-$C$12),"") -> 15 | T32: =IF($H32=$C$61,$R32,"") -> 3 | U32: =IF($S32="","",IF($S32<0,1,0)) -> 0 | V32: PS-86e + supuesto | W32: PS-86e: lavamanos NO manual por zona. No es un extra, es un requisito.
A33: Pendiente | B33: 18 | C33: Mobiliario de despacho (mostrador, estanterías, rótulo interior) | F33: Tienda y vitrina | G33: Tienda y vitrina | H33: Crítico | I33: 7500 | J33: sin IVA | K33: =$C$7 -> 0.21 | L33: =IFERROR(IF($I33="","",IF($J33=$E$62,$I33/(1+$K33),$I33)),"") -> 7500 | M33: =IF($L33="","",$L33*(1-$C$8)) -> 5625 | N33: =IF($L33="","",$L33*(1+$C$8)) -> 9375 | O33: 7500 | P33: =IFERROR(IF(OR($O33="",$L33=""),"",$O33/$L33-1),"") -> 0 | Q33: Pendiente: pide tres presupuestos | R33: 8 | S33: =IFERROR(IF(OR($R33="",$C$11="",$C$12=""),"",$C$11-$R33-$C$12),"") -> 10 | T33: =IF($H33=$C$61,$R33,"") -> 8 | U33: =IF($S33="","",IF($S33<0,1,0)) -> 0 | V33: supuesto
A34: Pendiente | B34: 19 | C34: TPV con software adaptado a Verifactu | F34: Tienda y vitrina | G34: Tienda y vitrina | H34: Crítico | I34: 1300 | J34: sin IVA | K34: =$C$7 -> 0.21 | L34: =IFERROR(IF($I34="","",IF($J34=$E$62,$I34/(1+$K34),$I34)),"") -> 1300 | M34: =IF($L34="","",$L34*(1-$C$8)) -> 975 | N34: =IF($L34="","",$L34*(1+$C$8)) -> 1625 | O34: 1300 | P34: =IFERROR(IF(OR($O34="",$L34=""),"",$O34/$L34-1),"") -> 0 | Q34: Pendiente: pide tres presupuestos | R34: 3 | S34: =IFERROR(IF(OR($R34="",$C$11="",$C$12=""),"",$C$11-$R34-$C$12),"") -> 15 | T34: =IF($H34=$C$61,$R34,"") -> 3 | U34: =IF($S34="","",IF($S34<0,1,0)) -> 0 | V34: PA-37 + supuesto | W34: El software que compres HOY ya tiene que estar adaptado: la obligación del fabricante es anterior a la tuya (PA-37). Y el TPV es el que separa el 10 %, el 4 % y el 21 % de la venta para llevar (PA-36d).
A35: Pendiente | B35: 20 | C35: Vitrina o armario expositor de temperatura ambiente | F35: Tienda y vitrina | G35: Tienda y vitrina | H35: Crítico | I35: 1600 | J35: sin IVA | K35: =$C$7 -> 0.21 | L35: =IFERROR(IF($I35="","",IF($J35=$E$62,$I35/(1+$K35),$I35)),"") -> 1600 | M35: =IF($L35="","",$L35*(1-$C$8)) -> 1200 | N35: =IF($L35="","",$L35*(1+$C$8)) -> 2000 | O35: 1600 | P35: =IFERROR(IF(OR($O35="",$L35=""),"",$O35/$L35-1),"") -> 0 | Q35: Pendiente: pide tres presupuestos | R35: 6 | S35: =IFERROR(IF(OR($R35="",$C$11="",$C$12=""),"",$C$11-$R35-$C$12),"") -> 12 | T35: =IF($H35=$C$61,$R35,"") -> 6 | U35: =IF($S35="","",IF($S35<0,1,0)) -> 0 | V35: supuesto | W35: Para lo estable a temperatura ambiente: palmeras, Sacher, huesos de santo, turrón y panes. Cuántos metros necesitas de este mueble y cuántos del refrigerado lo decide la hoja de huevo y temperatura del libro 4, no el gusto.
A36: Pendiente | B36: 21 | C36: Envasadora, selladora y utillaje de obrador (lote) | F36: Mobiliario de obrador | G36: Equipamiento de obrador | H36: Crítico | I36: 3200 | J36: sin IVA | K36: =$C$7 -> 0.21 | L36: =IFERROR(IF($I36="","",IF($J36=$E$62,$I36/(1+$K36),$I36)),"") -> 3200 | M36: =IF($L36="","",$L36*(1-$C$8)) -> 2400 | N36: =IF($L36="","",$L36*(1+$C$8)) -> 4000 | O36: 3200 | P36: =IFERROR(IF(OR($O36="",$L36=""),"",$O36/$L36-1),"") -> 0 | Q36: Pendiente: pide tres presupuestos | R36: 4 | S36: =IFERROR(IF(OR($R36="",$C$11="",$C$12=""),"",$C$11-$R36-$C$12),"") -> 14 | T36: =IF($H36=$C$61,$R36,"") -> 4 | U36: =IF($S36="","",IF($S36<0,1,0)) -> 0 | V36: supuesto
A37: Pendiente | B37: 22 | C37: Termómetros sonda, básculas y registradores de temperatura | F37: Control | G37: Equipamiento de obrador | H37: Crítico | I37: 900 | J37: sin IVA | K37: =$C$7 -> 0.21 | L37: =IFERROR(IF($I37="","",IF($J37=$E$62,$I37/(1+$K37),$I37)),"") -> 900 | M37: =IF($L37="","",$L37*(1-$C$8)) -> 675 | N37: =IF($L37="","",$L37*(1+$C$8)) -> 1125 | O37: 900 | P37: =IFERROR(IF(OR($O37="",$L37=""),"",$O37/$L37-1),"") -> 0 | Q37: Pendiente: pide tres presupuestos | R37: 2 | S37: =IFERROR(IF(OR($R37="",$C$11="",$C$12=""),"",$C$11-$R37-$C$12),"") -> 16 | T37: =IF($H37=$C$61,$R37,"") -> 2 | U37: =IF($S37="","",IF($S37<0,1,0)) -> 0 | V37: supuesto | W37: Sin sonda no puedes demostrar los 70 °C/2 s del art. 9.1.a) y la vía se te cae al ovoproducto. Es la compra más barata con más consecuencias.
A39: Resumen de esta hoja
A40: Líneas del checklist | I40: =COUNTIF($C$16:$C$37,"<>") -> 22 | K40: Las 22 líneas de la dotación tipo de una pastelería con obrador.
A41: Total de referencia sin IVA, sólo líneas críticas (€) | I41: =SUMPRODUCT(--($H$16:$H$37=$C$61),$L$16:$L$37) -> 66980.338 | K41: Lo que cuesta lo que no puedes dejar de comprar, a precio de referencia y en base imponible.
A42: Total de referencia sin IVA, todas las líneas (€) | I42: =SUM($L$16:$L$37) -> 86500.738 | K42: Con la atemperadora de chocolate y el horno de pisos dentro, que son opcionales según el concepto.
A43: Total real negociado sin IVA, sólo líneas críticas (€) | I43: =SUMPRODUCT(--($H$16:$H$37=$C$61),$O$16:$O$37) -> 66980.34 | K43: Lo mismo con TUS precios: es el número que se lleva al libro 2.
...

Sheet Variante del Formato
A1: Qué Equipo Pide Cada Variante de Formato
A2: AI Chef Pro · aichef.pro — Cómo Montar una Pastelería
A3: La dotación completa es la del local con venta. Las otras seis variantes se leen como desviaciones sobre ella: qué línea te sobra y qué línea te falta.
A5: Elige la variante que vas a montar
A6: Variante que vas a montar | C6: Local con venta (caso base) | E6: Desplegable contra la lista de más abajo. Viene con el caso base porque es el de «La Clara»; cámbialo por el tuyo.
A7: Líneas de equipamiento que necesitas | C7: =IFERROR(INDEX($E$38:$K$38,MATCH($C$6,$E$15:$K$15,0)),"") -> 19 | E7: Sólo las marcadas «Sí». Las «Depende» no se cuentan: son las que tienes que decidir tú.
A8: Inversión de referencia de esa variante (€, sin IVA) | C8: =IFERROR(INDEX($E$39:$K$39,MATCH($C$6,$E$15:$K$15,0)),"") -> 66980.338 | E8: Suma del precio de referencia sin IVA de las líneas marcadas «Sí». No incluye obra, licencias ni fondo de maniobra: eso es el libro 2.
A9: Inversión de referencia del caso base (€, sin IVA) | C9: =$G$39 -> 66980.338 | E9: El local con venta, que es el caso de «La Clara».
A10: Diferencia contra el caso base (€) | C10: =IFERROR(IF($C$8="","",$C$8-$C$9),"") -> 0 | E10: Negativo = tu variante necesita menos equipo que el caso base.
A11: Líneas del caso base que a ti te sobran | C11: =SUMPRODUCT(--($L$16:$L$37<>$C$43),--($G$16:$G$37=$C$43)) -> 0 | E11: Están en la dotación completa y tu formato no las pide.
A12: Líneas que te faltan respecto del caso base | C12: =SUMPRODUCT(--($L$16:$L$37=$C$43),--($G$16:$G$37<>$C$43)) -> 0 | E12: Las pide tu formato y no están en el caso base.
A14: Qué pide cada variante, línea a línea
A15: Nº | B15: Partida | C15: Precio de referencia sin IVA (€) | D15: Prioridad | E15: Obrador en casa | F15: Obrador a puerta cerrada | G15: Local con venta (caso base) | H15: Cafetería-pastelería | I15: Punto caliente | J15: Obrador B2B para hostelería | K15: Sin salida de humos | L15: ¿La necesitas tú? | M15: Por qué
A16: 1 | B16: Horno de convección, 6 bandejas | C16: ='Equipamiento'!$L$16 -> 2772 | D16: ='Equipamiento'!$H$16 -> Crítico | E16: No | F16: Sí | G16: Sí | H16: Sí | I16: Sí | J16: Sí | K16: Sí | L16: =IFERROR(INDEX($E16:$K16,MATCH($C$6,$E$15:$K$15,0)),"") -> Sí | M16: Precio publicado CON IVA en la ficha del distribuidor.
A17: 2 | B17: Horno de convección, 4 bandejas | C17: ='Equipamiento'!$L$17 -> 2077.1983 | D17: ='Equipamiento'!$H$17 -> Crítico | E17: No | F17: Depende | G17: Sí | H17: Sí | I17: Depende | J17: Sí | K17: Sí | L17: =IFERROR(INDEX($E17:$K17,MATCH($C$6,$E$15:$K$15,0)),"") -> Sí | M17: Segundo horno: sin él no hay dos cocciones a distinta temperatura a la vez.
A18: 3 | B18: Vitrina expositora pastelera refrigerada curva | C18: ='Equipamiento'!$L$18 -> 2284.1 | D18: ='Equipamiento'!$H$18 -> Crítico | E18: No | F18: No | G18: Sí | H18: Sí | I18: Sí | J18: No | K18: Sí | L18: =IFERROR(INDEX($E18:$K18,MATCH($C$6,$E$15:$K$15,0)),"") -> Sí | M18: 1505x900x1305 mm, 452 L, 0,93 m² de exposición, R-290. El precio lleva un descuento de campaña del 30 % sobre un PVP de 3.263,00 €: es un precio FECHADO el 10-09-2026 y puede caducar. Si lo reutilizas, vuelve a mirarlo (D17). Una sola vitrina, contada una sola vez.
A19: 4 | B19: Puertas correderas traseras para la vitrina | C19: ='Equipamiento'!$L$19 -> 120.4 | D19: ='Equipamiento'!$H$19 -> Opcional | E19: No | F19: No | G19: Depende | H19: Depende | I19: Depende | J19: No | K19: Depende | L19: =IFERROR(INDEX($E19:$K19,MATCH($C$6,$E$15:$K$15,0)),"") -> Depende | M19: Accesorio: no entra en el subtotal comparable de la dotación tipo.
A20: 5 | B20: Abatidor de temperatura, 4 bandejas | C20: ='Equipamiento'!$L$20 -> 10037 | D20: ='Equipamiento'!$H$20 -> Crítico | E20: No | F20: Sí | G20: Sí | H20: Sí | I20: No | J20: Sí | K20: Sí | L20: =IFERROR(INDEX($E20:$K20,MATCH($C$6,$E$15:$K$15,0)),"") -> Sí | M20: La compra más cara y la que más se discute (decisión 2 del bonus 2). Ciclos de +85 °C a -40 °C. Un arcón doméstico NO vale como abatidor: el art. 5 del RD 1021/2022 exige potencia suficiente para llegar a -18 °C en el centro con un descenso ininterrumpido (PA-13).
A21: 6 | B21: Laminadora automática de masa, hasta 40 cm | C21: ='Equipamiento'!$L$21 -> 1215 | D21: ='Equipamiento'!$H$21 -> Crítico | E21: No | F21: Sí | G21: Sí | H21: Sí | I21: No | J21: Sí | K21: Sí | L21: =IFERROR(INDEX($E21:$K21,MATCH($C$6,$E$15:$K$15,0)),"") -> Sí | M21: 1.215,00 € sin IVA / 1.470,15 € con IVA, según la propia ficha.
A22: 7 | B22: Batidora planetaria, 20 L | C22: ='Equipamiento'!$L$22 -> 595.04 | D22: ='Equipamiento'!$H$22 -> Crítico | E22: Depende | F22: Sí | G22: Sí | H22: Sí | I22: No | J22: Sí | K22: Sí | L22: =IFERROR(INDEX($E22:$K22,MATCH($C$6,$E$15:$K$15,0)),"") -> Sí | M22: 900 W, 95-392 rpm, temporizador 0-99 min. La ficha NO declara si el precio lleva IVA: se trata como base imponible y se marca. Es exactamente el caso que obliga a tener la columna.
A23: 8 | B23: Atemperadora de chocolate, 12 kg | C23: ='Equipamiento'!$L$23 -> 7400 | D23: ='Equipamiento'!$H$23 -> Opcional | E23: No | F23: Depende | G23: Depende | H23: Depende | I23: No | J23: Depende | K23: Depende | L23: =IFERROR(INDEX($E23:$K23,MATCH($C$6,$E$15:$K$15,0)),"") -> Depende | M23: OPCIONAL según el concepto: sólo si abres línea de bombonería o chocolatería. Por eso queda FUERA del subtotal comparable de la dotación tipo (D17): con ella dentro, un solo equipo era el 25 % del subtotal.
A24: 9 | B24: Horno de pisos modular (deck) | C24: ='Equipamiento'!$L$24 -> 12000 | D24: ='Equipamiento'!$H$24 -> Opcional | E24: No | F24: Depende | G24: Depende | H24: Depende | I24: No | J24: Sí | K24: Depende | L24: =IFERROR(INDEX($E24:$K24,MATCH($C$6,$E$15:$K$15,0)),"") -> Depende | M24: Salva vende por distribuidor y presupuesto: no hay precio publicado. Bongard, Wiesheu, Miwe y Sveba Dahlen, igual. El valor por defecto es un SUPUESTO para que la celda no quede vacía: pide tres presupuestos.
A25: 10 | B25: Cámara de fermentación controlada (roll-in) | C25: ='Equipamiento'!$L$25 -> 8500 | D25: ='Equipamiento'!$H$25 -> Crítico | E25: No | F25: Sí | G25: Sí | H25: Sí | I25: No | J25: Sí | K25: Sí | L25: =IFERROR(INDEX($E25:$K25,MATCH($C$6,$E$15:$K$15,0)),"") -> Sí | M25: PS-83 da un RANGO de categoría (hasta 19.438 € en la gama alta), no una ficha de producto: no es un precio. El valor por defecto es supuesto. Es lo que permite que la bollería esté horneada a las 7:00 sin entrar a las 3.
A26: 11 | B26: Conducto de extracción de humos en acero inoxidable | C26: ='Equipamiento'!$L$26 -> 6500 | D26: ='Equipamiento'!$H$26 -> Crítico | E26: No | F26: Sí | G26: Sí | H26: Sí | I26: Depende | J26: Sí | K26: No | L26: =IFERROR(INDEX($E26:$K26,MATCH($C$6,$E$15:$K$15,0)),"") -> Sí | M26: PS-84 dice «puede superar los 6.000 €»: es una frase, no un presupuesto. La partida que más locales tumba, y la que hay que resolver ANTES de firmar (cap. 06). El aire de la campana es categoría AE4 del RITE y no puede compartir conducto con el del despacho (PA-07b).
A27: 12 | B27: Amasadora de espiral, 25 kg | C27: ='Equipamiento'!$L$27 -> 5200 | D27: ='Equipamiento'!$H$27 -> Crítico | E27: No | F27: Sí | G27: Sí | H27: Sí | I27: No | J27: Sí | K27: Sí | L27: =IFERROR(INDEX($E27:$K27,MATCH($C$6,$E$15:$K$15,0)),"") -> Sí | M27: PS-75 da 4.000-8.000 € para «amasadora industrial», pero es un rango sin marca ni modelo: se usa como orden de magnitud, no como precio.
A28: 13 | B28: Cámara frigorífica modular de conservación (8 m³) | C28: ='Equipamiento'!$L$28 -> 4800 | D28: ='Equipamiento'!$H$28 -> Crítico | E28: No | F28: Sí | G28: Sí | H28: Sí | I28: Depende | J28: Sí | K28: Sí | L28: =IFERROR(INDEX($E28:$K28,MATCH($C$6,$E$15:$K$15,0)),"") -> Sí | M28: Es la que sostiene los 4 °C de la fila 9 del art. 4.1 (PA-12).
A29: 14 | B29: Armario de congelación -18 °C | C29: ='Equipamiento'!$L$29 -> 1900 | D29: ='Equipamiento'!$H$29 -> Crítico | E29: Depende | F29: Sí | G29: Sí | H29: Sí | I29: Sí | J29: Sí | K29: Sí | L29: =IFERROR(INDEX($E29:$K29,MATCH($C$6,$E$15:$K$15,0)),"") -> Sí | M29: CONSERVA congelado; no congela. No sustituye al abatidor (art. 5 del RD 1021/2022, PA-13).
A30: 15 | B30: Mesa de trabajo refrigerada con cajones (2 m) | C30: ='Equipamiento'!$L$30 -> 2400 | D30: ='Equipamiento'!$H$30 -> Crítico | E30: No | F30: Sí | G30: Sí | H30: Sí | I30: No | J30: Sí | K30: Sí | L30: =IFERROR(INDEX($E30:$K30,MATCH($C$6,$E$15:$K$15,0)),"") -> Sí
A31: 16 | B31: Mesas de acero inoxidable y estanterías (lote) | C31: ='Equipamiento'!$L$31 -> 2800 | D31: ='Equipamiento'!$H$31 -> Crítico | E31: Depende | F31: Sí | G31: Sí | H31: Sí | I31: Sí | J31: Sí | K31: Sí | L31: =IFERROR(INDEX($E31:$K31,MATCH($C$6,$E$15:$K$15,0)),"") -> Sí
A32: 17 | B32: Fregadero doble y lavamanos no manual de pedal | C32: ='Equipamiento'!$L$32 -> 1400 | D32: ='Equipamiento'!$H$32 -> Crítico | E32: Depende | F32: Sí | G32: Sí | H32: Sí | I32: Sí | J32: Sí | K32: Sí | L32: =IFERROR(INDEX($E32:$K32,MATCH($C$6,$E$15:$K$15,0)),"") -> Sí | M32: PS-86e: lavamanos NO manual por zona. No es un extra, es un requisito.
A33: 18 | B33: Mobiliario de despacho (mostrador, estanterías, rótulo interior) | C33: ='Equipamiento'!$L$33 -> 7500 | D33: ='Equipamiento'!$H$33 -> Crítico | E33: No | F33: No | G33: Sí | H33: Sí | I33: Sí | J33: No | K33: Sí | L33: =IFERROR(INDEX($E33:$K33,MATCH($C$6,$E$15:$K$15,0)),"") -> Sí
A34: 19 | B34: TPV con software adaptado a Verifactu | C34: ='Equipamiento'!$L$34 -> 1300 | D34: ='Equipamiento'!$H$34 -> Crítico | E34: Sí | F34: Sí | G34: Sí | H34: Sí | I34: Sí | J34: Sí | K34: Sí | L34: =IFERROR(INDEX($E34:$K34,MATCH($C$6,$E$15:$K$15,0)),"") -> Sí | M34: El software que compres HOY ya tiene que estar adaptado: la obligación del fabricante es anterior a la tuya (PA-37). Y el TPV es el que separa el 10 %, el 4 % y el 21 % de la venta para llevar (PA-36d).
A35: 20 | B35: Vitrina o armario expositor de temperatura ambiente | C35: ='Equipamiento'!$L$35 -> 1600 | D35: ='Equipamiento'!$H$35 -> Crítico | E35: No | F35: No | G35: Sí | H35: Sí | I35: Sí | J35: No | K35: Sí | L35: =IFERROR(INDEX($E35:$K35,MATCH($C$6,$E$15:$K$15,0)),"") -> Sí | M35: Para lo estable a temperatura ambiente: palmeras, Sacher, huesos de santo, turrón y panes. Cuántos metros necesitas de este mueble y cuántos del refrigerado lo decide la hoja de huevo y temperatura del libro 4, no el gusto.
A36: 21 | B36: Envasadora, selladora y utillaje de obrador (lote) | C36: ='Equipamiento'!$L$36 -> 3200 | D36: ='Equipamiento'!$H$36 -> Crítico | E36: Depende | F36: Sí | G36: Sí | H36: Sí | I36: Depende | J36: Sí | K36: Sí | L36: =IFERROR(INDEX($E36:$K36,MATCH($C$6,$E$15:$K$15,0)),"") -> Sí
A37: 22 | B37: Termómetros sonda, básculas y registradores de temperatura | C37: ='Equipamiento'!$L$37 -> 900 | D37: ='Equipamiento'!$H$37 -> Crítico | E37: Sí | F37: Sí | G37: Sí | H37: Sí | I37: Sí | J37: Sí | K37: Sí | L37: =IFERROR(INDEX($E37:$K37,MATCH($C$6,$E$15:$K$15,0)),"") -> Sí | M37: Sin sonda no puedes demostrar los 70 °C/2 s del art. 9.1.a) y la vía se te cae al ovoproducto. Es la compra más barata con más consecuencias.
A38: Líneas marcadas «Sí» | E38: =SUMPRODUCT(--($E$16:$E$37=$C$43)) -> 2 | F38: =SUMPRODUCT(--($F$16:$F$37=$C$43)) -> 15 | G38: =SUMPRODUCT(--($G$16:$G$37=$C$43)) -> 19 | H38: =SUMPRODUCT(--($H$16:$H$37=$C$43)) -> 19 | I38: =SUMPRODUCT(--($I$16:$I$37=$C$43)) -> 9 | J38: =SUMPRODUCT(--($J$16:$J$37=$C$43)) -> 17 | K38: =SUMPRODUCT(--($K$16:$K$37=$C$43)) -> 18
A39: Inversión de referencia sin IVA (€) | E39: =SUMPRODUCT(--($E$16:$E$37=$C$43),$C$16:$C$37) -> 2200 | F39: =SUMPRODUCT(--($F$16:$F$37=$C$43),$C$16:$C$37) -> 53519.04 | G39: =SUMPRODUCT(--($G$16:$G$37=$C$43),$C$16:$C$37) -> 66980.338 | H39: =SUMPRODUCT(--($H$16:$H$37=$C$43),$C$16:$C$37) -> 66980.338 | I39: =SUMPRODUCT(--($I$16:$I$37=$C$43),$C$16:$C$37) -> 22456.1 | J39: =SUMPRODUCT(--($J$16:$J$37=$C$43),$C$16:$C$37) -> 67596.238 | K39: =SUMPRODUCT(--($K$16:$K$37=$C$43),$C$16:$C$37) -> 60480.338
A41: Las siete variantes (lista del desplegable)
A42: Nº | B42: Variante | C42: Vocabulario | D42: Id | E42: Qué cambia respecto del caso base
A43: 1 | B43: Obrador en casa | C43: Sí | D43: PS-01 | E43: Venta directa al consumidor final desde vivienda particular (art. 13 del RD 1021/2022). Inversión publicada: 3.000-5.000 € mínimo viable.
...

Sheet Proveedores
A1: Proveedores de Materia Prima
A2: AI Chef Pro · aichef.pro — Cómo Montar una Pastelería
A3: Los nueve con URL comprobada el 10-09-2026. El research recogió otros 22 sin verificar y no se publican: un directorio con un enlace roto vale menos que uno corto.
A5: Los nueve proveedores verificados
A6: Nº | B6: Proveedor | C6: Qué te vende | D6: URL | E6: Id | F6: ¿Trabajas con él? | G6: Contacto comercial | H6: Pedido mínimo (€) | I6: Plazo (días) | J6: Condiciones de pago | K6: Notas de la negociación | L6: Por qué está en la lista
A7: 1 | B7: Sosa Ingredients | C7: Ingredientes premium y técnicos | D7: https://www.sosa.cat/ | E7: PS-87 | F7: No | G7: Pendiente: pide el alta de cliente | H7: 300 | I7: 7 | J7: Pendiente de negociar | K7: Pendiente de la primera visita comercial | L7: Fundada en Cataluña en 1967, presente en más de 80 países.
A8: 2 | B8: Puratos | C8: Masas madre, mejorantes, mixes, rellenos y chocolate | D8: https://www.puratos.com/products | E8: PS-88 | F8: No | G8: Pendiente: pide el alta de cliente | H8: 300 | I8: 7 | J8: Pendiente de negociar | K8: Pendiente de la primera visita comercial | L8: Fabricante o distribuidor con web propia comprobada el 10-09-2026.
A9: 3 | B9: Barry Callebaut | C9: Chocolate y coberturas | D9: https://www.barry-callebaut.com/ | E9: PS-89 | F9: No | G9: Pendiente: pide el alta de cliente | H9: 300 | I9: 7 | J9: Pendiente de negociar | K9: Pendiente de la primera visita comercial | L9: Marcas Callebaut, Cacao Barry y Chocovic.
A10: 4 | B10: Valrhona | C10: Chocolate premium y formación | D10: https://www.valrhona.com/ | E10: PS-90 | F10: No | G10: Pendiente: pide el alta de cliente | H10: 300 | I10: 7 | J10: Pendiente de negociar | K10: Pendiente de la primera visita comercial | L10: Distribuye la gama Sosa como marca socia.
A11: 5 | B11: Debic (FrieslandCampina) | C11: Mantequilla y nata profesional | D11: https://www.debic.com/ | E11: PS-91 | F11: No | G11: Pendiente: pide el alta de cliente | H11: 300 | I11: 7 | J11: Pendiente de negociar | K11: Pendiente de la primera visita comercial | L11: Mantequillas de punto de fusión fijo para hojaldre y bollería.
A12: 6 | B12: Elle & Vire Professionnel | C12: Mantequilla de laminado | D12: https://www.elle-et-vire.com/ | E12: PS-92 | F12: No | G12: Pendiente: pide el alta de cliente | H12: 300 | I12: 7 | J12: Pendiente de negociar | K12: Pendiente de la primera visita comercial | L12: Mantequilla seca de 84 % de materia grasa para hojaldre.
A13: 7 | B13: Ylla 1878 | C13: Harinas profesionales | D13: https://www.ylla1878.com/es/harinas-profesionales/ | E13: PS-93 | F13: No | G13: Pendiente: pide el alta de cliente | H13: 300 | I13: 7 | J13: Pendiente de negociar | K13: Pendiente de la primera visita comercial | L13: Panadería, pastelería, bollería, churrería y pizzería.
A14: 8 | B14: Farinera Coromina | C14: Harinas especiales | D14: https://www.farineracoromina.com/ | E14: PS-94 | F14: No | G14: Pendiente: pide el alta de cliente | H14: 300 | I14: 7 | J14: Pendiente de negociar | K14: Pendiente de la primera visita comercial | L14: Fundada en 1897 en Girona. Península, Baleares, Canarias y sur de Francia.
A15: 9 | B15: Cospan | C15: Distribución de materias primas | D15: https://cospan.es/ | E15: PS-95 | F15: No | G15: Pendiente: pide el alta de cliente | H15: 300 | I15: 7 | J15: Pendiente de negociar | K15: Pendiente de la primera visita comercial | L15: Fabricante o distribuidor con web propia comprobada el 10-09-2026.
A16: Proveedores publicados en esta hoja | F16: =COUNTIF($B$7:$B$15,"<>") -> 9 | G16: Nueve verificados. Los 22 sin verificar del research no entran.
A17: Proveedores con los que ya trabajas | F17: =SUMPRODUCT(--($F$7:$F$15=$B$23)) -> 0 | G17: Empieza por dos o tres: abrir ficha en nueve proveedores a la vez es una semana de papeleo y ningún descuento.
A18: Pedido mínimo acumulado si pides a todos a la vez (€) | F18: =SUM($H$7:$H$15) -> 2700 | G18: Es dinero parado en el almacén el día que menos caja tienes. Los pedidos mínimos son SUPUESTOS: te los confirma cada comercial.
A19: Plazo medio de entrega comprometido (días) | F19: =IFERROR(AVERAGE($I$7:$I$15),"") -> 7 | G19: Con qué antelación tienes que pedir la materia prima de cada pico. La antelación de compra por campaña la calcula el «estacionalidad-y-picos.xlsx» (libro 3).
A21: Listas (origen de los desplegables)
A22: Nº | B22: ¿Trabajas con él?
A23: 1 | B23: Sí
A24: 2 | B24: No
A26: Nueve proveedores con URL comprobada el 10-09-2026. El research recogió otros 22 sin verificar y NO se publican: un directorio con un enlace roto vale menos que uno corto. Directorio del grupo: hosply.pro (TLS comprobado el 10-09-2026).
A27: Directorio de proveedores del grupo (certificado comprobado el 10-09-2026): https://hosply.pro/?utm_source=guia-pasteleria-obrador&utm_medium=producto&utm_campaign=cap11-proveedores
A28: Los pedidos mínimos, los plazos y las condiciones de pago que vienen rellenos son SUPUESTOS para que la hoja funcione desde el primer minuto: no son las condiciones de estas empresas. Cada una te dará las suyas, y cambian con el volumen y con la provincia.
A30: Diseñado por John Guerrero — chef y consultor gastronómico desde 2010, en cocina desde los 17 años.
A31: Versión 1.0 · septiembre 2026 · aichef.pro/guia-pasteleria-obrador · info@aichef.pro

Sheet Contador
A1: Contador del Checklist
A2: AI Chef Pro · aichef.pro — Cómo Montar una Pastelería
A3: Todo lo de esta hoja se lee de «Equipamiento» y de «Proveedores»: aquí no se teclea nada.
A5: Avance del checklist de equipamiento
A6: Concepto | B6: Valor | C6: Nota
A7: Líneas del checklist | B7: =COUNTIF('Equipamiento'!$C$16:$C$37,"<>") -> 22 | C7: La dotación completa de una pastelería con obrador.
A8: Líneas marcadas «N/A» (fuera de tu alcance) | B8: =SUMPRODUCT(--('Equipamiento'!$A$16:$A$37='Equipamiento'!$A$66)) -> 0 | C8: Lo que tu formato no necesita. No cuenta ni a favor ni en contra.
A9: Líneas dentro de tu alcance | B9: =$B$7-$B$8 -> 22 | C9: Es el denominador del avance.
A10: Líneas instaladas | B10: =SUMPRODUCT(--('Equipamiento'!$A$16:$A$37='Equipamiento'!$A$65)) -> 0 | C10: Instalada quiere decir montada, conectada y probada; recibida no es instalada, y esa diferencia son días.
A11: Líneas recibidas | B11: =COUNTIF('Equipamiento'!$A$16:$A$37,"Recibido") -> 0 | C11: Están en el local, en su caja.
A12: Líneas pedidas | B12: =COUNTIF('Equipamiento'!$A$16:$A$37,"Pedido") -> 0 | C12: Pedidas y pagadas o con señal: el plazo ya corre.
A13: Líneas presupuestadas | B13: =COUNTIF('Equipamiento'!$A$16:$A$37,"Presupuestado") -> 0 | C13: Tienes el precio, no has pedido.
A14: Líneas pendientes | B14: =COUNTIF('Equipamiento'!$A$16:$A$37,"Pendiente") -> 22 | C14: Ni siquiera has pedido presupuesto.
A15: Avance del checklist (% instalado) | B15: =IFERROR(IF($B$9=0,"",$B$10/$B$9),"") -> 0 | C15: Sobre lo que está dentro de tu alcance, no sobre las 22 líneas.
A17: Lo crítico, que es lo que decide si abres
A18: Líneas críticas | B18: =SUMPRODUCT(--('Equipamiento'!$H$16:$H$37='Equipamiento'!$C$61)) -> 19 | C18: Sin ellas no se abre. Las opcionales no entran aquí.
A19: Líneas críticas instaladas | B19: =SUMPRODUCT(--('Equipamiento'!$H$16:$H$37='Equipamiento'!$C$61),--('Equipamiento'!$A$16:$A$37='Equipamiento'!$A$65)) -> 0
A20: Avance de lo crítico (%) | B20: =IFERROR(IF($B$18=0,"",$B$19/$B$18),"") -> 0 | C20: Éste es el porcentaje que hay que mirar la semana antes de abrir.
A21: ¿Puedes abrir con lo que está instalado? | B21: =IF($B$18=0,"",IF($B$19=$B$18,"Sí: todo lo crítico está instalado",CONCATENATE("No: faltan ",$B$18-$B$19," líneas críticas"))) -> No: faltan 19 líneas críticas | C21: La licencia y el registro sanitario van por su lado: eso lo contesta el libro 6.
A23: Por bloque de CAPEX
A24: Bloque | B24: Líneas | C24: Referencia sin IVA (€) | D24: Real negociado (€) | E24: Desviación (%) | F24: Nota
A25: Equipamiento de obrador | B25: =SUMPRODUCT(--('Equipamiento'!$G$16:$G$37=$A25)) -> 17 | C25: =SUMPRODUCT(--('Equipamiento'!$G$16:$G$37=$A25),'Equipamiento'!$L$16:$L$37) -> 73696.238 | D25: =SUMPRODUCT(--('Equipamiento'!$G$16:$G$37=$A25),'Equipamiento'!$O$16:$O$37) -> 73696.24 | E25: =IFERROR(IF($C25=0,"",$D25/$C25-1),"") -> 2.2428452e-08 | F25: Es el bloque que el libro 2 lleva a su hoja «CAPEX por Bloque» con este mismo nombre.
A26: Tienda y vitrina | B26: =SUMPRODUCT(--('Equipamiento'!$G$16:$G$37=$A26)) -> 5 | C26: =SUMPRODUCT(--('Equipamiento'!$G$16:$G$37=$A26),'Equipamiento'!$L$16:$L$37) -> 12804.5 | D26: =SUMPRODUCT(--('Equipamiento'!$G$16:$G$37=$A26),'Equipamiento'!$O$16:$O$37) -> 12804.5 | E26: =IFERROR(IF($C26=0,"",$D26/$C26-1),"") -> 0 | F26: Es el bloque que el libro 2 lleva a su hoja «CAPEX por Bloque» con este mismo nombre.
A27: TOTAL | B27: =SUMPRODUCT(--('Equipamiento'!$G$16:$G$37<>"")) -> 22 | C27: =SUMPRODUCT('Equipamiento'!$L$16:$L$37) -> 86500.738 | D27: =SUMPRODUCT('Equipamiento'!$O$16:$O$37) -> 86500.74 | E27: =IFERROR(IF($C$27=0,"",$D$27/$C$27-1),"") -> 1.9108422e-08
A29: Por categoría de equipo
A30: Categoría | B30: Líneas | C30: Referencia sin IVA (€) | D30: Real negociado (€) | E30: Instaladas | F30: Nota
A31: Calor | B31: =SUMPRODUCT(--('Equipamiento'!$F$16:$F$37=$A31)) -> 3 | C31: =SUMPRODUCT(--('Equipamiento'!$F$16:$F$37=$A31),'Equipamiento'!$L$16:$L$37) -> 16849.198 | D31: =SUMPRODUCT(--('Equipamiento'!$F$16:$F$37=$A31),'Equipamiento'!$O$16:$O$37) -> 16849.2 | E31: =SUMPRODUCT(--('Equipamiento'!$F$16:$F$37=$A31),--('Equipamiento'!$A$16:$A$37='Equipamiento'!$A$65)) -> 0
A32: Tienda y vitrina | B32: =SUMPRODUCT(--('Equipamiento'!$F$16:$F$37=$A32)) -> 5 | C32: =SUMPRODUCT(--('Equipamiento'!$F$16:$F$37=$A32),'Equipamiento'!$L$16:$L$37) -> 12804.5 | D32: =SUMPRODUCT(--('Equipamiento'!$F$16:$F$37=$A32),'Equipamiento'!$O$16:$O$37) -> 12804.5 | E32: =SUMPRODUCT(--('Equipamiento'!$F$16:$F$37=$A32),--('Equipamiento'!$A$16:$A$37='Equipamiento'!$A$65)) -> 0
A33: Frío negativo | B33: =SUMPRODUCT(--('Equipamiento'!$F$16:$F$37=$A33)) -> 2 | C33: =SUMPRODUCT(--('Equipamiento'!$F$16:$F$37=$A33),'Equipamiento'!$L$16:$L$37) -> 11937 | D33: =SUMPRODUCT(--('Equipamiento'!$F$16:$F$37=$A33),'Equipamiento'!$O$16:$O$37) -> 11937 | E33: =SUMPRODUCT(--('Equipamiento'!$F$16:$F$37=$A33),--('Equipamiento'!$A$16:$A$37='Equipamiento'!$A$65)) -> 0
A34: Laminación | B34: =SUMPRODUCT(--('Equipamiento'!$F$16:$F$37=$A34)) -> 1 | C34: =SUMPRODUCT(--('Equipamiento'!$F$16:$F$37=$A34),'Equipamiento'!$L$16:$L$37) -> 1215 | D34: =SUMPRODUCT(--('Equipamiento'!$F$16:$F$37=$A34),'Equipamiento'!$O$16:$O$37) -> 1215 | E34: =SUMPRODUCT(--('Equipamiento'!$F$16:$F$37=$A34),--('Equipamiento'!$A$16:$A$37='Equipamiento'!$A$65)) -> 0
A35: Amasado y batido | B35: =SUMPRODUCT(--('Equipamiento'!$F$16:$F$37=$A35)) -> 2 | C35: =SUMPRODUCT(--('Equipamiento'!$F$16:$F$37=$A35),'Equipamiento'!$L$16:$L$37) -> 5795.04 | D35: =SUMPRODUCT(--('Equipamiento'!$F$16:$F$37=$A35),'Equipamiento'!$O$16:$O$37) -> 5795.04 | E35: =SUMPRODUCT(--('Equipamiento'!$F$16:$F$37=$A35),--('Equipamiento'!$A$16:$A$37='Equipamiento'!$A$65)) -> 0
A36: Chocolate | B36: =SUMPRODUCT(--('Equipamiento'!$F$16:$F$37=$A36)) -> 1 | C36: =SUMPRODUCT(--('Equipamiento'!$F$16:$F$37=$A36),'Equipamiento'!$L$16:$L$37) -> 7400 | D36: =SUMPRODUCT(--('Equipamiento'!$F$16:$F$37=$A36),'Equipamiento'!$O$16:$O$37) -> 7400 | E36: =SUMPRODUCT(--('Equipamiento'!$F$16:$F$37=$A36),--('Equipamiento'!$A$16:$A$37='Equipamiento'!$A$65)) -> 0
A37: Frío positivo | B37: =SUMPRODUCT(--('Equipamiento'!$F$16:$F$37=$A37)) -> 3 | C37: =SUMPRODUCT(--('Equipamiento'!$F$16:$F$37=$A37),'Equipamiento'!$L$16:$L$37) -> 15700 | D37: =SUMPRODUCT(--('Equipamiento'!$F$16:$F$37=$A37),'Equipamiento'!$O$16:$O$37) -> 15700 | E37: =SUMPRODUCT(--('Equipamiento'!$F$16:$F$37=$A37),--('Equipamiento'!$A$16:$A$37='Equipamiento'!$A$65)) -> 0
A38: Instalaciones | B38: =SUMPRODUCT(--('Equipamiento'!$F$16:$F$37=$A38)) -> 2 | C38: =SUMPRODUCT(--('Equipamiento'!$F$16:$F$37=$A38),'Equipamiento'!$L$16:$L$37) -> 7900 | D38: =SUMPRODUCT(--('Equipamiento'!$F$16:$F$37=$A38),'Equipamiento'!$O$16:$O$37) -> 7900 | E38: =SUMPRODUCT(--('Equipamiento'!$F$16:$F$37=$A38),--('Equipamiento'!$A$16:$A$37='Equipamiento'!$A$65)) -> 0
A39: Mobiliario de obrador | B39: =SUMPRODUCT(--('Equipamiento'!$F$16:$F$37=$A39)) -> 2 | C39: =SUMPRODUCT(--('Equipamiento'!$F$16:$F$37=$A39),'Equipamiento'!$L$16:$L$37) -> 6000 | D39: =SUMPRODUCT(--('Equipamiento'!$F$16:$F$37=$A39),'Equipamiento'!$O$16:$O$37) -> 6000 | E39: =SUMPRODUCT(--('Equipamiento'!$F$16:$F$37=$A39),--('Equipamiento'!$A$16:$A$37='Equipamiento'!$A$65)) -> 0
A40: Control | B40: =SUMPRODUCT(--('Equipamiento'!$F$16:$F$37=$A40)) -> 1 | C40: =SUMPRODUCT(--('Equipamiento'!$F$16:$F$37=$A40),'Equipamiento'!$L$16:$L$37) -> 900 | D40: =SUMPRODUCT(--('Equipamiento'!$F$16:$F$37=$A40),'Equipamiento'!$O$16:$O$37) -> 900 | E40: =SUMPRODUCT(--('Equipamiento'!$F$16:$F$37=$A40),--('Equipamiento'!$A$16:$A$37='Equipamiento'!$A$65)) -> 0
A42: Proveedores
A43: Proveedores verificados publicados | B43: ='Proveedores'!$F$16 -> 9 | C43: Los nueve con URL comprobada el 10-09-2026.
A44: Proveedores con los que ya trabajas | B44: ='Proveedores'!$F$17 -> 0
A45: Líneas de equipamiento sin proveedor asignado | B45: =SUMPRODUCT(--('Equipamiento'!$Q$16:$Q$37='Equipamiento'!$G$61)) -> 13 | C45: Las que siguen con el texto «Pendiente: pide tres presupuestos». En maquinaria de obrador se vende por presupuesto: mientras no haya nombre, no hay precio.
...
