Workbook

Sheet Instrucciones
A1: Checklist legal, licencias y cronograma de apertura
A2: AI Chef Pro · aichef.pro — Cómo Montar una Pastelería
A3: Para qué sirve: saber qué papel te toca, en qué orden, si te basta la comunicación autonómica y cuándo abres.
A5: Instrucciones de uso
A6: 1. Hoja «Checklist Legal (F1-F6)»: los treinta trámites en el orden en que hay que hacerlos, repartidos en seis fases. Marca la casilla, escribe el coste que te presupuestan y el que acabas pagando, y pon las dos fechas. Cada fase lleva su contador y su porcentaje de avance; abajo está el resumen de todo y la desviación entre lo previsto y lo real.
A7: 2. Hoja «Árbol de Registro Sanitario»: tres preguntas y un veredicto. Es la hoja que corrige el error más caro del sector: una pastelería que vende al consumidor final está EXCLUIDA del registro estatal (RGSEAA) y lo que le toca es una comunicación o declaración responsable a su comunidad autónoma, que además NO habilita para abrir.
A8: 3. Hoja «Suministro a Otros Minoristas»: el árbol del art. 3 del RD 1021/2022, con su puerta de entrada delante. Si no sirves a otros comercios de distinta titularidad, este artículo no te aplica y la hoja te lo dice en la primera línea. Si te aplica, las tres condiciones son ACUMULATIVAS y dentro de «marginal» hay DOS vías alternativas.
A9: 4. Hoja «Ruta Doméstica»: si te planteas empezar desde casa. Los tres límites del art. 13.9 (el tope de kilos, la proporcionalidad con el tamaño y el «se demostrará documentalmente»), la lista blanca del art. 13.8 con sus CINCO letras y las cinco prohibiciones del 13.5 agrupadas por su régimen. Ojo con la letra e): tu comunidad puede haber ampliado la lista, y una ya lo ha hecho.
A10: 5. Hoja «Registro de Formación»: una línea por persona con la fecha, el contenido y la caducidad que TÚ fijas. El «carnet de manipulador» no existe desde 2010: lo que hay que tener es este registro, y la responsabilidad de tenerlo es de la empresa.
A11: 6. Hoja «Cronograma y Ruta Crítica»: doce hitos con su duración y sus dependencias. La hoja calcula cuándo empieza y acaba cada uno, cuánta holgura tiene, cuáles están en la ruta crítica -los que si se retrasan un día retrasan la apertura un día- y en qué mes acabas abriendo. Y te avisa si esa fecha cae dentro de una campaña.
A13: Celdas verdes = campos editables
A15: Lo que conviene saber antes de empezar
... A23: QUÉ HACE ESTE LIBRO Y QUÉ HACE OTRO (para no teclear dos veces)
A24: Producto o libro | B24: Qué aporta | C24: Qué NO hace este libro
A25: pack-appcc (14 €) | B25: Los registros del plan de APPCC ya montados y listos para rellenar. | C25: Aquí sólo hay una FILA de checklist que dice «redacta el plan y designa por su nombre al responsable». El plan en sí es aquel producto.
A26: kit-tareas-pasteleria (12 €) | B26: La matriz de alérgenos de vitrina y el registro de temperaturas de recepción, ya construidos. | C26: Aquí hay una fila que te recuerda publicar la matriz antes de abrir. La guía no rehace ninguna de las dos.
A27: El libro «checklist-equipamiento-y-proveedores» de esta misma guía | B27: El plazo de entrega de cada equipo, que es lo que de verdad mueve la fecha de apertura. | C27: El cronograma de este libro trabaja en MESES y con una duración por hito. Cuando tengas los plazos por escrito, tráelos al hito «Pedido y entrega del equipamiento».
A28: El libro «plan-financiero-3-anos-pasteleria» de esta misma guía | B28: Los euros: qué cuesta cada bloque de inversión y cuándo sale de caja. | C28: Los costes de este checklist son los de los TRÁMITES. La obra, el equipamiento y el fondo de maniobra están allí, y allí es donde se suman.
A30: Cada cuánto se usa este libro
A31: Cadencia: el checklist y el cronograma, UNA VEZ A LA SEMANA desde que decides abrir hasta que abres. Los tres árboles -registro sanitario, suministro a otros minoristas y ruta doméstica-, UNA VEZ AL PRINCIPIO y otra cada vez que cambies de canal: el día que aceptes servir a la cafetería de al lado estarás cambiando de régimen sin darte cuenta. El registro de formación, cada vez que entra alguien y cuando caduca la formación de alguien.
A33: Para editar la estructura o una celda que no esté en verde: Revisar > Desproteger hoja (no tiene contraseña).
A35: Diseñado por John Guerrero — chef y consultor gastronómico desde 2010, en cocina desde los 17 años.
A36: Versión 1.0 · septiembre 2026 · aichef.pro/guia-pasteleria-obrador · info@aichef.pro

Sheet Checklist Legal (F1-F6)
A1: Checklist Legal y de Licencias, en Seis Fases
A2: AI Chef Pro · aichef.pro — Cómo Montar una Pastelería
A3: Treinta trámites en el orden en que hay que hacerlos. Marca la casilla, escribe lo que te presupuestan y lo que acabas pagando, y pon las dos fechas. Lo que cambia según tu comunidad autónoma va marcado en su columna.
B5: Fase | C5: Trámite | D5: Responsable | E5: Plazo (días) | F5: Coste previsto (€) | G5: Coste real (€) | H5: Fecha objetivo | I5: Fecha hecha | J5: ¿Cambia por CCAA? | K5: Notas
A6: F1 · Antes de firmar nada: viabilidad del local
A7: Pendiente | B7: F1 | C7: Comprobar en el planeamiento si el uso admite obrador (industria artesanal) o sólo comercio | D7: Promotor | E7: 10 | F7: A presupuestar | G7: Sin pagar | H7: 46275 | I7: 46275 | J7: No | K7: PA-06 NO está verificado: la clasificación urbanística de un obrador sólo tiene fuente comercial. Va como PREGUNTA al ayuntamiento, nunca como afirmación. [Fuente: PA-06]
A8: Pendiente | B8: F1 | C8: Confirmar que existe salida de humos hasta cubierta y quién la autoriza | D8: Promotor | E8: 15 | F8: A presupuestar | G8: Sin pagar | H8: 46275 | I8: 46275 | J8: No | K8: PS-86c: hasta cubierta y 1 m por encima de la cumbrera. Ojo: PA-07 corrige el research -el DB-HS 3 del CTE NO regula la ventilación de un local comercial, sólo viviendas y garajes-, así que lo que manda es el RITE más la ordenanza municipal. La comunidad de propietarios es el riesgo real, y no es normativo: es una junta. [Fuente: PS-86c + PA-07]
A9: Pendiente | B9: F1 | C9: Pedir por escrito a la comunidad de propietarios la autorización del conducto | D9: Promotor | E9: 30 | F9: A presupuestar | G9: Sin pagar | H9: 46275 | I9: 46275 | J9: No | K9: El plazo depende de cuándo se reúna la junta. Es la variable que menos controlas. [Fuente: supuesto]
A10: Pendiente | B10: F1 | C10: Comprobar potencia eléctrica disponible y coste del aumento | D10: Promotor | E10: 15 | F10: A presupuestar | G10: Sin pagar | H10: 46275 | I10: 46275 | J10: No | K10: PS-86a: 20-80 kW SÓLO para los hornos. [Fuente: PS-86a]
A11: Pendiente | B11: F1 | C11: Verificar que caben las 7 zonas obligatorias con marcha adelante | D11: Promotor | E11: 5 | F11: A presupuestar | G11: Sin pagar | H11: 46275 | I11: 46275 | J11: No | K11: [Fuente: PS-86d]
C12: AVANCE DE LA FASE F1 | D12: =IFERROR(COUNTIF(A7:A11,"Hecho"),"") -> 0 | E12: =IFERROR(COUNTIF(B7:B11,"F1"),"") -> 5 | F12: =IFERROR(SUMIF(F7:F11,">=0"),"") -> 0 | G12: =IFERROR(SUMIF(G7:G11,">=0"),"") -> 0 | J12: =IFERROR(IF(E12=0,"",(D12+COUNTIF(A7:A11,"N/A"))/E12),"") -> 0 | K12: Hechos · trámites de la fase · coste previsto · coste real · % de avance (los «N/A» cuentan como resueltos).
A14: F2 · Sociedad, altas y proyecto técnico
A15: Pendiente | B15: F2 | C15: Constituir la sociedad o darse de alta como autónomo | D15: Promotor | E15: 20 | F15: 600 | G15: Sin pagar | H15: 46275 | I15: 46275 | J15: No | K15: Importa para Verifactu: sociedad, 1-ene-2027; autónomo, 1-jul-2027 (PA-37). [Fuente: supuesto]
A16: Pendiente | B16: F2 | C16: Alta censal (modelo 036) y epígrafe de IAE | D16: Gestoría | E16: 3 | F16: A presupuestar | G16: Sin pagar | H16: 46275 | I16: 46275 | J16: No | K16: PA-38 corrige el research: los epígrafes son 419.1, 419.2, 644.1, 644.2 y 644.3 del RDLeg 1175/1990 y NO se copian de la guía de panadería sin mirar cuál te toca. PA-38b: hay exención de cuota por cifra de negocio (art. 82.1.b y c del TRLRHL). [Fuente: PA-38]
A17: Pendiente | B17: F2 | C17: Alta en el régimen correspondiente de la Seguridad Social | D17: Gestoría | E17: 3 | F17: A presupuestar | G17: Sin pagar | H17: 46275 | I17: 46275 | J17: No | K17: [Fuente: supuesto]
A18: Pendiente | B18: F2 | C18: Encargar el proyecto técnico visado | D18: Ingeniería | E18: 30 | F18: 5000 | G18: Sin pagar | H18: 46275 | I18: 46275 | J18: No | K18: Es el documento del que cuelga todo lo demás: sin él no hay licencia ni obra. [Fuente: PS-85e]
A19: Pendiente | B19: F2 | C19: Firmar el arrendamiento y depositar la fianza | D19: Promotor | E19: 5 | F19: 2400 | G19: Sin pagar | H19: 46275 | I19: 46275 | J19: Sí | K19: El depósito de la fianza se hace en el organismo de vivienda de tu CCAA y el plazo cambia en cada una. [Fuente: supuesto]
C20: AVANCE DE LA FASE F2 | D20: =IFERROR(COUNTIF(A15:A19,"Hecho"),"") -> 0 | E20: =IFERROR(COUNTIF(B15:B19,"F2"),"") -> 5 | F20: =IFERROR(SUMIF(F15:F19,">=0"),"") -> 8000 | G20: =IFERROR(SUMIF(G15:G19,">=0"),"") -> 0 | J20: =IFERROR(IF(E20=0,"",(D20+COUNTIF(A15:A19,"N/A"))/E20),"") -> 0 | K20: Hechos · trámites de la fase · coste previsto · coste real · % de avance (los «N/A» cuentan como resueltos).
A22: F3 · Licencia de actividad
A23: Pendiente | B23: F3 | C23: Presentar la declaración responsable o solicitar la licencia de actividad | D23: Ingeniería | E23: 45 | F23: 1800 | G23: Sin pagar | H23: 46275 | I23: 46275 | J23: Sí | K23: PA-05 NO está verificado (Directiva 2006/123/CE, Ley 20/2013, art. 69 de la Ley 39/2015 y la ordenanza municipal). El régimen general es de declaración responsable, pero el procedimiento y la tasa los pone tu ayuntamiento: la guía entrega la plantilla para que rellenes el tuyo, no una afirmación nacional. [Fuente: PA-05 + supuesto]
A24: Pendiente | B24: F3 | C24: Solicitar la licencia de obra menor o mayor según el proyecto | D24: Ingeniería | E24: 30 | F24: A presupuestar | G24: Sin pagar | H24: 46275 | I24: 46275 | J24: Sí | K24: [Fuente: supuesto]
A25: Pendiente | B25: F3 | C25: Tramitar el rótulo y la ocupación de vía pública si la hay | D25: Promotor | E25: 20 | F25: A presupuestar | G25: Sin pagar | H25: 46275 | I25: 46275 | J25: Sí | K25: [Fuente: supuesto]
C26: AVANCE DE LA FASE F3 | D26: =IFERROR(COUNTIF(A23:A25,"Hecho"),"") -> 0 | E26: =IFERROR(COUNTIF(B23:B25,"F3"),"") -> 3 | F26: =IFERROR(SUMIF(F23:F25,">=0"),"") -> 1800 | G26: =IFERROR(SUMIF(G23:G25,">=0"),"") -> 0 | J26: =IFERROR(IF(E26=0,"",(D26+COUNTIF(A23:A25,"N/A"))/E26),"") -> 0 | K26: Hechos · trámites de la fase · coste previsto · coste real · % de avance (los «N/A» cuentan como resueltos).
A28: F4 · Obra, equipamiento e instalaciones
A29: Pendiente | B29: F4 | C29: Ejecutar la obra civil e instalaciones | D29: Constructora | E29: 60 | F29: 81000 | G29: Sin pagar | H29: 46275 | I29: 46275 | J29: No | K29: Escenario medio: 900 €/m² × 90 m². [Fuente: PS-85b]
A30: Pendiente | B30: F4 | C30: Pedir el equipamiento con el plazo de entrega por escrito | D30: Promotor | E30: 5 | F30: A presupuestar | G30: Sin pagar | H30: 46275 | I30: 46275 | J30: No | K30: El plazo de entrega es lo que mueve la fecha de apertura, no el precio. Pídelo por escrito y mételo en el libro 7. [Fuente: supuesto]
A31: Pendiente | B31: F4 | C31: Certificado de instalación de gas y puesta en servicio (sólo si hay horno de gas) | D31: Instalador habilitado | E31: 15 | F31: A presupuestar | G31: Sin pagar | H31: 46275 | I31: 46275 | J31: No | K31: PA-08: con gas asumes certificado de empresa habilitada, puesta en servicio por el distribuidor e inspección periódica obligatoria cada 5 años, que se te repercute. Por debajo de 70 kW la inspección INCLUYE los aparatos, y mira la ventilación y el volumen mínimo del local. [Fuente: PA-08]
A32: Pendiente | B32: F4 | C32: Boletín eléctrico y legalización de la instalación | D32: Instalador habilitado | E32: 10 | F32: A presupuestar | G32: Sin pagar | H32: 46275 | I32: 46275 | J32: No | K32: [Fuente: supuesto]
A33: Pendiente | B33: F4 | C33: Comprobar accesibilidad del local | D33: Ingeniería | E33: 10 | F33: A presupuestar | G33: Sin pagar | H33: 46275 | I33: 46275 | J33: No | K33: PA-40: RD 193/2023, arts. 17 y 25 y D.F. sexta. Verificado letra a letra el 10-09-2026; mira el calendario dos veces. [Fuente: PA-40]
C34: AVANCE DE LA FASE F4 | D34: =IFERROR(COUNTIF(A29:A33,"Hecho"),"") -> 0 | E34: =IFERROR(COUNTIF(B29:B33,"F4"),"") -> 5 | F34: =IFERROR(SUMIF(F29:F33,">=0"),"") -> 81000 | G34: =IFERROR(SUMIF(G29:G33,">=0"),"") -> 0 | J34: =IFERROR(IF(E34=0,"",(D34+COUNTIF(A29:A33,"N/A"))/E34),"") -> 0 | K34: Hechos · trámites de la fase · coste previsto · coste real · % de avance (los «N/A» cuentan como resueltos).
A36: F5 · Sanidad, APPCC y formación
A37: Pendiente | B37: F5 | C37: Presentar la comunicación o declaración responsable al registro sanitario de tu CCAA | D37: Promotor | E37: 5 | F37: 120 | G37: Sin pagar | H37: 46275 | I37: 46275 | J37: Sí | K37: NO es el RGSEAA: una pastelería que vende al consumidor final está EXCLUIDA del registro estatal (PA-01). Es un trámite autonómico que NO habilita para abrir. En Madrid, Decreto 26/2026, en vigor desde el 28-03-2026: se presenta a la vez que inicias la actividad, no antes, y las que ya estaban abiertas tienen hasta el 28-03-2027 (PA-04). [Fuente: PA-01 + PA-04]
A38: Pendiente | B38: F5 | C38: Comprobar si tu B2B te obliga a inscribirte en el RGSEAA | D38: Promotor | E38: 5 | F38: A presupuestar | G38: Sin pagar | H38: 46275 | I38: 46275 | J38: No | K38: Sólo aplica si suministras a otros comercios minoristas DE DISTINTA TITULARIDAD. Si entras, las tres condiciones son acumulativas -marginal Y localizado Y restringido- y dentro de «marginal» hay dos vías ALTERNATIVAS: 25 % del volumen anual o 500 kg a la semana en total. Lo de central y sucursales va aparte: son una sola unidad comercial, pero cada una se inscribe por separado (PA-03). [Fuente: PA-02]
A39: Pendiente | B39: F5 | C39: Redactar el plan de APPCC y designar por su nombre a la persona responsable | D39: Promotor | E39: 20 | F39: 800 | G39: Sin pagar | H39: 46275 | I39: 46275 | J39: No | K39: PA-10: el APPCC simplificado es legal y está escrito (art. 20 del RD 1021/2022). Las guías sectoriales son voluntarias. [Fuente: PA-10 + supuesto]
A40: Pendiente | B40: F5 | C40: Formación de manipuladores y registro de formación por persona | D40: Promotor | E40: 10 | F40: 240 | G40: Sin pagar | H40: 46275 | I40: 46275 | J40: No | K40: PA-11: el «carnet de manipulador» NO existe desde 2010. Lo que hay que tener es un REGISTRO de formación, y es responsabilidad de la empresa. [Fuente: PA-11 + supuesto]
A41: Pendiente | B41: F5 | C41: Matriz de alérgenos de vitrina publicada antes de abrir | D41: Promotor | E41: 5 | F41: A presupuestar | G41: Sin pagar | H41: 46275 | I41: 46275 | J41: No | K41: R3: la matriz de vitrina la resuelve el 12-control-alergenos-vitrina.xlsx del kit y la guía NO la rehace. Lo que sí construye la guía es la de OBRADOR: materias primas por alérgeno y orden de elaboración, que es otra cosa (PA-22). [Fuente: PA-21]
A42: Pendiente | B42: F5 | C42: Fichar el sistema de registro de jornada | D42: Gestoría | E42: 5 | F42: A presupuestar | G42: Sin pagar | H42: 46275 | I42: 46275 | J42: No | K42: PA-34: hoy vale papel o una hoja de cálculo, conservados 4 años. Hay una reforma de registro horario digital EN TRAMITACIÓN que lo prohibiría: comprueba el estado antes de comprar un sistema, y no des ninguna fecha por cierta. [Fuente: PA-34]
C43: AVANCE DE LA FASE F5 | D43: =IFERROR(COUNTIF(A37:A42,"Hecho"),"") -> 0 | E43: =IFERROR(COUNTIF(B37:B42,"F5"),"") -> 6 | F43: =IFERROR(SUMIF(F37:F42,">=0"),"") -> 1160 | G43: =IFERROR(SUMIF(G37:G42,">=0"),"") -> 0 | J43: =IFERROR(IF(E43=0,"",(D43+COUNTIF(A37:A42,"N/A"))/E43),"") -> 0 | K43: Hechos · trámites de la fase · coste previsto · coste real · % de avance (los «N/A» cuentan como resueltos).
A45: F6 · Apertura: fiscal, laboral y comercial
A46: Pendiente | B46: F6 | C46: Contratar al equipo con el convenio y el grupo correctos | D46: Gestoría | E46: 15 | F46: A presupuestar | G46: Sin pagar | H46: 46275 | I46: 46275 | J46: Sí | K46: PA-33: el convenio es PROVINCIAL o autonómico. El de Madrid tiene 6 grupos y 15 pagas. Los de Barcelona, Valencia y Sevilla NO están verificados: busca el tuyo. Y si abres pastelería-cafetería puede caerte el de hostelería, o convivir los dos por áreas funcionales: eso no está resuelto y es de dinero. [Fuente: PA-33]
...

Sheet Árbol de Registro Sanitario
A1: ¿Registro Autonómico o RGSEAA?
A2: AI Chef Pro · aichef.pro — Cómo Montar una Pastelería
A3: Tres preguntas y un veredicto. Es la hoja que corrige el error más caro del sector: hay consultoras cobrando por tramitar un registro estatal que a una pastelería minorista no le hace falta.
A5: LAS TRES PREGUNTAS
A6: ¿Vendes al consumidor final (mostrador, encargos o tu propia web)? | B6: Sí | C6: Si la respuesta es «Sí», eres comercio al por menor. Y el comercio al por menor está EXCLUIDO de la obligación de inscribirse en el Registro General Sanitario de Empresas Alimentarias y Alimentos.
A7: ¿Suministras a otros establecimientos MINORISTAS de distinta titularidad? | B7: No | C7: Ojo a «de distinta titularidad»: si el que recibe es una sucursal tuya, no cuenta como suministro entre minoristas. Si la respuesta es «Sí», ve a la hoja «Suministro a Otros Minoristas» antes de leer el veredicto.
A8: ¿Tienes sucursales de tu misma titularidad? | B8: No | C8: Central con obrador y sucursales son UNA sola unidad comercial y el suministro entre ellas no es B2B. Pero cada una se inscribe en el registro autonómico de manera independiente: la ventaja viene con su deber pegado.
A9: Tu comunidad autónoma | B9: Madrid | C9: Cuatro comunidades de EJEMPLO: son las que se están adaptando ahora mismo al RD 1021/2022. Si la tuya no está, elige «Otra» y busca «registro sanitario establecimientos alimentarios menores» más el nombre de tu comunidad.
A11: EL VEREDICTO
A12: Régimen que te toca | B12: =IFERROR(IF(B6<>"Sí","Esto no es una pastelería minorista: pide asesoramiento, el art. 3 no te cubre",IF(B7="No","Te basta la comunicación o declaración responsable de tu comunidad autónoma: estás EXCLUIDO del RGSEAA",'Suministro a Otros Minoristas'!$B$41)),"") -> Te basta la comunicación o declaración responsable de tu comunidad autónoma: estás EXCLUIDO del RGSEAA
A13: Trámite concreto | B13: =IFERROR(IF(B7="No","Comunicación o declaración responsable al registro de establecimientos alimentarios menores de tu comunidad autónoma","Comunicación autonómica MÁS lo que diga la hoja de suministro a otros minoristas"),"") -> Comunicación o declaración responsable al registro de establecimientos alimentarios menores de tu comunidad autónoma
A14: ¿Ese trámite te habilita para abrir? | B14: No. La comunicación o declaración responsable NO es habilitante: se presenta al iniciar la actividad, no antes, y no sustituye a la licencia municipal.
A15: Plazo que aplica en tu comunidad | B15: =IFERROR(IF(B9="Madrid","Decreto 26/2026: se presenta A LA VEZ que inicias la actividad. Los establecimientos que ya estaban abiertos tienen hasta el 28-03-2027","Busca el decreto de tu comunidad: el plazo y el modelo los pone ella"),"") -> Decreto 26/2026: se presenta A LA VEZ que inicias la actividad. Los establecimientos que ya estaban abiertos tienen hasta el 28-03-2027
A16: Si tienes sucursales | B16: =IFERROR(IF(B8="Sí","Central y sucursales son UNA unidad comercial y el suministro entre ellas no es B2B, PERO cada una se inscribe por separado en el registro autonómico","No aplica"),"") -> No aplica
A18: LOS TRES CASOS, PARA QUE SE VEA POR QUÉ
A19: Tu situación | B19: Lo que te toca | C19: Por qué
A20: Vendes sólo al consumidor final, en tu establecimiento y por tu web | B20: Comunicación o declaración responsable al registro de tu comunidad autónoma | C20: Estás EXCLUIDO del RGSEAA por norma. La venta a distancia ya está dentro de la definición de minorista: vender por internet no te saca de este régimen.
A21: Suministras además a otros minoristas de DISTINTA titularidad, y cumples las tres condiciones del art. 3 | B21: La misma comunicación autonómica, MÁS declaración responsable del art. 3.5 y registro de destinatarios, cantidades y fechas | C21: Sigues fuera del RGSEAA, pero con papeles añadidos. La hoja «Suministro a Otros Minoristas» comprueba las tres condiciones una a una.
A22: Suministras a otros minoristas y NO cumples alguna de las tres | B22: Inscripción en el RGSEAA | C22: Basta con fallar una: las tres son acumulativas. La que más fácil se rompe es «restringido», y basta un cliente inscrito en el RGSEAA.
A24: Una pastelería que vende al consumidor final está excluida de la inscripción en el RGSEAA por el art. 2.2 del RD 191/2011, en la redacción que le dio el RD 1021/2022. Lo que sí tiene que hacer es inscribirse en el registro de su comunidad autónoma previa comunicación o declaración responsable, que la propia norma dice que «no será habilitante». Todo eso está verificado contra el texto consolidado el 10 de septiembre de 2026, y el enlace está en el comentario de cada celda.
A26: Listas de validación (no las borres: de aquí salen los desplegables)
A27: Sí o No
A28: Sí
A29: No
A31: Comunidad autónoma
A32: Madrid
A33: Cataluña
A34: Andalucía
A35: Comunitat Valenciana
A36: Otra (busca su decreto)

Sheet Suministro a Otros Minoristas
A1: Suministro a Otros Minoristas: el Árbol del Art. 3
A2: AI Chef Pro · aichef.pro — Cómo Montar una Pastelería
A3: Primero la puerta de entrada: esto SÓLO te aplica si suministras a establecimientos minoristas de DISTINTA titularidad. Si entras, las tres condiciones son ACUMULATIVAS, y dentro de «marginal» hay dos vías ALTERNATIVAS.
A5: PUERTA DE ENTRADA: ¿TE APLICA SIQUIERA?
A6: ¿Suministras alimentos de producción propia a establecimientos MINORISTAS de distinta titularidad? | B6: No | F6: Si la respuesta es «No», el art. 3 no te aplica y puedes saltarte el resto de la hoja. Vender al consumidor final, aunque sea por internet y a toda España, NO es suministrar a otros minoristas.
A7: Lectura de la puerta de entrada | B7: =IFERROR(IF(B6="No","El art. 3 NO te aplica: nada de lo de abajo te obliga","Te aplica: sigue con las tres condiciones"),"") -> El art. 3 NO te aplica: nada de lo de abajo te obliga
A9: TUS DESTINATARIOS
A10: Destinatario | B10: Kilos a la semana | C10: % del volumen anual | D10: Kilómetros | E10: ¿Inscrito en el RGSEAA? | F10: Notas
A11: Cafetería de la esquina | B11: 22 | C11: 0.018 | D11: 1.2 | E11: No
A12: Restaurante del barrio | B12: 14 | C12: 0.011 | D12: 2.4 | E12: No
A13: Tienda gourmet del centro | B13: 9 | C13: 0.007 | D13: 3.1 | E13: No
A14: Hotel de la avenida | B14: 6 | C14: 0.005 | D14: 4 | E14: No
A15: (libre: escribe aquí tu quinto cliente) | B15: 0 | C15: 0 | D15: 0 | E15: No
A16: (libre: escribe aquí tu sexto cliente) | B16: 0 | C16: 0 | D16: 0 | E16: No
A17: TOTAL | B17: =IFERROR(SUM(B11:B16),"") -> 51 | C17: =IFERROR(SUM(C11:C16),"") -> 0.041 | D17: =IFERROR(MAX(D11:D16),"") -> 4 | E17: =IFERROR(COUNTIF(E11:E16,"Sí"),"") -> 0 | F17: Los kilos y el porcentaje se suman; los kilómetros se toman al MÁXIMO (el destinatario más lejano es el que decide) y en la última columna se cuentan los que están inscritos en el RGSEAA.
A19: CONDICIÓN 1 · MARGINAL (dos vías ALTERNATIVAS: basta con cumplir una)
A20: Vía a) · Umbral del volumen anual (%) | B20: 0.25 | F20: «El suministro de alimentos a otros establecimientos de comercio al por menor es inferior o igual al 25 % del volumen anual de alimentos comercializados».
A21: Tu porcentaje a otros minoristas | B21: =IFERROR(C17,"") -> 0.041
A22: ¿Cumples la vía a)? | B22: =IFERROR(IF(B21<=B20,"Sí","No"),"") -> Sí
A23: Vía b) · Comercialización TOTAL máxima a la semana (kg) | B23: 500 | F23: «Supone una comercialización total de un máximo de 500 kg a la semana, INCLUYENDO el suministro a consumidor final y a otros establecimientos de comercio al por menor». Ojo: es el total, mostrador incluido, no el B2B solo.
A24: Lo que comercializas en total a la semana, mostrador incluido (kg) | B24: 380 | F24: SUPUESTO sembrado. Cuéntalo de verdad: es el peso de todo lo que sale por la puerta, no sólo lo que va al B2B. Si te pasas de 500, la vía b) se cierra y sólo te queda la a).
A25: ¿Cumples la vía b)? | B25: =IFERROR(IF(B24<=B23,"Sí","No"),"") -> Sí
A26: ¿ES MARGINAL? | B26: =IFERROR(IF(OR(B22="Sí",B25="Sí"),"Sí","No"),"") -> Sí | F26: Basta con cumplir UNA de las dos vías. Un obrador que despacha 900 kg a la semana sigue siendo marginal si su B2B no llega al 25 %.
A28: CONDICIÓN 2 · LOCALIZADO
A29: ¿Todos tus destinatarios están en tu unidad sanitaria local, zona de salud o territorio equivalente, o en una zona limítrofe? | B29: Sí | F29: El texto no habla de kilómetros dentro de la misma comunidad: habla de unidad sanitaria local, zona de salud o territorio equivalente. Los kilómetros aparecen sólo para el comercio ENTRE comunidades autónomas.
A30: Radio máximo entre establecimientos de comunidades DISTINTAS (km) | B30: 50 | F30: Y sólo si los registros sanitarios autonómicos de origen y destino son públicos y accesibles de forma efectiva.
A31: Distancia al destinatario más lejano (km) | B31: =IFERROR(D17,"") -> 4
A32: ¿Alguno de tus destinatarios está en otra comunidad autónoma? | B32: No
A33: ¿ES LOCALIZADO? | B33: =IFERROR(IF(AND(B29="Sí",OR(B32="No",B31<=B30)),"Sí","No"),"") -> Sí
A35: CONDICIÓN 3 · RESTRINGIDO
A36: Destinatarios inscritos en el RGSEAA | B36: =IFERROR(E17,"") -> 0 | F36: «Una actividad se considerará restringida cuando no se suministren productos alimenticios a establecimientos inscritos en el RGSEAA». Es el requisito que más fácil se rompe: basta UN cliente inscrito.
A37: ¿ES RESTRINGIDO? | B37: =IFERROR(IF(B36=0,"Sí","No"),"") -> Sí
A39: EL VEREDICTO
A40: Condiciones cumplidas (de tres) | B40: =IFERROR(COUNTIF(B26:B26,"Sí")+COUNTIF(B33:B33,"Sí")+COUNTIF(B37:B37,"Sí"),"") -> 3
A41: VEREDICTO | B41: =IFERROR(IF(B6="No","El art. 3 no te aplica: no suministras a otros minoristas de distinta titularidad",IF(B40=3,"Cumples las tres: sigues FUERA del RGSEAA, con la declaración responsable y el registro del art. 3.5","Te toca inscribirte en el RGSEAA: falla al menos una de las tres condiciones")),"") -> El art. 3 no te aplica: no suministras a otros minoristas de distinta titularidad
A42: Lo que además tienes que hacer si haces B2B | B42: =IFERROR(IF(B6="No","Nada de esto te aplica","Presentar declaración responsable de que cumples el art. 3 y llevar registro de destinatarios, cantidades y fechas"),"") -> Nada de esto te aplica
A44: Las tres condiciones son ACUMULATIVAS: hay que cumplir marginal Y localizado Y restringido. Lo que es alternativo son las dos vías DENTRO de «marginal». Y no existe la lectura de que «los 500 kg incluyen el mostrador, así que puedes servir a quien quieras mientras no llegues a esa cifra»: si te pasas del 25 % y de los 500 kg dejas de ser marginal, y aunque seas marginal sigues teniendo que ser localizado y restringido.
A46: Listas de validación (no las borres: de aquí salen los desplegables)
A47: Sí o No
A48: Sí
...

Sheet Ruta Doméstica
A1: Ruta Doméstica: Elaborar en Vivienda Particular
A2: AI Chef Pro · aichef.pro — Cómo Montar una Pastelería
A3: El art. 13.9 pone TRES obligaciones, no una: un tope de kilos, la proporcionalidad con el tamaño de las instalaciones y el «se demostrará documentalmente». El tope casi nunca se alcanza; el que sí se incumple es el segundo.
A5: TUS DATOS
A6: Metros cuadrados ÚTILES dedicados a la elaboración | B6: 12 | C6: Útiles de verdad: la superficie de trabajo y el almacenamiento dedicados, no los metros de la cocina entera si además comes en ella.
A7: Kilos de producto que elaboras a la semana | B7: 60 | C7: SUPUESTO sembrado. Pésalo durante dos semanas: es el dato que decide toda esta hoja y el único que un inspector te va a pedir por escrito.
A8: ¿Llevas un registro documental del volumen que elaboras? | B8: No | C8: Sin él, el art. 13.9 no se cumple aunque el volumen sea pequeño: la norma dice literalmente «lo cual se demostrará documentalmente».
A9: ¿Tu comunidad autónoma ha ampliado la lista del art. 13.8 por la letra e)? | B9: No | C9: La Comunitat Valenciana ya lo hizo: su Decreto 13/2025 pasa la lista de cinco letras a ocho. Lo que NO amplía es la refrigeración: la repostería sigue teniendo que ser estable a temperatura ambiente.
A10: Tu comunidad autónoma | B10: Madrid
A12: LOS TRES LÍMITES DEL ART. 13.9
A13: Tope absoluto de la norma (kg a la semana) | B13: 100 | C13: «En ningún caso podrán superar los 100 kilogramos semanales». Son unos 14 kg al día: una cocina doméstica no suele llegar, y por eso este contador casi siempre está en verde. No te fíes de eso.
A14: Semáforo del tope de kilos | B14: =IFERROR(IF(B7<=B13,"Dentro del tope","FUERA: el art. 13.9 no lo permite"),"") -> Dentro del tope
A15: Criterio propio de proporcionalidad (kg por m2 útil y semana) | B15: 8 | C15: La norma no da cifra. Esta sí, y es nuestra: sirve para que puedas enseñar un cálculo, no para citarla como si fuera legal.
A16: Tus kilos por metro cuadrado útil y semana | B16: =IFERROR(IF(B6=0,"",B7/B6),"") -> 5
A17: Semáforo de proporcionalidad | B17: =IFERROR(IF(B16="","",IF(B16<=B15,"Proporcional","Revísalo: mucho volumen para esos metros")),"") -> Proporcional
A18: ¿Lo puedes demostrar documentalmente? | B18: =IFERROR(IF(B8="Sí","Sí","NO: el art. 13.9 exige demostrarlo documentalmente, y sin eso da igual el volumen"),"") -> NO: el art. 13.9 exige demostrarlo documentalmente, y sin eso da igual el volumen
A20: LA LISTA BLANCA DEL ART. 13.8: CINCO LETRAS
A21: Letra y qué permite | C21: Qué NO entra por ahí
A22: a) Comidas preparadas con tratamiento térmico suficiente | C22: Lo que no lleva tratamiento térmico suficiente.
A23: b) Productos de panadería y repostería ESTABLES A TEMPERATURA AMBIENTE | C23: Una tarta rellena de nata NO entra por esta letra: no es estable a temperatura ambiente. Podría entrar por la e) si tu comunidad la ha añadido.
A24: c) Mermeladas, confituras y jaleas con tratamiento térmico después del envasado | C24: Las que se envasan en frío.
A25: d) Conservas vegetales con pH inferior a 4,5 | C25: Las de pH más alto: ahí el riesgo cambia de categoría.
A26: e) Otros alimentos que las autoridades competentes de las comunidades autónomas permitan en sus territorios | C26: Nada por defecto: esta letra está vacía hasta que TU comunidad la rellene. Una ya lo ha hecho.
A27: Por eso NO se puede decir «la tarta de nata desde casa no es legal en España». Lo correcto es: por defecto el RD 1021/2022 sólo permite en vivienda repostería estable a temperatura ambiente, y una tarta rellena de nata no entra en la lista del art. 13.8 SALVO que tu comunidad la haya añadido por la letra e). Comprueba tu decreto autonómico.
A29: LAS CINCO PROHIBICIONES DEL ART. 13.5, POR RÉGIMEN
A30: Letra | B30: Qué prohíbe | C30: Régimen
A31: b) | B31: Suministro a colectividades y a eventos | C31: INCONDICIONAL: no tiene salvedad autonómica.
A32: e) | B32: Congelación | C32: Sólo se podrán mantener en congelación las materias primas que se adquieran ya congeladas.
A33: a), c) y d) | B33: Consumo in situ · venta en el propio domicilio · suministro a otros establecimientos minoristas | C33: Las tres llevan cláusula de escape autonómica: comprueba tu decreto antes de darlas por prohibidas.
A35: ETIQUETA OBLIGATORIA
A36: Mención que tienen que llevar los alimentos elaborados en vivienda | B36: Elaborado en vivienda particular | C36: Más la fecha de elaboración, y además todo lo que ya exige la normativa de información alimentaria.
A38: SI TU COMUNIDAD ES LA COMUNITAT VALENCIANA
A39: El Decreto 13/2025 del Consell amplía la lista de la vivienda privada a ocho letras: añade confitería, sidra, vino, cerveza y licores, elaborados de miel, aceite de oliva virgen y otros elaborados vegetales. Abre además la venta directa EN EL PROPIO DOMICILIO sin consumo in situ, permite el suministro a otros establecimientos alimentarios menores con una marginalidad de 100 kg a la semana o el 25 %, y amplía el territorio de reparto a toda la Comunitat.
A40: Lo que NO amplía es la refrigeración: la repostería sigue teniendo que ser estable a temperatura ambiente. Y la comunicación o declaración responsable es condición para empezar. Es la prueba de que la letra e) no es teórica.
A42: EL VEREDICTO
A43: Lectura conjunta de los tres límites | B43: =IFERROR(IF(B7>B13,"NO: te pasas del tope de kilos del art. 13.9",IF(B8<>"Sí","NO todavía: te falta el registro documental",IF(AND(ISNUMBER(B16),B16>B15),"Cuidado: dentro del tope, pero mucho volumen para esos metros","Dentro de los tres límites, con la lista del art. 13.8 por delante"))),"") -> NO todavía: te falta el registro documental
A45: Estar dentro de los tres límites del art. 13.9 no basta por sí solo: lo que elabores tiene que estar además en la lista del art. 13.8, y no puedes hacer nada de lo que prohíbe el 13.5. Esta hoja es para decidir si la ruta doméstica es viable para ti, no para sustituir la consulta a tu comunidad autónoma.
A47: Listas de validación (no las borres: de aquí salen los desplegables)
A48: Sí o No
A49: Sí
...

Sheet Registro de Formación
A1: Registro de Formación de Manipuladores
A2: AI Chef Pro · aichef.pro — Cómo Montar una Pastelería
A3: El «carnet de manipulador de alimentos» NO existe desde 2010. Lo que hay que tener es este registro, y la responsabilidad de tenerlo es de la empresa, no del trabajador.
A5: Persona | B5: Perfil | C5: Contenido de la formación | D5: Horas | E5: Fecha de la formación | F5: Caduca el | G5: Días restantes | H5: Notas
A6: P1 · Jefe Pastelero | B6: OBRADOR | C6: Higiene alimentaria y buenas prácticas de manipulación | D6: 6 | E6: 46275 | F6: =IFERROR(IF(E6="","",E6+$B$13),"") -> 47005 | G6: =IFERROR(IF(F6="","",F6-$B$14),"") -> 730 | H6: El contenido y las horas son SUPUESTOS: los pone quien te dé la formación. Lo que no es supuesto es que tiene que quedar por escrito y con nombre y apellidos.
A7: P2 · Pastelero | B7: OBRADOR | C7: Higiene alimentaria, alérgenos y contaminación cruzada | D7: 6 | E7: 46275 | F7: =IFERROR(IF(E7="","",E7+$B$13),"") -> 47005 | G7: =IFERROR(IF(F7="","",F7-$B$14),"") -> 730
A8: P3 · Ayudante | B8: OBRADOR | C8: Higiene alimentaria básica | D8: 6 | E8: 46275 | F8: =IFERROR(IF(E8="","",E8+$B$13),"") -> 47005 | G8: =IFERROR(IF(F8="","",F8-$B$14),"") -> 730
A9: P4 · Dependiente Vitrina A | B9: COMERCIO | C9: Higiene alimentaria y alérgenos en la venta al público | D9: 6 | E9: 46275 | F9: =IFERROR(IF(E9="","",E9+$B$13),"") -> 47005 | G9: =IFERROR(IF(F9="","",F9-$B$14),"") -> 730
A10: P5 · Dependiente Vitrina B | B10: COMERCIO | C10: Higiene alimentaria y alérgenos en la venta al público | D10: 6 | E10: 46275 | F10: =IFERROR(IF(E10="","",E10+$B$13),"") -> 47005 | G10: =IFERROR(IF(F10="","",F10-$B$14),"") -> 730
A12: PARÁMETROS DE LA CASA
A13: Validez interna de la formación (días) | B13: 730 | H13: No es un plazo legal: es tu propia política, y tenerla escrita es lo que la hace defendible.
A14: Fecha de control | B14: 46275 | H14: Cámbiala por la de hoy cada vez que revises la hoja.
A16: RESUMEN
A17: Personas con formación registrada | B17: =IFERROR(COUNTIF(E6:E10,">0"),"") -> 5
A18: Formaciones caducadas | B18: =IFERROR(COUNTIF(G6:G10,"<0"),"") -> 0
A19: Formaciones que caducan en menos de 90 días | B19: =IFERROR(COUNTIF(G6:G10,"<90")-B18,"") -> 0 | H19: Los 90 días son un aviso propio para que te dé tiempo a organizar la sesión sin parar el obrador.
A21: El «carnet de manipulador de alimentos» no existe desde 2010: lo derogó el RD 109/2010 al suprimir el RD 202/2000. Lo que obliga hoy es el Reglamento (CE) 852/2004, que exige que los manipuladores estén supervisados e instruidos en materia de higiene alimentaria de forma proporcionada a su cometido, y esa responsabilidad es de la EMPRESA. Guarda el temario, la duración, la fecha y quién la impartió: eso es lo que se enseña en una inspección.

Sheet Cronograma y Ruta Crítica
A1: Cronograma y Ruta Crítica de la Apertura
A2: AI Chef Pro · aichef.pro — Cómo Montar una Pastelería
A3: Doce hitos con su duración y sus dependencias. La hoja calcula cuándo empieza y acaba cada uno, cuánta holgura tiene, cuáles están en la ruta crítica y en qué mes acabas abriendo. Todo en MESES y con aritmética de índices: no hay ni una función de fecha.
A5: Mes en que arranca el proyecto (1-12) | C5: 1 | O5: El mes natural en el que das el primer paso. De aquí sale la fecha de apertura estimada, y por eso conviene probar dos o tres: mover el arranque dos meses puede sacarte de una campaña o meterte en ella.
A6: Valor centinela de la matriz de dependencias (meses) | C6: 999 | O6: Truco de cálculo, no un dato: en la matriz de dependencias las casillas que no aplican llevan este número en vez de quedarse vacías, para que MIN pueda trabajar sólo con números. El formato de la matriz lo esconde. No lo cambies salvo que tu proyecto dure más de 999 meses.
A8: Id | B8: Hito | C8: Duración (meses) | D8: Depende de (1) | E8: Depende de (2) | F8: Depende de (3) | G8: Empieza (mes del proyecto) | H8: Acaba (mes del proyecto) | I8: Holgura (meses) | J8: ¿Ruta crítica? | K8: Mes natural de fin | O8: Notas
A9: H1 | B9: Búsqueda y cribado de local | C9: 2 | D9: - | E9: - | F9: - | G9: =IFERROR(MAX(IFERROR(INDEX($H$8:H8,MATCH(D9,$A$8:A8,0)),0),IFERROR(INDEX($H$8:H8,MATCH(E9,$A$8:A8,0)),0),IFERROR(INDEX($H$8:H8,MATCH(F9,$A$8:A8,0)),0)),"") -> 0 | H9: =IFERROR(G9+C9,"") -> 2 | I9: =IFERROR(MIN(MIN(C24:C35),MAX($H$9:$H$20))-H9,"") -> 0 | J9: =IFERROR(IF(ROUND(I9,3)<=0,"Sí","No"),"") -> Sí | K9: =IFERROR(INDEX('Cronograma y Ruta Crítica'!$A$73:$A$84,ROUNDDOWN(MOD($C$5-1+H9,12),0)+1),"") -> Marzo | O9: La búsqueda es lo único que puedes acelerar tú solo, y es donde se deciden la salida de humos y la potencia eléctrica: mira la ficha de visita del libro de capacidad ANTES de enamorarte de un local.
A10: H2 | B10: Firma del arrendamiento y fianza | C10: 0.5 | D10: H1 | E10: - | F10: - | G10: =IFERROR(MAX(IFERROR(INDEX($H$8:H9,MATCH(D10,$A$8:A9,0)),0),IFERROR(INDEX($H$8:H9,MATCH(E10,$A$8:A9,0)),0),IFERROR(INDEX($H$8:H9,MATCH(F10,$A$8:A9,0)),0)),"") -> 2 | H10: =IFERROR(G10+C10,"") -> 2.5 | I10: =IFERROR(MIN(MIN(D24:D35),MAX($H$9:$H$20))-H10,"") -> 0 | J10: =IFERROR(IF(ROUND(I10,3)<=0,"Sí","No"),"") -> Sí | K10: =IFERROR(INDEX('Cronograma y Ruta Crítica'!$A$73:$A$84,ROUNDDOWN(MOD($C$5-1+H10,12),0)+1),"") -> Marzo
A11: H3 | B11: Proyecto técnico visado | C11: 1 | D11: H2 | E11: - | F11: - | G11: =IFERROR(MAX(IFERROR(INDEX($H$8:H10,MATCH(D11,$A$8:A10,0)),0),IFERROR(INDEX($H$8:H10,MATCH(E11,$A$8:A10,0)),0),IFERROR(INDEX($H$8:H10,MATCH(F11,$A$8:A10,0)),0)),"") -> 2.5 | H11: =IFERROR(G11+C11,"") -> 3.5 | I11: =IFERROR(MIN(MIN(E24:E35),MAX($H$9:$H$20))-H11,"") -> 0 | J11: =IFERROR(IF(ROUND(I11,3)<=0,"Sí","No"),"") -> Sí | K11: =IFERROR(INDEX('Cronograma y Ruta Crítica'!$A$73:$A$84,ROUNDDOWN(MOD($C$5-1+H11,12),0)+1),"") -> Abril
A12: H4 | B12: Licencia de actividad o declaración responsable | C12: 1.5 | D12: H3 | E12: - | F12: - | G12: =IFERROR(MAX(IFERROR(INDEX($H$8:H11,MATCH(D12,$A$8:A11,0)),0),IFERROR(INDEX($H$8:H11,MATCH(E12,$A$8:A11,0)),0),IFERROR(INDEX($H$8:H11,MATCH(F12,$A$8:A11,0)),0)),"") -> 3.5 | H12: =IFERROR(G12+C12,"") -> 5 | I12: =IFERROR(MIN(MIN(F24:F35),MAX($H$9:$H$20))-H12,"") -> 0 | J12: =IFERROR(IF(ROUND(I12,3)<=0,"Sí","No"),"") -> Sí | K12: =IFERROR(INDEX('Cronograma y Ruta Crítica'!$A$73:$A$84,ROUNDDOWN(MOD($C$5-1+H12,12),0)+1),"") -> Junio | O12: Depende de tu ayuntamiento. Es el hito con más varianza de todo el cuadro, y por eso lo que se negocia es empezar a pedir el equipamiento en paralelo.
A13: H5 | B13: Obra civil e instalaciones | C13: 2 | D13: H4 | E13: - | F13: - | G13: =IFERROR(MAX(IFERROR(INDEX($H$8:H12,MATCH(D13,$A$8:A12,0)),0),IFERROR(INDEX($H$8:H12,MATCH(E13,$A$8:A12,0)),0),IFERROR(INDEX($H$8:H12,MATCH(F13,$A$8:A12,0)),0)),"") -> 5 | H13: =IFERROR(G13+C13,"") -> 7 | I13: =IFERROR(MIN(MIN(G24:G35),MAX($H$9:$H$20))-H13,"") -> 0 | J13: =IFERROR(IF(ROUND(I13,3)<=0,"Sí","No"),"") -> Sí | K13: =IFERROR(INDEX('Cronograma y Ruta Crítica'!$A$73:$A$84,ROUNDDOWN(MOD($C$5-1+H13,12),0)+1),"") -> Agosto
A14: H6 | B14: Pedido y entrega del equipamiento | C14: 2.5 | D14: H3 | E14: - | F14: - | G14: =IFERROR(MAX(IFERROR(INDEX($H$8:H13,MATCH(D14,$A$8:A13,0)),0),IFERROR(INDEX($H$8:H13,MATCH(E14,$A$8:A13,0)),0),IFERROR(INDEX($H$8:H13,MATCH(F14,$A$8:A13,0)),0)),"") -> 3.5 | H14: =IFERROR(G14+C14,"") -> 6 | I14: =IFERROR(MIN(MIN(H24:H35),MAX($H$9:$H$20))-H14,"") -> 1 | J14: =IFERROR(IF(ROUND(I14,3)<=0,"Sí","No"),"") -> No | K14: =IFERROR(INDEX('Cronograma y Ruta Crítica'!$A$73:$A$84,ROUNDDOWN(MOD($C$5-1+H14,12),0)+1),"") -> Julio | O14: Va en PARALELO a la obra porque depende del proyecto, no de la licencia. Es lo que le da holgura: si la pides tarde, esa holgura desaparece y el equipamiento pasa a mandar sobre la apertura.
A15: H7 | B15: Montaje y puesta en marcha del equipamiento | C15: 0.5 | D15: H5 | E15: H6 | F15: - | G15: =IFERROR(MAX(IFERROR(INDEX($H$8:H14,MATCH(D15,$A$8:A14,0)),0),IFERROR(INDEX($H$8:H14,MATCH(E15,$A$8:A14,0)),0),IFERROR(INDEX($H$8:H14,MATCH(F15,$A$8:A14,0)),0)),"") -> 7 | H15: =IFERROR(G15+C15,"") -> 7.5 | I15: =IFERROR(MIN(MIN(I24:I35),MAX($H$9:$H$20))-H15,"") -> 0 | J15: =IFERROR(IF(ROUND(I15,3)<=0,"Sí","No"),"") -> Sí | K15: =IFERROR(INDEX('Cronograma y Ruta Crítica'!$A$73:$A$84,ROUNDDOWN(MOD($C$5-1+H15,12),0)+1),"") -> Agosto
A16: H8 | B16: Comunicación al registro sanitario autonómico | C16: 0.5 | D16: H7 | E16: - | F16: - | G16: =IFERROR(MAX(IFERROR(INDEX($H$8:H15,MATCH(D16,$A$8:A15,0)),0),IFERROR(INDEX($H$8:H15,MATCH(E16,$A$8:A15,0)),0),IFERROR(INDEX($H$8:H15,MATCH(F16,$A$8:A15,0)),0)),"") -> 7.5 | H16: =IFERROR(G16+C16,"") -> 8 | I16: =IFERROR(MIN(MIN(J24:J35),MAX($H$9:$H$20))-H16,"") -> 0 | J16: =IFERROR(IF(ROUND(I16,3)<=0,"Sí","No"),"") -> Sí | K16: =IFERROR(INDEX('Cronograma y Ruta Crítica'!$A$73:$A$84,ROUNDDOWN(MOD($C$5-1+H16,12),0)+1),"") -> Septiembre
A17: H9 | B17: Formación de manipuladores y plan de APPCC | C17: 0.5 | D17: H7 | E17: - | F17: - | G17: =IFERROR(MAX(IFERROR(INDEX($H$8:H16,MATCH(D17,$A$8:A16,0)),0),IFERROR(INDEX($H$8:H16,MATCH(E17,$A$8:A16,0)),0),IFERROR(INDEX($H$8:H16,MATCH(F17,$A$8:A16,0)),0)),"") -> 7.5 | H17: =IFERROR(G17+C17,"") -> 8 | I17: =IFERROR(MIN(MIN(K24:K35),MAX($H$9:$H$20))-H17,"") -> 0 | J17: =IFERROR(IF(ROUND(I17,3)<=0,"Sí","No"),"") -> Sí | K17: =IFERROR(INDEX('Cronograma y Ruta Crítica'!$A$73:$A$84,ROUNDDOWN(MOD($C$5-1+H17,12),0)+1),"") -> Septiembre
A18: H10 | B18: Contratación del equipo y altas en Seguridad Social | C18: 0.5 | D18: H7 | E18: - | F18: - | G18: =IFERROR(MAX(IFERROR(INDEX($H$8:H17,MATCH(D18,$A$8:A17,0)),0),IFERROR(INDEX($H$8:H17,MATCH(E18,$A$8:A17,0)),0),IFERROR(INDEX($H$8:H17,MATCH(F18,$A$8:A17,0)),0)),"") -> 7.5 | H18: =IFERROR(G18+C18,"") -> 8 | I18: =IFERROR(MIN(MIN(L24:L35),MAX($H$9:$H$20))-H18,"") -> 0 | J18: =IFERROR(IF(ROUND(I18,3)<=0,"Sí","No"),"") -> Sí | K18: =IFERROR(INDEX('Cronograma y Ruta Crítica'!$A$73:$A$84,ROUNDDOWN(MOD($C$5-1+H18,12),0)+1),"") -> Septiembre
A19: H11 | B19: Pruebas de producción y cierre de la carta de apertura | C19: 0.5 | D19: H8 | E19: H9 | F19: H10 | G19: =IFERROR(MAX(IFERROR(INDEX($H$8:H18,MATCH(D19,$A$8:A18,0)),0),IFERROR(INDEX($H$8:H18,MATCH(E19,$A$8:A18,0)),0),IFERROR(INDEX($H$8:H18,MATCH(F19,$A$8:A18,0)),0)),"") -> 8 | H19: =IFERROR(G19+C19,"") -> 8.5 | I19: =IFERROR(MIN(MIN(M24:M35),MAX($H$9:$H$20))-H19,"") -> 0 | J19: =IFERROR(IF(ROUND(I19,3)<=0,"Sí","No"),"") -> Sí | K19: =IFERROR(INDEX('Cronograma y Ruta Crítica'!$A$73:$A$84,ROUNDDOWN(MOD($C$5-1+H19,12),0)+1),"") -> Septiembre
A20: H12 | B20: Apertura | C20: 0 | D20: H11 | E20: - | F20: - | G20: =IFERROR(MAX(IFERROR(INDEX($H$8:H19,MATCH(D20,$A$8:A19,0)),0),IFERROR(INDEX($H$8:H19,MATCH(E20,$A$8:A19,0)),0),IFERROR(INDEX($H$8:H19,MATCH(F20,$A$8:A19,0)),0)),"") -> 8.5 | H20: =IFERROR(G20+C20,"") -> 8.5 | I20: =IFERROR(MIN(MIN(N24:N35),MAX($H$9:$H$20))-H20,"") -> 0 | J20: =IFERROR(IF(ROUND(I20,3)<=0,"Sí","No"),"") -> Sí | K20: =IFERROR(INDEX('Cronograma y Ruta Crítica'!$A$73:$A$84,ROUNDDOWN(MOD($C$5-1+H20,12),0)+1),"") -> Septiembre | O20: Duración cero: la apertura es un instante, no una tarea. Lo que tiene delante son las pruebas de producción, y ésas no se recortan.
A22: MATRIZ DE DEPENDENCIAS: QUÉ HITO BLOQUEA A CUÁL
A23: Sucesor | B23: empieza en el mes... | C23: H1 | D23: H2 | E23: H3 | F23: H4 | G23: H5 | H23: H6 | I23: H7 | J23: H8 | K23: H9 | L23: H10 | M23: H11 | N23: H12 | O23: Notas
A24: H1 | B24: =IFERROR(G9,"") -> 0 | C24: =IFERROR(IF(OR($D$9=$A$9,$E$9=$A$9,$F$9=$A$9),$G$9,$C$6),"") -> 999 | D24: =IFERROR(IF(OR($D$9=$A$10,$E$9=$A$10,$F$9=$A$10),$G$9,$C$6),"") -> 999 | E24: =IFERROR(IF(OR($D$9=$A$11,$E$9=$A$11,$F$9=$A$11),$G$9,$C$6),"") -> 999 | F24: =IFERROR(IF(OR($D$9=$A$12,$E$9=$A$12,$F$9=$A$12),$G$9,$C$6),"") -> 999 | G24: =IFERROR(IF(OR($D$9=$A$13,$E$9=$A$13,$F$9=$A$13),$G$9,$C$6),"") -> 999 | H24: =IFERROR(IF(OR($D$9=$A$14,$E$9=$A$14,$F$9=$A$14),$G$9,$C$6),"") -> 999 | I24: =IFERROR(IF(OR($D$9=$A$15,$E$9=$A$15,$F$9=$A$15),$G$9,$C$6),"") -> 999 | J24: =IFERROR(IF(OR($D$9=$A$16,$E$9=$A$16,$F$9=$A$16),$G$9,$C$6),"") -> 999 | K24: =IFERROR(IF(OR($D$9=$A$17,$E$9=$A$17,$F$9=$A$17),$G$9,$C$6),"") -> 999 | L24: =IFERROR(IF(OR($D$9=$A$18,$E$9=$A$18,$F$9=$A$18),$G$9,$C$6),"") -> 999 | M24: =IFERROR(IF(OR($D$9=$A$19,$E$9=$A$19,$F$9=$A$19),$G$9,$C$6),"") -> 999 | N24: =IFERROR(IF(OR($D$9=$A$20,$E$9=$A$20,$F$9=$A$20),$G$9,$C$6),"") -> 999 | O24: Se lee por COLUMNAS: en la columna de H5 aparece el mes en que empieza cada hito que depende de H5. La holgura de H5 es la distancia entre cuando acaba y el primero de esos meses. Las casillas vacías no lo están: llevan el centinela y el formato las esconde.
A25: H2 | B25: =IFERROR(G10,"") -> 2 | C25: =IFERROR(IF(OR($D$10=$A$9,$E$10=$A$9,$F$10=$A$9),$G$10,$C$6),"") -> 2 | D25: =IFERROR(IF(OR($D$10=$A$10,$E$10=$A$10,$F$10=$A$10),$G$10,$C$6),"") -> 999 | E25: =IFERROR(IF(OR($D$10=$A$11,$E$10=$A$11,$F$10=$A$11),$G$10,$C$6),"") -> 999 | F25: =IFERROR(IF(OR($D$10=$A$12,$E$10=$A$12,$F$10=$A$12),$G$10,$C$6),"") -> 999 | G25: =IFERROR(IF(OR($D$10=$A$13,$E$10=$A$13,$F$10=$A$13),$G$10,$C$6),"") -> 999 | H25: =IFERROR(IF(OR($D$10=$A$14,$E$10=$A$14,$F$10=$A$14),$G$10,$C$6),"") -> 999 | I25: =IFERROR(IF(OR($D$10=$A$15,$E$10=$A$15,$F$10=$A$15),$G$10,$C$6),"") -> 999 | J25: =IFERROR(IF(OR($D$10=$A$16,$E$10=$A$16,$F$10=$A$16),$G$10,$C$6),"") -> 999 | K25: =IFERROR(IF(OR($D$10=$A$17,$E$10=$A$17,$F$10=$A$17),$G$10,$C$6),"") -> 999 | L25: =IFERROR(IF(OR($D$10=$A$18,$E$10=$A$18,$F$10=$A$18),$G$10,$C$6),"") -> 999 | M25: =IFERROR(IF(OR($D$10=$A$19,$E$10=$A$19,$F$10=$A$19),$G$10,$C$6),"") -> 999 | N25: =IFERROR(IF(OR($D$10=$A$20,$E$10=$A$20,$F$10=$A$20),$G$10,$C$6),"") -> 999
A26: H3 | B26: =IFERROR(G11,"") -> 2.5 | C26: =IFERROR(IF(OR($D$11=$A$9,$E$11=$A$9,$F$11=$A$9),$G$11,$C$6),"") -> 999 | D26: =IFERROR(IF(OR($D$11=$A$10,$E$11=$A$10,$F$11=$A$10),$G$11,$C$6),"") -> 2.5 | E26: =IFERROR(IF(OR($D$11=$A$11,$E$11=$A$11,$F$11=$A$11),$G$11,$C$6),"") -> 999 | F26: =IFERROR(IF(OR($D$11=$A$12,$E$11=$A$12,$F$11=$A$12),$G$11,$C$6),"") -> 999 | G26: =IFERROR(IF(OR($D$11=$A$13,$E$11=$A$13,$F$11=$A$13),$G$11,$C$6),"") -> 999 | H26: =IFERROR(IF(OR($D$11=$A$14,$E$11=$A$14,$F$11=$A$14),$G$11,$C$6),"") -> 999 | I26: =IFERROR(IF(OR($D$11=$A$15,$E$11=$A$15,$F$11=$A$15),$G$11,$C$6),"") -> 999 | J26: =IFERROR(IF(OR($D$11=$A$16,$E$11=$A$16,$F$11=$A$16),$G$11,$C$6),"") -> 999 | K26: =IFERROR(IF(OR($D$11=$A$17,$E$11=$A$17,$F$11=$A$17),$G$11,$C$6),"") -> 999 | L26: =IFERROR(IF(OR($D$11=$A$18,$E$11=$A$18,$F$11=$A$18),$G$11,$C$6),"") -> 999 | M26: =IFERROR(IF(OR($D$11=$A$19,$E$11=$A$19,$F$11=$A$19),$G$11,$C$6),"") -> 999 | N26: =IFERROR(IF(OR($D$11=$A$20,$E$11=$A$20,$F$11=$A$20),$G$11,$C$6),"") -> 999
A27: H4 | B27: =IFERROR(G12,"") -> 3.5 | C27: =IFERROR(IF(OR($D$12=$A$9,$E$12=$A$9,$F$12=$A$9),$G$12,$C$6),"") -> 999 | D27: =IFERROR(IF(OR($D$12=$A$10,$E$12=$A$10,$F$12=$A$10),$G$12,$C$6),"") -> 999 | E27: =IFERROR(IF(OR($D$12=$A$11,$E$12=$A$11,$F$12=$A$11),$G$12,$C$6),"") -> 3.5 | F27: =IFERROR(IF(OR($D$12=$A$12,$E$12=$A$12,$F$12=$A$12),$G$12,$C$6),"") -> 999 | G27: =IFERROR(IF(OR($D$12=$A$13,$E$12=$A$13,$F$12=$A$13),$G$12,$C$6),"") -> 999 | H27: =IFERROR(IF(OR($D$12=$A$14,$E$12=$A$14,$F$12=$A$14),$G$12,$C$6),"") -> 999 | I27: =IFERROR(IF(OR($D$12=$A$15,$E$12=$A$15,$F$12=$A$15),$G$12,$C$6),"") -> 999 | J27: =IFERROR(IF(OR($D$12=$A$16,$E$12=$A$16,$F$12=$A$16),$G$12,$C$6),"") -> 999 | K27: =IFERROR(IF(OR($D$12=$A$17,$E$12=$A$17,$F$12=$A$17),$G$12,$C$6),"") -> 999 | L27: =IFERROR(IF(OR($D$12=$A$18,$E$12=$A$18,$F$12=$A$18),$G$12,$C$6),"") -> 999 | M27: =IFERROR(IF(OR($D$12=$A$19,$E$12=$A$19,$F$12=$A$19),$G$12,$C$6),"") -> 999 | N27: =IFERROR(IF(OR($D$12=$A$20,$E$12=$A$20,$F$12=$A$20),$G$12,$C$6),"") -> 999
A28: H5 | B28: =IFERROR(G13,"") -> 5 | C28: =IFERROR(IF(OR($D$13=$A$9,$E$13=$A$9,$F$13=$A$9),$G$13,$C$6),"") -> 999 | D28: =IFERROR(IF(OR($D$13=$A$10,$E$13=$A$10,$F$13=$A$10),$G$13,$C$6),"") -> 999 | E28: =IFERROR(IF(OR($D$13=$A$11,$E$13=$A$11,$F$13=$A$11),$G$13,$C$6),"") -> 999 | F28: =IFERROR(IF(OR($D$13=$A$12,$E$13=$A$12,$F$13=$A$12),$G$13,$C$6),"") -> 5 | G28: =IFERROR(IF(OR($D$13=$A$13,$E$13=$A$13,$F$13=$A$13),$G$13,$C$6),"") -> 999 | H28: =IFERROR(IF(OR($D$13=$A$14,$E$13=$A$14,$F$13=$A$14),$G$13,$C$6),"") -> 999 | I28: =IFERROR(IF(OR($D$13=$A$15,$E$13=$A$15,$F$13=$A$15),$G$13,$C$6),"") -> 999 | J28: =IFERROR(IF(OR($D$13=$A$16,$E$13=$A$16,$F$13=$A$16),$G$13,$C$6),"") -> 999 | K28: =IFERROR(IF(OR($D$13=$A$17,$E$13=$A$17,$F$13=$A$17),$G$13,$C$6),"") -> 999 | L28: =IFERROR(IF(OR($D$13=$A$18,$E$13=$A$18,$F$13=$A$18),$G$13,$C$6),"") -> 999 | M28: =IFERROR(IF(OR($D$13=$A$19,$E$13=$A$19,$F$13=$A$19),$G$13,$C$6),"") -> 999 | N28: =IFERROR(IF(OR($D$13=$A$20,$E$13=$A$20,$F$13=$A$20),$G$13,$C$6),"") -> 999
A29: H6 | B29: =IFERROR(G14,"") -> 3.5 | C29: =IFERROR(IF(OR($D$14=$A$9,$E$14=$A$9,$F$14=$A$9),$G$14,$C$6),"") -> 999 | D29: =IFERROR(IF(OR($D$14=$A$10,$E$14=$A$10,$F$14=$A$10),$G$14,$C$6),"") -> 999 | E29: =IFERROR(IF(OR($D$14=$A$11,$E$14=$A$11,$F$14=$A$11),$G$14,$C$6),"") -> 3.5 | F29: =IFERROR(IF(OR($D$14=$A$12,$E$14=$A$12,$F$14=$A$12),$G$14,$C$6),"") -> 999 | G29: =IFERROR(IF(OR($D$14=$A$13,$E$14=$A$13,$F$14=$A$13),$G$14,$C$6),"") -> 999 | H29: =IFERROR(IF(OR($D$14=$A$14,$E$14=$A$14,$F$14=$A$14),$G$14,$C$6),"") -> 999 | I29: =IFERROR(IF(OR($D$14=$A$15,$E$14=$A$15,$F$14=$A$15),$G$14,$C$6),"") -> 999 | J29: =IFERROR(IF(OR($D$14=$A$16,$E$14=$A$16,$F$14=$A$16),$G$14,$C$6),"") -> 999 | K29: =IFERROR(IF(OR($D$14=$A$17,$E$14=$A$17,$F$14=$A$17),$G$14,$C$6),"") -> 999 | L29: =IFERROR(IF(OR($D$14=$A$18,$E$14=$A$18,$F$14=$A$18),$G$14,$C$6),"") -> 999 | M29: =IFERROR(IF(OR($D$14=$A$19,$E$14=$A$19,$F$14=$A$19),$G$14,$C$6),"") -> 999 | N29: =IFERROR(IF(OR($D$14=$A$20,$E$14=$A$20,$F$14=$A$20),$G$14,$C$6),"") -> 999
A30: H7 | B30: =IFERROR(G15,"") -> 7 | C30: =IFERROR(IF(OR($D$15=$A$9,$E$15=$A$9,$F$15=$A$9),$G$15,$C$6),"") -> 999 | D30: =IFERROR(IF(OR($D$15=$A$10,$E$15=$A$10,$F$15=$A$10),$G$15,$C$6),"") -> 999 | E30: =IFERROR(IF(OR($D$15=$A$11,$E$15=$A$11,$F$15=$A$11),$G$15,$C$6),"") -> 999 | F30: =IFERROR(IF(OR($D$15=$A$12,$E$15=$A$12,$F$15=$A$12),$G$15,$C$6),"") -> 999 | G30: =IFERROR(IF(OR($D$15=$A$13,$E$15=$A$13,$F$15=$A$13),$G$15,$C$6),"") -> 7 | H30: =IFERROR(IF(OR($D$15=$A$14,$E$15=$A$14,$F$15=$A$14),$G$15,$C$6),"") -> 7 | I30: =IFERROR(IF(OR($D$15=$A$15,$E$15=$A$15,$F$15=$A$15),$G$15,$C$6),"") -> 999 | J30: =IFERROR(IF(OR($D$15=$A$16,$E$15=$A$16,$F$15=$A$16),$G$15,$C$6),"") -> 999 | K30: =IFERROR(IF(OR($D$15=$A$17,$E$15=$A$17,$F$15=$A$17),$G$15,$C$6),"") -> 999 | L30: =IFERROR(IF(OR($D$15=$A$18,$E$15=$A$18,$F$15=$A$18),$G$15,$C$6),"") -> 999 | M30: =IFERROR(IF(OR($D$15=$A$19,$E$15=$A$19,$F$15=$A$19),$G$15,$C$6),"") -> 999 | N30: =IFERROR(IF(OR($D$15=$A$20,$E$15=$A$20,$F$15=$A$20),$G$15,$C$6),"") -> 999
A31: H8 | B31: =IFERROR(G16,"") -> 7.5 | C31: =IFERROR(IF(OR($D$16=$A$9,$E$16=$A$9,$F$16=$A$9),$G$16,$C$6),"") -> 999 | D31: =IFERROR(IF(OR($D$16=$A$10,$E$16=$A$10,$F$16=$A$10),$G$16,$C$6),"") -> 999 | E31: =IFERROR(IF(OR($D$16=$A$11,$E$16=$A$11,$F$16=$A$11),$G$16,$C$6),"") -> 999 | F31: =IFERROR(IF(OR($D$16=$A$12,$E$16=$A$12,$F$16=$A$12),$G$16,$C$6),"") -> 999 | G31: =IFERROR(IF(OR($D$16=$A$13,$E$16=$A$13,$F$16=$A$13),$G$16,$C$6),"") -> 999 | H31: =IFERROR(IF(OR($D$16=$A$14,$E$16=$A$14,$F$16=$A$14),$G$16,$C$6),"") -> 999 | I31: =IFERROR(IF(OR($D$16=$A$15,$E$16=$A$15,$F$16=$A$15),$G$16,$C$6),"") -> 7.5 | J31: =IFERROR(IF(OR($D$16=$A$16,$E$16=$A$16,$F$16=$A$16),$G$16,$C$6),"") -> 999 | K31: =IFERROR(IF(OR($D$16=$A$17,$E$16=$A$17,$F$16=$A$17),$G$16,$C$6),"") -> 999 | L31: =IFERROR(IF(OR($D$16=$A$18,$E$16=$A$18,$F$16=$A$18),$G$16,$C$6),"") -> 999 | M31: =IFERROR(IF(OR($D$16=$A$19,$E$16=$A$19,$F$16=$A$19),$G$16,$C$6),"") -> 999 | N31: =IFERROR(IF(OR($D$16=$A$20,$E$16=$A$20,$F$16=$A$20),$G$16,$C$6),"") -> 999
A32: H9 | B32: =IFERROR(G17,"") -> 7.5 | C32: =IFERROR(IF(OR($D$17=$A$9,$E$17=$A$9,$F$17=$A$9),$G$17,$C$6),"") -> 999 | D32: =IFERROR(IF(OR($D$17=$A$10,$E$17=$A$10,$F$17=$A$10),$G$17,$C$6),"") -> 999 | E32: =IFERROR(IF(OR($D$17=$A$11,$E$17=$A$11,$F$17=$A$11),$G$17,$C$6),"") -> 999 | F32: =IFERROR(IF(OR($D$17=$A$12,$E$17=$A$12,$F$17=$A$12),$G$17,$C$6),"") -> 999 | G32: =IFERROR(IF(OR($D$17=$A$13,$E$17=$A$13,$F$17=$A$13),$G$17,$C$6),"") -> 999 | H32: =IFERROR(IF(OR($D$17=$A$14,$E$17=$A$14,$F$17=$A$14),$G$17,$C$6),"") -> 999 | I32: =IFERROR(IF(OR($D$17=$A$15,$E$17=$A$15,$F$17=$A$15),$G$17,$C$6),"") -> 7.5 | J32: =IFERROR(IF(OR($D$17=$A$16,$E$17=$A$16,$F$17=$A$16),$G$17,$C$6),"") -> 999 | K32: =IFERROR(IF(OR($D$17=$A$17,$E$17=$A$17,$F$17=$A$17),$G$17,$C$6),"") -> 999 | L32: =IFERROR(IF(OR($D$17=$A$18,$E$17=$A$18,$F$17=$A$18),$G$17,$C$6),"") -> 999 | M32: =IFERROR(IF(OR($D$17=$A$19,$E$17=$A$19,$F$17=$A$19),$G$17,$C$6),"") -> 999 | N32: =IFERROR(IF(OR($D$17=$A$20,$E$17=$A$20,$F$17=$A$20),$G$17,$C$6),"") -> 999
A33: H10 | B33: =IFERROR(G18,"") -> 7.5 | C33: =IFERROR(IF(OR($D$18=$A$9,$E$18=$A$9,$F$18=$A$9),$G$18,$C$6),"") -> 999 | D33: =IFERROR(IF(OR($D$18=$A$10,$E$18=$A$10,$F$18=$A$10),$G$18,$C$6),"") -> 999 | E33: =IFERROR(IF(OR($D$18=$A$11,$E$18=$A$11,$F$18=$A$11),$G$18,$C$6),"") -> 999 | F33: =IFERROR(IF(OR($D$18=$A$12,$E$18=$A$12,$F$18=$A$12),$G$18,$C$6),"") -> 999 | G33: =IFERROR(IF(OR($D$18=$A$13,$E$18=$A$13,$F$18=$A$13),$G$18,$C$6),"") -> 999 | H33: =IFERROR(IF(OR($D$18=$A$14,$E$18=$A$14,$F$18=$A$14),$G$18,$C$6),"") -> 999 | I33: =IFERROR(IF(OR($D$18=$A$15,$E$18=$A$15,$F$18=$A$15),$G$18,$C$6),"") -> 7.5 | J33: =IFERROR(IF(OR($D$18=$A$16,$E$18=$A$16,$F$18=$A$16),$G$18,$C$6),"") -> 999 | K33: =IFERROR(IF(OR($D$18=$A$17,$E$18=$A$17,$F$18=$A$17),$G$18,$C$6),"") -> 999 | L33: =IFERROR(IF(OR($D$18=$A$18,$E$18=$A$18,$F$18=$A$18),$G$18,$C$6),"") -> 999 | M33: =IFERROR(IF(OR($D$18=$A$19,$E$18=$A$19,$F$18=$A$19),$G$18,$C$6),"") -> 999 | N33: =IFERROR(IF(OR($D$18=$A$20,$E$18=$A$20,$F$18=$A$20),$G$18,$C$6),"") -> 999
A34: H11 | B34: =IFERROR(G19,"") -> 8 | C34: =IFERROR(IF(OR($D$19=$A$9,$E$19=$A$9,$F$19=$A$9),$G$19,$C$6),"") -> 999 | D34: =IFERROR(IF(OR($D$19=$A$10,$E$19=$A$10,$F$19=$A$10),$G$19,$C$6),"") -> 999 | E34: =IFERROR(IF(OR($D$19=$A$11,$E$19=$A$11,$F$19=$A$11),$G$19,$C$6),"") -> 999 | F34: =IFERROR(IF(OR($D$19=$A$12,$E$19=$A$12,$F$19=$A$12),$G$19,$C$6),"") -> 999 | G34: =IFERROR(IF(OR($D$19=$A$13,$E$19=$A$13,$F$19=$A$13),$G$19,$C$6),"") -> 999 | H34: =IFERROR(IF(OR($D$19=$A$14,$E$19=$A$14,$F$19=$A$14),$G$19,$C$6),"") -> 999 | I34: =IFERROR(IF(OR($D$19=$A$15,$E$19=$A$15,$F$19=$A$15),$G$19,$C$6),"") -> 999 | J34: =IFERROR(IF(OR($D$19=$A$16,$E$19=$A$16,$F$19=$A$16),$G$19,$C$6),"") -> 8 | K34: =IFERROR(IF(OR($D$19=$A$17,$E$19=$A$17,$F$19=$A$17),$G$19,$C$6),"") -> 8 | L34: =IFERROR(IF(OR($D$19=$A$18,$E$19=$A$18,$F$19=$A$18),$G$19,$C$6),"") -> 8 | M34: =IFERROR(IF(OR($D$19=$A$19,$E$19=$A$19,$F$19=$A$19),$G$19,$C$6),"") -> 999 | N34: =IFERROR(IF(OR($D$19=$A$20,$E$19=$A$20,$F$19=$A$20),$G$19,$C$6),"") -> 999
A35: H12 | B35: =IFERROR(G20,"") -> 8.5 | C35: =IFERROR(IF(OR($D$20=$A$9,$E$20=$A$9,$F$20=$A$9),$G$20,$C$6),"") -> 999 | D35: =IFERROR(IF(OR($D$20=$A$10,$E$20=$A$10,$F$20=$A$10),$G$20,$C$6),"") -> 999 | E35: =IFERROR(IF(OR($D$20=$A$11,$E$20=$A$11,$F$20=$A$11),$G$20,$C$6),"") -> 999 | F35: =IFERROR(IF(OR($D$20=$A$12,$E$20=$A$12,$F$20=$A$12),$G$20,$C$6),"") -> 999 | G35: =IFERROR(IF(OR($D$20=$A$13,$E$20=$A$13,$F$20=$A$13),$G$20,$C$6),"") -> 999 | H35: =IFERROR(IF(OR($D$20=$A$14,$E$20=$A$14,$F$20=$A$14),$G$20,$C$6),"") -> 999 | I35: =IFERROR(IF(OR($D$20=$A$15,$E$20=$A$15,$F$20=$A$15),$G$20,$C$6),"") -> 999 | J35: =IFERROR(IF(OR($D$20=$A$16,$E$20=$A$16,$F$20=$A$16),$G$20,$C$6),"") -> 999 | K35: =IFERROR(IF(OR($D$20=$A$17,$E$20=$A$17,$F$20=$A$17),$G$20,$C$6),"") -> 999 | L35: =IFERROR(IF(OR($D$20=$A$18,$E$20=$A$18,$F$20=$A$18),$G$20,$C$6),"") -> 999 | M35: =IFERROR(IF(OR($D$20=$A$19,$E$20=$A$19,$F$20=$A$19),$G$20,$C$6),"") -> 8.5 | N35: =IFERROR(IF(OR($D$20=$A$20,$E$20=$A$20,$F$20=$A$20),$G$20,$C$6),"") -> 999
A37: LO QUE SALE DE TODO ESTO
A38: Duración total del proyecto (meses) | C38: =IFERROR(MAX(H9:H20),"") -> 8.5 | O38: Desde el primer día de búsqueda hasta el día que abres la puerta. No incluye lo que tardes en decidirte.
A39: Hitos SIN holgura (ruta crítica) | C39: =IFERROR(COUNTIF(J9:J20,"Sí"),"") -> 11 | O39: Los que si se retrasan un día retrasan la apertura un día. Son los únicos que hay que vigilar a diario; los demás tienen colchón, y saber cuáles son te ahorra media úlcera. Cuenta TODOS los de holgura cero, que son más que los del camino más largo: dos hitos en paralelo de la misma duración no tienen holgura ninguno de los dos.
A40: Mes natural en el que abres (1-12) | C40: =IFERROR(ROUNDDOWN(MOD($C$5-1+C38,12),0)+1,"") -> 9
A41: Nombre de ese mes | C41: =IFERROR(INDEX('Cronograma y Ruta Crítica'!$A$73:$A$84,C40),"") -> Septiembre
A42: ¿Esa apertura cae dentro de una campaña? | C42: =IFERROR(IF(COUNTIF($C$47:$C$52,C40)>0,"Sí","No"),"") -> No
A43: Aviso | C43: =IFERROR(IF(C42="Sí","Abres DENTRO de una campaña: el equipo estrena obrador el mes de más carga del año, y eso se paga en mermas y en encargos que no salen","Abres fuera de campaña: tienes rodaje antes del siguiente pico"),"") -> Abres fuera de campaña: tienes rodaje antes del siguiente pico
A45: LAS SEIS CAMPAÑAS DEL AÑO
...
